{"channel":"book","type":"update","data":[{"symbol":"ETH/GBP","bids":[{"price":2977.22,"qty":1.31757806}],"asks":[],"checksum":1007473305,"timestamp":"2024-06-01T17:52:16.378440Z"}]}
{"channel":"book","type":"update","data":[{"symbol":"ETH/GBP","bids":[{"price":2978.49,"qty":6.58509426}],"asks":[],"checksum":3825614288,"timestamp":"2024-06-01T17:52:16.378480Z"}]}
{"channel":"book","type":"update","data":[{"symbol":"ETH/GBP","bids":[{"price":2978.49,"qty":0.00000000},{"price":2975.01,"qty":1.31855212}],"asks":[],"checksum":1007473305,"timestamp":"2024-06-01T17:52:16.494113Z"}]}
{"channel":"book","type":"update","data":[{"symbol":"ETH/GBP","bids":[],"asks":[{"price":2978.72,"qty":6.58460711}],"checksum":3631098370,"timestamp":"2024-06-01T17:52:16.499586Z"}]}
{"channel":"book","type":"update","data":[{"symbol":"ETH/GBP","bids":[{"price":2978.50,"qty":6.58506941}],"asks":[],"checksum":185649925,"timestamp":"2024-06-01T17:52:16.499627Z"}]}
{"channel":"book","type":"update","data":[{"symbol":"ETH/GBP","bids":[{"price":2978.50,"qty":0.00000000},{"price":2975.01,"qty":1.31855212}],"asks":[],"checksum":3631098370,"timestamp":"2024-06-01T17:52:16.529427Z"}]}
{"channel":"book","type":"update","data":[{"symbol":"ETH/GBP","bids":[{"price":2978.02,"qty":0.00000000},{"price":2974.50,"qty":0.27200000}],"asks":[],"checksum":3505030749,"timestamp":"2024-06-01T17:52:16.529439Z"}]}
{"channel":"book","type":"update","data":[{"symbol":"ETH/GBP","bids":[{"price":2978.10,"qty":0.00000000},{"price":2973.93,"qty":0.27474654}],"asks":[],"checksum":3873404260,"timestamp":"2024-06-01T17:52:16.531968Z"}]}
{"channel":"book","type":"update","data":[{"symbol":"ETH/GBP","bids":[{"price":2977.42,"qty":0.31000000}],"asks":[],"checksum":2018065869,"timestamp":"2024-06-01T17:52:16.532350Z"}]}
{"channel":"book","type":"update","data":[{"symbol":"ETH/GBP","bids":[{"price":2978.08,"qty":13.17196693}],"asks":[],"checksum":229138298,"timestamp":"2024-06-01T17:52:16.534207Z"}]}
{"channel":"book","type":"update","data":[{"symbol":"ETH/GBP","bids":[{"price":2977.42,"qty":0.00000000},{"price":2974.50,"qty":0.27200000}],"asks":[],"checksum":3504445263,"timestamp":"2024-06-01T17:52:16.537204Z"}]}
{"channel":"book","type":"update","data":[{"symbol":"ETH/GBP","bids":[{"price":2978.16,"qty":0.31000000}],"asks":[],"checksum":3138091896,"timestamp":"2024-06-01T17:52:16.537245Z"}]}
{"channel":"book","type":"update","data":[{"symbol":"ETH/GBP","bids":[],"asks":[{"price":2979.11,"qty":0.00000000},{"price":2980.93,"qty":0.27473522}],"checksum":2657310395,"timestamp":"2024-06-01T17:52:16.584664Z"}]}
{"channel":"book","type":"update","data":[{"symbol":"ETH/GBP","bids":[],"asks":[{"price":2978.72,"qty":0.00000000},{"price":2980.95,"qty":0.22400000}],"checksum":3303803065,"timestamp":"2024-06-01T17:52:16.584675Z"}]}
{"channel":"book","type":"update","data":[{"symbol":"ETH/GBP","bids":[{"price":2976.22,"qty":0.00000000},{"price":2974.50,"qty":0.27200000}],"asks":[],"checksum":3534166225,"timestamp":"2024-06-01T17:52:16.584683Z"}]}
{"channel":"book","type":"update","data":[{"symbol":"ETH/GBP","bids":[],"asks":[{"price":2979.73,"qty":0.31000000}],"checksum":1491558606,"timestamp":"2024-06-01T17:52:16.587762Z"}]}
{"channel":"book","type":"update","data":[{"symbol":"ETH/GBP","bids":[],"asks":[{"price":2979.18,"qty":13.16717736}],"checksum":729158105,"timestamp":"2024-06-01T17:52:16.589280Z"}]}
{"channel":"book","type":"update","data":[{"symbol":"ETH/GBP","bids":[{"price":2976.63,"qty":1.31784139}],"asks":[],"checksum":567869503,"timestamp":"2024-06-01T17:52:16.589324Z"}]}
{"channel":"book","type":"update","data":[{"symbol":"ETH/GBP","bids":[],"asks":[{"price":2978.75,"qty":6.58454072}],"checksum":52260299,"timestamp":"2024-06-01T17:52:16.627893Z"}]}
{"channel":"book","type":"update","data":[{"symbol":"ETH/GBP","bids":[{"price":2978.31,"qty":6.58549427}],"asks":[],"checksum":748074666,"timestamp":"2024-06-01T17:52:16.628005Z"}]}
{"channel":"book","type":"update","data":[{"symbol":"ETH/GBP","bids":[{"price":2978.31,"qty":0.00000000},{"price":2975.01,"qty":1.31855212}],"asks":[],"checksum":52260299,"timestamp":"2024-06-01T17:52:16.634808Z"}]}
{"channel":"book","type":"update","data":[{"symbol":"ETH/GBP","bids":[],"asks":[{"price":2978.75,"qty":0.00000000},{"price":2980.94,"qty":0.20717085}],"checksum":1846912423,"timestamp":"2024-06-01T17:52:16.735705Z"}]}
{"channel":"book","type":"update","data":[{"symbol":"ETH/GBP","bids":[],"asks":[{"price":2979.18,"qty":0.00000000},{"price":2980.95,"qty":0.22400000}],"checksum":2187911284,"timestamp":"2024-06-01T17:52:16.740527Z"}]}
{"channel":"book","type":"update","data":[{"symbol":"ETH/GBP","bids":[],"asks":[{"price":2978.74,"qty":6.58454667}],"checksum":3637820194,"timestamp":"2024-06-01T17:52:16.744952Z"}]}
{"channel":"book","type":"update","data":[{"symbol":"ETH/GBP","bids":[{"price":2978.52,"qty":6.58501814}],"asks":[],"checksum":1723360534,"timestamp":"2024-06-01T17:52:16.744991Z"}]}
{"channel":"book","type":"update","data":[{"symbol":"ETH/GBP","bids":[],"asks":[{"price":2979.20,"qty":0.00000000},{"price":2980.95,"qty":0.22400000},{"price":2979.80,"qty":0.06978000}],"checksum":1694845656,"timestamp":"2024-06-01T17:52:16.759777Z"}]}
{"channel":"book","type":"update","data":[{"symbol":"ETH/GBP","bids":[],"asks":[{"price":2978.74,"qty":0.00000000},{"price":2980.95,"qty":0.22400000}],"checksum":3539522328,"timestamp":"2024-06-01T17:52:16.870652Z"}]}
{"channel":"book","type":"update","data":[{"symbol":"ETH/GBP","bids":[{"price":2978.52,"qty":0.00000000},{"price":2975.01,"qty":1.31855212}],"asks":[],"checksum":1821642028,"timestamp":"2024-06-01T17:52:16.870673Z"}]}
{"channel":"book","type":"update","data":[{"symbol":"ETH/GBP","bids":[{"price":2978.54,"qty":6.58498456}],"asks":[],"checksum":4273455442,"timestamp":"2024-06-01T17:52:16.875729Z"}]}
{"channel":"book","type":"update","data":[{"symbol":"ETH/GBP","bids":[],"asks":[{"price":2979.17,"qty":13.16718646}],"checksum":1356216081,"timestamp":"2024-06-01T17:52:16.875756Z"}]}
{"channel":"book","type":"update","data":[{"symbol":"ETH/GBP","bids":[],"asks":[{"price":2978.76,"qty":6.58451309}],"checksum":406500021,"timestamp":"2024-06-01T17:52:16.875830Z"}]}
{"channel":"book","type":"update","data":[{"symbol":"ETH/GBP","bids":[],"asks":[{"price":2979.17,"qty":0.00000000},{"price":2980.94,"qty":0.20717085}],"checksum":1875017954,"timestamp":"2024-06-01T17:52:16.881110Z"}]}
{"channel":"book","type":"update","data":[{"symbol":"ETH/GBP","bids":[],"asks":[{"price":2979.86,"qty":0.00000000},{"price":2980.95,"qty":0.22400000}],"checksum":899646371,"timestamp":"2024-06-01T17:52:17.027212Z"}]}
{"channel":"book","type":"update","data":[{"symbol":"ETH/GBP","bids":[],"asks":[{"price":2979.17,"qty":0.52673177}],"checksum":3898289768,"timestamp":"2024-06-01T17:52:17.032917Z"}]}
{"channel":"book","type":"update","data":[{"symbol":"ETH/GBP","bids":[],"asks":[{"price":2980.10,"qty":17.16573762}],"checksum":295948846,"timestamp":"2024-06-01T17:52:17.033004Z"}]}
{"channel":"book","type":"update","data":[{"symbol":"ETH/GBP","bids":[{"price":2978.54,"qty":0.00000000},{"price":2975.01,"qty":1.31855212}],"asks":[],"checksum":2206211664,"timestamp":"2024-06-01T17:52:17.161736Z"}]}
{"channel":"book","type":"update","data":[{"symbol":"ETH/GBP","bids":[],"asks":[{"price":2978.76,"qty":0.00000000},{"price":2980.94,"qty":0.20717085}],"checksum":3946095291,"timestamp":"2024-06-01T17:52:17.161793Z"}]}
{"channel":"book","type":"update","data":[{"symbol":"ETH/GBP","bids":[],"asks":[{"price":2978.74,"qty":6.58455260}],"checksum":4147335918,"timestamp":"2024-06-01T17:52:17.166635Z"}]}
{"channel":"book","type":"update","data":[{"symbol":"ETH/GBP","bids":[{"price":2978.51,"qty":6.58503011}],"asks":[],"checksum":1765220805,"timestamp":"2024-06-01T17:52:17.166660Z"}]}
{"channel":"book","type":"update","data":[{"symbol":"ETH/GBP","bids":[],"asks":[{"price":2979.19,"qty":13.16712211}],"checksum":1263665599,"timestamp":"2024-06-01T17:52:17.166828Z"}]}
{"channel":"book","type":"update","data":[{"symbol":"ETH/GBP","bids":[],"asks":[{"price":2978.74,"qty":0.00000000},{"price":2980.82,"qty":1.00000000}],"checksum":446407982,"timestamp":"2024-06-01T17:52:17.459395Z"}]}
{"channel":"book","type":"update","data":[{"symbol":"ETH/GBP","bids":[],"asks":[{"price":2978.73,"qty":6.58457433}],"checksum":540220155,"timestamp":"2024-06-01T17:52:17.464189Z"}]}
{"channel":"book","type":"update","data":[{"symbol":"ETH/GBP","bids":[],"asks":[{"price":2978.73,"qty":0.00000000},{"price":2980.82,"qty":1.00000000}],"checksum":446407982,"timestamp":"2024-06-01T17:52:17.469751Z"}]}
{"channel":"book","type":"update","data":[{"symbol":"ETH/GBP","bids":[],"asks":[{"price":2979.19,"qty":0.00000000},{"price":2980.94,"qty":0.20717085}],"checksum":1966133648,"timestamp":"2024-06-01T17:52:17.527622Z"}]}
{"channel":"book","type":"update","data":[{"symbol":"ETH/GBP","bids":[],"asks":[{"price":2979.16,"qty":13.16723065}],"checksum":2529440023,"timestamp":"2024-06-01T17:52:17.531848Z"}]}
{"channel":"book","type":"update","data":[{"symbol":"ETH/GBP","bids":[{"price":2978.51,"qty":0.00000000},{"price":2975.01,"qty":1.31855212}],"asks":[],"checksum":146817596,"timestamp":"2024-06-01T17:52:17.584892Z"}]}
{"channel":"book","type":"update","data":[{"symbol":"ETH/GBP","bids":[],"asks":[{"price":2979.15,"qty":6.58363742}],"checksum":3050193679,"timestamp":"2024-06-01T17:52:17.589311Z"}]}
{"channel":"book","type":"update","data":[{"symbol":"ETH/GBP","bids":[{"price":2978.52,"qty":6.58502376}],"asks":[],"checksum":196869537,"timestamp":"2024-06-01T17:52:17.589384Z"}]}
{"channel":"book","type":"update","data":[{"symbol":"ETH/GBP","bids":[],"asks":[{"price":2979.15,"qty":0.00000000},{"price":2980.82,"qty":1.00000000}],"checksum":3065379986,"timestamp":"2024-06-01T17:52:17.594211Z"}]}
{"channel":"book","type":"update","data":[{"symbol":"ETH/GBP","bids":[],"asks":[{"price":2979.15,"qty":6.58363742}],"checksum":196869537,"timestamp":"2024-06-01T17:52:17.724112Z"}]}
{"channel":"book","type":"update","data":[{"symbol":"ETH/GBP","bids":[],"asks":[{"price":2980.32,"qty":0.00000000},{"price":2980.82,"qty":1.00000000}],"checksum":1374305811,"timestamp":"2024-06-01T17:52:17.729721Z"}]}
{"channel":"book","type":"update","data":[{"symbol":"ETH/GBP","bids":[],"asks":[{"price":2979.15,"qty":0.00000000},{"price":2980.94,"qty":0.20717085}],"checksum":3231575210,"timestamp":"2024-06-01T17:52:17.730193Z"}]}
{"channel":"book","type":"update","data":[{"symbol":"ETH/GBP","bids":[{"price":2978.52,"qty":0.00000000},{"price":2975.01,"qty":1.31855212}],"asks":[],"checksum":2129154564,"timestamp":"2024-06-01T17:52:17.730399Z"}]}
{"channel":"book","type":"update","data":[{"symbol":"ETH/GBP","bids":[],"asks":[{"price":2980.81,"qty":2.94416492}],"checksum":243953481,"timestamp":"2024-06-01T17:52:17.732398Z"}]}
{"channel":"book","type":"update","data":[{"symbol":"ETH/GBP","bids":[{"price":2978.53,"qty":6.58500663}],"asks":[],"checksum":2607625544,"timestamp":"2024-06-01T17:52:17.734597Z"}]}
{"channel":"book","type":"update","data":[{"symbol":"ETH/GBP","bids":[{"price":2978.53,"qty":0.00000000},{"price":2975.01,"qty":1.31855212}],"asks":[],"checksum":243953481,"timestamp":"2024-06-01T17:52:17.739941Z"}]}
{"channel":"book","type":"update","data":[{"symbol":"ETH/GBP","bids":[],"asks":[{"price":2979.16,"qty":0.00000000},{"price":2980.94,"qty":0.20717085}],"checksum":1129038282,"timestamp":"2024-06-01T17:52:17.746372Z"}]}
{"channel":"book","type":"update","data":[{"symbol":"ETH/GBP","bids":[],"asks":[{"price":2979.15,"qty":13.16727485}],"checksum":3144951536,"timestamp":"2024-06-01T17:52:17.750626Z"}]}
{"channel":"book","type":"update","data":[{"symbol":"ETH/GBP","bids":[],"asks":[{"price":2979.80,"qty":0.00000000},{"price":2980.94,"qty":0.20717085},{"price":2979.16,"qty":0.06978000}],"checksum":3615317952,"timestamp":"2024-06-01T17:52:17.938593Z"}]}
{"channel":"book","type":"update","data":[{"symbol":"ETH/GBP","bids":[{"price":2978.31,"qty":6.58549427}],"asks":[],"checksum":4176905377,"timestamp":"2024-06-01T17:52:18.063510Z"}]}
{"channel":"book","type":"update","data":[{"symbol":"ETH/GBP","bids":[],"asks":[{"price":2978.72,"qty":6.58459583}],"checksum":4068428967,"timestamp":"2024-06-01T17:52:18.063584Z"}]}
{"channel":"book","type":"update","data":[{"symbol":"ETH/GBP","bids":[{"price":2978.31,"qty":0.00000000},{"price":2975.01,"qty":1.31855212}],"asks":[],"checksum":3723794374,"timestamp":"2024-06-01T17:52:18.068511Z"}]}
{"channel":"book","type":"update","data":[{"symbol":"ETH/GBP","bids":[],"asks":[{"price":2978.72,"qty":0.00000000},{"price":2980.82,"qty":1.00000000}],"checksum":3615317952,"timestamp":"2024-06-01T17:52:18.115264Z"}]}
{"channel":"book","type":"update","data":[{"symbol":"ETH/GBP","bids":[],"asks":[{"price":2979.15,"qty":0.00000000},{"price":2980.94,"qty":0.20717085}],"checksum":312200572,"timestamp":"2024-06-01T17:52:18.119946Z"}]}
{"channel":"book","type":"update","data":[{"symbol":"ETH/GBP","bids":[],"asks":[{"price":2979.14,"qty":13.16731905}],"checksum":2519489044,"timestamp":"2024-06-01T17:52:18.124739Z"}]}
{"channel":"book","type":"update","data":[{"symbol":"ETH/GBP","bids":[{"price":2978.47,"qty":6.58513482}],"asks":[],"checksum":4223520172,"timestamp":"2024-06-01T17:52:18.168049Z"}]}
{"channel":"book","type":"update","data":[{"symbol":"ETH/GBP","bids":[],"asks":[{"price":2978.71,"qty":6.58462151}],"checksum":660765255,"timestamp":"2024-06-01T17:52:18.168079Z"}]}
{"channel":"book","type":"update","data":[{"symbol":"ETH/GBP","bids":[],"asks":[{"price":2978.71,"qty":0.00000000},{"price":2980.82,"qty":1.00000000}],"checksum":4223520172,"timestamp":"2024-06-01T17:52:18.252113Z"}]}
{"channel":"book","type":"update","data":[{"symbol":"ETH/GBP","bids":[{"price":2978.47,"qty":0.00000000},{"price":2975.01,"qty":1.31855212}],"asks":[],"checksum":2519489044,"timestamp":"2024-06-01T17:52:18.255022Z"}]}
{"channel":"book","type":"update","data":[{"symbol":"ETH/GBP","bids":[],"asks":[{"price":2979.14,"qty":0.00000000},{"price":2980.94,"qty":0.20717085}],"checksum":312200572,"timestamp":"2024-06-01T17:52:18.255095Z"}]}
{"channel":"book","type":"update","data":[{"symbol":"ETH/GBP","bids":[{"price":2978.08,"qty":0.00000000},{"price":2974.50,"qty":0.27200000}],"asks":[],"checksum":1252114353,"timestamp":"2024-06-01T17:52:18.255105Z"}]}
{"channel":"book","type":"update","data":[{"symbol":"ETH/GBP","bids":[{"price":2978.16,"qty":0.00000000},{"price":2973.93,"qty":0.27474654}],"asks":[],"checksum":2389983504,"timestamp":"2024-06-01T17:52:18.258200Z"}]}
{"channel":"book","type":"update","data":[{"symbol":"ETH/GBP","bids":[{"price":2977.42,"qty":0.31000000}],"asks":[],"checksum":2246310796,"timestamp":"2024-06-01T17:52:18.258567Z"}]}
{"channel":"book","type":"update","data":[{"symbol":"ETH/GBP","bids":[{"price":2977.89,"qty":13.17280228}],"asks":[],"checksum":3657818526,"timestamp":"2024-06-01T17:52:18.260553Z"}]}
{"channel":"book","type":"update","data":[{"symbol":"ETH/GBP","bids":[{"price":2977.42,"qty":0.00000000},{"price":2974.50,"qty":0.27200000}],"asks":[],"checksum":3683413375,"timestamp":"2024-06-01T17:52:18.263218Z"}]}
{"channel":"book","type":"update","data":[{"symbol":"ETH/GBP","bids":[{"price":2977.97,"qty":0.31000000}],"asks":[],"checksum":2410881275,"timestamp":"2024-06-01T17:52:18.263908Z"}]}
{"channel":"book","type":"update","data":[{"symbol":"ETH/GBP","bids":[],"asks":[{"price":2978.55,"qty":6.58497640}],"checksum":195673289,"timestamp":"2024-06-01T17:52:18.271668Z"}]}
{"channel":"book","type":"update","data":[{"symbol":"ETH/GBP","bids":[{"price":2978.32,"qty":6.58547096}],"asks":[],"checksum":1059074365,"timestamp":"2024-06-01T17:52:18.271701Z"}]}
{"channel":"book","type":"update","data":[{"symbol":"ETH/GBP","bids":[],"asks":[{"price":2978.55,"qty":0.00000000},{"price":2980.94,"qty":0.20717085}],"checksum":3141184783,"timestamp":"2024-06-01T17:52:18.278037Z"}]}
{"channel":"book","type":"update","data":[{"symbol":"ETH/GBP","bids":[{"price":2978.32,"qty":0.00000000},{"price":2975.01,"qty":1.31855212}],"asks":[],"checksum":2410881275,"timestamp":"2024-06-01T17:52:18.278129Z"}]}
{"channel":"book","type":"update","data":[{"symbol":"ETH/GBP","bids":[],"asks":[{"price":2979.15,"qty":13.16727485}],"checksum":1247130183,"timestamp":"2024-06-01T17:52:18.325766Z"}]}
{"channel":"book","type":"update","data":[{"symbol":"ETH/GBP","bids":[],"asks":[{"price":2979.15,"qty":0.00000000},{"price":2980.94,"qty":0.20717085}],"checksum":2410881275,"timestamp":"2024-06-01T17:52:18.330383Z"}]}
{"channel":"book","type":"update","data":[{"symbol":"ETH/GBP","bids":[],"asks":[{"price":2978.58,"qty":6.58491683}],"checksum":3719323648,"timestamp":"2024-06-01T17:52:18.374974Z"}]}
{"channel":"book","type":"update","data":[{"symbol":"ETH/GBP","bids":[{"price":2978.34,"qty":6.58541234}],"asks":[],"checksum":3657498931,"timestamp":"2024-06-01T17:52:18.375062Z"}]}
{"channel":"book","type":"update","data":[{"symbol":"ETH/GBP","bids":[],"asks":[{"price":2978.58,"qty":0.00000000},{"price":2980.94,"qty":0.20717085}],"checksum":2281849288,"timestamp":"2024-06-01T17:52:18.380076Z"}]}
{"channel":"book","type":"update","data":[{"symbol":"ETH/GBP","bids":[{"price":2978.34,"qty":0.00000000},{"price":2975.01,"qty":1.31855212}],"asks":[],"checksum":2410881275,"timestamp":"2024-06-01T17:52:18.380204Z"}]}
{"channel":"book","type":"update","data":[{"symbol":"ETH/GBP","bids":[],"asks":[{"price":2978.57,"qty":6.58493446}],"checksum":2071760932,"timestamp":"2024-06-01T17:52:18.476810Z"}]}
{"channel":"book","type":"update","data":[{"symbol":"ETH/GBP","bids":[{"price":2978.34,"qty":6.58542536}],"asks":[],"checksum":2814385940,"timestamp":"2024-06-01T17:52:18.476840Z"}]}
{"channel":"book","type":"update","data":[{"symbol":"ETH/GBP","bids":[{"price":2978.34,"qty":0.00000000},{"price":2975.01,"qty":1.31855212}],"asks":[],"checksum":2071760932,"timestamp":"2024-06-01T17:52:18.481921Z"}]}
{"channel":"book","type":"update","data":[{"symbol":"ETH/GBP","bids":[],"asks":[{"price":2978.57,"qty":0.00000000},{"price":2980.94,"qty":0.20717085}],"checksum":2410881275,"timestamp":"2024-06-01T17:52:18.482107Z"}]}
{"channel":"book","type":"update","data":[{"symbol":"ETH/GBP","bids":[],"asks":[{"price":2979.15,"qty":13.16727485}],"checksum":1247130183,"timestamp":"2024-06-01T17:52:18.569745Z"}]}
{"channel":"book","type":"update","data":[{"symbol":"ETH/GBP","bids":[],"asks":[{"price":2979.73,"qty":0.00000000},{"price":2980.94,"qty":0.20717085}],"checksum":3262679922,"timestamp":"2024-06-01T17:52:18.572462Z"}]}
{"channel":"book","type":"update","data":[{"symbol":"ETH/GBP","bids":[],"asks":[{"price":2979.11,"qty":0.31000000}],"checksum":742390300,"timestamp":"2024-06-01T17:52:18.572725Z"}]}
{"channel":"book","type":"update","data":[{"symbol":"ETH/GBP","bids":[],"asks":[{"price":2979.15,"qty":0.00000000},{"price":2980.94,"qty":0.20717085}],"checksum":1252595122,"timestamp":"2024-06-01T17:52:18.574345Z"}]}
{"channel":"book","type":"update","data":[{"symbol":"ETH/GBP","bids":[],"asks":[{"price":2978.57,"qty":6.58493446}],"checksum":3291766051,"timestamp":"2024-06-01T17:52:18.578324Z"}]}
{"channel":"book","type":"update","data":[{"symbol":"ETH/GBP","bids":[{"price":2978.33,"qty":6.58543788}],"asks":[],"checksum":2743647163,"timestamp":"2024-06-01T17:52:18.578401Z"}]}
{"channel":"book","type":"update","data":[{"symbol":"ETH/GBP","bids":[],"asks":[{"price":2978.57,"qty":0.00000000},{"price":2980.94,"qty":0.20717085}],"checksum":756413226,"timestamp":"2024-06-01T17:52:18.594774Z"}]}
{"channel":"book","type":"update","data":[{"symbol":"ETH/GBP","bids":[{"price":2978.33,"qty":0.00000000},{"price":2975.01,"qty":1.31855212}],"asks":[],"checksum":1252595122,"timestamp":"2024-06-01T17:52:18.594953Z"}]}
{"channel":"book","type":"update","data":[{"symbol":"ETH/GBP","bids":[],"asks":[{"price":2978.56,"qty":6.58494410}],"checksum":1466044940,"timestamp":"2024-06-01T17:52:18.688098Z"}]}
{"channel":"book","type":"update","data":[{"symbol":"ETH/GBP","bids":[{"price":2978.31,"qty":6.58549427}],"asks":[],"checksum":707398151,"timestamp":"2024-06-01T17:52:18.688122Z"}]}
{"channel":"book","type":"update","data":[{"symbol":"ETH/GBP","bids":[{"price":2978.31,"qty":0.00000000},{"price":2975.01,"qty":1.31855212}],"asks":[],"checksum":1466044940,"timestamp":"2024-06-01T17:52:18.693250Z"}]}
{"channel":"book","type":"update","data":[{"symbol":"ETH/GBP","bids":[],"asks":[{"price":2978.56,"qty":0.00000000},{"price":2980.94,"qty":0.20717085}],"checksum":1252595122,"timestamp":"2024-06-01T17:52:18.753632Z"}]}
{"channel":"book","type":"update","data":[{"symbol":"ETH/GBP","bids":[{"price":2978.31,"qty":6.58549427}],"asks":[],"checksum":937495993,"timestamp":"2024-06-01T17:52:18.825571Z"}]}
{"channel":"book","type":"update","data":[{"symbol":"ETH/GBP","bids":[],"asks":[{"price":2979.10,"qty":13.16749585}],"checksum":3821376557,"timestamp":"2024-06-01T17:52:18.825586Z"}]}
{"channel":"book","type":"update","data":[{"symbol":"ETH/GBP","bids":[],"asks":[{"price":2979.10,"qty":19.75124377}],"checksum":2053416238,"timestamp":"2024-06-01T17:52:18.825609Z"}]}
{"channel":"book","type":"update","data":[{"symbol":"ETH/GBP","bids":[],"asks":[{"price":2979.10,"qty":13.16749585}],"checksum":3821376557,"timestamp":"2024-06-01T17:52:18.831632Z"}]}
{"channel":"book","type":"update","data":[{"symbol":"ETH/GBP","bids":[],"asks":[{"price":2979.10,"qty":0.00000000},{"price":2980.94,"qty":0.20717085}],"checksum":937495993,"timestamp":"2024-06-01T17:52:18.831744Z"}]}
{"channel":"book","type":"update","data":[{"symbol":"ETH/GBP","bids":[],"asks":[{"price":2979.10,"qty":6.58374792}],"checksum":1225465843,"timestamp":"2024-06-01T17:52:18.940031Z"}]}
{"channel":"book","type":"update","data":[{"symbol":"ETH/GBP","bids":[],"asks":[{"price":2979.10,"qty":0.00000000},{"price":2980.94,"qty":0.20717085}],"checksum":937495993,"timestamp":"2024-06-01T17:52:18.944838Z"}]}
{"channel":"book","type":"update","data":[{"symbol":"ETH/GBP","bids":[{"price":2978.31,"qty":0.00000000},{"price":2975.01,"qty":1.31855212}],"asks":[],"checksum":1252595122,"timestamp":"2024-06-01T17:52:18.961416Z"}]}
{"channel":"book","type":"update","data":[{"symbol":"ETH/GBP","bids":[{"price":2978.32,"qty":6.58547004}],"asks":[],"checksum":49620184,"timestamp":"2024-06-01T17:52:18.965925Z"}]}
{"channel":"book","type":"update","data":[{"symbol":"ETH/GBP","bids":[{"price":2978.32,"qty":0.00000000},{"price":2975.01,"qty":1.31855212}],"asks":[],"checksum":1252595122,"timestamp":"2024-06-01T17:52:19.020182Z"}]}
{"channel":"book","type":"update","data":[{"symbol":"ETH/GBP","bids":[],"asks":[{"price":2979.10,"qty":13.16749585}],"checksum":2660076582,"timestamp":"2024-06-01T17:52:19.029009Z"}]}
{"channel":"book","type":"update","data":[{"symbol":"ETH/GBP","bids":[],"asks":[{"price":2979.10,"qty":0.00000000},{"price":2980.94,"qty":0.20717085}],"checksum":1252595122,"timestamp":"2024-06-01T17:52:19.033613Z"}]}
{"channel":"book","type":"update","data":[{"symbol":"ETH/GBP","bids":[],"asks":[{"price":2978.55,"qty":6.58497106}],"checksum":2679409696,"timestamp":"2024-06-01T17:52:19.184199Z"}]}
{"channel":"book","type":"update","data":[{"symbol":"ETH/GBP","bids":[{"price":2978.33,"qty":6.58542855}],"asks":[],"checksum":939169193,"timestamp":"2024-06-01T17:52:19.184407Z"}]}
{"channel":"book","type":"update","data":[{"symbol":"ETH/GBP","bids":[{"price":2978.33,"qty":0.00000000},{"price":2975.01,"qty":1.31855212}],"asks":[],"checksum":2679409696,"timestamp":"2024-06-01T17:52:19.200796Z"}]}
{"channel":"book","type":"update","data":[{"symbol":"ETH/GBP","bids":[],"asks":[{"price":2978.55,"qty":0.00000000},{"price":2980.94,"qty":0.20717085}],"checksum":1252595122,"timestamp":"2024-06-01T17:52:19.200875Z"}]}
{"channel":"book","type":"update","data":[{"symbol":"ETH/GBP","bids":[],"asks":[{"price":2979.10,"qty":13.16749585}],"checksum":2660076582,"timestamp":"2024-06-01T17:52:19.251276Z"}]}
{"channel":"book","type":"update","data":[{"symbol":"ETH/GBP","bids":[],"asks":[{"price":2979.10,"qty":0.00000000},{"price":2980.94,"qty":0.20717085}],"checksum":1252595122,"timestamp":"2024-06-01T17:52:19.255659Z"}]}
{"channel":"book","type":"update","data":[{"symbol":"ETH/GBP","bids":[],"asks":[{"price":2978.51,"qty":6.58507050}],"checksum":2380462283,"timestamp":"2024-06-01T17:52:19.297357Z"}]}
{"channel":"book","type":"update","data":[{"symbol":"ETH/GBP","bids":[{"price":2978.28,"qty":6.58554644}],"asks":[],"checksum":1517265771,"timestamp":"2024-06-01T17:52:19.297424Z"}]}
{"channel":"book","type":"update","data":[{"symbol":"ETH/GBP","bids":[{"price":2978.28,"qty":0.00000000},{"price":2975.01,"qty":1.31855212}],"asks":[],"checksum":2380462283,"timestamp":"2024-06-01T17:52:19.309287Z"}]}
{"channel":"book","type":"update","data":[{"symbol":"ETH/GBP","bids":[],"asks":[{"price":2978.51,"qty":0.00000000},{"price":2980.94,"qty":0.20717085}],"checksum":1252595122,"timestamp":"2024-06-01T17:52:19.381158Z"}]}
{"channel":"book","type":"update","data":[{"symbol":"ETH/GBP","bids":[],"asks":[{"price":2978.57,"qty":6.58493085}],"checksum":3359662826,"timestamp":"2024-06-01T17:52:19.423247Z"}]}
{"channel":"book","type":"update","data":[{"symbol":"ETH/GBP","bids":[{"price":2978.34,"qty":6.58542324}],"asks":[],"checksum":2148412391,"timestamp":"2024-06-01T17:52:19.423324Z"}]}
{"channel":"book","type":"update","data":[{"symbol":"ETH/GBP","bids":[],"asks":[{"price":2979.17,"qty":0.00000000},{"price":2980.94,"qty":0.20717085}],"checksum":3908784871,"timestamp":"2024-06-01T17:52:19.428224Z"}]}
{"channel":"book","type":"update","data":[{"symbol":"ETH/GBP","bids":[],"asks":[{"price":2980.10,"qty":0.00000000},{"price":2980.95,"qty":0.22400000}],"checksum":437169449,"timestamp":"2024-06-01T17:52:19.428454Z"}]}
{"channel":"book","type":"update","data":[{"symbol":"ETH/GBP","bids":[],"asks":[{"price":2978.57,"qty":0.00000000},{"price":2981.04,"qty":0.94850883}],"checksum":2885048904,"timestamp":"2024-06-01T17:52:19.429442Z"}]}
{"channel":"book","type":"update","data":[{"symbol":"ETH/GBP","bids":[{"price":2978.34,"qty":0.00000000},{"price":2975.01,"qty":1.31855212}],"asks":[],"checksum":3820491589,"timestamp":"2024-06-01T17:52:19.429480Z"}]}
{"channel":"book","type":"update","data":[{"symbol":"ETH/GBP","bids":[],"asks":[{"price":2979.80,"qty":7.28901879}],"checksum":1936515832,"timestamp":"2024-06-01T17:52:19.433083Z"}]}
{"channel":"book","type":"update","data":[{"symbol":"ETH/GBP","bids":[],"asks":[{"price":2979.10,"qty":13.16749585}],"checksum":2869480173,"timestamp":"2024-06-01T17:52:19.461996Z"}]}
{"channel":"book","type":"update","data":[{"symbol":"ETH/GBP","bids":[],"asks":[{"price":2979.10,"qty":0.00000000},{"price":2980.95,"qty":0.22400000}],"checksum":1936515832,"timestamp":"2024-06-01T17:52:19.466310Z"}]}
{"channel":"book","type":"update","data":[{"symbol":"ETH/GBP","bids":[],"asks":[{"price":2978.56,"qty":6.58494731}],"checksum":4170802758,"timestamp":"2024-06-01T17:52:19.530401Z"}]}
{"channel":"book","type":"update","data":[{"symbol":"ETH/GBP","bids":[{"price":2978.33,"qty":6.58543707}],"asks":[],"checksum":2639446720,"timestamp":"2024-06-01T17:52:19.530563Z"}]}
{"channel":"book","type":"update","data":[{"symbol":"ETH/GBP","bids":[{"price":2978.33,"qty":0.00000000},{"price":2975.01,"qty":1.31855212}],"asks":[],"checksum":4170802758,"timestamp":"2024-06-01T17:52:19.548956Z"}]}
{"channel":"book","type":"update","data":[{"symbol":"ETH/GBP","bids":[],"asks":[{"price":2978.99,"qty":13.16801240}],"checksum":1835938098,"timestamp":"2024-06-01T17:52:19.889643Z"}]}
{"channel":"book","type":"update","data":[{"symbol":"ETH/GBP","bids":[{"price":2978.31,"qty":6.58549427}],"asks":[],"checksum":270936377,"timestamp":"2024-06-01T17:52:19.889713Z"}]}
{"channel":"book","type":"update","data":[{"symbol":"ETH/GBP","bids":[{"price":2977.34,"qty":0.00000000},{"price":2975.01,"qty":1.31855212}],"asks":[],"checksum":4280665689,"timestamp":"2024-06-01T17:52:19.892870Z"}]}
{"channel":"book","type":"update","data":[{"symbol":"ETH/GBP","bids":[{"price":2978.31,"qty":0.00000000},{"price":2974.50,"qty":0.27200000}],"asks":[],"checksum":4060410704,"timestamp":"2024-06-01T17:52:19.894048Z"}]}
{"channel":"book","type":"update","data":[{"symbol":"ETH/GBP","bids":[{"price":2977.57,"qty":5.37374300}],"asks":[],"checksum":405115717,"timestamp":"2024-06-01T17:52:19.895708Z"}]}
{"channel":"book","type":"update","data":[{"symbol":"ETH/GBP","bids":[],"asks":[{"price":2978.56,"qty":0.00000000},{"price":2980.94,"qty":0.20717085}],"checksum":3806019150,"timestamp":"2024-06-01T17:52:19.909855Z"}]}
{"channel":"book","type":"update","data":[{"symbol":"ETH/GBP","bids":[],"asks":[{"price":2978.99,"qty":0.00000000},{"price":2980.95,"qty":0.22400000}],"checksum":103235727,"timestamp":"2024-06-01T17:52:19.914564Z"}]}
{"channel":"book","type":"update","data":[{"symbol":"ETH/GBP","bids":[],"asks":[{"price":2978.55,"qty":6.58497228}],"checksum":4188000572,"timestamp":"2024-06-01T17:52:19.914611Z"}]}
{"channel":"book","type":"update","data":[{"symbol":"ETH/GBP","bids":[],"asks":[{"price":2978.55,"qty":0.00000000},{"price":2980.95,"qty":0.22400000}],"checksum":103235727,"timestamp":"2024-06-01T17:52:19.976200Z"}]}
{"channel":"book","type":"update","data":[{"symbol":"ETH/GBP","bids":[],"asks":[{"price":2979.10,"qty":6.58374792}],"checksum":444918260,"timestamp":"2024-06-01T17:52:20.037356Z"}]}
{"channel":"book","type":"update","data":[{"symbol":"ETH/GBP","bids":[{"price":2978.33,"qty":6.58544380}],"asks":[],"checksum":2894968726,"timestamp":"2024-06-01T17:52:20.037533Z"}]}
{"channel":"book","type":"update","data":[{"symbol":"ETH/GBP","bids":[],"asks":[{"price":2979.10,"qty":0.00000000},{"price":2980.95,"qty":0.22400000}],"checksum":2955812589,"timestamp":"2024-06-01T17:52:20.042933Z"}]}
{"channel":"book","type":"update","data":[{"symbol":"ETH/GBP","bids":[{"price":2978.33,"qty":0.00000000},{"price":2975.01,"qty":1.31855212}],"asks":[],"checksum":103235727,"timestamp":"2024-06-01T17:52:20.132237Z"}]}
{"channel":"book","type":"update","data":[{"symbol":"ETH/GBP","bids":[{"price":2978.31,"qty":6.58547607}],"asks":[],"checksum":546313759,"timestamp":"2024-06-01T17:52:20.137832Z"}]}
{"channel":"book","type":"update","data":[{"symbol":"ETH/GBP","bids":[],"asks":[{"price":2979.09,"qty":13.16754005}],"checksum":4288454529,"timestamp":"2024-06-01T17:52:20.137864Z"}]}
{"channel":"book","type":"update","data":[{"symbol":"ETH/GBP","bids":[],"asks":[{"price":2978.53,"qty":6.58500849}],"checksum":2164673345,"timestamp":"2024-06-01T17:52:20.137976Z"}]}
{"channel":"book","type":"update","data":[{"symbol":"ETH/GBP","bids":[],"asks":[{"price":2979.09,"qty":0.00000000},{"price":2980.94,"qty":0.20717085}],"checksum":801884958,"timestamp":"2024-06-01T17:52:20.143443Z"}]}
{"channel":"book","type":"update","data":[{"symbol":"ETH/GBP","bids":[],"asks":[{"price":2978.53,"qty":0.00000000},{"price":2980.95,"qty":0.22400000}],"checksum":546313759,"timestamp":"2024-06-01T17:52:20.177011Z"}]}
{"channel":"book","type":"update","data":[{"symbol":"ETH/GBP","bids":[{"price":2978.31,"qty":0.00000000},{"price":2975.01,"qty":1.31855212}],"asks":[],"checksum":103235727,"timestamp":"2024-06-01T17:52:20.177195Z"}]}
{"channel":"book","type":"update","data":[{"symbol":"ETH/GBP","bids":[],"asks":[{"price":2979.10,"qty":6.58374792}],"checksum":444918260,"timestamp":"2024-06-01T17:52:20.238920Z"}]}
{"channel":"book","type":"update","data":[{"symbol":"ETH/GBP","bids":[{"price":2978.33,"qty":6.58544578}],"asks":[],"checksum":555133540,"timestamp":"2024-06-01T17:52:20.238978Z"}]}
{"channel":"book","type":"update","data":[{"symbol":"ETH/GBP","bids":[],"asks":[{"price":2979.10,"qty":0.00000000},{"price":2980.95,"qty":0.22400000}],"checksum":1035272991,"timestamp":"2024-06-01T17:52:20.243802Z"}]}
{"channel":"book","type":"update","data":[{"symbol":"ETH/GBP","bids":[{"price":2978.33,"qty":0.00000000},{"price":2975.01,"qty":1.31855212}],"asks":[],"checksum":103235727,"timestamp":"2024-06-01T17:52:20.268525Z"}]}
{"channel":"book","type":"update","data":[{"symbol":"ETH/GBP","bids":[{"price":2977.89,"qty":0.00000000},{"price":2974.50,"qty":0.27200000}],"asks":[],"checksum":4209920072,"timestamp":"2024-06-01T17:52:20.270224Z"}]}
{"channel":"book","type":"update","data":[{"symbol":"ETH/GBP","bids":[{"price":2977.97,"qty":0.00000000},{"price":2973.93,"qty":0.27474654}],"asks":[],"checksum":401058099,"timestamp":"2024-06-01T17:52:20.272805Z"}]}
{"channel":"book","type":"update","data":[{"symbol":"ETH/GBP","bids":[{"price":2977.94,"qty":13.17260690}],"asks":[],"checksum":2681966267,"timestamp":"2024-06-01T17:52:20.273792Z"}]}
{"channel":"book","type":"update","data":[{"symbol":"ETH/GBP","bids":[],"asks":[{"price":2978.59,"qty":6.58488205}],"checksum":2981330143,"timestamp":"2024-06-01T17:52:20.341247Z"}]}
{"channel":"book","type":"update","data":[{"symbol":"ETH/GBP","bids":[{"price":2978.37,"qty":6.58534963}],"asks":[],"checksum":2233660239,"timestamp":"2024-06-01T17:52:20.341302Z"}]}
{"channel":"book","type":"update","data":[{"symbol":"ETH/GBP","bids":[],"asks":[{"price":2979.10,"qty":13.16749585}],"checksum":1711473808,"timestamp":"2024-06-01T17:52:20.341410Z"}]}
{"channel":"book","type":"update","data":[{"symbol":"ETH/GBP","bids":[],"asks":[{"price":2979.10,"qty":0.00000000},{"price":2980.94,"qty":0.20717085}],"checksum":2233660239,"timestamp":"2024-06-01T17:52:20.346719Z"}]}
{"channel":"book","type":"update","data":[{"symbol":"ETH/GBP","bids":[],"asks":[{"price":2978.59,"qty":0.00000000},{"price":2980.95,"qty":0.22400000}],"checksum":3486727932,"timestamp":"2024-06-01T17:52:20.350249Z"}]}
{"channel":"book","type":"update","data":[{"symbol":"ETH/GBP","bids":[{"price":2978.37,"qty":0.00000000},{"price":2974.50,"qty":0.27200000}],"asks":[],"checksum":2681966267,"timestamp":"2024-06-01T17:52:20.376256Z"}]}
{"channel":"book","type":"update","data":[{"symbol":"ETH/GBP","bids":[],"asks":[{"price":2978.60,"qty":6.58485810}],"checksum":327797181,"timestamp":"2024-06-01T17:52:20.513864Z"}]}
{"channel":"book","type":"update","data":[{"symbol":"ETH/GBP","bids":[{"price":2978.31,"qty":6.58549427}],"asks":[],"checksum":390615372,"timestamp":"2024-06-01T17:52:20.513942Z"}]}
{"channel":"book","type":"update","data":[{"symbol":"ETH/GBP","bids":[{"price":2978.31,"qty":0.00000000},{"price":2974.50,"qty":0.27200000}],"asks":[],"checksum":327797181,"timestamp":"2024-06-01T17:52:20.519160Z"}]}
{"channel":"book","type":"update","data":[{"symbol":"ETH/GBP","bids":[{"price":2975.02,"qty":0.00000000},{"price":2973.93,"qty":0.27474654},{"price":2975.84,"qty":1.34000000}],"asks":[],"checksum":3502994280,"timestamp":"2024-06-01T17:52:20.661621Z"}]}
{"channel":"book","type":"update","data":[{"symbol":"ETH/GBP","bids":[],"asks":[{"price":2979.03,"qty":13.16780634}],"checksum":910674890,"timestamp":"2024-06-01T17:52:20.662220Z"}]}
{"channel":"book","type":"update","data":[{"symbol":"ETH/GBP","bids":[{"price":2977.94,"qty":0.00000000},{"price":2973.93,"qty":0.27474654}],"asks":[],"checksum":4197701814,"timestamp":"2024-06-01T17:52:20.662238Z"}]}
{"channel":"book","type":"update","data":[{"symbol":"ETH/GBP","bids":[],"asks":[{"price":2978.60,"qty":0.00000000},{"price":2980.94,"qty":0.20717085}],"checksum":2796197484,"timestamp":"2024-06-01T17:52:20.662321Z"}]}
{"channel":"book","type":"update","data":[{"symbol":"ETH/GBP","bids":[{"price":2978.39,"qty":6.58530793}],"asks":[],"checksum":3329345371,"timestamp":"2024-06-01T17:52:20.662481Z"}]}
{"channel":"book","type":"update","data":[{"symbol":"ETH/GBP","bids":[{"price":2978.39,"qty":0.00000000},{"price":2973.93,"qty":0.27474654}],"asks":[],"checksum":2796197484,"timestamp":"2024-06-01T17:52:20.670193Z"}]}
{"channel":"book","type":"update","data":[{"symbol":"ETH/GBP","bids":[],"asks":[{"price":2979.03,"qty":0.00000000},{"price":2980.95,"qty":0.22400000}],"checksum":1315122721,"timestamp":"2024-06-01T17:52:20.670389Z"}]}
{"channel":"book","type":"update","data":[{"symbol":"ETH/GBP","bids":[],"asks":[{"price":2980.94,"qty":0.21492266}],"checksum":3169535271,"timestamp":"2024-06-01T17:52:20.673124Z"}]}
{"channel":"book","type":"update","data":[{"symbol":"ETH/GBP","bids":[],"asks":[{"price":2980.94,"qty":0.00775181}],"checksum":439318890,"timestamp":"2024-06-01T17:52:20.673250Z"}]}
{"channel":"book","type":"update","data":[{"symbol":"ETH/GBP","bids":[],"asks":[{"price":2978.75,"qty":6.58453214}],"checksum":616153555,"timestamp":"2024-06-01T17:52:20.675875Z"}]}
{"channel":"book","type":"update","data":[{"symbol":"ETH/GBP","bids":[{"price":2978.12,"qty":13.17178686}],"asks":[],"checksum":1400718707,"timestamp":"2024-06-01T17:52:20.676022Z"}]}
{"channel":"book","type":"update","data":[{"symbol":"ETH/GBP","bids":[],"asks":[{"price":2978.75,"qty":0.00000000},{"price":2980.95,"qty":0.22400000}],"checksum":2747291050,"timestamp":"2024-06-01T17:52:20.703145Z"}]}
{"channel":"book","type":"update","data":[{"symbol":"ETH/GBP","bids":[{"price":2978.12,"qty":0.00000000},{"price":2973.93,"qty":0.27474654}],"asks":[],"checksum":439318890,"timestamp":"2024-06-01T17:52:20.708552Z"}]}
{"channel":"book","type":"update","data":[{"symbol":"ETH/GBP","bids":[{"price":2978.48,"qty":6.58510142}],"asks":[],"checksum":1542483604,"timestamp":"2024-06-01T17:52:20.767690Z"}]}
{"channel":"book","type":"update","data":[{"symbol":"ETH/GBP","bids":[],"asks":[{"price":2978.72,"qty":6.58459141}],"checksum":4061939019,"timestamp":"2024-06-01T17:52:20.792058Z"}]}
{"channel":"book","type":"update","data":[{"symbol":"ETH/GBP","bids":[],"asks":[{"price":2978.72,"qty":0.00000000},{"price":2980.95,"qty":0.22400000}],"checksum":1542483604,"timestamp":"2024-06-01T17:52:21.250591Z"}]}
{"channel":"book","type":"update","data":[{"symbol":"ETH/GBP","bids":[{"price":2978.48,"qty":0.00000000},{"price":2973.93,"qty":0.27474654}],"asks":[],"checksum":439318890,"timestamp":"2024-06-01T17:52:21.250681Z"}]}
{"channel":"book","type":"update","data":[{"symbol":"ETH/GBP","bids":[],"asks":[{"price":2978.75,"qty":6.58453017}],"checksum":160341939,"timestamp":"2024-06-01T17:52:21.256018Z"}]}
{"channel":"book","type":"update","data":[{"symbol":"ETH/GBP","bids":[],"asks":[{"price":2979.18,"qty":13.16715452}],"checksum":221912462,"timestamp":"2024-06-01T17:52:21.256065Z"}]}
{"channel":"book","type":"update","data":[{"symbol":"ETH/GBP","bids":[{"price":2978.50,"qty":6.58505269}],"asks":[],"checksum":2756033041,"timestamp":"2024-06-01T17:52:21.256080Z"}]}
{"channel":"book","type":"update","data":[{"symbol":"ETH/GBP","bids":[{"price":2978.05,"qty":13.17210121}],"asks":[],"checksum":4114892850,"timestamp":"2024-06-01T17:52:21.256134Z"}]}
{"channel":"book","type":"update","data":[{"symbol":"ETH/GBP","bids":[],"asks":[{"price":2978.75,"qty":0.00000000},{"price":2980.94,"qty":0.00775181}],"checksum":3935834614,"timestamp":"2024-06-01T17:52:21.277023Z"}]}
{"channel":"book","type":"update","data":[{"symbol":"ETH/GBP","bids":[],"asks":[{"price":2978.73,"qty":6.58456770}],"checksum":3025693767,"timestamp":"2024-06-01T17:52:21.376850Z"}]}
{"channel":"book","type":"update","data":[{"symbol":"ETH/GBP","bids":[{"price":2978.50,"qty":0.00000000},{"price":2974.50,"qty":0.27200000}],"asks":[],"checksum":495539670,"timestamp":"2024-06-01T17:52:21.550303Z"}]}
{"channel":"book","type":"update","data":[{"symbol":"ETH/GBP","bids":[{"price":2978.48,"qty":6.58509813}],"asks":[],"checksum":273379337,"timestamp":"2024-06-01T17:52:21.554549Z"}]}
{"channel":"book","type":"update","data":[{"symbol":"ETH/GBP","bids":[{"price":2978.48,"qty":0.00000000},{"price":2974.50,"qty":0.27200000}],"asks":[],"checksum":495539670,"timestamp":"2024-06-01T17:52:21.601279Z"}]}
{"channel":"book","type":"update","data":[{"symbol":"ETH/GBP","bids":[{"price":2978.50,"qty":6.58506966}],"asks":[],"checksum":3894301202,"timestamp":"2024-06-01T17:52:21.751046Z"}]}
{"channel":"book","type":"update","data":[{"symbol":"ETH/GBP","bids":[],"asks":[{"price":2978.73,"qty":0.00000000},{"price":2980.94,"qty":0.00775181}],"checksum":3068014499,"timestamp":"2024-06-01T17:52:21.826194Z"}]}
{"channel":"book","type":"update","data":[{"symbol":"ETH/GBP","bids":[{"price":2978.50,"qty":0.00000000},{"price":2974.50,"qty":0.27200000}],"asks":[],"checksum":51243694,"timestamp":"2024-06-01T17:52:21.826346Z"}]}
{"channel":"book","type":"update","data":[{"symbol":"ETH/GBP","bids":[],"asks":[{"price":2978.75,"qty":6.58453649}],"checksum":3058536947,"timestamp":"2024-06-01T17:52:21.831599Z"}]}
{"channel":"book","type":"update","data":[{"symbol":"ETH/GBP","bids":[],"asks":[{"price":2979.80,"qty":0.00000000},{"price":2980.94,"qty":0.00775181}],"checksum":770047394,"timestamp":"2024-06-01T17:52:21.847200Z"}]}
{"channel":"book","type":"update","data":[{"symbol":"ETH/GBP","bids":[],"asks":[{"price":2978.72,"qty":2.60743887}],"checksum":570179132,"timestamp":"2024-06-01T17:52:21.851850Z"}]}
{"channel":"book","type":"update","data":[{"symbol":"ETH/GBP","bids":[],"asks":[{"price":2980.10,"qty":15.05557901}],"checksum":3492411196,"timestamp":"2024-06-01T17:52:21.852097Z"}]}
{"channel":"book","type":"update","data":[{"symbol":"ETH/GBP","bids":[],"asks":[{"price":2978.75,"qty":0.00000000},{"price":2980.82,"qty":1.00000000}],"checksum":767433846,"timestamp":"2024-06-01T17:52:21.858403Z"}]}
{"channel":"book","type":"update","data":[{"symbol":"ETH/GBP","bids":[{"price":2978.31,"qty":6.58549427}],"asks":[],"checksum":3962771903,"timestamp":"2024-06-01T17:52:21.862149Z"}]}
{"channel":"book","type":"update","data":[{"symbol":"ETH/GBP","bids":[{"price":2978.31,"qty":0.00000000},{"price":2974.50,"qty":0.27200000}],"asks":[],"checksum":767433846,"timestamp":"2024-06-01T17:52:21.868243Z"}]}
{"channel":"book","type":"update","data":[{"symbol":"ETH/GBP","bids":[{"price":2978.05,"qty":0.00000000},{"price":2973.93,"qty":0.27474654}],"asks":[],"checksum":2197737950,"timestamp":"2024-06-01T17:52:22.097818Z"}]}
{"channel":"book","type":"update","data":[{"symbol":"ETH/GBP","bids":[{"price":2978.55,"qty":6.58496034}],"asks":[],"checksum":1501561693,"timestamp":"2024-06-01T17:52:22.102938Z"}]}
{"channel":"book","type":"update","data":[{"symbol":"ETH/GBP","bids":[{"price":2978.11,"qty":13.17183086}],"asks":[],"checksum":3864647136,"timestamp":"2024-06-01T17:52:22.102997Z"}]}
{"channel":"book","type":"update","data":[{"symbol":"ETH/GBP","bids":[],"asks":[{"price":2978.79,"qty":6.58445286}],"checksum":78562466,"timestamp":"2024-06-01T17:52:22.103029Z"}]}
{"channel":"book","type":"update","data":[{"symbol":"ETH/GBP","bids":[],"asks":[{"price":2979.11,"qty":0.00000000},{"price":2980.82,"qty":1.00000000}],"checksum":4234658769,"timestamp":"2024-06-01T17:52:22.106170Z"}]}
{"channel":"book","type":"update","data":[{"symbol":"ETH/GBP","bids":[],"asks":[{"price":2978.79,"qty":0.00000000},{"price":2980.94,"qty":0.00775181}],"checksum":319826567,"timestamp":"2024-06-01T17:52:22.110176Z"}]}
{"channel":"book","type":"update","data":[{"symbol":"ETH/GBP","bids":[{"price":2978.55,"qty":0.00000000},{"price":2974.50,"qty":0.27200000}],"asks":[],"checksum":3198438716,"timestamp":"2024-06-01T17:52:22.178058Z"}]}
{"channel":"book","type":"update","data":[{"symbol":"ETH/GBP","bids":[{"price":2978.31,"qty":6.58549427}],"asks":[],"checksum":3826683374,"timestamp":"2024-06-01T17:52:22.318036Z"}]}
{"channel":"book","type":"update","data":[{"symbol":"ETH/GBP","bids":[],"asks":[{"price":2978.76,"qty":6.58450149}],"checksum":1663348438,"timestamp":"2024-06-01T17:52:22.318091Z"}]}
{"channel":"book","type":"update","data":[{"symbol":"ETH/GBP","bids":[{"price":2978.31,"qty":0.00000000},{"price":2974.50,"qty":0.27200000}],"asks":[],"checksum":2216994733,"timestamp":"2024-06-01T17:52:22.323028Z"}]}
{"channel":"book","type":"update","data":[{"symbol":"ETH/GBP","bids":[],"asks":[{"price":2978.76,"qty":0.00000000},{"price":2980.94,"qty":0.00775181}],"checksum":3198438716,"timestamp":"2024-06-01T17:52:22.367119Z"}]}
{"channel":"book","type":"update","data":[{"symbol":"ETH/GBP","bids":[],"asks":[{"price":2978.74,"qty":6.58456405}],"checksum":2162495369,"timestamp":"2024-06-01T17:52:22.460712Z"}]}
{"channel":"book","type":"update","data":[{"symbol":"ETH/GBP","bids":[{"price":2978.51,"qty":6.58503278}],"asks":[],"checksum":2771153352,"timestamp":"2024-06-01T17:52:22.460863Z"}]}
{"channel":"book","type":"update","data":[{"symbol":"ETH/GBP","bids":[],"asks":[{"price":2978.74,"qty":0.00000000},{"price":2980.94,"qty":0.00775181}],"checksum":504985481,"timestamp":"2024-06-01T17:52:22.677806Z"}]}
{"channel":"book","type":"update","data":[{"symbol":"ETH/GBP","bids":[],"asks":[{"price":2978.76,"qty":6.58451997}],"checksum":681020544,"timestamp":"2024-06-01T17:52:22.681669Z"}]}
{"channel":"book","type":"update","data":[{"symbol":"ETH/GBP","bids":[{"price":2978.51,"qty":0.00000000},{"price":2974.50,"qty":0.27200000}],"asks":[],"checksum":857059990,"timestamp":"2024-06-01T17:52:22.754355Z"}]}
{"channel":"book","type":"update","data":[{"symbol":"ETH/GBP","bids":[{"price":2978.52,"qty":6.58502192}],"asks":[],"checksum":1614555310,"timestamp":"2024-06-01T17:52:22.758705Z"}]}
{"channel":"book","type":"update","data":[{"symbol":"ETH/GBP","bids":[{"price":2978.52,"qty":0.00000000},{"price":2974.50,"qty":0.27200000}],"asks":[],"checksum":857059990,"timestamp":"2024-06-01T17:52:22.787447Z"}]}
{"channel":"book","type":"update","data":[{"symbol":"ETH/GBP","bids":[],"asks":[{"price":2978.76,"qty":0.00000000},{"price":2980.94,"qty":0.00775181}],"checksum":3198438716,"timestamp":"2024-06-01T17:52:22.861310Z"}]}
{"channel":"book","type":"update","data":[{"symbol":"ETH/GBP","bids":[],"asks":[{"price":2978.75,"qty":6.58452919}],"checksum":796555392,"timestamp":"2024-06-01T17:52:22.865618Z"}]}
{"channel":"book","type":"update","data":[{"symbol":"ETH/GBP","bids":[{"price":2978.31,"qty":6.58549427}],"asks":[],"checksum":642821244,"timestamp":"2024-06-01T17:52:22.865691Z"}]}
{"channel":"book","type":"update","data":[{"symbol":"ETH/GBP","bids":[{"price":2978.31,"qty":0.00000000},{"price":2974.50,"qty":0.27200000}],"asks":[],"checksum":796555392,"timestamp":"2024-06-01T17:52:22.870127Z"}]}
{"channel":"book","type":"update","data":[{"symbol":"ETH/GBP","bids":[],"asks":[{"price":2978.75,"qty":0.00000000},{"price":2980.94,"qty":0.00775181}],"checksum":3198438716,"timestamp":"2024-06-01T17:52:23.213934Z"}]}
{"channel":"book","type":"update","data":[{"symbol":"ETH/GBP","bids":[],"asks":[{"price":2978.74,"qty":6.58455158}],"checksum":3880037907,"timestamp":"2024-06-01T17:52:23.218487Z"}]}
{"channel":"book","type":"update","data":[{"symbol":"ETH/GBP","bids":[{"price":2978.50,"qty":6.58505509}],"asks":[],"checksum":681620348,"timestamp":"2024-06-01T17:52:23.218649Z"}]}
{"channel":"book","type":"update","data":[{"symbol":"ETH/GBP","bids":[{"price":2978.50,"qty":0.00000000},{"price":2974.50,"qty":0.27200000}],"asks":[],"checksum":3880037907,"timestamp":"2024-06-01T17:52:23.248634Z"}]}
{"channel":"book","type":"update","data":[{"symbol":"ETH/GBP","bids":[],"asks":[{"price":2978.74,"qty":0.00000000},{"price":2980.94,"qty":0.00775181}],"checksum":3198438716,"timestamp":"2024-06-01T17:52:23.274694Z"}]}
{"channel":"book","type":"update","data":[{"symbol":"ETH/GBP","bids":[],"asks":[{"price":2979.18,"qty":0.00000000},{"price":2980.95,"qty":0.22400000}],"checksum":1413511248,"timestamp":"2024-06-01T17:52:23.286117Z"}]}
{"channel":"book","type":"update","data":[{"symbol":"ETH/GBP","bids":[],"asks":[{"price":2979.24,"qty":13.16688526}],"checksum":2617597647,"timestamp":"2024-06-01T17:52:23.290103Z"}]}
{"channel":"book","type":"update","data":[{"symbol":"ETH/GBP","bids":[],"asks":[{"price":2978.83,"qty":6.58435736}],"checksum":3068447879,"timestamp":"2024-06-01T17:52:23.336104Z"}]}
{"channel":"book","type":"update","data":[{"symbol":"ETH/GBP","bids":[{"price":2978.31,"qty":6.58549427}],"asks":[],"checksum":3098388331,"timestamp":"2024-06-01T17:52:23.336209Z"}]}
{"channel":"book","type":"update","data":[{"symbol":"ETH/GBP","bids":[{"price":2978.31,"qty":0.00000000},{"price":2974.50,"qty":0.27200000}],"asks":[],"checksum":3068447879,"timestamp":"2024-06-01T17:52:23.341136Z"}]}
{"channel":"book","type":"update","data":[{"symbol":"ETH/GBP","bids":[],"asks":[{"price":2978.83,"qty":0.00000000},{"price":2980.94,"qty":0.00775181}],"checksum":2617597647,"timestamp":"2024-06-01T17:52:23.412364Z"}]}
{"channel":"book","type":"update","data":[{"symbol":"ETH/GBP","bids":[{"price":2978.57,"qty":6.58491536}],"asks":[],"checksum":2726520857,"timestamp":"2024-06-01T17:52:23.477279Z"}]}
{"channel":"book","type":"update","data":[{"symbol":"ETH/GBP","bids":[],"asks":[{"price":2978.81,"qty":6.58439130}],"checksum":3209067598,"timestamp":"2024-06-01T17:52:23.477307Z"}]}
{"channel":"book","type":"update","data":[{"symbol":"ETH/GBP","bids":[],"asks":[{"price":2978.81,"qty":0.00000000},{"price":2980.94,"qty":0.00775181}],"checksum":2726520857,"timestamp":"2024-06-01T17:52:23.484254Z"}]}
{"channel":"book","type":"update","data":[{"symbol":"ETH/GBP","bids":[{"price":2978.57,"qty":0.00000000},{"price":2974.50,"qty":0.27200000}],"asks":[],"checksum":2617597647,"timestamp":"2024-06-01T17:52:23.484416Z"}]}
{"channel":"book","type":"update","data":[{"symbol":"ETH/GBP","bids":[{"price":2978.11,"qty":0.00000000},{"price":2973.93,"qty":0.27474654}],"asks":[],"checksum":3715664399,"timestamp":"2024-06-01T17:52:23.530263Z"}]}
{"channel":"book","type":"update","data":[{"symbol":"ETH/GBP","bids":[],"asks":[{"price":2979.81,"qty":0.00000000},{"price":2980.95,"qty":0.22400000}],"checksum":2264864655,"timestamp":"2024-06-01T17:52:23.530275Z"}]}
{"channel":"book","type":"update","data":[{"symbol":"ETH/GBP","bids":[],"asks":[{"price":2979.24,"qty":0.00000000},{"price":2981.04,"qty":0.94850883}],"checksum":3049272648,"timestamp":"2024-06-01T17:52:23.530377Z"}]}
{"channel":"book","type":"update","data":[{"symbol":"ETH/GBP","bids":[],"asks":[{"price":2980.34,"qty":0.00000000},{"price":2981.15,"qty":1.41091270}],"checksum":3214799778,"timestamp":"2024-06-01T17:52:23.530426Z"}]}
{"channel":"book","type":"update","data":[{"symbol":"ETH/GBP","bids":[],"asks":[{"price":2979.31,"qty":13.16659948}],"checksum":3900695540,"timestamp":"2024-06-01T17:52:23.538486Z"}]}
{"channel":"book","type":"update","data":[{"symbol":"ETH/GBP","bids":[],"asks":[{"price":2980.76,"qty":1.31601829}],"checksum":3872768921,"timestamp":"2024-06-01T17:52:23.538561Z"}]}
{"channel":"book","type":"update","data":[{"symbol":"ETH/GBP","bids":[],"asks":[{"price":2980.05,"qty":1.31633099}],"checksum":3922630971,"timestamp":"2024-06-01T17:52:23.538574Z"}]}
{"channel":"book","type":"update","data":[{"symbol":"ETH/GBP","bids":[{"price":2978.17,"qty":13.17158826}],"asks":[],"checksum":2674301367,"timestamp":"2024-06-01T17:52:23.538672Z"}]}
{"channel":"book","type":"update","data":[{"symbol":"ETH/GBP","bids":[],"asks":[{"price":2978.87,"qty":6.58427104}],"checksum":290072030,"timestamp":"2024-06-01T17:52:23.582978Z"}]}
{"channel":"book","type":"update","data":[{"symbol":"ETH/GBP","bids":[{"price":2977.22,"qty":0.00000000},{"price":2973.93,"qty":0.27474654}],"asks":[],"checksum":2273918889,"timestamp":"2024-06-01T17:52:23.583089Z"}]}
{"channel":"book","type":"update","data":[{"symbol":"ETH/GBP","bids":[{"price":2978.62,"qty":6.58479428}],"asks":[],"checksum":3977199374,"timestamp":"2024-06-01T17:52:23.583168Z"}]}
{"channel":"book","type":"update","data":[{"symbol":"ETH/GBP","bids":[],"asks":[{"price":2978.87,"qty":0.00000000},{"price":2980.94,"qty":0.00775181}],"checksum":1663271783,"timestamp":"2024-06-01T17:52:23.589348Z"}]}
{"channel":"book","type":"update","data":[{"symbol":"ETH/GBP","bids":[{"price":2978.62,"qty":0.00000000},{"price":2973.93,"qty":0.27474654}],"asks":[],"checksum":366653236,"timestamp":"2024-06-01T17:52:23.589392Z"}]}
{"channel":"book","type":"update","data":[{"symbol":"ETH/GBP","bids":[{"price":2977.45,"qty":1.31747668}],"asks":[],"checksum":940499837,"timestamp":"2024-06-01T17:52:23.594696Z"}]}
{"channel":"book","type":"update","data":[{"symbol":"ETH/GBP","bids":[],"asks":[{"price":2980.81,"qty":0.00000000},{"price":2980.95,"qty":0.22400000}],"checksum":4248769601,"timestamp":"2024-06-01T17:52:23.613810Z"}]}
{"channel":"book","type":"update","data":[{"symbol":"ETH/GBP","bids":[],"asks":[{"price":2980.75,"qty":2.94416492}],"checksum":1234023512,"timestamp":"2024-06-01T17:52:23.616611Z"}]}
{"channel":"book","type":"update","data":[{"symbol":"ETH/GBP","bids":[],"asks":[{"price":2978.88,"qty":6.58423567}],"checksum":1528262143,"timestamp":"2024-06-01T17:52:23.688371Z"}]}
{"channel":"book","type":"update","data":[{"symbol":"ETH/GBP","bids":[{"price":2978.31,"qty":6.58549427}],"asks":[],"checksum":2490323537,"timestamp":"2024-06-01T17:52:23.688605Z"}]}
{"channel":"book","type":"update","data":[{"symbol":"ETH/GBP","bids":[{"price":2978.31,"qty":0.00000000},{"price":2974.50,"qty":0.27200000}],"asks":[],"checksum":1528262143,"timestamp":"2024-06-01T17:52:23.693237Z"}]}
{"channel":"book","type":"update","data":[{"symbol":"ETH/GBP","bids":[],"asks":[{"price":2978.88,"qty":0.00000000},{"price":2980.94,"qty":0.00775181}],"checksum":1234023512,"timestamp":"2024-06-01T17:52:23.756953Z"}]}
{"channel":"book","type":"update","data":[{"symbol":"ETH/GBP","bids":[{"price":2978.30,"qty":0.00000000},{"price":2973.93,"qty":0.27474654},{"price":2978.63,"qty":0.08558500}],"asks":[],"checksum":3163168592,"timestamp":"2024-06-01T17:52:23.759782Z"}]}
{"channel":"book","type":"update","data":[{"symbol":"ETH/GBP","bids":[{"price":2978.62,"qty":6.58479031}],"asks":[],"checksum":4100094677,"timestamp":"2024-06-01T17:52:23.926660Z"}]}
{"channel":"book","type":"update","data":[{"symbol":"ETH/GBP","bids":[],"asks":[{"price":2978.86,"qty":6.58428073}],"checksum":846365408,"timestamp":"2024-06-01T17:52:23.926778Z"}]}
{"channel":"book","type":"update","data":[{"symbol":"ETH/GBP","bids":[{"price":2978.62,"qty":0.00000000},{"price":2974.50,"qty":0.27200000}],"asks":[],"checksum":2695600234,"timestamp":"2024-06-01T17:52:24.061990Z"}]}
{"channel":"book","type":"update","data":[{"symbol":"ETH/GBP","bids":[{"price":2978.60,"qty":6.58483341}],"asks":[],"checksum":213519231,"timestamp":"2024-06-01T17:52:24.066191Z"}]}
{"channel":"book","type":"update","data":[{"symbol":"ETH/GBP","bids":[],"asks":[{"price":2978.86,"qty":0.00000000},{"price":2980.94,"qty":0.00775181}],"checksum":3400201034,"timestamp":"2024-06-01T17:52:24.072088Z"}]}
{"channel":"book","type":"update","data":[{"symbol":"ETH/GBP","bids":[],"asks":[{"price":2978.85,"qty":6.58430904}],"checksum":2190642243,"timestamp":"2024-06-01T17:52:24.076043Z"}]}
{"channel":"book","type":"update","data":[{"symbol":"ETH/GBP","bids":[{"price":2978.60,"qty":0.00000000},{"price":2974.50,"qty":0.27200000}],"asks":[],"checksum":918773239,"timestamp":"2024-06-01T17:52:24.215834Z"}]}
{"channel":"book","type":"update","data":[{"symbol":"ETH/GBP","bids":[],"asks":[{"price":2978.85,"qty":0.00000000},{"price":2980.94,"qty":0.00775181}],"checksum":3163168592,"timestamp":"2024-06-01T17:52:24.215844Z"}]}
{"channel":"book","type":"update","data":[{"symbol":"ETH/GBP","bids":[{"price":2978.25,"qty":0.31000000}],"asks":[],"checksum":535311987,"timestamp":"2024-06-01T17:52:24.219202Z"}]}
{"channel":"book","type":"update","data":[{"symbol":"ETH/GBP","bids":[],"asks":[{"price":2978.83,"qty":6.58434921}],"checksum":2116183227,"timestamp":"2024-06-01T17:52:24.220638Z"}]}
{"channel":"book","type":"update","data":[{"symbol":"ETH/GBP","bids":[{"price":2978.57,"qty":6.58490478}],"asks":[],"checksum":3967738934,"timestamp":"2024-06-01T17:52:24.220752Z"}]}
{"channel":"book","type":"update","data":[{"symbol":"ETH/GBP","bids":[],"asks":[{"price":2978.72,"qty":0.00000000},{"price":2980.94,"qty":0.00775181}],"checksum":825440979,"timestamp":"2024-06-01T17:52:24.253839Z"}]}
{"channel":"book","type":"update","data":[{"symbol":"ETH/GBP","bids":[],"asks":[{"price":2980.10,"qty":0.00000000},{"price":2980.95,"qty":0.22400000}],"checksum":150227229,"timestamp":"2024-06-01T17:52:24.253932Z"}]}
{"channel":"book","type":"update","data":[{"symbol":"ETH/GBP","bids":[],"asks":[{"price":2979.30,"qty":8.32933909}],"checksum":528666360,"timestamp":"2024-06-01T17:52:24.258470Z"}]}
{"channel":"book","type":"update","data":[{"symbol":"ETH/GBP","bids":[],"asks":[{"price":2980.74,"qty":18.07274001}],"checksum":970401382,"timestamp":"2024-06-01T17:52:24.258579Z"}]}
{"channel":"book","type":"update","data":[{"symbol":"ETH/GBP","bids":[{"price":2978.57,"qty":0.00000000},{"price":2975.01,"qty":1.31855212}],"asks":[],"checksum":2878056171,"timestamp":"2024-06-01T17:52:24.258703Z"}]}
{"channel":"book","type":"update","data":[{"symbol":"ETH/GBP","bids":[],"asks":[{"price":2978.83,"qty":0.00000000},{"price":2980.94,"qty":0.00775181}],"checksum":482104825,"timestamp":"2024-06-01T17:52:24.369694Z"}]}
{"channel":"book","type":"update","data":[{"symbol":"ETH/GBP","bids":[],"asks":[{"price":2979.31,"qty":0.00000000},{"price":2980.95,"qty":0.22400000}],"checksum":4126461645,"timestamp":"2024-06-01T17:52:24.369742Z"}]}
{"channel":"book","type":"update","data":[{"symbol":"ETH/GBP","bids":[{"price":2978.17,"qty":0.00000000},{"price":2974.50,"qty":0.27200000}],"asks":[],"checksum":3326200508,"timestamp":"2024-06-01T17:52:24.369774Z"}]}
{"channel":"book","type":"update","data":[{"symbol":"ETH/GBP","bids":[{"price":2978.25,"qty":0.00000000},{"price":2973.93,"qty":0.27474654}],"asks":[],"checksum":881142590,"timestamp":"2024-06-01T17:52:24.372436Z"}]}
{"channel":"book","type":"update","data":[{"symbol":"ETH/GBP","bids":[{"price":2977.65,"qty":0.31000000}],"asks":[],"checksum":2143104644,"timestamp":"2024-06-01T17:52:24.372656Z"}]}
{"channel":"book","type":"update","data":[{"symbol":"ETH/GBP","bids":[],"asks":[{"price":2979.29,"qty":0.31000000}],"checksum":1865164285,"timestamp":"2024-06-01T17:52:24.372692Z"}]}
{"channel":"book","type":"update","data":[{"symbol":"ETH/GBP","bids":[],"asks":[{"price":2978.78,"qty":6.58446631}],"checksum":2897048923,"timestamp":"2024-06-01T17:52:24.375422Z"}]}
{"channel":"book","type":"update","data":[{"symbol":"ETH/GBP","bids":[],"asks":[{"price":2979.23,"qty":13.16694022}],"checksum":2062087775,"timestamp":"2024-06-01T17:52:24.375577Z"}]}
{"channel":"book","type":"update","data":[{"symbol":"ETH/GBP","bids":[{"price":2978.10,"qty":13.17190366}],"asks":[],"checksum":3629059232,"timestamp":"2024-06-01T17:52:24.375589Z"}]}
{"channel":"book","type":"update","data":[{"symbol":"ETH/GBP","bids":[{"price":2978.54,"qty":6.58497713}],"asks":[],"checksum":2426926239,"timestamp":"2024-06-01T17:52:24.375602Z"}]}
{"channel":"book","type":"update","data":[{"symbol":"ETH/GBP","bids":[],"asks":[{"price":2980.11,"qty":0.00000000},{"price":2980.94,"qty":0.00775181}],"checksum":1517181486,"timestamp":"2024-06-01T17:52:24.400823Z"}]}
{"channel":"book","type":"update","data":[{"symbol":"ETH/GBP","bids":[],"asks":[{"price":2978.78,"qty":0.00000000},{"price":2980.95,"qty":0.22400000}],"checksum":4130629439,"timestamp":"2024-06-01T17:52:24.401121Z"}]}
{"channel":"book","type":"update","data":[{"symbol":"ETH/GBP","bids":[{"price":2978.54,"qty":0.00000000},{"price":2975.01,"qty":1.31855212}],"asks":[],"checksum":3202129664,"timestamp":"2024-06-01T17:52:24.403568Z"}]}
{"channel":"book","type":"update","data":[{"symbol":"ETH/GBP","bids":[{"price":2978.10,"qty":0.00000000},{"price":2974.50,"qty":0.27200000}],"asks":[],"checksum":1841868439,"timestamp":"2024-06-01T17:52:24.403626Z"}]}
{"channel":"book","type":"update","data":[{"symbol":"ETH/GBP","bids":[],"asks":[{"price":2980.26,"qty":15.33347015}],"checksum":2263179202,"timestamp":"2024-06-01T17:52:24.404497Z"}]}
{"channel":"book","type":"update","data":[{"symbol":"ETH/GBP","bids":[],"asks":[{"price":2979.23,"qty":0.00000000},{"price":2980.95,"qty":0.22400000}],"checksum":2737434057,"timestamp":"2024-06-01T17:52:24.467502Z"}]}
{"channel":"book","type":"update","data":[{"symbol":"ETH/GBP","bids":[],"asks":[{"price":2978.86,"qty":6.58429168}],"checksum":3776176054,"timestamp":"2024-06-01T17:52:24.489084Z"}]}
{"channel":"book","type":"update","data":[{"symbol":"ETH/GBP","bids":[{"price":2978.62,"qty":6.58480215}],"asks":[],"checksum":2379894624,"timestamp":"2024-06-01T17:52:24.489211Z"}]}
{"channel":"book","type":"update","data":[{"symbol":"ETH/GBP","bids":[],"asks":[{"price":2978.86,"qty":0.00000000},{"price":2980.95,"qty":0.22400000}],"checksum":1294080511,"timestamp":"2024-06-01T17:52:24.576940Z"}]}
{"channel":"book","type":"update","data":[{"symbol":"ETH/GBP","bids":[{"price":2978.17,"qty":13.17157605}],"asks":[],"checksum":2923864124,"timestamp":"2024-06-01T17:52:24.581915Z"}]}
{"channel":"book","type":"update","data":[{"symbol":"ETH/GBP","bids":[],"asks":[{"price":2979.29,"qty":13.47666869}],"checksum":3166054433,"timestamp":"2024-06-01T17:52:24.581945Z"}]}
{"channel":"book","type":"update","data":[{"symbol":"ETH/GBP","bids":[{"price":2978.62,"qty":0.00000000},{"price":2975.01,"qty":1.31855212}],"asks":[],"checksum":1013743731,"timestamp":"2024-06-01T17:52:24.674383Z"}]}
{"channel":"book","type":"update","data":[{"symbol":"ETH/GBP","bids":[{"price":2978.60,"qty":6.58484035}],"asks":[],"checksum":1517399557,"timestamp":"2024-06-01T17:52:24.677948Z"}]}
{"channel":"book","type":"update","data":[{"symbol":"ETH/GBP","bids":[],"asks":[{"price":2978.84,"qty":6.58433909}],"checksum":3674302027,"timestamp":"2024-06-01T17:52:24.678022Z"}]}
{"channel":"book","type":"update","data":[{"symbol":"ETH/GBP","bids":[{"price":2978.60,"qty":0.00000000},{"price":2975.01,"qty":1.31855212}],"asks":[],"checksum":3172747325,"timestamp":"2024-06-01T17:52:24.682551Z"}]}
{"channel":"book","type":"update","data":[{"symbol":"ETH/GBP","bids":[],"asks":[{"price":2978.84,"qty":0.00000000},{"price":2980.95,"qty":0.22400000}],"checksum":1013743731,"timestamp":"2024-06-01T17:52:24.682686Z"}]}
{"channel":"book","type":"update","data":[{"symbol":"ETH/GBP","bids":[{"price":2977.65,"qty":0.00000000},{"price":2974.50,"qty":0.27200000}],"asks":[],"checksum":1698380941,"timestamp":"2024-06-01T17:52:24.817472Z"}]}
{"channel":"book","type":"update","data":[{"symbol":"ETH/GBP","bids":[{"price":2978.25,"qty":0.31000000}],"asks":[],"checksum":1367796662,"timestamp":"2024-06-01T17:52:24.817627Z"}]}
{"channel":"book","type":"update","data":[{"symbol":"ETH/GBP","bids":[{"price":2978.59,"qty":6.58485878}],"asks":[],"checksum":146222486,"timestamp":"2024-06-01T17:52:24.921257Z"}]}
{"channel":"book","type":"update","data":[{"symbol":"ETH/GBP","bids":[],"asks":[{"price":2978.82,"qty":6.58438277}],"checksum":973254358,"timestamp":"2024-06-01T17:52:24.921308Z"}]}
{"channel":"book","type":"update","data":[{"symbol":"ETH/GBP","bids":[],"asks":[{"price":2978.82,"qty":0.00000000},{"price":2980.95,"qty":0.22400000}],"checksum":146222486,"timestamp":"2024-06-01T17:52:24.969943Z"}]}
{"channel":"book","type":"update","data":[{"symbol":"ETH/GBP","bids":[],"asks":[{"price":2979.29,"qty":0.31000000}],"checksum":440903051,"timestamp":"2024-06-01T17:52:25.321318Z"}]}
{"channel":"book","type":"update","data":[{"symbol":"ETH/GBP","bids":[],"asks":[{"price":2979.24,"qty":13.16690968}],"checksum":1619643323,"timestamp":"2024-06-01T17:52:25.325170Z"}]}
{"channel":"book","type":"update","data":[{"symbol":"ETH/GBP","bids":[],"asks":[{"price":2978.81,"qty":6.58440055}],"checksum":4159065459,"timestamp":"2024-06-01T17:52:25.325191Z"}]}
{"channel":"book","type":"update","data":[{"symbol":"ETH/GBP","bids":[{"price":2978.59,"qty":0.00000000},{"price":2975.01,"qty":1.31855212}],"asks":[],"checksum":2933361491,"timestamp":"2024-06-01T17:52:25.357216Z"}]}
{"channel":"book","type":"update","data":[{"symbol":"ETH/GBP","bids":[{"price":2978.60,"qty":6.58485022}],"asks":[],"checksum":3487017722,"timestamp":"2024-06-01T17:52:25.361549Z"}]}
{"channel":"book","type":"update","data":[{"symbol":"ETH/GBP","bids":[],"asks":[{"price":2978.81,"qty":0.00000000},{"price":2980.94,"qty":0.00775181}],"checksum":1488464946,"timestamp":"2024-06-01T17:52:25.369336Z"}]}
{"channel":"book","type":"update","data":[{"symbol":"ETH/GBP","bids":[{"price":2978.60,"qty":0.00000000},{"price":2975.01,"qty":1.31855212}],"asks":[],"checksum":968363419,"timestamp":"2024-06-01T17:52:25.371934Z"}]}
{"channel":"book","type":"update","data":[{"symbol":"ETH/GBP","bids":[],"asks":[{"price":2978.80,"qty":6.58442553}],"checksum":1041689636,"timestamp":"2024-06-01T17:52:25.439437Z"}]}
{"channel":"book","type":"update","data":[{"symbol":"ETH/GBP","bids":[],"asks":[{"price":2978.80,"qty":0.00000000},{"price":2980.94,"qty":0.00775181}],"checksum":968363419,"timestamp":"2024-06-01T17:52:25.443569Z"}]}
{"channel":"book","type":"update","data":[{"symbol":"ETH/GBP","bids":[{"price":2978.57,"qty":6.58490615}],"asks":[],"checksum":2408502142,"timestamp":"2024-06-01T17:52:25.515215Z"}]}
{"channel":"book","type":"update","data":[{"symbol":"ETH/GBP","bids":[{"price":2978.63,"qty":0.00000000},{"price":2975.01,"qty":1.31855212},{"price":2978.26,"qty":0.08558900}],"asks":[],"checksum":1828269510,"timestamp":"2024-06-01T17:52:25.536363Z"}]}
{"channel":"book","type":"update","data":[{"symbol":"ETH/GBP","bids":[],"asks":[{"price":2978.79,"qty":6.58443673}],"checksum":1316164467,"timestamp":"2024-06-01T17:52:25.599188Z"}]}
{"channel":"book","type":"update","data":[{"symbol":"ETH/GBP","bids":[{"price":2978.57,"qty":0.00000000},{"price":2975.01,"qty":1.31855212}],"asks":[],"checksum":2198686553,"timestamp":"2024-06-01T17:52:25.699414Z"}]}
{"channel":"book","type":"update","data":[{"symbol":"ETH/GBP","bids":[{"price":2978.55,"qty":6.58494435}],"asks":[],"checksum":2145493,"timestamp":"2024-06-01T17:52:25.704182Z"}]}
{"channel":"book","type":"update","data":[{"symbol":"ETH/GBP","bids":[{"price":2978.55,"qty":0.00000000},{"price":2975.01,"qty":1.31855212}],"asks":[],"checksum":2198686553,"timestamp":"2024-06-01T17:52:25.785582Z"}]}
{"channel":"book","type":"update","data":[{"symbol":"ETH/GBP","bids":[],"asks":[{"price":2978.79,"qty":0.00000000},{"price":2980.94,"qty":0.00775181}],"checksum":2710009324,"timestamp":"2024-06-01T17:52:25.803144Z"}]}
{"channel":"book","type":"update","data":[{"symbol":"ETH/GBP","bids":[],"asks":[{"price":2978.81,"qty":6.58440380}],"checksum":4011777282,"timestamp":"2024-06-01T17:52:25.807486Z"}]}
{"channel":"book","type":"update","data":[{"symbol":"ETH/GBP","bids":[{"price":2978.57,"qty":6.58491339}],"asks":[],"checksum":964234251,"timestamp":"2024-06-01T17:52:25.807505Z"}]}
{"channel":"book","type":"update","data":[{"symbol":"ETH/GBP","bids":[],"asks":[{"price":2978.81,"qty":0.00000000},{"price":2980.94,"qty":0.00775181}],"checksum":2011210981,"timestamp":"2024-06-01T17:52:26.006007Z"}]}
{"channel":"book","type":"update","data":[{"symbol":"ETH/GBP","bids":[],"asks":[{"price":2978.80,"qty":6.58442028}],"checksum":245293947,"timestamp":"2024-06-01T17:52:26.010440Z"}]}
{"channel":"book","type":"update","data":[{"symbol":"ETH/GBP","bids":[],"asks":[{"price":2978.80,"qty":0.00000000},{"price":2980.94,"qty":0.00775181}],"checksum":2011210981,"timestamp":"2024-06-01T17:52:26.055585Z"}]}
{"channel":"book","type":"update","data":[{"symbol":"ETH/GBP","bids":[{"price":2978.57,"qty":0.00000000},{"price":2975.01,"qty":1.31855212}],"asks":[],"checksum":2710009324,"timestamp":"2024-06-01T17:52:26.338554Z"}]}
{"channel":"book","type":"update","data":[{"symbol":"ETH/GBP","bids":[],"asks":[{"price":2978.79,"qty":6.58444003}],"checksum":2317197392,"timestamp":"2024-06-01T17:52:26.343846Z"}]}
{"channel":"book","type":"update","data":[{"symbol":"ETH/GBP","bids":[{"price":2978.55,"qty":6.58494678}],"asks":[],"checksum":3758475165,"timestamp":"2024-06-01T17:52:26.343970Z"}]}
{"channel":"book","type":"update","data":[{"symbol":"ETH/GBP","bids":[],"asks":[{"price":2978.79,"qty":0.00000000},{"price":2980.94,"qty":0.00775181}],"checksum":3416199713,"timestamp":"2024-06-01T17:52:26.398837Z"}]}
{"channel":"book","type":"update","data":[{"symbol":"ETH/GBP","bids":[],"asks":[{"price":2979.30,"qty":0.00000000},{"price":2980.95,"qty":0.22400000}],"checksum":2832400113,"timestamp":"2024-06-01T17:52:26.638870Z"}]}
{"channel":"book","type":"update","data":[{"symbol":"ETH/GBP","bids":[],"asks":[{"price":2980.74,"qty":0.00000000},{"price":2981.04,"qty":0.94850883}],"checksum":2968133057,"timestamp":"2024-06-01T17:52:26.639008Z"}]}
{"channel":"book","type":"update","data":[{"symbol":"ETH/GBP","bids":[],"asks":[{"price":2979.15,"qty":6.58363742}],"checksum":3334425995,"timestamp":"2024-06-01T17:52:26.641107Z"}]}
{"channel":"book","type":"update","data":[{"symbol":"ETH/GBP","bids":[],"asks":[{"price":2979.29,"qty":0.00000000},{"price":2981.04,"qty":0.94850883}],"checksum":314103389,"timestamp":"2024-06-01T17:52:26.642146Z"}]}
{"channel":"book","type":"update","data":[{"symbol":"ETH/GBP","bids":[],"asks":[{"price":2979.23,"qty":7.80916577}],"checksum":3532272993,"timestamp":"2024-06-01T17:52:26.643644Z"}]}
{"channel":"book","type":"update","data":[{"symbol":"ETH/GBP","bids":[],"asks":[{"price":2980.25,"qty":19.11486568}],"checksum":895729207,"timestamp":"2024-06-01T17:52:26.643808Z"}]}
{"channel":"book","type":"update","data":[{"symbol":"ETH/GBP","bids":[],"asks":[{"price":2979.15,"qty":0.00000000},{"price":2980.95,"qty":0.22400000}],"checksum":2783840026,"timestamp":"2024-06-01T17:52:26.645460Z"}]}
{"channel":"book","type":"update","data":[{"symbol":"ETH/GBP","bids":[{"price":2978.55,"qty":0.00000000},{"price":2975.01,"qty":1.31855212}],"asks":[],"checksum":3489030359,"timestamp":"2024-06-01T17:52:26.650918Z"}]}
{"channel":"book","type":"update","data":[{"symbol":"ETH/GBP","bids":[{"price":2978.56,"qty":6.58492541}],"asks":[],"checksum":1057858177,"timestamp":"2024-06-01T17:52:26.655531Z"}]}
{"channel":"book","type":"update","data":[{"symbol":"ETH/GBP","bids":[{"price":2978.56,"qty":0.00000000},{"price":2975.01,"qty":1.31855212}],"asks":[],"checksum":3489030359,"timestamp":"2024-06-01T17:52:26.688068Z"}]}
{"channel":"book","type":"update","data":[{"symbol":"ETH/GBP","bids":[],"asks":[{"price":2978.80,"qty":6.58442473}],"checksum":1468668354,"timestamp":"2024-06-01T17:52:26.754593Z"}]}
{"channel":"book","type":"update","data":[{"symbol":"ETH/GBP","bids":[{"price":2978.56,"qty":6.58492667}],"asks":[],"checksum":60482326,"timestamp":"2024-06-01T17:52:26.760424Z"}]}
{"channel":"book","type":"update","data":[{"symbol":"ETH/GBP","bids":[],"asks":[{"price":2978.80,"qty":0.00000000},{"price":2980.95,"qty":0.22400000}],"checksum":2615581187,"timestamp":"2024-06-01T17:52:26.786217Z"}]}
{"channel":"book","type":"update","data":[{"symbol":"ETH/GBP","bids":[{"price":2978.56,"qty":0.00000000},{"price":2975.01,"qty":1.31855212}],"asks":[],"checksum":3489030359,"timestamp":"2024-06-01T17:52:27.114246Z"}]}
{"channel":"book","type":"update","data":[{"symbol":"ETH/GBP","bids":[{"price":2978.59,"qty":6.58487121}],"asks":[],"checksum":4139372139,"timestamp":"2024-06-01T17:52:27.118689Z"}]}
{"channel":"book","type":"update","data":[{"symbol":"ETH/GBP","bids":[],"asks":[{"price":2978.82,"qty":6.58438032}],"checksum":884132269,"timestamp":"2024-06-01T17:52:27.118841Z"}]}
{"channel":"book","type":"update","data":[{"symbol":"ETH/GBP","bids":[],"asks":[{"price":2978.82,"qty":0.00000000},{"price":2980.95,"qty":0.22400000}],"checksum":4139372139,"timestamp":"2024-06-01T17:52:27.139343Z"}]}
{"channel":"book","type":"update","data":[{"symbol":"ETH/GBP","bids":[{"price":2978.59,"qty":0.00000000},{"price":2975.01,"qty":1.31855212}],"asks":[],"checksum":3489030359,"timestamp":"2024-06-01T17:52:27.189118Z"}]}
{"channel":"book","type":"update","data":[{"symbol":"ETH/GBP","bids":[],"asks":[{"price":2979.15,"qty":6.58363742}],"checksum":1601952250,"timestamp":"2024-06-01T17:52:27.245463Z"}]}
{"channel":"book","type":"update","data":[{"symbol":"ETH/GBP","bids":[{"price":2978.58,"qty":6.58488636}],"asks":[],"checksum":2787376347,"timestamp":"2024-06-01T17:52:27.245490Z"}]}
{"channel":"book","type":"update","data":[{"symbol":"ETH/GBP","bids":[],"asks":[{"price":2979.15,"qty":0.00000000},{"price":2980.95,"qty":0.22400000}],"checksum":917390838,"timestamp":"2024-06-01T17:52:27.250614Z"}]}
{"channel":"book","type":"update","data":[{"symbol":"ETH/GBP","bids":[{"price":2978.58,"qty":0.00000000},{"price":2975.01,"qty":1.31855212}],"asks":[],"checksum":3489030359,"timestamp":"2024-06-01T17:52:27.400753Z"}]}
{"channel":"book","type":"update","data":[{"symbol":"ETH/GBP","bids":[],"asks":[{"price":2978.79,"qty":6.58443899}],"checksum":1664300223,"timestamp":"2024-06-01T17:52:27.406308Z"}]}
{"channel":"book","type":"update","data":[{"symbol":"ETH/GBP","bids":[{"price":2978.56,"qty":6.58492669}],"asks":[],"checksum":2513262815,"timestamp":"2024-06-01T17:52:27.406375Z"}]}
{"channel":"book","type":"update","data":[{"symbol":"ETH/GBP","bids":[{"price":2978.56,"qty":0.00000000},{"price":2975.01,"qty":1.31855212}],"asks":[],"checksum":1664300223,"timestamp":"2024-06-01T17:52:27.503925Z"}]}
{"channel":"book","type":"update","data":[{"symbol":"ETH/GBP","bids":[{"price":2978.57,"qty":6.58490891}],"asks":[],"checksum":4260554362,"timestamp":"2024-06-01T17:52:27.508390Z"}]}
{"channel":"book","type":"update","data":[{"symbol":"ETH/GBP","bids":[{"price":2978.57,"qty":0.00000000},{"price":2975.01,"qty":1.31855212}],"asks":[],"checksum":1664300223,"timestamp":"2024-06-01T17:52:27.913824Z"}]}
{"channel":"book","type":"update","data":[{"symbol":"ETH/GBP","bids":[{"price":2978.55,"qty":6.58494353}],"asks":[],"checksum":2080684401,"timestamp":"2024-06-01T17:52:27.918399Z"}]}
{"channel":"book","type":"update","data":[{"symbol":"ETH/GBP","bids":[{"price":2978.55,"qty":0.00000000},{"price":2975.01,"qty":1.31855212}],"asks":[],"checksum":1664300223,"timestamp":"2024-06-01T17:52:27.935700Z"}]}
{"channel":"book","type":"update","data":[{"symbol":"ETH/GBP","bids":[{"price":2978.57,"qty":6.58490863}],"asks":[],"checksum":4040843859,"timestamp":"2024-06-01T17:52:28.061473Z"}]}
{"channel":"book","type":"update","data":[{"symbol":"ETH/GBP","bids":[{"price":2978.26,"qty":0.00000000},{"price":2975.01,"qty":1.31855212},{"price":2978.56,"qty":0.08558900}],"asks":[],"checksum":1797630410,"timestamp":"2024-06-01T17:52:28.093214Z"}]}
{"channel":"book","type":"update","data":[{"symbol":"ETH/GBP","bids":[{"price":2978.57,"qty":0.00000000},{"price":2975.01,"qty":1.31855212}],"asks":[],"checksum":3002451310,"timestamp":"2024-06-01T17:52:28.096271Z"}]}
{"channel":"book","type":"update","data":[{"symbol":"ETH/GBP","bids":[],"asks":[{"price":2978.79,"qty":0.00000000},{"price":2980.95,"qty":0.22400000}],"checksum":506499334,"timestamp":"2024-06-01T17:52:28.096434Z"}]}
{"channel":"book","type":"update","data":[{"symbol":"ETH/GBP","bids":[],"asks":[{"price":2978.81,"qty":6.58439789}],"checksum":1131332879,"timestamp":"2024-06-01T17:52:28.101275Z"}]}
{"channel":"book","type":"update","data":[{"symbol":"ETH/GBP","bids":[],"asks":[{"price":2978.81,"qty":0.00000000},{"price":2980.95,"qty":0.22400000}],"checksum":506499334,"timestamp":"2024-06-01T17:52:28.112103Z"}]}
{"channel":"book","type":"update","data":[{"symbol":"ETH/GBP","bids":[{"price":2978.58,"qty":6.58488558}],"asks":[],"checksum":3108032199,"timestamp":"2024-06-01T17:52:28.165322Z"}]}
{"channel":"book","type":"update","data":[{"symbol":"ETH/GBP","bids":[],"asks":[{"price":2978.80,"qty":6.58441962}],"checksum":1353482427,"timestamp":"2024-06-01T17:52:28.243943Z"}]}
{"channel":"book","type":"update","data":[{"symbol":"ETH/GBP","bids":[{"price":2978.58,"qty":0.00000000},{"price":2975.01,"qty":1.31855212}],"asks":[],"checksum":4158447482,"timestamp":"2024-06-01T17:52:28.269634Z"}]}
{"channel":"book","type":"update","data":[{"symbol":"ETH/GBP","bids":[],"asks":[{"price":2978.80,"qty":0.00000000},{"price":2980.95,"qty":0.22400000}],"checksum":506499334,"timestamp":"2024-06-01T17:52:28.269769Z"}]}
{"channel":"book","type":"update","data":[{"symbol":"ETH/GBP","bids":[{"price":2978.56,"qty":6.67051211}],"asks":[],"checksum":3517334266,"timestamp":"2024-06-01T17:52:28.274536Z"}]}
{"channel":"book","type":"update","data":[{"symbol":"ETH/GBP","bids":[{"price":2978.56,"qty":0.08558900}],"asks":[],"checksum":506499334,"timestamp":"2024-06-01T17:52:28.331055Z"}]}
{"channel":"book","type":"update","data":[{"symbol":"ETH/GBP","bids":[],"asks":[{"price":2978.80,"qty":6.58442818}],"checksum":1949248583,"timestamp":"2024-06-01T17:52:28.343933Z"}]}
{"channel":"book","type":"update","data":[{"symbol":"ETH/GBP","bids":[],"asks":[{"price":2978.80,"qty":0.00000000},{"price":2980.95,"qty":0.22400000}],"checksum":506499334,"timestamp":"2024-06-01T17:52:28.402753Z"}]}
{"channel":"book","type":"update","data":[{"symbol":"ETH/GBP","bids":[{"price":2978.57,"qty":6.58491587}],"asks":[],"checksum":501319979,"timestamp":"2024-06-01T17:52:28.407223Z"}]}
{"channel":"book","type":"update","data":[{"symbol":"ETH/GBP","bids":[],"asks":[{"price":2979.15,"qty":6.58363742}],"checksum":2372677638,"timestamp":"2024-06-01T17:52:28.576280Z"}]}
{"channel":"book","type":"update","data":[{"symbol":"ETH/GBP","bids":[{"price":2978.57,"qty":0.00000000},{"price":2975.01,"qty":1.31855212}],"asks":[],"checksum":2394761259,"timestamp":"2024-06-01T17:52:28.577204Z"}]}
{"channel":"book","type":"update","data":[{"symbol":"ETH/GBP","bids":[],"asks":[{"price":2979.15,"qty":0.00000000},{"price":2980.95,"qty":0.22400000}],"checksum":506499334,"timestamp":"2024-06-01T17:52:28.581404Z"}]}
{"channel":"book","type":"update","data":[{"symbol":"ETH/GBP","bids":[{"price":2978.58,"qty":6.58488618}],"asks":[],"checksum":552333494,"timestamp":"2024-06-01T17:52:28.585862Z"}]}
{"channel":"book","type":"update","data":[{"symbol":"ETH/GBP","bids":[{"price":2978.58,"qty":0.00000000},{"price":2975.01,"qty":1.31855212}],"asks":[],"checksum":506499334,"timestamp":"2024-06-01T17:52:28.610495Z"}]}
{"channel":"book","type":"update","data":[{"symbol":"ETH/GBP","bids":[],"asks":[{"price":2978.82,"qty":6.58438597}],"checksum":2917797242,"timestamp":"2024-06-01T17:52:28.695676Z"}]}
{"channel":"book","type":"update","data":[{"symbol":"ETH/GBP","bids":[{"price":2978.59,"qty":6.58486313}],"asks":[],"checksum":1008930238,"timestamp":"2024-06-01T17:52:28.695700Z"}]}
{"channel":"book","type":"update","data":[{"symbol":"ETH/GBP","bids":[],"asks":[{"price":2978.82,"qty":0.00000000},{"price":2980.95,"qty":0.22400000}],"checksum":2415497666,"timestamp":"2024-06-01T17:52:28.716270Z"}]}
{"channel":"book","type":"update","data":[{"symbol":"ETH/GBP","bids":[],"asks":[{"price":2978.81,"qty":6.58439058}],"checksum":2455320445,"timestamp":"2024-06-01T17:52:28.822051Z"}]}
{"channel":"book","type":"update","data":[{"symbol":"ETH/GBP","bids":[],"asks":[{"price":2980.25,"qty":0.00000000},{"price":2980.95,"qty":0.22400000}],"checksum":2233998347,"timestamp":"2024-06-01T17:52:29.098237Z"}]}
{"channel":"book","type":"update","data":[{"symbol":"ETH/GBP","bids":[],"asks":[{"price":2980.25,"qty":18.59824701}],"checksum":1511792415,"timestamp":"2024-06-01T17:52:29.103154Z"}]}
{"channel":"book","type":"update","data":[{"symbol":"ETH/GBP","bids":[],"asks":[{"price":2978.81,"qty":0.00000000},{"price":2980.95,"qty":0.22400000}],"checksum":3097317131,"timestamp":"2024-06-01T17:52:29.283074Z"}]}
{"channel":"book","type":"update","data":[{"symbol":"ETH/GBP","bids":[{"price":2978.59,"qty":0.00000000},{"price":2975.01,"qty":1.31855212}],"asks":[],"checksum":693391311,"timestamp":"2024-06-01T17:52:29.283095Z"}]}
{"channel":"book","type":"update","data":[{"symbol":"ETH/GBP","bids":[{"price":2978.56,"qty":6.67052079}],"asks":[],"checksum":2763164223,"timestamp":"2024-06-01T17:52:29.287918Z"}]}
{"channel":"book","type":"update","data":[{"symbol":"ETH/GBP","bids":[],"asks":[{"price":2978.79,"qty":6.58444635}],"checksum":3355039770,"timestamp":"2024-06-01T17:52:29.288039Z"}]}
{"channel":"book","type":"update","data":[{"symbol":"ETH/GBP","bids":[],"asks":[{"price":2980.26,"qty":0.00000000},{"price":2980.95,"qty":0.22400000}],"checksum":96279557,"timestamp":"2024-06-01T17:52:29.384820Z"}]}
{"channel":"book","type":"update","data":[{"symbol":"ETH/GBP","bids":[{"price":2978.56,"qty":0.08558900}],"asks":[],"checksum":2542676770,"timestamp":"2024-06-01T17:52:29.387954Z"}]}
{"channel":"book","type":"update","data":[{"symbol":"ETH/GBP","bids":[],"asks":[{"price":2980.27,"qty":14.38512015}],"checksum":1317181354,"timestamp":"2024-06-01T17:52:29.389624Z"}]}
{"channel":"book","type":"update","data":[{"symbol":"ETH/GBP","bids":[{"price":2978.57,"qty":6.58491730}],"asks":[],"checksum":1193095967,"timestamp":"2024-06-01T17:52:29.391475Z"}]}
{"channel":"book","type":"update","data":[{"symbol":"ETH/GBP","bids":[],"asks":[{"price":2980.75,"qty":0.00000000},{"price":2980.95,"qty":0.22400000}],"checksum":4046358401,"timestamp":"2024-06-01T17:52:29.498961Z"}]}
{"channel":"book","type":"update","data":[{"symbol":"ETH/GBP","bids":[],"asks":[{"price":2980.74,"qty":2.94416492}],"checksum":3002711962,"timestamp":"2024-06-01T17:52:29.501838Z"}]}
{"channel":"book","type":"update","data":[{"symbol":"ETH/GBP","bids":[],"asks":[{"price":2980.27,"qty":0.00000000},{"price":2980.95,"qty":0.22400000}],"checksum":269902157,"timestamp":"2024-06-01T17:52:29.634078Z"}]}
{"channel":"book","type":"update","data":[{"symbol":"ETH/GBP","bids":[],"asks":[{"price":2978.79,"qty":0.00000000},{"price":2981.04,"qty":0.94850883}],"checksum":2717737819,"timestamp":"2024-06-01T17:52:29.636122Z"}]}
{"channel":"book","type":"update","data":[{"symbol":"ETH/GBP","bids":[{"price":2978.57,"qty":0.00000000},{"price":2975.01,"qty":1.31855212}],"asks":[],"checksum":2825045998,"timestamp":"2024-06-01T17:52:29.636303Z"}]}
{"channel":"book","type":"update","data":[{"symbol":"ETH/GBP","bids":[],"asks":[{"price":2980.33,"qty":15.42770419}],"checksum":749324548,"timestamp":"2024-06-01T17:52:29.638777Z"}]}
{"channel":"book","type":"update","data":[{"symbol":"ETH/GBP","bids":[],"asks":[{"price":2978.81,"qty":6.58439799}],"checksum":3264202024,"timestamp":"2024-06-01T17:52:29.641017Z"}]}
{"channel":"book","type":"update","data":[{"symbol":"ETH/GBP","bids":[{"price":2978.58,"qty":6.58488513}],"asks":[],"checksum":4082859489,"timestamp":"2024-06-01T17:52:29.641041Z"}]}
{"channel":"book","type":"update","data":[{"symbol":"ETH/GBP","bids":[],"asks":[{"price":2978.81,"qty":0.00000000},{"price":2980.95,"qty":0.22400000}],"checksum":494760397,"timestamp":"2024-06-01T17:52:29.682748Z"}]}
{"channel":"book","type":"update","data":[{"symbol":"ETH/GBP","bids":[{"price":2978.58,"qty":0.00000000},{"price":2975.01,"qty":1.31855212}],"asks":[],"checksum":749324548,"timestamp":"2024-06-01T17:52:29.806320Z"}]}
{"channel":"book","type":"update","data":[{"symbol":"ETH/GBP","bids":[],"asks":[{"price":2978.83,"qty":6.58434847}],"checksum":2397552672,"timestamp":"2024-06-01T17:52:29.811572Z"}]}
{"channel":"book","type":"update","data":[{"symbol":"ETH/GBP","bids":[{"price":2978.60,"qty":6.58484663}],"asks":[],"checksum":1288353969,"timestamp":"2024-06-01T17:52:29.811748Z"}]}
{"channel":"book","type":"update","data":[{"symbol":"ETH/GBP","bids":[],"asks":[{"price":2978.83,"qty":0.00000000},{"price":2980.95,"qty":0.22400000}],"checksum":4001673621,"timestamp":"2024-06-01T17:52:30.221149Z"}]}
{"channel":"book","type":"update","data":[{"symbol":"ETH/GBP","bids":[{"price":2978.60,"qty":0.00000000},{"price":2975.01,"qty":1.31855212}],"asks":[],"checksum":749324548,"timestamp":"2024-06-01T17:52:30.221219Z"}]}
{"channel":"book","type":"update","data":[{"symbol":"ETH/GBP","bids":[],"asks":[{"price":2979.24,"qty":0.00000000},{"price":2981.04,"qty":0.94850883}],"checksum":1820878766,"timestamp":"2024-06-01T17:52:30.227059Z"}]}
{"channel":"book","type":"update","data":[{"symbol":"ETH/GBP","bids":[{"price":2978.64,"qty":6.58476081}],"asks":[],"checksum":3556992989,"timestamp":"2024-06-01T17:52:30.231053Z"}]}
{"channel":"book","type":"update","data":[{"symbol":"ETH/GBP","bids":[],"asks":[{"price":2978.88,"qty":6.58424330}],"checksum":838684881,"timestamp":"2024-06-01T17:52:30.231170Z"}]}
{"channel":"book","type":"update","data":[{"symbol":"ETH/GBP","bids":[],"asks":[{"price":2979.31,"qty":13.16658162}],"checksum":3532021127,"timestamp":"2024-06-01T17:52:30.231194Z"}]}
{"channel":"book","type":"update","data":[{"symbol":"ETH/GBP","bids":[{"price":2978.64,"qty":0.00000000},{"price":2975.01,"qty":1.31855212}],"asks":[],"checksum":1779260916,"timestamp":"2024-06-01T17:52:30.263055Z"}]}
{"channel":"book","type":"update","data":[{"symbol":"ETH/GBP","bids":[],"asks":[{"price":2978.88,"qty":0.00000000},{"price":2980.95,"qty":0.22400000}],"checksum":1554994659,"timestamp":"2024-06-01T17:52:30.263086Z"}]}
{"channel":"book","type":"update","data":[{"symbol":"ETH/GBP","bids":[{"price":2978.17,"qty":0.00000000},{"price":2974.50,"qty":0.27200000}],"asks":[],"checksum":420599411,"timestamp":"2024-06-01T17:52:30.263172Z"}]}
{"channel":"book","type":"update","data":[{"symbol":"ETH/GBP","bids":[{"price":2978.25,"qty":0.00000000},{"price":2973.93,"qty":0.27474654}],"asks":[],"checksum":3956619249,"timestamp":"2024-06-01T17:52:30.266000Z"}]}
{"channel":"book","type":"update","data":[{"symbol":"ETH/GBP","bids":[{"price":2977.65,"qty":0.31000000}],"asks":[],"checksum":2699899467,"timestamp":"2024-06-01T17:52:30.266421Z"}]}
{"channel":"book","type":"update","data":[{"symbol":"ETH/GBP","bids":[{"price":2978.22,"qty":13.17135824}],"asks":[],"checksum":1035667681,"timestamp":"2024-06-01T17:52:30.269149Z"}]}
{"channel":"book","type":"update","data":[{"symbol":"ETH/GBP","bids":[{"price":2977.65,"qty":0.00000000},{"price":2974.50,"qty":0.27200000}],"asks":[],"checksum":1693234207,"timestamp":"2024-06-01T17:52:30.271802Z"}]}
{"channel":"book","type":"update","data":[{"symbol":"ETH/GBP","bids":[{"price":2978.30,"qty":0.31000000}],"asks":[],"checksum":1453423692,"timestamp":"2024-06-01T17:52:30.271872Z"}]}
{"channel":"book","type":"update","data":[{"symbol":"ETH/GBP","bids":[{"price":2978.67,"qty":6.58469403}],"asks":[],"checksum":2276115117,"timestamp":"2024-06-01T17:52:30.413404Z"}]}
{"channel":"book","type":"update","data":[{"symbol":"ETH/GBP","bids":[],"asks":[{"price":2979.15,"qty":6.58363742}],"checksum":1158023253,"timestamp":"2024-06-01T17:52:30.413799Z"}]}
{"channel":"book","type":"update","data":[{"symbol":"ETH/GBP","bids":[{"price":2978.67,"qty":0.00000000},{"price":2975.01,"qty":1.31855212}],"asks":[],"checksum":2483926708,"timestamp":"2024-06-01T17:52:30.418482Z"}]}
{"channel":"book","type":"update","data":[{"symbol":"ETH/GBP","bids":[],"asks":[{"price":2979.15,"qty":0.00000000},{"price":2980.95,"qty":0.22400000}],"checksum":1453423692,"timestamp":"2024-06-01T17:52:30.418501Z"}]}
{"channel":"book","type":"update","data":[{"symbol":"ETH/GBP","bids":[{"price":2978.22,"qty":0.00000000},{"price":2974.50,"qty":0.27200000}],"asks":[],"checksum":2470944795,"timestamp":"2024-06-01T17:52:30.423547Z"}]}
{"channel":"book","type":"update","data":[{"symbol":"ETH/GBP","bids":[{"price":2978.30,"qty":0.00000000},{"price":2973.93,"qty":0.27474654}],"asks":[],"checksum":3956619249,"timestamp":"2024-06-01T17:52:30.426167Z"}]}
{"channel":"book","type":"update","data":[{"symbol":"ETH/GBP","bids":[{"price":2977.65,"qty":0.31000000}],"asks":[],"checksum":2699899467,"timestamp":"2024-06-01T17:52:30.426600Z"}]}
{"channel":"book","type":"update","data":[{"symbol":"ETH/GBP","bids":[{"price":2978.28,"qty":13.17111445}],"asks":[],"checksum":1585846633,"timestamp":"2024-06-01T17:52:30.471999Z"}]}
{"channel":"book","type":"update","data":[{"symbol":"ETH/GBP","bids":[{"price":2977.65,"qty":0.00000000},{"price":2974.50,"qty":0.27200000}],"asks":[],"checksum":131179927,"timestamp":"2024-06-01T17:52:30.474856Z"}]}
{"channel":"book","type":"update","data":[{"symbol":"ETH/GBP","bids":[{"price":2978.36,"qty":0.31000000}],"asks":[],"checksum":3581452814,"timestamp":"2024-06-01T17:52:30.475009Z"}]}
{"channel":"book","type":"update","data":[{"symbol":"ETH/GBP","bids":[],"asks":[{"price":2978.93,"qty":6.58414542}],"checksum":3518020135,"timestamp":"2024-06-01T17:52:30.512154Z"}]}
{"channel":"book","type":"update","data":[{"symbol":"ETH/GBP","bids":[{"price":2978.70,"qty":6.58461903}],"asks":[],"checksum":1525679445,"timestamp":"2024-06-01T17:52:30.512356Z"}]}
{"channel":"book","type":"update","data":[{"symbol":"ETH/GBP","bids":[],"asks":[{"price":2979.16,"qty":0.00000000},{"price":2980.95,"qty":0.22400000},{"price":2979.64,"qty":0.06977600}],"checksum":3536890966,"timestamp":"2024-06-01T17:52:30.523004Z"}]}
{"channel":"book","type":"update","data":[{"symbol":"ETH/GBP","bids":[],"asks":[{"price":2978.93,"qty":0.00000000},{"price":2980.95,"qty":0.22400000}],"checksum":1674269583,"timestamp":"2024-06-01T17:52:30.523782Z"}]}
{"channel":"book","type":"update","data":[{"symbol":"ETH/GBP","bids":[],"asks":[{"price":2978.93,"qty":6.58414106}],"checksum":3396597007,"timestamp":"2024-06-01T17:52:30.621927Z"}]}
{"channel":"book","type":"update","data":[{"symbol":"ETH/GBP","bids":[{"price":2978.70,"qty":0.00000000},{"price":2975.01,"qty":1.31855212}],"asks":[],"checksum":1093880445,"timestamp":"2024-06-01T17:52:30.768099Z"}]}
{"channel":"book","type":"update","data":[{"symbol":"ETH/GBP","bids":[],"asks":[{"price":2979.31,"qty":0.00000000},{"price":2980.95,"qty":0.22400000}],"checksum":2981815254,"timestamp":"2024-06-01T17:52:30.768177Z"}]}
{"channel":"book","type":"update","data":[{"symbol":"ETH/GBP","bids":[],"asks":[{"price":2980.05,"qty":0.00000000},{"price":2981.04,"qty":0.94850883}],"checksum":591120257,"timestamp":"2024-06-01T17:52:30.780270Z"}]}
{"channel":"book","type":"update","data":[{"symbol":"ETH/GBP","bids":[],"asks":[{"price":2978.93,"qty":0.00000000},{"price":2981.15,"qty":1.41091270}],"checksum":153097976,"timestamp":"2024-06-01T17:52:30.780282Z"}]}
{"channel":"book","type":"update","data":[{"symbol":"ETH/GBP","bids":[{"price":2978.28,"qty":0.00000000},{"price":2974.50,"qty":0.27200000}],"asks":[],"checksum":4084238379,"timestamp":"2024-06-01T17:52:30.780294Z"}]}
{"channel":"book","type":"update","data":[{"symbol":"ETH/GBP","bids":[],"asks":[{"price":2980.76,"qty":0.00000000},{"price":2981.18,"qty":1.31583288}],"checksum":3613505156,"timestamp":"2024-06-01T17:52:30.780358Z"}]}
{"channel":"book","type":"update","data":[{"symbol":"ETH/GBP","bids":[],"asks":[{"price":2980.33,"qty":0.00000000},{"price":2981.21,"qty":1.00000000}],"checksum":875528045,"timestamp":"2024-06-01T17:52:30.782345Z"}]}
{"channel":"book","type":"update","data":[{"symbol":"ETH/GBP","bids":[{"price":2978.36,"qty":0.00000000},{"price":2973.93,"qty":0.27474654}],"asks":[],"checksum":727455530,"timestamp":"2024-06-01T17:52:30.783168Z"}]}
{"channel":"book","type":"update","data":[{"symbol":"ETH/GBP","bids":[{"price":2977.65,"qty":0.31000000}],"asks":[],"checksum":1617171088,"timestamp":"2024-06-01T17:52:30.783800Z"}]}
{"channel":"book","type":"update","data":[{"symbol":"ETH/GBP","bids":[],"asks":[{"price":2980.40,"qty":14.27472015}],"checksum":3385445865,"timestamp":"2024-06-01T17:52:30.786815Z"}]}
{"channel":"book","type":"update","data":[{"symbol":"ETH/GBP","bids":[{"price":2979.02,"qty":6.58391145}],"asks":[],"checksum":2239784522,"timestamp":"2024-06-01T17:52:30.789430Z"}]}
{"channel":"book","type":"update","data":[{"symbol":"ETH/GBP","bids":[],"asks":[{"price":2979.28,"qty":6.58335329}],"checksum":1934817182,"timestamp":"2024-06-01T17:52:30.789553Z"}]}
{"channel":"book","type":"update","data":[{"symbol":"ETH/GBP","bids":[],"asks":[{"price":2980.48,"qty":1.31614320}],"checksum":261433477,"timestamp":"2024-06-01T17:52:30.789572Z"}]}
{"channel":"book","type":"update","data":[{"symbol":"ETH/GBP","bids":[{"price":2978.59,"qty":13.16970831}],"asks":[],"checksum":4020378240,"timestamp":"2024-06-01T17:52:30.789584Z"}]}
{"channel":"book","type":"update","data":[{"symbol":"ETH/GBP","bids":[],"asks":[{"price":2979.71,"qty":13.16480186}],"checksum":3500680312,"timestamp":"2024-06-01T17:52:30.789623Z"}]}
{"channel":"book","type":"update","data":[{"symbol":"ETH/GBP","bids":[{"price":2977.83,"qty":1.31730802}],"asks":[],"checksum":4053772698,"timestamp":"2024-06-01T17:52:30.789643Z"}]}
{"channel":"book","type":"update","data":[{"symbol":"ETH/GBP","bids":[{"price":2975.83,"qty":0.00000000},{"price":2975.62,"qty":0.21200000}],"asks":[],"checksum":648446728,"timestamp":"2024-06-01T17:52:30.799686Z"}]}
{"channel":"book","type":"update","data":[{"symbol":"ETH/GBP","bids":[{"price":2978.59,"qty":0.00000000},{"price":2975.02,"qty":0.34530000}],"asks":[],"checksum":1490731612,"timestamp":"2024-06-01T17:52:30.803868Z"}]}
{"channel":"book","type":"update","data":[{"symbol":"ETH/GBP","bids":[],"asks":[{"price":2979.71,"qty":0.00000000},{"price":2981.04,"qty":0.94850883}],"checksum":2963173999,"timestamp":"2024-06-01T17:52:30.803886Z"}]}
{"channel":"book","type":"update","data":[{"symbol":"ETH/GBP","bids":[{"price":2979.02,"qty":0.00000000},{"price":2975.01,"qty":1.31855212}],"asks":[],"checksum":656292026,"timestamp":"2024-06-01T17:52:30.803954Z"}]}
{"channel":"book","type":"update","data":[{"symbol":"ETH/GBP","bids":[{"price":2977.45,"qty":0.00000000},{"price":2974.50,"qty":0.27200000}],"asks":[],"checksum":83071880,"timestamp":"2024-06-01T17:52:30.803964Z"}]}
{"channel":"book","type":"update","data":[{"symbol":"ETH/GBP","bids":[],"asks":[{"price":2979.28,"qty":0.00000000},{"price":2981.15,"qty":1.41091270}],"checksum":3165660220,"timestamp":"2024-06-01T17:52:30.803999Z"}]}
{"channel":"book","type":"update","data":[{"symbol":"ETH/GBP","bids":[{"price":2977.91,"qty":0.31000000}],"asks":[],"checksum":2006298473,"timestamp":"2024-06-01T17:52:30.807687Z"}]}
{"channel":"book","type":"update","data":[{"symbol":"ETH/GBP","bids":[{"price":2977.65,"qty":0.00000000},{"price":2974.50,"qty":0.27200000}],"asks":[],"checksum":2083600098,"timestamp":"2024-06-01T17:52:30.808537Z"}]}
{"channel":"book","type":"update","data":[{"symbol":"ETH/GBP","bids":[{"price":2975.84,"qty":0.00000000},{"price":2973.93,"qty":0.27474654},{"price":2975.03,"qty":1.34000000}],"asks":[],"checksum":3802432576,"timestamp":"2024-06-01T17:52:30.810682Z"}]}
{"channel":"book","type":"update","data":[{"symbol":"ETH/GBP","bids":[],"asks":[{"price":2980.40,"qty":0.00000000},{"price":2981.18,"qty":1.31583288}],"checksum":149598772,"timestamp":"2024-06-01T17:52:30.811150Z"}]}
{"channel":"book","type":"update","data":[{"symbol":"ETH/GBP","bids":[],"asks":[{"price":2980.48,"qty":11.91098835}],"checksum":1004607805,"timestamp":"2024-06-01T17:52:30.817252Z"}]}
{"channel":"book","type":"update","data":[{"symbol":"ETH/GBP","bids":[{"price":2977.03,"qty":1.31766423}],"asks":[],"checksum":105202046,"timestamp":"2024-06-01T17:52:30.817876Z"}]}
{"channel":"book","type":"update","data":[{"symbol":"ETH/GBP","bids":[],"asks":[{"price":2980.48,"qty":1.31614320}],"checksum":2141909617,"timestamp":"2024-06-01T17:52:30.843465Z"}]}
{"channel":"book","type":"update","data":[{"symbol":"ETH/GBP","bids":[],"asks":[{"price":2980.58,"qty":13.43327015}],"checksum":1765944188,"timestamp":"2024-06-01T17:52:30.848021Z"}]}
{"channel":"book","type":"update","data":[{"symbol":"ETH/GBP","bids":[{"price":2978.57,"qty":6.58491942}],"asks":[],"checksum":4047593225,"timestamp":"2024-06-01T17:52:30.895615Z"}]}
{"channel":"book","type":"update","data":[{"symbol":"ETH/GBP","bids":[],"asks":[{"price":2979.17,"qty":6.58360607}],"checksum":3462969174,"timestamp":"2024-06-01T17:52:30.895673Z"}]}
{"channel":"book","type":"update","data":[{"symbol":"ETH/GBP","bids":[{"price":2977.91,"qty":0.00000000},{"price":2975.01,"qty":1.31855212}],"asks":[],"checksum":4258470414,"timestamp":"2024-06-01T17:52:30.898462Z"}]}
{"channel":"book","type":"update","data":[{"symbol":"ETH/GBP","bids":[{"price":2978.59,"qty":0.31000000}],"asks":[],"checksum":1612055871,"timestamp":"2024-06-01T17:52:30.898635Z"}]}
{"channel":"book","type":"update","data":[{"symbol":"ETH/GBP","bids":[],"asks":[{"price":2979.17,"qty":0.00000000},{"price":2981.15,"qty":1.41091270}],"checksum":1598025056,"timestamp":"2024-06-01T17:52:30.900847Z"}]}
{"channel":"book","type":"update","data":[{"symbol":"ETH/GBP","bids":[{"price":2978.57,"qty":0.00000000},{"price":2975.01,"qty":1.31855212}],"asks":[],"checksum":157859275,"timestamp":"2024-06-01T17:52:30.900882Z"}]}
{"channel":"book","type":"update","data":[{"symbol":"ETH/GBP","bids":[],"asks":[{"price":2979.64,"qty":0.00000000},{"price":2981.18,"qty":1.31583288},{"price":2980.23,"qty":0.06981300}],"checksum":4004196632,"timestamp":"2024-06-01T17:52:30.931248Z"}]}
{"channel":"book","type":"update","data":[{"symbol":"ETH/GBP","bids":[{"price":2978.56,"qty":0.00000000},{"price":2974.50,"qty":0.27200000},{"price":2979.03,"qty":0.08557700}],"asks":[],"checksum":526357691,"timestamp":"2024-06-01T17:52:30.989199Z"}]}
{"channel":"book","type":"update","data":[{"symbol":"ETH/GBP","bids":[{"price":2977.57,"qty":0.00000000},{"price":2974.50,"qty":0.27200000}],"asks":[],"checksum":808616727,"timestamp":"2024-06-01T17:52:30.991438Z"}]}
{"channel":"book","type":"update","data":[{"symbol":"ETH/GBP","bids":[{"price":2978.59,"qty":0.00000000},{"price":2973.93,"qty":0.27474654}],"asks":[],"checksum":31407063,"timestamp":"2024-06-01T17:52:30.993043Z"}]}
{"channel":"book","type":"update","data":[{"symbol":"ETH/GBP","bids":[{"price":2977.91,"qty":0.31000000}],"asks":[],"checksum":3353581590,"timestamp":"2024-06-01T17:52:30.993067Z"}]}
{"channel":"book","type":"update","data":[{"symbol":"ETH/GBP","bids":[{"price":2978.43,"qty":13.17042891}],"asks":[],"checksum":1076927053,"timestamp":"2024-06-01T17:52:30.994896Z"}]}
{"channel":"book","type":"update","data":[{"symbol":"ETH/GBP","bids":[],"asks":[{"price":2980.48,"qty":0.00000000},{"price":2981.18,"qty":1.31583288}],"checksum":3708866714,"timestamp":"2024-06-01T17:52:30.994918Z"}]}
{"channel":"book","type":"update","data":[{"symbol":"ETH/GBP","bids":[],"asks":[{"price":2979.53,"qty":13.16559900}],"checksum":922242076,"timestamp":"2024-06-01T17:52:30.995009Z"}]}
{"channel":"book","type":"update","data":[{"symbol":"ETH/GBP","bids":[{"price":2977.03,"qty":0.00000000},{"price":2974.50,"qty":0.27200000}],"asks":[],"checksum":856920786,"timestamp":"2024-06-01T17:52:30.995047Z"}]}
{"channel":"book","type":"update","data":[{"symbol":"ETH/GBP","bids":[{"price":2977.83,"qty":0.00000000},{"price":2973.93,"qty":0.27474654}],"asks":[],"checksum":1060988546,"timestamp":"2024-06-01T17:52:30.995060Z"}]}
{"channel":"book","type":"update","data":[{"symbol":"ETH/GBP","bids":[{"price":2977.36,"qty":5.37412202}],"asks":[],"checksum":3165824109,"timestamp":"2024-06-01T17:52:30.996897Z"}]}
{"channel":"book","type":"update","data":[{"symbol":"ETH/GBP","bids":[{"price":2977.91,"qty":0.00000000},{"price":2973.93,"qty":0.27474654}],"asks":[],"checksum":4142447908,"timestamp":"2024-06-01T17:52:30.998475Z"}]}
{"channel":"book","type":"update","data":[{"symbol":"ETH/GBP","bids":[{"price":2978.51,"qty":0.31000000}],"asks":[],"checksum":4067041316,"timestamp":"2024-06-01T17:52:31.000871Z"}]}
{"channel":"book","type":"update","data":[{"symbol":"ETH/GBP","bids":[{"price":2975.02,"qty":0.00000000},{"price":2973.93,"qty":0.27474654}],"asks":[],"checksum":597121802,"timestamp":"2024-06-01T17:52:31.004277Z"}]}
{"channel":"book","type":"update","data":[{"symbol":"ETH/GBP","bids":[],"asks":[{"price":2979.53,"qty":0.00000000},{"price":2981.18,"qty":1.31583288}],"checksum":3309167311,"timestamp":"2024-06-01T17:52:31.008645Z"}]}
{"channel":"book","type":"update","data":[{"symbol":"ETH/GBP","bids":[{"price":2977.36,"qty":0.00000000},{"price":2973.19,"qty":0.14113766}],"asks":[],"checksum":3670760119,"timestamp":"2024-06-01T17:52:31.008695Z"}]}
{"channel":"book","type":"update","data":[{"symbol":"ETH/GBP","bids":[{"price":2978.43,"qty":0.00000000},{"price":2973.18,"qty":0.27800000}],"asks":[],"checksum":1367245601,"timestamp":"2024-06-01T17:52:31.008721Z"}]}
{"channel":"book","type":"update","data":[{"symbol":"ETH/GBP","bids":[{"price":2978.51,"qty":0.00000000},{"price":2972.51,"qty":1.14340000}],"asks":[],"checksum":463636074,"timestamp":"2024-06-01T17:52:31.012229Z"}]}
{"channel":"book","type":"update","data":[{"symbol":"ETH/GBP","bids":[],"asks":[{"price":2979.04,"qty":1.31752479}],"checksum":3928974633,"timestamp":"2024-06-01T17:52:31.012816Z"}]}
{"channel":"book","type":"update","data":[{"symbol":"ETH/GBP","bids":[],"asks":[{"price":2979.15,"qty":0.31000000}],"checksum":2758221751,"timestamp":"2024-06-01T17:52:31.015507Z"}]}
{"channel":"book","type":"update","data":[{"symbol":"ETH/GBP","bids":[{"price":2976.71,"qty":0.31000000}],"asks":[],"checksum":1141075377,"timestamp":"2024-06-01T17:52:31.015622Z"}]}
{"channel":"book","type":"update","data":[{"symbol":"ETH/GBP","bids":[{"price":2977.16,"qty":5.37448305}],"asks":[],"checksum":1592573978,"timestamp":"2024-06-01T17:52:31.020234Z"}]}
{"channel":"book","type":"update","data":[{"symbol":"ETH/GBP","bids":[],"asks":[{"price":2979.22,"qty":6.58348273}],"checksum":3267462167,"timestamp":"2024-06-01T17:52:31.020868Z"}]}
{"channel":"book","type":"update","data":[{"symbol":"ETH/GBP","bids":[{"price":2978.03,"qty":6.58609825}],"asks":[],"checksum":1590045564,"timestamp":"2024-06-01T17:52:31.020989Z"}]}
{"channel":"book","type":"update","data":[{"symbol":"ETH/GBP","bids":[{"price":2976.05,"qty":1.31809876}],"asks":[],"checksum":3706498729,"timestamp":"2024-06-01T17:52:31.021012Z"}]}
{"channel":"book","type":"update","data":[{"symbol":"ETH/GBP","bids":[],"asks":[{"price":2980.74,"qty":4.26019094}],"checksum":3174089446,"timestamp":"2024-06-01T17:52:31.021093Z"}]}
{"channel":"book","type":"update","data":[{"symbol":"ETH/GBP","bids":[{"price":2976.63,"qty":0.00000000},{"price":2974.45,"qty":1.31880744}],"asks":[],"checksum":722517321,"timestamp":"2024-06-01T17:52:31.023219Z"}]}
{"channel":"book","type":"update","data":[{"symbol":"ETH/GBP","bids":[],"asks":[{"price":2980.94,"qty":0.21492266}],"checksum":3054150682,"timestamp":"2024-06-01T17:52:31.023471Z"}]}
{"channel":"book","type":"update","data":[{"symbol":"ETH/GBP","bids":[],"asks":[{"price":2980.94,"qty":0.20717085}],"checksum":1149423388,"timestamp":"2024-06-01T17:52:31.024408Z"}]}
{"channel":"book","type":"update","data":[{"symbol":"ETH/GBP","bids":[{"price":2977.16,"qty":0.00000000},{"price":2973.93,"qty":0.27474654}],"asks":[],"checksum":951892810,"timestamp":"2024-06-01T17:52:31.027665Z"}]}
{"channel":"book","type":"update","data":[{"symbol":"ETH/GBP","bids":[{"price":2978.03,"qty":0.00000000},{"price":2973.19,"qty":0.14113766}],"asks":[],"checksum":725633978,"timestamp":"2024-06-01T17:52:31.033805Z"}]}
{"channel":"book","type":"update","data":[{"symbol":"ETH/GBP","bids":[],"asks":[{"price":2979.22,"qty":0.00000000},{"price":2981.04,"qty":0.94850883}],"checksum":1904208937,"timestamp":"2024-06-01T17:52:31.033855Z"}]}
{"channel":"book","type":"update","data":[{"symbol":"ETH/GBP","bids":[],"asks":[{"price":2980.74,"qty":2.94416492}],"checksum":989330718,"timestamp":"2024-06-01T17:52:31.033925Z"}]}
{"channel":"book","type":"update","data":[{"symbol":"ETH/GBP","bids":[{"price":2976.05,"qty":0.00000000},{"price":2973.18,"qty":0.27800000}],"asks":[],"checksum":4291042599,"timestamp":"2024-06-01T17:52:31.033949Z"}]}
{"channel":"book","type":"update","data":[{"symbol":"ETH/GBP","bids":[{"price":2976.71,"qty":0.00000000},{"price":2972.51,"qty":1.14340000}],"asks":[],"checksum":1426567181,"timestamp":"2024-06-01T17:52:31.035317Z"}]}
{"channel":"book","type":"update","data":[{"symbol":"ETH/GBP","bids":[{"price":2977.11,"qty":0.13051361}],"asks":[],"checksum":2312086107,"timestamp":"2024-06-01T17:52:31.041028Z"}]}
{"channel":"book","type":"update","data":[{"symbol":"ETH/GBP","bids":[{"price":2975.01,"qty":0.00000000},{"price":2972.51,"qty":1.14340000}],"asks":[],"checksum":1483482144,"timestamp":"2024-06-01T17:52:31.041767Z"}]}
{"channel":"book","type":"update","data":[{"symbol":"ETH/GBP","bids":[{"price":2975.03,"qty":0.00000000},{"price":2972.45,"qty":4.28760000}],"asks":[],"checksum":554005309,"timestamp":"2024-06-01T17:52:31.041863Z"}]}
{"channel":"book","type":"update","data":[{"symbol":"ETH/GBP","bids":[],"asks":[{"price":2980.59,"qty":1.00000000}],"checksum":3425318456,"timestamp":"2024-06-01T17:52:31.058330Z"}]}
{"channel":"book","type":"update","data":[{"symbol":"ETH/GBP","bids":[{"price":2974.51,"qty":0.14107504}],"asks":[],"checksum":1697884651,"timestamp":"2024-06-01T17:52:31.073202Z"}]}
{"channel":"book","type":"update","data":[{"symbol":"ETH/GBP","bids":[{"price":2973.19,"qty":0.00000000},{"price":2972.45,"qty":4.28760000}],"asks":[],"checksum":2665374644,"timestamp":"2024-06-01T17:52:31.073747Z"}]}
{"channel":"book","type":"update","data":[{"symbol":"ETH/GBP","bids":[{"price":2975.62,"qty":0.00000000},{"price":2972.24,"qty":1.31978122}],"asks":[],"checksum":2935470200,"timestamp":"2024-06-01T17:52:31.074417Z"}]}
{"channel":"book","type":"update","data":[{"symbol":"ETH/GBP","bids":[],"asks":[{"price":2979.83,"qty":0.27100000}],"checksum":1509645080,"timestamp":"2024-06-01T17:52:31.076377Z"}]}
{"channel":"book","type":"update","data":[{"symbol":"ETH/GBP","bids":[{"price":2974.50,"qty":0.00000000},{"price":2971.01,"qty":15.80544336}],"asks":[],"checksum":607962552,"timestamp":"2024-06-01T17:52:31.089826Z"}]}
{"channel":"book","type":"update","data":[{"symbol":"ETH/GBP","bids":[{"price":2977.11,"qty":0.00000000},{"price":2971.00,"qty":0.94850883}],"asks":[],"checksum":1179945990,"timestamp":"2024-06-01T17:52:31.096064Z"}]}
{"channel":"book","type":"update","data":[{"symbol":"ETH/GBP","bids":[{"price":2977.17,"qty":6.58800676}],"asks":[],"checksum":2315409799,"timestamp":"2024-06-01T17:52:31.116834Z"}]}
{"channel":"book","type":"update","data":[{"symbol":"ETH/GBP","bids":[],"asks":[{"price":2979.04,"qty":7.90140531}],"checksum":2592246540,"timestamp":"2024-06-01T17:52:31.116936Z"}]}
{"channel":"book","type":"update","data":[{"symbol":"ETH/GBP","bids":[{"price":2976.95,"qty":1.67251355}],"asks":[],"checksum":2339757993,"timestamp":"2024-06-01T17:52:31.118430Z"}]}
{"channel":"book","type":"update","data":[{"symbol":"ETH/GBP","bids":[{"price":2977.17,"qty":0.00000000},{"price":2971.01,"qty":15.80544336}],"asks":[],"checksum":2096723094,"timestamp":"2024-06-01T17:52:31.123690Z"}]}
{"channel":"book","type":"update","data":[{"symbol":"ETH/GBP","bids":[{"price":2976.95,"qty":0.00000000},{"price":2971.00,"qty":0.94850883}],"asks":[],"checksum":486301084,"timestamp":"2024-06-01T17:52:31.129724Z"}]}
{"channel":"book","type":"update","data":[{"symbol":"ETH/GBP","bids":[{"price":2976.79,"qty":4.39856949}],"asks":[],"checksum":2373919156,"timestamp":"2024-06-01T17:52:31.138576Z"}]}
{"channel":"book","type":"update","data":[{"symbol":"ETH/GBP","bids":[],"asks":[{"price":2979.04,"qty":21.06916636}],"checksum":1782943489,"timestamp":"2024-06-01T17:52:31.192653Z"}]}
{"channel":"book","type":"update","data":[{"symbol":"ETH/GBP","bids":[{"price":2976.62,"qty":13.17843135}],"asks":[],"checksum":2178757830,"timestamp":"2024-06-01T17:52:31.192770Z"}]}
{"channel":"book","type":"update","data":[{"symbol":"ETH/GBP","bids":[{"price":2976.62,"qty":0.00000000},{"price":2971.01,"qty":15.80544336}],"asks":[],"checksum":1782943489,"timestamp":"2024-06-01T17:52:31.200249Z"}]}
{"channel":"book","type":"update","data":[{"symbol":"ETH/GBP","bids":[],"asks":[{"price":2980.28,"qty":1.00000000}],"checksum":567566011,"timestamp":"2024-06-01T17:52:31.201749Z"}]}
{"channel":"book","type":"update","data":[{"symbol":"ETH/GBP","bids":[{"price":2976.79,"qty":0.00000000},{"price":2971.00,"qty":0.94850883}],"asks":[],"checksum":192549559,"timestamp":"2024-06-01T17:52:31.208024Z"}]}
{"channel":"book","type":"update","data":[{"symbol":"ETH/GBP","bids":[{"price":2974.53,"qty":1.34000000}],"asks":[],"checksum":3289830479,"timestamp":"2024-06-01T17:52:31.212505Z"}]}
{"channel":"book","type":"update","data":[{"symbol":"ETH/GBP","bids":[{"price":2976.17,"qty":4.39948581}],"asks":[],"checksum":3747903267,"timestamp":"2024-06-01T17:52:31.225359Z"}]}
{"channel":"book","type":"update","data":[{"symbol":"ETH/GBP","bids":[],"asks":[{"price":2980.59,"qty":0.00000000},{"price":2980.94,"qty":0.20717085}],"checksum":1506533300,"timestamp":"2024-06-01T17:52:31.225769Z"}]}
{"channel":"book","type":"update","data":[{"symbol":"ETH/GBP","bids":[{"price":2976.87,"qty":6.58865927}],"asks":[],"checksum":2744589044,"timestamp":"2024-06-01T17:52:31.226311Z"}]}
{"channel":"book","type":"update","data":[{"symbol":"ETH/GBP","bids":[{"price":2974.51,"qty":0.00000000},{"price":2972.24,"qty":1.31978122}],"asks":[],"checksum":724805921,"timestamp":"2024-06-01T17:52:31.229459Z"}]}
{"channel":"book","type":"update","data":[{"symbol":"ETH/GBP","bids":[{"price":2976.87,"qty":0.00000000},{"price":2971.01,"qty":15.80544336}],"asks":[],"checksum":1057116362,"timestamp":"2024-06-01T17:52:31.230604Z"}]}
{"channel":"book","type":"update","data":[{"symbol":"ETH/GBP","bids":[],"asks":[{"price":2980.05,"qty":0.27477173}],"checksum":1369414907,"timestamp":"2024-06-01T17:52:31.240287Z"}]}
{"channel":"book","type":"update","data":[{"symbol":"ETH/GBP","bids":[{"price":2974.54,"qty":0.14107364}],"asks":[],"checksum":1941056845,"timestamp":"2024-06-01T17:52:31.245415Z"}]}
{"channel":"book","type":"update","data":[{"symbol":"ETH/GBP","bids":[],"asks":[{"price":2979.65,"qty":1.00000000}],"checksum":2895685103,"timestamp":"2024-06-01T17:52:31.282949Z"}]}
{"channel":"book","type":"update","data":[{"symbol":"ETH/GBP","bids":[{"price":2973.20,"qty":0.34510000}],"asks":[],"checksum":3823666650,"timestamp":"2024-06-01T17:52:31.304344Z"}]}
{"channel":"book","type":"update","data":[{"symbol":"ETH/GBP","bids":[],"asks":[{"price":2980.28,"qty":0.00000000},{"price":2980.74,"qty":2.94416492}],"checksum":4162287206,"timestamp":"2024-06-01T17:52:31.316908Z"}]}
{"channel":"book","type":"update","data":[{"symbol":"ETH/GBP","bids":[{"price":2976.58,"qty":6.58930377}],"asks":[],"checksum":3881560613,"timestamp":"2024-06-01T17:52:31.326318Z"}]}
{"channel":"book","type":"update","data":[{"symbol":"ETH/GBP","bids":[{"price":2976.58,"qty":0.00000000},{"price":2972.45,"qty":4.28760000}],"asks":[],"checksum":4162287206,"timestamp":"2024-06-01T17:52:31.338255Z"}]}
{"channel":"book","type":"update","data":[{"symbol":"ETH/GBP","bids":[{"price":2976.15,"qty":13.18054449}],"asks":[],"checksum":142758118,"timestamp":"2024-06-01T17:52:31.396254Z"}]}
{"channel":"book","type":"update","data":[{"symbol":"ETH/GBP","bids":[{"price":2976.15,"qty":0.00000000},{"price":2972.45,"qty":4.28760000}],"asks":[],"checksum":4162287206,"timestamp":"2024-06-01T17:52:31.401930Z"}]}
{"channel":"book","type":"update","data":[{"symbol":"ETH/GBP","bids":[{"price":2976.54,"qty":6.58940693}],"asks":[],"checksum":1571254339,"timestamp":"2024-06-01T17:52:31.439740Z"}]}
{"channel":"book","type":"update","data":[{"symbol":"ETH/GBP","bids":[{"price":2976.54,"qty":0.00000000},{"price":2972.45,"qty":4.28760000}],"asks":[],"checksum":4162287206,"timestamp":"2024-06-01T17:52:31.464816Z"}]}
{"channel":"book","type":"update","data":[{"symbol":"ETH/GBP","bids":[],"asks":[{"price":2980.74,"qty":0.00000000},{"price":2980.94,"qty":0.20717085}],"checksum":217266403,"timestamp":"2024-06-01T17:52:31.476904Z"}]}
{"channel":"book","type":"update","data":[{"symbol":"ETH/GBP","bids":[],"asks":[{"price":2979.22,"qty":2.94416492}],"checksum":283109904,"timestamp":"2024-06-01T17:52:31.479565Z"}]}
{"channel":"book","type":"update","data":[{"symbol":"ETH/GBP","bids":[],"asks":[{"price":2979.39,"qty":0.94850883}],"checksum":1738014537,"timestamp":"2024-06-01T17:52:31.479646Z"}]}
{"channel":"book","type":"update","data":[{"symbol":"ETH/GBP","bids":[{"price":2979.03,"qty":0.00000000},{"price":2972.24,"qty":1.31978122},{"price":2974.52,"qty":0.08569300}],"asks":[],"checksum":3405402002,"timestamp":"2024-06-01T17:52:31.525125Z"}]}
{"channel":"book","type":"update","data":[{"symbol":"ETH/GBP","bids":[],"asks":[{"price":2979.22,"qty":0.00000000},{"price":2980.58,"qty":13.43327015}],"checksum":3460297583,"timestamp":"2024-06-01T17:52:31.527969Z"}]}
{"channel":"book","type":"update","data":[{"symbol":"ETH/GBP","bids":[],"asks":[{"price":2979.04,"qty":14.48528584}],"checksum":3482816263,"timestamp":"2024-06-01T17:52:31.529661Z"}]}
{"channel":"book","type":"update","data":[{"symbol":"ETH/GBP","bids":[],"asks":[{"price":2979.04,"qty":1.31752479}],"checksum":1598158687,"timestamp":"2024-06-01T17:52:31.529743Z"}]}
{"channel":"book","type":"update","data":[{"symbol":"ETH/GBP","bids":[],"asks":[{"price":2979.03,"qty":2.94416492}],"checksum":613266091,"timestamp":"2024-06-01T17:52:31.530742Z"}]}
{"channel":"book","type":"update","data":[{"symbol":"ETH/GBP","bids":[],"asks":[{"price":2980.24,"qty":1.34000000}],"checksum":2367830727,"timestamp":"2024-06-01T17:52:31.531563Z"}]}
{"channel":"book","type":"update","data":[{"symbol":"ETH/GBP","bids":[],"asks":[{"price":2979.00,"qty":1.31770808}],"checksum":2749566306,"timestamp":"2024-06-01T17:52:31.533777Z"}]}
{"channel":"book","type":"update","data":[{"symbol":"ETH/GBP","bids":[],"asks":[{"price":2977.02,"qty":6.58835104}],"checksum":3352199586,"timestamp":"2024-06-01T17:52:31.534166Z"}]}
{"channel":"book","type":"update","data":[{"symbol":"ETH/GBP","bids":[],"asks":[{"price":2979.04,"qty":0.00000000},{"price":2980.23,"qty":0.06981300}],"checksum":578032084,"timestamp":"2024-06-01T17:52:31.534189Z"}]}
{"channel":"book","type":"update","data":[{"symbol":"ETH/GBP","bids":[],"asks":[{"price":2979.02,"qty":13.16788791}],"checksum":2396165880,"timestamp":"2024-06-01T17:52:31.534299Z"}]}
{"channel":"book","type":"update","data":[{"symbol":"ETH/GBP","bids":[],"asks":[{"price":2979.03,"qty":0.00000000},{"price":2980.23,"qty":0.06981300}],"checksum":1403666047,"timestamp":"2024-06-01T17:52:31.536964Z"}]}
{"channel":"book","type":"update","data":[{"symbol":"ETH/GBP","bids":[],"asks":[{"price":2979.02,"qty":0.00000000},{"price":2980.24,"qty":1.34000000}],"checksum":3748430263,"timestamp":"2024-06-01T17:52:31.538811Z"}]}
{"channel":"book","type":"update","data":[{"symbol":"ETH/GBP","bids":[],"asks":[{"price":2978.99,"qty":2.94416492}],"checksum":2078844264,"timestamp":"2024-06-01T17:52:31.539689Z"}]}
{"channel":"book","type":"update","data":[{"symbol":"ETH/GBP","bids":[{"price":2976.47,"qty":6.58955279}],"asks":[],"checksum":3391390392,"timestamp":"2024-06-01T17:52:31.542907Z"}]}
{"channel":"book","type":"update","data":[{"symbol":"ETH/GBP","bids":[{"price":2973.21,"qty":0.14113671}],"asks":[],"checksum":680716306,"timestamp":"2024-06-01T17:52:31.548535Z"}]}
{"channel":"book","type":"update","data":[{"symbol":"ETH/GBP","bids":[{"price":2974.54,"qty":0.00000000},{"price":2972.51,"qty":1.14340000}],"asks":[],"checksum":2039324068,"timestamp":"2024-06-01T17:52:31.548638Z"}]}
{"channel":"book","type":"update","data":[{"symbol":"ETH/GBP","bids":[{"price":2976.47,"qty":0.00000000},{"price":2972.45,"qty":4.28760000}],"asks":[],"checksum":3718837319,"timestamp":"2024-06-01T17:52:31.556233Z"}]}
{"channel":"book","type":"update","data":[{"symbol":"ETH/GBP","bids":[],"asks":[{"price":2977.02,"qty":0.00000000},{"price":2980.24,"qty":1.34000000}],"checksum":3285914300,"timestamp":"2024-06-01T17:52:31.567304Z"}]}
{"channel":"book","type":"update","data":[{"symbol":"ETH/GBP","bids":[],"asks":[{"price":2978.96,"qty":1.31771684}],"checksum":1811678916,"timestamp":"2024-06-01T17:52:31.570729Z"}]}
{"channel":"book","type":"update","data":[{"symbol":"ETH/GBP","bids":[],"asks":[{"price":2979.00,"qty":0.00000000},{"price":2980.24,"qty":1.34000000}],"checksum":382598597,"timestamp":"2024-06-01T17:52:31.573679Z"}]}
{"channel":"book","type":"update","data":[{"symbol":"ETH/GBP","bids":[{"price":2976.05,"qty":13.18098228}],"asks":[],"checksum":828969089,"timestamp":"2024-06-01T17:52:31.595171Z"}]}
{"channel":"book","type":"update","data":[{"symbol":"ETH/GBP","bids":[{"price":2973.21,"qty":0.00000000},{"price":2972.45,"qty":4.28760000}],"asks":[],"checksum":156196218,"timestamp":"2024-06-01T17:52:31.614589Z"}]}
{"channel":"book","type":"update","data":[{"symbol":"ETH/GBP","bids":[{"price":2972.52,"qty":0.14116947}],"asks":[],"checksum":2491342715,"timestamp":"2024-06-01T17:52:31.614867Z"}]}
{"channel":"book","type":"update","data":[{"symbol":"ETH/GBP","bids":[{"price":2976.05,"qty":0.00000000},{"price":2972.45,"qty":4.28760000}],"asks":[],"checksum":2221303211,"timestamp":"2024-06-01T17:52:31.623098Z"}]}
{"channel":"book","type":"update","data":[{"symbol":"ETH/GBP","bids":[],"asks":[{"price":2977.12,"qty":6.58813995}],"checksum":189014671,"timestamp":"2024-06-01T17:52:31.637072Z"}]}
{"channel":"book","type":"update","data":[{"symbol":"ETH/GBP","bids":[],"asks":[{"price":2978.99,"qty":0.00000000},{"price":2980.24,"qty":1.34000000}],"checksum":3095031892,"timestamp":"2024-06-01T17:52:31.640258Z"}]}
{"channel":"book","type":"update","data":[{"symbol":"ETH/GBP","bids":[],"asks":[{"price":2977.12,"qty":0.00000000},{"price":2980.25,"qty":18.59824701}],"checksum":3346032197,"timestamp":"2024-06-01T17:52:31.642381Z"}]}
{"channel":"book","type":"update","data":[{"symbol":"ETH/GBP","bids":[],"asks":[{"price":2978.95,"qty":2.94416492}],"checksum":165311134,"timestamp":"2024-06-01T17:52:31.643044Z"}]}
{"channel":"book","type":"update","data":[{"symbol":"ETH/GBP","bids":[{"price":2976.61,"qty":6.58924213}],"asks":[],"checksum":995603680,"timestamp":"2024-06-01T17:52:31.645960Z"}]}
{"channel":"book","type":"update","data":[{"symbol":"ETH/GBP","bids":[],"asks":[{"price":2978.95,"qty":0.00000000},{"price":2980.25,"qty":18.59824701}],"checksum":4127039547,"timestamp":"2024-06-01T17:52:31.646273Z"}]}
{"channel":"book","type":"update","data":[{"symbol":"ETH/GBP","bids":[],"asks":[{"price":2978.92,"qty":1.31768077}],"checksum":2078161614,"timestamp":"2024-06-01T17:52:31.646990Z"}]}
{"channel":"book","type":"update","data":[{"symbol":"ETH/GBP","bids":[],"asks":[{"price":2978.96,"qty":0.00000000},{"price":2980.25,"qty":18.59824701}],"checksum":2733151305,"timestamp":"2024-06-01T17:52:31.649716Z"}]}
{"channel":"book","type":"update","data":[{"symbol":"ETH/GBP","bids":[],"asks":[{"price":2979.14,"qty":2.94416492}],"checksum":310634520,"timestamp":"2024-06-01T17:52:31.649857Z"}]}
{"channel":"book","type":"update","data":[{"symbol":"ETH/GBP","bids":[{"price":2976.61,"qty":0.00000000},{"price":2972.45,"qty":4.28760000}],"asks":[],"checksum":537800294,"timestamp":"2024-06-01T17:52:31.654473Z"}]}
{"channel":"book","type":"update","data":[{"symbol":"ETH/GBP","bids":[{"price":2976.19,"qty":1.31746510}],"asks":[],"checksum":298545216,"timestamp":"2024-06-01T17:52:31.680700Z"}]}
{"channel":"book","type":"update","data":[{"symbol":"ETH/GBP","bids":[],"asks":[{"price":2980.24,"qty":0.00000000},{"price":2980.25,"qty":18.59824701}],"checksum":2167406697,"timestamp":"2024-06-01T17:52:31.729830Z"}]}
{"channel":"book","type":"update","data":[{"symbol":"ETH/GBP","bids":[],"asks":[{"price":2977.96,"qty":13.17255812}],"checksum":1600280760,"timestamp":"2024-06-01T17:52:31.746061Z"}]}
{"channel":"book","type":"update","data":[{"symbol":"ETH/GBP","bids":[],"asks":[{"price":2977.48,"qty":6.58733949}],"checksum":572060825,"timestamp":"2024-06-01T17:52:31.746125Z"}]}
{"channel":"book","type":"update","data":[{"symbol":"ETH/GBP","bids":[],"asks":[{"price":2979.14,"qty":0.00000000},{"price":2980.23,"qty":0.06981300}],"checksum":3125719521,"timestamp":"2024-06-01T17:52:31.749279Z"}]}
{"channel":"book","type":"update","data":[{"symbol":"ETH/GBP","bids":[],"asks":[{"price":2979.38,"qty":2.94416492}],"checksum":2284888526,"timestamp":"2024-06-01T17:52:31.752033Z"}]}
{"channel":"book","type":"update","data":[{"symbol":"ETH/GBP","bids":[],"asks":[{"price":2977.48,"qty":0.00000000},{"price":2980.23,"qty":0.06981300}],"checksum":224833543,"timestamp":"2024-06-01T17:52:31.752357Z"}]}
{"channel":"book","type":"update","data":[{"symbol":"ETH/GBP","bids":[{"price":2976.95,"qty":6.58849494}],"asks":[],"checksum":2941326796,"timestamp":"2024-06-01T17:52:31.756249Z"}]}
{"channel":"book","type":"update","data":[{"symbol":"ETH/GBP","bids":[{"price":2976.95,"qty":0.00000000},{"price":2972.51,"qty":1.14340000}],"asks":[],"checksum":224833543,"timestamp":"2024-06-01T17:52:31.761878Z"}]}
{"channel":"book","type":"update","data":[{"symbol":"ETH/GBP","bids":[],"asks":[{"price":2979.65,"qty":0.00000000},{"price":2980.25,"qty":18.59824701}],"checksum":3504672996,"timestamp":"2024-06-01T17:52:31.767645Z"}]}
{"channel":"book","type":"update","data":[{"symbol":"ETH/GBP","bids":[],"asks":[{"price":2977.96,"qty":0.00000000},{"price":2980.58,"qty":13.43327015}],"checksum":658712327,"timestamp":"2024-06-01T17:52:31.781962Z"}]}
{"channel":"book","type":"update","data":[{"symbol":"ETH/GBP","bids":[],"asks":[{"price":2979.38,"qty":0.00000000},{"price":2980.94,"qty":0.20717085}],"checksum":3742405109,"timestamp":"2024-06-01T17:52:31.785646Z"}]}
{"channel":"book","type":"update","data":[{"symbol":"ETH/GBP","bids":[],"asks":[{"price":2979.82,"qty":2.94416492}],"checksum":2118008771,"timestamp":"2024-06-01T17:52:31.788570Z"}]}
{"channel":"book","type":"update","data":[{"symbol":"ETH/GBP","bids":[{"price":2975.63,"qty":1.31828319}],"asks":[],"checksum":605467624,"timestamp":"2024-06-01T17:52:31.793163Z"}]}
{"channel":"book","type":"update","data":[{"symbol":"ETH/GBP","bids":[],"asks":[{"price":2978.90,"qty":1.31684121}],"checksum":3053415293,"timestamp":"2024-06-01T17:52:31.793321Z"}]}
{"channel":"book","type":"update","data":[{"symbol":"ETH/GBP","bids":[],"asks":[{"price":2978.87,"qty":1.31735742}],"checksum":3507018746,"timestamp":"2024-06-01T17:52:31.796585Z"}]}
{"channel":"book","type":"update","data":[{"symbol":"ETH/GBP","bids":[{"price":2976.21,"qty":13.18024960}],"asks":[],"checksum":3296696900,"timestamp":"2024-06-01T17:52:31.798057Z"}]}
{"channel":"book","type":"update","data":[{"symbol":"ETH/GBP","bids":[],"asks":[{"price":2978.92,"qty":0.00000000},{"price":2980.25,"qty":18.59824701}],"checksum":2273263606,"timestamp":"2024-06-01T17:52:31.798411Z"}]}
{"channel":"book","type":"update","data":[{"symbol":"ETH/GBP","bids":[{"price":2976.24,"qty":1.31733582}],"asks":[],"checksum":3543185707,"timestamp":"2024-06-01T17:52:31.801372Z"}]}
{"channel":"book","type":"update","data":[{"symbol":"ETH/GBP","bids":[{"price":2976.19,"qty":0.00000000},{"price":2973.18,"qty":0.27800000}],"asks":[],"checksum":3104340504,"timestamp":"2024-06-01T17:52:31.801968Z"}]}
{"channel":"book","type":"update","data":[{"symbol":"ETH/GBP","bids":[{"price":2976.21,"qty":0.00000000},{"price":2972.52,"qty":0.14116947}],"asks":[],"checksum":1095517665,"timestamp":"2024-06-01T17:52:31.803072Z"}]}
{"channel":"book","type":"update","data":[{"symbol":"ETH/GBP","bids":[{"price":2974.53,"qty":0.00000000},{"price":2972.51,"qty":1.14340000},{"price":2974.46,"qty":1.34000000}],"asks":[],"checksum":679186117,"timestamp":"2024-06-01T17:52:31.819460Z"}]}
{"channel":"book","type":"update","data":[{"symbol":"ETH/GBP","bids":[{"price":2975.63,"qty":0.00000000},{"price":2972.51,"qty":1.14340000}],"asks":[],"checksum":1541278759,"timestamp":"2024-06-01T17:52:31.846389Z"}]}
{"channel":"book","type":"update","data":[{"symbol":"ETH/GBP","bids":[],"asks":[{"price":2977.73,"qty":6.58677786}],"checksum":2254452700,"timestamp":"2024-06-01T17:52:31.851436Z"}]}
{"channel":"book","type":"update","data":[{"symbol":"ETH/GBP","bids":[],"asks":[{"price":2977.73,"qty":0.00000000},{"price":2980.25,"qty":18.59824701}],"checksum":1541278759,"timestamp":"2024-06-01T17:52:31.855768Z"}]}
{"channel":"book","type":"update","data":[{"symbol":"ETH/GBP","bids":[{"price":2977.18,"qty":6.58797749}],"asks":[],"checksum":2543460586,"timestamp":"2024-06-01T17:52:31.859042Z"}]}
{"channel":"book","type":"update","data":[{"symbol":"ETH/GBP","bids":[],"asks":[{"price":2980.21,"qty":1.00000000}],"checksum":2475775232,"timestamp":"2024-06-01T17:52:31.869161Z"}]}
{"channel":"book","type":"update","data":[{"symbol":"ETH/GBP","bids":[{"price":2977.18,"qty":0.00000000},{"price":2972.51,"qty":1.14340000}],"asks":[],"checksum":1607825869,"timestamp":"2024-06-01T17:52:31.894122Z"}]}
{"channel":"book","type":"update","data":[{"symbol":"ETH/GBP","bids":[{"price":2974.30,"qty":0.30200000}],"asks":[],"checksum":2188067858,"timestamp":"2024-06-01T17:52:31.901260Z"}]}
{"channel":"book","type":"update","data":[{"symbol":"ETH/GBP","bids":[],"asks":[{"price":2978.21,"qty":13.17144163}],"checksum":587892661,"timestamp":"2024-06-01T17:52:31.946402Z"}]}
{"channel":"book","type":"update","data":[{"symbol":"ETH/GBP","bids":[],"asks":[{"price":2978.21,"qty":0.00000000},{"price":2980.23,"qty":0.06981300}],"checksum":2188067858,"timestamp":"2024-06-01T17:52:31.951275Z"}]}
{"channel":"book","type":"update","data":[{"symbol":"ETH/GBP","bids":[],"asks":[{"price":2977.75,"qty":6.58675349}],"checksum":974856877,"timestamp":"2024-06-01T17:52:31.955837Z"}]}
{"channel":"book","type":"update","data":[{"symbol":"ETH/GBP","bids":[{"price":2977.21,"qty":6.58791028}],"asks":[],"checksum":1153350279,"timestamp":"2024-06-01T17:52:31.960397Z"}]}
{"channel":"book","type":"update","data":[{"symbol":"ETH/GBP","bids":[{"price":2973.20,"qty":0.00000000},{"price":2972.52,"qty":0.14116947},{"price":2972.52,"qty":0.48626947}],"asks":[],"checksum":3968383729,"timestamp":"2024-06-01T17:52:31.969046Z"}]}
{"channel":"book","type":"update","data":[{"symbol":"ETH/GBP","bids":[{"price":2977.21,"qty":0.00000000},{"price":2972.51,"qty":1.14340000}],"asks":[],"checksum":1390541862,"timestamp":"2024-06-01T17:52:31.969847Z"}]}
{"channel":"book","type":"update","data":[{"symbol":"ETH/GBP","bids":[],"asks":[{"price":2980.05,"qty":0.00000000},{"price":2980.23,"qty":0.06981300}],"checksum":1609556928,"timestamp":"2024-06-01T17:52:31.980652Z"}]}
{"channel":"book","type":"update","data":[{"symbol":"ETH/GBP","bids":[{"price":2976.20,"qty":1.04098877}],"asks":[],"checksum":1305895201,"timestamp":"2024-06-01T17:52:31.997234Z"}]}
{"channel":"book","type":"update","data":[{"symbol":"ETH/GBP","bids":[{"price":2972.53,"qty":11.29832356}],"asks":[],"checksum":3320396325,"timestamp":"2024-06-01T17:52:31.997392Z"}]}
{"channel":"book","type":"update","data":[{"symbol":"ETH/GBP","bids":[],"asks":[{"price":2977.75,"qty":0.00000000},{"price":2980.25,"qty":18.59824701}],"checksum":4240524827,"timestamp":"2024-06-01T17:52:31.998939Z"}]}
{"channel":"book","type":"update","data":[{"symbol":"ETH/GBP","bids":[{"price":2976.25,"qty":13.18008220}],"asks":[],"checksum":3395907022,"timestamp":"2024-06-01T17:52:32.004297Z"}]}
{"channel":"book","type":"update","data":[{"symbol":"ETH/GBP","bids":[{"price":2976.28,"qty":1.31727479}],"asks":[],"checksum":426934119,"timestamp":"2024-06-01T17:52:32.007832Z"}]}
{"channel":"book","type":"update","data":[{"symbol":"ETH/GBP","bids":[{"price":2976.25,"qty":0.00000000},{"price":2973.18,"qty":0.27800000}],"asks":[],"checksum":1786392083,"timestamp":"2024-06-01T17:52:32.008797Z"}]}
{"channel":"book","type":"update","data":[{"symbol":"ETH/GBP","bids":[{"price":2976.24,"qty":0.00000000},{"price":2972.53,"qty":11.29832356}],"asks":[],"checksum":3878810883,"timestamp":"2024-06-01T17:52:32.010828Z"}]}
{"channel":"book","type":"update","data":[{"symbol":"ETH/GBP","bids":[{"price":2973.19,"qty":0.14113766}],"asks":[],"checksum":1154562304,"timestamp":"2024-06-01T17:52:32.011726Z"}]}
{"channel":"book","type":"update","data":[{"symbol":"ETH/GBP","bids":[],"asks":[{"price":2978.90,"qty":0.00000000},{"price":2980.58,"qty":13.43327015}],"checksum":2096306147,"timestamp":"2024-06-01T17:52:32.117466Z"}]}
{"channel":"book","type":"update","data":[{"symbol":"ETH/GBP","bids":[],"asks":[{"price":2980.23,"qty":0.00000000},{"price":2980.89,"qty":1.34000000},{"price":2978.89,"qty":0.06949500}],"checksum":1387556572,"timestamp":"2024-06-01T17:52:32.121571Z"}]}
{"channel":"book","type":"update","data":[{"symbol":"ETH/GBP","bids":[{"price":2977.31,"qty":6.58769156}],"asks":[],"checksum":1859894145,"timestamp":"2024-06-01T17:52:32.121643Z"}]}
{"channel":"book","type":"update","data":[{"symbol":"ETH/GBP","bids":[],"asks":[{"price":2977.85,"qty":6.58652110}],"checksum":1557836709,"timestamp":"2024-06-01T17:52:32.121751Z"}]}
{"channel":"book","type":"update","data":[{"symbol":"ETH/GBP","bids":[{"price":2977.31,"qty":0.00000000},{"price":2973.18,"qty":0.27800000}],"asks":[],"checksum":2345708016,"timestamp":"2024-06-01T17:52:32.138192Z"}]}
{"channel":"book","type":"update","data":[{"symbol":"ETH/GBP","bids":[],"asks":[{"price":2977.85,"qty":0.00000000},{"price":2980.58,"qty":13.43327015}],"checksum":1387556572,"timestamp":"2024-06-01T17:52:32.138232Z"}]}
{"channel":"book","type":"update","data":[{"symbol":"ETH/GBP","bids":[],"asks":[{"price":2978.85,"qty":13.16862701}],"checksum":2452747434,"timestamp":"2024-06-01T17:52:32.149117Z"}]}
{"channel":"book","type":"update","data":[{"symbol":"ETH/GBP","bids":[],"asks":[{"price":2978.85,"qty":0.00000000},{"price":2980.58,"qty":13.43327015}],"checksum":1387556572,"timestamp":"2024-06-01T17:52:32.154782Z"}]}
{"channel":"book","type":"update","data":[{"symbol":"ETH/GBP","bids":[{"price":2976.30,"qty":13.17985724}],"asks":[],"checksum":3690084965,"timestamp":"2024-06-01T17:52:32.205405Z"}]}
{"channel":"book","type":"update","data":[{"symbol":"ETH/GBP","bids":[{"price":2976.33,"qty":1.31729489}],"asks":[],"checksum":3963381886,"timestamp":"2024-06-01T17:52:32.208846Z"}]}
{"channel":"book","type":"update","data":[{"symbol":"ETH/GBP","bids":[{"price":2976.30,"qty":0.00000000},{"price":2973.19,"qty":0.14113766}],"asks":[],"checksum":3031301242,"timestamp":"2024-06-01T17:52:32.210586Z"}]}
{"channel":"book","type":"update","data":[{"symbol":"ETH/GBP","bids":[{"price":2976.28,"qty":0.00000000},{"price":2973.18,"qty":0.27800000}],"asks":[],"checksum":3937032240,"timestamp":"2024-06-01T17:52:32.211690Z"}]}
{"channel":"book","type":"update","data":[{"symbol":"ETH/GBP","bids":[],"asks":[{"price":2980.39,"qty":0.27478155}],"checksum":572964443,"timestamp":"2024-06-01T17:52:32.279383Z"}]}
{"channel":"book","type":"update","data":[{"symbol":"ETH/GBP","bids":[{"price":2977.31,"qty":6.58769511}],"asks":[],"checksum":88957587,"timestamp":"2024-06-01T17:52:32.283982Z"}]}
{"channel":"book","type":"update","data":[{"symbol":"ETH/GBP","bids":[],"asks":[{"price":2977.76,"qty":6.58672791}],"checksum":3484279270,"timestamp":"2024-06-01T17:52:32.284030Z"}]}
{"channel":"book","type":"update","data":[{"symbol":"ETH/GBP","bids":[{"price":2977.31,"qty":0.00000000},{"price":2973.18,"qty":0.27800000}],"asks":[],"checksum":2020032938,"timestamp":"2024-06-01T17:52:32.289228Z"}]}
{"channel":"book","type":"update","data":[{"symbol":"ETH/GBP","bids":[],"asks":[{"price":2977.76,"qty":0.00000000},{"price":2980.39,"qty":0.27478155}],"checksum":572964443,"timestamp":"2024-06-01T17:52:32.347868Z"}]}
{"channel":"book","type":"update","data":[{"symbol":"ETH/GBP","bids":[],"asks":[{"price":2978.85,"qty":13.16862480}],"checksum":2874789175,"timestamp":"2024-06-01T17:52:32.352916Z"}]}
{"channel":"book","type":"update","data":[{"symbol":"ETH/GBP","bids":[],"asks":[{"price":2978.85,"qty":0.00000000},{"price":2980.39,"qty":0.27478155}],"checksum":572964443,"timestamp":"2024-06-01T17:52:32.357886Z"}]}
{"channel":"book","type":"update","data":[{"symbol":"ETH/GBP","bids":[],"asks":[{"price":2977.77,"qty":6.58669958}],"checksum":4057567469,"timestamp":"2024-06-01T17:52:32.395555Z"}]}
{"channel":"book","type":"update","data":[{"symbol":"ETH/GBP","bids":[{"price":2977.33,"qty":6.58765095}],"asks":[],"checksum":2015301313,"timestamp":"2024-06-01T17:52:32.395757Z"}]}
{"channel":"book","type":"update","data":[{"symbol":"ETH/GBP","bids":[],"asks":[{"price":2977.77,"qty":0.00000000},{"price":2980.39,"qty":0.27478155}],"checksum":1523509078,"timestamp":"2024-06-01T17:52:32.594201Z"}]}
{"channel":"book","type":"update","data":[{"symbol":"ETH/GBP","bids":[],"asks":[{"price":2977.76,"qty":6.58672396}],"checksum":809722562,"timestamp":"2024-06-01T17:52:32.598999Z"}]}
{"channel":"book","type":"update","data":[{"symbol":"ETH/GBP","bids":[{"price":2976.85,"qty":13.17742321}],"asks":[],"checksum":1836558181,"timestamp":"2024-06-01T17:52:32.599064Z"}]}
{"channel":"book","type":"update","data":[{"symbol":"ETH/GBP","bids":[],"asks":[{"price":2978.25,"qty":13.17127851}],"checksum":2735634435,"timestamp":"2024-06-01T17:52:32.599144Z"}]}
{"channel":"book","type":"update","data":[{"symbol":"ETH/GBP","bids":[],"asks":[{"price":2978.25,"qty":0.00000000},{"price":2980.25,"qty":18.59824701}],"checksum":1836558181,"timestamp":"2024-06-01T17:52:32.603091Z"}]}
{"channel":"book","type":"update","data":[{"symbol":"ETH/GBP","bids":[{"price":2977.33,"qty":0.00000000},{"price":2973.19,"qty":0.14113766}],"asks":[],"checksum":2817452493,"timestamp":"2024-06-01T17:52:32.625086Z"}]}
{"channel":"book","type":"update","data":[{"symbol":"ETH/GBP","bids":[],"asks":[{"price":2977.76,"qty":0.00000000},{"price":2980.39,"qty":0.27478155}],"checksum":1357263637,"timestamp":"2024-06-01T17:52:32.625150Z"}]}
{"channel":"book","type":"update","data":[{"symbol":"ETH/GBP","bids":[{"price":2977.29,"qty":6.58773331}],"asks":[],"checksum":3841140256,"timestamp":"2024-06-01T17:52:32.630668Z"}]}
{"channel":"book","type":"update","data":[{"symbol":"ETH/GBP","bids":[{"price":2977.29,"qty":0.00000000},{"price":2973.19,"qty":0.14113766}],"asks":[],"checksum":1357263637,"timestamp":"2024-06-01T17:52:32.715349Z"}]}
{"channel":"book","type":"update","data":[{"symbol":"ETH/GBP","bids":[],"asks":[{"price":2978.86,"qty":6.58429118}],"checksum":3426870831,"timestamp":"2024-06-01T17:52:32.720601Z"}]}
{"channel":"book","type":"update","data":[{"symbol":"ETH/GBP","bids":[],"asks":[{"price":2978.86,"qty":0.00000000},{"price":2980.39,"qty":0.27478155}],"checksum":1357263637,"timestamp":"2024-06-01T17:52:32.725042Z"}]}
{"channel":"book","type":"update","data":[{"symbol":"ETH/GBP","bids":[{"price":2974.52,"qty":0.00000000},{"price":2973.18,"qty":0.27800000},{"price":2977.34,"qty":0.08559700}],"asks":[],"checksum":2726170845,"timestamp":"2024-06-01T17:52:32.768336Z"}]}
{"channel":"book","type":"update","data":[{"symbol":"ETH/GBP","bids":[],"asks":[{"price":2978.84,"qty":13.16864558}],"checksum":245822219,"timestamp":"2024-06-01T17:52:32.861375Z"}]}
{"channel":"book","type":"update","data":[{"symbol":"ETH/GBP","bids":[{"price":2977.31,"qty":6.58769180}],"asks":[],"checksum":1062806748,"timestamp":"2024-06-01T17:52:32.861392Z"}]}
{"channel":"book","type":"update","data":[{"symbol":"ETH/GBP","bids":[{"price":2975.87,"qty":1.31817568}],"asks":[],"checksum":1448339223,"timestamp":"2024-06-01T17:52:32.861447Z"}]}
{"channel":"book","type":"update","data":[{"symbol":"ETH/GBP","bids":[],"asks":[{"price":2977.74,"qty":6.58676282}],"checksum":4188458305,"timestamp":"2024-06-01T17:52:32.861475Z"}]}
{"channel":"book","type":"update","data":[{"symbol":"ETH/GBP","bids":[{"price":2974.89,"qty":1.31861080}],"asks":[],"checksum":3213200807,"timestamp":"2024-06-01T17:52:32.861499Z"}]}
{"channel":"book","type":"update","data":[{"symbol":"ETH/GBP","bids":[],"asks":[{"price":2979.14,"qty":1.31673300}],"checksum":120198581,"timestamp":"2024-06-01T17:52:32.861513Z"}]}
{"channel":"book","type":"update","data":[{"symbol":"ETH/GBP","bids":[],"asks":[{"price":2978.84,"qty":0.00000000},{"price":2980.21,"qty":1.00000000}],"checksum":3121820001,"timestamp":"2024-06-01T17:52:32.867770Z"}]}
{"channel":"book","type":"update","data":[{"symbol":"ETH/GBP","bids":[{"price":2974.46,"qty":0.00000000},{"price":2974.30,"qty":0.30200000},{"price":2974.90,"qty":1.34000000}],"asks":[],"checksum":1413293375,"timestamp":"2024-06-01T17:52:32.870588Z"}]}
{"channel":"book","type":"update","data":[{"symbol":"ETH/GBP","bids":[{"price":2977.31,"qty":0.00000000},{"price":2974.30,"qty":0.30200000}],"asks":[],"checksum":178254049,"timestamp":"2024-06-01T17:52:32.903256Z"}]}
{"channel":"book","type":"update","data":[{"symbol":"ETH/GBP","bids":[],"asks":[{"price":2977.74,"qty":0.00000000},{"price":2980.25,"qty":18.59824701}],"checksum":2906334118,"timestamp":"2024-06-01T17:52:32.903474Z"}]}
{"channel":"book","type":"update","data":[{"symbol":"ETH/GBP","bids":[{"price":2977.34,"qty":0.00000000},{"price":2973.93,"qty":0.27474654},{"price":2976.86,"qty":0.08561500}],"asks":[],"checksum":785260345,"timestamp":"2024-06-01T17:52:32.941471Z"}]}
{"channel":"book","type":"update","data":[{"symbol":"ETH/GBP","bids":[],"asks":[{"price":2977.74,"qty":6.58677468}],"checksum":2219552915,"timestamp":"2024-06-01T17:52:32.966463Z"}]}
{"channel":"book","type":"update","data":[{"symbol":"ETH/GBP","bids":[{"price":2977.30,"qty":6.58772606}],"asks":[],"checksum":904107273,"timestamp":"2024-06-01T17:52:32.966516Z"}]}
{"channel":"book","type":"update","data":[{"symbol":"ETH/GBP","bids":[],"asks":[{"price":2977.74,"qty":0.00000000},{"price":2980.25,"qty":18.59824701}],"checksum":55204432,"timestamp":"2024-06-01T17:52:33.005504Z"}]}
{"channel":"book","type":"update","data":[{"symbol":"ETH/GBP","bids":[{"price":2976.85,"qty":0.00000000},{"price":2974.30,"qty":0.30200000}],"asks":[],"checksum":785503315,"timestamp":"2024-06-01T17:52:33.005525Z"}]}
{"channel":"book","type":"update","data":[{"symbol":"ETH/GBP","bids":[{"price":2977.30,"qty":0.00000000},{"price":2973.93,"qty":0.27474654}],"asks":[],"checksum":3086275362,"timestamp":"2024-06-01T17:52:33.005635Z"}]}
{"channel":"book","type":"update","data":[{"symbol":"ETH/GBP","bids":[{"price":2976.78,"qty":13.17772106}],"asks":[],"checksum":2677729972,"timestamp":"2024-06-01T17:52:33.010532Z"}]}
{"channel":"book","type":"update","data":[{"symbol":"ETH/GBP","bids":[],"asks":[{"price":2978.85,"qty":13.16860137}],"checksum":840618211,"timestamp":"2024-06-01T17:52:33.117812Z"}]}
{"channel":"book","type":"update","data":[{"symbol":"ETH/GBP","bids":[],"asks":[{"price":2978.85,"qty":19.75290205}],"checksum":2727541137,"timestamp":"2024-06-01T17:52:33.117892Z"}]}
{"channel":"book","type":"update","data":[{"symbol":"ETH/GBP","bids":[{"price":2977.29,"qty":6.58773133}],"asks":[],"checksum":2643983859,"timestamp":"2024-06-01T17:52:33.117970Z"}]}
{"channel":"book","type":"update","data":[{"symbol":"ETH/GBP","bids":[],"asks":[{"price":2978.85,"qty":6.58430068}],"checksum":1366527817,"timestamp":"2024-06-01T17:52:33.122921Z"}]}
{"channel":"book","type":"update","data":[{"symbol":"ETH/GBP","bids":[],"asks":[{"price":2978.85,"qty":0.00000000},{"price":2980.25,"qty":18.59824701}],"checksum":3601736103,"timestamp":"2024-06-01T17:52:33.123039Z"}]}
{"channel":"book","type":"update","data":[{"symbol":"ETH/GBP","bids":[{"price":2977.29,"qty":0.00000000},{"price":2974.30,"qty":0.30200000}],"asks":[],"checksum":2677729972,"timestamp":"2024-06-01T17:52:33.171041Z"}]}
{"channel":"book","type":"update","data":[{"symbol":"ETH/GBP","bids":[{"price":2976.78,"qty":0.00000000},{"price":2973.93,"qty":0.27474654}],"asks":[],"checksum":3086275362,"timestamp":"2024-06-01T17:52:33.191880Z"}]}
{"channel":"book","type":"update","data":[{"symbol":"ETH/GBP","bids":[],"asks":[{"price":2977.63,"qty":6.58700618}],"checksum":536412875,"timestamp":"2024-06-01T17:52:33.248617Z"}]}
{"channel":"book","type":"update","data":[{"symbol":"ETH/GBP","bids":[{"price":2976.84,"qty":13.17745971}],"asks":[],"checksum":3013004325,"timestamp":"2024-06-01T17:52:33.248677Z"}]}
{"channel":"book","type":"update","data":[{"symbol":"ETH/GBP","bids":[{"price":2976.88,"qty":6.58865751}],"asks":[],"checksum":4057798251,"timestamp":"2024-06-01T17:52:33.248839Z"}]}
{"channel":"book","type":"update","data":[{"symbol":"ETH/GBP","bids":[],"asks":[{"price":2977.63,"qty":0.00000000},{"price":2980.25,"qty":18.59824701}],"checksum":2977723663,"timestamp":"2024-06-01T17:52:33.253725Z"}]}
{"channel":"book","type":"update","data":[{"symbol":"ETH/GBP","bids":[{"price":2976.88,"qty":0.00000000},{"price":2974.30,"qty":0.30200000}],"asks":[],"checksum":3456028367,"timestamp":"2024-06-01T17:52:33.253830Z"}]}
{"channel":"book","type":"update","data":[{"symbol":"ETH/GBP","bids":[],"asks":[{"price":2978.85,"qty":6.58430068}],"checksum":418640478,"timestamp":"2024-06-01T17:52:33.425112Z"}]}
{"channel":"book","type":"update","data":[{"symbol":"ETH/GBP","bids":[{"price":2977.33,"qty":6.58765339}],"asks":[],"checksum":1956175078,"timestamp":"2024-06-01T17:52:33.425159Z"}]}
{"channel":"book","type":"update","data":[{"symbol":"ETH/GBP","bids":[],"asks":[{"price":2978.85,"qty":19.75290205}],"checksum":3095178844,"timestamp":"2024-06-01T17:52:33.425383Z"}]}
{"channel":"book","type":"update","data":[{"symbol":"ETH/GBP","bids":[],"asks":[{"price":2978.85,"qty":13.16860137}],"checksum":115816037,"timestamp":"2024-06-01T17:52:33.430646Z"}]}
{"channel":"book","type":"update","data":[{"symbol":"ETH/GBP","bids":[],"asks":[{"price":2978.85,"qty":0.00000000},{"price":2980.25,"qty":18.59824701}],"checksum":4081414664,"timestamp":"2024-06-01T17:52:33.430900Z"}]}
{"channel":"book","type":"update","data":[{"symbol":"ETH/GBP","bids":[],"asks":[{"price":2977.67,"qty":6.58692779}],"checksum":4250402578,"timestamp":"2024-06-01T17:52:33.568501Z"}]}
{"channel":"book","type":"update","data":[{"symbol":"ETH/GBP","bids":[{"price":2977.33,"qty":0.00000000},{"price":2974.30,"qty":0.30200000}],"asks":[],"checksum":83617479,"timestamp":"2024-06-01T17:52:33.606877Z"}]}
{"channel":"book","type":"update","data":[{"symbol":"ETH/GBP","bids":[{"price":2977.34,"qty":6.58762571}],"asks":[],"checksum":3855457877,"timestamp":"2024-06-01T17:52:33.611172Z"}]}
{"channel":"book","type":"update","data":[{"symbol":"ETH/GBP","bids":[],"asks":[{"price":2977.67,"qty":0.00000000},{"price":2980.25,"qty":18.59824701}],"checksum":3957265231,"timestamp":"2024-06-01T17:52:33.689651Z"}]}
{"channel":"book","type":"update","data":[{"symbol":"ETH/GBP","bids":[],"asks":[{"price":2977.66,"qty":6.58695348}],"checksum":3581303154,"timestamp":"2024-06-01T17:52:33.694683Z"}]}
{"channel":"book","type":"update","data":[{"symbol":"ETH/GBP","bids":[],"asks":[{"price":2978.86,"qty":13.16858015}],"checksum":2516143330,"timestamp":"2024-06-01T17:52:33.695056Z"}]}
{"channel":"book","type":"update","data":[{"symbol":"ETH/GBP","bids":[],"asks":[{"price":2978.86,"qty":0.00000000},{"price":2980.21,"qty":1.00000000}],"checksum":3581303154,"timestamp":"2024-06-01T17:52:33.702518Z"}]}
{"channel":"book","type":"update","data":[{"symbol":"ETH/GBP","bids":[],"asks":[{"price":2977.66,"qty":0.00000000},{"price":2980.25,"qty":18.59824701}],"checksum":3957265231,"timestamp":"2024-06-01T17:52:33.738945Z"}]}
{"channel":"book","type":"update","data":[{"symbol":"ETH/GBP","bids":[{"price":2977.34,"qty":0.00000000},{"price":2974.30,"qty":0.30200000}],"asks":[],"checksum":3456028367,"timestamp":"2024-06-01T17:52:33.739015Z"}]}
{"channel":"book","type":"update","data":[{"symbol":"ETH/GBP","bids":[{"price":2977.32,"qty":6.58767711}],"asks":[],"checksum":3528880081,"timestamp":"2024-06-01T17:52:33.744861Z"}]}
{"channel":"book","type":"update","data":[{"symbol":"ETH/GBP","bids":[],"asks":[{"price":2978.85,"qty":13.16860137}],"checksum":670313404,"timestamp":"2024-06-01T17:52:33.948739Z"}]}
{"channel":"book","type":"update","data":[{"symbol":"ETH/GBP","bids":[],"asks":[{"price":2978.86,"qty":6.58429051}],"checksum":3446271426,"timestamp":"2024-06-01T17:52:33.948845Z"}]}
{"channel":"book","type":"update","data":[{"symbol":"ETH/GBP","bids":[],"asks":[{"price":2978.85,"qty":0.00000000},{"price":2980.09,"qty":1.31631591}],"checksum":3597449531,"timestamp":"2024-06-01T17:52:33.953880Z"}]}
{"channel":"book","type":"update","data":[{"symbol":"ETH/GBP","bids":[],"asks":[{"price":2978.86,"qty":0.00000000},{"price":2980.21,"qty":1.00000000}],"checksum":2028731017,"timestamp":"2024-06-01T17:52:33.954011Z"}]}
{"channel":"book","type":"update","data":[{"symbol":"ETH/GBP","bids":[],"asks":[{"price":2979.23,"qty":0.00000000},{"price":2980.25,"qty":18.59824701}],"checksum":629410678,"timestamp":"2024-06-01T17:52:34.139061Z"}]}
{"channel":"book","type":"update","data":[{"symbol":"ETH/GBP","bids":[],"asks":[{"price":2980.25,"qty":0.00000000},{"price":2980.39,"qty":0.27478155}],"checksum":2844575547,"timestamp":"2024-06-01T17:52:34.139328Z"}]}
{"channel":"book","type":"update","data":[{"symbol":"ETH/GBP","bids":[],"asks":[{"price":2978.86,"qty":5.72861187}],"checksum":4160590233,"timestamp":"2024-06-01T17:52:34.143990Z"}]}
{"channel":"book","type":"update","data":[{"symbol":"ETH/GBP","bids":[{"price":2977.32,"qty":0.00000000},{"price":2974.30,"qty":0.30200000}],"asks":[],"checksum":164767357,"timestamp":"2024-06-01T17:52:34.174539Z"}]}
{"channel":"book","type":"update","data":[{"symbol":"ETH/GBP","bids":[],"asks":[{"price":2978.15,"qty":13.17173422}],"checksum":3905716980,"timestamp":"2024-06-01T17:52:34.179536Z"}]}
{"channel":"book","type":"update","data":[{"symbol":"ETH/GBP","bids":[{"price":2977.34,"qty":6.58763924}],"asks":[],"checksum":3282225074,"timestamp":"2024-06-01T17:52:34.179748Z"}]}
{"channel":"book","type":"update","data":[{"symbol":"ETH/GBP","bids":[],"asks":[{"price":2977.67,"qty":6.58692747}],"checksum":1643468070,"timestamp":"2024-06-01T17:52:34.179833Z"}]}
{"channel":"book","type":"update","data":[{"symbol":"ETH/GBP","bids":[],"asks":[{"price":2977.67,"qty":0.00000000},{"price":2980.09,"qty":1.31631591}],"checksum":3282225074,"timestamp":"2024-06-01T17:52:34.203174Z"}]}
{"channel":"book","type":"update","data":[{"symbol":"ETH/GBP","bids":[],"asks":[{"price":2978.15,"qty":0.00000000},{"price":2980.21,"qty":1.00000000}],"checksum":1462231698,"timestamp":"2024-06-01T17:52:34.207844Z"}]}
{"channel":"book","type":"update","data":[{"symbol":"ETH/GBP","bids":[],"asks":[{"price":2979.14,"qty":0.00000000},{"price":2980.39,"qty":0.27478155}],"checksum":19749880,"timestamp":"2024-06-01T17:52:34.240577Z"}]}
{"channel":"book","type":"update","data":[{"symbol":"ETH/GBP","bids":[],"asks":[{"price":2978.90,"qty":1.31684223}],"checksum":3544828574,"timestamp":"2024-06-01T17:52:34.246195Z"}]}
{"channel":"book","type":"update","data":[{"symbol":"ETH/GBP","bids":[],"asks":[{"price":2979.64,"qty":1.31651506}],"checksum":2031461580,"timestamp":"2024-06-01T17:52:34.246210Z"}]}
{"channel":"book","type":"update","data":[{"symbol":"ETH/GBP","bids":[{"price":2977.34,"qty":0.00000000},{"price":2974.30,"qty":0.30200000}],"asks":[],"checksum":2409232640,"timestamp":"2024-06-01T17:52:34.305723Z"}]}
{"channel":"book","type":"update","data":[{"symbol":"ETH/GBP","bids":[],"asks":[{"price":2977.58,"qty":6.58711557}],"checksum":1747873009,"timestamp":"2024-06-01T17:52:34.310260Z"}]}
{"channel":"book","type":"update","data":[{"symbol":"ETH/GBP","bids":[{"price":2977.32,"qty":6.58768076}],"asks":[],"checksum":929503595,"timestamp":"2024-06-01T17:52:34.310274Z"}]}
{"channel":"book","type":"update","data":[{"symbol":"ETH/GBP","bids":[{"price":2974.89,"qty":0.00000000},{"price":2974.30,"qty":0.30200000}],"asks":[],"checksum":1257044555,"timestamp":"2024-06-01T17:52:34.355533Z"}]}
{"channel":"book","type":"update","data":[{"symbol":"ETH/GBP","bids":[{"price":2974.90,"qty":0.00000000},{"price":2973.93,"qty":0.27474654},{"price":2974.46,"qty":1.34000000}],"asks":[],"checksum":857576859,"timestamp":"2024-06-01T17:52:34.358678Z"}]}
{"channel":"book","type":"update","data":[{"symbol":"ETH/GBP","bids":[],"asks":[{"price":2977.58,"qty":0.00000000},{"price":2980.09,"qty":1.31631591}],"checksum":3567911018,"timestamp":"2024-06-01T17:52:34.378032Z"}]}
{"channel":"book","type":"update","data":[{"symbol":"ETH/GBP","bids":[{"price":2977.32,"qty":0.00000000},{"price":2973.93,"qty":0.27474654}],"asks":[],"checksum":864297072,"timestamp":"2024-06-01T17:52:34.382747Z"}]}
{"channel":"book","type":"update","data":[{"symbol":"ETH/GBP","bids":[],"asks":[{"price":2978.90,"qty":0.00000000},{"price":2980.21,"qty":1.00000000}],"checksum":603867795,"timestamp":"2024-06-01T17:52:34.383610Z"}]}
{"channel":"book","type":"update","data":[{"symbol":"ETH/GBP","bids":[{"price":2976.84,"qty":0.00000000},{"price":2973.19,"qty":0.14113766}],"asks":[],"checksum":3859590800,"timestamp":"2024-06-01T17:52:34.387425Z"}]}
{"channel":"book","type":"update","data":[{"symbol":"ETH/GBP","bids":[],"asks":[{"price":2978.85,"qty":13.16862480}],"checksum":1111916558,"timestamp":"2024-06-01T17:52:34.391307Z"}]}
{"channel":"book","type":"update","data":[{"symbol":"ETH/GBP","bids":[{"price":2976.77,"qty":13.17777526}],"asks":[],"checksum":1004818145,"timestamp":"2024-06-01T17:52:34.391507Z"}]}
{"channel":"book","type":"update","data":[{"symbol":"ETH/GBP","bids":[],"asks":[{"price":2978.85,"qty":0.00000000},{"price":2980.21,"qty":1.00000000}],"checksum":149962992,"timestamp":"2024-06-01T17:52:34.395410Z"}]}
{"channel":"book","type":"update","data":[{"symbol":"ETH/GBP","bids":[{"price":2976.94,"qty":0.31000000}],"asks":[],"checksum":4246422932,"timestamp":"2024-06-01T17:52:34.404566Z"}]}
{"channel":"book","type":"update","data":[{"symbol":"ETH/GBP","bids":[],"asks":[{"price":2979.15,"qty":0.00000000},{"price":2980.39,"qty":0.27478155}],"checksum":771771450,"timestamp":"2024-06-01T17:52:34.404623Z"}]}
{"channel":"book","type":"update","data":[{"symbol":"ETH/GBP","bids":[],"asks":[{"price":2978.78,"qty":0.31000000}],"checksum":1904828580,"timestamp":"2024-06-01T17:52:34.404710Z"}]}
{"channel":"book","type":"update","data":[{"symbol":"ETH/GBP","bids":[],"asks":[{"price":2978.84,"qty":1.31734990}],"checksum":1206390854,"timestamp":"2024-06-01T17:52:34.405386Z"}]}
{"channel":"book","type":"update","data":[{"symbol":"ETH/GBP","bids":[],"asks":[{"price":2978.87,"qty":0.00000000},{"price":2980.21,"qty":1.00000000}],"checksum":3014273898,"timestamp":"2024-06-01T17:52:34.407712Z"}]}
{"channel":"book","type":"update","data":[{"symbol":"ETH/GBP","bids":[],"asks":[{"price":2977.49,"qty":6.58732882}],"checksum":3152206171,"timestamp":"2024-06-01T17:52:34.426902Z"}]}
{"channel":"book","type":"update","data":[{"symbol":"ETH/GBP","bids":[{"price":2976.95,"qty":6.58848422}],"asks":[],"checksum":3080363166,"timestamp":"2024-06-01T17:52:34.427048Z"}]}
{"channel":"book","type":"update","data":[{"symbol":"ETH/GBP","bids":[{"price":2976.94,"qty":0.00000000},{"price":2974.30,"qty":0.30200000}],"asks":[],"checksum":1562716219,"timestamp":"2024-06-01T17:52:34.430025Z"}]}
{"channel":"book","type":"update","data":[{"symbol":"ETH/GBP","bids":[{"price":2977.03,"qty":0.31000000}],"asks":[],"checksum":1627233437,"timestamp":"2024-06-01T17:52:34.430155Z"}]}
{"channel":"book","type":"update","data":[{"symbol":"ETH/GBP","bids":[{"price":2976.95,"qty":0.00000000},{"price":2974.30,"qty":0.30200000}],"asks":[],"checksum":1241113072,"timestamp":"2024-06-01T17:52:34.431907Z"}]}
{"channel":"book","type":"update","data":[{"symbol":"ETH/GBP","bids":[],"asks":[{"price":2977.49,"qty":0.00000000},{"price":2980.21,"qty":1.00000000}],"checksum":1102123969,"timestamp":"2024-06-01T17:52:34.431955Z"}]}
{"channel":"book","type":"update","data":[{"symbol":"ETH/GBP","bids":[],"asks":[{"price":2978.77,"qty":1.31738089}],"checksum":2601998981,"timestamp":"2024-06-01T17:52:34.458134Z"}]}
{"channel":"book","type":"update","data":[{"symbol":"ETH/GBP","bids":[],"asks":[{"price":2978.84,"qty":0.00000000},{"price":2980.21,"qty":1.00000000}],"checksum":3170824809,"timestamp":"2024-06-01T17:52:34.461096Z"}]}
{"channel":"book","type":"update","data":[{"symbol":"ETH/GBP","bids":[{"price":2976.77,"qty":0.00000000},{"price":2973.93,"qty":0.27474654}],"asks":[],"checksum":1961606755,"timestamp":"2024-06-01T17:52:34.506189Z"}]}
{"channel":"book","type":"update","data":[{"symbol":"ETH/GBP","bids":[],"asks":[{"price":2977.43,"qty":6.58744346}],"checksum":267429233,"timestamp":"2024-06-01T17:52:34.528877Z"}]}
{"channel":"book","type":"update","data":[{"symbol":"ETH/GBP","bids":[{"price":2977.17,"qty":6.58801390}],"asks":[],"checksum":1487006775,"timestamp":"2024-06-01T17:52:34.528960Z"}]}
{"channel":"book","type":"update","data":[{"symbol":"ETH/GBP","bids":[{"price":2976.20,"qty":0.00000000},{"price":2973.93,"qty":0.27474654}],"asks":[],"checksum":1496192160,"timestamp":"2024-06-01T17:52:34.540547Z"}]}
{"channel":"book","type":"update","data":[{"symbol":"ETH/GBP","bids":[{"price":2977.17,"qty":0.00000000},{"price":2973.19,"qty":0.14113766}],"asks":[],"checksum":2668352896,"timestamp":"2024-06-01T17:52:34.560333Z"}]}
{"channel":"book","type":"update","data":[{"symbol":"ETH/GBP","bids":[],"asks":[{"price":2977.43,"qty":0.00000000},{"price":2980.21,"qty":1.00000000}],"checksum":893086026,"timestamp":"2024-06-01T17:52:34.597648Z"}]}
{"channel":"book","type":"update","data":[{"symbol":"ETH/GBP","bids":[{"price":2976.70,"qty":13.17807472}],"asks":[],"checksum":1837824538,"timestamp":"2024-06-01T17:52:34.602453Z"}]}
{"channel":"book","type":"update","data":[{"symbol":"ETH/GBP","bids":[],"asks":[{"price":2978.76,"qty":13.16903152}],"checksum":3977100009,"timestamp":"2024-06-01T17:52:34.602556Z"}]}
{"channel":"book","type":"update","data":[{"symbol":"ETH/GBP","bids":[],"asks":[{"price":2978.73,"qty":1.31742037}],"checksum":2891787913,"timestamp":"2024-06-01T17:52:34.605357Z"}]}
{"channel":"book","type":"update","data":[{"symbol":"ETH/GBP","bids":[],"asks":[{"price":2978.76,"qty":0.00000000},{"price":2980.09,"qty":1.31631591}],"checksum":3853004696,"timestamp":"2024-06-01T17:52:34.607278Z"}]}
{"channel":"book","type":"update","data":[{"symbol":"ETH/GBP","bids":[],"asks":[{"price":2978.77,"qty":0.00000000},{"price":2980.21,"qty":1.00000000}],"checksum":4227528397,"timestamp":"2024-06-01T17:52:34.609053Z"}]}
{"channel":"book","type":"update","data":[{"symbol":"ETH/GBP","bids":[],"asks":[{"price":2978.72,"qty":6.58460329}],"checksum":1770707864,"timestamp":"2024-06-01T17:52:34.680145Z"}]}
{"channel":"book","type":"update","data":[{"symbol":"ETH/GBP","bids":[{"price":2977.22,"qty":6.58789991}],"asks":[],"checksum":2765228969,"timestamp":"2024-06-01T17:52:34.680414Z"}]}
{"channel":"book","type":"update","data":[{"symbol":"ETH/GBP","bids":[],"asks":[{"price":2978.72,"qty":0.00000000},{"price":2980.21,"qty":1.00000000}],"checksum":3208765183,"timestamp":"2024-06-01T17:52:34.686156Z"}]}
{"channel":"book","type":"update","data":[{"symbol":"ETH/GBP","bids":[{"price":2976.70,"qty":0.00000000},{"price":2973.93,"qty":0.27474654}],"asks":[],"checksum":3689967085,"timestamp":"2024-06-01T17:52:34.719180Z"}]}
{"channel":"book","type":"update","data":[{"symbol":"ETH/GBP","bids":[{"price":2976.86,"qty":0.00000000},{"price":2973.19,"qty":0.14113766},{"price":2977.18,"qty":0.08561200}],"asks":[],"checksum":1483867507,"timestamp":"2024-06-01T17:52:34.720195Z"}]}
{"channel":"book","type":"update","data":[{"symbol":"ETH/GBP","bids":[{"price":2976.76,"qty":13.17784538}],"asks":[],"checksum":839573130,"timestamp":"2024-06-01T17:52:34.805551Z"}]}
{"channel":"book","type":"update","data":[{"symbol":"ETH/GBP","bids":[],"asks":[{"price":2977.47,"qty":6.58735582}],"checksum":1865004243,"timestamp":"2024-06-01T17:52:34.805576Z"}]}
{"channel":"book","type":"update","data":[{"symbol":"ETH/GBP","bids":[],"asks":[{"price":2978.72,"qty":13.16919819}],"checksum":1971112358,"timestamp":"2024-06-01T17:52:34.805729Z"}]}
{"channel":"book","type":"update","data":[{"symbol":"ETH/GBP","bids":[],"asks":[{"price":2978.72,"qty":0.00000000},{"price":2980.09,"qty":1.31631591}],"checksum":1865004243,"timestamp":"2024-06-01T17:52:34.810353Z"}]}
{"channel":"book","type":"update","data":[{"symbol":"ETH/GBP","bids":[],"asks":[{"price":2977.47,"qty":0.00000000},{"price":2980.21,"qty":1.00000000}],"checksum":839573130,"timestamp":"2024-06-01T17:52:34.869322Z"}]}
{"channel":"book","type":"update","data":[{"symbol":"ETH/GBP","bids":[{"price":2976.76,"qty":0.00000000},{"price":2973.93,"qty":0.27474654}],"asks":[],"checksum":1483867507,"timestamp":"2024-06-01T17:52:34.869350Z"}]}
{"channel":"book","type":"update","data":[{"symbol":"ETH/GBP","bids":[{"price":2977.22,"qty":0.00000000},{"price":2973.19,"qty":0.14113766}],"asks":[],"checksum":1435478687,"timestamp":"2024-06-01T17:52:34.869398Z"}]}
{"channel":"book","type":"update","data":[{"symbol":"ETH/GBP","bids":[{"price":2977.03,"qty":0.00000000},{"price":2973.18,"qty":0.27800000}],"asks":[],"checksum":2847199544,"timestamp":"2024-06-01T17:52:34.872354Z"}]}
{"channel":"book","type":"update","data":[{"symbol":"ETH/GBP","bids":[{"price":2977.15,"qty":6.58805354}],"asks":[],"checksum":1374992367,"timestamp":"2024-06-01T17:52:34.876394Z"}]}
{"channel":"book","type":"update","data":[{"symbol":"ETH/GBP","bids":[{"price":2975.32,"qty":1.31842115}],"asks":[],"checksum":1847178332,"timestamp":"2024-06-01T17:52:34.876422Z"}]}
{"channel":"book","type":"update","data":[{"symbol":"ETH/GBP","bids":[{"price":2977.15,"qty":0.00000000},{"price":2973.19,"qty":0.14113766}],"asks":[],"checksum":3759823804,"timestamp":"2024-06-01T17:52:34.881352Z"}]}
{"channel":"book","type":"update","data":[{"symbol":"ETH/GBP","bids":[],"asks":[{"price":2977.43,"qty":6.58744919}],"checksum":1052665926,"timestamp":"2024-06-01T17:52:34.905275Z"}]}
{"channel":"book","type":"update","data":[{"symbol":"ETH/GBP","bids":[],"asks":[{"price":2977.43,"qty":0.00000000},{"price":2980.21,"qty":1.00000000}],"checksum":3759823804,"timestamp":"2024-06-01T17:52:34.909925Z"}]}
{"channel":"book","type":"update","data":[{"symbol":"ETH/GBP","bids":[{"price":2977.20,"qty":6.58793996}],"asks":[],"checksum":3322510478,"timestamp":"2024-06-01T17:52:34.979687Z"}]}
{"channel":"book","type":"update","data":[{"symbol":"ETH/GBP","bids":[],"asks":[{"price":2978.72,"qty":13.16919908}],"checksum":3429027955,"timestamp":"2024-06-01T17:52:35.056224Z"}]}
{"channel":"book","type":"update","data":[{"symbol":"ETH/GBP","bids":[],"asks":[{"price":2977.46,"qty":6.58738980}],"checksum":4053264476,"timestamp":"2024-06-01T17:52:35.056319Z"}]}
{"channel":"book","type":"update","data":[{"symbol":"ETH/GBP","bids":[{"price":2976.74,"qty":13.17793208}],"asks":[],"checksum":2117386592,"timestamp":"2024-06-01T17:52:35.056345Z"}]}
{"channel":"book","type":"update","data":[{"symbol":"ETH/GBP","bids":[],"asks":[{"price":2978.78,"qty":0.00000000},{"price":2980.09,"qty":1.31631591}],"checksum":3132757898,"timestamp":"2024-06-01T17:52:35.058837Z"}]}
{"channel":"book","type":"update","data":[{"symbol":"ETH/GBP","bids":[{"price":2977.22,"qty":0.31000000}],"asks":[],"checksum":687305756,"timestamp":"2024-06-01T17:52:35.059133Z"}]}
{"channel":"book","type":"update","data":[{"symbol":"ETH/GBP","bids":[],"asks":[{"price":2978.69,"qty":1.31741971}],"checksum":312399163,"timestamp":"2024-06-01T17:52:35.059226Z"}]}
{"channel":"book","type":"update","data":[{"symbol":"ETH/GBP","bids":[],"asks":[{"price":2978.73,"qty":0.00000000},{"price":2980.09,"qty":1.31631591}],"checksum":3991669978,"timestamp":"2024-06-01T17:52:35.059267Z"}]}
{"channel":"book","type":"update","data":[{"symbol":"ETH/GBP","bids":[],"asks":[{"price":2978.64,"qty":0.31000000}],"checksum":507063156,"timestamp":"2024-06-01T17:52:35.059318Z"}]}
{"channel":"book","type":"update","data":[{"symbol":"ETH/GBP","bids":[],"asks":[{"price":2978.72,"qty":0.00000000},{"price":2980.09,"qty":1.31631591}],"checksum":2252030026,"timestamp":"2024-06-01T17:52:35.061804Z"}]}
{"channel":"book","type":"update","data":[{"symbol":"ETH/GBP","bids":[{"price":2977.20,"qty":0.00000000},{"price":2974.30,"qty":0.30200000}],"asks":[],"checksum":4168995719,"timestamp":"2024-06-01T17:52:35.209127Z"}]}
{"channel":"book","type":"update","data":[{"symbol":"ETH/GBP","bids":[{"price":2977.21,"qty":6.58791162}],"asks":[],"checksum":905356192,"timestamp":"2024-06-01T17:52:35.213255Z"}]}
{"channel":"book","type":"update","data":[{"symbol":"ETH/GBP","bids":[],"asks":[{"price":2977.46,"qty":0.00000000},{"price":2980.21,"qty":1.00000000}],"checksum":1728227895,"timestamp":"2024-06-01T17:52:35.260648Z"}]}
{"channel":"book","type":"update","data":[{"symbol":"ETH/GBP","bids":[{"price":2977.21,"qty":0.00000000},{"price":2974.30,"qty":0.30200000}],"asks":[],"checksum":1687581236,"timestamp":"2024-06-01T17:52:35.260672Z"}]}
{"channel":"book","type":"update","data":[{"symbol":"ETH/GBP","bids":[],"asks":[{"price":2977.48,"qty":6.58734416}],"checksum":3927806283,"timestamp":"2024-06-01T17:52:35.265324Z"}]}
{"channel":"book","type":"update","data":[{"symbol":"ETH/GBP","bids":[],"asks":[{"price":2978.63,"qty":13.16959212}],"checksum":3698923197,"timestamp":"2024-06-01T17:52:35.265517Z"}]}
{"channel":"book","type":"update","data":[{"symbol":"ETH/GBP","bids":[],"asks":[{"price":2978.72,"qty":1.31691999}],"checksum":1371958694,"timestamp":"2024-06-01T17:52:35.265616Z"}]}
{"channel":"book","type":"update","data":[{"symbol":"ETH/GBP","bids":[],"asks":[{"price":2978.63,"qty":0.00000000},{"price":2979.83,"qty":0.27100000}],"checksum":4130576570,"timestamp":"2024-06-01T17:52:35.269913Z"}]}
{"channel":"book","type":"update","data":[{"symbol":"ETH/GBP","bids":[],"asks":[{"price":2977.48,"qty":0.00000000},{"price":2980.09,"qty":1.31631591}],"checksum":4262757647,"timestamp":"2024-06-01T17:52:35.350147Z"}]}
{"channel":"book","type":"update","data":[{"symbol":"ETH/GBP","bids":[{"price":2977.22,"qty":6.89789647}],"asks":[],"checksum":2162264527,"timestamp":"2024-06-01T17:52:35.355913Z"}]}
{"channel":"book","type":"update","data":[{"symbol":"ETH/GBP","bids":[{"price":2977.22,"qty":0.31000000}],"asks":[],"checksum":4262757647,"timestamp":"2024-06-01T17:52:35.405296Z"}]}
{"channel":"book","type":"update","data":[{"symbol":"ETH/GBP","bids":[],"asks":[{"price":2978.63,"qty":6.58479606}],"checksum":3275765060,"timestamp":"2024-06-01T17:52:35.410428Z"}]}
{"channel":"book","type":"update","data":[{"symbol":"ETH/GBP","bids":[],"asks":[{"price":2978.64,"qty":0.00000000},{"price":2980.09,"qty":1.31631591}],"checksum":789670603,"timestamp":"2024-06-01T17:52:35.412987Z"}]}
{"channel":"book","type":"update","data":[{"symbol":"ETH/GBP","bids":[],"asks":[{"price":2978.55,"qty":0.31000000}],"checksum":538672946,"timestamp":"2024-06-01T17:52:35.413058Z"}]}
{"channel":"book","type":"update","data":[{"symbol":"ETH/GBP","bids":[],"asks":[{"price":2978.63,"qty":0.00000000},{"price":2980.09,"qty":1.31631591}],"checksum":16301562,"timestamp":"2024-06-01T17:52:35.414755Z"}]}
{"channel":"book","type":"update","data":[{"symbol":"ETH/GBP","bids":[],"asks":[{"price":2978.54,"qty":13.16998608}],"checksum":2570103304,"timestamp":"2024-06-01T17:52:35.506636Z"}]}
{"channel":"book","type":"update","data":[{"symbol":"ETH/GBP","bids":[{"price":2977.20,"qty":6.58792855}],"asks":[],"checksum":3191738779,"timestamp":"2024-06-01T17:52:35.506734Z"}]}
{"channel":"book","type":"update","data":[{"symbol":"ETH/GBP","bids":[],"asks":[{"price":2978.54,"qty":0.00000000},{"price":2980.09,"qty":1.31631591}],"checksum":3977530044,"timestamp":"2024-06-01T17:52:35.512115Z"}]}
{"channel":"book","type":"update","data":[{"symbol":"ETH/GBP","bids":[{"price":2977.20,"qty":0.00000000},{"price":2974.30,"qty":0.30200000}],"asks":[],"checksum":16301562,"timestamp":"2024-06-01T17:52:35.515121Z"}]}
{"channel":"book","type":"update","data":[{"symbol":"ETH/GBP","bids":[],"asks":[{"price":2977.46,"qty":6.58738981}],"checksum":610046821,"timestamp":"2024-06-01T17:52:35.519375Z"}]}
{"channel":"book","type":"update","data":[{"symbol":"ETH/GBP","bids":[],"asks":[{"price":2977.46,"qty":0.00000000},{"price":2980.09,"qty":1.31631591}],"checksum":16301562,"timestamp":"2024-06-01T17:52:35.525777Z"}]}
{"channel":"book","type":"update","data":[{"symbol":"ETH/GBP","bids":[],"asks":[{"price":2978.89,"qty":0.00000000},{"price":2980.21,"qty":1.00000000},{"price":2978.54,"qty":0.06970900}],"checksum":643524964,"timestamp":"2024-06-01T17:52:35.586908Z"}]}
{"channel":"book","type":"update","data":[{"symbol":"ETH/GBP","bids":[{"price":2977.18,"qty":6.67360002}],"asks":[],"checksum":4130399488,"timestamp":"2024-06-01T17:52:35.608553Z"}]}
{"channel":"book","type":"update","data":[{"symbol":"ETH/GBP","bids":[],"asks":[{"price":2977.43,"qty":6.58745056}],"checksum":4042115963,"timestamp":"2024-06-01T17:52:35.628475Z"}]}
{"channel":"book","type":"update","data":[{"symbol":"ETH/GBP","bids":[{"price":2977.18,"qty":0.08561200}],"asks":[],"checksum":3597588532,"timestamp":"2024-06-01T17:52:35.818995Z"}]}
{"channel":"book","type":"update","data":[{"symbol":"ETH/GBP","bids":[{"price":2977.19,"qty":6.58796627}],"asks":[],"checksum":2161304049,"timestamp":"2024-06-01T17:52:35.823390Z"}]}
{"channel":"book","type":"update","data":[{"symbol":"ETH/GBP","bids":[],"asks":[{"price":2977.88,"qty":13.17290886}],"checksum":530332063,"timestamp":"2024-06-01T17:52:35.823409Z"}]}
{"channel":"book","type":"update","data":[{"symbol":"ETH/GBP","bids":[],"asks":[{"price":2977.43,"qty":0.00000000},{"price":2979.83,"qty":0.27100000}],"checksum":2311005930,"timestamp":"2024-06-01T17:52:35.839816Z"}]}
{"channel":"book","type":"update","data":[{"symbol":"ETH/GBP","bids":[],"asks":[{"price":2977.45,"qty":6.58741367}],"checksum":3621259985,"timestamp":"2024-06-01T17:52:35.844617Z"}]}
{"channel":"book","type":"update","data":[{"symbol":"ETH/GBP","bids":[],"asks":[{"price":2977.45,"qty":0.00000000},{"price":2979.83,"qty":0.27100000}],"checksum":2311005930,"timestamp":"2024-06-01T17:52:35.850373Z"}]}
{"channel":"book","type":"update","data":[{"symbol":"ETH/GBP","bids":[{"price":2977.19,"qty":0.00000000},{"price":2974.30,"qty":0.30200000}],"asks":[],"checksum":233171000,"timestamp":"2024-06-01T17:52:35.850406Z"}]}
{"channel":"book","type":"update","data":[{"symbol":"ETH/GBP","bids":[],"asks":[{"price":2977.46,"qty":6.58738455}],"checksum":3519174905,"timestamp":"2024-06-01T17:52:35.947060Z"}]}
{"channel":"book","type":"update","data":[{"symbol":"ETH/GBP","bids":[{"price":2977.20,"qty":6.58794079}],"asks":[],"checksum":2030630789,"timestamp":"2024-06-01T17:52:35.947159Z"}]}
{"channel":"book","type":"update","data":[{"symbol":"ETH/GBP","bids":[{"price":2977.20,"qty":0.00000000},{"price":2974.30,"qty":0.30200000}],"asks":[],"checksum":3519174905,"timestamp":"2024-06-01T17:52:36.018523Z"}]}
{"channel":"book","type":"update","data":[{"symbol":"ETH/GBP","bids":[],"asks":[{"price":2977.46,"qty":0.00000000},{"price":2979.83,"qty":0.27100000}],"checksum":233171000,"timestamp":"2024-06-01T17:52:36.018685Z"}]}
{"channel":"book","type":"update","data":[{"symbol":"ETH/GBP","bids":[{"price":2977.22,"qty":0.00000000},{"price":2973.93,"qty":0.27474654}],"asks":[],"checksum":1784352269,"timestamp":"2024-06-01T17:52:36.104854Z"}]}
{"channel":"book","type":"update","data":[{"symbol":"ETH/GBP","bids":[],"asks":[{"price":2977.87,"qty":6.58646732}],"checksum":2008136998,"timestamp":"2024-06-01T17:52:36.170997Z"}]}
{"channel":"book","type":"update","data":[{"symbol":"ETH/GBP","bids":[{"price":2977.19,"qty":6.58797169}],"asks":[],"checksum":4112259990,"timestamp":"2024-06-01T17:52:36.171198Z"}]}
{"channel":"book","type":"update","data":[{"symbol":"ETH/GBP","bids":[],"asks":[{"price":2977.87,"qty":0.00000000},{"price":2979.83,"qty":0.27100000}],"checksum":1505560677,"timestamp":"2024-06-01T17:52:36.176962Z"}]}
{"channel":"book","type":"update","data":[{"symbol":"ETH/GBP","bids":[{"price":2977.19,"qty":0.00000000},{"price":2973.93,"qty":0.27474654}],"asks":[],"checksum":1784352269,"timestamp":"2024-06-01T17:52:36.183312Z"}]}
{"channel":"book","type":"update","data":[{"symbol":"ETH/GBP","bids":[{"price":2977.21,"qty":6.58790850}],"asks":[],"checksum":3480571766,"timestamp":"2024-06-01T17:52:36.272372Z"}]}
{"channel":"book","type":"update","data":[{"symbol":"ETH/GBP","bids":[],"asks":[{"price":2977.47,"qty":6.58736083}],"checksum":2352526551,"timestamp":"2024-06-01T17:52:36.272402Z"}]}
{"channel":"book","type":"update","data":[{"symbol":"ETH/GBP","bids":[{"price":2977.21,"qty":0.00000000},{"price":2973.93,"qty":0.27474654}],"asks":[],"checksum":1313457509,"timestamp":"2024-06-01T17:52:36.277731Z"}]}
{"channel":"book","type":"update","data":[{"symbol":"ETH/GBP","bids":[],"asks":[{"price":2977.47,"qty":0.00000000},{"price":2979.83,"qty":0.27100000}],"checksum":1784352269,"timestamp":"2024-06-01T17:52:36.277901Z"}]}
{"channel":"book","type":"update","data":[{"symbol":"ETH/GBP","bids":[],"asks":[{"price":2977.88,"qty":0.00000000},{"price":2980.09,"qty":1.31631591}],"checksum":1105563473,"timestamp":"2024-06-01T17:52:36.301806Z"}]}
{"channel":"book","type":"update","data":[{"symbol":"ETH/GBP","bids":[],"asks":[{"price":2977.87,"qty":13.17293464}],"checksum":2280126818,"timestamp":"2024-06-01T17:52:36.306664Z"}]}
{"channel":"book","type":"update","data":[{"symbol":"ETH/GBP","bids":[],"asks":[{"price":2977.87,"qty":0.00000000},{"price":2980.09,"qty":1.31631591}],"checksum":1105563473,"timestamp":"2024-06-01T17:52:36.317550Z"}]}
{"channel":"book","type":"update","data":[{"symbol":"ETH/GBP","bids":[{"price":2976.74,"qty":0.00000000},{"price":2973.66,"qty":1.31915783}],"asks":[],"checksum":3560939299,"timestamp":"2024-06-01T17:52:36.331621Z"}]}
{"channel":"book","type":"update","data":[{"symbol":"ETH/GBP","bids":[{"price":2976.65,"qty":13.17832272}],"asks":[],"checksum":2840928803,"timestamp":"2024-06-01T17:52:36.336210Z"}]}
{"channel":"book","type":"update","data":[{"symbol":"ETH/GBP","bids":[{"price":2976.65,"qty":0.00000000},{"price":2973.66,"qty":1.31915783}],"asks":[],"checksum":3560939299,"timestamp":"2024-06-01T17:52:36.355564Z"}]}
{"channel":"book","type":"update","data":[{"symbol":"ETH/GBP","bids":[],"asks":[{"price":2977.38,"qty":6.58755528}],"checksum":3405270687,"timestamp":"2024-06-01T17:52:36.372353Z"}]}
{"channel":"book","type":"update","data":[{"symbol":"ETH/GBP","bids":[{"price":2977.11,"qty":6.58812898}],"asks":[],"checksum":1407302052,"timestamp":"2024-06-01T17:52:36.372439Z"}]}
{"channel":"book","type":"update","data":[{"symbol":"ETH/GBP","bids":[],"asks":[{"price":2977.38,"qty":0.00000000},{"price":2980.09,"qty":1.31631591}],"checksum":1294362648,"timestamp":"2024-06-01T17:52:36.382480Z"}]}
{"channel":"book","type":"update","data":[{"symbol":"ETH/GBP","bids":[{"price":2977.11,"qty":0.00000000},{"price":2973.66,"qty":1.31915783}],"asks":[],"checksum":3560939299,"timestamp":"2024-06-01T17:52:36.382622Z"}]}
{"channel":"book","type":"update","data":[{"symbol":"ETH/GBP","bids":[],"asks":[{"price":2978.86,"qty":0.00000000},{"price":2980.21,"qty":1.00000000}],"checksum":2226319255,"timestamp":"2024-06-01T17:52:36.476042Z"}]}
{"channel":"book","type":"update","data":[{"symbol":"ETH/GBP","bids":[],"asks":[{"price":2977.35,"qty":6.58762196}],"checksum":1289065908,"timestamp":"2024-06-01T17:52:36.485808Z"}]}
{"channel":"book","type":"update","data":[{"symbol":"ETH/GBP","bids":[{"price":2977.08,"qty":6.58819846}],"asks":[],"checksum":2770063276,"timestamp":"2024-06-01T17:52:36.485838Z"}]}
{"channel":"book","type":"update","data":[{"symbol":"ETH/GBP","bids":[{"price":2977.18,"qty":0.00000000},{"price":2973.66,"qty":1.31915783},{"price":2976.34,"qty":0.08562900}],"asks":[],"checksum":107945716,"timestamp":"2024-06-01T17:52:36.515500Z"}]}
{"channel":"book","type":"update","data":[{"symbol":"ETH/GBP","bids":[{"price":2977.08,"qty":0.00000000},{"price":2973.66,"qty":1.31915783}],"asks":[],"checksum":981840924,"timestamp":"2024-06-01T17:52:36.532419Z"}]}
{"channel":"book","type":"update","data":[{"symbol":"ETH/GBP","bids":[],"asks":[{"price":2977.81,"qty":13.17323089}],"checksum":4217133140,"timestamp":"2024-06-01T17:52:36.537031Z"}]}
{"channel":"book","type":"update","data":[{"symbol":"ETH/GBP","bids":[{"price":2976.35,"qty":13.17966152}],"asks":[],"checksum":22611369,"timestamp":"2024-06-01T17:52:36.537103Z"}]}
{"channel":"book","type":"update","data":[{"symbol":"ETH/GBP","bids":[{"price":2976.35,"qty":0.00000000},{"price":2973.66,"qty":1.31915783}],"asks":[],"checksum":4217133140,"timestamp":"2024-06-01T17:52:36.541690Z"}]}
{"channel":"book","type":"update","data":[{"symbol":"ETH/GBP","bids":[],"asks":[{"price":2977.35,"qty":0.00000000},{"price":2980.09,"qty":1.31631591}],"checksum":857861629,"timestamp":"2024-06-01T17:52:36.595335Z"}]}
{"channel":"book","type":"update","data":[{"symbol":"ETH/GBP","bids":[{"price":2977.08,"qty":6.58820929}],"asks":[],"checksum":884656488,"timestamp":"2024-06-01T17:52:36.600141Z"}]}
{"channel":"book","type":"update","data":[{"symbol":"ETH/GBP","bids":[],"asks":[{"price":2977.37,"qty":6.58758673}],"checksum":2613364376,"timestamp":"2024-06-01T17:52:36.600297Z"}]}
{"channel":"book","type":"update","data":[{"symbol":"ETH/GBP","bids":[{"price":2977.08,"qty":0.00000000},{"price":2973.66,"qty":1.31915783}],"asks":[],"checksum":2623529485,"timestamp":"2024-06-01T17:52:36.608558Z"}]}
{"channel":"book","type":"update","data":[{"symbol":"ETH/GBP","bids":[],"asks":[{"price":2977.37,"qty":0.00000000},{"price":2980.09,"qty":1.31631591}],"checksum":857861629,"timestamp":"2024-06-01T17:52:36.608566Z"}]}
{"channel":"book","type":"update","data":[{"symbol":"ETH/GBP","bids":[],"asks":[{"price":2977.81,"qty":0.00000000},{"price":2980.21,"qty":1.00000000}],"checksum":4074950207,"timestamp":"2024-06-01T17:52:36.646766Z"}]}
{"channel":"book","type":"update","data":[{"symbol":"ETH/GBP","bids":[],"asks":[{"price":2977.43,"qty":6.58745019}],"checksum":2696598601,"timestamp":"2024-06-01T17:52:36.707463Z"}]}
{"channel":"book","type":"update","data":[{"symbol":"ETH/GBP","bids":[{"price":2977.16,"qty":6.58802997}],"asks":[],"checksum":83878428,"timestamp":"2024-06-01T17:52:36.707580Z"}]}
{"channel":"book","type":"update","data":[{"symbol":"ETH/GBP","bids":[],"asks":[{"price":2977.43,"qty":0.00000000},{"price":2980.21,"qty":1.00000000}],"checksum":1453848682,"timestamp":"2024-06-01T17:52:36.712481Z"}]}
{"channel":"book","type":"update","data":[{"symbol":"ETH/GBP","bids":[{"price":2977.16,"qty":0.00000000},{"price":2973.66,"qty":1.31915783}],"asks":[],"checksum":4074950207,"timestamp":"2024-06-01T17:52:36.712507Z"}]}
{"channel":"book","type":"update","data":[{"symbol":"ETH/GBP","bids":[],"asks":[{"price":2978.52,"qty":13.17006876}],"checksum":3465920918,"timestamp":"2024-06-01T17:52:36.743710Z"}]}
{"channel":"book","type":"update","data":[{"symbol":"ETH/GBP","bids":[{"price":2976.36,"qty":13.17960882}],"asks":[],"checksum":440111926,"timestamp":"2024-06-01T17:52:36.743796Z"}]}
{"channel":"book","type":"update","data":[{"symbol":"ETH/GBP","bids":[{"price":2976.36,"qty":0.00000000},{"price":2973.66,"qty":1.31915783}],"asks":[],"checksum":3465920918,"timestamp":"2024-06-01T17:52:36.754258Z"}]}
{"channel":"book","type":"update","data":[{"symbol":"ETH/GBP","bids":[],"asks":[{"price":2978.52,"qty":0.00000000},{"price":2980.21,"qty":1.00000000}],"checksum":4074950207,"timestamp":"2024-06-01T17:52:36.754311Z"}]}
{"channel":"book","type":"update","data":[{"symbol":"ETH/GBP","bids":[{"price":2977.10,"qty":6.58816385}],"asks":[],"checksum":342174998,"timestamp":"2024-06-01T17:52:36.831221Z"}]}
{"channel":"book","type":"update","data":[{"symbol":"ETH/GBP","bids":[],"asks":[{"price":2977.38,"qty":6.58756747}],"checksum":2864218716,"timestamp":"2024-06-01T17:52:36.831343Z"}]}
{"channel":"book","type":"update","data":[{"symbol":"ETH/GBP","bids":[{"price":2977.10,"qty":0.00000000},{"price":2973.66,"qty":1.31915783}],"asks":[],"checksum":1279222133,"timestamp":"2024-06-01T17:52:36.845861Z"}]}
{"channel":"book","type":"update","data":[{"symbol":"ETH/GBP","bids":[],"asks":[{"price":2977.38,"qty":0.00000000},{"price":2980.21,"qty":1.00000000}],"checksum":4074950207,"timestamp":"2024-06-01T17:52:36.846000Z"}]}
{"channel":"book","type":"update","data":[{"symbol":"ETH/GBP","bids":[],"asks":[{"price":2978.54,"qty":1.38718156}],"checksum":1540166926,"timestamp":"2024-06-01T17:52:36.871754Z"}]}
{"channel":"book","type":"update","data":[{"symbol":"ETH/GBP","bids":[],"asks":[{"price":2978.69,"qty":0.00000000},{"price":2980.39,"qty":0.27478155}],"checksum":3845989381,"timestamp":"2024-06-01T17:52:36.876621Z"}]}
{"channel":"book","type":"update","data":[{"symbol":"ETH/GBP","bids":[],"asks":[{"price":2978.52,"qty":13.17006876}],"checksum":2730897244,"timestamp":"2024-06-01T17:52:36.948669Z"}]}
{"channel":"book","type":"update","data":[{"symbol":"ETH/GBP","bids":[{"price":2977.04,"qty":6.58828273}],"asks":[],"checksum":295720832,"timestamp":"2024-06-01T17:52:36.948687Z"}]}
{"channel":"book","type":"update","data":[{"symbol":"ETH/GBP","bids":[],"asks":[{"price":2977.32,"qty":6.58770223}],"checksum":3604445008,"timestamp":"2024-06-01T17:52:36.948739Z"}]}
{"channel":"book","type":"update","data":[{"symbol":"ETH/GBP","bids":[{"price":2976.36,"qty":13.17960882}],"asks":[],"checksum":1576721973,"timestamp":"2024-06-01T17:52:36.948795Z"}]}
{"channel":"book","type":"update","data":[{"symbol":"ETH/GBP","bids":[],"asks":[{"price":2978.49,"qty":1.31749400}],"checksum":1967484635,"timestamp":"2024-06-01T17:52:36.951447Z"}]}
{"channel":"book","type":"update","data":[{"symbol":"ETH/GBP","bids":[],"asks":[{"price":2978.54,"qty":0.06970900}],"checksum":814675559,"timestamp":"2024-06-01T17:52:36.951573Z"}]}
{"channel":"book","type":"update","data":[{"symbol":"ETH/GBP","bids":[],"asks":[{"price":2978.52,"qty":0.00000000},{"price":2980.09,"qty":1.31631591}],"checksum":1332761385,"timestamp":"2024-06-01T17:52:36.954152Z"}]}
{"channel":"book","type":"update","data":[{"symbol":"ETH/GBP","bids":[{"price":2976.36,"qty":0.00000000},{"price":2973.93,"qty":0.27474654}],"asks":[],"checksum":1779366197,"timestamp":"2024-06-01T17:52:36.954365Z"}]}
{"channel":"book","type":"update","data":[{"symbol":"ETH/GBP","bids":[{"price":2977.04,"qty":0.00000000},{"price":2973.66,"qty":1.31915783}],"asks":[],"checksum":3647504873,"timestamp":"2024-06-01T17:52:36.969664Z"}]}
{"channel":"book","type":"update","data":[{"symbol":"ETH/GBP","bids":[],"asks":[{"price":2977.32,"qty":0.00000000},{"price":2980.21,"qty":1.00000000}],"checksum":1603881000,"timestamp":"2024-06-01T17:52:36.969780Z"}]}
{"channel":"book","type":"update","data":[{"symbol":"ETH/GBP","bids":[],"asks":[{"price":2977.31,"qty":6.58771955}],"checksum":2551604968,"timestamp":"2024-06-01T17:52:37.234431Z"}]}
{"channel":"book","type":"update","data":[{"symbol":"ETH/GBP","bids":[{"price":2976.36,"qty":13.17961104}],"asks":[],"checksum":616697727,"timestamp":"2024-06-01T17:52:37.234488Z"}]}
{"channel":"book","type":"update","data":[{"symbol":"ETH/GBP","bids":[],"asks":[{"price":2977.77,"qty":13.17340101}],"checksum":2745712615,"timestamp":"2024-06-01T17:52:37.234564Z"}]}
{"channel":"book","type":"update","data":[{"symbol":"ETH/GBP","bids":[{"price":2977.02,"qty":6.58833055}],"asks":[],"checksum":429429560,"timestamp":"2024-06-01T17:52:37.234743Z"}]}
{"channel":"book","type":"update","data":[{"symbol":"ETH/GBP","bids":[{"price":2976.36,"qty":0.00000000},{"price":2973.93,"qty":0.27474654}],"asks":[],"checksum":3542288843,"timestamp":"2024-06-01T17:52:37.240341Z"}]}
{"channel":"book","type":"update","data":[{"symbol":"ETH/GBP","bids":[{"price":2977.02,"qty":0.00000000},{"price":2973.66,"qty":1.31915783}],"asks":[],"checksum":4203031673,"timestamp":"2024-06-01T17:52:37.294834Z"}]}
{"channel":"book","type":"update","data":[{"symbol":"ETH/GBP","bids":[{"price":2977.03,"qty":6.58831329}],"asks":[],"checksum":3899757712,"timestamp":"2024-06-01T17:52:37.336816Z"}]}
{"channel":"book","type":"update","data":[{"symbol":"ETH/GBP","bids":[],"asks":[{"price":2977.31,"qty":0.00000000},{"price":2980.09,"qty":1.31631591}],"checksum":1168709110,"timestamp":"2024-06-01T17:52:37.348919Z"}]}
{"channel":"book","type":"update","data":[{"symbol":"ETH/GBP","bids":[{"price":2977.03,"qty":0.00000000},{"price":2973.66,"qty":1.31915783}],"asks":[],"checksum":1465756959,"timestamp":"2024-06-01T17:52:37.348968Z"}]}
{"channel":"book","type":"update","data":[{"symbol":"ETH/GBP","bids":[],"asks":[{"price":2977.77,"qty":0.00000000},{"price":2980.21,"qty":1.00000000}],"checksum":1603881000,"timestamp":"2024-06-01T17:52:37.355251Z"}]}
{"channel":"book","type":"update","data":[{"symbol":"ETH/GBP","bids":[],"asks":[{"price":2977.29,"qty":6.58776616}],"checksum":1747943601,"timestamp":"2024-06-01T17:52:37.359964Z"}]}
{"channel":"book","type":"update","data":[{"symbol":"ETH/GBP","bids":[],"asks":[{"price":2977.29,"qty":0.00000000},{"price":2980.21,"qty":1.00000000}],"checksum":1603881000,"timestamp":"2024-06-01T17:52:37.368201Z"}]}
{"channel":"book","type":"update","data":[{"symbol":"ETH/GBP","bids":[],"asks":[{"price":2978.54,"qty":0.00000000},{"price":2980.39,"qty":0.27478155},{"price":2977.97,"qty":0.06961200}],"checksum":3405380737,"timestamp":"2024-06-01T17:52:37.414338Z"}]}
{"channel":"book","type":"update","data":[{"symbol":"ETH/GBP","bids":[],"asks":[{"price":2977.78,"qty":13.17335982}],"checksum":1084841643,"timestamp":"2024-06-01T17:52:37.434679Z"}]}
{"channel":"book","type":"update","data":[{"symbol":"ETH/GBP","bids":[{"price":2976.36,"qty":13.17961104}],"asks":[],"checksum":3419381869,"timestamp":"2024-06-01T17:52:37.434840Z"}]}
{"channel":"book","type":"update","data":[{"symbol":"ETH/GBP","bids":[{"price":2976.36,"qty":0.00000000},{"price":2973.66,"qty":1.31915783}],"asks":[],"checksum":1084841643,"timestamp":"2024-06-01T17:52:37.440002Z"}]}
{"channel":"book","type":"update","data":[{"symbol":"ETH/GBP","bids":[{"price":2977.03,"qty":6.58830736}],"asks":[],"checksum":294803475,"timestamp":"2024-06-01T17:52:37.444014Z"}]}
{"channel":"book","type":"update","data":[{"symbol":"ETH/GBP","bids":[],"asks":[{"price":2977.78,"qty":0.00000000},{"price":2980.21,"qty":1.00000000}],"checksum":2613246521,"timestamp":"2024-06-01T17:52:37.517750Z"}]}
{"channel":"book","type":"update","data":[{"symbol":"ETH/GBP","bids":[{"price":2977.03,"qty":0.00000000},{"price":2973.66,"qty":1.31915783}],"asks":[],"checksum":3405380737,"timestamp":"2024-06-01T17:52:37.517855Z"}]}
{"channel":"book","type":"update","data":[{"symbol":"ETH/GBP","bids":[],"asks":[{"price":2977.28,"qty":6.58777487}],"checksum":2635493133,"timestamp":"2024-06-01T17:52:37.522964Z"}]}
{"channel":"book","type":"update","data":[{"symbol":"ETH/GBP","bids":[{"price":2977.00,"qty":6.58838116}],"asks":[],"checksum":2418233303,"timestamp":"2024-06-01T17:52:37.584834Z"}]}
{"channel":"book","type":"update","data":[{"symbol":"ETH/GBP","bids":[],"asks":[{"price":2977.97,"qty":0.00000000},{"price":2980.21,"qty":1.00000000},{"price":2978.48,"qty":0.06963400}],"checksum":2987933116,"timestamp":"2024-06-01T17:52:37.588165Z"}]}
{"channel":"book","type":"update","data":[{"symbol":"ETH/GBP","bids":[{"price":2977.00,"qty":0.00000000},{"price":2973.66,"qty":1.31915783}],"asks":[],"checksum":3207404902,"timestamp":"2024-06-01T17:52:37.716742Z"}]}
{"channel":"book","type":"update","data":[{"symbol":"ETH/GBP","bids":[],"asks":[{"price":2977.74,"qty":13.17351163}],"checksum":4126540847,"timestamp":"2024-06-01T17:52:37.721317Z"}]}
{"channel":"book","type":"update","data":[{"symbol":"ETH/GBP","bids":[{"price":2977.01,"qty":6.58836139}],"asks":[],"checksum":1366441901,"timestamp":"2024-06-01T17:52:37.721354Z"}]}
{"channel":"book","type":"update","data":[{"symbol":"ETH/GBP","bids":[{"price":2976.54,"qty":13.17880095}],"asks":[],"checksum":2092034728,"timestamp":"2024-06-01T17:52:37.721499Z"}]}
{"channel":"book","type":"update","data":[{"symbol":"ETH/GBP","bids":[{"price":2976.54,"qty":0.00000000},{"price":2973.93,"qty":0.27474654}],"asks":[],"checksum":1366441901,"timestamp":"2024-06-01T17:52:37.726424Z"}]}
{"channel":"book","type":"update","data":[{"symbol":"ETH/GBP","bids":[],"asks":[{"price":2977.28,"qty":0.00000000},{"price":2980.09,"qty":1.31631591}],"checksum":252325225,"timestamp":"2024-06-01T17:52:37.808067Z"}]}
{"channel":"book","type":"update","data":[{"symbol":"ETH/GBP","bids":[],"asks":[{"price":2977.30,"qty":6.58773862}],"checksum":3505540896,"timestamp":"2024-06-01T17:52:37.812487Z"}]}
{"channel":"book","type":"update","data":[{"symbol":"ETH/GBP","bids":[],"asks":[{"price":2977.30,"qty":0.00000000},{"price":2980.09,"qty":1.31631591}],"checksum":252325225,"timestamp":"2024-06-01T17:52:37.833596Z"}]}
{"channel":"book","type":"update","data":[{"symbol":"ETH/GBP","bids":[],"asks":[{"price":2977.74,"qty":0.00000000},{"price":2980.21,"qty":1.00000000}],"checksum":3977004061,"timestamp":"2024-06-01T17:52:37.841386Z"}]}
{"channel":"book","type":"update","data":[{"symbol":"ETH/GBP","bids":[{"price":2977.01,"qty":0.00000000},{"price":2973.66,"qty":1.31915783}],"asks":[],"checksum":1233682335,"timestamp":"2024-06-01T17:52:37.841493Z"}]}
{"channel":"book","type":"update","data":[{"symbol":"ETH/GBP","bids":[{"price":2976.97,"qty":6.58844608}],"asks":[],"checksum":879339970,"timestamp":"2024-06-01T17:52:37.846162Z"}]}
{"channel":"book","type":"update","data":[{"symbol":"ETH/GBP","bids":[],"asks":[{"price":2979.64,"qty":0.00000000},{"price":2980.39,"qty":0.27478155}],"checksum":2075612251,"timestamp":"2024-06-01T17:52:37.847245Z"}]}
{"channel":"book","type":"update","data":[{"symbol":"ETH/GBP","bids":[],"asks":[{"price":2978.72,"qty":0.00000000},{"price":2980.57,"qty":23.93473548}],"checksum":661596919,"timestamp":"2024-06-01T17:52:37.847401Z"}]}
{"channel":"book","type":"update","data":[{"symbol":"ETH/GBP","bids":[{"price":2976.97,"qty":0.00000000},{"price":2973.66,"qty":1.31915783}],"asks":[],"checksum":1519320234,"timestamp":"2024-06-01T17:52:37.850500Z"}]}
{"channel":"book","type":"update","data":[{"symbol":"ETH/GBP","bids":[],"asks":[{"price":2979.22,"qty":1.31669873}],"checksum":550799762,"timestamp":"2024-06-01T17:52:37.854688Z"}]}
{"channel":"book","type":"update","data":[{"symbol":"ETH/GBP","bids":[],"asks":[{"price":2978.49,"qty":2.63451429}],"checksum":2440686459,"timestamp":"2024-06-01T17:52:37.854802Z"}]}
{"channel":"book","type":"update","data":[{"symbol":"ETH/GBP","bids":[{"price":2976.34,"qty":0.00000000},{"price":2973.19,"qty":0.14113766},{"price":2977.02,"qty":0.08559000}],"asks":[],"checksum":28209954,"timestamp":"2024-06-01T17:52:37.896279Z"}]}
{"channel":"book","type":"update","data":[{"symbol":"ETH/GBP","bids":[],"asks":[{"price":2978.46,"qty":1.31750569}],"checksum":2396213794,"timestamp":"2024-06-01T17:52:37.899290Z"}]}
{"channel":"book","type":"update","data":[{"symbol":"ETH/GBP","bids":[],"asks":[{"price":2978.49,"qty":1.31702029}],"checksum":1903013370,"timestamp":"2024-06-01T17:52:37.902103Z"}]}
{"channel":"book","type":"update","data":[{"symbol":"ETH/GBP","bids":[],"asks":[{"price":2978.45,"qty":13.17038890}],"checksum":3867834402,"timestamp":"2024-06-01T17:52:37.939291Z"}]}
{"channel":"book","type":"update","data":[{"symbol":"ETH/GBP","bids":[{"price":2976.51,"qty":13.17895057}],"asks":[],"checksum":3067435196,"timestamp":"2024-06-01T17:52:37.939369Z"}]}
{"channel":"book","type":"update","data":[{"symbol":"ETH/GBP","bids":[],"asks":[{"price":2978.45,"qty":19.75558335}],"checksum":2787024252,"timestamp":"2024-06-01T17:52:37.939402Z"}]}
{"channel":"book","type":"update","data":[{"symbol":"ETH/GBP","bids":[],"asks":[{"price":2978.45,"qty":13.17038890}],"checksum":3067435196,"timestamp":"2024-06-01T17:52:37.944362Z"}]}
{"channel":"book","type":"update","data":[{"symbol":"ETH/GBP","bids":[],"asks":[{"price":2978.45,"qty":0.00000000},{"price":2980.21,"qty":1.00000000}],"checksum":1045095823,"timestamp":"2024-06-01T17:52:37.944380Z"}]}
{"channel":"book","type":"update","data":[{"symbol":"ETH/GBP","bids":[{"price":2976.96,"qty":6.58847112}],"asks":[],"checksum":3192863220,"timestamp":"2024-06-01T17:52:37.948674Z"}]}
{"channel":"book","type":"update","data":[{"symbol":"ETH/GBP","bids":[{"price":2976.96,"qty":0.00000000},{"price":2973.93,"qty":0.27474654}],"asks":[],"checksum":1045095823,"timestamp":"2024-06-01T17:52:37.968979Z"}]}
{"channel":"book","type":"update","data":[{"symbol":"ETH/GBP","bids":[],"asks":[{"price":2980.21,"qty":0.00000000},{"price":2980.39,"qty":0.27478155}],"checksum":811795322,"timestamp":"2024-06-01T17:52:37.975227Z"}]}
{"channel":"book","type":"update","data":[{"symbol":"ETH/GBP","bids":[],"asks":[{"price":2978.49,"qty":0.00000000},{"price":2980.57,"qty":23.93473548}],"checksum":3615902904,"timestamp":"2024-06-01T17:52:37.977373Z"}]}
{"channel":"book","type":"update","data":[{"symbol":"ETH/GBP","bids":[{"price":2976.51,"qty":0.00000000},{"price":2973.66,"qty":1.31915783}],"asks":[],"checksum":3730943996,"timestamp":"2024-06-01T17:52:37.977417Z"}]}
{"channel":"book","type":"update","data":[{"symbol":"ETH/GBP","bids":[{"price":2973.67,"qty":0.34510000}],"asks":[],"checksum":296670948,"timestamp":"2024-06-01T17:52:37.980730Z"}]}
{"channel":"book","type":"update","data":[{"symbol":"ETH/GBP","bids":[],"asks":[{"price":2979.22,"qty":0.00000000},{"price":2980.58,"qty":13.43327015}],"checksum":3190320316,"timestamp":"2024-06-01T17:52:37.980956Z"}]}
{"channel":"book","type":"update","data":[{"symbol":"ETH/GBP","bids":[{"price":2975.87,"qty":0.00000000},{"price":2973.66,"qty":1.31915783}],"asks":[],"checksum":2271633728,"timestamp":"2024-06-01T17:52:37.985126Z"}]}
{"channel":"book","type":"update","data":[{"symbol":"ETH/GBP","bids":[{"price":2973.66,"qty":0.00000000},{"price":2973.19,"qty":0.14113766}],"asks":[],"checksum":4264838080,"timestamp":"2024-06-01T17:52:37.990404Z"}]}
{"channel":"book","type":"update","data":[{"symbol":"ETH/GBP","bids":[],"asks":[{"price":2978.46,"qty":0.00000000},{"price":2980.94,"qty":0.20717085}],"checksum":3432312459,"timestamp":"2024-06-01T17:52:37.993677Z"}]}
{"channel":"book","type":"update","data":[{"symbol":"ETH/GBP","bids":[{"price":2977.05,"qty":1.31707300}],"asks":[],"checksum":2180967981,"timestamp":"2024-06-01T17:52:37.994754Z"}]}
{"channel":"book","type":"update","data":[{"symbol":"ETH/GBP","bids":[{"price":2976.52,"qty":1.31788825}],"asks":[],"checksum":2691082436,"timestamp":"2024-06-01T17:52:37.996226Z"}]}
{"channel":"book","type":"update","data":[{"symbol":"ETH/GBP","bids":[{"price":2975.79,"qty":1.31821010}],"asks":[],"checksum":4259405891,"timestamp":"2024-06-01T17:52:37.996417Z"}]}
{"channel":"book","type":"update","data":[{"symbol":"ETH/GBP","bids":[],"asks":[{"price":2978.55,"qty":0.00000000},{"price":2980.95,"qty":0.22400000}],"checksum":3990335696,"timestamp":"2024-06-01T17:52:37.996761Z"}]}
{"channel":"book","type":"update","data":[{"symbol":"ETH/GBP","bids":[{"price":2976.33,"qty":0.00000000},{"price":2973.93,"qty":0.27474654}],"asks":[],"checksum":134119618,"timestamp":"2024-06-01T17:52:37.996797Z"}]}
{"channel":"book","type":"update","data":[{"symbol":"ETH/GBP","bids":[],"asks":[{"price":2980.94,"qty":0.00000000},{"price":2981.04,"qty":1.34000000}],"checksum":297600716,"timestamp":"2024-06-01T17:52:38.002525Z"}]}
{"channel":"book","type":"update","data":[{"symbol":"ETH/GBP","bids":[],"asks":[{"price":2980.94,"qty":0.09333652}],"checksum":1386907166,"timestamp":"2024-06-01T17:52:38.002583Z"}]}
{"channel":"book","type":"update","data":[{"symbol":"ETH/GBP","bids":[],"asks":[{"price":2980.94,"qty":0.27666780}],"checksum":1830765348,"timestamp":"2024-06-01T17:52:38.019347Z"}]}
{"channel":"book","type":"update","data":[{"symbol":"ETH/GBP","bids":[],"asks":[{"price":2980.94,"qty":0.18333128}],"checksum":1624652640,"timestamp":"2024-06-01T17:52:38.020879Z"}]}
{"channel":"book","type":"update","data":[{"symbol":"ETH/GBP","bids":[{"price":2976.52,"qty":0.00000000},{"price":2973.67,"qty":0.34510000}],"asks":[],"checksum":208956968,"timestamp":"2024-06-01T17:52:38.025331Z"}]}
{"channel":"book","type":"update","data":[{"symbol":"ETH/GBP","bids":[],"asks":[{"price":2978.23,"qty":6.58568027}],"checksum":3452051936,"timestamp":"2024-06-01T17:52:38.042075Z"}]}
{"channel":"book","type":"update","data":[{"symbol":"ETH/GBP","bids":[],"asks":[{"price":2978.23,"qty":0.00000000},{"price":2980.95,"qty":0.22400000}],"checksum":208956968,"timestamp":"2024-06-01T17:52:38.046324Z"}]}
{"channel":"book","type":"update","data":[{"symbol":"ETH/GBP","bids":[{"price":2974.46,"qty":0.00000000},{"price":2973.19,"qty":0.14113766},{"price":2975.33,"qty":1.34000000}],"asks":[],"checksum":91803772,"timestamp":"2024-06-01T17:52:38.049976Z"}]}
{"channel":"book","type":"update","data":[{"symbol":"ETH/GBP","bids":[{"price":2977.97,"qty":6.58623006}],"asks":[],"checksum":2612247703,"timestamp":"2024-06-01T17:52:38.050925Z"}]}
{"channel":"book","type":"update","data":[{"symbol":"ETH/GBP","bids":[{"price":2977.97,"qty":0.00000000},{"price":2973.67,"qty":0.34510000}],"asks":[],"checksum":91803772,"timestamp":"2024-06-01T17:52:38.058484Z"}]}
{"channel":"book","type":"update","data":[{"symbol":"ETH/GBP","bids":[{"price":2977.02,"qty":0.00000000},{"price":2973.19,"qty":0.14113766},{"price":2976.35,"qty":0.08562000}],"asks":[],"checksum":3159764087,"timestamp":"2024-06-01T17:52:38.070394Z"}]}
{"channel":"book","type":"update","data":[{"symbol":"ETH/GBP","bids":[],"asks":[{"price":2980.39,"qty":0.00000000},{"price":2981.05,"qty":0.96923516}],"checksum":879751445,"timestamp":"2024-06-01T17:52:38.081927Z"}]}
{"channel":"book","type":"update","data":[{"symbol":"ETH/GBP","bids":[],"asks":[{"price":2978.31,"qty":6.58551066}],"checksum":2033482813,"timestamp":"2024-06-01T17:52:38.141728Z"}]}
{"channel":"book","type":"update","data":[{"symbol":"ETH/GBP","bids":[],"asks":[{"price":2978.76,"qty":13.16900367}],"checksum":3360077240,"timestamp":"2024-06-01T17:52:38.141757Z"}]}
{"channel":"book","type":"update","data":[{"symbol":"ETH/GBP","bids":[{"price":2977.06,"qty":13.17649971}],"asks":[],"checksum":4238221464,"timestamp":"2024-06-01T17:52:38.141873Z"}]}
{"channel":"book","type":"update","data":[{"symbol":"ETH/GBP","bids":[{"price":2977.09,"qty":1.31700582}],"asks":[],"checksum":617836334,"timestamp":"2024-06-01T17:52:38.145252Z"}]}
{"channel":"book","type":"update","data":[{"symbol":"ETH/GBP","bids":[{"price":2977.06,"qty":0.00000000},{"price":2973.93,"qty":0.27474654}],"asks":[],"checksum":2116230255,"timestamp":"2024-06-01T17:52:38.147932Z"}]}
{"channel":"book","type":"update","data":[{"symbol":"ETH/GBP","bids":[{"price":2977.05,"qty":0.00000000},{"price":2973.67,"qty":0.34510000}],"asks":[],"checksum":589816878,"timestamp":"2024-06-01T17:52:38.148210Z"}]}
{"channel":"book","type":"update","data":[{"symbol":"ETH/GBP","bids":[{"price":2977.96,"qty":6.58626432}],"asks":[],"checksum":1284005256,"timestamp":"2024-06-01T17:52:38.151884Z"}]}
{"channel":"book","type":"update","data":[{"symbol":"ETH/GBP","bids":[],"asks":[{"price":2978.48,"qty":0.00000000},{"price":2980.95,"qty":0.22400000},{"price":2979.00,"qty":0.06963200}],"checksum":3525870361,"timestamp":"2024-06-01T17:52:38.152780Z"}]}
{"channel":"book","type":"update","data":[{"symbol":"ETH/GBP","bids":[],"asks":[{"price":2980.94,"qty":0.00000000},{"price":2980.95,"qty":0.22400000}],"checksum":609792539,"timestamp":"2024-06-01T17:52:38.152861Z"}]}
{"channel":"book","type":"update","data":[{"symbol":"ETH/GBP","bids":[],"asks":[{"price":2980.94,"qty":0.00775181}],"checksum":2506027874,"timestamp":"2024-06-01T17:52:38.152940Z"}]}
{"channel":"book","type":"update","data":[{"symbol":"ETH/GBP","bids":[],"asks":[{"price":2978.31,"qty":0.00000000},{"price":2980.95,"qty":0.22400000}],"checksum":1227818838,"timestamp":"2024-06-01T17:52:38.167565Z"}]}
{"channel":"book","type":"update","data":[{"symbol":"ETH/GBP","bids":[{"price":2977.96,"qty":0.00000000},{"price":2973.67,"qty":0.34510000}],"asks":[],"checksum":2217355753,"timestamp":"2024-06-01T17:52:38.182068Z"}]}
{"channel":"book","type":"update","data":[{"symbol":"ETH/GBP","bids":[],"asks":[{"price":2978.76,"qty":0.00000000},{"price":2981.15,"qty":1.41091270}],"checksum":512209377,"timestamp":"2024-06-01T17:52:38.188508Z"}]}
{"channel":"book","type":"update","data":[{"symbol":"ETH/GBP","bids":[],"asks":[{"price":2979.39,"qty":0.00000000},{"price":2981.18,"qty":1.31583288}],"checksum":2176959009,"timestamp":"2024-06-01T17:52:38.191772Z"}]}
{"channel":"book","type":"update","data":[{"symbol":"ETH/GBP","bids":[],"asks":[{"price":2980.29,"qty":0.94850883}],"checksum":786105185,"timestamp":"2024-06-01T17:52:38.194694Z"}]}
{"channel":"book","type":"update","data":[{"symbol":"ETH/GBP","bids":[],"asks":[{"price":2978.37,"qty":6.58537152}],"checksum":3333828032,"timestamp":"2024-06-01T17:52:38.245541Z"}]}
{"channel":"book","type":"update","data":[{"symbol":"ETH/GBP","bids":[],"asks":[{"price":2978.37,"qty":0.00000000},{"price":2981.15,"qty":1.41091270}],"checksum":786105185,"timestamp":"2024-06-01T17:52:38.268293Z"}]}
{"channel":"book","type":"update","data":[{"symbol":"ETH/GBP","bids":[{"price":2977.97,"qty":6.58622832}],"asks":[],"checksum":3492195438,"timestamp":"2024-06-01T17:52:38.272880Z"}]}
{"channel":"book","type":"update","data":[{"symbol":"ETH/GBP","bids":[],"asks":[{"price":2981.05,"qty":0.27472973}],"checksum":3575663193,"timestamp":"2024-06-01T17:52:38.334090Z"}]}
{"channel":"book","type":"update","data":[{"symbol":"ETH/GBP","bids":[],"asks":[{"price":2979.00,"qty":0.00000000},{"price":2981.15,"qty":1.41091270},{"price":2979.38,"qty":0.06967500}],"checksum":728132352,"timestamp":"2024-06-01T17:52:38.341483Z"}]}
{"channel":"book","type":"update","data":[{"symbol":"ETH/GBP","bids":[],"asks":[{"price":2979.37,"qty":13.16632068}],"checksum":746403299,"timestamp":"2024-06-01T17:52:38.346265Z"}]}
{"channel":"book","type":"update","data":[{"symbol":"ETH/GBP","bids":[],"asks":[{"price":2978.39,"qty":6.58533333}],"checksum":2185464764,"timestamp":"2024-06-01T17:52:38.346305Z"}]}
{"channel":"book","type":"update","data":[{"symbol":"ETH/GBP","bids":[{"price":2977.51,"qty":13.17449461}],"asks":[],"checksum":4050987047,"timestamp":"2024-06-01T17:52:38.346429Z"}]}
{"channel":"book","type":"update","data":[{"symbol":"ETH/GBP","bids":[],"asks":[{"price":2979.37,"qty":0.00000000},{"price":2980.95,"qty":0.22400000}],"checksum":3058098080,"timestamp":"2024-06-01T17:52:38.351874Z"}]}
{"channel":"book","type":"update","data":[{"symbol":"ETH/GBP","bids":[{"price":2977.97,"qty":0.00000000},{"price":2973.93,"qty":0.27474654}],"asks":[],"checksum":3234538404,"timestamp":"2024-06-01T17:52:38.356814Z"}]}
{"channel":"book","type":"update","data":[{"symbol":"ETH/GBP","bids":[{"price":2977.51,"qty":0.00000000},{"price":2973.67,"qty":0.34510000}],"asks":[],"checksum":519038722,"timestamp":"2024-06-01T17:52:38.361707Z"}]}
{"channel":"book","type":"update","data":[{"symbol":"ETH/GBP","bids":[{"price":2978.07,"qty":6.58600371}],"asks":[],"checksum":1105870889,"timestamp":"2024-06-01T17:52:38.409277Z"}]}
{"channel":"book","type":"update","data":[{"symbol":"ETH/GBP","bids":[{"price":2978.07,"qty":0.00000000},{"price":2973.67,"qty":0.34510000}],"asks":[],"checksum":519038722,"timestamp":"2024-06-01T17:52:38.414473Z"}]}
{"channel":"book","type":"update","data":[{"symbol":"ETH/GBP","bids":[],"asks":[{"price":2978.39,"qty":0.00000000},{"price":2981.05,"qty":0.27472973}],"checksum":3125807166,"timestamp":"2024-06-01T17:52:38.414503Z"}]}
{"channel":"book","type":"update","data":[{"symbol":"ETH/GBP","bids":[],"asks":[{"price":2978.43,"qty":6.58524018}],"checksum":3013642830,"timestamp":"2024-06-01T17:52:38.476206Z"}]}
{"channel":"book","type":"update","data":[{"symbol":"ETH/GBP","bids":[],"asks":[{"price":2978.43,"qty":0.00000000},{"price":2981.05,"qty":0.27472973}],"checksum":3125807166,"timestamp":"2024-06-01T17:52:38.492350Z"}]}
{"channel":"book","type":"update","data":[{"symbol":"ETH/GBP","bids":[],"asks":[{"price":2979.38,"qty":0.00000000},{"price":2981.15,"qty":1.41091270},{"price":2979.81,"qty":0.06977200}],"checksum":211449924,"timestamp":"2024-06-01T17:52:38.524635Z"}]}
{"channel":"book","type":"update","data":[{"symbol":"ETH/GBP","bids":[],"asks":[{"price":2979.78,"qty":1.31696899}],"checksum":3024925798,"timestamp":"2024-06-01T17:52:38.527615Z"}]}
{"channel":"book","type":"update","data":[{"symbol":"ETH/GBP","bids":[{"price":2978.07,"qty":6.58600449}],"asks":[],"checksum":4226271930,"timestamp":"2024-06-01T17:52:38.529479Z"}]}
{"channel":"book","type":"update","data":[{"symbol":"ETH/GBP","bids":[{"price":2977.61,"qty":13.17404686}],"asks":[],"checksum":1180014545,"timestamp":"2024-06-01T17:52:38.550067Z"}]}
{"channel":"book","type":"update","data":[{"symbol":"ETH/GBP","bids":[],"asks":[{"price":2979.76,"qty":13.16460980}],"checksum":1162202611,"timestamp":"2024-06-01T17:52:38.550098Z"}]}
{"channel":"book","type":"update","data":[{"symbol":"ETH/GBP","bids":[],"asks":[{"price":2979.73,"qty":1.31696899}],"checksum":3505092549,"timestamp":"2024-06-01T17:52:38.553170Z"}]}
{"channel":"book","type":"update","data":[{"symbol":"ETH/GBP","bids":[],"asks":[{"price":2979.76,"qty":0.00000000},{"price":2980.94,"qty":0.00775181}],"checksum":480849339,"timestamp":"2024-06-01T17:52:38.554634Z"}]}
{"channel":"book","type":"update","data":[{"symbol":"ETH/GBP","bids":[],"asks":[{"price":2979.78,"qty":0.00000000},{"price":2980.95,"qty":0.22400000}],"checksum":2297349668,"timestamp":"2024-06-01T17:52:38.556225Z"}]}
{"channel":"book","type":"update","data":[{"symbol":"ETH/GBP","bids":[{"price":2974.46,"qty":0.34510000}],"asks":[],"checksum":3841288051,"timestamp":"2024-06-01T17:52:38.598351Z"}]}
