{"channel":"book","type":"update","data":[{"symbol":"ETH/USDT","bids":[],"asks":[{"price":3800.26,"qty":0.72912968}],"checksum":666685287,"timestamp":"2024-06-01T17:52:19.592982Z"}]}
{"channel":"book","type":"update","data":[{"symbol":"ETH/USDT","bids":[],"asks":[{"price":3800.25,"qty":2.94745410}],"checksum":2039549179,"timestamp":"2024-06-01T17:52:19.593079Z"}]}
{"channel":"book","type":"update","data":[{"symbol":"ETH/USDT","bids":[{"price":3799.29,"qty":0.25000000}],"asks":[],"checksum":3297473762,"timestamp":"2024-06-01T17:52:20.087163Z"}]}
{"channel":"book","type":"update","data":[{"symbol":"ETH/USDT","bids":[],"asks":[{"price":3800.26,"qty":0.00000000},{"price":3800.96,"qty":2.63306005}],"checksum":3121436556,"timestamp":"2024-06-01T17:52:20.090163Z"}]}
{"channel":"book","type":"update","data":[{"symbol":"ETH/USDT","bids":[{"price":3799.27,"qty":0.00000000},{"price":3798.65,"qty":0.84627249}],"asks":[],"checksum":4202142245,"timestamp":"2024-06-01T17:52:20.091525Z"}]}
{"channel":"book","type":"update","data":[{"symbol":"ETH/USDT","bids":[{"price":3799.26,"qty":0.00000000},{"price":3798.64,"qty":0.00502641}],"asks":[],"checksum":49439391,"timestamp":"2024-06-01T17:52:20.096594Z"}]}
{"channel":"book","type":"update","data":[{"symbol":"ETH/USDT","bids":[{"price":3799.28,"qty":0.00000000},{"price":3798.63,"qty":5.19054309}],"asks":[],"checksum":1465710625,"timestamp":"2024-06-01T17:52:20.129011Z"}]}
{"channel":"book","type":"update","data":[{"symbol":"ETH/USDT","bids":[],"asks":[{"price":3800.25,"qty":2.60745410}],"checksum":158415805,"timestamp":"2024-06-01T17:52:20.131687Z"}]}
{"channel":"book","type":"update","data":[{"symbol":"ETH/USDT","bids":[],"asks":[{"price":3800.24,"qty":1.06912968}],"checksum":2880609996,"timestamp":"2024-06-01T17:52:20.131975Z"}]}
{"channel":"book","type":"update","data":[{"symbol":"ETH/USDT","bids":[{"price":3799.30,"qty":0.73120000}],"asks":[],"checksum":1566717036,"timestamp":"2024-06-01T17:52:20.262107Z"}]}
{"channel":"book","type":"update","data":[{"symbol":"ETH/USDT","bids":[{"price":3799.31,"qty":0.25000000}],"asks":[],"checksum":3923185252,"timestamp":"2024-06-01T17:52:20.273460Z"}]}
{"channel":"book","type":"update","data":[{"symbol":"ETH/USDT","bids":[{"price":3799.31,"qty":0.98120000}],"asks":[],"checksum":1559772004,"timestamp":"2024-06-01T17:52:20.289895Z"}]}
{"channel":"book","type":"update","data":[{"symbol":"ETH/USDT","bids":[{"price":3799.30,"qty":0.00000000},{"price":3798.64,"qty":0.00502641}],"asks":[],"checksum":2482200058,"timestamp":"2024-06-01T17:52:20.290800Z"}]}
{"channel":"book","type":"update","data":[{"symbol":"ETH/USDT","bids":[{"price":3799.32,"qty":0.73120000}],"asks":[],"checksum":2282465837,"timestamp":"2024-06-01T17:52:20.293498Z"}]}
{"channel":"book","type":"update","data":[{"symbol":"ETH/USDT","bids":[{"price":3799.31,"qty":0.73120000}],"asks":[],"checksum":540078287,"timestamp":"2024-06-01T17:52:20.588031Z"}]}
{"channel":"book","type":"update","data":[{"symbol":"ETH/USDT","bids":[{"price":3799.33,"qty":0.25000000}],"asks":[],"checksum":684002104,"timestamp":"2024-06-01T17:52:20.588194Z"}]}
{"channel":"book","type":"update","data":[{"symbol":"ETH/USDT","bids":[{"price":3799.31,"qty":0.00000000},{"price":3798.65,"qty":0.84627249}],"asks":[],"checksum":442626177,"timestamp":"2024-06-01T17:52:20.591654Z"}]}
{"channel":"book","type":"update","data":[{"symbol":"ETH/USDT","bids":[{"price":3799.40,"qty":0.73120000}],"asks":[],"checksum":552963238,"timestamp":"2024-06-01T17:52:20.592313Z"}]}
{"channel":"book","type":"update","data":[{"symbol":"ETH/USDT","bids":[{"price":3799.29,"qty":0.00000000},{"price":3798.65,"qty":0.84627249}],"asks":[],"checksum":105515541,"timestamp":"2024-06-01T17:52:20.593035Z"}]}
{"channel":"book","type":"update","data":[{"symbol":"ETH/USDT","bids":[{"price":3799.34,"qty":0.73120000}],"asks":[],"checksum":3029482316,"timestamp":"2024-06-01T17:52:20.595401Z"}]}
{"channel":"book","type":"update","data":[{"symbol":"ETH/USDT","bids":[],"asks":[{"price":3800.24,"qty":0.34000000}],"checksum":4120993610,"timestamp":"2024-06-01T17:52:20.658061Z"}]}
{"channel":"book","type":"update","data":[{"symbol":"ETH/USDT","bids":[],"asks":[{"price":3800.27,"qty":0.25000000}],"checksum":3290086367,"timestamp":"2024-06-01T17:52:20.663183Z"}]}
{"channel":"book","type":"update","data":[{"symbol":"ETH/USDT","bids":[{"price":3799.41,"qty":0.07902033}],"asks":[],"checksum":139036348,"timestamp":"2024-06-01T17:52:20.663392Z"}]}
{"channel":"book","type":"update","data":[{"symbol":"ETH/USDT","bids":[{"price":3799.41,"qty":0.00000000},{"price":3798.66,"qty":2.15500000}],"asks":[],"checksum":3290086367,"timestamp":"2024-06-01T17:52:20.667455Z"}]}
{"channel":"book","type":"update","data":[{"symbol":"ETH/USDT","bids":[],"asks":[{"price":3800.27,"qty":0.98120000}],"checksum":4120993610,"timestamp":"2024-06-01T17:52:20.674175Z"}]}
{"channel":"book","type":"update","data":[{"symbol":"ETH/USDT","bids":[],"asks":[{"price":3800.94,"qty":0.00000000},{"price":3801.01,"qty":5.00000000}],"checksum":739343,"timestamp":"2024-06-01T17:52:20.860576Z"}]}
{"channel":"book","type":"update","data":[{"symbol":"ETH/USDT","bids":[],"asks":[{"price":3800.92,"qty":0.48955613}],"checksum":153152849,"timestamp":"2024-06-01T17:52:20.863968Z"}]}
{"channel":"book","type":"update","data":[{"symbol":"ETH/USDT","bids":[],"asks":[{"price":3800.67,"qty":0.72912968}],"checksum":2237639460,"timestamp":"2024-06-01T17:52:21.088789Z"}]}
{"channel":"book","type":"update","data":[{"symbol":"ETH/USDT","bids":[],"asks":[{"price":3800.25,"qty":0.00000000},{"price":3800.96,"qty":2.63306005}],"checksum":1753408345,"timestamp":"2024-06-01T17:52:21.847125Z"}]}
{"channel":"book","type":"update","data":[{"symbol":"ETH/USDT","bids":[],"asks":[{"price":3800.93,"qty":0.00000000},{"price":3801.01,"qty":5.00000000}],"checksum":4011969832,"timestamp":"2024-06-01T17:52:21.847224Z"}]}
{"channel":"book","type":"update","data":[{"symbol":"ETH/USDT","bids":[],"asks":[{"price":3800.95,"qty":49.33603586}],"checksum":4155432825,"timestamp":"2024-06-01T17:52:21.851775Z"}]}
{"channel":"book","type":"update","data":[{"symbol":"ETH/USDT","bids":[],"asks":[{"price":3800.39,"qty":2.08726501}],"checksum":690124943,"timestamp":"2024-06-01T17:52:21.851908Z"}]}
{"channel":"book","type":"update","data":[{"symbol":"ETH/USDT","bids":[],"asks":[{"price":3800.23,"qty":1.04691728}],"checksum":250168384,"timestamp":"2024-06-01T17:52:21.851974Z"}]}
{"channel":"book","type":"update","data":[{"symbol":"ETH/USDT","bids":[],"asks":[{"price":3800.27,"qty":0.25000000}],"checksum":80875106,"timestamp":"2024-06-01T17:52:21.875226Z"}]}
{"channel":"book","type":"update","data":[{"symbol":"ETH/USDT","bids":[],"asks":[{"price":3800.27,"qty":0.98120000}],"checksum":250168384,"timestamp":"2024-06-01T17:52:21.895499Z"}]}
{"channel":"book","type":"update","data":[{"symbol":"ETH/USDT","bids":[],"asks":[{"price":3800.27,"qty":0.25000000}],"checksum":80875106,"timestamp":"2024-06-01T17:52:21.990157Z"}]}
{"channel":"book","type":"update","data":[{"symbol":"ETH/USDT","bids":[{"price":3798.67,"qty":0.00526743}],"asks":[],"checksum":325052587,"timestamp":"2024-06-01T17:52:22.173721Z"}]}
{"channel":"book","type":"update","data":[{"symbol":"ETH/USDT","bids":[],"asks":[{"price":3800.27,"qty":0.98120000}],"checksum":1406149808,"timestamp":"2024-06-01T17:52:22.363698Z"}]}
{"channel":"book","type":"update","data":[{"symbol":"ETH/USDT","bids":[],"asks":[{"price":3800.27,"qty":0.25000000}],"checksum":325052587,"timestamp":"2024-06-01T17:52:22.463220Z"}]}
{"channel":"book","type":"update","data":[{"symbol":"ETH/USDT","bids":[],"asks":[{"price":3800.92,"qty":0.00000000},{"price":3800.95,"qty":49.33603586}],"checksum":837123616,"timestamp":"2024-06-01T17:52:23.070145Z"}]}
{"channel":"book","type":"update","data":[{"symbol":"ETH/USDT","bids":[],"asks":[{"price":3800.94,"qty":0.43430165}],"checksum":654391392,"timestamp":"2024-06-01T17:52:23.071535Z"}]}
{"channel":"book","type":"update","data":[{"symbol":"ETH/USDT","bids":[],"asks":[{"price":3800.27,"qty":0.98120000}],"checksum":1737421947,"timestamp":"2024-06-01T17:52:23.075362Z"}]}
{"channel":"book","type":"update","data":[{"symbol":"ETH/USDT","bids":[],"asks":[{"price":3800.27,"qty":0.25000000}],"checksum":654391392,"timestamp":"2024-06-01T17:52:23.267758Z"}]}
{"channel":"book","type":"update","data":[{"symbol":"ETH/USDT","bids":[{"price":3799.41,"qty":1.31694353}],"asks":[],"checksum":38231881,"timestamp":"2024-06-01T17:52:23.292545Z"}]}
{"channel":"book","type":"update","data":[{"symbol":"ETH/USDT","bids":[{"price":3799.10,"qty":0.29500386}],"asks":[],"checksum":2616000143,"timestamp":"2024-06-01T17:52:23.296166Z"}]}
{"channel":"book","type":"update","data":[{"symbol":"ETH/USDT","bids":[{"price":3799.59,"qty":0.73120000}],"asks":[],"checksum":4099367755,"timestamp":"2024-06-01T17:52:23.297114Z"}]}
{"channel":"book","type":"update","data":[{"symbol":"ETH/USDT","bids":[{"price":3799.32,"qty":0.00000000},{"price":3798.77,"qty":1.31708923}],"asks":[],"checksum":1606191149,"timestamp":"2024-06-01T17:52:23.298275Z"}]}
{"channel":"book","type":"update","data":[{"symbol":"ETH/USDT","bids":[{"price":3799.42,"qty":0.07901166}],"asks":[],"checksum":3531146639,"timestamp":"2024-06-01T17:52:23.559891Z"}]}
{"channel":"book","type":"update","data":[{"symbol":"ETH/USDT","bids":[{"price":3799.24,"qty":0.00000000},{"price":3798.77,"qty":1.31708923}],"asks":[],"checksum":3010498038,"timestamp":"2024-06-01T17:52:23.579294Z"}]}
{"channel":"book","type":"update","data":[{"symbol":"ETH/USDT","bids":[{"price":3799.42,"qty":0.41901166}],"asks":[],"checksum":1712516926,"timestamp":"2024-06-01T17:52:23.579430Z"}]}
{"channel":"book","type":"update","data":[{"symbol":"ETH/USDT","bids":[],"asks":[{"price":3800.24,"qty":0.00000000},{"price":3800.95,"qty":49.33603586}],"checksum":2483800998,"timestamp":"2024-06-01T17:52:23.579481Z"}]}
{"channel":"book","type":"update","data":[{"symbol":"ETH/USDT","bids":[],"asks":[{"price":3800.23,"qty":0.00000000},{"price":3801.01,"qty":5.00000000}],"checksum":1991655801,"timestamp":"2024-06-01T17:52:24.253787Z"}]}
{"channel":"book","type":"update","data":[{"symbol":"ETH/USDT","bids":[],"asks":[{"price":3800.95,"qty":0.00000000},{"price":3801.02,"qty":0.84627249}],"checksum":1565768294,"timestamp":"2024-06-01T17:52:24.253801Z"}]}
{"channel":"book","type":"update","data":[{"symbol":"ETH/USDT","bids":[],"asks":[{"price":3801.00,"qty":46.30203142}],"checksum":549229115,"timestamp":"2024-06-01T17:52:24.258327Z"}]}
{"channel":"book","type":"update","data":[{"symbol":"ETH/USDT","bids":[],"asks":[{"price":3801.01,"qty":0.00000000},{"price":3801.02,"qty":0.84627249}],"checksum":2383332742,"timestamp":"2024-06-01T17:52:24.399735Z"}]}
{"channel":"book","type":"update","data":[{"symbol":"ETH/USDT","bids":[],"asks":[{"price":3800.27,"qty":0.00000000},{"price":3801.13,"qty":5.43232015}],"checksum":1917294245,"timestamp":"2024-06-01T17:52:24.400000Z"}]}
{"channel":"book","type":"update","data":[{"symbol":"ETH/USDT","bids":[],"asks":[{"price":3801.02,"qty":0.00000000},{"price":3801.15,"qty":0.73120000}],"checksum":2559271475,"timestamp":"2024-06-01T17:52:24.400132Z"}]}
{"channel":"book","type":"update","data":[{"symbol":"ETH/USDT","bids":[],"asks":[{"price":3801.13,"qty":0.00000000},{"price":3801.20,"qty":0.21133384}],"checksum":1635825823,"timestamp":"2024-06-01T17:52:24.400851Z"}]}
{"channel":"book","type":"update","data":[{"symbol":"ETH/USDT","bids":[{"price":3798.92,"qty":0.20145795}],"asks":[],"checksum":2985278469,"timestamp":"2024-06-01T17:52:24.427031Z"}]}
{"channel":"book","type":"update","data":[{"symbol":"ETH/USDT","bids":[{"price":3798.92,"qty":0.00000000},{"price":3798.77,"qty":1.31708923}],"asks":[],"checksum":1635825823,"timestamp":"2024-06-01T17:52:24.432626Z"}]}
{"channel":"book","type":"update","data":[{"symbol":"ETH/USDT","bids":[{"price":3798.92,"qty":0.20957538}],"asks":[],"checksum":3564482440,"timestamp":"2024-06-01T17:52:24.575482Z"}]}
{"channel":"book","type":"update","data":[{"symbol":"ETH/USDT","bids":[{"price":3798.92,"qty":0.00000000},{"price":3798.77,"qty":1.31708923}],"asks":[],"checksum":1635825823,"timestamp":"2024-06-01T17:52:24.581559Z"}]}
{"channel":"book","type":"update","data":[{"symbol":"ETH/USDT","bids":[{"price":3799.60,"qty":0.25000000}],"asks":[],"checksum":1759304800,"timestamp":"2024-06-01T17:52:24.586799Z"}]}
{"channel":"book","type":"update","data":[{"symbol":"ETH/USDT","bids":[],"asks":[{"price":3800.77,"qty":0.98120000}],"checksum":1197673480,"timestamp":"2024-06-01T17:52:24.586956Z"}]}
{"channel":"book","type":"update","data":[{"symbol":"ETH/USDT","bids":[],"asks":[{"price":3800.38,"qty":0.72912968}],"checksum":4069989502,"timestamp":"2024-06-01T17:52:24.588464Z"}]}
{"channel":"book","type":"update","data":[{"symbol":"ETH/USDT","bids":[{"price":3799.72,"qty":0.73120000}],"asks":[],"checksum":3977490988,"timestamp":"2024-06-01T17:52:24.590682Z"}]}
{"channel":"book","type":"update","data":[{"symbol":"ETH/USDT","bids":[{"price":3799.33,"qty":0.00000000},{"price":3798.91,"qty":0.06693358}],"asks":[],"checksum":3714367679,"timestamp":"2024-06-01T17:52:24.592466Z"}]}
{"channel":"book","type":"update","data":[{"symbol":"ETH/USDT","bids":[{"price":3799.40,"qty":0.00000000},{"price":3798.77,"qty":1.31708923}],"asks":[],"checksum":1138321113,"timestamp":"2024-06-01T17:52:24.592506Z"}]}
{"channel":"book","type":"update","data":[{"symbol":"ETH/USDT","bids":[{"price":3799.42,"qty":0.34000000}],"asks":[],"checksum":259684161,"timestamp":"2024-06-01T17:52:24.595232Z"}]}
{"channel":"book","type":"update","data":[{"symbol":"ETH/USDT","bids":[{"price":3798.92,"qty":0.19611074}],"asks":[],"checksum":4090308240,"timestamp":"2024-06-01T17:52:24.727624Z"}]}
{"channel":"book","type":"update","data":[{"symbol":"ETH/USDT","bids":[{"price":3798.92,"qty":0.00000000},{"price":3798.77,"qty":1.31708923}],"asks":[],"checksum":259684161,"timestamp":"2024-06-01T17:52:24.733025Z"}]}
{"channel":"book","type":"update","data":[{"symbol":"ETH/USDT","bids":[{"price":3798.92,"qty":0.19951585}],"asks":[],"checksum":136616101,"timestamp":"2024-06-01T17:52:24.876768Z"}]}
{"channel":"book","type":"update","data":[{"symbol":"ETH/USDT","bids":[{"price":3798.92,"qty":0.00000000},{"price":3798.77,"qty":1.31708923}],"asks":[],"checksum":259684161,"timestamp":"2024-06-01T17:52:24.883724Z"}]}
{"channel":"book","type":"update","data":[{"symbol":"ETH/USDT","bids":[{"price":3798.92,"qty":0.20199061}],"asks":[],"checksum":4131952347,"timestamp":"2024-06-01T17:52:25.028933Z"}]}
{"channel":"book","type":"update","data":[{"symbol":"ETH/USDT","bids":[{"price":3798.92,"qty":0.00000000},{"price":3798.77,"qty":1.31708923}],"asks":[],"checksum":259684161,"timestamp":"2024-06-01T17:52:25.035478Z"}]}
{"channel":"book","type":"update","data":[{"symbol":"ETH/USDT","bids":[],"asks":[{"price":3800.67,"qty":0.00000000},{"price":3801.20,"qty":0.21133384}],"checksum":1309897510,"timestamp":"2024-06-01T17:52:25.088840Z"}]}
{"channel":"book","type":"update","data":[{"symbol":"ETH/USDT","bids":[{"price":3799.72,"qty":0.00000000},{"price":3798.67,"qty":0.33082234}],"asks":[],"checksum":1657580396,"timestamp":"2024-06-01T17:52:25.120614Z"}]}
{"channel":"book","type":"update","data":[{"symbol":"ETH/USDT","bids":[{"price":3799.64,"qty":0.73120000}],"asks":[],"checksum":3136597855,"timestamp":"2024-06-01T17:52:25.124618Z"}]}
{"channel":"book","type":"update","data":[{"symbol":"ETH/USDT","bids":[{"price":3799.43,"qty":0.07901168}],"asks":[],"checksum":3362955802,"timestamp":"2024-06-01T17:52:25.125621Z"}]}
{"channel":"book","type":"update","data":[{"symbol":"ETH/USDT","bids":[{"price":3799.43,"qty":0.00000000},{"price":3798.77,"qty":1.31708923}],"asks":[],"checksum":3136597855,"timestamp":"2024-06-01T17:52:25.129369Z"}]}
{"channel":"book","type":"update","data":[{"symbol":"ETH/USDT","bids":[{"price":3798.92,"qty":0.21872281}],"asks":[],"checksum":3574539384,"timestamp":"2024-06-01T17:52:25.176397Z"}]}
{"channel":"book","type":"update","data":[{"symbol":"ETH/USDT","bids":[{"price":3798.92,"qty":0.00000000},{"price":3798.77,"qty":1.31708923}],"asks":[],"checksum":3136597855,"timestamp":"2024-06-01T17:52:25.182159Z"}]}
{"channel":"book","type":"update","data":[{"symbol":"ETH/USDT","bids":[{"price":3798.92,"qty":0.18327724}],"asks":[],"checksum":1979421509,"timestamp":"2024-06-01T17:52:25.325831Z"}]}
{"channel":"book","type":"update","data":[{"symbol":"ETH/USDT","bids":[{"price":3798.92,"qty":0.00000000},{"price":3798.77,"qty":1.31708923}],"asks":[],"checksum":3136597855,"timestamp":"2024-06-01T17:52:25.331552Z"}]}
{"channel":"book","type":"update","data":[{"symbol":"ETH/USDT","bids":[{"price":3798.91,"qty":0.28062384}],"asks":[],"checksum":2229840688,"timestamp":"2024-06-01T17:52:25.475748Z"}]}
{"channel":"book","type":"update","data":[{"symbol":"ETH/USDT","bids":[{"price":3798.91,"qty":0.06693358}],"asks":[],"checksum":3136597855,"timestamp":"2024-06-01T17:52:25.481638Z"}]}
{"channel":"book","type":"update","data":[{"symbol":"ETH/USDT","bids":[],"asks":[{"price":3800.94,"qty":0.00000000},{"price":3801.33,"qty":6.85575763}],"checksum":2291009226,"timestamp":"2024-06-01T17:52:25.484433Z"}]}
{"channel":"book","type":"update","data":[{"symbol":"ETH/USDT","bids":[],"asks":[{"price":3800.99,"qty":0.62281659}],"checksum":2207818641,"timestamp":"2024-06-01T17:52:25.486148Z"}]}
{"channel":"book","type":"update","data":[{"symbol":"ETH/USDT","bids":[{"price":3798.91,"qty":0.26949400}],"asks":[],"checksum":983644734,"timestamp":"2024-06-01T17:52:25.627306Z"}]}
{"channel":"book","type":"update","data":[{"symbol":"ETH/USDT","bids":[{"price":3798.91,"qty":0.06693358}],"asks":[],"checksum":2207818641,"timestamp":"2024-06-01T17:52:25.632472Z"}]}
{"channel":"book","type":"update","data":[{"symbol":"ETH/USDT","bids":[{"price":3798.91,"qty":0.26290961}],"asks":[],"checksum":4138255273,"timestamp":"2024-06-01T17:52:25.776647Z"}]}
{"channel":"book","type":"update","data":[{"symbol":"ETH/USDT","bids":[{"price":3798.91,"qty":0.06693358}],"asks":[],"checksum":2207818641,"timestamp":"2024-06-01T17:52:25.782654Z"}]}
{"channel":"book","type":"update","data":[{"symbol":"ETH/USDT","bids":[{"price":3798.91,"qty":0.25830033}],"asks":[],"checksum":3539867614,"timestamp":"2024-06-01T17:52:25.925882Z"}]}
{"channel":"book","type":"update","data":[{"symbol":"ETH/USDT","bids":[{"price":3798.91,"qty":0.06693358}],"asks":[],"checksum":2207818641,"timestamp":"2024-06-01T17:52:25.931909Z"}]}
{"channel":"book","type":"update","data":[{"symbol":"ETH/USDT","bids":[{"price":3798.91,"qty":0.25810961}],"asks":[],"checksum":2470293584,"timestamp":"2024-06-01T17:52:26.075796Z"}]}
{"channel":"book","type":"update","data":[{"symbol":"ETH/USDT","bids":[{"price":3798.91,"qty":0.06693358}],"asks":[],"checksum":2207818641,"timestamp":"2024-06-01T17:52:26.081548Z"}]}
{"channel":"book","type":"update","data":[{"symbol":"ETH/USDT","bids":[{"price":3798.97,"qty":0.19745602}],"asks":[],"checksum":2278121090,"timestamp":"2024-06-01T17:52:26.227281Z"}]}
{"channel":"book","type":"update","data":[{"symbol":"ETH/USDT","bids":[{"price":3798.97,"qty":0.00000000},{"price":3798.77,"qty":1.31708923}],"asks":[],"checksum":2207818641,"timestamp":"2024-06-01T17:52:26.233632Z"}]}
{"channel":"book","type":"update","data":[{"symbol":"ETH/USDT","bids":[{"price":3798.97,"qty":0.21189521}],"asks":[],"checksum":422648489,"timestamp":"2024-06-01T17:52:26.377339Z"}]}
{"channel":"book","type":"update","data":[{"symbol":"ETH/USDT","bids":[{"price":3798.97,"qty":0.00000000},{"price":3798.77,"qty":1.31708923}],"asks":[],"checksum":2207818641,"timestamp":"2024-06-01T17:52:26.384574Z"}]}
{"channel":"book","type":"update","data":[{"symbol":"ETH/USDT","bids":[{"price":3798.97,"qty":0.21641404}],"asks":[],"checksum":4039822942,"timestamp":"2024-06-01T17:52:26.527411Z"}]}
{"channel":"book","type":"update","data":[{"symbol":"ETH/USDT","bids":[{"price":3798.97,"qty":0.00000000},{"price":3798.77,"qty":1.31708923}],"asks":[],"checksum":2207818641,"timestamp":"2024-06-01T17:52:26.533399Z"}]}
{"channel":"book","type":"update","data":[{"symbol":"ETH/USDT","bids":[],"asks":[{"price":3800.39,"qty":0.00000000},{"price":3801.33,"qty":6.85575763}],"checksum":2148072607,"timestamp":"2024-06-01T17:52:26.638690Z"}]}
{"channel":"book","type":"update","data":[{"symbol":"ETH/USDT","bids":[],"asks":[{"price":3801.00,"qty":0.00000000},{"price":3801.37,"qty":9.37995221}],"checksum":4152310414,"timestamp":"2024-06-01T17:52:26.638893Z"}]}
{"channel":"book","type":"update","data":[{"symbol":"ETH/USDT","bids":[],"asks":[{"price":3800.37,"qty":1.56707936}],"checksum":1398025858,"timestamp":"2024-06-01T17:52:26.643555Z"}]}
{"channel":"book","type":"update","data":[{"symbol":"ETH/USDT","bids":[],"asks":[{"price":3801.32,"qty":64.95823562}],"checksum":4173143929,"timestamp":"2024-06-01T17:52:26.643630Z"}]}
{"channel":"book","type":"update","data":[{"symbol":"ETH/USDT","bids":[],"asks":[{"price":3800.39,"qty":0.72912968}],"checksum":1470343225,"timestamp":"2024-06-01T17:52:26.643842Z"}]}
{"channel":"book","type":"update","data":[{"symbol":"ETH/USDT","bids":[],"asks":[{"price":3800.38,"qty":0.00000000},{"price":3801.32,"qty":64.95823562}],"checksum":738580067,"timestamp":"2024-06-01T17:52:26.643877Z"}]}
{"channel":"book","type":"update","data":[{"symbol":"ETH/USDT","bids":[{"price":3798.97,"qty":0.20754792}],"asks":[],"checksum":3158683033,"timestamp":"2024-06-01T17:52:26.677745Z"}]}
{"channel":"book","type":"update","data":[{"symbol":"ETH/USDT","bids":[],"asks":[{"price":3800.36,"qty":0.72912968}],"checksum":3107101788,"timestamp":"2024-06-01T17:52:27.088354Z"}]}
{"channel":"book","type":"update","data":[{"symbol":"ETH/USDT","bids":[],"asks":[{"price":3800.39,"qty":0.00000000},{"price":3801.32,"qty":64.95823562}],"checksum":3542773032,"timestamp":"2024-06-01T17:52:27.587937Z"}]}
{"channel":"book","type":"update","data":[{"symbol":"ETH/USDT","bids":[],"asks":[{"price":3800.99,"qty":0.00000000},{"price":3801.33,"qty":6.85575763}],"checksum":4019647433,"timestamp":"2024-06-01T17:52:27.799163Z"}]}
{"channel":"book","type":"update","data":[{"symbol":"ETH/USDT","bids":[],"asks":[{"price":3801.31,"qty":0.52205855}],"checksum":559509556,"timestamp":"2024-06-01T17:52:27.800748Z"}]}
{"channel":"book","type":"update","data":[{"symbol":"ETH/USDT","bids":[],"asks":[{"price":3800.37,"qty":0.00000000},{"price":3801.33,"qty":6.85575763}],"checksum":3116990769,"timestamp":"2024-06-01T17:52:29.098081Z"}]}
{"channel":"book","type":"update","data":[{"symbol":"ETH/USDT","bids":[],"asks":[{"price":3801.32,"qty":0.00000000},{"price":3801.37,"qty":9.37995221}],"checksum":3847067720,"timestamp":"2024-06-01T17:52:29.098269Z"}]}
{"channel":"book","type":"update","data":[{"symbol":"ETH/USDT","bids":[],"asks":[{"price":3800.36,"qty":0.00000000},{"price":3801.51,"qty":5.00000000}],"checksum":2005918321,"timestamp":"2024-06-01T17:52:29.102661Z"}]}
{"channel":"book","type":"update","data":[{"symbol":"ETH/USDT","bids":[],"asks":[{"price":3800.39,"qty":0.72912968}],"checksum":2962285175,"timestamp":"2024-06-01T17:52:29.102821Z"}]}
{"channel":"book","type":"update","data":[{"symbol":"ETH/USDT","bids":[],"asks":[{"price":3800.35,"qty":1.04690480}],"checksum":4125464199,"timestamp":"2024-06-01T17:52:29.102933Z"}]}
{"channel":"book","type":"update","data":[{"symbol":"ETH/USDT","bids":[],"asks":[{"price":3801.30,"qty":52.54411770}],"checksum":3598468646,"timestamp":"2024-06-01T17:52:29.103009Z"}]}
{"channel":"book","type":"update","data":[{"symbol":"ETH/USDT","bids":[],"asks":[{"price":3800.34,"qty":0.72912968}],"checksum":2511028726,"timestamp":"2024-06-01T17:52:29.590501Z"}]}
{"channel":"book","type":"update","data":[{"symbol":"ETH/USDT","bids":[{"price":3799.65,"qty":0.25000000}],"asks":[],"checksum":561513107,"timestamp":"2024-06-01T17:52:30.085773Z"}]}
{"channel":"book","type":"update","data":[{"symbol":"ETH/USDT","bids":[],"asks":[{"price":3800.39,"qty":0.00000000},{"price":3801.31,"qty":0.52205855}],"checksum":1073287099,"timestamp":"2024-06-01T17:52:30.088323Z"}]}
{"channel":"book","type":"update","data":[{"symbol":"ETH/USDT","bids":[{"price":3799.59,"qty":0.00000000},{"price":3798.91,"qty":0.06693358}],"asks":[],"checksum":1298222083,"timestamp":"2024-06-01T17:52:30.089468Z"}]}
{"channel":"book","type":"update","data":[{"symbol":"ETH/USDT","bids":[{"price":3799.82,"qty":0.73120000}],"asks":[],"checksum":1196135765,"timestamp":"2024-06-01T17:52:30.089490Z"}]}
{"channel":"book","type":"update","data":[{"symbol":"ETH/USDT","bids":[{"price":3799.60,"qty":0.00000000},{"price":3798.91,"qty":0.06693358}],"asks":[],"checksum":3512918920,"timestamp":"2024-06-01T17:52:30.090106Z"}]}
{"channel":"book","type":"update","data":[{"symbol":"ETH/USDT","bids":[{"price":3799.72,"qty":0.73120000}],"asks":[],"checksum":2188021612,"timestamp":"2024-06-01T17:52:30.091757Z"}]}
{"channel":"book","type":"update","data":[{"symbol":"ETH/USDT","bids":[],"asks":[{"price":3801.31,"qty":0.00000000},{"price":3801.37,"qty":9.37995221}],"checksum":247193982,"timestamp":"2024-06-01T17:52:30.147021Z"}]}
{"channel":"book","type":"update","data":[{"symbol":"ETH/USDT","bids":[],"asks":[{"price":3801.29,"qty":0.65206885}],"checksum":2488404871,"timestamp":"2024-06-01T17:52:30.149598Z"}]}
{"channel":"book","type":"update","data":[{"symbol":"ETH/USDT","bids":[],"asks":[{"price":3800.51,"qty":0.00000000},{"price":3801.37,"qty":9.37995221}],"checksum":1760727653,"timestamp":"2024-06-01T17:52:30.763365Z"}]}
{"channel":"book","type":"update","data":[{"symbol":"ETH/USDT","bids":[],"asks":[{"price":3800.77,"qty":0.25000000}],"checksum":468850317,"timestamp":"2024-06-01T17:52:30.763451Z"}]}
{"channel":"book","type":"update","data":[{"symbol":"ETH/USDT","bids":[],"asks":[{"price":3800.34,"qty":0.00000000},{"price":3801.43,"qty":6.85559494}],"checksum":2128010944,"timestamp":"2024-06-01T17:52:30.766068Z"}]}
{"channel":"book","type":"update","data":[{"symbol":"ETH/USDT","bids":[{"price":3799.42,"qty":0.00000000},{"price":3798.91,"qty":0.06693358}],"asks":[],"checksum":184435631,"timestamp":"2024-06-01T17:52:30.768802Z"}]}
{"channel":"book","type":"update","data":[{"symbol":"ETH/USDT","bids":[{"price":3799.74,"qty":0.34000000}],"asks":[],"checksum":1665907931,"timestamp":"2024-06-01T17:52:30.768904Z"}]}
{"channel":"book","type":"update","data":[{"symbol":"ETH/USDT","bids":[{"price":3798.96,"qty":0.73120000}],"asks":[],"checksum":4294787961,"timestamp":"2024-06-01T17:52:30.775138Z"}]}
{"channel":"book","type":"update","data":[{"symbol":"ETH/USDT","bids":[],"asks":[{"price":3800.40,"qty":0.00000000},{"price":3801.51,"qty":5.00000000}],"checksum":94645282,"timestamp":"2024-06-01T17:52:30.776575Z"}]}
{"channel":"book","type":"update","data":[{"symbol":"ETH/USDT","bids":[],"asks":[{"price":3801.43,"qty":0.00000000},{"price":3801.52,"qty":0.84627249}],"checksum":3292838223,"timestamp":"2024-06-01T17:52:30.782365Z"}]}
{"channel":"book","type":"update","data":[{"symbol":"ETH/USDT","bids":[{"price":3799.65,"qty":2.88396315}],"asks":[],"checksum":1111207577,"timestamp":"2024-06-01T17:52:30.782866Z"}]}
{"channel":"book","type":"update","data":[{"symbol":"ETH/USDT","bids":[],"asks":[{"price":3800.76,"qty":2.63319882}],"checksum":1794893968,"timestamp":"2024-06-01T17:52:30.782911Z"}]}
{"channel":"book","type":"update","data":[{"symbol":"ETH/USDT","bids":[{"price":3799.74,"qty":0.00000000},{"price":3798.91,"qty":0.06693358}],"asks":[],"checksum":19913893,"timestamp":"2024-06-01T17:52:30.786310Z"}]}
{"channel":"book","type":"update","data":[{"symbol":"ETH/USDT","bids":[{"price":3799.87,"qty":0.34000000}],"asks":[],"checksum":4225686743,"timestamp":"2024-06-01T17:52:30.786764Z"}]}
{"channel":"book","type":"update","data":[{"symbol":"ETH/USDT","bids":[],"asks":[{"price":3801.51,"qty":11.85545034}],"checksum":1485457157,"timestamp":"2024-06-01T17:52:30.786989Z"}]}
{"channel":"book","type":"update","data":[{"symbol":"ETH/USDT","bids":[{"price":3799.88,"qty":0.73120000}],"asks":[],"checksum":2975871646,"timestamp":"2024-06-01T17:52:30.790226Z"}]}
{"channel":"book","type":"update","data":[{"symbol":"ETH/USDT","bids":[{"price":3799.64,"qty":0.00000000},{"price":3798.96,"qty":0.73120000}],"asks":[],"checksum":4026389270,"timestamp":"2024-06-01T17:52:30.790563Z"}]}
{"channel":"book","type":"update","data":[{"symbol":"ETH/USDT","bids":[{"price":3799.88,"qty":0.81020027}],"asks":[],"checksum":1095533929,"timestamp":"2024-06-01T17:52:30.792844Z"}]}
{"channel":"book","type":"update","data":[{"symbol":"ETH/USDT","bids":[{"price":3799.88,"qty":2.12705015}],"asks":[],"checksum":3967531767,"timestamp":"2024-06-01T17:52:30.793766Z"}]}
{"channel":"book","type":"update","data":[{"symbol":"ETH/USDT","bids":[],"asks":[{"price":3801.20,"qty":0.00000000},{"price":3801.52,"qty":0.84627249}],"checksum":3538412236,"timestamp":"2024-06-01T17:52:30.794756Z"}]}
{"channel":"book","type":"update","data":[{"symbol":"ETH/USDT","bids":[],"asks":[{"price":3801.42,"qty":0.18177610}],"checksum":3534229322,"timestamp":"2024-06-01T17:52:30.796722Z"}]}
{"channel":"book","type":"update","data":[{"symbol":"ETH/USDT","bids":[{"price":3799.41,"qty":0.00000000},{"price":3798.91,"qty":0.06693358}],"asks":[],"checksum":2819669575,"timestamp":"2024-06-01T17:52:30.797538Z"}]}
{"channel":"book","type":"update","data":[{"symbol":"ETH/USDT","bids":[],"asks":[{"price":3801.42,"qty":0.00000000},{"price":3801.52,"qty":0.84627249}],"checksum":2590305508,"timestamp":"2024-06-01T17:52:30.804324Z"}]}
{"channel":"book","type":"update","data":[{"symbol":"ETH/USDT","bids":[],"asks":[{"price":3801.51,"qty":5.00000000}],"checksum":2434841688,"timestamp":"2024-06-01T17:52:30.811231Z"}]}
{"channel":"book","type":"update","data":[{"symbol":"ETH/USDT","bids":[{"price":3798.97,"qty":0.00000000},{"price":3798.82,"qty":0.92625361}],"asks":[],"checksum":2156374128,"timestamp":"2024-06-01T17:52:30.833592Z"}]}
{"channel":"book","type":"update","data":[{"symbol":"ETH/USDT","bids":[{"price":3799.19,"qty":0.21834302}],"asks":[],"checksum":2020170330,"timestamp":"2024-06-01T17:52:30.834194Z"}]}
{"channel":"book","type":"update","data":[{"symbol":"ETH/USDT","bids":[{"price":3799.19,"qty":0.00000000},{"price":3798.82,"qty":0.92625361}],"asks":[],"checksum":2156374128,"timestamp":"2024-06-01T17:52:30.840012Z"}]}
{"channel":"book","type":"update","data":[{"symbol":"ETH/USDT","bids":[{"price":3799.10,"qty":0.00000000},{"price":3798.77,"qty":1.31708923}],"asks":[],"checksum":2706034523,"timestamp":"2024-06-01T17:52:30.840276Z"}]}
{"channel":"book","type":"update","data":[{"symbol":"ETH/USDT","bids":[{"price":3799.63,"qty":0.29500386}],"asks":[],"checksum":4100257639,"timestamp":"2024-06-01T17:52:30.840485Z"}]}
{"channel":"book","type":"update","data":[{"symbol":"ETH/USDT","bids":[{"price":3799.88,"qty":2.04804988}],"asks":[],"checksum":2332548027,"timestamp":"2024-06-01T17:52:30.840637Z"}]}
{"channel":"book","type":"update","data":[{"symbol":"ETH/USDT","bids":[],"asks":[{"price":3801.51,"qty":0.00000000},{"price":3801.53,"qty":0.73120000}],"checksum":1011198797,"timestamp":"2024-06-01T17:52:30.844957Z"}]}
{"channel":"book","type":"update","data":[{"symbol":"ETH/USDT","bids":[],"asks":[{"price":3800.77,"qty":0.00000000},{"price":3801.64,"qty":5.26500000}],"checksum":1110788209,"timestamp":"2024-06-01T17:52:30.845009Z"}]}
{"channel":"book","type":"update","data":[{"symbol":"ETH/USDT","bids":[],"asks":[{"price":3801.52,"qty":0.00000000},{"price":3801.71,"qty":0.68800000}],"checksum":653799017,"timestamp":"2024-06-01T17:52:30.845094Z"}]}
{"channel":"book","type":"update","data":[{"symbol":"ETH/USDT","bids":[],"asks":[{"price":3801.37,"qty":0.00000000},{"price":3801.75,"qty":6.85501657}],"checksum":3257709103,"timestamp":"2024-06-01T17:52:30.853048Z"}]}
{"channel":"book","type":"update","data":[{"symbol":"ETH/USDT","bids":[{"price":3799.10,"qty":0.39451602}],"asks":[],"checksum":1438521843,"timestamp":"2024-06-01T17:52:30.858918Z"}]}
{"channel":"book","type":"update","data":[{"symbol":"ETH/USDT","bids":[],"asks":[{"price":3801.09,"qty":2.13500000}],"checksum":3595972934,"timestamp":"2024-06-01T17:52:30.863480Z"}]}
{"channel":"book","type":"update","data":[{"symbol":"ETH/USDT","bids":[{"price":3799.88,"qty":2.29804988}],"asks":[],"checksum":2108870845,"timestamp":"2024-06-01T17:52:30.879147Z"}]}
{"channel":"book","type":"update","data":[{"symbol":"ETH/USDT","bids":[{"price":3798.91,"qty":0.00000000},{"price":3798.82,"qty":0.92625361}],"asks":[],"checksum":3187828375,"timestamp":"2024-06-01T17:52:30.882826Z"}]}
{"channel":"book","type":"update","data":[{"symbol":"ETH/USDT","bids":[],"asks":[{"price":3801.12,"qty":0.72912968}],"checksum":1369405048,"timestamp":"2024-06-01T17:52:30.883462Z"}]}
{"channel":"book","type":"update","data":[{"symbol":"ETH/USDT","bids":[{"price":3799.88,"qty":2.36498346}],"asks":[],"checksum":1070384428,"timestamp":"2024-06-01T17:52:30.883818Z"}]}
{"channel":"book","type":"update","data":[{"symbol":"ETH/USDT","bids":[{"price":3799.24,"qty":5.00000000}],"asks":[],"checksum":1274006237,"timestamp":"2024-06-01T17:52:30.890251Z"}]}
{"channel":"book","type":"update","data":[{"symbol":"ETH/USDT","bids":[{"price":3799.26,"qty":0.84627249}],"asks":[],"checksum":369756768,"timestamp":"2024-06-01T17:52:30.894986Z"}]}
{"channel":"book","type":"update","data":[{"symbol":"ETH/USDT","bids":[{"price":3799.65,"qty":2.63396315}],"asks":[],"checksum":444341134,"timestamp":"2024-06-01T17:52:30.916866Z"}]}
{"channel":"book","type":"update","data":[{"symbol":"ETH/USDT","bids":[{"price":3799.88,"qty":2.81498346}],"asks":[],"checksum":3684522528,"timestamp":"2024-06-01T17:52:30.958383Z"}]}
{"channel":"book","type":"update","data":[{"symbol":"ETH/USDT","bids":[],"asks":[{"price":3801.18,"qty":0.25000000}],"checksum":149135903,"timestamp":"2024-06-01T17:52:30.964568Z"}]}
{"channel":"book","type":"update","data":[{"symbol":"ETH/USDT","bids":[{"price":3799.88,"qty":2.08378346}],"asks":[],"checksum":939867401,"timestamp":"2024-06-01T17:52:30.980142Z"}]}
{"channel":"book","type":"update","data":[{"symbol":"ETH/USDT","bids":[{"price":3799.82,"qty":0.00000000},{"price":3798.97,"qty":0.30661093}],"asks":[],"checksum":949098904,"timestamp":"2024-06-01T17:52:30.980825Z"}]}
{"channel":"book","type":"update","data":[{"symbol":"ETH/USDT","bids":[{"price":3799.72,"qty":0.00000000},{"price":3798.96,"qty":0.73120000}],"asks":[],"checksum":272843226,"timestamp":"2024-06-01T17:52:30.981008Z"}]}
{"channel":"book","type":"update","data":[{"symbol":"ETH/USDT","bids":[],"asks":[{"price":3800.65,"qty":0.73120000}],"checksum":3732741476,"timestamp":"2024-06-01T17:52:30.981899Z"}]}
{"channel":"book","type":"update","data":[{"symbol":"ETH/USDT","bids":[{"price":3799.34,"qty":0.00000000},{"price":3798.82,"qty":0.72912968}],"asks":[],"checksum":139879950,"timestamp":"2024-06-01T17:52:30.984558Z"}]}
{"channel":"book","type":"update","data":[{"symbol":"ETH/USDT","bids":[],"asks":[{"price":3799.89,"qty":0.73541065}],"checksum":3610328547,"timestamp":"2024-06-01T17:52:30.987487Z"}]}
{"channel":"book","type":"update","data":[{"symbol":"ETH/USDT","bids":[{"price":3799.88,"qty":2.01684988}],"asks":[],"checksum":3666894902,"timestamp":"2024-06-01T17:52:30.987516Z"}]}
{"channel":"book","type":"update","data":[{"symbol":"ETH/USDT","bids":[{"price":3798.96,"qty":0.00000000},{"price":3798.77,"qty":1.31708923}],"asks":[],"checksum":3083133770,"timestamp":"2024-06-01T17:52:30.987856Z"}]}
{"channel":"book","type":"update","data":[{"symbol":"ETH/USDT","bids":[],"asks":[{"price":3799.89,"qty":1.46661065}],"checksum":3416940224,"timestamp":"2024-06-01T17:52:30.988087Z"}]}
{"channel":"book","type":"update","data":[{"symbol":"ETH/USDT","bids":[{"price":3798.82,"qty":0.00000000},{"price":3798.67,"qty":0.16356018}],"asks":[],"checksum":3288033923,"timestamp":"2024-06-01T17:52:30.988586Z"}]}
{"channel":"book","type":"update","data":[{"symbol":"ETH/USDT","bids":[{"price":3799.88,"qty":1.76684988}],"asks":[],"checksum":546291033,"timestamp":"2024-06-01T17:52:30.990050Z"}]}
{"channel":"book","type":"update","data":[{"symbol":"ETH/USDT","bids":[{"price":3799.24,"qty":0.00000000},{"price":3798.51,"qty":0.73120000}],"asks":[],"checksum":820693224,"timestamp":"2024-06-01T17:52:30.991590Z"}]}
{"channel":"book","type":"update","data":[{"symbol":"ETH/USDT","bids":[{"price":3799.26,"qty":0.00000000},{"price":3798.48,"qty":0.02386706}],"asks":[],"checksum":3184370352,"timestamp":"2024-06-01T17:52:30.991835Z"}]}
{"channel":"book","type":"update","data":[{"symbol":"ETH/USDT","bids":[{"price":3799.65,"qty":0.00000000},{"price":3798.47,"qty":24.61091525}],"asks":[],"checksum":3743002714,"timestamp":"2024-06-01T17:52:30.992727Z"}]}
{"channel":"book","type":"update","data":[{"symbol":"ETH/USDT","bids":[{"price":3799.01,"qty":0.19712973}],"asks":[],"checksum":1382046940,"timestamp":"2024-06-01T17:52:30.995170Z"}]}
{"channel":"book","type":"update","data":[{"symbol":"ETH/USDT","bids":[{"price":3799.87,"qty":0.00000000},{"price":3798.47,"qty":24.61091525}],"asks":[],"checksum":3445201199,"timestamp":"2024-06-01T17:52:30.996377Z"}]}
{"channel":"book","type":"update","data":[{"symbol":"ETH/USDT","bids":[{"price":3799.88,"qty":0.45000000}],"asks":[],"checksum":4294656910,"timestamp":"2024-06-01T17:52:30.997219Z"}]}
{"channel":"book","type":"update","data":[{"symbol":"ETH/USDT","bids":[],"asks":[{"price":3801.09,"qty":0.00000000},{"price":3801.53,"qty":0.73120000}],"checksum":2955168529,"timestamp":"2024-06-01T17:52:31.003688Z"}]}
{"channel":"book","type":"update","data":[{"symbol":"ETH/USDT","bids":[{"price":3799.18,"qty":0.34000000}],"asks":[],"checksum":1827394146,"timestamp":"2024-06-01T17:52:31.003754Z"}]}
{"channel":"book","type":"update","data":[{"symbol":"ETH/USDT","bids":[],"asks":[{"price":3800.76,"qty":0.00000000},{"price":3801.64,"qty":5.26500000}],"checksum":513140180,"timestamp":"2024-06-01T17:52:31.004591Z"}]}
{"channel":"book","type":"update","data":[{"symbol":"ETH/USDT","bids":[],"asks":[{"price":3799.91,"qty":2.13500000}],"checksum":1669733066,"timestamp":"2024-06-01T17:52:31.007914Z"}]}
{"channel":"book","type":"update","data":[{"symbol":"ETH/USDT","bids":[{"price":3798.51,"qty":0.00000000},{"price":3798.47,"qty":24.61091525}],"asks":[],"checksum":28092439,"timestamp":"2024-06-01T17:52:31.009033Z"}]}
{"channel":"book","type":"update","data":[{"symbol":"ETH/USDT","bids":[],"asks":[{"price":3799.89,"qty":4.10166024}],"checksum":2448091464,"timestamp":"2024-06-01T17:52:31.012685Z"}]}
{"channel":"book","type":"update","data":[{"symbol":"ETH/USDT","bids":[{"price":3798.77,"qty":0.00000000},{"price":3798.38,"qty":5.17595381}],"asks":[],"checksum":2653484604,"timestamp":"2024-06-01T17:52:31.017520Z"}]}
{"channel":"book","type":"update","data":[{"symbol":"ETH/USDT","bids":[],"asks":[{"price":3800.43,"qty":0.25000000}],"checksum":3950223116,"timestamp":"2024-06-01T17:52:31.025312Z"}]}
{"channel":"book","type":"update","data":[{"symbol":"ETH/USDT","bids":[{"price":3799.10,"qty":0.00000000},{"price":3797.69,"qty":2.63532290}],"asks":[],"checksum":1378231931,"timestamp":"2024-06-01T17:52:31.030412Z"}]}
{"channel":"book","type":"update","data":[{"symbol":"ETH/USDT","bids":[{"price":3799.63,"qty":0.00000000},{"price":3797.54,"qty":0.73120000}],"asks":[],"checksum":875077478,"timestamp":"2024-06-01T17:52:31.031212Z"}]}
{"channel":"book","type":"update","data":[{"symbol":"ETH/USDT","bids":[{"price":3799.18,"qty":0.00000000},{"price":3797.34,"qty":0.70300000}],"asks":[],"checksum":1637873085,"timestamp":"2024-06-01T17:52:31.031319Z"}]}
{"channel":"book","type":"update","data":[{"symbol":"ETH/USDT","bids":[],"asks":[{"price":3799.89,"qty":4.44166024}],"checksum":610604778,"timestamp":"2024-06-01T17:52:31.039917Z"}]}
{"channel":"book","type":"update","data":[{"symbol":"ETH/USDT","bids":[{"price":3798.97,"qty":0.00000000},{"price":3796.95,"qty":0.73120000}],"asks":[],"checksum":3962669398,"timestamp":"2024-06-01T17:52:31.039959Z"}]}
{"channel":"book","type":"update","data":[{"symbol":"ETH/USDT","bids":[{"price":3797.87,"qty":0.12551658}],"asks":[],"checksum":3229751056,"timestamp":"2024-06-01T17:52:31.041658Z"}]}
{"channel":"book","type":"update","data":[{"symbol":"ETH/USDT","bids":[{"price":3797.98,"qty":0.73120000}],"asks":[],"checksum":1868212878,"timestamp":"2024-06-01T17:52:31.042180Z"}]}
{"channel":"book","type":"update","data":[{"symbol":"ETH/USDT","bids":[],"asks":[{"price":3800.77,"qty":1.59222281}],"checksum":185224946,"timestamp":"2024-06-01T17:52:31.049338Z"}]}
{"channel":"book","type":"update","data":[{"symbol":"ETH/USDT","bids":[{"price":3798.75,"qty":0.34000000}],"asks":[],"checksum":2453483120,"timestamp":"2024-06-01T17:52:31.052562Z"}]}
{"channel":"book","type":"update","data":[{"symbol":"ETH/USDT","bids":[],"asks":[{"price":3800.80,"qty":1.10898881}],"checksum":883631224,"timestamp":"2024-06-01T17:52:31.057054Z"}]}
{"channel":"book","type":"update","data":[{"symbol":"ETH/USDT","bids":[{"price":3797.98,"qty":0.00000000},{"price":3797.54,"qty":0.73120000}],"asks":[],"checksum":1456080627,"timestamp":"2024-06-01T17:52:31.058047Z"}]}
{"channel":"book","type":"update","data":[{"symbol":"ETH/USDT","bids":[{"price":3798.38,"qty":0.00000000},{"price":3796.95,"qty":0.73120000}],"asks":[],"checksum":557221545,"timestamp":"2024-06-01T17:52:31.067351Z"}]}
{"channel":"book","type":"update","data":[{"symbol":"ETH/USDT","bids":[{"price":3798.36,"qty":0.73120000}],"asks":[],"checksum":2856621492,"timestamp":"2024-06-01T17:52:31.068433Z"}]}
{"channel":"book","type":"update","data":[{"symbol":"ETH/USDT","bids":[],"asks":[{"price":3800.53,"qty":0.74200000}],"checksum":4093645222,"timestamp":"2024-06-01T17:52:31.072567Z"}]}
{"channel":"book","type":"update","data":[{"symbol":"ETH/USDT","bids":[{"price":3798.48,"qty":0.00000000},{"price":3796.95,"qty":0.73120000}],"asks":[],"checksum":1166912259,"timestamp":"2024-06-01T17:52:31.084487Z"}]}
{"channel":"book","type":"update","data":[{"symbol":"ETH/USDT","bids":[{"price":3798.36,"qty":0.00000000},{"price":3796.81,"qty":4.76511993}],"asks":[],"checksum":1796418047,"timestamp":"2024-06-01T17:52:31.085224Z"}]}
{"channel":"book","type":"update","data":[{"symbol":"ETH/USDT","bids":[{"price":3798.67,"qty":0.00000000},{"price":3796.70,"qty":4.32795000}],"asks":[],"checksum":2081255982,"timestamp":"2024-06-01T17:52:31.085915Z"}]}
{"channel":"book","type":"update","data":[{"symbol":"ETH/USDT","bids":[],"asks":[{"price":3799.89,"qty":4.69166024}],"checksum":2716758195,"timestamp":"2024-06-01T17:52:31.088455Z"}]}
{"channel":"book","type":"update","data":[{"symbol":"ETH/USDT","bids":[],"asks":[{"price":3800.55,"qty":1.70363569}],"checksum":3374419141,"timestamp":"2024-06-01T17:52:31.088610Z"}]}
{"channel":"book","type":"update","data":[{"symbol":"ETH/USDT","bids":[{"price":3799.88,"qty":0.00000000},{"price":3796.53,"qty":2.63612711}],"asks":[],"checksum":3791254004,"timestamp":"2024-06-01T17:52:31.090053Z"}]}
{"channel":"book","type":"update","data":[{"symbol":"ETH/USDT","bids":[{"price":3798.36,"qty":0.73120000}],"asks":[],"checksum":2138500444,"timestamp":"2024-06-01T17:52:31.090904Z"}]}
{"channel":"book","type":"update","data":[{"symbol":"ETH/USDT","bids":[],"asks":[{"price":3799.89,"qty":5.42078992}],"checksum":4053731362,"timestamp":"2024-06-01T17:52:31.095158Z"}]}
{"channel":"book","type":"update","data":[{"symbol":"ETH/USDT","bids":[{"price":3798.36,"qty":0.00000000},{"price":3796.53,"qty":2.63612711}],"asks":[],"checksum":1456096298,"timestamp":"2024-06-01T17:52:31.096100Z"}]}
{"channel":"book","type":"update","data":[{"symbol":"ETH/USDT","bids":[{"price":3797.87,"qty":0.00000000},{"price":3796.47,"qty":1.05333348}],"asks":[],"checksum":1778006738,"timestamp":"2024-06-01T17:52:31.096220Z"}]}
{"channel":"book","type":"update","data":[{"symbol":"ETH/USDT","bids":[{"price":3798.75,"qty":0.00000000},{"price":3796.38,"qty":0.73120000}],"asks":[],"checksum":399826874,"timestamp":"2024-06-01T17:52:31.100701Z"}]}
{"channel":"book","type":"update","data":[{"symbol":"ETH/USDT","bids":[{"price":3798.54,"qty":0.34000000}],"asks":[],"checksum":4273206374,"timestamp":"2024-06-01T17:52:31.101065Z"}]}
{"channel":"book","type":"update","data":[{"symbol":"ETH/USDT","bids":[{"price":3797.98,"qty":0.73120000}],"asks":[],"checksum":1911396579,"timestamp":"2024-06-01T17:52:31.106681Z"}]}
{"channel":"book","type":"update","data":[{"symbol":"ETH/USDT","bids":[],"asks":[{"price":3799.88,"qty":2.63380542}],"checksum":1439254885,"timestamp":"2024-06-01T17:52:31.108627Z"}]}
{"channel":"book","type":"update","data":[{"symbol":"ETH/USDT","bids":[],"asks":[{"price":3799.88,"qty":5.26761084}],"checksum":3140177968,"timestamp":"2024-06-01T17:52:31.108678Z"}]}
{"channel":"book","type":"update","data":[{"symbol":"ETH/USDT","bids":[],"asks":[{"price":3799.89,"qty":5.08078992}],"checksum":2495703600,"timestamp":"2024-06-01T17:52:31.112350Z"}]}
{"channel":"book","type":"update","data":[{"symbol":"ETH/USDT","bids":[{"price":3797.69,"qty":0.00000000},{"price":3796.47,"qty":1.05333348}],"asks":[],"checksum":753998194,"timestamp":"2024-06-01T17:52:31.118336Z"}]}
{"channel":"book","type":"update","data":[{"symbol":"ETH/USDT","bids":[],"asks":[{"price":3799.88,"qty":2.63380542}],"checksum":3256025127,"timestamp":"2024-06-01T17:52:31.118445Z"}]}
{"channel":"book","type":"update","data":[{"symbol":"ETH/USDT","bids":[{"price":3797.67,"qty":1.05076626}],"asks":[],"checksum":1467790986,"timestamp":"2024-06-01T17:52:31.118454Z"}]}
{"channel":"book","type":"update","data":[{"symbol":"ETH/USDT","bids":[],"asks":[{"price":3800.43,"qty":0.00000000},{"price":3801.12,"qty":0.72912968}],"checksum":2498892951,"timestamp":"2024-06-01T17:52:31.121563Z"}]}
{"channel":"book","type":"update","data":[{"symbol":"ETH/USDT","bids":[],"asks":[{"price":3801.12,"qty":0.00000000},{"price":3801.15,"qty":0.73120000}],"checksum":3724196948,"timestamp":"2024-06-01T17:52:31.122917Z"}]}
{"channel":"book","type":"update","data":[{"symbol":"ETH/USDT","bids":[{"price":3797.93,"qty":1.31674931}],"asks":[],"checksum":2988433430,"timestamp":"2024-06-01T17:52:31.125675Z"}]}
{"channel":"book","type":"update","data":[{"symbol":"ETH/USDT","bids":[],"asks":[{"price":3799.81,"qty":0.34000000}],"checksum":714106774,"timestamp":"2024-06-01T17:52:31.127187Z"}]}
{"channel":"book","type":"update","data":[{"symbol":"ETH/USDT","bids":[{"price":3797.26,"qty":2.63562138}],"asks":[],"checksum":51807437,"timestamp":"2024-06-01T17:52:31.128269Z"}]}
{"channel":"book","type":"update","data":[{"symbol":"ETH/USDT","bids":[],"asks":[{"price":3799.70,"qty":0.73120000}],"checksum":925116282,"timestamp":"2024-06-01T17:52:31.128840Z"}]}
{"channel":"book","type":"update","data":[{"symbol":"ETH/USDT","bids":[{"price":3797.94,"qty":1.31674931}],"asks":[],"checksum":715754223,"timestamp":"2024-06-01T17:52:31.129435Z"}]}
{"channel":"book","type":"update","data":[{"symbol":"ETH/USDT","bids":[],"asks":[{"price":3799.51,"qty":0.73120000}],"checksum":401702420,"timestamp":"2024-06-01T17:52:31.130403Z"}]}
{"channel":"book","type":"update","data":[{"symbol":"ETH/USDT","bids":[],"asks":[{"price":3799.88,"qty":0.00000000},{"price":3800.77,"qty":1.59222281}],"checksum":1304703064,"timestamp":"2024-06-01T17:52:31.132035Z"}]}
{"channel":"book","type":"update","data":[{"symbol":"ETH/USDT","bids":[{"price":3797.67,"qty":0.00000000},{"price":3796.81,"qty":4.76511993}],"asks":[],"checksum":1046599252,"timestamp":"2024-06-01T17:52:31.132888Z"}]}
{"channel":"book","type":"update","data":[{"symbol":"ETH/USDT","bids":[],"asks":[{"price":3799.89,"qty":6.22109337}],"checksum":3071765212,"timestamp":"2024-06-01T17:52:31.137743Z"}]}
{"channel":"book","type":"update","data":[{"symbol":"ETH/USDT","bids":[],"asks":[{"price":3799.89,"qty":3.58604378}],"checksum":3779207109,"timestamp":"2024-06-01T17:52:31.139462Z"}]}
{"channel":"book","type":"update","data":[{"symbol":"ETH/USDT","bids":[],"asks":[{"price":3799.84,"qty":2.63499067}],"checksum":3953823175,"timestamp":"2024-06-01T17:52:31.139546Z"}]}
{"channel":"book","type":"update","data":[{"symbol":"ETH/USDT","bids":[{"price":3798.54,"qty":0.00000000},{"price":3796.70,"qty":4.32795000}],"asks":[],"checksum":3813138754,"timestamp":"2024-06-01T17:52:31.140399Z"}]}
{"channel":"book","type":"update","data":[{"symbol":"ETH/USDT","bids":[],"asks":[{"price":3799.89,"qty":4.81258452}],"checksum":2070003513,"timestamp":"2024-06-01T17:52:31.141941Z"}]}
{"channel":"book","type":"update","data":[{"symbol":"ETH/USDT","bids":[{"price":3797.47,"qty":4.15961594}],"asks":[],"checksum":2722471272,"timestamp":"2024-06-01T17:52:31.144322Z"}]}
{"channel":"book","type":"update","data":[{"symbol":"ETH/USDT","bids":[{"price":3797.94,"qty":0.00000000},{"price":3796.70,"qty":4.32795000}],"asks":[],"checksum":3513501059,"timestamp":"2024-06-01T17:52:31.145815Z"}]}
{"channel":"book","type":"update","data":[{"symbol":"ETH/USDT","bids":[{"price":3797.93,"qty":0.00000000},{"price":3796.53,"qty":2.63612711}],"asks":[],"checksum":2600728953,"timestamp":"2024-06-01T17:52:31.149955Z"}]}
{"channel":"book","type":"update","data":[{"symbol":"ETH/USDT","bids":[],"asks":[{"price":3799.89,"qty":4.08138452}],"checksum":586493875,"timestamp":"2024-06-01T17:52:31.151943Z"}]}
{"channel":"book","type":"update","data":[{"symbol":"ETH/USDT","bids":[],"asks":[{"price":3799.87,"qty":0.25000000}],"checksum":3059856515,"timestamp":"2024-06-01T17:52:31.152874Z"}]}
{"channel":"book","type":"update","data":[{"symbol":"ETH/USDT","bids":[],"asks":[{"price":3799.89,"qty":5.91768445}],"checksum":3025927726,"timestamp":"2024-06-01T17:52:31.153512Z"}]}
{"channel":"book","type":"update","data":[{"symbol":"ETH/USDT","bids":[],"asks":[{"price":3799.81,"qty":0.00000000},{"price":3800.65,"qty":0.73120000}],"checksum":1827610626,"timestamp":"2024-06-01T17:52:31.156163Z"}]}
{"channel":"book","type":"update","data":[{"symbol":"ETH/USDT","bids":[],"asks":[{"price":3799.62,"qty":0.34000000}],"checksum":496310839,"timestamp":"2024-06-01T17:52:31.156721Z"}]}
{"channel":"book","type":"update","data":[{"symbol":"ETH/USDT","bids":[],"asks":[{"price":3799.87,"qty":5.51500000}],"checksum":2162074659,"timestamp":"2024-06-01T17:52:31.157243Z"}]}
{"channel":"book","type":"update","data":[{"symbol":"ETH/USDT","bids":[],"asks":[{"price":3799.69,"qty":0.72912968}],"checksum":2677864129,"timestamp":"2024-06-01T17:52:31.158088Z"}]}
{"channel":"book","type":"update","data":[{"symbol":"ETH/USDT","bids":[],"asks":[{"price":3799.51,"qty":1.46240000}],"checksum":3793409797,"timestamp":"2024-06-01T17:52:31.158142Z"}]}
{"channel":"book","type":"update","data":[{"symbol":"ETH/USDT","bids":[],"asks":[{"price":3799.89,"qty":7.02667326}],"checksum":1980384587,"timestamp":"2024-06-01T17:52:31.159211Z"}]}
{"channel":"book","type":"update","data":[{"symbol":"ETH/USDT","bids":[],"asks":[{"price":3799.70,"qty":0.00000000},{"price":3800.55,"qty":1.70363569}],"checksum":1122092880,"timestamp":"2024-06-01T17:52:31.164196Z"}]}
{"channel":"book","type":"update","data":[{"symbol":"ETH/USDT","bids":[],"asks":[{"price":3799.89,"qty":7.09360684}],"checksum":3808537698,"timestamp":"2024-06-01T17:52:31.169573Z"}]}
{"channel":"book","type":"update","data":[{"symbol":"ETH/USDT","bids":[],"asks":[{"price":3799.47,"qty":2.63495671}],"checksum":2602910667,"timestamp":"2024-06-01T17:52:31.172068Z"}]}
{"channel":"book","type":"update","data":[{"symbol":"ETH/USDT","bids":[],"asks":[{"price":3799.84,"qty":0.00000000},{"price":3800.55,"qty":1.70363569}],"checksum":2252267085,"timestamp":"2024-06-01T17:52:31.172116Z"}]}
{"channel":"book","type":"update","data":[{"symbol":"ETH/USDT","bids":[],"asks":[{"price":3799.62,"qty":0.00000000},{"price":3800.65,"qty":0.73120000}],"checksum":1247720872,"timestamp":"2024-06-01T17:52:31.174484Z"}]}
{"channel":"book","type":"update","data":[{"symbol":"ETH/USDT","bids":[],"asks":[{"price":3799.43,"qty":0.34000000}],"checksum":1207841598,"timestamp":"2024-06-01T17:52:31.174813Z"}]}
{"channel":"book","type":"update","data":[{"symbol":"ETH/USDT","bids":[],"asks":[{"price":3799.89,"qty":6.36447716}],"checksum":4124738494,"timestamp":"2024-06-01T17:52:31.181423Z"}]}
{"channel":"book","type":"update","data":[{"symbol":"ETH/USDT","bids":[],"asks":[{"price":3799.89,"qty":6.11447716}],"checksum":51730895,"timestamp":"2024-06-01T17:52:31.183965Z"}]}
{"channel":"book","type":"update","data":[{"symbol":"ETH/USDT","bids":[],"asks":[{"price":3800.55,"qty":0.00000000},{"price":3800.65,"qty":0.73120000}],"checksum":493848630,"timestamp":"2024-06-01T17:52:31.189302Z"}]}
{"channel":"book","type":"update","data":[{"symbol":"ETH/USDT","bids":[],"asks":[{"price":3799.89,"qty":7.81811285}],"checksum":1691638572,"timestamp":"2024-06-01T17:52:31.189376Z"}]}
{"channel":"book","type":"update","data":[{"symbol":"ETH/USDT","bids":[],"asks":[{"price":3800.32,"qty":5.00000000}],"checksum":204189019,"timestamp":"2024-06-01T17:52:31.192822Z"}]}
{"channel":"book","type":"update","data":[{"symbol":"ETH/USDT","bids":[],"asks":[{"price":3799.29,"qty":0.73120000}],"checksum":474173861,"timestamp":"2024-06-01T17:52:31.195976Z"}]}
{"channel":"book","type":"update","data":[{"symbol":"ETH/USDT","bids":[],"asks":[{"price":3799.10,"qty":0.73120000}],"checksum":636348779,"timestamp":"2024-06-01T17:52:31.196109Z"}]}
{"channel":"book","type":"update","data":[{"symbol":"ETH/USDT","bids":[{"price":3797.98,"qty":0.00000000},{"price":3796.47,"qty":1.05333348}],"asks":[],"checksum":382002250,"timestamp":"2024-06-01T17:52:31.204865Z"}]}
{"channel":"book","type":"update","data":[{"symbol":"ETH/USDT","bids":[],"asks":[{"price":3799.39,"qty":2.63491853}],"checksum":871191329,"timestamp":"2024-06-01T17:52:31.205881Z"}]}
{"channel":"book","type":"update","data":[{"symbol":"ETH/USDT","bids":[],"asks":[{"price":3799.47,"qty":0.00000000},{"price":3800.32,"qty":5.00000000}],"checksum":352973966,"timestamp":"2024-06-01T17:52:31.205901Z"}]}
{"channel":"book","type":"update","data":[{"symbol":"ETH/USDT","bids":[{"price":3797.47,"qty":0.00000000},{"price":3796.38,"qty":0.73120000}],"asks":[],"checksum":3313428398,"timestamp":"2024-06-01T17:52:31.208152Z"}]}
{"channel":"book","type":"update","data":[{"symbol":"ETH/USDT","bids":[],"asks":[{"price":3799.88,"qty":5.00000000}],"checksum":3609213918,"timestamp":"2024-06-01T17:52:31.208795Z"}]}
{"channel":"book","type":"update","data":[{"symbol":"ETH/USDT","bids":[],"asks":[{"price":3799.29,"qty":0.00000000},{"price":3800.32,"qty":5.00000000}],"checksum":3867021279,"timestamp":"2024-06-01T17:52:31.212731Z"}]}
{"channel":"book","type":"update","data":[{"symbol":"ETH/USDT","bids":[],"asks":[{"price":3799.51,"qty":0.73120000}],"checksum":3752994123,"timestamp":"2024-06-01T17:52:31.212797Z"}]}
{"channel":"book","type":"update","data":[{"symbol":"ETH/USDT","bids":[],"asks":[{"price":3799.10,"qty":1.46240000}],"checksum":3189018621,"timestamp":"2024-06-01T17:52:31.213148Z"}]}
{"channel":"book","type":"update","data":[{"symbol":"ETH/USDT","bids":[],"asks":[{"price":3799.09,"qty":0.72912968}],"checksum":1216248657,"timestamp":"2024-06-01T17:52:31.214276Z"}]}
{"channel":"book","type":"update","data":[{"symbol":"ETH/USDT","bids":[],"asks":[{"price":3799.50,"qty":0.25000000}],"checksum":1756340152,"timestamp":"2024-06-01T17:52:31.214664Z"}]}
{"channel":"book","type":"update","data":[{"symbol":"ETH/USDT","bids":[{"price":3797.26,"qty":0.00000000},{"price":3796.00,"qty":0.73120000}],"asks":[],"checksum":1200743771,"timestamp":"2024-06-01T17:52:31.216569Z"}]}
{"channel":"book","type":"update","data":[{"symbol":"ETH/USDT","bids":[{"price":3796.53,"qty":0.00000000},{"price":3795.62,"qty":0.73120000}],"asks":[],"checksum":4191609054,"timestamp":"2024-06-01T17:52:31.216609Z"}]}
{"channel":"book","type":"update","data":[{"symbol":"ETH/USDT","bids":[],"asks":[{"price":3799.21,"qty":0.34000000}],"checksum":1150006771,"timestamp":"2024-06-01T17:52:31.217448Z"}]}
{"channel":"book","type":"update","data":[{"symbol":"ETH/USDT","bids":[],"asks":[{"price":3799.43,"qty":0.00000000},{"price":3799.89,"qty":7.81811285}],"checksum":4053306467,"timestamp":"2024-06-01T17:52:31.217510Z"}]}
{"channel":"book","type":"update","data":[{"symbol":"ETH/USDT","bids":[],"asks":[{"price":3799.21,"qty":0.00000000},{"price":3799.91,"qty":2.13500000}],"checksum":661355767,"timestamp":"2024-06-01T17:52:31.218028Z"}]}
{"channel":"book","type":"update","data":[{"symbol":"ETH/USDT","bids":[],"asks":[{"price":3799.08,"qty":0.34000000}],"checksum":315981195,"timestamp":"2024-06-01T17:52:31.218871Z"}]}
{"channel":"book","type":"update","data":[{"symbol":"ETH/USDT","bids":[],"asks":[{"price":3799.88,"qty":5.84627249}],"checksum":1749012235,"timestamp":"2024-06-01T17:52:31.221851Z"}]}
{"channel":"book","type":"update","data":[{"symbol":"ETH/USDT","bids":[{"price":3795.94,"qty":2.63653260}],"asks":[],"checksum":2088105605,"timestamp":"2024-06-01T17:52:31.223452Z"}]}
{"channel":"book","type":"update","data":[{"symbol":"ETH/USDT","bids":[],"asks":[{"price":3799.10,"qty":4.09743445}],"checksum":372074622,"timestamp":"2024-06-01T17:52:31.224868Z"}]}
{"channel":"book","type":"update","data":[{"symbol":"ETH/USDT","bids":[{"price":3796.67,"qty":8.85436466}],"asks":[],"checksum":10887068,"timestamp":"2024-06-01T17:52:31.225489Z"}]}
{"channel":"book","type":"update","data":[{"symbol":"ETH/USDT","bids":[],"asks":[{"price":3799.39,"qty":0.00000000},{"price":3799.91,"qty":2.13500000}],"checksum":1033569981,"timestamp":"2024-06-01T17:52:31.226503Z"}]}
{"channel":"book","type":"update","data":[{"symbol":"ETH/USDT","bids":[],"asks":[{"price":3799.89,"qty":6.67780940}],"checksum":2463103319,"timestamp":"2024-06-01T17:52:31.236339Z"}]}
{"channel":"book","type":"update","data":[{"symbol":"ETH/USDT","bids":[],"asks":[{"price":3799.10,"qty":1.46240000}],"checksum":4170672044,"timestamp":"2024-06-01T17:52:31.236792Z"}]}
{"channel":"book","type":"update","data":[{"symbol":"ETH/USDT","bids":[],"asks":[{"price":3799.02,"qty":2.63533439}],"checksum":1244100349,"timestamp":"2024-06-01T17:52:31.236905Z"}]}
{"channel":"book","type":"update","data":[{"symbol":"ETH/USDT","bids":[],"asks":[{"price":3799.07,"qty":2.13500000}],"checksum":4182004980,"timestamp":"2024-06-01T17:52:31.240631Z"}]}
{"channel":"book","type":"update","data":[{"symbol":"ETH/USDT","bids":[],"asks":[{"price":3799.02,"qty":3.36653439}],"checksum":3916899947,"timestamp":"2024-06-01T17:52:31.246360Z"}]}
{"channel":"book","type":"update","data":[{"symbol":"ETH/USDT","bids":[],"asks":[{"price":3799.02,"qty":4.50683784}],"checksum":2378197564,"timestamp":"2024-06-01T17:52:31.248472Z"}]}
{"channel":"book","type":"update","data":[{"symbol":"ETH/USDT","bids":[{"price":3797.54,"qty":0.00000000},{"price":3795.94,"qty":2.63653260}],"asks":[],"checksum":1719226948,"timestamp":"2024-06-01T17:52:31.254365Z"}]}
{"channel":"book","type":"update","data":[{"symbol":"ETH/USDT","bids":[],"asks":[{"price":3799.08,"qty":0.00000000},{"price":3799.89,"qty":2.50597992}],"checksum":221208666,"timestamp":"2024-06-01T17:52:31.258381Z"}]}
{"channel":"book","type":"update","data":[{"symbol":"ETH/USDT","bids":[],"asks":[{"price":3799.02,"qty":4.84683784}],"checksum":733170763,"timestamp":"2024-06-01T17:52:31.261703Z"}]}
{"channel":"book","type":"update","data":[{"symbol":"ETH/USDT","bids":[],"asks":[{"price":3799.89,"qty":2.43904634}],"checksum":3641132926,"timestamp":"2024-06-01T17:52:31.274442Z"}]}
{"channel":"book","type":"update","data":[{"symbol":"ETH/USDT","bids":[],"asks":[{"price":3799.87,"qty":5.26500000}],"checksum":406789965,"timestamp":"2024-06-01T17:52:31.279430Z"}]}
{"channel":"book","type":"update","data":[{"symbol":"ETH/USDT","bids":[],"asks":[{"price":3799.09,"qty":0.97912968}],"checksum":317855446,"timestamp":"2024-06-01T17:52:31.279596Z"}]}
{"channel":"book","type":"update","data":[{"symbol":"ETH/USDT","bids":[],"asks":[{"price":3799.89,"qty":0.73541065}],"checksum":1802010004,"timestamp":"2024-06-01T17:52:31.285071Z"}]}
{"channel":"book","type":"update","data":[{"symbol":"ETH/USDT","bids":[],"asks":[{"price":3799.50,"qty":1.09627249}],"checksum":385937659,"timestamp":"2024-06-01T17:52:31.285330Z"}]}
{"channel":"book","type":"update","data":[{"symbol":"ETH/USDT","bids":[],"asks":[{"price":3799.02,"qty":6.66666127}],"checksum":3667954341,"timestamp":"2024-06-01T17:52:31.288003Z"}]}
{"channel":"book","type":"update","data":[{"symbol":"ETH/USDT","bids":[],"asks":[{"price":3799.68,"qty":5.00000000}],"checksum":1804305461,"timestamp":"2024-06-01T17:52:31.289772Z"}]}
{"channel":"book","type":"update","data":[{"symbol":"ETH/USDT","bids":[],"asks":[{"price":3799.69,"qty":0.00000000},{"price":3799.89,"qty":0.73541065}],"checksum":1116372612,"timestamp":"2024-06-01T17:52:31.290464Z"}]}
{"channel":"book","type":"update","data":[{"symbol":"ETH/USDT","bids":[{"price":3796.47,"qty":0.00000000},{"price":3795.62,"qty":0.73120000}],"asks":[],"checksum":1446045645,"timestamp":"2024-06-01T17:52:31.293361Z"}]}
{"channel":"book","type":"update","data":[{"symbol":"ETH/USDT","bids":[{"price":3798.47,"qty":0.00000000},{"price":3795.24,"qty":0.73120000}],"asks":[],"checksum":958381655,"timestamp":"2024-06-01T17:52:31.304165Z"}]}
{"channel":"book","type":"update","data":[{"symbol":"ETH/USDT","bids":[],"asks":[{"price":3799.02,"qty":6.91666127}],"checksum":2697081097,"timestamp":"2024-06-01T17:52:31.310860Z"}]}
{"channel":"book","type":"update","data":[{"symbol":"ETH/USDT","bids":[],"asks":[{"price":3799.50,"qty":0.84627249}],"checksum":1900315569,"timestamp":"2024-06-01T17:52:31.310936Z"}]}
{"channel":"book","type":"update","data":[{"symbol":"ETH/USDT","bids":[{"price":3797.26,"qty":1.31755430}],"asks":[],"checksum":2326352441,"timestamp":"2024-06-01T17:52:31.311356Z"}]}
{"channel":"book","type":"update","data":[{"symbol":"ETH/USDT","bids":[{"price":3797.03,"qty":0.34000000}],"asks":[],"checksum":1512367405,"timestamp":"2024-06-01T17:52:31.311841Z"}]}
{"channel":"book","type":"update","data":[{"symbol":"ETH/USDT","bids":[{"price":3797.07,"qty":1.31755430}],"asks":[],"checksum":2114726490,"timestamp":"2024-06-01T17:52:31.312407Z"}]}
{"channel":"book","type":"update","data":[{"symbol":"ETH/USDT","bids":[],"asks":[{"price":3799.88,"qty":5.00000000}],"checksum":4276355793,"timestamp":"2024-06-01T17:52:31.315888Z"}]}
{"channel":"book","type":"update","data":[{"symbol":"ETH/USDT","bids":[{"price":3797.03,"qty":0.00000000},{"price":3795.94,"qty":2.63653260}],"asks":[],"checksum":1385067081,"timestamp":"2024-06-01T17:52:31.316974Z"}]}
{"channel":"book","type":"update","data":[{"symbol":"ETH/USDT","bids":[{"price":3797.31,"qty":0.34000000}],"asks":[],"checksum":3450721110,"timestamp":"2024-06-01T17:52:31.317145Z"}]}
{"channel":"book","type":"update","data":[{"symbol":"ETH/USDT","bids":[],"asks":[{"price":3799.02,"qty":7.64579095}],"checksum":1277790795,"timestamp":"2024-06-01T17:52:31.323084Z"}]}
{"channel":"book","type":"update","data":[{"symbol":"ETH/USDT","bids":[],"asks":[{"price":3799.88,"qty":0.00000000},{"price":3800.48,"qty":0.73171449}],"checksum":3476697662,"timestamp":"2024-06-01T17:52:31.326460Z"}]}
{"channel":"book","type":"update","data":[{"symbol":"ETH/USDT","bids":[],"asks":[{"price":3799.38,"qty":5.00000000}],"checksum":2968783091,"timestamp":"2024-06-01T17:52:31.326598Z"}]}
{"channel":"book","type":"update","data":[{"symbol":"ETH/USDT","bids":[],"asks":[{"price":3799.09,"qty":0.72912968}],"checksum":3226342662,"timestamp":"2024-06-01T17:52:31.349397Z"}]}
{"channel":"book","type":"update","data":[{"symbol":"ETH/USDT","bids":[],"asks":[{"price":3799.09,"qty":0.00000000},{"price":3800.48,"qty":0.73171449}],"checksum":1221417471,"timestamp":"2024-06-01T17:52:31.355093Z"}]}
{"channel":"book","type":"update","data":[{"symbol":"ETH/USDT","bids":[],"asks":[{"price":3800.48,"qty":0.00000000},{"price":3800.53,"qty":0.74200000}],"checksum":3578559601,"timestamp":"2024-06-01T17:52:31.359850Z"}]}
{"channel":"book","type":"update","data":[{"symbol":"ETH/USDT","bids":[],"asks":[{"price":3799.68,"qty":0.00000000},{"price":3800.65,"qty":0.73120000}],"checksum":4156508889,"timestamp":"2024-06-01T17:52:31.361175Z"}]}
{"channel":"book","type":"update","data":[{"symbol":"ETH/USDT","bids":[{"price":3796.81,"qty":0.00000000},{"price":3795.94,"qty":2.63653260}],"asks":[],"checksum":2154964442,"timestamp":"2024-06-01T17:52:31.395595Z"}]}
{"channel":"book","type":"update","data":[{"symbol":"ETH/USDT","bids":[{"price":3795.94,"qty":0.00000000},{"price":3795.62,"qty":0.73120000}],"asks":[],"checksum":3596938320,"timestamp":"2024-06-01T17:52:31.473650Z"}]}
{"channel":"book","type":"update","data":[{"symbol":"ETH/USDT","bids":[{"price":3796.46,"qty":2.63617757}],"asks":[],"checksum":2213566501,"timestamp":"2024-06-01T17:52:31.478940Z"}]}
{"channel":"book","type":"update","data":[{"symbol":"ETH/USDT","bids":[],"asks":[{"price":3799.07,"qty":4.76936698}],"checksum":1746148407,"timestamp":"2024-06-01T17:52:31.479013Z"}]}
{"channel":"book","type":"update","data":[{"symbol":"ETH/USDT","bids":[],"asks":[{"price":3799.06,"qty":0.40000000}],"checksum":1844113006,"timestamp":"2024-06-01T17:52:31.501337Z"}]}
{"channel":"book","type":"update","data":[{"symbol":"ETH/USDT","bids":[],"asks":[{"price":3799.52,"qty":0.85200000}],"checksum":911142269,"timestamp":"2024-06-01T17:52:31.573231Z"}]}
{"channel":"book","type":"update","data":[{"symbol":"ETH/USDT","bids":[{"price":3799.01,"qty":0.00000000},{"price":3795.62,"qty":0.73120000}],"asks":[],"checksum":2583184283,"timestamp":"2024-06-01T17:52:31.598880Z"}]}
{"channel":"book","type":"update","data":[{"symbol":"ETH/USDT","bids":[],"asks":[{"price":3799.02,"qty":7.30579095}],"checksum":1426161200,"timestamp":"2024-06-01T17:52:31.601675Z"}]}
{"channel":"book","type":"update","data":[{"symbol":"ETH/USDT","bids":[],"asks":[{"price":3798.94,"qty":0.34000000}],"checksum":2586020074,"timestamp":"2024-06-01T17:52:31.601780Z"}]}
{"channel":"book","type":"update","data":[{"symbol":"ETH/USDT","bids":[],"asks":[{"price":3799.01,"qty":0.72912968}],"checksum":289428819,"timestamp":"2024-06-01T17:52:31.603008Z"}]}
{"channel":"book","type":"update","data":[{"symbol":"ETH/USDT","bids":[],"asks":[{"price":3798.65,"qty":0.73120000}],"checksum":2150964374,"timestamp":"2024-06-01T17:52:31.603026Z"}]}
{"channel":"book","type":"update","data":[{"symbol":"ETH/USDT","bids":[{"price":3797.41,"qty":0.73120000}],"asks":[],"checksum":19187218,"timestamp":"2024-06-01T17:52:31.603040Z"}]}
{"channel":"book","type":"update","data":[{"symbol":"ETH/USDT","bids":[],"asks":[{"price":3799.07,"qty":2.13500000}],"checksum":1606420106,"timestamp":"2024-06-01T17:52:31.603819Z"}]}
{"channel":"book","type":"update","data":[{"symbol":"ETH/USDT","bids":[],"asks":[{"price":3799.01,"qty":0.97912968}],"checksum":796531583,"timestamp":"2024-06-01T17:52:31.604147Z"}]}
{"channel":"book","type":"update","data":[{"symbol":"ETH/USDT","bids":[],"asks":[{"price":3798.90,"qty":2.63535762}],"checksum":956312109,"timestamp":"2024-06-01T17:52:31.605301Z"}]}
{"channel":"book","type":"update","data":[{"symbol":"ETH/USDT","bids":[],"asks":[{"price":3798.76,"qty":0.73120000}],"checksum":1708245612,"timestamp":"2024-06-01T17:52:31.605370Z"}]}
{"channel":"book","type":"update","data":[{"symbol":"ETH/USDT","bids":[],"asks":[{"price":3799.10,"qty":0.73120000}],"checksum":3635552937,"timestamp":"2024-06-01T17:52:31.605421Z"}]}
{"channel":"book","type":"update","data":[{"symbol":"ETH/USDT","bids":[],"asks":[{"price":3798.94,"qty":0.00000000},{"price":3799.50,"qty":0.84627249}],"checksum":2549442406,"timestamp":"2024-06-01T17:52:31.605889Z"}]}
{"channel":"book","type":"update","data":[{"symbol":"ETH/USDT","bids":[],"asks":[{"price":3798.57,"qty":0.34000000}],"checksum":1779894578,"timestamp":"2024-06-01T17:52:31.606149Z"}]}
{"channel":"book","type":"update","data":[{"symbol":"ETH/USDT","bids":[],"asks":[{"price":3799.02,"qty":4.67045656}],"checksum":3009624597,"timestamp":"2024-06-01T17:52:31.606206Z"}]}
{"channel":"book","type":"update","data":[{"symbol":"ETH/USDT","bids":[{"price":3797.49,"qty":0.73120000}],"asks":[],"checksum":3440540616,"timestamp":"2024-06-01T17:52:31.607659Z"}]}
{"channel":"book","type":"update","data":[{"symbol":"ETH/USDT","bids":[],"asks":[{"price":3798.65,"qty":3.36654866}],"checksum":422050783,"timestamp":"2024-06-01T17:52:31.608815Z"}]}
{"channel":"book","type":"update","data":[{"symbol":"ETH/USDT","bids":[],"asks":[{"price":3798.90,"qty":0.00000000},{"price":3799.50,"qty":0.84627249}],"checksum":1728466855,"timestamp":"2024-06-01T17:52:31.609130Z"}]}
{"channel":"book","type":"update","data":[{"symbol":"ETH/USDT","bids":[],"asks":[{"price":3799.02,"qty":3.93925656}],"checksum":1356566613,"timestamp":"2024-06-01T17:52:31.611814Z"}]}
{"channel":"book","type":"update","data":[{"symbol":"ETH/USDT","bids":[],"asks":[{"price":3798.43,"qty":0.73120000}],"checksum":1927341463,"timestamp":"2024-06-01T17:52:31.611905Z"}]}
{"channel":"book","type":"update","data":[{"symbol":"ETH/USDT","bids":[],"asks":[{"price":3798.40,"qty":0.34000000}],"checksum":3443567947,"timestamp":"2024-06-01T17:52:31.615266Z"}]}
{"channel":"book","type":"update","data":[{"symbol":"ETH/USDT","bids":[],"asks":[{"price":3798.57,"qty":0.00000000},{"price":3799.38,"qty":5.00000000}],"checksum":823420703,"timestamp":"2024-06-01T17:52:31.615281Z"}]}
{"channel":"book","type":"update","data":[{"symbol":"ETH/USDT","bids":[],"asks":[{"price":3799.02,"qty":2.79895311}],"checksum":2583503040,"timestamp":"2024-06-01T17:52:31.622554Z"}]}
{"channel":"book","type":"update","data":[{"symbol":"ETH/USDT","bids":[],"asks":[{"price":3799.02,"qty":0.97912968}],"checksum":3735295811,"timestamp":"2024-06-01T17:52:31.622592Z"}]}
{"channel":"book","type":"update","data":[{"symbol":"ETH/USDT","bids":[],"asks":[{"price":3798.43,"qty":0.00000000},{"price":3799.50,"qty":0.84627249}],"checksum":3974452042,"timestamp":"2024-06-01T17:52:31.633306Z"}]}
{"channel":"book","type":"update","data":[{"symbol":"ETH/USDT","bids":[],"asks":[{"price":3799.02,"qty":0.25000000}],"checksum":484802836,"timestamp":"2024-06-01T17:52:31.637799Z"}]}
{"channel":"book","type":"update","data":[{"symbol":"ETH/USDT","bids":[],"asks":[{"price":3799.02,"qty":0.00000000},{"price":3799.51,"qty":0.73120000}],"checksum":1332046406,"timestamp":"2024-06-01T17:52:31.638323Z"}]}
{"channel":"book","type":"update","data":[{"symbol":"ETH/USDT","bids":[{"price":3797.14,"qty":0.19744577}],"asks":[],"checksum":1233004183,"timestamp":"2024-06-01T17:52:31.639324Z"}]}
{"channel":"book","type":"update","data":[{"symbol":"ETH/USDT","bids":[],"asks":[{"price":3799.07,"qty":0.00000000},{"price":3799.52,"qty":0.85200000}],"checksum":154932817,"timestamp":"2024-06-01T17:52:31.642729Z"}]}
{"channel":"book","type":"update","data":[{"symbol":"ETH/USDT","bids":[],"asks":[{"price":3799.02,"qty":0.06693358}],"checksum":4232160316,"timestamp":"2024-06-01T17:52:31.645836Z"}]}
{"channel":"book","type":"update","data":[{"symbol":"ETH/USDT","bids":[{"price":3797.50,"qty":0.07905112}],"asks":[],"checksum":75953204,"timestamp":"2024-06-01T17:52:31.657394Z"}]}
{"channel":"book","type":"update","data":[{"symbol":"ETH/USDT","bids":[],"asks":[{"price":3798.65,"qty":2.63534866}],"checksum":447368826,"timestamp":"2024-06-01T17:52:31.661313Z"}]}
{"channel":"book","type":"update","data":[{"symbol":"ETH/USDT","bids":[{"price":3797.80,"qty":0.73120000}],"asks":[],"checksum":3821468824,"timestamp":"2024-06-01T17:52:31.662163Z"}]}
{"channel":"book","type":"update","data":[{"symbol":"ETH/USDT","bids":[],"asks":[{"price":3798.76,"qty":0.00000000},{"price":3799.52,"qty":0.85200000}],"checksum":1582276800,"timestamp":"2024-06-01T17:52:31.662498Z"}]}
{"channel":"book","type":"update","data":[{"symbol":"ETH/USDT","bids":[{"price":3797.80,"qty":1.46240000}],"asks":[],"checksum":2200625956,"timestamp":"2024-06-01T17:52:31.666673Z"}]}
{"channel":"book","type":"update","data":[{"symbol":"ETH/USDT","bids":[{"price":3797.50,"qty":0.00000000},{"price":3796.67,"qty":8.85436466}],"asks":[],"checksum":3744000935,"timestamp":"2024-06-01T17:52:31.667095Z"}]}
{"channel":"book","type":"update","data":[{"symbol":"ETH/USDT","bids":[{"price":3797.81,"qty":0.07904678}],"asks":[],"checksum":1655531219,"timestamp":"2024-06-01T17:52:31.667345Z"}]}
{"channel":"book","type":"update","data":[{"symbol":"ETH/USDT","bids":[],"asks":[{"price":3798.65,"qty":0.00000000},{"price":3799.87,"qty":5.26500000}],"checksum":107893147,"timestamp":"2024-06-01T17:52:31.668085Z"}]}
{"channel":"book","type":"update","data":[{"symbol":"ETH/USDT","bids":[{"price":3797.99,"qty":0.73120000}],"asks":[],"checksum":729791845,"timestamp":"2024-06-01T17:52:31.671677Z"}]}
{"channel":"book","type":"update","data":[{"symbol":"ETH/USDT","bids":[{"price":3797.49,"qty":0.00000000},{"price":3796.70,"qty":4.32795000}],"asks":[],"checksum":1678646714,"timestamp":"2024-06-01T17:52:31.672022Z"}]}
{"channel":"book","type":"update","data":[{"symbol":"ETH/USDT","bids":[],"asks":[{"price":3798.40,"qty":0.00000000},{"price":3799.89,"qty":0.73541065}],"checksum":180372480,"timestamp":"2024-06-01T17:52:31.672334Z"}]}
{"channel":"book","type":"update","data":[{"symbol":"ETH/USDT","bids":[],"asks":[{"price":3799.38,"qty":0.00000000},{"price":3800.53,"qty":0.74200000}],"checksum":4068424358,"timestamp":"2024-06-01T17:52:31.674391Z"}]}
{"channel":"book","type":"update","data":[{"symbol":"ETH/USDT","bids":[],"asks":[{"price":3799.76,"qty":5.00000000}],"checksum":919441227,"timestamp":"2024-06-01T17:52:31.674610Z"}]}
{"channel":"book","type":"update","data":[{"symbol":"ETH/USDT","bids":[],"asks":[{"price":3799.86,"qty":2.79800000}],"checksum":1975213724,"timestamp":"2024-06-01T17:52:31.677355Z"}]}
{"channel":"book","type":"update","data":[{"symbol":"ETH/USDT","bids":[],"asks":[{"price":3799.10,"qty":0.00000000},{"price":3799.89,"qty":0.73541065}],"checksum":291200236,"timestamp":"2024-06-01T17:52:31.703885Z"}]}
{"channel":"book","type":"update","data":[{"symbol":"ETH/USDT","bids":[],"asks":[{"price":3799.49,"qty":5.00000000}],"checksum":708860208,"timestamp":"2024-06-01T17:52:31.711711Z"}]}
{"channel":"book","type":"update","data":[{"symbol":"ETH/USDT","bids":[{"price":3797.81,"qty":0.00000000},{"price":3796.67,"qty":8.85436466}],"asks":[],"checksum":2115523976,"timestamp":"2024-06-01T17:52:31.716073Z"}]}
{"channel":"book","type":"update","data":[{"symbol":"ETH/USDT","bids":[{"price":3798.00,"qty":0.07904660}],"asks":[],"checksum":151288686,"timestamp":"2024-06-01T17:52:31.716312Z"}]}
{"channel":"book","type":"update","data":[{"symbol":"ETH/USDT","bids":[{"price":3797.40,"qty":0.98017644}],"asks":[],"checksum":216497444,"timestamp":"2024-06-01T17:52:31.717715Z"}]}
{"channel":"book","type":"update","data":[{"symbol":"ETH/USDT","bids":[{"price":3798.20,"qty":0.73120000}],"asks":[],"checksum":4165290571,"timestamp":"2024-06-01T17:52:31.720271Z"}]}
{"channel":"book","type":"update","data":[{"symbol":"ETH/USDT","bids":[{"price":3797.81,"qty":0.07904394}],"asks":[],"checksum":1918821972,"timestamp":"2024-06-01T17:52:31.720285Z"}]}
{"channel":"book","type":"update","data":[{"symbol":"ETH/USDT","bids":[{"price":3798.00,"qty":0.00000000},{"price":3797.07,"qty":1.31755430}],"asks":[],"checksum":3329816803,"timestamp":"2024-06-01T17:52:31.720681Z"}]}
{"channel":"book","type":"update","data":[{"symbol":"ETH/USDT","bids":[{"price":3797.80,"qty":0.73120000}],"asks":[],"checksum":2135834655,"timestamp":"2024-06-01T17:52:31.724765Z"}]}
{"channel":"book","type":"update","data":[{"symbol":"ETH/USDT","bids":[{"price":3797.81,"qty":0.00000000},{"price":3796.95,"qty":0.73120000}],"asks":[],"checksum":1707475673,"timestamp":"2024-06-01T17:52:31.724916Z"}]}
{"channel":"book","type":"update","data":[{"symbol":"ETH/USDT","bids":[{"price":3797.99,"qty":0.00000000},{"price":3796.70,"qty":4.32795000}],"asks":[],"checksum":2353871238,"timestamp":"2024-06-01T17:52:31.724969Z"}]}
{"channel":"book","type":"update","data":[{"symbol":"ETH/USDT","bids":[{"price":3798.20,"qty":1.46240000}],"asks":[],"checksum":1448959452,"timestamp":"2024-06-01T17:52:31.724987Z"}]}
{"channel":"book","type":"update","data":[{"symbol":"ETH/USDT","bids":[],"asks":[{"price":3799.86,"qty":0.00000000},{"price":3799.89,"qty":0.73541065}],"checksum":3463282450,"timestamp":"2024-06-01T17:52:31.731624Z"}]}
{"channel":"book","type":"update","data":[{"symbol":"ETH/USDT","bids":[],"asks":[{"price":3799.00,"qty":2.13500000}],"checksum":2941883763,"timestamp":"2024-06-01T17:52:31.741252Z"}]}
{"channel":"book","type":"update","data":[{"symbol":"ETH/USDT","bids":[],"asks":[{"price":3799.49,"qty":0.00000000},{"price":3799.89,"qty":0.73541065}],"checksum":838136093,"timestamp":"2024-06-01T17:52:31.746090Z"}]}
{"channel":"book","type":"update","data":[{"symbol":"ETH/USDT","bids":[],"asks":[{"price":3798.99,"qty":0.25000000}],"checksum":4089778438,"timestamp":"2024-06-01T17:52:31.746485Z"}]}
{"channel":"book","type":"update","data":[{"symbol":"ETH/USDT","bids":[],"asks":[{"price":3799.00,"qty":0.00000000},{"price":3799.89,"qty":0.73541065}],"checksum":2403963129,"timestamp":"2024-06-01T17:52:31.752339Z"}]}
{"channel":"book","type":"update","data":[{"symbol":"ETH/USDT","bids":[],"asks":[{"price":3798.98,"qty":2.63442941}],"checksum":2626005422,"timestamp":"2024-06-01T17:52:31.752686Z"}]}
{"channel":"book","type":"update","data":[{"symbol":"ETH/USDT","bids":[{"price":3796.84,"qty":2.63590821}],"asks":[],"checksum":2855261149,"timestamp":"2024-06-01T17:52:31.752805Z"}]}
{"channel":"book","type":"update","data":[{"symbol":"ETH/USDT","bids":[{"price":3797.32,"qty":0.35000000}],"asks":[],"checksum":1419236212,"timestamp":"2024-06-01T17:52:31.753245Z"}]}
{"channel":"book","type":"update","data":[{"symbol":"ETH/USDT","bids":[{"price":3797.42,"qty":0.13000000}],"asks":[],"checksum":1428685857,"timestamp":"2024-06-01T17:52:31.757126Z"}]}
{"channel":"book","type":"update","data":[{"symbol":"ETH/USDT","bids":[],"asks":[{"price":3799.50,"qty":0.00000000},{"price":3799.89,"qty":0.73541065}],"checksum":4087364324,"timestamp":"2024-06-01T17:52:31.765422Z"}]}
{"channel":"book","type":"update","data":[{"symbol":"ETH/USDT","bids":[],"asks":[{"price":3799.02,"qty":0.00000000},{"price":3800.53,"qty":0.74200000}],"checksum":2813311212,"timestamp":"2024-06-01T17:52:31.773529Z"}]}
{"channel":"book","type":"update","data":[{"symbol":"ETH/USDT","bids":[],"asks":[{"price":3798.99,"qty":0.00000000},{"price":3800.65,"qty":0.73120000}],"checksum":1966172331,"timestamp":"2024-06-01T17:52:31.778656Z"}]}
{"channel":"book","type":"update","data":[{"symbol":"ETH/USDT","bids":[],"asks":[{"price":3798.97,"qty":0.25000000}],"checksum":333189649,"timestamp":"2024-06-01T17:52:31.778739Z"}]}
{"channel":"book","type":"update","data":[{"symbol":"ETH/USDT","bids":[],"asks":[{"price":3798.97,"qty":0.00000000},{"price":3800.65,"qty":0.73120000}],"checksum":1966172331,"timestamp":"2024-06-01T17:52:31.782931Z"}]}
{"channel":"book","type":"update","data":[{"symbol":"ETH/USDT","bids":[{"price":3797.32,"qty":0.00000000},{"price":3796.95,"qty":0.73120000}],"asks":[],"checksum":2582017142,"timestamp":"2024-06-01T17:52:31.785236Z"}]}
{"channel":"book","type":"update","data":[{"symbol":"ETH/USDT","bids":[],"asks":[{"price":3800.05,"qty":2.63368772}],"checksum":191233686,"timestamp":"2024-06-01T17:52:31.785247Z"}]}
{"channel":"book","type":"update","data":[{"symbol":"ETH/USDT","bids":[{"price":3798.97,"qty":1.00000000}],"asks":[],"checksum":2000101771,"timestamp":"2024-06-01T17:52:31.787216Z"}]}
{"channel":"book","type":"update","data":[{"symbol":"ETH/USDT","bids":[{"price":3797.42,"qty":0.00000000},{"price":3796.95,"qty":0.73120000}],"asks":[],"checksum":4263543403,"timestamp":"2024-06-01T17:52:31.787282Z"}]}
{"channel":"book","type":"update","data":[{"symbol":"ETH/USDT","bids":[{"price":3797.40,"qty":0.00000000},{"price":3796.84,"qty":2.63590821}],"asks":[],"checksum":3644824291,"timestamp":"2024-06-01T17:52:31.811634Z"}]}
{"channel":"book","type":"update","data":[{"symbol":"ETH/USDT","bids":[],"asks":[{"price":3798.98,"qty":3.36355909}],"checksum":1852369144,"timestamp":"2024-06-01T17:52:31.815824Z"}]}
{"channel":"book","type":"update","data":[{"symbol":"ETH/USDT","bids":[],"asks":[{"price":3799.76,"qty":0.00000000},{"price":3800.65,"qty":0.73120000}],"checksum":530987828,"timestamp":"2024-06-01T17:52:31.846902Z"}]}
{"channel":"book","type":"update","data":[{"symbol":"ETH/USDT","bids":[],"asks":[{"price":3799.01,"qty":0.72912968}],"checksum":3483235289,"timestamp":"2024-06-01T17:52:31.847500Z"}]}
{"channel":"book","type":"update","data":[{"symbol":"ETH/USDT","bids":[{"price":3798.22,"qty":1.31758555}],"asks":[],"checksum":3336631107,"timestamp":"2024-06-01T17:52:31.848761Z"}]}
{"channel":"book","type":"update","data":[{"symbol":"ETH/USDT","bids":[],"asks":[{"price":3799.06,"qty":0.00000000},{"price":3800.89,"qty":2.63310660}],"checksum":3168209212,"timestamp":"2024-06-01T17:52:31.849850Z"}]}
{"channel":"book","type":"update","data":[{"symbol":"ETH/USDT","bids":[{"price":3797.26,"qty":0.00000000},{"price":3796.70,"qty":4.32795000}],"asks":[],"checksum":3641764210,"timestamp":"2024-06-01T17:52:31.853983Z"}]}
{"channel":"book","type":"update","data":[{"symbol":"ETH/USDT","bids":[{"price":3797.80,"qty":0.00000000},{"price":3796.67,"qty":8.85436466}],"asks":[],"checksum":839435778,"timestamp":"2024-06-01T17:52:31.855075Z"}]}
{"channel":"book","type":"update","data":[{"symbol":"ETH/USDT","bids":[{"price":3798.59,"qty":0.73120000}],"asks":[],"checksum":2686072231,"timestamp":"2024-06-01T17:52:31.858400Z"}]}
{"channel":"book","type":"update","data":[{"symbol":"ETH/USDT","bids":[{"price":3796.76,"qty":2.13500000}],"asks":[],"checksum":1296696299,"timestamp":"2024-06-01T17:52:31.861716Z"}]}
{"channel":"book","type":"update","data":[{"symbol":"ETH/USDT","bids":[],"asks":[{"price":3799.38,"qty":0.06693358}],"checksum":1686264411,"timestamp":"2024-06-01T17:52:31.877519Z"}]}
{"channel":"book","type":"update","data":[{"symbol":"ETH/USDT","bids":[],"asks":[{"price":3799.01,"qty":0.00000000},{"price":3800.89,"qty":2.63310660}],"checksum":908488531,"timestamp":"2024-06-01T17:52:31.881622Z"}]}
{"channel":"book","type":"update","data":[{"symbol":"ETH/USDT","bids":[],"asks":[{"price":3800.24,"qty":0.84627249}],"checksum":2236063898,"timestamp":"2024-06-01T17:52:31.882450Z"}]}
{"channel":"book","type":"update","data":[{"symbol":"ETH/USDT","bids":[],"asks":[{"price":3799.52,"qty":0.00000000},{"price":3800.89,"qty":2.63310660}],"checksum":2223684437,"timestamp":"2024-06-01T17:52:31.890150Z"}]}
{"channel":"book","type":"update","data":[{"symbol":"ETH/USDT","bids":[],"asks":[{"price":3798.98,"qty":5.49855909}],"checksum":297064366,"timestamp":"2024-06-01T17:52:31.903218Z"}]}
{"channel":"book","type":"update","data":[{"symbol":"ETH/USDT","bids":[{"price":3798.59,"qty":0.00000000},{"price":3796.70,"qty":4.32795000}],"asks":[],"checksum":205660126,"timestamp":"2024-06-01T17:52:31.906847Z"}]}
{"channel":"book","type":"update","data":[{"symbol":"ETH/USDT","bids":[{"price":3798.97,"qty":1.84197644}],"asks":[],"checksum":864637558,"timestamp":"2024-06-01T17:52:31.911305Z"}]}
{"channel":"book","type":"update","data":[{"symbol":"ETH/USDT","bids":[],"asks":[{"price":3798.98,"qty":3.36355909}],"checksum":426985358,"timestamp":"2024-06-01T17:52:31.923421Z"}]}
{"channel":"book","type":"update","data":[{"symbol":"ETH/USDT","bids":[{"price":3798.59,"qty":0.73120000}],"asks":[],"checksum":4207005427,"timestamp":"2024-06-01T17:52:31.925768Z"}]}
{"channel":"book","type":"update","data":[{"symbol":"ETH/USDT","bids":[],"asks":[{"price":3799.38,"qty":0.00000000},{"price":3801.15,"qty":0.73120000}],"checksum":1207941056,"timestamp":"2024-06-01T17:52:31.981801Z"}]}
{"channel":"book","type":"update","data":[{"symbol":"ETH/USDT","bids":[],"asks":[{"price":3800.23,"qty":5.00000000}],"checksum":484531983,"timestamp":"2024-06-01T17:52:31.986469Z"}]}
{"channel":"book","type":"update","data":[{"symbol":"ETH/USDT","bids":[],"asks":[{"price":3799.49,"qty":0.25000000}],"checksum":3195212145,"timestamp":"2024-06-01T17:52:31.986580Z"}]}
{"channel":"book","type":"update","data":[{"symbol":"ETH/USDT","bids":[],"asks":[{"price":3798.98,"qty":5.49855909}],"checksum":2492007561,"timestamp":"2024-06-01T17:52:32.022005Z"}]}
{"channel":"book","type":"update","data":[{"symbol":"ETH/USDT","bids":[{"price":3798.59,"qty":0.00000000},{"price":3796.70,"qty":4.32795000}],"asks":[],"checksum":2848823142,"timestamp":"2024-06-01T17:52:32.033780Z"}]}
{"channel":"book","type":"update","data":[{"symbol":"ETH/USDT","bids":[{"price":3797.58,"qty":2.79800000}],"asks":[],"checksum":2812645455,"timestamp":"2024-06-01T17:52:32.037008Z"}]}
{"channel":"book","type":"update","data":[{"symbol":"ETH/USDT","bids":[{"price":3798.97,"qty":1.00000000}],"asks":[],"checksum":2557402599,"timestamp":"2024-06-01T17:52:32.081277Z"}]}
{"channel":"book","type":"update","data":[{"symbol":"ETH/USDT","bids":[{"price":3798.97,"qty":0.00000000},{"price":3796.70,"qty":4.32795000}],"asks":[],"checksum":3335892671,"timestamp":"2024-06-01T17:52:32.081357Z"}]}
{"channel":"book","type":"update","data":[{"symbol":"ETH/USDT","bids":[],"asks":[{"price":3800.26,"qty":2.79800000}],"checksum":3934165608,"timestamp":"2024-06-01T17:52:32.084705Z"}]}
{"channel":"book","type":"update","data":[{"symbol":"ETH/USDT","bids":[{"price":3798.40,"qty":0.73120000}],"asks":[],"checksum":2313912525,"timestamp":"2024-06-01T17:52:32.085198Z"}]}
{"channel":"book","type":"update","data":[{"symbol":"ETH/USDT","bids":[],"asks":[{"price":3799.63,"qty":0.06693358}],"checksum":3317778190,"timestamp":"2024-06-01T17:52:32.086304Z"}]}
{"channel":"book","type":"update","data":[{"symbol":"ETH/USDT","bids":[],"asks":[{"price":3798.97,"qty":0.72912968}],"checksum":926240,"timestamp":"2024-06-01T17:52:32.089379Z"}]}
{"channel":"book","type":"update","data":[{"symbol":"ETH/USDT","bids":[{"price":3798.82,"qty":1.16226117}],"asks":[],"checksum":4279341627,"timestamp":"2024-06-01T17:52:32.177606Z"}]}
{"channel":"book","type":"update","data":[{"symbol":"ETH/USDT","bids":[{"price":3797.31,"qty":1.27749431}],"asks":[],"checksum":3216359669,"timestamp":"2024-06-01T17:52:32.178520Z"}]}
{"channel":"book","type":"update","data":[{"symbol":"ETH/USDT","bids":[],"asks":[{"price":3798.98,"qty":4.76942941}],"checksum":1940338500,"timestamp":"2024-06-01T17:52:32.181588Z"}]}
{"channel":"book","type":"update","data":[{"symbol":"ETH/USDT","bids":[{"price":3797.24,"qty":0.34268737}],"asks":[],"checksum":2730690460,"timestamp":"2024-06-01T17:52:32.191204Z"}]}
{"channel":"book","type":"update","data":[{"symbol":"ETH/USDT","bids":[{"price":3797.14,"qty":0.00000000},{"price":3796.95,"qty":0.73120000}],"asks":[],"checksum":492352686,"timestamp":"2024-06-01T17:52:32.241755Z"}]}
{"channel":"book","type":"update","data":[{"symbol":"ETH/USDT","bids":[{"price":3797.53,"qty":0.19737891}],"asks":[],"checksum":85968514,"timestamp":"2024-06-01T17:52:32.282096Z"}]}
{"channel":"book","type":"update","data":[{"symbol":"ETH/USDT","bids":[{"price":3797.23,"qty":2.63563868}],"asks":[],"checksum":3890216357,"timestamp":"2024-06-01T17:52:32.349765Z"}]}
{"channel":"book","type":"update","data":[{"symbol":"ETH/USDT","bids":[{"price":3797.57,"qty":0.84627249}],"asks":[],"checksum":2536159371,"timestamp":"2024-06-01T17:52:32.453569Z"}]}
{"channel":"book","type":"update","data":[{"symbol":"ETH/USDT","bids":[],"asks":[{"price":3799.86,"qty":0.40000000}],"checksum":1114479886,"timestamp":"2024-06-01T17:52:32.490114Z"}]}
{"channel":"book","type":"update","data":[{"symbol":"ETH/USDT","bids":[{"price":3797.31,"qty":0.34000000}],"asks":[],"checksum":1739596087,"timestamp":"2024-06-01T17:52:32.614732Z"}]}
{"channel":"book","type":"update","data":[{"symbol":"ETH/USDT","bids":[{"price":3797.77,"qty":0.93749431}],"asks":[],"checksum":1772981914,"timestamp":"2024-06-01T17:52:32.615576Z"}]}
{"channel":"book","type":"update","data":[{"symbol":"ETH/USDT","bids":[{"price":3797.53,"qty":0.00000000},{"price":3797.24,"qty":0.34268737}],"asks":[],"checksum":1004191504,"timestamp":"2024-06-01T17:52:32.810084Z"}]}
{"channel":"book","type":"update","data":[{"symbol":"ETH/USDT","bids":[{"price":3797.60,"qty":0.19736966}],"asks":[],"checksum":1245556948,"timestamp":"2024-06-01T17:52:32.850479Z"}]}
{"channel":"book","type":"update","data":[{"symbol":"ETH/USDT","bids":[{"price":3798.40,"qty":0.00000000},{"price":3797.24,"qty":0.34268737}],"asks":[],"checksum":169418670,"timestamp":"2024-06-01T17:52:32.999953Z"}]}
{"channel":"book","type":"update","data":[{"symbol":"ETH/USDT","bids":[{"price":3797.60,"qty":0.00000000},{"price":3797.23,"qty":2.63563868}],"asks":[],"checksum":1300769009,"timestamp":"2024-06-01T17:52:33.453282Z"}]}
{"channel":"book","type":"update","data":[{"symbol":"ETH/USDT","bids":[{"price":3797.55,"qty":5.00000000}],"asks":[],"checksum":3829404223,"timestamp":"2024-06-01T17:52:33.458102Z"}]}
{"channel":"book","type":"update","data":[{"symbol":"ETH/USDT","bids":[{"price":3797.95,"qty":0.25000000}],"asks":[],"checksum":4102545212,"timestamp":"2024-06-01T17:52:33.458495Z"}]}
{"channel":"book","type":"update","data":[{"symbol":"ETH/USDT","bids":[{"price":3797.58,"qty":2.99537240}],"asks":[],"checksum":649260389,"timestamp":"2024-06-01T17:52:33.493664Z"}]}
{"channel":"book","type":"update","data":[{"symbol":"ETH/USDT","bids":[{"price":3798.82,"qty":0.00000000},{"price":3797.24,"qty":0.34268737}],"asks":[],"checksum":2397228660,"timestamp":"2024-06-01T17:52:33.639258Z"}]}
{"channel":"book","type":"update","data":[{"symbol":"ETH/USDT","bids":[{"price":3797.31,"qty":0.00000000},{"price":3797.23,"qty":2.63563868}],"asks":[],"checksum":1949877757,"timestamp":"2024-06-01T17:52:33.639545Z"}]}
{"channel":"book","type":"update","data":[{"symbol":"ETH/USDT","bids":[{"price":3798.24,"qty":0.34000000}],"asks":[],"checksum":2383529190,"timestamp":"2024-06-01T17:52:33.639884Z"}]}
{"channel":"book","type":"update","data":[{"symbol":"ETH/USDT","bids":[{"price":3798.40,"qty":0.73120000}],"asks":[],"checksum":3355526339,"timestamp":"2024-06-01T17:52:33.642669Z"}]}
{"channel":"book","type":"update","data":[{"symbol":"ETH/USDT","bids":[{"price":3798.23,"qty":0.25000000}],"asks":[],"checksum":3387912590,"timestamp":"2024-06-01T17:52:33.644255Z"}]}
{"channel":"book","type":"update","data":[{"symbol":"ETH/USDT","bids":[{"price":3797.58,"qty":3.89799030}],"asks":[],"checksum":4228246510,"timestamp":"2024-06-01T17:52:33.985909Z"}]}
{"channel":"book","type":"update","data":[{"symbol":"ETH/USDT","bids":[{"price":3798.23,"qty":0.00000000},{"price":3797.41,"qty":0.73120000}],"asks":[],"checksum":2440110806,"timestamp":"2024-06-01T17:52:34.086646Z"}]}
{"channel":"book","type":"update","data":[{"symbol":"ETH/USDT","bids":[{"price":3797.58,"qty":3.70061790}],"asks":[],"checksum":1452933612,"timestamp":"2024-06-01T17:52:34.095935Z"}]}
{"channel":"book","type":"update","data":[{"symbol":"ETH/USDT","bids":[{"price":3797.57,"qty":1.04364552}],"asks":[],"checksum":1940385125,"timestamp":"2024-06-01T17:52:34.136268Z"}]}
{"channel":"book","type":"update","data":[{"symbol":"ETH/USDT","bids":[],"asks":[{"price":3798.98,"qty":2.13500000}],"checksum":1529739709,"timestamp":"2024-06-01T17:52:34.350887Z"}]}
{"channel":"book","type":"update","data":[{"symbol":"ETH/USDT","bids":[],"asks":[{"price":3798.96,"qty":2.63444334}],"checksum":4104587361,"timestamp":"2024-06-01T17:52:34.355712Z"}]}
{"channel":"book","type":"update","data":[{"symbol":"ETH/USDT","bids":[{"price":3798.40,"qty":0.00000000},{"price":3797.24,"qty":0.34268737}],"asks":[],"checksum":3611618572,"timestamp":"2024-06-01T17:52:34.372694Z"}]}
{"channel":"book","type":"update","data":[{"symbol":"ETH/USDT","bids":[{"price":3798.20,"qty":0.73120000}],"asks":[],"checksum":229967561,"timestamp":"2024-06-01T17:52:34.374244Z"}]}
{"channel":"book","type":"update","data":[{"symbol":"ETH/USDT","bids":[{"price":3798.30,"qty":0.73120000}],"asks":[],"checksum":2834485842,"timestamp":"2024-06-01T17:52:34.376121Z"}]}
{"channel":"book","type":"update","data":[{"symbol":"ETH/USDT","bids":[{"price":3797.86,"qty":0.73120000}],"asks":[],"checksum":1179570498,"timestamp":"2024-06-01T17:52:34.377692Z"}]}
{"channel":"book","type":"update","data":[{"symbol":"ETH/USDT","bids":[{"price":3798.24,"qty":1.07120000}],"asks":[],"checksum":3157078921,"timestamp":"2024-06-01T17:52:34.379244Z"}]}
{"channel":"book","type":"update","data":[{"symbol":"ETH/USDT","bids":[{"price":3798.24,"qty":0.34000000}],"asks":[],"checksum":1179570498,"timestamp":"2024-06-01T17:52:34.508549Z"}]}
{"channel":"book","type":"update","data":[{"symbol":"ETH/USDT","bids":[{"price":3798.31,"qty":0.25000000}],"asks":[],"checksum":1924067913,"timestamp":"2024-06-01T17:52:34.513424Z"}]}
{"channel":"book","type":"update","data":[{"symbol":"ETH/USDT","bids":[],"asks":[{"price":3798.95,"qty":0.72912968}],"checksum":631977624,"timestamp":"2024-06-01T17:52:34.513686Z"}]}
{"channel":"book","type":"update","data":[{"symbol":"ETH/USDT","bids":[{"price":3798.20,"qty":0.00000000},{"price":3797.55,"qty":5.00000000}],"asks":[],"checksum":1022491166,"timestamp":"2024-06-01T17:52:34.517200Z"}]}
{"channel":"book","type":"update","data":[{"symbol":"ETH/USDT","bids":[{"price":3798.31,"qty":0.98120000}],"asks":[],"checksum":1011143979,"timestamp":"2024-06-01T17:52:34.517354Z"}]}
{"channel":"book","type":"update","data":[{"symbol":"ETH/USDT","bids":[{"price":3798.30,"qty":0.00000000},{"price":3797.41,"qty":0.73120000}],"asks":[],"checksum":1591315674,"timestamp":"2024-06-01T17:52:34.518203Z"}]}
{"channel":"book","type":"update","data":[{"symbol":"ETH/USDT","bids":[],"asks":[{"price":3798.96,"qty":0.00000000},{"price":3800.05,"qty":2.63368772}],"checksum":3580119483,"timestamp":"2024-06-01T17:52:34.519776Z"}]}
{"channel":"book","type":"update","data":[{"symbol":"ETH/USDT","bids":[{"price":3798.32,"qty":0.73120000}],"asks":[],"checksum":3089963759,"timestamp":"2024-06-01T17:52:34.521513Z"}]}
{"channel":"book","type":"update","data":[{"symbol":"ETH/USDT","bids":[],"asks":[{"price":3798.95,"qty":0.00000000},{"price":3800.23,"qty":5.00000000}],"checksum":1123657889,"timestamp":"2024-06-01T17:52:34.587487Z"}]}
{"channel":"book","type":"update","data":[{"symbol":"ETH/USDT","bids":[{"price":3798.31,"qty":0.73120000}],"asks":[],"checksum":206901423,"timestamp":"2024-06-01T17:52:34.588768Z"}]}
{"channel":"book","type":"update","data":[{"symbol":"ETH/USDT","bids":[{"price":3798.31,"qty":0.00000000},{"price":3797.41,"qty":0.73120000}],"asks":[],"checksum":4007209071,"timestamp":"2024-06-01T17:52:34.593192Z"}]}
{"channel":"book","type":"update","data":[{"symbol":"ETH/USDT","bids":[{"price":3798.32,"qty":1.46240000}],"asks":[],"checksum":841075012,"timestamp":"2024-06-01T17:52:34.596754Z"}]}
{"channel":"book","type":"update","data":[{"symbol":"ETH/USDT","bids":[{"price":3798.32,"qty":0.73120000}],"asks":[],"checksum":4007209071,"timestamp":"2024-06-01T17:52:34.722501Z"}]}
{"channel":"book","type":"update","data":[{"symbol":"ETH/USDT","bids":[{"price":3797.57,"qty":0.84627249}],"asks":[],"checksum":4196967529,"timestamp":"2024-06-01T17:52:34.740428Z"}]}
{"channel":"book","type":"update","data":[{"symbol":"ETH/USDT","bids":[{"price":3798.32,"qty":0.00000000},{"price":3797.23,"qty":2.63563868}],"asks":[],"checksum":1541197748,"timestamp":"2024-06-01T17:52:34.757178Z"}]}
{"channel":"book","type":"update","data":[{"symbol":"ETH/USDT","bids":[{"price":3798.28,"qty":0.73120000}],"asks":[],"checksum":2325721743,"timestamp":"2024-06-01T17:52:34.760862Z"}]}
{"channel":"book","type":"update","data":[{"symbol":"ETH/USDT","bids":[{"price":3797.55,"qty":0.00000000},{"price":3797.23,"qty":2.63563868}],"asks":[],"checksum":2423567357,"timestamp":"2024-06-01T17:52:34.761812Z"}]}
{"channel":"book","type":"update","data":[{"symbol":"ETH/USDT","bids":[{"price":3798.25,"qty":0.25000000}],"asks":[],"checksum":966238117,"timestamp":"2024-06-01T17:52:34.761923Z"}]}
{"channel":"book","type":"update","data":[{"symbol":"ETH/USDT","bids":[{"price":3797.60,"qty":0.19736990}],"asks":[],"checksum":3282224717,"timestamp":"2024-06-01T17:52:34.781202Z"}]}
{"channel":"book","type":"update","data":[{"symbol":"ETH/USDT","bids":[{"price":3798.28,"qty":1.46240000}],"asks":[],"checksum":907941587,"timestamp":"2024-06-01T17:52:34.799473Z"}]}
{"channel":"book","type":"update","data":[{"symbol":"ETH/USDT","bids":[{"price":3798.25,"qty":0.00000000},{"price":3797.41,"qty":0.73120000}],"asks":[],"checksum":2755214262,"timestamp":"2024-06-01T17:52:34.804147Z"}]}
{"channel":"book","type":"update","data":[{"symbol":"ETH/USDT","bids":[{"price":3798.28,"qty":0.73120000}],"asks":[],"checksum":1367730984,"timestamp":"2024-06-01T17:52:34.813488Z"}]}
{"channel":"book","type":"update","data":[{"symbol":"ETH/USDT","bids":[{"price":3798.28,"qty":0.00000000},{"price":3797.23,"qty":2.63563868}],"asks":[],"checksum":3573232416,"timestamp":"2024-06-01T17:52:34.862702Z"}]}
{"channel":"book","type":"update","data":[{"symbol":"ETH/USDT","bids":[],"asks":[{"price":3798.97,"qty":1.46032968}],"checksum":314001468,"timestamp":"2024-06-01T17:52:34.863138Z"}]}
{"channel":"book","type":"update","data":[{"symbol":"ETH/USDT","bids":[],"asks":[{"price":3798.97,"qty":0.72912968}],"checksum":3573232416,"timestamp":"2024-06-01T17:52:34.866460Z"}]}
{"channel":"book","type":"update","data":[{"symbol":"ETH/USDT","bids":[{"price":3798.27,"qty":0.73120000}],"asks":[],"checksum":1925264139,"timestamp":"2024-06-01T17:52:34.866546Z"}]}
{"channel":"book","type":"update","data":[{"symbol":"ETH/USDT","bids":[{"price":3798.25,"qty":0.25000000}],"asks":[],"checksum":3773177454,"timestamp":"2024-06-01T17:52:34.867621Z"}]}
{"channel":"book","type":"update","data":[{"symbol":"ETH/USDT","bids":[{"price":3798.25,"qty":0.00000000},{"price":3797.41,"qty":0.73120000}],"asks":[],"checksum":1925264139,"timestamp":"2024-06-01T17:52:35.086877Z"}]}
{"channel":"book","type":"update","data":[{"symbol":"ETH/USDT","bids":[{"price":3797.77,"qty":0.00000000},{"price":3797.23,"qty":2.63563868}],"asks":[],"checksum":3319213268,"timestamp":"2024-06-01T17:52:35.233232Z"}]}
{"channel":"book","type":"update","data":[{"symbol":"ETH/USDT","bids":[{"price":3797.42,"qty":0.49488748}],"asks":[],"checksum":1451087197,"timestamp":"2024-06-01T17:52:35.333440Z"}]}
{"channel":"book","type":"update","data":[{"symbol":"ETH/USDT","bids":[{"price":3797.60,"qty":0.00000000},{"price":3797.23,"qty":2.63563868}],"asks":[],"checksum":4075486296,"timestamp":"2024-06-01T17:52:35.389999Z"}]}
{"channel":"book","type":"update","data":[{"symbol":"ETH/USDT","bids":[{"price":3797.42,"qty":0.69228271}],"asks":[],"checksum":3315947571,"timestamp":"2024-06-01T17:52:35.430342Z"}]}
{"channel":"book","type":"update","data":[{"symbol":"ETH/USDT","bids":[{"price":3798.27,"qty":0.00000000},{"price":3797.07,"qty":1.31755430}],"asks":[],"checksum":3141557653,"timestamp":"2024-06-01T17:52:35.471153Z"}]}
{"channel":"book","type":"update","data":[{"symbol":"ETH/USDT","bids":[],"asks":[{"price":3798.97,"qty":1.46032968}],"checksum":2944880033,"timestamp":"2024-06-01T17:52:35.484919Z"}]}
{"channel":"book","type":"update","data":[{"symbol":"ETH/USDT","bids":[],"asks":[{"price":3798.97,"qty":2.19152968}],"checksum":2543168844,"timestamp":"2024-06-01T17:52:35.519920Z"}]}
{"channel":"book","type":"update","data":[{"symbol":"ETH/USDT","bids":[],"asks":[{"price":3798.96,"qty":0.73120000}],"checksum":3681871605,"timestamp":"2024-06-01T17:52:35.523485Z"}]}
{"channel":"book","type":"update","data":[{"symbol":"ETH/USDT","bids":[],"asks":[{"price":3798.97,"qty":1.46032968}],"checksum":506204571,"timestamp":"2024-06-01T17:52:35.527312Z"}]}
{"channel":"book","type":"update","data":[{"symbol":"ETH/USDT","bids":[],"asks":[{"price":3798.96,"qty":1.46240000}],"checksum":3162428583,"timestamp":"2024-06-01T17:52:35.529930Z"}]}
{"channel":"book","type":"update","data":[{"symbol":"ETH/USDT","bids":[{"price":3798.24,"qty":0.00000000},{"price":3797.03,"qty":0.72912968}],"asks":[],"checksum":3494666818,"timestamp":"2024-06-01T17:52:35.549587Z"}]}
{"channel":"book","type":"update","data":[{"symbol":"ETH/USDT","bids":[],"asks":[{"price":3798.95,"qty":0.72912968}],"checksum":2370089636,"timestamp":"2024-06-01T17:52:35.554282Z"}]}
{"channel":"book","type":"update","data":[{"symbol":"ETH/USDT","bids":[],"asks":[{"price":3798.96,"qty":0.73120000}],"checksum":3463055930,"timestamp":"2024-06-01T17:52:35.554347Z"}]}
{"channel":"book","type":"update","data":[{"symbol":"ETH/USDT","bids":[{"price":3798.23,"qty":0.25000000}],"asks":[],"checksum":3950181753,"timestamp":"2024-06-01T17:52:35.555464Z"}]}
{"channel":"book","type":"update","data":[{"symbol":"ETH/USDT","bids":[],"asks":[{"price":3798.92,"qty":0.73120000}],"checksum":544045411,"timestamp":"2024-06-01T17:52:35.557144Z"}]}
{"channel":"book","type":"update","data":[{"symbol":"ETH/USDT","bids":[],"asks":[{"price":3798.92,"qty":0.00000000},{"price":3799.89,"qty":0.73541065}],"checksum":3950181753,"timestamp":"2024-06-01T17:52:35.559654Z"}]}
{"channel":"book","type":"update","data":[{"symbol":"ETH/USDT","bids":[],"asks":[{"price":3798.91,"qty":2.63447819}],"checksum":4191969149,"timestamp":"2024-06-01T17:52:35.562778Z"}]}
{"channel":"book","type":"update","data":[{"symbol":"ETH/USDT","bids":[{"price":3797.95,"qty":0.00000000},{"price":3797.03,"qty":0.72912968}],"asks":[],"checksum":1788120026,"timestamp":"2024-06-01T17:52:35.585487Z"}]}
{"channel":"book","type":"update","data":[{"symbol":"ETH/USDT","bids":[],"asks":[{"price":3798.95,"qty":0.00000000},{"price":3799.89,"qty":0.73541065}],"checksum":2907135454,"timestamp":"2024-06-01T17:52:35.588033Z"}]}
{"channel":"book","type":"update","data":[{"symbol":"ETH/USDT","bids":[],"asks":[{"price":3798.89,"qty":0.73120000}],"checksum":2245875882,"timestamp":"2024-06-01T17:52:35.601009Z"}]}
{"channel":"book","type":"update","data":[{"symbol":"ETH/USDT","bids":[],"asks":[{"price":3798.91,"qty":3.36567819}],"checksum":1489481209,"timestamp":"2024-06-01T17:52:35.603047Z"}]}
{"channel":"book","type":"update","data":[{"symbol":"ETH/USDT","bids":[],"asks":[{"price":3798.97,"qty":0.72912968}],"checksum":137221805,"timestamp":"2024-06-01T17:52:35.603434Z"}]}
{"channel":"book","type":"update","data":[{"symbol":"ETH/USDT","bids":[],"asks":[{"price":3798.89,"qty":0.00000000},{"price":3799.89,"qty":0.73541065}],"checksum":2521069386,"timestamp":"2024-06-01T17:52:35.604241Z"}]}
{"channel":"book","type":"update","data":[{"symbol":"ETH/USDT","bids":[],"asks":[{"price":3798.91,"qty":0.73120000}],"checksum":3986633029,"timestamp":"2024-06-01T17:52:35.605822Z"}]}
{"channel":"book","type":"update","data":[{"symbol":"ETH/USDT","bids":[],"asks":[{"price":3798.87,"qty":0.73120000}],"checksum":3544136418,"timestamp":"2024-06-01T17:52:35.606628Z"}]}
{"channel":"book","type":"update","data":[{"symbol":"ETH/USDT","bids":[],"asks":[{"price":3798.90,"qty":0.73120000}],"checksum":4161438354,"timestamp":"2024-06-01T17:52:35.608624Z"}]}
{"channel":"book","type":"update","data":[{"symbol":"ETH/USDT","bids":[],"asks":[{"price":3798.96,"qty":0.00000000},{"price":3799.87,"qty":5.26500000}],"checksum":674578755,"timestamp":"2024-06-01T17:52:35.608787Z"}]}
{"channel":"book","type":"update","data":[{"symbol":"ETH/USDT","bids":[],"asks":[{"price":3798.91,"qty":0.00000000},{"price":3799.89,"qty":0.73541065}],"checksum":1326830395,"timestamp":"2024-06-01T17:52:35.609775Z"}]}
{"channel":"book","type":"update","data":[{"symbol":"ETH/USDT","bids":[],"asks":[{"price":3798.87,"qty":0.00000000},{"price":3800.05,"qty":2.63368772}],"checksum":2998292720,"timestamp":"2024-06-01T17:52:35.610046Z"}]}
{"channel":"book","type":"update","data":[{"symbol":"ETH/USDT","bids":[],"asks":[{"price":3798.85,"qty":0.73120000}],"checksum":2898216841,"timestamp":"2024-06-01T17:52:35.612738Z"}]}
{"channel":"book","type":"update","data":[{"symbol":"ETH/USDT","bids":[],"asks":[{"price":3798.85,"qty":0.00000000},{"price":3800.05,"qty":2.63368772}],"checksum":2998292720,"timestamp":"2024-06-01T17:52:35.615863Z"}]}
{"channel":"book","type":"update","data":[{"symbol":"ETH/USDT","bids":[],"asks":[{"price":3798.85,"qty":0.73120000}],"checksum":2898216841,"timestamp":"2024-06-01T17:52:35.618401Z"}]}
{"channel":"book","type":"update","data":[{"symbol":"ETH/USDT","bids":[],"asks":[{"price":3798.85,"qty":0.00000000},{"price":3800.05,"qty":2.63368772}],"checksum":2998292720,"timestamp":"2024-06-01T17:52:35.621328Z"}]}
{"channel":"book","type":"update","data":[{"symbol":"ETH/USDT","bids":[],"asks":[{"price":3798.90,"qty":1.46240000}],"checksum":2334466008,"timestamp":"2024-06-01T17:52:35.628708Z"}]}
{"channel":"book","type":"update","data":[{"symbol":"ETH/USDT","bids":[],"asks":[{"price":3798.90,"qty":0.73120000}],"checksum":2998292720,"timestamp":"2024-06-01T17:52:35.694946Z"}]}
{"channel":"book","type":"update","data":[{"symbol":"ETH/USDT","bids":[],"asks":[{"price":3798.90,"qty":0.00000000},{"price":3800.23,"qty":5.00000000}],"checksum":1629669524,"timestamp":"2024-06-01T17:52:35.702596Z"}]}
{"channel":"book","type":"update","data":[{"symbol":"ETH/USDT","bids":[],"asks":[{"price":3798.95,"qty":0.73120000}],"checksum":3949501570,"timestamp":"2024-06-01T17:52:35.708510Z"}]}
{"channel":"book","type":"update","data":[{"symbol":"ETH/USDT","bids":[],"asks":[{"price":3798.95,"qty":0.00000000},{"price":3800.23,"qty":5.00000000}],"checksum":1629669524,"timestamp":"2024-06-01T17:52:35.711803Z"}]}
{"channel":"book","type":"update","data":[{"symbol":"ETH/USDT","bids":[],"asks":[{"price":3798.95,"qty":0.73120000}],"checksum":3949501570,"timestamp":"2024-06-01T17:52:35.717658Z"}]}
{"channel":"book","type":"update","data":[{"symbol":"ETH/USDT","bids":[],"asks":[{"price":3798.95,"qty":0.00000000},{"price":3800.23,"qty":5.00000000}],"checksum":1629669524,"timestamp":"2024-06-01T17:52:35.720813Z"}]}
{"channel":"book","type":"update","data":[{"symbol":"ETH/USDT","bids":[],"asks":[{"price":3798.95,"qty":0.73120000}],"checksum":3949501570,"timestamp":"2024-06-01T17:52:35.731304Z"}]}
{"channel":"book","type":"update","data":[{"symbol":"ETH/USDT","bids":[],"asks":[{"price":3798.95,"qty":0.00000000},{"price":3800.23,"qty":5.00000000}],"checksum":1629669524,"timestamp":"2024-06-01T17:52:35.734699Z"}]}
{"channel":"book","type":"update","data":[{"symbol":"ETH/USDT","bids":[],"asks":[{"price":3798.95,"qty":0.73120000}],"checksum":3949501570,"timestamp":"2024-06-01T17:52:35.745916Z"}]}
{"channel":"book","type":"update","data":[{"symbol":"ETH/USDT","bids":[],"asks":[{"price":3798.95,"qty":0.00000000},{"price":3800.23,"qty":5.00000000}],"checksum":1629669524,"timestamp":"2024-06-01T17:52:35.749034Z"}]}
{"channel":"book","type":"update","data":[{"symbol":"ETH/USDT","bids":[],"asks":[{"price":3798.95,"qty":0.73120000}],"checksum":3949501570,"timestamp":"2024-06-01T17:52:35.757083Z"}]}
{"channel":"book","type":"update","data":[{"symbol":"ETH/USDT","bids":[],"asks":[{"price":3798.95,"qty":0.00000000},{"price":3800.23,"qty":5.00000000}],"checksum":1629669524,"timestamp":"2024-06-01T17:52:35.761123Z"}]}
{"channel":"book","type":"update","data":[{"symbol":"ETH/USDT","bids":[],"asks":[{"price":3798.93,"qty":0.73120000}],"checksum":2247890142,"timestamp":"2024-06-01T17:52:35.776810Z"}]}
{"channel":"book","type":"update","data":[{"symbol":"ETH/USDT","bids":[],"asks":[{"price":3798.93,"qty":0.00000000},{"price":3800.23,"qty":5.00000000}],"checksum":1629669524,"timestamp":"2024-06-01T17:52:35.785463Z"}]}
{"channel":"book","type":"update","data":[{"symbol":"ETH/USDT","bids":[],"asks":[{"price":3798.94,"qty":0.73120000}],"checksum":4188971160,"timestamp":"2024-06-01T17:52:35.791758Z"}]}
{"channel":"book","type":"update","data":[{"symbol":"ETH/USDT","bids":[],"asks":[{"price":3798.94,"qty":0.00000000},{"price":3800.23,"qty":5.00000000}],"checksum":1629669524,"timestamp":"2024-06-01T17:52:35.794892Z"}]}
{"channel":"book","type":"update","data":[{"symbol":"ETH/USDT","bids":[],"asks":[{"price":3798.95,"qty":0.73120000}],"checksum":3949501570,"timestamp":"2024-06-01T17:52:35.799486Z"}]}
{"channel":"book","type":"update","data":[{"symbol":"ETH/USDT","bids":[],"asks":[{"price":3798.96,"qty":0.73120000}],"checksum":4055572064,"timestamp":"2024-06-01T17:52:35.799950Z"}]}
{"channel":"book","type":"update","data":[{"symbol":"ETH/USDT","bids":[],"asks":[{"price":3798.95,"qty":0.00000000},{"price":3800.05,"qty":2.63368772}],"checksum":3693271212,"timestamp":"2024-06-01T17:52:35.803049Z"}]}
{"channel":"book","type":"update","data":[{"symbol":"ETH/USDT","bids":[],"asks":[{"price":3798.96,"qty":1.46240000}],"checksum":3918960271,"timestamp":"2024-06-01T17:52:35.811851Z"}]}
{"channel":"book","type":"update","data":[{"symbol":"ETH/USDT","bids":[],"asks":[{"price":3798.95,"qty":0.72912968}],"checksum":1123564813,"timestamp":"2024-06-01T17:52:35.815912Z"}]}
{"channel":"book","type":"update","data":[{"symbol":"ETH/USDT","bids":[],"asks":[{"price":3798.96,"qty":0.73120000}],"checksum":95013221,"timestamp":"2024-06-01T17:52:35.819163Z"}]}
{"channel":"book","type":"update","data":[{"symbol":"ETH/USDT","bids":[],"asks":[{"price":3798.94,"qty":0.73120000}],"checksum":462778367,"timestamp":"2024-06-01T17:52:35.823072Z"}]}
{"channel":"book","type":"update","data":[{"symbol":"ETH/USDT","bids":[],"asks":[{"price":3798.94,"qty":0.00000000},{"price":3799.89,"qty":0.73541065}],"checksum":95013221,"timestamp":"2024-06-01T17:52:35.826374Z"}]}
{"channel":"book","type":"update","data":[{"symbol":"ETH/USDT","bids":[],"asks":[{"price":3798.94,"qty":0.73120000}],"checksum":462778367,"timestamp":"2024-06-01T17:52:35.833143Z"}]}
{"channel":"book","type":"update","data":[{"symbol":"ETH/USDT","bids":[],"asks":[{"price":3798.94,"qty":0.00000000},{"price":3799.89,"qty":0.73541065}],"checksum":95013221,"timestamp":"2024-06-01T17:52:35.836515Z"}]}
{"channel":"book","type":"update","data":[{"symbol":"ETH/USDT","bids":[],"asks":[{"price":3798.93,"qty":0.73120000}],"checksum":2513346097,"timestamp":"2024-06-01T17:52:35.856453Z"}]}
{"channel":"book","type":"update","data":[{"symbol":"ETH/USDT","bids":[],"asks":[{"price":3798.93,"qty":0.00000000},{"price":3799.89,"qty":0.73541065}],"checksum":95013221,"timestamp":"2024-06-01T17:52:35.860995Z"}]}
{"channel":"book","type":"update","data":[{"symbol":"ETH/USDT","bids":[],"asks":[{"price":3798.95,"qty":0.00000000},{"price":3800.05,"qty":2.63368772}],"checksum":3693271212,"timestamp":"2024-06-01T17:52:35.861005Z"}]}
{"channel":"book","type":"update","data":[{"symbol":"ETH/USDT","bids":[],"asks":[{"price":3798.96,"qty":1.46240000}],"checksum":3918960271,"timestamp":"2024-06-01T17:52:35.866667Z"}]}
{"channel":"book","type":"update","data":[{"symbol":"ETH/USDT","bids":[],"asks":[{"price":3798.96,"qty":0.73120000}],"checksum":3693271212,"timestamp":"2024-06-01T17:52:35.922779Z"}]}
{"channel":"book","type":"update","data":[{"symbol":"ETH/USDT","bids":[{"price":3798.23,"qty":0.98120000}],"asks":[],"checksum":3700946841,"timestamp":"2024-06-01T17:52:35.923676Z"}]}
{"channel":"book","type":"update","data":[{"symbol":"ETH/USDT","bids":[],"asks":[{"price":3798.96,"qty":1.46240000}],"checksum":3911432634,"timestamp":"2024-06-01T17:52:35.926429Z"}]}
{"channel":"book","type":"update","data":[{"symbol":"ETH/USDT","bids":[],"asks":[{"price":3798.95,"qty":0.72912968}],"checksum":1112347192,"timestamp":"2024-06-01T17:52:35.926962Z"}]}
{"channel":"book","type":"update","data":[{"symbol":"ETH/USDT","bids":[{"price":3798.23,"qty":0.25000000}],"asks":[],"checksum":1123564813,"timestamp":"2024-06-01T17:52:35.927760Z"}]}
{"channel":"book","type":"update","data":[{"symbol":"ETH/USDT","bids":[],"asks":[{"price":3798.96,"qty":0.73120000}],"checksum":95013221,"timestamp":"2024-06-01T17:52:35.930349Z"}]}
{"channel":"book","type":"update","data":[{"symbol":"ETH/USDT","bids":[],"asks":[{"price":3798.93,"qty":0.73120000}],"checksum":2513346097,"timestamp":"2024-06-01T17:52:35.932754Z"}]}
{"channel":"book","type":"update","data":[{"symbol":"ETH/USDT","bids":[],"asks":[{"price":3798.93,"qty":0.00000000},{"price":3799.89,"qty":0.73541065}],"checksum":95013221,"timestamp":"2024-06-01T17:52:35.936530Z"}]}
{"channel":"book","type":"update","data":[{"symbol":"ETH/USDT","bids":[],"asks":[{"price":3798.92,"qty":0.73120000}],"checksum":3827029096,"timestamp":"2024-06-01T17:52:35.942589Z"}]}
{"channel":"book","type":"update","data":[{"symbol":"ETH/USDT","bids":[],"asks":[{"price":3798.92,"qty":0.00000000},{"price":3799.89,"qty":0.73541065}],"checksum":95013221,"timestamp":"2024-06-01T17:52:35.946557Z"}]}
{"channel":"book","type":"update","data":[{"symbol":"ETH/USDT","bids":[],"asks":[{"price":3798.95,"qty":1.46032968}],"checksum":2200800217,"timestamp":"2024-06-01T17:52:35.951803Z"}]}
{"channel":"book","type":"update","data":[{"symbol":"ETH/USDT","bids":[],"asks":[{"price":3798.95,"qty":2.19152968}],"checksum":466002728,"timestamp":"2024-06-01T17:52:36.000782Z"}]}
{"channel":"book","type":"update","data":[{"symbol":"ETH/USDT","bids":[],"asks":[{"price":3798.97,"qty":0.00000000},{"price":3800.05,"qty":2.63368772}],"checksum":3780102011,"timestamp":"2024-06-01T17:52:36.004801Z"}]}
{"channel":"book","type":"update","data":[{"symbol":"ETH/USDT","bids":[{"price":3797.87,"qty":5.00000000}],"asks":[],"checksum":2851282374,"timestamp":"2024-06-01T17:52:36.005825Z"}]}
{"channel":"book","type":"update","data":[{"symbol":"ETH/USDT","bids":[{"price":3797.42,"qty":0.49488748}],"asks":[],"checksum":2563669487,"timestamp":"2024-06-01T17:52:36.027554Z"}]}
{"channel":"book","type":"update","data":[{"symbol":"ETH/USDT","bids":[{"price":3797.41,"qty":0.92862090}],"asks":[],"checksum":34551075,"timestamp":"2024-06-01T17:52:36.067553Z"}]}
{"channel":"book","type":"update","data":[{"symbol":"ETH/USDT","bids":[],"asks":[{"price":3798.95,"qty":1.46032968}],"checksum":975033806,"timestamp":"2024-06-01T17:52:36.157287Z"}]}
{"channel":"book","type":"update","data":[{"symbol":"ETH/USDT","bids":[{"price":3798.23,"qty":0.98120000}],"asks":[],"checksum":1823384770,"timestamp":"2024-06-01T17:52:36.157613Z"}]}
{"channel":"book","type":"update","data":[{"symbol":"ETH/USDT","bids":[],"asks":[{"price":3798.96,"qty":0.00000000},{"price":3800.23,"qty":5.00000000}],"checksum":1705219312,"timestamp":"2024-06-01T17:52:36.157740Z"}]}
{"channel":"book","type":"update","data":[{"symbol":"ETH/USDT","bids":[],"asks":[{"price":3798.95,"qty":0.72912968}],"checksum":2172516796,"timestamp":"2024-06-01T17:52:36.158498Z"}]}
{"channel":"book","type":"update","data":[{"symbol":"ETH/USDT","bids":[{"price":3798.27,"qty":0.73120000}],"asks":[],"checksum":470942057,"timestamp":"2024-06-01T17:52:36.161848Z"}]}
{"channel":"book","type":"update","data":[{"symbol":"ETH/USDT","bids":[{"price":3798.27,"qty":0.00000000},{"price":3797.07,"qty":1.31755430}],"asks":[],"checksum":2172516796,"timestamp":"2024-06-01T17:52:36.197860Z"}]}
{"channel":"book","type":"update","data":[{"symbol":"ETH/USDT","bids":[],"asks":[{"price":3798.91,"qty":0.73120000}],"checksum":3526557583,"timestamp":"2024-06-01T17:52:36.199883Z"}]}
{"channel":"book","type":"update","data":[{"symbol":"ETH/USDT","bids":[{"price":3798.23,"qty":0.25000000}],"asks":[],"checksum":2223083139,"timestamp":"2024-06-01T17:52:36.200421Z"}]}
{"channel":"book","type":"update","data":[{"symbol":"ETH/USDT","bids":[],"asks":[{"price":3798.91,"qty":0.00000000},{"price":3800.23,"qty":5.00000000}],"checksum":3620636848,"timestamp":"2024-06-01T17:52:36.202353Z"}]}
{"channel":"book","type":"update","data":[{"symbol":"ETH/USDT","bids":[],"asks":[{"price":3798.95,"qty":1.46032968}],"checksum":856745468,"timestamp":"2024-06-01T17:52:36.208205Z"}]}
{"channel":"book","type":"update","data":[{"symbol":"ETH/USDT","bids":[{"price":3798.29,"qty":0.73120000}],"asks":[],"checksum":1575272090,"timestamp":"2024-06-01T17:52:36.263321Z"}]}
{"channel":"book","type":"update","data":[{"symbol":"ETH/USDT","bids":[],"asks":[{"price":3798.95,"qty":0.72912968}],"checksum":2370238742,"timestamp":"2024-06-01T17:52:36.263387Z"}]}
{"channel":"book","type":"update","data":[{"symbol":"ETH/USDT","bids":[{"price":3798.29,"qty":0.00000000},{"price":3797.07,"qty":1.31755430}],"asks":[],"checksum":3620636848,"timestamp":"2024-06-01T17:52:36.266324Z"}]}
{"channel":"book","type":"update","data":[{"symbol":"ETH/USDT","bids":[],"asks":[{"price":3798.95,"qty":1.46032968}],"checksum":856745468,"timestamp":"2024-06-01T17:52:36.271648Z"}]}
{"channel":"book","type":"update","data":[{"symbol":"ETH/USDT","bids":[],"asks":[{"price":3798.90,"qty":0.73120000}],"checksum":3745790983,"timestamp":"2024-06-01T17:52:36.473010Z"}]}
{"channel":"book","type":"update","data":[{"symbol":"ETH/USDT","bids":[],"asks":[{"price":3798.90,"qty":0.00000000},{"price":3800.23,"qty":5.00000000}],"checksum":856745468,"timestamp":"2024-06-01T17:52:36.475689Z"}]}
{"channel":"book","type":"update","data":[{"symbol":"ETH/USDT","bids":[],"asks":[{"price":3798.95,"qty":0.72912968}],"checksum":3620636848,"timestamp":"2024-06-01T17:52:36.476992Z"}]}
{"channel":"book","type":"update","data":[{"symbol":"ETH/USDT","bids":[],"asks":[{"price":3799.85,"qty":29.13647326}],"checksum":2063897389,"timestamp":"2024-06-01T17:52:36.478826Z"}]}
{"channel":"book","type":"update","data":[{"symbol":"ETH/USDT","bids":[],"asks":[{"price":3798.95,"qty":1.46032968}],"checksum":76169467,"timestamp":"2024-06-01T17:52:36.480382Z"}]}
{"channel":"book","type":"update","data":[{"symbol":"ETH/USDT","bids":[],"asks":[{"price":3798.95,"qty":2.19152968}],"checksum":1330648880,"timestamp":"2024-06-01T17:52:36.480397Z"}]}
{"channel":"book","type":"update","data":[{"symbol":"ETH/USDT","bids":[],"asks":[{"price":3798.94,"qty":0.73120000}],"checksum":1441188021,"timestamp":"2024-06-01T17:52:36.486369Z"}]}
{"channel":"book","type":"update","data":[{"symbol":"ETH/USDT","bids":[],"asks":[{"price":3798.95,"qty":1.46032968}],"checksum":2369858683,"timestamp":"2024-06-01T17:52:36.489535Z"}]}
{"channel":"book","type":"update","data":[{"symbol":"ETH/USDT","bids":[],"asks":[{"price":3798.94,"qty":1.46240000}],"checksum":3434079595,"timestamp":"2024-06-01T17:52:36.492301Z"}]}
{"channel":"book","type":"update","data":[{"symbol":"ETH/USDT","bids":[],"asks":[{"price":3798.94,"qty":0.73120000}],"checksum":2369858683,"timestamp":"2024-06-01T17:52:36.508985Z"}]}
{"channel":"book","type":"update","data":[{"symbol":"ETH/USDT","bids":[],"asks":[{"price":3798.95,"qty":0.72912968}],"checksum":2835382777,"timestamp":"2024-06-01T17:52:36.508999Z"}]}
{"channel":"book","type":"update","data":[{"symbol":"ETH/USDT","bids":[],"asks":[{"price":3798.94,"qty":1.46240000}],"checksum":1135866194,"timestamp":"2024-06-01T17:52:36.529472Z"}]}
{"channel":"book","type":"update","data":[{"symbol":"ETH/USDT","bids":[],"asks":[{"price":3798.94,"qty":0.73120000}],"checksum":2835382777,"timestamp":"2024-06-01T17:52:36.616422Z"}]}
{"channel":"book","type":"update","data":[{"symbol":"ETH/USDT","bids":[],"asks":[{"price":3798.94,"qty":1.46240000}],"checksum":1135866194,"timestamp":"2024-06-01T17:52:36.703162Z"}]}
{"channel":"book","type":"update","data":[{"symbol":"ETH/USDT","bids":[],"asks":[{"price":3798.94,"qty":0.73120000}],"checksum":2835382777,"timestamp":"2024-06-01T17:52:36.778118Z"}]}
{"channel":"book","type":"update","data":[{"symbol":"ETH/USDT","bids":[],"asks":[{"price":3798.94,"qty":1.46240000}],"checksum":1135866194,"timestamp":"2024-06-01T17:52:36.802415Z"}]}
{"channel":"book","type":"update","data":[{"symbol":"ETH/USDT","bids":[{"price":3797.58,"qty":0.90261790}],"asks":[],"checksum":3178900010,"timestamp":"2024-06-01T17:52:36.840835Z"}]}
{"channel":"book","type":"update","data":[{"symbol":"ETH/USDT","bids":[{"price":3797.39,"qty":2.79800000}],"asks":[],"checksum":1148720192,"timestamp":"2024-06-01T17:52:36.846250Z"}]}
{"channel":"book","type":"update","data":[{"symbol":"ETH/USDT","bids":[{"price":3798.22,"qty":0.00000000},{"price":3797.07,"qty":1.31755430}],"asks":[],"checksum":992386393,"timestamp":"2024-06-01T17:52:36.849442Z"}]}
{"channel":"book","type":"update","data":[{"symbol":"ETH/USDT","bids":[],"asks":[{"price":3798.84,"qty":2.63452674}],"checksum":1736072054,"timestamp":"2024-06-01T17:52:36.882267Z"}]}
{"channel":"book","type":"update","data":[{"symbol":"ETH/USDT","bids":[],"asks":[{"price":3798.82,"qty":0.73120000}],"checksum":3155242235,"timestamp":"2024-06-01T17:52:36.885511Z"}]}
{"channel":"book","type":"update","data":[{"symbol":"ETH/USDT","bids":[{"price":3797.86,"qty":0.00000000},{"price":3797.03,"qty":0.72912968}],"asks":[],"checksum":717948322,"timestamp":"2024-06-01T17:52:36.885538Z"}]}
{"channel":"book","type":"update","data":[{"symbol":"ETH/USDT","bids":[],"asks":[{"price":3798.83,"qty":0.72912968}],"checksum":4190865318,"timestamp":"2024-06-01T17:52:36.886442Z"}]}
{"channel":"book","type":"update","data":[{"symbol":"ETH/USDT","bids":[{"price":3798.23,"qty":0.00000000},{"price":3796.95,"qty":0.73120000}],"asks":[],"checksum":1555114384,"timestamp":"2024-06-01T17:52:36.887894Z"}]}
{"channel":"book","type":"update","data":[{"symbol":"ETH/USDT","bids":[{"price":3797.85,"qty":0.73120000}],"asks":[],"checksum":1148786508,"timestamp":"2024-06-01T17:52:36.888436Z"}]}
{"channel":"book","type":"update","data":[{"symbol":"ETH/USDT","bids":[{"price":3797.58,"qty":5.90261790}],"asks":[],"checksum":647950094,"timestamp":"2024-06-01T17:52:36.888483Z"}]}
{"channel":"book","type":"update","data":[{"symbol":"ETH/USDT","bids":[{"price":3797.87,"qty":0.00000000},{"price":3796.95,"qty":0.73120000}],"asks":[],"checksum":1857884256,"timestamp":"2024-06-01T17:52:36.888497Z"}]}
{"channel":"book","type":"update","data":[{"symbol":"ETH/USDT","bids":[{"price":3798.00,"qty":0.73120000}],"asks":[],"checksum":2828613439,"timestamp":"2024-06-01T17:52:36.891839Z"}]}
{"channel":"book","type":"update","data":[{"symbol":"ETH/USDT","bids":[],"asks":[{"price":3798.84,"qty":0.00000000},{"price":3799.86,"qty":0.40000000}],"checksum":1395853887,"timestamp":"2024-06-01T17:52:36.892448Z"}]}
{"channel":"book","type":"update","data":[{"symbol":"ETH/USDT","bids":[{"price":3798.00,"qty":0.00000000},{"price":3796.95,"qty":0.73120000}],"asks":[],"checksum":2501324128,"timestamp":"2024-06-01T17:52:36.901486Z"}]}
{"channel":"book","type":"update","data":[{"symbol":"ETH/USDT","bids":[{"price":3797.85,"qty":0.00000000},{"price":3796.77,"qty":0.10355379}],"asks":[],"checksum":4173432841,"timestamp":"2024-06-01T17:52:36.905505Z"}]}
{"channel":"book","type":"update","data":[{"symbol":"ETH/USDT","bids":[{"price":3797.86,"qty":0.73120000}],"asks":[],"checksum":2604104543,"timestamp":"2024-06-01T17:52:36.908072Z"}]}
{"channel":"book","type":"update","data":[{"symbol":"ETH/USDT","bids":[{"price":3797.76,"qty":0.73120000}],"asks":[],"checksum":1106527977,"timestamp":"2024-06-01T17:52:36.909492Z"}]}
{"channel":"book","type":"update","data":[{"symbol":"ETH/USDT","bids":[{"price":3797.86,"qty":1.46240000}],"asks":[],"checksum":3067728825,"timestamp":"2024-06-01T17:52:36.911411Z"}]}
{"channel":"book","type":"update","data":[{"symbol":"ETH/USDT","bids":[{"price":3797.86,"qty":0.73120000}],"asks":[],"checksum":1106527977,"timestamp":"2024-06-01T17:52:36.911703Z"}]}
{"channel":"book","type":"update","data":[{"symbol":"ETH/USDT","bids":[{"price":3797.76,"qty":0.00000000},{"price":3796.95,"qty":0.73120000}],"asks":[],"checksum":2604104543,"timestamp":"2024-06-01T17:52:36.913102Z"}]}
{"channel":"book","type":"update","data":[{"symbol":"ETH/USDT","bids":[{"price":3797.86,"qty":1.46240000}],"asks":[],"checksum":1813704207,"timestamp":"2024-06-01T17:52:36.914258Z"}]}
{"channel":"book","type":"update","data":[{"symbol":"ETH/USDT","bids":[],"asks":[{"price":3798.83,"qty":0.00000000},{"price":3799.87,"qty":5.26500000}],"checksum":2795893571,"timestamp":"2024-06-01T17:52:36.916821Z"}]}
{"channel":"book","type":"update","data":[{"symbol":"ETH/USDT","bids":[{"price":3797.87,"qty":0.25000000}],"asks":[],"checksum":410541472,"timestamp":"2024-06-01T17:52:36.917776Z"}]}
{"channel":"book","type":"update","data":[{"symbol":"ETH/USDT","bids":[{"price":3797.87,"qty":1.09627249}],"asks":[],"checksum":3848590295,"timestamp":"2024-06-01T17:52:36.919936Z"}]}
{"channel":"book","type":"update","data":[{"symbol":"ETH/USDT","bids":[{"price":3797.86,"qty":0.73120000}],"asks":[],"checksum":2059986268,"timestamp":"2024-06-01T17:52:36.921102Z"}]}
{"channel":"book","type":"update","data":[{"symbol":"ETH/USDT","bids":[{"price":3797.57,"qty":0.00000000},{"price":3796.95,"qty":0.73120000}],"asks":[],"checksum":1337232792,"timestamp":"2024-06-01T17:52:36.952379Z"}]}
{"channel":"book","type":"update","data":[{"symbol":"ETH/USDT","bids":[],"asks":[{"price":3798.81,"qty":0.72912968}],"checksum":4230419197,"timestamp":"2024-06-01T17:52:36.956555Z"}]}
{"channel":"book","type":"update","data":[{"symbol":"ETH/USDT","bids":[],"asks":[{"price":3799.86,"qty":1.24627249}],"checksum":2243683624,"timestamp":"2024-06-01T17:52:36.957200Z"}]}
{"channel":"book","type":"update","data":[{"symbol":"ETH/USDT","bids":[{"price":3797.59,"qty":5.00000000}],"asks":[],"checksum":1222781130,"timestamp":"2024-06-01T17:52:36.957404Z"}]}
{"channel":"book","type":"update","data":[{"symbol":"ETH/USDT","bids":[],"asks":[{"price":3798.71,"qty":0.73120000}],"checksum":2931856107,"timestamp":"2024-06-01T17:52:36.960481Z"}]}
{"channel":"book","type":"update","data":[{"symbol":"ETH/USDT","bids":[],"asks":[{"price":3798.94,"qty":0.73120000}],"checksum":1550190541,"timestamp":"2024-06-01T17:52:36.960576Z"}]}
{"channel":"book","type":"update","data":[{"symbol":"ETH/USDT","bids":[{"price":3797.88,"qty":1.31735991}],"asks":[],"checksum":4215032834,"timestamp":"2024-06-01T17:52:36.981591Z"}]}
{"channel":"book","type":"update","data":[{"symbol":"ETH/USDT","bids":[{"price":3797.88,"qty":1.54735991}],"asks":[],"checksum":1593682644,"timestamp":"2024-06-01T17:52:36.987373Z"}]}
{"channel":"book","type":"update","data":[{"symbol":"ETH/USDT","bids":[],"asks":[{"price":3798.81,"qty":0.00000000},{"price":3799.86,"qty":1.24627249}],"checksum":96741076,"timestamp":"2024-06-01T17:52:36.991483Z"}]}
{"channel":"book","type":"update","data":[{"symbol":"ETH/USDT","bids":[{"price":3797.89,"qty":0.84627249}],"asks":[],"checksum":444719220,"timestamp":"2024-06-01T17:52:36.992611Z"}]}
{"channel":"book","type":"update","data":[{"symbol":"ETH/USDT","bids":[{"price":3797.59,"qty":0.00000000},{"price":3797.07,"qty":1.31755430}],"asks":[],"checksum":3466698717,"timestamp":"2024-06-01T17:52:36.992716Z"}]}
{"channel":"book","type":"update","data":[{"symbol":"ETH/USDT","bids":[],"asks":[{"price":3798.82,"qty":0.00000000},{"price":3799.87,"qty":5.26500000}],"checksum":2215518260,"timestamp":"2024-06-01T17:52:36.995825Z"}]}
{"channel":"book","type":"update","data":[{"symbol":"ETH/USDT","bids":[{"price":3797.90,"qty":1.31740156}],"asks":[],"checksum":2868707126,"timestamp":"2024-06-01T17:52:37.009567Z"}]}
{"channel":"book","type":"update","data":[{"symbol":"ETH/USDT","bids":[{"price":3797.88,"qty":0.23000000}],"asks":[],"checksum":475898664,"timestamp":"2024-06-01T17:52:37.013367Z"}]}
{"channel":"book","type":"update","data":[{"symbol":"ETH/USDT","bids":[{"price":3797.88,"qty":0.00000000},{"price":3797.07,"qty":1.31755430}],"asks":[],"checksum":1724334054,"timestamp":"2024-06-01T17:52:37.031875Z"}]}
{"channel":"book","type":"update","data":[{"symbol":"ETH/USDT","bids":[{"price":3797.90,"qty":6.31740156}],"asks":[],"checksum":3166578600,"timestamp":"2024-06-01T17:52:37.036697Z"}]}
{"channel":"book","type":"update","data":[{"symbol":"ETH/USDT","bids":[{"price":3797.89,"qty":0.00000000},{"price":3797.03,"qty":0.72912968}],"asks":[],"checksum":1203207834,"timestamp":"2024-06-01T17:52:37.037346Z"}]}
{"channel":"book","type":"update","data":[{"symbol":"ETH/USDT","bids":[{"price":3797.91,"qty":0.84627249}],"asks":[],"checksum":2989268700,"timestamp":"2024-06-01T17:52:37.037408Z"}]}
{"channel":"book","type":"update","data":[{"symbol":"ETH/USDT","bids":[],"asks":[{"price":3799.84,"qty":0.20358573}],"checksum":2182616999,"timestamp":"2024-06-01T17:52:37.135911Z"}]}
{"channel":"book","type":"update","data":[{"symbol":"ETH/USDT","bids":[{"price":3797.41,"qty":0.73120000}],"asks":[],"checksum":2011749126,"timestamp":"2024-06-01T17:52:37.146440Z"}]}
{"channel":"book","type":"update","data":[{"symbol":"ETH/USDT","bids":[{"price":3797.39,"qty":2.99542386}],"asks":[],"checksum":3641973275,"timestamp":"2024-06-01T17:52:37.186634Z"}]}
{"channel":"book","type":"update","data":[{"symbol":"ETH/USDT","bids":[{"price":3797.90,"qty":1.31740156}],"asks":[],"checksum":3036637915,"timestamp":"2024-06-01T17:52:37.207560Z"}]}
{"channel":"book","type":"update","data":[{"symbol":"ETH/USDT","bids":[{"price":3797.91,"qty":5.84627249}],"asks":[],"checksum":637330467,"timestamp":"2024-06-01T17:52:37.207598Z"}]}
{"channel":"book","type":"update","data":[{"symbol":"ETH/USDT","bids":[{"price":3797.87,"qty":0.25000000}],"asks":[],"checksum":2062757096,"timestamp":"2024-06-01T17:52:37.212650Z"}]}
{"channel":"book","type":"update","data":[{"symbol":"ETH/USDT","bids":[{"price":3797.93,"qty":0.73120000}],"asks":[],"checksum":284671551,"timestamp":"2024-06-01T17:52:37.222771Z"}]}
{"channel":"book","type":"update","data":[{"symbol":"ETH/USDT","bids":[{"price":3797.93,"qty":0.00000000},{"price":3797.07,"qty":1.31755430}],"asks":[],"checksum":2062757096,"timestamp":"2024-06-01T17:52:37.360479Z"}]}
{"channel":"book","type":"update","data":[{"symbol":"ETH/USDT","bids":[{"price":3797.58,"qty":0.90261790}],"asks":[],"checksum":1140085338,"timestamp":"2024-06-01T17:52:37.365196Z"}]}
{"channel":"book","type":"update","data":[{"symbol":"ETH/USDT","bids":[],"asks":[{"price":3798.71,"qty":0.00000000},{"price":3799.87,"qty":5.26500000}],"checksum":2905574213,"timestamp":"2024-06-01T17:52:37.396091Z"}]}
{"channel":"book","type":"update","data":[{"symbol":"ETH/USDT","bids":[{"price":3797.97,"qty":0.73120000}],"asks":[],"checksum":2695767997,"timestamp":"2024-06-01T17:52:37.396102Z"}]}
{"channel":"book","type":"update","data":[{"symbol":"ETH/USDT","bids":[],"asks":[{"price":3798.94,"qty":1.46240000}],"checksum":1243436822,"timestamp":"2024-06-01T17:52:37.400121Z"}]}
{"channel":"book","type":"update","data":[{"symbol":"ETH/USDT","bids":[],"asks":[{"price":3798.93,"qty":0.72912968}],"checksum":2616920358,"timestamp":"2024-06-01T17:52:37.401073Z"}]}
{"channel":"book","type":"update","data":[{"symbol":"ETH/USDT","bids":[],"asks":[{"price":3798.79,"qty":0.73120000}],"checksum":3232321627,"timestamp":"2024-06-01T17:52:37.404797Z"}]}
{"channel":"book","type":"update","data":[{"symbol":"ETH/USDT","bids":[],"asks":[{"price":3798.93,"qty":0.00000000},{"price":3799.86,"qty":0.84627249}],"checksum":525526309,"timestamp":"2024-06-01T17:52:37.588065Z"}]}
{"channel":"book","type":"update","data":[{"symbol":"ETH/USDT","bids":[{"price":3797.98,"qty":0.25000000}],"asks":[],"checksum":3814743073,"timestamp":"2024-06-01T17:52:37.588691Z"}]}
{"channel":"book","type":"update","data":[{"symbol":"ETH/USDT","bids":[{"price":3797.99,"qty":1.31740156}],"asks":[],"checksum":2904880466,"timestamp":"2024-06-01T17:52:37.649989Z"}]}
{"channel":"book","type":"update","data":[{"symbol":"ETH/USDT","bids":[{"price":3797.90,"qty":0.00000000},{"price":3797.39,"qty":2.99542386}],"asks":[],"checksum":771927493,"timestamp":"2024-06-01T17:52:37.653725Z"}]}
{"channel":"book","type":"update","data":[{"symbol":"ETH/USDT","bids":[],"asks":[{"price":3798.78,"qty":0.72912968}],"checksum":771857415,"timestamp":"2024-06-01T17:52:37.653940Z"}]}
{"channel":"book","type":"update","data":[{"symbol":"ETH/USDT","bids":[{"price":3797.87,"qty":0.00000000},{"price":3797.23,"qty":2.63563868}],"asks":[],"checksum":4078344909,"timestamp":"2024-06-01T17:52:37.655935Z"}]}
{"channel":"book","type":"update","data":[{"symbol":"ETH/USDT","bids":[],"asks":[{"price":3798.78,"qty":1.46032968}],"checksum":2191662994,"timestamp":"2024-06-01T17:52:37.658662Z"}]}
{"channel":"book","type":"update","data":[{"symbol":"ETH/USDT","bids":[],"asks":[{"price":3798.94,"qty":0.73120000}],"checksum":3354332642,"timestamp":"2024-06-01T17:52:37.659330Z"}]}
{"channel":"book","type":"update","data":[{"symbol":"ETH/USDT","bids":[],"asks":[{"price":3798.79,"qty":0.00000000},{"price":3799.86,"qty":0.84627249}],"checksum":2183297509,"timestamp":"2024-06-01T17:52:37.659615Z"}]}
{"channel":"book","type":"update","data":[{"symbol":"ETH/USDT","bids":[],"asks":[{"price":3798.77,"qty":0.73120000}],"checksum":645520866,"timestamp":"2024-06-01T17:52:37.663288Z"}]}
{"channel":"book","type":"update","data":[{"symbol":"ETH/USDT","bids":[{"price":3797.39,"qty":2.79800000}],"asks":[],"checksum":109409373,"timestamp":"2024-06-01T17:52:37.758604Z"}]}
{"channel":"book","type":"update","data":[{"symbol":"ETH/USDT","bids":[{"price":3797.37,"qty":0.19742844}],"asks":[],"checksum":2436842067,"timestamp":"2024-06-01T17:52:37.798667Z"}]}
{"channel":"book","type":"update","data":[{"symbol":"ETH/USDT","bids":[{"price":3797.97,"qty":0.00000000},{"price":3797.23,"qty":2.63563868}],"asks":[],"checksum":2600100003,"timestamp":"2024-06-01T17:52:37.833330Z"}]}
{"channel":"book","type":"update","data":[{"symbol":"ETH/USDT","bids":[],"asks":[{"price":3798.78,"qty":0.73120000}],"checksum":117586089,"timestamp":"2024-06-01T17:52:37.836992Z"}]}
{"channel":"book","type":"update","data":[{"symbol":"ETH/USDT","bids":[{"price":3797.91,"qty":0.84627249}],"asks":[],"checksum":1463448236,"timestamp":"2024-06-01T17:52:37.838059Z"}]}
{"channel":"book","type":"update","data":[{"symbol":"ETH/USDT","bids":[{"price":3798.00,"qty":0.25000000}],"asks":[],"checksum":2927728507,"timestamp":"2024-06-01T17:52:37.838490Z"}]}
{"channel":"book","type":"update","data":[{"symbol":"ETH/USDT","bids":[],"asks":[{"price":3798.78,"qty":0.00000000},{"price":3799.86,"qty":0.84627249}],"checksum":3642435250,"timestamp":"2024-06-01T17:52:37.841398Z"}]}
{"channel":"book","type":"update","data":[{"symbol":"ETH/USDT","bids":[],"asks":[{"price":3798.70,"qty":2.63462384}],"checksum":4277448578,"timestamp":"2024-06-01T17:52:37.882870Z"}]}
{"channel":"book","type":"update","data":[{"symbol":"ETH/USDT","bids":[{"price":3797.98,"qty":0.00000000},{"price":3797.23,"qty":2.63563868}],"asks":[],"checksum":3875351909,"timestamp":"2024-06-01T17:52:37.887519Z"}]}
{"channel":"book","type":"update","data":[{"symbol":"ETH/USDT","bids":[],"asks":[{"price":3798.70,"qty":3.36582384}],"checksum":2797214270,"timestamp":"2024-06-01T17:52:37.887679Z"}]}
{"channel":"book","type":"update","data":[{"symbol":"ETH/USDT","bids":[],"asks":[{"price":3798.77,"qty":0.00000000},{"price":3799.86,"qty":0.84627249}],"checksum":296255652,"timestamp":"2024-06-01T17:52:37.898844Z"}]}
{"channel":"book","type":"update","data":[{"symbol":"ETH/USDT","bids":[],"asks":[{"price":3798.67,"qty":0.73120000}],"checksum":873168612,"timestamp":"2024-06-01T17:52:37.899189Z"}]}
{"channel":"book","type":"update","data":[{"symbol":"ETH/USDT","bids":[],"asks":[{"price":3798.70,"qty":0.73120000}],"checksum":3673334715,"timestamp":"2024-06-01T17:52:37.904720Z"}]}
{"channel":"book","type":"update","data":[{"symbol":"ETH/USDT","bids":[],"asks":[{"price":3798.70,"qty":0.00000000},{"price":3799.86,"qty":0.84627249}],"checksum":3536178778,"timestamp":"2024-06-01T17:52:37.908342Z"}]}
{"channel":"book","type":"update","data":[{"symbol":"ETH/USDT","bids":[{"price":3797.86,"qty":0.00000000},{"price":3797.07,"qty":1.31755430}],"asks":[],"checksum":2893178388,"timestamp":"2024-06-01T17:52:37.912005Z"}]}
{"channel":"book","type":"update","data":[{"symbol":"ETH/USDT","bids":[{"price":3797.39,"qty":0.00000000},{"price":3797.03,"qty":0.72912968},{"price":3797.24,"qty":2.79800000}],"asks":[],"checksum":1636885877,"timestamp":"2024-06-01T17:52:37.914797Z"}]}
{"channel":"book","type":"update","data":[{"symbol":"ETH/USDT","bids":[{"price":3797.42,"qty":0.00000000},{"price":3797.03,"qty":0.72912968}],"asks":[],"checksum":1392927125,"timestamp":"2024-06-01T17:52:37.918627Z"}]}
{"channel":"book","type":"update","data":[{"symbol":"ETH/USDT","bids":[{"price":3797.10,"qty":2.13500000}],"asks":[],"checksum":619027894,"timestamp":"2024-06-01T17:52:37.923013Z"}]}
{"channel":"book","type":"update","data":[{"symbol":"ETH/USDT","bids":[],"asks":[{"price":3798.98,"qty":0.00000000},{"price":3799.87,"qty":5.26500000}],"checksum":2866320925,"timestamp":"2024-06-01T17:52:37.951180Z"}]}
{"channel":"book","type":"update","data":[{"symbol":"ETH/USDT","bids":[],"asks":[{"price":3799.87,"qty":0.00000000},{"price":3799.89,"qty":0.73541065}],"checksum":435837530,"timestamp":"2024-06-01T17:52:37.951310Z"}]}
{"channel":"book","type":"update","data":[{"symbol":"ETH/USDT","bids":[],"asks":[{"price":3798.67,"qty":0.00000000},{"price":3800.05,"qty":2.63368772}],"checksum":127396348,"timestamp":"2024-06-01T17:52:37.966827Z"}]}
{"channel":"book","type":"update","data":[{"symbol":"ETH/USDT","bids":[{"price":3798.13,"qty":0.73120000}],"asks":[],"checksum":2175803171,"timestamp":"2024-06-01T17:52:37.967867Z"}]}
{"channel":"book","type":"update","data":[{"symbol":"ETH/USDT","bids":[{"price":3798.18,"qty":0.73120000}],"asks":[],"checksum":957174092,"timestamp":"2024-06-01T17:52:37.968247Z"}]}
{"channel":"book","type":"update","data":[{"symbol":"ETH/USDT","bids":[],"asks":[{"price":3798.94,"qty":0.00000000},{"price":3800.23,"qty":5.00000000}],"checksum":3236841272,"timestamp":"2024-06-01T17:52:37.969171Z"}]}
{"channel":"book","type":"update","data":[{"symbol":"ETH/USDT","bids":[],"asks":[{"price":3799.51,"qty":0.00000000},{"price":3800.26,"qty":2.79800000}],"checksum":2827735896,"timestamp":"2024-06-01T17:52:37.970986Z"}]}
{"channel":"book","type":"update","data":[{"symbol":"ETH/USDT","bids":[],"asks":[{"price":3800.26,"qty":0.00000000},{"price":3800.53,"qty":0.74200000}],"checksum":2884683170,"timestamp":"2024-06-01T17:52:37.973241Z"}]}
{"channel":"book","type":"update","data":[{"symbol":"ETH/USDT","bids":[],"asks":[{"price":3798.95,"qty":0.00000000},{"price":3800.65,"qty":0.73120000}],"checksum":2006571700,"timestamp":"2024-06-01T17:52:37.974702Z"}]}
{"channel":"book","type":"update","data":[{"symbol":"ETH/USDT","bids":[],"asks":[{"price":3800.23,"qty":0.00000000},{"price":3800.89,"qty":2.63310660}],"checksum":2853713951,"timestamp":"2024-06-01T17:52:37.974976Z"}]}
{"channel":"book","type":"update","data":[{"symbol":"ETH/USDT","bids":[],"asks":[{"price":3799.86,"qty":0.00000000},{"price":3801.12,"qty":3.55776000}],"checksum":1769013405,"timestamp":"2024-06-01T17:52:37.975192Z"}]}
{"channel":"book","type":"update","data":[{"symbol":"ETH/USDT","bids":[],"asks":[{"price":3799.49,"qty":0.00000000},{"price":3801.15,"qty":0.73120000}],"checksum":3694373068,"timestamp":"2024-06-01T17:52:37.975293Z"}]}
{"channel":"book","type":"update","data":[{"symbol":"ETH/USDT","bids":[],"asks":[{"price":3800.80,"qty":2.79800000}],"checksum":744473931,"timestamp":"2024-06-01T17:52:37.976742Z"}]}
{"channel":"book","type":"update","data":[{"symbol":"ETH/USDT","bids":[],"asks":[{"price":3799.45,"qty":2.63501328}],"checksum":3718403098,"timestamp":"2024-06-01T17:52:37.978507Z"}]}
{"channel":"book","type":"update","data":[{"symbol":"ETH/USDT","bids":[{"price":3797.23,"qty":0.00000000},{"price":3797.10,"qty":2.13500000}],"asks":[],"checksum":1859494979,"timestamp":"2024-06-01T17:52:37.981312Z"}]}
{"channel":"book","type":"update","data":[{"symbol":"ETH/USDT","bids":[],"asks":[{"price":3800.05,"qty":0.00000000},{"price":3801.15,"qty":0.73120000}],"checksum":2373064013,"timestamp":"2024-06-01T17:52:37.990073Z"}]}
{"channel":"book","type":"update","data":[{"symbol":"ETH/USDT","bids":[],"asks":[{"price":3799.45,"qty":0.00000000},{"price":3801.18,"qty":9.38363325}],"checksum":2345510406,"timestamp":"2024-06-01T17:52:37.994848Z"}]}
{"channel":"book","type":"update","data":[{"symbol":"ETH/USDT","bids":[{"price":3798.22,"qty":2.63401792}],"asks":[],"checksum":3358956777,"timestamp":"2024-06-01T17:52:37.995129Z"}]}
{"channel":"book","type":"update","data":[{"symbol":"ETH/USDT","bids":[{"price":3798.02,"qty":2.63509124}],"asks":[],"checksum":2758854563,"timestamp":"2024-06-01T17:52:37.995590Z"}]}
{"channel":"book","type":"update","data":[{"symbol":"ETH/USDT","bids":[],"asks":[{"price":3799.89,"qty":0.00421065}],"checksum":1675867103,"timestamp":"2024-06-01T17:52:37.996431Z"}]}
{"channel":"book","type":"update","data":[{"symbol":"ETH/USDT","bids":[],"asks":[{"price":3800.80,"qty":0.00000000},{"price":3801.43,"qty":1.05332805}],"checksum":1756803257,"timestamp":"2024-06-01T17:52:38.002476Z"}]}
{"channel":"book","type":"update","data":[{"symbol":"ETH/USDT","bids":[{"price":3798.40,"qty":0.73120000}],"asks":[],"checksum":4204930837,"timestamp":"2024-06-01T17:52:38.004774Z"}]}
{"channel":"book","type":"update","data":[{"symbol":"ETH/USDT","bids":[{"price":3798.59,"qty":0.73120000}],"asks":[],"checksum":209311555,"timestamp":"2024-06-01T17:52:38.004831Z"}]}
{"channel":"book","type":"update","data":[{"symbol":"ETH/USDT","bids":[],"asks":[{"price":3800.01,"qty":0.73120000}],"checksum":3293569725,"timestamp":"2024-06-01T17:52:38.006197Z"}]}
{"channel":"book","type":"update","data":[{"symbol":"ETH/USDT","bids":[{"price":3798.22,"qty":0.00000000},{"price":3797.41,"qty":0.73120000}],"asks":[],"checksum":3724241005,"timestamp":"2024-06-01T17:52:38.007226Z"}]}
{"channel":"book","type":"update","data":[{"symbol":"ETH/USDT","bids":[{"price":3799.62,"qty":2.63305110}],"asks":[],"checksum":643625675,"timestamp":"2024-06-01T17:52:38.007236Z"}]}
{"channel":"book","type":"update","data":[{"symbol":"ETH/USDT","bids":[{"price":3798.23,"qty":0.07902886}],"asks":[],"checksum":1932062852,"timestamp":"2024-06-01T17:52:38.009631Z"}]}
{"channel":"book","type":"update","data":[{"symbol":"ETH/USDT","bids":[{"price":3798.60,"qty":0.07902875}],"asks":[],"checksum":2353360149,"timestamp":"2024-06-01T17:52:38.010725Z"}]}
{"channel":"book","type":"update","data":[{"symbol":"ETH/USDT","bids":[{"price":3798.40,"qty":0.00000000},{"price":3797.91,"qty":0.84627249}],"asks":[],"checksum":1831030379,"timestamp":"2024-06-01T17:52:38.012012Z"}]}
{"channel":"book","type":"update","data":[{"symbol":"ETH/USDT","bids":[{"price":3798.59,"qty":1.46240000}],"asks":[],"checksum":1383249577,"timestamp":"2024-06-01T17:52:38.012053Z"}]}
{"channel":"book","type":"update","data":[{"symbol":"ETH/USDT","bids":[{"price":3799.62,"qty":0.00000000},{"price":3797.58,"qty":0.90261790}],"asks":[],"checksum":2907984041,"timestamp":"2024-06-01T17:52:38.012191Z"}]}
{"channel":"book","type":"update","data":[{"symbol":"ETH/USDT","bids":[{"price":3798.18,"qty":0.00000000},{"price":3797.41,"qty":0.73120000}],"asks":[],"checksum":3090603580,"timestamp":"2024-06-01T17:52:38.012593Z"}]}
{"channel":"book","type":"update","data":[{"symbol":"ETH/USDT","bids":[{"price":3798.23,"qty":0.00000000},{"price":3797.37,"qty":0.19742844}],"asks":[],"checksum":3992447627,"timestamp":"2024-06-01T17:52:38.013877Z"}]}
{"channel":"book","type":"update","data":[{"symbol":"ETH/USDT","bids":[{"price":3798.60,"qty":0.00000000},{"price":3797.24,"qty":2.79800000}],"asks":[],"checksum":220886587,"timestamp":"2024-06-01T17:52:38.015564Z"}]}
{"channel":"book","type":"update","data":[{"symbol":"ETH/USDT","bids":[{"price":3798.78,"qty":0.73120000}],"asks":[],"checksum":1602590344,"timestamp":"2024-06-01T17:52:38.019227Z"}]}
{"channel":"book","type":"update","data":[{"symbol":"ETH/USDT","bids":[{"price":3798.60,"qty":0.84627249}],"asks":[],"checksum":1082500598,"timestamp":"2024-06-01T17:52:38.019259Z"}]}
{"channel":"book","type":"update","data":[{"symbol":"ETH/USDT","bids":[{"price":3798.97,"qty":0.73120000}],"asks":[],"checksum":3784915100,"timestamp":"2024-06-01T17:52:38.019719Z"}]}
{"channel":"book","type":"update","data":[{"symbol":"ETH/USDT","bids":[{"price":3798.64,"qty":2.63365618}],"asks":[],"checksum":1593904740,"timestamp":"2024-06-01T17:52:38.020334Z"}]}
{"channel":"book","type":"update","data":[{"symbol":"ETH/USDT","bids":[{"price":3798.59,"qty":0.73120000}],"asks":[],"checksum":1068234259,"timestamp":"2024-06-01T17:52:38.024467Z"}]}
{"channel":"book","type":"update","data":[{"symbol":"ETH/USDT","bids":[{"price":3798.78,"qty":0.00000000},{"price":3797.58,"qty":0.90261790}],"asks":[],"checksum":1048309689,"timestamp":"2024-06-01T17:52:38.024704Z"}]}
{"channel":"book","type":"update","data":[{"symbol":"ETH/USDT","bids":[{"price":3798.97,"qty":1.46240000}],"asks":[],"checksum":2968432029,"timestamp":"2024-06-01T17:52:38.025586Z"}]}
{"channel":"book","type":"update","data":[{"symbol":"ETH/USDT","bids":[],"asks":[{"price":3799.63,"qty":0.00000000},{"price":3801.43,"qty":1.05332805}],"checksum":1817216013,"timestamp":"2024-06-01T17:52:38.028749Z"}]}
{"channel":"book","type":"update","data":[{"symbol":"ETH/USDT","bids":[{"price":3797.93,"qty":2.13500000}],"asks":[],"checksum":2305113154,"timestamp":"2024-06-01T17:52:38.033571Z"}]}
{"channel":"book","type":"update","data":[{"symbol":"ETH/USDT","bids":[{"price":3798.64,"qty":0.00000000},{"price":3797.58,"qty":0.90261790}],"asks":[],"checksum":4053466171,"timestamp":"2024-06-01T17:52:38.039707Z"}]}
{"channel":"book","type":"update","data":[{"symbol":"ETH/USDT","bids":[],"asks":[{"price":3800.01,"qty":0.00000000},{"price":3801.53,"qty":0.73120000}],"checksum":2780579418,"timestamp":"2024-06-01T17:52:38.043021Z"}]}
{"channel":"book","type":"update","data":[{"symbol":"ETH/USDT","bids":[],"asks":[{"price":3800.22,"qty":0.73120000}],"checksum":207682230,"timestamp":"2024-06-01T17:52:38.046597Z"}]}
{"channel":"book","type":"update","data":[{"symbol":"ETH/USDT","bids":[{"price":3797.91,"qty":0.00000000},{"price":3797.41,"qty":0.73120000}],"asks":[],"checksum":1933162839,"timestamp":"2024-06-01T17:52:38.050049Z"}]}
{"channel":"book","type":"update","data":[{"symbol":"ETH/USDT","bids":[{"price":3798.98,"qty":0.84627249}],"asks":[],"checksum":3994778337,"timestamp":"2024-06-01T17:52:38.050326Z"}]}
{"channel":"book","type":"update","data":[{"symbol":"ETH/USDT","bids":[{"price":3797.82,"qty":0.72912968}],"asks":[],"checksum":1162953246,"timestamp":"2024-06-01T17:52:38.050799Z"}]}
{"channel":"book","type":"update","data":[{"symbol":"ETH/USDT","bids":[{"price":3799.16,"qty":0.73120000}],"asks":[],"checksum":2716004926,"timestamp":"2024-06-01T17:52:38.054799Z"}]}
{"channel":"book","type":"update","data":[{"symbol":"ETH/USDT","bids":[{"price":3798.09,"qty":0.70488890}],"asks":[],"checksum":1731719923,"timestamp":"2024-06-01T17:52:38.062067Z"}]}
{"channel":"book","type":"update","data":[{"symbol":"ETH/USDT","bids":[],"asks":[{"price":3801.43,"qty":0.00000000},{"price":3801.53,"qty":0.73120000}],"checksum":3849164118,"timestamp":"2024-06-01T17:52:38.068196Z"}]}
{"channel":"book","type":"update","data":[{"symbol":"ETH/USDT","bids":[],"asks":[{"price":3800.67,"qty":2.13500000}],"checksum":2530849140,"timestamp":"2024-06-01T17:52:38.074429Z"}]}
{"channel":"book","type":"update","data":[{"symbol":"ETH/USDT","bids":[],"asks":[{"price":3799.83,"qty":0.72912968}],"checksum":758723670,"timestamp":"2024-06-01T17:52:38.088779Z"}]}
{"channel":"book","type":"update","data":[{"symbol":"ETH/USDT","bids":[{"price":3798.98,"qty":0.00000000},{"price":3797.93,"qty":2.13500000}],"asks":[],"checksum":3314454469,"timestamp":"2024-06-01T17:52:38.095672Z"}]}
{"channel":"book","type":"update","data":[{"symbol":"ETH/USDT","bids":[{"price":3798.42,"qty":0.44053478}],"asks":[],"checksum":2429977352,"timestamp":"2024-06-01T17:52:38.127158Z"}]}
{"channel":"book","type":"update","data":[{"symbol":"ETH/USDT","bids":[{"price":3798.09,"qty":0.00000000},{"price":3797.93,"qty":2.13500000}],"asks":[],"checksum":2340042971,"timestamp":"2024-06-01T17:52:38.185687Z"}]}
{"channel":"book","type":"update","data":[{"symbol":"ETH/USDT","bids":[{"price":3798.88,"qty":0.06693358}],"asks":[],"checksum":3456176276,"timestamp":"2024-06-01T17:52:38.193893Z"}]}
{"channel":"book","type":"update","data":[{"symbol":"ETH/USDT","bids":[{"price":3799.16,"qty":0.00000000},{"price":3797.93,"qty":2.13500000}],"asks":[],"checksum":191374093,"timestamp":"2024-06-01T17:52:38.206570Z"}]}
{"channel":"book","type":"update","data":[{"symbol":"ETH/USDT","bids":[{"price":3798.97,"qty":0.73120000}],"asks":[],"checksum":2672297205,"timestamp":"2024-06-01T17:52:38.210771Z"}]}
{"channel":"book","type":"update","data":[{"symbol":"ETH/USDT","bids":[{"price":3798.60,"qty":1.55116139}],"asks":[],"checksum":1828362973,"timestamp":"2024-06-01T17:52:38.210895Z"}]}
{"channel":"book","type":"update","data":[{"symbol":"ETH/USDT","bids":[{"price":3799.03,"qty":0.73120000}],"asks":[],"checksum":3203293661,"timestamp":"2024-06-01T17:52:38.213234Z"}]}
{"channel":"book","type":"update","data":[{"symbol":"ETH/USDT","bids":[{"price":3799.03,"qty":0.00000000},{"price":3797.93,"qty":2.13500000}],"asks":[],"checksum":1828362973,"timestamp":"2024-06-01T17:52:38.216514Z"}]}
{"channel":"book","type":"update","data":[{"symbol":"ETH/USDT","bids":[{"price":3798.97,"qty":0.00000000},{"price":3797.82,"qty":0.72912968}],"asks":[],"checksum":2426123062,"timestamp":"2024-06-01T17:52:38.216887Z"}]}
{"channel":"book","type":"update","data":[{"symbol":"ETH/USDT","bids":[{"price":3799.03,"qty":0.73120000}],"asks":[],"checksum":481635111,"timestamp":"2024-06-01T17:52:38.217163Z"}]}
{"channel":"book","type":"update","data":[{"symbol":"ETH/USDT","bids":[{"price":3799.03,"qty":1.46240000}],"asks":[],"checksum":2182124647,"timestamp":"2024-06-01T17:52:38.219175Z"}]}
{"channel":"book","type":"update","data":[{"symbol":"ETH/USDT","bids":[{"price":3798.14,"qty":2.79800000}],"asks":[],"checksum":2135849393,"timestamp":"2024-06-01T17:52:38.335133Z"}]}
{"channel":"book","type":"update","data":[{"symbol":"ETH/USDT","bids":[{"price":3799.04,"qty":0.07902061}],"asks":[],"checksum":3772609403,"timestamp":"2024-06-01T17:52:38.368165Z"}]}
{"channel":"book","type":"update","data":[{"symbol":"ETH/USDT","bids":[{"price":3798.02,"qty":0.00000000},{"price":3797.99,"qty":1.31740156}],"asks":[],"checksum":1445167185,"timestamp":"2024-06-01T17:52:38.409638Z"}]}
{"channel":"book","type":"update","data":[{"symbol":"ETH/USDT","bids":[{"price":3798.39,"qty":0.19726685}],"asks":[],"checksum":2719549613,"timestamp":"2024-06-01T17:52:38.414865Z"}]}
{"channel":"book","type":"update","data":[{"symbol":"ETH/USDT","bids":[],"asks":[{"price":3799.83,"qty":3.36297037}],"checksum":1159750295,"timestamp":"2024-06-01T17:52:38.415285Z"}]}
{"channel":"book","type":"update","data":[{"symbol":"ETH/USDT","bids":[{"price":3798.40,"qty":2.63483056}],"asks":[],"checksum":1068528174,"timestamp":"2024-06-01T17:52:38.415356Z"}]}
{"channel":"book","type":"update","data":[{"symbol":"ETH/USDT","bids":[],"asks":[{"price":3799.84,"qty":0.00000000},{"price":3801.18,"qty":9.38363325}],"checksum":3824367358,"timestamp":"2024-06-01T17:52:38.452328Z"}]}
{"channel":"book","type":"update","data":[{"symbol":"ETH/USDT","bids":[{"price":3799.04,"qty":0.00000000},{"price":3798.00,"qty":0.25000000}],"asks":[],"checksum":2305217875,"timestamp":"2024-06-01T17:52:38.552952Z"}]}
{"channel":"book","type":"update","data":[{"symbol":"ETH/USDT","bids":[{"price":3799.04,"qty":0.25000000}],"asks":[],"checksum":3479561074,"timestamp":"2024-06-01T17:52:38.558116Z"}]}
{"channel":"book","type":"update","data":[{"symbol":"ETH/USDT","bids":[{"price":3799.22,"qty":0.73120000}],"asks":[],"checksum":80773191,"timestamp":"2024-06-01T17:52:38.562173Z"}]}
{"channel":"book","type":"update","data":[{"symbol":"ETH/USDT","bids":[],"asks":[{"price":3799.83,"qty":2.63384069}],"checksum":859686725,"timestamp":"2024-06-01T17:52:38.596582Z"}]}
{"channel":"book","type":"update","data":[{"symbol":"ETH/USDT","bids":[{"price":3799.23,"qty":1.31700944}],"asks":[],"checksum":2607345462,"timestamp":"2024-06-01T17:52:38.601372Z"}]}
{"channel":"book","type":"update","data":[{"symbol":"ETH/USDT","bids":[{"price":3799.28,"qty":0.73120000}],"asks":[],"checksum":2049401962,"timestamp":"2024-06-01T17:52:38.604764Z"}]}
{"channel":"book","type":"update","data":[{"symbol":"ETH/USDT","bids":[{"price":3799.03,"qty":0.73120000}],"asks":[],"checksum":3431144936,"timestamp":"2024-06-01T17:52:38.605067Z"}]}
{"channel":"book","type":"update","data":[{"symbol":"ETH/USDT","bids":[],"asks":[{"price":3801.18,"qty":0.00000000},{"price":3801.53,"qty":0.73120000}],"checksum":541348159,"timestamp":"2024-06-01T17:52:38.672687Z"}]}
{"channel":"book","type":"update","data":[{"symbol":"ETH/USDT","bids":[{"price":3798.61,"qty":2.79800000}],"asks":[],"checksum":1644541697,"timestamp":"2024-06-01T17:52:38.879860Z"}]}
{"channel":"book","type":"update","data":[{"symbol":"ETH/USDT","bids":[],"asks":[{"price":3799.85,"qty":0.00000000},{"price":3801.75,"qty":6.85501657}],"checksum":2973404269,"timestamp":"2024-06-01T17:52:38.897451Z"}]}
{"channel":"book","type":"update","data":[{"symbol":"ETH/USDT","bids":[],"asks":[{"price":3801.14,"qty":21.85389089}],"checksum":159936150,"timestamp":"2024-06-01T17:52:38.901924Z"}]}
{"channel":"book","type":"update","data":[{"symbol":"ETH/USDT","bids":[],"asks":[{"price":3800.35,"qty":0.72912968}],"checksum":1339433612,"timestamp":"2024-06-01T17:52:38.901956Z"}]}
{"channel":"book","type":"update","data":[{"symbol":"ETH/USDT","bids":[{"price":3798.48,"qty":0.19725068}],"asks":[],"checksum":1737747807,"timestamp":"2024-06-01T17:52:39.034375Z"}]}
{"channel":"book","type":"update","data":[{"symbol":"ETH/USDT","bids":[{"price":3798.63,"qty":5.00000000}],"asks":[],"checksum":799619293,"timestamp":"2024-06-01T17:52:39.208542Z"}]}
{"channel":"book","type":"update","data":[{"symbol":"ETH/USDT","bids":[],"asks":[{"price":3800.94,"qty":0.84627249}],"checksum":219818590,"timestamp":"2024-06-01T17:52:39.452086Z"}]}
{"channel":"book","type":"update","data":[{"symbol":"ETH/USDT","bids":[],"asks":[{"price":3801.13,"qty":0.21709301}],"checksum":2870376002,"timestamp":"2024-06-01T17:52:39.481898Z"}]}
{"channel":"book","type":"update","data":[{"symbol":"ETH/USDT","bids":[{"price":3799.29,"qty":0.25000000}],"asks":[],"checksum":2839163539,"timestamp":"2024-06-01T17:52:39.585998Z"}]}
{"channel":"book","type":"update","data":[{"symbol":"ETH/USDT","bids":[{"price":3799.32,"qty":0.73120000}],"asks":[],"checksum":3088554392,"timestamp":"2024-06-01T17:52:39.589339Z"}]}
{"channel":"book","type":"update","data":[{"symbol":"ETH/USDT","bids":[{"price":3799.22,"qty":0.00000000},{"price":3798.60,"qty":1.55116139}],"asks":[],"checksum":44226243,"timestamp":"2024-06-01T17:52:39.590267Z"}]}
{"channel":"book","type":"update","data":[{"symbol":"ETH/USDT","bids":[{"price":3799.04,"qty":0.00000000},{"price":3798.59,"qty":0.73120000}],"asks":[],"checksum":1090015762,"timestamp":"2024-06-01T17:52:39.590404Z"}]}
{"channel":"book","type":"update","data":[{"symbol":"ETH/USDT","bids":[],"asks":[{"price":3799.83,"qty":0.00000000},{"price":3801.14,"qty":21.85389089}],"checksum":1865770560,"timestamp":"2024-06-01T17:52:39.959113Z"}]}
{"channel":"book","type":"update","data":[{"symbol":"ETH/USDT","bids":[],"asks":[{"price":3800.22,"qty":0.00000000},{"price":3801.15,"qty":0.73120000}],"checksum":673772895,"timestamp":"2024-06-01T17:52:39.962881Z"}]}
{"channel":"book","type":"update","data":[{"symbol":"ETH/USDT","bids":[],"asks":[{"price":3800.22,"qty":2.63357353}],"checksum":1310244956,"timestamp":"2024-06-01T17:52:39.964315Z"}]}
{"channel":"book","type":"update","data":[{"symbol":"ETH/USDT","bids":[],"asks":[{"price":3800.21,"qty":0.72912968}],"checksum":1342376447,"timestamp":"2024-06-01T17:52:39.964389Z"}]}
{"channel":"book","type":"update","data":[{"symbol":"ETH/USDT","bids":[],"asks":[{"price":3800.27,"qty":0.73120000}],"checksum":3691218947,"timestamp":"2024-06-01T17:52:39.971400Z"}]}
{"channel":"book","type":"update","data":[{"symbol":"ETH/USDT","bids":[],"asks":[{"price":3800.35,"qty":0.00000000},{"price":3801.13,"qty":0.21709301}],"checksum":1525386264,"timestamp":"2024-06-01T17:52:40.088754Z"}]}
{"channel":"book","type":"update","data":[{"symbol":"ETH/USDT","bids":[{"price":3798.60,"qty":1.74846908}],"asks":[],"checksum":1534363340,"timestamp":"2024-06-01T17:52:40.254208Z"}]}
{"channel":"book","type":"update","data":[{"symbol":"ETH/USDT","bids":[{"price":3799.33,"qty":0.25000000}],"asks":[],"checksum":2380363005,"timestamp":"2024-06-01T17:52:40.585553Z"}]}
{"channel":"book","type":"update","data":[{"symbol":"ETH/USDT","bids":[],"asks":[{"price":3800.57,"qty":0.25000000}],"checksum":3201899388,"timestamp":"2024-06-01T17:52:40.585606Z"}]}
{"channel":"book","type":"update","data":[{"symbol":"ETH/USDT","bids":[{"price":3799.28,"qty":0.00000000},{"price":3798.59,"qty":0.73120000}],"asks":[],"checksum":2417773984,"timestamp":"2024-06-01T17:52:40.589517Z"}]}
{"channel":"book","type":"update","data":[{"symbol":"ETH/USDT","bids":[{"price":3799.44,"qty":0.73120000}],"asks":[],"checksum":2618258959,"timestamp":"2024-06-01T17:52:40.589814Z"}]}
{"channel":"book","type":"update","data":[{"symbol":"ETH/USDT","bids":[{"price":3799.29,"qty":0.00000000},{"price":3798.59,"qty":0.73120000}],"asks":[],"checksum":3141640362,"timestamp":"2024-06-01T17:52:40.591759Z"}]}
{"channel":"book","type":"update","data":[{"symbol":"ETH/USDT","bids":[],"asks":[{"price":3800.27,"qty":0.00000000},{"price":3801.13,"qty":0.21709301}],"checksum":775799049,"timestamp":"2024-06-01T17:52:40.593057Z"}]}
{"channel":"book","type":"update","data":[{"symbol":"ETH/USDT","bids":[],"asks":[{"price":3800.27,"qty":0.73120000}],"checksum":3141640362,"timestamp":"2024-06-01T17:52:40.601575Z"}]}
{"channel":"book","type":"update","data":[{"symbol":"ETH/USDT","bids":[{"price":3798.60,"qty":1.55116139}],"asks":[],"checksum":3135154814,"timestamp":"2024-06-01T17:52:40.749374Z"}]}
{"channel":"book","type":"update","data":[{"symbol":"ETH/USDT","bids":[{"price":3798.61,"qty":0.00000000},{"price":3798.42,"qty":0.44053478}],"asks":[],"checksum":2029776767,"timestamp":"2024-06-01T17:52:40.778413Z"}]}
{"channel":"book","type":"update","data":[{"symbol":"ETH/USDT","bids":[{"price":3799.44,"qty":0.00000000},{"price":3798.40,"qty":2.63483056}],"asks":[],"checksum":884126939,"timestamp":"2024-06-01T17:52:40.780290Z"}]}
{"channel":"book","type":"update","data":[{"symbol":"ETH/USDT","bids":[{"price":3799.32,"qty":0.00000000},{"price":3798.13,"qty":0.73120000}],"asks":[],"checksum":2179198824,"timestamp":"2024-06-01T17:52:40.781057Z"}]}
{"channel":"book","type":"update","data":[{"symbol":"ETH/USDT","bids":[],"asks":[{"price":3799.85,"qty":0.73120000}],"checksum":2471177770,"timestamp":"2024-06-01T17:52:40.781695Z"}]}
{"channel":"book","type":"update","data":[{"symbol":"ETH/USDT","bids":[{"price":3799.03,"qty":0.00000000},{"price":3797.93,"qty":2.13500000}],"asks":[],"checksum":1629510348,"timestamp":"2024-06-01T17:52:40.783761Z"}]}
{"channel":"book","type":"update","data":[{"symbol":"ETH/USDT","bids":[{"price":3798.40,"qty":5.43283056}],"asks":[],"checksum":1631516140,"timestamp":"2024-06-01T17:52:40.784129Z"}]}
{"channel":"book","type":"update","data":[{"symbol":"ETH/USDT","bids":[{"price":3799.08,"qty":1.31700944}],"asks":[],"checksum":4073190494,"timestamp":"2024-06-01T17:52:40.784181Z"}]}
{"channel":"book","type":"update","data":[{"symbol":"ETH/USDT","bids":[],"asks":[{"price":3799.85,"qty":0.00000000},{"price":3800.94,"qty":0.84627249}],"checksum":1778875427,"timestamp":"2024-06-01T17:52:40.784277Z"}]}
{"channel":"book","type":"update","data":[{"symbol":"ETH/USDT","bids":[{"price":3798.61,"qty":0.19732039}],"asks":[],"checksum":2518101149,"timestamp":"2024-06-01T17:52:40.789731Z"}]}
{"channel":"book","type":"update","data":[{"symbol":"ETH/USDT","bids":[{"price":3799.33,"qty":0.98120000}],"asks":[],"checksum":2527200168,"timestamp":"2024-06-01T17:52:40.790446Z"}]}
{"channel":"book","type":"update","data":[{"symbol":"ETH/USDT","bids":[{"price":3799.34,"qty":0.73120000}],"asks":[],"checksum":1640431626,"timestamp":"2024-06-01T17:52:40.794825Z"}]}
{"channel":"book","type":"update","data":[{"symbol":"ETH/USDT","bids":[{"price":3799.34,"qty":0.00000000},{"price":3798.40,"qty":5.43283056}],"asks":[],"checksum":2527200168,"timestamp":"2024-06-01T17:52:40.805655Z"}]}
{"channel":"book","type":"update","data":[{"symbol":"ETH/USDT","bids":[{"price":3799.33,"qty":0.25000000}],"asks":[],"checksum":2518101149,"timestamp":"2024-06-01T17:52:40.806092Z"}]}
{"channel":"book","type":"update","data":[{"symbol":"ETH/USDT","bids":[{"price":3799.23,"qty":1.65700944}],"asks":[],"checksum":2832334058,"timestamp":"2024-06-01T17:52:40.808781Z"}]}
{"channel":"book","type":"update","data":[{"symbol":"ETH/USDT","bids":[],"asks":[{"price":3800.22,"qty":2.97357353}],"checksum":1542155922,"timestamp":"2024-06-01T17:52:40.819100Z"}]}
{"channel":"book","type":"update","data":[{"symbol":"ETH/USDT","bids":[{"price":3798.88,"qty":0.00000000},{"price":3798.13,"qty":0.73120000}],"asks":[],"checksum":1849192076,"timestamp":"2024-06-01T17:52:40.834981Z"}]}
{"channel":"book","type":"update","data":[{"symbol":"ETH/USDT","bids":[],"asks":[{"price":3800.34,"qty":0.06693358}],"checksum":2229946454,"timestamp":"2024-06-01T17:52:40.836587Z"}]}
{"channel":"book","type":"update","data":[{"symbol":"ETH/USDT","bids":[],"asks":[{"price":3799.88,"qty":0.73120000}],"checksum":2876552115,"timestamp":"2024-06-01T17:52:40.850967Z"}]}
{"channel":"book","type":"update","data":[{"symbol":"ETH/USDT","bids":[],"asks":[{"price":3799.88,"qty":0.00000000},{"price":3800.89,"qty":2.63310660}],"checksum":2229946454,"timestamp":"2024-06-01T17:52:40.854370Z"}]}
{"channel":"book","type":"update","data":[{"symbol":"ETH/USDT","bids":[],"asks":[{"price":3799.87,"qty":0.72912968}],"checksum":412376730,"timestamp":"2024-06-01T17:52:40.855176Z"}]}
{"channel":"book","type":"update","data":[{"symbol":"ETH/USDT","bids":[{"price":3798.60,"qty":0.84627249}],"asks":[],"checksum":1110401767,"timestamp":"2024-06-01T17:52:40.877855Z"}]}
{"channel":"book","type":"update","data":[{"symbol":"ETH/USDT","bids":[],"asks":[{"price":3799.85,"qty":0.73120000}],"checksum":2220075282,"timestamp":"2024-06-01T17:52:40.884255Z"}]}
{"channel":"book","type":"update","data":[{"symbol":"ETH/USDT","bids":[],"asks":[{"price":3799.87,"qty":1.46032968}],"checksum":3840829258,"timestamp":"2024-06-01T17:52:40.887378Z"}]}
{"channel":"book","type":"update","data":[{"symbol":"ETH/USDT","bids":[],"asks":[{"price":3799.85,"qty":0.00000000},{"price":3800.67,"qty":2.13500000}],"checksum":2531579190,"timestamp":"2024-06-01T17:52:40.887512Z"}]}
{"channel":"book","type":"update","data":[{"symbol":"ETH/USDT","bids":[],"asks":[{"price":3799.87,"qty":0.73120000}],"checksum":748865245,"timestamp":"2024-06-01T17:52:40.888375Z"}]}
{"channel":"book","type":"update","data":[{"symbol":"ETH/USDT","bids":[{"price":3799.23,"qty":1.31700944}],"asks":[],"checksum":308549290,"timestamp":"2024-06-01T17:52:40.890140Z"}]}
{"channel":"book","type":"update","data":[{"symbol":"ETH/USDT","bids":[],"asks":[{"price":3799.84,"qty":0.73120000}],"checksum":13742058,"timestamp":"2024-06-01T17:52:40.890500Z"}]}
{"channel":"book","type":"update","data":[{"symbol":"ETH/USDT","bids":[{"price":3799.23,"qty":0.00000000},{"price":3797.82,"qty":0.72912968}],"asks":[],"checksum":1513399078,"timestamp":"2024-06-01T17:52:40.891573Z"}]}
{"channel":"book","type":"update","data":[{"symbol":"ETH/USDT","bids":[],"asks":[{"price":3799.84,"qty":0.00000000},{"price":3800.67,"qty":2.13500000}],"checksum":1482994559,"timestamp":"2024-06-01T17:52:40.893860Z"}]}
{"channel":"book","type":"update","data":[{"symbol":"ETH/USDT","bids":[],"asks":[{"price":3799.87,"qty":1.46240000}],"checksum":1368614725,"timestamp":"2024-06-01T17:52:40.898739Z"}]}
{"channel":"book","type":"update","data":[{"symbol":"ETH/USDT","bids":[{"price":3798.34,"qty":2.13500000}],"asks":[],"checksum":330102147,"timestamp":"2024-06-01T17:52:40.911014Z"}]}
{"channel":"book","type":"update","data":[{"symbol":"ETH/USDT","bids":[],"asks":[{"price":3799.87,"qty":0.73120000}],"checksum":3584678885,"timestamp":"2024-06-01T17:52:40.932027Z"}]}
{"channel":"book","type":"update","data":[{"symbol":"ETH/USDT","bids":[],"asks":[{"price":3799.86,"qty":0.72912968}],"checksum":2823770559,"timestamp":"2024-06-01T17:52:40.936602Z"}]}
{"channel":"book","type":"update","data":[{"symbol":"ETH/USDT","bids":[{"price":3798.63,"qty":0.00000000},{"price":3797.82,"qty":0.72912968}],"asks":[],"checksum":1415232152,"timestamp":"2024-06-01T17:52:40.936765Z"}]}
{"channel":"book","type":"update","data":[{"symbol":"ETH/USDT","bids":[{"price":3798.61,"qty":5.19732039}],"asks":[],"checksum":2444144917,"timestamp":"2024-06-01T17:52:40.936861Z"}]}
{"channel":"book","type":"update","data":[{"symbol":"ETH/USDT","bids":[{"price":3798.26,"qty":0.06693358}],"asks":[],"checksum":2574051307,"timestamp":"2024-06-01T17:52:40.939553Z"}]}
{"channel":"book","type":"update","data":[{"symbol":"ETH/USDT","bids":[],"asks":[{"price":3799.87,"qty":0.00000000},{"price":3800.67,"qty":2.13500000}],"checksum":932881813,"timestamp":"2024-06-01T17:52:40.940821Z"}]}
{"channel":"book","type":"update","data":[{"symbol":"ETH/USDT","bids":[],"asks":[{"price":3799.86,"qty":0.00000000},{"price":3800.89,"qty":2.63310660}],"checksum":2307884018,"timestamp":"2024-06-01T17:52:41.089832Z"}]}
{"channel":"book","type":"update","data":[{"symbol":"ETH/USDT","bids":[{"price":3799.33,"qty":0.00000000},{"price":3797.82,"qty":0.72912968}],"asks":[],"checksum":1516542600,"timestamp":"2024-06-01T17:52:41.094690Z"}]}
{"channel":"book","type":"update","data":[{"symbol":"ETH/USDT","bids":[{"price":3799.20,"qty":0.73120000}],"asks":[],"checksum":831436249,"timestamp":"2024-06-01T17:52:41.098263Z"}]}
{"channel":"book","type":"update","data":[{"symbol":"ETH/USDT","bids":[{"price":3799.08,"qty":2.04820944}],"asks":[],"checksum":2034640227,"timestamp":"2024-06-01T17:52:41.099246Z"}]}
{"channel":"book","type":"update","data":[{"symbol":"ETH/USDT","bids":[],"asks":[{"price":3800.22,"qty":2.63357353}],"checksum":1240723572,"timestamp":"2024-06-01T17:52:41.101642Z"}]}
{"channel":"book","type":"update","data":[{"symbol":"ETH/USDT","bids":[],"asks":[{"price":3800.15,"qty":0.34000000}],"checksum":3182067822,"timestamp":"2024-06-01T17:52:41.101785Z"}]}
{"channel":"book","type":"update","data":[{"symbol":"ETH/USDT","bids":[{"price":3799.08,"qty":2.38820944}],"asks":[],"checksum":3595914827,"timestamp":"2024-06-01T17:52:41.102015Z"}]}
{"channel":"book","type":"update","data":[{"symbol":"ETH/USDT","bids":[{"price":3799.08,"qty":1.65700944}],"asks":[],"checksum":1573239859,"timestamp":"2024-06-01T17:52:41.102346Z"}]}
{"channel":"book","type":"update","data":[{"symbol":"ETH/USDT","bids":[{"price":3799.08,"qty":1.31700944}],"asks":[],"checksum":4116844756,"timestamp":"2024-06-01T17:52:41.130509Z"}]}
{"channel":"book","type":"update","data":[{"symbol":"ETH/USDT","bids":[{"price":3799.09,"qty":0.34000000}],"asks":[],"checksum":3451922079,"timestamp":"2024-06-01T17:52:41.130709Z"}]}
{"channel":"book","type":"update","data":[{"symbol":"ETH/USDT","bids":[],"asks":[{"price":3800.14,"qty":0.72912968}],"checksum":3839808576,"timestamp":"2024-06-01T17:52:41.134835Z"}]}
{"channel":"book","type":"update","data":[{"symbol":"ETH/USDT","bids":[{"price":3798.61,"qty":5.00000000}],"asks":[],"checksum":2256772692,"timestamp":"2024-06-01T17:52:41.326606Z"}]}
{"channel":"book","type":"update","data":[{"symbol":"ETH/USDT","bids":[],"asks":[{"price":3800.21,"qty":0.00000000},{"price":3800.67,"qty":2.13500000}],"checksum":2107164353,"timestamp":"2024-06-01T17:52:41.330332Z"}]}
{"channel":"book","type":"update","data":[{"symbol":"ETH/USDT","bids":[{"price":3798.54,"qty":0.19733310}],"asks":[],"checksum":938288294,"timestamp":"2024-06-01T17:52:41.367011Z"}]}
{"channel":"book","type":"update","data":[{"symbol":"ETH/USDT","bids":[{"price":3799.21,"qty":0.25000000}],"asks":[],"checksum":1506221839,"timestamp":"2024-06-01T17:52:41.585871Z"}]}
{"channel":"book","type":"update","data":[{"symbol":"ETH/USDT","bids":[{"price":3799.22,"qty":0.73120000}],"asks":[],"checksum":41818513,"timestamp":"2024-06-01T17:52:41.590060Z"}]}
{"channel":"book","type":"update","data":[{"symbol":"ETH/USDT","bids":[{"price":3799.22,"qty":1.46240000}],"asks":[],"checksum":1007413900,"timestamp":"2024-06-01T17:52:41.789336Z"}]}
{"channel":"book","type":"update","data":[{"symbol":"ETH/USDT","bids":[{"price":3799.22,"qty":0.73120000}],"asks":[],"checksum":41818513,"timestamp":"2024-06-01T17:52:41.792012Z"}]}
{"channel":"book","type":"update","data":[{"symbol":"ETH/USDT","bids":[{"price":3798.54,"qty":0.00000000},{"price":3798.40,"qty":5.43283056}],"asks":[],"checksum":1537821075,"timestamp":"2024-06-01T17:52:41.896816Z"}]}
{"channel":"book","type":"update","data":[{"symbol":"ETH/USDT","bids":[{"price":3798.55,"qty":0.19733260}],"asks":[],"checksum":3813851251,"timestamp":"2024-06-01T17:52:41.937193Z"}]}
{"channel":"book","type":"update","data":[{"symbol":"ETH/USDT","bids":[{"price":3799.22,"qty":0.00000000},{"price":3798.40,"qty":5.43283056}],"asks":[],"checksum":220364144,"timestamp":"2024-06-01T17:52:42.293617Z"}]}
{"channel":"book","type":"update","data":[{"symbol":"ETH/USDT","bids":[{"price":3799.20,"qty":0.00000000},{"price":3798.34,"qty":2.13500000}],"asks":[],"checksum":1314767807,"timestamp":"2024-06-01T17:52:42.297233Z"}]}
{"channel":"book","type":"update","data":[{"symbol":"ETH/USDT","bids":[{"price":3799.21,"qty":0.98120000}],"asks":[],"checksum":1323887754,"timestamp":"2024-06-01T17:52:42.298178Z"}]}
{"channel":"book","type":"update","data":[{"symbol":"ETH/USDT","bids":[{"price":3799.22,"qty":0.73120000}],"asks":[],"checksum":1828641081,"timestamp":"2024-06-01T17:52:42.301934Z"}]}
{"channel":"book","type":"update","data":[{"symbol":"ETH/USDT","bids":[{"price":3799.22,"qty":1.46240000}],"asks":[],"checksum":264683539,"timestamp":"2024-06-01T17:52:42.303079Z"}]}
{"channel":"book","type":"update","data":[{"symbol":"ETH/USDT","bids":[{"price":3799.22,"qty":0.73120000}],"asks":[],"checksum":1828641081,"timestamp":"2024-06-01T17:52:42.305715Z"}]}
{"channel":"book","type":"update","data":[{"symbol":"ETH/USDT","bids":[{"price":3798.55,"qty":0.00000000},{"price":3798.34,"qty":2.13500000}],"asks":[],"checksum":290277125,"timestamp":"2024-06-01T17:52:42.399958Z"}]}
{"channel":"book","type":"update","data":[{"symbol":"ETH/USDT","bids":[{"price":3798.63,"qty":0.19732239}],"asks":[],"checksum":2175817871,"timestamp":"2024-06-01T17:52:42.440366Z"}]}
{"channel":"book","type":"update","data":[{"symbol":"ETH/USDT","bids":[{"price":3799.23,"qty":0.25000000}],"asks":[],"checksum":4126356776,"timestamp":"2024-06-01T17:52:42.588524Z"}]}
{"channel":"book","type":"update","data":[{"symbol":"ETH/USDT","bids":[{"price":3799.26,"qty":0.73120000}],"asks":[],"checksum":1276929126,"timestamp":"2024-06-01T17:52:42.591943Z"}]}
{"channel":"book","type":"update","data":[{"symbol":"ETH/USDT","bids":[{"price":3799.21,"qty":0.25000000}],"asks":[],"checksum":316582185,"timestamp":"2024-06-01T17:52:42.592323Z"}]}
{"channel":"book","type":"update","data":[{"symbol":"ETH/USDT","bids":[{"price":3799.21,"qty":0.00000000},{"price":3798.42,"qty":0.44053478}],"asks":[],"checksum":2614988998,"timestamp":"2024-06-01T17:52:42.593739Z"}]}
{"channel":"book","type":"update","data":[{"symbol":"ETH/USDT","bids":[{"price":3798.97,"qty":1.31701985}],"asks":[],"checksum":1435948696,"timestamp":"2024-06-01T17:52:42.852712Z"}]}
{"channel":"book","type":"update","data":[{"symbol":"ETH/USDT","bids":[{"price":3798.63,"qty":0.00000000},{"price":3798.42,"qty":0.44053478}],"asks":[],"checksum":1995611463,"timestamp":"2024-06-01T17:52:42.969691Z"}]}
{"channel":"book","type":"update","data":[{"symbol":"ETH/USDT","bids":[{"price":3799.26,"qty":0.00000000},{"price":3798.40,"qty":5.43283056}],"asks":[],"checksum":3096126611,"timestamp":"2024-06-01T17:52:42.973909Z"}]}
{"channel":"book","type":"update","data":[{"symbol":"ETH/USDT","bids":[{"price":3799.22,"qty":0.00000000},{"price":3798.34,"qty":2.13500000}],"asks":[],"checksum":1867379099,"timestamp":"2024-06-01T17:52:42.977441Z"}]}
{"channel":"book","type":"update","data":[{"symbol":"ETH/USDT","bids":[{"price":3799.23,"qty":0.98120000}],"asks":[],"checksum":972980375,"timestamp":"2024-06-01T17:52:42.978165Z"}]}
{"channel":"book","type":"update","data":[{"symbol":"ETH/USDT","bids":[{"price":3798.59,"qty":0.92853111}],"asks":[],"checksum":866066011,"timestamp":"2024-06-01T17:52:43.010162Z"}]}
{"channel":"book","type":"update","data":[{"symbol":"ETH/USDT","bids":[{"price":3799.27,"qty":0.73120000}],"asks":[],"checksum":826287722,"timestamp":"2024-06-01T17:52:43.068868Z"}]}
{"channel":"book","type":"update","data":[{"symbol":"ETH/USDT","bids":[{"price":3799.26,"qty":0.73120000}],"asks":[],"checksum":1658129676,"timestamp":"2024-06-01T17:52:43.070737Z"}]}
{"channel":"book","type":"update","data":[{"symbol":"ETH/USDT","bids":[{"price":3798.61,"qty":7.79800000}],"asks":[],"checksum":535662482,"timestamp":"2024-06-01T17:52:43.071340Z"}]}
{"channel":"book","type":"update","data":[{"symbol":"ETH/USDT","bids":[],"asks":[{"price":3800.27,"qty":0.00000000},{"price":3800.89,"qty":2.63310660}],"checksum":148970343,"timestamp":"2024-06-01T17:52:43.073122Z"}]}
{"channel":"book","type":"update","data":[{"symbol":"ETH/USDT","bids":[{"price":3799.26,"qty":0.00000000},{"price":3798.40,"qty":2.63483056}],"asks":[],"checksum":1854490450,"timestamp":"2024-06-01T17:52:43.073897Z"}]}
{"channel":"book","type":"update","data":[{"symbol":"ETH/USDT","bids":[],"asks":[{"price":3800.27,"qty":0.73120000}],"checksum":2739490133,"timestamp":"2024-06-01T17:52:43.078067Z"}]}
{"channel":"book","type":"update","data":[{"symbol":"ETH/USDT","bids":[{"price":3799.27,"qty":1.46240000}],"asks":[],"checksum":1798854439,"timestamp":"2024-06-01T17:52:43.085209Z"}]}
{"channel":"book","type":"update","data":[{"symbol":"ETH/USDT","bids":[],"asks":[{"price":3800.34,"qty":0.00000000},{"price":3800.89,"qty":2.63310660}],"checksum":2445626843,"timestamp":"2024-06-01T17:52:43.125353Z"}]}
{"channel":"book","type":"update","data":[{"symbol":"ETH/USDT","bids":[{"price":3799.28,"qty":1.31701985}],"asks":[],"checksum":2188840959,"timestamp":"2024-06-01T17:52:43.189087Z"}]}
{"channel":"book","type":"update","data":[{"symbol":"ETH/USDT","bids":[{"price":3799.09,"qty":0.00000000},{"price":3798.40,"qty":2.63483056}],"asks":[],"checksum":2998539484,"timestamp":"2024-06-01T17:52:43.191649Z"}]}
{"channel":"book","type":"update","data":[{"symbol":"ETH/USDT","bids":[{"price":3799.28,"qty":1.65701985}],"asks":[],"checksum":2544695555,"timestamp":"2024-06-01T17:52:43.191830Z"}]}
{"channel":"book","type":"update","data":[{"symbol":"ETH/USDT","bids":[{"price":3799.23,"qty":0.25000000}],"asks":[],"checksum":2676127350,"timestamp":"2024-06-01T17:52:43.192486Z"}]}
{"channel":"book","type":"update","data":[{"symbol":"ETH/USDT","bids":[{"price":3798.97,"qty":0.00000000},{"price":3798.34,"qty":2.13500000}],"asks":[],"checksum":2993626219,"timestamp":"2024-06-01T17:52:43.192693Z"}]}
{"channel":"book","type":"update","data":[{"symbol":"ETH/USDT","bids":[{"price":3799.40,"qty":0.73120000}],"asks":[],"checksum":2519970866,"timestamp":"2024-06-01T17:52:43.193094Z"}]}
{"channel":"book","type":"update","data":[{"symbol":"ETH/USDT","bids":[{"price":3799.28,"qty":1.31701985}],"asks":[],"checksum":1483511421,"timestamp":"2024-06-01T17:52:43.204356Z"}]}
{"channel":"book","type":"update","data":[{"symbol":"ETH/USDT","bids":[{"price":3799.29,"qty":0.34000000}],"asks":[],"checksum":2503049118,"timestamp":"2024-06-01T17:52:43.204652Z"}]}
{"channel":"book","type":"update","data":[{"symbol":"ETH/USDT","bids":[],"asks":[{"price":3800.67,"qty":2.20193358}],"checksum":3674136636,"timestamp":"2024-06-01T17:52:43.229613Z"}]}
{"channel":"book","type":"update","data":[{"symbol":"ETH/USDT","bids":[{"price":3799.40,"qty":0.00000000},{"price":3798.40,"qty":2.63483056}],"asks":[],"checksum":2929215858,"timestamp":"2024-06-01T17:52:43.536271Z"}]}
{"channel":"book","type":"update","data":[{"symbol":"ETH/USDT","bids":[{"price":3799.27,"qty":0.73120000}],"asks":[],"checksum":153918306,"timestamp":"2024-06-01T17:52:43.539696Z"}]}
{"channel":"book","type":"update","data":[{"symbol":"ETH/USDT","bids":[{"price":3799.32,"qty":0.73120000}],"asks":[],"checksum":3871488303,"timestamp":"2024-06-01T17:52:43.540670Z"}]}
{"channel":"book","type":"update","data":[{"symbol":"ETH/USDT","bids":[{"price":3799.30,"qty":0.25000000}],"asks":[],"checksum":3489908538,"timestamp":"2024-06-01T17:52:43.541498Z"}]}
{"channel":"book","type":"update","data":[{"symbol":"ETH/USDT","bids":[{"price":3799.32,"qty":0.00000000},{"price":3798.42,"qty":0.44053478}],"asks":[],"checksum":3141942230,"timestamp":"2024-06-01T17:52:43.552934Z"}]}
{"channel":"book","type":"update","data":[{"symbol":"ETH/USDT","bids":[{"price":3799.30,"qty":0.98120000}],"asks":[],"checksum":241766102,"timestamp":"2024-06-01T17:52:43.558505Z"}]}
{"channel":"book","type":"update","data":[{"symbol":"ETH/USDT","bids":[{"price":3799.27,"qty":0.00000000},{"price":3798.40,"qty":2.63483056}],"asks":[],"checksum":2799702107,"timestamp":"2024-06-01T17:52:43.568112Z"}]}
{"channel":"book","type":"update","data":[{"symbol":"ETH/USDT","bids":[{"price":3799.32,"qty":0.73120000}],"asks":[],"checksum":4180889467,"timestamp":"2024-06-01T17:52:43.568542Z"}]}
{"channel":"book","type":"update","data":[{"symbol":"ETH/USDT","bids":[{"price":3799.23,"qty":0.00000000},{"price":3798.40,"qty":2.63483056}],"asks":[],"checksum":302359422,"timestamp":"2024-06-01T17:52:43.572935Z"}]}
{"channel":"book","type":"update","data":[{"symbol":"ETH/USDT","bids":[{"price":3799.32,"qty":0.00000000},{"price":3798.34,"qty":2.13500000}],"asks":[],"checksum":3793582795,"timestamp":"2024-06-01T17:52:43.581838Z"}]}
{"channel":"book","type":"update","data":[{"symbol":"ETH/USDT","bids":[{"price":3799.33,"qty":0.25000000}],"asks":[],"checksum":3625532411,"timestamp":"2024-06-01T17:52:43.587885Z"}]}
{"channel":"book","type":"update","data":[{"symbol":"ETH/USDT","bids":[{"price":3799.30,"qty":0.25000000}],"asks":[],"checksum":2047672146,"timestamp":"2024-06-01T17:52:43.595303Z"}]}
{"channel":"book","type":"update","data":[{"symbol":"ETH/USDT","bids":[],"asks":[{"price":3800.67,"qty":0.06693358}],"checksum":2664935946,"timestamp":"2024-06-01T17:52:43.717433Z"}]}
{"channel":"book","type":"update","data":[{"symbol":"ETH/USDT","bids":[],"asks":[{"price":3800.17,"qty":2.13500000}],"checksum":1153192383,"timestamp":"2024-06-01T17:52:43.816017Z"}]}
{"channel":"book","type":"update","data":[{"symbol":"ETH/USDT","bids":[{"price":3798.59,"qty":0.73120000}],"asks":[],"checksum":3686197437,"timestamp":"2024-06-01T17:52:43.817970Z"}]}
{"channel":"book","type":"update","data":[{"symbol":"ETH/USDT","bids":[{"price":3799.33,"qty":0.00000000},{"price":3798.34,"qty":2.13500000}],"asks":[],"checksum":1615510368,"timestamp":"2024-06-01T17:52:43.820825Z"}]}
{"channel":"book","type":"update","data":[{"symbol":"ETH/USDT","bids":[{"price":3798.74,"qty":0.19730750}],"asks":[],"checksum":3629501991,"timestamp":"2024-06-01T17:52:43.858373Z"}]}
{"channel":"book","type":"update","data":[{"symbol":"ETH/USDT","bids":[{"price":3799.29,"qty":0.00000000},{"price":3798.34,"qty":2.13500000}],"asks":[],"checksum":4001302818,"timestamp":"2024-06-01T17:52:44.094532Z"}]}
{"channel":"book","type":"update","data":[{"symbol":"ETH/USDT","bids":[{"price":3799.30,"qty":0.00000000},{"price":3798.26,"qty":0.06693358}],"asks":[],"checksum":3761016202,"timestamp":"2024-06-01T17:52:44.099889Z"}]}
{"channel":"book","type":"update","data":[{"symbol":"ETH/USDT","bids":[],"asks":[{"price":3799.89,"qty":0.73541065}],"checksum":3703788899,"timestamp":"2024-06-01T17:52:44.431763Z"}]}
{"channel":"book","type":"update","data":[{"symbol":"ETH/USDT","bids":[],"asks":[{"price":3799.89,"qty":0.00421065}],"checksum":3761016202,"timestamp":"2024-06-01T17:52:44.523114Z"}]}
{"channel":"book","type":"update","data":[{"symbol":"ETH/USDT","bids":[{"price":3799.29,"qty":0.25000000}],"asks":[],"checksum":2766640581,"timestamp":"2024-06-01T17:52:44.587276Z"}]}
{"channel":"book","type":"update","data":[{"symbol":"ETH/USDT","bids":[],"asks":[{"price":3799.89,"qty":0.73541065}],"checksum":2098012353,"timestamp":"2024-06-01T17:52:46.171509Z"}]}
{"channel":"book","type":"update","data":[{"symbol":"ETH/USDT","bids":[],"asks":[{"price":3799.89,"qty":1.46661065}],"checksum":2667295618,"timestamp":"2024-06-01T17:52:46.240129Z"}]}
{"channel":"book","type":"update","data":[{"symbol":"ETH/USDT","bids":[],"asks":[{"price":3799.87,"qty":0.73120000}],"checksum":2312919252,"timestamp":"2024-06-01T17:52:46.244072Z"}]}
{"channel":"book","type":"update","data":[{"symbol":"ETH/USDT","bids":[{"price":3798.46,"qty":8.85019210}],"asks":[],"checksum":2564934254,"timestamp":"2024-06-01T17:52:46.252319Z"}]}
{"channel":"book","type":"update","data":[{"symbol":"ETH/USDT","bids":[],"asks":[{"price":3799.87,"qty":0.00000000},{"price":3800.67,"qty":0.06693358}],"checksum":2412126520,"timestamp":"2024-06-01T17:52:46.314460Z"}]}
{"channel":"book","type":"update","data":[{"symbol":"ETH/USDT","bids":[],"asks":[{"price":3799.89,"qty":0.73541065}],"checksum":1815130747,"timestamp":"2024-06-01T17:52:46.317833Z"}]}
{"channel":"book","type":"update","data":[{"symbol":"ETH/USDT","bids":[],"asks":[{"price":3799.89,"qty":1.46661065}],"checksum":2412126520,"timestamp":"2024-06-01T17:52:46.321217Z"}]}
{"channel":"book","type":"update","data":[{"symbol":"ETH/USDT","bids":[],"asks":[{"price":3799.88,"qty":0.73120000}],"checksum":3556546684,"timestamp":"2024-06-01T17:52:46.508504Z"}]}
{"channel":"book","type":"update","data":[{"symbol":"ETH/USDT","bids":[],"asks":[{"price":3799.89,"qty":0.73541065}],"checksum":808983596,"timestamp":"2024-06-01T17:52:46.512060Z"}]}
{"channel":"book","type":"update","data":[{"symbol":"ETH/USDT","bids":[],"asks":[{"price":3799.88,"qty":1.46240000}],"checksum":1095584750,"timestamp":"2024-06-01T17:52:46.514862Z"}]}
{"channel":"book","type":"update","data":[{"symbol":"ETH/USDT","bids":[],"asks":[{"price":3799.88,"qty":0.73120000}],"checksum":808983596,"timestamp":"2024-06-01T17:52:46.590895Z"}]}
{"channel":"book","type":"update","data":[{"symbol":"ETH/USDT","bids":[],"asks":[{"price":3799.89,"qty":0.00421065}],"checksum":2000353045,"timestamp":"2024-06-01T17:52:46.594872Z"}]}
{"channel":"book","type":"update","data":[{"symbol":"ETH/USDT","bids":[{"price":3798.55,"qty":0.31046272}],"asks":[],"checksum":416769129,"timestamp":"2024-06-01T17:52:46.692491Z"}]}
{"channel":"book","type":"update","data":[{"symbol":"ETH/USDT","bids":[],"asks":[{"price":3799.88,"qty":0.00000000},{"price":3800.67,"qty":0.06693358}],"checksum":802728405,"timestamp":"2024-06-01T17:52:47.030130Z"}]}
{"channel":"book","type":"update","data":[{"symbol":"ETH/USDT","bids":[],"asks":[{"price":3799.89,"qty":0.73541065}],"checksum":322400572,"timestamp":"2024-06-01T17:52:47.172667Z"}]}
{"channel":"book","type":"update","data":[{"symbol":"ETH/USDT","bids":[{"price":3798.74,"qty":0.00000000},{"price":3798.40,"qty":2.63483056}],"asks":[],"checksum":2156810832,"timestamp":"2024-06-01T17:52:47.387873Z"}]}
{"channel":"book","type":"update","data":[{"symbol":"ETH/USDT","bids":[{"price":3798.73,"qty":0.19727687}],"asks":[],"checksum":1820485228,"timestamp":"2024-06-01T17:52:47.427796Z"}]}
{"channel":"book","type":"update","data":[{"symbol":"ETH/USDT","bids":[],"asks":[{"price":3799.89,"qty":0.00421065}],"checksum":1349369477,"timestamp":"2024-06-01T17:52:47.436405Z"}]}
{"channel":"book","type":"update","data":[{"symbol":"ETH/USDT","bids":[{"price":3799.31,"qty":0.73120000}],"asks":[],"checksum":2337167964,"timestamp":"2024-06-01T17:52:47.615978Z"}]}
{"channel":"book","type":"update","data":[{"symbol":"ETH/USDT","bids":[{"price":3799.32,"qty":0.25000000}],"asks":[],"checksum":2470465887,"timestamp":"2024-06-01T17:52:47.621128Z"}]}
{"channel":"book","type":"update","data":[{"symbol":"ETH/USDT","bids":[{"price":3799.31,"qty":0.00000000},{"price":3798.46,"qty":8.85019210}],"asks":[],"checksum":1251124979,"timestamp":"2024-06-01T17:52:47.621579Z"}]}
{"channel":"book","type":"update","data":[{"symbol":"ETH/USDT","bids":[{"price":3799.34,"qty":0.73120000}],"asks":[],"checksum":3208104518,"timestamp":"2024-06-01T17:52:47.667147Z"}]}
{"channel":"book","type":"update","data":[{"symbol":"ETH/USDT","bids":[{"price":3799.33,"qty":0.73120000}],"asks":[],"checksum":3012002836,"timestamp":"2024-06-01T17:52:47.668298Z"}]}
{"channel":"book","type":"update","data":[{"symbol":"ETH/USDT","bids":[{"price":3799.33,"qty":0.00000000},{"price":3798.55,"qty":0.31046272}],"asks":[],"checksum":3208104518,"timestamp":"2024-06-01T17:52:47.670978Z"}]}
{"channel":"book","type":"update","data":[{"symbol":"ETH/USDT","bids":[{"price":3799.32,"qty":0.00000000},{"price":3798.46,"qty":8.85019210}],"asks":[],"checksum":2569969693,"timestamp":"2024-06-01T17:52:47.673139Z"}]}
{"channel":"book","type":"update","data":[{"symbol":"ETH/USDT","bids":[{"price":3799.35,"qty":0.25000000}],"asks":[],"checksum":545545545,"timestamp":"2024-06-01T17:52:47.673314Z"}]}
{"channel":"book","type":"update","data":[{"symbol":"ETH/USDT","bids":[{"price":3799.39,"qty":0.73120000}],"asks":[],"checksum":256922498,"timestamp":"2024-06-01T17:52:47.677559Z"}]}
{"channel":"book","type":"update","data":[{"symbol":"ETH/USDT","bids":[{"price":3798.97,"qty":0.73120000}],"asks":[],"checksum":504591740,"timestamp":"2024-06-01T17:52:47.681638Z"}]}
{"channel":"book","type":"update","data":[{"symbol":"ETH/USDT","bids":[],"asks":[{"price":3800.17,"qty":0.00000000},{"price":3800.89,"qty":2.63310660}],"checksum":357044247,"timestamp":"2024-06-01T17:52:47.699152Z"}]}
{"channel":"book","type":"update","data":[{"symbol":"ETH/USDT","bids":[{"price":3799.35,"qty":0.00000000},{"price":3798.59,"qty":0.73120000}],"asks":[],"checksum":2612943913,"timestamp":"2024-06-01T17:52:47.704116Z"}]}
{"channel":"book","type":"update","data":[{"symbol":"ETH/USDT","bids":[{"price":3799.40,"qty":0.25000000}],"asks":[],"checksum":57613135,"timestamp":"2024-06-01T17:52:47.704282Z"}]}
{"channel":"book","type":"update","data":[{"symbol":"ETH/USDT","bids":[{"price":3799.39,"qty":0.00000000},{"price":3798.59,"qty":0.73120000}],"asks":[],"checksum":1252582031,"timestamp":"2024-06-01T17:52:47.707034Z"}]}
{"channel":"book","type":"update","data":[{"symbol":"ETH/USDT","bids":[{"price":3799.45,"qty":0.73120000}],"asks":[],"checksum":478841675,"timestamp":"2024-06-01T17:52:47.715763Z"}]}
{"channel":"book","type":"update","data":[{"symbol":"ETH/USDT","bids":[{"price":3799.45,"qty":0.00000000},{"price":3798.59,"qty":0.73120000}],"asks":[],"checksum":1252582031,"timestamp":"2024-06-01T17:52:47.720860Z"}]}
{"channel":"book","type":"update","data":[{"symbol":"ETH/USDT","bids":[{"price":3799.40,"qty":0.98120000}],"asks":[],"checksum":4287092623,"timestamp":"2024-06-01T17:52:47.737140Z"}]}
{"channel":"book","type":"update","data":[{"symbol":"ETH/USDT","bids":[{"price":3799.34,"qty":0.00000000},{"price":3798.55,"qty":0.31046272}],"asks":[],"checksum":2799502060,"timestamp":"2024-06-01T17:52:47.737414Z"}]}
{"channel":"book","type":"update","data":[{"symbol":"ETH/USDT","bids":[{"price":3799.40,"qty":1.71240000}],"asks":[],"checksum":3802853981,"timestamp":"2024-06-01T17:52:47.738658Z"}]}
{"channel":"book","type":"update","data":[{"symbol":"ETH/USDT","bids":[],"asks":[{"price":3800.27,"qty":0.00000000},{"price":3800.94,"qty":0.84627249}],"checksum":24349479,"timestamp":"2024-06-01T17:52:47.739099Z"}]}
{"channel":"book","type":"update","data":[{"symbol":"ETH/USDT","bids":[{"price":3799.58,"qty":0.73120000}],"asks":[],"checksum":830539474,"timestamp":"2024-06-01T17:52:47.743078Z"}]}
{"channel":"book","type":"update","data":[{"symbol":"ETH/USDT","bids":[],"asks":[{"price":3800.15,"qty":0.00000000},{"price":3801.15,"qty":0.73120000}],"checksum":379610433,"timestamp":"2024-06-01T17:52:47.746289Z"}]}
{"channel":"book","type":"update","data":[{"symbol":"ETH/USDT","bids":[],"asks":[{"price":3800.14,"qty":0.00000000},{"price":3801.28,"qty":6.24866486}],"checksum":3653711364,"timestamp":"2024-06-01T17:52:47.746704Z"}]}
{"channel":"book","type":"update","data":[{"symbol":"ETH/USDT","bids":[],"asks":[{"price":3801.20,"qty":5.54112015}],"checksum":14432609,"timestamp":"2024-06-01T17:52:47.750824Z"}]}
{"channel":"book","type":"update","data":[{"symbol":"ETH/USDT","bids":[{"price":3798.78,"qty":2.63456872}],"asks":[],"checksum":4245157496,"timestamp":"2024-06-01T17:52:47.753473Z"}]}
{"channel":"book","type":"update","data":[{"symbol":"ETH/USDT","bids":[{"price":3799.40,"qty":2.05240000}],"asks":[],"checksum":2149024783,"timestamp":"2024-06-01T17:52:47.761404Z"}]}
{"channel":"book","type":"update","data":[{"symbol":"ETH/USDT","bids":[{"price":3799.41,"qty":0.07901194}],"asks":[],"checksum":1330244755,"timestamp":"2024-06-01T17:52:47.769548Z"}]}
{"channel":"book","type":"update","data":[{"symbol":"ETH/USDT","bids":[{"price":3799.40,"qty":1.71240000}],"asks":[],"checksum":1046658862,"timestamp":"2024-06-01T17:52:47.771118Z"}]}
{"channel":"book","type":"update","data":[{"symbol":"ETH/USDT","bids":[{"price":3799.41,"qty":0.41901194}],"asks":[],"checksum":804312049,"timestamp":"2024-06-01T17:52:47.771760Z"}]}
{"channel":"book","type":"update","data":[{"symbol":"ETH/USDT","bids":[{"price":3799.40,"qty":1.46240000}],"asks":[],"checksum":451930583,"timestamp":"2024-06-01T17:52:47.774143Z"}]}
{"channel":"book","type":"update","data":[{"symbol":"ETH/USDT","bids":[{"price":3799.58,"qty":0.00000000},{"price":3798.60,"qty":0.84627249}],"asks":[],"checksum":2816471783,"timestamp":"2024-06-01T17:52:47.776729Z"}]}
{"channel":"book","type":"update","data":[{"symbol":"ETH/USDT","bids":[],"asks":[{"price":3800.67,"qty":0.00000000},{"price":3801.28,"qty":6.24866486}],"checksum":2930193202,"timestamp":"2024-06-01T17:52:47.779484Z"}]}
{"channel":"book","type":"update","data":[{"symbol":"ETH/USDT","bids":[{"price":3799.40,"qty":0.73120000}],"asks":[],"checksum":2825159421,"timestamp":"2024-06-01T17:52:47.780458Z"}]}
{"channel":"book","type":"update","data":[{"symbol":"ETH/USDT","bids":[{"price":3799.52,"qty":0.73120000}],"asks":[],"checksum":436254826,"timestamp":"2024-06-01T17:52:47.780734Z"}]}
{"channel":"book","type":"update","data":[{"symbol":"ETH/USDT","bids":[{"price":3798.61,"qty":5.00000000},{"price":3798.79,"qty":2.79800000}],"asks":[],"checksum":668782862,"timestamp":"2024-06-01T17:52:47.783184Z"}]}
{"channel":"book","type":"update","data":[{"symbol":"ETH/USDT","bids":[{"price":3799.46,"qty":0.73120000}],"asks":[],"checksum":504246714,"timestamp":"2024-06-01T17:52:47.783748Z"}]}
{"channel":"book","type":"update","data":[{"symbol":"ETH/USDT","bids":[{"price":3799.41,"qty":0.34000000}],"asks":[],"checksum":1818643956,"timestamp":"2024-06-01T17:52:47.785287Z"}]}
{"channel":"book","type":"update","data":[{"symbol":"ETH/USDT","bids":[{"price":3799.53,"qty":0.07901192}],"asks":[],"checksum":836236470,"timestamp":"2024-06-01T17:52:47.785377Z"}]}
{"channel":"book","type":"update","data":[{"symbol":"ETH/USDT","bids":[{"price":3799.46,"qty":0.00000000},{"price":3798.78,"qty":2.63456872}],"asks":[],"checksum":1544208799,"timestamp":"2024-06-01T17:52:47.789266Z"}]}
{"channel":"book","type":"update","data":[{"symbol":"ETH/USDT","bids":[],"asks":[{"price":3800.47,"qty":2.13500000}],"checksum":40767801,"timestamp":"2024-06-01T17:52:47.798018Z"}]}
{"channel":"book","type":"update","data":[{"symbol":"ETH/USDT","bids":[],"asks":[{"price":3801.01,"qty":0.06693358}],"checksum":2178852950,"timestamp":"2024-06-01T17:52:47.883706Z"}]}
{"channel":"book","type":"update","data":[{"symbol":"ETH/USDT","bids":[],"asks":[{"price":3800.27,"qty":0.73120000}],"checksum":3237376912,"timestamp":"2024-06-01T17:52:47.905318Z"}]}
{"channel":"book","type":"update","data":[{"symbol":"ETH/USDT","bids":[{"price":3799.52,"qty":0.00000000},{"price":3798.61,"qty":5.00000000}],"asks":[],"checksum":2582333212,"timestamp":"2024-06-01T17:52:47.909198Z"}]}
{"channel":"book","type":"update","data":[{"symbol":"ETH/USDT","bids":[],"asks":[{"price":3800.21,"qty":0.72912968}],"checksum":1954566900,"timestamp":"2024-06-01T17:52:47.909886Z"}]}
{"channel":"book","type":"update","data":[{"symbol":"ETH/USDT","bids":[{"price":3798.76,"qty":0.19727158}],"asks":[],"checksum":753344106,"timestamp":"2024-06-01T17:52:47.918806Z"}]}
{"channel":"book","type":"update","data":[{"symbol":"ETH/USDT","bids":[{"price":3799.40,"qty":0.00000000},{"price":3798.61,"qty":5.00000000}],"asks":[],"checksum":3583731656,"timestamp":"2024-06-01T17:52:48.290045Z"}]}
{"channel":"book","type":"update","data":[{"symbol":"ETH/USDT","bids":[{"price":3798.76,"qty":0.00000000},{"price":3798.60,"qty":0.84627249}],"asks":[],"checksum":4122497918,"timestamp":"2024-06-01T17:52:48.498108Z"}]}
{"channel":"book","type":"update","data":[{"symbol":"ETH/USDT","bids":[{"price":3799.53,"qty":0.00000000},{"price":3798.59,"qty":0.73120000}],"asks":[],"checksum":1623167586,"timestamp":"2024-06-01T17:52:48.498634Z"}]}
{"channel":"book","type":"update","data":[{"symbol":"ETH/USDT","bids":[{"price":3799.42,"qty":0.25000000}],"asks":[],"checksum":858286335,"timestamp":"2024-06-01T17:52:48.503495Z"}]}
{"channel":"book","type":"update","data":[{"symbol":"ETH/USDT","bids":[{"price":3798.80,"qty":0.19726672}],"asks":[],"checksum":2632133129,"timestamp":"2024-06-01T17:52:48.538591Z"}]}
{"channel":"book","type":"update","data":[{"symbol":"ETH/USDT","bids":[{"price":3799.29,"qty":0.00000000},{"price":3798.60,"qty":0.84627249}],"asks":[],"checksum":2374946333,"timestamp":"2024-06-01T17:52:48.587059Z"}]}
{"channel":"book","type":"update","data":[{"symbol":"ETH/USDT","bids":[{"price":3798.97,"qty":0.00000000},{"price":3798.59,"qty":0.73120000}],"asks":[],"checksum":2828436767,"timestamp":"2024-06-01T17:52:49.017150Z"}]}
{"channel":"book","type":"update","data":[{"symbol":"ETH/USDT","bids":[],"asks":[{"price":3799.71,"qty":0.73120000}],"checksum":3383879673,"timestamp":"2024-06-01T17:52:49.017161Z"}]}
{"channel":"book","type":"update","data":[{"symbol":"ETH/USDT","bids":[],"asks":[{"price":3799.66,"qty":0.73120000}],"checksum":1530118412,"timestamp":"2024-06-01T17:52:49.017415Z"}]}
{"channel":"book","type":"update","data":[{"symbol":"ETH/USDT","bids":[{"price":3798.79,"qty":0.00000000},{"price":3798.55,"qty":0.31046272}],"asks":[],"checksum":1721153957,"timestamp":"2024-06-01T17:52:49.019626Z"}]}
{"channel":"book","type":"update","data":[{"symbol":"ETH/USDT","bids":[],"asks":[{"price":3799.66,"qty":0.00000000},{"price":3800.89,"qty":2.63310660}],"checksum":910088041,"timestamp":"2024-06-01T17:52:49.020690Z"}]}
{"channel":"book","type":"update","data":[{"symbol":"ETH/USDT","bids":[{"price":3799.41,"qty":0.00000000},{"price":3798.46,"qty":8.85019210}],"asks":[],"checksum":90857062,"timestamp":"2024-06-01T17:52:49.020716Z"}]}
{"channel":"book","type":"update","data":[{"symbol":"ETH/USDT","bids":[],"asks":[{"price":3799.71,"qty":0.00000000},{"price":3800.94,"qty":0.84627249}],"checksum":1682783360,"timestamp":"2024-06-01T17:52:49.020903Z"}]}
{"channel":"book","type":"update","data":[{"symbol":"ETH/USDT","bids":[{"price":3799.42,"qty":1.56690885}],"asks":[],"checksum":5333819,"timestamp":"2024-06-01T17:52:49.024106Z"}]}
{"channel":"book","type":"update","data":[{"symbol":"ETH/USDT","bids":[],"asks":[{"price":3799.87,"qty":0.73120000}],"checksum":1626855505,"timestamp":"2024-06-01T17:52:49.024274Z"}]}
{"channel":"book","type":"update","data":[{"symbol":"ETH/USDT","bids":[{"price":3798.61,"qty":7.79800000}],"asks":[],"checksum":48446151,"timestamp":"2024-06-01T17:52:49.024361Z"}]}
{"channel":"book","type":"update","data":[{"symbol":"ETH/USDT","bids":[],"asks":[{"price":3799.88,"qty":0.73120000}],"checksum":1795048713,"timestamp":"2024-06-01T17:52:49.025027Z"}]}
{"channel":"book","type":"update","data":[{"symbol":"ETH/USDT","bids":[{"price":3799.28,"qty":0.00000000},{"price":3798.42,"qty":0.44053478}],"asks":[],"checksum":4170699134,"timestamp":"2024-06-01T17:52:49.027978Z"}]}
{"channel":"book","type":"update","data":[{"symbol":"ETH/USDT","bids":[],"asks":[{"price":3799.88,"qty":0.00000000},{"price":3800.89,"qty":2.63310660}],"checksum":945547180,"timestamp":"2024-06-01T17:52:49.028658Z"}]}
{"channel":"book","type":"update","data":[{"symbol":"ETH/USDT","bids":[{"price":3798.61,"qty":5.00000000}],"asks":[],"checksum":3963342060,"timestamp":"2024-06-01T17:52:49.029232Z"}]}
{"channel":"book","type":"update","data":[{"symbol":"ETH/USDT","bids":[],"asks":[{"price":3799.87,"qty":1.46240000}],"checksum":3675031067,"timestamp":"2024-06-01T17:52:49.031291Z"}]}
{"channel":"book","type":"update","data":[{"symbol":"ETH/USDT","bids":[{"price":3799.42,"qty":0.25000000}],"asks":[],"checksum":1006163294,"timestamp":"2024-06-01T17:52:49.034883Z"}]}
{"channel":"book","type":"update","data":[{"symbol":"ETH/USDT","bids":[{"price":3799.16,"qty":0.34000000}],"asks":[],"checksum":2855902916,"timestamp":"2024-06-01T17:52:49.037775Z"}]}
{"channel":"book","type":"update","data":[{"symbol":"ETH/USDT","bids":[{"price":3799.16,"qty":0.00000000},{"price":3798.42,"qty":0.44053478}],"asks":[],"checksum":1006163294,"timestamp":"2024-06-01T17:52:49.075813Z"}]}
{"channel":"book","type":"update","data":[{"symbol":"ETH/USDT","bids":[],"asks":[{"price":3799.86,"qty":0.72912968}],"checksum":2378770853,"timestamp":"2024-06-01T17:52:49.080454Z"}]}
{"channel":"book","type":"update","data":[{"symbol":"ETH/USDT","bids":[],"asks":[{"price":3799.87,"qty":0.73120000}],"checksum":3626121519,"timestamp":"2024-06-01T17:52:49.080647Z"}]}
{"channel":"book","type":"update","data":[{"symbol":"ETH/USDT","bids":[{"price":3798.79,"qty":5.00000000}],"asks":[],"checksum":329863870,"timestamp":"2024-06-01T17:52:49.080684Z"}]}
{"channel":"book","type":"update","data":[{"symbol":"ETH/USDT","bids":[{"price":3799.42,"qty":0.00000000},{"price":3798.42,"qty":0.44053478}],"asks":[],"checksum":3565418379,"timestamp":"2024-06-01T17:52:49.080776Z"}]}
{"channel":"book","type":"update","data":[{"symbol":"ETH/USDT","bids":[{"price":3799.09,"qty":0.25000000}],"asks":[],"checksum":915124429,"timestamp":"2024-06-01T17:52:49.080883Z"}]}
{"channel":"book","type":"update","data":[{"symbol":"ETH/USDT","bids":[{"price":3799.04,"qty":0.73120000}],"asks":[],"checksum":3330310083,"timestamp":"2024-06-01T17:52:49.081037Z"}]}
{"channel":"book","type":"update","data":[{"symbol":"ETH/USDT","bids":[{"price":3799.04,"qty":0.00000000},{"price":3798.46,"qty":8.85019210}],"asks":[],"checksum":915124429,"timestamp":"2024-06-01T17:52:49.083902Z"}]}
{"channel":"book","type":"update","data":[{"symbol":"ETH/USDT","bids":[],"asks":[{"price":3799.87,"qty":0.00000000},{"price":3800.89,"qty":2.63310660}],"checksum":1141226302,"timestamp":"2024-06-01T17:52:49.083991Z"}]}
{"channel":"book","type":"update","data":[{"symbol":"ETH/USDT","bids":[{"price":3799.11,"qty":0.73120000}],"asks":[],"checksum":3906793957,"timestamp":"2024-06-01T17:52:49.084478Z"}]}
{"channel":"book","type":"update","data":[{"symbol":"ETH/USDT","bids":[],"asks":[{"price":3800.13,"qty":0.34000000}],"checksum":2499886034,"timestamp":"2024-06-01T17:52:49.086675Z"}]}
{"channel":"book","type":"update","data":[{"symbol":"ETH/USDT","bids":[],"asks":[{"price":3799.86,"qty":1.46032968}],"checksum":1897629754,"timestamp":"2024-06-01T17:52:49.086906Z"}]}
{"channel":"book","type":"update","data":[{"symbol":"ETH/USDT","bids":[],"asks":[{"price":3799.86,"qty":0.73120000}],"checksum":1399025604,"timestamp":"2024-06-01T17:52:49.088652Z"}]}
{"channel":"book","type":"update","data":[{"symbol":"ETH/USDT","bids":[{"price":3799.12,"qty":1.31690885}],"asks":[],"checksum":603091756,"timestamp":"2024-06-01T17:52:49.092163Z"}]}
{"channel":"book","type":"update","data":[{"symbol":"ETH/USDT","bids":[],"asks":[{"price":3799.86,"qty":0.00000000},{"price":3800.89,"qty":2.63310660}],"checksum":2295548025,"timestamp":"2024-06-01T17:52:49.096301Z"}]}
{"channel":"book","type":"update","data":[{"symbol":"ETH/USDT","bids":[],"asks":[{"price":3799.88,"qty":0.73120000}],"checksum":3828651761,"timestamp":"2024-06-01T17:52:49.099527Z"}]}
{"channel":"book","type":"update","data":[{"symbol":"ETH/USDT","bids":[],"asks":[{"price":3799.85,"qty":0.73120000}],"checksum":4088458290,"timestamp":"2024-06-01T17:52:49.099619Z"}]}
{"channel":"book","type":"update","data":[{"symbol":"ETH/USDT","bids":[],"asks":[{"price":3799.85,"qty":0.00000000},{"price":3800.65,"qty":0.73120000}],"checksum":3828651761,"timestamp":"2024-06-01T17:52:49.103032Z"}]}
{"channel":"book","type":"update","data":[{"symbol":"ETH/USDT","bids":[],"asks":[{"price":3799.85,"qty":0.73120000}],"checksum":4088458290,"timestamp":"2024-06-01T17:52:49.106336Z"}]}
