{"channel":"book","type":"update","data":[{"symbol":"ETH/USD","bids":[],"asks":[{"price":3796.49,"qty":0.00000000},{"price":3797.78,"qty":4.53808791}],"checksum":1197359829,"timestamp":"2024-06-01T17:52:53.592447Z"}]}
{"channel":"book","type":"update","data":[{"symbol":"ETH/USD","bids":[{"price":3796.21,"qty":6.00000000}],"asks":[],"checksum":3812081207,"timestamp":"2024-06-01T17:52:53.592738Z"}]}
{"channel":"book","type":"update","data":[{"symbol":"ETH/USD","bids":[{"price":3796.26,"qty":0.00000000},{"price":3795.60,"qty":3.95587791}],"asks":[],"checksum":576675433,"timestamp":"2024-06-01T17:52:53.593636Z"}]}
{"channel":"book","type":"update","data":[{"symbol":"ETH/USD","bids":[{"price":3796.22,"qty":3.95106995}],"asks":[],"checksum":3076370805,"timestamp":"2024-06-01T17:52:53.593745Z"}]}
{"channel":"book","type":"update","data":[{"symbol":"ETH/USD","bids":[],"asks":[{"price":3797.25,"qty":0.00000000},{"price":3797.79,"qty":0.52680238}],"checksum":3358078717,"timestamp":"2024-06-01T17:52:53.593915Z"}]}
{"channel":"book","type":"update","data":[{"symbol":"ETH/USD","bids":[],"asks":[{"price":3796.72,"qty":0.00000000},{"price":3797.92,"qty":0.06693358}],"checksum":880782843,"timestamp":"2024-06-01T17:52:53.594446Z"}]}
{"channel":"book","type":"update","data":[{"symbol":"ETH/USD","bids":[{"price":3796.21,"qty":3.00000000}],"asks":[],"checksum":4213768077,"timestamp":"2024-06-01T17:52:53.596658Z"}]}
{"channel":"book","type":"update","data":[{"symbol":"ETH/USD","bids":[{"price":3795.93,"qty":0.00000000},{"price":3795.60,"qty":3.95587791}],"asks":[],"checksum":1937320414,"timestamp":"2024-06-01T17:52:53.597404Z"}]}
{"channel":"book","type":"update","data":[{"symbol":"ETH/USD","bids":[{"price":3796.25,"qty":3.00000000}],"asks":[],"checksum":93805368,"timestamp":"2024-06-01T17:52:53.598204Z"}]}
{"channel":"book","type":"update","data":[{"symbol":"ETH/USD","bids":[{"price":3795.94,"qty":5.27100000}],"asks":[],"checksum":1923458312,"timestamp":"2024-06-01T17:52:53.598945Z"}]}
{"channel":"book","type":"update","data":[{"symbol":"ETH/USD","bids":[{"price":3796.22,"qty":6.95106995}],"asks":[],"checksum":3186816894,"timestamp":"2024-06-01T17:52:53.599953Z"}]}
{"channel":"book","type":"update","data":[{"symbol":"ETH/USD","bids":[],"asks":[{"price":3797.78,"qty":0.00000000},{"price":3797.93,"qty":0.00500884}],"checksum":2835127802,"timestamp":"2024-06-01T17:52:53.605534Z"}]}
{"channel":"book","type":"update","data":[{"symbol":"ETH/USD","bids":[],"asks":[{"price":3796.93,"qty":0.00000000},{"price":3797.97,"qty":3.00000000}],"checksum":3938747264,"timestamp":"2024-06-01T17:52:53.605803Z"}]}
{"channel":"book","type":"update","data":[{"symbol":"ETH/USD","bids":[],"asks":[{"price":3797.17,"qty":3.00000000}],"checksum":3569479240,"timestamp":"2024-06-01T17:52:53.609415Z"}]}
{"channel":"book","type":"update","data":[{"symbol":"ETH/USD","bids":[{"price":3795.95,"qty":3.30000000}],"asks":[],"checksum":1036644696,"timestamp":"2024-06-01T17:52:53.610330Z"}]}
{"channel":"book","type":"update","data":[{"symbol":"ETH/USD","bids":[],"asks":[{"price":3796.29,"qty":0.09000000}],"checksum":4105642268,"timestamp":"2024-06-01T17:52:53.610532Z"}]}
{"channel":"book","type":"update","data":[{"symbol":"ETH/USD","bids":[],"asks":[{"price":3796.74,"qty":26.33844365}],"checksum":960868721,"timestamp":"2024-06-01T17:52:53.611846Z"}]}
{"channel":"book","type":"update","data":[{"symbol":"ETH/USD","bids":[],"asks":[{"price":3797.34,"qty":26.33423036}],"checksum":4017328015,"timestamp":"2024-06-01T17:52:53.611897Z"}]}
{"channel":"book","type":"update","data":[{"symbol":"ETH/USD","bids":[{"price":3796.18,"qty":26.34220250}],"asks":[],"checksum":3539348484,"timestamp":"2024-06-01T17:52:53.611920Z"}]}
{"channel":"book","type":"update","data":[{"symbol":"ETH/USD","bids":[],"asks":[{"price":3797.34,"qty":52.66846072}],"checksum":2677326598,"timestamp":"2024-06-01T17:52:53.611953Z"}]}
{"channel":"book","type":"update","data":[{"symbol":"ETH/USD","bids":[],"asks":[{"price":3797.34,"qty":79.00269108}],"checksum":3489804411,"timestamp":"2024-06-01T17:52:53.612248Z"}]}
{"channel":"book","type":"update","data":[{"symbol":"ETH/USD","bids":[{"price":3795.73,"qty":3.00541614}],"asks":[],"checksum":3607685511,"timestamp":"2024-06-01T17:52:53.612309Z"}]}
{"channel":"book","type":"update","data":[{"symbol":"ETH/USD","bids":[{"price":3796.22,"qty":3.95106995}],"asks":[],"checksum":1856072412,"timestamp":"2024-06-01T17:52:53.613301Z"}]}
{"channel":"book","type":"update","data":[{"symbol":"ETH/USD","bids":[{"price":3795.95,"qty":5.15000000}],"asks":[],"checksum":3800245928,"timestamp":"2024-06-01T17:52:53.616608Z"}]}
{"channel":"book","type":"update","data":[{"symbol":"ETH/USD","bids":[{"price":3796.25,"qty":6.00000000}],"asks":[],"checksum":809150754,"timestamp":"2024-06-01T17:52:53.616974Z"}]}
{"channel":"book","type":"update","data":[{"symbol":"ETH/USD","bids":[],"asks":[{"price":3797.34,"qty":52.66846072}],"checksum":2142001759,"timestamp":"2024-06-01T17:52:53.618409Z"}]}
{"channel":"book","type":"update","data":[{"symbol":"ETH/USD","bids":[],"asks":[{"price":3796.74,"qty":0.00000000},{"price":3797.79,"qty":0.52680238}],"checksum":3446072402,"timestamp":"2024-06-01T17:52:53.618420Z"}]}
{"channel":"book","type":"update","data":[{"symbol":"ETH/USD","bids":[],"asks":[{"price":3797.34,"qty":26.33423036}],"checksum":2085924092,"timestamp":"2024-06-01T17:52:53.618542Z"}]}
{"channel":"book","type":"update","data":[{"symbol":"ETH/USD","bids":[{"price":3796.12,"qty":0.00000000},{"price":3795.68,"qty":1.00000000},{"price":3796.27,"qty":0.00936730}],"asks":[],"checksum":672632002,"timestamp":"2024-06-01T17:52:53.632019Z"}]}
{"channel":"book","type":"update","data":[{"symbol":"ETH/USD","bids":[{"price":3796.25,"qty":3.00000000}],"asks":[],"checksum":4149911022,"timestamp":"2024-06-01T17:52:53.635641Z"}]}
{"channel":"book","type":"update","data":[{"symbol":"ETH/USD","bids":[],"asks":[{"price":3797.69,"qty":0.00000000},{"price":3797.97,"qty":3.00000000}],"checksum":3624206310,"timestamp":"2024-06-01T17:52:53.635979Z"}]}
{"channel":"book","type":"update","data":[{"symbol":"ETH/USD","bids":[{"price":3796.27,"qty":3.00936730}],"asks":[],"checksum":2447121970,"timestamp":"2024-06-01T17:52:53.638467Z"}]}
{"channel":"book","type":"update","data":[{"symbol":"ETH/USD","bids":[],"asks":[{"price":3797.96,"qty":12.49076899}],"checksum":444076483,"timestamp":"2024-06-01T17:52:53.639802Z"}]}
{"channel":"book","type":"update","data":[{"symbol":"ETH/USD","bids":[{"price":3796.28,"qty":3.00000000}],"asks":[],"checksum":2093701406,"timestamp":"2024-06-01T17:52:53.643186Z"}]}
{"channel":"book","type":"update","data":[{"symbol":"ETH/USD","bids":[{"price":3796.21,"qty":0.00000000},{"price":3795.73,"qty":3.00541614}],"asks":[],"checksum":827300708,"timestamp":"2024-06-01T17:52:53.643551Z"}]}
{"channel":"book","type":"update","data":[{"symbol":"ETH/USD","bids":[{"price":3796.27,"qty":0.00936730}],"asks":[],"checksum":438515266,"timestamp":"2024-06-01T17:52:53.647107Z"}]}
{"channel":"book","type":"update","data":[{"symbol":"ETH/USD","bids":[],"asks":[{"price":3797.16,"qty":1.00000000}],"checksum":2036808987,"timestamp":"2024-06-01T17:52:53.647841Z"}]}
{"channel":"book","type":"update","data":[{"symbol":"ETH/USD","bids":[],"asks":[{"price":3797.34,"qty":32.22423036}],"checksum":1894513221,"timestamp":"2024-06-01T17:52:53.647996Z"}]}
{"channel":"book","type":"update","data":[{"symbol":"ETH/USD","bids":[{"price":3796.28,"qty":6.00000000}],"asks":[],"checksum":2723313103,"timestamp":"2024-06-01T17:52:53.651581Z"}]}
{"channel":"book","type":"update","data":[{"symbol":"ETH/USD","bids":[],"asks":[{"price":3797.47,"qty":5.20100000}],"checksum":1430432666,"timestamp":"2024-06-01T17:52:53.658711Z"}]}
{"channel":"book","type":"update","data":[{"symbol":"ETH/USD","bids":[{"price":3796.28,"qty":32.34155068}],"asks":[],"checksum":2016566157,"timestamp":"2024-06-01T17:52:53.673866Z"}]}
{"channel":"book","type":"update","data":[{"symbol":"ETH/USD","bids":[],"asks":[{"price":3796.75,"qty":26.33836643}],"checksum":361926047,"timestamp":"2024-06-01T17:52:53.673881Z"}]}
{"channel":"book","type":"update","data":[{"symbol":"ETH/USD","bids":[],"asks":[{"price":3797.34,"qty":26.33423036}],"checksum":2512156281,"timestamp":"2024-06-01T17:52:53.679717Z"}]}
{"channel":"book","type":"update","data":[{"symbol":"ETH/USD","bids":[],"asks":[{"price":3797.16,"qty":0.00000000},{"price":3797.79,"qty":0.52680238}],"checksum":3395427791,"timestamp":"2024-06-01T17:52:53.680075Z"}]}
{"channel":"book","type":"update","data":[{"symbol":"ETH/USD","bids":[{"price":3796.28,"qty":29.34155068}],"asks":[],"checksum":2378908221,"timestamp":"2024-06-01T17:52:53.680463Z"}]}
{"channel":"book","type":"update","data":[{"symbol":"ETH/USD","bids":[{"price":3796.28,"qty":26.34155068}],"asks":[],"checksum":561042658,"timestamp":"2024-06-01T17:52:53.680950Z"}]}
{"channel":"book","type":"update","data":[{"symbol":"ETH/USD","bids":[{"price":3796.25,"qty":0.00000000},{"price":3795.68,"qty":1.00000000}],"asks":[],"checksum":2749002195,"timestamp":"2024-06-01T17:52:53.681820Z"}]}
{"channel":"book","type":"update","data":[{"symbol":"ETH/USD","bids":[],"asks":[{"price":3796.75,"qty":0.00000000},{"price":3797.96,"qty":12.49076899}],"checksum":3596514637,"timestamp":"2024-06-01T17:52:53.683601Z"}]}
{"channel":"book","type":"update","data":[{"symbol":"ETH/USD","bids":[{"price":3796.22,"qty":0.00000000},{"price":3795.60,"qty":4.01766012}],"asks":[],"checksum":3009708030,"timestamp":"2024-06-01T17:52:53.690557Z"}]}
{"channel":"book","type":"update","data":[{"symbol":"ETH/USD","bids":[{"price":3796.27,"qty":0.00000000},{"price":3795.45,"qty":6.38468581},{"price":3796.26,"qty":0.00936733}],"asks":[],"checksum":3827188750,"timestamp":"2024-06-01T17:52:53.691684Z"}]}
{"channel":"book","type":"update","data":[{"symbol":"ETH/USD","bids":[],"asks":[{"price":3796.29,"qty":0.00000000},{"price":3797.97,"qty":3.00000000}],"checksum":2637013529,"timestamp":"2024-06-01T17:52:53.714062Z"}]}
{"channel":"book","type":"update","data":[{"symbol":"ETH/USD","bids":[],"asks":[{"price":3797.64,"qty":0.72912968}],"checksum":495409751,"timestamp":"2024-06-01T17:52:53.718657Z"}]}
{"channel":"book","type":"update","data":[{"symbol":"ETH/USD","bids":[],"asks":[{"price":3797.16,"qty":1.00000000}],"checksum":1242356605,"timestamp":"2024-06-01T17:52:53.719337Z"}]}
{"channel":"book","type":"update","data":[{"symbol":"ETH/USD","bids":[],"asks":[{"price":3796.98,"qty":3.00000000}],"checksum":3441182044,"timestamp":"2024-06-01T17:52:53.722797Z"}]}
{"channel":"book","type":"update","data":[{"symbol":"ETH/USD","bids":[{"price":3796.28,"qty":0.00000000},{"price":3795.45,"qty":6.38468581}],"asks":[],"checksum":3174818118,"timestamp":"2024-06-01T17:52:53.724818Z"}]}
{"channel":"book","type":"update","data":[{"symbol":"ETH/USD","bids":[{"price":3796.43,"qty":26.34052421}],"asks":[],"checksum":1061912140,"timestamp":"2024-06-01T17:52:53.729677Z"}]}
{"channel":"book","type":"update","data":[{"symbol":"ETH/USD","bids":[],"asks":[{"price":3796.78,"qty":26.33811660}],"checksum":1320095661,"timestamp":"2024-06-01T17:52:53.729705Z"}]}
{"channel":"book","type":"update","data":[{"symbol":"ETH/USD","bids":[{"price":3796.29,"qty":26.34150710}],"asks":[],"checksum":617764753,"timestamp":"2024-06-01T17:52:53.729850Z"}]}
{"channel":"book","type":"update","data":[{"symbol":"ETH/USD","bids":[],"asks":[{"price":3797.49,"qty":1.85000000}],"checksum":4128920504,"timestamp":"2024-06-01T17:52:53.733496Z"}]}
{"channel":"book","type":"update","data":[{"symbol":"ETH/USD","bids":[{"price":3796.26,"qty":0.00000000},{"price":3795.60,"qty":4.01766012},{"price":3796.19,"qty":0.00936750}],"asks":[],"checksum":1102652691,"timestamp":"2024-06-01T17:52:53.748469Z"}]}
{"channel":"book","type":"update","data":[{"symbol":"ETH/USD","bids":[],"asks":[{"price":3797.16,"qty":0.00000000},{"price":3797.64,"qty":0.72912968}],"checksum":3597688157,"timestamp":"2024-06-01T17:52:53.752763Z"}]}
{"channel":"book","type":"update","data":[{"symbol":"ETH/USD","bids":[],"asks":[{"price":3797.17,"qty":0.00000000},{"price":3797.71,"qty":10.43462302}],"checksum":345676740,"timestamp":"2024-06-01T17:52:53.756725Z"}]}
{"channel":"book","type":"update","data":[{"symbol":"ETH/USD","bids":[{"price":3795.94,"qty":0.00000000},{"price":3795.60,"qty":4.01766012}],"asks":[],"checksum":3543651485,"timestamp":"2024-06-01T17:52:53.760837Z"}]}
{"channel":"book","type":"update","data":[{"symbol":"ETH/USD","bids":[],"asks":[{"price":3796.78,"qty":29.33811660}],"checksum":3558110724,"timestamp":"2024-06-01T17:52:53.760847Z"}]}
{"channel":"book","type":"update","data":[{"symbol":"ETH/USD","bids":[],"asks":[{"price":3796.77,"qty":3.00000000}],"checksum":761850325,"timestamp":"2024-06-01T17:52:53.763200Z"}]}
{"channel":"book","type":"update","data":[{"symbol":"ETH/USD","bids":[],"asks":[{"price":3796.98,"qty":0.00000000},{"price":3797.71,"qty":10.43462302}],"checksum":30357900,"timestamp":"2024-06-01T17:52:53.763292Z"}]}
{"channel":"book","type":"update","data":[{"symbol":"ETH/USD","bids":[{"price":3795.60,"qty":3.95072654}],"asks":[],"checksum":2821454241,"timestamp":"2024-06-01T17:52:53.767561Z"}]}
{"channel":"book","type":"update","data":[{"symbol":"ETH/USD","bids":[],"asks":[{"price":3796.78,"qty":3.00000000}],"checksum":801426588,"timestamp":"2024-06-01T17:52:53.779775Z"}]}
{"channel":"book","type":"update","data":[{"symbol":"ETH/USD","bids":[],"asks":[{"price":3796.77,"qty":29.33821406}],"checksum":1378390248,"timestamp":"2024-06-01T17:52:53.784225Z"}]}
{"channel":"book","type":"update","data":[{"symbol":"ETH/USD","bids":[],"asks":[{"price":3796.78,"qty":0.00000000},{"price":3797.79,"qty":0.52680238}],"checksum":112430620,"timestamp":"2024-06-01T17:52:53.784380Z"}]}
{"channel":"book","type":"update","data":[{"symbol":"ETH/USD","bids":[],"asks":[{"price":3796.44,"qty":0.09000000}],"checksum":319872019,"timestamp":"2024-06-01T17:52:53.797760Z"}]}
{"channel":"book","type":"update","data":[{"symbol":"ETH/USD","bids":[],"asks":[{"price":3797.33,"qty":0.79163089}],"checksum":1908233777,"timestamp":"2024-06-01T17:52:53.801076Z"}]}
{"channel":"book","type":"update","data":[{"symbol":"ETH/USD","bids":[],"asks":[{"price":3796.77,"qty":3.00000000}],"checksum":1794092841,"timestamp":"2024-06-01T17:52:53.807090Z"}]}
{"channel":"book","type":"update","data":[{"symbol":"ETH/USD","bids":[{"price":3796.43,"qty":0.00000000},{"price":3795.45,"qty":6.38468581}],"asks":[],"checksum":2222633822,"timestamp":"2024-06-01T17:52:53.807195Z"}]}
{"channel":"book","type":"update","data":[{"symbol":"ETH/USD","bids":[{"price":3796.29,"qty":0.00000000},{"price":3795.39,"qty":0.06693358}],"asks":[],"checksum":3871976628,"timestamp":"2024-06-01T17:52:53.812560Z"}]}
{"channel":"book","type":"update","data":[{"symbol":"ETH/USD","bids":[{"price":3795.68,"qty":0.00000000},{"price":3795.35,"qty":0.72912968}],"asks":[],"checksum":3072850927,"timestamp":"2024-06-01T17:52:53.816790Z"}]}
{"channel":"book","type":"update","data":[{"symbol":"ETH/USD","bids":[],"asks":[{"price":3796.87,"qty":26.33754775}],"checksum":1407808233,"timestamp":"2024-06-01T17:52:53.817142Z"}]}
{"channel":"book","type":"update","data":[{"symbol":"ETH/USD","bids":[{"price":3796.41,"qty":26.34065117}],"asks":[],"checksum":1059349357,"timestamp":"2024-06-01T17:52:53.817204Z"}]}
{"channel":"book","type":"update","data":[{"symbol":"ETH/USD","bids":[],"asks":[{"price":3796.76,"qty":2.40000000}],"checksum":2880793541,"timestamp":"2024-06-01T17:52:53.821645Z"}]}
{"channel":"book","type":"update","data":[{"symbol":"ETH/USD","bids":[{"price":3796.41,"qty":0.00000000},{"price":3795.35,"qty":0.72912968}],"asks":[],"checksum":1862380734,"timestamp":"2024-06-01T17:52:53.901039Z"}]}
{"channel":"book","type":"update","data":[{"symbol":"ETH/USD","bids":[],"asks":[{"price":3796.74,"qty":26.33842154}],"checksum":59989709,"timestamp":"2024-06-01T17:52:53.906018Z"}]}
{"channel":"book","type":"update","data":[{"symbol":"ETH/USD","bids":[{"price":3796.39,"qty":26.34079435}],"asks":[],"checksum":213016188,"timestamp":"2024-06-01T17:52:53.906191Z"}]}
{"channel":"book","type":"update","data":[{"symbol":"ETH/USD","bids":[{"price":3795.95,"qty":3.30000000},{"price":3795.71,"qty":1.85000000}],"asks":[],"checksum":560376454,"timestamp":"2024-06-01T17:52:53.925979Z"}]}
{"channel":"book","type":"update","data":[{"symbol":"ETH/USD","bids":[{"price":3795.71,"qty":3.70000000}],"asks":[],"checksum":4092525518,"timestamp":"2024-06-01T17:52:53.929056Z"}]}
{"channel":"book","type":"update","data":[{"symbol":"ETH/USD","bids":[],"asks":[{"price":3797.04,"qty":26.33636370}],"checksum":3030654147,"timestamp":"2024-06-01T17:52:54.048841Z"}]}
{"channel":"book","type":"update","data":[{"symbol":"ETH/USD","bids":[{"price":3796.43,"qty":26.34053571}],"asks":[],"checksum":2239995687,"timestamp":"2024-06-01T17:52:54.048886Z"}]}
{"channel":"book","type":"update","data":[{"symbol":"ETH/USD","bids":[],"asks":[{"price":3796.74,"qty":0.00000000},{"price":3797.46,"qty":1.00000000}],"checksum":3882051447,"timestamp":"2024-06-01T17:52:54.087313Z"}]}
{"channel":"book","type":"update","data":[{"symbol":"ETH/USD","bids":[{"price":3795.96,"qty":3.95106995}],"asks":[],"checksum":186711941,"timestamp":"2024-06-01T17:52:54.091284Z"}]}
{"channel":"book","type":"update","data":[{"symbol":"ETH/USD","bids":[],"asks":[{"price":3796.75,"qty":26.33838053}],"checksum":409355921,"timestamp":"2024-06-01T17:52:54.092286Z"}]}
{"channel":"book","type":"update","data":[{"symbol":"ETH/USD","bids":[],"asks":[{"price":3796.75,"qty":0.00000000},{"price":3797.46,"qty":1.00000000}],"checksum":186711941,"timestamp":"2024-06-01T17:52:54.101679Z"}]}
{"channel":"book","type":"update","data":[{"symbol":"ETH/USD","bids":[{"price":3795.77,"qty":5.27100000}],"asks":[],"checksum":1184265782,"timestamp":"2024-06-01T17:52:54.104933Z"}]}
{"channel":"book","type":"update","data":[{"symbol":"ETH/USD","bids":[],"asks":[{"price":3796.77,"qty":29.33821985}],"checksum":373874480,"timestamp":"2024-06-01T17:52:54.148986Z"}]}
{"channel":"book","type":"update","data":[{"symbol":"ETH/USD","bids":[],"asks":[{"price":3796.87,"qty":0.00000000},{"price":3797.47,"qty":5.20100000}],"checksum":367130835,"timestamp":"2024-06-01T17:52:54.155130Z"}]}
{"channel":"book","type":"update","data":[{"symbol":"ETH/USD","bids":[],"asks":[{"price":3796.73,"qty":26.33849379}],"checksum":349743996,"timestamp":"2024-06-01T17:52:54.283043Z"}]}
{"channel":"book","type":"update","data":[{"symbol":"ETH/USD","bids":[{"price":3796.43,"qty":0.00000000},{"price":3795.71,"qty":3.70000000}],"asks":[],"checksum":3328877777,"timestamp":"2024-06-01T17:52:54.303183Z"}]}
{"channel":"book","type":"update","data":[{"symbol":"ETH/USD","bids":[],"asks":[{"price":3796.73,"qty":0.00000000},{"price":3797.47,"qty":5.20100000}],"checksum":608701840,"timestamp":"2024-06-01T17:52:54.303206Z"}]}
{"channel":"book","type":"update","data":[{"symbol":"ETH/USD","bids":[{"price":3796.41,"qty":26.34064941}],"asks":[],"checksum":254971826,"timestamp":"2024-06-01T17:52:54.308380Z"}]}
{"channel":"book","type":"update","data":[{"symbol":"ETH/USD","bids":[{"price":3796.19,"qty":0.00000000},{"price":3795.71,"qty":3.70000000},{"price":3796.42,"qty":0.00935993}],"asks":[],"checksum":2356335971,"timestamp":"2024-06-01T17:52:54.368463Z"}]}
{"channel":"book","type":"update","data":[{"symbol":"ETH/USD","bids":[],"asks":[{"price":3796.72,"qty":26.33854708}],"checksum":499616574,"timestamp":"2024-06-01T17:52:54.442160Z"}]}
{"channel":"book","type":"update","data":[{"symbol":"ETH/USD","bids":[{"price":3796.41,"qty":0.00000000},{"price":3795.71,"qty":3.70000000}],"asks":[],"checksum":3670953526,"timestamp":"2024-06-01T17:52:54.444953Z"}]}
{"channel":"book","type":"update","data":[{"symbol":"ETH/USD","bids":[],"asks":[{"price":3796.71,"qty":2.40000000}],"checksum":1874621084,"timestamp":"2024-06-01T17:52:54.447335Z"}]}
{"channel":"book","type":"update","data":[{"symbol":"ETH/USD","bids":[],"asks":[{"price":3796.76,"qty":0.00000000},{"price":3797.46,"qty":1.00000000}],"checksum":3988603857,"timestamp":"2024-06-01T17:52:54.447633Z"}]}
{"channel":"book","type":"update","data":[{"symbol":"ETH/USD","bids":[{"price":3796.42,"qty":26.34989904}],"asks":[],"checksum":195396242,"timestamp":"2024-06-01T17:52:54.449205Z"}]}
{"channel":"book","type":"update","data":[{"symbol":"ETH/USD","bids":[],"asks":[{"price":3796.72,"qty":0.00000000},{"price":3797.47,"qty":5.20100000}],"checksum":2789004753,"timestamp":"2024-06-01T17:52:54.455055Z"}]}
{"channel":"book","type":"update","data":[{"symbol":"ETH/USD","bids":[{"price":3796.40,"qty":0.32778701}],"asks":[],"checksum":1268708170,"timestamp":"2024-06-01T17:52:54.461830Z"}]}
{"channel":"book","type":"update","data":[{"symbol":"ETH/USD","bids":[{"price":3796.40,"qty":0.67261270}],"asks":[],"checksum":3262539783,"timestamp":"2024-06-01T17:52:54.464597Z"}]}
{"channel":"book","type":"update","data":[{"symbol":"ETH/USD","bids":[],"asks":[{"price":3796.73,"qty":26.33849489}],"checksum":968184819,"timestamp":"2024-06-01T17:52:54.696928Z"}]}
{"channel":"book","type":"update","data":[{"symbol":"ETH/USD","bids":[],"asks":[{"price":3796.71,"qty":0.00000000},{"price":3797.47,"qty":5.20100000}],"checksum":2519259133,"timestamp":"2024-06-01T17:52:54.780058Z"}]}
{"channel":"book","type":"update","data":[{"symbol":"ETH/USD","bids":[],"asks":[{"price":3796.72,"qty":2.40000000}],"checksum":3191383518,"timestamp":"2024-06-01T17:52:54.845420Z"}]}
{"channel":"book","type":"update","data":[{"symbol":"ETH/USD","bids":[],"asks":[{"price":3797.33,"qty":0.00000000},{"price":3797.47,"qty":5.20100000}],"checksum":2593853160,"timestamp":"2024-06-01T17:52:54.848781Z"}]}
{"channel":"book","type":"update","data":[{"symbol":"ETH/USD","bids":[{"price":3796.43,"qty":0.52681071}],"asks":[],"checksum":3925773319,"timestamp":"2024-06-01T17:52:55.001560Z"}]}
{"channel":"book","type":"update","data":[{"symbol":"ETH/USD","bids":[],"asks":[{"price":3797.03,"qty":0.79163089}],"checksum":1180977550,"timestamp":"2024-06-01T17:52:55.005209Z"}]}
{"channel":"book","type":"update","data":[{"symbol":"ETH/USD","bids":[],"asks":[{"price":3796.82,"qty":3.00000000}],"checksum":2218572791,"timestamp":"2024-06-01T17:52:55.089519Z"}]}
{"channel":"book","type":"update","data":[{"symbol":"ETH/USD","bids":[{"price":3796.42,"qty":26.34053911},{"price":3796.43,"qty":0.53617061}],"asks":[],"checksum":185297231,"timestamp":"2024-06-01T17:52:55.136167Z"}]}
{"channel":"book","type":"update","data":[{"symbol":"ETH/USD","bids":[],"asks":[{"price":3796.82,"qty":0.00000000},{"price":3797.46,"qty":1.00000000}],"checksum":3377699638,"timestamp":"2024-06-01T17:52:55.231324Z"}]}
{"channel":"book","type":"update","data":[{"symbol":"ETH/USD","bids":[],"asks":[{"price":3796.73,"qty":0.00000000},{"price":3797.47,"qty":5.20100000}],"checksum":386200070,"timestamp":"2024-06-01T17:52:55.288033Z"}]}
{"channel":"book","type":"update","data":[{"symbol":"ETH/USD","bids":[],"asks":[{"price":3796.85,"qty":26.33764193}],"checksum":1686738800,"timestamp":"2024-06-01T17:52:55.292258Z"}]}
{"channel":"book","type":"update","data":[{"symbol":"ETH/USD","bids":[],"asks":[{"price":3796.72,"qty":0.00000000},{"price":3797.47,"qty":5.20100000}],"checksum":271685558,"timestamp":"2024-06-01T17:52:55.293558Z"}]}
{"channel":"book","type":"update","data":[{"symbol":"ETH/USD","bids":[],"asks":[{"price":3796.76,"qty":2.40000000}],"checksum":1288321805,"timestamp":"2024-06-01T17:52:55.386346Z"}]}
{"channel":"book","type":"update","data":[{"symbol":"ETH/USD","bids":[{"price":3796.43,"qty":4.48699080}],"asks":[],"checksum":2089728388,"timestamp":"2024-06-01T17:52:55.490059Z"}]}
{"channel":"book","type":"update","data":[{"symbol":"ETH/USD","bids":[{"price":3795.96,"qty":0.00000000},{"price":3795.73,"qty":3.00541614}],"asks":[],"checksum":2943644816,"timestamp":"2024-06-01T17:52:55.493726Z"}]}
{"channel":"book","type":"update","data":[{"symbol":"ETH/USD","bids":[],"asks":[{"price":3796.77,"qty":3.00000000}],"checksum":1445238916,"timestamp":"2024-06-01T17:52:55.498125Z"}]}
{"channel":"book","type":"update","data":[{"symbol":"ETH/USD","bids":[{"price":3796.24,"qty":3.95082019}],"asks":[],"checksum":2208958131,"timestamp":"2024-06-01T17:52:55.501806Z"}]}
{"channel":"book","type":"update","data":[{"symbol":"ETH/USD","bids":[],"asks":[{"price":3796.74,"qty":26.33838860}],"checksum":3500988315,"timestamp":"2024-06-01T17:52:55.503927Z"}]}
{"channel":"book","type":"update","data":[{"symbol":"ETH/USD","bids":[],"asks":[{"price":3797.25,"qty":1.85000000}],"checksum":1925837676,"timestamp":"2024-06-01T17:52:55.546648Z"}]}
{"channel":"book","type":"update","data":[{"symbol":"ETH/USD","bids":[],"asks":[{"price":3797.25,"qty":3.70000000}],"checksum":3755794658,"timestamp":"2024-06-01T17:52:55.549702Z"}]}
{"channel":"book","type":"update","data":[{"symbol":"ETH/USD","bids":[],"asks":[{"price":3796.82,"qty":3.00000000}],"checksum":591939816,"timestamp":"2024-06-01T17:52:55.552240Z"}]}
{"channel":"book","type":"update","data":[{"symbol":"ETH/USD","bids":[{"price":3795.77,"qty":0.00000000},{"price":3795.73,"qty":3.00541614}],"asks":[],"checksum":1447497063,"timestamp":"2024-06-01T17:52:55.553396Z"}]}
{"channel":"book","type":"update","data":[{"symbol":"ETH/USD","bids":[{"price":3795.73,"qty":0.00541614}],"asks":[],"checksum":2393835123,"timestamp":"2024-06-01T17:52:55.553485Z"}]}
{"channel":"book","type":"update","data":[{"symbol":"ETH/USD","bids":[],"asks":[{"price":3796.44,"qty":3.09000000}],"checksum":3020306130,"timestamp":"2024-06-01T17:52:55.554067Z"}]}
{"channel":"book","type":"update","data":[{"symbol":"ETH/USD","bids":[],"asks":[{"price":3796.44,"qty":0.09000000}],"checksum":2393835123,"timestamp":"2024-06-01T17:52:55.557067Z"}]}
{"channel":"book","type":"update","data":[{"symbol":"ETH/USD","bids":[{"price":3795.73,"qty":0.00000000},{"price":3795.67,"qty":3.00000000}],"asks":[],"checksum":2569579297,"timestamp":"2024-06-01T17:52:55.558437Z"}]}
{"channel":"book","type":"update","data":[{"symbol":"ETH/USD","bids":[],"asks":[{"price":3796.85,"qty":0.00000000},{"price":3797.35,"qty":3.30000000}],"checksum":319658664,"timestamp":"2024-06-01T17:52:55.559518Z"}]}
{"channel":"book","type":"update","data":[{"symbol":"ETH/USD","bids":[],"asks":[{"price":3797.34,"qty":0.00000000},{"price":3797.44,"qty":10.81226191}],"checksum":1498026974,"timestamp":"2024-06-01T17:52:55.559572Z"}]}
{"channel":"book","type":"update","data":[{"symbol":"ETH/USD","bids":[{"price":3796.39,"qty":0.00000000},{"price":3795.62,"qty":5.27100000}],"asks":[],"checksum":3686888946,"timestamp":"2024-06-01T17:52:55.559643Z"}]}
{"channel":"book","type":"update","data":[{"symbol":"ETH/USD","bids":[{"price":3796.42,"qty":0.00000000},{"price":3795.46,"qty":0.00538061}],"asks":[],"checksum":439800976,"timestamp":"2024-06-01T17:52:55.559737Z"}]}
{"channel":"book","type":"update","data":[{"symbol":"ETH/USD","bids":[],"asks":[{"price":3796.44,"qty":3.09000000}],"checksum":2036316954,"timestamp":"2024-06-01T17:52:55.561673Z"}]}
{"channel":"book","type":"update","data":[{"symbol":"ETH/USD","bids":[],"asks":[{"price":3796.57,"qty":26.33959883}],"checksum":86110001,"timestamp":"2024-06-01T17:52:55.565214Z"}]}
{"channel":"book","type":"update","data":[{"symbol":"ETH/USD","bids":[{"price":3796.27,"qty":26.34161404}],"asks":[],"checksum":2997904149,"timestamp":"2024-06-01T17:52:55.565300Z"}]}
{"channel":"book","type":"update","data":[{"symbol":"ETH/USD","bids":[{"price":3795.70,"qty":26.34559104}],"asks":[],"checksum":3647924583,"timestamp":"2024-06-01T17:52:55.565516Z"}]}
{"channel":"book","type":"update","data":[{"symbol":"ETH/USD","bids":[{"price":3796.43,"qty":3.96018009}],"asks":[],"checksum":1847808081,"timestamp":"2024-06-01T17:52:55.595490Z"}]}
{"channel":"book","type":"update","data":[{"symbol":"ETH/USD","bids":[{"price":3796.43,"qty":3.95082019},{"price":3796.41,"qty":0.00935996}],"asks":[],"checksum":1943070671,"timestamp":"2024-06-01T17:52:55.599193Z"}]}
{"channel":"book","type":"update","data":[{"symbol":"ETH/USD","bids":[],"asks":[{"price":3797.25,"qty":1.85000000}],"checksum":4018688848,"timestamp":"2024-06-01T17:52:55.605685Z"}]}
{"channel":"book","type":"update","data":[{"symbol":"ETH/USD","bids":[{"price":3796.27,"qty":0.00000000},{"price":3795.67,"qty":3.00000000}],"asks":[],"checksum":798198588,"timestamp":"2024-06-01T17:52:55.608510Z"}]}
{"channel":"book","type":"update","data":[{"symbol":"ETH/USD","bids":[],"asks":[{"price":3796.74,"qty":0.00000000},{"price":3797.44,"qty":10.81226191}],"checksum":1309903626,"timestamp":"2024-06-01T17:52:55.608677Z"}]}
{"channel":"book","type":"update","data":[{"symbol":"ETH/USD","bids":[],"asks":[{"price":3796.57,"qty":0.00000000},{"price":3797.46,"qty":1.00000000}],"checksum":4109001846,"timestamp":"2024-06-01T17:52:55.608736Z"}]}
{"channel":"book","type":"update","data":[{"symbol":"ETH/USD","bids":[{"price":3795.71,"qty":0.00524446}],"asks":[],"checksum":1063107393,"timestamp":"2024-06-01T17:52:55.610425Z"}]}
{"channel":"book","type":"update","data":[{"symbol":"ETH/USD","bids":[],"asks":[{"price":3796.57,"qty":26.33959787}],"checksum":3038372142,"timestamp":"2024-06-01T17:52:55.615603Z"}]}
{"channel":"book","type":"update","data":[{"symbol":"ETH/USD","bids":[],"asks":[{"price":3796.88,"qty":26.33744167}],"checksum":4040519180,"timestamp":"2024-06-01T17:52:55.615828Z"}]}
{"channel":"book","type":"update","data":[{"symbol":"ETH/USD","bids":[{"price":3796.27,"qty":26.34161307}],"asks":[],"checksum":2303272201,"timestamp":"2024-06-01T17:52:55.615856Z"}]}
{"channel":"book","type":"update","data":[{"symbol":"ETH/USD","bids":[{"price":3796.27,"qty":0.00000000},{"price":3795.70,"qty":26.34559104}],"asks":[],"checksum":4040519180,"timestamp":"2024-06-01T17:52:55.634556Z"}]}
{"channel":"book","type":"update","data":[{"symbol":"ETH/USD","bids":[],"asks":[{"price":3796.57,"qty":0.00000000},{"price":3797.44,"qty":10.81226191}],"checksum":3520236859,"timestamp":"2024-06-01T17:52:55.634564Z"}]}
{"channel":"book","type":"update","data":[{"symbol":"ETH/USD","bids":[],"asks":[{"price":3796.44,"qty":0.09000000}],"checksum":1660318189,"timestamp":"2024-06-01T17:52:55.686810Z"}]}
{"channel":"book","type":"update","data":[{"symbol":"ETH/USD","bids":[{"price":3795.71,"qty":3.40793681}],"asks":[],"checksum":409291061,"timestamp":"2024-06-01T17:52:55.700389Z"}]}
{"channel":"book","type":"update","data":[{"symbol":"ETH/USD","bids":[{"price":3796.40,"qty":0.32778701}],"asks":[],"checksum":3969668229,"timestamp":"2024-06-01T17:52:55.704259Z"}]}
{"channel":"book","type":"update","data":[{"symbol":"ETH/USD","bids":[{"price":3796.40,"qty":0.00000000},{"price":3795.67,"qty":3.00000000}],"asks":[],"checksum":11513123,"timestamp":"2024-06-01T17:52:55.708197Z"}]}
{"channel":"book","type":"update","data":[{"symbol":"ETH/USD","bids":[],"asks":[{"price":3796.54,"qty":26.33981707}],"checksum":2315963409,"timestamp":"2024-06-01T17:52:55.708239Z"}]}
{"channel":"book","type":"update","data":[{"symbol":"ETH/USD","bids":[{"price":3796.24,"qty":30.29262302}],"asks":[],"checksum":1772562991,"timestamp":"2024-06-01T17:52:55.708355Z"}]}
{"channel":"book","type":"update","data":[{"symbol":"ETH/USD","bids":[{"price":3796.41,"qty":0.00000000},{"price":3795.62,"qty":5.27100000},{"price":3796.25,"qty":0.00936035}],"asks":[],"checksum":4009529880,"timestamp":"2024-06-01T17:52:55.768609Z"}]}
{"channel":"book","type":"update","data":[{"symbol":"ETH/USD","bids":[],"asks":[{"price":3796.53,"qty":2.40000000}],"checksum":3840775201,"timestamp":"2024-06-01T17:52:55.827787Z"}]}
{"channel":"book","type":"update","data":[{"symbol":"ETH/USD","bids":[],"asks":[{"price":3797.03,"qty":0.00000000},{"price":3797.35,"qty":3.30000000}],"checksum":3346507588,"timestamp":"2024-06-01T17:52:55.830195Z"}]}
{"channel":"book","type":"update","data":[{"symbol":"ETH/USD","bids":[],"asks":[{"price":3796.76,"qty":0.00000000},{"price":3797.44,"qty":10.81226191}],"checksum":364846174,"timestamp":"2024-06-01T17:52:55.830526Z"}]}
{"channel":"book","type":"update","data":[{"symbol":"ETH/USD","bids":[],"asks":[{"price":3796.52,"qty":0.79163089}],"checksum":2364014454,"timestamp":"2024-06-01T17:52:56.057205Z"}]}
{"channel":"book","type":"update","data":[{"symbol":"ETH/USD","bids":[],"asks":[{"price":3797.25,"qty":0.00000000},{"price":3797.44,"qty":10.81226191},{"price":3796.98,"qty":1.85000000}],"checksum":119742142,"timestamp":"2024-06-01T17:52:56.289419Z"}]}
{"channel":"book","type":"update","data":[{"symbol":"ETH/USD","bids":[],"asks":[{"price":3796.98,"qty":3.70000000}],"checksum":2609705336,"timestamp":"2024-06-01T17:52:56.292517Z"}]}
{"channel":"book","type":"update","data":[{"symbol":"ETH/USD","bids":[],"asks":[{"price":3796.54,"qty":0.00000000},{"price":3797.44,"qty":10.81226191}],"checksum":1945058671,"timestamp":"2024-06-01T17:52:56.637419Z"}]}
{"channel":"book","type":"update","data":[{"symbol":"ETH/USD","bids":[{"price":3796.24,"qty":3.95082019}],"asks":[],"checksum":415887621,"timestamp":"2024-06-01T17:52:56.637432Z"}]}
{"channel":"book","type":"update","data":[{"symbol":"ETH/USD","bids":[{"price":3796.22,"qty":26.34197298}],"asks":[],"checksum":3890997823,"timestamp":"2024-06-01T17:52:56.641999Z"}]}
{"channel":"book","type":"update","data":[{"symbol":"ETH/USD","bids":[],"asks":[{"price":3796.53,"qty":28.73989371}],"checksum":3732741274,"timestamp":"2024-06-01T17:52:56.642116Z"}]}
{"channel":"book","type":"update","data":[{"symbol":"ETH/USD","bids":[],"asks":[{"price":3796.53,"qty":2.40000000}],"checksum":3890997823,"timestamp":"2024-06-01T17:52:56.697027Z"}]}
{"channel":"book","type":"update","data":[{"symbol":"ETH/USD","bids":[],"asks":[{"price":3796.51,"qty":26.34000961}],"checksum":2013211349,"timestamp":"2024-06-01T17:52:56.701139Z"}]}
{"channel":"book","type":"update","data":[{"symbol":"ETH/USD","bids":[],"asks":[{"price":3796.53,"qty":0.00000000},{"price":3797.44,"qty":10.81226191}],"checksum":1570204980,"timestamp":"2024-06-01T17:52:56.740377Z"}]}
{"channel":"book","type":"update","data":[{"symbol":"ETH/USD","bids":[],"asks":[{"price":3796.50,"qty":2.00000000}],"checksum":2951813448,"timestamp":"2024-06-01T17:52:56.740691Z"}]}
{"channel":"book","type":"update","data":[{"symbol":"ETH/USD","bids":[{"price":3796.22,"qty":0.00000000},{"price":3795.67,"qty":3.00000000}],"asks":[],"checksum":2953629090,"timestamp":"2024-06-01T17:52:56.861389Z"}]}
{"channel":"book","type":"update","data":[{"symbol":"ETH/USD","bids":[],"asks":[{"price":3796.60,"qty":26.33939600}],"checksum":4077431785,"timestamp":"2024-06-01T17:52:56.865631Z"}]}
{"channel":"book","type":"update","data":[{"symbol":"ETH/USD","bids":[{"price":3796.19,"qty":26.34213368}],"asks":[],"checksum":2092022212,"timestamp":"2024-06-01T17:52:56.865666Z"}]}
{"channel":"book","type":"update","data":[{"symbol":"ETH/USD","bids":[{"price":3796.19,"qty":0.00000000},{"price":3795.67,"qty":3.00000000}],"asks":[],"checksum":4077431785,"timestamp":"2024-06-01T17:52:57.006581Z"}]}
{"channel":"book","type":"update","data":[{"symbol":"ETH/USD","bids":[{"price":3796.20,"qty":26.34206518}],"asks":[],"checksum":785884631,"timestamp":"2024-06-01T17:52:57.010980Z"}]}
{"channel":"book","type":"update","data":[{"symbol":"ETH/USD","bids":[{"price":3795.75,"qty":0.00000000},{"price":3795.67,"qty":3.00000000}],"asks":[],"checksum":3176203137,"timestamp":"2024-06-01T17:52:57.149742Z"}]}
{"channel":"book","type":"update","data":[{"symbol":"ETH/USD","bids":[],"asks":[{"price":3796.44,"qty":3.09000000}],"checksum":747930668,"timestamp":"2024-06-01T17:52:57.151495Z"}]}
{"channel":"book","type":"update","data":[{"symbol":"ETH/USD","bids":[{"price":3795.67,"qty":0.00000000},{"price":3795.45,"qty":6.38468581}],"asks":[],"checksum":4018800183,"timestamp":"2024-06-01T17:52:57.154254Z"}]}
{"channel":"book","type":"update","data":[{"symbol":"ETH/USD","bids":[],"asks":[{"price":3797.04,"qty":0.00000000},{"price":3797.35,"qty":3.30000000}],"checksum":2647524430,"timestamp":"2024-06-01T17:52:57.154365Z"}]}
{"channel":"book","type":"update","data":[{"symbol":"ETH/USD","bids":[{"price":3796.20,"qty":0.00000000},{"price":3795.28,"qty":3.94900000}],"asks":[],"checksum":3432759974,"timestamp":"2024-06-01T17:52:57.154377Z"}]}
{"channel":"book","type":"update","data":[{"symbol":"ETH/USD","bids":[{"price":3796.18,"qty":0.00000000},{"price":3795.25,"qty":2.20100000}],"asks":[],"checksum":3208426319,"timestamp":"2024-06-01T17:52:57.154386Z"}]}
{"channel":"book","type":"update","data":[{"symbol":"ETH/USD","bids":[{"price":3796.43,"qty":0.00000000},{"price":3795.23,"qty":3.00000000}],"asks":[],"checksum":1891624055,"timestamp":"2024-06-01T17:52:57.154985Z"}]}
{"channel":"book","type":"update","data":[{"symbol":"ETH/USD","bids":[{"price":3796.24,"qty":0.00000000},{"price":3795.20,"qty":0.52681071}],"asks":[],"checksum":1207432713,"timestamp":"2024-06-01T17:52:57.155361Z"}]}
{"channel":"book","type":"update","data":[{"symbol":"ETH/USD","bids":[],"asks":[{"price":3797.23,"qty":0.72912968}],"checksum":1041623970,"timestamp":"2024-06-01T17:52:57.156138Z"}]}
{"channel":"book","type":"update","data":[{"symbol":"ETH/USD","bids":[],"asks":[{"price":3796.60,"qty":0.00000000},{"price":3797.35,"qty":3.30000000}],"checksum":613325661,"timestamp":"2024-06-01T17:52:57.156561Z"}]}
{"channel":"book","type":"update","data":[{"symbol":"ETH/USD","bids":[{"price":3795.95,"qty":0.00000000},{"price":3794.88,"qty":0.06693358}],"asks":[],"checksum":2754036925,"timestamp":"2024-06-01T17:52:57.157617Z"}]}
{"channel":"book","type":"update","data":[{"symbol":"ETH/USD","bids":[],"asks":[{"price":3796.44,"qty":6.09000000}],"checksum":2265373873,"timestamp":"2024-06-01T17:52:57.158390Z"}]}
{"channel":"book","type":"update","data":[{"symbol":"ETH/USD","bids":[{"price":3795.29,"qty":0.78110913}],"asks":[],"checksum":3120394311,"timestamp":"2024-06-01T17:52:57.159228Z"}]}
{"channel":"book","type":"update","data":[{"symbol":"ETH/USD","bids":[{"price":3795.96,"qty":3.95082019}],"asks":[],"checksum":4263062718,"timestamp":"2024-06-01T17:52:57.160730Z"}]}
{"channel":"book","type":"update","data":[{"symbol":"ETH/USD","bids":[{"price":3795.96,"qty":7.90164038}],"asks":[],"checksum":1428263105,"timestamp":"2024-06-01T17:52:57.161802Z"}]}
{"channel":"book","type":"update","data":[{"symbol":"ETH/USD","bids":[{"price":3795.77,"qty":3.95082019}],"asks":[],"checksum":1513171823,"timestamp":"2024-06-01T17:52:57.162301Z"}]}
{"channel":"book","type":"update","data":[{"symbol":"ETH/USD","bids":[],"asks":[{"price":3796.32,"qty":26.34136190}],"checksum":2829328240,"timestamp":"2024-06-01T17:52:57.163959Z"}]}
{"channel":"book","type":"update","data":[{"symbol":"ETH/USD","bids":[],"asks":[{"price":3796.26,"qty":26.34171526}],"checksum":3288095868,"timestamp":"2024-06-01T17:52:57.163979Z"}]}
{"channel":"book","type":"update","data":[{"symbol":"ETH/USD","bids":[{"price":3795.94,"qty":26.34388217}],"asks":[],"checksum":3803357901,"timestamp":"2024-06-01T17:52:57.164107Z"}]}
{"channel":"book","type":"update","data":[{"symbol":"ETH/USD","bids":[{"price":3795.37,"qty":26.34783230}],"asks":[],"checksum":2390738761,"timestamp":"2024-06-01T17:52:57.164132Z"}]}
{"channel":"book","type":"update","data":[{"symbol":"ETH/USD","bids":[{"price":3795.92,"qty":0.00000000},{"price":3795.28,"qty":3.94900000}],"asks":[],"checksum":3281396391,"timestamp":"2024-06-01T17:52:57.164154Z"}]}
{"channel":"book","type":"update","data":[{"symbol":"ETH/USD","bids":[{"price":3795.96,"qty":3.95082019}],"asks":[],"checksum":59209398,"timestamp":"2024-06-01T17:52:57.164224Z"}]}
{"channel":"book","type":"update","data":[{"symbol":"ETH/USD","bids":[],"asks":[{"price":3796.44,"qty":3.09000000}],"checksum":862868014,"timestamp":"2024-06-01T17:52:57.167933Z"}]}
{"channel":"book","type":"update","data":[{"symbol":"ETH/USD","bids":[],"asks":[{"price":3796.44,"qty":3.00000000}],"checksum":1920982542,"timestamp":"2024-06-01T17:52:57.168163Z"}]}
{"channel":"book","type":"update","data":[{"symbol":"ETH/USD","bids":[],"asks":[{"price":3796.26,"qty":29.34171526}],"checksum":1008295434,"timestamp":"2024-06-01T17:52:57.168179Z"}]}
{"channel":"book","type":"update","data":[{"symbol":"ETH/USD","bids":[],"asks":[{"price":3796.77,"qty":0.00000000},{"price":3797.23,"qty":0.72912968}],"checksum":2953042228,"timestamp":"2024-06-01T17:52:57.169106Z"}]}
{"channel":"book","type":"update","data":[{"symbol":"ETH/USD","bids":[{"price":3795.94,"qty":0.00000000},{"price":3795.25,"qty":2.20100000}],"asks":[],"checksum":3690999064,"timestamp":"2024-06-01T17:52:57.171933Z"}]}
{"channel":"book","type":"update","data":[{"symbol":"ETH/USD","bids":[{"price":3795.60,"qty":26.34626753}],"asks":[],"checksum":486505294,"timestamp":"2024-06-01T17:52:57.176006Z"}]}
{"channel":"book","type":"update","data":[{"symbol":"ETH/USD","bids":[{"price":3795.71,"qty":0.00524446}],"asks":[],"checksum":3414733627,"timestamp":"2024-06-01T17:52:57.176742Z"}]}
{"channel":"book","type":"update","data":[{"symbol":"ETH/USD","bids":[],"asks":[{"price":3796.50,"qty":0.00000000},{"price":3797.35,"qty":3.30000000}],"checksum":3150440539,"timestamp":"2024-06-01T17:52:57.184740Z"}]}
{"channel":"book","type":"update","data":[{"symbol":"ETH/USD","bids":[{"price":3795.97,"qty":1.00000000}],"asks":[],"checksum":3123383200,"timestamp":"2024-06-01T17:52:57.189191Z"}]}
{"channel":"book","type":"update","data":[{"symbol":"ETH/USD","bids":[{"price":3795.70,"qty":0.00000000},{"price":3795.28,"qty":3.94900000}],"asks":[],"checksum":1686119591,"timestamp":"2024-06-01T17:52:57.204706Z"}]}
{"channel":"book","type":"update","data":[{"symbol":"ETH/USD","bids":[{"price":3796.25,"qty":0.00000000},{"price":3795.25,"qty":2.20100000},{"price":3795.97,"qty":1.00936050}],"asks":[],"checksum":1864051608,"timestamp":"2024-06-01T17:52:57.206303Z"}]}
{"channel":"book","type":"update","data":[{"symbol":"ETH/USD","bids":[{"price":3795.71,"qty":0.00000000},{"price":3795.23,"qty":3.00000000}],"asks":[],"checksum":2943563985,"timestamp":"2024-06-01T17:52:57.209117Z"}]}
{"channel":"book","type":"update","data":[{"symbol":"ETH/USD","bids":[{"price":3795.61,"qty":0.00524666}],"asks":[],"checksum":4053193692,"timestamp":"2024-06-01T17:52:57.209129Z"}]}
{"channel":"book","type":"update","data":[{"symbol":"ETH/USD","bids":[],"asks":[{"price":3796.26,"qty":3.00000000}],"checksum":2137942891,"timestamp":"2024-06-01T17:52:57.211159Z"}]}
{"channel":"book","type":"update","data":[{"symbol":"ETH/USD","bids":[{"price":3795.89,"qty":26.34424240}],"asks":[],"checksum":3617773975,"timestamp":"2024-06-01T17:52:57.215174Z"}]}
{"channel":"book","type":"update","data":[{"symbol":"ETH/USD","bids":[],"asks":[{"price":3796.23,"qty":26.34194851}],"checksum":2486812936,"timestamp":"2024-06-01T17:52:57.215221Z"}]}
{"channel":"book","type":"update","data":[{"symbol":"ETH/USD","bids":[{"price":3795.61,"qty":0.00000000},{"price":3795.25,"qty":2.20100000}],"asks":[],"checksum":3319130928,"timestamp":"2024-06-01T17:52:57.220132Z"}]}
{"channel":"book","type":"update","data":[{"symbol":"ETH/USD","bids":[],"asks":[{"price":3796.44,"qty":0.00000000},{"price":3797.35,"qty":3.30000000}],"checksum":2166455711,"timestamp":"2024-06-01T17:52:57.226873Z"}]}
{"channel":"book","type":"update","data":[{"symbol":"ETH/USD","bids":[],"asks":[{"price":3796.23,"qty":29.34194851}],"checksum":150304221,"timestamp":"2024-06-01T17:52:57.226896Z"}]}
{"channel":"book","type":"update","data":[{"symbol":"ETH/USD","bids":[],"asks":[{"price":3796.26,"qty":0.00000000},{"price":3797.44,"qty":10.81226191}],"checksum":501411995,"timestamp":"2024-06-01T17:52:57.230447Z"}]}
{"channel":"book","type":"update","data":[{"symbol":"ETH/USD","bids":[],"asks":[{"price":3796.22,"qty":3.00000000}],"checksum":42209963,"timestamp":"2024-06-01T17:52:57.231193Z"}]}
{"channel":"book","type":"update","data":[{"symbol":"ETH/USD","bids":[{"price":3795.89,"qty":0.00000000},{"price":3795.23,"qty":3.00000000}],"asks":[],"checksum":2482826295,"timestamp":"2024-06-01T17:52:57.233114Z"}]}
{"channel":"book","type":"update","data":[{"symbol":"ETH/USD","bids":[],"asks":[{"price":3796.21,"qty":0.52684124}],"checksum":1652458920,"timestamp":"2024-06-01T17:52:57.237232Z"}]}
{"channel":"book","type":"update","data":[{"symbol":"ETH/USD","bids":[{"price":3795.98,"qty":7.78000000}],"asks":[],"checksum":2121954354,"timestamp":"2024-06-01T17:52:57.262804Z"}]}
{"channel":"book","type":"update","data":[{"symbol":"ETH/USD","bids":[{"price":3795.61,"qty":0.00545621}],"asks":[],"checksum":604920553,"timestamp":"2024-06-01T17:52:57.264348Z"}]}
{"channel":"book","type":"update","data":[{"symbol":"ETH/USD","bids":[],"asks":[{"price":3796.52,"qty":0.00000000},{"price":3797.35,"qty":3.30000000}],"checksum":3567337715,"timestamp":"2024-06-01T17:52:57.265891Z"}]}
{"channel":"book","type":"update","data":[{"symbol":"ETH/USD","bids":[],"asks":[{"price":3796.21,"qty":0.00000000},{"price":3797.44,"qty":10.81226191},{"price":3797.31,"qty":0.52684124}],"checksum":4244015141,"timestamp":"2024-06-01T17:52:57.267011Z"}]}
{"channel":"book","type":"update","data":[{"symbol":"ETH/USD","bids":[{"price":3795.64,"qty":3.40275510}],"asks":[],"checksum":2443751069,"timestamp":"2024-06-01T17:52:57.296150Z"}]}
{"channel":"book","type":"update","data":[{"symbol":"ETH/USD","bids":[{"price":3795.36,"qty":1.85000000}],"asks":[],"checksum":1369433209,"timestamp":"2024-06-01T17:52:57.310452Z"}]}
{"channel":"book","type":"update","data":[{"symbol":"ETH/USD","bids":[],"asks":[{"price":3796.21,"qty":1.60000000}],"checksum":2898911449,"timestamp":"2024-06-01T17:52:57.396550Z"}]}
{"channel":"book","type":"update","data":[{"symbol":"ETH/USD","bids":[],"asks":[{"price":3796.20,"qty":0.80329133}],"checksum":1157527347,"timestamp":"2024-06-01T17:52:57.399744Z"}]}
{"channel":"book","type":"update","data":[{"symbol":"ETH/USD","bids":[],"asks":[{"price":3796.22,"qty":0.00000000},{"price":3797.31,"qty":0.52684124}],"checksum":4041902071,"timestamp":"2024-06-01T17:52:57.465135Z"}]}
{"channel":"book","type":"update","data":[{"symbol":"ETH/USD","bids":[{"price":3795.78,"qty":0.00535638}],"asks":[],"checksum":856195332,"timestamp":"2024-06-01T17:52:57.469770Z"}]}
{"channel":"book","type":"update","data":[{"symbol":"ETH/USD","bids":[{"price":3795.61,"qty":0.00000000},{"price":3795.36,"qty":1.85000000}],"asks":[],"checksum":1406555878,"timestamp":"2024-06-01T17:52:57.469927Z"}]}
{"channel":"book","type":"update","data":[{"symbol":"ETH/USD","bids":[],"asks":[{"price":3796.23,"qty":3.00000000}],"checksum":1783239911,"timestamp":"2024-06-01T17:52:57.501540Z"}]}
{"channel":"book","type":"update","data":[{"symbol":"ETH/USD","bids":[{"price":3795.90,"qty":26.34417654}],"asks":[],"checksum":3229138346,"timestamp":"2024-06-01T17:52:57.506216Z"}]}
{"channel":"book","type":"update","data":[{"symbol":"ETH/USD","bids":[],"asks":[{"price":3796.25,"qty":26.34182206}],"checksum":1431423037,"timestamp":"2024-06-01T17:52:57.506238Z"}]}
{"channel":"book","type":"update","data":[{"symbol":"ETH/USD","bids":[],"asks":[{"price":3796.23,"qty":0.00000000},{"price":3797.31,"qty":0.52684124}],"checksum":973661788,"timestamp":"2024-06-01T17:52:57.521541Z"}]}
{"channel":"book","type":"update","data":[{"symbol":"ETH/USD","bids":[],"asks":[{"price":3796.25,"qty":0.00000000},{"price":3797.35,"qty":3.30000000}],"checksum":3794110395,"timestamp":"2024-06-01T17:52:57.588652Z"}]}
{"channel":"book","type":"update","data":[{"symbol":"ETH/USD","bids":[{"price":3795.88,"qty":26.34432796}],"asks":[],"checksum":315745301,"timestamp":"2024-06-01T17:52:57.593508Z"}]}
{"channel":"book","type":"update","data":[{"symbol":"ETH/USD","bids":[],"asks":[{"price":3796.23,"qty":26.34198539}],"checksum":1119236486,"timestamp":"2024-06-01T17:52:57.593615Z"}]}
{"channel":"book","type":"update","data":[{"symbol":"ETH/USD","bids":[],"asks":[{"price":3796.23,"qty":0.00000000},{"price":3797.35,"qty":3.30000000}],"checksum":315745301,"timestamp":"2024-06-01T17:52:57.655033Z"}]}
{"channel":"book","type":"update","data":[{"symbol":"ETH/USD","bids":[{"price":3795.90,"qty":0.00000000},{"price":3795.37,"qty":26.34783230}],"asks":[],"checksum":2107497623,"timestamp":"2024-06-01T17:52:57.655119Z"}]}
{"channel":"book","type":"update","data":[{"symbol":"ETH/USD","bids":[],"asks":[{"price":3796.20,"qty":27.14543478}],"checksum":2827389006,"timestamp":"2024-06-01T17:52:57.659780Z"}]}
{"channel":"book","type":"update","data":[{"symbol":"ETH/USD","bids":[{"price":3795.86,"qty":26.34446509}],"asks":[],"checksum":4101898936,"timestamp":"2024-06-01T17:52:57.659966Z"}]}
{"channel":"book","type":"update","data":[{"symbol":"ETH/USD","bids":[],"asks":[{"price":3796.20,"qty":0.80329133}],"checksum":560289377,"timestamp":"2024-06-01T17:52:57.715702Z"}]}
{"channel":"book","type":"update","data":[{"symbol":"ETH/USD","bids":[],"asks":[{"price":3796.22,"qty":26.34203017}],"checksum":3544381228,"timestamp":"2024-06-01T17:52:57.719904Z"}]}
{"channel":"book","type":"update","data":[{"symbol":"ETH/USD","bids":[{"price":3795.64,"qty":0.00000000},{"price":3795.37,"qty":26.34783230}],"asks":[],"checksum":906084743,"timestamp":"2024-06-01T17:52:57.732806Z"}]}
{"channel":"book","type":"update","data":[{"symbol":"ETH/USD","bids":[],"asks":[{"price":3796.22,"qty":0.00000000},{"price":3797.35,"qty":3.30000000}],"checksum":1050598155,"timestamp":"2024-06-01T17:52:57.743297Z"}]}
{"channel":"book","type":"update","data":[{"symbol":"ETH/USD","bids":[],"asks":[{"price":3796.21,"qty":0.00000000},{"price":3797.44,"qty":10.81226191}],"checksum":106539151,"timestamp":"2024-06-01T17:52:57.805018Z"}]}
{"channel":"book","type":"update","data":[{"symbol":"ETH/USD","bids":[],"asks":[{"price":3796.19,"qty":2.00000000}],"checksum":1352653638,"timestamp":"2024-06-01T17:52:57.805112Z"}]}
{"channel":"book","type":"update","data":[{"symbol":"ETH/USD","bids":[{"price":3795.43,"qty":1.85000000}],"asks":[],"checksum":3216744410,"timestamp":"2024-06-01T17:52:57.809256Z"}]}
{"channel":"book","type":"update","data":[{"symbol":"ETH/USD","bids":[{"price":3795.99,"qty":0.32778701}],"asks":[],"checksum":1531174845,"timestamp":"2024-06-01T17:52:57.816062Z"}]}
{"channel":"book","type":"update","data":[{"symbol":"ETH/USD","bids":[{"price":3795.98,"qty":0.00000000},{"price":3795.43,"qty":1.85000000}],"asks":[],"checksum":4147108911,"timestamp":"2024-06-01T17:52:57.871621Z"}]}
{"channel":"book","type":"update","data":[{"symbol":"ETH/USD","bids":[{"price":3795.59,"qty":3.40279992}],"asks":[],"checksum":734058869,"timestamp":"2024-06-01T17:52:57.883291Z"}]}
{"channel":"book","type":"update","data":[{"symbol":"ETH/USD","bids":[{"price":3795.97,"qty":1.00000000},{"price":3796.00,"qty":0.00936042}],"asks":[],"checksum":2792133704,"timestamp":"2024-06-01T17:52:57.946910Z"}]}
{"channel":"book","type":"update","data":[{"symbol":"ETH/USD","bids":[],"asks":[{"price":3796.20,"qty":27.14546997}],"checksum":3983566335,"timestamp":"2024-06-01T17:52:57.959600Z"}]}
{"channel":"book","type":"update","data":[{"symbol":"ETH/USD","bids":[],"asks":[{"price":3796.19,"qty":5.00000000}],"checksum":4090196031,"timestamp":"2024-06-01T17:52:58.020300Z"}]}
{"channel":"book","type":"update","data":[{"symbol":"ETH/USD","bids":[{"price":3795.88,"qty":0.00000000},{"price":3795.45,"qty":6.38468581}],"asks":[],"checksum":3670639278,"timestamp":"2024-06-01T17:52:58.024041Z"}]}
{"channel":"book","type":"update","data":[{"symbol":"ETH/USD","bids":[],"asks":[{"price":3796.32,"qty":0.00000000},{"price":3797.44,"qty":10.81226191}],"checksum":1849946551,"timestamp":"2024-06-01T17:52:58.024072Z"}]}
{"channel":"book","type":"update","data":[{"symbol":"ETH/USD","bids":[],"asks":[{"price":3796.18,"qty":3.00000000}],"checksum":1708838630,"timestamp":"2024-06-01T17:52:58.026063Z"}]}
{"channel":"book","type":"update","data":[{"symbol":"ETH/USD","bids":[],"asks":[{"price":3796.18,"qty":29.34227038}],"checksum":1448566578,"timestamp":"2024-06-01T17:52:58.028649Z"}]}
{"channel":"book","type":"update","data":[{"symbol":"ETH/USD","bids":[{"price":3795.84,"qty":26.34461331}],"asks":[],"checksum":2751954024,"timestamp":"2024-06-01T17:52:58.028746Z"}]}
{"channel":"book","type":"update","data":[{"symbol":"ETH/USD","bids":[{"price":3795.86,"qty":0.00000000},{"price":3795.45,"qty":6.38468581}],"asks":[],"checksum":4047262750,"timestamp":"2024-06-01T17:52:58.119118Z"}]}
{"channel":"book","type":"update","data":[{"symbol":"ETH/USD","bids":[],"asks":[{"price":3796.18,"qty":3.00000000}],"checksum":3266430410,"timestamp":"2024-06-01T17:52:58.119251Z"}]}
{"channel":"book","type":"update","data":[{"symbol":"ETH/USD","bids":[{"price":3795.81,"qty":26.34479522}],"asks":[],"checksum":1726296854,"timestamp":"2024-06-01T17:52:58.124149Z"}]}
{"channel":"book","type":"update","data":[{"symbol":"ETH/USD","bids":[],"asks":[{"price":3796.16,"qty":26.34243885}],"checksum":3609669511,"timestamp":"2024-06-01T17:52:58.124186Z"}]}
{"channel":"book","type":"update","data":[{"symbol":"ETH/USD","bids":[],"asks":[{"price":3796.19,"qty":2.00000000}],"checksum":1834619425,"timestamp":"2024-06-01T17:52:58.131044Z"}]}
{"channel":"book","type":"update","data":[{"symbol":"ETH/USD","bids":[],"asks":[{"price":3796.16,"qty":29.34243885}],"checksum":2011538676,"timestamp":"2024-06-01T17:52:58.131078Z"}]}
{"channel":"book","type":"update","data":[{"symbol":"ETH/USD","bids":[],"asks":[{"price":3796.15,"qty":3.00000000}],"checksum":42896203,"timestamp":"2024-06-01T17:52:58.135062Z"}]}
{"channel":"book","type":"update","data":[{"symbol":"ETH/USD","bids":[],"asks":[{"price":3796.18,"qty":0.00000000},{"price":3797.31,"qty":0.52684124}],"checksum":3858720923,"timestamp":"2024-06-01T17:52:58.136489Z"}]}
{"channel":"book","type":"update","data":[{"symbol":"ETH/USD","bids":[],"asks":[{"price":3796.16,"qty":3.00000000}],"checksum":1107751776,"timestamp":"2024-06-01T17:52:58.155687Z"}]}
{"channel":"book","type":"update","data":[{"symbol":"ETH/USD","bids":[{"price":3795.84,"qty":0.00000000},{"price":3795.45,"qty":6.38468581}],"asks":[],"checksum":2773518604,"timestamp":"2024-06-01T17:52:58.155755Z"}]}
{"channel":"book","type":"update","data":[{"symbol":"ETH/USD","bids":[],"asks":[{"price":3796.16,"qty":0.00000000},{"price":3797.35,"qty":3.30000000}],"checksum":2864700875,"timestamp":"2024-06-01T17:52:58.159546Z"}]}
{"channel":"book","type":"update","data":[{"symbol":"ETH/USD","bids":[{"price":3795.72,"qty":26.34544074}],"asks":[],"checksum":324590186,"timestamp":"2024-06-01T17:52:58.159971Z"}]}
{"channel":"book","type":"update","data":[{"symbol":"ETH/USD","bids":[],"asks":[{"price":3796.88,"qty":0.00000000},{"price":3797.44,"qty":10.81226191}],"checksum":859335062,"timestamp":"2024-06-01T17:52:58.163036Z"}]}
{"channel":"book","type":"update","data":[{"symbol":"ETH/USD","bids":[{"price":3795.81,"qty":0.00000000},{"price":3795.45,"qty":6.38468581}],"asks":[],"checksum":2716253749,"timestamp":"2024-06-01T17:52:58.163211Z"}]}
{"channel":"book","type":"update","data":[{"symbol":"ETH/USD","bids":[],"asks":[{"price":3796.71,"qty":26.33865284}],"checksum":3515345954,"timestamp":"2024-06-01T17:52:58.167594Z"}]}
{"channel":"book","type":"update","data":[{"symbol":"ETH/USD","bids":[],"asks":[{"price":3796.19,"qty":0.00000000},{"price":3797.44,"qty":10.81226191}],"checksum":1530971991,"timestamp":"2024-06-01T17:52:58.173693Z"}]}
{"channel":"book","type":"update","data":[{"symbol":"ETH/USD","bids":[],"asks":[{"price":3796.14,"qty":1.60000000}],"checksum":3315474434,"timestamp":"2024-06-01T17:52:58.173754Z"}]}
{"channel":"book","type":"update","data":[{"symbol":"ETH/USD","bids":[],"asks":[{"price":3796.12,"qty":26.34268913}],"checksum":2508384629,"timestamp":"2024-06-01T17:52:58.204136Z"}]}
{"channel":"book","type":"update","data":[{"symbol":"ETH/USD","bids":[{"price":3795.79,"qty":26.34495857}],"asks":[],"checksum":2595013371,"timestamp":"2024-06-01T17:52:58.204335Z"}]}
{"channel":"book","type":"update","data":[{"symbol":"ETH/USD","bids":[{"price":3795.79,"qty":0.00000000},{"price":3795.45,"qty":6.38468581}],"asks":[],"checksum":2508384629,"timestamp":"2024-06-01T17:52:58.279772Z"}]}
{"channel":"book","type":"update","data":[{"symbol":"ETH/USD","bids":[{"price":3795.80,"qty":26.34487444}],"asks":[],"checksum":2193939149,"timestamp":"2024-06-01T17:52:58.284450Z"}]}
{"channel":"book","type":"update","data":[{"symbol":"ETH/USD","bids":[],"asks":[{"price":3796.98,"qty":1.85000000}],"checksum":155675651,"timestamp":"2024-06-01T17:52:58.293061Z"}]}
{"channel":"book","type":"update","data":[{"symbol":"ETH/USD","bids":[{"price":3796.01,"qty":3.95124688}],"asks":[],"checksum":3140289038,"timestamp":"2024-06-01T17:52:58.309543Z"}]}
{"channel":"book","type":"update","data":[{"symbol":"ETH/USD","bids":[],"asks":[{"price":3796.15,"qty":0.00000000},{"price":3797.35,"qty":3.30000000}],"checksum":4067281739,"timestamp":"2024-06-01T17:52:58.312888Z"}]}
{"channel":"book","type":"update","data":[{"symbol":"ETH/USD","bids":[{"price":3795.96,"qty":0.00000000},{"price":3795.59,"qty":3.40279992}],"asks":[],"checksum":2039118350,"timestamp":"2024-06-01T17:52:58.313445Z"}]}
{"channel":"book","type":"update","data":[{"symbol":"ETH/USD","bids":[],"asks":[{"price":3796.12,"qty":0.00000000},{"price":3797.44,"qty":10.81226191}],"checksum":3947138464,"timestamp":"2024-06-01T17:52:58.497569Z"}]}
{"channel":"book","type":"update","data":[{"symbol":"ETH/USD","bids":[{"price":3795.80,"qty":0.00000000},{"price":3795.45,"qty":6.38468581}],"asks":[],"checksum":320305894,"timestamp":"2024-06-01T17:52:58.497592Z"}]}
{"channel":"book","type":"update","data":[{"symbol":"ETH/USD","bids":[],"asks":[{"price":3796.17,"qty":26.34239143}],"checksum":3976961844,"timestamp":"2024-06-01T17:52:58.502896Z"}]}
{"channel":"book","type":"update","data":[{"symbol":"ETH/USD","bids":[{"price":3795.83,"qty":26.34463350}],"asks":[],"checksum":1869718153,"timestamp":"2024-06-01T17:52:58.502975Z"}]}
{"channel":"book","type":"update","data":[{"symbol":"ETH/USD","bids":[{"price":3795.83,"qty":0.00000000},{"price":3795.45,"qty":6.38468581}],"asks":[],"checksum":3976961844,"timestamp":"2024-06-01T17:52:58.507335Z"}]}
{"channel":"book","type":"update","data":[{"symbol":"ETH/USD","bids":[],"asks":[{"price":3796.17,"qty":0.00000000},{"price":3797.44,"qty":10.81226191}],"checksum":320305894,"timestamp":"2024-06-01T17:52:58.573231Z"}]}
{"channel":"book","type":"update","data":[{"symbol":"ETH/USD","bids":[],"asks":[{"price":3796.15,"qty":26.34252052}],"checksum":4035112139,"timestamp":"2024-06-01T17:52:58.577457Z"}]}
{"channel":"book","type":"update","data":[{"symbol":"ETH/USD","bids":[{"price":3795.82,"qty":26.34476260}],"asks":[],"checksum":931309453,"timestamp":"2024-06-01T17:52:58.577540Z"}]}
{"channel":"book","type":"update","data":[{"symbol":"ETH/USD","bids":[{"price":3795.97,"qty":0.00000000},{"price":3795.45,"qty":6.38468581}],"asks":[],"checksum":107127184,"timestamp":"2024-06-01T17:52:58.578122Z"}]}
{"channel":"book","type":"update","data":[{"symbol":"ETH/USD","bids":[],"asks":[{"price":3796.15,"qty":0.00000000},{"price":3797.44,"qty":10.81226191}],"checksum":1130260595,"timestamp":"2024-06-01T17:52:58.592760Z"}]}
{"channel":"book","type":"update","data":[{"symbol":"ETH/USD","bids":[{"price":3795.72,"qty":0.00000000},{"price":3795.37,"qty":26.34783230}],"asks":[],"checksum":1866596961,"timestamp":"2024-06-01T17:52:58.592856Z"}]}
{"channel":"book","type":"update","data":[{"symbol":"ETH/USD","bids":[],"asks":[{"price":3796.19,"qty":26.34223864}],"checksum":387233661,"timestamp":"2024-06-01T17:52:58.644335Z"}]}
{"channel":"book","type":"update","data":[{"symbol":"ETH/USD","bids":[{"price":3795.83,"qty":26.34463040}],"asks":[],"checksum":2822696688,"timestamp":"2024-06-01T17:52:58.644433Z"}]}
{"channel":"book","type":"update","data":[{"symbol":"ETH/USD","bids":[{"price":3796.00,"qty":0.00000000},{"price":3795.37,"qty":26.34783230},{"price":3796.02,"qty":0.00936122}],"asks":[],"checksum":3479773438,"timestamp":"2024-06-01T17:52:58.655952Z"}]}
{"channel":"book","type":"update","data":[{"symbol":"ETH/USD","bids":[],"asks":[{"price":3796.19,"qty":0.00000000},{"price":3797.44,"qty":21.24688493}],"checksum":2972908831,"timestamp":"2024-06-01T17:52:58.661572Z"}]}
{"channel":"book","type":"update","data":[{"symbol":"ETH/USD","bids":[{"price":3796.03,"qty":3.95124688}],"asks":[],"checksum":440747010,"timestamp":"2024-06-01T17:52:58.666011Z"}]}
{"channel":"book","type":"update","data":[{"symbol":"ETH/USD","bids":[{"price":3796.01,"qty":0.00000000},{"price":3795.45,"qty":6.38468581}],"asks":[],"checksum":3280194307,"timestamp":"2024-06-01T17:52:58.669560Z"}]}
{"channel":"book","type":"update","data":[{"symbol":"ETH/USD","bids":[{"price":3795.83,"qty":0.00000000},{"price":3795.37,"qty":26.34783230}],"asks":[],"checksum":2091487886,"timestamp":"2024-06-01T17:52:58.698191Z"}]}
{"channel":"book","type":"update","data":[{"symbol":"ETH/USD","bids":[{"price":3795.84,"qty":26.34456902}],"asks":[],"checksum":198685487,"timestamp":"2024-06-01T17:52:58.702802Z"}]}
{"channel":"book","type":"update","data":[{"symbol":"ETH/USD","bids":[],"asks":[{"price":3796.17,"qty":26.34238479}],"checksum":1790293890,"timestamp":"2024-06-01T17:52:58.702979Z"}]}
{"channel":"book","type":"update","data":[{"symbol":"ETH/USD","bids":[],"asks":[{"price":3796.17,"qty":0.00000000},{"price":3797.44,"qty":21.24688493}],"checksum":198685487,"timestamp":"2024-06-01T17:52:58.900191Z"}]}
{"channel":"book","type":"update","data":[{"symbol":"ETH/USD","bids":[],"asks":[{"price":3796.19,"qty":26.34223256}],"checksum":2376850523,"timestamp":"2024-06-01T17:52:58.905192Z"}]}
{"channel":"book","type":"update","data":[{"symbol":"ETH/USD","bids":[{"price":3795.84,"qty":0.00000000},{"price":3795.37,"qty":26.34783230}],"asks":[],"checksum":4208328186,"timestamp":"2024-06-01T17:52:58.910916Z"}]}
{"channel":"book","type":"update","data":[{"symbol":"ETH/USD","bids":[],"asks":[{"price":3796.19,"qty":0.00000000},{"price":3797.44,"qty":21.24688493}],"checksum":2091487886,"timestamp":"2024-06-01T17:52:58.912271Z"}]}
{"channel":"book","type":"update","data":[{"symbol":"ETH/USD","bids":[{"price":3795.85,"qty":26.34450579}],"asks":[],"checksum":649879504,"timestamp":"2024-06-01T17:52:58.917947Z"}]}
{"channel":"book","type":"update","data":[{"symbol":"ETH/USD","bids":[],"asks":[{"price":3796.28,"qty":26.34160669}],"checksum":1301153696,"timestamp":"2024-06-01T17:52:58.923302Z"}]}
{"channel":"book","type":"update","data":[{"symbol":"ETH/USD","bids":[{"price":3795.85,"qty":0.00000000},{"price":3795.37,"qty":26.34783230}],"asks":[],"checksum":396086014,"timestamp":"2024-06-01T17:52:58.940665Z"}]}
{"channel":"book","type":"update","data":[{"symbol":"ETH/USD","bids":[],"asks":[{"price":3796.20,"qty":0.80329133}],"checksum":3256495098,"timestamp":"2024-06-01T17:52:59.237687Z"}]}
{"channel":"book","type":"update","data":[{"symbol":"ETH/USD","bids":[],"asks":[{"price":3796.19,"qty":26.34224531}],"checksum":2114308495,"timestamp":"2024-06-01T17:52:59.242246Z"}]}
{"channel":"book","type":"update","data":[{"symbol":"ETH/USD","bids":[{"price":3795.86,"qty":26.34444520}],"asks":[],"checksum":2749832058,"timestamp":"2024-06-01T17:52:59.242284Z"}]}
{"channel":"book","type":"update","data":[{"symbol":"ETH/USD","bids":[{"price":3796.02,"qty":0.00000000},{"price":3795.37,"qty":26.34783230},{"price":3796.04,"qty":0.00936117}],"asks":[],"checksum":3364486184,"timestamp":"2024-06-01T17:52:59.318879Z"}]}
{"channel":"book","type":"update","data":[{"symbol":"ETH/USD","bids":[{"price":3796.05,"qty":3.95124688}],"asks":[],"checksum":740130373,"timestamp":"2024-06-01T17:52:59.485490Z"}]}
{"channel":"book","type":"update","data":[{"symbol":"ETH/USD","bids":[{"price":3796.03,"qty":0.00000000},{"price":3795.45,"qty":6.38468581}],"asks":[],"checksum":2806939909,"timestamp":"2024-06-01T17:52:59.489272Z"}]}
{"channel":"book","type":"update","data":[{"symbol":"ETH/USD","bids":[{"price":3795.86,"qty":0.00000000},{"price":3795.37,"qty":26.34783230}],"asks":[],"checksum":2058114032,"timestamp":"2024-06-01T17:52:59.494794Z"}]}
{"channel":"book","type":"update","data":[{"symbol":"ETH/USD","bids":[{"price":3795.88,"qty":26.34433296}],"asks":[],"checksum":2861430533,"timestamp":"2024-06-01T17:52:59.499196Z"}]}
{"channel":"book","type":"update","data":[{"symbol":"ETH/USD","bids":[{"price":3795.88,"qty":0.00000000},{"price":3795.37,"qty":26.34783230}],"asks":[],"checksum":2058114032,"timestamp":"2024-06-01T17:52:59.562415Z"}]}
{"channel":"book","type":"update","data":[{"symbol":"ETH/USD","bids":[{"price":3795.86,"qty":26.34445679}],"asks":[],"checksum":663397052,"timestamp":"2024-06-01T17:52:59.567715Z"}]}
{"channel":"book","type":"update","data":[{"symbol":"ETH/USD","bids":[],"asks":[{"price":3796.19,"qty":0.00000000},{"price":3797.35,"qty":3.30000000}],"checksum":2610249929,"timestamp":"2024-06-01T17:52:59.667703Z"}]}
{"channel":"book","type":"update","data":[{"symbol":"ETH/USD","bids":[],"asks":[{"price":3796.17,"qty":26.34235191}],"checksum":1530680150,"timestamp":"2024-06-01T17:52:59.671952Z"}]}
{"channel":"book","type":"update","data":[{"symbol":"ETH/USD","bids":[],"asks":[{"price":3796.17,"qty":0.00000000},{"price":3797.35,"qty":3.30000000}],"checksum":2610249929,"timestamp":"2024-06-01T17:52:59.701579Z"}]}
{"channel":"book","type":"update","data":[{"symbol":"ETH/USD","bids":[{"price":3795.86,"qty":0.00000000},{"price":3795.37,"qty":26.34783230}],"asks":[],"checksum":3333665157,"timestamp":"2024-06-01T17:52:59.717877Z"}]}
{"channel":"book","type":"update","data":[{"symbol":"ETH/USD","bids":[{"price":3795.87,"qty":26.34435518}],"asks":[],"checksum":917606816,"timestamp":"2024-06-01T17:52:59.721808Z"}]}
{"channel":"book","type":"update","data":[{"symbol":"ETH/USD","bids":[],"asks":[{"price":3796.19,"qty":26.34224042}],"checksum":757772759,"timestamp":"2024-06-01T17:52:59.725742Z"}]}
{"channel":"book","type":"update","data":[{"symbol":"ETH/USD","bids":[{"price":3795.87,"qty":0.00000000},{"price":3795.37,"qty":26.34783230}],"asks":[],"checksum":3710423538,"timestamp":"2024-06-01T17:52:59.768526Z"}]}
{"channel":"book","type":"update","data":[{"symbol":"ETH/USD","bids":[{"price":3795.88,"qty":26.34431303}],"asks":[],"checksum":324135946,"timestamp":"2024-06-01T17:52:59.773025Z"}]}
{"channel":"book","type":"update","data":[{"symbol":"ETH/USD","bids":[{"price":3796.06,"qty":0.34482569}],"asks":[],"checksum":3603667986,"timestamp":"2024-06-01T17:52:59.837918Z"}]}
{"channel":"book","type":"update","data":[{"symbol":"ETH/USD","bids":[{"price":3796.07,"qty":3.95124688}],"asks":[],"checksum":2459890316,"timestamp":"2024-06-01T17:52:59.841726Z"}]}
{"channel":"book","type":"update","data":[{"symbol":"ETH/USD","bids":[{"price":3796.05,"qty":0.00000000},{"price":3795.59,"qty":3.40279992}],"asks":[],"checksum":1349437934,"timestamp":"2024-06-01T17:52:59.845278Z"}]}
{"channel":"book","type":"update","data":[{"symbol":"ETH/USD","bids":[{"price":3795.99,"qty":0.00000000},{"price":3795.45,"qty":6.38468581}],"asks":[],"checksum":1022225277,"timestamp":"2024-06-01T17:52:59.974266Z"}]}
{"channel":"book","type":"update","data":[{"symbol":"ETH/USD","bids":[{"price":3796.04,"qty":0.00000000},{"price":3795.37,"qty":26.34783230},{"price":3796.08,"qty":0.00936107}],"asks":[],"checksum":4122856449,"timestamp":"2024-06-01T17:53:00.011301Z"}]}
{"channel":"book","type":"update","data":[{"symbol":"ETH/USD","bids":[{"price":3796.08,"qty":1.00936107}],"asks":[],"checksum":3467368751,"timestamp":"2024-06-01T17:53:00.100231Z"}]}
{"channel":"book","type":"update","data":[{"symbol":"ETH/USD","bids":[],"asks":[{"price":3796.19,"qty":0.00000000},{"price":3797.35,"qty":3.30000000}],"checksum":1833748879,"timestamp":"2024-06-01T17:53:00.149953Z"}]}
{"channel":"book","type":"update","data":[{"symbol":"ETH/USD","bids":[{"price":3795.89,"qty":15.80382189}],"asks":[],"checksum":856015310,"timestamp":"2024-06-01T17:53:00.154030Z"}]}
{"channel":"book","type":"update","data":[{"symbol":"ETH/USD","bids":[{"price":3795.88,"qty":0.00000000},{"price":3795.45,"qty":6.38468581}],"asks":[],"checksum":4052760313,"timestamp":"2024-06-01T17:53:00.154413Z"}]}
{"channel":"book","type":"update","data":[{"symbol":"ETH/USD","bids":[],"asks":[{"price":3796.21,"qty":26.34206918}],"checksum":2062153161,"timestamp":"2024-06-01T17:53:00.158906Z"}]}
{"channel":"book","type":"update","data":[{"symbol":"ETH/USD","bids":[{"price":3795.90,"qty":26.34420764}],"asks":[],"checksum":2703296321,"timestamp":"2024-06-01T17:53:00.159186Z"}]}
{"channel":"book","type":"update","data":[{"symbol":"ETH/USD","bids":[],"asks":[{"price":3796.14,"qty":0.00000000},{"price":3797.35,"qty":3.30000000}],"checksum":3818210751,"timestamp":"2024-06-01T17:53:00.173420Z"}]}
{"channel":"book","type":"update","data":[{"symbol":"ETH/USD","bids":[],"asks":[{"price":3796.67,"qty":2.20100000}],"checksum":2978539187,"timestamp":"2024-06-01T17:53:00.617627Z"}]}
{"channel":"book","type":"update","data":[{"symbol":"ETH/USD","bids":[{"price":3796.08,"qty":1.00000000},{"price":3796.09,"qty":0.00936104}],"asks":[],"checksum":4022718660,"timestamp":"2024-06-01T17:53:00.660493Z"}]}
{"channel":"book","type":"update","data":[{"symbol":"ETH/USD","bids":[{"price":3796.10,"qty":3.95124688}],"asks":[],"checksum":2615764961,"timestamp":"2024-06-01T17:53:00.765412Z"}]}
{"channel":"book","type":"update","data":[{"symbol":"ETH/USD","bids":[{"price":3796.07,"qty":0.00000000},{"price":3795.60,"qty":26.34626753}],"asks":[],"checksum":461002160,"timestamp":"2024-06-01T17:53:00.769105Z"}]}
{"channel":"book","type":"update","data":[{"symbol":"ETH/USD","bids":[],"asks":[{"price":3796.21,"qty":0.00000000},{"price":3797.35,"qty":3.30000000}],"checksum":574819895,"timestamp":"2024-06-01T17:53:00.914569Z"}]}
{"channel":"book","type":"update","data":[{"symbol":"ETH/USD","bids":[],"asks":[{"price":3796.23,"qty":26.34195477}],"checksum":738588429,"timestamp":"2024-06-01T17:53:00.918468Z"}]}
{"channel":"book","type":"update","data":[{"symbol":"ETH/USD","bids":[{"price":3795.90,"qty":0.00000000},{"price":3795.59,"qty":3.40279992}],"asks":[],"checksum":2367373972,"timestamp":"2024-06-01T17:53:00.927007Z"}]}
{"channel":"book","type":"update","data":[{"symbol":"ETH/USD","bids":[{"price":3795.92,"qty":26.34404421}],"asks":[],"checksum":3101117814,"timestamp":"2024-06-01T17:53:00.931887Z"}]}
{"channel":"book","type":"update","data":[{"symbol":"ETH/USD","bids":[{"price":3796.09,"qty":0.00000000},{"price":3795.45,"qty":6.38468581},{"price":3796.11,"qty":0.00936048}],"asks":[],"checksum":4265621652,"timestamp":"2024-06-01T17:53:01.347949Z"}]}
{"channel":"book","type":"update","data":[{"symbol":"ETH/USD","bids":[{"price":3795.92,"qty":0.00000000},{"price":3795.45,"qty":6.38468581}],"asks":[],"checksum":22204435,"timestamp":"2024-06-01T17:53:01.404174Z"}]}
{"channel":"book","type":"update","data":[{"symbol":"ETH/USD","bids":[],"asks":[{"price":3796.23,"qty":0.00000000},{"price":3797.35,"qty":3.30000000}],"checksum":2619594779,"timestamp":"2024-06-01T17:53:01.404230Z"}]}
{"channel":"book","type":"update","data":[{"symbol":"ETH/USD","bids":[{"price":3796.12,"qty":3.95124688}],"asks":[],"checksum":3123953486,"timestamp":"2024-06-01T17:53:01.408456Z"}]}
{"channel":"book","type":"update","data":[{"symbol":"ETH/USD","bids":[{"price":3795.87,"qty":26.34436916}],"asks":[],"checksum":1603443106,"timestamp":"2024-06-01T17:53:01.408968Z"}]}
{"channel":"book","type":"update","data":[{"symbol":"ETH/USD","bids":[],"asks":[{"price":3796.19,"qty":26.34220099}],"checksum":2774351267,"timestamp":"2024-06-01T17:53:01.408987Z"}]}
{"channel":"book","type":"update","data":[{"symbol":"ETH/USD","bids":[{"price":3796.10,"qty":0.00000000},{"price":3795.60,"qty":26.34626753}],"asks":[],"checksum":4242302809,"timestamp":"2024-06-01T17:53:01.412142Z"}]}
{"channel":"book","type":"update","data":[{"symbol":"ETH/USD","bids":[],"asks":[{"price":3796.20,"qty":0.00000000},{"price":3797.35,"qty":3.30000000}],"checksum":4035049677,"timestamp":"2024-06-01T17:53:01.461897Z"}]}
{"channel":"book","type":"update","data":[{"symbol":"ETH/USD","bids":[],"asks":[{"price":3796.18,"qty":0.76301391}],"checksum":2121166876,"timestamp":"2024-06-01T17:53:01.573096Z"}]}
{"channel":"book","type":"update","data":[{"symbol":"ETH/USD","bids":[{"price":3796.08,"qty":0.00000000},{"price":3795.45,"qty":6.38468581}],"asks":[],"checksum":3955792077,"timestamp":"2024-06-01T17:53:01.576968Z"}]}
{"channel":"book","type":"update","data":[{"symbol":"ETH/USD","bids":[],"asks":[{"price":3796.19,"qty":0.00000000},{"price":3797.35,"qty":3.30000000}],"checksum":631133945,"timestamp":"2024-06-01T17:53:01.915469Z"}]}
{"channel":"book","type":"update","data":[{"symbol":"ETH/USD","bids":[{"price":3795.87,"qty":0.00000000},{"price":3795.43,"qty":3.40294337}],"asks":[],"checksum":2591849137,"timestamp":"2024-06-01T17:53:01.915556Z"}]}
{"channel":"book","type":"update","data":[{"symbol":"ETH/USD","bids":[],"asks":[{"price":3796.22,"qty":26.34203043}],"checksum":160192813,"timestamp":"2024-06-01T17:53:01.920891Z"}]}
{"channel":"book","type":"update","data":[{"symbol":"ETH/USD","bids":[{"price":3795.88,"qty":26.34429168}],"asks":[],"checksum":2875686835,"timestamp":"2024-06-01T17:53:01.920987Z"}]}
{"channel":"book","type":"update","data":[{"symbol":"ETH/USD","bids":[{"price":3796.11,"qty":0.00000000},{"price":3795.43,"qty":3.40294337},{"price":3796.13,"qty":0.00936043}],"asks":[],"checksum":3351325943,"timestamp":"2024-06-01T17:53:01.989102Z"}]}
{"channel":"book","type":"update","data":[{"symbol":"ETH/USD","bids":[{"price":3796.06,"qty":0.00000000},{"price":3795.43,"qty":3.40294337}],"asks":[],"checksum":874795914,"timestamp":"2024-06-01T17:53:01.993577Z"}]}
{"channel":"book","type":"update","data":[{"symbol":"ETH/USD","bids":[{"price":3795.89,"qty":0.00000000},{"price":3795.37,"qty":26.34783230}],"asks":[],"checksum":3546149472,"timestamp":"2024-06-01T17:53:01.997169Z"}]}
{"channel":"book","type":"update","data":[{"symbol":"ETH/USD","bids":[{"price":3796.14,"qty":3.95124688}],"asks":[],"checksum":4171534899,"timestamp":"2024-06-01T17:53:01.997796Z"}]}
{"channel":"book","type":"update","data":[{"symbol":"ETH/USD","bids":[{"price":3796.12,"qty":0.00000000},{"price":3795.37,"qty":26.34783230}],"asks":[],"checksum":1874543496,"timestamp":"2024-06-01T17:53:02.001419Z"}]}
{"channel":"book","type":"update","data":[{"symbol":"ETH/USD","bids":[],"asks":[{"price":3796.22,"qty":0.00000000},{"price":3797.35,"qty":3.30000000}],"checksum":271082524,"timestamp":"2024-06-01T17:53:02.020160Z"}]}
{"channel":"book","type":"update","data":[{"symbol":"ETH/USD","bids":[],"asks":[{"price":3796.20,"qty":26.34217795}],"checksum":1637312069,"timestamp":"2024-06-01T17:53:02.024460Z"}]}
{"channel":"book","type":"update","data":[{"symbol":"ETH/USD","bids":[],"asks":[{"price":3796.20,"qty":0.00000000},{"price":3797.35,"qty":3.30000000}],"checksum":271082524,"timestamp":"2024-06-01T17:53:02.029006Z"}]}
{"channel":"book","type":"update","data":[{"symbol":"ETH/USD","bids":[],"asks":[{"price":3796.21,"qty":26.34211736}],"checksum":853314639,"timestamp":"2024-06-01T17:53:02.257205Z"}]}
{"channel":"book","type":"update","data":[{"symbol":"ETH/USD","bids":[],"asks":[{"price":3796.21,"qty":0.00000000},{"price":3797.35,"qty":3.30000000}],"checksum":271082524,"timestamp":"2024-06-01T17:53:02.296090Z"}]}
{"channel":"book","type":"update","data":[{"symbol":"ETH/USD","bids":[{"price":3795.88,"qty":0.00000000},{"price":3795.29,"qty":0.78110913}],"asks":[],"checksum":2367192111,"timestamp":"2024-06-01T17:53:02.296110Z"}]}
{"channel":"book","type":"update","data":[{"symbol":"ETH/USD","bids":[{"price":3795.90,"qty":26.34418893}],"asks":[],"checksum":3253654099,"timestamp":"2024-06-01T17:53:02.300704Z"}]}
{"channel":"book","type":"update","data":[{"symbol":"ETH/USD","bids":[],"asks":[{"price":3796.22,"qty":26.34202604}],"checksum":676167466,"timestamp":"2024-06-01T17:53:02.393675Z"}]}
{"channel":"book","type":"update","data":[{"symbol":"ETH/USD","bids":[{"price":3795.90,"qty":0.00000000},{"price":3795.29,"qty":0.78110913}],"asks":[],"checksum":1060689744,"timestamp":"2024-06-01T17:53:02.503680Z"}]}
{"channel":"book","type":"update","data":[{"symbol":"ETH/USD","bids":[{"price":3795.91,"qty":26.34410438}],"asks":[],"checksum":3965453308,"timestamp":"2024-06-01T17:53:02.507631Z"}]}
{"channel":"book","type":"update","data":[{"symbol":"ETH/USD","bids":[{"price":3796.13,"qty":0.00000000},{"price":3795.29,"qty":0.78110913},{"price":3796.15,"qty":0.00936038}],"asks":[],"checksum":1001045448,"timestamp":"2024-06-01T17:53:02.588365Z"}]}
{"channel":"book","type":"update","data":[{"symbol":"ETH/USD","bids":[{"price":3795.91,"qty":0.00000000},{"price":3795.29,"qty":0.78110913}],"asks":[],"checksum":2276348687,"timestamp":"2024-06-01T17:53:02.661603Z"}]}
{"channel":"book","type":"update","data":[{"symbol":"ETH/USD","bids":[{"price":3796.16,"qty":3.95124688}],"asks":[],"checksum":131259001,"timestamp":"2024-06-01T17:53:02.665437Z"}]}
{"channel":"book","type":"update","data":[{"symbol":"ETH/USD","bids":[{"price":3795.89,"qty":26.34425082}],"asks":[],"checksum":3400773715,"timestamp":"2024-06-01T17:53:02.666272Z"}]}
{"channel":"book","type":"update","data":[{"symbol":"ETH/USD","bids":[{"price":3796.14,"qty":0.00000000},{"price":3795.37,"qty":26.34783230}],"asks":[],"checksum":305521636,"timestamp":"2024-06-01T17:53:02.669232Z"}]}
{"channel":"book","type":"update","data":[{"symbol":"ETH/USD","bids":[{"price":3795.89,"qty":0.00000000},{"price":3795.29,"qty":0.78110913}],"asks":[],"checksum":4131749461,"timestamp":"2024-06-01T17:53:02.671927Z"}]}
{"channel":"book","type":"update","data":[{"symbol":"ETH/USD","bids":[],"asks":[{"price":3796.22,"qty":0.00000000},{"price":3797.35,"qty":3.30000000}],"checksum":1147524394,"timestamp":"2024-06-01T17:53:02.671947Z"}]}
{"channel":"book","type":"update","data":[{"symbol":"ETH/USD","bids":[],"asks":[{"price":3796.19,"qty":26.34224053}],"checksum":2702963777,"timestamp":"2024-06-01T17:53:02.675998Z"}]}
{"channel":"book","type":"update","data":[{"symbol":"ETH/USD","bids":[],"asks":[{"price":3796.19,"qty":0.00000000},{"price":3797.35,"qty":3.30000000}],"checksum":1147524394,"timestamp":"2024-06-01T17:53:02.720271Z"}]}
{"channel":"book","type":"update","data":[{"symbol":"ETH/USD","bids":[{"price":3795.88,"qty":26.34432875}],"asks":[],"checksum":577432059,"timestamp":"2024-06-01T17:53:02.724525Z"}]}
{"channel":"book","type":"update","data":[{"symbol":"ETH/USD","bids":[],"asks":[{"price":3796.21,"qty":26.34207226}],"checksum":2673638187,"timestamp":"2024-06-01T17:53:02.728970Z"}]}
{"channel":"book","type":"update","data":[{"symbol":"ETH/USD","bids":[{"price":3795.88,"qty":0.00000000},{"price":3795.29,"qty":0.78110913}],"asks":[],"checksum":2584858480,"timestamp":"2024-06-01T17:53:02.778118Z"}]}
{"channel":"book","type":"update","data":[{"symbol":"ETH/USD","bids":[],"asks":[{"price":3796.21,"qty":0.00000000},{"price":3797.35,"qty":3.30000000}],"checksum":1147524394,"timestamp":"2024-06-01T17:53:02.778188Z"}]}
{"channel":"book","type":"update","data":[{"symbol":"ETH/USD","bids":[],"asks":[{"price":3796.23,"qty":26.34193000}],"checksum":3832709944,"timestamp":"2024-06-01T17:53:02.783117Z"}]}
{"channel":"book","type":"update","data":[{"symbol":"ETH/USD","bids":[{"price":3795.91,"qty":26.34413379}],"asks":[],"checksum":877469146,"timestamp":"2024-06-01T17:53:02.783220Z"}]}
