{"channel":"book","type":"snapshot","data":[{"symbol":"ETH/EUR","bids":[{"price":3500.77,"qty":80.61060961},{"price":3500.59,"qty":0.02847448},{"price":3500.58,"qty":26.33829935},{"price":3500.43,"qty":15.89358967},{"price":3500.27,"qty":0.26346782},{"price":3500.19,"qty":0.26346782},{"price":3500.18,"qty":1.35385073},{"price":3500.17,"qty":2.00000000},{"price":3500.16,"qty":0.84644082},{"price":3500.03,"qty":4.00000000}],"asks":[{"price":3500.78,"qty":0.10000000},{"price":3501.09,"qty":0.00220000},{"price":3501.29,"qty":26.33298632},{"price":3501.35,"qty":26.33255797},{"price":3501.47,"qty":0.72912968},{"price":3501.48,"qty":0.08779300},{"price":3501.55,"qty":1.60220000},{"price":3501.57,"qty":26.33089945},{"price":3501.72,"qty":0.63767388},{"price":3501.86,"qty":0.00220000}],"checksum":3141708876}]}
{"channel":"book","type":"update","data":[{"symbol":"ETH/EUR","bids":[],"asks":[{"price":3501.29,"qty":0.00000000},{"price":3501.89,"qty":0.00775094}],"checksum":1135030596,"timestamp":"2024-06-01T17:51:43.385983Z"}]}
{"channel":"book","type":"update","data":[{"symbol":"ETH/EUR","bids":[],"asks":[{"price":3501.31,"qty":26.33283629}],"checksum":3775714454,"timestamp":"2024-06-01T17:51:43.389348Z"}]}
{"channel":"book","type":"update","data":[{"symbol":"ETH/EUR","bids":[],"asks":[{"price":3501.56,"qty":0.00775613}],"checksum":2474005976,"timestamp":"2024-06-01T17:51:43.444277Z"}]}
{"channel":"book","type":"update","data":[{"symbol":"ETH/EUR","bids":[],"asks":[{"price":3501.31,"qty":0.00000000},{"price":3501.86,"qty":0.00220000}],"checksum":1452879476,"timestamp":"2024-06-01T17:51:43.479921Z"}]}
{"channel":"book","type":"update","data":[{"symbol":"ETH/EUR","bids":[],"asks":[{"price":3501.30,"qty":26.33294684}],"checksum":3461519526,"timestamp":"2024-06-01T17:51:43.483685Z"}]}
{"channel":"book","type":"update","data":[{"symbol":"ETH/EUR","bids":[],"asks":[{"price":3501.56,"qty":0.00000000},{"price":3501.86,"qty":0.00220000},{"price":3501.85,"qty":0.00775613}],"checksum":4086022250,"timestamp":"2024-06-01T17:51:43.510204Z"}]}
{"channel":"book","type":"update","data":[{"symbol":"ETH/EUR","bids":[],"asks":[{"price":3501.85,"qty":0.00000000},{"price":3501.86,"qty":0.00220000}],"checksum":3156744680,"timestamp":"2024-06-01T17:51:43.576396Z"}]}
{"channel":"book","type":"update","data":[{"symbol":"ETH/EUR","bids":[],"asks":[{"price":3501.30,"qty":0.00000000},{"price":3501.89,"qty":0.00775613}],"checksum":1872105987,"timestamp":"2024-06-01T17:51:43.580993Z"}]}
{"channel":"book","type":"update","data":[{"symbol":"ETH/EUR","bids":[],"asks":[{"price":3501.29,"qty":26.33300957}],"checksum":4112403493,"timestamp":"2024-06-01T17:51:43.584486Z"}]}
{"channel":"book","type":"update","data":[{"symbol":"ETH/EUR","bids":[],"asks":[{"price":3501.29,"qty":0.00000000},{"price":3501.89,"qty":0.00775613}],"checksum":1872105987,"timestamp":"2024-06-01T17:51:43.692314Z"}]}
{"channel":"book","type":"update","data":[{"symbol":"ETH/EUR","bids":[],"asks":[{"price":3501.35,"qty":0.00000000},{"price":3501.90,"qty":26.32844497}],"checksum":3077201631,"timestamp":"2024-06-01T17:51:43.694280Z"}]}
{"channel":"book","type":"update","data":[{"symbol":"ETH/EUR","bids":[],"asks":[{"price":3501.46,"qty":26.33171975}],"checksum":2965396413,"timestamp":"2024-06-01T17:51:43.701599Z"}]}
{"channel":"book","type":"update","data":[{"symbol":"ETH/EUR","bids":[],"asks":[{"price":3501.71,"qty":26.32982184}],"checksum":1601957782,"timestamp":"2024-06-01T17:51:43.701627Z"}]}
{"channel":"book","type":"update","data":[{"symbol":"ETH/EUR","bids":[],"asks":[{"price":3501.57,"qty":0.00000000},{"price":3501.89,"qty":0.00775613}],"checksum":2295089114,"timestamp":"2024-06-01T17:51:43.716325Z"}]}
{"channel":"book","type":"update","data":[{"symbol":"ETH/EUR","bids":[],"asks":[{"price":3501.46,"qty":0.00000000},{"price":3501.90,"qty":26.32844497}],"checksum":97170153,"timestamp":"2024-06-01T17:51:43.716490Z"}]}
{"channel":"book","type":"update","data":[{"symbol":"ETH/EUR","bids":[],"asks":[{"price":3501.57,"qty":26.33089777}],"checksum":2228354133,"timestamp":"2024-06-01T17:51:43.736157Z"}]}
{"channel":"book","type":"update","data":[{"symbol":"ETH/EUR","bids":[],"asks":[{"price":3501.57,"qty":0.00000000},{"price":3501.90,"qty":26.32844497}],"checksum":97170153,"timestamp":"2024-06-01T17:51:43.746379Z"}]}
{"channel":"book","type":"update","data":[{"symbol":"ETH/EUR","bids":[],"asks":[{"price":3501.46,"qty":26.33172052}],"checksum":3109807226,"timestamp":"2024-06-01T17:51:43.751573Z"}]}
{"channel":"book","type":"update","data":[{"symbol":"ETH/EUR","bids":[],"asks":[{"price":3501.46,"qty":0.00000000},{"price":3501.90,"qty":26.32844497}],"checksum":97170153,"timestamp":"2024-06-01T17:51:43.768177Z"}]}
{"channel":"book","type":"update","data":[{"symbol":"ETH/EUR","bids":[],"asks":[{"price":3501.55,"qty":0.00220000}],"checksum":1274177874,"timestamp":"2024-06-01T17:51:43.779862Z"}]}
{"channel":"book","type":"update","data":[{"symbol":"ETH/EUR","bids":[],"asks":[{"price":3501.45,"qty":26.33182357}],"checksum":3570169330,"timestamp":"2024-06-01T17:51:43.881042Z"}]}
{"channel":"book","type":"update","data":[{"symbol":"ETH/EUR","bids":[],"asks":[{"price":3501.45,"qty":0.00000000},{"price":3501.90,"qty":26.32844497}],"checksum":1274177874,"timestamp":"2024-06-01T17:51:43.948583Z"}]}
{"channel":"book","type":"update","data":[{"symbol":"ETH/EUR","bids":[],"asks":[{"price":3501.44,"qty":26.33189463}],"checksum":2111326323,"timestamp":"2024-06-01T17:51:43.953019Z"}]}
{"channel":"book","type":"update","data":[{"symbol":"ETH/EUR","bids":[],"asks":[{"price":3501.44,"qty":0.00000000},{"price":3501.90,"qty":26.32844497}],"checksum":1274177874,"timestamp":"2024-06-01T17:51:43.971814Z"}]}
{"channel":"book","type":"update","data":[{"symbol":"ETH/EUR","bids":[],"asks":[{"price":3501.44,"qty":26.33187884}],"checksum":3665855019,"timestamp":"2024-06-01T17:51:44.080571Z"}]}
{"channel":"book","type":"update","data":[{"symbol":"ETH/EUR","bids":[],"asks":[{"price":3501.44,"qty":0.00000000},{"price":3501.90,"qty":26.32844497}],"checksum":1274177874,"timestamp":"2024-06-01T17:51:44.131047Z"}]}
{"channel":"book","type":"update","data":[{"symbol":"ETH/EUR","bids":[],"asks":[{"price":3501.46,"qty":26.33172737}],"checksum":3553873152,"timestamp":"2024-06-01T17:51:44.135240Z"}]}
{"channel":"book","type":"update","data":[{"symbol":"ETH/EUR","bids":[],"asks":[{"price":3501.46,"qty":0.00000000},{"price":3501.90,"qty":26.32844497}],"checksum":1274177874,"timestamp":"2024-06-01T17:51:44.180920Z"}]}
{"channel":"book","type":"update","data":[{"symbol":"ETH/EUR","bids":[],"asks":[{"price":3501.43,"qty":26.33195372}],"checksum":1162243914,"timestamp":"2024-06-01T17:51:44.216567Z"}]}
{"channel":"book","type":"update","data":[{"symbol":"ETH/EUR","bids":[],"asks":[{"price":3501.43,"qty":0.00000000},{"price":3501.90,"qty":26.32844497}],"checksum":1274177874,"timestamp":"2024-06-01T17:51:44.234695Z"}]}
{"channel":"book","type":"update","data":[{"symbol":"ETH/EUR","bids":[],"asks":[{"price":3501.45,"qty":26.33181274}],"checksum":3851123266,"timestamp":"2024-06-01T17:51:44.285215Z"}]}
{"channel":"book","type":"update","data":[{"symbol":"ETH/EUR","bids":[],"asks":[{"price":3501.45,"qty":0.00000000},{"price":3501.90,"qty":26.32844497}],"checksum":1274177874,"timestamp":"2024-06-01T17:51:44.289119Z"}]}
{"channel":"book","type":"update","data":[{"symbol":"ETH/EUR","bids":[],"asks":[{"price":3501.89,"qty":0.00000000},{"price":3502.06,"qty":1.09100000},{"price":3501.46,"qty":0.00776138}],"checksum":630333091,"timestamp":"2024-06-01T17:51:44.373469Z"}]}
{"channel":"book","type":"update","data":[{"symbol":"ETH/EUR","bids":[],"asks":[{"price":3501.42,"qty":26.33202857}],"checksum":3099999433,"timestamp":"2024-06-01T17:51:44.446051Z"}]}
{"channel":"book","type":"update","data":[{"symbol":"ETH/EUR","bids":[],"asks":[{"price":3501.42,"qty":0.00000000},{"price":3501.90,"qty":26.32844497}],"checksum":630333091,"timestamp":"2024-06-01T17:51:44.480161Z"}]}
{"channel":"book","type":"update","data":[{"symbol":"ETH/EUR","bids":[],"asks":[{"price":3501.46,"qty":0.00000000},{"price":3502.06,"qty":1.09100000},{"price":3501.70,"qty":0.00776136}],"checksum":264560827,"timestamp":"2024-06-01T17:51:44.504758Z"}]}
{"channel":"book","type":"update","data":[{"symbol":"ETH/EUR","bids":[],"asks":[{"price":3501.38,"qty":26.33229535}],"checksum":2988818313,"timestamp":"2024-06-01T17:51:44.743047Z"}]}
{"channel":"book","type":"update","data":[{"symbol":"ETH/EUR","bids":[],"asks":[{"price":3501.38,"qty":0.00000000},{"price":3501.90,"qty":26.32844497}],"checksum":264560827,"timestamp":"2024-06-01T17:51:44.771770Z"}]}
{"channel":"book","type":"update","data":[{"symbol":"ETH/EUR","bids":[],"asks":[{"price":3501.58,"qty":2.00000000}],"checksum":1499788635,"timestamp":"2024-06-01T17:51:44.972031Z"}]}
{"channel":"book","type":"update","data":[{"symbol":"ETH/EUR","bids":[],"asks":[{"price":3501.39,"qty":26.33224271}],"checksum":2494715973,"timestamp":"2024-06-01T17:51:44.991763Z"}]}
{"channel":"book","type":"update","data":[{"symbol":"ETH/EUR","bids":[],"asks":[{"price":3501.39,"qty":0.00000000},{"price":3501.86,"qty":0.00220000}],"checksum":1499788635,"timestamp":"2024-06-01T17:51:45.134148Z"}]}
{"channel":"book","type":"update","data":[{"symbol":"ETH/EUR","bids":[],"asks":[{"price":3501.38,"qty":26.33234960}],"checksum":2866056340,"timestamp":"2024-06-01T17:51:45.138307Z"}]}
{"channel":"book","type":"update","data":[{"symbol":"ETH/EUR","bids":[],"asks":[{"price":3501.38,"qty":0.00000000},{"price":3501.86,"qty":0.00220000}],"checksum":1499788635,"timestamp":"2024-06-01T17:51:45.218085Z"}]}
{"channel":"book","type":"update","data":[{"symbol":"ETH/EUR","bids":[],"asks":[{"price":3501.40,"qty":26.33217325}],"checksum":962703061,"timestamp":"2024-06-01T17:51:45.222149Z"}]}
{"channel":"book","type":"update","data":[{"symbol":"ETH/EUR","bids":[],"asks":[{"price":3501.40,"qty":0.00000000},{"price":3501.86,"qty":0.00220000}],"checksum":1499788635,"timestamp":"2024-06-01T17:51:45.266586Z"}]}
{"channel":"book","type":"update","data":[{"symbol":"ETH/EUR","bids":[],"asks":[{"price":3501.70,"qty":0.00000000},{"price":3501.90,"qty":26.32844497},{"price":3501.57,"qty":0.00776135}],"checksum":3667164562,"timestamp":"2024-06-01T17:51:45.323258Z"}]}
{"channel":"book","type":"update","data":[{"symbol":"ETH/EUR","bids":[],"asks":[{"price":3501.42,"qty":26.33198100}],"checksum":1472554329,"timestamp":"2024-06-01T17:51:45.389750Z"}]}
{"channel":"book","type":"update","data":[{"symbol":"ETH/EUR","bids":[],"asks":[{"price":3501.42,"qty":0.00000000},{"price":3501.86,"qty":0.00220000}],"checksum":3667164562,"timestamp":"2024-06-01T17:51:45.437295Z"}]}
{"channel":"book","type":"update","data":[{"symbol":"ETH/EUR","bids":[],"asks":[{"price":3501.40,"qty":26.33214144}],"checksum":59655116,"timestamp":"2024-06-01T17:51:45.440803Z"}]}
{"channel":"book","type":"update","data":[{"symbol":"ETH/EUR","bids":[],"asks":[{"price":3501.57,"qty":0.00000000},{"price":3501.86,"qty":0.00220000},{"price":3501.70,"qty":0.00776134}],"checksum":2446710470,"timestamp":"2024-06-01T17:51:45.453790Z"}]}
{"channel":"book","type":"update","data":[{"symbol":"ETH/EUR","bids":[],"asks":[{"price":3501.58,"qty":0.00000000},{"price":3501.86,"qty":0.00220000}],"checksum":2047034771,"timestamp":"2024-06-01T17:51:45.569934Z"}]}
{"channel":"book","type":"update","data":[{"symbol":"ETH/EUR","bids":[],"asks":[{"price":3501.40,"qty":0.00000000},{"price":3501.90,"qty":26.32844497}],"checksum":946375006,"timestamp":"2024-06-01T17:51:45.626759Z"}]}
{"channel":"book","type":"update","data":[{"symbol":"ETH/EUR","bids":[],"asks":[{"price":3501.39,"qty":26.33222829}],"checksum":3935587579,"timestamp":"2024-06-01T17:51:45.630329Z"}]}
{"channel":"book","type":"update","data":[{"symbol":"ETH/EUR","bids":[],"asks":[{"price":3501.39,"qty":0.00000000},{"price":3501.90,"qty":26.32844497}],"checksum":946375006,"timestamp":"2024-06-01T17:51:45.927303Z"}]}
{"channel":"book","type":"update","data":[{"symbol":"ETH/EUR","bids":[],"asks":[{"price":3501.37,"qty":26.33236253}],"checksum":3947678002,"timestamp":"2024-06-01T17:51:45.931661Z"}]}
{"channel":"book","type":"update","data":[{"symbol":"ETH/EUR","bids":[],"asks":[{"price":3501.35,"qty":26.33254414}],"checksum":206619220,"timestamp":"2024-06-01T17:51:46.001323Z"}]}
{"channel":"book","type":"update","data":[{"symbol":"ETH/EUR","bids":[],"asks":[{"price":3501.35,"qty":0.00000000},{"price":3501.86,"qty":0.00220000}],"checksum":3947678002,"timestamp":"2024-06-01T17:51:46.007212Z"}]}
{"channel":"book","type":"update","data":[{"symbol":"ETH/EUR","bids":[],"asks":[{"price":3501.71,"qty":0.00000000},{"price":3501.90,"qty":26.32844497}],"checksum":771461745,"timestamp":"2024-06-01T17:51:46.007259Z"}]}
{"channel":"book","type":"update","data":[{"symbol":"ETH/EUR","bids":[],"asks":[{"price":3501.59,"qty":26.33070671}],"checksum":187528145,"timestamp":"2024-06-01T17:51:46.012436Z"}]}
{"channel":"book","type":"update","data":[{"symbol":"ETH/EUR","bids":[],"asks":[{"price":3501.39,"qty":26.33222829}],"checksum":3966722036,"timestamp":"2024-06-01T17:51:46.060171Z"}]}
{"channel":"book","type":"update","data":[{"symbol":"ETH/EUR","bids":[],"asks":[{"price":3501.37,"qty":0.00000000},{"price":3501.86,"qty":0.00220000}],"checksum":183891480,"timestamp":"2024-06-01T17:51:46.063638Z"}]}
{"channel":"book","type":"update","data":[{"symbol":"ETH/EUR","bids":[],"asks":[{"price":3501.39,"qty":0.00000000},{"price":3501.90,"qty":26.32844497}],"checksum":779673781,"timestamp":"2024-06-01T17:51:46.065777Z"}]}
{"channel":"book","type":"update","data":[{"symbol":"ETH/EUR","bids":[],"asks":[{"price":3501.48,"qty":26.41939255}],"checksum":230289515,"timestamp":"2024-06-01T17:51:46.069595Z"}]}
{"channel":"book","type":"update","data":[{"symbol":"ETH/EUR","bids":[],"asks":[{"price":3501.48,"qty":0.08779300}],"checksum":779673781,"timestamp":"2024-06-01T17:51:46.087076Z"}]}
{"channel":"book","type":"update","data":[{"symbol":"ETH/EUR","bids":[],"asks":[{"price":3501.70,"qty":0.00000000},{"price":3502.06,"qty":1.09100000},{"price":3501.89,"qty":0.00776134}],"checksum":3000479348,"timestamp":"2024-06-01T17:51:46.087691Z"}]}
{"channel":"book","type":"update","data":[{"symbol":"ETH/EUR","bids":[],"asks":[{"price":3501.89,"qty":0.00000000},{"price":3502.06,"qty":1.09100000},{"price":3501.46,"qty":0.00776136}],"checksum":3699180403,"timestamp":"2024-06-01T17:51:46.268266Z"}]}
{"channel":"book","type":"update","data":[{"symbol":"ETH/EUR","bids":[],"asks":[{"price":3501.59,"qty":0.00000000},{"price":3502.06,"qty":1.09100000}],"checksum":3419556230,"timestamp":"2024-06-01T17:51:46.282319Z"}]}
{"channel":"book","type":"update","data":[{"symbol":"ETH/EUR","bids":[],"asks":[{"price":3501.46,"qty":26.33951634}],"checksum":2754186810,"timestamp":"2024-06-01T17:51:46.286086Z"}]}
{"channel":"book","type":"update","data":[{"symbol":"ETH/EUR","bids":[],"asks":[{"price":3501.46,"qty":0.00776136}],"checksum":3419556230,"timestamp":"2024-06-01T17:51:46.562457Z"}]}
{"channel":"book","type":"update","data":[{"symbol":"ETH/EUR","bids":[],"asks":[{"price":3501.72,"qty":26.96740199}],"checksum":3538594363,"timestamp":"2024-06-01T17:51:46.567051Z"}]}
{"channel":"book","type":"update","data":[{"symbol":"ETH/EUR","bids":[],"asks":[{"price":3501.44,"qty":26.33185657}],"checksum":304867191,"timestamp":"2024-06-01T17:51:46.567242Z"}]}
{"channel":"book","type":"update","data":[{"symbol":"ETH/EUR","bids":[],"asks":[{"price":3501.44,"qty":0.00000000},{"price":3502.06,"qty":1.09100000}],"checksum":3538594363,"timestamp":"2024-06-01T17:51:46.650185Z"}]}
{"channel":"book","type":"update","data":[{"symbol":"ETH/EUR","bids":[],"asks":[{"price":3501.46,"qty":26.33947054}],"checksum":3934183321,"timestamp":"2024-06-01T17:51:46.654221Z"}]}
{"channel":"book","type":"update","data":[{"symbol":"ETH/EUR","bids":[],"asks":[{"price":3501.46,"qty":0.00776136}],"checksum":3538594363,"timestamp":"2024-06-01T17:51:46.729520Z"}]}
{"channel":"book","type":"update","data":[{"symbol":"ETH/EUR","bids":[],"asks":[{"price":3501.47,"qty":27.06075569}],"checksum":206443044,"timestamp":"2024-06-01T17:51:46.733372Z"}]}
{"channel":"book","type":"update","data":[{"symbol":"ETH/EUR","bids":[],"asks":[{"price":3501.47,"qty":0.72912968}],"checksum":3538594363,"timestamp":"2024-06-01T17:51:46.756122Z"}]}
{"channel":"book","type":"update","data":[{"symbol":"ETH/EUR","bids":[],"asks":[{"price":3501.47,"qty":0.00000000},{"price":3502.08,"qty":0.00220000}],"checksum":2309356943,"timestamp":"2024-06-01T17:51:46.756231Z"}]}
{"channel":"book","type":"update","data":[{"symbol":"ETH/EUR","bids":[{"price":3500.58,"qty":0.00000000},{"price":3500.00,"qty":0.64484148}],"asks":[],"checksum":885644766,"timestamp":"2024-06-01T17:51:46.759436Z"}]}
{"channel":"book","type":"update","data":[{"symbol":"ETH/EUR","bids":[],"asks":[{"price":3501.90,"qty":0.00000000},{"price":3502.11,"qty":0.84644082}],"checksum":3068136739,"timestamp":"2024-06-01T17:51:46.759479Z"}]}
{"channel":"book","type":"update","data":[{"symbol":"ETH/EUR","bids":[],"asks":[{"price":3502.07,"qty":26.32710256}],"checksum":1874478191,"timestamp":"2024-06-01T17:51:46.764179Z"}]}
{"channel":"book","type":"update","data":[{"symbol":"ETH/EUR","bids":[],"asks":[{"price":3501.60,"qty":26.33069110}],"checksum":1280368010,"timestamp":"2024-06-01T17:51:46.764219Z"}]}
{"channel":"book","type":"update","data":[{"symbol":"ETH/EUR","bids":[],"asks":[{"price":3501.72,"qty":26.32972811}],"checksum":2084405813,"timestamp":"2024-06-01T17:51:46.765898Z"}]}
{"channel":"book","type":"update","data":[{"symbol":"ETH/EUR","bids":[],"asks":[{"price":3501.60,"qty":0.00000000},{"price":3502.08,"qty":0.00220000}],"checksum":2293163018,"timestamp":"2024-06-01T17:51:46.768912Z"}]}
{"channel":"book","type":"update","data":[{"symbol":"ETH/EUR","bids":[{"price":3500.64,"qty":15.80765248}],"asks":[],"checksum":2368849799,"timestamp":"2024-06-01T17:51:46.771958Z"}]}
{"channel":"book","type":"update","data":[{"symbol":"ETH/EUR","bids":[{"price":3500.46,"qty":0.26346782}],"asks":[],"checksum":3881273630,"timestamp":"2024-06-01T17:51:46.777105Z"}]}
{"channel":"book","type":"update","data":[{"symbol":"ETH/EUR","bids":[{"price":3500.27,"qty":0.00000000},{"price":3500.03,"qty":4.00000000}],"asks":[],"checksum":4157794051,"timestamp":"2024-06-01T17:51:46.780698Z"}]}
{"channel":"book","type":"update","data":[{"symbol":"ETH/EUR","bids":[],"asks":[{"price":3501.71,"qty":26.32982933}],"checksum":1705605001,"timestamp":"2024-06-01T17:51:46.789750Z"}]}
{"channel":"book","type":"update","data":[{"symbol":"ETH/EUR","bids":[],"asks":[{"price":3501.71,"qty":0.00000000},{"price":3502.08,"qty":0.00220000}],"checksum":4157794051,"timestamp":"2024-06-01T17:51:46.793055Z"}]}
{"channel":"book","type":"update","data":[{"symbol":"ETH/EUR","bids":[{"price":3500.59,"qty":0.00000000},{"price":3500.00,"qty":0.64484148},{"price":3500.44,"qty":0.02851171}],"asks":[],"checksum":1420126367,"timestamp":"2024-06-01T17:51:46.823274Z"}]}
{"channel":"book","type":"update","data":[{"symbol":"ETH/EUR","bids":[],"asks":[{"price":3501.46,"qty":0.00000000},{"price":3502.11,"qty":0.84644082},{"price":3501.71,"qty":0.00776129}],"checksum":617339324,"timestamp":"2024-06-01T17:51:46.823373Z"}]}
{"channel":"book","type":"update","data":[{"symbol":"ETH/EUR","bids":[{"price":3500.05,"qty":0.72912968}],"asks":[],"checksum":4247560557,"timestamp":"2024-06-01T17:51:46.833382Z"}]}
{"channel":"book","type":"update","data":[{"symbol":"ETH/EUR","bids":[],"asks":[{"price":3501.72,"qty":0.00000000},{"price":3502.11,"qty":0.84644082}],"checksum":488026058,"timestamp":"2024-06-01T17:51:46.872270Z"}]}
{"channel":"book","type":"update","data":[{"symbol":"ETH/EUR","bids":[],"asks":[{"price":3501.88,"qty":26.32853836}],"checksum":4051938583,"timestamp":"2024-06-01T17:51:46.876906Z"}]}
{"channel":"book","type":"update","data":[{"symbol":"ETH/EUR","bids":[],"asks":[{"price":3501.75,"qty":26.32954870}],"checksum":3166290652,"timestamp":"2024-06-01T17:51:46.876921Z"}]}
{"channel":"book","type":"update","data":[{"symbol":"ETH/EUR","bids":[],"asks":[{"price":3501.88,"qty":0.00000000},{"price":3502.08,"qty":0.00220000}],"checksum":1688538883,"timestamp":"2024-06-01T17:51:46.902624Z"}]}
{"channel":"book","type":"update","data":[{"symbol":"ETH/EUR","bids":[],"asks":[{"price":3501.71,"qty":0.00000000},{"price":3502.11,"qty":0.84644082},{"price":3501.74,"qty":0.00776129}],"checksum":2208618826,"timestamp":"2024-06-01T17:51:46.939289Z"}]}
{"channel":"book","type":"update","data":[{"symbol":"ETH/EUR","bids":[],"asks":[{"price":3501.77,"qty":26.32936365}],"checksum":1489303204,"timestamp":"2024-06-01T17:51:47.016941Z"}]}
{"channel":"book","type":"update","data":[{"symbol":"ETH/EUR","bids":[{"price":3500.47,"qty":0.60495221}],"asks":[],"checksum":1331332444,"timestamp":"2024-06-01T17:51:47.020394Z"}]}
{"channel":"book","type":"update","data":[{"symbol":"ETH/EUR","bids":[],"asks":[{"price":3501.75,"qty":0.00000000},{"price":3502.08,"qty":0.00220000}],"checksum":2155887045,"timestamp":"2024-06-01T17:51:47.028175Z"}]}
{"channel":"book","type":"update","data":[{"symbol":"ETH/EUR","bids":[],"asks":[{"price":3501.86,"qty":26.33091169}],"checksum":294615020,"timestamp":"2024-06-01T17:51:47.032108Z"}]}
{"channel":"book","type":"update","data":[{"symbol":"ETH/EUR","bids":[],"asks":[{"price":3501.77,"qty":0.00000000},{"price":3502.11,"qty":0.84644082}],"checksum":3499740266,"timestamp":"2024-06-01T17:51:47.056458Z"}]}
{"channel":"book","type":"update","data":[{"symbol":"ETH/EUR","bids":[],"asks":[{"price":3501.48,"qty":0.00220000},{"price":3502.02,"qty":0.08558200}],"checksum":2954625290,"timestamp":"2024-06-01T17:51:47.095491Z"}]}
{"channel":"book","type":"update","data":[{"symbol":"ETH/EUR","bids":[],"asks":[{"price":3501.74,"qty":0.00000000},{"price":3502.11,"qty":0.84644082},{"price":3501.76,"qty":0.00776129}],"checksum":1830105780,"timestamp":"2024-06-01T17:51:47.095550Z"}]}
{"channel":"book","type":"update","data":[{"symbol":"ETH/EUR","bids":[],"asks":[{"price":3501.83,"qty":26.32890090}],"checksum":1026641476,"timestamp":"2024-06-01T17:51:47.115514Z"}]}
{"channel":"book","type":"update","data":[{"symbol":"ETH/EUR","bids":[],"asks":[{"price":3502.06,"qty":0.00000000},{"price":3502.08,"qty":0.00220000}],"checksum":2836493773,"timestamp":"2024-06-01T17:51:47.159912Z"}]}
{"channel":"book","type":"update","data":[{"symbol":"ETH/EUR","bids":[],"asks":[{"price":3501.83,"qty":0.00000000},{"price":3502.11,"qty":0.84644082}],"checksum":483244347,"timestamp":"2024-06-01T17:51:47.194018Z"}]}
{"channel":"book","type":"update","data":[{"symbol":"ETH/EUR","bids":[],"asks":[{"price":3500.78,"qty":0.00000000},{"price":3502.17,"qty":0.72912968}],"checksum":1823758523,"timestamp":"2024-06-01T17:51:47.209615Z"}]}
{"channel":"book","type":"update","data":[{"symbol":"ETH/EUR","bids":[{"price":3500.78,"qty":0.11847376}],"asks":[],"checksum":3700420414,"timestamp":"2024-06-01T17:51:47.214274Z"}]}
{"channel":"book","type":"update","data":[{"symbol":"ETH/EUR","bids":[{"price":3500.77,"qty":54.27373974}],"asks":[],"checksum":386835876,"timestamp":"2024-06-01T17:51:47.214525Z"}]}
{"channel":"book","type":"update","data":[{"symbol":"ETH/EUR","bids":[{"price":3500.77,"qty":27.93686987}],"asks":[],"checksum":1289158210,"timestamp":"2024-06-01T17:51:47.214655Z"}]}
{"channel":"book","type":"update","data":[{"symbol":"ETH/EUR","bids":[{"price":3500.77,"qty":1.60000000}],"asks":[],"checksum":648859385,"timestamp":"2024-06-01T17:51:47.214782Z"}]}
{"channel":"book","type":"update","data":[{"symbol":"ETH/EUR","bids":[],"asks":[{"price":3501.86,"qty":0.00220000}],"checksum":753038732,"timestamp":"2024-06-01T17:51:47.229985Z"}]}
{"channel":"book","type":"update","data":[{"symbol":"ETH/EUR","bids":[],"asks":[{"price":3502.07,"qty":0.00000000},{"price":3502.30,"qty":0.65080166}],"checksum":1479535132,"timestamp":"2024-06-01T17:51:47.236668Z"}]}
{"channel":"book","type":"update","data":[{"symbol":"ETH/EUR","bids":[],"asks":[{"price":3501.92,"qty":26.32825552}],"checksum":1220619544,"timestamp":"2024-06-01T17:51:47.240442Z"}]}
{"channel":"book","type":"update","data":[{"symbol":"ETH/EUR","bids":[],"asks":[{"price":3501.94,"qty":26.32813435}],"checksum":265505491,"timestamp":"2024-06-01T17:51:47.240464Z"}]}
{"channel":"book","type":"update","data":[{"symbol":"ETH/EUR","bids":[],"asks":[{"price":3501.94,"qty":0.00000000},{"price":3502.17,"qty":0.72912968}],"checksum":1220619544,"timestamp":"2024-06-01T17:51:47.245257Z"}]}
{"channel":"book","type":"update","data":[{"symbol":"ETH/EUR","bids":[],"asks":[{"price":3501.92,"qty":0.00000000},{"price":3502.30,"qty":0.65080166}],"checksum":1479535132,"timestamp":"2024-06-01T17:51:47.245266Z"}]}
{"channel":"book","type":"update","data":[{"symbol":"ETH/EUR","bids":[{"price":3500.78,"qty":0.00000000},{"price":3500.16,"qty":0.84644082}],"asks":[],"checksum":3869951788,"timestamp":"2024-06-01T17:51:47.245854Z"}]}
{"channel":"book","type":"update","data":[{"symbol":"ETH/EUR","bids":[],"asks":[{"price":3502.25,"qty":26.32578327}],"checksum":3623032652,"timestamp":"2024-06-01T17:51:47.280696Z"}]}
{"channel":"book","type":"update","data":[{"symbol":"ETH/EUR","bids":[],"asks":[{"price":3501.94,"qty":26.32807695}],"checksum":2126610500,"timestamp":"2024-06-01T17:51:47.295829Z"}]}
{"channel":"book","type":"update","data":[{"symbol":"ETH/EUR","bids":[],"asks":[{"price":3500.83,"qty":0.10000000}],"checksum":190385297,"timestamp":"2024-06-01T17:51:47.305226Z"}]}
{"channel":"book","type":"update","data":[{"symbol":"ETH/EUR","bids":[{"price":3500.82,"qty":26.33649372}],"asks":[],"checksum":948319103,"timestamp":"2024-06-01T17:51:47.337379Z"}]}
{"channel":"book","type":"update","data":[{"symbol":"ETH/EUR","bids":[],"asks":[{"price":3501.94,"qty":0.00000000},{"price":3502.17,"qty":0.72912968}],"checksum":648875563,"timestamp":"2024-06-01T17:51:47.351248Z"}]}
{"channel":"book","type":"update","data":[{"symbol":"ETH/EUR","bids":[],"asks":[{"price":3501.92,"qty":26.32827834}],"checksum":2586236761,"timestamp":"2024-06-01T17:51:47.354996Z"}]}
{"channel":"book","type":"update","data":[{"symbol":"ETH/EUR","bids":[{"price":3500.78,"qty":4.73500000}],"asks":[],"checksum":782776993,"timestamp":"2024-06-01T17:51:47.357103Z"}]}
{"channel":"book","type":"update","data":[{"symbol":"ETH/EUR","bids":[{"price":3500.77,"qty":0.00000000},{"price":3500.17,"qty":2.00000000}],"asks":[],"checksum":1593529153,"timestamp":"2024-06-01T17:51:47.359965Z"}]}
{"channel":"book","type":"update","data":[{"symbol":"ETH/EUR","bids":[{"price":3500.82,"qty":27.93649372}],"asks":[],"checksum":2718679757,"timestamp":"2024-06-01T17:51:47.360189Z"}]}
{"channel":"book","type":"update","data":[{"symbol":"ETH/EUR","bids":[{"price":3500.43,"qty":15.80798567},{"price":3500.79,"qty":0.08559300}],"asks":[],"checksum":2852974397,"timestamp":"2024-06-01T17:51:47.394066Z"}]}
{"channel":"book","type":"update","data":[{"symbol":"ETH/EUR","bids":[{"price":3500.44,"qty":0.00000000},{"price":3500.17,"qty":2.00000000},{"price":3500.79,"qty":0.11410186}],"asks":[],"checksum":1566844157,"timestamp":"2024-06-01T17:51:47.469082Z"}]}
{"channel":"book","type":"update","data":[{"symbol":"ETH/EUR","bids":[],"asks":[{"price":3501.76,"qty":0.00000000},{"price":3502.17,"qty":0.72912968},{"price":3501.91,"qty":0.00776129}],"checksum":1956627848,"timestamp":"2024-06-01T17:51:47.469256Z"}]}
{"channel":"book","type":"update","data":[{"symbol":"ETH/EUR","bids":[],"asks":[{"price":3501.92,"qty":0.00000000},{"price":3502.17,"qty":0.72912968}],"checksum":3374874498,"timestamp":"2024-06-01T17:51:47.733140Z"}]}
{"channel":"book","type":"update","data":[{"symbol":"ETH/EUR","bids":[],"asks":[{"price":3501.94,"qty":26.32809754}],"checksum":146305171,"timestamp":"2024-06-01T17:51:47.737085Z"}]}
{"channel":"book","type":"update","data":[{"symbol":"ETH/EUR","bids":[{"price":3500.78,"qty":31.07179464}],"asks":[],"checksum":3056833354,"timestamp":"2024-06-01T17:51:47.737188Z"}]}
{"channel":"book","type":"update","data":[{"symbol":"ETH/EUR","bids":[],"asks":[{"price":3502.03,"qty":26.32743629}],"checksum":2628329579,"timestamp":"2024-06-01T17:51:47.737263Z"}]}
{"channel":"book","type":"update","data":[{"symbol":"ETH/EUR","bids":[{"price":3500.78,"qty":57.40858928}],"asks":[],"checksum":84550044,"timestamp":"2024-06-01T17:51:47.737373Z"}]}
{"channel":"book","type":"update","data":[{"symbol":"ETH/EUR","bids":[],"asks":[{"price":3501.91,"qty":0.00000000},{"price":3502.11,"qty":0.84644082},{"price":3502.01,"qty":0.00776129}],"checksum":383326013,"timestamp":"2024-06-01T17:51:47.780983Z"}]}
{"channel":"book","type":"update","data":[{"symbol":"ETH/EUR","bids":[],"asks":[{"price":3501.94,"qty":0.00000000},{"price":3502.11,"qty":0.84644082}],"checksum":1311366180,"timestamp":"2024-06-01T17:51:47.864370Z"}]}
{"channel":"book","type":"update","data":[{"symbol":"ETH/EUR","bids":[{"price":3500.26,"qty":39.51104861}],"asks":[],"checksum":1168745502,"timestamp":"2024-06-01T17:51:47.868835Z"}]}
{"channel":"book","type":"update","data":[{"symbol":"ETH/EUR","bids":[],"asks":[{"price":3501.98,"qty":26.32782122}],"checksum":609968135,"timestamp":"2024-06-01T17:51:47.868937Z"}]}
{"channel":"book","type":"update","data":[{"symbol":"ETH/EUR","bids":[],"asks":[{"price":3501.98,"qty":0.00000000},{"price":3502.11,"qty":0.84644082}],"checksum":1168745502,"timestamp":"2024-06-01T17:51:47.898571Z"}]}
{"channel":"book","type":"update","data":[{"symbol":"ETH/EUR","bids":[{"price":3500.78,"qty":83.74538392}],"asks":[],"checksum":487789770,"timestamp":"2024-06-01T17:51:47.902375Z"}]}
{"channel":"book","type":"update","data":[{"symbol":"ETH/EUR","bids":[],"asks":[{"price":3501.95,"qty":26.32802122}],"checksum":2385223537,"timestamp":"2024-06-01T17:51:47.944504Z"}]}
{"channel":"book","type":"update","data":[{"symbol":"ETH/EUR","bids":[],"asks":[{"price":3501.95,"qty":0.00000000},{"price":3502.11,"qty":0.84644082}],"checksum":487789770,"timestamp":"2024-06-01T17:51:47.963135Z"}]}
{"channel":"book","type":"update","data":[{"symbol":"ETH/EUR","bids":[],"asks":[{"price":3502.03,"qty":0.00000000},{"price":3502.17,"qty":0.72912968}],"checksum":1752593267,"timestamp":"2024-06-01T17:51:47.984976Z"}]}
{"channel":"book","type":"update","data":[{"symbol":"ETH/EUR","bids":[],"asks":[{"price":3502.13,"qty":26.32668232}],"checksum":3627118580,"timestamp":"2024-06-01T17:51:47.990993Z"}]}
{"channel":"book","type":"update","data":[{"symbol":"ETH/EUR","bids":[],"asks":[{"price":3501.91,"qty":26.32834660}],"checksum":2628913148,"timestamp":"2024-06-01T17:51:47.995247Z"}]}
{"channel":"book","type":"update","data":[{"symbol":"ETH/EUR","bids":[],"asks":[{"price":3501.91,"qty":0.00000000},{"price":3502.13,"qty":26.32668232}],"checksum":3627118580,"timestamp":"2024-06-01T17:51:48.244756Z"}]}
{"channel":"book","type":"update","data":[{"symbol":"ETH/EUR","bids":[],"asks":[{"price":3501.94,"qty":26.32807817}],"checksum":2317830531,"timestamp":"2024-06-01T17:51:48.248744Z"}]}
{"channel":"book","type":"update","data":[{"symbol":"ETH/EUR","bids":[],"asks":[{"price":3502.03,"qty":26.32746004}],"checksum":2659164977,"timestamp":"2024-06-01T17:51:48.248870Z"}]}
{"channel":"book","type":"update","data":[{"symbol":"ETH/EUR","bids":[],"asks":[{"price":3501.94,"qty":0.00000000},{"price":3502.11,"qty":0.84644082}],"checksum":2212992064,"timestamp":"2024-06-01T17:51:48.410888Z"}]}
{"channel":"book","type":"update","data":[{"symbol":"ETH/EUR","bids":[],"asks":[{"price":3501.93,"qty":26.32819659}],"checksum":4197771098,"timestamp":"2024-06-01T17:51:48.414726Z"}]}
{"channel":"book","type":"update","data":[{"symbol":"ETH/EUR","bids":[],"asks":[{"price":3502.03,"qty":0.00000000},{"price":3502.11,"qty":0.84644082}],"checksum":151643126,"timestamp":"2024-06-01T17:51:48.419619Z"}]}
{"channel":"book","type":"update","data":[{"symbol":"ETH/EUR","bids":[],"asks":[{"price":3502.00,"qty":26.32768057}],"checksum":1047502679,"timestamp":"2024-06-01T17:51:48.452810Z"}]}
{"channel":"book","type":"update","data":[{"symbol":"ETH/EUR","bids":[],"asks":[{"price":3501.93,"qty":0.00000000},{"price":3502.11,"qty":0.84644082}],"checksum":2289297922,"timestamp":"2024-06-01T17:51:48.480722Z"}]}
{"channel":"book","type":"update","data":[{"symbol":"ETH/EUR","bids":[],"asks":[{"price":3501.92,"qty":26.32826975}],"checksum":2382670071,"timestamp":"2024-06-01T17:51:48.485176Z"}]}
{"channel":"book","type":"update","data":[{"symbol":"ETH/EUR","bids":[],"asks":[{"price":3501.92,"qty":0.00000000},{"price":3502.11,"qty":0.84644082}],"checksum":2289297922,"timestamp":"2024-06-01T17:51:48.494334Z"}]}
{"channel":"book","type":"update","data":[{"symbol":"ETH/EUR","bids":[],"asks":[{"price":3502.01,"qty":0.00000000},{"price":3502.13,"qty":26.32668232},{"price":3501.99,"qty":0.00775876}],"checksum":1633626757,"timestamp":"2024-06-01T17:51:48.539249Z"}]}
{"channel":"book","type":"update","data":[{"symbol":"ETH/EUR","bids":[],"asks":[{"price":3502.00,"qty":0.00000000},{"price":3502.13,"qty":26.32668232}],"checksum":2603111537,"timestamp":"2024-06-01T17:51:48.619240Z"}]}
{"channel":"book","type":"update","data":[{"symbol":"ETH/EUR","bids":[],"asks":[{"price":3501.88,"qty":26.32854608}],"checksum":2056977651,"timestamp":"2024-06-01T17:51:48.622978Z"}]}
{"channel":"book","type":"update","data":[{"symbol":"ETH/EUR","bids":[],"asks":[{"price":3501.88,"qty":0.00000000},{"price":3502.13,"qty":26.32668232}],"checksum":2603111537,"timestamp":"2024-06-01T17:51:48.658693Z"}]}
{"channel":"book","type":"update","data":[{"symbol":"ETH/EUR","bids":[],"asks":[{"price":3501.99,"qty":0.00000000},{"price":3502.30,"qty":0.65080166},{"price":3502.01,"qty":0.00775871}],"checksum":3843296947,"timestamp":"2024-06-01T17:51:48.660793Z"}]}
{"channel":"book","type":"update","data":[{"symbol":"ETH/EUR","bids":[{"price":3500.64,"qty":16.07108143}],"asks":[],"checksum":2844351393,"timestamp":"2024-06-01T17:51:48.989187Z"}]}
{"channel":"book","type":"update","data":[{"symbol":"ETH/EUR","bids":[],"asks":[{"price":3501.86,"qty":26.33090070}],"checksum":893423072,"timestamp":"2024-06-01T17:51:48.989718Z"}]}
{"channel":"book","type":"update","data":[{"symbol":"ETH/EUR","bids":[{"price":3500.46,"qty":0.00000000},{"price":3500.17,"qty":2.00000000}],"asks":[],"checksum":4148592079,"timestamp":"2024-06-01T17:51:48.993631Z"}]}
{"channel":"book","type":"update","data":[{"symbol":"ETH/EUR","bids":[],"asks":[{"price":3501.86,"qty":0.00220000}],"checksum":4127311135,"timestamp":"2024-06-01T17:51:49.579384Z"}]}
{"channel":"book","type":"update","data":[{"symbol":"ETH/EUR","bids":[],"asks":[{"price":3502.11,"qty":0.00000000},{"price":3502.30,"qty":0.65080166}],"checksum":288569754,"timestamp":"2024-06-01T17:51:49.584668Z"}]}
{"channel":"book","type":"update","data":[{"symbol":"ETH/EUR","bids":[{"price":3500.43,"qty":16.53711535}],"asks":[],"checksum":1173980559,"timestamp":"2024-06-01T17:51:49.585960Z"}]}
{"channel":"book","type":"update","data":[{"symbol":"ETH/EUR","bids":[{"price":3500.82,"qty":28.78293454}],"asks":[],"checksum":1178730686,"timestamp":"2024-06-01T17:51:49.588215Z"}]}
{"channel":"book","type":"update","data":[{"symbol":"ETH/EUR","bids":[{"price":3500.82,"qty":30.78293454}],"asks":[],"checksum":2331570359,"timestamp":"2024-06-01T17:51:49.589166Z"}]}
{"channel":"book","type":"update","data":[{"symbol":"ETH/EUR","bids":[{"price":3500.82,"qty":37.36799523}],"asks":[],"checksum":2253342199,"timestamp":"2024-06-01T17:51:49.603623Z"}]}
{"channel":"book","type":"update","data":[{"symbol":"ETH/EUR","bids":[],"asks":[{"price":3500.83,"qty":0.00000000},{"price":3502.31,"qty":3.01305282}],"checksum":3735900868,"timestamp":"2024-06-01T17:51:49.611936Z"}]}
{"channel":"book","type":"update","data":[{"symbol":"ETH/EUR","bids":[{"price":3500.82,"qty":53.17373219}],"asks":[],"checksum":1984450861,"timestamp":"2024-06-01T17:51:49.615351Z"}]}
{"channel":"book","type":"update","data":[{"symbol":"ETH/EUR","bids":[{"price":3500.82,"qty":51.57373219}],"asks":[],"checksum":1544132579,"timestamp":"2024-06-01T17:51:49.617073Z"}]}
{"channel":"book","type":"update","data":[{"symbol":"ETH/EUR","bids":[{"price":3500.88,"qty":1.60000000}],"asks":[],"checksum":651408809,"timestamp":"2024-06-01T17:51:49.617338Z"}]}
{"channel":"book","type":"update","data":[{"symbol":"ETH/EUR","bids":[{"price":3500.83,"qty":0.11846312}],"asks":[],"checksum":2788224072,"timestamp":"2024-06-01T17:51:49.619711Z"}]}
{"channel":"book","type":"update","data":[{"symbol":"ETH/EUR","bids":[{"price":3500.83,"qty":0.00000000},{"price":3500.18,"qty":1.35385073}],"asks":[],"checksum":651408809,"timestamp":"2024-06-01T17:51:49.623437Z"}]}
{"channel":"book","type":"update","data":[{"symbol":"ETH/EUR","bids":[{"price":3500.89,"qty":0.11846150}],"asks":[],"checksum":3821395575,"timestamp":"2024-06-01T17:51:49.623650Z"}]}
{"channel":"book","type":"update","data":[{"symbol":"ETH/EUR","bids":[],"asks":[{"price":3502.07,"qty":26.32713836}],"checksum":3311028448,"timestamp":"2024-06-01T17:51:49.631099Z"}]}
{"channel":"book","type":"update","data":[{"symbol":"ETH/EUR","bids":[{"price":3500.60,"qty":0.26342895}],"asks":[],"checksum":3770747629,"timestamp":"2024-06-01T17:51:49.636522Z"}]}
{"channel":"book","type":"update","data":[{"symbol":"ETH/EUR","bids":[{"price":3500.43,"qty":0.72912968}],"asks":[],"checksum":2472346630,"timestamp":"2024-06-01T17:51:49.641035Z"}]}
{"channel":"book","type":"update","data":[{"symbol":"ETH/EUR","bids":[{"price":3500.78,"qty":57.40858928}],"asks":[],"checksum":1896736696,"timestamp":"2024-06-01T17:51:49.641977Z"}]}
{"channel":"book","type":"update","data":[{"symbol":"ETH/EUR","bids":[{"price":3500.78,"qty":31.07179464}],"asks":[],"checksum":3894644655,"timestamp":"2024-06-01T17:51:49.642058Z"}]}
{"channel":"book","type":"update","data":[{"symbol":"ETH/EUR","bids":[{"price":3500.82,"qty":25.23723847}],"asks":[],"checksum":3628547501,"timestamp":"2024-06-01T17:51:49.642155Z"}]}
{"channel":"book","type":"update","data":[{"symbol":"ETH/EUR","bids":[{"price":3500.78,"qty":4.73500000}],"asks":[],"checksum":2081149150,"timestamp":"2024-06-01T17:51:49.642291Z"}]}
{"channel":"book","type":"update","data":[{"symbol":"ETH/EUR","bids":[],"asks":[{"price":3502.07,"qty":0.00000000},{"price":3502.31,"qty":3.01305282}],"checksum":1138222824,"timestamp":"2024-06-01T17:51:49.665798Z"}]}
{"channel":"book","type":"update","data":[{"symbol":"ETH/EUR","bids":[{"price":3500.83,"qty":2.00000000}],"asks":[],"checksum":3585021229,"timestamp":"2024-06-01T17:51:49.673759Z"}]}
{"channel":"book","type":"update","data":[{"symbol":"ETH/EUR","bids":[{"price":3500.70,"qty":1.31732867}],"asks":[],"checksum":1636521385,"timestamp":"2024-06-01T17:51:49.675759Z"}]}
{"channel":"book","type":"update","data":[{"symbol":"ETH/EUR","bids":[{"price":3500.90,"qty":0.72912968}],"asks":[],"checksum":1137453449,"timestamp":"2024-06-01T17:51:49.679415Z"}]}
{"channel":"book","type":"update","data":[{"symbol":"ETH/EUR","bids":[{"price":3500.89,"qty":0.00000000},{"price":3500.47,"qty":0.60495221}],"asks":[],"checksum":1547961443,"timestamp":"2024-06-01T17:51:49.683426Z"}]}
{"channel":"book","type":"update","data":[{"symbol":"ETH/EUR","bids":[{"price":3500.91,"qty":0.11846051}],"asks":[],"checksum":3021843404,"timestamp":"2024-06-01T17:51:49.683767Z"}]}
{"channel":"book","type":"update","data":[{"symbol":"ETH/EUR","bids":[],"asks":[{"price":3502.20,"qty":26.32617674}],"checksum":2250479334,"timestamp":"2024-06-01T17:51:49.690458Z"}]}
{"channel":"book","type":"update","data":[{"symbol":"ETH/EUR","bids":[{"price":3501.08,"qty":26.33453790}],"asks":[],"checksum":2603739722,"timestamp":"2024-06-01T17:51:49.690523Z"}]}
{"channel":"book","type":"update","data":[{"symbol":"ETH/EUR","bids":[{"price":3500.90,"qty":1.57557050}],"asks":[],"checksum":3342911913,"timestamp":"2024-06-01T17:51:49.693796Z"}]}
{"channel":"book","type":"update","data":[{"symbol":"ETH/EUR","bids":[{"price":3500.79,"qty":0.08559300},{"price":3500.83,"qty":2.02850300}],"asks":[],"checksum":2166077686,"timestamp":"2024-06-01T17:51:49.697217Z"}]}
{"channel":"book","type":"update","data":[{"symbol":"ETH/EUR","bids":[{"price":3500.91,"qty":0.00000000},{"price":3500.60,"qty":0.26342895}],"asks":[],"checksum":945043534,"timestamp":"2024-06-01T17:51:49.698769Z"}]}
{"channel":"book","type":"update","data":[{"symbol":"ETH/EUR","bids":[{"price":3500.63,"qty":1.31732867}],"asks":[],"checksum":142633000,"timestamp":"2024-06-01T17:51:49.702665Z"}]}
{"channel":"book","type":"update","data":[{"symbol":"ETH/EUR","bids":[{"price":3500.82,"qty":23.23723847}],"asks":[],"checksum":494965292,"timestamp":"2024-06-01T17:51:49.709084Z"}]}
{"channel":"book","type":"update","data":[{"symbol":"ETH/EUR","bids":[],"asks":[{"price":3502.13,"qty":0.00000000},{"price":3502.31,"qty":3.01305282}],"checksum":2435476623,"timestamp":"2024-06-01T17:51:49.710790Z"}]}
{"channel":"book","type":"update","data":[{"symbol":"ETH/EUR","bids":[],"asks":[{"price":3502.12,"qty":26.32674540}],"checksum":428657193,"timestamp":"2024-06-01T17:51:49.714925Z"}]}
{"channel":"book","type":"update","data":[{"symbol":"ETH/EUR","bids":[{"price":3500.82,"qty":22.39079765}],"asks":[],"checksum":3949270304,"timestamp":"2024-06-01T17:51:49.732407Z"}]}
{"channel":"book","type":"update","data":[{"symbol":"ETH/EUR","bids":[{"price":3501.08,"qty":28.33453790}],"asks":[],"checksum":3525204487,"timestamp":"2024-06-01T17:51:49.736830Z"}]}
{"channel":"book","type":"update","data":[{"symbol":"ETH/EUR","bids":[{"price":3501.08,"qty":29.18097872}],"asks":[],"checksum":2801003654,"timestamp":"2024-06-01T17:51:49.763008Z"}]}
{"channel":"book","type":"update","data":[{"symbol":"ETH/EUR","bids":[{"price":3500.83,"qty":0.02850300}],"asks":[],"checksum":75810754,"timestamp":"2024-06-01T17:51:49.780636Z"}]}
{"channel":"book","type":"update","data":[{"symbol":"ETH/EUR","bids":[],"asks":[{"price":3502.02,"qty":0.00000000},{"price":3502.31,"qty":3.01305282}],"checksum":1590026419,"timestamp":"2024-06-01T17:51:49.784505Z"}]}
{"channel":"book","type":"update","data":[{"symbol":"ETH/EUR","bids":[{"price":3501.03,"qty":1.35352203}],"asks":[],"checksum":3434813781,"timestamp":"2024-06-01T17:51:49.808936Z"}]}
{"channel":"book","type":"update","data":[{"symbol":"ETH/EUR","bids":[{"price":3500.88,"qty":0.00000000},{"price":3500.63,"qty":1.31732867}],"asks":[],"checksum":3588718827,"timestamp":"2024-06-01T17:51:49.812127Z"}]}
{"channel":"book","type":"update","data":[{"symbol":"ETH/EUR","bids":[{"price":3501.08,"qty":30.78097872}],"asks":[],"checksum":1404950476,"timestamp":"2024-06-01T17:51:49.812236Z"}]}
{"channel":"book","type":"update","data":[{"symbol":"ETH/EUR","bids":[{"price":3500.82,"qty":26.39079765}],"asks":[],"checksum":1245873204,"timestamp":"2024-06-01T17:51:49.824561Z"}]}
{"channel":"book","type":"update","data":[{"symbol":"ETH/EUR","bids":[{"price":3500.90,"qty":0.72912968}],"asks":[],"checksum":3035905857,"timestamp":"2024-06-01T17:51:49.828649Z"}]}
{"channel":"book","type":"update","data":[{"symbol":"ETH/EUR","bids":[],"asks":[{"price":3502.01,"qty":0.00000000},{"price":3502.38,"qty":26.32482080},{"price":3502.11,"qty":0.00775861}],"checksum":3621629905,"timestamp":"2024-06-01T17:51:49.850471Z"}]}
{"channel":"book","type":"update","data":[{"symbol":"ETH/EUR","bids":[{"price":3500.78,"qty":0.00000000},{"price":3500.60,"qty":0.26342895}],"asks":[],"checksum":295567552,"timestamp":"2024-06-01T17:51:49.882274Z"}]}
{"channel":"book","type":"update","data":[{"symbol":"ETH/EUR","bids":[{"price":3500.82,"qty":29.04079765}],"asks":[],"checksum":3293955273,"timestamp":"2024-06-01T17:51:49.891387Z"}]}
{"channel":"book","type":"update","data":[{"symbol":"ETH/EUR","bids":[],"asks":[{"price":3502.12,"qty":0.00000000},{"price":3502.38,"qty":26.32482080}],"checksum":2343321762,"timestamp":"2024-06-01T17:51:49.946100Z"}]}
{"channel":"book","type":"update","data":[{"symbol":"ETH/EUR","bids":[],"asks":[{"price":3502.15,"qty":26.32653613}],"checksum":3821741980,"timestamp":"2024-06-01T17:51:49.952346Z"}]}
{"channel":"book","type":"update","data":[{"symbol":"ETH/EUR","bids":[{"price":3501.08,"qty":57.11551662}],"asks":[],"checksum":2198370622,"timestamp":"2024-06-01T17:51:49.952474Z"}]}
{"channel":"book","type":"update","data":[{"symbol":"ETH/EUR","bids":[],"asks":[{"price":3502.31,"qty":0.00000000},{"price":3502.38,"qty":26.32482080}],"checksum":4110077816,"timestamp":"2024-06-01T17:51:49.952534Z"}]}
{"channel":"book","type":"update","data":[{"symbol":"ETH/EUR","bids":[{"price":3501.08,"qty":56.86551662}],"asks":[],"checksum":2137748362,"timestamp":"2024-06-01T17:51:50.053322Z"}]}
{"channel":"book","type":"update","data":[{"symbol":"ETH/EUR","bids":[{"price":3500.67,"qty":6.00000000}],"asks":[],"checksum":2239336645,"timestamp":"2024-06-01T17:51:50.062050Z"}]}
{"channel":"book","type":"update","data":[{"symbol":"ETH/EUR","bids":[],"asks":[{"price":3502.15,"qty":0.00000000},{"price":3502.45,"qty":0.08777600}],"checksum":4139494000,"timestamp":"2024-06-01T17:51:50.082804Z"}]}
{"channel":"book","type":"update","data":[{"symbol":"ETH/EUR","bids":[],"asks":[{"price":3502.14,"qty":26.32661508}],"checksum":4037467929,"timestamp":"2024-06-01T17:51:50.087462Z"}]}
{"channel":"book","type":"update","data":[{"symbol":"ETH/EUR","bids":[{"price":3501.08,"qty":83.20005452}],"asks":[],"checksum":2320781166,"timestamp":"2024-06-01T17:51:50.087504Z"}]}
{"channel":"book","type":"update","data":[{"symbol":"ETH/EUR","bids":[{"price":3500.82,"qty":26.39079765}],"asks":[],"checksum":4082973710,"timestamp":"2024-06-01T17:51:50.117874Z"}]}
{"channel":"book","type":"update","data":[{"symbol":"ETH/EUR","bids":[],"asks":[{"price":3502.14,"qty":0.00000000},{"price":3502.45,"qty":0.08777600}],"checksum":4114631015,"timestamp":"2024-06-01T17:51:50.167574Z"}]}
{"channel":"book","type":"update","data":[{"symbol":"ETH/EUR","bids":[],"asks":[{"price":3502.16,"qty":26.32645102}],"checksum":3651708790,"timestamp":"2024-06-01T17:51:50.171416Z"}]}
{"channel":"book","type":"update","data":[{"symbol":"ETH/EUR","bids":[],"asks":[{"price":3502.16,"qty":0.00000000},{"price":3502.45,"qty":0.08777600}],"checksum":4114631015,"timestamp":"2024-06-01T17:51:50.176831Z"}]}
{"channel":"book","type":"update","data":[{"symbol":"ETH/EUR","bids":[{"price":3501.08,"qty":109.53459242}],"asks":[],"checksum":1358133974,"timestamp":"2024-06-01T17:51:50.240159Z"}]}
{"channel":"book","type":"update","data":[{"symbol":"ETH/EUR","bids":[],"asks":[{"price":3502.14,"qty":26.32661345}],"checksum":3589815403,"timestamp":"2024-06-01T17:51:50.240286Z"}]}
{"channel":"book","type":"update","data":[{"symbol":"ETH/EUR","bids":[],"asks":[{"price":3502.14,"qty":0.00000000},{"price":3502.45,"qty":0.08777600}],"checksum":1358133974,"timestamp":"2024-06-01T17:51:50.270645Z"}]}
{"channel":"book","type":"update","data":[{"symbol":"ETH/EUR","bids":[],"asks":[{"price":3502.12,"qty":26.32676082}],"checksum":2074446258,"timestamp":"2024-06-01T17:51:50.292446Z"}]}
{"channel":"book","type":"update","data":[{"symbol":"ETH/EUR","bids":[],"asks":[{"price":3502.12,"qty":0.00000000},{"price":3502.45,"qty":0.08777600}],"checksum":1358133974,"timestamp":"2024-06-01T17:51:50.621538Z"}]}
{"channel":"book","type":"update","data":[{"symbol":"ETH/EUR","bids":[],"asks":[{"price":3502.20,"qty":0.00000000},{"price":3502.46,"qty":1.09100000}],"checksum":3466741507,"timestamp":"2024-06-01T17:51:50.621643Z"}]}
{"channel":"book","type":"update","data":[{"symbol":"ETH/EUR","bids":[],"asks":[{"price":3502.09,"qty":26.32701629}],"checksum":635785366,"timestamp":"2024-06-01T17:51:50.625833Z"}]}
{"channel":"book","type":"update","data":[{"symbol":"ETH/EUR","bids":[],"asks":[{"price":3502.09,"qty":0.00000000},{"price":3502.46,"qty":1.09100000}],"checksum":3466741507,"timestamp":"2024-06-01T17:51:50.693940Z"}]}
{"channel":"book","type":"update","data":[{"symbol":"ETH/EUR","bids":[],"asks":[{"price":3502.07,"qty":26.32711942}],"checksum":541952,"timestamp":"2024-06-01T17:51:50.698290Z"}]}
{"channel":"book","type":"update","data":[{"symbol":"ETH/EUR","bids":[],"asks":[{"price":3502.11,"qty":0.00000000},{"price":3502.46,"qty":1.09100000},{"price":3502.06,"qty":0.00775902}],"checksum":1489210078,"timestamp":"2024-06-01T17:51:50.742961Z"}]}
{"channel":"book","type":"update","data":[{"symbol":"ETH/EUR","bids":[],"asks":[{"price":3502.07,"qty":0.00000000},{"price":3502.46,"qty":1.09100000}],"checksum":3896141293,"timestamp":"2024-06-01T17:51:50.851527Z"}]}
{"channel":"book","type":"update","data":[{"symbol":"ETH/EUR","bids":[],"asks":[{"price":3502.09,"qty":26.32697074}],"checksum":283787678,"timestamp":"2024-06-01T17:51:50.855504Z"}]}
{"channel":"book","type":"update","data":[{"symbol":"ETH/EUR","bids":[],"asks":[{"price":3502.06,"qty":0.00000000},{"price":3502.46,"qty":1.09100000},{"price":3502.29,"qty":0.00775902}],"checksum":4025317723,"timestamp":"2024-06-01T17:51:50.900980Z"}]}
{"channel":"book","type":"update","data":[{"symbol":"ETH/EUR","bids":[],"asks":[{"price":3502.09,"qty":0.00000000},{"price":3502.46,"qty":1.09100000}],"checksum":3370536846,"timestamp":"2024-06-01T17:51:51.213620Z"}]}
{"channel":"book","type":"update","data":[{"symbol":"ETH/EUR","bids":[],"asks":[{"price":3502.11,"qty":26.32685840}],"checksum":2284406602,"timestamp":"2024-06-01T17:51:51.218445Z"}]}
{"channel":"book","type":"update","data":[{"symbol":"ETH/EUR","bids":[],"asks":[{"price":3502.11,"qty":0.00000000},{"price":3502.46,"qty":1.09100000}],"checksum":3370536846,"timestamp":"2024-06-01T17:51:51.284276Z"}]}
{"channel":"book","type":"update","data":[{"symbol":"ETH/EUR","bids":[],"asks":[{"price":3502.13,"qty":26.32668917}],"checksum":179224489,"timestamp":"2024-06-01T17:51:51.288422Z"}]}
{"channel":"book","type":"update","data":[{"symbol":"ETH/EUR","bids":[{"price":3501.04,"qty":2.47000000}],"asks":[],"checksum":1678577808,"timestamp":"2024-06-01T17:51:51.303801Z"}]}
{"channel":"book","type":"update","data":[{"symbol":"ETH/EUR","bids":[],"asks":[{"price":3502.13,"qty":0.00000000},{"price":3502.46,"qty":1.09100000}],"checksum":2789597367,"timestamp":"2024-06-01T17:51:51.560386Z"}]}
{"channel":"book","type":"update","data":[{"symbol":"ETH/EUR","bids":[],"asks":[{"price":3502.30,"qty":0.00000000},{"price":3502.52,"qty":0.72912968}],"checksum":216264908,"timestamp":"2024-06-01T17:51:51.564131Z"}]}
{"channel":"book","type":"update","data":[{"symbol":"ETH/EUR","bids":[],"asks":[{"price":3502.11,"qty":26.32681643}],"checksum":4110627909,"timestamp":"2024-06-01T17:51:51.564384Z"}]}
{"channel":"book","type":"update","data":[{"symbol":"ETH/EUR","bids":[],"asks":[{"price":3502.11,"qty":0.00000000},{"price":3502.57,"qty":0.00220000}],"checksum":857737987,"timestamp":"2024-06-01T17:51:51.574984Z"}]}
{"channel":"book","type":"update","data":[{"symbol":"ETH/EUR","bids":[{"price":3501.05,"qty":15.80573696}],"asks":[],"checksum":199696431,"timestamp":"2024-06-01T17:51:51.575859Z"}]}
{"channel":"book","type":"update","data":[{"symbol":"ETH/EUR","bids":[{"price":3500.87,"qty":0.26342895}],"asks":[],"checksum":2314861586,"timestamp":"2024-06-01T17:51:51.576450Z"}]}
{"channel":"book","type":"update","data":[{"symbol":"ETH/EUR","bids":[{"price":3501.08,"qty":110.26372210}],"asks":[],"checksum":1286021982,"timestamp":"2024-06-01T17:51:51.582966Z"}]}
{"channel":"book","type":"update","data":[{"symbol":"ETH/EUR","bids":[{"price":3500.90,"qty":0.00000000},{"price":3500.67,"qty":6.00000000}],"asks":[],"checksum":273412934,"timestamp":"2024-06-01T17:51:51.592137Z"}]}
{"channel":"book","type":"update","data":[{"symbol":"ETH/EUR","bids":[],"asks":[{"price":3502.29,"qty":0.00000000},{"price":3502.79,"qty":29.33477867},{"price":3502.37,"qty":0.00775904}],"checksum":3320901032,"timestamp":"2024-06-01T17:51:51.621286Z"}]}
{"channel":"book","type":"update","data":[{"symbol":"ETH/EUR","bids":[],"asks":[{"price":3502.20,"qty":26.32614144}],"checksum":945133424,"timestamp":"2024-06-01T17:51:51.632811Z"}]}
{"channel":"book","type":"update","data":[{"symbol":"ETH/EUR","bids":[{"price":3501.08,"qty":114.41372210}],"asks":[],"checksum":3711750366,"timestamp":"2024-06-01T17:51:51.670005Z"}]}
{"channel":"book","type":"update","data":[{"symbol":"ETH/EUR","bids":[],"asks":[{"price":3502.20,"qty":0.00000000},{"price":3502.57,"qty":0.00220000}],"checksum":546941446,"timestamp":"2024-06-01T17:51:51.681137Z"}]}
{"channel":"book","type":"update","data":[{"symbol":"ETH/EUR","bids":[],"asks":[{"price":3502.22,"qty":26.32597565}],"checksum":3384543875,"timestamp":"2024-06-01T17:51:51.686765Z"}]}
{"channel":"book","type":"update","data":[{"symbol":"ETH/EUR","bids":[{"price":3501.04,"qty":0.00000000},{"price":3500.63,"qty":1.31732867}],"asks":[],"checksum":3318166673,"timestamp":"2024-06-01T17:51:51.763777Z"}]}
{"channel":"book","type":"update","data":[{"symbol":"ETH/EUR","bids":[],"asks":[{"price":3502.37,"qty":0.00000000},{"price":3502.57,"qty":0.00220000},{"price":3502.21,"qty":0.00775904}],"checksum":240431709,"timestamp":"2024-06-01T17:51:51.802322Z"}]}
{"channel":"book","type":"update","data":[{"symbol":"ETH/EUR","bids":[{"price":3500.83,"qty":0.00000000},{"price":3500.60,"qty":0.26342895},{"price":3501.06,"qty":0.02849944}],"asks":[],"checksum":1636456665,"timestamp":"2024-06-01T17:51:51.802355Z"}]}
{"channel":"book","type":"update","data":[{"symbol":"ETH/EUR","bids":[],"asks":[{"price":3502.22,"qty":0.00000000},{"price":3502.57,"qty":0.00220000}],"checksum":627868313,"timestamp":"2024-06-01T17:51:51.911944Z"}]}
{"channel":"book","type":"update","data":[{"symbol":"ETH/EUR","bids":[],"asks":[{"price":3502.20,"qty":26.32611844}],"checksum":3188853268,"timestamp":"2024-06-01T17:51:51.916960Z"}]}
{"channel":"book","type":"update","data":[{"symbol":"ETH/EUR","bids":[],"asks":[{"price":3502.20,"qty":0.00000000},{"price":3502.57,"qty":0.00220000}],"checksum":627868313,"timestamp":"2024-06-01T17:51:52.004450Z"}]}
{"channel":"book","type":"update","data":[{"symbol":"ETH/EUR","bids":[],"asks":[{"price":3502.19,"qty":26.32622788}],"checksum":10860565,"timestamp":"2024-06-01T17:51:52.008125Z"}]}
{"channel":"book","type":"update","data":[{"symbol":"ETH/EUR","bids":[],"asks":[{"price":3502.19,"qty":0.00000000},{"price":3502.57,"qty":0.00220000}],"checksum":627868313,"timestamp":"2024-06-01T17:51:52.080773Z"}]}
{"channel":"book","type":"update","data":[{"symbol":"ETH/EUR","bids":[],"asks":[{"price":3502.16,"qty":26.32645156}],"checksum":1073302995,"timestamp":"2024-06-01T17:51:52.085583Z"}]}
{"channel":"book","type":"update","data":[{"symbol":"ETH/EUR","bids":[],"asks":[{"price":3502.16,"qty":0.00000000},{"price":3502.57,"qty":0.00220000}],"checksum":627868313,"timestamp":"2024-06-01T17:51:52.201126Z"}]}
{"channel":"book","type":"update","data":[{"symbol":"ETH/EUR","bids":[],"asks":[{"price":3502.18,"qty":26.32627525}],"checksum":984080519,"timestamp":"2024-06-01T17:51:52.206517Z"}]}
{"channel":"book","type":"update","data":[{"symbol":"ETH/EUR","bids":[],"asks":[{"price":3502.18,"qty":0.00000000},{"price":3502.57,"qty":0.00220000}],"checksum":627868313,"timestamp":"2024-06-01T17:51:52.330164Z"}]}
{"channel":"book","type":"update","data":[{"symbol":"ETH/EUR","bids":[],"asks":[{"price":3502.16,"qty":26.32643577}],"checksum":2645746837,"timestamp":"2024-06-01T17:51:52.333655Z"}]}
{"channel":"book","type":"update","data":[{"symbol":"ETH/EUR","bids":[{"price":3501.08,"qty":118.41372210}],"asks":[],"checksum":1074506595,"timestamp":"2024-06-01T17:51:52.398570Z"}]}
{"channel":"book","type":"update","data":[{"symbol":"ETH/EUR","bids":[],"asks":[{"price":3502.16,"qty":0.00000000},{"price":3502.57,"qty":0.00220000}],"checksum":4174761327,"timestamp":"2024-06-01T17:51:52.573571Z"}]}
{"channel":"book","type":"update","data":[{"symbol":"ETH/EUR","bids":[],"asks":[{"price":3502.17,"qty":26.32641158}],"checksum":2764096954,"timestamp":"2024-06-01T17:51:52.578336Z"}]}
{"channel":"book","type":"update","data":[{"symbol":"ETH/EUR","bids":[],"asks":[{"price":3502.17,"qty":0.00000000},{"price":3502.57,"qty":0.00220000}],"checksum":4174761327,"timestamp":"2024-06-01T17:51:52.581799Z"}]}
{"channel":"book","type":"update","data":[{"symbol":"ETH/EUR","bids":[{"price":3500.82,"qty":22.39079765}],"asks":[],"checksum":2688636620,"timestamp":"2024-06-01T17:51:52.587500Z"}]}
{"channel":"book","type":"update","data":[{"symbol":"ETH/EUR","bids":[],"asks":[{"price":3502.18,"qty":26.32631947}],"checksum":2842009874,"timestamp":"2024-06-01T17:51:52.736667Z"}]}
{"channel":"book","type":"update","data":[{"symbol":"ETH/EUR","bids":[],"asks":[{"price":3502.18,"qty":0.00000000},{"price":3502.57,"qty":0.00220000}],"checksum":2688636620,"timestamp":"2024-06-01T17:51:52.765554Z"}]}
{"channel":"book","type":"update","data":[{"symbol":"ETH/EUR","bids":[],"asks":[{"price":3502.21,"qty":0.00000000},{"price":3502.78,"qty":0.64279700},{"price":3502.37,"qty":0.00775595}],"checksum":3040716497,"timestamp":"2024-06-01T17:51:52.926385Z"}]}
{"channel":"book","type":"update","data":[{"symbol":"ETH/EUR","bids":[],"asks":[{"price":3502.37,"qty":6.77658446}],"checksum":2668139363,"timestamp":"2024-06-01T17:51:53.041875Z"}]}
{"channel":"book","type":"update","data":[{"symbol":"ETH/EUR","bids":[],"asks":[{"price":3502.16,"qty":26.32644315}],"checksum":1981156389,"timestamp":"2024-06-01T17:51:53.207287Z"}]}
{"channel":"book","type":"update","data":[{"symbol":"ETH/EUR","bids":[{"price":3501.08,"qty":117.56728128}],"asks":[],"checksum":2405033350,"timestamp":"2024-06-01T17:51:53.232223Z"}]}
{"channel":"book","type":"update","data":[{"symbol":"ETH/EUR","bids":[{"price":3500.65,"qty":0.84644082}],"asks":[],"checksum":1501050692,"timestamp":"2024-06-01T17:51:53.232371Z"}]}
{"channel":"book","type":"update","data":[{"symbol":"ETH/EUR","bids":[],"asks":[{"price":3502.18,"qty":26.32631677}],"checksum":1041682569,"timestamp":"2024-06-01T17:51:53.344446Z"}]}
{"channel":"book","type":"update","data":[{"symbol":"ETH/EUR","bids":[{"price":3501.08,"qty":133.37301824}],"asks":[],"checksum":1472976016,"timestamp":"2024-06-01T17:51:53.584079Z"}]}
{"channel":"book","type":"update","data":[{"symbol":"ETH/EUR","bids":[{"price":3500.82,"qty":6.58506069}],"asks":[],"checksum":2490800848,"timestamp":"2024-06-01T17:51:53.588208Z"}]}
{"channel":"book","type":"update","data":[{"symbol":"ETH/EUR","bids":[{"price":3500.96,"qty":0.26339773}],"asks":[],"checksum":4271155748,"timestamp":"2024-06-01T17:51:53.588675Z"}]}
{"channel":"book","type":"update","data":[{"symbol":"ETH/EUR","bids":[{"price":3501.06,"qty":0.00000000},{"price":3500.65,"qty":0.84644082},{"price":3500.83,"qty":0.02850206}],"asks":[],"checksum":1330707640,"timestamp":"2024-06-01T17:51:53.626963Z"}]}
{"channel":"book","type":"update","data":[{"symbol":"ETH/EUR","bids":[],"asks":[{"price":3502.16,"qty":0.00000000},{"price":3502.46,"qty":1.09100000}],"checksum":322193311,"timestamp":"2024-06-01T17:51:53.707127Z"}]}
{"channel":"book","type":"update","data":[{"symbol":"ETH/EUR","bids":[],"asks":[{"price":3502.15,"qty":26.32652693}],"checksum":1395332364,"timestamp":"2024-06-01T17:51:53.711168Z"}]}
{"channel":"book","type":"update","data":[{"symbol":"ETH/EUR","bids":[],"asks":[{"price":3502.15,"qty":0.00000000},{"price":3502.46,"qty":1.09100000}],"checksum":322193311,"timestamp":"2024-06-01T17:51:53.866513Z"}]}
{"channel":"book","type":"update","data":[{"symbol":"ETH/EUR","bids":[],"asks":[{"price":3502.13,"qty":26.32664470}],"checksum":986181547,"timestamp":"2024-06-01T17:51:53.870692Z"}]}
{"channel":"book","type":"update","data":[{"symbol":"ETH/EUR","bids":[],"asks":[{"price":3502.13,"qty":0.00000000},{"price":3502.46,"qty":1.09100000}],"checksum":322193311,"timestamp":"2024-06-01T17:51:53.875056Z"}]}
{"channel":"book","type":"update","data":[{"symbol":"ETH/EUR","bids":[],"asks":[{"price":3502.18,"qty":0.00000000},{"price":3502.57,"qty":0.00220000}],"checksum":3239070380,"timestamp":"2024-06-01T17:51:53.875064Z"}]}
{"channel":"book","type":"update","data":[{"symbol":"ETH/EUR","bids":[{"price":3500.83,"qty":0.00000000},{"price":3500.65,"qty":0.84644082},{"price":3500.68,"qty":0.02850328}],"asks":[],"checksum":2975439409,"timestamp":"2024-06-01T17:51:53.998218Z"}]}
{"channel":"book","type":"update","data":[{"symbol":"ETH/EUR","bids":[],"asks":[{"price":3502.11,"qty":26.32686367}],"checksum":1242951280,"timestamp":"2024-06-01T17:51:54.185418Z"}]}
{"channel":"book","type":"update","data":[{"symbol":"ETH/EUR","bids":[],"asks":[{"price":3502.11,"qty":0.00000000},{"price":3502.57,"qty":0.00220000}],"checksum":2975439409,"timestamp":"2024-06-01T17:51:54.340543Z"}]}
{"channel":"book","type":"update","data":[{"symbol":"ETH/EUR","bids":[],"asks":[{"price":3502.10,"qty":26.32690314}],"checksum":2304545428,"timestamp":"2024-06-01T17:51:54.345168Z"}]}
{"channel":"book","type":"update","data":[{"symbol":"ETH/EUR","bids":[],"asks":[{"price":3502.10,"qty":0.00000000},{"price":3502.57,"qty":0.00220000}],"checksum":2975439409,"timestamp":"2024-06-01T17:51:54.449844Z"}]}
{"channel":"book","type":"update","data":[{"symbol":"ETH/EUR","bids":[],"asks":[{"price":3502.08,"qty":26.32927420}],"checksum":2414413255,"timestamp":"2024-06-01T17:51:54.454894Z"}]}
{"channel":"book","type":"update","data":[{"symbol":"ETH/EUR","bids":[],"asks":[{"price":3502.08,"qty":0.00220000}],"checksum":2975439409,"timestamp":"2024-06-01T17:51:54.492280Z"}]}
{"channel":"book","type":"update","data":[{"symbol":"ETH/EUR","bids":[],"asks":[{"price":3502.09,"qty":26.32698735}],"checksum":2888259056,"timestamp":"2024-06-01T17:51:54.545282Z"}]}
{"channel":"book","type":"update","data":[{"symbol":"ETH/EUR","bids":[],"asks":[{"price":3502.09,"qty":0.00000000},{"price":3502.57,"qty":0.00220000}],"checksum":2975439409,"timestamp":"2024-06-01T17:51:54.634034Z"}]}
{"channel":"book","type":"update","data":[{"symbol":"ETH/EUR","bids":[],"asks":[{"price":3502.08,"qty":26.32928209}],"checksum":1168928219,"timestamp":"2024-06-01T17:51:54.637629Z"}]}
{"channel":"book","type":"update","data":[{"symbol":"ETH/EUR","bids":[],"asks":[{"price":3502.08,"qty":0.00220000}],"checksum":2975439409,"timestamp":"2024-06-01T17:51:54.741745Z"}]}
{"channel":"book","type":"update","data":[{"symbol":"ETH/EUR","bids":[],"asks":[{"price":3502.11,"qty":26.32684100}],"checksum":2618814150,"timestamp":"2024-06-01T17:51:54.745719Z"}]}
{"channel":"book","type":"update","data":[{"symbol":"ETH/EUR","bids":[],"asks":[{"price":3502.11,"qty":0.00000000},{"price":3502.57,"qty":0.00220000}],"checksum":2975439409,"timestamp":"2024-06-01T17:51:54.903631Z"}]}
{"channel":"book","type":"update","data":[{"symbol":"ETH/EUR","bids":[],"asks":[{"price":3502.10,"qty":26.32690571}],"checksum":2185954660,"timestamp":"2024-06-01T17:51:54.908014Z"}]}
{"channel":"book","type":"update","data":[{"symbol":"ETH/EUR","bids":[{"price":3501.08,"qty":133.63641597}],"asks":[],"checksum":2794641515,"timestamp":"2024-06-01T17:51:54.988446Z"}]}
{"channel":"book","type":"update","data":[{"symbol":"ETH/EUR","bids":[{"price":3500.87,"qty":0.00000000},{"price":3500.65,"qty":0.84644082}],"asks":[],"checksum":2093509606,"timestamp":"2024-06-01T17:51:54.992098Z"}]}
{"channel":"book","type":"update","data":[{"symbol":"ETH/EUR","bids":[],"asks":[{"price":3502.37,"qty":6.76882851},{"price":3502.09,"qty":0.00775565}],"checksum":173622338,"timestamp":"2024-06-01T17:51:55.067102Z"}]}
{"channel":"book","type":"update","data":[{"symbol":"ETH/EUR","bids":[],"asks":[{"price":3502.10,"qty":0.00000000},{"price":3502.46,"qty":1.09100000}],"checksum":3726989189,"timestamp":"2024-06-01T17:51:55.250560Z"}]}
{"channel":"book","type":"update","data":[{"symbol":"ETH/EUR","bids":[],"asks":[{"price":3502.08,"qty":26.32929047}],"checksum":3448403952,"timestamp":"2024-06-01T17:51:55.254428Z"}]}
{"channel":"book","type":"update","data":[{"symbol":"ETH/EUR","bids":[],"asks":[{"price":3502.08,"qty":0.00220000}],"checksum":3726989189,"timestamp":"2024-06-01T17:51:55.280438Z"}]}
{"channel":"book","type":"update","data":[{"symbol":"ETH/EUR","bids":[],"asks":[{"price":3502.09,"qty":0.00000000},{"price":3502.57,"qty":0.00220000},{"price":3502.36,"qty":0.00774798}],"checksum":455235519,"timestamp":"2024-06-01T17:51:55.308190Z"}]}
{"channel":"book","type":"update","data":[{"symbol":"ETH/EUR","bids":[],"asks":[{"price":3502.09,"qty":26.32694310}],"checksum":3242336570,"timestamp":"2024-06-01T17:51:55.401886Z"}]}
{"channel":"book","type":"update","data":[{"symbol":"ETH/EUR","bids":[],"asks":[{"price":3502.37,"qty":0.00000000},{"price":3502.46,"qty":1.09100000}],"checksum":3528243932,"timestamp":"2024-06-01T17:51:55.470793Z"}]}
{"channel":"book","type":"update","data":[{"symbol":"ETH/EUR","bids":[],"asks":[{"price":3502.09,"qty":0.00000000},{"price":3502.57,"qty":0.00220000}],"checksum":1683751562,"timestamp":"2024-06-01T17:51:55.690905Z"}]}
{"channel":"book","type":"update","data":[{"symbol":"ETH/EUR","bids":[],"asks":[{"price":3502.11,"qty":26.32682731}],"checksum":455055554,"timestamp":"2024-06-01T17:51:55.694225Z"}]}
{"channel":"book","type":"update","data":[{"symbol":"ETH/EUR","bids":[],"asks":[{"price":3502.36,"qty":0.00000000},{"price":3502.57,"qty":0.00220000},{"price":3502.37,"qty":0.00774798}],"checksum":2501408280,"timestamp":"2024-06-01T17:51:55.729503Z"}]}
{"channel":"book","type":"update","data":[{"symbol":"ETH/EUR","bids":[],"asks":[{"price":3502.11,"qty":0.00000000},{"price":3502.57,"qty":0.00220000}],"checksum":3957298946,"timestamp":"2024-06-01T17:51:55.901532Z"}]}
{"channel":"book","type":"update","data":[{"symbol":"ETH/EUR","bids":[],"asks":[{"price":3502.10,"qty":26.32690735}],"checksum":3884406293,"timestamp":"2024-06-01T17:51:55.905314Z"}]}
{"channel":"book","type":"update","data":[{"symbol":"ETH/EUR","bids":[],"asks":[{"price":3502.10,"qty":0.00000000},{"price":3502.57,"qty":0.00220000}],"checksum":3957298946,"timestamp":"2024-06-01T17:51:55.923085Z"}]}
{"channel":"book","type":"update","data":[{"symbol":"ETH/EUR","bids":[],"asks":[{"price":3502.12,"qty":26.32678189}],"checksum":1982032982,"timestamp":"2024-06-01T17:51:55.958529Z"}]}
{"channel":"book","type":"update","data":[{"symbol":"ETH/EUR","bids":[],"asks":[{"price":3502.21,"qty":26.32609401}],"checksum":2255667346,"timestamp":"2024-06-01T17:51:55.958646Z"}]}
{"channel":"book","type":"update","data":[{"symbol":"ETH/EUR","bids":[],"asks":[{"price":3502.12,"qty":0.00000000},{"price":3502.46,"qty":1.09100000}],"checksum":1562993589,"timestamp":"2024-06-01T17:51:55.979451Z"}]}
{"channel":"book","type":"update","data":[{"symbol":"ETH/EUR","bids":[{"price":3501.08,"qty":140.22136194}],"asks":[],"checksum":1218428879,"timestamp":"2024-06-01T17:51:56.028897Z"}]}
{"channel":"book","type":"update","data":[{"symbol":"ETH/EUR","bids":[{"price":3500.82,"qty":0.00000000},{"price":3500.63,"qty":1.31732867}],"asks":[],"checksum":970679636,"timestamp":"2024-06-01T17:51:56.030507Z"}]}
{"channel":"book","type":"update","data":[{"symbol":"ETH/EUR","bids":[],"asks":[{"price":3502.37,"qty":0.00000000},{"price":3502.57,"qty":0.00220000},{"price":3502.20,"qty":0.00774798}],"checksum":96379429,"timestamp":"2024-06-01T17:51:56.102721Z"}]}
{"channel":"book","type":"update","data":[{"symbol":"ETH/EUR","bids":[],"asks":[{"price":3502.16,"qty":26.32642779}],"checksum":2699469543,"timestamp":"2024-06-01T17:51:56.162705Z"}]}
{"channel":"book","type":"update","data":[{"symbol":"ETH/EUR","bids":[{"price":3501.08,"qty":139.49223226}],"asks":[],"checksum":3648832615,"timestamp":"2024-06-01T17:51:56.275826Z"}]}
{"channel":"book","type":"update","data":[{"symbol":"ETH/EUR","bids":[{"price":3501.08,"qty":139.22883453}],"asks":[],"checksum":256862501,"timestamp":"2024-06-01T17:51:56.283546Z"}]}
{"channel":"book","type":"update","data":[{"symbol":"ETH/EUR","bids":[{"price":3500.96,"qty":0.00000000},{"price":3500.59,"qty":0.19291452}],"asks":[],"checksum":1166727792,"timestamp":"2024-06-01T17:51:56.283885Z"}]}
{"channel":"book","type":"update","data":[{"symbol":"ETH/EUR","bids":[],"asks":[{"price":3502.16,"qty":0.00000000},{"price":3502.46,"qty":1.09100000}],"checksum":3771914930,"timestamp":"2024-06-01T17:51:56.283949Z"}]}
{"channel":"book","type":"update","data":[{"symbol":"ETH/EUR","bids":[],"asks":[{"price":3502.21,"qty":0.00000000},{"price":3502.57,"qty":0.00220000}],"checksum":2445641161,"timestamp":"2024-06-01T17:51:56.284011Z"}]}
{"channel":"book","type":"update","data":[{"symbol":"ETH/EUR","bids":[{"price":3501.08,"qty":132.64388856}],"asks":[],"checksum":818106580,"timestamp":"2024-06-01T17:51:56.300148Z"}]}
{"channel":"book","type":"update","data":[{"symbol":"ETH/EUR","bids":[],"asks":[{"price":3501.91,"qty":26.32835138}],"checksum":1486843872,"timestamp":"2024-06-01T17:51:56.305555Z"}]}
{"channel":"book","type":"update","data":[{"symbol":"ETH/EUR","bids":[],"asks":[{"price":3501.80,"qty":26.32914426}],"checksum":2283828293,"timestamp":"2024-06-01T17:51:56.305623Z"}]}
{"channel":"book","type":"update","data":[{"symbol":"ETH/EUR","bids":[],"asks":[{"price":3502.02,"qty":26.32750390}],"checksum":2631619120,"timestamp":"2024-06-01T17:51:56.305661Z"}]}
{"channel":"book","type":"update","data":[{"symbol":"ETH/EUR","bids":[{"price":3501.03,"qty":0.00000000},{"price":3500.58,"qty":17.28022880}],"asks":[],"checksum":324491051,"timestamp":"2024-06-01T17:51:56.305983Z"}]}
{"channel":"book","type":"update","data":[{"symbol":"ETH/EUR","bids":[],"asks":[{"price":3501.91,"qty":0.00000000},{"price":3502.45,"qty":0.08777600}],"checksum":2454807716,"timestamp":"2024-06-01T17:51:56.314137Z"}]}
{"channel":"book","type":"update","data":[{"symbol":"ETH/EUR","bids":[{"price":3500.70,"qty":0.00000000},{"price":3500.47,"qty":0.60495221}],"asks":[],"checksum":889672203,"timestamp":"2024-06-01T17:51:56.391214Z"}]}
{"channel":"book","type":"update","data":[{"symbol":"ETH/EUR","bids":[{"price":3500.72,"qty":0.26339773}],"asks":[],"checksum":1406731532,"timestamp":"2024-06-01T17:51:56.392251Z"}]}
{"channel":"book","type":"update","data":[{"symbol":"ETH/EUR","bids":[{"price":3500.64,"qty":0.26339773}],"asks":[],"checksum":2964621845,"timestamp":"2024-06-01T17:51:56.392895Z"}]}
{"channel":"book","type":"update","data":[{"symbol":"ETH/EUR","bids":[{"price":3500.93,"qty":1.35356069}],"asks":[],"checksum":1365225615,"timestamp":"2024-06-01T17:51:56.432371Z"}]}
{"channel":"book","type":"update","data":[{"symbol":"ETH/EUR","bids":[],"asks":[{"price":3501.79,"qty":0.64327416}],"checksum":1335475180,"timestamp":"2024-06-01T17:51:56.565876Z"}]}
{"channel":"book","type":"update","data":[{"symbol":"ETH/EUR","bids":[{"price":3500.64,"qty":0.00000000},{"price":3500.59,"qty":0.19291452}],"asks":[],"checksum":3595405318,"timestamp":"2024-06-01T17:51:56.619458Z"}]}
{"channel":"book","type":"update","data":[{"symbol":"ETH/EUR","bids":[{"price":3500.72,"qty":0.00000000},{"price":3500.58,"qty":17.28022880}],"asks":[],"checksum":2821886195,"timestamp":"2024-06-01T17:51:56.619485Z"}]}
{"channel":"book","type":"update","data":[{"symbol":"ETH/EUR","bids":[],"asks":[{"price":3501.77,"qty":26.32938146}],"checksum":2670878262,"timestamp":"2024-06-01T17:51:56.748771Z"}]}
{"channel":"book","type":"update","data":[{"symbol":"ETH/EUR","bids":[],"asks":[{"price":3501.77,"qty":0.00000000},{"price":3502.38,"qty":26.32482080}],"checksum":2821886195,"timestamp":"2024-06-01T17:51:56.779675Z"}]}
{"channel":"book","type":"update","data":[{"symbol":"ETH/EUR","bids":[],"asks":[{"price":3501.79,"qty":26.97250240}],"checksum":4141837494,"timestamp":"2024-06-01T17:51:56.938237Z"}]}
{"channel":"book","type":"update","data":[{"symbol":"ETH/EUR","bids":[],"asks":[{"price":3501.79,"qty":0.64327416}],"checksum":2821886195,"timestamp":"2024-06-01T17:51:56.951480Z"}]}
{"channel":"book","type":"update","data":[{"symbol":"ETH/EUR","bids":[],"asks":[{"price":3502.20,"qty":0.00000000},{"price":3502.45,"qty":0.08777600},{"price":3502.37,"qty":0.00774370}],"checksum":2252112067,"timestamp":"2024-06-01T17:51:56.982567Z"}]}
{"channel":"book","type":"update","data":[{"symbol":"ETH/EUR","bids":[],"asks":[{"price":3502.37,"qty":0.00000000},{"price":3502.45,"qty":0.08777600},{"price":3502.01,"qty":0.00774370}],"checksum":2467826216,"timestamp":"2024-06-01T17:51:57.151354Z"}]}
{"channel":"book","type":"update","data":[{"symbol":"ETH/EUR","bids":[],"asks":[{"price":3501.80,"qty":0.00000000},{"price":3502.45,"qty":0.08777600}],"checksum":4073667520,"timestamp":"2024-06-01T17:51:57.192933Z"}]}
{"channel":"book","type":"update","data":[{"symbol":"ETH/EUR","bids":[],"asks":[{"price":3501.79,"qty":26.97253715}],"checksum":3741226462,"timestamp":"2024-06-01T17:51:57.196810Z"}]}
{"channel":"book","type":"update","data":[{"symbol":"ETH/EUR","bids":[],"asks":[{"price":3501.79,"qty":0.64327416}],"checksum":4073667520,"timestamp":"2024-06-01T17:51:57.237919Z"}]}
{"channel":"book","type":"update","data":[{"symbol":"ETH/EUR","bids":[],"asks":[{"price":3501.78,"qty":26.32931826}],"checksum":68385811,"timestamp":"2024-06-01T17:51:57.249180Z"}]}
{"channel":"book","type":"update","data":[{"symbol":"ETH/EUR","bids":[],"asks":[{"price":3501.78,"qty":0.00000000},{"price":3502.45,"qty":0.08777600}],"checksum":4073667520,"timestamp":"2024-06-01T17:51:57.451768Z"}]}
{"channel":"book","type":"update","data":[{"symbol":"ETH/EUR","bids":[],"asks":[{"price":3501.80,"qty":26.32914719}],"checksum":164551528,"timestamp":"2024-06-01T17:51:57.455379Z"}]}
{"channel":"book","type":"update","data":[{"symbol":"ETH/EUR","bids":[],"asks":[{"price":3501.80,"qty":0.00000000},{"price":3502.45,"qty":0.08777600}],"checksum":4073667520,"timestamp":"2024-06-01T17:51:57.483346Z"}]}
{"channel":"book","type":"update","data":[{"symbol":"ETH/EUR","bids":[{"price":3501.05,"qty":0.00000000},{"price":3500.48,"qty":1.31708923}],"asks":[],"checksum":3981773639,"timestamp":"2024-06-01T17:51:57.535825Z"}]}
{"channel":"book","type":"update","data":[{"symbol":"ETH/EUR","bids":[{"price":3501.08,"qty":116.83815160}],"asks":[],"checksum":1744392752,"timestamp":"2024-06-01T17:51:57.535937Z"}]}
{"channel":"book","type":"update","data":[{"symbol":"ETH/EUR","bids":[],"asks":[{"price":3501.80,"qty":26.32919364}],"checksum":4027918173,"timestamp":"2024-06-01T17:51:57.595401Z"}]}
{"channel":"book","type":"update","data":[{"symbol":"ETH/EUR","bids":[],"asks":[{"price":3501.80,"qty":0.00000000},{"price":3502.45,"qty":0.08777600}],"checksum":1744392752,"timestamp":"2024-06-01T17:51:57.690817Z"}]}
{"channel":"book","type":"update","data":[{"symbol":"ETH/EUR","bids":[],"asks":[{"price":3501.78,"qty":26.32930155}],"checksum":3664080783,"timestamp":"2024-06-01T17:51:57.694189Z"}]}
{"channel":"book","type":"update","data":[{"symbol":"ETH/EUR","bids":[{"price":3500.59,"qty":0.00000000},{"price":3500.47,"qty":0.60495221}],"asks":[],"checksum":271208354,"timestamp":"2024-06-01T17:51:57.712468Z"}]}
{"channel":"book","type":"update","data":[{"symbol":"ETH/EUR","bids":[],"asks":[{"price":3502.09,"qty":0.08557600}],"checksum":1698765982,"timestamp":"2024-06-01T17:51:57.907046Z"}]}
{"channel":"book","type":"update","data":[{"symbol":"ETH/EUR","bids":[],"asks":[{"price":3501.78,"qty":0.00000000},{"price":3502.38,"qty":26.32482080}],"checksum":3309454159,"timestamp":"2024-06-01T17:51:57.951449Z"}]}
{"channel":"book","type":"update","data":[{"symbol":"ETH/EUR","bids":[],"asks":[{"price":3501.77,"qty":26.32940362}],"checksum":2494508144,"timestamp":"2024-06-01T17:51:57.954886Z"}]}
{"channel":"book","type":"update","data":[{"symbol":"ETH/EUR","bids":[],"asks":[{"price":3501.77,"qty":0.00000000},{"price":3502.38,"qty":26.32482080}],"checksum":3309454159,"timestamp":"2024-06-01T17:51:57.979924Z"}]}
{"channel":"book","type":"update","data":[{"symbol":"ETH/EUR","bids":[],"asks":[{"price":3501.75,"qty":26.32956153}],"checksum":771972888,"timestamp":"2024-06-01T17:51:58.364219Z"}]}
{"channel":"book","type":"update","data":[{"symbol":"ETH/EUR","bids":[{"price":3500.58,"qty":0.00000000},{"price":3500.45,"qty":0.72912968}],"asks":[],"checksum":1067091762,"timestamp":"2024-06-01T17:51:58.461311Z"}]}
{"channel":"book","type":"update","data":[{"symbol":"ETH/EUR","bids":[{"price":3500.68,"qty":0.00000000},{"price":3500.41,"qty":3.01305282}],"asks":[],"checksum":876634158,"timestamp":"2024-06-01T17:51:58.514210Z"}]}
{"channel":"book","type":"update","data":[{"symbol":"ETH/EUR","bids":[],"asks":[{"price":3501.75,"qty":0.00000000},{"price":3502.38,"qty":26.32482080}],"checksum":3741416569,"timestamp":"2024-06-01T17:51:58.739021Z"}]}
{"channel":"book","type":"update","data":[{"symbol":"ETH/EUR","bids":[],"asks":[{"price":3501.74,"qty":26.32959837}],"checksum":1913592407,"timestamp":"2024-06-01T17:51:58.743274Z"}]}
{"channel":"book","type":"update","data":[{"symbol":"ETH/EUR","bids":[{"price":3500.41,"qty":0.00000000},{"price":3500.30,"qty":0.02851380}],"asks":[],"checksum":2441908455,"timestamp":"2024-06-01T17:51:58.815909Z"}]}
{"channel":"book","type":"update","data":[{"symbol":"ETH/EUR","bids":[{"price":3500.30,"qty":0.00000000},{"price":3500.29,"qty":1.07700000}],"asks":[],"checksum":1297547314,"timestamp":"2024-06-01T17:51:58.880322Z"}]}
{"channel":"book","type":"update","data":[{"symbol":"ETH/EUR","bids":[],"asks":[{"price":3501.74,"qty":0.00000000},{"price":3502.38,"qty":26.32482080}],"checksum":3763955228,"timestamp":"2024-06-01T17:51:59.118651Z"}]}
{"channel":"book","type":"update","data":[{"symbol":"ETH/EUR","bids":[],"asks":[{"price":3502.01,"qty":0.00000000},{"price":3502.45,"qty":0.00220000},{"price":3502.37,"qty":0.00773976}],"checksum":4170827720,"timestamp":"2024-06-01T17:51:59.122240Z"}]}
{"channel":"book","type":"update","data":[{"symbol":"ETH/EUR","bids":[],"asks":[{"price":3501.76,"qty":26.32943885}],"checksum":3256079256,"timestamp":"2024-06-01T17:51:59.122306Z"}]}
{"channel":"book","type":"update","data":[{"symbol":"ETH/EUR","bids":[],"asks":[{"price":3501.76,"qty":0.00000000},{"price":3502.38,"qty":26.32482080}],"checksum":4170827720,"timestamp":"2024-06-01T17:51:59.177633Z"}]}
{"channel":"book","type":"update","data":[{"symbol":"ETH/EUR","bids":[],"asks":[{"price":3501.78,"qty":26.32929937}],"checksum":1452618787,"timestamp":"2024-06-01T17:51:59.181733Z"}]}
{"channel":"book","type":"update","data":[{"symbol":"ETH/EUR","bids":[],"asks":[{"price":3501.78,"qty":0.00000000},{"price":3502.38,"qty":26.32482080}],"checksum":4170827720,"timestamp":"2024-06-01T17:51:59.296259Z"}]}
{"channel":"book","type":"update","data":[{"symbol":"ETH/EUR","bids":[],"asks":[{"price":3501.76,"qty":26.32943622}],"checksum":3506750075,"timestamp":"2024-06-01T17:51:59.299935Z"}]}
{"channel":"book","type":"update","data":[{"symbol":"ETH/EUR","bids":[],"asks":[{"price":3501.76,"qty":0.00000000},{"price":3502.38,"qty":26.32482080}],"checksum":4170827720,"timestamp":"2024-06-01T17:51:59.387696Z"}]}
{"channel":"book","type":"update","data":[{"symbol":"ETH/EUR","bids":[],"asks":[{"price":3501.78,"qty":26.32931911}],"checksum":1338167699,"timestamp":"2024-06-01T17:51:59.391823Z"}]}
{"channel":"book","type":"update","data":[{"symbol":"ETH/EUR","bids":[],"asks":[{"price":3502.37,"qty":0.00000000},{"price":3502.38,"qty":26.32482080},{"price":3502.01,"qty":0.00773976}],"checksum":3423834759,"timestamp":"2024-06-01T17:51:59.506621Z"}]}
{"channel":"book","type":"update","data":[{"symbol":"ETH/EUR","bids":[],"asks":[{"price":3501.78,"qty":0.00000000},{"price":3502.38,"qty":26.32482080}],"checksum":903751685,"timestamp":"2024-06-01T17:52:00.007675Z"}]}
{"channel":"book","type":"update","data":[{"symbol":"ETH/EUR","bids":[],"asks":[{"price":3501.77,"qty":26.32940347}],"checksum":361343522,"timestamp":"2024-06-01T17:52:00.011709Z"}]}
{"channel":"book","type":"update","data":[{"symbol":"ETH/EUR","bids":[],"asks":[{"price":3501.77,"qty":0.00000000},{"price":3502.38,"qty":26.32482080}],"checksum":903751685,"timestamp":"2024-06-01T17:52:00.138622Z"}]}
{"channel":"book","type":"update","data":[{"symbol":"ETH/EUR","bids":[],"asks":[{"price":3501.76,"qty":26.32944765}],"checksum":403024448,"timestamp":"2024-06-01T17:52:00.142716Z"}]}
{"channel":"book","type":"update","data":[{"symbol":"ETH/EUR","bids":[],"asks":[{"price":3501.76,"qty":0.00000000},{"price":3502.38,"qty":26.32482080}],"checksum":903751685,"timestamp":"2024-06-01T17:52:00.183249Z"}]}
{"channel":"book","type":"update","data":[{"symbol":"ETH/EUR","bids":[],"asks":[{"price":3501.76,"qty":26.32947376}],"checksum":2729360086,"timestamp":"2024-06-01T17:52:00.274828Z"}]}
{"channel":"book","type":"update","data":[{"symbol":"ETH/EUR","bids":[],"asks":[{"price":3501.76,"qty":0.00000000},{"price":3502.38,"qty":26.32482080}],"checksum":903751685,"timestamp":"2024-06-01T17:52:00.303927Z"}]}
{"channel":"book","type":"update","data":[{"symbol":"ETH/EUR","bids":[],"asks":[{"price":3501.80,"qty":26.32914071}],"checksum":26730047,"timestamp":"2024-06-01T17:52:00.372111Z"}]}
{"channel":"book","type":"update","data":[{"symbol":"ETH/EUR","bids":[],"asks":[{"price":3501.80,"qty":0.00000000},{"price":3502.38,"qty":26.32482080}],"checksum":903751685,"timestamp":"2024-06-01T17:52:00.446211Z"}]}
{"channel":"book","type":"update","data":[{"symbol":"ETH/EUR","bids":[],"asks":[{"price":3501.90,"qty":26.32839844}],"checksum":847705918,"timestamp":"2024-06-01T17:52:00.451393Z"}]}
{"channel":"book","type":"update","data":[{"symbol":"ETH/EUR","bids":[],"asks":[{"price":3502.02,"qty":0.00000000},{"price":3502.15,"qty":26.32649858}],"checksum":2266222808,"timestamp":"2024-06-01T17:52:00.503891Z"}]}
{"channel":"book","type":"update","data":[{"symbol":"ETH/EUR","bids":[],"asks":[{"price":3501.89,"qty":26.32848002}],"checksum":2629349678,"timestamp":"2024-06-01T17:52:00.508122Z"}]}
{"channel":"book","type":"update","data":[{"symbol":"ETH/EUR","bids":[],"asks":[{"price":3502.01,"qty":0.00000000},{"price":3502.15,"qty":26.32649858},{"price":3501.78,"qty":0.00773995}],"checksum":3774884548,"timestamp":"2024-06-01T17:52:00.527678Z"}]}
{"channel":"book","type":"update","data":[{"symbol":"ETH/EUR","bids":[],"asks":[{"price":3501.89,"qty":0.00000000},{"price":3502.15,"qty":26.32649858}],"checksum":3799557337,"timestamp":"2024-06-01T17:52:00.540361Z"}]}
{"channel":"book","type":"update","data":[{"symbol":"ETH/EUR","bids":[],"asks":[{"price":3501.87,"qty":26.32863266}],"checksum":3257913222,"timestamp":"2024-06-01T17:52:00.589223Z"}]}
{"channel":"book","type":"update","data":[{"symbol":"ETH/EUR","bids":[],"asks":[{"price":3501.87,"qty":0.00000000},{"price":3502.15,"qty":26.32649858}],"checksum":3799557337,"timestamp":"2024-06-01T17:52:00.669691Z"}]}
{"channel":"book","type":"update","data":[{"symbol":"ETH/EUR","bids":[],"asks":[{"price":3501.86,"qty":26.33090898}],"checksum":1671923655,"timestamp":"2024-06-01T17:52:00.673566Z"}]}
{"channel":"book","type":"update","data":[{"symbol":"ETH/EUR","bids":[],"asks":[{"price":3501.86,"qty":0.00220000}],"checksum":3799557337,"timestamp":"2024-06-01T17:52:00.720761Z"}]}
{"channel":"book","type":"update","data":[{"symbol":"ETH/EUR","bids":[],"asks":[{"price":3501.85,"qty":26.32879057}],"checksum":2748965750,"timestamp":"2024-06-01T17:52:00.724396Z"}]}
{"channel":"book","type":"update","data":[{"symbol":"ETH/EUR","bids":[],"asks":[{"price":3501.85,"qty":0.00000000},{"price":3502.15,"qty":26.32649858}],"checksum":3799557337,"timestamp":"2024-06-01T17:52:01.030416Z"}]}
{"channel":"book","type":"update","data":[{"symbol":"ETH/EUR","bids":[],"asks":[{"price":3501.84,"qty":26.32888902}],"checksum":2996164177,"timestamp":"2024-06-01T17:52:01.033897Z"}]}
{"channel":"book","type":"update","data":[{"symbol":"ETH/EUR","bids":[],"asks":[{"price":3501.84,"qty":0.00000000},{"price":3502.15,"qty":26.32649858}],"checksum":3799557337,"timestamp":"2024-06-01T17:52:01.175091Z"}]}
{"channel":"book","type":"update","data":[{"symbol":"ETH/EUR","bids":[],"asks":[{"price":3501.79,"qty":26.97248496}],"checksum":3262940281,"timestamp":"2024-06-01T17:52:01.182071Z"}]}
{"channel":"book","type":"update","data":[{"symbol":"ETH/EUR","bids":[],"asks":[{"price":3501.79,"qty":0.64327416}],"checksum":3799557337,"timestamp":"2024-06-01T17:52:01.271082Z"}]}
{"channel":"book","type":"update","data":[{"symbol":"ETH/EUR","bids":[],"asks":[{"price":3501.82,"qty":26.32903710}],"checksum":1557979744,"timestamp":"2024-06-01T17:52:01.274677Z"}]}
{"channel":"book","type":"update","data":[{"symbol":"ETH/EUR","bids":[],"asks":[{"price":3501.82,"qty":0.00000000},{"price":3502.15,"qty":26.32649858}],"checksum":3799557337,"timestamp":"2024-06-01T17:52:01.322381Z"}]}
{"channel":"book","type":"update","data":[{"symbol":"ETH/EUR","bids":[],"asks":[{"price":3501.80,"qty":26.32915290}],"checksum":1297265238,"timestamp":"2024-06-01T17:52:01.326348Z"}]}
{"channel":"book","type":"update","data":[{"symbol":"ETH/EUR","bids":[],"asks":[{"price":3501.80,"qty":0.00000000},{"price":3502.15,"qty":26.32649858}],"checksum":3799557337,"timestamp":"2024-06-01T17:52:01.473105Z"}]}
{"channel":"book","type":"update","data":[{"symbol":"ETH/EUR","bids":[],"asks":[{"price":3501.83,"qty":26.32894762}],"checksum":930464980,"timestamp":"2024-06-01T17:52:01.476814Z"}]}
{"channel":"book","type":"update","data":[{"symbol":"ETH/EUR","bids":[],"asks":[{"price":3501.83,"qty":0.00000000},{"price":3502.15,"qty":26.32649858}],"checksum":3799557337,"timestamp":"2024-06-01T17:52:01.820226Z"}]}
{"channel":"book","type":"update","data":[{"symbol":"ETH/EUR","bids":[],"asks":[{"price":3501.79,"qty":26.97247706}],"checksum":2621437267,"timestamp":"2024-06-01T17:52:01.823842Z"}]}
{"channel":"book","type":"update","data":[{"symbol":"ETH/EUR","bids":[],"asks":[{"price":3502.15,"qty":0.00000000},{"price":3502.38,"qty":26.32482080}],"checksum":3742586267,"timestamp":"2024-06-01T17:52:01.825510Z"}]}
{"channel":"book","type":"update","data":[{"symbol":"ETH/EUR","bids":[],"asks":[{"price":3502.04,"qty":26.32739246}],"checksum":3675437090,"timestamp":"2024-06-01T17:52:01.828788Z"}]}
{"channel":"book","type":"update","data":[{"symbol":"ETH/EUR","bids":[],"asks":[{"price":3501.90,"qty":0.00000000},{"price":3502.38,"qty":26.32482080}],"checksum":272489118,"timestamp":"2024-06-01T17:52:02.055391Z"}]}
{"channel":"book","type":"update","data":[{"symbol":"ETH/EUR","bids":[],"asks":[{"price":3501.78,"qty":26.33708643}],"checksum":2652198138,"timestamp":"2024-06-01T17:52:02.059421Z"}]}
{"channel":"book","type":"update","data":[{"symbol":"ETH/EUR","bids":[],"asks":[{"price":3501.78,"qty":26.32934648},{"price":3501.77,"qty":0.00770935}],"checksum":1383017221,"timestamp":"2024-06-01T17:52:02.139380Z"}]}
{"channel":"book","type":"update","data":[{"symbol":"ETH/EUR","bids":[],"asks":[{"price":3501.78,"qty":0.00000000},{"price":3502.38,"qty":26.32482080}],"checksum":756673989,"timestamp":"2024-06-01T17:52:02.177715Z"}]}
{"channel":"book","type":"update","data":[{"symbol":"ETH/EUR","bids":[],"asks":[{"price":3501.76,"qty":26.32942849}],"checksum":2338664410,"timestamp":"2024-06-01T17:52:02.181143Z"}]}
{"channel":"book","type":"update","data":[{"symbol":"ETH/EUR","bids":[],"asks":[{"price":3501.76,"qty":0.00000000},{"price":3502.38,"qty":26.32482080}],"checksum":756673989,"timestamp":"2024-06-01T17:52:02.225656Z"}]}
{"channel":"book","type":"update","data":[{"symbol":"ETH/EUR","bids":[],"asks":[{"price":3501.77,"qty":0.00000000},{"price":3502.45,"qty":0.00220000},{"price":3502.03,"qty":0.00770935}],"checksum":2659698184,"timestamp":"2024-06-01T17:52:02.228461Z"}]}
{"channel":"book","type":"update","data":[{"symbol":"ETH/EUR","bids":[],"asks":[{"price":3501.81,"qty":26.32904951}],"checksum":1976191341,"timestamp":"2024-06-01T17:52:02.264400Z"}]}
{"channel":"book","type":"update","data":[{"symbol":"ETH/EUR","bids":[],"asks":[{"price":3501.79,"qty":0.64327416}],"checksum":3998481432,"timestamp":"2024-06-01T17:52:02.287990Z"}]}
{"channel":"book","type":"update","data":[{"symbol":"ETH/EUR","bids":[],"asks":[{"price":3501.90,"qty":26.32843100}],"checksum":806363855,"timestamp":"2024-06-01T17:52:02.291892Z"}]}
{"channel":"book","type":"update","data":[{"symbol":"ETH/EUR","bids":[],"asks":[{"price":3501.81,"qty":0.00000000},{"price":3502.09,"qty":0.08557600}],"checksum":335275422,"timestamp":"2024-06-01T17:52:02.302833Z"}]}
{"channel":"book","type":"update","data":[{"symbol":"ETH/EUR","bids":[],"asks":[{"price":3501.85,"qty":26.32875606}],"checksum":1825584498,"timestamp":"2024-06-01T17:52:02.322873Z"}]}
{"channel":"book","type":"update","data":[{"symbol":"ETH/EUR","bids":[],"asks":[{"price":3501.85,"qty":0.00000000},{"price":3502.09,"qty":0.08557600}],"checksum":335275422,"timestamp":"2024-06-01T17:52:02.326405Z"}]}
{"channel":"book","type":"update","data":[{"symbol":"ETH/EUR","bids":[],"asks":[{"price":3501.86,"qty":26.33091658}],"checksum":3693727274,"timestamp":"2024-06-01T17:52:02.502061Z"}]}
{"channel":"book","type":"update","data":[{"symbol":"ETH/EUR","bids":[],"asks":[{"price":3501.86,"qty":0.00220000}],"checksum":335275422,"timestamp":"2024-06-01T17:52:02.955891Z"}]}
{"channel":"book","type":"update","data":[{"symbol":"ETH/EUR","bids":[],"asks":[{"price":3501.84,"qty":26.32882975}],"checksum":4254178163,"timestamp":"2024-06-01T17:52:02.960667Z"}]}
{"channel":"book","type":"update","data":[{"symbol":"ETH/EUR","bids":[],"asks":[{"price":3501.84,"qty":0.00000000},{"price":3502.09,"qty":0.08557600}],"checksum":335275422,"timestamp":"2024-06-01T17:52:03.010623Z"}]}
{"channel":"book","type":"update","data":[{"symbol":"ETH/EUR","bids":[],"asks":[{"price":3502.03,"qty":0.00000000},{"price":3502.15,"qty":26.32649881},{"price":3501.78,"qty":0.00770914}],"checksum":3793006273,"timestamp":"2024-06-01T17:52:03.071285Z"}]}
{"channel":"book","type":"update","data":[{"symbol":"ETH/EUR","bids":[],"asks":[{"price":3501.90,"qty":0.00000000},{"price":3502.15,"qty":26.32649881}],"checksum":2359796446,"timestamp":"2024-06-01T17:52:03.113582Z"}]}
{"channel":"book","type":"update","data":[{"symbol":"ETH/EUR","bids":[],"asks":[{"price":3501.97,"qty":26.32786371}],"checksum":3940954478,"timestamp":"2024-06-01T17:52:03.117490Z"}]}
{"channel":"book","type":"update","data":[{"symbol":"ETH/EUR","bids":[],"asks":[{"price":3501.97,"qty":0.00000000},{"price":3502.15,"qty":26.32649881}],"checksum":2359796446,"timestamp":"2024-06-01T17:52:03.127305Z"}]}
{"channel":"book","type":"update","data":[{"symbol":"ETH/EUR","bids":[],"asks":[{"price":3502.04,"qty":0.00000000},{"price":3502.38,"qty":26.32482080}],"checksum":3212624462,"timestamp":"2024-06-01T17:52:03.133735Z"}]}
{"channel":"book","type":"update","data":[{"symbol":"ETH/EUR","bids":[{"price":3500.79,"qty":0.00000000},{"price":3500.24,"qty":0.02851621},{"price":3501.08,"qty":116.92373760}],"asks":[],"checksum":3455717435,"timestamp":"2024-06-01T17:52:03.139944Z"}]}
{"channel":"book","type":"update","data":[{"symbol":"ETH/EUR","bids":[],"asks":[{"price":3501.94,"qty":26.32810586}],"checksum":3438711412,"timestamp":"2024-06-01T17:52:03.171889Z"}]}
{"channel":"book","type":"update","data":[{"symbol":"ETH/EUR","bids":[],"asks":[{"price":3501.94,"qty":0.00000000},{"price":3502.38,"qty":26.32482080}],"checksum":3455717435,"timestamp":"2024-06-01T17:52:03.689474Z"}]}
{"channel":"book","type":"update","data":[{"symbol":"ETH/EUR","bids":[],"asks":[{"price":3501.96,"qty":26.32797687}],"checksum":3561163000,"timestamp":"2024-06-01T17:52:03.693673Z"}]}
{"channel":"book","type":"update","data":[{"symbol":"ETH/EUR","bids":[],"asks":[{"price":3501.96,"qty":0.00000000},{"price":3502.38,"qty":26.32482080}],"checksum":3455717435,"timestamp":"2024-06-01T17:52:03.771666Z"}]}
{"channel":"book","type":"update","data":[{"symbol":"ETH/EUR","bids":[],"asks":[{"price":3502.02,"qty":26.32751127}],"checksum":313277162,"timestamp":"2024-06-01T17:52:03.775390Z"}]}
{"channel":"book","type":"update","data":[{"symbol":"ETH/EUR","bids":[],"asks":[{"price":3502.15,"qty":0.00000000},{"price":3502.27,"qty":26.32562553}],"checksum":1031845546,"timestamp":"2024-06-01T17:52:03.831036Z"}]}
{"channel":"book","type":"update","data":[{"symbol":"ETH/EUR","bids":[],"asks":[{"price":3502.01,"qty":26.32757706}],"checksum":779114189,"timestamp":"2024-06-01T17:52:03.834785Z"}]}
{"channel":"book","type":"update","data":[{"symbol":"ETH/EUR","bids":[],"asks":[{"price":3502.01,"qty":0.00000000},{"price":3502.27,"qty":26.32562553}],"checksum":1031845546,"timestamp":"2024-06-01T17:52:03.882038Z"}]}
{"channel":"book","type":"update","data":[{"symbol":"ETH/EUR","bids":[],"asks":[{"price":3502.00,"qty":26.32765864}],"checksum":152989460,"timestamp":"2024-06-01T17:52:03.889309Z"}]}
{"channel":"book","type":"update","data":[{"symbol":"ETH/EUR","bids":[],"asks":[{"price":3502.00,"qty":0.00000000},{"price":3502.27,"qty":26.32562553}],"checksum":1031845546,"timestamp":"2024-06-01T17:52:03.928351Z"}]}
{"channel":"book","type":"update","data":[{"symbol":"ETH/EUR","bids":[],"asks":[{"price":3501.94,"qty":26.32812062}],"checksum":3818984153,"timestamp":"2024-06-01T17:52:04.003812Z"}]}
{"channel":"book","type":"update","data":[{"symbol":"ETH/EUR","bids":[],"asks":[{"price":3501.94,"qty":0.00000000},{"price":3502.27,"qty":26.32562553}],"checksum":1031845546,"timestamp":"2024-06-01T17:52:04.047913Z"}]}
{"channel":"book","type":"update","data":[{"symbol":"ETH/EUR","bids":[],"asks":[{"price":3502.27,"qty":0.00000000},{"price":3502.38,"qty":26.32482080}],"checksum":3563888604,"timestamp":"2024-06-01T17:52:04.105976Z"}]}
{"channel":"book","type":"update","data":[{"symbol":"ETH/EUR","bids":[],"asks":[{"price":3501.91,"qty":26.32834168}],"checksum":125220290,"timestamp":"2024-06-01T17:52:04.109751Z"}]}
{"channel":"book","type":"update","data":[{"symbol":"ETH/EUR","bids":[],"asks":[{"price":3501.91,"qty":0.00000000},{"price":3502.16,"qty":26.32645588}],"checksum":1922874511,"timestamp":"2024-06-01T17:52:04.351198Z"}]}
{"channel":"book","type":"update","data":[{"symbol":"ETH/EUR","bids":[],"asks":[{"price":3501.93,"qty":26.32819694}],"checksum":3563725083,"timestamp":"2024-06-01T17:52:04.355492Z"}]}
{"channel":"book","type":"update","data":[{"symbol":"ETH/EUR","bids":[],"asks":[{"price":3501.93,"qty":0.00000000},{"price":3502.16,"qty":26.32645588}],"checksum":1922874511,"timestamp":"2024-06-01T17:52:04.374771Z"}]}
{"channel":"book","type":"update","data":[{"symbol":"ETH/EUR","bids":[],"asks":[{"price":3501.95,"qty":26.32804956}],"checksum":1242188153,"timestamp":"2024-06-01T17:52:04.487307Z"}]}
{"channel":"book","type":"update","data":[{"symbol":"ETH/EUR","bids":[],"asks":[{"price":3501.95,"qty":0.00000000},{"price":3502.16,"qty":26.32645588}],"checksum":1922874511,"timestamp":"2024-06-01T17:52:04.699870Z"}]}
{"channel":"book","type":"update","data":[{"symbol":"ETH/EUR","bids":[],"asks":[{"price":3501.93,"qty":26.32819694}],"checksum":3563725083,"timestamp":"2024-06-01T17:52:04.704590Z"}]}
{"channel":"book","type":"update","data":[{"symbol":"ETH/EUR","bids":[{"price":3500.62,"qty":7.27644158}],"asks":[],"checksum":1390224810,"timestamp":"2024-06-01T17:52:04.782470Z"}]}
{"channel":"book","type":"update","data":[{"symbol":"ETH/EUR","bids":[],"asks":[{"price":3501.93,"qty":0.00000000},{"price":3502.16,"qty":26.32645588}],"checksum":3377341371,"timestamp":"2024-06-01T17:52:05.092341Z"}]}
{"channel":"book","type":"update","data":[{"symbol":"ETH/EUR","bids":[],"asks":[{"price":3501.95,"qty":26.32803875}],"checksum":2012545050,"timestamp":"2024-06-01T17:52:05.096122Z"}]}
{"channel":"book","type":"update","data":[{"symbol":"ETH/EUR","bids":[],"asks":[{"price":3501.95,"qty":0.00000000},{"price":3502.16,"qty":26.32645588}],"checksum":3377341371,"timestamp":"2024-06-01T17:52:05.219342Z"}]}
{"channel":"book","type":"update","data":[{"symbol":"ETH/EUR","bids":[],"asks":[{"price":3501.94,"qty":26.32810980}],"checksum":4103703388,"timestamp":"2024-06-01T17:52:05.222785Z"}]}
{"channel":"book","type":"update","data":[{"symbol":"ETH/EUR","bids":[],"asks":[{"price":3501.94,"qty":0.00000000},{"price":3502.16,"qty":26.32645588}],"checksum":3377341371,"timestamp":"2024-06-01T17:52:05.312875Z"}]}
{"channel":"book","type":"update","data":[{"symbol":"ETH/EUR","bids":[],"asks":[{"price":3501.96,"qty":26.32796506}],"checksum":1775321870,"timestamp":"2024-06-01T17:52:05.316757Z"}]}
{"channel":"book","type":"update","data":[{"symbol":"ETH/EUR","bids":[{"price":3500.29,"qty":0.00000000},{"price":3500.24,"qty":0.02851621}],"asks":[],"checksum":2976415877,"timestamp":"2024-06-01T17:52:05.402547Z"}]}
{"channel":"book","type":"update","data":[{"symbol":"ETH/EUR","bids":[{"price":3500.47,"qty":0.00000000},{"price":3500.23,"qty":39.51129862}],"asks":[],"checksum":3949195077,"timestamp":"2024-06-01T17:52:05.405090Z"}]}
{"channel":"book","type":"update","data":[{"symbol":"ETH/EUR","bids":[{"price":3500.63,"qty":0.00000000},{"price":3499.86,"qty":3.01305282}],"asks":[],"checksum":3344064614,"timestamp":"2024-06-01T17:52:05.410687Z"}]}
{"channel":"book","type":"update","data":[{"symbol":"ETH/EUR","bids":[],"asks":[{"price":3502.02,"qty":0.00000000},{"price":3502.16,"qty":26.32645588}],"checksum":1801617199,"timestamp":"2024-06-01T17:52:05.414704Z"}]}
{"channel":"book","type":"update","data":[{"symbol":"ETH/EUR","bids":[],"asks":[{"price":3501.96,"qty":0.00000000},{"price":3502.38,"qty":26.32482080}],"checksum":2511072925,"timestamp":"2024-06-01T17:52:05.414759Z"}]}
{"channel":"book","type":"update","data":[{"symbol":"ETH/EUR","bids":[],"asks":[{"price":3502.38,"qty":0.00000000},{"price":3502.45,"qty":0.00220000}],"checksum":2490243806,"timestamp":"2024-06-01T17:52:05.414813Z"}]}
{"channel":"book","type":"update","data":[{"symbol":"ETH/EUR","bids":[{"price":3501.08,"qty":90.58919970}],"asks":[],"checksum":3857097176,"timestamp":"2024-06-01T17:52:05.414866Z"}]}
{"channel":"book","type":"update","data":[{"symbol":"ETH/EUR","bids":[],"asks":[{"price":3502.27,"qty":0.72912968}],"checksum":4164503625,"timestamp":"2024-06-01T17:52:05.414934Z"}]}
{"channel":"book","type":"update","data":[{"symbol":"ETH/EUR","bids":[{"price":3500.23,"qty":0.00000000},{"price":3499.37,"qty":1.05333347}],"asks":[],"checksum":27772428,"timestamp":"2024-06-01T17:52:05.415123Z"}]}
{"channel":"book","type":"update","data":[{"symbol":"ETH/EUR","bids":[],"asks":[{"price":3501.57,"qty":26.33087353}],"checksum":1527535081,"timestamp":"2024-06-01T17:52:05.420431Z"}]}
{"channel":"book","type":"update","data":[{"symbol":"ETH/EUR","bids":[],"asks":[{"price":3501.57,"qty":0.00000000},{"price":3502.27,"qty":0.72912968}],"checksum":27772428,"timestamp":"2024-06-01T17:52:05.431675Z"}]}
{"channel":"book","type":"update","data":[{"symbol":"ETH/EUR","bids":[{"price":3500.93,"qty":0.00000000},{"price":3499.32,"qty":0.55493113}],"asks":[],"checksum":3557244584,"timestamp":"2024-06-01T17:52:05.435326Z"}]}
{"channel":"book","type":"update","data":[{"symbol":"ETH/EUR","bids":[],"asks":[{"price":3501.78,"qty":0.00000000},{"price":3502.45,"qty":3.95520000},{"price":3502.15,"qty":0.00770889}],"checksum":2912392662,"timestamp":"2024-06-01T17:52:05.471360Z"}]}
{"channel":"book","type":"update","data":[{"symbol":"ETH/EUR","bids":[{"price":3500.24,"qty":0.00000000},{"price":3499.31,"qty":70.37242407},{"price":3499.33,"qty":0.02852101}],"asks":[],"checksum":221571666,"timestamp":"2024-06-01T17:52:05.471382Z"}]}
{"channel":"book","type":"update","data":[{"symbol":"ETH/EUR","bids":[],"asks":[{"price":3501.65,"qty":26.33030008}],"checksum":1917557236,"timestamp":"2024-06-01T17:52:05.492421Z"}]}
{"channel":"book","type":"update","data":[{"symbol":"ETH/EUR","bids":[{"price":3500.32,"qty":1.31708923}],"asks":[],"checksum":2221650826,"timestamp":"2024-06-01T17:52:05.494241Z"}]}
{"channel":"book","type":"update","data":[{"symbol":"ETH/EUR","bids":[],"asks":[{"price":3501.65,"qty":0.00000000},{"price":3502.27,"qty":0.72912968}],"checksum":3147942436,"timestamp":"2024-06-01T17:52:05.496083Z"}]}
{"channel":"book","type":"update","data":[{"symbol":"ETH/EUR","bids":[{"price":3500.09,"qty":1.07700000}],"asks":[],"checksum":933678687,"timestamp":"2024-06-01T17:52:05.501101Z"}]}
{"channel":"book","type":"update","data":[{"symbol":"ETH/EUR","bids":[{"price":3500.33,"qty":0.65955913}],"asks":[],"checksum":2186050460,"timestamp":"2024-06-01T17:52:05.527603Z"}]}
{"channel":"book","type":"update","data":[{"symbol":"ETH/EUR","bids":[{"price":3500.93,"qty":1.35356069}],"asks":[],"checksum":1295892661,"timestamp":"2024-06-01T17:52:05.560029Z"}]}
{"channel":"book","type":"update","data":[{"symbol":"ETH/EUR","bids":[{"price":3501.08,"qty":90.50361370},{"price":3500.68,"qty":0.08559000}],"asks":[],"checksum":1623230970,"timestamp":"2024-06-01T17:52:05.631487Z"}]}
{"channel":"book","type":"update","data":[{"symbol":"ETH/EUR","bids":[],"asks":[{"price":3501.75,"qty":26.32957393}],"checksum":3500208092,"timestamp":"2024-06-01T17:52:05.708866Z"}]}
{"channel":"book","type":"update","data":[{"symbol":"ETH/EUR","bids":[],"asks":[{"price":3501.67,"qty":26.33015743}],"checksum":3202643467,"timestamp":"2024-06-01T17:52:05.708960Z"}]}
{"channel":"book","type":"update","data":[{"symbol":"ETH/EUR","bids":[],"asks":[{"price":3501.75,"qty":0.00000000},{"price":3502.16,"qty":26.32645588}],"checksum":3301980005,"timestamp":"2024-06-01T17:52:05.910233Z"}]}
{"channel":"book","type":"update","data":[{"symbol":"ETH/EUR","bids":[],"asks":[{"price":3501.64,"qty":26.33040009}],"checksum":2340977059,"timestamp":"2024-06-01T17:52:05.914464Z"}]}
{"channel":"book","type":"update","data":[{"symbol":"ETH/EUR","bids":[],"asks":[{"price":3501.64,"qty":0.00000000},{"price":3502.16,"qty":26.32645588}],"checksum":3301980005,"timestamp":"2024-06-01T17:52:06.078909Z"}]}
{"channel":"book","type":"update","data":[{"symbol":"ETH/EUR","bids":[],"asks":[{"price":3501.63,"qty":26.33046012}],"checksum":434411261,"timestamp":"2024-06-01T17:52:06.082779Z"}]}
{"channel":"book","type":"update","data":[{"symbol":"ETH/EUR","bids":[{"price":3501.08,"qty":86.50361370}],"asks":[],"checksum":1752972890,"timestamp":"2024-06-01T17:52:06.169926Z"}]}
{"channel":"book","type":"update","data":[{"symbol":"ETH/EUR","bids":[],"asks":[{"price":3501.63,"qty":0.00000000},{"price":3502.16,"qty":26.32645588}],"checksum":3041435586,"timestamp":"2024-06-01T17:52:06.410256Z"}]}
{"channel":"book","type":"update","data":[{"symbol":"ETH/EUR","bids":[],"asks":[{"price":3501.61,"qty":26.33057856}],"checksum":384270763,"timestamp":"2024-06-01T17:52:06.413766Z"}]}
{"channel":"book","type":"update","data":[{"symbol":"ETH/EUR","bids":[],"asks":[{"price":3501.61,"qty":0.00000000},{"price":3502.16,"qty":26.32645588}],"checksum":3041435586,"timestamp":"2024-06-01T17:52:06.591067Z"}]}
{"channel":"book","type":"update","data":[{"symbol":"ETH/EUR","bids":[],"asks":[{"price":3501.66,"qty":26.33022302}],"checksum":469808483,"timestamp":"2024-06-01T17:52:06.595494Z"}]}
{"channel":"book","type":"update","data":[{"symbol":"ETH/EUR","bids":[{"price":3500.90,"qty":26.33584919}],"asks":[],"checksum":1550314488,"timestamp":"2024-06-01T17:52:06.595516Z"}]}
{"channel":"book","type":"update","data":[{"symbol":"ETH/EUR","bids":[],"asks":[{"price":3501.66,"qty":0.00000000},{"price":3502.16,"qty":26.32645588}],"checksum":4246679724,"timestamp":"2024-06-01T17:52:06.638736Z"}]}
{"channel":"book","type":"update","data":[{"symbol":"ETH/EUR","bids":[],"asks":[{"price":3501.63,"qty":26.33044673}],"checksum":3026613800,"timestamp":"2024-06-01T17:52:06.689099Z"}]}
{"channel":"book","type":"update","data":[{"symbol":"ETH/EUR","bids":[{"price":3500.91,"qty":0.02850271}],"asks":[],"checksum":2030427203,"timestamp":"2024-06-01T17:52:07.102766Z"}]}
{"channel":"book","type":"update","data":[{"symbol":"ETH/EUR","bids":[],"asks":[{"price":3501.63,"qty":0.00000000},{"price":3502.16,"qty":26.32645588}],"checksum":1761875365,"timestamp":"2024-06-01T17:52:07.559605Z"}]}
{"channel":"book","type":"update","data":[{"symbol":"ETH/EUR","bids":[],"asks":[{"price":3501.65,"qty":26.33025695}],"checksum":4153061685,"timestamp":"2024-06-01T17:52:07.563997Z"}]}
{"channel":"book","type":"update","data":[{"symbol":"ETH/EUR","bids":[],"asks":[{"price":3501.65,"qty":0.00000000},{"price":3502.16,"qty":26.32645588}],"checksum":1761875365,"timestamp":"2024-06-01T17:52:08.271951Z"}]}
{"channel":"book","type":"update","data":[{"symbol":"ETH/EUR","bids":[],"asks":[{"price":3501.64,"qty":26.33039184}],"checksum":2117287050,"timestamp":"2024-06-01T17:52:08.277285Z"}]}
{"channel":"book","type":"update","data":[{"symbol":"ETH/EUR","bids":[],"asks":[{"price":3501.64,"qty":0.00000000},{"price":3502.16,"qty":26.32645588}],"checksum":1761875365,"timestamp":"2024-06-01T17:52:08.871897Z"}]}
{"channel":"book","type":"update","data":[{"symbol":"ETH/EUR","bids":[],"asks":[{"price":3501.75,"qty":26.32955876}],"checksum":3592020271,"timestamp":"2024-06-01T17:52:08.875856Z"}]}
{"channel":"book","type":"update","data":[{"symbol":"ETH/EUR","bids":[],"asks":[{"price":3501.93,"qty":26.32816833}],"checksum":2705460680,"timestamp":"2024-06-01T17:52:08.876039Z"}]}
{"channel":"book","type":"update","data":[{"symbol":"ETH/EUR","bids":[],"asks":[{"price":3501.92,"qty":0.00770105}],"checksum":3560897634,"timestamp":"2024-06-01T17:52:08.936744Z"}]}
{"channel":"book","type":"update","data":[{"symbol":"ETH/EUR","bids":[{"price":3500.68,"qty":0.00000000},{"price":3500.33,"qty":0.65955913},{"price":3500.94,"qty":0.08558900}],"asks":[],"checksum":914544221,"timestamp":"2024-06-01T17:52:09.047157Z"}]}
{"channel":"book","type":"update","data":[{"symbol":"ETH/EUR","bids":[],"asks":[{"price":3501.75,"qty":0.00000000},{"price":3502.09,"qty":0.08557600}],"checksum":2728670569,"timestamp":"2024-06-01T17:52:09.190640Z"}]}
{"channel":"book","type":"update","data":[{"symbol":"ETH/EUR","bids":[],"asks":[{"price":3501.64,"qty":26.33037816}],"checksum":741761443,"timestamp":"2024-06-01T17:52:09.194476Z"}]}
{"channel":"book","type":"update","data":[{"symbol":"ETH/EUR","bids":[],"asks":[{"price":3501.64,"qty":0.00000000},{"price":3502.09,"qty":0.08557600}],"checksum":2728670569,"timestamp":"2024-06-01T17:52:09.391785Z"}]}
{"channel":"book","type":"update","data":[{"symbol":"ETH/EUR","bids":[],"asks":[{"price":3501.62,"qty":26.33047681}],"checksum":3612865488,"timestamp":"2024-06-01T17:52:09.395672Z"}]}
{"channel":"book","type":"update","data":[{"symbol":"ETH/EUR","bids":[],"asks":[{"price":3501.62,"qty":0.00000000},{"price":3502.09,"qty":0.08557600}],"checksum":2728670569,"timestamp":"2024-06-01T17:52:09.402088Z"}]}
{"channel":"book","type":"update","data":[{"symbol":"ETH/EUR","bids":[],"asks":[{"price":3501.66,"qty":26.33020369}],"checksum":2842739148,"timestamp":"2024-06-01T17:52:09.455821Z"}]}
{"channel":"book","type":"update","data":[{"symbol":"ETH/EUR","bids":[],"asks":[{"price":3501.66,"qty":0.00000000},{"price":3502.09,"qty":0.08557600}],"checksum":2728670569,"timestamp":"2024-06-01T17:52:09.651314Z"}]}
{"channel":"book","type":"update","data":[{"symbol":"ETH/EUR","bids":[],"asks":[{"price":3501.69,"qty":26.32998261}],"checksum":1892198506,"timestamp":"2024-06-01T17:52:09.655180Z"}]}
{"channel":"book","type":"update","data":[{"symbol":"ETH/EUR","bids":[],"asks":[{"price":3501.67,"qty":0.00000000},{"price":3502.09,"qty":0.08557600}],"checksum":3308659171,"timestamp":"2024-06-01T17:52:09.871015Z"}]}
{"channel":"book","type":"update","data":[{"symbol":"ETH/EUR","bids":[],"asks":[{"price":3501.62,"qty":26.33055181}],"checksum":3452602244,"timestamp":"2024-06-01T17:52:09.875182Z"}]}
{"channel":"book","type":"update","data":[{"symbol":"ETH/EUR","bids":[],"asks":[{"price":3501.73,"qty":0.08558000}],"checksum":576592265,"timestamp":"2024-06-01T17:52:09.886822Z"}]}
{"channel":"book","type":"update","data":[{"symbol":"ETH/EUR","bids":[],"asks":[{"price":3501.62,"qty":0.00000000},{"price":3502.08,"qty":0.00220000}],"checksum":1186073689,"timestamp":"2024-06-01T17:52:09.929541Z"}]}
{"channel":"book","type":"update","data":[{"symbol":"ETH/EUR","bids":[],"asks":[{"price":3501.64,"qty":26.33037810}],"checksum":1448643449,"timestamp":"2024-06-01T17:52:09.933223Z"}]}
{"channel":"book","type":"update","data":[{"symbol":"ETH/EUR","bids":[],"asks":[{"price":3501.64,"qty":0.00000000},{"price":3502.08,"qty":0.00220000}],"checksum":1186073689,"timestamp":"2024-06-01T17:52:09.987405Z"}]}
{"channel":"book","type":"update","data":[{"symbol":"ETH/EUR","bids":[],"asks":[{"price":3501.66,"qty":26.33020878}],"checksum":806073709,"timestamp":"2024-06-01T17:52:09.990361Z"}]}
{"channel":"book","type":"update","data":[{"symbol":"ETH/EUR","bids":[],"asks":[{"price":3501.66,"qty":0.00000000},{"price":3502.08,"qty":0.00220000}],"checksum":1186073689,"timestamp":"2024-06-01T17:52:10.122261Z"}]}
{"channel":"book","type":"update","data":[{"symbol":"ETH/EUR","bids":[],"asks":[{"price":3501.64,"qty":26.33034564}],"checksum":1830710157,"timestamp":"2024-06-01T17:52:10.126219Z"}]}
{"channel":"book","type":"update","data":[{"symbol":"ETH/EUR","bids":[],"asks":[{"price":3501.64,"qty":0.00000000},{"price":3502.08,"qty":0.00220000}],"checksum":1186073689,"timestamp":"2024-06-01T17:52:10.230494Z"}]}
{"channel":"book","type":"update","data":[{"symbol":"ETH/EUR","bids":[],"asks":[{"price":3501.64,"qty":26.33038132}],"checksum":535935455,"timestamp":"2024-06-01T17:52:10.237063Z"}]}
{"channel":"book","type":"update","data":[{"symbol":"ETH/EUR","bids":[],"asks":[{"price":3501.64,"qty":0.00000000},{"price":3502.08,"qty":0.00220000}],"checksum":1186073689,"timestamp":"2024-06-01T17:52:10.315684Z"}]}
{"channel":"book","type":"update","data":[{"symbol":"ETH/EUR","bids":[],"asks":[{"price":3501.62,"qty":26.33048133}],"checksum":1949948258,"timestamp":"2024-06-01T17:52:10.319742Z"}]}
{"channel":"book","type":"update","data":[{"symbol":"ETH/EUR","bids":[],"asks":[{"price":3501.62,"qty":0.00000000},{"price":3502.08,"qty":0.00220000}],"checksum":1186073689,"timestamp":"2024-06-01T17:52:10.578942Z"}]}
{"channel":"book","type":"update","data":[{"symbol":"ETH/EUR","bids":[],"asks":[{"price":3501.64,"qty":26.33033394}],"checksum":3837817980,"timestamp":"2024-06-01T17:52:10.583018Z"}]}
{"channel":"book","type":"update","data":[{"symbol":"ETH/EUR","bids":[],"asks":[{"price":3501.64,"qty":0.00000000},{"price":3502.08,"qty":0.00220000}],"checksum":1186073689,"timestamp":"2024-06-01T17:52:10.967231Z"}]}
{"channel":"book","type":"update","data":[{"symbol":"ETH/EUR","bids":[],"asks":[{"price":3501.67,"qty":26.33015535}],"checksum":3666150168,"timestamp":"2024-06-01T17:52:10.971449Z"}]}
{"channel":"book","type":"update","data":[{"symbol":"ETH/EUR","bids":[],"asks":[{"price":3501.67,"qty":0.00000000},{"price":3502.08,"qty":0.00220000}],"checksum":1186073689,"timestamp":"2024-06-01T17:52:11.005327Z"}]}
{"channel":"book","type":"update","data":[{"symbol":"ETH/EUR","bids":[],"asks":[{"price":3501.63,"qty":26.33040802}],"checksum":3835396578,"timestamp":"2024-06-01T17:52:11.068620Z"}]}
{"channel":"book","type":"update","data":[{"symbol":"ETH/EUR","bids":[],"asks":[{"price":3501.63,"qty":0.00000000},{"price":3502.08,"qty":0.00220000}],"checksum":1186073689,"timestamp":"2024-06-01T17:52:11.225859Z"}]}
{"channel":"book","type":"update","data":[{"symbol":"ETH/EUR","bids":[],"asks":[{"price":3501.62,"qty":26.33050803}],"checksum":2612167410,"timestamp":"2024-06-01T17:52:11.229624Z"}]}
{"channel":"book","type":"update","data":[{"symbol":"ETH/EUR","bids":[],"asks":[{"price":3501.62,"qty":0.00000000},{"price":3502.08,"qty":0.00220000}],"checksum":1186073689,"timestamp":"2024-06-01T17:52:11.330780Z"}]}
{"channel":"book","type":"update","data":[{"symbol":"ETH/EUR","bids":[],"asks":[{"price":3501.64,"qty":26.33036558}],"checksum":2806497841,"timestamp":"2024-06-01T17:52:11.334583Z"}]}
{"channel":"book","type":"update","data":[{"symbol":"ETH/EUR","bids":[],"asks":[{"price":3501.64,"qty":0.00000000},{"price":3502.08,"qty":0.00220000}],"checksum":1186073689,"timestamp":"2024-06-01T17:52:11.608554Z"}]}
{"channel":"book","type":"update","data":[{"symbol":"ETH/EUR","bids":[],"asks":[{"price":3501.67,"qty":26.33017081}],"checksum":239822162,"timestamp":"2024-06-01T17:52:11.613106Z"}]}
{"channel":"book","type":"update","data":[{"symbol":"ETH/EUR","bids":[],"asks":[{"price":3501.67,"qty":0.00000000},{"price":3502.08,"qty":0.00220000}],"checksum":1186073689,"timestamp":"2024-06-01T17:52:11.628950Z"}]}
{"channel":"book","type":"update","data":[{"symbol":"ETH/EUR","bids":[],"asks":[{"price":3501.65,"qty":26.33031030}],"checksum":2768157478,"timestamp":"2024-06-01T17:52:11.681230Z"}]}
{"channel":"book","type":"update","data":[{"symbol":"ETH/EUR","bids":[],"asks":[{"price":3501.65,"qty":0.00000000},{"price":3502.08,"qty":0.00220000}],"checksum":1186073689,"timestamp":"2024-06-01T17:52:12.046326Z"}]}
{"channel":"book","type":"update","data":[{"symbol":"ETH/EUR","bids":[],"asks":[{"price":3501.63,"qty":26.33042769}],"checksum":91577497,"timestamp":"2024-06-01T17:52:12.050323Z"}]}
{"channel":"book","type":"update","data":[{"symbol":"ETH/EUR","bids":[],"asks":[{"price":3501.63,"qty":0.00000000},{"price":3502.08,"qty":0.00220000}],"checksum":1186073689,"timestamp":"2024-06-01T17:52:12.140744Z"}]}
{"channel":"book","type":"update","data":[{"symbol":"ETH/EUR","bids":[],"asks":[{"price":3501.65,"qty":26.33029609}],"checksum":3913525871,"timestamp":"2024-06-01T17:52:12.144551Z"}]}
{"channel":"book","type":"update","data":[{"symbol":"ETH/EUR","bids":[],"asks":[{"price":3501.65,"qty":0.00000000},{"price":3502.08,"qty":0.00220000}],"checksum":1186073689,"timestamp":"2024-06-01T17:52:12.349093Z"}]}
{"channel":"book","type":"update","data":[{"symbol":"ETH/EUR","bids":[],"asks":[{"price":3501.63,"qty":26.33044085}],"checksum":4230432608,"timestamp":"2024-06-01T17:52:12.352803Z"}]}
{"channel":"book","type":"update","data":[{"symbol":"ETH/EUR","bids":[],"asks":[{"price":3501.63,"qty":0.00000000},{"price":3502.08,"qty":0.00220000}],"checksum":1186073689,"timestamp":"2024-06-01T17:52:12.523595Z"}]}
{"channel":"book","type":"update","data":[{"symbol":"ETH/EUR","bids":[],"asks":[{"price":3501.62,"qty":26.33054415}],"checksum":1397358250,"timestamp":"2024-06-01T17:52:12.527305Z"}]}
{"channel":"book","type":"update","data":[{"symbol":"ETH/EUR","bids":[],"asks":[{"price":3501.62,"qty":0.00000000},{"price":3502.08,"qty":0.00220000}],"checksum":1186073689,"timestamp":"2024-06-01T17:52:12.693239Z"}]}
{"channel":"book","type":"update","data":[{"symbol":"ETH/EUR","bids":[],"asks":[{"price":3501.64,"qty":26.33034938}],"checksum":2465134415,"timestamp":"2024-06-01T17:52:12.696753Z"}]}
{"channel":"book","type":"update","data":[{"symbol":"ETH/EUR","bids":[],"asks":[{"price":3501.64,"qty":0.00000000},{"price":3502.08,"qty":0.00220000}],"checksum":1186073689,"timestamp":"2024-06-01T17:52:12.721941Z"}]}
{"channel":"book","type":"update","data":[{"symbol":"ETH/EUR","bids":[],"asks":[{"price":3501.66,"qty":26.33018883}],"checksum":783805123,"timestamp":"2024-06-01T17:52:12.768234Z"}]}
{"channel":"book","type":"update","data":[{"symbol":"ETH/EUR","bids":[],"asks":[{"price":3501.66,"qty":0.00000000},{"price":3502.08,"qty":0.00220000}],"checksum":1186073689,"timestamp":"2024-06-01T17:52:13.107621Z"}]}
{"channel":"book","type":"update","data":[{"symbol":"ETH/EUR","bids":[],"asks":[{"price":3501.63,"qty":26.33041101}],"checksum":1891313010,"timestamp":"2024-06-01T17:52:13.112528Z"}]}
{"channel":"book","type":"update","data":[{"symbol":"ETH/EUR","bids":[],"asks":[{"price":3501.63,"qty":0.00000000},{"price":3502.08,"qty":0.00220000}],"checksum":1186073689,"timestamp":"2024-06-01T17:52:13.230300Z"}]}
{"channel":"book","type":"update","data":[{"symbol":"ETH/EUR","bids":[],"asks":[{"price":3501.66,"qty":26.33018203}],"checksum":3943060556,"timestamp":"2024-06-01T17:52:13.234031Z"}]}
{"channel":"book","type":"update","data":[{"symbol":"ETH/EUR","bids":[],"asks":[{"price":3501.66,"qty":0.00000000},{"price":3502.08,"qty":0.00220000}],"checksum":1186073689,"timestamp":"2024-06-01T17:52:13.271755Z"}]}
{"channel":"book","type":"update","data":[{"symbol":"ETH/EUR","bids":[],"asks":[{"price":3501.65,"qty":26.33032416}],"checksum":2953189050,"timestamp":"2024-06-01T17:52:13.585018Z"}]}
{"channel":"book","type":"update","data":[{"symbol":"ETH/EUR","bids":[],"asks":[{"price":3501.65,"qty":0.00000000},{"price":3502.08,"qty":0.00220000}],"checksum":1186073689,"timestamp":"2024-06-01T17:52:14.016897Z"}]}
{"channel":"book","type":"update","data":[{"symbol":"ETH/EUR","bids":[],"asks":[{"price":3501.76,"qty":26.32944431}],"checksum":2817539469,"timestamp":"2024-06-01T17:52:14.021070Z"}]}
{"channel":"book","type":"update","data":[{"symbol":"ETH/EUR","bids":[],"asks":[{"price":3501.69,"qty":0.00000000},{"price":3502.08,"qty":0.00220000}],"checksum":3831749880,"timestamp":"2024-06-01T17:52:14.050753Z"}]}
{"channel":"book","type":"update","data":[{"symbol":"ETH/EUR","bids":[],"asks":[{"price":3501.74,"qty":26.32957524}],"checksum":3141576223,"timestamp":"2024-06-01T17:52:14.054647Z"}]}
{"channel":"book","type":"update","data":[{"symbol":"ETH/EUR","bids":[],"asks":[{"price":3501.92,"qty":0.00000000},{"price":3502.08,"qty":0.00220000},{"price":3501.75,"qty":0.00770664}],"checksum":490729585,"timestamp":"2024-06-01T17:52:14.087565Z"}]}
{"channel":"book","type":"update","data":[{"symbol":"ETH/EUR","bids":[],"asks":[{"price":3501.74,"qty":0.00000000},{"price":3502.08,"qty":0.00220000}],"checksum":636965370,"timestamp":"2024-06-01T17:52:14.207790Z"}]}
{"channel":"book","type":"update","data":[{"symbol":"ETH/EUR","bids":[],"asks":[{"price":3501.76,"qty":0.00000000},{"price":3502.16,"qty":26.32645588}],"checksum":735683217,"timestamp":"2024-06-01T17:52:14.207883Z"}]}
{"channel":"book","type":"update","data":[{"symbol":"ETH/EUR","bids":[],"asks":[{"price":3502.05,"qty":26.32730483}],"checksum":3819637468,"timestamp":"2024-06-01T17:52:14.211507Z"}]}
{"channel":"book","type":"update","data":[{"symbol":"ETH/EUR","bids":[],"asks":[{"price":3501.80,"qty":26.32916273}],"checksum":676061749,"timestamp":"2024-06-01T17:52:14.211549Z"}]}
{"channel":"book","type":"update","data":[{"symbol":"ETH/EUR","bids":[],"asks":[{"price":3501.93,"qty":0.00000000},{"price":3502.08,"qty":0.00220000}],"checksum":1578946505,"timestamp":"2024-06-01T17:52:14.222836Z"}]}
{"channel":"book","type":"update","data":[{"symbol":"ETH/EUR","bids":[],"asks":[{"price":3501.76,"qty":26.32945222}],"checksum":579333712,"timestamp":"2024-06-01T17:52:14.295622Z"}]}
{"channel":"book","type":"update","data":[{"symbol":"ETH/EUR","bids":[],"asks":[{"price":3501.76,"qty":0.00000000},{"price":3502.08,"qty":0.00220000}],"checksum":1578946505,"timestamp":"2024-06-01T17:52:14.321521Z"}]}
{"channel":"book","type":"update","data":[{"symbol":"ETH/EUR","bids":[],"asks":[{"price":3501.78,"qty":26.32930748}],"checksum":3717137807,"timestamp":"2024-06-01T17:52:14.376944Z"}]}
{"channel":"book","type":"update","data":[{"symbol":"ETH/EUR","bids":[],"asks":[{"price":3501.75,"qty":0.00000000},{"price":3502.08,"qty":0.00220000},{"price":3501.72,"qty":0.00770664}],"checksum":3378705388,"timestamp":"2024-06-01T17:52:14.451362Z"}]}
{"channel":"book","type":"update","data":[{"symbol":"ETH/EUR","bids":[],"asks":[{"price":3501.78,"qty":0.00000000},{"price":3502.08,"qty":0.00220000}],"checksum":1239302639,"timestamp":"2024-06-01T17:52:14.474835Z"}]}
{"channel":"book","type":"update","data":[{"symbol":"ETH/EUR","bids":[],"asks":[{"price":3501.76,"qty":26.32944433}],"checksum":1300221287,"timestamp":"2024-06-01T17:52:14.479685Z"}]}
{"channel":"book","type":"update","data":[{"symbol":"ETH/EUR","bids":[],"asks":[{"price":3501.76,"qty":0.00000000},{"price":3502.08,"qty":0.00220000}],"checksum":1239302639,"timestamp":"2024-06-01T17:52:14.567846Z"}]}
{"channel":"book","type":"update","data":[{"symbol":"ETH/EUR","bids":[],"asks":[{"price":3501.74,"qty":26.32957592}],"checksum":2945942127,"timestamp":"2024-06-01T17:52:14.572023Z"}]}
{"channel":"book","type":"update","data":[{"symbol":"ETH/EUR","bids":[],"asks":[{"price":3501.78,"qty":2.60751233}],"checksum":2667123113,"timestamp":"2024-06-01T17:52:14.650082Z"}]}
{"channel":"book","type":"update","data":[{"symbol":"ETH/EUR","bids":[],"asks":[{"price":3501.79,"qty":6.37182945}],"checksum":662633792,"timestamp":"2024-06-01T17:52:14.650173Z"}]}
{"channel":"book","type":"update","data":[{"symbol":"ETH/EUR","bids":[],"asks":[{"price":3501.74,"qty":0.00000000},{"price":3502.04,"qty":34.66212950}],"checksum":151569001,"timestamp":"2024-06-01T17:52:14.654202Z"}]}
{"channel":"book","type":"update","data":[{"symbol":"ETH/EUR","bids":[],"asks":[{"price":3501.77,"qty":26.32938380}],"checksum":3133877196,"timestamp":"2024-06-01T17:52:14.658284Z"}]}
{"channel":"book","type":"update","data":[{"symbol":"ETH/EUR","bids":[],"asks":[{"price":3501.77,"qty":0.00000000},{"price":3502.04,"qty":34.66212950}],"checksum":151569001,"timestamp":"2024-06-01T17:52:14.688341Z"}]}
{"channel":"book","type":"update","data":[{"symbol":"ETH/EUR","bids":[],"asks":[{"price":3501.78,"qty":28.93681981}],"checksum":2160310198,"timestamp":"2024-06-01T17:52:14.781478Z"}]}
{"channel":"book","type":"update","data":[{"symbol":"ETH/EUR","bids":[],"asks":[{"price":3501.78,"qty":2.60751233}],"checksum":151569001,"timestamp":"2024-06-01T17:52:14.785566Z"}]}
{"channel":"book","type":"update","data":[{"symbol":"ETH/EUR","bids":[],"asks":[{"price":3501.75,"qty":26.32956313}],"checksum":3584244660,"timestamp":"2024-06-01T17:52:14.875437Z"}]}
{"channel":"book","type":"update","data":[{"symbol":"ETH/EUR","bids":[],"asks":[{"price":3501.75,"qty":0.00000000},{"price":3502.04,"qty":34.66212950}],"checksum":151569001,"timestamp":"2024-06-01T17:52:14.904846Z"}]}
{"channel":"book","type":"update","data":[{"symbol":"ETH/EUR","bids":[],"asks":[{"price":3501.75,"qty":26.32953372}],"checksum":3338375258,"timestamp":"2024-06-01T17:52:15.106369Z"}]}
{"channel":"book","type":"update","data":[{"symbol":"ETH/EUR","bids":[],"asks":[{"price":3501.75,"qty":0.00000000},{"price":3502.04,"qty":34.66212950}],"checksum":151569001,"timestamp":"2024-06-01T17:52:15.146259Z"}]}
{"channel":"book","type":"update","data":[{"symbol":"ETH/EUR","bids":[],"asks":[{"price":3501.77,"qty":26.32940476}],"checksum":2183725021,"timestamp":"2024-06-01T17:52:15.163435Z"}]}
{"channel":"book","type":"update","data":[{"symbol":"ETH/EUR","bids":[],"asks":[{"price":3501.72,"qty":0.00000000},{"price":3502.04,"qty":34.66212950},{"price":3501.76,"qty":0.00770653}],"checksum":2652186839,"timestamp":"2024-06-01T17:52:15.324520Z"}]}
{"channel":"book","type":"update","data":[{"symbol":"ETH/EUR","bids":[],"asks":[{"price":3501.79,"qty":5.72855529}],"checksum":3255751355,"timestamp":"2024-06-01T17:52:15.355684Z"}]}
{"channel":"book","type":"update","data":[{"symbol":"ETH/EUR","bids":[],"asks":[{"price":3501.77,"qty":0.00000000},{"price":3502.04,"qty":34.66212950}],"checksum":507024678,"timestamp":"2024-06-01T17:52:15.361444Z"}]}
{"channel":"book","type":"update","data":[{"symbol":"ETH/EUR","bids":[],"asks":[{"price":3501.80,"qty":0.00000000},{"price":3502.05,"qty":26.32730483}],"checksum":1747053602,"timestamp":"2024-06-01T17:52:15.363789Z"}]}
{"channel":"book","type":"update","data":[{"symbol":"ETH/EUR","bids":[{"price":3500.90,"qty":0.00000000},{"price":3500.33,"qty":0.65955913}],"asks":[],"checksum":887455167,"timestamp":"2024-06-01T17:52:15.363813Z"}]}
{"channel":"book","type":"update","data":[{"symbol":"ETH/EUR","bids":[],"asks":[{"price":3501.82,"qty":26.32898885}],"checksum":467116314,"timestamp":"2024-06-01T17:52:15.368701Z"}]}
{"channel":"book","type":"update","data":[{"symbol":"ETH/EUR","bids":[],"asks":[{"price":3501.82,"qty":0.00000000},{"price":3502.05,"qty":26.32730483}],"checksum":887455167,"timestamp":"2024-06-01T17:52:15.373593Z"}]}
{"channel":"book","type":"update","data":[{"symbol":"ETH/EUR","bids":[],"asks":[{"price":3502.05,"qty":0.00000000},{"price":3502.08,"qty":0.00220000}],"checksum":2655851827,"timestamp":"2024-06-01T17:52:15.377308Z"}]}
{"channel":"book","type":"update","data":[{"symbol":"ETH/EUR","bids":[{"price":3501.08,"qty":93.08815582}],"asks":[],"checksum":4070825974,"timestamp":"2024-06-01T17:52:15.393036Z"}]}
{"channel":"book","type":"update","data":[{"symbol":"ETH/EUR","bids":[{"price":3501.08,"qty":93.93459664}],"asks":[],"checksum":306913959,"timestamp":"2024-06-01T17:52:15.428733Z"}]}
{"channel":"book","type":"update","data":[{"symbol":"ETH/EUR","bids":[{"price":3500.91,"qty":0.00000000},{"price":3500.32,"qty":1.31708923}],"asks":[],"checksum":3399720452,"timestamp":"2024-06-01T17:52:15.432819Z"}]}
{"channel":"book","type":"update","data":[{"symbol":"ETH/EUR","bids":[],"asks":[{"price":3501.76,"qty":0.00000000},{"price":3502.22,"qty":26.32602356},{"price":3501.77,"qty":0.00770653}],"checksum":1035705440,"timestamp":"2024-06-01T17:52:15.432897Z"}]}
{"channel":"book","type":"update","data":[{"symbol":"ETH/EUR","bids":[{"price":3500.67,"qty":0.00000000},{"price":3500.00,"qty":0.02852461}],"asks":[],"checksum":3055348992,"timestamp":"2024-06-01T17:52:15.433811Z"}]}
{"channel":"book","type":"update","data":[{"symbol":"ETH/EUR","bids":[],"asks":[{"price":3501.79,"qty":0.00000000},{"price":3502.18,"qty":26.32627625}],"checksum":4004858130,"timestamp":"2024-06-01T17:52:15.473616Z"}]}
{"channel":"book","type":"update","data":[{"symbol":"ETH/EUR","bids":[{"price":3500.03,"qty":0.30672660}],"asks":[],"checksum":3843710425,"timestamp":"2024-06-01T17:52:15.474333Z"}]}
{"channel":"book","type":"update","data":[{"symbol":"ETH/EUR","bids":[],"asks":[{"price":3502.18,"qty":0.00000000},{"price":3502.22,"qty":26.32602356}],"checksum":766540925,"timestamp":"2024-06-01T17:52:15.475134Z"}]}
{"channel":"book","type":"update","data":[{"symbol":"ETH/EUR","bids":[],"asks":[{"price":3501.78,"qty":0.00000000},{"price":3502.38,"qty":0.60943644}],"checksum":1846922741,"timestamp":"2024-06-01T17:52:15.475223Z"}]}
{"channel":"book","type":"update","data":[{"symbol":"ETH/EUR","bids":[{"price":3500.65,"qty":0.00000000},{"price":3500.00,"qty":0.02852461}],"asks":[],"checksum":224926353,"timestamp":"2024-06-01T17:52:15.475820Z"}]}
{"channel":"book","type":"update","data":[{"symbol":"ETH/EUR","bids":[],"asks":[{"price":3501.73,"qty":0.00000000},{"price":3502.39,"qty":3.01305282},{"price":3502.09,"qty":0.08557600}],"checksum":1138037502,"timestamp":"2024-06-01T17:52:15.488573Z"}]}
{"channel":"book","type":"update","data":[{"symbol":"ETH/EUR","bids":[],"asks":[{"price":3501.09,"qty":0.00000000},{"price":3502.39,"qty":3.01305282},{"price":3501.48,"qty":0.00000000},{"price":3502.45,"qty":0.00220000},{"price":3501.55,"qty":0.00000000},{"price":3502.46,"qty":1.09100000},{"price":3501.77,"qty":0.00118045}],"checksum":3001488879,"timestamp":"2024-06-01T17:52:15.490882Z"}]}
{"channel":"book","type":"update","data":[{"symbol":"ETH/EUR","bids":[{"price":3501.08,"qty":67.60005874}],"asks":[],"checksum":2919558280,"timestamp":"2024-06-01T17:52:15.497325Z"}]}
{"channel":"book","type":"update","data":[{"symbol":"ETH/EUR","bids":[{"price":3501.08,"qty":41.26552084}],"asks":[],"checksum":1967101010,"timestamp":"2024-06-01T17:52:15.497365Z"}]}
{"channel":"book","type":"update","data":[{"symbol":"ETH/EUR","bids":[{"price":3501.08,"qty":15.18098294}],"asks":[],"checksum":2997947497,"timestamp":"2024-06-01T17:52:15.497524Z"}]}
{"channel":"book","type":"update","data":[{"symbol":"ETH/EUR","bids":[{"price":3500.49,"qty":3.95300000}],"asks":[],"checksum":2402741780,"timestamp":"2024-06-01T17:52:15.501022Z"}]}
{"channel":"book","type":"update","data":[{"symbol":"ETH/EUR","bids":[{"price":3500.04,"qty":0.52710000}],"asks":[],"checksum":107327177,"timestamp":"2024-06-01T17:52:15.501594Z"}]}
{"channel":"book","type":"update","data":[{"symbol":"ETH/EUR","bids":[],"asks":[{"price":3502.20,"qty":26.32617248}],"checksum":3202794869,"timestamp":"2024-06-01T17:52:15.502987Z"}]}
{"channel":"book","type":"update","data":[{"symbol":"ETH/EUR","bids":[],"asks":[{"price":3501.77,"qty":0.00000000},{"price":3502.46,"qty":1.09100000},{"price":3502.03,"qty":0.00770653}],"checksum":3526782022,"timestamp":"2024-06-01T17:52:15.508794Z"}]}
{"channel":"book","type":"update","data":[{"symbol":"ETH/EUR","bids":[],"asks":[{"price":3502.39,"qty":0.00000000},{"price":3502.46,"qty":1.09100000}],"checksum":3039090075,"timestamp":"2024-06-01T17:52:15.512291Z"}]}
{"channel":"book","type":"update","data":[{"symbol":"ETH/EUR","bids":[{"price":3501.09,"qty":6.00000000}],"asks":[],"checksum":587039021,"timestamp":"2024-06-01T17:52:15.513920Z"}]}
{"channel":"book","type":"update","data":[{"symbol":"ETH/EUR","bids":[{"price":3501.08,"qty":13.58098294}],"asks":[],"checksum":2668767004,"timestamp":"2024-06-01T17:52:15.516926Z"}]}
{"channel":"book","type":"update","data":[{"symbol":"ETH/EUR","bids":[{"price":3501.15,"qty":1.60000000}],"asks":[],"checksum":3156670261,"timestamp":"2024-06-01T17:52:15.517246Z"}]}
{"channel":"book","type":"update","data":[{"symbol":"ETH/EUR","bids":[{"price":3501.10,"qty":2.00000000}],"asks":[],"checksum":304293134,"timestamp":"2024-06-01T17:52:15.545305Z"}]}
{"channel":"book","type":"update","data":[{"symbol":"ETH/EUR","bids":[],"asks":[{"price":3502.20,"qty":0.00000000},{"price":3502.57,"qty":0.00220000}],"checksum":509208446,"timestamp":"2024-06-01T17:52:15.546103Z"}]}
{"channel":"book","type":"update","data":[{"symbol":"ETH/EUR","bids":[{"price":3501.08,"qty":17.58098294}],"asks":[],"checksum":3567377652,"timestamp":"2024-06-01T17:52:15.550116Z"}]}
{"channel":"book","type":"update","data":[{"symbol":"ETH/EUR","bids":[],"asks":[{"price":3502.19,"qty":26.32623037}],"checksum":3778432007,"timestamp":"2024-06-01T17:52:15.562680Z"}]}
{"channel":"book","type":"update","data":[{"symbol":"ETH/EUR","bids":[{"price":3501.09,"qty":6.84644082}],"asks":[],"checksum":4221748385,"timestamp":"2024-06-01T17:52:15.577731Z"}]}
{"channel":"book","type":"update","data":[{"symbol":"ETH/EUR","bids":[],"asks":[{"price":3502.19,"qty":0.00000000},{"price":3502.57,"qty":0.00220000}],"checksum":3459601490,"timestamp":"2024-06-01T17:52:15.583562Z"}]}
{"channel":"book","type":"update","data":[{"symbol":"ETH/EUR","bids":[{"price":3501.08,"qty":15.58098294}],"asks":[],"checksum":2873706903,"timestamp":"2024-06-01T17:52:15.584782Z"}]}
{"channel":"book","type":"update","data":[{"symbol":"ETH/EUR","bids":[],"asks":[{"price":3502.30,"qty":26.32543476}],"checksum":402048386,"timestamp":"2024-06-01T17:52:15.587232Z"}]}
{"channel":"book","type":"update","data":[{"symbol":"ETH/EUR","bids":[{"price":3501.09,"qty":6.00000000}],"asks":[],"checksum":224546084,"timestamp":"2024-06-01T17:52:15.609843Z"}]}
{"channel":"book","type":"update","data":[{"symbol":"ETH/EUR","bids":[{"price":3501.16,"qty":0.84644082}],"asks":[],"checksum":2241540166,"timestamp":"2024-06-01T17:52:15.609976Z"}]}
{"channel":"book","type":"update","data":[{"symbol":"ETH/EUR","bids":[{"price":3501.16,"qty":2.84644082}],"asks":[],"checksum":3271732686,"timestamp":"2024-06-01T17:52:15.616653Z"}]}
{"channel":"book","type":"update","data":[{"symbol":"ETH/EUR","bids":[{"price":3501.15,"qty":0.00000000},{"price":3500.45,"qty":0.72912968}],"asks":[],"checksum":3044845541,"timestamp":"2024-06-01T17:52:15.619456Z"}]}
{"channel":"book","type":"update","data":[{"symbol":"ETH/EUR","bids":[{"price":3501.22,"qty":1.60000000}],"asks":[],"checksum":4124275250,"timestamp":"2024-06-01T17:52:15.619528Z"}]}
{"channel":"book","type":"update","data":[{"symbol":"ETH/EUR","bids":[],"asks":[{"price":3502.22,"qty":0.00000000},{"price":3502.57,"qty":0.00220000}],"checksum":363876709,"timestamp":"2024-06-01T17:52:15.621200Z"}]}
{"channel":"book","type":"update","data":[{"symbol":"ETH/EUR","bids":[],"asks":[{"price":3502.24,"qty":26.32587040}],"checksum":127516163,"timestamp":"2024-06-01T17:52:15.624522Z"}]}
{"channel":"book","type":"update","data":[{"symbol":"ETH/EUR","bids":[{"price":3501.16,"qty":0.84644082}],"asks":[],"checksum":2935348149,"timestamp":"2024-06-01T17:52:15.633755Z"}]}
{"channel":"book","type":"update","data":[{"symbol":"ETH/EUR","bids":[{"price":3501.09,"qty":6.34402640}],"asks":[],"checksum":3429716867,"timestamp":"2024-06-01T17:52:15.647247Z"}]}
{"channel":"book","type":"update","data":[{"symbol":"ETH/EUR","bids":[{"price":3501.17,"qty":2.00000000}],"asks":[],"checksum":2136550883,"timestamp":"2024-06-01T17:52:15.652093Z"}]}
{"channel":"book","type":"update","data":[{"symbol":"ETH/EUR","bids":[{"price":3501.16,"qty":0.00000000},{"price":3500.48,"qty":1.31708923}],"asks":[],"checksum":831191022,"timestamp":"2024-06-01T17:52:15.653154Z"}]}
{"channel":"book","type":"update","data":[{"symbol":"ETH/EUR","bids":[{"price":3501.23,"qty":0.84644082}],"asks":[],"checksum":470765434,"timestamp":"2024-06-01T17:52:15.653354Z"}]}
{"channel":"book","type":"update","data":[{"symbol":"ETH/EUR","bids":[{"price":3501.09,"qty":6.68907572}],"asks":[],"checksum":837024499,"timestamp":"2024-06-01T17:52:15.654498Z"}]}
{"channel":"book","type":"update","data":[{"symbol":"ETH/EUR","bids":[],"asks":[{"price":3502.03,"qty":0.00000000},{"price":3502.57,"qty":0.00220000},{"price":3502.03,"qty":0.00759964}],"checksum":1604002882,"timestamp":"2024-06-01T17:52:15.663887Z"}]}
{"channel":"book","type":"update","data":[{"symbol":"ETH/EUR","bids":[],"asks":[{"price":3502.04,"qty":0.00000000},{"price":3502.57,"qty":0.00220000}],"checksum":2955790452,"timestamp":"2024-06-01T17:52:15.677293Z"}]}
{"channel":"book","type":"update","data":[{"symbol":"ETH/EUR","bids":[{"price":3501.09,"qty":0.68907572}],"asks":[],"checksum":2103494940,"timestamp":"2024-06-01T17:52:15.682097Z"}]}
{"channel":"book","type":"update","data":[{"symbol":"ETH/EUR","bids":[{"price":3501.17,"qty":0.00000000},{"price":3500.48,"qty":1.31708923}],"asks":[],"checksum":280276960,"timestamp":"2024-06-01T17:52:15.683036Z"}]}
{"channel":"book","type":"update","data":[{"symbol":"ETH/EUR","bids":[{"price":3501.08,"qty":14.73454212}],"asks":[],"checksum":1253406817,"timestamp":"2024-06-01T17:52:15.689010Z"}]}
{"channel":"book","type":"update","data":[{"symbol":"ETH/EUR","bids":[],"asks":[{"price":3502.45,"qty":26.32645147}],"checksum":1684224751,"timestamp":"2024-06-01T17:52:15.690546Z"}]}
{"channel":"book","type":"update","data":[{"symbol":"ETH/EUR","bids":[{"price":3501.09,"qty":5.54907572}],"asks":[],"checksum":946019623,"timestamp":"2024-06-01T17:52:15.694677Z"}]}
{"channel":"book","type":"update","data":[{"symbol":"ETH/EUR","bids":[],"asks":[{"price":3502.24,"qty":0.00000000},{"price":3502.79,"qty":0.84644082}],"checksum":2046817061,"timestamp":"2024-06-01T17:52:15.717832Z"}]}
{"channel":"book","type":"update","data":[{"symbol":"ETH/EUR","bids":[],"asks":[{"price":3502.23,"qty":26.32593973}],"checksum":956677116,"timestamp":"2024-06-01T17:52:15.720969Z"}]}
{"channel":"book","type":"update","data":[{"symbol":"ETH/EUR","bids":[{"price":3501.23,"qty":2.84644082}],"asks":[],"checksum":1120764371,"timestamp":"2024-06-01T17:52:15.722660Z"}]}
{"channel":"book","type":"update","data":[{"symbol":"ETH/EUR","bids":[{"price":3501.08,"qty":10.58454212}],"asks":[],"checksum":3481265716,"timestamp":"2024-06-01T17:52:15.725200Z"}]}
{"channel":"book","type":"update","data":[{"symbol":"ETH/EUR","bids":[{"price":3501.22,"qty":0.00000000},{"price":3500.45,"qty":0.72912968}],"asks":[],"checksum":2433630193,"timestamp":"2024-06-01T17:52:15.725271Z"}]}
{"channel":"book","type":"update","data":[{"symbol":"ETH/EUR","bids":[{"price":3501.29,"qty":1.60000000}],"asks":[],"checksum":2360361039,"timestamp":"2024-06-01T17:52:15.725389Z"}]}
{"channel":"book","type":"update","data":[{"symbol":"ETH/EUR","bids":[],"asks":[{"price":3502.23,"qty":0.00000000},{"price":3502.79,"qty":0.84644082}],"checksum":1946144887,"timestamp":"2024-06-01T17:52:15.737910Z"}]}
{"channel":"book","type":"update","data":[{"symbol":"ETH/EUR","bids":[],"asks":[{"price":3502.03,"qty":0.00000000},{"price":3502.81,"qty":0.72912968},{"price":3502.23,"qty":0.00759964}],"checksum":3875170078,"timestamp":"2024-06-01T17:52:15.750016Z"}]}
{"channel":"book","type":"update","data":[{"symbol":"ETH/EUR","bids":[{"price":3501.23,"qty":0.84644082}],"asks":[],"checksum":2062465626,"timestamp":"2024-06-01T17:52:15.756421Z"}]}
{"channel":"book","type":"update","data":[{"symbol":"ETH/EUR","bids":[],"asks":[{"price":3502.21,"qty":26.32611340}],"checksum":1885601912,"timestamp":"2024-06-01T17:52:15.774813Z"}]}
{"channel":"book","type":"update","data":[{"symbol":"ETH/EUR","bids":[{"price":3501.85,"qty":26.32874736}],"asks":[],"checksum":4167223552,"timestamp":"2024-06-01T17:52:15.778361Z"}]}
{"channel":"book","type":"update","data":[{"symbol":"ETH/EUR","bids":[{"price":3501.11,"qty":0.65854485}],"asks":[],"checksum":1898502067,"timestamp":"2024-06-01T17:52:15.781880Z"}]}
{"channel":"book","type":"update","data":[{"symbol":"ETH/EUR","bids":[],"asks":[{"price":3502.21,"qty":0.00000000},{"price":3502.79,"qty":0.84644082}],"checksum":2074242449,"timestamp":"2024-06-01T17:52:15.797536Z"}]}
{"channel":"book","type":"update","data":[{"symbol":"ETH/EUR","bids":[],"asks":[{"price":3502.23,"qty":0.00000000},{"price":3502.81,"qty":0.72912968},{"price":3502.29,"qty":0.00759964}],"checksum":723064045,"timestamp":"2024-06-01T17:52:15.804810Z"}]}
{"channel":"book","type":"update","data":[{"symbol":"ETH/EUR","bids":[],"asks":[{"price":3502.22,"qty":26.32599341}],"checksum":2778418218,"timestamp":"2024-06-01T17:52:15.849041Z"}]}
{"channel":"book","type":"update","data":[{"symbol":"ETH/EUR","bids":[],"asks":[{"price":3502.22,"qty":0.00000000},{"price":3502.79,"qty":0.84644082}],"checksum":723064045,"timestamp":"2024-06-01T17:52:15.876142Z"}]}
{"channel":"book","type":"update","data":[{"symbol":"ETH/EUR","bids":[{"price":3501.85,"qty":52.65749472}],"asks":[],"checksum":2687762547,"timestamp":"2024-06-01T17:52:15.881009Z"}]}
{"channel":"book","type":"update","data":[{"symbol":"ETH/EUR","bids":[{"price":3501.46,"qty":26.33162191}],"asks":[],"checksum":1884454952,"timestamp":"2024-06-01T17:52:15.881073Z"}]}
{"channel":"book","type":"update","data":[{"symbol":"ETH/EUR","bids":[],"asks":[{"price":3502.64,"qty":26.32287114}],"checksum":845852395,"timestamp":"2024-06-01T17:52:15.881088Z"}]}
{"channel":"book","type":"update","data":[{"symbol":"ETH/EUR","bids":[{"price":3500.94,"qty":0.00000000},{"price":3500.62,"qty":7.27644158},{"price":3501.30,"qty":0.08558300}],"asks":[],"checksum":2113900283,"timestamp":"2024-06-01T17:52:15.901971Z"}]}
{"channel":"book","type":"update","data":[{"symbol":"ETH/EUR","bids":[{"price":3501.09,"qty":0.68907572}],"asks":[],"checksum":2585233275,"timestamp":"2024-06-01T17:52:15.993469Z"}]}
{"channel":"book","type":"update","data":[{"symbol":"ETH/EUR","bids":[],"asks":[{"price":3502.23,"qty":26.32592762}],"checksum":3583385444,"timestamp":"2024-06-01T17:52:16.013141Z"}]}
{"channel":"book","type":"update","data":[{"symbol":"ETH/EUR","bids":[{"price":3501.69,"qty":26.32988216}],"asks":[],"checksum":3754497878,"timestamp":"2024-06-01T17:52:16.013220Z"}]}
{"channel":"book","type":"update","data":[{"symbol":"ETH/EUR","bids":[{"price":3501.70,"qty":0.02851391}],"asks":[],"checksum":1354341994,"timestamp":"2024-06-01T17:52:16.095653Z"}]}
{"channel":"book","type":"update","data":[{"symbol":"ETH/EUR","bids":[],"asks":[{"price":3502.29,"qty":0.00000000},{"price":3502.64,"qty":26.32287114},{"price":3502.22,"qty":0.00759964}],"checksum":2856901878,"timestamp":"2024-06-01T17:52:16.096358Z"}]}
{"channel":"book","type":"update","data":[{"symbol":"ETH/EUR","bids":[],"asks":[{"price":3502.23,"qty":0.00000000},{"price":3502.64,"qty":26.32287114}],"checksum":3164980808,"timestamp":"2024-06-01T17:52:16.184574Z"}]}
{"channel":"book","type":"update","data":[{"symbol":"ETH/EUR","bids":[],"asks":[{"price":3502.22,"qty":26.33360621}],"checksum":799574833,"timestamp":"2024-06-01T17:52:16.188444Z"}]}
{"channel":"book","type":"update","data":[{"symbol":"ETH/EUR","bids":[],"asks":[{"price":3502.22,"qty":0.00759964}],"checksum":3164980808,"timestamp":"2024-06-01T17:52:16.235914Z"}]}
{"channel":"book","type":"update","data":[{"symbol":"ETH/EUR","bids":[],"asks":[{"price":3502.21,"qty":26.32607498}],"checksum":1814883658,"timestamp":"2024-06-01T17:52:16.239647Z"}]}
{"channel":"book","type":"update","data":[{"symbol":"ETH/EUR","bids":[],"asks":[{"price":3502.21,"qty":0.00000000},{"price":3502.64,"qty":26.32287114}],"checksum":3164980808,"timestamp":"2024-06-01T17:52:16.243092Z"}]}
{"channel":"book","type":"update","data":[{"symbol":"ETH/EUR","bids":[],"asks":[{"price":3502.22,"qty":0.00000000},{"price":3502.79,"qty":0.84644082},{"price":3502.29,"qty":0.00759929}],"checksum":2970376657,"timestamp":"2024-06-01T17:52:16.291976Z"}]}
{"channel":"book","type":"update","data":[{"symbol":"ETH/EUR","bids":[],"asks":[{"price":3502.24,"qty":26.32585657}],"checksum":1737212083,"timestamp":"2024-06-01T17:52:16.374696Z"}]}
{"channel":"book","type":"update","data":[{"symbol":"ETH/EUR","bids":[],"asks":[{"price":3502.46,"qty":0.00000000},{"price":3502.64,"qty":26.32287114}],"checksum":2116966780,"timestamp":"2024-06-01T17:52:16.500800Z"}]}
{"channel":"book","type":"update","data":[{"symbol":"ETH/EUR","bids":[],"asks":[{"price":3502.24,"qty":0.00000000},{"price":3502.79,"qty":0.84644082}],"checksum":2667020807,"timestamp":"2024-06-01T17:52:16.529970Z"}]}
{"channel":"book","type":"update","data":[{"symbol":"ETH/EUR","bids":[],"asks":[{"price":3502.27,"qty":26.32566287}],"checksum":1526253176,"timestamp":"2024-06-01T17:52:16.533619Z"}]}
{"channel":"book","type":"update","data":[{"symbol":"ETH/EUR","bids":[{"price":3501.26,"qty":15.80577859}],"asks":[],"checksum":2849852708,"timestamp":"2024-06-01T17:52:16.565839Z"}]}
{"channel":"book","type":"update","data":[{"symbol":"ETH/EUR","bids":[],"asks":[{"price":3502.29,"qty":0.00000000},{"price":3502.79,"qty":0.84644082},{"price":3502.26,"qty":0.00759932}],"checksum":2905930134,"timestamp":"2024-06-01T17:52:16.662948Z"}]}
{"channel":"book","type":"update","data":[{"symbol":"ETH/EUR","bids":[],"asks":[{"price":3502.27,"qty":0.00000000},{"price":3502.79,"qty":0.84644082}],"checksum":2168369436,"timestamp":"2024-06-01T17:52:16.675533Z"}]}
{"channel":"book","type":"update","data":[{"symbol":"ETH/EUR","bids":[],"asks":[{"price":3502.64,"qty":0.00000000},{"price":3502.80,"qty":26.32164238}],"checksum":2039041851,"timestamp":"2024-06-01T17:52:16.683644Z"}]}
{"channel":"book","type":"update","data":[{"symbol":"ETH/EUR","bids":[],"asks":[{"price":3502.29,"qty":26.32549081}],"checksum":3205644411,"timestamp":"2024-06-01T17:52:16.687220Z"}]}
{"channel":"book","type":"update","data":[{"symbol":"ETH/EUR","bids":[],"asks":[{"price":3502.26,"qty":0.00000000},{"price":3502.80,"qty":26.32164238},{"price":3502.29,"qty":26.33309014}],"checksum":1127664225,"timestamp":"2024-06-01T17:52:16.717237Z"}]}
{"channel":"book","type":"update","data":[{"symbol":"ETH/EUR","bids":[],"asks":[{"price":3502.29,"qty":0.00759933}],"checksum":1398429430,"timestamp":"2024-06-01T17:52:16.735931Z"}]}
{"channel":"book","type":"update","data":[{"symbol":"ETH/EUR","bids":[],"asks":[{"price":3502.28,"qty":26.32558439}],"checksum":4186917440,"timestamp":"2024-06-01T17:52:16.739655Z"}]}
{"channel":"book","type":"update","data":[{"symbol":"ETH/EUR","bids":[],"asks":[{"price":3502.28,"qty":0.00000000},{"price":3502.80,"qty":26.32164238}],"checksum":1398429430,"timestamp":"2024-06-01T17:52:16.830723Z"}]}
{"channel":"book","type":"update","data":[{"symbol":"ETH/EUR","bids":[],"asks":[{"price":3502.27,"qty":26.32561070}],"checksum":3451719339,"timestamp":"2024-06-01T17:52:16.834414Z"}]}
{"channel":"book","type":"update","data":[{"symbol":"ETH/EUR","bids":[],"asks":[{"price":3502.27,"qty":0.00000000},{"price":3502.80,"qty":26.32164238}],"checksum":1398429430,"timestamp":"2024-06-01T17:52:16.954662Z"}]}
{"channel":"book","type":"update","data":[{"symbol":"ETH/EUR","bids":[],"asks":[{"price":3502.29,"qty":26.33308109}],"checksum":2879416203,"timestamp":"2024-06-01T17:52:16.959210Z"}]}
{"channel":"book","type":"update","data":[{"symbol":"ETH/EUR","bids":[],"asks":[{"price":3502.63,"qty":5.72847044}],"checksum":3328941903,"timestamp":"2024-06-01T17:52:17.032418Z"}]}
{"channel":"book","type":"update","data":[{"symbol":"ETH/EUR","bids":[],"asks":[{"price":3502.29,"qty":0.00759933}],"checksum":1593084818,"timestamp":"2024-06-01T17:52:17.162048Z"}]}
{"channel":"book","type":"update","data":[{"symbol":"ETH/EUR","bids":[],"asks":[{"price":3502.27,"qty":26.32560807}],"checksum":3893331426,"timestamp":"2024-06-01T17:52:17.166500Z"}]}
{"channel":"book","type":"update","data":[{"symbol":"ETH/EUR","bids":[],"asks":[{"price":3502.29,"qty":0.00000000},{"price":3502.79,"qty":0.84644082},{"price":3502.26,"qty":0.00759935}],"checksum":331965326,"timestamp":"2024-06-01T17:52:17.223829Z"}]}
{"channel":"book","type":"update","data":[{"symbol":"ETH/EUR","bids":[],"asks":[{"price":3502.09,"qty":0.00000000},{"price":3502.79,"qty":0.84644082},{"price":3502.45,"qty":26.41202747}],"checksum":1759943964,"timestamp":"2024-06-01T17:52:17.294837Z"}]}
{"channel":"book","type":"update","data":[{"symbol":"ETH/EUR","bids":[],"asks":[{"price":3502.27,"qty":0.00000000},{"price":3502.80,"qty":26.32164238}],"checksum":1071651270,"timestamp":"2024-06-01T17:52:17.459267Z"}]}
{"channel":"book","type":"update","data":[{"symbol":"ETH/EUR","bids":[],"asks":[{"price":3502.26,"qty":26.33329426}],"checksum":2615948590,"timestamp":"2024-06-01T17:52:17.463060Z"}]}
{"channel":"book","type":"update","data":[{"symbol":"ETH/EUR","bids":[],"asks":[{"price":3502.26,"qty":0.00759935}],"checksum":1071651270,"timestamp":"2024-06-01T17:52:17.724892Z"}]}
{"channel":"book","type":"update","data":[{"symbol":"ETH/EUR","bids":[],"asks":[{"price":3502.29,"qty":26.32547966}],"checksum":3274677154,"timestamp":"2024-06-01T17:52:17.729595Z"}]}
{"channel":"book","type":"update","data":[{"symbol":"ETH/EUR","bids":[],"asks":[{"price":3502.29,"qty":0.00000000},{"price":3502.80,"qty":26.32164238}],"checksum":1071651270,"timestamp":"2024-06-01T17:52:17.739655Z"}]}
{"channel":"book","type":"update","data":[{"symbol":"ETH/EUR","bids":[],"asks":[{"price":3502.26,"qty":0.00000000},{"price":3502.81,"qty":0.72912968},{"price":3502.29,"qty":0.00759936}],"checksum":1856610007,"timestamp":"2024-06-01T17:52:17.777021Z"}]}
{"channel":"book","type":"update","data":[{"symbol":"ETH/EUR","bids":[],"asks":[{"price":3502.24,"qty":26.32584196}],"checksum":539203970,"timestamp":"2024-06-01T17:52:18.063248Z"}]}
{"channel":"book","type":"update","data":[{"symbol":"ETH/EUR","bids":[],"asks":[{"price":3502.29,"qty":0.00000000},{"price":3502.80,"qty":26.32164238},{"price":3502.23,"qty":0.00759937}],"checksum":2001405848,"timestamp":"2024-06-01T17:52:18.117018Z"}]}
{"channel":"book","type":"update","data":[{"symbol":"ETH/EUR","bids":[{"price":3501.71,"qty":2.43000000}],"asks":[],"checksum":1752639632,"timestamp":"2024-06-01T17:52:18.190454Z"}]}
{"channel":"book","type":"update","data":[{"symbol":"ETH/EUR","bids":[{"price":3501.11,"qty":0.00000000},{"price":3501.10,"qty":2.00000000}],"asks":[],"checksum":2497070245,"timestamp":"2024-06-01T17:52:18.250627Z"}]}
{"channel":"book","type":"update","data":[{"symbol":"ETH/EUR","bids":[],"asks":[{"price":3502.24,"qty":0.00000000},{"price":3502.80,"qty":26.32164238}],"checksum":779752651,"timestamp":"2024-06-01T17:52:18.256613Z"}]}
{"channel":"book","type":"update","data":[{"symbol":"ETH/EUR","bids":[{"price":3501.85,"qty":26.32874736}],"asks":[],"checksum":960923548,"timestamp":"2024-06-01T17:52:18.256754Z"}]}
{"channel":"book","type":"update","data":[{"symbol":"ETH/EUR","bids":[],"asks":[{"price":3502.80,"qty":0.00000000},{"price":3502.81,"qty":0.72912968}],"checksum":1101929586,"timestamp":"2024-06-01T17:52:18.256802Z"}]}
{"channel":"book","type":"update","data":[{"symbol":"ETH/EUR","bids":[],"asks":[{"price":3502.30,"qty":0.00000000},{"price":3502.83,"qty":0.00220000}],"checksum":1107442981,"timestamp":"2024-06-01T17:52:18.256836Z"}]}
{"channel":"book","type":"update","data":[{"symbol":"ETH/EUR","bids":[{"price":3501.85,"qty":0.00000000},{"price":3501.08,"qty":10.58454212}],"asks":[],"checksum":209014799,"timestamp":"2024-06-01T17:52:18.256896Z"}]}
{"channel":"book","type":"update","data":[{"symbol":"ETH/EUR","bids":[{"price":3501.46,"qty":0.00000000},{"price":3500.93,"qty":1.35356069}],"asks":[],"checksum":2748664708,"timestamp":"2024-06-01T17:52:18.258703Z"}]}
{"channel":"book","type":"update","data":[{"symbol":"ETH/EUR","bids":[],"asks":[{"price":3502.45,"qty":0.08777600}],"checksum":4189106637,"timestamp":"2024-06-01T17:52:18.259270Z"}]}
{"channel":"book","type":"update","data":[{"symbol":"ETH/EUR","bids":[{"price":3501.29,"qty":0.00000000},{"price":3500.62,"qty":7.27644158}],"asks":[],"checksum":3884503669,"timestamp":"2024-06-01T17:52:18.259915Z"}]}
{"channel":"book","type":"update","data":[{"symbol":"ETH/EUR","bids":[{"price":3501.71,"qty":4.03000000}],"asks":[],"checksum":2262949908,"timestamp":"2024-06-01T17:52:18.260068Z"}]}
{"channel":"book","type":"update","data":[{"symbol":"ETH/EUR","bids":[],"asks":[{"price":3502.29,"qty":0.72912968}],"checksum":1602407185,"timestamp":"2024-06-01T17:52:18.260973Z"}]}
{"channel":"book","type":"update","data":[{"symbol":"ETH/EUR","bids":[],"asks":[{"price":3502.44,"qty":1.60000000}],"checksum":3056495426,"timestamp":"2024-06-01T17:52:18.261795Z"}]}
{"channel":"book","type":"update","data":[{"symbol":"ETH/EUR","bids":[{"price":3501.73,"qty":1.60000000}],"asks":[],"checksum":3521541214,"timestamp":"2024-06-01T17:52:18.263531Z"}]}
{"channel":"book","type":"update","data":[{"symbol":"ETH/EUR","bids":[],"asks":[{"price":3502.03,"qty":26.32745018}],"checksum":1898891667,"timestamp":"2024-06-01T17:52:18.263646Z"}]}
{"channel":"book","type":"update","data":[{"symbol":"ETH/EUR","bids":[],"asks":[{"price":3502.61,"qty":26.32308144}],"checksum":3586485224,"timestamp":"2024-06-01T17:52:18.263676Z"}]}
{"channel":"book","type":"update","data":[{"symbol":"ETH/EUR","bids":[{"price":3501.71,"qty":2.43000000}],"asks":[],"checksum":741201768,"timestamp":"2024-06-01T17:52:18.263724Z"}]}
{"channel":"book","type":"update","data":[{"symbol":"ETH/EUR","bids":[],"asks":[{"price":3502.03,"qty":0.00000000},{"price":3502.63,"qty":5.72847044}],"checksum":3724838278,"timestamp":"2024-06-01T17:52:18.274362Z"}]}
{"channel":"book","type":"update","data":[{"symbol":"ETH/EUR","bids":[{"price":3501.08,"qty":4.00000000}],"asks":[],"checksum":2165075641,"timestamp":"2024-06-01T17:52:18.275392Z"}]}
{"channel":"book","type":"update","data":[{"symbol":"ETH/EUR","bids":[],"asks":[{"price":3502.30,"qty":26.32540547}],"checksum":2448183413,"timestamp":"2024-06-01T17:52:18.277601Z"}]}
{"channel":"book","type":"update","data":[{"symbol":"ETH/EUR","bids":[{"price":3500.93,"qty":0.00000000},{"price":3500.62,"qty":7.27644158}],"asks":[],"checksum":1605754458,"timestamp":"2024-06-01T17:52:18.278064Z"}]}
{"channel":"book","type":"update","data":[{"symbol":"ETH/EUR","bids":[{"price":3501.69,"qty":0.00000000},{"price":3500.48,"qty":1.31708923}],"asks":[],"checksum":270515405,"timestamp":"2024-06-01T17:52:18.303649Z"}]}
{"channel":"book","type":"update","data":[{"symbol":"ETH/EUR","bids":[{"price":3501.73,"qty":0.00000000},{"price":3500.45,"qty":0.72912968}],"asks":[],"checksum":623879781,"timestamp":"2024-06-01T17:52:18.306367Z"}]}
{"channel":"book","type":"update","data":[{"symbol":"ETH/EUR","bids":[{"price":3501.36,"qty":1.60000000}],"asks":[],"checksum":1182206655,"timestamp":"2024-06-01T17:52:18.306718Z"}]}
{"channel":"book","type":"update","data":[{"symbol":"ETH/EUR","bids":[],"asks":[{"price":3502.18,"qty":26.32634024}],"checksum":2539208446,"timestamp":"2024-06-01T17:52:18.307927Z"}]}
{"channel":"book","type":"update","data":[{"symbol":"ETH/EUR","bids":[],"asks":[{"price":3502.23,"qty":0.00000000},{"price":3502.61,"qty":26.32308144},{"price":3502.28,"qty":0.00759937}],"checksum":3833804065,"timestamp":"2024-06-01T17:52:18.317233Z"}]}
{"channel":"book","type":"update","data":[{"symbol":"ETH/EUR","bids":[],"asks":[{"price":3502.09,"qty":26.32698175}],"checksum":2550408390,"timestamp":"2024-06-01T17:52:18.326096Z"}]}
{"channel":"book","type":"update","data":[{"symbol":"ETH/EUR","bids":[],"asks":[{"price":3502.09,"qty":0.00000000},{"price":3502.57,"qty":0.00220000}],"checksum":3833804065,"timestamp":"2024-06-01T17:52:18.354170Z"}]}
{"channel":"book","type":"update","data":[{"symbol":"ETH/EUR","bids":[],"asks":[{"price":3502.07,"qty":26.32714109}],"checksum":2994186202,"timestamp":"2024-06-01T17:52:18.376053Z"}]}
{"channel":"book","type":"update","data":[{"symbol":"ETH/EUR","bids":[],"asks":[{"price":3502.18,"qty":0.00000000},{"price":3502.57,"qty":0.00220000}],"checksum":291164667,"timestamp":"2024-06-01T17:52:18.380186Z"}]}
{"channel":"book","type":"update","data":[{"symbol":"ETH/EUR","bids":[{"price":3501.23,"qty":2.19988553}],"asks":[],"checksum":3676952268,"timestamp":"2024-06-01T17:52:18.403701Z"}]}
{"channel":"book","type":"update","data":[{"symbol":"ETH/EUR","bids":[{"price":3501.85,"qty":3.24000000}],"asks":[],"checksum":1451519689,"timestamp":"2024-06-01T17:52:18.404504Z"}]}
{"channel":"book","type":"update","data":[{"symbol":"ETH/EUR","bids":[],"asks":[{"price":3502.06,"qty":26.32719321}],"checksum":2858566613,"timestamp":"2024-06-01T17:52:18.427934Z"}]}
{"channel":"book","type":"update","data":[{"symbol":"ETH/EUR","bids":[{"price":3501.71,"qty":0.00000000},{"price":3500.48,"qty":1.31708923}],"asks":[],"checksum":3846367126,"timestamp":"2024-06-01T17:52:18.444194Z"}]}
{"channel":"book","type":"update","data":[{"symbol":"ETH/EUR","bids":[],"asks":[{"price":3502.28,"qty":0.00000000},{"price":3502.57,"qty":0.00220000},{"price":3502.29,"qty":0.73672896}],"checksum":74607256,"timestamp":"2024-06-01T17:52:18.476913Z"}]}
{"channel":"book","type":"update","data":[{"symbol":"ETH/EUR","bids":[{"price":3501.70,"qty":0.00000000},{"price":3500.45,"qty":0.72912968},{"price":3501.37,"qty":0.02851601}],"asks":[],"checksum":464242525,"timestamp":"2024-06-01T17:52:18.499746Z"}]}
{"channel":"book","type":"update","data":[{"symbol":"ETH/EUR","bids":[{"price":3501.27,"qty":4.00000000}],"asks":[],"checksum":1418243862,"timestamp":"2024-06-01T17:52:18.501534Z"}]}
{"channel":"book","type":"update","data":[{"symbol":"ETH/EUR","bids":[],"asks":[{"price":3502.29,"qty":0.72912968}],"checksum":1029074492,"timestamp":"2024-06-01T17:52:18.535989Z"}]}
{"channel":"book","type":"update","data":[{"symbol":"ETH/EUR","bids":[{"price":3501.08,"qty":0.00000000},{"price":3500.48,"qty":1.31708923}],"asks":[],"checksum":147574516,"timestamp":"2024-06-01T17:52:18.678564Z"}]}
{"channel":"book","type":"update","data":[{"symbol":"ETH/EUR","bids":[],"asks":[{"price":3502.06,"qty":0.00000000},{"price":3502.60,"qty":0.00759928}],"checksum":239972927,"timestamp":"2024-06-01T17:52:18.753648Z"}]}
{"channel":"book","type":"update","data":[{"symbol":"ETH/EUR","bids":[],"asks":[{"price":3502.03,"qty":26.32745672}],"checksum":1050990159,"timestamp":"2024-06-01T17:52:18.758379Z"}]}
{"channel":"book","type":"update","data":[{"symbol":"ETH/EUR","bids":[],"asks":[{"price":3502.28,"qty":0.00759927}],"checksum":2301208288,"timestamp":"2024-06-01T17:52:18.818021Z"}]}
{"channel":"book","type":"update","data":[{"symbol":"ETH/EUR","bids":[],"asks":[{"price":3502.28,"qty":0.00000000},{"price":3502.57,"qty":0.00220000}],"checksum":1050990159,"timestamp":"2024-06-01T17:52:18.864224Z"}]}
{"channel":"book","type":"update","data":[{"symbol":"ETH/EUR","bids":[{"price":3501.78,"qty":26.32924359}],"asks":[],"checksum":862110955,"timestamp":"2024-06-01T17:52:19.004541Z"}]}
{"channel":"book","type":"update","data":[{"symbol":"ETH/EUR","bids":[{"price":3501.51,"qty":26.33129479}],"asks":[],"checksum":1257753311,"timestamp":"2024-06-01T17:52:19.004608Z"}]}
{"channel":"book","type":"update","data":[{"symbol":"ETH/EUR","bids":[],"asks":[{"price":3502.03,"qty":0.00000000},{"price":3502.60,"qty":0.00759927}],"checksum":3119026198,"timestamp":"2024-06-01T17:52:19.019805Z"}]}
{"channel":"book","type":"update","data":[{"symbol":"ETH/EUR","bids":[{"price":3501.78,"qty":0.00000000},{"price":3500.62,"qty":7.27644158}],"asks":[],"checksum":4242105769,"timestamp":"2024-06-01T17:52:19.019826Z"}]}
{"channel":"book","type":"update","data":[{"symbol":"ETH/EUR","bids":[],"asks":[{"price":3502.06,"qty":26.32720935}],"checksum":323013845,"timestamp":"2024-06-01T17:52:19.023472Z"}]}
{"channel":"book","type":"update","data":[{"symbol":"ETH/EUR","bids":[{"price":3501.36,"qty":0.00000000},{"price":3500.48,"qty":1.31708923}],"asks":[],"checksum":3567465006,"timestamp":"2024-06-01T17:52:19.023651Z"}]}
{"channel":"book","type":"update","data":[{"symbol":"ETH/EUR","bids":[{"price":3501.52,"qty":1.60000000}],"asks":[],"checksum":685909191,"timestamp":"2024-06-01T17:52:19.023720Z"}]}
{"channel":"book","type":"update","data":[{"symbol":"ETH/EUR","bids":[],"asks":[{"price":3502.06,"qty":0.00000000},{"price":3502.60,"qty":0.00759927}],"checksum":3346763195,"timestamp":"2024-06-01T17:52:19.182880Z"}]}
{"channel":"book","type":"update","data":[{"symbol":"ETH/EUR","bids":[],"asks":[{"price":3502.05,"qty":26.32728289}],"checksum":2437513662,"timestamp":"2024-06-01T17:52:19.186708Z"}]}
{"channel":"book","type":"update","data":[{"symbol":"ETH/EUR","bids":[{"price":3501.31,"qty":26.33280348}],"asks":[],"checksum":2126985809,"timestamp":"2024-06-01T17:52:19.186800Z"}]}
{"channel":"book","type":"update","data":[{"symbol":"ETH/EUR","bids":[{"price":3501.80,"qty":26.32911200}],"asks":[],"checksum":3314094822,"timestamp":"2024-06-01T17:52:19.186814Z"}]}
{"channel":"book","type":"update","data":[{"symbol":"ETH/EUR","bids":[],"asks":[{"price":3502.05,"qty":0.00000000},{"price":3502.60,"qty":0.00759927}],"checksum":2974350522,"timestamp":"2024-06-01T17:52:19.200729Z"}]}
{"channel":"book","type":"update","data":[{"symbol":"ETH/EUR","bids":[{"price":3501.80,"qty":0.00000000},{"price":3501.10,"qty":2.00000000}],"asks":[],"checksum":251395282,"timestamp":"2024-06-01T17:52:19.200805Z"}]}
{"channel":"book","type":"update","data":[{"symbol":"ETH/EUR","bids":[{"price":3501.79,"qty":26.32916990}],"asks":[],"checksum":2295034723,"timestamp":"2024-06-01T17:52:19.251490Z"}]}
{"channel":"book","type":"update","data":[{"symbol":"ETH/EUR","bids":[],"asks":[{"price":3502.05,"qty":26.32726710}],"checksum":3983612966,"timestamp":"2024-06-01T17:52:19.251665Z"}]}
{"channel":"book","type":"update","data":[{"symbol":"ETH/EUR","bids":[],"asks":[{"price":3502.05,"qty":0.00000000},{"price":3502.60,"qty":0.00759927}],"checksum":2295034723,"timestamp":"2024-06-01T17:52:19.255272Z"}]}
{"channel":"book","type":"update","data":[{"symbol":"ETH/EUR","bids":[{"price":3501.79,"qty":0.00000000},{"price":3501.10,"qty":2.00000000}],"asks":[],"checksum":251395282,"timestamp":"2024-06-01T17:52:19.255735Z"}]}
{"channel":"book","type":"update","data":[{"symbol":"ETH/EUR","bids":[{"price":3501.74,"qty":26.32951730}],"asks":[],"checksum":1228039061,"timestamp":"2024-06-01T17:52:19.309416Z"}]}
{"channel":"book","type":"update","data":[{"symbol":"ETH/EUR","bids":[],"asks":[{"price":3502.00,"qty":26.32768027}],"checksum":1792496062,"timestamp":"2024-06-01T17:52:19.309482Z"}]}
{"channel":"book","type":"update","data":[{"symbol":"ETH/EUR","bids":[{"price":3501.74,"qty":0.00000000},{"price":3501.10,"qty":2.00000000}],"asks":[],"checksum":850290725,"timestamp":"2024-06-01T17:52:19.323096Z"}]}
{"channel":"book","type":"update","data":[{"symbol":"ETH/EUR","bids":[],"asks":[{"price":3502.00,"qty":0.00000000},{"price":3502.60,"qty":0.00759927}],"checksum":251395282,"timestamp":"2024-06-01T17:52:19.381827Z"}]}
{"channel":"book","type":"update","data":[{"symbol":"ETH/EUR","bids":[],"asks":[{"price":3502.05,"qty":26.32725640}],"checksum":50200275,"timestamp":"2024-06-01T17:52:19.386153Z"}]}
{"channel":"book","type":"update","data":[{"symbol":"ETH/EUR","bids":[{"price":3501.80,"qty":26.32909077}],"asks":[],"checksum":1342263719,"timestamp":"2024-06-01T17:52:19.386179Z"}]}
{"channel":"book","type":"update","data":[{"symbol":"ETH/EUR","bids":[{"price":3501.80,"qty":0.00000000},{"price":3501.10,"qty":2.00000000}],"asks":[],"checksum":50200275,"timestamp":"2024-06-01T17:52:19.423090Z"}]}
{"channel":"book","type":"update","data":[{"symbol":"ETH/EUR","bids":[],"asks":[{"price":3502.05,"qty":0.00000000},{"price":3502.60,"qty":0.00759927}],"checksum":251395282,"timestamp":"2024-06-01T17:52:19.461747Z"}]}
{"channel":"book","type":"update","data":[{"symbol":"ETH/EUR","bids":[{"price":3501.82,"qty":26.32893549}],"asks":[],"checksum":2063313739,"timestamp":"2024-06-01T17:52:19.465869Z"}]}
{"channel":"book","type":"update","data":[{"symbol":"ETH/EUR","bids":[],"asks":[{"price":3502.15,"qty":26.32649383}],"checksum":778212655,"timestamp":"2024-06-01T17:52:19.465936Z"}]}
{"channel":"book","type":"update","data":[{"symbol":"ETH/EUR","bids":[{"price":3501.82,"qty":0.00000000},{"price":3501.10,"qty":2.00000000}],"asks":[],"checksum":1234350372,"timestamp":"2024-06-01T17:52:19.484618Z"}]}
{"channel":"book","type":"update","data":[{"symbol":"ETH/EUR","bids":[],"asks":[{"price":3502.07,"qty":0.00000000},{"price":3502.60,"qty":0.00759927}],"checksum":320478863,"timestamp":"2024-06-01T17:52:19.484651Z"}]}
{"channel":"book","type":"update","data":[{"symbol":"ETH/EUR","bids":[],"asks":[{"price":3502.06,"qty":26.32718797}],"checksum":2960399202,"timestamp":"2024-06-01T17:52:19.488684Z"}]}
{"channel":"book","type":"update","data":[{"symbol":"ETH/EUR","bids":[],"asks":[{"price":3502.28,"qty":0.00759926}],"checksum":3015394401,"timestamp":"2024-06-01T17:52:19.514731Z"}]}
{"channel":"book","type":"update","data":[{"symbol":"ETH/EUR","bids":[{"price":3501.81,"qty":26.32902761}],"asks":[],"checksum":2534629326,"timestamp":"2024-06-01T17:52:19.549544Z"}]}
{"channel":"book","type":"update","data":[{"symbol":"ETH/EUR","bids":[],"asks":[{"price":3502.28,"qty":0.00000000},{"price":3502.57,"qty":0.00220000}],"checksum":236568875,"timestamp":"2024-06-01T17:52:19.562346Z"}]}
{"channel":"book","type":"update","data":[{"symbol":"ETH/EUR","bids":[{"price":3501.81,"qty":0.00000000},{"price":3501.10,"qty":2.00000000}],"asks":[],"checksum":2960399202,"timestamp":"2024-06-01T17:52:19.910464Z"}]}
{"channel":"book","type":"update","data":[{"symbol":"ETH/EUR","bids":[],"asks":[{"price":3502.06,"qty":0.00000000},{"price":3502.60,"qty":0.00759926}],"checksum":3530271628,"timestamp":"2024-06-01T17:52:19.910581Z"}]}
{"channel":"book","type":"update","data":[{"symbol":"ETH/EUR","bids":[{"price":3501.79,"qty":26.32915713}],"asks":[],"checksum":3695970485,"timestamp":"2024-06-01T17:52:19.914509Z"}]}
{"channel":"book","type":"update","data":[{"symbol":"ETH/EUR","bids":[],"asks":[{"price":3502.05,"qty":26.32728775}],"checksum":3014302758,"timestamp":"2024-06-01T17:52:19.914531Z"}]}
{"channel":"book","type":"update","data":[{"symbol":"ETH/EUR","bids":[],"asks":[{"price":3502.05,"qty":0.00000000},{"price":3502.60,"qty":0.00759926}],"checksum":3695970485,"timestamp":"2024-06-01T17:52:19.976446Z"}]}
{"channel":"book","type":"update","data":[{"symbol":"ETH/EUR","bids":[],"asks":[{"price":3502.04,"qty":26.32735880}],"checksum":488848269,"timestamp":"2024-06-01T17:52:19.980485Z"}]}
{"channel":"book","type":"update","data":[{"symbol":"ETH/EUR","bids":[],"asks":[{"price":3502.04,"qty":0.00000000},{"price":3502.60,"qty":0.00759926}],"checksum":3695970485,"timestamp":"2024-06-01T17:52:20.132226Z"}]}
{"channel":"book","type":"update","data":[{"symbol":"ETH/EUR","bids":[{"price":3501.79,"qty":0.00000000},{"price":3501.10,"qty":2.00000000}],"asks":[],"checksum":3530271628,"timestamp":"2024-06-01T17:52:20.132306Z"}]}
{"channel":"book","type":"update","data":[{"symbol":"ETH/EUR","bids":[],"asks":[{"price":3502.03,"qty":26.32743243}],"checksum":736668617,"timestamp":"2024-06-01T17:52:20.136418Z"}]}
{"channel":"book","type":"update","data":[{"symbol":"ETH/EUR","bids":[],"asks":[{"price":3502.03,"qty":0.00000000},{"price":3502.60,"qty":0.00759926}],"checksum":3530271628,"timestamp":"2024-06-01T17:52:20.180929Z"}]}
{"channel":"book","type":"update","data":[{"symbol":"ETH/EUR","bids":[],"asks":[{"price":3502.04,"qty":26.32734296}],"checksum":3537650569,"timestamp":"2024-06-01T17:52:20.198492Z"}]}
{"channel":"book","type":"update","data":[{"symbol":"ETH/EUR","bids":[],"asks":[{"price":3502.04,"qty":0.00000000},{"price":3502.60,"qty":0.00759926}],"checksum":3530271628,"timestamp":"2024-06-01T17:52:20.268888Z"}]}
{"channel":"book","type":"update","data":[{"symbol":"ETH/EUR","bids":[],"asks":[{"price":3502.10,"qty":26.32692190}],"checksum":4284748192,"timestamp":"2024-06-01T17:52:20.272738Z"}]}
{"channel":"book","type":"update","data":[{"symbol":"ETH/EUR","bids":[{"price":3501.37,"qty":0.00000000},{"price":3500.62,"qty":7.27644158},{"price":3501.53,"qty":0.02852096}],"asks":[],"checksum":1653525313,"timestamp":"2024-06-01T17:52:20.298010Z"}]}
{"channel":"book","type":"update","data":[{"symbol":"ETH/EUR","bids":[],"asks":[{"price":3502.10,"qty":0.00000000},{"price":3502.60,"qty":0.00759926}],"checksum":1333883245,"timestamp":"2024-06-01T17:52:20.349318Z"}]}
{"channel":"book","type":"update","data":[{"symbol":"ETH/EUR","bids":[],"asks":[{"price":3502.09,"qty":26.32697717}],"checksum":1751001573,"timestamp":"2024-06-01T17:52:20.354029Z"}]}
{"channel":"book","type":"update","data":[{"symbol":"ETH/EUR","bids":[],"asks":[{"price":3502.09,"qty":0.00000000},{"price":3502.60,"qty":0.00759926}],"checksum":1333883245,"timestamp":"2024-06-01T17:52:20.381201Z"}]}
{"channel":"book","type":"update","data":[{"symbol":"ETH/EUR","bids":[],"asks":[{"price":3501.86,"qty":0.10220000}],"checksum":1549668368,"timestamp":"2024-06-01T17:52:20.513058Z"}]}
{"channel":"book","type":"update","data":[{"symbol":"ETH/EUR","bids":[],"asks":[{"price":3502.11,"qty":26.32683140}],"checksum":3629400655,"timestamp":"2024-06-01T17:52:20.513919Z"}]}
{"channel":"book","type":"update","data":[{"symbol":"ETH/EUR","bids":[],"asks":[{"price":3502.29,"qty":0.00000000},{"price":3502.60,"qty":0.00759926}],"checksum":1518926499,"timestamp":"2024-06-01T17:52:20.657855Z"}]}
{"channel":"book","type":"update","data":[{"symbol":"ETH/EUR","bids":[{"price":3501.31,"qty":0.00000000},{"price":3500.62,"qty":7.27644158}],"asks":[],"checksum":1781192013,"timestamp":"2024-06-01T17:52:20.663091Z"}]}
{"channel":"book","type":"update","data":[{"symbol":"ETH/EUR","bids":[],"asks":[{"price":3502.11,"qty":0.00000000},{"price":3502.61,"qty":26.32308144}],"checksum":3445962682,"timestamp":"2024-06-01T17:52:20.663126Z"}]}
{"channel":"book","type":"update","data":[{"symbol":"ETH/EUR","bids":[],"asks":[{"price":3502.30,"qty":0.00000000},{"price":3502.79,"qty":0.84644082}],"checksum":2687094734,"timestamp":"2024-06-01T17:52:20.663219Z"}]}
{"channel":"book","type":"update","data":[{"symbol":"ETH/EUR","bids":[],"asks":[{"price":3502.15,"qty":0.00000000},{"price":3502.83,"qty":0.00220000}],"checksum":3622422208,"timestamp":"2024-06-01T17:52:20.663255Z"}]}
{"channel":"book","type":"update","data":[{"symbol":"ETH/EUR","bids":[],"asks":[{"price":3502.32,"qty":26.32524392}],"checksum":887624183,"timestamp":"2024-06-01T17:52:20.677571Z"}]}
{"channel":"book","type":"update","data":[{"symbol":"ETH/EUR","bids":[],"asks":[{"price":3502.32,"qty":0.00000000},{"price":3502.83,"qty":0.00220000}],"checksum":3622422208,"timestamp":"2024-06-01T17:52:20.682636Z"}]}
{"channel":"book","type":"update","data":[{"symbol":"ETH/EUR","bids":[],"asks":[{"price":3502.61,"qty":0.00000000},{"price":3502.85,"qty":26.32123505}],"checksum":1621567093,"timestamp":"2024-06-01T17:52:20.710804Z"}]}
{"channel":"book","type":"update","data":[{"symbol":"ETH/EUR","bids":[],"asks":[{"price":3502.49,"qty":26.32395927}],"checksum":32351817,"timestamp":"2024-06-01T17:52:20.714750Z"}]}
{"channel":"book","type":"update","data":[{"symbol":"ETH/EUR","bids":[],"asks":[{"price":3502.24,"qty":26.32582492}],"checksum":538065101,"timestamp":"2024-06-01T17:52:20.732338Z"}]}
{"channel":"book","type":"update","data":[{"symbol":"ETH/EUR","bids":[{"price":3500.91,"qty":0.72912968}],"asks":[],"checksum":775484086,"timestamp":"2024-06-01T17:52:20.736483Z"}]}
{"channel":"book","type":"update","data":[{"symbol":"ETH/EUR","bids":[],"asks":[{"price":3502.24,"qty":0.00000000},{"price":3502.83,"qty":0.00220000}],"checksum":1699922818,"timestamp":"2024-06-01T17:52:20.767577Z"}]}
{"channel":"book","type":"update","data":[{"symbol":"ETH/EUR","bids":[],"asks":[{"price":3502.26,"qty":26.32571440}],"checksum":3860968301,"timestamp":"2024-06-01T17:52:20.792772Z"}]}
{"channel":"book","type":"update","data":[{"symbol":"ETH/EUR","bids":[],"asks":[{"price":3502.26,"qty":0.00000000},{"price":3502.83,"qty":0.00220000}],"checksum":1699922818,"timestamp":"2024-06-01T17:52:20.796207Z"}]}
{"channel":"book","type":"update","data":[{"symbol":"ETH/EUR","bids":[],"asks":[{"price":3502.25,"qty":26.32576440}],"checksum":2240719851,"timestamp":"2024-06-01T17:52:20.842379Z"}]}
{"channel":"book","type":"update","data":[{"symbol":"ETH/EUR","bids":[],"asks":[{"price":3502.28,"qty":26.32552757}],"checksum":917282404,"timestamp":"2024-06-01T17:52:20.971844Z"}]}
{"channel":"book","type":"update","data":[{"symbol":"ETH/EUR","bids":[{"price":3501.85,"qty":29.56874736}],"asks":[],"checksum":2764047731,"timestamp":"2024-06-01T17:52:20.999161Z"}]}
{"channel":"book","type":"update","data":[{"symbol":"ETH/EUR","bids":[],"asks":[{"price":3502.60,"qty":0.00000000},{"price":3502.79,"qty":0.84644082},{"price":3502.24,"qty":0.00759963}],"checksum":188745045,"timestamp":"2024-06-01T17:52:21.063389Z"}]}
{"channel":"book","type":"update","data":[{"symbol":"ETH/EUR","bids":[{"price":3501.85,"qty":55.89749472}],"asks":[],"checksum":3785302413,"timestamp":"2024-06-01T17:52:21.199514Z"}]}
{"channel":"book","type":"update","data":[{"symbol":"ETH/EUR","bids":[{"price":3501.11,"qty":0.61328748}],"asks":[],"checksum":1069903987,"timestamp":"2024-06-01T17:52:21.203278Z"}]}
{"channel":"book","type":"update","data":[{"symbol":"ETH/EUR","bids":[],"asks":[{"price":3502.25,"qty":0.00000000},{"price":3502.79,"qty":0.84644082}],"checksum":2571352795,"timestamp":"2024-06-01T17:52:21.251050Z"}]}
{"channel":"book","type":"update","data":[{"symbol":"ETH/EUR","bids":[],"asks":[{"price":3502.36,"qty":26.32498082}],"checksum":1894630262,"timestamp":"2024-06-01T17:52:21.255094Z"}]}
{"channel":"book","type":"update","data":[{"symbol":"ETH/EUR","bids":[],"asks":[{"price":3502.28,"qty":0.00000000},{"price":3502.79,"qty":0.84644082}],"checksum":640999453,"timestamp":"2024-06-01T17:52:21.277116Z"}]}
{"channel":"book","type":"update","data":[{"symbol":"ETH/EUR","bids":[],"asks":[{"price":3502.27,"qty":26.32565914}],"checksum":96780756,"timestamp":"2024-06-01T17:52:21.282624Z"}]}
{"channel":"book","type":"update","data":[{"symbol":"ETH/EUR","bids":[],"asks":[{"price":3502.27,"qty":0.00000000},{"price":3502.79,"qty":0.84644082}],"checksum":640999453,"timestamp":"2024-06-01T17:52:21.286389Z"}]}
{"channel":"book","type":"update","data":[{"symbol":"ETH/EUR","bids":[],"asks":[{"price":3502.24,"qty":0.00000000},{"price":3502.83,"qty":0.00220000},{"price":3502.27,"qty":0.00759963}],"checksum":3515554948,"timestamp":"2024-06-01T17:52:21.303979Z"}]}
{"channel":"book","type":"update","data":[{"symbol":"ETH/EUR","bids":[],"asks":[{"price":3502.26,"qty":26.32569843}],"checksum":3108602311,"timestamp":"2024-06-01T17:52:21.336931Z"}]}
{"channel":"book","type":"update","data":[{"symbol":"ETH/EUR","bids":[],"asks":[{"price":3502.27,"qty":0.00000000},{"price":3502.79,"qty":0.84644082},{"price":3502.35,"qty":0.00759963}],"checksum":1278745467,"timestamp":"2024-06-01T17:52:21.359733Z"}]}
{"channel":"book","type":"update","data":[{"symbol":"ETH/EUR","bids":[],"asks":[{"price":3501.86,"qty":0.10000000},{"price":3501.86,"qty":0.08550000}],"checksum":2207966766,"timestamp":"2024-06-01T17:52:21.627780Z"}]}
{"channel":"book","type":"update","data":[{"symbol":"ETH/EUR","bids":[],"asks":[{"price":3502.35,"qty":0.00000000},{"price":3502.79,"qty":0.84644082},{"price":3502.25,"qty":0.00759964}],"checksum":3761928424,"timestamp":"2024-06-01T17:52:21.786291Z"}]}
{"channel":"book","type":"update","data":[{"symbol":"ETH/EUR","bids":[],"asks":[{"price":3502.26,"qty":0.00000000},{"price":3502.79,"qty":0.84644082}],"checksum":1555801493,"timestamp":"2024-06-01T17:52:21.827024Z"}]}
{"channel":"book","type":"update","data":[{"symbol":"ETH/EUR","bids":[],"asks":[{"price":3502.28,"qty":26.32554483}],"checksum":1910543913,"timestamp":"2024-06-01T17:52:21.830542Z"}]}
{"channel":"book","type":"update","data":[{"symbol":"ETH/EUR","bids":[],"asks":[{"price":3502.25,"qty":0.00000000},{"price":3502.79,"qty":0.84644082},{"price":3502.35,"qty":0.00759964}],"checksum":398867040,"timestamp":"2024-06-01T17:52:21.864606Z"}]}
{"channel":"book","type":"update","data":[{"symbol":"ETH/EUR","bids":[],"asks":[{"price":3502.28,"qty":0.00000000},{"price":3502.79,"qty":0.84644082}],"checksum":2458440798,"timestamp":"2024-06-01T17:52:22.098073Z"}]}
{"channel":"book","type":"update","data":[{"symbol":"ETH/EUR","bids":[],"asks":[{"price":3502.33,"qty":26.32521064}],"checksum":543838230,"timestamp":"2024-06-01T17:52:22.102292Z"}]}
{"channel":"book","type":"update","data":[{"symbol":"ETH/EUR","bids":[],"asks":[{"price":3502.33,"qty":0.00000000},{"price":3502.79,"qty":0.84644082}],"checksum":2458440798,"timestamp":"2024-06-01T17:52:22.125730Z"}]}
{"channel":"book","type":"update","data":[{"symbol":"ETH/EUR","bids":[],"asks":[{"price":3502.32,"qty":26.32527642}],"checksum":2228053617,"timestamp":"2024-06-01T17:52:22.160864Z"}]}
{"channel":"book","type":"update","data":[{"symbol":"ETH/EUR","bids":[],"asks":[{"price":3502.32,"qty":0.00000000},{"price":3502.79,"qty":0.84644082}],"checksum":2458440798,"timestamp":"2024-06-01T17:52:22.177360Z"}]}
{"channel":"book","type":"update","data":[{"symbol":"ETH/EUR","bids":[{"price":3501.45,"qty":15.80365539}],"asks":[],"checksum":689279178,"timestamp":"2024-06-01T17:52:22.205945Z"}]}
{"channel":"book","type":"update","data":[{"symbol":"ETH/EUR","bids":[],"asks":[{"price":3502.31,"qty":26.32534747}],"checksum":2118362228,"timestamp":"2024-06-01T17:52:22.236344Z"}]}
{"channel":"book","type":"update","data":[{"symbol":"ETH/EUR","bids":[],"asks":[{"price":3502.31,"qty":0.00000000},{"price":3502.79,"qty":0.84644082}],"checksum":689279178,"timestamp":"2024-06-01T17:52:22.317639Z"}]}
{"channel":"book","type":"update","data":[{"symbol":"ETH/EUR","bids":[],"asks":[{"price":3502.30,"qty":26.32540499}],"checksum":1769762332,"timestamp":"2024-06-01T17:52:22.321657Z"}]}
{"channel":"book","type":"update","data":[{"symbol":"ETH/EUR","bids":[],"asks":[{"price":3502.30,"qty":0.00000000},{"price":3502.79,"qty":0.84644082}],"checksum":689279178,"timestamp":"2024-06-01T17:52:22.366934Z"}]}
{"channel":"book","type":"update","data":[{"symbol":"ETH/EUR","bids":[],"asks":[{"price":3502.27,"qty":26.32565497}],"checksum":3269161954,"timestamp":"2024-06-01T17:52:22.374304Z"}]}
{"channel":"book","type":"update","data":[{"symbol":"ETH/EUR","bids":[],"asks":[{"price":3502.27,"qty":0.00000000},{"price":3502.79,"qty":0.84644082}],"checksum":689279178,"timestamp":"2024-06-01T17:52:22.460608Z"}]}
{"channel":"book","type":"update","data":[{"symbol":"ETH/EUR","bids":[],"asks":[{"price":3502.29,"qty":26.32548656}],"checksum":3770025091,"timestamp":"2024-06-01T17:52:22.465262Z"}]}
{"channel":"book","type":"update","data":[{"symbol":"ETH/EUR","bids":[],"asks":[{"price":3502.35,"qty":0.00000000},{"price":3502.79,"qty":0.84644082},{"price":3502.28,"qty":0.00760190}],"checksum":1673158169,"timestamp":"2024-06-01T17:52:22.614318Z"}]}
{"channel":"book","type":"update","data":[{"symbol":"ETH/EUR","bids":[],"asks":[{"price":3502.29,"qty":0.00000000},{"price":3502.79,"qty":0.84644082}],"checksum":605240042,"timestamp":"2024-06-01T17:52:22.901865Z"}]}
{"channel":"book","type":"update","data":[{"symbol":"ETH/EUR","bids":[],"asks":[{"price":3502.28,"qty":26.33314914}],"checksum":1674127109,"timestamp":"2024-06-01T17:52:22.906277Z"}]}
{"channel":"book","type":"update","data":[{"symbol":"ETH/EUR","bids":[],"asks":[{"price":3502.28,"qty":0.00760190}],"checksum":605240042,"timestamp":"2024-06-01T17:52:23.276647Z"}]}
{"channel":"book","type":"update","data":[{"symbol":"ETH/EUR","bids":[],"asks":[{"price":3502.35,"qty":26.32503674}],"checksum":988257562,"timestamp":"2024-06-01T17:52:23.280379Z"}]}
{"channel":"book","type":"update","data":[{"symbol":"ETH/EUR","bids":[],"asks":[{"price":3502.35,"qty":0.00000000},{"price":3502.79,"qty":0.84644082}],"checksum":605240042,"timestamp":"2024-06-01T17:52:23.298201Z"}]}
{"channel":"book","type":"update","data":[{"symbol":"ETH/EUR","bids":[],"asks":[{"price":3502.36,"qty":0.00000000},{"price":3502.83,"qty":0.00220000}],"checksum":1929560750,"timestamp":"2024-06-01T17:52:23.301627Z"}]}
{"channel":"book","type":"update","data":[{"symbol":"ETH/EUR","bids":[],"asks":[{"price":3502.62,"qty":26.32296336}],"checksum":1872609854,"timestamp":"2024-06-01T17:52:23.305087Z"}]}
{"channel":"book","type":"update","data":[{"symbol":"ETH/EUR","bids":[],"asks":[{"price":3502.28,"qty":0.00000000},{"price":3502.83,"qty":0.00220000},{"price":3502.34,"qty":0.00760181}],"checksum":2690846693,"timestamp":"2024-06-01T17:52:23.332954Z"}]}
{"channel":"book","type":"update","data":[{"symbol":"ETH/EUR","bids":[],"asks":[{"price":3502.38,"qty":26.93422065}],"checksum":1334910204,"timestamp":"2024-06-01T17:52:23.336292Z"}]}
{"channel":"book","type":"update","data":[{"symbol":"ETH/EUR","bids":[],"asks":[{"price":3502.38,"qty":0.60943644}],"checksum":2690846693,"timestamp":"2024-06-01T17:52:23.392866Z"}]}
{"channel":"book","type":"update","data":[{"symbol":"ETH/EUR","bids":[],"asks":[{"price":3502.37,"qty":26.32487104}],"checksum":3443758012,"timestamp":"2024-06-01T17:52:23.397011Z"}]}
{"channel":"book","type":"update","data":[{"symbol":"ETH/EUR","bids":[],"asks":[{"price":3502.34,"qty":0.00000000},{"price":3502.79,"qty":0.84644082},{"price":3502.37,"qty":26.33247285}],"checksum":643399695,"timestamp":"2024-06-01T17:52:23.398184Z"}]}
{"channel":"book","type":"update","data":[{"symbol":"ETH/EUR","bids":[],"asks":[{"price":3502.37,"qty":26.32487104},{"price":3502.36,"qty":0.00760181}],"checksum":3545928068,"timestamp":"2024-06-01T17:52:23.462679Z"}]}
{"channel":"book","type":"update","data":[{"symbol":"ETH/EUR","bids":[],"asks":[{"price":3502.49,"qty":0.00000000},{"price":3502.79,"qty":0.84644082}],"checksum":1391028997,"timestamp":"2024-06-01T17:52:23.476909Z"}]}
{"channel":"book","type":"update","data":[{"symbol":"ETH/EUR","bids":[],"asks":[{"price":3502.36,"qty":26.33256637}],"checksum":1572989096,"timestamp":"2024-06-01T17:52:23.480346Z"}]}
{"channel":"book","type":"update","data":[{"symbol":"ETH/EUR","bids":[],"asks":[{"price":3502.36,"qty":0.00760181}],"checksum":1391028997,"timestamp":"2024-06-01T17:52:23.530547Z"}]}
{"channel":"book","type":"update","data":[{"symbol":"ETH/EUR","bids":[],"asks":[{"price":3502.37,"qty":0.00000000},{"price":3502.83,"qty":0.00220000}],"checksum":2136092382,"timestamp":"2024-06-01T17:52:23.530602Z"}]}
{"channel":"book","type":"update","data":[{"symbol":"ETH/EUR","bids":[],"asks":[{"price":3502.43,"qty":26.32441809}],"checksum":1987448374,"timestamp":"2024-06-01T17:52:23.536689Z"}]}
{"channel":"book","type":"update","data":[{"symbol":"ETH/EUR","bids":[],"asks":[{"price":3502.48,"qty":26.32405029}],"checksum":3264064338,"timestamp":"2024-06-01T17:52:23.536844Z"}]}
{"channel":"book","type":"update","data":[{"symbol":"ETH/EUR","bids":[],"asks":[{"price":3502.43,"qty":0.00000000},{"price":3502.79,"qty":0.84644082}],"checksum":2823783928,"timestamp":"2024-06-01T17:52:23.563910Z"}]}
{"channel":"book","type":"update","data":[{"symbol":"ETH/EUR","bids":[],"asks":[{"price":3502.44,"qty":0.00000000},{"price":3502.83,"qty":0.00220000}],"checksum":1581785519,"timestamp":"2024-06-01T17:52:23.574824Z"}]}
{"channel":"book","type":"update","data":[{"symbol":"ETH/EUR","bids":[],"asks":[{"price":3502.36,"qty":0.00000000},{"price":3502.84,"qty":20.29335016},{"price":3502.37,"qty":0.00760180}],"checksum":3041373363,"timestamp":"2024-06-01T17:52:23.577238Z"}]}
{"channel":"book","type":"update","data":[{"symbol":"ETH/EUR","bids":[],"asks":[{"price":3502.46,"qty":26.32422866}],"checksum":4254944474,"timestamp":"2024-06-01T17:52:23.589621Z"}]}
{"channel":"book","type":"update","data":[{"symbol":"ETH/EUR","bids":[],"asks":[{"price":3502.46,"qty":0.00000000},{"price":3502.83,"qty":0.00220000}],"checksum":3041373363,"timestamp":"2024-06-01T17:52:23.663471Z"}]}
{"channel":"book","type":"update","data":[{"symbol":"ETH/EUR","bids":[],"asks":[{"price":3502.45,"qty":26.41208425}],"checksum":3684298771,"timestamp":"2024-06-01T17:52:23.668373Z"}]}
{"channel":"book","type":"update","data":[{"symbol":"ETH/EUR","bids":[],"asks":[{"price":3502.45,"qty":0.08777600}],"checksum":3041373363,"timestamp":"2024-06-01T17:52:23.758570Z"}]}
{"channel":"book","type":"update","data":[{"symbol":"ETH/EUR","bids":[],"asks":[{"price":3502.43,"qty":26.32441753}],"checksum":1603363053,"timestamp":"2024-06-01T17:52:23.762400Z"}]}
{"channel":"book","type":"update","data":[{"symbol":"ETH/EUR","bids":[],"asks":[{"price":3502.43,"qty":0.00000000},{"price":3502.83,"qty":0.00220000}],"checksum":3041373363,"timestamp":"2024-06-01T17:52:23.926230Z"}]}
{"channel":"book","type":"update","data":[{"symbol":"ETH/EUR","bids":[],"asks":[{"price":3502.42,"qty":26.32451875}],"checksum":1822301280,"timestamp":"2024-06-01T17:52:23.930095Z"}]}
{"channel":"book","type":"update","data":[{"symbol":"ETH/EUR","bids":[],"asks":[{"price":3502.42,"qty":0.00000000},{"price":3502.83,"qty":0.00220000}],"checksum":3041373363,"timestamp":"2024-06-01T17:52:23.933645Z"}]}
{"channel":"book","type":"update","data":[{"symbol":"ETH/EUR","bids":[],"asks":[{"price":3502.41,"qty":26.32459243}],"checksum":490334116,"timestamp":"2024-06-01T17:52:23.987772Z"}]}
{"channel":"book","type":"update","data":[{"symbol":"ETH/EUR","bids":[],"asks":[{"price":3502.41,"qty":0.00000000},{"price":3502.83,"qty":0.00220000}],"checksum":3041373363,"timestamp":"2024-06-01T17:52:24.072194Z"}]}
{"channel":"book","type":"update","data":[{"symbol":"ETH/EUR","bids":[],"asks":[{"price":3502.40,"qty":26.32463190}],"checksum":654761221,"timestamp":"2024-06-01T17:52:24.075810Z"}]}
{"channel":"book","type":"update","data":[{"symbol":"ETH/EUR","bids":[],"asks":[{"price":3502.40,"qty":0.00000000},{"price":3502.83,"qty":0.00220000}],"checksum":3041373363,"timestamp":"2024-06-01T17:52:24.215753Z"}]}
{"channel":"book","type":"update","data":[{"symbol":"ETH/EUR","bids":[],"asks":[{"price":3502.38,"qty":26.93422885}],"checksum":3703032275,"timestamp":"2024-06-01T17:52:24.219427Z"}]}
{"channel":"book","type":"update","data":[{"symbol":"ETH/EUR","bids":[],"asks":[{"price":3502.42,"qty":21.33368578}],"checksum":3233251097,"timestamp":"2024-06-01T17:52:24.258076Z"}]}
{"channel":"book","type":"update","data":[{"symbol":"ETH/EUR","bids":[],"asks":[{"price":3502.48,"qty":0.00000000},{"price":3502.83,"qty":0.00220000}],"checksum":2326089351,"timestamp":"2024-06-01T17:52:24.370172Z"}]}
{"channel":"book","type":"update","data":[{"symbol":"ETH/EUR","bids":[],"asks":[{"price":3502.31,"qty":26.32532832}],"checksum":875200849,"timestamp":"2024-06-01T17:52:24.374613Z"}]}
{"channel":"book","type":"update","data":[{"symbol":"ETH/EUR","bids":[{"price":3501.30,"qty":0.00000000},{"price":3501.10,"qty":2.00000000},{"price":3501.54,"qty":0.08558600}],"asks":[],"checksum":3158421434,"timestamp":"2024-06-01T17:52:24.395095Z"}]}
{"channel":"book","type":"update","data":[{"symbol":"ETH/EUR","bids":[],"asks":[{"price":3502.79,"qty":0.00000000},{"price":3502.83,"qty":0.00220000}],"checksum":1931758416,"timestamp":"2024-06-01T17:52:24.400221Z"}]}
{"channel":"book","type":"update","data":[{"symbol":"ETH/EUR","bids":[],"asks":[{"price":3502.31,"qty":0.00000000},{"price":3502.85,"qty":26.32123505}],"checksum":29289308,"timestamp":"2024-06-01T17:52:24.404511Z"}]}
{"channel":"book","type":"update","data":[{"symbol":"ETH/EUR","bids":[],"asks":[{"price":3502.46,"qty":26.32417119}],"checksum":1570676089,"timestamp":"2024-06-01T17:52:24.408979Z"}]}
{"channel":"book","type":"update","data":[{"symbol":"ETH/EUR","bids":[],"asks":[{"price":3502.38,"qty":0.60943644}],"checksum":96144121,"timestamp":"2024-06-01T17:52:24.410872Z"}]}
{"channel":"book","type":"update","data":[{"symbol":"ETH/EUR","bids":[],"asks":[{"price":3502.37,"qty":0.00000000},{"price":3502.85,"qty":26.32123505},{"price":3502.30,"qty":0.00760238}],"checksum":1504384771,"timestamp":"2024-06-01T17:52:24.426997Z"}]}
{"channel":"book","type":"update","data":[{"symbol":"ETH/EUR","bids":[],"asks":[{"price":3502.41,"qty":26.32459877}],"checksum":4255518896,"timestamp":"2024-06-01T17:52:24.439030Z"}]}
{"channel":"book","type":"update","data":[{"symbol":"ETH/EUR","bids":[],"asks":[{"price":3502.30,"qty":0.00000000},{"price":3502.83,"qty":0.00220000},{"price":3502.37,"qty":0.00760238}],"checksum":2441978586,"timestamp":"2024-06-01T17:52:24.496988Z"}]}
{"channel":"book","type":"update","data":[{"symbol":"ETH/EUR","bids":[{"price":3501.13,"qty":6.00000000}],"asks":[],"checksum":1145328592,"timestamp":"2024-06-01T17:52:24.630956Z"}]}
{"channel":"book","type":"update","data":[{"symbol":"ETH/EUR","bids":[],"asks":[{"price":3502.41,"qty":0.00000000},{"price":3502.83,"qty":0.00220000}],"checksum":3163046055,"timestamp":"2024-06-01T17:52:24.649892Z"}]}
{"channel":"book","type":"update","data":[{"symbol":"ETH/EUR","bids":[],"asks":[{"price":3502.40,"qty":26.32465403}],"checksum":1405925452,"timestamp":"2024-06-01T17:52:24.652874Z"}]}
{"channel":"book","type":"update","data":[{"symbol":"ETH/EUR","bids":[],"asks":[{"price":3502.40,"qty":0.00000000},{"price":3502.83,"qty":0.00220000}],"checksum":3163046055,"timestamp":"2024-06-01T17:52:24.674734Z"}]}
{"channel":"book","type":"update","data":[{"symbol":"ETH/EUR","bids":[],"asks":[{"price":3502.41,"qty":26.32459087}],"checksum":1962011952,"timestamp":"2024-06-01T17:52:24.718819Z"}]}
{"channel":"book","type":"update","data":[{"symbol":"ETH/EUR","bids":[],"asks":[{"price":3502.41,"qty":0.00000000},{"price":3502.83,"qty":0.00220000}],"checksum":3163046055,"timestamp":"2024-06-01T17:52:24.859207Z"}]}
{"channel":"book","type":"update","data":[{"symbol":"ETH/EUR","bids":[],"asks":[{"price":3502.40,"qty":26.32468389}],"checksum":3330346685,"timestamp":"2024-06-01T17:52:24.862953Z"}]}
{"channel":"book","type":"update","data":[{"symbol":"ETH/EUR","bids":[],"asks":[{"price":3502.40,"qty":0.00000000},{"price":3502.83,"qty":0.00220000}],"checksum":3163046055,"timestamp":"2024-06-01T17:52:24.920960Z"}]}
{"channel":"book","type":"update","data":[{"symbol":"ETH/EUR","bids":[],"asks":[{"price":3502.36,"qty":26.32492597}],"checksum":1798267681,"timestamp":"2024-06-01T17:52:24.925525Z"}]}
{"channel":"book","type":"update","data":[{"symbol":"ETH/EUR","bids":[],"asks":[{"price":3502.37,"qty":0.00000000},{"price":3502.83,"qty":0.00220000},{"price":3502.35,"qty":0.00760238}],"checksum":1398443037,"timestamp":"2024-06-01T17:52:25.259840Z"}]}
{"channel":"book","type":"update","data":[{"symbol":"ETH/EUR","bids":[],"asks":[{"price":3502.36,"qty":0.00000000},{"price":3502.83,"qty":0.00220000}],"checksum":4221543792,"timestamp":"2024-06-01T17:52:25.320821Z"}]}
{"channel":"book","type":"update","data":[{"symbol":"ETH/EUR","bids":[],"asks":[{"price":3502.35,"qty":26.33264590}],"checksum":1929370847,"timestamp":"2024-06-01T17:52:25.324525Z"}]}
{"channel":"book","type":"update","data":[{"symbol":"ETH/EUR","bids":[],"asks":[{"price":3502.35,"qty":0.00760238}],"checksum":4221543792,"timestamp":"2024-06-01T17:52:25.357597Z"}]}
{"channel":"book","type":"update","data":[{"symbol":"ETH/EUR","bids":[{"price":3501.24,"qty":1.31694353}],"asks":[],"checksum":1400977953,"timestamp":"2024-06-01T17:52:25.391157Z"}]}
{"channel":"book","type":"update","data":[{"symbol":"ETH/EUR","bids":[],"asks":[{"price":3502.46,"qty":0.00000000},{"price":3502.85,"qty":26.32123505}],"checksum":416927248,"timestamp":"2024-06-01T17:52:25.400074Z"}]}
{"channel":"book","type":"update","data":[{"symbol":"ETH/EUR","bids":[],"asks":[{"price":3502.38,"qty":26.93420441}],"checksum":1109841677,"timestamp":"2024-06-01T17:52:25.400174Z"}]}
{"channel":"book","type":"update","data":[{"symbol":"ETH/EUR","bids":[],"asks":[{"price":3502.35,"qty":0.00000000},{"price":3502.93,"qty":3.01305282},{"price":3502.37,"qty":0.00760238}],"checksum":1547687221,"timestamp":"2024-06-01T17:52:25.420183Z"}]}
{"channel":"book","type":"update","data":[{"symbol":"ETH/EUR","bids":[],"asks":[{"price":3502.84,"qty":0.05077094}],"checksum":163038351,"timestamp":"2024-06-01T17:52:25.486187Z"}]}
{"channel":"book","type":"update","data":[{"symbol":"ETH/EUR","bids":[],"asks":[{"price":3502.33,"qty":26.32517320}],"checksum":11523332,"timestamp":"2024-06-01T17:52:25.699988Z"}]}
{"channel":"book","type":"update","data":[{"symbol":"ETH/EUR","bids":[],"asks":[{"price":3502.33,"qty":0.00000000},{"price":3502.84,"qty":0.05077094}],"checksum":163038351,"timestamp":"2024-06-01T17:52:25.804066Z"}]}
{"channel":"book","type":"update","data":[{"symbol":"ETH/EUR","bids":[],"asks":[{"price":3502.35,"qty":26.32501005}],"checksum":2023643009,"timestamp":"2024-06-01T17:52:25.808219Z"}]}
{"channel":"book","type":"update","data":[{"symbol":"ETH/EUR","bids":[],"asks":[{"price":3502.35,"qty":0.00000000},{"price":3502.84,"qty":0.05077094}],"checksum":163038351,"timestamp":"2024-06-01T17:52:26.056796Z"}]}
{"channel":"book","type":"update","data":[{"symbol":"ETH/EUR","bids":[],"asks":[{"price":3502.33,"qty":26.32515493}],"checksum":3344485937,"timestamp":"2024-06-01T17:52:26.061828Z"}]}
{"channel":"book","type":"update","data":[{"symbol":"ETH/EUR","bids":[],"asks":[{"price":3502.37,"qty":0.00000000},{"price":3502.84,"qty":0.05077094},{"price":3502.34,"qty":0.00760238}],"checksum":3748420187,"timestamp":"2024-06-01T17:52:26.081945Z"}]}
{"channel":"book","type":"update","data":[{"symbol":"ETH/EUR","bids":[],"asks":[{"price":3502.33,"qty":0.00000000},{"price":3502.84,"qty":0.05077094}],"checksum":4261951510,"timestamp":"2024-06-01T17:52:26.399207Z"}]}
{"channel":"book","type":"update","data":[{"symbol":"ETH/EUR","bids":[],"asks":[{"price":3502.32,"qty":26.32525086}],"checksum":2849691491,"timestamp":"2024-06-01T17:52:26.407083Z"}]}
{"channel":"book","type":"update","data":[{"symbol":"ETH/EUR","bids":[{"price":3501.64,"qty":15.80307264}],"asks":[],"checksum":2505462301,"timestamp":"2024-06-01T17:52:26.464811Z"}]}
{"channel":"book","type":"update","data":[{"symbol":"ETH/EUR","bids":[{"price":3501.26,"qty":0.00000000},{"price":3501.23,"qty":2.19988553}],"asks":[],"checksum":340167556,"timestamp":"2024-06-01T17:52:26.468350Z"}]}
{"channel":"book","type":"update","data":[{"symbol":"ETH/EUR","bids":[],"asks":[{"price":3502.42,"qty":0.00000000},{"price":3502.84,"qty":0.05077094}],"checksum":2009434542,"timestamp":"2024-06-01T17:52:26.638600Z"}]}
{"channel":"book","type":"update","data":[{"symbol":"ETH/EUR","bids":[],"asks":[{"price":3502.84,"qty":10.88501727}],"checksum":1096939856,"timestamp":"2024-06-01T17:52:26.643465Z"}]}
{"channel":"book","type":"update","data":[{"symbol":"ETH/EUR","bids":[],"asks":[{"price":3502.61,"qty":8.32933964}],"checksum":4072958944,"timestamp":"2024-06-01T17:52:26.643479Z"}]}
{"channel":"book","type":"update","data":[{"symbol":"ETH/EUR","bids":[],"asks":[{"price":3502.32,"qty":0.00000000},{"price":3502.84,"qty":10.88501727}],"checksum":184765069,"timestamp":"2024-06-01T17:52:26.650221Z"}]}
{"channel":"book","type":"update","data":[{"symbol":"ETH/EUR","bids":[],"asks":[{"price":3502.34,"qty":26.33268937}],"checksum":1723619650,"timestamp":"2024-06-01T17:52:26.656627Z"}]}
{"channel":"book","type":"update","data":[{"symbol":"ETH/EUR","bids":[{"price":3501.24,"qty":0.00000000},{"price":3501.13,"qty":6.00000000}],"asks":[],"checksum":3466774035,"timestamp":"2024-06-01T17:52:26.888543Z"}]}
{"channel":"book","type":"update","data":[{"symbol":"ETH/EUR","bids":[{"price":3501.53,"qty":0.00000000},{"price":3501.11,"qty":0.61328748},{"price":3501.65,"qty":0.02857115}],"asks":[],"checksum":701685767,"timestamp":"2024-06-01T17:52:26.933426Z"}]}
{"channel":"book","type":"update","data":[{"symbol":"ETH/EUR","bids":[],"asks":[{"price":3502.34,"qty":26.32508699},{"price":3502.33,"qty":0.00760259}],"checksum":3613147806,"timestamp":"2024-06-01T17:52:26.933647Z"}]}
{"channel":"book","type":"update","data":[{"symbol":"ETH/EUR","bids":[],"asks":[{"price":3502.34,"qty":0.00000000},{"price":3502.84,"qty":10.88501727}],"checksum":638276863,"timestamp":"2024-06-01T17:52:27.116804Z"}]}
{"channel":"book","type":"update","data":[{"symbol":"ETH/EUR","bids":[],"asks":[{"price":3502.37,"qty":26.32488345}],"checksum":2977563691,"timestamp":"2024-06-01T17:52:27.120488Z"}]}
{"channel":"book","type":"update","data":[{"symbol":"ETH/EUR","bids":[],"asks":[{"price":3502.37,"qty":0.00000000},{"price":3502.84,"qty":10.88501727}],"checksum":638276863,"timestamp":"2024-06-01T17:52:27.139171Z"}]}
{"channel":"book","type":"update","data":[{"symbol":"ETH/EUR","bids":[],"asks":[{"price":3502.33,"qty":0.00000000},{"price":3502.85,"qty":26.32123505},{"price":3502.36,"qty":0.00760259}],"checksum":462675346,"timestamp":"2024-06-01T17:52:27.177038Z"}]}
{"channel":"book","type":"update","data":[{"symbol":"ETH/EUR","bids":[],"asks":[{"price":3502.35,"qty":26.32501239}],"checksum":152515627,"timestamp":"2024-06-01T17:52:27.189855Z"}]}
{"channel":"book","type":"update","data":[{"symbol":"ETH/EUR","bids":[],"asks":[{"price":3502.36,"qty":0.00000000},{"price":3502.84,"qty":10.88501727},{"price":3502.37,"qty":0.00760259}],"checksum":2007383910,"timestamp":"2024-06-01T17:52:27.219758Z"}]}
{"channel":"book","type":"update","data":[{"symbol":"ETH/EUR","bids":[{"price":3501.24,"qty":1.31694353}],"asks":[],"checksum":3753418807,"timestamp":"2024-06-01T17:52:27.288616Z"}]}
{"channel":"book","type":"update","data":[{"symbol":"ETH/EUR","bids":[],"asks":[{"price":3502.35,"qty":0.00000000},{"price":3502.84,"qty":10.88501727}],"checksum":3220531850,"timestamp":"2024-06-01T17:52:27.400587Z"}]}
{"channel":"book","type":"update","data":[{"symbol":"ETH/EUR","bids":[],"asks":[{"price":3502.34,"qty":26.32511791}],"checksum":750453498,"timestamp":"2024-06-01T17:52:27.405408Z"}]}
{"channel":"book","type":"update","data":[{"symbol":"ETH/EUR","bids":[],"asks":[{"price":3502.37,"qty":0.00000000},{"price":3502.84,"qty":10.83424633},{"price":3502.33,"qty":0.00760259}],"checksum":3666194265,"timestamp":"2024-06-01T17:52:27.835769Z"}]}
{"channel":"book","type":"update","data":[{"symbol":"ETH/EUR","bids":[],"asks":[{"price":3502.34,"qty":0.00000000},{"price":3502.84,"qty":10.83424633}],"checksum":879530221,"timestamp":"2024-06-01T17:52:27.913883Z"}]}
{"channel":"book","type":"update","data":[{"symbol":"ETH/EUR","bids":[],"asks":[{"price":3502.33,"qty":26.33278628}],"checksum":2719541675,"timestamp":"2024-06-01T17:52:27.917553Z"}]}
{"channel":"book","type":"update","data":[{"symbol":"ETH/EUR","bids":[],"asks":[{"price":3502.33,"qty":0.00760259}],"checksum":879530221,"timestamp":"2024-06-01T17:52:28.096182Z"}]}
{"channel":"book","type":"update","data":[{"symbol":"ETH/EUR","bids":[],"asks":[{"price":3502.36,"qty":26.32495366}],"checksum":1594878795,"timestamp":"2024-06-01T17:52:28.100042Z"}]}
{"channel":"book","type":"update","data":[{"symbol":"ETH/EUR","bids":[],"asks":[{"price":3502.36,"qty":0.00000000},{"price":3502.84,"qty":10.83424633}],"checksum":879530221,"timestamp":"2024-06-01T17:52:28.112047Z"}]}
{"channel":"book","type":"update","data":[{"symbol":"ETH/EUR","bids":[],"asks":[{"price":3502.33,"qty":0.00000000},{"price":3502.85,"qty":26.32123505},{"price":3502.37,"qty":0.00760259}],"checksum":93073865,"timestamp":"2024-06-01T17:52:28.150021Z"}]}
{"channel":"book","type":"update","data":[{"symbol":"ETH/EUR","bids":[],"asks":[{"price":3502.36,"qty":26.32492734}],"checksum":1487034189,"timestamp":"2024-06-01T17:52:28.165041Z"}]}
{"channel":"book","type":"update","data":[{"symbol":"ETH/EUR","bids":[],"asks":[{"price":3502.36,"qty":0.00000000},{"price":3502.84,"qty":10.83424633}],"checksum":93073865,"timestamp":"2024-06-01T17:52:28.243768Z"}]}
{"channel":"book","type":"update","data":[{"symbol":"ETH/EUR","bids":[{"price":3501.52,"qty":0.00000000},{"price":3501.13,"qty":6.00000000}],"asks":[],"checksum":3585466597,"timestamp":"2024-06-01T17:52:28.246656Z"}]}
{"channel":"book","type":"update","data":[{"symbol":"ETH/EUR","bids":[{"price":3501.85,"qty":57.49749472}],"asks":[],"checksum":1573858531,"timestamp":"2024-06-01T17:52:28.246758Z"}]}
{"channel":"book","type":"update","data":[{"symbol":"ETH/EUR","bids":[],"asks":[{"price":3502.35,"qty":26.32504049}],"checksum":1579314516,"timestamp":"2024-06-01T17:52:28.247711Z"}]}
{"channel":"book","type":"update","data":[{"symbol":"ETH/EUR","bids":[],"asks":[{"price":3502.35,"qty":0.00000000},{"price":3502.84,"qty":10.83424633}],"checksum":1573858531,"timestamp":"2024-06-01T17:52:28.270285Z"}]}
{"channel":"book","type":"update","data":[{"symbol":"ETH/EUR","bids":[],"asks":[{"price":3502.36,"qty":26.32496532}],"checksum":1846650637,"timestamp":"2024-06-01T17:52:28.578438Z"}]}
{"channel":"book","type":"update","data":[{"symbol":"ETH/EUR","bids":[],"asks":[{"price":3502.37,"qty":0.00000000},{"price":3502.84,"qty":10.83424633},{"price":3502.35,"qty":0.00760262}],"checksum":3964949796,"timestamp":"2024-06-01T17:52:28.748543Z"}]}
{"channel":"book","type":"update","data":[{"symbol":"ETH/EUR","bids":[],"asks":[{"price":3502.61,"qty":0.00000000},{"price":3502.85,"qty":26.32123505}],"checksum":2182089909,"timestamp":"2024-06-01T17:52:29.098323Z"}]}
{"channel":"book","type":"update","data":[{"symbol":"ETH/EUR","bids":[],"asks":[{"price":3502.35,"qty":6.25624610}],"checksum":575102021,"timestamp":"2024-06-01T17:52:29.103056Z"}]}
{"channel":"book","type":"update","data":[{"symbol":"ETH/EUR","bids":[],"asks":[{"price":3502.36,"qty":0.00000000},{"price":3502.93,"qty":3.01305282}],"checksum":1305559202,"timestamp":"2024-06-01T17:52:29.282622Z"}]}
{"channel":"book","type":"update","data":[{"symbol":"ETH/EUR","bids":[],"asks":[{"price":3502.33,"qty":26.32514609}],"checksum":2365668545,"timestamp":"2024-06-01T17:52:29.286448Z"}]}
{"channel":"book","type":"update","data":[{"symbol":"ETH/EUR","bids":[],"asks":[{"price":3502.33,"qty":0.00000000},{"price":3502.93,"qty":3.01305282}],"checksum":1305559202,"timestamp":"2024-06-01T17:52:29.562010Z"}]}
{"channel":"book","type":"update","data":[{"symbol":"ETH/EUR","bids":[],"asks":[{"price":3502.35,"qty":32.58125154}],"checksum":1593641083,"timestamp":"2024-06-01T17:52:29.565978Z"}]}
{"channel":"book","type":"update","data":[{"symbol":"ETH/EUR","bids":[],"asks":[{"price":3502.35,"qty":32.57364892},{"price":3502.34,"qty":0.00760262}],"checksum":3093683714,"timestamp":"2024-06-01T17:52:29.649500Z"}]}
{"channel":"book","type":"update","data":[{"symbol":"ETH/EUR","bids":[{"price":3501.85,"qty":83.82624208}],"asks":[],"checksum":251628511,"timestamp":"2024-06-01T17:52:29.737907Z"}]}
{"channel":"book","type":"update","data":[{"symbol":"ETH/EUR","bids":[{"price":3501.85,"qty":57.49749472}],"asks":[],"checksum":3093683714,"timestamp":"2024-06-01T17:52:29.801716Z"}]}
{"channel":"book","type":"update","data":[{"symbol":"ETH/EUR","bids":[],"asks":[{"price":3502.35,"qty":6.24864348}],"checksum":693921806,"timestamp":"2024-06-01T17:52:29.806520Z"}]}
{"channel":"book","type":"update","data":[{"symbol":"ETH/EUR","bids":[],"asks":[{"price":3502.46,"qty":26.32421477}],"checksum":2031496759,"timestamp":"2024-06-01T17:52:29.812156Z"}]}
{"channel":"book","type":"update","data":[{"symbol":"ETH/EUR","bids":[],"asks":[{"price":3502.38,"qty":0.60943644}],"checksum":2735896445,"timestamp":"2024-06-01T17:52:30.221371Z"}]}
{"channel":"book","type":"update","data":[{"symbol":"ETH/EUR","bids":[],"asks":[{"price":3502.44,"qty":26.32433239}],"checksum":1064294193,"timestamp":"2024-06-01T17:52:30.226823Z"}]}
{"channel":"book","type":"update","data":[{"symbol":"ETH/EUR","bids":[{"price":3501.51,"qty":0.00000000},{"price":3501.11,"qty":0.61328748}],"asks":[],"checksum":1895620295,"timestamp":"2024-06-01T17:52:30.266058Z"}]}
{"channel":"book","type":"update","data":[{"symbol":"ETH/EUR","bids":[],"asks":[{"price":3502.44,"qty":0.00000000},{"price":3502.83,"qty":0.00220000}],"checksum":1741389892,"timestamp":"2024-06-01T17:52:30.266088Z"}]}
{"channel":"book","type":"update","data":[{"symbol":"ETH/EUR","bids":[],"asks":[{"price":3502.46,"qty":0.00000000},{"price":3502.85,"qty":26.32123505}],"checksum":2403115751,"timestamp":"2024-06-01T17:52:30.266436Z"}]}
{"channel":"book","type":"update","data":[{"symbol":"ETH/EUR","bids":[],"asks":[{"price":3502.72,"qty":26.32222815}],"checksum":2345640402,"timestamp":"2024-06-01T17:52:30.271027Z"}]}
