{"channel":"book","type":"update","data":[{"symbol":"ETH/AUD","bids":[],"asks":[{"price":5716.74,"qty":0.00000000},{"price":5719.79,"qty":1.60677000},{"price":5717.47,"qty":0.53135194}],"checksum":1862286513,"timestamp":"2024-06-01T17:52:47.749918Z"}]}
{"channel":"book","type":"update","data":[{"symbol":"ETH/AUD","bids":[],"asks":[{"price":5716.86,"qty":9.81384515}],"checksum":4180835387,"timestamp":"2024-06-01T17:52:47.752198Z"}]}
{"channel":"book","type":"update","data":[{"symbol":"ETH/AUD","bids":[],"asks":[{"price":5716.72,"qty":0.83372964}],"checksum":1897871171,"timestamp":"2024-06-01T17:52:47.764588Z"}]}
{"channel":"book","type":"update","data":[{"symbol":"ETH/AUD","bids":[{"price":5709.88,"qty":0.01716359}],"asks":[],"checksum":2081597021,"timestamp":"2024-06-01T17:52:47.912365Z"}]}
{"channel":"book","type":"update","data":[{"symbol":"ETH/AUD","bids":[{"price":5709.89,"qty":0.90387105}],"asks":[],"checksum":911750383,"timestamp":"2024-06-01T17:52:47.918184Z"}]}
{"channel":"book","type":"update","data":[{"symbol":"ETH/AUD","bids":[{"price":5709.86,"qty":0.00000000},{"price":5705.25,"qty":1.60677000},{"price":5709.90,"qty":0.07347674}],"asks":[],"checksum":3507286543,"timestamp":"2024-06-01T17:52:47.946173Z"}]}
{"channel":"book","type":"update","data":[{"symbol":"ETH/AUD","bids":[{"price":5709.85,"qty":0.00000000},{"price":5705.25,"qty":1.60677000}],"asks":[],"checksum":1318513934,"timestamp":"2024-06-01T17:52:47.952938Z"}]}
{"channel":"book","type":"update","data":[{"symbol":"ETH/AUD","bids":[],"asks":[{"price":5716.72,"qty":0.00000000},{"price":5719.72,"qty":0.08600000}],"checksum":1804039126,"timestamp":"2024-06-01T17:52:48.020179Z"}]}
{"channel":"book","type":"update","data":[{"symbol":"ETH/AUD","bids":[{"price":5705.44,"qty":0.00000000},{"price":5703.19,"qty":0.74674649}],"asks":[],"checksum":3958984330,"timestamp":"2024-06-01T17:52:48.076811Z"}]}
{"channel":"book","type":"update","data":[{"symbol":"ETH/AUD","bids":[{"price":5705.29,"qty":0.52676214}],"asks":[],"checksum":2257514975,"timestamp":"2024-06-01T17:52:48.204967Z"}]}
{"channel":"book","type":"update","data":[{"symbol":"ETH/AUD","bids":[{"price":5703.20,"qty":0.02559260}],"asks":[],"checksum":1232082283,"timestamp":"2024-06-01T17:52:48.205560Z"}]}
{"channel":"book","type":"update","data":[{"symbol":"ETH/AUD","bids":[{"price":5705.31,"qty":0.02582156}],"asks":[],"checksum":1072044964,"timestamp":"2024-06-01T17:52:48.205603Z"}]}
{"channel":"book","type":"update","data":[{"symbol":"ETH/AUD","bids":[{"price":5705.29,"qty":0.00000000},{"price":5703.20,"qty":0.02559260}],"asks":[],"checksum":2343995904,"timestamp":"2024-06-01T17:52:48.229386Z"}]}
{"channel":"book","type":"update","data":[{"symbol":"ETH/AUD","bids":[{"price":5705.31,"qty":1.06639942}],"asks":[],"checksum":1108986291,"timestamp":"2024-06-01T17:52:48.230235Z"}]}
{"channel":"book","type":"update","data":[{"symbol":"ETH/AUD","bids":[{"price":5703.20,"qty":7.09115743}],"asks":[],"checksum":296560097,"timestamp":"2024-06-01T17:52:48.230280Z"}]}
{"channel":"book","type":"update","data":[{"symbol":"ETH/AUD","bids":[{"price":5705.30,"qty":0.00000000},{"price":5703.19,"qty":0.74674649},{"price":5705.26,"qty":0.52360000}],"asks":[],"checksum":3266218001,"timestamp":"2024-06-01T17:52:48.232519Z"}]}
{"channel":"book","type":"update","data":[{"symbol":"ETH/AUD","bids":[{"price":5703.21,"qty":0.74674387}],"asks":[],"checksum":3338498169,"timestamp":"2024-06-01T17:52:48.260227Z"}]}
{"channel":"book","type":"update","data":[{"symbol":"ETH/AUD","bids":[],"asks":[{"price":5717.47,"qty":0.00775194},{"price":5716.85,"qty":0.52360000}],"checksum":2092258942,"timestamp":"2024-06-01T17:52:48.262993Z"}]}
{"channel":"book","type":"update","data":[{"symbol":"ETH/AUD","bids":[{"price":5709.87,"qty":0.00000000},{"price":5703.20,"qty":7.09115743},{"price":5709.91,"qty":1.03772098}],"asks":[],"checksum":937037278,"timestamp":"2024-06-01T17:52:48.445030Z"}]}
{"channel":"book","type":"update","data":[{"symbol":"ETH/AUD","bids":[{"price":5709.90,"qty":0.00000000},{"price":5703.20,"qty":7.09115743},{"price":5709.92,"qty":0.07347674}],"asks":[],"checksum":680785908,"timestamp":"2024-06-01T17:52:48.468163Z"}]}
