{"channel":"book","type":"update","data":[{"symbol":"ETH/GBP","bids":[{"price":2978.07,"qty":0.00000000},{"price":2974.30,"qty":0.30200000}],"asks":[],"checksum":3975129177,"timestamp":"2024-06-01T17:52:38.601665Z"}]}
{"channel":"book","type":"update","data":[{"symbol":"ETH/GBP","bids":[{"price":2977.61,"qty":0.00000000},{"price":2973.93,"qty":0.27474654}],"asks":[],"checksum":1391271989,"timestamp":"2024-06-01T17:52:38.601708Z"}]}
{"channel":"book","type":"update","data":[{"symbol":"ETH/GBP","bids":[],"asks":[{"price":2978.47,"qty":6.58514394}],"checksum":1280886479,"timestamp":"2024-06-01T17:52:38.609171Z"}]}
{"channel":"book","type":"update","data":[{"symbol":"ETH/GBP","bids":[{"price":2977.10,"qty":6.58816244}],"asks":[],"checksum":362024706,"timestamp":"2024-06-01T17:52:38.642105Z"}]}
{"channel":"book","type":"update","data":[{"symbol":"ETH/GBP","bids":[{"price":2977.13,"qty":1.31697214}],"asks":[],"checksum":3265147279,"timestamp":"2024-06-01T17:52:38.645177Z"}]}
{"channel":"book","type":"update","data":[{"symbol":"ETH/GBP","bids":[{"price":2977.10,"qty":0.00000000},{"price":2974.30,"qty":0.30200000}],"asks":[],"checksum":2884370540,"timestamp":"2024-06-01T17:52:38.646399Z"}]}
{"channel":"book","type":"update","data":[{"symbol":"ETH/GBP","bids":[{"price":2977.09,"qty":0.00000000},{"price":2973.93,"qty":0.27474654}],"asks":[],"checksum":3630701857,"timestamp":"2024-06-01T17:52:38.647893Z"}]}
{"channel":"book","type":"update","data":[{"symbol":"ETH/GBP","bids":[],"asks":[{"price":2978.47,"qty":0.00000000},{"price":2980.95,"qty":0.22400000}],"checksum":3336436699,"timestamp":"2024-06-01T17:52:38.649891Z"}]}
{"channel":"book","type":"update","data":[{"symbol":"ETH/GBP","bids":[],"asks":[{"price":2978.47,"qty":6.58514189}],"checksum":3505209230,"timestamp":"2024-06-01T17:52:38.727148Z"}]}
{"channel":"book","type":"update","data":[{"symbol":"ETH/GBP","bids":[],"asks":[{"price":2978.94,"qty":13.16824649}],"checksum":531924773,"timestamp":"2024-06-01T17:52:38.789848Z"}]}
{"channel":"book","type":"update","data":[{"symbol":"ETH/GBP","bids":[{"price":2978.15,"qty":6.58583376}],"asks":[],"checksum":3969132719,"timestamp":"2024-06-01T17:52:38.789996Z"}]}
{"channel":"book","type":"update","data":[{"symbol":"ETH/GBP","bids":[{"price":2977.14,"qty":13.17614962}],"asks":[],"checksum":48432618,"timestamp":"2024-06-01T17:52:38.790065Z"}]}
{"channel":"book","type":"update","data":[{"symbol":"ETH/GBP","bids":[{"price":2977.14,"qty":0.00000000},{"price":2974.30,"qty":0.30200000}],"asks":[],"checksum":3969132719,"timestamp":"2024-06-01T17:52:38.794678Z"}]}
{"channel":"book","type":"update","data":[{"symbol":"ETH/GBP","bids":[{"price":2978.15,"qty":0.00000000},{"price":2973.93,"qty":0.27474654}],"asks":[],"checksum":531924773,"timestamp":"2024-06-01T17:52:38.873045Z"}]}
{"channel":"book","type":"update","data":[{"symbol":"ETH/GBP","bids":[],"asks":[{"price":2978.47,"qty":0.00000000},{"price":2980.94,"qty":0.00775181}],"checksum":2071363271,"timestamp":"2024-06-01T17:52:38.873152Z"}]}
{"channel":"book","type":"update","data":[{"symbol":"ETH/GBP","bids":[],"asks":[{"price":2978.93,"qty":6.58414154}],"checksum":791016875,"timestamp":"2024-06-01T17:52:38.878088Z"}]}
{"channel":"book","type":"update","data":[{"symbol":"ETH/GBP","bids":[],"asks":[{"price":2979.66,"qty":1.31650600}],"checksum":327064547,"timestamp":"2024-06-01T17:52:38.878230Z"}]}
{"channel":"book","type":"update","data":[{"symbol":"ETH/GBP","bids":[],"asks":[{"price":2978.93,"qty":0.00000000},{"price":2980.58,"qty":13.43327015}],"checksum":1922884660,"timestamp":"2024-06-01T17:52:38.882850Z"}]}
{"channel":"book","type":"update","data":[{"symbol":"ETH/GBP","bids":[],"asks":[{"price":2980.57,"qty":0.00000000},{"price":2980.94,"qty":0.00775181}],"checksum":3810170963,"timestamp":"2024-06-01T17:52:38.897471Z"}]}
{"channel":"book","type":"update","data":[{"symbol":"ETH/GBP","bids":[],"asks":[{"price":2979.72,"qty":0.52676296}],"checksum":2721438456,"timestamp":"2024-06-01T17:52:38.902172Z"}]}
{"channel":"book","type":"update","data":[{"symbol":"ETH/GBP","bids":[],"asks":[{"price":2980.57,"qty":20.80695408}],"checksum":986687784,"timestamp":"2024-06-01T17:52:38.902219Z"}]}
{"channel":"book","type":"update","data":[{"symbol":"ETH/GBP","bids":[{"price":2977.14,"qty":6.58806441}],"asks":[],"checksum":1438434674,"timestamp":"2024-06-01T17:52:38.923516Z"}]}
{"channel":"book","type":"update","data":[{"symbol":"ETH/GBP","bids":[{"price":2977.17,"qty":1.31696465}],"asks":[],"checksum":2792455058,"timestamp":"2024-06-01T17:52:38.926716Z"}]}
{"channel":"book","type":"update","data":[{"symbol":"ETH/GBP","bids":[{"price":2977.14,"qty":0.00000000},{"price":2974.30,"qty":0.30200000}],"asks":[],"checksum":1597563035,"timestamp":"2024-06-01T17:52:38.928105Z"}]}
{"channel":"book","type":"update","data":[{"symbol":"ETH/GBP","bids":[{"price":2977.13,"qty":0.00000000},{"price":2973.93,"qty":0.27474654}],"asks":[],"checksum":736015585,"timestamp":"2024-06-01T17:52:38.929740Z"}]}
{"channel":"book","type":"update","data":[{"symbol":"ETH/GBP","bids":[],"asks":[{"price":2978.49,"qty":6.58510238}],"checksum":3119967796,"timestamp":"2024-06-01T17:52:38.979097Z"}]}
{"channel":"book","type":"update","data":[{"symbol":"ETH/GBP","bids":[{"price":2977.18,"qty":13.17597347}],"asks":[],"checksum":2857315050,"timestamp":"2024-06-01T17:52:39.022277Z"}]}
{"channel":"book","type":"update","data":[{"symbol":"ETH/GBP","bids":[{"price":2976.77,"qty":1.31777658}],"asks":[],"checksum":3540536704,"timestamp":"2024-06-01T17:52:39.022343Z"}]}
{"channel":"book","type":"update","data":[{"symbol":"ETH/GBP","bids":[{"price":2977.21,"qty":1.31696389}],"asks":[],"checksum":3436489949,"timestamp":"2024-06-01T17:52:39.025175Z"}]}
{"channel":"book","type":"update","data":[{"symbol":"ETH/GBP","bids":[{"price":2977.17,"qty":0.00000000},{"price":2974.45,"qty":1.31880744}],"asks":[],"checksum":2810833137,"timestamp":"2024-06-01T17:52:39.025263Z"}]}
{"channel":"book","type":"update","data":[{"symbol":"ETH/GBP","bids":[{"price":2977.18,"qty":0.00000000},{"price":2974.30,"qty":0.30200000}],"asks":[],"checksum":794016733,"timestamp":"2024-06-01T17:52:39.029835Z"}]}
{"channel":"book","type":"update","data":[{"symbol":"ETH/GBP","bids":[{"price":2978.17,"qty":6.58579490}],"asks":[],"checksum":166670981,"timestamp":"2024-06-01T17:52:39.033596Z"}]}
{"channel":"book","type":"update","data":[{"symbol":"ETH/GBP","bids":[{"price":2978.17,"qty":0.00000000},{"price":2974.30,"qty":0.30200000}],"asks":[],"checksum":794016733,"timestamp":"2024-06-01T17:52:39.037921Z"}]}
{"channel":"book","type":"update","data":[{"symbol":"ETH/GBP","bids":[],"asks":[{"price":2978.49,"qty":0.00000000},{"price":2980.57,"qty":20.80695408}],"checksum":3648566748,"timestamp":"2024-06-01T17:52:39.099877Z"}]}
{"channel":"book","type":"update","data":[{"symbol":"ETH/GBP","bids":[],"asks":[{"price":2978.51,"qty":6.58506751}],"checksum":1892433723,"timestamp":"2024-06-01T17:52:39.104592Z"}]}
{"channel":"book","type":"update","data":[{"symbol":"ETH/GBP","bids":[{"price":2975.79,"qty":0.00000000},{"price":2973.93,"qty":0.27474654}],"asks":[],"checksum":3591134550,"timestamp":"2024-06-01T17:52:39.128860Z"}]}
{"channel":"book","type":"update","data":[{"symbol":"ETH/GBP","bids":[],"asks":[{"price":2978.51,"qty":0.00000000},{"price":2980.57,"qty":20.80695408}],"checksum":3727223226,"timestamp":"2024-06-01T17:52:39.178852Z"}]}
{"channel":"book","type":"update","data":[{"symbol":"ETH/GBP","bids":[{"price":2978.19,"qty":6.58575340}],"asks":[],"checksum":3099039314,"timestamp":"2024-06-01T17:52:39.183185Z"}]}
{"channel":"book","type":"update","data":[{"symbol":"ETH/GBP","bids":[{"price":2978.19,"qty":0.00000000},{"price":2973.93,"qty":0.27474654}],"asks":[],"checksum":3727223226,"timestamp":"2024-06-01T17:52:39.206979Z"}]}
{"channel":"book","type":"update","data":[{"symbol":"ETH/GBP","bids":[],"asks":[{"price":2978.50,"qty":6.58508812}],"checksum":3321091043,"timestamp":"2024-06-01T17:52:39.211752Z"}]}
{"channel":"book","type":"update","data":[{"symbol":"ETH/GBP","bids":[{"price":2977.22,"qty":13.17579778}],"asks":[],"checksum":1553836879,"timestamp":"2024-06-01T17:52:39.228143Z"}]}
{"channel":"book","type":"update","data":[{"symbol":"ETH/GBP","bids":[{"price":2977.25,"qty":1.31693921}],"asks":[],"checksum":3363218993,"timestamp":"2024-06-01T17:52:39.231641Z"}]}
{"channel":"book","type":"update","data":[{"symbol":"ETH/GBP","bids":[{"price":2977.22,"qty":0.00000000},{"price":2974.30,"qty":0.30200000}],"asks":[],"checksum":2407429415,"timestamp":"2024-06-01T17:52:39.233010Z"}]}
{"channel":"book","type":"update","data":[{"symbol":"ETH/GBP","bids":[{"price":2977.21,"qty":0.00000000},{"price":2973.93,"qty":0.27474654}],"asks":[],"checksum":3730475806,"timestamp":"2024-06-01T17:52:39.234416Z"}]}
{"channel":"book","type":"update","data":[{"symbol":"ETH/GBP","bids":[],"asks":[{"price":2978.50,"qty":0.00000000},{"price":2980.57,"qty":20.80695408}],"checksum":3313611079,"timestamp":"2024-06-01T17:52:39.253551Z"}]}
{"channel":"book","type":"update","data":[{"symbol":"ETH/GBP","bids":[{"price":2978.16,"qty":6.58580543}],"asks":[],"checksum":232850620,"timestamp":"2024-06-01T17:52:39.427012Z"}]}
{"channel":"book","type":"update","data":[{"symbol":"ETH/GBP","bids":[],"asks":[{"price":2978.93,"qty":6.58413889}],"checksum":1908875417,"timestamp":"2024-06-01T17:52:39.427046Z"}]}
{"channel":"book","type":"update","data":[{"symbol":"ETH/GBP","bids":[],"asks":[{"price":2978.93,"qty":0.00000000},{"price":2980.57,"qty":20.80695408}],"checksum":232850620,"timestamp":"2024-06-01T17:52:39.432304Z"}]}
{"channel":"book","type":"update","data":[{"symbol":"ETH/GBP","bids":[{"price":2977.70,"qty":13.17364869}],"asks":[],"checksum":2628725778,"timestamp":"2024-06-01T17:52:39.439091Z"}]}
{"channel":"book","type":"update","data":[{"symbol":"ETH/GBP","bids":[{"price":2978.16,"qty":0.00000000},{"price":2974.30,"qty":0.30200000}],"asks":[],"checksum":1003316218,"timestamp":"2024-06-01T17:52:39.439582Z"}]}
{"channel":"book","type":"update","data":[{"symbol":"ETH/GBP","bids":[{"price":2976.77,"qty":0.00000000},{"price":2973.93,"qty":0.27474654}],"asks":[],"checksum":315200660,"timestamp":"2024-06-01T17:52:39.439591Z"}]}
{"channel":"book","type":"update","data":[{"symbol":"ETH/GBP","bids":[{"price":2977.70,"qty":0.00000000},{"price":2973.19,"qty":0.14113766}],"asks":[],"checksum":2804903130,"timestamp":"2024-06-01T17:52:39.443284Z"}]}
{"channel":"book","type":"update","data":[{"symbol":"ETH/GBP","bids":[],"asks":[{"price":2978.52,"qty":6.58504342}],"checksum":692241466,"timestamp":"2024-06-01T17:52:39.534807Z"}]}
{"channel":"book","type":"update","data":[{"symbol":"ETH/GBP","bids":[{"price":2977.26,"qty":6.58780153}],"asks":[],"checksum":2680361840,"timestamp":"2024-06-01T17:52:39.535045Z"}]}
{"channel":"book","type":"update","data":[{"symbol":"ETH/GBP","bids":[{"price":2976.18,"qty":1.04065154}],"asks":[],"checksum":3240223936,"timestamp":"2024-06-01T17:52:39.537435Z"}]}
{"channel":"book","type":"update","data":[{"symbol":"ETH/GBP","bids":[{"price":2977.29,"qty":1.31694209}],"asks":[],"checksum":3785318266,"timestamp":"2024-06-01T17:52:39.537897Z"}]}
{"channel":"book","type":"update","data":[{"symbol":"ETH/GBP","bids":[{"price":2977.26,"qty":0.00000000},{"price":2974.30,"qty":0.30200000}],"asks":[],"checksum":2142114677,"timestamp":"2024-06-01T17:52:39.539465Z"}]}
{"channel":"book","type":"update","data":[{"symbol":"ETH/GBP","bids":[{"price":2977.25,"qty":0.00000000},{"price":2973.93,"qty":0.27474654}],"asks":[],"checksum":4020132993,"timestamp":"2024-06-01T17:52:39.540487Z"}]}
{"channel":"book","type":"update","data":[{"symbol":"ETH/GBP","bids":[],"asks":[{"price":2978.52,"qty":0.00000000},{"price":2980.57,"qty":20.80695408}],"checksum":1327158097,"timestamp":"2024-06-01T17:52:39.585124Z"}]}
{"channel":"book","type":"update","data":[{"symbol":"ETH/GBP","bids":[{"price":2977.77,"qty":13.17334874}],"asks":[],"checksum":3178341707,"timestamp":"2024-06-01T17:52:39.670289Z"}]}
{"channel":"book","type":"update","data":[{"symbol":"ETH/GBP","bids":[],"asks":[{"price":2978.93,"qty":6.58413800}],"checksum":974280580,"timestamp":"2024-06-01T17:52:39.670360Z"}]}
{"channel":"book","type":"update","data":[{"symbol":"ETH/GBP","bids":[{"price":2978.23,"qty":6.58565548}],"asks":[],"checksum":912316424,"timestamp":"2024-06-01T17:52:39.670459Z"}]}
{"channel":"book","type":"update","data":[{"symbol":"ETH/GBP","bids":[],"asks":[{"price":2978.93,"qty":0.00000000},{"price":2980.57,"qty":20.80695408}],"checksum":1027368155,"timestamp":"2024-06-01T17:52:39.675571Z"}]}
{"channel":"book","type":"update","data":[{"symbol":"ETH/GBP","bids":[{"price":2978.23,"qty":0.00000000},{"price":2974.30,"qty":0.30200000}],"asks":[],"checksum":3178341707,"timestamp":"2024-06-01T17:52:39.878388Z"}]}
{"channel":"book","type":"update","data":[{"symbol":"ETH/GBP","bids":[{"price":2977.77,"qty":0.00000000},{"price":2973.93,"qty":0.27474654}],"asks":[],"checksum":1327158097,"timestamp":"2024-06-01T17:52:39.883716Z"}]}
{"channel":"book","type":"update","data":[{"symbol":"ETH/GBP","bids":[],"asks":[{"price":2978.53,"qty":6.58501594}],"checksum":1144788056,"timestamp":"2024-06-01T17:52:39.888750Z"}]}
{"channel":"book","type":"update","data":[{"symbol":"ETH/GBP","bids":[{"price":2978.24,"qty":6.58563039}],"asks":[],"checksum":3034893527,"timestamp":"2024-06-01T17:52:39.888790Z"}]}
{"channel":"book","type":"update","data":[{"symbol":"ETH/GBP","bids":[{"price":2977.30,"qty":13.17542781}],"asks":[],"checksum":2873012451,"timestamp":"2024-06-01T17:52:39.888830Z"}]}
{"channel":"book","type":"update","data":[{"symbol":"ETH/GBP","bids":[{"price":2977.30,"qty":0.00000000},{"price":2974.30,"qty":0.30200000}],"asks":[],"checksum":3034893527,"timestamp":"2024-06-01T17:52:39.894596Z"}]}
{"channel":"book","type":"update","data":[{"symbol":"ETH/GBP","bids":[],"asks":[{"price":2978.94,"qty":0.00000000},{"price":2980.57,"qty":20.80695408}],"checksum":590257027,"timestamp":"2024-06-01T17:52:39.959280Z"}]}
{"channel":"book","type":"update","data":[{"symbol":"ETH/GBP","bids":[{"price":2978.24,"qty":0.00000000},{"price":2973.93,"qty":0.27474654}],"asks":[],"checksum":1555220563,"timestamp":"2024-06-01T17:52:39.959292Z"}]}
{"channel":"book","type":"update","data":[{"symbol":"ETH/GBP","bids":[],"asks":[{"price":2980.09,"qty":0.00000000},{"price":2980.58,"qty":13.43327015}],"checksum":3565397586,"timestamp":"2024-06-01T17:52:39.959382Z"}]}
{"channel":"book","type":"update","data":[{"symbol":"ETH/GBP","bids":[],"asks":[{"price":2978.53,"qty":0.00000000},{"price":2980.94,"qty":0.00775181}],"checksum":2509063536,"timestamp":"2024-06-01T17:52:39.959408Z"}]}
{"channel":"book","type":"update","data":[{"symbol":"ETH/GBP","bids":[],"asks":[{"price":2980.57,"qty":22.12305810}],"checksum":3856395204,"timestamp":"2024-06-01T17:52:39.966318Z"}]}
{"channel":"book","type":"update","data":[{"symbol":"ETH/GBP","bids":[],"asks":[{"price":2979.64,"qty":13.16512585}],"checksum":2376518322,"timestamp":"2024-06-01T17:52:39.966367Z"}]}
{"channel":"book","type":"update","data":[{"symbol":"ETH/GBP","bids":[],"asks":[{"price":2979.64,"qty":0.00000000},{"price":2980.94,"qty":0.00775181}],"checksum":3856395204,"timestamp":"2024-06-01T17:52:39.971375Z"}]}
{"channel":"book","type":"update","data":[{"symbol":"ETH/GBP","bids":[],"asks":[{"price":2978.57,"qty":6.58492967}],"checksum":3265025254,"timestamp":"2024-06-01T17:52:40.054553Z"}]}
{"channel":"book","type":"update","data":[{"symbol":"ETH/GBP","bids":[{"price":2977.31,"qty":6.58769797}],"asks":[],"checksum":4279940188,"timestamp":"2024-06-01T17:52:40.054621Z"}]}
{"channel":"book","type":"update","data":[{"symbol":"ETH/GBP","bids":[{"price":2977.00,"qty":1.31767616}],"asks":[],"checksum":588545829,"timestamp":"2024-06-01T17:52:40.054746Z"}]}
{"channel":"book","type":"update","data":[{"symbol":"ETH/GBP","bids":[{"price":2976.21,"qty":1.31802709}],"asks":[],"checksum":2194600170,"timestamp":"2024-06-01T17:52:40.054767Z"}]}
{"channel":"book","type":"update","data":[{"symbol":"ETH/GBP","bids":[{"price":2977.34,"qty":1.31691819}],"asks":[],"checksum":148505074,"timestamp":"2024-06-01T17:52:40.058114Z"}]}
{"channel":"book","type":"update","data":[{"symbol":"ETH/GBP","bids":[{"price":2977.31,"qty":0.00000000},{"price":2974.46,"qty":0.34510000}],"asks":[],"checksum":3431342133,"timestamp":"2024-06-01T17:52:40.060476Z"}]}
{"channel":"book","type":"update","data":[{"symbol":"ETH/GBP","bids":[{"price":2977.29,"qty":0.00000000},{"price":2974.45,"qty":1.31880744}],"asks":[],"checksum":3090677410,"timestamp":"2024-06-01T17:52:40.061185Z"}]}
{"channel":"book","type":"update","data":[{"symbol":"ETH/GBP","bids":[{"price":2977.42,"qty":0.31000000}],"asks":[],"checksum":928005484,"timestamp":"2024-06-01T17:52:40.107809Z"}]}
{"channel":"book","type":"update","data":[{"symbol":"ETH/GBP","bids":[{"price":2977.43,"qty":13.17487468}],"asks":[],"checksum":977218076,"timestamp":"2024-06-01T17:52:40.113147Z"}]}
{"channel":"book","type":"update","data":[{"symbol":"ETH/GBP","bids":[{"price":2977.43,"qty":0.00000000},{"price":2974.46,"qty":0.34510000}],"asks":[],"checksum":928005484,"timestamp":"2024-06-01T17:52:40.117501Z"}]}
{"channel":"book","type":"update","data":[{"symbol":"ETH/GBP","bids":[{"price":2976.35,"qty":0.00000000},{"price":2974.45,"qty":1.31880744},{"price":2977.43,"qty":0.08560700}],"asks":[],"checksum":1189565960,"timestamp":"2024-06-01T17:52:40.282275Z"}]}
{"channel":"book","type":"update","data":[{"symbol":"ETH/GBP","bids":[],"asks":[{"price":2978.57,"qty":0.00000000},{"price":2980.94,"qty":0.00775181}],"checksum":2476757075,"timestamp":"2024-06-01T17:52:40.358987Z"}]}
{"channel":"book","type":"update","data":[{"symbol":"ETH/GBP","bids":[],"asks":[{"price":2979.58,"qty":0.31000000}],"checksum":3720380736,"timestamp":"2024-06-01T17:52:40.362146Z"}]}
{"channel":"book","type":"update","data":[{"symbol":"ETH/GBP","bids":[],"asks":[{"price":2979.64,"qty":13.16511966}],"checksum":4044901426,"timestamp":"2024-06-01T17:52:40.364119Z"}]}
{"channel":"book","type":"update","data":[{"symbol":"ETH/GBP","bids":[{"price":2978.27,"qty":6.58556651}],"asks":[],"checksum":969151891,"timestamp":"2024-06-01T17:52:40.364220Z"}]}
{"channel":"book","type":"update","data":[{"symbol":"ETH/GBP","bids":[],"asks":[{"price":2978.56,"qty":6.58495206}],"checksum":83055811,"timestamp":"2024-06-01T17:52:40.364233Z"}]}
{"channel":"book","type":"update","data":[{"symbol":"ETH/GBP","bids":[{"price":2977.81,"qty":13.17317076}],"asks":[],"checksum":4106879973,"timestamp":"2024-06-01T17:52:40.364277Z"}]}
{"channel":"book","type":"update","data":[{"symbol":"ETH/GBP","bids":[],"asks":[{"price":2979.64,"qty":0.00000000},{"price":2980.57,"qty":22.12305810}],"checksum":3673259634,"timestamp":"2024-06-01T17:52:40.369705Z"}]}
{"channel":"book","type":"update","data":[{"symbol":"ETH/GBP","bids":[{"price":2978.27,"qty":0.00000000},{"price":2975.32,"qty":1.31842115}],"asks":[],"checksum":1910734952,"timestamp":"2024-06-01T17:52:40.410230Z"}]}
{"channel":"book","type":"update","data":[{"symbol":"ETH/GBP","bids":[{"price":2977.42,"qty":0.00000000},{"price":2974.46,"qty":0.34510000}],"asks":[],"checksum":1285887132,"timestamp":"2024-06-01T17:52:40.412856Z"}]}
{"channel":"book","type":"update","data":[{"symbol":"ETH/GBP","bids":[{"price":2977.89,"qty":0.31000000}],"asks":[],"checksum":4215923016,"timestamp":"2024-06-01T17:52:40.413390Z"}]}
{"channel":"book","type":"update","data":[{"symbol":"ETH/GBP","bids":[{"price":2977.81,"qty":0.00000000},{"price":2974.46,"qty":0.34510000}],"asks":[],"checksum":2272118602,"timestamp":"2024-06-01T17:52:40.414571Z"}]}
{"channel":"book","type":"update","data":[{"symbol":"ETH/GBP","bids":[{"price":2977.89,"qty":0.00000000},{"price":2974.45,"qty":1.31880744}],"asks":[],"checksum":1843665059,"timestamp":"2024-06-01T17:52:40.417225Z"}]}
{"channel":"book","type":"update","data":[{"symbol":"ETH/GBP","bids":[{"price":2978.30,"qty":6.58550711}],"asks":[],"checksum":2356076990,"timestamp":"2024-06-01T17:52:40.475625Z"}]}
{"channel":"book","type":"update","data":[{"symbol":"ETH/GBP","bids":[],"asks":[{"price":2979.82,"qty":0.00000000},{"price":2980.58,"qty":13.43327015}],"checksum":1756456116,"timestamp":"2024-06-01T17:52:40.478660Z"}]}
{"channel":"book","type":"update","data":[{"symbol":"ETH/GBP","bids":[],"asks":[{"price":2980.56,"qty":2.94416492}],"checksum":3274339289,"timestamp":"2024-06-01T17:52:40.481498Z"}]}
{"channel":"book","type":"update","data":[{"symbol":"ETH/GBP","bids":[{"price":2978.30,"qty":0.00000000},{"price":2974.45,"qty":1.31880744}],"asks":[],"checksum":580946628,"timestamp":"2024-06-01T17:52:40.517266Z"}]}
{"channel":"book","type":"update","data":[{"symbol":"ETH/GBP","bids":[{"price":2977.43,"qty":1.40252749}],"asks":[],"checksum":1572978143,"timestamp":"2024-06-01T17:52:40.520332Z"}]}
{"channel":"book","type":"update","data":[{"symbol":"ETH/GBP","bids":[],"asks":[{"price":2978.56,"qty":0.00000000},{"price":2980.58,"qty":13.43327015}],"checksum":105421920,"timestamp":"2024-06-01T17:52:40.786225Z"}]}
{"channel":"book","type":"update","data":[{"symbol":"ETH/GBP","bids":[{"price":2977.34,"qty":0.00000000},{"price":2974.30,"qty":0.30200000}],"asks":[],"checksum":4110252557,"timestamp":"2024-06-01T17:52:40.789242Z"}]}
{"channel":"book","type":"update","data":[{"symbol":"ETH/GBP","bids":[],"asks":[{"price":2978.42,"qty":6.58527308}],"checksum":617481219,"timestamp":"2024-06-01T17:52:40.791893Z"}]}
{"channel":"book","type":"update","data":[{"symbol":"ETH/GBP","bids":[{"price":2978.16,"qty":6.58580830}],"asks":[],"checksum":4076473508,"timestamp":"2024-06-01T17:52:40.792021Z"}]}
{"channel":"book","type":"update","data":[{"symbol":"ETH/GBP","bids":[{"price":2977.70,"qty":13.17365443}],"asks":[],"checksum":1108735105,"timestamp":"2024-06-01T17:52:40.792173Z"}]}
{"channel":"book","type":"update","data":[{"symbol":"ETH/GBP","bids":[],"asks":[{"price":2978.91,"qty":13.16835035}],"checksum":1719696650,"timestamp":"2024-06-01T17:52:40.792349Z"}]}
{"channel":"book","type":"update","data":[{"symbol":"ETH/GBP","bids":[],"asks":[{"price":2978.91,"qty":0.00000000},{"price":2980.57,"qty":22.12305810}],"checksum":1108735105,"timestamp":"2024-06-01T17:52:40.798357Z"}]}
{"channel":"book","type":"update","data":[{"symbol":"ETH/GBP","bids":[{"price":2977.43,"qty":0.08560700}],"asks":[],"checksum":172224716,"timestamp":"2024-06-01T17:52:40.810107Z"}]}
{"channel":"book","type":"update","data":[{"symbol":"ETH/GBP","bids":[{"price":2978.16,"qty":0.00000000},{"price":2974.45,"qty":1.31880744}],"asks":[],"checksum":1065454018,"timestamp":"2024-06-01T17:52:40.874291Z"}]}
{"channel":"book","type":"update","data":[{"symbol":"ETH/GBP","bids":[],"asks":[{"price":2978.42,"qty":0.00000000},{"price":2980.58,"qty":13.43327015}],"checksum":4021483468,"timestamp":"2024-06-01T17:52:40.874565Z"}]}
{"channel":"book","type":"update","data":[{"symbol":"ETH/GBP","bids":[],"asks":[{"price":2979.55,"qty":1.31708025}],"checksum":3821046830,"timestamp":"2024-06-01T17:52:40.877695Z"}]}
{"channel":"book","type":"update","data":[{"symbol":"ETH/GBP","bids":[],"asks":[{"price":2979.73,"qty":0.00000000},{"price":2980.58,"qty":13.43327015}],"checksum":4069208626,"timestamp":"2024-06-01T17:52:40.880739Z"}]}
{"channel":"book","type":"update","data":[{"symbol":"ETH/GBP","bids":[{"price":2977.71,"qty":6.58680242}],"asks":[],"checksum":3818156252,"timestamp":"2024-06-01T17:52:40.907989Z"}]}
{"channel":"book","type":"update","data":[{"symbol":"ETH/GBP","bids":[],"asks":[{"price":2978.36,"qty":6.58538999}],"checksum":3678131754,"timestamp":"2024-06-01T17:52:40.908029Z"}]}
{"channel":"book","type":"update","data":[{"symbol":"ETH/GBP","bids":[{"price":2977.71,"qty":0.00000000},{"price":2974.45,"qty":1.31880744}],"asks":[],"checksum":3391395012,"timestamp":"2024-06-01T17:52:40.913974Z"}]}
{"channel":"book","type":"update","data":[{"symbol":"ETH/GBP","bids":[{"price":2977.70,"qty":0.00000000},{"price":2974.30,"qty":0.30200000}],"asks":[],"checksum":260626028,"timestamp":"2024-06-01T17:52:40.937753Z"}]}
{"channel":"book","type":"update","data":[{"symbol":"ETH/GBP","bids":[],"asks":[{"price":2978.36,"qty":0.00000000},{"price":2980.58,"qty":13.43327015}],"checksum":1821041261,"timestamp":"2024-06-01T17:52:40.970497Z"}]}
{"channel":"book","type":"update","data":[{"symbol":"ETH/GBP","bids":[],"asks":[{"price":2979.81,"qty":0.00000000},{"price":2980.94,"qty":0.00775181},{"price":2979.03,"qty":0.06969100}],"checksum":4116770780,"timestamp":"2024-06-01T17:52:40.978213Z"}]}
{"channel":"book","type":"update","data":[{"symbol":"ETH/GBP","bids":[{"price":2977.45,"qty":13.17478751}],"asks":[],"checksum":2390520692,"timestamp":"2024-06-01T17:52:41.041935Z"}]}
{"channel":"book","type":"update","data":[{"symbol":"ETH/GBP","bids":[],"asks":[{"price":2978.37,"qty":6.58538370}],"checksum":1097998032,"timestamp":"2024-06-01T17:52:41.041964Z"}]}
{"channel":"book","type":"update","data":[{"symbol":"ETH/GBP","bids":[],"asks":[{"price":2978.83,"qty":13.16873003}],"checksum":3606468744,"timestamp":"2024-06-01T17:52:41.042044Z"}]}
{"channel":"book","type":"update","data":[{"symbol":"ETH/GBP","bids":[{"price":2978.10,"qty":6.58595243}],"asks":[],"checksum":850347176,"timestamp":"2024-06-01T17:52:41.042114Z"}]}
{"channel":"book","type":"update","data":[{"symbol":"ETH/GBP","bids":[{"price":2977.45,"qty":0.00000000},{"price":2974.45,"qty":1.31880744}],"asks":[],"checksum":2616413630,"timestamp":"2024-06-01T17:52:41.047701Z"}]}
{"channel":"book","type":"update","data":[{"symbol":"ETH/GBP","bids":[{"price":2978.10,"qty":0.00000000},{"price":2974.30,"qty":0.30200000}],"asks":[],"checksum":720881173,"timestamp":"2024-06-01T17:52:41.072767Z"}]}
{"channel":"book","type":"update","data":[{"symbol":"ETH/GBP","bids":[],"asks":[{"price":2978.37,"qty":0.00000000},{"price":2980.57,"qty":22.12305810}],"checksum":2414500436,"timestamp":"2024-06-01T17:52:41.113572Z"}]}
{"channel":"book","type":"update","data":[{"symbol":"ETH/GBP","bids":[],"asks":[{"price":2979.03,"qty":0.00000000},{"price":2980.58,"qty":13.43327015},{"price":2979.54,"qty":0.06976400}],"checksum":3465340750,"timestamp":"2024-06-01T17:52:41.158201Z"}]}
{"channel":"book","type":"update","data":[{"symbol":"ETH/GBP","bids":[],"asks":[{"price":2978.38,"qty":6.58534748}],"checksum":2890983263,"timestamp":"2024-06-01T17:52:41.276203Z"}]}
{"channel":"book","type":"update","data":[{"symbol":"ETH/GBP","bids":[{"price":2977.44,"qty":6.58740968}],"asks":[],"checksum":920613292,"timestamp":"2024-06-01T17:52:41.276231Z"}]}
{"channel":"book","type":"update","data":[{"symbol":"ETH/GBP","bids":[{"price":2977.44,"qty":19.76224675}],"asks":[],"checksum":3174099515,"timestamp":"2024-06-01T17:52:41.276323Z"}]}
{"channel":"book","type":"update","data":[{"symbol":"ETH/GBP","bids":[{"price":2977.44,"qty":6.58740968}],"asks":[],"checksum":920613292,"timestamp":"2024-06-01T17:52:41.283494Z"}]}
{"channel":"book","type":"update","data":[{"symbol":"ETH/GBP","bids":[{"price":2977.44,"qty":0.00000000},{"price":2974.30,"qty":0.30200000}],"asks":[],"checksum":2890983263,"timestamp":"2024-06-01T17:52:41.283572Z"}]}
{"channel":"book","type":"update","data":[{"symbol":"ETH/GBP","bids":[],"asks":[{"price":2978.38,"qty":0.00000000},{"price":2980.57,"qty":22.12305810}],"checksum":3465340750,"timestamp":"2024-06-01T17:52:41.283579Z"}]}
{"channel":"book","type":"update","data":[{"symbol":"ETH/GBP","bids":[],"asks":[{"price":2979.72,"qty":0.00000000},{"price":2980.58,"qty":13.43327015}],"checksum":1442100901,"timestamp":"2024-06-01T17:52:41.445021Z"}]}
{"channel":"book","type":"update","data":[{"symbol":"ETH/GBP","bids":[],"asks":[{"price":2980.57,"qty":1.31610402}],"checksum":1702349411,"timestamp":"2024-06-01T17:52:41.445189Z"}]}
{"channel":"book","type":"update","data":[{"symbol":"ETH/GBP","bids":[],"asks":[{"price":2980.55,"qty":26.01528441}],"checksum":483582843,"timestamp":"2024-06-01T17:52:41.447796Z"}]}
{"channel":"book","type":"update","data":[{"symbol":"ETH/GBP","bids":[],"asks":[{"price":2978.82,"qty":6.58437561}],"checksum":3741263935,"timestamp":"2024-06-01T17:52:41.731314Z"}]}
{"channel":"book","type":"update","data":[{"symbol":"ETH/GBP","bids":[{"price":2978.11,"qty":6.58592345}],"asks":[],"checksum":327097237,"timestamp":"2024-06-01T17:52:41.731382Z"}]}
{"channel":"book","type":"update","data":[{"symbol":"ETH/GBP","bids":[{"price":2977.44,"qty":13.17481937}],"asks":[],"checksum":3975693958,"timestamp":"2024-06-01T17:52:41.731398Z"}]}
{"channel":"book","type":"update","data":[{"symbol":"ETH/GBP","bids":[],"asks":[{"price":2978.82,"qty":0.00000000},{"price":2980.57,"qty":1.31610402}],"checksum":1952126354,"timestamp":"2024-06-01T17:52:41.736708Z"}]}
{"channel":"book","type":"update","data":[{"symbol":"ETH/GBP","bids":[{"price":2977.44,"qty":0.00000000},{"price":2974.45,"qty":1.31880744}],"asks":[],"checksum":1644999639,"timestamp":"2024-06-01T17:52:41.736748Z"}]}
{"channel":"book","type":"update","data":[{"symbol":"ETH/GBP","bids":[{"price":2978.11,"qty":0.00000000},{"price":2974.30,"qty":0.30200000}],"asks":[],"checksum":483582843,"timestamp":"2024-06-01T17:52:41.744276Z"}]}
{"channel":"book","type":"update","data":[{"symbol":"ETH/GBP","bids":[{"price":2978.13,"qty":6.58587858}],"asks":[],"checksum":3398989950,"timestamp":"2024-06-01T17:52:41.900614Z"}]}
{"channel":"book","type":"update","data":[{"symbol":"ETH/GBP","bids":[],"asks":[{"price":2978.82,"qty":6.58437561}],"checksum":3152793660,"timestamp":"2024-06-01T17:52:41.900661Z"}]}
{"channel":"book","type":"update","data":[{"symbol":"ETH/GBP","bids":[],"asks":[{"price":2978.82,"qty":0.00000000},{"price":2980.57,"qty":1.31610402}],"checksum":3398989950,"timestamp":"2024-06-01T17:52:41.905092Z"}]}
{"channel":"book","type":"update","data":[{"symbol":"ETH/GBP","bids":[{"price":2976.18,"qty":0.00000000},{"price":2974.30,"qty":0.30200000}],"asks":[],"checksum":3716179966,"timestamp":"2024-06-01T17:52:42.062829Z"}]}
{"channel":"book","type":"update","data":[{"symbol":"ETH/GBP","bids":[{"price":2976.22,"qty":2.58238670}],"asks":[],"checksum":2880237767,"timestamp":"2024-06-01T17:52:42.063864Z"}]}
{"channel":"book","type":"update","data":[{"symbol":"ETH/GBP","bids":[{"price":2977.67,"qty":13.17381345}],"asks":[],"checksum":75685046,"timestamp":"2024-06-01T17:52:42.141732Z"}]}
{"channel":"book","type":"update","data":[{"symbol":"ETH/GBP","bids":[],"asks":[{"price":2978.40,"qty":6.58530630}],"checksum":1339073350,"timestamp":"2024-06-01T17:52:42.141771Z"}]}
{"channel":"book","type":"update","data":[{"symbol":"ETH/GBP","bids":[{"price":2978.13,"qty":0.00000000},{"price":2974.45,"qty":1.31880744}],"asks":[],"checksum":3343593402,"timestamp":"2024-06-01T17:52:42.312962Z"}]}
{"channel":"book","type":"update","data":[{"symbol":"ETH/GBP","bids":[],"asks":[{"price":2978.40,"qty":0.00000000},{"price":2980.57,"qty":1.31610402}],"checksum":2350469194,"timestamp":"2024-06-01T17:52:42.313097Z"}]}
{"channel":"book","type":"update","data":[{"symbol":"ETH/GBP","bids":[{"price":2977.67,"qty":0.00000000},{"price":2974.30,"qty":0.30200000}],"asks":[],"checksum":3862758804,"timestamp":"2024-06-01T17:52:42.318512Z"}]}
{"channel":"book","type":"update","data":[{"symbol":"ETH/GBP","bids":[{"price":2978.14,"qty":6.58585026}],"asks":[],"checksum":1292434870,"timestamp":"2024-06-01T17:52:42.322681Z"}]}
{"channel":"book","type":"update","data":[{"symbol":"ETH/GBP","bids":[],"asks":[{"price":2978.43,"qty":6.58524505}],"checksum":2086609085,"timestamp":"2024-06-01T17:52:42.322815Z"}]}
{"channel":"book","type":"update","data":[{"symbol":"ETH/GBP","bids":[],"asks":[{"price":2978.43,"qty":0.00000000},{"price":2980.57,"qty":1.31610402}],"checksum":1292434870,"timestamp":"2024-06-01T17:52:42.328169Z"}]}
{"channel":"book","type":"update","data":[{"symbol":"ETH/GBP","bids":[{"price":2978.14,"qty":0.00000000},{"price":2974.30,"qty":0.30200000}],"asks":[],"checksum":3862758804,"timestamp":"2024-06-01T17:52:42.343626Z"}]}
{"channel":"book","type":"update","data":[{"symbol":"ETH/GBP","bids":[],"asks":[{"price":2978.83,"qty":0.00000000},{"price":2980.58,"qty":13.43327015}],"checksum":2976654282,"timestamp":"2024-06-01T17:52:42.343718Z"}]}
{"channel":"book","type":"update","data":[{"symbol":"ETH/GBP","bids":[],"asks":[{"price":2979.52,"qty":13.16564459}],"checksum":57545278,"timestamp":"2024-06-01T17:52:42.348742Z"}]}
{"channel":"book","type":"update","data":[{"symbol":"ETH/GBP","bids":[{"price":2977.45,"qty":13.17478795}],"asks":[],"checksum":1146152347,"timestamp":"2024-06-01T17:52:42.348792Z"}]}
{"channel":"book","type":"update","data":[{"symbol":"ETH/GBP","bids":[],"asks":[{"price":2979.52,"qty":0.00000000},{"price":2980.58,"qty":13.43327015}],"checksum":1700688666,"timestamp":"2024-06-01T17:52:42.354604Z"}]}
{"channel":"book","type":"update","data":[{"symbol":"ETH/GBP","bids":[{"price":2977.45,"qty":0.00000000},{"price":2974.30,"qty":0.30200000}],"asks":[],"checksum":2976654282,"timestamp":"2024-06-01T17:52:42.354691Z"}]}
{"channel":"book","type":"update","data":[{"symbol":"ETH/GBP","bids":[{"price":2977.45,"qty":6.58739397}],"asks":[],"checksum":2082138971,"timestamp":"2024-06-01T17:52:42.453143Z"}]}
{"channel":"book","type":"update","data":[{"symbol":"ETH/GBP","bids":[],"asks":[{"price":2978.43,"qty":6.58523651}],"checksum":2608734286,"timestamp":"2024-06-01T17:52:42.453229Z"}]}
{"channel":"book","type":"update","data":[{"symbol":"ETH/GBP","bids":[{"price":2977.45,"qty":0.00000000},{"price":2974.30,"qty":0.30200000}],"asks":[],"checksum":1837773252,"timestamp":"2024-06-01T17:52:42.457966Z"}]}
{"channel":"book","type":"update","data":[{"symbol":"ETH/GBP","bids":[],"asks":[{"price":2978.43,"qty":0.00000000},{"price":2980.58,"qty":13.43327015}],"checksum":2976654282,"timestamp":"2024-06-01T17:52:42.547131Z"}]}
{"channel":"book","type":"update","data":[{"symbol":"ETH/GBP","bids":[{"price":2978.19,"qty":6.58574875}],"asks":[],"checksum":2420737297,"timestamp":"2024-06-01T17:52:42.554108Z"}]}
{"channel":"book","type":"update","data":[{"symbol":"ETH/GBP","bids":[{"price":2977.44,"qty":13.17483707}],"asks":[],"checksum":371990966,"timestamp":"2024-06-01T17:52:42.554171Z"}]}
{"channel":"book","type":"update","data":[{"symbol":"ETH/GBP","bids":[],"asks":[{"price":2979.52,"qty":13.16564459}],"checksum":925022007,"timestamp":"2024-06-01T17:52:42.554267Z"}]}
{"channel":"book","type":"update","data":[{"symbol":"ETH/GBP","bids":[],"asks":[{"price":2978.45,"qty":6.58519766}],"checksum":2571720130,"timestamp":"2024-06-01T17:52:42.554282Z"}]}
{"channel":"book","type":"update","data":[{"symbol":"ETH/GBP","bids":[{"price":2977.44,"qty":0.00000000},{"price":2974.45,"qty":1.31880744}],"asks":[],"checksum":2426605261,"timestamp":"2024-06-01T17:52:42.560146Z"}]}
{"channel":"book","type":"update","data":[{"symbol":"ETH/GBP","bids":[],"asks":[{"price":2979.52,"qty":0.00000000},{"price":2980.57,"qty":1.31610402}],"checksum":637644776,"timestamp":"2024-06-01T17:52:42.560236Z"}]}
{"channel":"book","type":"update","data":[{"symbol":"ETH/GBP","bids":[],"asks":[{"price":2978.45,"qty":0.00000000},{"price":2980.58,"qty":13.43327015}],"checksum":2420737297,"timestamp":"2024-06-01T17:52:42.570070Z"}]}
{"channel":"book","type":"update","data":[{"symbol":"ETH/GBP","bids":[],"asks":[{"price":2979.58,"qty":0.00000000},{"price":2980.94,"qty":0.00775181}],"checksum":3570563911,"timestamp":"2024-06-01T17:52:42.686509Z"}]}
{"channel":"book","type":"update","data":[{"symbol":"ETH/GBP","bids":[],"asks":[{"price":2979.46,"qty":0.31000000}],"checksum":2260013374,"timestamp":"2024-06-01T17:52:42.686855Z"}]}
{"channel":"book","type":"update","data":[{"symbol":"ETH/GBP","bids":[],"asks":[{"price":2978.44,"qty":6.58521354}],"checksum":1681770453,"timestamp":"2024-06-01T17:52:42.690982Z"}]}
{"channel":"book","type":"update","data":[{"symbol":"ETH/GBP","bids":[{"price":2978.19,"qty":0.00000000},{"price":2974.30,"qty":0.30200000}],"asks":[],"checksum":295417564,"timestamp":"2024-06-01T17:52:43.077715Z"}]}
{"channel":"book","type":"update","data":[{"symbol":"ETH/GBP","bids":[],"asks":[{"price":2978.44,"qty":0.00000000},{"price":2980.58,"qty":13.43327015}],"checksum":557271317,"timestamp":"2024-06-01T17:52:43.077864Z"}]}
{"channel":"book","type":"update","data":[{"symbol":"ETH/GBP","bids":[{"price":2977.51,"qty":0.31000000}],"asks":[],"checksum":3457106666,"timestamp":"2024-06-01T17:52:43.080876Z"}]}
{"channel":"book","type":"update","data":[{"symbol":"ETH/GBP","bids":[],"asks":[{"price":2978.57,"qty":6.58493336}],"checksum":1704151842,"timestamp":"2024-06-01T17:52:43.085338Z"}]}
{"channel":"book","type":"update","data":[{"symbol":"ETH/GBP","bids":[],"asks":[{"price":2979.03,"qty":13.16782949}],"checksum":3166833133,"timestamp":"2024-06-01T17:52:43.085362Z"}]}
{"channel":"book","type":"update","data":[{"symbol":"ETH/GBP","bids":[{"price":2978.31,"qty":6.58547769}],"asks":[],"checksum":3557747130,"timestamp":"2024-06-01T17:52:43.085418Z"}]}
{"channel":"book","type":"update","data":[{"symbol":"ETH/GBP","bids":[{"price":2977.44,"qty":13.17483662}],"asks":[],"checksum":2310685882,"timestamp":"2024-06-01T17:52:43.085515Z"}]}
{"channel":"book","type":"update","data":[{"symbol":"ETH/GBP","bids":[],"asks":[{"price":2978.57,"qty":0.00000000},{"price":2980.57,"qty":1.31610402}],"checksum":3931672760,"timestamp":"2024-06-01T17:52:43.092279Z"}]}
{"channel":"book","type":"update","data":[{"symbol":"ETH/GBP","bids":[{"price":2978.31,"qty":0.00000000},{"price":2974.46,"qty":0.34510000}],"asks":[],"checksum":2288885345,"timestamp":"2024-06-01T17:52:43.092340Z"}]}
{"channel":"book","type":"update","data":[{"symbol":"ETH/GBP","bids":[{"price":2977.44,"qty":0.00000000},{"price":2974.45,"qty":1.31880744}],"asks":[],"checksum":181804897,"timestamp":"2024-06-01T17:52:43.092416Z"}]}
{"channel":"book","type":"update","data":[{"symbol":"ETH/GBP","bids":[],"asks":[{"price":2979.03,"qty":0.00000000},{"price":2980.58,"qty":13.43327015}],"checksum":3457106666,"timestamp":"2024-06-01T17:52:43.092478Z"}]}
{"channel":"book","type":"update","data":[{"symbol":"ETH/GBP","bids":[],"asks":[{"price":2979.45,"qty":6.58299551}],"checksum":716133905,"timestamp":"2024-06-01T17:52:43.384531Z"}]}
{"channel":"book","type":"update","data":[{"symbol":"ETH/GBP","bids":[],"asks":[{"price":2979.45,"qty":19.74898653}],"checksum":1969775633,"timestamp":"2024-06-01T17:52:43.384567Z"}]}
{"channel":"book","type":"update","data":[{"symbol":"ETH/GBP","bids":[{"price":2977.52,"qty":13.17444105}],"asks":[],"checksum":2399292514,"timestamp":"2024-06-01T17:52:43.384629Z"}]}
{"channel":"book","type":"update","data":[{"symbol":"ETH/GBP","bids":[{"price":2978.35,"qty":6.58538482}],"asks":[],"checksum":6137308,"timestamp":"2024-06-01T17:52:43.384682Z"}]}
{"channel":"book","type":"update","data":[{"symbol":"ETH/GBP","bids":[],"asks":[{"price":2979.45,"qty":6.58299551}],"checksum":3364531099,"timestamp":"2024-06-01T17:52:43.392090Z"}]}
{"channel":"book","type":"update","data":[{"symbol":"ETH/GBP","bids":[],"asks":[{"price":2979.45,"qty":0.00000000},{"price":2980.58,"qty":13.43327015}],"checksum":622371632,"timestamp":"2024-06-01T17:52:43.392122Z"}]}
{"channel":"book","type":"update","data":[{"symbol":"ETH/GBP","bids":[{"price":2978.35,"qty":0.00000000},{"price":2974.46,"qty":0.34510000}],"asks":[],"checksum":2782265552,"timestamp":"2024-06-01T17:52:43.392136Z"}]}
{"channel":"book","type":"update","data":[{"symbol":"ETH/GBP","bids":[{"price":2977.52,"qty":0.00000000},{"price":2974.45,"qty":1.31880744}],"asks":[],"checksum":3457106666,"timestamp":"2024-06-01T17:52:43.392313Z"}]}
{"channel":"book","type":"update","data":[{"symbol":"ETH/GBP","bids":[{"price":2978.33,"qty":6.58543100}],"asks":[],"checksum":4173591279,"timestamp":"2024-06-01T17:52:43.508986Z"}]}
{"channel":"book","type":"update","data":[{"symbol":"ETH/GBP","bids":[],"asks":[{"price":2978.58,"qty":6.58490056}],"checksum":4243658741,"timestamp":"2024-06-01T17:52:43.509022Z"}]}
{"channel":"book","type":"update","data":[{"symbol":"ETH/GBP","bids":[],"asks":[{"price":2978.58,"qty":0.00000000},{"price":2980.58,"qty":13.43327015}],"checksum":4173591279,"timestamp":"2024-06-01T17:52:43.543831Z"}]}
{"channel":"book","type":"update","data":[{"symbol":"ETH/GBP","bids":[{"price":2978.33,"qty":0.00000000},{"price":2974.45,"qty":1.31880744}],"asks":[],"checksum":3457106666,"timestamp":"2024-06-01T17:52:43.543903Z"}]}
{"channel":"book","type":"update","data":[{"symbol":"ETH/GBP","bids":[],"asks":[{"price":2978.97,"qty":13.16811427}],"checksum":3847994430,"timestamp":"2024-06-01T17:52:43.591705Z"}]}
{"channel":"book","type":"update","data":[{"symbol":"ETH/GBP","bids":[{"price":2977.52,"qty":13.17444105}],"asks":[],"checksum":608387811,"timestamp":"2024-06-01T17:52:43.591880Z"}]}
{"channel":"book","type":"update","data":[{"symbol":"ETH/GBP","bids":[{"price":2977.52,"qty":0.00000000},{"price":2974.45,"qty":1.31880744}],"asks":[],"checksum":3847994430,"timestamp":"2024-06-01T17:52:43.596797Z"}]}
{"channel":"book","type":"update","data":[{"symbol":"ETH/GBP","bids":[],"asks":[{"price":2978.97,"qty":0.00000000},{"price":2980.58,"qty":13.43327015}],"checksum":3457106666,"timestamp":"2024-06-01T17:52:43.599057Z"}]}
{"channel":"book","type":"update","data":[{"symbol":"ETH/GBP","bids":[],"asks":[{"price":2978.50,"qty":6.58508881}],"checksum":2084853902,"timestamp":"2024-06-01T17:52:43.611109Z"}]}
{"channel":"book","type":"update","data":[{"symbol":"ETH/GBP","bids":[{"price":2978.25,"qty":6.58561946}],"asks":[],"checksum":540667635,"timestamp":"2024-06-01T17:52:43.611168Z"}]}
{"channel":"book","type":"update","data":[{"symbol":"ETH/GBP","bids":[{"price":2978.25,"qty":0.00000000},{"price":2974.45,"qty":1.31880744}],"asks":[],"checksum":2084853902,"timestamp":"2024-06-01T17:52:43.700198Z"}]}
{"channel":"book","type":"update","data":[{"symbol":"ETH/GBP","bids":[{"price":2978.26,"qty":6.58559510}],"asks":[],"checksum":715827389,"timestamp":"2024-06-01T17:52:43.717968Z"}]}
{"channel":"book","type":"update","data":[{"symbol":"ETH/GBP","bids":[{"price":2978.26,"qty":0.00000000},{"price":2974.45,"qty":1.31880744}],"asks":[],"checksum":2084853902,"timestamp":"2024-06-01T17:52:43.786104Z"}]}
{"channel":"book","type":"update","data":[{"symbol":"ETH/GBP","bids":[],"asks":[{"price":2978.50,"qty":0.00000000},{"price":2980.58,"qty":13.43327015}],"checksum":3457106666,"timestamp":"2024-06-01T17:52:43.788603Z"}]}
{"channel":"book","type":"update","data":[{"symbol":"ETH/GBP","bids":[],"asks":[{"price":2978.51,"qty":6.58505313}],"checksum":4099348134,"timestamp":"2024-06-01T17:52:43.794346Z"}]}
{"channel":"book","type":"update","data":[{"symbol":"ETH/GBP","bids":[{"price":2977.81,"qty":13.17317896}],"asks":[],"checksum":2061114052,"timestamp":"2024-06-01T17:52:43.794392Z"}]}
{"channel":"book","type":"update","data":[{"symbol":"ETH/GBP","bids":[],"asks":[{"price":2979.45,"qty":13.16599102}],"checksum":316349263,"timestamp":"2024-06-01T17:52:43.794408Z"}]}
{"channel":"book","type":"update","data":[{"symbol":"ETH/GBP","bids":[{"price":2977.51,"qty":0.00000000},{"price":2974.45,"qty":1.31880744}],"asks":[],"checksum":2649213030,"timestamp":"2024-06-01T17:52:43.797234Z"}]}
{"channel":"book","type":"update","data":[{"symbol":"ETH/GBP","bids":[{"price":2977.89,"qty":0.31000000}],"asks":[],"checksum":1542081633,"timestamp":"2024-06-01T17:52:43.797312Z"}]}
{"channel":"book","type":"update","data":[{"symbol":"ETH/GBP","bids":[],"asks":[{"price":2979.45,"qty":0.00000000},{"price":2980.57,"qty":1.31610402}],"checksum":871058922,"timestamp":"2024-06-01T17:52:43.799205Z"}]}
{"channel":"book","type":"update","data":[{"symbol":"ETH/GBP","bids":[],"asks":[{"price":2978.51,"qty":0.00000000},{"price":2980.58,"qty":13.43327015}],"checksum":1287329797,"timestamp":"2024-06-01T17:52:43.817105Z"}]}
{"channel":"book","type":"update","data":[{"symbol":"ETH/GBP","bids":[{"price":2978.29,"qty":6.58553649}],"asks":[],"checksum":2508233492,"timestamp":"2024-06-01T17:52:43.821551Z"}]}
{"channel":"book","type":"update","data":[{"symbol":"ETH/GBP","bids":[{"price":2978.29,"qty":0.00000000},{"price":2974.46,"qty":0.34510000}],"asks":[],"checksum":1287329797,"timestamp":"2024-06-01T17:52:43.827433Z"}]}
{"channel":"book","type":"update","data":[{"symbol":"ETH/GBP","bids":[],"asks":[{"price":2980.55,"qty":0.00000000},{"price":2980.94,"qty":0.00775181}],"checksum":563840486,"timestamp":"2024-06-01T17:52:43.856435Z"}]}
{"channel":"book","type":"update","data":[{"symbol":"ETH/GBP","bids":[],"asks":[{"price":2979.53,"qty":4.68813639}],"checksum":2150425981,"timestamp":"2024-06-01T17:52:43.860793Z"}]}
{"channel":"book","type":"update","data":[{"symbol":"ETH/GBP","bids":[],"asks":[{"price":2979.45,"qty":1.56709322}],"checksum":3167868802,"timestamp":"2024-06-01T17:52:43.860851Z"}]}
{"channel":"book","type":"update","data":[{"symbol":"ETH/GBP","bids":[],"asks":[{"price":2980.55,"qty":27.96699686}],"checksum":2170705986,"timestamp":"2024-06-01T17:52:43.861043Z"}]}
{"channel":"book","type":"update","data":[{"symbol":"ETH/GBP","bids":[],"asks":[{"price":2979.46,"qty":0.00000000},{"price":2980.57,"qty":1.31610402}],"checksum":488591966,"timestamp":"2024-06-01T17:52:43.863842Z"}]}
{"channel":"book","type":"update","data":[{"symbol":"ETH/GBP","bids":[],"asks":[{"price":2979.37,"qty":0.31000000}],"checksum":948903027,"timestamp":"2024-06-01T17:52:43.864078Z"}]}
{"channel":"book","type":"update","data":[{"symbol":"ETH/GBP","bids":[],"asks":[{"price":2978.51,"qty":6.58506579}],"checksum":764148051,"timestamp":"2024-06-01T17:52:43.933637Z"}]}
{"channel":"book","type":"update","data":[{"symbol":"ETH/GBP","bids":[{"price":2978.26,"qty":6.58559379}],"asks":[],"checksum":971580188,"timestamp":"2024-06-01T17:52:43.933689Z"}]}
{"channel":"book","type":"update","data":[{"symbol":"ETH/GBP","bids":[{"price":2978.26,"qty":0.00000000},{"price":2974.46,"qty":0.34510000}],"asks":[],"checksum":764148051,"timestamp":"2024-06-01T17:52:43.961248Z"}]}
{"channel":"book","type":"update","data":[{"symbol":"ETH/GBP","bids":[],"asks":[{"price":2978.51,"qty":0.00000000},{"price":2980.56,"qty":2.94416492}],"checksum":948903027,"timestamp":"2024-06-01T17:52:43.961425Z"}]}
{"channel":"book","type":"update","data":[{"symbol":"ETH/GBP","bids":[{"price":2978.28,"qty":6.58554505}],"asks":[],"checksum":581071463,"timestamp":"2024-06-01T17:52:44.042568Z"}]}
{"channel":"book","type":"update","data":[{"symbol":"ETH/GBP","bids":[],"asks":[{"price":2978.53,"qty":6.58501706}],"checksum":645226781,"timestamp":"2024-06-01T17:52:44.042631Z"}]}
{"channel":"book","type":"update","data":[{"symbol":"ETH/GBP","bids":[],"asks":[{"price":2979.36,"qty":13.16636797}],"checksum":3799254555,"timestamp":"2024-06-01T17:52:44.042688Z"}]}
{"channel":"book","type":"update","data":[{"symbol":"ETH/GBP","bids":[],"asks":[{"price":2979.36,"qty":0.00000000},{"price":2980.55,"qty":27.96699686}],"checksum":645226781,"timestamp":"2024-06-01T17:52:44.047721Z"}]}
{"channel":"book","type":"update","data":[{"symbol":"ETH/GBP","bids":[{"price":2978.28,"qty":0.00000000},{"price":2974.46,"qty":0.34510000}],"asks":[],"checksum":884634613,"timestamp":"2024-06-01T17:52:44.083870Z"}]}
{"channel":"book","type":"update","data":[{"symbol":"ETH/GBP","bids":[],"asks":[{"price":2978.53,"qty":0.00000000},{"price":2980.56,"qty":2.94416492}],"checksum":948903027,"timestamp":"2024-06-01T17:52:44.087225Z"}]}
{"channel":"book","type":"update","data":[{"symbol":"ETH/GBP","bids":[],"asks":[{"price":2978.51,"qty":6.58506843}],"checksum":689448240,"timestamp":"2024-06-01T17:52:44.194048Z"}]}
{"channel":"book","type":"update","data":[{"symbol":"ETH/GBP","bids":[{"price":2978.23,"qty":6.58566983}],"asks":[],"checksum":2556789377,"timestamp":"2024-06-01T17:52:44.194076Z"}]}
{"channel":"book","type":"update","data":[{"symbol":"ETH/GBP","bids":[],"asks":[{"price":2978.51,"qty":0.00000000},{"price":2980.56,"qty":2.94416492}],"checksum":2007041426,"timestamp":"2024-06-01T17:52:44.280401Z"}]}
{"channel":"book","type":"update","data":[{"symbol":"ETH/GBP","bids":[{"price":2977.81,"qty":0.00000000},{"price":2974.46,"qty":0.34510000}],"asks":[],"checksum":3331425003,"timestamp":"2024-06-01T17:52:44.280482Z"}]}
{"channel":"book","type":"update","data":[{"symbol":"ETH/GBP","bids":[{"price":2978.23,"qty":0.00000000},{"price":2974.45,"qty":1.31880744}],"asks":[],"checksum":3734773052,"timestamp":"2024-06-01T17:52:44.280558Z"}]}
{"channel":"book","type":"update","data":[{"symbol":"ETH/GBP","bids":[{"price":2977.89,"qty":0.00000000},{"price":2974.30,"qty":0.30200000}],"asks":[],"checksum":2766251414,"timestamp":"2024-06-01T17:52:44.283278Z"}]}
{"channel":"book","type":"update","data":[{"symbol":"ETH/GBP","bids":[{"price":2977.74,"qty":13.17349080}],"asks":[],"checksum":3127747295,"timestamp":"2024-06-01T17:52:44.288716Z"}]}
{"channel":"book","type":"update","data":[{"symbol":"ETH/GBP","bids":[],"asks":[{"price":2979.36,"qty":13.16636797}],"checksum":3342635973,"timestamp":"2024-06-01T17:52:44.288729Z"}]}
{"channel":"book","type":"update","data":[{"symbol":"ETH/GBP","bids":[],"asks":[{"price":2979.36,"qty":0.00000000},{"price":2980.56,"qty":2.94416492}],"checksum":3127747295,"timestamp":"2024-06-01T17:52:44.293851Z"}]}
{"channel":"book","type":"update","data":[{"symbol":"ETH/GBP","bids":[{"price":2977.74,"qty":0.00000000},{"price":2974.30,"qty":0.30200000}],"asks":[],"checksum":2766251414,"timestamp":"2024-06-01T17:52:44.294077Z"}]}
{"channel":"book","type":"update","data":[{"symbol":"ETH/GBP","bids":[],"asks":[{"price":2978.50,"qty":6.58508094}],"checksum":263370575,"timestamp":"2024-06-01T17:52:44.299057Z"}]}
{"channel":"book","type":"update","data":[{"symbol":"ETH/GBP","bids":[{"price":2978.20,"qty":6.58573124}],"asks":[],"checksum":83097264,"timestamp":"2024-06-01T17:52:44.299119Z"}]}
{"channel":"book","type":"update","data":[{"symbol":"ETH/GBP","bids":[{"price":2978.20,"qty":0.00000000},{"price":2974.30,"qty":0.30200000}],"asks":[],"checksum":263370575,"timestamp":"2024-06-01T17:52:44.332910Z"}]}
{"channel":"book","type":"update","data":[{"symbol":"ETH/GBP","bids":[],"asks":[{"price":2978.50,"qty":0.00000000},{"price":2980.56,"qty":2.94416492}],"checksum":2766251414,"timestamp":"2024-06-01T17:52:44.446989Z"}]}
{"channel":"book","type":"update","data":[{"symbol":"ETH/GBP","bids":[{"price":2978.24,"qty":6.58564765}],"asks":[],"checksum":1682368880,"timestamp":"2024-06-01T17:52:44.451802Z"}]}
{"channel":"book","type":"update","data":[{"symbol":"ETH/GBP","bids":[],"asks":[{"price":2978.53,"qty":6.58501529}],"checksum":3688354639,"timestamp":"2024-06-01T17:52:44.451849Z"}]}
{"channel":"book","type":"update","data":[{"symbol":"ETH/GBP","bids":[],"asks":[{"price":2978.53,"qty":0.00000000},{"price":2980.56,"qty":2.94416492}],"checksum":1682368880,"timestamp":"2024-06-01T17:52:44.497967Z"}]}
{"channel":"book","type":"update","data":[{"symbol":"ETH/GBP","bids":[{"price":2977.78,"qty":13.17332359}],"asks":[],"checksum":555659596,"timestamp":"2024-06-01T17:52:44.502639Z"}]}
{"channel":"book","type":"update","data":[{"symbol":"ETH/GBP","bids":[],"asks":[{"price":2979.36,"qty":13.16635250}],"checksum":3420001299,"timestamp":"2024-06-01T17:52:44.502797Z"}]}
{"channel":"book","type":"update","data":[{"symbol":"ETH/GBP","bids":[],"asks":[{"price":2979.36,"qty":0.00000000},{"price":2980.56,"qty":2.94416492}],"checksum":555659596,"timestamp":"2024-06-01T17:52:44.507363Z"}]}
{"channel":"book","type":"update","data":[{"symbol":"ETH/GBP","bids":[{"price":2976.22,"qty":0.00000000},{"price":2974.45,"qty":1.31880744}],"asks":[],"checksum":2114512272,"timestamp":"2024-06-01T17:52:44.540640Z"}]}
{"channel":"book","type":"update","data":[{"symbol":"ETH/GBP","bids":[{"price":2978.24,"qty":0.00000000},{"price":2974.30,"qty":0.30200000}],"asks":[],"checksum":2415160901,"timestamp":"2024-06-01T17:52:44.542670Z"}]}
{"channel":"book","type":"update","data":[{"symbol":"ETH/GBP","bids":[],"asks":[{"price":2978.49,"qty":6.58511829}],"checksum":3735751735,"timestamp":"2024-06-01T17:52:44.662847Z"}]}
{"channel":"book","type":"update","data":[{"symbol":"ETH/GBP","bids":[{"price":2978.22,"qty":6.58567998}],"asks":[],"checksum":2736049452,"timestamp":"2024-06-01T17:52:44.662897Z"}]}
{"channel":"book","type":"update","data":[{"symbol":"ETH/GBP","bids":[{"price":2978.22,"qty":0.00000000},{"price":2974.30,"qty":0.30200000}],"asks":[],"checksum":3735751735,"timestamp":"2024-06-01T17:52:44.728453Z"}]}
{"channel":"book","type":"update","data":[{"symbol":"ETH/GBP","bids":[],"asks":[{"price":2978.94,"qty":13.16820877}],"checksum":58767566,"timestamp":"2024-06-01T17:52:44.733268Z"}]}
{"channel":"book","type":"update","data":[{"symbol":"ETH/GBP","bids":[],"asks":[{"price":2978.49,"qty":0.00000000},{"price":2980.55,"qty":27.96699686}],"checksum":2796116780,"timestamp":"2024-06-01T17:52:44.744393Z"}]}
{"channel":"book","type":"update","data":[{"symbol":"ETH/GBP","bids":[],"asks":[{"price":2978.94,"qty":0.00000000},{"price":2980.56,"qty":2.94416492}],"checksum":2415160901,"timestamp":"2024-06-01T17:52:44.832525Z"}]}
{"channel":"book","type":"update","data":[{"symbol":"ETH/GBP","bids":[{"price":2978.20,"qty":6.58571686}],"asks":[],"checksum":2431639061,"timestamp":"2024-06-01T17:52:44.837141Z"}]}
{"channel":"book","type":"update","data":[{"symbol":"ETH/GBP","bids":[],"asks":[{"price":2978.47,"qty":6.58514463}],"checksum":2041281726,"timestamp":"2024-06-01T17:52:44.837287Z"}]}
{"channel":"book","type":"update","data":[{"symbol":"ETH/GBP","bids":[{"price":2978.20,"qty":0.00000000},{"price":2974.30,"qty":0.30200000}],"asks":[],"checksum":2834559043,"timestamp":"2024-06-01T17:52:45.138940Z"}]}
{"channel":"book","type":"update","data":[{"symbol":"ETH/GBP","bids":[{"price":2977.86,"qty":0.31000000}],"asks":[],"checksum":2321824262,"timestamp":"2024-06-01T17:52:45.141695Z"}]}
{"channel":"book","type":"update","data":[{"symbol":"ETH/GBP","bids":[],"asks":[{"price":2978.92,"qty":13.16829964}],"checksum":3286065411,"timestamp":"2024-06-01T17:52:45.143157Z"}]}
{"channel":"book","type":"update","data":[{"symbol":"ETH/GBP","bids":[{"price":2978.21,"qty":6.58570567}],"asks":[],"checksum":3567642727,"timestamp":"2024-06-01T17:52:45.143281Z"}]}
{"channel":"book","type":"update","data":[{"symbol":"ETH/GBP","bids":[{"price":2978.21,"qty":0.00000000},{"price":2974.45,"qty":1.31880744}],"asks":[],"checksum":3286065411,"timestamp":"2024-06-01T17:52:45.219930Z"}]}
{"channel":"book","type":"update","data":[{"symbol":"ETH/GBP","bids":[],"asks":[{"price":2978.47,"qty":0.00000000},{"price":2980.55,"qty":27.96699686}],"checksum":684561649,"timestamp":"2024-06-01T17:52:45.234284Z"}]}
{"channel":"book","type":"update","data":[{"symbol":"ETH/GBP","bids":[],"asks":[{"price":2978.49,"qty":6.58511289}],"checksum":3722104683,"timestamp":"2024-06-01T17:52:45.238435Z"}]}
{"channel":"book","type":"update","data":[{"symbol":"ETH/GBP","bids":[],"asks":[{"price":2978.49,"qty":0.00000000},{"price":2980.55,"qty":27.96699686}],"checksum":684561649,"timestamp":"2024-06-01T17:52:45.242839Z"}]}
{"channel":"book","type":"update","data":[{"symbol":"ETH/GBP","bids":[{"price":2978.24,"qty":6.58563849}],"asks":[],"checksum":3479002314,"timestamp":"2024-06-01T17:52:45.246668Z"}]}
{"channel":"book","type":"update","data":[{"symbol":"ETH/GBP","bids":[{"price":2978.24,"qty":0.00000000},{"price":2974.45,"qty":1.31880744}],"asks":[],"checksum":684561649,"timestamp":"2024-06-01T17:52:45.252079Z"}]}
{"channel":"book","type":"update","data":[{"symbol":"ETH/GBP","bids":[],"asks":[{"price":2978.47,"qty":6.58515795}],"checksum":1042633270,"timestamp":"2024-06-01T17:52:45.437662Z"}]}
{"channel":"book","type":"update","data":[{"symbol":"ETH/GBP","bids":[{"price":2978.22,"qty":6.58568222}],"asks":[],"checksum":3579982461,"timestamp":"2024-06-01T17:52:45.437812Z"}]}
{"channel":"book","type":"update","data":[{"symbol":"ETH/GBP","bids":[{"price":2978.22,"qty":0.00000000},{"price":2974.45,"qty":1.31880744}],"asks":[],"checksum":1042633270,"timestamp":"2024-06-01T17:52:46.160546Z"}]}
{"channel":"book","type":"update","data":[{"symbol":"ETH/GBP","bids":[],"asks":[{"price":2978.47,"qty":0.00000000},{"price":2980.55,"qty":27.96699686}],"checksum":684561649,"timestamp":"2024-06-01T17:52:46.160699Z"}]}
{"channel":"book","type":"update","data":[{"symbol":"ETH/GBP","bids":[{"price":2977.78,"qty":0.00000000},{"price":2974.30,"qty":0.30200000}],"asks":[],"checksum":3826248840,"timestamp":"2024-06-01T17:52:46.165123Z"}]}
{"channel":"book","type":"update","data":[{"symbol":"ETH/GBP","bids":[],"asks":[{"price":2980.10,"qty":8.26799515}],"checksum":2953453078,"timestamp":"2024-06-01T17:52:46.166288Z"}]}
{"channel":"book","type":"update","data":[{"symbol":"ETH/GBP","bids":[],"asks":[{"price":2978.92,"qty":0.00000000},{"price":2980.55,"qty":27.96699686}],"checksum":1769294459,"timestamp":"2024-06-01T17:52:46.166473Z"}]}
{"channel":"book","type":"update","data":[{"symbol":"ETH/GBP","bids":[{"price":2977.86,"qty":0.00000000},{"price":2973.93,"qty":0.27474654}],"asks":[],"checksum":3814750069,"timestamp":"2024-06-01T17:52:46.167616Z"}]}
{"channel":"book","type":"update","data":[{"symbol":"ETH/GBP","bids":[],"asks":[{"price":2979.37,"qty":0.00000000},{"price":2980.56,"qty":2.94416492}],"checksum":843721626,"timestamp":"2024-06-01T17:52:46.167754Z"}]}
{"channel":"book","type":"update","data":[{"symbol":"ETH/GBP","bids":[{"price":2977.51,"qty":0.31000000}],"asks":[],"checksum":1090384728,"timestamp":"2024-06-01T17:52:46.167816Z"}]}
{"channel":"book","type":"update","data":[{"symbol":"ETH/GBP","bids":[],"asks":[{"price":2978.43,"qty":6.58522896}],"checksum":2687619443,"timestamp":"2024-06-01T17:52:46.172086Z"}]}
{"channel":"book","type":"update","data":[{"symbol":"ETH/GBP","bids":[{"price":2977.72,"qty":13.17358858}],"asks":[],"checksum":3707971218,"timestamp":"2024-06-01T17:52:46.172260Z"}]}
{"channel":"book","type":"update","data":[{"symbol":"ETH/GBP","bids":[],"asks":[{"price":2978.91,"qty":13.16833834}],"checksum":2392572923,"timestamp":"2024-06-01T17:52:46.172296Z"}]}
{"channel":"book","type":"update","data":[{"symbol":"ETH/GBP","bids":[{"price":2977.87,"qty":6.58646599}],"asks":[],"checksum":3051121476,"timestamp":"2024-06-01T17:52:46.172424Z"}]}
{"channel":"book","type":"update","data":[{"symbol":"ETH/GBP","bids":[{"price":2977.72,"qty":0.00000000},{"price":2974.45,"qty":1.31880744}],"asks":[],"checksum":467832641,"timestamp":"2024-06-01T17:52:46.177484Z"}]}
{"channel":"book","type":"update","data":[{"symbol":"ETH/GBP","bids":[{"price":2977.87,"qty":0.00000000},{"price":2974.30,"qty":0.30200000}],"asks":[],"checksum":1647489481,"timestamp":"2024-06-01T17:52:46.177564Z"}]}
{"channel":"book","type":"update","data":[{"symbol":"ETH/GBP","bids":[],"asks":[{"price":2978.91,"qty":0.00000000},{"price":2980.55,"qty":27.96699686}],"checksum":2687619443,"timestamp":"2024-06-01T17:52:46.177635Z"}]}
{"channel":"book","type":"update","data":[{"symbol":"ETH/GBP","bids":[{"price":2978.17,"qty":6.58579330}],"asks":[],"checksum":34689713,"timestamp":"2024-06-01T17:52:46.271697Z"}]}
{"channel":"book","type":"update","data":[{"symbol":"ETH/GBP","bids":[{"price":2976.17,"qty":0.00000000},{"price":2974.30,"qty":0.30200000}],"asks":[],"checksum":4272867092,"timestamp":"2024-06-01T17:52:46.275749Z"}]}
{"channel":"book","type":"update","data":[{"symbol":"ETH/GBP","bids":[{"price":2977.55,"qty":4.39744678}],"asks":[],"checksum":945586215,"timestamp":"2024-06-01T17:52:46.278730Z"}]}
{"channel":"book","type":"update","data":[{"symbol":"ETH/GBP","bids":[],"asks":[{"price":2979.53,"qty":0.00000000},{"price":2980.56,"qty":2.94416492}],"checksum":2064072081,"timestamp":"2024-06-01T17:52:46.309038Z"}]}
{"channel":"book","type":"update","data":[{"symbol":"ETH/GBP","bids":[],"asks":[{"price":2979.45,"qty":0.00000000},{"price":2980.57,"qty":1.31610402}],"checksum":1770939934,"timestamp":"2024-06-01T17:52:46.309191Z"}]}
{"channel":"book","type":"update","data":[{"symbol":"ETH/GBP","bids":[],"asks":[{"price":2980.55,"qty":0.00000000},{"price":2980.94,"qty":0.00775181}],"checksum":4197885730,"timestamp":"2024-06-01T17:52:46.309305Z"}]}
{"channel":"book","type":"update","data":[{"symbol":"ETH/GBP","bids":[],"asks":[{"price":2980.55,"qty":20.29335900}],"checksum":938804407,"timestamp":"2024-06-01T17:52:46.312025Z"}]}
{"channel":"book","type":"update","data":[{"symbol":"ETH/GBP","bids":[],"asks":[{"price":2978.43,"qty":0.00000000},{"price":2980.94,"qty":0.00775181}],"checksum":2950478459,"timestamp":"2024-06-01T17:52:46.313026Z"}]}
{"channel":"book","type":"update","data":[{"symbol":"ETH/GBP","bids":[],"asks":[{"price":2978.42,"qty":6.58526593}],"checksum":3152726179,"timestamp":"2024-06-01T17:52:46.317569Z"}]}
{"channel":"book","type":"update","data":[{"symbol":"ETH/GBP","bids":[{"price":2978.17,"qty":0.00000000},{"price":2974.30,"qty":0.30200000}],"asks":[],"checksum":1967786231,"timestamp":"2024-06-01T17:52:46.351778Z"}]}
{"channel":"book","type":"update","data":[{"symbol":"ETH/GBP","bids":[],"asks":[{"price":2978.88,"qty":13.16849734}],"checksum":3068284096,"timestamp":"2024-06-01T17:52:46.422324Z"}]}
{"channel":"book","type":"update","data":[{"symbol":"ETH/GBP","bids":[{"price":2978.18,"qty":6.58577162}],"asks":[],"checksum":574822603,"timestamp":"2024-06-01T17:52:46.422359Z"}]}
{"channel":"book","type":"update","data":[{"symbol":"ETH/GBP","bids":[{"price":2977.56,"qty":13.17430610}],"asks":[],"checksum":2295159834,"timestamp":"2024-06-01T17:52:46.422392Z"}]}
{"channel":"book","type":"update","data":[{"symbol":"ETH/GBP","bids":[{"price":2977.56,"qty":0.00000000},{"price":2974.45,"qty":1.31880744}],"asks":[],"checksum":574822603,"timestamp":"2024-06-01T17:52:46.427191Z"}]}
{"channel":"book","type":"update","data":[{"symbol":"ETH/GBP","bids":[{"price":2977.43,"qty":0.00000000},{"price":2974.30,"qty":0.30200000},{"price":2978.18,"qty":6.67135662}],"asks":[],"checksum":2263636978,"timestamp":"2024-06-01T17:52:46.449854Z"}]}
{"channel":"book","type":"update","data":[{"symbol":"ETH/GBP","bids":[],"asks":[{"price":2979.54,"qty":0.00000000},{"price":2980.57,"qty":1.31610402},{"price":2979.10,"qty":0.06973500}],"checksum":3229670222,"timestamp":"2024-06-01T17:52:46.629419Z"}]}
{"channel":"book","type":"update","data":[{"symbol":"ETH/GBP","bids":[],"asks":[{"price":2978.42,"qty":0.00000000},{"price":2980.57,"qty":1.31610402}],"checksum":1605586482,"timestamp":"2024-06-01T17:52:46.691382Z"}]}
{"channel":"book","type":"update","data":[{"symbol":"ETH/GBP","bids":[{"price":2978.18,"qty":0.08558500}],"asks":[],"checksum":3707493976,"timestamp":"2024-06-01T17:52:46.691521Z"}]}
{"channel":"book","type":"update","data":[{"symbol":"ETH/GBP","bids":[{"price":2977.51,"qty":0.00000000},{"price":2973.93,"qty":0.27474654}],"asks":[],"checksum":4076683174,"timestamp":"2024-06-01T17:52:46.694304Z"}]}
{"channel":"book","type":"update","data":[{"symbol":"ETH/GBP","bids":[{"price":2977.63,"qty":0.31000000}],"asks":[],"checksum":3556545901,"timestamp":"2024-06-01T17:52:46.694595Z"}]}
{"channel":"book","type":"update","data":[{"symbol":"ETH/GBP","bids":[],"asks":[{"price":2978.46,"qty":6.58516380}],"checksum":145764849,"timestamp":"2024-06-01T17:52:46.696157Z"}]}
{"channel":"book","type":"update","data":[{"symbol":"ETH/GBP","bids":[{"price":2978.21,"qty":6.58570576}],"asks":[],"checksum":3450998749,"timestamp":"2024-06-01T17:52:46.696178Z"}]}
{"channel":"book","type":"update","data":[{"symbol":"ETH/GBP","bids":[{"price":2977.72,"qty":13.17357158}],"asks":[],"checksum":1402601800,"timestamp":"2024-06-01T17:52:46.696284Z"}]}
{"channel":"book","type":"update","data":[{"symbol":"ETH/GBP","bids":[],"asks":[{"price":2978.46,"qty":0.00000000},{"price":2980.57,"qty":1.31610402}],"checksum":1607825635,"timestamp":"2024-06-01T17:52:46.765259Z"}]}
{"channel":"book","type":"update","data":[{"symbol":"ETH/GBP","bids":[{"price":2978.21,"qty":0.00000000},{"price":2974.45,"qty":1.31880744}],"asks":[],"checksum":2757561630,"timestamp":"2024-06-01T17:52:46.994161Z"}]}
{"channel":"book","type":"update","data":[{"symbol":"ETH/GBP","bids":[{"price":2977.80,"qty":0.31000000}],"asks":[],"checksum":489513078,"timestamp":"2024-06-01T17:52:46.996779Z"}]}
{"channel":"book","type":"update","data":[{"symbol":"ETH/GBP","bids":[{"price":2977.63,"qty":0.00000000},{"price":2974.45,"qty":1.31880744}],"asks":[],"checksum":3849284095,"timestamp":"2024-06-01T17:52:46.996850Z"}]}
{"channel":"book","type":"update","data":[{"symbol":"ETH/GBP","bids":[],"asks":[{"price":2978.47,"qty":6.58514273}],"checksum":1920689061,"timestamp":"2024-06-01T17:52:46.998821Z"}]}
{"channel":"book","type":"update","data":[{"symbol":"ETH/GBP","bids":[{"price":2978.23,"qty":6.58566798}],"asks":[],"checksum":1624592805,"timestamp":"2024-06-01T17:52:46.999132Z"}]}
{"channel":"book","type":"update","data":[{"symbol":"ETH/GBP","bids":[{"price":2978.23,"qty":0.00000000},{"price":2974.45,"qty":1.31880744}],"asks":[],"checksum":1920689061,"timestamp":"2024-06-01T17:52:47.284948Z"}]}
{"channel":"book","type":"update","data":[{"symbol":"ETH/GBP","bids":[],"asks":[{"price":2978.47,"qty":0.00000000},{"price":2980.57,"qty":1.31610402}],"checksum":3849284095,"timestamp":"2024-06-01T17:52:47.284966Z"}]}
{"channel":"book","type":"update","data":[{"symbol":"ETH/GBP","bids":[{"price":2978.21,"qty":6.58570401}],"asks":[],"checksum":408795424,"timestamp":"2024-06-01T17:52:47.290407Z"}]}
{"channel":"book","type":"update","data":[{"symbol":"ETH/GBP","bids":[],"asks":[{"price":2978.46,"qty":6.58516816}],"checksum":1513594396,"timestamp":"2024-06-01T17:52:47.290592Z"}]}
{"channel":"book","type":"update","data":[{"symbol":"ETH/GBP","bids":[],"asks":[{"price":2978.46,"qty":0.00000000},{"price":2980.57,"qty":1.31610402}],"checksum":408795424,"timestamp":"2024-06-01T17:52:47.312457Z"}]}
{"channel":"book","type":"update","data":[{"symbol":"ETH/GBP","bids":[{"price":2978.21,"qty":0.00000000},{"price":2974.45,"qty":1.31880744}],"asks":[],"checksum":3849284095,"timestamp":"2024-06-01T17:52:47.312518Z"}]}
{"channel":"book","type":"update","data":[{"symbol":"ETH/GBP","bids":[],"asks":[{"price":2978.87,"qty":6.58425625}],"checksum":1199798926,"timestamp":"2024-06-01T17:52:47.442369Z"}]}
{"channel":"book","type":"update","data":[{"symbol":"ETH/GBP","bids":[{"price":2978.21,"qty":6.58570993}],"asks":[],"checksum":2560821063,"timestamp":"2024-06-01T17:52:47.442494Z"}]}
{"channel":"book","type":"update","data":[{"symbol":"ETH/GBP","bids":[],"asks":[{"price":2978.87,"qty":0.00000000},{"price":2980.57,"qty":1.31610402}],"checksum":978261046,"timestamp":"2024-06-01T17:52:47.447095Z"}]}
{"channel":"book","type":"update","data":[{"symbol":"ETH/GBP","bids":[],"asks":[{"price":2978.45,"qty":6.58518912}],"checksum":1361611560,"timestamp":"2024-06-01T17:52:47.580383Z"}]}
{"channel":"book","type":"update","data":[{"symbol":"ETH/GBP","bids":[{"price":2978.21,"qty":0.00000000},{"price":2974.45,"qty":1.31880744}],"asks":[],"checksum":2382952161,"timestamp":"2024-06-01T17:52:47.586330Z"}]}
{"channel":"book","type":"update","data":[{"symbol":"ETH/GBP","bids":[{"price":2978.19,"qty":6.58574418}],"asks":[],"checksum":3839731717,"timestamp":"2024-06-01T17:52:47.590556Z"}]}
{"channel":"book","type":"update","data":[{"symbol":"ETH/GBP","bids":[{"price":2978.19,"qty":0.00000000},{"price":2974.45,"qty":1.31880744}],"asks":[],"checksum":2382952161,"timestamp":"2024-06-01T17:52:47.616203Z"}]}
{"channel":"book","type":"update","data":[{"symbol":"ETH/GBP","bids":[],"asks":[{"price":2978.45,"qty":0.00000000},{"price":2980.57,"qty":1.31610402}],"checksum":3849284095,"timestamp":"2024-06-01T17:52:47.618012Z"}]}
{"channel":"book","type":"update","data":[{"symbol":"ETH/GBP","bids":[],"asks":[{"price":2978.88,"qty":0.00000000},{"price":2980.94,"qty":0.00775181}],"checksum":2455997038,"timestamp":"2024-06-01T17:52:47.623936Z"}]}
{"channel":"book","type":"update","data":[{"symbol":"ETH/GBP","bids":[{"price":2977.72,"qty":0.00000000},{"price":2974.30,"qty":0.30200000}],"asks":[],"checksum":3923925031,"timestamp":"2024-06-01T17:52:47.624136Z"}]}
{"channel":"book","type":"update","data":[{"symbol":"ETH/GBP","bids":[{"price":2977.80,"qty":0.00000000},{"price":2973.93,"qty":0.27474654}],"asks":[],"checksum":4196736873,"timestamp":"2024-06-01T17:52:47.626749Z"}]}
{"channel":"book","type":"update","data":[{"symbol":"ETH/GBP","bids":[{"price":2977.63,"qty":0.31000000}],"asks":[],"checksum":3676616098,"timestamp":"2024-06-01T17:52:47.626989Z"}]}
{"channel":"book","type":"update","data":[{"symbol":"ETH/GBP","bids":[],"asks":[{"price":2979.47,"qty":0.31000000}],"checksum":3017648523,"timestamp":"2024-06-01T17:52:47.627001Z"}]}
{"channel":"book","type":"update","data":[{"symbol":"ETH/GBP","bids":[],"asks":[{"price":2979.09,"qty":13.16754005}],"checksum":1792088785,"timestamp":"2024-06-01T17:52:47.629071Z"}]}
{"channel":"book","type":"update","data":[{"symbol":"ETH/GBP","bids":[{"price":2977.79,"qty":13.17327032}],"asks":[],"checksum":3452709924,"timestamp":"2024-06-01T17:52:47.629144Z"}]}
{"channel":"book","type":"update","data":[{"symbol":"ETH/GBP","bids":[],"asks":[{"price":2979.09,"qty":0.00000000},{"price":2980.57,"qty":1.31610402}],"checksum":3757089472,"timestamp":"2024-06-01T17:52:47.633612Z"}]}
{"channel":"book","type":"update","data":[{"symbol":"ETH/GBP","bids":[],"asks":[{"price":2978.50,"qty":6.58508354}],"checksum":2207901396,"timestamp":"2024-06-01T17:52:47.682066Z"}]}
{"channel":"book","type":"update","data":[{"symbol":"ETH/GBP","bids":[],"asks":[{"price":2978.50,"qty":0.00000000},{"price":2980.57,"qty":1.31610402}],"checksum":3757089472,"timestamp":"2024-06-01T17:52:47.697775Z"}]}
{"channel":"book","type":"update","data":[{"symbol":"ETH/GBP","bids":[{"price":2978.24,"qty":6.58564428}],"asks":[],"checksum":1226620360,"timestamp":"2024-06-01T17:52:47.702272Z"}]}
{"channel":"book","type":"update","data":[{"symbol":"ETH/GBP","bids":[{"price":2977.79,"qty":0.00000000},{"price":2974.45,"qty":1.31880744}],"asks":[],"checksum":2312939378,"timestamp":"2024-06-01T17:52:47.722987Z"}]}
{"channel":"book","type":"update","data":[{"symbol":"ETH/GBP","bids":[{"price":2978.24,"qty":0.00000000},{"price":2974.30,"qty":0.30200000}],"asks":[],"checksum":3017648523,"timestamp":"2024-06-01T17:52:47.723027Z"}]}
{"channel":"book","type":"update","data":[{"symbol":"ETH/GBP","bids":[],"asks":[{"price":2980.10,"qty":0.00000000},{"price":2980.94,"qty":0.00775181}],"checksum":3536526739,"timestamp":"2024-06-01T17:52:47.746062Z"}]}
{"channel":"book","type":"update","data":[{"symbol":"ETH/GBP","bids":[],"asks":[{"price":2979.10,"qty":0.00000000},{"price":2980.95,"qty":0.22400000},{"price":2979.62,"qty":0.06973400}],"checksum":25235078,"timestamp":"2024-06-01T17:52:47.750780Z"}]}
{"channel":"book","type":"update","data":[{"symbol":"ETH/GBP","bids":[],"asks":[{"price":2979.66,"qty":0.00000000},{"price":2980.95,"qty":0.22400000}],"checksum":2007334617,"timestamp":"2024-06-01T17:52:47.751593Z"}]}
{"channel":"book","type":"update","data":[{"symbol":"ETH/GBP","bids":[],"asks":[{"price":2980.16,"qty":9.81384515}],"checksum":2066993572,"timestamp":"2024-06-01T17:52:47.752210Z"}]}
{"channel":"book","type":"update","data":[{"symbol":"ETH/GBP","bids":[],"asks":[{"price":2979.91,"qty":1.31639388}],"checksum":2026076424,"timestamp":"2024-06-01T17:52:47.756404Z"}]}
{"channel":"book","type":"update","data":[{"symbol":"ETH/GBP","bids":[],"asks":[{"price":2979.55,"qty":0.00000000},{"price":2980.94,"qty":0.00775181}],"checksum":3638398073,"timestamp":"2024-06-01T17:52:47.765695Z"}]}
{"channel":"book","type":"update","data":[{"symbol":"ETH/GBP","bids":[],"asks":[{"price":2978.64,"qty":6.58476608}],"checksum":1012463507,"timestamp":"2024-06-01T17:52:47.784692Z"}]}
{"channel":"book","type":"update","data":[{"symbol":"ETH/GBP","bids":[],"asks":[{"price":2978.64,"qty":0.00000000},{"price":2980.94,"qty":0.00775181}],"checksum":3638398073,"timestamp":"2024-06-01T17:52:47.798874Z"}]}
{"channel":"book","type":"update","data":[{"symbol":"ETH/GBP","bids":[{"price":2978.38,"qty":6.58533010}],"asks":[],"checksum":369871583,"timestamp":"2024-06-01T17:52:47.803254Z"}]}
{"channel":"book","type":"update","data":[{"symbol":"ETH/GBP","bids":[],"asks":[{"price":2979.46,"qty":13.16590883}],"checksum":669384518,"timestamp":"2024-06-01T17:52:47.843567Z"}]}
{"channel":"book","type":"update","data":[{"symbol":"ETH/GBP","bids":[{"price":2977.92,"qty":13.17269613}],"asks":[],"checksum":1650022020,"timestamp":"2024-06-01T17:52:47.843675Z"}]}
{"channel":"book","type":"update","data":[{"symbol":"ETH/GBP","bids":[{"price":2978.38,"qty":0.00000000},{"price":2974.45,"qty":1.31880744}],"asks":[],"checksum":3041818603,"timestamp":"2024-06-01T17:52:47.849865Z"}]}
{"channel":"book","type":"update","data":[{"symbol":"ETH/GBP","bids":[],"asks":[{"price":2979.46,"qty":0.00000000},{"price":2980.94,"qty":0.00775181}],"checksum":1017950782,"timestamp":"2024-06-01T17:52:47.850127Z"}]}
{"channel":"book","type":"update","data":[{"symbol":"ETH/GBP","bids":[],"asks":[{"price":2979.46,"qty":6.58295883}],"checksum":658506484,"timestamp":"2024-06-01T17:52:47.926198Z"}]}
{"channel":"book","type":"update","data":[{"symbol":"ETH/GBP","bids":[{"price":2978.39,"qty":6.58530179}],"asks":[],"checksum":2420756093,"timestamp":"2024-06-01T17:52:47.926351Z"}]}
{"channel":"book","type":"update","data":[{"symbol":"ETH/GBP","bids":[],"asks":[{"price":2979.46,"qty":0.00000000},{"price":2980.94,"qty":0.00775181}],"checksum":2342878903,"timestamp":"2024-06-01T17:52:47.931141Z"}]}
{"channel":"book","type":"update","data":[{"symbol":"ETH/GBP","bids":[],"asks":[{"price":2978.69,"qty":6.58467559}],"checksum":2421545598,"timestamp":"2024-06-01T17:52:48.075301Z"}]}
{"channel":"book","type":"update","data":[{"symbol":"ETH/GBP","bids":[],"asks":[{"price":2979.46,"qty":13.16590839}],"checksum":3908943481,"timestamp":"2024-06-01T17:52:48.075426Z"}]}
{"channel":"book","type":"update","data":[{"symbol":"ETH/GBP","bids":[{"price":2978.39,"qty":0.00000000},{"price":2974.45,"qty":1.31880744}],"asks":[],"checksum":1609855728,"timestamp":"2024-06-01T17:52:48.081237Z"}]}
{"channel":"book","type":"update","data":[{"symbol":"ETH/GBP","bids":[],"asks":[{"price":2979.46,"qty":0.00000000},{"price":2980.57,"qty":1.31610402}],"checksum":660346615,"timestamp":"2024-06-01T17:52:48.081437Z"}]}
{"channel":"book","type":"update","data":[{"symbol":"ETH/GBP","bids":[{"price":2978.40,"qty":6.58528795}],"asks":[],"checksum":1444866116,"timestamp":"2024-06-01T17:52:48.086015Z"}]}
{"channel":"book","type":"update","data":[{"symbol":"ETH/GBP","bids":[],"asks":[{"price":2978.69,"qty":0.00000000},{"price":2980.94,"qty":0.00775181}],"checksum":1307462797,"timestamp":"2024-06-01T17:52:48.148964Z"}]}
{"channel":"book","type":"update","data":[{"symbol":"ETH/GBP","bids":[],"asks":[{"price":2979.46,"qty":6.58295397}],"checksum":3470939569,"timestamp":"2024-06-01T17:52:48.176886Z"}]}
{"channel":"book","type":"update","data":[{"symbol":"ETH/GBP","bids":[],"asks":[{"price":2979.46,"qty":0.00000000},{"price":2980.94,"qty":0.00775181}],"checksum":1307462797,"timestamp":"2024-06-01T17:52:48.182344Z"}]}
{"channel":"book","type":"update","data":[{"symbol":"ETH/GBP","bids":[{"price":2978.40,"qty":0.00000000},{"price":2974.45,"qty":1.31880744}],"asks":[],"checksum":1017950782,"timestamp":"2024-06-01T17:52:48.194347Z"}]}
{"channel":"book","type":"update","data":[{"symbol":"ETH/GBP","bids":[{"price":2978.36,"qty":6.58536728}],"asks":[],"checksum":1218285745,"timestamp":"2024-06-01T17:52:48.199322Z"}]}
{"channel":"book","type":"update","data":[{"symbol":"ETH/GBP","bids":[{"price":2978.36,"qty":0.00000000},{"price":2974.45,"qty":1.31880744}],"asks":[],"checksum":1017950782,"timestamp":"2024-06-01T17:52:48.203222Z"}]}
{"channel":"book","type":"update","data":[{"symbol":"ETH/GBP","bids":[],"asks":[{"price":2978.65,"qty":6.58475473}],"checksum":960713551,"timestamp":"2024-06-01T17:52:48.293059Z"}]}
{"channel":"book","type":"update","data":[{"symbol":"ETH/GBP","bids":[],"asks":[{"price":2979.46,"qty":13.16591767}],"checksum":987364361,"timestamp":"2024-06-01T17:52:48.293177Z"}]}
{"channel":"book","type":"update","data":[{"symbol":"ETH/GBP","bids":[],"asks":[{"price":2979.46,"qty":0.00000000},{"price":2980.57,"qty":1.31610402}],"checksum":960713551,"timestamp":"2024-06-01T17:52:48.297820Z"}]}
{"channel":"book","type":"update","data":[{"symbol":"ETH/GBP","bids":[{"price":2978.36,"qty":6.58537452}],"asks":[],"checksum":3944299132,"timestamp":"2024-06-01T17:52:48.301823Z"}]}
{"channel":"book","type":"update","data":[{"symbol":"ETH/GBP","bids":[],"asks":[{"price":2978.65,"qty":0.00000000},{"price":2980.94,"qty":0.00775181}],"checksum":4009155341,"timestamp":"2024-06-01T17:52:48.394332Z"}]}
{"channel":"book","type":"update","data":[{"symbol":"ETH/GBP","bids":[],"asks":[{"price":2978.64,"qty":6.58478305}],"checksum":2357539836,"timestamp":"2024-06-01T17:52:48.399017Z"}]}
{"channel":"book","type":"update","data":[{"symbol":"ETH/GBP","bids":[{"price":2978.36,"qty":0.00000000},{"price":2974.45,"qty":1.31880744}],"asks":[],"checksum":1591696079,"timestamp":"2024-06-01T17:52:48.694739Z"}]}
{"channel":"book","type":"update","data":[{"symbol":"ETH/GBP","bids":[],"asks":[{"price":2979.09,"qty":13.16755552}],"checksum":3794973384,"timestamp":"2024-06-01T17:52:48.700318Z"}]}
{"channel":"book","type":"update","data":[{"symbol":"ETH/GBP","bids":[{"price":2978.37,"qty":6.58535542}],"asks":[],"checksum":390138920,"timestamp":"2024-06-01T17:52:48.700382Z"}]}
{"channel":"book","type":"update","data":[{"symbol":"ETH/GBP","bids":[{"price":2978.37,"qty":0.00000000},{"price":2974.45,"qty":1.31880744}],"asks":[],"checksum":3794973384,"timestamp":"2024-06-01T17:52:48.706568Z"}]}
{"channel":"book","type":"update","data":[{"symbol":"ETH/GBP","bids":[],"asks":[{"price":2980.55,"qty":0.00000000},{"price":2980.57,"qty":1.31610402}],"checksum":912012136,"timestamp":"2024-06-01T17:52:48.771129Z"}]}
{"channel":"book","type":"update","data":[{"symbol":"ETH/GBP","bids":[],"asks":[{"price":2979.82,"qty":1.04691520}],"checksum":1889754437,"timestamp":"2024-06-01T17:52:48.773189Z"}]}
{"channel":"book","type":"update","data":[{"symbol":"ETH/GBP","bids":[],"asks":[{"price":2980.15,"qty":32.75495190}],"checksum":1033835793,"timestamp":"2024-06-01T17:52:48.773290Z"}]}
{"channel":"book","type":"update","data":[{"symbol":"ETH/GBP","bids":[],"asks":[{"price":2978.64,"qty":0.00000000},{"price":2980.56,"qty":2.94416492}],"checksum":1751614328,"timestamp":"2024-06-01T17:52:48.824006Z"}]}
{"channel":"book","type":"update","data":[{"symbol":"ETH/GBP","bids":[{"price":2978.38,"qty":6.58532967}],"asks":[],"checksum":1647742212,"timestamp":"2024-06-01T17:52:48.828452Z"}]}
{"channel":"book","type":"update","data":[{"symbol":"ETH/GBP","bids":[],"asks":[{"price":2978.67,"qty":6.58470456}],"checksum":2749653537,"timestamp":"2024-06-01T17:52:48.828468Z"}]}
{"channel":"book","type":"update","data":[{"symbol":"ETH/GBP","bids":[{"price":2978.38,"qty":0.00000000},{"price":2974.45,"qty":1.31880744}],"asks":[],"checksum":2847239261,"timestamp":"2024-06-01T17:52:48.838261Z"}]}
{"channel":"book","type":"update","data":[{"symbol":"ETH/GBP","bids":[{"price":2977.92,"qty":0.00000000},{"price":2974.30,"qty":0.30200000}],"asks":[],"checksum":4033553372,"timestamp":"2024-06-01T17:52:48.895513Z"}]}
{"channel":"book","type":"update","data":[{"symbol":"ETH/GBP","bids":[{"price":2977.97,"qty":13.17245380}],"asks":[],"checksum":3960394508,"timestamp":"2024-06-01T17:52:48.899465Z"}]}
{"channel":"book","type":"update","data":[{"symbol":"ETH/GBP","bids":[],"asks":[{"price":2979.09,"qty":0.00000000},{"price":2980.56,"qty":2.94416492}],"checksum":585794881,"timestamp":"2024-06-01T17:52:49.026832Z"}]}
{"channel":"book","type":"update","data":[{"symbol":"ETH/GBP","bids":[],"asks":[{"price":2978.67,"qty":0.00000000},{"price":2980.57,"qty":1.31610402}],"checksum":1173985586,"timestamp":"2024-06-01T17:52:49.026921Z"}]}
{"channel":"book","type":"update","data":[{"symbol":"ETH/GBP","bids":[{"price":2977.97,"qty":0.00000000},{"price":2974.30,"qty":0.30200000}],"asks":[],"checksum":282233081,"timestamp":"2024-06-01T17:52:49.026937Z"}]}
{"channel":"book","type":"update","data":[{"symbol":"ETH/GBP","bids":[{"price":2974.47,"qty":0.14107694}],"asks":[],"checksum":3321968952,"timestamp":"2024-06-01T17:52:49.030657Z"}]}
{"channel":"book","type":"update","data":[{"symbol":"ETH/GBP","bids":[{"price":2978.27,"qty":6.58557001}],"asks":[],"checksum":3508699019,"timestamp":"2024-06-01T17:52:49.032489Z"}]}
{"channel":"book","type":"update","data":[{"symbol":"ETH/GBP","bids":[],"asks":[{"price":2978.51,"qty":6.58505793}],"checksum":2297976897,"timestamp":"2024-06-01T17:52:49.032505Z"}]}
{"channel":"book","type":"update","data":[{"symbol":"ETH/GBP","bids":[],"asks":[{"price":2979.46,"qty":13.16591767}],"checksum":3273752424,"timestamp":"2024-06-01T17:52:49.032711Z"}]}
{"channel":"book","type":"update","data":[{"symbol":"ETH/GBP","bids":[],"asks":[{"price":2979.91,"qty":0.00000000},{"price":2980.56,"qty":2.94416492}],"checksum":215650319,"timestamp":"2024-06-01T17:52:49.035175Z"}]}
{"channel":"book","type":"update","data":[{"symbol":"ETH/GBP","bids":[],"asks":[{"price":2978.51,"qty":0.00000000},{"price":2980.57,"qty":1.31610402}],"checksum":4038810436,"timestamp":"2024-06-01T17:52:49.037999Z"}]}
{"channel":"book","type":"update","data":[{"symbol":"ETH/GBP","bids":[{"price":2978.27,"qty":0.00000000},{"price":2974.45,"qty":1.31880744}],"asks":[],"checksum":3885506039,"timestamp":"2024-06-01T17:52:49.038052Z"}]}
{"channel":"book","type":"update","data":[{"symbol":"ETH/GBP","bids":[],"asks":[{"price":2979.46,"qty":0.00000000},{"price":2980.94,"qty":0.00775181}],"checksum":517446126,"timestamp":"2024-06-01T17:52:49.038060Z"}]}
{"channel":"book","type":"update","data":[{"symbol":"ETH/GBP","bids":[],"asks":[{"price":2979.44,"qty":1.31710510}],"checksum":2624401079,"timestamp":"2024-06-01T17:52:49.042153Z"}]}
{"channel":"book","type":"update","data":[{"symbol":"ETH/GBP","bids":[],"asks":[{"price":2979.66,"qty":1.31650256}],"checksum":1560099057,"timestamp":"2024-06-01T17:52:49.046616Z"}]}
{"channel":"book","type":"update","data":[{"symbol":"ETH/GBP","bids":[{"price":2977.71,"qty":13.17362767}],"asks":[],"checksum":1872670033,"timestamp":"2024-06-01T17:52:49.113016Z"}]}
{"channel":"book","type":"update","data":[{"symbol":"ETH/GBP","bids":[],"asks":[{"price":2978.41,"qty":6.58528276}],"checksum":1005130513,"timestamp":"2024-06-01T17:52:49.135487Z"}]}
{"channel":"book","type":"update","data":[{"symbol":"ETH/GBP","bids":[{"price":2978.13,"qty":6.58587689}],"asks":[],"checksum":1174814523,"timestamp":"2024-06-01T17:52:49.135643Z"}]}
{"channel":"book","type":"update","data":[{"symbol":"ETH/GBP","bids":[{"price":2978.13,"qty":0.00000000},{"price":2974.46,"qty":0.34510000}],"asks":[],"checksum":1005130513,"timestamp":"2024-06-01T17:52:49.171039Z"}]}
{"channel":"book","type":"update","data":[{"symbol":"ETH/GBP","bids":[{"price":2978.18,"qty":0.00000000},{"price":2974.45,"qty":1.31880744},{"price":2977.64,"qty":0.08561200}],"asks":[],"checksum":2807264443,"timestamp":"2024-06-01T17:52:49.215702Z"}]}
{"channel":"book","type":"update","data":[{"symbol":"ETH/GBP","bids":[],"asks":[{"price":2978.41,"qty":0.00000000},{"price":2980.56,"qty":2.94416492}],"checksum":4079274747,"timestamp":"2024-06-01T17:52:49.220775Z"}]}
{"channel":"book","type":"update","data":[{"symbol":"ETH/GBP","bids":[{"price":2978.14,"qty":6.58585976}],"asks":[],"checksum":1752329385,"timestamp":"2024-06-01T17:52:49.257260Z"}]}
{"channel":"book","type":"update","data":[{"symbol":"ETH/GBP","bids":[],"asks":[{"price":2979.43,"qty":13.16606968}],"checksum":2219402770,"timestamp":"2024-06-01T17:52:49.257287Z"}]}
{"channel":"book","type":"update","data":[{"symbol":"ETH/GBP","bids":[],"asks":[{"price":2979.43,"qty":19.74910452}],"checksum":3884554216,"timestamp":"2024-06-01T17:52:49.257338Z"}]}
{"channel":"book","type":"update","data":[{"symbol":"ETH/GBP","bids":[],"asks":[{"price":2979.43,"qty":13.16606968}],"checksum":2219402770,"timestamp":"2024-06-01T17:52:49.263341Z"}]}
{"channel":"book","type":"update","data":[{"symbol":"ETH/GBP","bids":[],"asks":[{"price":2979.43,"qty":0.00000000},{"price":2980.56,"qty":2.94416492}],"checksum":1752329385,"timestamp":"2024-06-01T17:52:49.263363Z"}]}
{"channel":"book","type":"update","data":[{"symbol":"ETH/GBP","bids":[{"price":2978.14,"qty":0.00000000},{"price":2974.46,"qty":0.34510000}],"asks":[],"checksum":4079274747,"timestamp":"2024-06-01T17:52:49.376306Z"}]}
{"channel":"book","type":"update","data":[{"symbol":"ETH/GBP","bids":[{"price":2977.71,"qty":0.00000000},{"price":2974.45,"qty":1.31880744}],"asks":[],"checksum":1625946315,"timestamp":"2024-06-01T17:52:49.381389Z"}]}
{"channel":"book","type":"update","data":[{"symbol":"ETH/GBP","bids":[{"price":2978.19,"qty":6.58575873}],"asks":[],"checksum":1775737362,"timestamp":"2024-06-01T17:52:49.386457Z"}]}
{"channel":"book","type":"update","data":[{"symbol":"ETH/GBP","bids":[{"price":2977.72,"qty":13.17356592}],"asks":[],"checksum":3043494894,"timestamp":"2024-06-01T17:52:49.386478Z"}]}
{"channel":"book","type":"update","data":[{"symbol":"ETH/GBP","bids":[],"asks":[{"price":2978.45,"qty":6.58520001}],"checksum":3122821239,"timestamp":"2024-06-01T17:52:49.386568Z"}]}
{"channel":"book","type":"update","data":[{"symbol":"ETH/GBP","bids":[{"price":2977.72,"qty":0.00000000},{"price":2974.46,"qty":0.34510000}],"asks":[],"checksum":1021284982,"timestamp":"2024-06-01T17:52:49.392056Z"}]}
{"channel":"book","type":"update","data":[{"symbol":"ETH/GBP","bids":[],"asks":[{"price":2978.45,"qty":0.00000000},{"price":2980.56,"qty":2.94416492}],"checksum":1775737362,"timestamp":"2024-06-01T17:52:49.422168Z"}]}
{"channel":"book","type":"update","data":[{"symbol":"ETH/GBP","bids":[{"price":2978.19,"qty":0.00000000},{"price":2974.45,"qty":1.31880744}],"asks":[],"checksum":1625946315,"timestamp":"2024-06-01T17:52:49.441270Z"}]}
{"channel":"book","type":"update","data":[{"symbol":"ETH/GBP","bids":[],"asks":[{"price":2978.87,"qty":13.16853368}],"checksum":1805250921,"timestamp":"2024-06-01T17:52:49.470508Z"}]}
{"channel":"book","type":"update","data":[{"symbol":"ETH/GBP","bids":[],"asks":[{"price":2978.41,"qty":6.58527752}],"checksum":3382734790,"timestamp":"2024-06-01T17:52:49.522773Z"}]}
{"channel":"book","type":"update","data":[{"symbol":"ETH/GBP","bids":[],"asks":[{"price":2978.87,"qty":0.00000000},{"price":2980.29,"qty":0.94850883}],"checksum":142638212,"timestamp":"2024-06-01T17:52:49.523802Z"}]}
{"channel":"book","type":"update","data":[{"symbol":"ETH/GBP","bids":[{"price":2978.15,"qty":6.58583564}],"asks":[],"checksum":2810204266,"timestamp":"2024-06-01T17:52:49.524831Z"}]}
{"channel":"book","type":"update","data":[{"symbol":"ETH/GBP","bids":[],"asks":[{"price":2978.41,"qty":0.00000000},{"price":2980.56,"qty":2.94416492}],"checksum":3488207909,"timestamp":"2024-06-01T17:52:49.529340Z"}]}
{"channel":"book","type":"update","data":[{"symbol":"ETH/GBP","bids":[{"price":2978.15,"qty":0.00000000},{"price":2974.45,"qty":1.31880744}],"asks":[],"checksum":1625946315,"timestamp":"2024-06-01T17:52:49.529421Z"}]}
{"channel":"book","type":"update","data":[{"symbol":"ETH/GBP","bids":[{"price":2977.65,"qty":13.17387251}],"asks":[],"checksum":2864966884,"timestamp":"2024-06-01T17:52:49.597906Z"}]}
{"channel":"book","type":"update","data":[{"symbol":"ETH/GBP","bids":[{"price":2977.65,"qty":0.00000000},{"price":2974.45,"qty":1.31880744}],"asks":[],"checksum":1625946315,"timestamp":"2024-06-01T17:52:49.602118Z"}]}
{"channel":"book","type":"update","data":[{"symbol":"ETH/GBP","bids":[],"asks":[{"price":2979.47,"qty":0.00000000},{"price":2980.57,"qty":1.31610402}],"checksum":3480132100,"timestamp":"2024-06-01T17:52:49.604729Z"}]}
{"channel":"book","type":"update","data":[{"symbol":"ETH/GBP","bids":[],"asks":[{"price":2979.36,"qty":0.31000000}],"checksum":760017857,"timestamp":"2024-06-01T17:52:49.605074Z"}]}
{"channel":"book","type":"update","data":[{"symbol":"ETH/GBP","bids":[],"asks":[{"price":2978.41,"qty":6.58529479}],"checksum":2087884263,"timestamp":"2024-06-01T17:52:49.842238Z"}]}
{"channel":"book","type":"update","data":[{"symbol":"ETH/GBP","bids":[],"asks":[{"price":2979.35,"qty":13.16642277}],"checksum":816868736,"timestamp":"2024-06-01T17:52:49.842405Z"}]}
{"channel":"book","type":"update","data":[{"symbol":"ETH/GBP","bids":[{"price":2978.15,"qty":6.58583685}],"asks":[],"checksum":1391311328,"timestamp":"2024-06-01T17:52:49.842555Z"}]}
{"channel":"book","type":"update","data":[{"symbol":"ETH/GBP","bids":[{"price":2977.66,"qty":13.17382871}],"asks":[],"checksum":3118655018,"timestamp":"2024-06-01T17:52:49.842671Z"}]}
{"channel":"book","type":"update","data":[{"symbol":"ETH/GBP","bids":[],"asks":[{"price":2979.35,"qty":0.00000000},{"price":2980.29,"qty":0.94850883}],"checksum":540552614,"timestamp":"2024-06-01T17:52:49.848005Z"}]}
{"channel":"book","type":"update","data":[{"symbol":"ETH/GBP","bids":[{"price":2978.15,"qty":0.00000000},{"price":2974.46,"qty":0.34510000}],"asks":[],"checksum":3378993815,"timestamp":"2024-06-01T17:52:49.996173Z"}]}
{"channel":"book","type":"update","data":[{"symbol":"ETH/GBP","bids":[{"price":2977.66,"qty":0.00000000},{"price":2974.45,"qty":1.31880744}],"asks":[],"checksum":2087884263,"timestamp":"2024-06-01T17:52:49.996244Z"}]}
{"channel":"book","type":"update","data":[{"symbol":"ETH/GBP","bids":[{"price":2977.00,"qty":0.00000000},{"price":2974.30,"qty":0.30200000}],"asks":[],"checksum":145957131,"timestamp":"2024-06-01T17:52:49.996255Z"}]}
{"channel":"book","type":"update","data":[{"symbol":"ETH/GBP","bids":[],"asks":[{"price":2978.41,"qty":0.00000000},{"price":2980.56,"qty":2.94416492}],"checksum":3906288954,"timestamp":"2024-06-01T17:52:49.996271Z"}]}
{"channel":"book","type":"update","data":[{"symbol":"ETH/GBP","bids":[{"price":2977.63,"qty":0.00000000},{"price":2973.93,"qty":0.27474654}],"asks":[],"checksum":1436263980,"timestamp":"2024-06-01T17:52:49.999158Z"}]}
{"channel":"book","type":"update","data":[{"symbol":"ETH/GBP","bids":[{"price":2977.74,"qty":0.31000000}],"asks":[],"checksum":199712471,"timestamp":"2024-06-01T17:52:49.999309Z"}]}
{"channel":"book","type":"update","data":[{"symbol":"ETH/GBP","bids":[],"asks":[{"price":2978.26,"qty":6.58562124}],"checksum":3096134499,"timestamp":"2024-06-01T17:52:50.002557Z"}]}
{"channel":"book","type":"update","data":[{"symbol":"ETH/GBP","bids":[{"price":2977.98,"qty":6.58620618}],"asks":[],"checksum":3523993177,"timestamp":"2024-06-01T17:52:50.002676Z"}]}
{"channel":"book","type":"update","data":[{"symbol":"ETH/GBP","bids":[{"price":2976.75,"qty":1.31778891}],"asks":[],"checksum":3384461947,"timestamp":"2024-06-01T17:52:50.002719Z"}]}
{"channel":"book","type":"update","data":[{"symbol":"ETH/GBP","bids":[{"price":2977.98,"qty":0.00000000},{"price":2974.45,"qty":1.31880744}],"asks":[],"checksum":2623813052,"timestamp":"2024-06-01T17:52:50.017986Z"}]}
{"channel":"book","type":"update","data":[{"symbol":"ETH/GBP","bids":[],"asks":[{"price":2978.26,"qty":0.00000000},{"price":2980.56,"qty":2.94416492}],"checksum":1356541492,"timestamp":"2024-06-01T17:52:50.018149Z"}]}
{"channel":"book","type":"update","data":[{"symbol":"ETH/GBP","bids":[],"asks":[{"price":2979.33,"qty":1.31718289}],"checksum":2882841984,"timestamp":"2024-06-01T17:52:50.021302Z"}]}
{"channel":"book","type":"update","data":[{"symbol":"ETH/GBP","bids":[],"asks":[{"price":2979.44,"qty":0.00000000},{"price":2980.56,"qty":2.94416492}],"checksum":3787387996,"timestamp":"2024-06-01T17:52:50.024074Z"}]}
{"channel":"book","type":"update","data":[{"symbol":"ETH/GBP","bids":[],"asks":[{"price":2979.36,"qty":0.00000000},{"price":2980.57,"qty":1.31610402}],"checksum":473447432,"timestamp":"2024-06-01T17:52:50.024287Z"}]}
{"channel":"book","type":"update","data":[{"symbol":"ETH/GBP","bids":[],"asks":[{"price":2979.25,"qty":0.31000000}],"checksum":1616041354,"timestamp":"2024-06-01T17:52:50.024354Z"}]}
{"channel":"book","type":"update","data":[{"symbol":"ETH/GBP","bids":[],"asks":[{"price":2979.24,"qty":13.16689962}],"checksum":2441359536,"timestamp":"2024-06-01T17:52:50.042680Z"}]}
{"channel":"book","type":"update","data":[{"symbol":"ETH/GBP","bids":[{"price":2977.53,"qty":13.17441589}],"asks":[],"checksum":1489564854,"timestamp":"2024-06-01T17:52:50.042786Z"}]}
{"channel":"book","type":"update","data":[{"symbol":"ETH/GBP","bids":[],"asks":[{"price":2979.25,"qty":0.00000000},{"price":2980.56,"qty":2.94416492}],"checksum":3934254767,"timestamp":"2024-06-01T17:52:50.045592Z"}]}
{"channel":"book","type":"update","data":[{"symbol":"ETH/GBP","bids":[],"asks":[{"price":2979.16,"qty":0.31000000}],"checksum":1061404377,"timestamp":"2024-06-01T17:52:50.045643Z"}]}
{"channel":"book","type":"update","data":[{"symbol":"ETH/GBP","bids":[],"asks":[{"price":2979.24,"qty":0.00000000},{"price":2980.56,"qty":2.94416492}],"checksum":2946080809,"timestamp":"2024-06-01T17:52:50.048057Z"}]}
{"channel":"book","type":"update","data":[{"symbol":"ETH/GBP","bids":[{"price":2977.53,"qty":0.00000000},{"price":2974.45,"qty":1.31880744}],"asks":[],"checksum":2726818340,"timestamp":"2024-06-01T17:52:50.048086Z"}]}
{"channel":"book","type":"update","data":[{"symbol":"ETH/GBP","bids":[],"asks":[{"price":2978.27,"qty":6.58560002}],"checksum":76329099,"timestamp":"2024-06-01T17:52:50.113617Z"}]}
{"channel":"book","type":"update","data":[{"symbol":"ETH/GBP","bids":[{"price":2977.98,"qty":6.58620462}],"asks":[],"checksum":2810414757,"timestamp":"2024-06-01T17:52:50.113703Z"}]}
{"channel":"book","type":"update","data":[{"symbol":"ETH/GBP","bids":[],"asks":[{"price":2978.27,"qty":0.00000000},{"price":2980.56,"qty":2.94416492}],"checksum":25740298,"timestamp":"2024-06-01T17:52:50.119019Z"}]}
{"channel":"book","type":"update","data":[{"symbol":"ETH/GBP","bids":[{"price":2974.47,"qty":0.00000000},{"price":2974.45,"qty":1.31880744}],"asks":[],"checksum":3030219586,"timestamp":"2024-06-01T17:52:50.183783Z"}]}
{"channel":"book","type":"update","data":[{"symbol":"ETH/GBP","bids":[{"price":2977.98,"qty":0.00000000},{"price":2974.30,"qty":0.30200000}],"asks":[],"checksum":1951679461,"timestamp":"2024-06-01T17:52:50.185074Z"}]}
{"channel":"book","type":"update","data":[{"symbol":"ETH/GBP","bids":[{"price":2977.99,"qty":6.58619672}],"asks":[],"checksum":4042585,"timestamp":"2024-06-01T17:52:50.221691Z"}]}
{"channel":"book","type":"update","data":[{"symbol":"ETH/GBP","bids":[],"asks":[{"price":2978.27,"qty":6.58559212}],"checksum":2575418837,"timestamp":"2024-06-01T17:52:50.221713Z"}]}
{"channel":"book","type":"update","data":[{"symbol":"ETH/GBP","bids":[],"asks":[{"price":2978.27,"qty":0.00000000},{"price":2980.56,"qty":2.94416492}],"checksum":4042585,"timestamp":"2024-06-01T17:52:50.315475Z"}]}
{"channel":"book","type":"update","data":[{"symbol":"ETH/GBP","bids":[],"asks":[{"price":2979.15,"qty":13.16728236}],"checksum":2605135204,"timestamp":"2024-06-01T17:52:50.322077Z"}]}
{"channel":"book","type":"update","data":[{"symbol":"ETH/GBP","bids":[{"price":2977.53,"qty":13.17442741}],"asks":[],"checksum":819237134,"timestamp":"2024-06-01T17:52:50.322101Z"}]}
{"channel":"book","type":"update","data":[{"symbol":"ETH/GBP","bids":[],"asks":[{"price":2978.26,"qty":6.58562391}],"checksum":4074995921,"timestamp":"2024-06-01T17:52:50.322137Z"}]}
{"channel":"book","type":"update","data":[{"symbol":"ETH/GBP","bids":[],"asks":[{"price":2979.15,"qty":0.00000000},{"price":2980.29,"qty":0.94850883}],"checksum":120545041,"timestamp":"2024-06-01T17:52:50.327421Z"}]}
{"channel":"book","type":"update","data":[{"symbol":"ETH/GBP","bids":[],"asks":[{"price":2978.26,"qty":0.00000000},{"price":2980.56,"qty":2.94416492}],"checksum":1747429253,"timestamp":"2024-06-01T17:52:50.331984Z"}]}
{"channel":"book","type":"update","data":[{"symbol":"ETH/GBP","bids":[{"price":2977.99,"qty":0.00000000},{"price":2974.45,"qty":1.31880744}],"asks":[],"checksum":2989895838,"timestamp":"2024-06-01T17:52:50.332168Z"}]}
{"channel":"book","type":"update","data":[{"symbol":"ETH/GBP","bids":[{"price":2977.97,"qty":6.58623407}],"asks":[],"checksum":345028925,"timestamp":"2024-06-01T17:52:50.337901Z"}]}
{"channel":"book","type":"update","data":[{"symbol":"ETH/GBP","bids":[{"price":2977.97,"qty":0.00000000},{"price":2974.45,"qty":1.31880744}],"asks":[],"checksum":2989895838,"timestamp":"2024-06-01T17:52:50.388394Z"}]}
{"channel":"book","type":"update","data":[{"symbol":"ETH/GBP","bids":[],"asks":[{"price":2979.15,"qty":6.58364670}],"checksum":3138734903,"timestamp":"2024-06-01T17:52:50.438799Z"}]}
{"channel":"book","type":"update","data":[{"symbol":"ETH/GBP","bids":[{"price":2977.93,"qty":6.58632827}],"asks":[],"checksum":2458793402,"timestamp":"2024-06-01T17:52:50.438851Z"}]}
{"channel":"book","type":"update","data":[{"symbol":"ETH/GBP","bids":[],"asks":[{"price":2979.15,"qty":0.00000000},{"price":2980.56,"qty":2.94416492}],"checksum":2611826195,"timestamp":"2024-06-01T17:52:50.443722Z"}]}
{"channel":"book","type":"update","data":[{"symbol":"ETH/GBP","bids":[{"price":2977.55,"qty":0.00000000},{"price":2974.45,"qty":1.31880744}],"asks":[],"checksum":1903752932,"timestamp":"2024-06-01T17:52:50.448903Z"}]}
{"channel":"book","type":"update","data":[{"symbol":"ETH/GBP","bids":[],"asks":[{"price":2979.66,"qty":0.00000000},{"price":2980.57,"qty":1.31610402}],"checksum":596601766,"timestamp":"2024-06-01T17:52:50.450512Z"}]}
{"channel":"book","type":"update","data":[{"symbol":"ETH/GBP","bids":[{"price":2977.93,"qty":0.00000000},{"price":2974.30,"qty":0.30200000}],"asks":[],"checksum":194045565,"timestamp":"2024-06-01T17:52:50.450522Z"}]}
{"channel":"book","type":"update","data":[{"symbol":"ETH/GBP","bids":[{"price":2977.53,"qty":0.00000000},{"price":2973.94,"qty":0.14110207}],"asks":[],"checksum":4186475523,"timestamp":"2024-06-01T17:52:50.450614Z"}]}
{"channel":"book","type":"update","data":[{"symbol":"ETH/GBP","bids":[{"price":2977.74,"qty":0.00000000},{"price":2973.93,"qty":0.27474654}],"asks":[],"checksum":1786054386,"timestamp":"2024-06-01T17:52:50.453316Z"}]}
{"channel":"book","type":"update","data":[{"symbol":"ETH/GBP","bids":[{"price":2977.16,"qty":4.67279727}],"asks":[],"checksum":600753874,"timestamp":"2024-06-01T17:52:50.453495Z"}]}
{"channel":"book","type":"update","data":[{"symbol":"ETH/GBP","bids":[{"price":2976.22,"qty":0.14493675}],"asks":[],"checksum":2484121682,"timestamp":"2024-06-01T17:52:50.455362Z"}]}
{"channel":"book","type":"update","data":[{"symbol":"ETH/GBP","bids":[],"asks":[{"price":2980.13,"qty":1.31629644}],"checksum":1609669488,"timestamp":"2024-06-01T17:52:50.455843Z"}]}
{"channel":"book","type":"update","data":[{"symbol":"ETH/GBP","bids":[],"asks":[{"price":2979.41,"qty":1.31661520}],"checksum":1456574675,"timestamp":"2024-06-01T17:52:50.455866Z"}]}
{"channel":"book","type":"update","data":[{"symbol":"ETH/GBP","bids":[{"price":2976.22,"qty":0.00000000},{"price":2973.94,"qty":0.14110207}],"asks":[],"checksum":3775915603,"timestamp":"2024-06-01T17:52:50.459138Z"}]}
{"channel":"book","type":"update","data":[{"symbol":"ETH/GBP","bids":[],"asks":[{"price":2979.16,"qty":1.62721635}],"checksum":2590721244,"timestamp":"2024-06-01T17:52:50.470426Z"}]}
{"channel":"book","type":"update","data":[{"symbol":"ETH/GBP","bids":[],"asks":[{"price":2979.33,"qty":0.00000000},{"price":2980.56,"qty":2.94416492}],"checksum":858152154,"timestamp":"2024-06-01T17:52:50.473689Z"}]}
{"channel":"book","type":"update","data":[{"symbol":"ETH/GBP","bids":[],"asks":[{"price":2979.14,"qty":13.16733717}],"checksum":1034670328,"timestamp":"2024-06-01T17:52:50.585192Z"}]}
{"channel":"book","type":"update","data":[{"symbol":"ETH/GBP","bids":[],"asks":[{"price":2979.15,"qty":6.58364891}],"checksum":1452433619,"timestamp":"2024-06-01T17:52:50.585217Z"}]}
{"channel":"book","type":"update","data":[{"symbol":"ETH/GBP","bids":[{"price":2977.85,"qty":6.58650278}],"asks":[],"checksum":1606958532,"timestamp":"2024-06-01T17:52:50.585302Z"}]}
{"channel":"book","type":"update","data":[{"symbol":"ETH/GBP","bids":[{"price":2977.40,"qty":13.17500406}],"asks":[],"checksum":2003179677,"timestamp":"2024-06-01T17:52:50.585388Z"}]}
{"channel":"book","type":"update","data":[{"symbol":"ETH/GBP","bids":[],"asks":[{"price":2979.15,"qty":0.00000000},{"price":2980.29,"qty":0.94850883}],"checksum":4173240135,"timestamp":"2024-06-01T17:52:50.591290Z"}]}
{"channel":"book","type":"update","data":[{"symbol":"ETH/GBP","bids":[],"asks":[{"price":2979.14,"qty":0.00000000},{"price":2980.56,"qty":2.94416492}],"checksum":3343396125,"timestamp":"2024-06-01T17:52:50.591317Z"}]}
{"channel":"book","type":"update","data":[{"symbol":"ETH/GBP","bids":[{"price":2977.85,"qty":0.00000000},{"price":2974.30,"qty":0.30200000}],"asks":[],"checksum":1843100140,"timestamp":"2024-06-01T17:52:50.610299Z"}]}
{"channel":"book","type":"update","data":[{"symbol":"ETH/GBP","bids":[],"asks":[{"price":2978.13,"qty":6.58591268}],"checksum":957928078,"timestamp":"2024-06-01T17:52:50.699267Z"}]}
{"channel":"book","type":"update","data":[{"symbol":"ETH/GBP","bids":[{"price":2977.87,"qty":6.58646183}],"asks":[],"checksum":134450719,"timestamp":"2024-06-01T17:52:50.699331Z"}]}
{"channel":"book","type":"update","data":[{"symbol":"ETH/GBP","bids":[],"asks":[{"price":2978.13,"qty":0.00000000},{"price":2980.56,"qty":2.94416492}],"checksum":2884324800,"timestamp":"2024-06-01T17:52:50.716902Z"}]}
{"channel":"book","type":"update","data":[{"symbol":"ETH/GBP","bids":[],"asks":[{"price":2979.15,"qty":13.16728767}],"checksum":1911915926,"timestamp":"2024-06-01T17:52:50.791268Z"}]}
{"channel":"book","type":"update","data":[{"symbol":"ETH/GBP","bids":[],"asks":[{"price":2979.13,"qty":1.31722904}],"checksum":1165807963,"timestamp":"2024-06-01T17:52:50.794092Z"}]}
{"channel":"book","type":"update","data":[{"symbol":"ETH/GBP","bids":[],"asks":[{"price":2979.15,"qty":0.00000000},{"price":2980.29,"qty":0.94850883}],"checksum":2526922654,"timestamp":"2024-06-01T17:52:50.795608Z"}]}
{"channel":"book","type":"update","data":[{"symbol":"ETH/GBP","bids":[],"asks":[{"price":2979.16,"qty":0.31000000}],"checksum":4106953216,"timestamp":"2024-06-01T17:52:50.797062Z"}]}
{"channel":"book","type":"update","data":[{"symbol":"ETH/GBP","bids":[],"asks":[{"price":2978.13,"qty":6.58589434}],"checksum":1636496371,"timestamp":"2024-06-01T17:52:50.799392Z"}]}
{"channel":"book","type":"update","data":[{"symbol":"ETH/GBP","bids":[{"price":2977.87,"qty":0.00000000},{"price":2974.30,"qty":0.30200000}],"asks":[],"checksum":3064447005,"timestamp":"2024-06-01T17:52:50.892351Z"}]}
{"channel":"book","type":"update","data":[{"symbol":"ETH/GBP","bids":[{"price":2977.88,"qty":6.58643556}],"asks":[],"checksum":1861330797,"timestamp":"2024-06-01T17:52:50.896590Z"}]}
{"channel":"book","type":"update","data":[{"symbol":"ETH/GBP","bids":[],"asks":[{"price":2978.13,"qty":0.00000000},{"price":2980.29,"qty":0.94850883}],"checksum":4222645918,"timestamp":"2024-06-01T17:52:50.965862Z"}]}
{"channel":"book","type":"update","data":[{"symbol":"ETH/GBP","bids":[{"price":2977.88,"qty":0.00000000},{"price":2974.30,"qty":0.30200000}],"asks":[],"checksum":1211937237,"timestamp":"2024-06-01T17:52:50.965895Z"}]}
{"channel":"book","type":"update","data":[{"symbol":"ETH/GBP","bids":[],"asks":[{"price":2978.11,"qty":6.58595123}],"checksum":198550842,"timestamp":"2024-06-01T17:52:50.972009Z"}]}
{"channel":"book","type":"update","data":[{"symbol":"ETH/GBP","bids":[],"asks":[{"price":2978.11,"qty":0.00000000},{"price":2980.29,"qty":0.94850883}],"checksum":1211937237,"timestamp":"2024-06-01T17:52:51.015753Z"}]}
{"channel":"book","type":"update","data":[{"symbol":"ETH/GBP","bids":[],"asks":[{"price":2979.12,"qty":13.16742910}],"checksum":911991902,"timestamp":"2024-06-01T17:52:51.020537Z"}]}
{"channel":"book","type":"update","data":[{"symbol":"ETH/GBP","bids":[{"price":2977.83,"qty":6.58654040}],"asks":[],"checksum":4151930561,"timestamp":"2024-06-01T17:52:51.020575Z"}]}
{"channel":"book","type":"update","data":[{"symbol":"ETH/GBP","bids":[],"asks":[{"price":2979.12,"qty":0.00000000},{"price":2980.29,"qty":0.94850883}],"checksum":2372752188,"timestamp":"2024-06-01T17:52:51.025568Z"}]}
{"channel":"book","type":"update","data":[{"symbol":"ETH/GBP","bids":[{"price":2977.83,"qty":0.00000000},{"price":2974.30,"qty":0.30200000}],"asks":[],"checksum":1211937237,"timestamp":"2024-06-01T17:52:51.054064Z"}]}
{"channel":"book","type":"update","data":[{"symbol":"ETH/GBP","bids":[],"asks":[{"price":2979.82,"qty":0.00000000},{"price":2980.56,"qty":2.94416492}],"checksum":160675351,"timestamp":"2024-06-01T17:52:51.245344Z"}]}
{"channel":"book","type":"update","data":[{"symbol":"ETH/GBP","bids":[],"asks":[{"price":2980.15,"qty":0.00000000},{"price":2980.57,"qty":1.31610402}],"checksum":3961109568,"timestamp":"2024-06-01T17:52:51.245593Z"}]}
{"channel":"book","type":"update","data":[{"symbol":"ETH/GBP","bids":[],"asks":[{"price":2980.12,"qty":31.73723707}],"checksum":3187419738,"timestamp":"2024-06-01T17:52:51.249813Z"}]}
{"channel":"book","type":"update","data":[{"symbol":"ETH/GBP","bids":[{"price":2977.65,"qty":6.58694311}],"asks":[],"checksum":102998102,"timestamp":"2024-06-01T17:52:51.287797Z"}]}
{"channel":"book","type":"update","data":[{"symbol":"ETH/GBP","bids":[],"asks":[{"price":2978.10,"qty":6.58597211}],"checksum":2128340873,"timestamp":"2024-06-01T17:52:51.287922Z"}]}
{"channel":"book","type":"update","data":[{"symbol":"ETH/GBP","bids":[],"asks":[{"price":2979.11,"qty":13.16746446}],"checksum":1864008618,"timestamp":"2024-06-01T17:52:51.287948Z"}]}
{"channel":"book","type":"update","data":[{"symbol":"ETH/GBP","bids":[],"asks":[{"price":2979.11,"qty":0.00000000},{"price":2980.29,"qty":0.94850883}],"checksum":2128340873,"timestamp":"2024-06-01T17:52:51.292828Z"}]}
{"channel":"book","type":"update","data":[{"symbol":"ETH/GBP","bids":[{"price":2977.65,"qty":0.00000000},{"price":2974.30,"qty":0.30200000}],"asks":[],"checksum":1114789650,"timestamp":"2024-06-01T17:52:51.292950Z"}]}
{"channel":"book","type":"update","data":[{"symbol":"ETH/GBP","bids":[{"price":2977.85,"qty":6.58650387}],"asks":[],"checksum":4185146818,"timestamp":"2024-06-01T17:52:51.485284Z"}]}
{"channel":"book","type":"update","data":[{"symbol":"ETH/GBP","bids":[],"asks":[{"price":2978.55,"qty":13.16996796}],"checksum":3888511257,"timestamp":"2024-06-01T17:52:51.489944Z"}]}
{"channel":"book","type":"update","data":[{"symbol":"ETH/GBP","bids":[],"asks":[{"price":2978.10,"qty":0.00000000},{"price":2980.29,"qty":0.94850883}],"checksum":4161542976,"timestamp":"2024-06-01T17:52:51.593765Z"}]}
{"channel":"book","type":"update","data":[{"symbol":"ETH/GBP","bids":[],"asks":[{"price":2978.12,"qty":6.58593128}],"checksum":1303953034,"timestamp":"2024-06-01T17:52:51.598881Z"}]}
{"channel":"book","type":"update","data":[{"symbol":"ETH/GBP","bids":[],"asks":[{"price":2978.12,"qty":0.00000000},{"price":2980.29,"qty":0.94850883}],"checksum":4161542976,"timestamp":"2024-06-01T17:52:51.725336Z"}]}
{"channel":"book","type":"update","data":[{"symbol":"ETH/GBP","bids":[],"asks":[{"price":2978.11,"qty":6.58594116}],"checksum":2040338555,"timestamp":"2024-06-01T17:52:51.730074Z"}]}
{"channel":"book","type":"update","data":[{"symbol":"ETH/GBP","bids":[{"price":2977.85,"qty":0.00000000},{"price":2974.30,"qty":0.30200000}],"asks":[],"checksum":3460834695,"timestamp":"2024-06-01T17:52:51.947594Z"}]}
{"channel":"book","type":"update","data":[{"symbol":"ETH/GBP","bids":[],"asks":[{"price":2978.11,"qty":0.00000000},{"price":2980.29,"qty":0.94850883}],"checksum":3781022547,"timestamp":"2024-06-01T17:52:51.947707Z"}]}
{"channel":"book","type":"update","data":[{"symbol":"ETH/GBP","bids":[],"asks":[{"price":2978.55,"qty":0.00000000},{"price":2980.56,"qty":2.94416492}],"checksum":3187419738,"timestamp":"2024-06-01T17:52:51.952225Z"}]}
{"channel":"book","type":"update","data":[{"symbol":"ETH/GBP","bids":[{"price":2977.40,"qty":0.00000000},{"price":2973.93,"qty":0.27474654}],"asks":[],"checksum":2889238756,"timestamp":"2024-06-01T17:52:51.952237Z"}]}
{"channel":"book","type":"update","data":[{"symbol":"ETH/GBP","bids":[{"price":2977.95,"qty":6.58627772}],"asks":[],"checksum":679873815,"timestamp":"2024-06-01T17:52:51.958665Z"}]}
{"channel":"book","type":"update","data":[{"symbol":"ETH/GBP","bids":[{"price":2977.47,"qty":13.17468129}],"asks":[],"checksum":2067989845,"timestamp":"2024-06-01T17:52:51.958783Z"}]}
{"channel":"book","type":"update","data":[{"symbol":"ETH/GBP","bids":[],"asks":[{"price":2979.12,"qty":13.16742910}],"checksum":2364104706,"timestamp":"2024-06-01T17:52:51.958816Z"}]}
{"channel":"book","type":"update","data":[{"symbol":"ETH/GBP","bids":[],"asks":[{"price":2979.12,"qty":19.75114365}],"checksum":2735608154,"timestamp":"2024-06-01T17:52:51.958856Z"}]}
{"channel":"book","type":"update","data":[{"symbol":"ETH/GBP","bids":[],"asks":[{"price":2979.12,"qty":13.16742910}],"checksum":2364104706,"timestamp":"2024-06-01T17:52:51.966110Z"}]}
{"channel":"book","type":"update","data":[{"symbol":"ETH/GBP","bids":[{"price":2977.47,"qty":0.00000000},{"price":2974.30,"qty":0.30200000}],"asks":[],"checksum":3453819173,"timestamp":"2024-06-01T17:52:51.966171Z"}]}
{"channel":"book","type":"update","data":[{"symbol":"ETH/GBP","bids":[],"asks":[{"price":2979.12,"qty":0.00000000},{"price":2980.56,"qty":2.94416492}],"checksum":679873815,"timestamp":"2024-06-01T17:52:51.966283Z"}]}
{"channel":"book","type":"update","data":[{"symbol":"ETH/GBP","bids":[{"price":2977.95,"qty":0.00000000},{"price":2973.93,"qty":0.27474654}],"asks":[],"checksum":2889238756,"timestamp":"2024-06-01T17:52:51.966425Z"}]}
{"channel":"book","type":"update","data":[{"symbol":"ETH/GBP","bids":[],"asks":[{"price":2979.13,"qty":0.00000000},{"price":2980.57,"qty":1.31610402}],"checksum":2732336698,"timestamp":"2024-06-01T17:52:51.967783Z"}]}
{"channel":"book","type":"update","data":[{"symbol":"ETH/GBP","bids":[{"price":2977.17,"qty":0.14492486}],"asks":[],"checksum":643951934,"timestamp":"2024-06-01T17:52:51.973733Z"}]}
{"channel":"book","type":"update","data":[{"symbol":"ETH/GBP","bids":[],"asks":[{"price":2980.13,"qty":0.00000000},{"price":2980.94,"qty":0.00775181}],"checksum":2565571542,"timestamp":"2024-06-01T17:52:52.049501Z"}]}
{"channel":"book","type":"update","data":[{"symbol":"ETH/GBP","bids":[],"asks":[{"price":2979.41,"qty":0.00000000},{"price":2980.95,"qty":0.22400000}],"checksum":3651961816,"timestamp":"2024-06-01T17:52:52.049715Z"}]}
{"channel":"book","type":"update","data":[{"symbol":"ETH/GBP","bids":[],"asks":[{"price":2979.16,"qty":0.00000000},{"price":2981.05,"qty":1.00000000}],"checksum":4075258900,"timestamp":"2024-06-01T17:52:52.052288Z"}]}
{"channel":"book","type":"update","data":[{"symbol":"ETH/GBP","bids":[],"asks":[{"price":2979.64,"qty":1.31651275}],"checksum":1672820516,"timestamp":"2024-06-01T17:52:52.053419Z"}]}
