{"channel":"book","type":"update","data":[{"symbol":"ETH/EUR","bids":[],"asks":[{"price":3502.62,"qty":0.00000000},{"price":3502.85,"qty":26.32123505}],"checksum":1520177608,"timestamp":"2024-06-01T17:52:30.288328Z"}]}
{"channel":"book","type":"update","data":[{"symbol":"ETH/EUR","bids":[],"asks":[{"price":3502.47,"qty":26.32411016}],"checksum":1293829894,"timestamp":"2024-06-01T17:52:30.291629Z"}]}
{"channel":"book","type":"update","data":[{"symbol":"ETH/EUR","bids":[],"asks":[{"price":3502.47,"qty":0.00000000},{"price":3502.85,"qty":26.32123505}],"checksum":1520177608,"timestamp":"2024-06-01T17:52:30.363753Z"}]}
{"channel":"book","type":"update","data":[{"symbol":"ETH/EUR","bids":[],"asks":[{"price":3502.46,"qty":26.32418383}],"checksum":4120921429,"timestamp":"2024-06-01T17:52:30.367313Z"}]}
{"channel":"book","type":"update","data":[{"symbol":"ETH/EUR","bids":[],"asks":[{"price":3502.46,"qty":0.00000000},{"price":3502.85,"qty":26.32123505}],"checksum":1520177608,"timestamp":"2024-06-01T17:52:30.413487Z"}]}
{"channel":"book","type":"update","data":[{"symbol":"ETH/EUR","bids":[],"asks":[{"price":3502.48,"qty":26.32404964}],"checksum":2735850354,"timestamp":"2024-06-01T17:52:30.417627Z"}]}
{"channel":"book","type":"update","data":[{"symbol":"ETH/EUR","bids":[],"asks":[{"price":3502.57,"qty":26.32560408}],"checksum":1632869726,"timestamp":"2024-06-01T17:52:30.417929Z"}]}
{"channel":"book","type":"update","data":[{"symbol":"ETH/EUR","bids":[],"asks":[{"price":3502.48,"qty":0.00000000},{"price":3502.85,"qty":26.32123505}],"checksum":1946225038,"timestamp":"2024-06-01T17:52:30.422534Z"}]}
{"channel":"book","type":"update","data":[{"symbol":"ETH/EUR","bids":[],"asks":[{"price":3502.50,"qty":26.32387103}],"checksum":1665897170,"timestamp":"2024-06-01T17:52:30.473613Z"}]}
{"channel":"book","type":"update","data":[{"symbol":"ETH/EUR","bids":[],"asks":[{"price":3502.45,"qty":0.00220000}],"checksum":3138991915,"timestamp":"2024-06-01T17:52:30.523076Z"}]}
{"channel":"book","type":"update","data":[{"symbol":"ETH/EUR","bids":[],"asks":[{"price":3502.50,"qty":0.00000000},{"price":3502.85,"qty":26.32123505}],"checksum":2891164791,"timestamp":"2024-06-01T17:52:30.524208Z"}]}
{"channel":"book","type":"update","data":[{"symbol":"ETH/EUR","bids":[],"asks":[{"price":3502.49,"qty":26.32396049}],"checksum":3239673393,"timestamp":"2024-06-01T17:52:30.527902Z"}]}
{"channel":"book","type":"update","data":[{"symbol":"ETH/EUR","bids":[],"asks":[{"price":3502.38,"qty":0.00000000},{"price":3502.85,"qty":26.32123505}],"checksum":3215135021,"timestamp":"2024-06-01T17:52:30.764587Z"}]}
{"channel":"book","type":"update","data":[{"symbol":"ETH/EUR","bids":[],"asks":[{"price":3502.49,"qty":0.00000000},{"price":3502.87,"qty":0.08557000}],"checksum":1301037559,"timestamp":"2024-06-01T17:52:30.768783Z"}]}
{"channel":"book","type":"update","data":[{"symbol":"ETH/EUR","bids":[],"asks":[{"price":3502.85,"qty":0.00000000},{"price":3503.09,"qty":0.00220000}],"checksum":4045655392,"timestamp":"2024-06-01T17:52:30.769078Z"}]}
{"channel":"book","type":"update","data":[{"symbol":"ETH/EUR","bids":[],"asks":[{"price":3502.57,"qty":0.00220000}],"checksum":4086222790,"timestamp":"2024-06-01T17:52:30.781347Z"}]}
{"channel":"book","type":"update","data":[{"symbol":"ETH/EUR","bids":[],"asks":[{"price":3502.72,"qty":0.00000000},{"price":3503.20,"qty":0.84644082}],"checksum":1890769657,"timestamp":"2024-06-01T17:52:30.781477Z"}]}
{"channel":"book","type":"update","data":[{"symbol":"ETH/EUR","bids":[],"asks":[{"price":3502.91,"qty":26.32081358}],"checksum":1819081662,"timestamp":"2024-06-01T17:52:30.787887Z"}]}
{"channel":"book","type":"update","data":[{"symbol":"ETH/EUR","bids":[],"asks":[{"price":3503.02,"qty":26.31998404}],"checksum":2967166904,"timestamp":"2024-06-01T17:52:30.787900Z"}]}
{"channel":"book","type":"update","data":[{"symbol":"ETH/EUR","bids":[{"price":3501.85,"qty":64.08033714}],"asks":[],"checksum":909718771,"timestamp":"2024-06-01T17:52:30.792477Z"}]}
{"channel":"book","type":"update","data":[{"symbol":"ETH/EUR","bids":[],"asks":[{"price":3501.86,"qty":0.00000000},{"price":3503.09,"qty":0.00220000}],"checksum":3905901881,"timestamp":"2024-06-01T17:52:30.796280Z"}]}
{"channel":"book","type":"update","data":[{"symbol":"ETH/EUR","bids":[{"price":3501.85,"qty":62.48033714}],"asks":[],"checksum":3926058983,"timestamp":"2024-06-01T17:52:30.799700Z"}]}
{"channel":"book","type":"update","data":[{"symbol":"ETH/EUR","bids":[{"price":3501.91,"qty":1.60000000}],"asks":[],"checksum":2431308837,"timestamp":"2024-06-01T17:52:30.799941Z"}]}
{"channel":"book","type":"update","data":[{"symbol":"ETH/EUR","bids":[{"price":3501.86,"qty":0.11843927}],"asks":[],"checksum":1970470956,"timestamp":"2024-06-01T17:52:30.801478Z"}]}
{"channel":"book","type":"update","data":[{"symbol":"ETH/EUR","bids":[],"asks":[{"price":3502.91,"qty":0.00000000},{"price":3503.16,"qty":26.31891410}],"checksum":4220248201,"timestamp":"2024-06-01T17:52:30.801517Z"}]}
{"channel":"book","type":"update","data":[{"symbol":"ETH/EUR","bids":[],"asks":[{"price":3503.02,"qty":0.00000000},{"price":3503.20,"qty":0.84644082}],"checksum":1166590211,"timestamp":"2024-06-01T17:52:30.801542Z"}]}
{"channel":"book","type":"update","data":[{"symbol":"ETH/EUR","bids":[{"price":3501.85,"qty":36.15158978}],"asks":[],"checksum":20792782,"timestamp":"2024-06-01T17:52:30.803371Z"}]}
{"channel":"book","type":"update","data":[{"symbol":"ETH/EUR","bids":[{"price":3501.85,"qty":9.82284242}],"asks":[],"checksum":4283025689,"timestamp":"2024-06-01T17:52:30.803424Z"}]}
{"channel":"book","type":"update","data":[{"symbol":"ETH/EUR","bids":[{"price":3501.92,"qty":0.11843942}],"asks":[],"checksum":2777313381,"timestamp":"2024-06-01T17:52:30.805275Z"}]}
{"channel":"book","type":"update","data":[{"symbol":"ETH/EUR","bids":[{"price":3501.86,"qty":0.00000000},{"price":3501.23,"qty":2.19988553}],"asks":[],"checksum":2379839856,"timestamp":"2024-06-01T17:52:30.805929Z"}]}
{"channel":"book","type":"update","data":[{"symbol":"ETH/EUR","bids":[{"price":3501.43,"qty":0.72912968}],"asks":[],"checksum":4188900474,"timestamp":"2024-06-01T17:52:30.806439Z"}]}
{"channel":"book","type":"update","data":[{"symbol":"ETH/EUR","bids":[{"price":3501.85,"qty":3.24000000}],"asks":[],"checksum":3417373602,"timestamp":"2024-06-01T17:52:30.819900Z"}]}
{"channel":"book","type":"update","data":[{"symbol":"ETH/EUR","bids":[],"asks":[{"price":3502.88,"qty":26.32101172}],"checksum":3698944249,"timestamp":"2024-06-01T17:52:30.820224Z"}]}
{"channel":"book","type":"update","data":[{"symbol":"ETH/EUR","bids":[],"asks":[{"price":3503.16,"qty":0.00000000},{"price":3503.20,"qty":0.84644082}],"checksum":2697946368,"timestamp":"2024-06-01T17:52:30.824305Z"}]}
{"channel":"book","type":"update","data":[{"symbol":"ETH/EUR","bids":[{"price":3501.92,"qty":0.00000000},{"price":3501.23,"qty":2.19988553}],"asks":[],"checksum":3901296783,"timestamp":"2024-06-01T17:52:30.840365Z"}]}
{"channel":"book","type":"update","data":[{"symbol":"ETH/EUR","bids":[],"asks":[{"price":3502.80,"qty":26.32166431}],"checksum":3470979191,"timestamp":"2024-06-01T17:52:30.842459Z"}]}
{"channel":"book","type":"update","data":[{"symbol":"ETH/EUR","bids":[{"price":3501.65,"qty":0.00000000},{"price":3501.13,"qty":6.00000000},{"price":3501.92,"qty":0.02856390}],"asks":[],"checksum":3378105959,"timestamp":"2024-06-01T17:52:30.846614Z"}]}
{"channel":"book","type":"update","data":[{"symbol":"ETH/EUR","bids":[],"asks":[{"price":3502.34,"qty":0.00000000},{"price":3503.21,"qty":0.00220000},{"price":3503.15,"qty":0.00759494}],"checksum":3797943125,"timestamp":"2024-06-01T17:52:30.862080Z"}]}
{"channel":"book","type":"update","data":[{"symbol":"ETH/EUR","bids":[],"asks":[{"price":3502.80,"qty":0.00000000},{"price":3503.21,"qty":0.00220000}],"checksum":320387193,"timestamp":"2024-06-01T17:52:30.870477Z"}]}
{"channel":"book","type":"update","data":[{"symbol":"ETH/EUR","bids":[{"price":3501.23,"qty":0.84644082}],"asks":[],"checksum":3732611048,"timestamp":"2024-06-01T17:52:30.873203Z"}]}
{"channel":"book","type":"update","data":[{"symbol":"ETH/EUR","bids":[{"price":3501.86,"qty":2.00000000}],"asks":[],"checksum":3681428133,"timestamp":"2024-06-01T17:52:30.874219Z"}]}
{"channel":"book","type":"update","data":[{"symbol":"ETH/EUR","bids":[],"asks":[{"price":3502.78,"qty":26.32178446}],"checksum":2007464329,"timestamp":"2024-06-01T17:52:30.895531Z"}]}
{"channel":"book","type":"update","data":[{"symbol":"ETH/EUR","bids":[],"asks":[{"price":3502.78,"qty":0.00000000},{"price":3503.21,"qty":0.00220000}],"checksum":3681428133,"timestamp":"2024-06-01T17:52:30.917719Z"}]}
{"channel":"book","type":"update","data":[{"symbol":"ETH/EUR","bids":[],"asks":[{"price":3502.87,"qty":0.00000000},{"price":3503.25,"qty":0.00220000}],"checksum":2142111967,"timestamp":"2024-06-01T17:52:30.933768Z"}]}
{"channel":"book","type":"update","data":[{"symbol":"ETH/EUR","bids":[],"asks":[{"price":3502.88,"qty":0.00000000},{"price":3503.33,"qty":0.65056936}],"checksum":1120328013,"timestamp":"2024-06-01T17:52:30.938501Z"}]}
{"channel":"book","type":"update","data":[{"symbol":"ETH/EUR","bids":[],"asks":[{"price":3502.35,"qty":0.00000000},{"price":3503.34,"qty":0.00421266}],"checksum":232040347,"timestamp":"2024-06-01T17:52:30.941047Z"}]}
{"channel":"book","type":"update","data":[{"symbol":"ETH/EUR","bids":[],"asks":[{"price":3503.07,"qty":1.60000000}],"checksum":447593343,"timestamp":"2024-06-01T17:52:30.943913Z"}]}
{"channel":"book","type":"update","data":[{"symbol":"ETH/EUR","bids":[],"asks":[{"price":3502.75,"qty":26.32202652}],"checksum":1017513214,"timestamp":"2024-06-01T17:52:30.949190Z"}]}
{"channel":"book","type":"update","data":[{"symbol":"ETH/EUR","bids":[{"price":3501.86,"qty":2.32778701}],"asks":[],"checksum":1319389192,"timestamp":"2024-06-01T17:52:30.960145Z"}]}
{"channel":"book","type":"update","data":[{"symbol":"ETH/EUR","bids":[{"price":3501.86,"qty":2.67199531}],"asks":[],"checksum":2834318447,"timestamp":"2024-06-01T17:52:30.971757Z"}]}
{"channel":"book","type":"update","data":[{"symbol":"ETH/EUR","bids":[{"price":3501.43,"qty":0.00000000},{"price":3501.23,"qty":0.84644082}],"asks":[],"checksum":712146426,"timestamp":"2024-06-01T17:52:30.988529Z"}]}
{"channel":"book","type":"update","data":[{"symbol":"ETH/EUR","bids":[{"price":3501.82,"qty":15.80244833}],"asks":[],"checksum":3441671436,"timestamp":"2024-06-01T17:52:30.988537Z"}]}
{"channel":"book","type":"update","data":[{"symbol":"ETH/EUR","bids":[{"price":3501.86,"qty":0.67199531}],"asks":[],"checksum":3134997218,"timestamp":"2024-06-01T17:52:30.989304Z"}]}
{"channel":"book","type":"update","data":[{"symbol":"ETH/EUR","bids":[{"price":3501.93,"qty":1.35317417}],"asks":[],"checksum":2630086340,"timestamp":"2024-06-01T17:52:30.991211Z"}]}
{"channel":"book","type":"update","data":[{"symbol":"ETH/EUR","bids":[],"asks":[{"price":3503.18,"qty":0.72912968}],"checksum":3034167256,"timestamp":"2024-06-01T17:52:30.993608Z"}]}
{"channel":"book","type":"update","data":[{"symbol":"ETH/EUR","bids":[],"asks":[{"price":3502.75,"qty":0.00000000},{"price":3503.25,"qty":0.00220000}],"checksum":2877670174,"timestamp":"2024-06-01T17:52:30.993683Z"}]}
{"channel":"book","type":"update","data":[{"symbol":"ETH/EUR","bids":[{"price":3501.54,"qty":0.00000000},{"price":3501.24,"qty":1.31694353},{"price":3501.92,"qty":0.11414190}],"asks":[],"checksum":2464975454,"timestamp":"2024-06-01T17:52:30.994055Z"}]}
{"channel":"book","type":"update","data":[{"symbol":"ETH/EUR","bids":[{"price":3501.45,"qty":0.00000000},{"price":3500.86,"qty":0.84644082}],"asks":[],"checksum":3724525749,"timestamp":"2024-06-01T17:52:30.996480Z"}]}
{"channel":"book","type":"update","data":[{"symbol":"ETH/EUR","bids":[{"price":3501.86,"qty":5.56199531}],"asks":[],"checksum":904608499,"timestamp":"2024-06-01T17:52:30.998355Z"}]}
{"channel":"book","type":"update","data":[{"symbol":"ETH/EUR","bids":[{"price":3501.82,"qty":0.00000000},{"price":3500.52,"qty":0.30948565}],"asks":[],"checksum":2790132764,"timestamp":"2024-06-01T17:52:31.000682Z"}]}
{"channel":"book","type":"update","data":[{"symbol":"ETH/EUR","bids":[{"price":3501.24,"qty":0.00000000},{"price":3500.48,"qty":1.31708923}],"asks":[],"checksum":1440336765,"timestamp":"2024-06-01T17:52:31.001545Z"}]}
{"channel":"book","type":"update","data":[{"symbol":"ETH/EUR","bids":[{"price":3500.63,"qty":7.26877150}],"asks":[],"checksum":1395998883,"timestamp":"2024-06-01T17:52:31.006198Z"}]}
{"channel":"book","type":"update","data":[{"symbol":"ETH/EUR","bids":[],"asks":[{"price":3502.24,"qty":26.32586302}],"checksum":2145681034,"timestamp":"2024-06-01T17:52:31.006292Z"}]}
{"channel":"book","type":"update","data":[{"symbol":"ETH/EUR","bids":[{"price":3501.93,"qty":0.00000000},{"price":3500.48,"qty":1.31708923}],"asks":[],"checksum":1652921155,"timestamp":"2024-06-01T17:52:31.006614Z"}]}
{"channel":"book","type":"update","data":[{"symbol":"ETH/EUR","bids":[{"price":3500.63,"qty":0.00000000},{"price":3500.32,"qty":3.58840000}],"asks":[],"checksum":2116648247,"timestamp":"2024-06-01T17:52:31.008831Z"}]}
{"channel":"book","type":"update","data":[{"symbol":"ETH/EUR","bids":[],"asks":[{"price":3502.23,"qty":0.65056936}],"checksum":2626815946,"timestamp":"2024-06-01T17:52:31.011995Z"}]}
{"channel":"book","type":"update","data":[{"symbol":"ETH/EUR","bids":[],"asks":[{"price":3501.93,"qty":6.58762397}],"checksum":2668975049,"timestamp":"2024-06-01T17:52:31.012852Z"}]}
{"channel":"book","type":"update","data":[{"symbol":"ETH/EUR","bids":[{"price":3501.91,"qty":0.00000000},{"price":3500.10,"qty":0.67500000}],"asks":[],"checksum":952774315,"timestamp":"2024-06-01T17:52:31.018530Z"}]}
{"channel":"book","type":"update","data":[{"symbol":"ETH/EUR","bids":[{"price":3501.64,"qty":0.00000000},{"price":3500.04,"qty":0.52710000}],"asks":[],"checksum":115216978,"timestamp":"2024-06-01T17:52:31.021272Z"}]}
{"channel":"book","type":"update","data":[{"symbol":"ETH/EUR","bids":[{"price":3500.86,"qty":0.00000000},{"price":3499.79,"qty":10.43976375}],"asks":[],"checksum":2606223156,"timestamp":"2024-06-01T17:52:31.023436Z"}]}
{"channel":"book","type":"update","data":[{"symbol":"ETH/EUR","bids":[{"price":3500.48,"qty":0.00000000},{"price":3499.73,"qty":3.95300000}],"asks":[],"checksum":1060005480,"timestamp":"2024-06-01T17:52:31.024701Z"}]}
{"channel":"book","type":"update","data":[{"symbol":"ETH/EUR","bids":[],"asks":[{"price":3502.24,"qty":0.00000000},{"price":3503.18,"qty":0.72912968}],"checksum":4244144441,"timestamp":"2024-06-01T17:52:31.024937Z"}]}
{"channel":"book","type":"update","data":[{"symbol":"ETH/EUR","bids":[{"price":3500.04,"qty":0.00000000},{"price":3499.37,"qty":1.05333347}],"asks":[],"checksum":3827275825,"timestamp":"2024-06-01T17:52:31.025508Z"}]}
{"channel":"book","type":"update","data":[{"symbol":"ETH/EUR","bids":[],"asks":[{"price":3502.88,"qty":0.84644082}],"checksum":3349803800,"timestamp":"2024-06-01T17:52:31.026719Z"}]}
{"channel":"book","type":"update","data":[{"symbol":"ETH/EUR","bids":[{"price":3499.73,"qty":0.00000000},{"price":3499.31,"qty":66.17015710}],"asks":[],"checksum":3076877186,"timestamp":"2024-06-01T17:52:31.027049Z"}]}
{"channel":"book","type":"update","data":[{"symbol":"ETH/EUR","bids":[{"price":3500.40,"qty":7.26924911}],"asks":[],"checksum":1275384572,"timestamp":"2024-06-01T17:52:31.027617Z"}]}
{"channel":"book","type":"update","data":[{"symbol":"ETH/EUR","bids":[{"price":3500.40,"qty":0.00000000},{"price":3499.31,"qty":66.17015710}],"asks":[],"checksum":3076877186,"timestamp":"2024-06-01T17:52:31.027683Z"}]}
{"channel":"book","type":"update","data":[{"symbol":"ETH/EUR","bids":[],"asks":[{"price":3502.14,"qty":1.06800000}],"checksum":1064720577,"timestamp":"2024-06-01T17:52:31.027837Z"}]}
{"channel":"book","type":"update","data":[{"symbol":"ETH/EUR","bids":[],"asks":[{"price":3502.23,"qty":2.25056936}],"checksum":1050333493,"timestamp":"2024-06-01T17:52:31.028859Z"}]}
{"channel":"book","type":"update","data":[{"symbol":"ETH/EUR","bids":[],"asks":[{"price":3503.07,"qty":0.00000000},{"price":3503.15,"qty":0.00759494}],"checksum":3144751383,"timestamp":"2024-06-01T17:52:31.029114Z"}]}
{"channel":"book","type":"update","data":[{"symbol":"ETH/EUR","bids":[{"price":3499.61,"qty":0.52710000}],"asks":[],"checksum":1978113385,"timestamp":"2024-06-01T17:52:31.030891Z"}]}
{"channel":"book","type":"update","data":[{"symbol":"ETH/EUR","bids":[{"price":3501.85,"qty":0.00000000},{"price":3499.31,"qty":66.17015710}],"asks":[],"checksum":1839782189,"timestamp":"2024-06-01T17:52:31.032523Z"}]}
{"channel":"book","type":"update","data":[{"symbol":"ETH/EUR","bids":[{"price":3500.32,"qty":0.00000000},{"price":3499.30,"qty":0.68200000},{"price":3499.80,"qty":3.58840000}],"asks":[],"checksum":4115157013,"timestamp":"2024-06-01T17:52:31.038277Z"}]}
{"channel":"book","type":"update","data":[{"symbol":"ETH/EUR","bids":[{"price":3500.34,"qty":0.13122280}],"asks":[],"checksum":2482192136,"timestamp":"2024-06-01T17:52:31.041311Z"}]}
{"channel":"book","type":"update","data":[{"symbol":"ETH/EUR","bids":[],"asks":[{"price":3501.93,"qty":32.91576986}],"checksum":50932732,"timestamp":"2024-06-01T17:52:31.042572Z"}]}
{"channel":"book","type":"update","data":[{"symbol":"ETH/EUR","bids":[{"price":3501.31,"qty":1.60000000}],"asks":[],"checksum":627566627,"timestamp":"2024-06-01T17:52:31.051101Z"}]}
{"channel":"book","type":"update","data":[{"symbol":"ETH/EUR","bids":[{"price":3500.10,"qty":0.00000000},{"price":3499.37,"qty":1.05333347}],"asks":[],"checksum":2612095280,"timestamp":"2024-06-01T17:52:31.053127Z"}]}
{"channel":"book","type":"update","data":[{"symbol":"ETH/EUR","bids":[],"asks":[{"price":3503.03,"qty":1.21518881}],"checksum":3989438912,"timestamp":"2024-06-01T17:52:31.053686Z"}]}
{"channel":"book","type":"update","data":[{"symbol":"ETH/EUR","bids":[],"asks":[{"price":3502.93,"qty":6.00000000}],"checksum":4214092898,"timestamp":"2024-06-01T17:52:31.057891Z"}]}
{"channel":"book","type":"update","data":[{"symbol":"ETH/EUR","bids":[],"asks":[{"price":3501.93,"qty":59.24391575}],"checksum":1418094850,"timestamp":"2024-06-01T17:52:31.061073Z"}]}
{"channel":"book","type":"update","data":[{"symbol":"ETH/EUR","bids":[{"price":3501.31,"qty":0.00000000},{"price":3499.31,"qty":66.17015710}],"asks":[],"checksum":3024554042,"timestamp":"2024-06-01T17:52:31.064376Z"}]}
{"channel":"book","type":"update","data":[{"symbol":"ETH/EUR","bids":[],"asks":[{"price":3501.93,"qty":59.97304543}],"checksum":2780739258,"timestamp":"2024-06-01T17:52:31.068197Z"}]}
{"channel":"book","type":"update","data":[{"symbol":"ETH/EUR","bids":[{"price":3499.79,"qty":0.00000000},{"price":3499.30,"qty":0.68200000}],"asks":[],"checksum":1480638522,"timestamp":"2024-06-01T17:52:31.071138Z"}]}
{"channel":"book","type":"update","data":[{"symbol":"ETH/EUR","bids":[{"price":3501.65,"qty":4.00000000}],"asks":[],"checksum":2910590248,"timestamp":"2024-06-01T17:52:31.071900Z"}]}
{"channel":"book","type":"update","data":[{"symbol":"ETH/EUR","bids":[],"asks":[{"price":3502.61,"qty":0.77800000}],"checksum":20916097,"timestamp":"2024-06-01T17:52:31.077945Z"}]}
{"channel":"book","type":"update","data":[{"symbol":"ETH/EUR","bids":[],"asks":[{"price":3501.93,"qty":60.82803617}],"checksum":163326924,"timestamp":"2024-06-01T17:52:31.083790Z"}]}
{"channel":"book","type":"update","data":[{"symbol":"ETH/EUR","bids":[{"price":3499.80,"qty":0.00000000},{"price":3498.52,"qty":0.85500000},{"price":3499.38,"qty":3.58840000}],"asks":[],"checksum":31148369,"timestamp":"2024-06-01T17:52:31.088333Z"}]}
{"channel":"book","type":"update","data":[{"symbol":"ETH/EUR","bids":[{"price":3499.61,"qty":0.00000000},{"price":3498.73,"qty":10.43976375}],"asks":[],"checksum":240689157,"timestamp":"2024-06-01T17:52:31.088712Z"}]}
{"channel":"book","type":"update","data":[{"symbol":"ETH/EUR","bids":[{"price":3500.52,"qty":0.00000000},{"price":3498.52,"qty":0.85500000}],"asks":[],"checksum":3922501624,"timestamp":"2024-06-01T17:52:31.090235Z"}]}
{"channel":"book","type":"update","data":[{"symbol":"ETH/EUR","bids":[],"asks":[{"price":3501.93,"qty":87.15618206}],"checksum":59622373,"timestamp":"2024-06-01T17:52:31.090459Z"}]}
{"channel":"book","type":"update","data":[{"symbol":"ETH/EUR","bids":[{"price":3501.92,"qty":0.08557800},{"price":3501.87,"qty":0.02857045}],"asks":[],"checksum":3543596077,"timestamp":"2024-06-01T17:52:31.093986Z"}]}
{"channel":"book","type":"update","data":[{"symbol":"ETH/EUR","bids":[{"price":3500.34,"qty":0.00000000},{"price":3498.52,"qty":0.85500000}],"asks":[],"checksum":1911375367,"timestamp":"2024-06-01T17:52:31.096588Z"}]}
{"channel":"book","type":"update","data":[{"symbol":"ETH/EUR","bids":[],"asks":[{"price":3502.29,"qty":0.84644082}],"checksum":1584990399,"timestamp":"2024-06-01T17:52:31.107745Z"}]}
{"channel":"book","type":"update","data":[{"symbol":"ETH/EUR","bids":[{"price":3500.15,"qty":4.07877279}],"asks":[],"checksum":3554148286,"timestamp":"2024-06-01T17:52:31.119460Z"}]}
{"channel":"book","type":"update","data":[{"symbol":"ETH/EUR","bids":[{"price":3501.86,"qty":5.23420830}],"asks":[],"checksum":439456869,"timestamp":"2024-06-01T17:52:31.124976Z"}]}
{"channel":"book","type":"update","data":[{"symbol":"ETH/EUR","bids":[{"price":3501.27,"qty":0.00000000},{"price":3498.52,"qty":0.85500000}],"asks":[],"checksum":850902636,"timestamp":"2024-06-01T17:52:31.128381Z"}]}
{"channel":"book","type":"update","data":[{"symbol":"ETH/EUR","bids":[{"price":3500.15,"qty":0.00000000},{"price":3498.45,"qty":3.01305282}],"asks":[],"checksum":3285012324,"timestamp":"2024-06-01T17:52:31.129666Z"}]}
{"channel":"book","type":"update","data":[{"symbol":"ETH/EUR","bids":[{"price":3499.97,"qty":4.78132277}],"asks":[],"checksum":1049088369,"timestamp":"2024-06-01T17:52:31.137079Z"}]}
{"channel":"book","type":"update","data":[{"symbol":"ETH/EUR","bids":[{"price":3499.66,"qty":1.31722109}],"asks":[],"checksum":1127456598,"timestamp":"2024-06-01T17:52:31.140801Z"}]}
{"channel":"book","type":"update","data":[{"symbol":"ETH/EUR","bids":[{"price":3499.48,"qty":1.31722109}],"asks":[],"checksum":2766976881,"timestamp":"2024-06-01T17:52:31.141572Z"}]}
{"channel":"book","type":"update","data":[{"symbol":"ETH/EUR","bids":[],"asks":[{"price":3502.88,"qty":0.00000000},{"price":3502.93,"qty":6.00000000}],"checksum":4154365252,"timestamp":"2024-06-01T17:52:31.142054Z"}]}
{"channel":"book","type":"update","data":[{"symbol":"ETH/EUR","bids":[],"asks":[{"price":3501.93,"qty":88.00262288}],"checksum":3921754340,"timestamp":"2024-06-01T17:52:31.142285Z"}]}
{"channel":"book","type":"update","data":[{"symbol":"ETH/EUR","bids":[{"price":3499.61,"qty":1.31722109}],"asks":[],"checksum":4153561399,"timestamp":"2024-06-01T17:52:31.143083Z"}]}
{"channel":"book","type":"update","data":[{"symbol":"ETH/EUR","bids":[{"price":3499.43,"qty":1.31722109}],"asks":[],"checksum":3864014361,"timestamp":"2024-06-01T17:52:31.144544Z"}]}
{"channel":"book","type":"update","data":[{"symbol":"ETH/EUR","bids":[{"price":3501.86,"qty":4.89000000}],"asks":[],"checksum":1711406887,"timestamp":"2024-06-01T17:52:31.146807Z"}]}
{"channel":"book","type":"update","data":[{"symbol":"ETH/EUR","bids":[],"asks":[{"price":3501.93,"qty":89.48316169}],"checksum":1827088303,"timestamp":"2024-06-01T17:52:31.152594Z"}]}
{"channel":"book","type":"update","data":[{"symbol":"ETH/EUR","bids":[],"asks":[{"price":3502.56,"qty":6.00000000}],"checksum":2157140399,"timestamp":"2024-06-01T17:52:31.154908Z"}]}
{"channel":"book","type":"update","data":[{"symbol":"ETH/EUR","bids":[{"price":3499.66,"qty":0.00000000},{"price":3499.37,"qty":1.05333347}],"asks":[],"checksum":1184412377,"timestamp":"2024-06-01T17:52:31.161662Z"}]}
{"channel":"book","type":"update","data":[{"symbol":"ETH/EUR","bids":[{"price":3499.61,"qty":0.00000000},{"price":3499.31,"qty":66.17015710}],"asks":[],"checksum":1353302580,"timestamp":"2024-06-01T17:52:31.162111Z"}]}
{"channel":"book","type":"update","data":[{"symbol":"ETH/EUR","bids":[],"asks":[{"price":3502.29,"qty":0.00000000},{"price":3502.93,"qty":6.00000000}],"checksum":2690679045,"timestamp":"2024-06-01T17:52:31.177281Z"}]}
{"channel":"book","type":"update","data":[{"symbol":"ETH/EUR","bids":[{"price":3501.87,"qty":0.00000000},{"price":3498.73,"qty":10.43976375},{"price":3499.39,"qty":0.02859069}],"asks":[],"checksum":3045945112,"timestamp":"2024-06-01T17:52:31.181716Z"}]}
{"channel":"book","type":"update","data":[{"symbol":"ETH/EUR","bids":[],"asks":[{"price":3501.93,"qty":88.62817095}],"checksum":1515176677,"timestamp":"2024-06-01T17:52:31.185455Z"}]}
{"channel":"book","type":"update","data":[{"symbol":"ETH/EUR","bids":[],"asks":[{"price":3502.93,"qty":0.00000000},{"price":3503.09,"qty":0.00220000}],"checksum":4253866170,"timestamp":"2024-06-01T17:52:31.193837Z"}]}
{"channel":"book","type":"update","data":[{"symbol":"ETH/EUR","bids":[{"price":3499.48,"qty":0.00000000},{"price":3498.73,"qty":10.43976375}],"asks":[],"checksum":2793651024,"timestamp":"2024-06-01T17:52:31.207745Z"}]}
{"channel":"book","type":"update","data":[{"symbol":"ETH/EUR","bids":[{"price":3499.97,"qty":0.00000000},{"price":3498.52,"qty":0.85500000}],"asks":[],"checksum":2909576712,"timestamp":"2024-06-01T17:52:31.208109Z"}]}
{"channel":"book","type":"update","data":[{"symbol":"ETH/EUR","bids":[{"price":3499.43,"qty":0.00000000},{"price":3498.45,"qty":3.01305282}],"asks":[],"checksum":1604313875,"timestamp":"2024-06-01T17:52:31.210438Z"}]}
{"channel":"book","type":"update","data":[{"symbol":"ETH/EUR","bids":[],"asks":[{"price":3501.93,"qty":94.62817095}],"checksum":1573658504,"timestamp":"2024-06-01T17:52:31.214445Z"}]}
{"channel":"book","type":"update","data":[{"symbol":"ETH/EUR","bids":[{"price":3499.23,"qty":5.13672894}],"asks":[],"checksum":1650585236,"timestamp":"2024-06-01T17:52:31.225238Z"}]}
{"channel":"book","type":"update","data":[{"symbol":"ETH/EUR","bids":[{"price":3499.95,"qty":26.34296933}],"asks":[],"checksum":605091481,"timestamp":"2024-06-01T17:52:31.234852Z"}]}
{"channel":"book","type":"update","data":[{"symbol":"ETH/EUR","bids":[{"price":3499.81,"qty":26.34405701}],"asks":[],"checksum":3249905678,"timestamp":"2024-06-01T17:52:31.235013Z"}]}
{"channel":"book","type":"update","data":[{"symbol":"ETH/EUR","bids":[{"price":3499.38,"qty":0.00000000},{"price":3498.73,"qty":10.43976375},{"price":3499.96,"qty":3.58840000}],"asks":[],"checksum":1928558252,"timestamp":"2024-06-01T17:52:31.246539Z"}]}
{"channel":"book","type":"update","data":[{"symbol":"ETH/EUR","bids":[],"asks":[{"price":3501.93,"qty":93.14763214}],"checksum":769699916,"timestamp":"2024-06-01T17:52:31.252534Z"}]}
{"channel":"book","type":"update","data":[{"symbol":"ETH/EUR","bids":[],"asks":[{"price":3502.89,"qty":0.73171449}],"checksum":509465842,"timestamp":"2024-06-01T17:52:31.252749Z"}]}
{"channel":"book","type":"update","data":[{"symbol":"ETH/EUR","bids":[],"asks":[{"price":3502.07,"qty":26.32709339}],"checksum":2125013783,"timestamp":"2024-06-01T17:52:31.253839Z"}]}
{"channel":"book","type":"update","data":[{"symbol":"ETH/EUR","bids":[{"price":3499.95,"qty":0.00000000},{"price":3498.73,"qty":10.43976375}],"asks":[],"checksum":2355479174,"timestamp":"2024-06-01T17:52:31.254243Z"}]}
{"channel":"book","type":"update","data":[{"symbol":"ETH/EUR","bids":[{"price":3499.81,"qty":0.00000000},{"price":3498.52,"qty":0.85500000}],"asks":[],"checksum":1034125733,"timestamp":"2024-06-01T17:52:31.266747Z"}]}
{"channel":"book","type":"update","data":[{"symbol":"ETH/EUR","bids":[],"asks":[{"price":3502.56,"qty":0.00000000},{"price":3502.89,"qty":0.73171449}],"checksum":1010227524,"timestamp":"2024-06-01T17:52:31.267621Z"}]}
{"channel":"book","type":"update","data":[{"symbol":"ETH/EUR","bids":[],"asks":[{"price":3502.07,"qty":27.32709339}],"checksum":4194570825,"timestamp":"2024-06-01T17:52:31.276705Z"}]}
{"channel":"book","type":"update","data":[{"symbol":"ETH/EUR","bids":[{"price":3499.96,"qty":0.00000000},{"price":3498.45,"qty":3.01305282},{"price":3499.38,"qty":3.58840000}],"asks":[],"checksum":2293731513,"timestamp":"2024-06-01T17:52:31.277216Z"}]}
{"channel":"book","type":"update","data":[{"symbol":"ETH/EUR","bids":[],"asks":[{"price":3502.23,"qty":0.65056936}],"checksum":425469529,"timestamp":"2024-06-01T17:52:31.277585Z"}]}
{"channel":"book","type":"update","data":[{"symbol":"ETH/EUR","bids":[],"asks":[{"price":3501.93,"qty":94.74763214}],"checksum":2519781698,"timestamp":"2024-06-01T17:52:31.277994Z"}]}
{"channel":"book","type":"update","data":[{"symbol":"ETH/EUR","bids":[],"asks":[{"price":3502.06,"qty":1.00000000}],"checksum":144606688,"timestamp":"2024-06-01T17:52:31.294867Z"}]}
{"channel":"book","type":"update","data":[{"symbol":"ETH/EUR","bids":[{"price":3499.37,"qty":0.00000000},{"price":3498.45,"qty":3.01305282}],"asks":[],"checksum":2022047475,"timestamp":"2024-06-01T17:52:31.298857Z"}]}
{"channel":"book","type":"update","data":[{"symbol":"ETH/EUR","bids":[{"price":3499.77,"qty":26.34435454}],"asks":[],"checksum":722196809,"timestamp":"2024-06-01T17:52:31.302813Z"}]}
{"channel":"book","type":"update","data":[{"symbol":"ETH/EUR","bids":[{"price":3501.65,"qty":0.00000000},{"price":3498.45,"qty":3.01305282}],"asks":[],"checksum":1218136640,"timestamp":"2024-06-01T17:52:31.304862Z"}]}
{"channel":"book","type":"update","data":[{"symbol":"ETH/EUR","bids":[{"price":3499.38,"qty":0.00000000},{"price":3498.26,"qty":3.94900000},{"price":3499.78,"qty":3.58840000}],"asks":[],"checksum":777339697,"timestamp":"2024-06-01T17:52:31.306846Z"}]}
{"channel":"book","type":"update","data":[{"symbol":"ETH/EUR","bids":[],"asks":[{"price":3501.93,"qty":98.70063214}],"checksum":2776683230,"timestamp":"2024-06-01T17:52:31.307342Z"}]}
{"channel":"book","type":"update","data":[{"symbol":"ETH/EUR","bids":[{"price":3499.77,"qty":0.00000000},{"price":3498.26,"qty":3.94900000}],"asks":[],"checksum":2059390817,"timestamp":"2024-06-01T17:52:31.307591Z"}]}
{"channel":"book","type":"update","data":[{"symbol":"ETH/EUR","bids":[{"price":3499.83,"qty":1.60000000}],"asks":[],"checksum":2992898040,"timestamp":"2024-06-01T17:52:31.312720Z"}]}
{"channel":"book","type":"update","data":[{"symbol":"ETH/EUR","bids":[],"asks":[{"price":3501.93,"qty":98.79063214}],"checksum":3316415600,"timestamp":"2024-06-01T17:52:31.335306Z"}]}
{"channel":"book","type":"update","data":[{"symbol":"ETH/EUR","bids":[{"price":3499.78,"qty":0.00000000},{"price":3498.26,"qty":3.94900000},{"price":3499.32,"qty":3.58840000}],"asks":[],"checksum":1066248957,"timestamp":"2024-06-01T17:52:31.339657Z"}]}
{"channel":"book","type":"update","data":[{"symbol":"ETH/EUR","bids":[{"price":3499.83,"qty":0.00000000},{"price":3498.26,"qty":3.94900000}],"asks":[],"checksum":588330386,"timestamp":"2024-06-01T17:52:31.346015Z"}]}
{"channel":"book","type":"update","data":[{"symbol":"ETH/EUR","bids":[{"price":3499.45,"qty":1.60000000}],"asks":[],"checksum":1122799682,"timestamp":"2024-06-01T17:52:31.346469Z"}]}
{"channel":"book","type":"update","data":[{"symbol":"ETH/EUR","bids":[{"price":3499.77,"qty":26.34432743}],"asks":[],"checksum":1842111527,"timestamp":"2024-06-01T17:52:31.362396Z"}]}
{"channel":"book","type":"update","data":[{"symbol":"ETH/EUR","bids":[{"price":3499.45,"qty":0.00000000},{"price":3498.45,"qty":3.01305282}],"asks":[],"checksum":816448943,"timestamp":"2024-06-01T17:52:31.365398Z"}]}
{"channel":"book","type":"update","data":[{"symbol":"ETH/EUR","bids":[{"price":3499.83,"qty":1.60000000}],"asks":[],"checksum":1901257017,"timestamp":"2024-06-01T17:52:31.365607Z"}]}
{"channel":"book","type":"update","data":[{"symbol":"ETH/EUR","bids":[{"price":3499.77,"qty":0.00000000},{"price":3498.45,"qty":3.01305282}],"asks":[],"checksum":1066248957,"timestamp":"2024-06-01T17:52:31.367188Z"}]}
{"channel":"book","type":"update","data":[{"symbol":"ETH/EUR","bids":[{"price":3499.32,"qty":0.00000000},{"price":3498.26,"qty":3.94900000},{"price":3499.78,"qty":3.58840000}],"asks":[],"checksum":3316415600,"timestamp":"2024-06-01T17:52:31.369362Z"}]}
{"channel":"book","type":"update","data":[{"symbol":"ETH/EUR","bids":[{"price":3499.83,"qty":0.00000000},{"price":3498.26,"qty":3.94900000}],"asks":[],"checksum":225463529,"timestamp":"2024-06-01T17:52:31.370346Z"}]}
{"channel":"book","type":"update","data":[{"symbol":"ETH/EUR","bids":[{"price":3499.45,"qty":1.60000000}],"asks":[],"checksum":4029049278,"timestamp":"2024-06-01T17:52:31.370359Z"}]}
{"channel":"book","type":"update","data":[{"symbol":"ETH/EUR","bids":[{"price":3499.45,"qty":0.00000000},{"price":3498.26,"qty":3.94900000}],"asks":[],"checksum":225463529,"timestamp":"2024-06-01T17:52:31.373241Z"}]}
{"channel":"book","type":"update","data":[{"symbol":"ETH/EUR","bids":[{"price":3499.84,"qty":1.60000000}],"asks":[],"checksum":1690872361,"timestamp":"2024-06-01T17:52:31.373413Z"}]}
{"channel":"book","type":"update","data":[{"symbol":"ETH/EUR","bids":[],"asks":[{"price":3502.05,"qty":0.50000000}],"checksum":3057835479,"timestamp":"2024-06-01T17:52:31.377731Z"}]}
{"channel":"book","type":"update","data":[{"symbol":"ETH/EUR","bids":[{"price":3499.62,"qty":26.34545451}],"asks":[],"checksum":160124910,"timestamp":"2024-06-01T17:52:31.396287Z"}]}
{"channel":"book","type":"update","data":[{"symbol":"ETH/EUR","bids":[{"price":3501.86,"qty":0.00000000},{"price":3498.45,"qty":3.01305282}],"asks":[],"checksum":578055362,"timestamp":"2024-06-01T17:52:31.399068Z"}]}
{"channel":"book","type":"update","data":[{"symbol":"ETH/EUR","bids":[{"price":3499.78,"qty":0.00000000},{"price":3498.26,"qty":3.94900000},{"price":3499.63,"qty":3.58840000}],"asks":[],"checksum":2482520098,"timestamp":"2024-06-01T17:52:31.402813Z"}]}
{"channel":"book","type":"update","data":[{"symbol":"ETH/EUR","bids":[{"price":3499.84,"qty":0.00000000},{"price":3498.26,"qty":3.94900000}],"asks":[],"checksum":1732928140,"timestamp":"2024-06-01T17:52:31.406163Z"}]}
{"channel":"book","type":"update","data":[{"symbol":"ETH/EUR","bids":[{"price":3499.69,"qty":1.60000000}],"asks":[],"checksum":1858803254,"timestamp":"2024-06-01T17:52:31.406512Z"}]}
{"channel":"book","type":"update","data":[{"symbol":"ETH/EUR","bids":[{"price":3499.31,"qty":0.00000000},{"price":3498.26,"qty":3.94900000}],"asks":[],"checksum":2617944224,"timestamp":"2024-06-01T17:52:31.412217Z"}]}
{"channel":"book","type":"update","data":[{"symbol":"ETH/EUR","bids":[{"price":3499.67,"qty":26.34507497}],"asks":[],"checksum":1672202738,"timestamp":"2024-06-01T17:52:31.414535Z"}]}
{"channel":"book","type":"update","data":[{"symbol":"ETH/EUR","bids":[{"price":3499.67,"qty":0.00000000},{"price":3498.26,"qty":3.94900000}],"asks":[],"checksum":2617944224,"timestamp":"2024-06-01T17:52:31.419260Z"}]}
{"channel":"book","type":"update","data":[{"symbol":"ETH/EUR","bids":[{"price":3498.45,"qty":0.00000000},{"price":3497.46,"qty":0.84000000}],"asks":[],"checksum":2497044233,"timestamp":"2024-06-01T17:52:31.431522Z"}]}
{"channel":"book","type":"update","data":[{"symbol":"ETH/EUR","bids":[],"asks":[{"price":3502.45,"qty":3.01525282}],"checksum":698416882,"timestamp":"2024-06-01T17:52:31.434560Z"}]}
{"channel":"book","type":"update","data":[{"symbol":"ETH/EUR","bids":[],"asks":[{"price":3502.06,"qty":0.00000000},{"price":3502.83,"qty":1.83186454}],"checksum":2567929085,"timestamp":"2024-06-01T17:52:31.459603Z"}]}
{"channel":"book","type":"update","data":[{"symbol":"ETH/EUR","bids":[{"price":3499.65,"qty":26.34523199}],"asks":[],"checksum":3037297775,"timestamp":"2024-06-01T17:52:31.466276Z"}]}
{"channel":"book","type":"update","data":[{"symbol":"ETH/EUR","bids":[],"asks":[{"price":3502.07,"qty":26.32709339}],"checksum":1220492764,"timestamp":"2024-06-01T17:52:31.467781Z"}]}
{"channel":"book","type":"update","data":[{"symbol":"ETH/EUR","bids":[{"price":3499.63,"qty":0.00000000},{"price":3497.46,"qty":0.84000000},{"price":3499.70,"qty":3.58840000}],"asks":[],"checksum":2670934978,"timestamp":"2024-06-01T17:52:31.469882Z"}]}
{"channel":"book","type":"update","data":[{"symbol":"ETH/EUR","bids":[{"price":3499.69,"qty":0.00000000},{"price":3497.46,"qty":0.84000000}],"asks":[],"checksum":184238666,"timestamp":"2024-06-01T17:52:31.472999Z"}]}
{"channel":"book","type":"update","data":[{"symbol":"ETH/EUR","bids":[{"price":3499.76,"qty":1.60000000}],"asks":[],"checksum":3121355240,"timestamp":"2024-06-01T17:52:31.473049Z"}]}
{"channel":"book","type":"update","data":[{"symbol":"ETH/EUR","bids":[{"price":3499.65,"qty":0.00000000},{"price":3497.46,"qty":0.84000000}],"asks":[],"checksum":2246716419,"timestamp":"2024-06-01T17:52:31.473502Z"}]}
{"channel":"book","type":"update","data":[{"symbol":"ETH/EUR","bids":[{"price":3499.62,"qty":0.00000000},{"price":3497.38,"qty":3.01305282}],"asks":[],"checksum":1011966721,"timestamp":"2024-06-01T17:52:31.475347Z"}]}
{"channel":"book","type":"update","data":[{"symbol":"ETH/EUR","bids":[{"price":3499.76,"qty":0.00000000},{"price":3496.93,"qty":0.06454864}],"asks":[],"checksum":339476251,"timestamp":"2024-06-01T17:52:31.478515Z"}]}
{"channel":"book","type":"update","data":[{"symbol":"ETH/EUR","bids":[{"price":3499.45,"qty":1.60000000}],"asks":[],"checksum":3969232712,"timestamp":"2024-06-01T17:52:31.478756Z"}]}
{"channel":"book","type":"update","data":[{"symbol":"ETH/EUR","bids":[{"price":3498.26,"qty":0.00000000},{"price":3496.93,"qty":0.06454864},{"price":3497.47,"qty":3.94900000}],"asks":[],"checksum":803774553,"timestamp":"2024-06-01T17:52:31.479038Z"}]}
{"channel":"book","type":"update","data":[{"symbol":"ETH/EUR","bids":[{"price":3497.48,"qty":0.06453849}],"asks":[],"checksum":2185364128,"timestamp":"2024-06-01T17:52:31.485875Z"}]}
{"channel":"book","type":"update","data":[{"symbol":"ETH/EUR","bids":[{"price":3499.62,"qty":26.34545986}],"asks":[],"checksum":2824207069,"timestamp":"2024-06-01T17:52:31.520130Z"}]}
{"channel":"book","type":"update","data":[{"symbol":"ETH/EUR","bids":[{"price":3499.45,"qty":0.00000000},{"price":3497.46,"qty":0.84000000}],"asks":[],"checksum":2090901058,"timestamp":"2024-06-01T17:52:31.523141Z"}]}
{"channel":"book","type":"update","data":[{"symbol":"ETH/EUR","bids":[{"price":3499.76,"qty":1.60000000}],"asks":[],"checksum":2049196869,"timestamp":"2024-06-01T17:52:31.523232Z"}]}
{"channel":"book","type":"update","data":[{"symbol":"ETH/EUR","bids":[{"price":3501.92,"qty":0.00000000},{"price":3497.46,"qty":0.84000000},{"price":3499.34,"qty":0.08560700}],"asks":[],"checksum":863483582,"timestamp":"2024-06-01T17:52:31.534790Z"}]}
{"channel":"book","type":"update","data":[{"symbol":"ETH/EUR","bids":[{"price":3497.48,"qty":0.00000000},{"price":3497.46,"qty":0.84000000}],"asks":[],"checksum":2689207457,"timestamp":"2024-06-01T17:52:31.535624Z"}]}
{"channel":"book","type":"update","data":[{"symbol":"ETH/EUR","bids":[],"asks":[{"price":3501.93,"qty":97.19063214}],"checksum":3612922328,"timestamp":"2024-06-01T17:52:31.537422Z"}]}
{"channel":"book","type":"update","data":[{"symbol":"ETH/EUR","bids":[],"asks":[{"price":3501.87,"qty":1.60000000}],"checksum":3338167468,"timestamp":"2024-06-01T17:52:31.537535Z"}]}
{"channel":"book","type":"update","data":[{"symbol":"ETH/EUR","bids":[{"price":3499.70,"qty":0.00000000},{"price":3497.38,"qty":3.01305282},{"price":3498.74,"qty":3.58840000}],"asks":[],"checksum":1589851430,"timestamp":"2024-06-01T17:52:31.537984Z"}]}
{"channel":"book","type":"update","data":[{"symbol":"ETH/EUR","bids":[],"asks":[{"price":3501.93,"qty":70.86248625}],"checksum":1946881606,"timestamp":"2024-06-01T17:52:31.539261Z"}]}
{"channel":"book","type":"update","data":[{"symbol":"ETH/EUR","bids":[],"asks":[{"price":3501.93,"qty":44.53434036}],"checksum":1552347980,"timestamp":"2024-06-01T17:52:31.539314Z"}]}
{"channel":"book","type":"update","data":[{"symbol":"ETH/EUR","bids":[],"asks":[{"price":3502.07,"qty":0.00000000},{"price":3502.83,"qty":1.83186454}],"checksum":3048988340,"timestamp":"2024-06-01T17:52:31.539334Z"}]}
{"channel":"book","type":"update","data":[{"symbol":"ETH/EUR","bids":[],"asks":[{"price":3501.93,"qty":18.20619447}],"checksum":435997620,"timestamp":"2024-06-01T17:52:31.539456Z"}]}
{"channel":"book","type":"update","data":[{"symbol":"ETH/EUR","bids":[],"asks":[{"price":3502.05,"qty":0.00000000},{"price":3503.09,"qty":0.00220000}],"checksum":1178729784,"timestamp":"2024-06-01T17:52:31.540426Z"}]}
{"channel":"book","type":"update","data":[{"symbol":"ETH/EUR","bids":[],"asks":[{"price":3501.93,"qty":18.11619447}],"checksum":48948399,"timestamp":"2024-06-01T17:52:31.541710Z"}]}
{"channel":"book","type":"update","data":[{"symbol":"ETH/EUR","bids":[],"asks":[{"price":3502.04,"qty":3.94900000}],"checksum":4276765860,"timestamp":"2024-06-01T17:52:31.543170Z"}]}
{"channel":"book","type":"update","data":[{"symbol":"ETH/EUR","bids":[],"asks":[{"price":3500.26,"qty":26.34077642}],"checksum":1869338780,"timestamp":"2024-06-01T17:52:31.544421Z"}]}
{"channel":"book","type":"update","data":[{"symbol":"ETH/EUR","bids":[],"asks":[{"price":3501.85,"qty":26.32875563}],"checksum":3943137855,"timestamp":"2024-06-01T17:52:31.544616Z"}]}
{"channel":"book","type":"update","data":[{"symbol":"ETH/EUR","bids":[],"asks":[{"price":3501.85,"qty":52.65751126}],"checksum":3318550179,"timestamp":"2024-06-01T17:52:31.544630Z"}]}
{"channel":"book","type":"update","data":[{"symbol":"ETH/EUR","bids":[],"asks":[{"price":3501.85,"qty":78.98626689}],"checksum":3133373371,"timestamp":"2024-06-01T17:52:31.544830Z"}]}
{"channel":"book","type":"update","data":[{"symbol":"ETH/EUR","bids":[],"asks":[{"price":3502.44,"qty":0.52710000}],"checksum":1369383524,"timestamp":"2024-06-01T17:52:31.545238Z"}]}
{"channel":"book","type":"update","data":[{"symbol":"ETH/EUR","bids":[],"asks":[{"price":3502.14,"qty":0.00000000},{"price":3502.57,"qty":0.00220000}],"checksum":3978879750,"timestamp":"2024-06-01T17:52:31.547191Z"}]}
{"channel":"book","type":"update","data":[{"symbol":"ETH/EUR","bids":[],"asks":[{"price":3500.67,"qty":1.06800000}],"checksum":3220189554,"timestamp":"2024-06-01T17:52:31.549404Z"}]}
{"channel":"book","type":"update","data":[{"symbol":"ETH/EUR","bids":[],"asks":[{"price":3501.85,"qty":52.65751126}],"checksum":647853707,"timestamp":"2024-06-01T17:52:31.550104Z"}]}
{"channel":"book","type":"update","data":[{"symbol":"ETH/EUR","bids":[],"asks":[{"price":3501.85,"qty":26.32875563}],"checksum":2804788396,"timestamp":"2024-06-01T17:52:31.550136Z"}]}
{"channel":"book","type":"update","data":[{"symbol":"ETH/EUR","bids":[],"asks":[{"price":3501.85,"qty":0.00000000},{"price":3502.57,"qty":0.00220000}],"checksum":1171580690,"timestamp":"2024-06-01T17:52:31.550271Z"}]}
{"channel":"book","type":"update","data":[{"symbol":"ETH/EUR","bids":[{"price":3498.52,"qty":0.00000000},{"price":3497.38,"qty":3.01305282}],"asks":[],"checksum":3363129526,"timestamp":"2024-06-01T17:52:31.554579Z"}]}
{"channel":"book","type":"update","data":[{"symbol":"ETH/EUR","bids":[],"asks":[{"price":3500.26,"qty":0.00000000},{"price":3502.61,"qty":0.77800000}],"checksum":234731719,"timestamp":"2024-06-01T17:52:31.567352Z"}]}
{"channel":"book","type":"update","data":[{"symbol":"ETH/EUR","bids":[],"asks":[{"price":3502.23,"qty":0.00000000},{"price":3502.83,"qty":1.83186454}],"checksum":3796722314,"timestamp":"2024-06-01T17:52:31.571284Z"}]}
{"channel":"book","type":"update","data":[{"symbol":"ETH/EUR","bids":[{"price":3498.74,"qty":0.00000000},{"price":3496.92,"qty":0.27474678}],"asks":[],"checksum":1546129641,"timestamp":"2024-06-01T17:52:31.571340Z"}]}
{"channel":"book","type":"update","data":[{"symbol":"ETH/EUR","bids":[],"asks":[{"price":3501.13,"qty":0.72912968}],"checksum":2736203143,"timestamp":"2024-06-01T17:52:31.572259Z"}]}
{"channel":"book","type":"update","data":[{"symbol":"ETH/EUR","bids":[{"price":3499.59,"qty":26.34570217}],"asks":[],"checksum":4211609453,"timestamp":"2024-06-01T17:52:31.573797Z"}]}
{"channel":"book","type":"update","data":[{"symbol":"ETH/EUR","bids":[{"price":3499.62,"qty":0.00000000},{"price":3496.92,"qty":0.27474678}],"asks":[],"checksum":3716276779,"timestamp":"2024-06-01T17:52:31.575242Z"}]}
{"channel":"book","type":"update","data":[{"symbol":"ETH/EUR","bids":[{"price":3499.39,"qty":26.37583233}],"asks":[],"checksum":1091721654,"timestamp":"2024-06-01T17:52:31.578439Z"}]}
{"channel":"book","type":"update","data":[{"symbol":"ETH/EUR","bids":[],"asks":[{"price":3501.93,"qty":17.38706479}],"checksum":1821644183,"timestamp":"2024-06-01T17:52:31.589862Z"}]}
{"channel":"book","type":"update","data":[{"symbol":"ETH/EUR","bids":[],"asks":[{"price":3500.35,"qty":26.34007604}],"checksum":158320939,"timestamp":"2024-06-01T17:52:31.597963Z"}]}
{"channel":"book","type":"update","data":[{"symbol":"ETH/EUR","bids":[],"asks":[{"price":3500.35,"qty":0.00000000},{"price":3502.61,"qty":0.77800000}],"checksum":1821644183,"timestamp":"2024-06-01T17:52:31.602294Z"}]}
{"channel":"book","type":"update","data":[{"symbol":"ETH/EUR","bids":[],"asks":[{"price":3501.92,"qty":6.00000000}],"checksum":3786595297,"timestamp":"2024-06-01T17:52:31.610923Z"}]}
{"channel":"book","type":"update","data":[{"symbol":"ETH/EUR","bids":[],"asks":[{"price":3501.93,"qty":18.38706479}],"checksum":4053455559,"timestamp":"2024-06-01T17:52:31.621903Z"}]}
{"channel":"book","type":"update","data":[{"symbol":"ETH/EUR","bids":[{"price":3499.59,"qty":0.00000000},{"price":3496.90,"qty":4.43456333}],"asks":[],"checksum":1065547767,"timestamp":"2024-06-01T17:52:31.623362Z"}]}
{"channel":"book","type":"update","data":[{"symbol":"ETH/EUR","bids":[{"price":3499.76,"qty":0.00000000},{"price":3496.87,"qty":1.00000000}],"asks":[],"checksum":3221755327,"timestamp":"2024-06-01T17:52:31.626523Z"}]}
{"channel":"book","type":"update","data":[{"symbol":"ETH/EUR","bids":[{"price":3499.45,"qty":1.60000000}],"asks":[],"checksum":3860746464,"timestamp":"2024-06-01T17:52:31.626758Z"}]}
{"channel":"book","type":"update","data":[{"symbol":"ETH/EUR","bids":[],"asks":[{"price":3501.93,"qty":19.38706479}],"checksum":159475831,"timestamp":"2024-06-01T17:52:31.629671Z"}]}
{"channel":"book","type":"update","data":[{"symbol":"ETH/EUR","bids":[],"asks":[{"price":3501.93,"qty":13.38706479}],"checksum":485737124,"timestamp":"2024-06-01T17:52:31.631244Z"}]}
{"channel":"book","type":"update","data":[{"symbol":"ETH/EUR","bids":[{"price":3499.74,"qty":26.34461598}],"asks":[],"checksum":2667388477,"timestamp":"2024-06-01T17:52:31.632202Z"}]}
{"channel":"book","type":"update","data":[{"symbol":"ETH/EUR","bids":[],"asks":[{"price":3500.66,"qty":0.65056936}],"checksum":4079592403,"timestamp":"2024-06-01T17:52:31.633601Z"}]}
{"channel":"book","type":"update","data":[{"symbol":"ETH/EUR","bids":[{"price":3499.39,"qty":0.02859069}],"asks":[],"checksum":1090161565,"timestamp":"2024-06-01T17:52:31.634942Z"}]}
{"channel":"book","type":"update","data":[{"symbol":"ETH/EUR","bids":[{"price":3499.45,"qty":0.00000000},{"price":3496.90,"qty":4.43456333}],"asks":[],"checksum":698154905,"timestamp":"2024-06-01T17:52:31.635145Z"}]}
{"channel":"book","type":"update","data":[{"symbol":"ETH/EUR","bids":[{"price":3499.80,"qty":1.60000000}],"asks":[],"checksum":3332694518,"timestamp":"2024-06-01T17:52:31.635521Z"}]}
{"channel":"book","type":"update","data":[{"symbol":"ETH/EUR","bids":[{"price":3499.74,"qty":0.00000000},{"price":3496.90,"qty":4.43456333}],"asks":[],"checksum":3709427489,"timestamp":"2024-06-01T17:52:31.638397Z"}]}
{"channel":"book","type":"update","data":[{"symbol":"ETH/EUR","bids":[{"price":3499.80,"qty":0.00000000},{"price":3496.87,"qty":1.00000000}],"asks":[],"checksum":2032447495,"timestamp":"2024-06-01T17:52:31.641534Z"}]}
{"channel":"book","type":"update","data":[{"symbol":"ETH/EUR","bids":[{"price":3497.39,"qty":3.58840000}],"asks":[],"checksum":2391598523,"timestamp":"2024-06-01T17:52:31.642161Z"}]}
{"channel":"book","type":"update","data":[{"symbol":"ETH/EUR","bids":[],"asks":[{"price":3500.67,"qty":0.00000000},{"price":3502.57,"qty":0.00220000}],"checksum":3617849594,"timestamp":"2024-06-01T17:52:31.642523Z"}]}
{"channel":"book","type":"update","data":[{"symbol":"ETH/EUR","bids":[{"price":3499.65,"qty":26.34529846}],"asks":[],"checksum":3998603012,"timestamp":"2024-06-01T17:52:31.642744Z"}]}
{"channel":"book","type":"update","data":[{"symbol":"ETH/EUR","bids":[{"price":3499.65,"qty":0.00000000},{"price":3496.90,"qty":4.43456333}],"asks":[],"checksum":3617849594,"timestamp":"2024-06-01T17:52:31.655709Z"}]}
{"channel":"book","type":"update","data":[{"symbol":"ETH/EUR","bids":[{"price":3499.39,"qty":0.00000000},{"price":3496.87,"qty":1.00000000},{"price":3499.77,"qty":0.02858758}],"asks":[],"checksum":2782449115,"timestamp":"2024-06-01T17:52:31.660734Z"}]}
{"channel":"book","type":"update","data":[{"symbol":"ETH/EUR","bids":[],"asks":[{"price":3500.66,"qty":0.65815271}],"checksum":2082269400,"timestamp":"2024-06-01T17:52:31.660812Z"}]}
{"channel":"book","type":"update","data":[{"symbol":"ETH/EUR","bids":[{"price":3499.26,"qty":1.31758555}],"asks":[],"checksum":3620859713,"timestamp":"2024-06-01T17:52:31.661520Z"}]}
{"channel":"book","type":"update","data":[{"symbol":"ETH/EUR","bids":[{"price":3499.08,"qty":1.31758555}],"asks":[],"checksum":4158222348,"timestamp":"2024-06-01T17:52:31.662275Z"}]}
{"channel":"book","type":"update","data":[{"symbol":"ETH/EUR","bids":[],"asks":[{"price":3500.59,"qty":26.33824133}],"checksum":1164334007,"timestamp":"2024-06-01T17:52:31.672679Z"}]}
{"channel":"book","type":"update","data":[{"symbol":"ETH/EUR","bids":[],"asks":[{"price":3502.04,"qty":0.00000000},{"price":3502.57,"qty":0.00220000}],"checksum":1222269972,"timestamp":"2024-06-01T17:52:31.673157Z"}]}
{"channel":"book","type":"update","data":[{"symbol":"ETH/EUR","bids":[],"asks":[{"price":3500.59,"qty":0.00000000},{"price":3502.61,"qty":0.77800000}],"checksum":1138362655,"timestamp":"2024-06-01T17:52:31.683628Z"}]}
{"channel":"book","type":"update","data":[{"symbol":"ETH/EUR","bids":[{"price":3500.04,"qty":26.34232048}],"asks":[],"checksum":78904094,"timestamp":"2024-06-01T17:52:31.688555Z"}]}
{"channel":"book","type":"update","data":[{"symbol":"ETH/EUR","bids":[{"price":3498.71,"qty":1.05352725}],"asks":[],"checksum":3250659364,"timestamp":"2024-06-01T17:52:31.692779Z"}]}
{"channel":"book","type":"update","data":[{"symbol":"ETH/EUR","bids":[],"asks":[{"price":3502.44,"qty":0.00000000},{"price":3502.83,"qty":0.00220000}],"checksum":1743969173,"timestamp":"2024-06-01T17:52:31.699269Z"}]}
{"channel":"book","type":"update","data":[{"symbol":"ETH/EUR","bids":[{"price":3500.04,"qty":0.00000000},{"price":3497.39,"qty":3.58840000}],"asks":[],"checksum":557958098,"timestamp":"2024-06-01T17:52:31.706640Z"}]}
{"channel":"book","type":"update","data":[{"symbol":"ETH/EUR","bids":[],"asks":[{"price":3501.13,"qty":0.00000000},{"price":3503.09,"qty":0.00220000}],"checksum":1087098966,"timestamp":"2024-06-01T17:52:31.714142Z"}]}
{"channel":"book","type":"update","data":[{"symbol":"ETH/EUR","bids":[],"asks":[{"price":3500.78,"qty":26.33679491}],"checksum":924150555,"timestamp":"2024-06-01T17:52:31.719506Z"}]}
{"channel":"book","type":"update","data":[{"symbol":"ETH/EUR","bids":[],"asks":[{"price":3500.78,"qty":0.00000000},{"price":3503.09,"qty":0.00220000}],"checksum":1087098966,"timestamp":"2024-06-01T17:52:31.723520Z"}]}
{"channel":"book","type":"update","data":[{"symbol":"ETH/EUR","bids":[{"price":3499.77,"qty":0.00000000},{"price":3497.38,"qty":3.01305282},{"price":3499.35,"qty":0.02859101}],"asks":[],"checksum":101687786,"timestamp":"2024-06-01T17:52:31.728766Z"}]}
{"channel":"book","type":"update","data":[{"symbol":"ETH/EUR","bids":[{"price":3499.77,"qty":0.32778701}],"asks":[],"checksum":175343645,"timestamp":"2024-06-01T17:52:31.732382Z"}]}
{"channel":"book","type":"update","data":[{"symbol":"ETH/EUR","bids":[{"price":3498.09,"qty":1.06800000}],"asks":[],"checksum":1013810105,"timestamp":"2024-06-01T17:52:31.733568Z"}]}
{"channel":"book","type":"update","data":[{"symbol":"ETH/EUR","bids":[{"price":3499.45,"qty":26.34673032}],"asks":[],"checksum":3834152924,"timestamp":"2024-06-01T17:52:31.736414Z"}]}
{"channel":"book","type":"update","data":[{"symbol":"ETH/EUR","bids":[{"price":3500.11,"qty":26.34182192}],"asks":[],"checksum":2384316943,"timestamp":"2024-06-01T17:52:31.739601Z"}]}
{"channel":"book","type":"update","data":[{"symbol":"ETH/EUR","bids":[],"asks":[{"price":3500.66,"qty":0.65056936},{"price":3501.12,"qty":0.00758335}],"checksum":3920301306,"timestamp":"2024-06-01T17:52:31.741926Z"}]}
{"channel":"book","type":"update","data":[{"symbol":"ETH/EUR","bids":[],"asks":[{"price":3500.66,"qty":0.00000000},{"price":3503.09,"qty":0.00220000}],"checksum":4191906270,"timestamp":"2024-06-01T17:52:31.763050Z"}]}
{"channel":"book","type":"update","data":[{"symbol":"ETH/EUR","bids":[],"asks":[{"price":3501.86,"qty":0.65056936}],"checksum":3248284967,"timestamp":"2024-06-01T17:52:31.766935Z"}]}
{"channel":"book","type":"update","data":[{"symbol":"ETH/EUR","bids":[],"asks":[{"price":3500.88,"qty":26.33610213}],"checksum":4089746520,"timestamp":"2024-06-01T17:52:31.769246Z"}]}
{"channel":"book","type":"update","data":[{"symbol":"ETH/EUR","bids":[],"asks":[{"price":3501.93,"qty":13.88706479}],"checksum":1597484441,"timestamp":"2024-06-01T17:52:31.772296Z"}]}
{"channel":"book","type":"update","data":[{"symbol":"ETH/EUR","bids":[],"asks":[{"price":3501.86,"qty":0.00000000},{"price":3502.83,"qty":0.00220000}],"checksum":3703554566,"timestamp":"2024-06-01T17:52:31.773191Z"}]}
{"channel":"book","type":"update","data":[{"symbol":"ETH/EUR","bids":[{"price":3499.45,"qty":0.00000000},{"price":3498.09,"qty":1.06800000}],"asks":[],"checksum":80529008,"timestamp":"2024-06-01T17:52:31.778799Z"}]}
{"channel":"book","type":"update","data":[{"symbol":"ETH/EUR","bids":[],"asks":[{"price":3500.88,"qty":0.00000000},{"price":3503.09,"qty":0.00220000}],"checksum":3602951501,"timestamp":"2024-06-01T17:52:31.778925Z"}]}
{"channel":"book","type":"update","data":[{"symbol":"ETH/EUR","bids":[{"price":3500.11,"qty":0.00000000},{"price":3497.47,"qty":3.94900000}],"asks":[],"checksum":1837005422,"timestamp":"2024-06-01T17:52:31.780894Z"}]}
{"channel":"book","type":"update","data":[{"symbol":"ETH/EUR","bids":[],"asks":[{"price":3501.92,"qty":0.00000000},{"price":3503.21,"qty":0.00220000}],"checksum":1310802419,"timestamp":"2024-06-01T17:52:31.781749Z"}]}
{"channel":"book","type":"update","data":[{"symbol":"ETH/EUR","bids":[{"price":3498.74,"qty":3.58840000}],"asks":[],"checksum":3912282465,"timestamp":"2024-06-01T17:52:31.783055Z"}]}
{"channel":"book","type":"update","data":[{"symbol":"ETH/EUR","bids":[],"asks":[{"price":3501.86,"qty":0.65056936}],"checksum":608408593,"timestamp":"2024-06-01T17:52:31.783127Z"}]}
{"channel":"book","type":"update","data":[{"symbol":"ETH/EUR","bids":[{"price":3500.29,"qty":26.34042480}],"asks":[],"checksum":2411858364,"timestamp":"2024-06-01T17:52:31.792497Z"}]}
{"channel":"book","type":"update","data":[{"symbol":"ETH/EUR","bids":[],"asks":[{"price":3502.48,"qty":39.48610391}],"checksum":1521012742,"timestamp":"2024-06-01T17:52:31.792571Z"}]}
{"channel":"book","type":"update","data":[{"symbol":"ETH/EUR","bids":[],"asks":[{"price":3501.11,"qty":26.33433857}],"checksum":2723435497,"timestamp":"2024-06-01T17:52:31.792649Z"}]}
{"channel":"book","type":"update","data":[{"symbol":"ETH/EUR","bids":[],"asks":[{"price":3501.86,"qty":0.00000000},{"price":3502.83,"qty":0.00220000}],"checksum":382565819,"timestamp":"2024-06-01T17:52:31.796665Z"}]}
{"channel":"book","type":"update","data":[{"symbol":"ETH/EUR","bids":[],"asks":[{"price":3501.93,"qty":9.93406479}],"checksum":3759786638,"timestamp":"2024-06-01T17:52:31.797725Z"}]}
{"channel":"book","type":"update","data":[{"symbol":"ETH/EUR","bids":[{"price":3500.29,"qty":0.00000000},{"price":3498.09,"qty":1.06800000}],"asks":[],"checksum":1341605831,"timestamp":"2024-06-01T17:52:31.798321Z"}]}
{"channel":"book","type":"update","data":[{"symbol":"ETH/EUR","bids":[],"asks":[{"price":3501.11,"qty":0.00000000},{"price":3503.09,"qty":0.00220000}],"checksum":2992052035,"timestamp":"2024-06-01T17:52:31.798395Z"}]}
{"channel":"book","type":"update","data":[{"symbol":"ETH/EUR","bids":[],"asks":[{"price":3502.96,"qty":1.82966454}],"checksum":3780329273,"timestamp":"2024-06-01T17:52:31.800472Z"}]}
{"channel":"book","type":"update","data":[{"symbol":"ETH/EUR","bids":[],"asks":[{"price":3501.10,"qty":0.65056936}],"checksum":1541338420,"timestamp":"2024-06-01T17:52:31.802231Z"}]}
{"channel":"book","type":"update","data":[{"symbol":"ETH/EUR","bids":[{"price":3499.78,"qty":0.11849725}],"asks":[],"checksum":2708202977,"timestamp":"2024-06-01T17:52:31.806183Z"}]}
{"channel":"book","type":"update","data":[{"symbol":"ETH/EUR","bids":[],"asks":[{"price":3501.12,"qty":0.00000000},{"price":3502.96,"qty":1.82966454},{"price":3501.86,"qty":0.00758335}],"checksum":4065161408,"timestamp":"2024-06-01T17:52:31.806795Z"}]}
{"channel":"book","type":"update","data":[{"symbol":"ETH/EUR","bids":[{"price":3498.74,"qty":0.00000000},{"price":3498.09,"qty":1.06800000}],"asks":[],"checksum":962263104,"timestamp":"2024-06-01T17:52:31.810159Z"}]}
{"channel":"book","type":"update","data":[{"symbol":"ETH/EUR","bids":[],"asks":[{"price":3501.93,"qty":8.93406479}],"checksum":2358016441,"timestamp":"2024-06-01T17:52:31.840558Z"}]}
{"channel":"book","type":"update","data":[{"symbol":"ETH/EUR","bids":[{"price":3499.79,"qty":26.34422055}],"asks":[],"checksum":4026942364,"timestamp":"2024-06-01T17:52:31.841461Z"}]}
{"channel":"book","type":"update","data":[{"symbol":"ETH/EUR","bids":[],"asks":[{"price":3501.01,"qty":26.33506929}],"checksum":335506669,"timestamp":"2024-06-01T17:52:31.841549Z"}]}
{"channel":"book","type":"update","data":[{"symbol":"ETH/EUR","bids":[],"asks":[{"price":3501.85,"qty":0.72912968}],"checksum":2384647642,"timestamp":"2024-06-01T17:52:31.845439Z"}]}
{"channel":"book","type":"update","data":[{"symbol":"ETH/EUR","bids":[{"price":3499.78,"qty":0.00000000},{"price":3498.09,"qty":1.06800000}],"asks":[],"checksum":911414312,"timestamp":"2024-06-01T17:52:31.845656Z"}]}
{"channel":"book","type":"update","data":[{"symbol":"ETH/EUR","bids":[{"price":3499.80,"qty":0.11849116}],"asks":[],"checksum":1227947157,"timestamp":"2024-06-01T17:52:31.845739Z"}]}
{"channel":"book","type":"update","data":[{"symbol":"ETH/EUR","bids":[{"price":3499.79,"qty":0.00000000},{"price":3498.09,"qty":1.06800000}],"asks":[],"checksum":371662448,"timestamp":"2024-06-01T17:52:31.853040Z"}]}
{"channel":"book","type":"update","data":[{"symbol":"ETH/EUR","bids":[],"asks":[{"price":3501.01,"qty":0.00000000},{"price":3502.61,"qty":0.77800000}],"checksum":3404877491,"timestamp":"2024-06-01T17:52:31.853048Z"}]}
{"channel":"book","type":"update","data":[{"symbol":"ETH/EUR","bids":[{"price":3499.79,"qty":26.34422055}],"asks":[],"checksum":1266793167,"timestamp":"2024-06-01T17:52:31.853098Z"}]}
{"channel":"book","type":"update","data":[{"symbol":"ETH/EUR","bids":[],"asks":[{"price":3501.93,"qty":7.93406479}],"checksum":1526558364,"timestamp":"2024-06-01T17:52:31.854249Z"}]}
{"channel":"book","type":"update","data":[{"symbol":"ETH/EUR","bids":[{"price":3499.79,"qty":0.00000000},{"price":3498.09,"qty":1.06800000}],"asks":[],"checksum":3073196392,"timestamp":"2024-06-01T17:52:31.858022Z"}]}
{"channel":"book","type":"update","data":[{"symbol":"ETH/EUR","bids":[{"price":3498.40,"qty":0.31470858}],"asks":[],"checksum":1816797845,"timestamp":"2024-06-01T17:52:31.879764Z"}]}
{"channel":"book","type":"update","data":[{"symbol":"ETH/EUR","bids":[{"price":3500.16,"qty":26.34142905}],"asks":[],"checksum":895515452,"timestamp":"2024-06-01T17:52:31.889395Z"}]}
{"channel":"book","type":"update","data":[{"symbol":"ETH/EUR","bids":[{"price":3499.80,"qty":0.00000000},{"price":3498.40,"qty":0.31470858}],"asks":[],"checksum":2626275985,"timestamp":"2024-06-01T17:52:31.894084Z"}]}
{"channel":"book","type":"update","data":[{"symbol":"ETH/EUR","bids":[{"price":3500.17,"qty":0.11849172}],"asks":[],"checksum":522336028,"timestamp":"2024-06-01T17:52:31.894096Z"}]}
{"channel":"book","type":"update","data":[{"symbol":"ETH/EUR","bids":[],"asks":[{"price":3502.48,"qty":45.48610391}],"checksum":4222886791,"timestamp":"2024-06-01T17:52:31.894264Z"}]}
{"channel":"book","type":"update","data":[{"symbol":"ETH/EUR","bids":[],"asks":[{"price":3501.09,"qty":26.33446268}],"checksum":1499639623,"timestamp":"2024-06-01T17:52:31.895276Z"}]}
{"channel":"book","type":"update","data":[{"symbol":"ETH/EUR","bids":[{"price":3500.44,"qty":26.33932642}],"asks":[],"checksum":498938006,"timestamp":"2024-06-01T17:52:31.895480Z"}]}
{"channel":"book","type":"update","data":[{"symbol":"ETH/EUR","bids":[{"price":3500.17,"qty":0.00000000},{"price":3498.71,"qty":1.05352725}],"asks":[],"checksum":2346238560,"timestamp":"2024-06-01T17:52:31.900031Z"}]}
{"channel":"book","type":"update","data":[{"symbol":"ETH/EUR","bids":[{"price":3500.16,"qty":0.00000000},{"price":3498.40,"qty":0.31470858}],"asks":[],"checksum":1871047226,"timestamp":"2024-06-01T17:52:31.901292Z"}]}
{"channel":"book","type":"update","data":[{"symbol":"ETH/EUR","bids":[],"asks":[{"price":3501.35,"qty":1.06800000}],"checksum":3295535655,"timestamp":"2024-06-01T17:52:31.903331Z"}]}
{"channel":"book","type":"update","data":[{"symbol":"ETH/EUR","bids":[{"price":3498.74,"qty":3.58840000}],"asks":[],"checksum":1509768328,"timestamp":"2024-06-01T17:52:31.904574Z"}]}
{"channel":"book","type":"update","data":[{"symbol":"ETH/EUR","bids":[{"price":3500.44,"qty":0.00000000},{"price":3498.40,"qty":0.31470858}],"asks":[],"checksum":1041206809,"timestamp":"2024-06-01T17:52:31.918611Z"}]}
{"channel":"book","type":"update","data":[{"symbol":"ETH/EUR","bids":[{"price":3499.36,"qty":0.11849172}],"asks":[],"checksum":2336788494,"timestamp":"2024-06-01T17:52:31.922872Z"}]}
{"channel":"book","type":"update","data":[{"symbol":"ETH/EUR","bids":[],"asks":[{"price":3501.35,"qty":0.00000000},{"price":3502.57,"qty":0.00220000}],"checksum":2994590753,"timestamp":"2024-06-01T17:52:31.923282Z"}]}
{"channel":"book","type":"update","data":[{"symbol":"ETH/EUR","bids":[],"asks":[{"price":3501.93,"qty":7.43406479}],"checksum":1446288617,"timestamp":"2024-06-01T17:52:31.934799Z"}]}
{"channel":"book","type":"update","data":[{"symbol":"ETH/EUR","bids":[{"price":3498.74,"qty":0.00000000},{"price":3498.40,"qty":0.31470858}],"asks":[],"checksum":221558638,"timestamp":"2024-06-01T17:52:31.937986Z"}]}
{"channel":"book","type":"update","data":[{"symbol":"ETH/EUR","bids":[],"asks":[{"price":3501.07,"qty":26.33461582}],"checksum":1557327774,"timestamp":"2024-06-01T17:52:31.948384Z"}]}
{"channel":"book","type":"update","data":[{"symbol":"ETH/EUR","bids":[{"price":3500.47,"qty":26.33906837}],"asks":[],"checksum":3504965655,"timestamp":"2024-06-01T17:52:31.952375Z"}]}
{"channel":"book","type":"update","data":[{"symbol":"ETH/EUR","bids":[{"price":3499.36,"qty":0.00000000},{"price":3498.40,"qty":0.31470858}],"asks":[],"checksum":4044208566,"timestamp":"2024-06-01T17:52:31.956468Z"}]}
{"channel":"book","type":"update","data":[{"symbol":"ETH/EUR","bids":[],"asks":[{"price":3501.07,"qty":0.00000000},{"price":3502.57,"qty":0.00220000}],"checksum":2147602475,"timestamp":"2024-06-01T17:52:31.970716Z"}]}
{"channel":"book","type":"update","data":[{"symbol":"ETH/EUR","bids":[{"price":3500.47,"qty":0.00000000},{"price":3498.23,"qty":0.71700000}],"asks":[],"checksum":4052769793,"timestamp":"2024-06-01T17:52:31.970815Z"}]}
{"channel":"book","type":"update","data":[{"symbol":"ETH/EUR","bids":[],"asks":[{"price":3501.09,"qty":0.00000000},{"price":3502.61,"qty":0.77800000}],"checksum":2731258888,"timestamp":"2024-06-01T17:52:31.970857Z"}]}
{"channel":"book","type":"update","data":[{"symbol":"ETH/EUR","bids":[{"price":3498.74,"qty":3.94900000}],"asks":[],"checksum":3378949238,"timestamp":"2024-06-01T17:52:31.989477Z"}]}
{"channel":"book","type":"update","data":[{"symbol":"ETH/EUR","bids":[],"asks":[{"price":3501.86,"qty":0.00000000},{"price":3502.83,"qty":0.00220000},{"price":3502.44,"qty":0.00758335}],"checksum":3643505935,"timestamp":"2024-06-01T17:52:31.990513Z"}]}
{"channel":"book","type":"update","data":[{"symbol":"ETH/EUR","bids":[{"price":3498.40,"qty":0.00000000},{"price":3498.23,"qty":0.71700000}],"asks":[],"checksum":553237510,"timestamp":"2024-06-01T17:52:31.991883Z"}]}
{"channel":"book","type":"update","data":[{"symbol":"ETH/EUR","bids":[],"asks":[{"price":3501.11,"qty":26.33431320}],"checksum":2893958758,"timestamp":"2024-06-01T17:52:31.997301Z"}]}
{"channel":"book","type":"update","data":[{"symbol":"ETH/EUR","bids":[],"asks":[{"price":3501.11,"qty":0.00000000},{"price":3502.61,"qty":0.77800000}],"checksum":553237510,"timestamp":"2024-06-01T17:52:32.002723Z"}]}
{"channel":"book","type":"update","data":[{"symbol":"ETH/EUR","bids":[],"asks":[{"price":3501.26,"qty":26.33320751}],"checksum":2335784232,"timestamp":"2024-06-01T17:52:32.006921Z"}]}
{"channel":"book","type":"update","data":[{"symbol":"ETH/EUR","bids":[{"price":3500.54,"qty":26.33854439}],"asks":[],"checksum":3132196693,"timestamp":"2024-06-01T17:52:32.006960Z"}]}
{"channel":"book","type":"update","data":[{"symbol":"ETH/EUR","bids":[{"price":3498.88,"qty":0.31470858}],"asks":[],"checksum":191534237,"timestamp":"2024-06-01T17:52:32.007633Z"}]}
{"channel":"book","type":"update","data":[{"symbol":"ETH/EUR","bids":[],"asks":[{"price":3501.10,"qty":0.00000000},{"price":3502.61,"qty":0.77800000}],"checksum":3075676783,"timestamp":"2024-06-01T17:52:32.010437Z"}]}
{"channel":"book","type":"update","data":[{"symbol":"ETH/EUR","bids":[],"asks":[{"price":3501.59,"qty":1.06800000}],"checksum":4034256267,"timestamp":"2024-06-01T17:52:32.021959Z"}]}
{"channel":"book","type":"update","data":[{"symbol":"ETH/EUR","bids":[{"price":3500.54,"qty":0.00000000},{"price":3498.71,"qty":1.05352725}],"asks":[],"checksum":1467243050,"timestamp":"2024-06-01T17:52:32.023359Z"}]}
{"channel":"book","type":"update","data":[{"symbol":"ETH/EUR","bids":[{"price":3499.60,"qty":3.95300000}],"asks":[],"checksum":471413439,"timestamp":"2024-06-01T17:52:32.025508Z"}]}
{"channel":"book","type":"update","data":[{"symbol":"ETH/EUR","bids":[],"asks":[{"price":3501.58,"qty":0.65056936}],"checksum":3711461487,"timestamp":"2024-06-01T17:52:32.027587Z"}]}
{"channel":"book","type":"update","data":[{"symbol":"ETH/EUR","bids":[{"price":3499.66,"qty":0.52710000}],"asks":[],"checksum":3531552683,"timestamp":"2024-06-01T17:52:32.042133Z"}]}
{"channel":"book","type":"update","data":[{"symbol":"ETH/EUR","bids":[],"asks":[{"price":3501.44,"qty":26.33184517}],"checksum":852851569,"timestamp":"2024-06-01T17:52:32.052878Z"}]}
{"channel":"book","type":"update","data":[{"symbol":"ETH/EUR","bids":[],"asks":[{"price":3501.25,"qty":26.33329610}],"checksum":3304890583,"timestamp":"2024-06-01T17:52:32.052894Z"}]}
{"channel":"book","type":"update","data":[{"symbol":"ETH/EUR","bids":[{"price":3500.51,"qty":26.33881331}],"asks":[],"checksum":2960213072,"timestamp":"2024-06-01T17:52:32.052917Z"}]}
{"channel":"book","type":"update","data":[{"symbol":"ETH/EUR","bids":[],"asks":[{"price":3501.25,"qty":0.00000000},{"price":3502.45,"qty":3.01525282}],"checksum":2402446166,"timestamp":"2024-06-01T17:52:32.058870Z"}]}
{"channel":"book","type":"update","data":[{"symbol":"ETH/EUR","bids":[{"price":3500.59,"qty":26.33819420}],"asks":[],"checksum":166895584,"timestamp":"2024-06-01T17:52:32.063349Z"}]}
{"channel":"book","type":"update","data":[{"symbol":"ETH/EUR","bids":[],"asks":[{"price":3502.00,"qty":3.00000000}],"checksum":3764771487,"timestamp":"2024-06-01T17:52:32.066590Z"}]}
{"channel":"book","type":"update","data":[{"symbol":"ETH/EUR","bids":[{"price":3500.29,"qty":1.35380818}],"asks":[],"checksum":4222765238,"timestamp":"2024-06-01T17:52:32.100242Z"}]}
{"channel":"book","type":"update","data":[{"symbol":"ETH/EUR","bids":[{"price":3499.34,"qty":0.42841003}],"asks":[],"checksum":755530471,"timestamp":"2024-06-01T17:52:32.113794Z"}]}
{"channel":"book","type":"update","data":[{"symbol":"ETH/EUR","bids":[],"asks":[{"price":3501.23,"qty":26.33347641}],"checksum":2218321726,"timestamp":"2024-06-01T17:52:32.118711Z"}]}
{"channel":"book","type":"update","data":[{"symbol":"ETH/EUR","bids":[],"asks":[{"price":3501.26,"qty":0.00000000},{"price":3502.44,"qty":0.00758335}],"checksum":1766267556,"timestamp":"2024-06-01T17:52:32.140003Z"}]}
{"channel":"book","type":"update","data":[{"symbol":"ETH/EUR","bids":[],"asks":[{"price":3501.51,"qty":0.08557900}],"checksum":2657978519,"timestamp":"2024-06-01T17:52:32.144921Z"}]}
{"channel":"book","type":"update","data":[{"symbol":"ETH/EUR","bids":[{"price":3500.59,"qty":0.00000000},{"price":3499.08,"qty":1.31758555}],"asks":[],"checksum":2451509734,"timestamp":"2024-06-01T17:52:32.150022Z"}]}
{"channel":"book","type":"update","data":[{"symbol":"ETH/EUR","bids":[],"asks":[{"price":3501.23,"qty":0.00000000},{"price":3502.44,"qty":0.00758335}],"checksum":225907914,"timestamp":"2024-06-01T17:52:32.150206Z"}]}
{"channel":"book","type":"update","data":[{"symbol":"ETH/EUR","bids":[{"price":3499.24,"qty":3.58840000}],"asks":[],"checksum":2095593530,"timestamp":"2024-06-01T17:52:32.153401Z"}]}
{"channel":"book","type":"update","data":[{"symbol":"ETH/EUR","bids":[{"price":3500.61,"qty":26.33806849}],"asks":[],"checksum":177722797,"timestamp":"2024-06-01T17:52:32.155398Z"}]}
{"channel":"book","type":"update","data":[{"symbol":"ETH/EUR","bids":[],"asks":[{"price":3501.44,"qty":0.00000000},{"price":3502.45,"qty":3.01525282}],"checksum":4074865253,"timestamp":"2024-06-01T17:52:32.155411Z"}]}
{"channel":"book","type":"update","data":[{"symbol":"ETH/EUR","bids":[{"price":3500.51,"qty":0.00000000},{"price":3499.23,"qty":5.13672894}],"asks":[],"checksum":393633234,"timestamp":"2024-06-01T17:52:32.155541Z"}]}
{"channel":"book","type":"update","data":[{"symbol":"ETH/EUR","bids":[],"asks":[{"price":3501.43,"qty":26.33190552}],"checksum":186257038,"timestamp":"2024-06-01T17:52:32.163700Z"}]}
{"channel":"book","type":"update","data":[{"symbol":"ETH/EUR","bids":[],"asks":[{"price":3501.43,"qty":0.00000000},{"price":3502.45,"qty":3.01525282}],"checksum":393633234,"timestamp":"2024-06-01T17:52:32.171288Z"}]}
{"channel":"book","type":"update","data":[{"symbol":"ETH/EUR","bids":[{"price":3500.61,"qty":0.00000000},{"price":3499.08,"qty":1.31758555}],"asks":[],"checksum":3553611278,"timestamp":"2024-06-01T17:52:32.171419Z"}]}
{"channel":"book","type":"update","data":[{"symbol":"ETH/EUR","bids":[],"asks":[{"price":3501.09,"qty":26.33450018}],"checksum":4205263953,"timestamp":"2024-06-01T17:52:32.178758Z"}]}
{"channel":"book","type":"update","data":[{"symbol":"ETH/EUR","bids":[{"price":3499.24,"qty":0.00000000},{"price":3498.74,"qty":3.94900000}],"asks":[],"checksum":2688270997,"timestamp":"2024-06-01T17:52:32.181931Z"}]}
{"channel":"book","type":"update","data":[{"symbol":"ETH/EUR","bids":[],"asks":[{"price":3501.09,"qty":0.00000000},{"price":3502.45,"qty":3.01525282}],"checksum":2303930570,"timestamp":"2024-06-01T17:52:32.182885Z"}]}
{"channel":"book","type":"update","data":[{"symbol":"ETH/EUR","bids":[{"price":3500.29,"qty":0.00000000},{"price":3498.73,"qty":10.43976375}],"asks":[],"checksum":3226633141,"timestamp":"2024-06-01T17:52:32.186804Z"}]}
{"channel":"book","type":"update","data":[{"symbol":"ETH/EUR","bids":[{"price":3499.78,"qty":26.34426421}],"asks":[],"checksum":4132510353,"timestamp":"2024-06-01T17:52:32.191165Z"}]}
{"channel":"book","type":"update","data":[{"symbol":"ETH/EUR","bids":[{"price":3499.78,"qty":0.00000000},{"price":3498.73,"qty":10.43976375}],"asks":[],"checksum":3226633141,"timestamp":"2024-06-01T17:52:32.195366Z"}]}
{"channel":"book","type":"update","data":[{"symbol":"ETH/EUR","bids":[{"price":3499.40,"qty":0.49780000}],"asks":[],"checksum":3869626388,"timestamp":"2024-06-01T17:52:32.205192Z"}]}
{"channel":"book","type":"update","data":[{"symbol":"ETH/EUR","bids":[{"price":3499.40,"qty":1.49780000}],"asks":[],"checksum":3646819010,"timestamp":"2024-06-01T17:52:32.207885Z"}]}
{"channel":"book","type":"update","data":[{"symbol":"ETH/EUR","bids":[{"price":3500.59,"qty":26.33820843}],"asks":[],"checksum":712215385,"timestamp":"2024-06-01T17:52:32.217826Z"}]}
{"channel":"book","type":"update","data":[{"symbol":"ETH/EUR","bids":[{"price":3499.40,"qty":1.99780000}],"asks":[],"checksum":2817962928,"timestamp":"2024-06-01T17:52:32.218929Z"}]}
{"channel":"book","type":"update","data":[{"symbol":"ETH/EUR","bids":[{"price":3500.50,"qty":26.33882754}],"asks":[],"checksum":372436683,"timestamp":"2024-06-01T17:52:32.284086Z"}]}
{"channel":"book","type":"update","data":[{"symbol":"ETH/EUR","bids":[{"price":3500.02,"qty":26.34244904}],"asks":[],"checksum":1121611750,"timestamp":"2024-06-01T17:52:32.284187Z"}]}
{"channel":"book","type":"update","data":[{"symbol":"ETH/EUR","bids":[],"asks":[{"price":3501.11,"qty":26.33431591}],"checksum":245137900,"timestamp":"2024-06-01T17:52:32.289012Z"}]}
{"channel":"book","type":"update","data":[{"symbol":"ETH/EUR","bids":[],"asks":[{"price":3501.20,"qty":26.33369690}],"checksum":1073058651,"timestamp":"2024-06-01T17:52:32.289284Z"}]}
{"channel":"book","type":"update","data":[{"symbol":"ETH/EUR","bids":[{"price":3500.27,"qty":1.35381592}],"asks":[],"checksum":2920756377,"timestamp":"2024-06-01T17:52:32.307363Z"}]}
{"channel":"book","type":"update","data":[{"symbol":"ETH/EUR","bids":[{"price":3500.59,"qty":0.00000000},{"price":3499.26,"qty":1.31758555}],"asks":[],"checksum":123133070,"timestamp":"2024-06-01T17:52:32.344753Z"}]}
{"channel":"book","type":"update","data":[{"symbol":"ETH/EUR","bids":[],"asks":[{"price":3501.11,"qty":0.00000000},{"price":3502.44,"qty":0.00758335}],"checksum":3708452388,"timestamp":"2024-06-01T17:52:32.344781Z"}]}
{"channel":"book","type":"update","data":[{"symbol":"ETH/EUR","bids":[],"asks":[{"price":3502.10,"qty":3.95300000}],"checksum":4213509571,"timestamp":"2024-06-01T17:52:32.348551Z"}]}
{"channel":"book","type":"update","data":[{"symbol":"ETH/EUR","bids":[{"price":3500.50,"qty":0.00000000},{"price":3499.23,"qty":5.13672894}],"asks":[],"checksum":575564273,"timestamp":"2024-06-01T17:52:32.349986Z"}]}
{"channel":"book","type":"update","data":[{"symbol":"ETH/EUR","bids":[],"asks":[{"price":3501.13,"qty":26.33417113}],"checksum":3833219134,"timestamp":"2024-06-01T17:52:32.355182Z"}]}
{"channel":"book","type":"update","data":[{"symbol":"ETH/EUR","bids":[{"price":3500.62,"qty":26.33797666}],"asks":[],"checksum":1168614220,"timestamp":"2024-06-01T17:52:32.355324Z"}]}
{"channel":"book","type":"update","data":[{"symbol":"ETH/EUR","bids":[{"price":3500.27,"qty":0.00000000},{"price":3499.23,"qty":5.13672894}],"asks":[],"checksum":403448036,"timestamp":"2024-06-01T17:52:32.357397Z"}]}
{"channel":"book","type":"update","data":[{"symbol":"ETH/EUR","bids":[],"asks":[{"price":3502.00,"qty":0.00000000},{"price":3502.10,"qty":3.95300000}],"checksum":1605150539,"timestamp":"2024-06-01T17:52:32.381154Z"}]}
{"channel":"book","type":"update","data":[{"symbol":"ETH/EUR","bids":[{"price":3500.60,"qty":5.99000000}],"asks":[],"checksum":2848430002,"timestamp":"2024-06-01T17:52:32.421491Z"}]}
{"channel":"book","type":"update","data":[{"symbol":"ETH/EUR","bids":[{"price":3500.63,"qty":2.60000000}],"asks":[],"checksum":3343773179,"timestamp":"2024-06-01T17:52:32.436685Z"}]}
{"channel":"book","type":"update","data":[{"symbol":"ETH/EUR","bids":[{"price":3500.25,"qty":1.35382365}],"asks":[],"checksum":565745556,"timestamp":"2024-06-01T17:52:32.478643Z"}]}
{"channel":"book","type":"update","data":[{"symbol":"ETH/EUR","bids":[{"price":3500.01,"qty":6.00000000}],"asks":[],"checksum":1681255226,"timestamp":"2024-06-01T17:52:32.483375Z"}]}
{"channel":"book","type":"update","data":[{"symbol":"ETH/EUR","bids":[{"price":3499.69,"qty":2.00000000}],"asks":[],"checksum":2863035601,"timestamp":"2024-06-01T17:52:32.484617Z"}]}
{"channel":"book","type":"update","data":[{"symbol":"ETH/EUR","bids":[{"price":3499.89,"qty":0.84644082}],"asks":[],"checksum":612428075,"timestamp":"2024-06-01T17:52:32.485335Z"}]}
{"channel":"book","type":"update","data":[{"symbol":"ETH/EUR","bids":[{"price":3500.28,"qty":0.34420830}],"asks":[],"checksum":825747481,"timestamp":"2024-06-01T17:52:32.519854Z"}]}
{"channel":"book","type":"update","data":[{"symbol":"ETH/EUR","bids":[{"price":3500.06,"qty":1.31730437}],"asks":[],"checksum":1595108129,"timestamp":"2024-06-01T17:52:32.522421Z"}]}
{"channel":"book","type":"update","data":[{"symbol":"ETH/EUR","bids":[],"asks":[{"price":3501.13,"qty":0.00000000},{"price":3502.44,"qty":0.02585312}],"checksum":3591311367,"timestamp":"2024-06-01T17:52:32.560140Z"}]}
{"channel":"book","type":"update","data":[{"symbol":"ETH/EUR","bids":[{"price":3500.54,"qty":26.33859314}],"asks":[],"checksum":3840164870,"timestamp":"2024-06-01T17:52:32.564597Z"}]}
{"channel":"book","type":"update","data":[{"symbol":"ETH/EUR","bids":[],"asks":[{"price":3501.12,"qty":26.33427642}],"checksum":386066729,"timestamp":"2024-06-01T17:52:32.564721Z"}]}
{"channel":"book","type":"update","data":[{"symbol":"ETH/EUR","bids":[],"asks":[{"price":3501.42,"qty":26.33198072}],"checksum":565954834,"timestamp":"2024-06-01T17:52:32.564795Z"}]}
{"channel":"book","type":"update","data":[{"symbol":"ETH/EUR","bids":[{"price":3500.31,"qty":26.34031097}],"asks":[],"checksum":2114906316,"timestamp":"2024-06-01T17:52:32.564809Z"}]}
{"channel":"book","type":"update","data":[{"symbol":"ETH/EUR","bids":[],"asks":[{"price":3501.63,"qty":26.33041927}],"checksum":442446926,"timestamp":"2024-06-01T17:52:32.564857Z"}]}
{"channel":"book","type":"update","data":[{"symbol":"ETH/EUR","bids":[{"price":3500.62,"qty":0.00000000},{"price":3499.89,"qty":0.84644082}],"asks":[],"checksum":4189864773,"timestamp":"2024-06-01T17:52:32.594063Z"}]}
{"channel":"book","type":"update","data":[{"symbol":"ETH/EUR","bids":[{"price":3500.60,"qty":32.32812937}],"asks":[],"checksum":1792039889,"timestamp":"2024-06-01T17:52:32.597572Z"}]}
{"channel":"book","type":"update","data":[{"symbol":"ETH/EUR","bids":[],"asks":[{"price":3501.20,"qty":0.00000000},{"price":3502.08,"qty":0.00220000}],"checksum":802695060,"timestamp":"2024-06-01T17:52:32.625023Z"}]}
{"channel":"book","type":"update","data":[{"symbol":"ETH/EUR","bids":[{"price":3500.60,"qty":5.99000000}],"asks":[],"checksum":782005096,"timestamp":"2024-06-01T17:52:32.625164Z"}]}
{"channel":"book","type":"update","data":[{"symbol":"ETH/EUR","bids":[],"asks":[{"price":3501.08,"qty":26.33455809}],"checksum":2643778889,"timestamp":"2024-06-01T17:52:32.630423Z"}]}
{"channel":"book","type":"update","data":[{"symbol":"ETH/EUR","bids":[{"price":3500.64,"qty":0.02858804}],"asks":[],"checksum":4059825184,"timestamp":"2024-06-01T17:52:32.662584Z"}]}
{"channel":"book","type":"update","data":[{"symbol":"ETH/EUR","bids":[],"asks":[{"price":3501.08,"qty":0.00000000},{"price":3502.08,"qty":0.00220000}],"checksum":2670201816,"timestamp":"2024-06-01T17:52:32.715526Z"}]}
{"channel":"book","type":"update","data":[{"symbol":"ETH/EUR","bids":[{"price":3500.59,"qty":26.33819519}],"asks":[],"checksum":2465797530,"timestamp":"2024-06-01T17:52:32.720011Z"}]}
{"channel":"book","type":"update","data":[{"symbol":"ETH/EUR","bids":[],"asks":[{"price":3501.10,"qty":26.33439225}],"checksum":2445096047,"timestamp":"2024-06-01T17:52:32.720172Z"}]}
{"channel":"book","type":"update","data":[{"symbol":"ETH/EUR","bids":[],"asks":[{"price":3501.10,"qty":0.00000000},{"price":3502.08,"qty":0.00220000}],"checksum":2465797530,"timestamp":"2024-06-01T17:52:32.860786Z"}]}
{"channel":"book","type":"update","data":[{"symbol":"ETH/EUR","bids":[],"asks":[{"price":3501.09,"qty":26.33453177}],"checksum":3680410965,"timestamp":"2024-06-01T17:52:32.865554Z"}]}
{"channel":"book","type":"update","data":[{"symbol":"ETH/EUR","bids":[],"asks":[{"price":3501.09,"qty":0.00000000},{"price":3502.08,"qty":0.00220000}],"checksum":2465797530,"timestamp":"2024-06-01T17:52:32.903550Z"}]}
{"channel":"book","type":"update","data":[{"symbol":"ETH/EUR","bids":[{"price":3500.59,"qty":0.00000000},{"price":3500.01,"qty":6.00000000}],"asks":[],"checksum":2670201816,"timestamp":"2024-06-01T17:52:32.903561Z"}]}
{"channel":"book","type":"update","data":[{"symbol":"ETH/EUR","bids":[{"price":3500.47,"qty":26.33910921}],"asks":[],"checksum":2019357496,"timestamp":"2024-06-01T17:52:32.908098Z"}]}
{"channel":"book","type":"update","data":[{"symbol":"ETH/EUR","bids":[{"price":3500.54,"qty":0.00000000},{"price":3500.01,"qty":6.00000000}],"asks":[],"checksum":906173032,"timestamp":"2024-06-01T17:52:32.914248Z"}]}
{"channel":"book","type":"update","data":[{"symbol":"ETH/EUR","bids":[],"asks":[{"price":3501.09,"qty":26.33452914}],"checksum":239307595,"timestamp":"2024-06-01T17:52:32.918161Z"}]}
{"channel":"book","type":"update","data":[{"symbol":"ETH/EUR","bids":[{"price":3500.57,"qty":26.33833211}],"asks":[],"checksum":2780528033,"timestamp":"2024-06-01T17:52:32.918200Z"}]}
{"channel":"book","type":"update","data":[{"symbol":"ETH/EUR","bids":[{"price":3500.63,"qty":0.00000000},{"price":3500.01,"qty":6.00000000}],"asks":[],"checksum":3739412536,"timestamp":"2024-06-01T17:52:32.974407Z"}]}
{"channel":"book","type":"update","data":[{"symbol":"ETH/EUR","bids":[{"price":3500.65,"qty":2.60000000}],"asks":[],"checksum":1052993845,"timestamp":"2024-06-01T17:52:32.974646Z"}]}
{"channel":"book","type":"update","data":[{"symbol":"ETH/EUR","bids":[],"asks":[{"price":3501.09,"qty":0.00000000},{"price":3502.08,"qty":0.00220000}],"checksum":2627492054,"timestamp":"2024-06-01T17:52:33.005898Z"}]}
{"channel":"book","type":"update","data":[{"symbol":"ETH/EUR","bids":[{"price":3500.57,"qty":0.00000000},{"price":3500.01,"qty":6.00000000}],"asks":[],"checksum":718618280,"timestamp":"2024-06-01T17:52:33.005974Z"}]}
{"channel":"book","type":"update","data":[{"symbol":"ETH/EUR","bids":[],"asks":[{"price":3501.05,"qty":26.33482397}],"checksum":215031072,"timestamp":"2024-06-01T17:52:33.011061Z"}]}
{"channel":"book","type":"update","data":[{"symbol":"ETH/EUR","bids":[{"price":3500.53,"qty":26.33862701}],"asks":[],"checksum":3137592730,"timestamp":"2024-06-01T17:52:33.011106Z"}]}
{"channel":"book","type":"update","data":[{"symbol":"ETH/EUR","bids":[{"price":3500.53,"qty":0.00000000},{"price":3500.01,"qty":6.00000000}],"asks":[],"checksum":215031072,"timestamp":"2024-06-01T17:52:33.117310Z"}]}
{"channel":"book","type":"update","data":[{"symbol":"ETH/EUR","bids":[],"asks":[{"price":3501.05,"qty":0.00000000},{"price":3502.08,"qty":0.00220000}],"checksum":718618280,"timestamp":"2024-06-01T17:52:33.117354Z"}]}
{"channel":"book","type":"update","data":[{"symbol":"ETH/EUR","bids":[],"asks":[{"price":3501.08,"qty":26.33455020}],"checksum":425715557,"timestamp":"2024-06-01T17:52:33.122444Z"}]}
{"channel":"book","type":"update","data":[{"symbol":"ETH/EUR","bids":[{"price":3500.57,"qty":26.33835317}],"asks":[],"checksum":2403930614,"timestamp":"2024-06-01T17:52:33.122561Z"}]}
{"channel":"book","type":"update","data":[{"symbol":"ETH/EUR","bids":[{"price":3500.60,"qty":0.00000000},{"price":3500.01,"qty":6.00000000}],"asks":[],"checksum":2049046044,"timestamp":"2024-06-01T17:52:33.123699Z"}]}
{"channel":"book","type":"update","data":[{"symbol":"ETH/EUR","bids":[{"price":3500.65,"qty":8.73500000}],"asks":[],"checksum":588505834,"timestamp":"2024-06-01T17:52:33.131993Z"}]}
{"channel":"book","type":"update","data":[{"symbol":"ETH/EUR","bids":[{"price":3500.47,"qty":0.00000000},{"price":3499.89,"qty":0.84644082}],"asks":[],"checksum":815359116,"timestamp":"2024-06-01T17:52:33.192664Z"}]}
{"channel":"book","type":"update","data":[{"symbol":"ETH/EUR","bids":[],"asks":[{"price":3501.12,"qty":0.00000000},{"price":3502.08,"qty":0.00220000}],"checksum":817729007,"timestamp":"2024-06-01T17:52:33.192732Z"}]}
{"channel":"book","type":"update","data":[{"symbol":"ETH/EUR","bids":[],"asks":[{"price":3501.42,"qty":0.00000000},{"price":3502.44,"qty":0.02585312}],"checksum":1655832961,"timestamp":"2024-06-01T17:52:33.192768Z"}]}
{"channel":"book","type":"update","data":[{"symbol":"ETH/EUR","bids":[],"asks":[{"price":3500.99,"qty":26.33525942}],"checksum":1993213344,"timestamp":"2024-06-01T17:52:33.197701Z"}]}
{"channel":"book","type":"update","data":[{"symbol":"ETH/EUR","bids":[],"asks":[{"price":3501.27,"qty":26.33315728}],"checksum":373375305,"timestamp":"2024-06-01T17:52:33.197873Z"}]}
{"channel":"book","type":"update","data":[{"symbol":"ETH/EUR","bids":[{"price":3500.60,"qty":26.33810485}],"asks":[],"checksum":1895691735,"timestamp":"2024-06-01T17:52:33.197915Z"}]}
{"channel":"book","type":"update","data":[{"symbol":"ETH/EUR","bids":[],"asks":[{"price":3500.99,"qty":0.00000000},{"price":3502.08,"qty":0.00220000}],"checksum":3340559743,"timestamp":"2024-06-01T17:52:33.247689Z"}]}
{"channel":"book","type":"update","data":[{"symbol":"ETH/EUR","bids":[],"asks":[{"price":3501.08,"qty":0.00000000},{"price":3502.44,"qty":0.02585312}],"checksum":1312852087,"timestamp":"2024-06-01T17:52:33.252786Z"}]}
{"channel":"book","type":"update","data":[{"symbol":"ETH/EUR","bids":[],"asks":[{"price":3500.97,"qty":26.33540684}],"checksum":4159367145,"timestamp":"2024-06-01T17:52:33.257768Z"}]}
{"channel":"book","type":"update","data":[{"symbol":"ETH/EUR","bids":[],"asks":[{"price":3501.27,"qty":0.00000000},{"price":3502.44,"qty":0.02585312}],"checksum":4156322171,"timestamp":"2024-06-01T17:52:33.257876Z"}]}
{"channel":"book","type":"update","data":[{"symbol":"ETH/EUR","bids":[],"asks":[{"price":3501.05,"qty":26.33478781}],"checksum":3679418685,"timestamp":"2024-06-01T17:52:33.263091Z"}]}
{"channel":"book","type":"update","data":[{"symbol":"ETH/EUR","bids":[],"asks":[{"price":3500.97,"qty":0.00000000},{"price":3502.44,"qty":0.02585312}],"checksum":2008831185,"timestamp":"2024-06-01T17:52:33.425091Z"}]}
{"channel":"book","type":"update","data":[{"symbol":"ETH/EUR","bids":[],"asks":[{"price":3502.10,"qty":3.95300000}],"checksum":977527738,"timestamp":"2024-06-01T17:52:33.428132Z"}]}
{"channel":"book","type":"update","data":[{"symbol":"ETH/EUR","bids":[],"asks":[{"price":3501.00,"qty":26.33519624}],"checksum":4250770604,"timestamp":"2024-06-01T17:52:33.429739Z"}]}
{"channel":"book","type":"update","data":[{"symbol":"ETH/EUR","bids":[],"asks":[{"price":3501.00,"qty":0.00000000},{"price":3502.10,"qty":3.95300000}],"checksum":977527738,"timestamp":"2024-06-01T17:52:33.448450Z"}]}
{"channel":"book","type":"update","data":[{"symbol":"ETH/EUR","bids":[{"price":3500.60,"qty":0.00000000},{"price":3499.89,"qty":0.84644082}],"asks":[],"checksum":3465737879,"timestamp":"2024-06-01T17:52:33.478761Z"}]}
{"channel":"book","type":"update","data":[{"symbol":"ETH/EUR","bids":[],"asks":[{"price":3501.04,"qty":26.33483878}],"checksum":2404125048,"timestamp":"2024-06-01T17:52:33.482785Z"}]}
{"channel":"book","type":"update","data":[{"symbol":"ETH/EUR","bids":[],"asks":[{"price":3501.04,"qty":0.00000000},{"price":3502.10,"qty":3.95300000}],"checksum":3465737879,"timestamp":"2024-06-01T17:52:33.487298Z"}]}
{"channel":"book","type":"update","data":[{"symbol":"ETH/EUR","bids":[],"asks":[{"price":3501.04,"qty":26.33483878}],"checksum":2404125048,"timestamp":"2024-06-01T17:52:33.607161Z"}]}
{"channel":"book","type":"update","data":[{"symbol":"ETH/EUR","bids":[],"asks":[{"price":3501.26,"qty":26.33318404}],"checksum":1918274243,"timestamp":"2024-06-01T17:52:33.607299Z"}]}
{"channel":"book","type":"update","data":[{"symbol":"ETH/EUR","bids":[],"asks":[{"price":3501.04,"qty":0.00000000},{"price":3502.08,"qty":0.00220000}],"checksum":3665623498,"timestamp":"2024-06-01T17:52:33.612128Z"}]}
{"channel":"book","type":"update","data":[{"symbol":"ETH/EUR","bids":[],"asks":[{"price":3501.00,"qty":26.33518044}],"checksum":255379829,"timestamp":"2024-06-01T17:52:33.660898Z"}]}
{"channel":"book","type":"update","data":[{"symbol":"ETH/EUR","bids":[],"asks":[{"price":3501.00,"qty":0.00000000},{"price":3502.08,"qty":0.00220000}],"checksum":3665623498,"timestamp":"2024-06-01T17:52:33.738906Z"}]}
{"channel":"book","type":"update","data":[{"symbol":"ETH/EUR","bids":[],"asks":[{"price":3500.98,"qty":26.33529101}],"checksum":444378813,"timestamp":"2024-06-01T17:52:33.743583Z"}]}
{"channel":"book","type":"update","data":[{"symbol":"ETH/EUR","bids":[{"price":3500.64,"qty":0.00000000},{"price":3499.77,"qty":1.05691669},{"price":3500.66,"qty":0.02858793}],"asks":[],"checksum":3295568985,"timestamp":"2024-06-01T17:52:33.769600Z"}]}
{"channel":"book","type":"update","data":[{"symbol":"ETH/EUR","bids":[],"asks":[{"price":3501.62,"qty":0.00757869}],"checksum":924722962,"timestamp":"2024-06-01T17:52:33.769639Z"}]}
{"channel":"book","type":"update","data":[{"symbol":"ETH/EUR","bids":[{"price":3500.64,"qty":0.08559500}],"asks":[],"checksum":1079463160,"timestamp":"2024-06-01T17:52:33.781331Z"}]}
{"channel":"book","type":"update","data":[{"symbol":"ETH/EUR","bids":[],"asks":[{"price":3500.98,"qty":0.00000000},{"price":3501.93,"qty":7.43406479}],"checksum":2344201353,"timestamp":"2024-06-01T17:52:34.174873Z"}]}
{"channel":"book","type":"update","data":[{"symbol":"ETH/EUR","bids":[],"asks":[{"price":3501.01,"qty":26.33513965}],"checksum":3347327554,"timestamp":"2024-06-01T17:52:34.179463Z"}]}
{"channel":"book","type":"update","data":[{"symbol":"ETH/EUR","bids":[],"asks":[{"price":3501.01,"qty":0.00000000},{"price":3501.93,"qty":7.43406479}],"checksum":2344201353,"timestamp":"2024-06-01T17:52:34.203592Z"}]}
{"channel":"book","type":"update","data":[{"symbol":"ETH/EUR","bids":[],"asks":[{"price":3501.00,"qty":26.33518704}],"checksum":1843924833,"timestamp":"2024-06-01T17:52:34.241034Z"}]}
{"channel":"book","type":"update","data":[{"symbol":"ETH/EUR","bids":[],"asks":[{"price":3501.05,"qty":0.00000000},{"price":3501.93,"qty":7.43406479}],"checksum":2192021809,"timestamp":"2024-06-01T17:52:34.242259Z"}]}
{"channel":"book","type":"update","data":[{"symbol":"ETH/EUR","bids":[],"asks":[{"price":3501.00,"qty":0.00000000},{"price":3502.08,"qty":0.00220000}],"checksum":1371906089,"timestamp":"2024-06-01T17:52:34.305080Z"}]}
{"channel":"book","type":"update","data":[{"symbol":"ETH/EUR","bids":[{"price":3500.59,"qty":26.33815100}],"asks":[],"checksum":1408277750,"timestamp":"2024-06-01T17:52:34.310064Z"}]}
{"channel":"book","type":"update","data":[{"symbol":"ETH/EUR","bids":[],"asks":[{"price":3501.26,"qty":0.00000000},{"price":3502.10,"qty":3.95300000}],"checksum":3043748727,"timestamp":"2024-06-01T17:52:34.310165Z"}]}
{"channel":"book","type":"update","data":[{"symbol":"ETH/EUR","bids":[],"asks":[{"price":3500.91,"qty":26.33589132}],"checksum":1144524239,"timestamp":"2024-06-01T17:52:34.310215Z"}]}
{"channel":"book","type":"update","data":[{"symbol":"ETH/EUR","bids":[],"asks":[{"price":3501.63,"qty":0.00000000},{"price":3502.10,"qty":3.95300000}],"checksum":187172332,"timestamp":"2024-06-01T17:52:34.317585Z"}]}
{"channel":"book","type":"update","data":[{"symbol":"ETH/EUR","bids":[],"asks":[{"price":3500.99,"qty":26.33527227}],"checksum":129600973,"timestamp":"2024-06-01T17:52:34.321348Z"}]}
{"channel":"book","type":"update","data":[{"symbol":"ETH/EUR","bids":[],"asks":[{"price":3501.18,"qty":26.33378913}],"checksum":1286691619,"timestamp":"2024-06-01T17:52:34.321436Z"}]}
{"channel":"book","type":"update","data":[{"symbol":"ETH/EUR","bids":[],"asks":[{"price":3501.50,"qty":26.33137911}],"checksum":1258902483,"timestamp":"2024-06-01T17:52:34.321503Z"}]}
{"channel":"book","type":"update","data":[{"symbol":"ETH/EUR","bids":[{"price":3500.59,"qty":0.00000000},{"price":3500.01,"qty":6.00000000}],"asks":[],"checksum":525202174,"timestamp":"2024-06-01T17:52:34.355967Z"}]}
{"channel":"book","type":"update","data":[{"symbol":"ETH/EUR","bids":[{"price":3500.61,"qty":26.33805805}],"asks":[],"checksum":1136029151,"timestamp":"2024-06-01T17:52:34.360159Z"}]}
{"channel":"book","type":"update","data":[{"symbol":"ETH/EUR","bids":[],"asks":[{"price":3501.62,"qty":0.00000000},{"price":3501.93,"qty":7.43406479},{"price":3501.84,"qty":0.00757811}],"checksum":4133228138,"timestamp":"2024-06-01T17:52:34.371615Z"}]}
{"channel":"book","type":"update","data":[{"symbol":"ETH/EUR","bids":[],"asks":[{"price":3500.91,"qty":0.00000000},{"price":3501.93,"qty":7.43406479}],"checksum":2713856713,"timestamp":"2024-06-01T17:52:34.375782Z"}]}
{"channel":"book","type":"update","data":[{"symbol":"ETH/EUR","bids":[{"price":3500.61,"qty":0.00000000},{"price":3500.01,"qty":6.00000000}],"asks":[],"checksum":3547394103,"timestamp":"2024-06-01T17:52:34.381426Z"}]}
{"channel":"book","type":"update","data":[{"symbol":"ETH/EUR","bids":[],"asks":[{"price":3500.99,"qty":0.00000000},{"price":3502.08,"qty":0.00220000}],"checksum":1435319625,"timestamp":"2024-06-01T17:52:34.384023Z"}]}
{"channel":"book","type":"update","data":[{"symbol":"ETH/EUR","bids":[{"price":3500.57,"qty":0.00000000},{"price":3499.89,"qty":0.84644082}],"asks":[],"checksum":3986087034,"timestamp":"2024-06-01T17:52:34.388638Z"}]}
{"channel":"book","type":"update","data":[{"symbol":"ETH/EUR","bids":[],"asks":[{"price":3501.50,"qty":0.00000000},{"price":3502.10,"qty":3.95300000}],"checksum":129807887,"timestamp":"2024-06-01T17:52:34.390173Z"}]}
{"channel":"book","type":"update","data":[{"symbol":"ETH/EUR","bids":[{"price":3500.01,"qty":0.00000000},{"price":3499.77,"qty":0.72912968}],"asks":[],"checksum":2815012667,"timestamp":"2024-06-01T17:52:34.393163Z"}]}
{"channel":"book","type":"update","data":[{"symbol":"ETH/EUR","bids":[],"asks":[{"price":3501.17,"qty":26.33386095}],"checksum":3079235006,"timestamp":"2024-06-01T17:52:34.393313Z"}]}
{"channel":"book","type":"update","data":[{"symbol":"ETH/EUR","bids":[{"price":3500.65,"qty":6.13500000}],"asks":[],"checksum":3671772698,"timestamp":"2024-06-01T17:52:34.396837Z"}]}
{"channel":"book","type":"update","data":[{"symbol":"ETH/EUR","bids":[],"asks":[{"price":3501.17,"qty":0.00000000},{"price":3502.10,"qty":3.95300000}],"checksum":3399091359,"timestamp":"2024-06-01T17:52:34.420198Z"}]}
{"channel":"book","type":"update","data":[{"symbol":"ETH/EUR","bids":[{"price":3500.51,"qty":26.33876033}],"asks":[],"checksum":3477121640,"timestamp":"2024-06-01T17:52:34.427022Z"}]}
{"channel":"book","type":"update","data":[{"symbol":"ETH/EUR","bids":[{"price":3500.51,"qty":0.00000000},{"price":3499.77,"qty":0.72912968}],"asks":[],"checksum":3399091359,"timestamp":"2024-06-01T17:52:34.430909Z"}]}
{"channel":"book","type":"update","data":[{"symbol":"ETH/EUR","bids":[{"price":3500.20,"qty":26.34112843}],"asks":[],"checksum":4141718481,"timestamp":"2024-06-01T17:52:34.435160Z"}]}
{"channel":"book","type":"update","data":[{"symbol":"ETH/EUR","bids":[],"asks":[{"price":3500.77,"qty":26.33690164}],"checksum":3016396792,"timestamp":"2024-06-01T17:52:34.457882Z"}]}
{"channel":"book","type":"update","data":[{"symbol":"ETH/EUR","bids":[],"asks":[{"price":3500.77,"qty":0.00000000},{"price":3502.10,"qty":3.95300000}],"checksum":4141718481,"timestamp":"2024-06-01T17:52:34.478086Z"}]}
{"channel":"book","type":"update","data":[{"symbol":"ETH/EUR","bids":[{"price":3500.44,"qty":26.33931126}],"asks":[],"checksum":693400119,"timestamp":"2024-06-01T17:52:34.483338Z"}]}
{"channel":"book","type":"update","data":[{"symbol":"ETH/EUR","bids":[{"price":3500.06,"qty":0.00000000},{"price":3499.89,"qty":0.84644082}],"asks":[],"checksum":2660862344,"timestamp":"2024-06-01T17:52:34.487883Z"}]}
{"channel":"book","type":"update","data":[{"symbol":"ETH/EUR","bids":[{"price":3500.44,"qty":0.00000000},{"price":3499.77,"qty":0.72912968}],"asks":[],"checksum":2688056272,"timestamp":"2024-06-01T17:52:34.511096Z"}]}
{"channel":"book","type":"update","data":[{"symbol":"ETH/EUR","bids":[],"asks":[{"price":3500.72,"qty":26.33728078}],"checksum":3229121297,"timestamp":"2024-06-01T17:52:34.514820Z"}]}
{"channel":"book","type":"update","data":[{"symbol":"ETH/EUR","bids":[],"asks":[{"price":3500.80,"qty":26.33667500}],"checksum":4058581115,"timestamp":"2024-06-01T17:52:34.560233Z"}]}
{"channel":"book","type":"update","data":[{"symbol":"ETH/EUR","bids":[{"price":3500.44,"qty":26.33935075}],"asks":[],"checksum":3238849209,"timestamp":"2024-06-01T17:52:34.560397Z"}]}
{"channel":"book","type":"update","data":[{"symbol":"ETH/EUR","bids":[],"asks":[{"price":3501.84,"qty":0.00000000},{"price":3502.08,"qty":0.00220000},{"price":3501.92,"qty":0.00757813}],"checksum":3168565603,"timestamp":"2024-06-01T17:52:34.568467Z"}]}
{"channel":"book","type":"update","data":[{"symbol":"ETH/EUR","bids":[],"asks":[{"price":3500.72,"qty":0.00000000},{"price":3502.08,"qty":0.00220000}],"checksum":3001672766,"timestamp":"2024-06-01T17:52:34.575356Z"}]}
{"channel":"book","type":"update","data":[{"symbol":"ETH/EUR","bids":[],"asks":[{"price":3500.74,"qty":26.33710437}],"checksum":2064947375,"timestamp":"2024-06-01T17:52:34.580518Z"}]}
{"channel":"book","type":"update","data":[{"symbol":"ETH/EUR","bids":[{"price":3500.32,"qty":4.00000000}],"asks":[],"checksum":3105521063,"timestamp":"2024-06-01T17:52:34.584782Z"}]}
{"channel":"book","type":"update","data":[{"symbol":"ETH/EUR","bids":[],"asks":[{"price":3500.74,"qty":0.00000000},{"price":3502.08,"qty":0.00220000}],"checksum":1054548745,"timestamp":"2024-06-01T17:52:34.597747Z"}]}
{"channel":"book","type":"update","data":[{"symbol":"ETH/EUR","bids":[{"price":3500.31,"qty":0.00000000},{"price":3499.89,"qty":0.84644082}],"asks":[],"checksum":1150235787,"timestamp":"2024-06-01T17:52:34.597913Z"}]}
{"channel":"book","type":"update","data":[{"symbol":"ETH/EUR","bids":[{"price":3500.28,"qty":0.00000000},{"price":3499.77,"qty":0.72912968}],"asks":[],"checksum":2861527372,"timestamp":"2024-06-01T17:52:34.671847Z"}]}
{"channel":"book","type":"update","data":[{"symbol":"ETH/EUR","bids":[{"price":3500.48,"qty":26.33902688}],"asks":[],"checksum":3439262267,"timestamp":"2024-06-01T17:52:34.681809Z"}]}
{"channel":"book","type":"update","data":[{"symbol":"ETH/EUR","bids":[],"asks":[{"price":3500.99,"qty":26.33521768}],"checksum":4188711038,"timestamp":"2024-06-01T17:52:34.681876Z"}]}
{"channel":"book","type":"update","data":[{"symbol":"ETH/EUR","bids":[],"asks":[{"price":3500.79,"qty":26.33671941}],"checksum":4235868229,"timestamp":"2024-06-01T17:52:34.682068Z"}]}
{"channel":"book","type":"update","data":[{"symbol":"ETH/EUR","bids":[],"asks":[{"price":3500.79,"qty":0.00000000},{"price":3501.93,"qty":7.43406479}],"checksum":4188711038,"timestamp":"2024-06-01T17:52:34.805023Z"}]}
{"channel":"book","type":"update","data":[{"symbol":"ETH/EUR","bids":[],"asks":[{"price":3500.78,"qty":26.33685155}],"checksum":1671712675,"timestamp":"2024-06-01T17:52:34.809383Z"}]}
{"channel":"book","type":"update","data":[{"symbol":"ETH/EUR","bids":[],"asks":[{"price":3500.78,"qty":0.00000000},{"price":3501.93,"qty":7.43406479}],"checksum":4188711038,"timestamp":"2024-06-01T17:52:34.870118Z"}]}
{"channel":"book","type":"update","data":[{"symbol":"ETH/EUR","bids":[{"price":3500.48,"qty":0.00000000},{"price":3499.77,"qty":0.72912968}],"asks":[],"checksum":1588084999,"timestamp":"2024-06-01T17:52:34.870161Z"}]}
{"channel":"book","type":"update","data":[{"symbol":"ETH/EUR","bids":[{"price":3500.44,"qty":0.00000000},{"price":3499.69,"qty":2.00000000}],"asks":[],"checksum":1816217435,"timestamp":"2024-06-01T17:52:34.870244Z"}]}
{"channel":"book","type":"update","data":[{"symbol":"ETH/EUR","bids":[{"price":3500.02,"qty":0.00000000},{"price":3499.66,"qty":0.52710000}],"asks":[],"checksum":1704746472,"timestamp":"2024-06-01T17:52:34.872248Z"}]}
{"channel":"book","type":"update","data":[{"symbol":"ETH/EUR","bids":[],"asks":[{"price":3500.72,"qty":26.33728375}],"checksum":1378048925,"timestamp":"2024-06-01T17:52:34.878058Z"}]}
{"channel":"book","type":"update","data":[{"symbol":"ETH/EUR","bids":[{"price":3500.42,"qty":26.33948561}],"asks":[],"checksum":4247924560,"timestamp":"2024-06-01T17:52:34.878179Z"}]}
{"channel":"book","type":"update","data":[{"symbol":"ETH/EUR","bids":[],"asks":[{"price":3500.72,"qty":0.00000000},{"price":3501.93,"qty":7.43406479}],"checksum":1176055913,"timestamp":"2024-06-01T17:52:34.882780Z"}]}
{"channel":"book","type":"update","data":[{"symbol":"ETH/EUR","bids":[{"price":3500.42,"qty":0.00000000},{"price":3499.66,"qty":0.52710000}],"asks":[],"checksum":1704746472,"timestamp":"2024-06-01T17:52:34.882897Z"}]}
{"channel":"book","type":"update","data":[{"symbol":"ETH/EUR","bids":[],"asks":[{"price":3500.77,"qty":26.33690470}],"checksum":1534069665,"timestamp":"2024-06-01T17:52:34.961007Z"}]}
{"channel":"book","type":"update","data":[{"symbol":"ETH/EUR","bids":[{"price":3500.46,"qty":26.33918698}],"asks":[],"checksum":4189143694,"timestamp":"2024-06-01T17:52:34.961136Z"}]}
{"channel":"book","type":"update","data":[{"symbol":"ETH/EUR","bids":[],"asks":[{"price":3500.77,"qty":0.00000000},{"price":3501.93,"qty":7.43406479}],"checksum":1510112495,"timestamp":"2024-06-01T17:52:35.055414Z"}]}
{"channel":"book","type":"update","data":[{"symbol":"ETH/EUR","bids":[],"asks":[{"price":3500.76,"qty":26.33698106}],"checksum":2764923474,"timestamp":"2024-06-01T17:52:35.060034Z"}]}
{"channel":"book","type":"update","data":[{"symbol":"ETH/EUR","bids":[{"price":3500.01,"qty":6.00000000}],"asks":[],"checksum":1965375859,"timestamp":"2024-06-01T17:52:35.061516Z"}]}
{"channel":"book","type":"update","data":[{"symbol":"ETH/EUR","bids":[{"price":3500.46,"qty":0.00000000},{"price":3499.69,"qty":2.00000000}],"asks":[],"checksum":728159086,"timestamp":"2024-06-01T17:52:35.209052Z"}]}
{"channel":"book","type":"update","data":[{"symbol":"ETH/EUR","bids":[{"price":3500.47,"qty":26.33907375}],"asks":[],"checksum":1295294515,"timestamp":"2024-06-01T17:52:35.212891Z"}]}
{"channel":"book","type":"update","data":[{"symbol":"ETH/EUR","bids":[],"asks":[{"price":3500.76,"qty":0.00000000},{"price":3501.93,"qty":7.43406479}],"checksum":3019619982,"timestamp":"2024-06-01T17:52:35.233147Z"}]}
{"channel":"book","type":"update","data":[{"symbol":"ETH/EUR","bids":[],"asks":[{"price":3500.78,"qty":26.33683027}],"checksum":1560901212,"timestamp":"2024-06-01T17:52:35.237500Z"}]}
{"channel":"book","type":"update","data":[{"symbol":"ETH/EUR","bids":[{"price":3500.47,"qty":0.00000000},{"price":3499.69,"qty":2.00000000}],"asks":[],"checksum":3435849460,"timestamp":"2024-06-01T17:52:35.260316Z"}]}
{"channel":"book","type":"update","data":[{"symbol":"ETH/EUR","bids":[{"price":3500.48,"qty":26.33901319}],"asks":[],"checksum":1210663854,"timestamp":"2024-06-01T17:52:35.263780Z"}]}
{"channel":"book","type":"update","data":[{"symbol":"ETH/EUR","bids":[{"price":3500.49,"qty":26.33894306}],"asks":[],"checksum":2045902477,"timestamp":"2024-06-01T17:52:35.350260Z"}]}
{"channel":"book","type":"update","data":[{"symbol":"ETH/EUR","bids":[{"price":3500.49,"qty":0.00000000},{"price":3499.77,"qty":0.72912968}],"asks":[],"checksum":1210663854,"timestamp":"2024-06-01T17:52:35.405541Z"}]}
{"channel":"book","type":"update","data":[{"symbol":"ETH/EUR","bids":[],"asks":[{"price":3500.78,"qty":0.00000000},{"price":3501.93,"qty":7.43406479}],"checksum":2799405948,"timestamp":"2024-06-01T17:52:35.405719Z"}]}
{"channel":"book","type":"update","data":[{"symbol":"ETH/EUR","bids":[{"price":3500.48,"qty":0.00000000},{"price":3499.69,"qty":2.00000000}],"asks":[],"checksum":811800822,"timestamp":"2024-06-01T17:52:35.411250Z"}]}
{"channel":"book","type":"update","data":[{"symbol":"ETH/EUR","bids":[],"asks":[{"price":3500.78,"qty":26.33682820}],"checksum":3315622847,"timestamp":"2024-06-01T17:52:35.414815Z"}]}
{"channel":"book","type":"update","data":[{"symbol":"ETH/EUR","bids":[{"price":3500.49,"qty":26.33892200}],"asks":[],"checksum":4248033673,"timestamp":"2024-06-01T17:52:35.414992Z"}]}
{"channel":"book","type":"update","data":[{"symbol":"ETH/EUR","bids":[],"asks":[{"price":3500.78,"qty":0.00000000},{"price":3501.93,"qty":7.43406479}],"checksum":4073120710,"timestamp":"2024-06-01T17:52:35.505838Z"}]}
{"channel":"book","type":"update","data":[{"symbol":"ETH/EUR","bids":[{"price":3500.49,"qty":0.00000000},{"price":3499.69,"qty":2.00000000}],"asks":[],"checksum":811800822,"timestamp":"2024-06-01T17:52:35.505920Z"}]}
{"channel":"book","type":"update","data":[{"symbol":"ETH/EUR","bids":[],"asks":[{"price":3500.75,"qty":26.33705224}],"checksum":4112599653,"timestamp":"2024-06-01T17:52:35.511187Z"}]}
{"channel":"book","type":"update","data":[{"symbol":"ETH/EUR","bids":[{"price":3500.46,"qty":26.33913504}],"asks":[],"checksum":4170323356,"timestamp":"2024-06-01T17:52:35.511205Z"}]}
{"channel":"book","type":"update","data":[{"symbol":"ETH/EUR","bids":[{"price":3500.46,"qty":0.00000000},{"price":3499.69,"qty":2.00000000}],"asks":[],"checksum":4112599653,"timestamp":"2024-06-01T17:52:35.517245Z"}]}
{"channel":"book","type":"update","data":[{"symbol":"ETH/EUR","bids":[],"asks":[{"price":3500.75,"qty":0.00000000},{"price":3501.93,"qty":7.43406479}],"checksum":811800822,"timestamp":"2024-06-01T17:52:35.517309Z"}]}
{"channel":"book","type":"update","data":[{"symbol":"ETH/EUR","bids":[],"asks":[{"price":3500.80,"qty":0.00000000},{"price":3502.08,"qty":0.00220000}],"checksum":3559206959,"timestamp":"2024-06-01T17:52:35.526644Z"}]}
{"channel":"book","type":"update","data":[{"symbol":"ETH/EUR","bids":[],"asks":[{"price":3500.99,"qty":0.00000000},{"price":3502.10,"qty":3.95300000}],"checksum":2062065181,"timestamp":"2024-06-01T17:52:35.532391Z"}]}
{"channel":"book","type":"update","data":[{"symbol":"ETH/EUR","bids":[{"price":3500.35,"qty":26.34002136}],"asks":[],"checksum":1184545610,"timestamp":"2024-06-01T17:52:35.532449Z"}]}
{"channel":"book","type":"update","data":[{"symbol":"ETH/EUR","bids":[],"asks":[{"price":3500.98,"qty":26.33529010}],"checksum":755801127,"timestamp":"2024-06-01T17:52:35.537492Z"}]}
{"channel":"book","type":"update","data":[{"symbol":"ETH/EUR","bids":[],"asks":[{"price":3500.98,"qty":52.67058020}],"checksum":2280428279,"timestamp":"2024-06-01T17:52:35.537634Z"}]}
{"channel":"book","type":"update","data":[{"symbol":"ETH/EUR","bids":[],"asks":[{"price":3500.98,"qty":26.33529010}],"checksum":755801127,"timestamp":"2024-06-01T17:52:35.542591Z"}]}
{"channel":"book","type":"update","data":[{"symbol":"ETH/EUR","bids":[],"asks":[{"price":3500.98,"qty":0.00000000},{"price":3502.10,"qty":3.95300000}],"checksum":1184545610,"timestamp":"2024-06-01T17:52:35.542607Z"}]}
{"channel":"book","type":"update","data":[{"symbol":"ETH/EUR","bids":[],"asks":[{"price":3500.71,"qty":26.33735572}],"checksum":2830898925,"timestamp":"2024-06-01T17:52:35.580890Z"}]}
{"channel":"book","type":"update","data":[{"symbol":"ETH/EUR","bids":[{"price":3500.44,"qty":26.33928010}],"asks":[],"checksum":440527980,"timestamp":"2024-06-01T17:52:35.581089Z"}]}
{"channel":"book","type":"update","data":[{"symbol":"ETH/EUR","bids":[],"asks":[{"price":3500.71,"qty":0.00000000},{"price":3502.10,"qty":3.95300000}],"checksum":1398863665,"timestamp":"2024-06-01T17:52:35.585666Z"}]}
{"channel":"book","type":"update","data":[{"symbol":"ETH/EUR","bids":[],"asks":[{"price":3501.92,"qty":0.00000000},{"price":3502.21,"qty":39.48916889},{"price":3502.09,"qty":0.00757817}],"checksum":1899741362,"timestamp":"2024-06-01T17:52:35.587687Z"}]}
{"channel":"book","type":"update","data":[{"symbol":"ETH/EUR","bids":[{"price":3500.44,"qty":0.00000000},{"price":3499.77,"qty":0.72912968}],"asks":[],"checksum":3567065654,"timestamp":"2024-06-01T17:52:35.608069Z"}]}
{"channel":"book","type":"update","data":[{"symbol":"ETH/EUR","bids":[],"asks":[{"price":3500.72,"qty":26.33728455}],"checksum":2663109638,"timestamp":"2024-06-01T17:52:35.630130Z"}]}
{"channel":"book","type":"update","data":[{"symbol":"ETH/EUR","bids":[{"price":3500.42,"qty":26.33946226}],"asks":[],"checksum":738199489,"timestamp":"2024-06-01T17:52:35.630182Z"}]}
{"channel":"book","type":"update","data":[{"symbol":"ETH/EUR","bids":[{"price":3500.42,"qty":0.00000000},{"price":3499.77,"qty":0.72912968}],"asks":[],"checksum":2663109638,"timestamp":"2024-06-01T17:52:35.699976Z"}]}
{"channel":"book","type":"update","data":[{"symbol":"ETH/EUR","bids":[],"asks":[{"price":3500.72,"qty":0.00000000},{"price":3502.10,"qty":3.95300000}],"checksum":3567065654,"timestamp":"2024-06-01T17:52:35.819024Z"}]}
{"channel":"book","type":"update","data":[{"symbol":"ETH/EUR","bids":[],"asks":[{"price":3500.74,"qty":26.33710814}],"checksum":1264540194,"timestamp":"2024-06-01T17:52:35.823724Z"}]}
{"channel":"book","type":"update","data":[{"symbol":"ETH/EUR","bids":[],"asks":[{"price":3500.80,"qty":26.33670286}],"checksum":3492960139,"timestamp":"2024-06-01T17:52:35.823837Z"}]}
{"channel":"book","type":"update","data":[{"symbol":"ETH/EUR","bids":[{"price":3500.64,"qty":0.00000000},{"price":3499.69,"qty":2.00000000},{"price":3500.20,"qty":26.42672643}],"asks":[],"checksum":3553634913,"timestamp":"2024-06-01T17:52:35.824273Z"}]}
{"channel":"book","type":"update","data":[{"symbol":"ETH/EUR","bids":[],"asks":[{"price":3500.80,"qty":0.00000000},{"price":3502.09,"qty":0.00757817}],"checksum":3534014993,"timestamp":"2024-06-01T17:52:35.828324Z"}]}
{"channel":"book","type":"update","data":[{"symbol":"ETH/EUR","bids":[],"asks":[{"price":3500.74,"qty":0.00000000},{"price":3502.10,"qty":3.95300000}],"checksum":2329330454,"timestamp":"2024-06-01T17:52:35.850630Z"}]}
{"channel":"book","type":"update","data":[{"symbol":"ETH/EUR","bids":[{"price":3500.35,"qty":0.00000000},{"price":3499.66,"qty":0.52710000}],"asks":[],"checksum":2584308252,"timestamp":"2024-06-01T17:52:35.850733Z"}]}
{"channel":"book","type":"update","data":[{"symbol":"ETH/EUR","bids":[],"asks":[{"price":3501.17,"qty":26.33386095}],"checksum":2575127185,"timestamp":"2024-06-01T17:52:35.855445Z"}]}
{"channel":"book","type":"update","data":[{"symbol":"ETH/EUR","bids":[],"asks":[{"price":3501.17,"qty":0.00000000},{"price":3502.10,"qty":3.95300000}],"checksum":2584308252,"timestamp":"2024-06-01T17:52:35.859848Z"}]}
{"channel":"book","type":"update","data":[{"symbol":"ETH/EUR","bids":[],"asks":[{"price":3500.76,"qty":26.33696023}],"checksum":2146360012,"timestamp":"2024-06-01T17:52:35.946645Z"}]}
{"channel":"book","type":"update","data":[{"symbol":"ETH/EUR","bids":[],"asks":[{"price":3500.73,"qty":26.33724195}],"checksum":791522227,"timestamp":"2024-06-01T17:52:36.018840Z"}]}
{"channel":"book","type":"update","data":[{"symbol":"ETH/EUR","bids":[{"price":3500.65,"qty":0.00000000},{"price":3499.60,"qty":3.95300000}],"asks":[],"checksum":3716435221,"timestamp":"2024-06-01T17:52:36.129774Z"}]}
{"channel":"book","type":"update","data":[{"symbol":"ETH/EUR","bids":[{"price":3499.90,"qty":0.60164648}],"asks":[],"checksum":2154130488,"timestamp":"2024-06-01T17:52:36.133324Z"}]}
{"channel":"book","type":"update","data":[{"symbol":"ETH/EUR","bids":[{"price":3500.33,"qty":2.00000000}],"asks":[],"checksum":1329563466,"timestamp":"2024-06-01T17:52:36.135652Z"}]}
{"channel":"book","type":"update","data":[{"symbol":"ETH/EUR","bids":[{"price":3500.66,"qty":0.00000000},{"price":3499.66,"qty":0.52710000},{"price":3500.33,"qty":2.02859484}],"asks":[],"checksum":2769455766,"timestamp":"2024-06-01T17:52:36.177439Z"}]}
{"channel":"book","type":"update","data":[{"symbol":"ETH/EUR","bids":[{"price":3499.69,"qty":0.00000000},{"price":3499.60,"qty":3.95300000}],"asks":[],"checksum":3246017537,"timestamp":"2024-06-01T17:52:36.183082Z"}]}
{"channel":"book","type":"update","data":[{"symbol":"ETH/EUR","bids":[],"asks":[{"price":3501.03,"qty":26.33497898}],"checksum":1802909875,"timestamp":"2024-06-01T17:52:36.185030Z"}]}
{"channel":"book","type":"update","data":[{"symbol":"ETH/EUR","bids":[],"asks":[{"price":3500.73,"qty":0.00000000},{"price":3502.08,"qty":0.00220000}],"checksum":875364353,"timestamp":"2024-06-01T17:52:36.195273Z"}]}
{"channel":"book","type":"update","data":[{"symbol":"ETH/EUR","bids":[],"asks":[{"price":3500.75,"qty":26.33706292}],"checksum":310088053,"timestamp":"2024-06-01T17:52:36.199075Z"}]}
{"channel":"book","type":"update","data":[{"symbol":"ETH/EUR","bids":[],"asks":[{"price":3500.75,"qty":0.00000000},{"price":3502.08,"qty":0.00220000}],"checksum":875364353,"timestamp":"2024-06-01T17:52:36.268920Z"}]}
{"channel":"book","type":"update","data":[{"symbol":"ETH/EUR","bids":[],"asks":[{"price":3500.78,"qty":26.33683122}],"checksum":2233210765,"timestamp":"2024-06-01T17:52:36.273421Z"}]}
{"channel":"book","type":"update","data":[{"symbol":"ETH/EUR","bids":[],"asks":[{"price":3500.76,"qty":0.00000000},{"price":3502.08,"qty":0.00220000}],"checksum":355081834,"timestamp":"2024-06-01T17:52:36.283380Z"}]}
{"channel":"book","type":"update","data":[{"symbol":"ETH/EUR","bids":[],"asks":[{"price":3500.78,"qty":0.00000000},{"price":3502.09,"qty":0.00757817}],"checksum":2892621480,"timestamp":"2024-06-01T17:52:36.326301Z"}]}
{"channel":"book","type":"update","data":[{"symbol":"ETH/EUR","bids":[],"asks":[{"price":3501.03,"qty":0.00000000},{"price":3502.10,"qty":3.95300000}],"checksum":2275858105,"timestamp":"2024-06-01T17:52:36.335912Z"}]}
{"channel":"book","type":"update","data":[{"symbol":"ETH/EUR","bids":[],"asks":[{"price":3500.69,"qty":26.33754469}],"checksum":3745820514,"timestamp":"2024-06-01T17:52:36.340198Z"}]}
{"channel":"book","type":"update","data":[{"symbol":"ETH/EUR","bids":[],"asks":[{"price":3501.02,"qty":26.33498922}],"checksum":1568207899,"timestamp":"2024-06-01T17:52:36.340250Z"}]}
{"channel":"book","type":"update","data":[{"symbol":"ETH/EUR","bids":[],"asks":[{"price":3501.02,"qty":0.00000000},{"price":3502.09,"qty":0.00757817}],"checksum":3745820514,"timestamp":"2024-06-01T17:52:36.346131Z"}]}
{"channel":"book","type":"update","data":[{"symbol":"ETH/EUR","bids":[],"asks":[{"price":3500.69,"qty":0.00000000},{"price":3502.10,"qty":3.95300000}],"checksum":2275858105,"timestamp":"2024-06-01T17:52:36.346274Z"}]}
{"channel":"book","type":"update","data":[{"symbol":"ETH/EUR","bids":[{"price":3500.20,"qty":0.08559800}],"asks":[],"checksum":1688718096,"timestamp":"2024-06-01T17:52:36.356209Z"}]}
{"channel":"book","type":"update","data":[{"symbol":"ETH/EUR","bids":[],"asks":[{"price":3501.18,"qty":0.00000000},{"price":3502.21,"qty":39.48916889}],"checksum":4098524761,"timestamp":"2024-06-01T17:52:36.356244Z"}]}
{"channel":"book","type":"update","data":[{"symbol":"ETH/EUR","bids":[],"asks":[{"price":3502.10,"qty":0.00000000},{"price":3502.45,"qty":3.01525282},{"price":3502.20,"qty":3.95300000}],"checksum":2440280488,"timestamp":"2024-06-01T17:52:36.359330Z"}]}
{"channel":"book","type":"update","data":[{"symbol":"ETH/EUR","bids":[{"price":3499.66,"qty":0.00000000},{"price":3499.40,"qty":1.49780000},{"price":3499.61,"qty":0.52710000}],"asks":[],"checksum":2691403487,"timestamp":"2024-06-01T17:52:36.359358Z"}]}
{"channel":"book","type":"update","data":[{"symbol":"ETH/EUR","bids":[{"price":3499.60,"qty":0.00000000},{"price":3499.40,"qty":1.49780000},{"price":3499.41,"qty":3.95300000}],"asks":[],"checksum":398810144,"timestamp":"2024-06-01T17:52:36.359510Z"}]}
{"channel":"book","type":"update","data":[{"symbol":"ETH/EUR","bids":[],"asks":[{"price":3501.50,"qty":26.33139264}],"checksum":3100526443,"timestamp":"2024-06-01T17:52:36.361362Z"}]}
{"channel":"book","type":"update","data":[{"symbol":"ETH/EUR","bids":[],"asks":[{"price":3501.50,"qty":0.00000000},{"price":3502.21,"qty":39.48916889}],"checksum":398810144,"timestamp":"2024-06-01T17:52:36.365781Z"}]}
{"channel":"book","type":"update","data":[{"symbol":"ETH/EUR","bids":[],"asks":[{"price":3500.64,"qty":26.33790647}],"checksum":2300537644,"timestamp":"2024-06-01T17:52:36.416994Z"}]}
{"channel":"book","type":"update","data":[{"symbol":"ETH/EUR","bids":[],"asks":[{"price":3501.51,"qty":0.00000000},{"price":3502.21,"qty":39.48916889},{"price":3501.07,"qty":0.08558800}],"checksum":3203051246,"timestamp":"2024-06-01T17:52:36.424420Z"}]}
{"channel":"book","type":"update","data":[{"symbol":"ETH/EUR","bids":[{"price":3500.20,"qty":0.00000000},{"price":3499.40,"qty":1.49780000},{"price":3499.82,"qty":0.08560200}],"asks":[],"checksum":3961642482,"timestamp":"2024-06-01T17:52:36.475083Z"}]}
{"channel":"book","type":"update","data":[{"symbol":"ETH/EUR","bids":[],"asks":[{"price":3502.20,"qty":9.68165327}],"checksum":1536911146,"timestamp":"2024-06-01T17:52:36.478485Z"}]}
{"channel":"book","type":"update","data":[{"symbol":"ETH/EUR","bids":[],"asks":[{"price":3500.71,"qty":26.33732842}],"checksum":2043962365,"timestamp":"2024-06-01T17:52:36.562844Z"}]}
{"channel":"book","type":"update","data":[{"symbol":"ETH/EUR","bids":[],"asks":[{"price":3500.90,"qty":26.33592514}],"checksum":4167767892,"timestamp":"2024-06-01T17:52:36.562986Z"}]}
{"channel":"book","type":"update","data":[{"symbol":"ETH/EUR","bids":[],"asks":[{"price":3501.07,"qty":0.00000000},{"price":3502.09,"qty":0.00757817},{"price":3501.57,"qty":0.08557900}],"checksum":1350866746,"timestamp":"2024-06-01T17:52:36.603342Z"}]}
{"channel":"book","type":"update","data":[{"symbol":"ETH/EUR","bids":[],"asks":[{"price":3500.64,"qty":0.00000000},{"price":3502.09,"qty":0.00757817}],"checksum":1057688908,"timestamp":"2024-06-01T17:52:36.607681Z"}]}
{"channel":"book","type":"update","data":[{"symbol":"ETH/EUR","bids":[],"asks":[{"price":3500.65,"qty":26.33784061}],"checksum":1168951426,"timestamp":"2024-06-01T17:52:36.616204Z"}]}
{"channel":"book","type":"update","data":[{"symbol":"ETH/EUR","bids":[],"asks":[{"price":3500.65,"qty":0.00000000},{"price":3502.09,"qty":0.00757817}],"checksum":1057688908,"timestamp":"2024-06-01T17:52:36.620084Z"}]}
{"channel":"book","type":"update","data":[{"symbol":"ETH/EUR","bids":[{"price":3500.33,"qty":2.00000000},{"price":3500.34,"qty":0.02859476}],"asks":[],"checksum":1767894115,"timestamp":"2024-06-01T17:52:36.622845Z"}]}
{"channel":"book","type":"update","data":[{"symbol":"ETH/EUR","bids":[],"asks":[{"price":3502.09,"qty":0.00000000},{"price":3502.20,"qty":5.72865327},{"price":3501.92,"qty":0.00757021}],"checksum":2496347274,"timestamp":"2024-06-01T17:52:36.622869Z"}]}
{"channel":"book","type":"update","data":[{"symbol":"ETH/EUR","bids":[],"asks":[{"price":3501.83,"qty":0.72700000}],"checksum":2342258699,"timestamp":"2024-06-01T17:52:36.627650Z"}]}
{"channel":"book","type":"update","data":[{"symbol":"ETH/EUR","bids":[],"asks":[{"price":3500.71,"qty":0.00000000},{"price":3502.08,"qty":0.00220000}],"checksum":2800454121,"timestamp":"2024-06-01T17:52:36.646707Z"}]}
{"channel":"book","type":"update","data":[{"symbol":"ETH/EUR","bids":[],"asks":[{"price":3500.90,"qty":0.00000000},{"price":3502.20,"qty":5.72865327}],"checksum":1253039032,"timestamp":"2024-06-01T17:52:36.651321Z"}]}
{"channel":"book","type":"update","data":[{"symbol":"ETH/EUR","bids":[],"asks":[{"price":3501.92,"qty":0.00000000},{"price":3502.21,"qty":39.48916889},{"price":3502.19,"qty":0.00757021}],"checksum":3135376456,"timestamp":"2024-06-01T17:52:36.678886Z"}]}
{"channel":"book","type":"update","data":[{"symbol":"ETH/EUR","bids":[],"asks":[{"price":3500.75,"qty":26.33706467}],"checksum":1747666140,"timestamp":"2024-06-01T17:52:36.678949Z"}]}
{"channel":"book","type":"update","data":[{"symbol":"ETH/EUR","bids":[],"asks":[{"price":3500.75,"qty":0.00000000},{"price":3502.20,"qty":5.72865327}],"checksum":3135376456,"timestamp":"2024-06-01T17:52:36.686515Z"}]}
{"channel":"book","type":"update","data":[{"symbol":"ETH/EUR","bids":[{"price":3500.35,"qty":26.34001267}],"asks":[],"checksum":2919063989,"timestamp":"2024-06-01T17:52:36.744355Z"}]}
{"channel":"book","type":"update","data":[{"symbol":"ETH/EUR","bids":[],"asks":[{"price":3500.71,"qty":26.33735693}],"checksum":3745825933,"timestamp":"2024-06-01T17:52:36.744377Z"}]}
{"channel":"book","type":"update","data":[{"symbol":"ETH/EUR","bids":[],"asks":[{"price":3501.56,"qty":0.72912968}],"checksum":3435593755,"timestamp":"2024-06-01T17:52:36.748985Z"}]}
{"channel":"book","type":"update","data":[{"symbol":"ETH/EUR","bids":[{"price":3500.01,"qty":0.00000000},{"price":3499.61,"qty":0.52710000}],"asks":[],"checksum":3940111325,"timestamp":"2024-06-01T17:52:36.749280Z"}]}
{"channel":"book","type":"update","data":[{"symbol":"ETH/EUR","bids":[{"price":3500.36,"qty":2.00000000}],"asks":[],"checksum":548051417,"timestamp":"2024-06-01T17:52:36.749849Z"}]}
{"channel":"book","type":"update","data":[{"symbol":"ETH/EUR","bids":[],"asks":[{"price":3500.71,"qty":0.00000000},{"price":3502.19,"qty":0.00757021}],"checksum":747038799,"timestamp":"2024-06-01T17:52:36.750961Z"}]}
{"channel":"book","type":"update","data":[{"symbol":"ETH/EUR","bids":[],"asks":[{"price":3501.55,"qty":26.33101815}],"checksum":3335932921,"timestamp":"2024-06-01T17:52:36.765728Z"}]}
{"channel":"book","type":"update","data":[{"symbol":"ETH/EUR","bids":[{"price":3500.35,"qty":27.68501267}],"asks":[],"checksum":3680316307,"timestamp":"2024-06-01T17:52:36.770958Z"}]}
{"channel":"book","type":"update","data":[{"symbol":"ETH/EUR","bids":[],"asks":[{"price":3501.55,"qty":0.00000000},{"price":3502.19,"qty":0.00757021}],"checksum":822970405,"timestamp":"2024-06-01T17:52:36.776496Z"}]}
{"channel":"book","type":"update","data":[{"symbol":"ETH/EUR","bids":[],"asks":[{"price":3501.85,"qty":0.00000000},{"price":3502.20,"qty":5.72865327}],"checksum":950076053,"timestamp":"2024-06-01T17:52:36.780322Z"}]}
{"channel":"book","type":"update","data":[{"symbol":"ETH/EUR","bids":[{"price":3500.33,"qty":0.00000000},{"price":3499.61,"qty":0.52710000}],"asks":[],"checksum":2593206013,"timestamp":"2024-06-01T17:52:36.782139Z"}]}
{"channel":"book","type":"update","data":[{"symbol":"ETH/EUR","bids":[],"asks":[{"price":3500.67,"qty":26.33769131}],"checksum":134447397,"timestamp":"2024-06-01T17:52:36.830788Z"}]}
{"channel":"book","type":"update","data":[{"symbol":"ETH/EUR","bids":[],"asks":[{"price":3500.67,"qty":0.00000000},{"price":3502.20,"qty":5.72865327}],"checksum":2593206013,"timestamp":"2024-06-01T17:52:36.845794Z"}]}
{"channel":"book","type":"update","data":[{"symbol":"ETH/EUR","bids":[{"price":3500.35,"qty":1.34500000}],"asks":[],"checksum":3343897636,"timestamp":"2024-06-01T17:52:36.845840Z"}]}
{"channel":"book","type":"update","data":[{"symbol":"ETH/EUR","bids":[{"price":3500.34,"qty":4.02859476}],"asks":[],"checksum":2821234749,"timestamp":"2024-06-01T17:52:36.849299Z"}]}
{"channel":"book","type":"update","data":[{"symbol":"ETH/EUR","bids":[{"price":3499.85,"qty":1.31730437}],"asks":[],"checksum":1834495709,"timestamp":"2024-06-01T17:52:36.849811Z"}]}
{"channel":"book","type":"update","data":[{"symbol":"ETH/EUR","bids":[{"price":3500.26,"qty":26.34064099}],"asks":[],"checksum":2718634014,"timestamp":"2024-06-01T17:52:36.856607Z"}]}
{"channel":"book","type":"update","data":[{"symbol":"ETH/EUR","bids":[],"asks":[{"price":3501.94,"qty":3.95300000}],"checksum":2905716855,"timestamp":"2024-06-01T17:52:36.860356Z"}]}
{"channel":"book","type":"update","data":[{"symbol":"ETH/EUR","bids":[],"asks":[{"price":3501.55,"qty":26.33101815}],"checksum":3961510611,"timestamp":"2024-06-01T17:52:36.862332Z"}]}
{"channel":"book","type":"update","data":[{"symbol":"ETH/EUR","bids":[{"price":3500.25,"qty":0.00000000},{"price":3499.77,"qty":0.72912968}],"asks":[],"checksum":2402619301,"timestamp":"2024-06-01T17:52:36.864618Z"}]}
{"channel":"book","type":"update","data":[{"symbol":"ETH/EUR","bids":[],"asks":[{"price":3501.54,"qty":0.72912968}],"checksum":4144663764,"timestamp":"2024-06-01T17:52:36.867073Z"}]}
{"channel":"book","type":"update","data":[{"symbol":"ETH/EUR","bids":[],"asks":[{"price":3501.55,"qty":0.00000000},{"price":3502.08,"qty":0.00220000}],"checksum":1233518991,"timestamp":"2024-06-01T17:52:36.867302Z"}]}
{"channel":"book","type":"update","data":[{"symbol":"ETH/EUR","bids":[],"asks":[{"price":3501.55,"qty":26.33101815}],"checksum":4144663764,"timestamp":"2024-06-01T17:52:36.867311Z"}]}
{"channel":"book","type":"update","data":[{"symbol":"ETH/EUR","bids":[{"price":3500.26,"qty":0.00000000},{"price":3499.61,"qty":0.52710000}],"asks":[],"checksum":1583102872,"timestamp":"2024-06-01T17:52:36.872872Z"}]}
{"channel":"book","type":"update","data":[{"symbol":"ETH/EUR","bids":[],"asks":[{"price":3501.55,"qty":0.00000000},{"price":3502.08,"qty":0.00220000}],"checksum":3417611017,"timestamp":"2024-06-01T17:52:36.872952Z"}]}
{"channel":"book","type":"update","data":[{"symbol":"ETH/EUR","bids":[],"asks":[{"price":3501.53,"qty":26.33116705}],"checksum":4041796700,"timestamp":"2024-06-01T17:52:36.884208Z"}]}
{"channel":"book","type":"update","data":[{"symbol":"ETH/EUR","bids":[],"asks":[{"price":3501.53,"qty":0.00000000},{"price":3502.08,"qty":0.00220000}],"checksum":3417611017,"timestamp":"2024-06-01T17:52:36.889116Z"}]}
{"channel":"book","type":"update","data":[{"symbol":"ETH/EUR","bids":[{"price":3500.28,"qty":26.34055116}],"asks":[],"checksum":2512788852,"timestamp":"2024-06-01T17:52:36.913810Z"}]}
{"channel":"book","type":"update","data":[{"symbol":"ETH/EUR","bids":[],"asks":[{"price":3501.54,"qty":0.00000000},{"price":3502.19,"qty":0.00757021}],"checksum":2037241845,"timestamp":"2024-06-01T17:52:36.917976Z"}]}
{"channel":"book","type":"update","data":[{"symbol":"ETH/EUR","bids":[],"asks":[{"price":3500.61,"qty":26.33811703}],"checksum":3887080103,"timestamp":"2024-06-01T17:52:36.935114Z"}]}
{"channel":"book","type":"update","data":[{"symbol":"ETH/EUR","bids":[],"asks":[{"price":3500.61,"qty":0.00000000},{"price":3502.19,"qty":0.00757021}],"checksum":2037241845,"timestamp":"2024-06-01T17:52:36.947851Z"}]}
{"channel":"book","type":"update","data":[{"symbol":"ETH/EUR","bids":[{"price":3500.28,"qty":0.00000000},{"price":3499.61,"qty":0.52710000}],"asks":[],"checksum":608361019,"timestamp":"2024-06-01T17:52:36.967019Z"}]}
{"channel":"book","type":"update","data":[{"symbol":"ETH/EUR","bids":[],"asks":[{"price":3501.55,"qty":26.33101815}],"checksum":3427645242,"timestamp":"2024-06-01T17:52:36.970333Z"}]}
{"channel":"book","type":"update","data":[{"symbol":"ETH/EUR","bids":[{"price":3500.16,"qty":26.34144753}],"asks":[],"checksum":2773751015,"timestamp":"2024-06-01T17:52:36.970456Z"}]}
{"channel":"book","type":"update","data":[{"symbol":"ETH/EUR","bids":[{"price":3500.24,"qty":26.34081607}],"asks":[],"checksum":3161142192,"timestamp":"2024-06-01T17:52:36.970495Z"}]}
{"channel":"book","type":"update","data":[{"symbol":"ETH/EUR","bids":[],"asks":[{"price":3501.55,"qty":0.00000000},{"price":3502.19,"qty":0.00757021}],"checksum":1838250531,"timestamp":"2024-06-01T17:52:36.974882Z"}]}
{"channel":"book","type":"update","data":[{"symbol":"ETH/EUR","bids":[{"price":3499.85,"qty":0.00000000},{"price":3499.77,"qty":0.72912968}],"asks":[],"checksum":4185266911,"timestamp":"2024-06-01T17:52:36.982065Z"}]}
{"channel":"book","type":"update","data":[{"symbol":"ETH/EUR","bids":[{"price":3500.18,"qty":1.35385073}],"asks":[],"checksum":2173197029,"timestamp":"2024-06-01T17:52:37.002013Z"}]}
{"channel":"book","type":"update","data":[{"symbol":"ETH/EUR","bids":[{"price":3500.32,"qty":0.00000000},{"price":3499.77,"qty":0.72912968}],"asks":[],"checksum":3315118230,"timestamp":"2024-06-01T17:52:37.030210Z"}]}
{"channel":"book","type":"update","data":[{"symbol":"ETH/EUR","bids":[{"price":3500.24,"qty":0.00000000},{"price":3499.61,"qty":0.52710000}],"asks":[],"checksum":3875761261,"timestamp":"2024-06-01T17:52:37.042979Z"}]}
{"channel":"book","type":"update","data":[{"symbol":"ETH/EUR","bids":[{"price":3500.25,"qty":26.34074233}],"asks":[],"checksum":2552183631,"timestamp":"2024-06-01T17:52:37.046543Z"}]}
{"channel":"book","type":"update","data":[{"symbol":"ETH/EUR","bids":[],"asks":[{"price":3500.59,"qty":26.33827004}],"checksum":288205533,"timestamp":"2024-06-01T17:52:37.070004Z"}]}
{"channel":"book","type":"update","data":[{"symbol":"ETH/EUR","bids":[{"price":3499.84,"qty":26.34383562}],"asks":[],"checksum":3514458329,"timestamp":"2024-06-01T17:52:37.070046Z"}]}
{"channel":"book","type":"update","data":[{"symbol":"ETH/EUR","bids":[{"price":3500.37,"qty":2.26500000}],"asks":[],"checksum":1811741914,"timestamp":"2024-06-01T17:52:37.091544Z"}]}
{"channel":"book","type":"update","data":[{"symbol":"ETH/EUR","bids":[{"price":3500.37,"qty":2.59278701}],"asks":[],"checksum":293401786,"timestamp":"2024-06-01T17:52:37.118517Z"}]}
{"channel":"book","type":"update","data":[{"symbol":"ETH/EUR","bids":[{"price":3500.38,"qty":2.00000000}],"asks":[],"checksum":2859833507,"timestamp":"2024-06-01T17:52:37.124195Z"}]}
{"channel":"book","type":"update","data":[{"symbol":"ETH/EUR","bids":[{"price":3500.36,"qty":0.00000000},{"price":3499.84,"qty":26.34383562}],"asks":[],"checksum":3130423230,"timestamp":"2024-06-01T17:52:37.131453Z"}]}
{"channel":"book","type":"update","data":[{"symbol":"ETH/EUR","bids":[{"price":3500.35,"qty":0.00000000},{"price":3499.82,"qty":0.08560200}],"asks":[],"checksum":2195081909,"timestamp":"2024-06-01T17:52:37.134724Z"}]}
{"channel":"book","type":"update","data":[{"symbol":"ETH/EUR","bids":[{"price":3500.25,"qty":0.00000000},{"price":3499.77,"qty":0.72912968}],"asks":[],"checksum":2346373653,"timestamp":"2024-06-01T17:52:37.294324Z"}]}
{"channel":"book","type":"update","data":[{"symbol":"ETH/EUR","bids":[{"price":3499.97,"qty":26.34286759}],"asks":[],"checksum":1803022349,"timestamp":"2024-06-01T17:52:37.298223Z"}]}
{"channel":"book","type":"update","data":[{"symbol":"ETH/EUR","bids":[],"asks":[{"price":3500.85,"qty":26.33628868}],"checksum":1706656138,"timestamp":"2024-06-01T17:52:37.298242Z"}]}
{"channel":"book","type":"update","data":[{"symbol":"ETH/EUR","bids":[],"asks":[{"price":3500.67,"qty":26.33769198}],"checksum":3913423491,"timestamp":"2024-06-01T17:52:37.298298Z"}]}
{"channel":"book","type":"update","data":[{"symbol":"ETH/EUR","bids":[],"asks":[{"price":3500.59,"qty":0.00000000},{"price":3501.94,"qty":3.95300000}],"checksum":1250656954,"timestamp":"2024-06-01T17:52:37.348753Z"}]}
{"channel":"book","type":"update","data":[{"symbol":"ETH/EUR","bids":[],"asks":[{"price":3500.59,"qty":26.33826002}],"checksum":4147984731,"timestamp":"2024-06-01T17:52:37.356068Z"}]}
{"channel":"book","type":"update","data":[{"symbol":"ETH/EUR","bids":[],"asks":[{"price":3500.67,"qty":0.00000000},{"price":3501.94,"qty":3.95300000}],"checksum":459813144,"timestamp":"2024-06-01T17:52:37.356303Z"}]}
{"channel":"book","type":"update","data":[{"symbol":"ETH/EUR","bids":[],"asks":[{"price":3501.12,"qty":26.33424582}],"checksum":2548110374,"timestamp":"2024-06-01T17:52:37.363607Z"}]}
{"channel":"book","type":"update","data":[{"symbol":"ETH/EUR","bids":[],"asks":[{"price":3500.56,"qty":26.33852059}],"checksum":3200302508,"timestamp":"2024-06-01T17:52:37.518135Z"}]}
{"channel":"book","type":"update","data":[{"symbol":"ETH/EUR","bids":[{"price":3500.34,"qty":4.00000000},{"price":3500.39,"qty":0.02859339}],"asks":[],"checksum":615644962,"timestamp":"2024-06-01T17:52:37.681768Z"}]}
{"channel":"book","type":"update","data":[{"symbol":"ETH/EUR","bids":[],"asks":[{"price":3501.86,"qty":0.00757020}],"checksum":1664098397,"timestamp":"2024-06-01T17:52:37.681979Z"}]}
{"channel":"book","type":"update","data":[{"symbol":"ETH/EUR","bids":[{"price":3500.18,"qty":0.00000000},{"price":3499.82,"qty":0.08560200}],"asks":[],"checksum":1603625061,"timestamp":"2024-06-01T17:52:37.819730Z"}]}
{"channel":"book","type":"update","data":[{"symbol":"ETH/EUR","bids":[],"asks":[{"price":3500.56,"qty":0.00000000},{"price":3501.87,"qty":1.60000000}],"checksum":2129930889,"timestamp":"2024-06-01T17:52:37.840855Z"}]}
{"channel":"book","type":"update","data":[{"symbol":"ETH/EUR","bids":[{"price":3499.84,"qty":0.00000000},{"price":3499.80,"qty":1.31740156}],"asks":[],"checksum":135334989,"timestamp":"2024-06-01T17:52:37.841022Z"}]}
{"channel":"book","type":"update","data":[{"symbol":"ETH/EUR","bids":[],"asks":[{"price":3500.52,"qty":26.33881772}],"checksum":3652547833,"timestamp":"2024-06-01T17:52:37.845857Z"}]}
{"channel":"book","type":"update","data":[{"symbol":"ETH/EUR","bids":[],"asks":[{"price":3500.59,"qty":0.00000000},{"price":3501.87,"qty":1.60000000}],"checksum":3488762402,"timestamp":"2024-06-01T17:52:37.847718Z"}]}
{"channel":"book","type":"update","data":[{"symbol":"ETH/EUR","bids":[],"asks":[{"price":3501.57,"qty":0.00000000},{"price":3501.93,"qty":7.43406479},{"price":3500.93,"qty":0.08559000}],"checksum":2525595860,"timestamp":"2024-06-01T17:52:37.855989Z"}]}
{"channel":"book","type":"update","data":[{"symbol":"ETH/EUR","bids":[],"asks":[{"price":3501.86,"qty":0.00000000},{"price":3501.93,"qty":7.43406479},{"price":3501.92,"qty":0.00757020}],"checksum":3574009325,"timestamp":"2024-06-01T17:52:37.894274Z"}]}
{"channel":"book","type":"update","data":[{"symbol":"ETH/EUR","bids":[{"price":3500.11,"qty":1.35387780}],"asks":[],"checksum":929955889,"timestamp":"2024-06-01T17:52:37.941617Z"}]}
{"channel":"book","type":"update","data":[{"symbol":"ETH/EUR","bids":[],"asks":[{"price":3501.59,"qty":0.00000000},{"price":3501.93,"qty":7.43406479}],"checksum":4196379042,"timestamp":"2024-06-01T17:52:37.951169Z"}]}
{"channel":"book","type":"update","data":[{"symbol":"ETH/EUR","bids":[],"asks":[{"price":3501.58,"qty":0.00000000},{"price":3502.08,"qty":0.00220000}],"checksum":2191359346,"timestamp":"2024-06-01T17:52:37.971894Z"}]}
{"channel":"book","type":"update","data":[{"symbol":"ETH/EUR","bids":[],"asks":[{"price":3501.56,"qty":0.00000000},{"price":3502.19,"qty":0.16676640}],"checksum":3822187266,"timestamp":"2024-06-01T17:52:37.974527Z"}]}
{"channel":"book","type":"update","data":[{"symbol":"ETH/EUR","bids":[],"asks":[{"price":3501.93,"qty":6.58762397}],"checksum":1651120276,"timestamp":"2024-06-01T17:52:37.974718Z"}]}
{"channel":"book","type":"update","data":[{"symbol":"ETH/EUR","bids":[],"asks":[{"price":3500.52,"qty":0.00000000},{"price":3502.20,"qty":5.72865327}],"checksum":3877215794,"timestamp":"2024-06-01T17:52:37.978796Z"}]}
{"channel":"book","type":"update","data":[{"symbol":"ETH/EUR","bids":[{"price":3500.40,"qty":0.84644082}],"asks":[],"checksum":2867593837,"timestamp":"2024-06-01T17:52:37.980759Z"}]}
{"channel":"book","type":"update","data":[{"symbol":"ETH/EUR","bids":[{"price":3500.17,"qty":6.00000000}],"asks":[],"checksum":3915335650,"timestamp":"2024-06-01T17:52:37.981957Z"}]}
{"channel":"book","type":"update","data":[{"symbol":"ETH/EUR","bids":[],"asks":[{"price":3500.85,"qty":0.00000000},{"price":3502.21,"qty":39.48916889}],"checksum":3266761566,"timestamp":"2024-06-01T17:52:37.982345Z"}]}
{"channel":"book","type":"update","data":[{"symbol":"ETH/EUR","bids":[{"price":3500.16,"qty":0.00000000},{"price":3499.89,"qty":0.84644082}],"asks":[],"checksum":937761830,"timestamp":"2024-06-01T17:52:37.988455Z"}]}
{"channel":"book","type":"update","data":[{"symbol":"ETH/EUR","bids":[],"asks":[{"price":3501.12,"qty":0.00000000},{"price":3502.44,"qty":0.60432639}],"checksum":3916569885,"timestamp":"2024-06-01T17:52:37.988481Z"}]}
{"channel":"book","type":"update","data":[{"symbol":"ETH/EUR","bids":[],"asks":[{"price":3502.21,"qty":0.00000000},{"price":3502.45,"qty":0.00220000}],"checksum":1774238946,"timestamp":"2024-06-01T17:52:37.988527Z"}]}
{"channel":"book","type":"update","data":[{"symbol":"ETH/EUR","bids":[],"asks":[{"price":3501.93,"qty":0.00000000},{"price":3502.57,"qty":0.00220000}],"checksum":1010580032,"timestamp":"2024-06-01T17:52:37.994606Z"}]}
{"channel":"book","type":"update","data":[{"symbol":"ETH/EUR","bids":[{"price":3500.92,"qty":6.58504480}],"asks":[],"checksum":388389831,"timestamp":"2024-06-01T17:52:37.995094Z"}]}
{"channel":"book","type":"update","data":[{"symbol":"ETH/EUR","bids":[{"price":3499.97,"qty":0.00000000},{"price":3499.89,"qty":0.84644082}],"asks":[],"checksum":1044770725,"timestamp":"2024-06-01T17:52:37.996071Z"}]}
{"channel":"book","type":"update","data":[{"symbol":"ETH/EUR","bids":[{"price":3500.11,"qty":0.00000000},{"price":3499.82,"qty":0.08560200}],"asks":[],"checksum":3625052972,"timestamp":"2024-06-01T17:52:38.004579Z"}]}
{"channel":"book","type":"update","data":[{"symbol":"ETH/EUR","bids":[{"price":3500.17,"qty":0.00000000},{"price":3499.80,"qty":1.31740156}],"asks":[],"checksum":793781061,"timestamp":"2024-06-01T17:52:38.016613Z"}]}
{"channel":"book","type":"update","data":[{"symbol":"ETH/EUR","bids":[],"asks":[{"price":3501.75,"qty":26.32951914}],"checksum":2802426277,"timestamp":"2024-06-01T17:52:38.021007Z"}]}
{"channel":"book","type":"update","data":[{"symbol":"ETH/EUR","bids":[],"asks":[{"price":3501.85,"qty":26.32880392}],"checksum":2981465202,"timestamp":"2024-06-01T17:52:38.021159Z"}]}
{"channel":"book","type":"update","data":[{"symbol":"ETH/EUR","bids":[{"price":3500.56,"qty":1.31740156}],"asks":[],"checksum":3974343560,"timestamp":"2024-06-01T17:52:38.022165Z"}]}
{"channel":"book","type":"update","data":[{"symbol":"ETH/EUR","bids":[{"price":3500.51,"qty":0.72912968}],"asks":[],"checksum":1841716021,"timestamp":"2024-06-01T17:52:38.026751Z"}]}
{"channel":"book","type":"update","data":[{"symbol":"ETH/EUR","bids":[],"asks":[{"price":3501.85,"qty":0.00000000},{"price":3502.45,"qty":0.00220000}],"checksum":1969725551,"timestamp":"2024-06-01T17:52:38.042793Z"}]}
{"channel":"book","type":"update","data":[{"symbol":"ETH/EUR","bids":[{"price":3499.89,"qty":0.00000000},{"price":3499.82,"qty":0.08560200}],"asks":[],"checksum":292237298,"timestamp":"2024-06-01T17:52:38.044539Z"}]}
{"channel":"book","type":"update","data":[{"symbol":"ETH/EUR","bids":[{"price":3500.92,"qty":7.43148562}],"asks":[],"checksum":2324946397,"timestamp":"2024-06-01T17:52:38.044728Z"}]}
{"channel":"book","type":"update","data":[{"symbol":"ETH/EUR","bids":[],"asks":[{"price":3501.99,"qty":26.32773309}],"checksum":106882742,"timestamp":"2024-06-01T17:52:38.048556Z"}]}
{"channel":"book","type":"update","data":[{"symbol":"ETH/EUR","bids":[],"asks":[{"price":3501.83,"qty":0.00000000},{"price":3502.45,"qty":0.00220000}],"checksum":1612626047,"timestamp":"2024-06-01T17:52:38.049227Z"}]}
{"channel":"book","type":"update","data":[{"symbol":"ETH/EUR","bids":[],"asks":[{"price":3501.68,"qty":26.33003139}],"checksum":1846206661,"timestamp":"2024-06-01T17:52:38.065229Z"}]}
{"channel":"book","type":"update","data":[{"symbol":"ETH/EUR","bids":[{"price":3500.39,"qty":0.52859339}],"asks":[],"checksum":1869057566,"timestamp":"2024-06-01T17:52:38.072623Z"}]}
{"channel":"book","type":"update","data":[{"symbol":"ETH/EUR","bids":[{"price":3500.92,"qty":9.43148562}],"asks":[],"checksum":759610739,"timestamp":"2024-06-01T17:52:38.076032Z"}]}
{"channel":"book","type":"update","data":[{"symbol":"ETH/EUR","bids":[],"asks":[{"price":3502.19,"qty":0.00000000},{"price":3502.45,"qty":0.00220000}],"checksum":229896293,"timestamp":"2024-06-01T17:52:38.077000Z"}]}
{"channel":"book","type":"update","data":[{"symbol":"ETH/EUR","bids":[{"price":3500.40,"qty":0.00000000},{"price":3499.43,"qty":3.95300000}],"asks":[],"checksum":3616047750,"timestamp":"2024-06-01T17:52:38.087465Z"}]}
{"channel":"book","type":"update","data":[{"symbol":"ETH/EUR","bids":[],"asks":[{"price":3501.68,"qty":0.00000000},{"price":3502.57,"qty":0.00220000}],"checksum":1071615801,"timestamp":"2024-06-01T17:52:38.097269Z"}]}
{"channel":"book","type":"update","data":[{"symbol":"ETH/EUR","bids":[{"price":3500.38,"qty":0.00000000},{"price":3499.42,"qty":0.52710000}],"asks":[],"checksum":397924134,"timestamp":"2024-06-01T17:52:38.106840Z"}]}
{"channel":"book","type":"update","data":[{"symbol":"ETH/EUR","bids":[],"asks":[{"price":3501.84,"qty":26.32888164}],"checksum":3911836589,"timestamp":"2024-06-01T17:52:38.142092Z"}]}
{"channel":"book","type":"update","data":[{"symbol":"ETH/EUR","bids":[],"asks":[{"price":3500.93,"qty":0.00000000},{"price":3502.57,"qty":0.00220000},{"price":3502.22,"qty":0.08557300}],"checksum":4045432615,"timestamp":"2024-06-01T17:52:38.144132Z"}]}
{"channel":"book","type":"update","data":[{"symbol":"ETH/EUR","bids":[{"price":3499.82,"qty":0.00000000},{"price":3499.40,"qty":0.49780000},{"price":3500.27,"qty":0.08559400}],"asks":[],"checksum":1009729466,"timestamp":"2024-06-01T17:52:38.145310Z"}]}
{"channel":"book","type":"update","data":[{"symbol":"ETH/EUR","bids":[{"price":3500.93,"qty":0.84644082}],"asks":[],"checksum":3123655483,"timestamp":"2024-06-01T17:52:38.156807Z"}]}
{"channel":"book","type":"update","data":[{"symbol":"ETH/EUR","bids":[{"price":3500.93,"qty":2.84644082}],"asks":[],"checksum":2321526827,"timestamp":"2024-06-01T17:52:38.176391Z"}]}
{"channel":"book","type":"update","data":[{"symbol":"ETH/EUR","bids":[],"asks":[{"price":3501.75,"qty":0.00000000},{"price":3502.57,"qty":0.00220000}],"checksum":2668730586,"timestamp":"2024-06-01T17:52:38.182190Z"}]}
{"channel":"book","type":"update","data":[{"symbol":"ETH/EUR","bids":[],"asks":[{"price":3501.87,"qty":0.00000000},{"price":3502.61,"qty":0.77800000}],"checksum":4287556415,"timestamp":"2024-06-01T17:52:38.185425Z"}]}
{"channel":"book","type":"update","data":[{"symbol":"ETH/EUR","bids":[{"price":3499.90,"qty":0.00000000},{"price":3499.42,"qty":0.52710000}],"asks":[],"checksum":130252044,"timestamp":"2024-06-01T17:52:38.185754Z"}]}
{"channel":"book","type":"update","data":[{"symbol":"ETH/EUR","bids":[{"price":3500.92,"qty":8.58504480}],"asks":[],"checksum":2035084365,"timestamp":"2024-06-01T17:52:38.187690Z"}]}
{"channel":"book","type":"update","data":[{"symbol":"ETH/EUR","bids":[],"asks":[{"price":3501.84,"qty":0.00000000},{"price":3502.63,"qty":0.72912968}],"checksum":3040503111,"timestamp":"2024-06-01T17:52:38.192106Z"}]}
{"channel":"book","type":"update","data":[{"symbol":"ETH/EUR","bids":[],"asks":[{"price":3501.77,"qty":26.32936452}],"checksum":195787100,"timestamp":"2024-06-01T17:52:38.192130Z"}]}
{"channel":"book","type":"update","data":[{"symbol":"ETH/EUR","bids":[],"asks":[{"price":3501.77,"qty":0.00000000},{"price":3502.63,"qty":0.72912968}],"checksum":3040503111,"timestamp":"2024-06-01T17:52:38.196688Z"}]}
{"channel":"book","type":"update","data":[{"symbol":"ETH/EUR","bids":[],"asks":[{"price":3501.99,"qty":0.00000000},{"price":3502.83,"qty":0.00220000}],"checksum":3530588991,"timestamp":"2024-06-01T17:52:38.204134Z"}]}
{"channel":"book","type":"update","data":[{"symbol":"ETH/EUR","bids":[{"price":3500.92,"qty":6.58504480}],"asks":[],"checksum":667042346,"timestamp":"2024-06-01T17:52:38.208726Z"}]}
{"channel":"book","type":"update","data":[{"symbol":"ETH/EUR","bids":[],"asks":[{"price":3501.92,"qty":0.00000000},{"price":3503.09,"qty":0.00220000},{"price":3502.56,"qty":0.00757020}],"checksum":2448502186,"timestamp":"2024-06-01T17:52:38.216904Z"}]}
{"channel":"book","type":"update","data":[{"symbol":"ETH/EUR","bids":[{"price":3500.94,"qty":0.66220830}],"asks":[],"checksum":27249864,"timestamp":"2024-06-01T17:52:38.220367Z"}]}
{"channel":"book","type":"update","data":[{"symbol":"ETH/EUR","bids":[{"price":3500.95,"qty":0.84644082}],"asks":[],"checksum":3969670986,"timestamp":"2024-06-01T17:52:38.230007Z"}]}
{"channel":"book","type":"update","data":[{"symbol":"ETH/EUR","bids":[],"asks":[{"price":3501.83,"qty":26.32894454}],"checksum":2475936338,"timestamp":"2024-06-01T17:52:38.238655Z"}]}
{"channel":"book","type":"update","data":[{"symbol":"ETH/EUR","bids":[{"price":3500.39,"qty":1.52859339}],"asks":[],"checksum":3534838343,"timestamp":"2024-06-01T17:52:38.238921Z"}]}
{"channel":"book","type":"update","data":[{"symbol":"ETH/EUR","bids":[],"asks":[{"price":3501.83,"qty":0.00000000},{"price":3502.83,"qty":0.00220000}],"checksum":3248672132,"timestamp":"2024-06-01T17:52:38.267805Z"}]}
{"channel":"book","type":"update","data":[{"symbol":"ETH/EUR","bids":[{"price":3500.93,"qty":2.00000000}],"asks":[],"checksum":2415793808,"timestamp":"2024-06-01T17:52:38.272714Z"}]}
{"channel":"book","type":"update","data":[{"symbol":"ETH/EUR","bids":[{"price":3500.37,"qty":0.32778701}],"asks":[],"checksum":2118581539,"timestamp":"2024-06-01T17:52:38.273626Z"}]}
{"channel":"book","type":"update","data":[{"symbol":"ETH/EUR","bids":[{"price":3500.95,"qty":2.19999378}],"asks":[],"checksum":4123043217,"timestamp":"2024-06-01T17:52:38.278461Z"}]}
{"channel":"book","type":"update","data":[{"symbol":"ETH/EUR","bids":[],"asks":[{"price":3501.84,"qty":26.32882343}],"checksum":1961598512,"timestamp":"2024-06-01T17:52:38.294691Z"}]}
{"channel":"book","type":"update","data":[{"symbol":"ETH/EUR","bids":[],"asks":[{"price":3502.56,"qty":0.00000000},{"price":3502.83,"qty":0.00220000},{"price":3502.82,"qty":0.00757386}],"checksum":881418803,"timestamp":"2024-06-01T17:52:38.295838Z"}]}
{"channel":"book","type":"update","data":[{"symbol":"ETH/EUR","bids":[{"price":3501.01,"qty":1.60000000}],"asks":[],"checksum":1593228976,"timestamp":"2024-06-01T17:52:38.322239Z"}]}
{"channel":"book","type":"update","data":[{"symbol":"ETH/EUR","bids":[{"price":3500.96,"qty":2.00000000}],"asks":[],"checksum":3482957026,"timestamp":"2024-06-01T17:52:38.327423Z"}]}
{"channel":"book","type":"update","data":[{"symbol":"ETH/EUR","bids":[{"price":3501.02,"qty":0.84644082}],"asks":[],"checksum":2882261858,"timestamp":"2024-06-01T17:52:38.328934Z"}]}
{"channel":"book","type":"update","data":[{"symbol":"ETH/EUR","bids":[],"asks":[{"price":3501.84,"qty":0.00000000},{"price":3502.83,"qty":0.00220000}],"checksum":3701388696,"timestamp":"2024-06-01T17:52:38.356689Z"}]}
{"channel":"book","type":"update","data":[{"symbol":"ETH/EUR","bids":[{"price":3500.95,"qty":1.35355296}],"asks":[],"checksum":2260593645,"timestamp":"2024-06-01T17:52:38.361563Z"}]}
{"channel":"book","type":"update","data":[{"symbol":"ETH/EUR","bids":[],"asks":[{"price":3501.87,"qty":26.32863393}],"checksum":3018609098,"timestamp":"2024-06-01T17:52:38.361826Z"}]}
{"channel":"book","type":"update","data":[{"symbol":"ETH/EUR","bids":[],"asks":[{"price":3501.92,"qty":26.32823606}],"checksum":2857601322,"timestamp":"2024-06-01T17:52:38.361845Z"}]}
{"channel":"book","type":"update","data":[{"symbol":"ETH/EUR","bids":[{"price":3500.96,"qty":0.00000000},{"price":3500.37,"qty":0.32778701}],"asks":[],"checksum":2594649932,"timestamp":"2024-06-01T17:52:38.361927Z"}]}
{"channel":"book","type":"update","data":[{"symbol":"ETH/EUR","bids":[],"asks":[{"price":3502.10,"qty":26.32688056}],"checksum":4138797901,"timestamp":"2024-06-01T17:52:38.361947Z"}]}
{"channel":"book","type":"update","data":[{"symbol":"ETH/EUR","bids":[],"asks":[{"price":3501.92,"qty":0.00000000},{"price":3502.63,"qty":0.72912968}],"checksum":2839365493,"timestamp":"2024-06-01T17:52:38.366499Z"}]}
{"channel":"book","type":"update","data":[{"symbol":"ETH/EUR","bids":[{"price":3501.03,"qty":2.60000000}],"asks":[],"checksum":7945104,"timestamp":"2024-06-01T17:52:38.369793Z"}]}
{"channel":"book","type":"update","data":[{"symbol":"ETH/EUR","bids":[],"asks":[{"price":3501.86,"qty":2.60000000}],"checksum":2506547209,"timestamp":"2024-06-01T17:52:38.369835Z"}]}
{"channel":"book","type":"update","data":[{"symbol":"ETH/EUR","bids":[],"asks":[{"price":3501.87,"qty":0.00000000},{"price":3502.63,"qty":0.72912968}],"checksum":2695060389,"timestamp":"2024-06-01T17:52:38.413068Z"}]}
{"channel":"book","type":"update","data":[{"symbol":"ETH/EUR","bids":[],"asks":[{"price":3501.90,"qty":26.32838793}],"checksum":1025042586,"timestamp":"2024-06-01T17:52:38.416727Z"}]}
{"channel":"book","type":"update","data":[{"symbol":"ETH/EUR","bids":[{"price":3501.04,"qty":2.00000000}],"asks":[],"checksum":3747299104,"timestamp":"2024-06-01T17:52:38.418273Z"}]}
{"channel":"book","type":"update","data":[{"symbol":"ETH/EUR","bids":[{"price":3501.04,"qty":2.84644082}],"asks":[],"checksum":3923461604,"timestamp":"2024-06-01T17:52:38.418776Z"}]}
{"channel":"book","type":"update","data":[{"symbol":"ETH/EUR","bids":[],"asks":[{"price":3501.90,"qty":0.00000000},{"price":3502.63,"qty":0.72912968}],"checksum":1952511707,"timestamp":"2024-06-01T17:52:38.492551Z"}]}
{"channel":"book","type":"update","data":[{"symbol":"ETH/EUR","bids":[],"asks":[{"price":3501.89,"qty":26.32848530}],"checksum":1364234658,"timestamp":"2024-06-01T17:52:38.496057Z"}]}
{"channel":"book","type":"update","data":[{"symbol":"ETH/EUR","bids":[{"price":3501.02,"qty":0.00000000},{"price":3500.39,"qty":1.52859339}],"asks":[],"checksum":2188246,"timestamp":"2024-06-01T17:52:38.497545Z"}]}
{"channel":"book","type":"update","data":[{"symbol":"ETH/EUR","bids":[{"price":3500.93,"qty":0.00000000},{"price":3500.37,"qty":0.32778701}],"asks":[],"checksum":3370728003,"timestamp":"2024-06-01T17:52:38.497570Z"}]}
{"channel":"book","type":"update","data":[{"symbol":"ETH/EUR","bids":[{"price":3500.40,"qty":0.52710000}],"asks":[],"checksum":1372776154,"timestamp":"2024-06-01T17:52:38.510162Z"}]}
{"channel":"book","type":"update","data":[{"symbol":"ETH/EUR","bids":[],"asks":[{"price":3501.89,"qty":0.00000000},{"price":3502.63,"qty":0.72912968}],"checksum":1961001379,"timestamp":"2024-06-01T17:52:38.549891Z"}]}
{"channel":"book","type":"update","data":[{"symbol":"ETH/EUR","bids":[],"asks":[{"price":3501.88,"qty":26.32856426}],"checksum":3487987277,"timestamp":"2024-06-01T17:52:38.553926Z"}]}
{"channel":"book","type":"update","data":[{"symbol":"ETH/EUR","bids":[],"asks":[{"price":3502.29,"qty":26.32545479}],"checksum":970319213,"timestamp":"2024-06-01T17:52:38.553961Z"}]}
{"channel":"book","type":"update","data":[{"symbol":"ETH/EUR","bids":[{"price":3501.05,"qty":0.11846684}],"asks":[],"checksum":3248541211,"timestamp":"2024-06-01T17:52:38.554494Z"}]}
{"channel":"book","type":"update","data":[{"symbol":"ETH/EUR","bids":[{"price":3501.05,"qty":0.00000000},{"price":3500.39,"qty":1.52859339}],"asks":[],"checksum":970319213,"timestamp":"2024-06-01T17:52:38.558549Z"}]}
{"channel":"book","type":"update","data":[{"symbol":"ETH/EUR","bids":[],"asks":[{"price":3501.95,"qty":26.32804658}],"checksum":1636068509,"timestamp":"2024-06-01T17:52:38.563066Z"}]}
{"channel":"book","type":"update","data":[{"symbol":"ETH/EUR","bids":[{"price":3500.39,"qty":2.02639339}],"asks":[],"checksum":2778974956,"timestamp":"2024-06-01T17:52:38.581497Z"}]}
{"channel":"book","type":"update","data":[{"symbol":"ETH/EUR","bids":[],"asks":[{"price":3501.86,"qty":0.00000000},{"price":3502.57,"qty":0.00220000}],"checksum":2012513687,"timestamp":"2024-06-01T17:52:38.595605Z"}]}
{"channel":"book","type":"update","data":[{"symbol":"ETH/EUR","bids":[{"price":3501.05,"qty":0.72912968}],"asks":[],"checksum":548621928,"timestamp":"2024-06-01T17:52:38.600904Z"}]}
{"channel":"book","type":"update","data":[{"symbol":"ETH/EUR","bids":[{"price":3500.92,"qty":22.39269728}],"asks":[],"checksum":2940580099,"timestamp":"2024-06-01T17:52:38.601620Z"}]}
{"channel":"book","type":"update","data":[{"symbol":"ETH/EUR","bids":[],"asks":[{"price":3501.88,"qty":0.00000000},{"price":3502.61,"qty":0.77800000}],"checksum":1673024478,"timestamp":"2024-06-01T17:52:38.606912Z"}]}
{"channel":"book","type":"update","data":[{"symbol":"ETH/EUR","bids":[],"asks":[{"price":3501.95,"qty":0.00000000},{"price":3502.63,"qty":0.72912968}],"checksum":1862237189,"timestamp":"2024-06-01T17:52:38.606947Z"}]}
{"channel":"book","type":"update","data":[{"symbol":"ETH/EUR","bids":[],"asks":[{"price":3502.10,"qty":0.00000000},{"price":3502.82,"qty":0.00757386}],"checksum":423558676,"timestamp":"2024-06-01T17:52:38.607485Z"}]}
{"channel":"book","type":"update","data":[{"symbol":"ETH/EUR","bids":[],"asks":[{"price":3502.01,"qty":26.32761601}],"checksum":3399789141,"timestamp":"2024-06-01T17:52:38.614999Z"}]}
{"channel":"book","type":"update","data":[{"symbol":"ETH/EUR","bids":[],"asks":[{"price":3501.94,"qty":26.32810257}],"checksum":2071833579,"timestamp":"2024-06-01T17:52:38.697249Z"}]}
{"channel":"book","type":"update","data":[{"symbol":"ETH/EUR","bids":[],"asks":[{"price":3501.94,"qty":0.00000000},{"price":3502.63,"qty":0.72912968}],"checksum":3399789141,"timestamp":"2024-06-01T17:52:38.703710Z"}]}
{"channel":"book","type":"update","data":[{"symbol":"ETH/EUR","bids":[{"price":3501.06,"qty":0.84644082}],"asks":[],"checksum":2011048251,"timestamp":"2024-06-01T17:52:38.705227Z"}]}
{"channel":"book","type":"update","data":[{"symbol":"ETH/EUR","bids":[{"price":3500.51,"qty":0.00000000},{"price":3500.40,"qty":0.52710000}],"asks":[],"checksum":168946939,"timestamp":"2024-06-01T17:52:38.709315Z"}]}
{"channel":"book","type":"update","data":[{"symbol":"ETH/EUR","bids":[{"price":3501.04,"qty":2.00000000}],"asks":[],"checksum":901676718,"timestamp":"2024-06-01T17:52:38.732508Z"}]}
{"channel":"book","type":"update","data":[{"symbol":"ETH/EUR","bids":[],"asks":[{"price":3501.96,"qty":26.32796308}],"checksum":3282046354,"timestamp":"2024-06-01T17:52:38.789365Z"}]}
{"channel":"book","type":"update","data":[{"symbol":"ETH/EUR","bids":[{"price":3501.07,"qty":0.72912968}],"asks":[],"checksum":1747435854,"timestamp":"2024-06-01T17:52:38.793357Z"}]}
{"channel":"book","type":"update","data":[{"symbol":"ETH/EUR","bids":[{"price":3501.03,"qty":28.93484288}],"asks":[],"checksum":2379613990,"timestamp":"2024-06-01T17:52:38.816628Z"}]}
{"channel":"book","type":"update","data":[{"symbol":"ETH/EUR","bids":[{"price":3501.57,"qty":26.33079384}],"asks":[],"checksum":3974421707,"timestamp":"2024-06-01T17:52:38.844683Z"}]}
{"channel":"book","type":"update","data":[{"symbol":"ETH/EUR","bids":[{"price":3501.07,"qty":0.00000000},{"price":3500.56,"qty":1.31740156}],"asks":[],"checksum":297870538,"timestamp":"2024-06-01T17:52:38.848721Z"}]}
{"channel":"book","type":"update","data":[{"symbol":"ETH/EUR","bids":[],"asks":[{"price":3501.96,"qty":0.00000000},{"price":3502.63,"qty":0.72912968}],"checksum":3266129822,"timestamp":"2024-06-01T17:52:38.872958Z"}]}
{"channel":"book","type":"update","data":[{"symbol":"ETH/EUR","bids":[{"price":3501.57,"qty":0.00000000},{"price":3500.40,"qty":0.52710000}],"asks":[],"checksum":1686228141,"timestamp":"2024-06-01T17:52:38.873035Z"}]}
{"channel":"book","type":"update","data":[{"symbol":"ETH/EUR","bids":[{"price":3501.03,"qty":2.60000000}],"asks":[],"checksum":901676718,"timestamp":"2024-06-01T17:52:38.877516Z"}]}
{"channel":"book","type":"update","data":[{"symbol":"ETH/EUR","bids":[],"asks":[{"price":3501.99,"qty":26.32775780}],"checksum":4180627945,"timestamp":"2024-06-01T17:52:38.880366Z"}]}
{"channel":"book","type":"update","data":[{"symbol":"ETH/EUR","bids":[{"price":3501.07,"qty":0.72912968}],"asks":[],"checksum":1386782005,"timestamp":"2024-06-01T17:52:38.881654Z"}]}
{"channel":"book","type":"update","data":[{"symbol":"ETH/EUR","bids":[],"asks":[{"price":3502.20,"qty":0.00000000},{"price":3502.63,"qty":0.72912968}],"checksum":83400024,"timestamp":"2024-06-01T17:52:38.897273Z"}]}
{"channel":"book","type":"update","data":[{"symbol":"ETH/EUR","bids":[{"price":3501.08,"qty":26.33453790}],"asks":[],"checksum":3272361322,"timestamp":"2024-06-01T17:52:38.923304Z"}]}
{"channel":"book","type":"update","data":[{"symbol":"ETH/EUR","bids":[{"price":3501.08,"qty":52.66907580}],"asks":[],"checksum":1969085782,"timestamp":"2024-06-01T17:52:38.923449Z"}]}
{"channel":"book","type":"update","data":[{"symbol":"ETH/EUR","bids":[{"price":3501.07,"qty":0.00000000},{"price":3500.56,"qty":1.31740156}],"asks":[],"checksum":2998062479,"timestamp":"2024-06-01T17:52:38.927161Z"}]}
{"channel":"book","type":"update","data":[{"symbol":"ETH/EUR","bids":[{"price":3501.09,"qty":0.84644082}],"asks":[],"checksum":1618597149,"timestamp":"2024-06-01T17:52:38.928313Z"}]}
{"channel":"book","type":"update","data":[{"symbol":"ETH/EUR","bids":[{"price":3501.09,"qty":2.84644082}],"asks":[],"checksum":1399259034,"timestamp":"2024-06-01T17:52:38.928488Z"}]}
{"channel":"book","type":"update","data":[{"symbol":"ETH/EUR","bids":[{"price":3501.08,"qty":26.33453790}],"asks":[],"checksum":1806554040,"timestamp":"2024-06-01T17:52:38.929095Z"}]}
{"channel":"book","type":"update","data":[{"symbol":"ETH/EUR","bids":[{"price":3501.08,"qty":0.00000000},{"price":3500.56,"qty":1.31740156}],"asks":[],"checksum":3018206196,"timestamp":"2024-06-01T17:52:38.929140Z"}]}
{"channel":"book","type":"update","data":[{"symbol":"ETH/EUR","bids":[],"asks":[{"price":3501.99,"qty":0.00000000},{"price":3502.82,"qty":0.00757386}],"checksum":956829688,"timestamp":"2024-06-01T17:52:38.966906Z"}]}
{"channel":"book","type":"update","data":[{"symbol":"ETH/EUR","bids":[{"price":3501.09,"qty":2.00000000}],"asks":[],"checksum":2771880235,"timestamp":"2024-06-01T17:52:38.971583Z"}]}
{"channel":"book","type":"update","data":[{"symbol":"ETH/EUR","bids":[{"price":3501.09,"qty":0.00000000},{"price":3500.40,"qty":0.52710000}],"asks":[],"checksum":613595551,"timestamp":"2024-06-01T17:52:38.971613Z"}]}
{"channel":"book","type":"update","data":[{"symbol":"ETH/EUR","bids":[],"asks":[{"price":3501.98,"qty":26.32783676}],"checksum":544996908,"timestamp":"2024-06-01T17:52:38.973027Z"}]}
{"channel":"book","type":"update","data":[{"symbol":"ETH/EUR","bids":[],"asks":[{"price":3501.98,"qty":0.00000000},{"price":3502.82,"qty":0.00757386}],"checksum":613595551,"timestamp":"2024-06-01T17:52:38.977017Z"}]}
{"channel":"book","type":"update","data":[{"symbol":"ETH/EUR","bids":[{"price":3501.59,"qty":26.33063591}],"asks":[],"checksum":942292276,"timestamp":"2024-06-01T17:52:38.980792Z"}]}
{"channel":"book","type":"update","data":[{"symbol":"ETH/EUR","bids":[],"asks":[{"price":3502.00,"qty":2.00000000}],"checksum":1405574574,"timestamp":"2024-06-01T17:52:39.014356Z"}]}
{"channel":"book","type":"update","data":[{"symbol":"ETH/EUR","bids":[{"price":3501.03,"qty":0.00000000},{"price":3500.40,"qty":0.52710000}],"asks":[],"checksum":1924963877,"timestamp":"2024-06-01T17:52:39.014419Z"}]}
{"channel":"book","type":"update","data":[{"symbol":"ETH/EUR","bids":[],"asks":[{"price":3501.99,"qty":26.32769481}],"checksum":2286409261,"timestamp":"2024-06-01T17:52:39.029615Z"}]}
{"channel":"book","type":"update","data":[{"symbol":"ETH/EUR","bids":[{"price":3501.51,"qty":26.33124438}],"asks":[],"checksum":880748602,"timestamp":"2024-06-01T17:52:39.029741Z"}]}
{"channel":"book","type":"update","data":[{"symbol":"ETH/EUR","bids":[],"asks":[{"price":3501.99,"qty":0.00000000},{"price":3502.63,"qty":0.72912968}],"checksum":2225181035,"timestamp":"2024-06-01T17:52:39.035150Z"}]}
{"channel":"book","type":"update","data":[{"symbol":"ETH/EUR","bids":[{"price":3501.08,"qty":4.00000000}],"asks":[],"checksum":3502973227,"timestamp":"2024-06-01T17:52:39.057504Z"}]}
{"channel":"book","type":"update","data":[{"symbol":"ETH/EUR","bids":[{"price":3501.59,"qty":0.00000000},{"price":3500.56,"qty":1.31740156}],"asks":[],"checksum":562322714,"timestamp":"2024-06-01T17:52:39.101040Z"}]}
{"channel":"book","type":"update","data":[{"symbol":"ETH/EUR","bids":[{"price":3501.60,"qty":26.33059379}],"asks":[],"checksum":2201573040,"timestamp":"2024-06-01T17:52:39.107451Z"}]}
{"channel":"book","type":"update","data":[{"symbol":"ETH/EUR","bids":[{"price":3501.51,"qty":0.00000000},{"price":3500.56,"qty":1.31740156}],"asks":[],"checksum":2681185439,"timestamp":"2024-06-01T17:52:39.107535Z"}]}
{"channel":"book","type":"update","data":[{"symbol":"ETH/EUR","bids":[],"asks":[{"price":3502.51,"qty":26.32385464}],"checksum":3665578184,"timestamp":"2024-06-01T17:52:39.107561Z"}]}
{"channel":"book","type":"update","data":[{"symbol":"ETH/EUR","bids":[],"asks":[{"price":3501.98,"qty":26.32780694}],"checksum":528026884,"timestamp":"2024-06-01T17:52:39.107575Z"}]}
{"channel":"book","type":"update","data":[{"symbol":"ETH/EUR","bids":[{"price":3501.60,"qty":0.00000000},{"price":3500.40,"qty":0.52710000}],"asks":[],"checksum":4162705963,"timestamp":"2024-06-01T17:52:39.121602Z"}]}
{"channel":"book","type":"update","data":[{"symbol":"ETH/EUR","bids":[{"price":3501.09,"qty":2.60000000}],"asks":[],"checksum":335037142,"timestamp":"2024-06-01T17:52:39.128486Z"}]}
{"channel":"book","type":"update","data":[{"symbol":"ETH/EUR","bids":[{"price":3501.09,"qty":4.60000000}],"asks":[],"checksum":972666341,"timestamp":"2024-06-01T17:52:39.131706Z"}]}
{"channel":"book","type":"update","data":[{"symbol":"ETH/EUR","bids":[{"price":3501.04,"qty":0.00000000},{"price":3500.40,"qty":0.52710000}],"asks":[],"checksum":2077756997,"timestamp":"2024-06-01T17:52:39.136333Z"}]}
{"channel":"book","type":"update","data":[{"symbol":"ETH/EUR","bids":[{"price":3501.10,"qty":0.84644082}],"asks":[],"checksum":4257454229,"timestamp":"2024-06-01T17:52:39.136902Z"}]}
{"channel":"book","type":"update","data":[{"symbol":"ETH/EUR","bids":[],"asks":[{"price":3501.98,"qty":0.00000000},{"price":3502.61,"qty":0.77800000}],"checksum":1406154406,"timestamp":"2024-06-01T17:52:39.177253Z"}]}
{"channel":"book","type":"update","data":[{"symbol":"ETH/EUR","bids":[],"asks":[{"price":3502.10,"qty":26.32691269}],"checksum":109474616,"timestamp":"2024-06-01T17:52:39.181764Z"}]}
{"channel":"book","type":"update","data":[{"symbol":"ETH/EUR","bids":[{"price":3501.62,"qty":26.33044113}],"asks":[],"checksum":3206059017,"timestamp":"2024-06-01T17:52:39.181936Z"}]}
{"channel":"book","type":"update","data":[{"symbol":"ETH/EUR","bids":[{"price":3501.06,"qty":0.00000000},{"price":3500.56,"qty":1.31740156}],"asks":[],"checksum":956751145,"timestamp":"2024-06-01T17:52:39.184618Z"}]}
{"channel":"book","type":"update","data":[{"symbol":"ETH/EUR","bids":[{"price":3501.62,"qty":0.00000000},{"price":3500.40,"qty":0.52710000}],"asks":[],"checksum":2738104357,"timestamp":"2024-06-01T17:52:39.207178Z"}]}
{"channel":"book","type":"update","data":[{"symbol":"ETH/EUR","bids":[],"asks":[{"price":3502.01,"qty":0.00000000},{"price":3502.61,"qty":0.77800000}],"checksum":35121236,"timestamp":"2024-06-01T17:52:39.207286Z"}]}
{"channel":"book","type":"update","data":[{"symbol":"ETH/EUR","bids":[],"asks":[{"price":3501.99,"qty":26.32769481}],"checksum":3730942878,"timestamp":"2024-06-01T17:52:39.212301Z"}]}
{"channel":"book","type":"update","data":[{"symbol":"ETH/EUR","bids":[],"asks":[{"price":3501.99,"qty":0.00000000},{"price":3502.61,"qty":0.77800000}],"checksum":35121236,"timestamp":"2024-06-01T17:52:39.228403Z"}]}
{"channel":"book","type":"update","data":[{"symbol":"ETH/EUR","bids":[{"price":3501.63,"qty":0.02855175}],"asks":[],"checksum":4269089693,"timestamp":"2024-06-01T17:52:39.232386Z"}]}
{"channel":"book","type":"update","data":[{"symbol":"ETH/EUR","bids":[],"asks":[{"price":3502.28,"qty":0.00757430}],"checksum":2579972609,"timestamp":"2024-06-01T17:52:39.232448Z"}]}
{"channel":"book","type":"update","data":[{"symbol":"ETH/EUR","bids":[{"price":3501.58,"qty":26.33070434}],"asks":[],"checksum":730619335,"timestamp":"2024-06-01T17:52:39.233782Z"}]}
{"channel":"book","type":"update","data":[{"symbol":"ETH/EUR","bids":[{"price":3501.32,"qty":26.33271334}],"asks":[],"checksum":2993070427,"timestamp":"2024-06-01T17:52:39.233800Z"}]}
{"channel":"book","type":"update","data":[{"symbol":"ETH/EUR","bids":[{"price":3501.51,"qty":26.33129176}],"asks":[],"checksum":4032768604,"timestamp":"2024-06-01T17:52:39.233946Z"}]}
{"channel":"book","type":"update","data":[{"symbol":"ETH/EUR","bids":[{"price":3501.58,"qty":0.00000000},{"price":3500.94,"qty":0.66220830}],"asks":[],"checksum":1900833415,"timestamp":"2024-06-01T17:52:39.425659Z"}]}
{"channel":"book","type":"update","data":[{"symbol":"ETH/EUR","bids":[],"asks":[{"price":3501.98,"qty":26.32780607}],"checksum":3441922478,"timestamp":"2024-06-01T17:52:39.429720Z"}]}
{"channel":"book","type":"update","data":[{"symbol":"ETH/EUR","bids":[{"price":3501.59,"qty":26.33064907}],"asks":[],"checksum":1107728298,"timestamp":"2024-06-01T17:52:39.429988Z"}]}
{"channel":"book","type":"update","data":[{"symbol":"ETH/EUR","bids":[{"price":3501.32,"qty":0.00000000},{"price":3500.94,"qty":0.66220830}],"asks":[],"checksum":3056339769,"timestamp":"2024-06-01T17:52:39.438816Z"}]}
{"channel":"book","type":"update","data":[{"symbol":"ETH/EUR","bids":[{"price":3501.09,"qty":2.00000000}],"asks":[],"checksum":3675179791,"timestamp":"2024-06-01T17:52:39.459215Z"}]}
{"channel":"book","type":"update","data":[{"symbol":"ETH/EUR","bids":[],"asks":[{"price":3502.00,"qty":0.00000000},{"price":3502.57,"qty":0.00220000}],"checksum":2056589737,"timestamp":"2024-06-01T17:52:39.459239Z"}]}
{"channel":"book","type":"update","data":[{"symbol":"ETH/EUR","bids":[{"price":3501.59,"qty":0.00000000},{"price":3500.92,"qty":22.39269728}],"asks":[],"checksum":3061192192,"timestamp":"2024-06-01T17:52:39.478167Z"}]}
{"channel":"book","type":"update","data":[{"symbol":"ETH/EUR","bids":[],"asks":[{"price":3501.98,"qty":0.00000000},{"price":3502.61,"qty":0.77800000}],"checksum":3530176365,"timestamp":"2024-06-01T17:52:39.478218Z"}]}
{"channel":"book","type":"update","data":[{"symbol":"ETH/EUR","bids":[],"asks":[{"price":3502.01,"qty":26.32755817}],"checksum":3187883412,"timestamp":"2024-06-01T17:52:39.485674Z"}]}
{"channel":"book","type":"update","data":[{"symbol":"ETH/EUR","bids":[],"asks":[{"price":3502.01,"qty":0.00000000},{"price":3502.61,"qty":0.77800000}],"checksum":3530176365,"timestamp":"2024-06-01T17:52:39.584722Z"}]}
{"channel":"book","type":"update","data":[{"symbol":"ETH/EUR","bids":[],"asks":[{"price":3502.00,"qty":26.32766870}],"checksum":2991163203,"timestamp":"2024-06-01T17:52:39.590050Z"}]}
{"channel":"book","type":"update","data":[{"symbol":"ETH/EUR","bids":[],"asks":[{"price":3502.00,"qty":0.00000000},{"price":3502.61,"qty":0.77800000}],"checksum":3530176365,"timestamp":"2024-06-01T17:52:39.630648Z"}]}
{"channel":"book","type":"update","data":[{"symbol":"ETH/EUR","bids":[],"asks":[{"price":3502.10,"qty":0.00000000},{"price":3502.63,"qty":0.72912968}],"checksum":62820028,"timestamp":"2024-06-01T17:52:39.634945Z"}]}
{"channel":"book","type":"update","data":[{"symbol":"ETH/EUR","bids":[],"asks":[{"price":3502.07,"qty":26.32709339}],"checksum":2202412941,"timestamp":"2024-06-01T17:52:39.638644Z"}]}
{"channel":"book","type":"update","data":[{"symbol":"ETH/EUR","bids":[],"asks":[{"price":3501.99,"qty":26.32772925}],"checksum":1381123442,"timestamp":"2024-06-01T17:52:39.642659Z"}]}
{"channel":"book","type":"update","data":[{"symbol":"ETH/EUR","bids":[],"asks":[{"price":3501.98,"qty":2.00000000}],"checksum":915754941,"timestamp":"2024-06-01T17:52:39.741548Z"}]}
{"channel":"book","type":"update","data":[{"symbol":"ETH/EUR","bids":[],"asks":[{"price":3501.99,"qty":0.00000000},{"price":3502.57,"qty":0.00220000}],"checksum":2057725384,"timestamp":"2024-06-01T17:52:39.878142Z"}]}
{"channel":"book","type":"update","data":[{"symbol":"ETH/EUR","bids":[],"asks":[{"price":3502.02,"qty":26.32749303}],"checksum":991935722,"timestamp":"2024-06-01T17:52:39.882450Z"}]}
{"channel":"book","type":"update","data":[{"symbol":"ETH/EUR","bids":[],"asks":[{"price":3502.02,"qty":0.00000000},{"price":3502.57,"qty":0.00220000}],"checksum":2057725384,"timestamp":"2024-06-01T17:52:39.959129Z"}]}
{"channel":"book","type":"update","data":[{"symbol":"ETH/EUR","bids":[],"asks":[{"price":3502.16,"qty":26.32643504}],"checksum":3044017543,"timestamp":"2024-06-01T17:52:39.963988Z"}]}
{"channel":"book","type":"update","data":[{"symbol":"ETH/EUR","bids":[],"asks":[{"price":3502.28,"qty":0.00000000},{"price":3502.57,"qty":0.00220000},{"price":3502.15,"qty":0.00757428}],"checksum":2785683148,"timestamp":"2024-06-01T17:52:40.332413Z"}]}
{"channel":"book","type":"update","data":[{"symbol":"ETH/EUR","bids":[{"price":3501.63,"qty":0.00000000},{"price":3500.56,"qty":1.31740156},{"price":3501.52,"qty":0.02855264}],"asks":[],"checksum":2197201032,"timestamp":"2024-06-01T17:52:40.332592Z"}]}
{"channel":"book","type":"update","data":[{"symbol":"ETH/EUR","bids":[],"asks":[{"price":3502.07,"qty":0.00000000},{"price":3502.57,"qty":0.00220000}],"checksum":2799316362,"timestamp":"2024-06-01T17:52:40.358870Z"}]}
{"channel":"book","type":"update","data":[{"symbol":"ETH/EUR","bids":[],"asks":[{"price":3502.06,"qty":26.32723553}],"checksum":3788691962,"timestamp":"2024-06-01T17:52:40.362200Z"}]}
{"channel":"book","type":"update","data":[{"symbol":"ETH/EUR","bids":[{"price":3501.53,"qty":26.33115351}],"asks":[],"checksum":3472610889,"timestamp":"2024-06-01T17:52:40.478529Z"}]}
{"channel":"book","type":"update","data":[{"symbol":"ETH/EUR","bids":[{"price":3501.75,"qty":26.32945468}],"asks":[],"checksum":802621859,"timestamp":"2024-06-01T17:52:40.478562Z"}]}
{"channel":"book","type":"update","data":[{"symbol":"ETH/EUR","bids":[{"price":3501.53,"qty":0.00000000},{"price":3500.94,"qty":0.66220830}],"asks":[],"checksum":278372681,"timestamp":"2024-06-01T17:52:40.485706Z"}]}
{"channel":"book","type":"update","data":[{"symbol":"ETH/EUR","bids":[],"asks":[{"price":3501.98,"qty":0.00000000},{"price":3502.57,"qty":0.00220000}],"checksum":2280530479,"timestamp":"2024-06-01T17:52:40.485872Z"}]}
{"channel":"book","type":"update","data":[{"symbol":"ETH/EUR","bids":[{"price":3501.23,"qty":0.08558900}],"asks":[],"checksum":1034210646,"timestamp":"2024-06-01T17:52:40.508312Z"}]}
{"channel":"book","type":"update","data":[{"symbol":"ETH/EUR","bids":[{"price":3501.75,"qty":0.00000000},{"price":3500.94,"qty":0.66220830}],"asks":[],"checksum":100248429,"timestamp":"2024-06-01T17:52:40.517601Z"}]}
{"channel":"book","type":"update","data":[{"symbol":"ETH/EUR","bids":[],"asks":[{"price":3502.15,"qty":0.00000000},{"price":3502.61,"qty":0.77800000},{"price":3502.50,"qty":0.00757501}],"checksum":2404879186,"timestamp":"2024-06-01T17:52:40.540101Z"}]}
{"channel":"book","type":"update","data":[{"symbol":"ETH/EUR","bids":[{"price":3501.54,"qty":3.06500000}],"asks":[],"checksum":387233818,"timestamp":"2024-06-01T17:52:40.603675Z"}]}
{"channel":"book","type":"update","data":[{"symbol":"ETH/EUR","bids":[{"price":3501.76,"qty":26.32935203}],"asks":[],"checksum":348512905,"timestamp":"2024-06-01T17:52:40.608449Z"}]}
{"channel":"book","type":"update","data":[{"symbol":"ETH/EUR","bids":[{"price":3501.05,"qty":0.00000000},{"price":3500.95,"qty":1.35355296}],"asks":[],"checksum":4249966031,"timestamp":"2024-06-01T17:52:40.780264Z"}]}
{"channel":"book","type":"update","data":[{"symbol":"ETH/EUR","bids":[{"price":3501.16,"qty":15.80353051}],"asks":[],"checksum":3735733291,"timestamp":"2024-06-01T17:52:40.786162Z"}]}
{"channel":"book","type":"update","data":[{"symbol":"ETH/EUR","bids":[{"price":3501.76,"qty":0.00000000},{"price":3500.95,"qty":1.35355296}],"asks":[],"checksum":2739452619,"timestamp":"2024-06-01T17:52:40.787773Z"}]}
{"channel":"book","type":"update","data":[{"symbol":"ETH/EUR","bids":[],"asks":[{"price":3502.06,"qty":0.00000000},{"price":3502.61,"qty":0.77800000}],"checksum":666522497,"timestamp":"2024-06-01T17:52:40.787786Z"}]}
{"channel":"book","type":"update","data":[{"symbol":"ETH/EUR","bids":[],"asks":[{"price":3502.29,"qty":0.00000000},{"price":3502.63,"qty":0.72912968}],"checksum":3648915506,"timestamp":"2024-06-01T17:52:40.787816Z"}]}
{"channel":"book","type":"update","data":[{"symbol":"ETH/EUR","bids":[],"asks":[{"price":3501.89,"qty":26.32851903}],"checksum":3377658894,"timestamp":"2024-06-01T17:52:40.794484Z"}]}
{"channel":"book","type":"update","data":[{"symbol":"ETH/EUR","bids":[{"price":3501.59,"qty":26.33067908}],"asks":[],"checksum":1190561101,"timestamp":"2024-06-01T17:52:40.794537Z"}]}
{"channel":"book","type":"update","data":[{"symbol":"ETH/EUR","bids":[],"asks":[{"price":3502.05,"qty":26.32724374}],"checksum":600018192,"timestamp":"2024-06-01T17:52:40.794797Z"}]}
{"channel":"book","type":"update","data":[{"symbol":"ETH/EUR","bids":[{"price":3501.35,"qty":26.33246301}],"asks":[],"checksum":1392497017,"timestamp":"2024-06-01T17:52:40.794880Z"}]}
{"channel":"book","type":"update","data":[{"symbol":"ETH/EUR","bids":[{"price":3501.59,"qty":0.00000000},{"price":3501.01,"qty":1.60000000}],"asks":[],"checksum":4267567259,"timestamp":"2024-06-01T17:52:40.874192Z"}]}
{"channel":"book","type":"update","data":[{"symbol":"ETH/EUR","bids":[],"asks":[{"price":3502.16,"qty":0.00000000},{"price":3502.61,"qty":0.77800000}],"checksum":4201469902,"timestamp":"2024-06-01T17:52:40.874231Z"}]}
{"channel":"book","type":"update","data":[{"symbol":"ETH/EUR","bids":[],"asks":[{"price":3501.83,"qty":26.32893223}],"checksum":3592355696,"timestamp":"2024-06-01T17:52:40.879067Z"}]}
{"channel":"book","type":"update","data":[{"symbol":"ETH/EUR","bids":[{"price":3501.53,"qty":26.33109231}],"asks":[],"checksum":3276753989,"timestamp":"2024-06-01T17:52:40.879265Z"}]}
{"channel":"book","type":"update","data":[{"symbol":"ETH/EUR","bids":[{"price":3501.53,"qty":0.00000000},{"price":3501.01,"qty":1.60000000}],"asks":[],"checksum":3592355696,"timestamp":"2024-06-01T17:52:40.887938Z"}]}
{"channel":"book","type":"update","data":[{"symbol":"ETH/EUR","bids":[],"asks":[{"price":3501.83,"qty":0.00000000},{"price":3502.61,"qty":0.77800000}],"checksum":4201469902,"timestamp":"2024-06-01T17:52:40.937801Z"}]}
{"channel":"book","type":"update","data":[{"symbol":"ETH/EUR","bids":[],"asks":[{"price":3501.81,"qty":26.32904946}],"checksum":443943328,"timestamp":"2024-06-01T17:52:40.942120Z"}]}
{"channel":"book","type":"update","data":[{"symbol":"ETH/EUR","bids":[{"price":3501.55,"qty":4.34500000}],"asks":[],"checksum":4081691798,"timestamp":"2024-06-01T17:52:40.985921Z"}]}
{"channel":"book","type":"update","data":[{"symbol":"ETH/EUR","bids":[{"price":3501.35,"qty":0.00000000},{"price":3501.01,"qty":1.60000000}],"asks":[],"checksum":1143807153,"timestamp":"2024-06-01T17:52:40.990605Z"}]}
{"channel":"book","type":"update","data":[{"symbol":"ETH/EUR","bids":[{"price":3501.51,"qty":0.00000000},{"price":3500.94,"qty":0.66220830}],"asks":[],"checksum":2615834696,"timestamp":"2024-06-01T17:52:40.990635Z"}]}
{"channel":"book","type":"update","data":[{"symbol":"ETH/EUR","bids":[],"asks":[{"price":3502.51,"qty":0.00000000},{"price":3502.61,"qty":0.77800000}],"checksum":3103493702,"timestamp":"2024-06-01T17:52:40.990765Z"}]}
{"channel":"book","type":"update","data":[{"symbol":"ETH/EUR","bids":[],"asks":[{"price":3501.81,"qty":0.00000000},{"price":3502.63,"qty":0.72912968}],"checksum":1508204438,"timestamp":"2024-06-01T17:52:40.990785Z"}]}
{"channel":"book","type":"update","data":[{"symbol":"ETH/EUR","bids":[{"price":3501.29,"qty":1.60000000}],"asks":[],"checksum":2852603735,"timestamp":"2024-06-01T17:52:40.993433Z"}]}
{"channel":"book","type":"update","data":[{"symbol":"ETH/EUR","bids":[{"price":3501.01,"qty":0.00000000},{"price":3500.94,"qty":0.66220830}],"asks":[],"checksum":1839083572,"timestamp":"2024-06-01T17:52:40.993457Z"}]}
{"channel":"book","type":"update","data":[{"symbol":"ETH/EUR","bids":[],"asks":[{"price":3502.34,"qty":26.32510032}],"checksum":2704937059,"timestamp":"2024-06-01T17:52:40.995828Z"}]}
{"channel":"book","type":"update","data":[{"symbol":"ETH/EUR","bids":[],"asks":[{"price":3501.82,"qty":26.32899531}],"checksum":876326858,"timestamp":"2024-06-01T17:52:40.995930Z"}]}
{"channel":"book","type":"update","data":[{"symbol":"ETH/EUR","bids":[{"price":3501.51,"qty":26.33125507}],"asks":[],"checksum":304217391,"timestamp":"2024-06-01T17:52:40.995947Z"}]}
{"channel":"book","type":"update","data":[{"symbol":"ETH/EUR","bids":[{"price":3501.09,"qty":28.33446268}],"asks":[],"checksum":3858892595,"timestamp":"2024-06-01T17:52:40.995978Z"}]}
{"channel":"book","type":"update","data":[{"symbol":"ETH/EUR","bids":[{"price":3501.51,"qty":0.00000000},{"price":3501.06,"qty":1.35351043}],"asks":[],"checksum":2933498589,"timestamp":"2024-06-01T17:52:41.040921Z"}]}
{"channel":"book","type":"update","data":[{"symbol":"ETH/EUR","bids":[{"price":3501.54,"qty":0.00000000},{"price":3500.94,"qty":0.66220830}],"asks":[],"checksum":3547761619,"timestamp":"2024-06-01T17:52:41.049803Z"}]}
{"channel":"book","type":"update","data":[{"symbol":"ETH/EUR","bids":[],"asks":[{"price":3501.82,"qty":0.00000000},{"price":3502.61,"qty":0.77800000}],"checksum":2095681824,"timestamp":"2024-06-01T17:52:41.094091Z"}]}
{"channel":"book","type":"update","data":[{"symbol":"ETH/EUR","bids":[],"asks":[{"price":3501.85,"qty":26.32881634}],"checksum":1308548505,"timestamp":"2024-06-01T17:52:41.098793Z"}]}
{"channel":"book","type":"update","data":[{"symbol":"ETH/EUR","bids":[{"price":3501.25,"qty":26.33324380}],"asks":[],"checksum":661971660,"timestamp":"2024-06-01T17:52:41.098940Z"}]}
{"channel":"book","type":"update","data":[{"symbol":"ETH/EUR","bids":[{"price":3501.54,"qty":26.33104187}],"asks":[],"checksum":1878303318,"timestamp":"2024-06-01T17:52:41.098976Z"}]}
{"channel":"book","type":"update","data":[{"symbol":"ETH/EUR","bids":[{"price":3501.54,"qty":0.00000000},{"price":3501.06,"qty":1.35351043}],"asks":[],"checksum":661971660,"timestamp":"2024-06-01T17:52:41.124546Z"}]}
{"channel":"book","type":"update","data":[{"symbol":"ETH/EUR","bids":[{"price":3501.30,"qty":4.00000000}],"asks":[],"checksum":3499487767,"timestamp":"2024-06-01T17:52:41.239492Z"}]}
{"channel":"book","type":"update","data":[{"symbol":"ETH/EUR","bids":[{"price":3501.29,"qty":0.00000000},{"price":3501.06,"qty":1.35351043}],"asks":[],"checksum":1320116363,"timestamp":"2024-06-01T17:52:41.242247Z"}]}
{"channel":"book","type":"update","data":[{"symbol":"ETH/EUR","bids":[{"price":3501.36,"qty":1.60000000}],"asks":[],"checksum":224075462,"timestamp":"2024-06-01T17:52:41.242626Z"}]}
{"channel":"book","type":"update","data":[{"symbol":"ETH/EUR","bids":[],"asks":[{"price":3501.84,"qty":2.00000000}],"checksum":2056941951,"timestamp":"2024-06-01T17:52:41.281161Z"}]}
{"channel":"book","type":"update","data":[{"symbol":"ETH/EUR","bids":[],"asks":[{"price":3501.85,"qty":0.00000000},{"price":3502.57,"qty":0.00220000}],"checksum":1352669928,"timestamp":"2024-06-01T17:52:41.282858Z"}]}
{"channel":"book","type":"update","data":[{"symbol":"ETH/EUR","bids":[{"price":3501.53,"qty":26.33113926}],"asks":[],"checksum":1750573470,"timestamp":"2024-06-01T17:52:41.287014Z"}]}
{"channel":"book","type":"update","data":[{"symbol":"ETH/EUR","bids":[],"asks":[{"price":3501.83,"qty":26.32891372}],"checksum":756603391,"timestamp":"2024-06-01T17:52:41.287043Z"}]}
{"channel":"book","type":"update","data":[{"symbol":"ETH/EUR","bids":[],"asks":[{"price":3501.84,"qty":0.00000000},{"price":3502.57,"qty":0.00220000}],"checksum":27774033,"timestamp":"2024-06-01T17:52:41.336316Z"}]}
{"channel":"book","type":"update","data":[{"symbol":"ETH/EUR","bids":[],"asks":[{"price":3502.50,"qty":0.00000000},{"price":3502.61,"qty":0.77800000},{"price":3502.60,"qty":0.00757500}],"checksum":1720899264,"timestamp":"2024-06-01T17:52:41.391413Z"}]}
{"channel":"book","type":"update","data":[{"symbol":"ETH/EUR","bids":[{"price":3501.52,"qty":0.00000000},{"price":3501.08,"qty":4.00000000},{"price":3501.56,"qty":0.02854926}],"asks":[],"checksum":3625752795,"timestamp":"2024-06-01T17:52:41.426815Z"}]}
{"channel":"book","type":"update","data":[{"symbol":"ETH/EUR","bids":[],"asks":[{"price":3501.83,"qty":0.00000000},{"price":3502.61,"qty":0.77800000}],"checksum":473000325,"timestamp":"2024-06-01T17:52:41.731173Z"}]}
{"channel":"book","type":"update","data":[{"symbol":"ETH/EUR","bids":[],"asks":[{"price":3501.86,"qty":26.32869555}],"checksum":3927516641,"timestamp":"2024-06-01T17:52:41.736045Z"}]}
{"channel":"book","type":"update","data":[{"symbol":"ETH/EUR","bids":[{"price":3501.53,"qty":0.00000000},{"price":3501.06,"qty":1.35351043}],"asks":[],"checksum":2357502998,"timestamp":"2024-06-01T17:52:41.745459Z"}]}
{"channel":"book","type":"update","data":[{"symbol":"ETH/EUR","bids":[],"asks":[{"price":3501.86,"qty":0.00000000},{"price":3502.61,"qty":0.77800000}],"checksum":502176707,"timestamp":"2024-06-01T17:52:41.792323Z"}]}
{"channel":"book","type":"update","data":[{"symbol":"ETH/EUR","bids":[],"asks":[{"price":3502.05,"qty":0.00000000},{"price":3502.63,"qty":0.72912968}],"checksum":922008026,"timestamp":"2024-06-01T17:52:41.795335Z"}]}
{"channel":"book","type":"update","data":[{"symbol":"ETH/EUR","bids":[],"asks":[{"price":3501.87,"qty":26.32865353}],"checksum":2676048670,"timestamp":"2024-06-01T17:52:41.798806Z"}]}
{"channel":"book","type":"update","data":[{"symbol":"ETH/EUR","bids":[],"asks":[{"price":3502.17,"qty":26.32640402}],"checksum":991040377,"timestamp":"2024-06-01T17:52:41.798821Z"}]}
{"channel":"book","type":"update","data":[{"symbol":"ETH/EUR","bids":[],"asks":[{"price":3501.87,"qty":0.00000000},{"price":3502.61,"qty":0.77800000}],"checksum":426921221,"timestamp":"2024-06-01T17:52:42.343337Z"}]}
{"channel":"book","type":"update","data":[{"symbol":"ETH/EUR","bids":[],"asks":[{"price":3501.91,"qty":26.32832195}],"checksum":2200670696,"timestamp":"2024-06-01T17:52:42.347734Z"}]}
{"channel":"book","type":"update","data":[{"symbol":"ETH/EUR","bids":[{"price":3501.57,"qty":0.32778701}],"asks":[],"checksum":2605191826,"timestamp":"2024-06-01T17:52:42.500333Z"}]}
{"channel":"book","type":"update","data":[{"symbol":"ETH/EUR","bids":[{"price":3501.31,"qty":6.00000000}],"asks":[],"checksum":1447007388,"timestamp":"2024-06-01T17:52:42.504785Z"}]}
{"channel":"book","type":"update","data":[{"symbol":"ETH/EUR","bids":[{"price":3501.56,"qty":0.00000000},{"price":3501.09,"qty":28.33446268},{"price":3501.58,"qty":0.02855186}],"asks":[],"checksum":3855055275,"timestamp":"2024-06-01T17:52:42.544915Z"}]}
{"channel":"book","type":"update","data":[{"symbol":"ETH/EUR","bids":[{"price":3501.31,"qty":0.00000000},{"price":3501.09,"qty":28.33446268}],"asks":[],"checksum":591810416,"timestamp":"2024-06-01T17:52:42.549544Z"}]}
{"channel":"book","type":"update","data":[{"symbol":"ETH/EUR","bids":[{"price":3501.30,"qty":0.00000000},{"price":3501.06,"qty":1.35351043}],"asks":[],"checksum":3565623582,"timestamp":"2024-06-01T17:52:42.714261Z"}]}
{"channel":"book","type":"update","data":[{"symbol":"ETH/EUR","bids":[{"price":3501.55,"qty":0.00000000},{"price":3500.94,"qty":0.66220830}],"asks":[],"checksum":1885499648,"timestamp":"2024-06-01T17:52:42.740895Z"}]}
{"channel":"book","type":"update","data":[{"symbol":"ETH/EUR","bids":[],"asks":[{"price":3501.91,"qty":0.00000000},{"price":3502.61,"qty":0.77800000}],"checksum":2087055695,"timestamp":"2024-06-01T17:52:43.078504Z"}]}
{"channel":"book","type":"update","data":[{"symbol":"ETH/EUR","bids":[],"asks":[{"price":3501.89,"qty":0.00000000},{"price":3502.63,"qty":0.72912968}],"checksum":3918585583,"timestamp":"2024-06-01T17:52:43.078653Z"}]}
{"channel":"book","type":"update","data":[{"symbol":"ETH/EUR","bids":[{"price":3501.09,"qty":2.00000000}],"asks":[],"checksum":4006727922,"timestamp":"2024-06-01T17:52:43.078718Z"}]}
{"channel":"book","type":"update","data":[{"symbol":"ETH/EUR","bids":[{"price":3501.26,"qty":2.00000000}],"asks":[],"checksum":4190540441,"timestamp":"2024-06-01T17:52:43.084672Z"}]}
{"channel":"book","type":"update","data":[{"symbol":"ETH/EUR","bids":[],"asks":[{"price":3502.05,"qty":26.32725316}],"checksum":1493785639,"timestamp":"2024-06-01T17:52:43.087154Z"}]}
{"channel":"book","type":"update","data":[{"symbol":"ETH/EUR","bids":[{"price":3501.59,"qty":26.33069114}],"asks":[],"checksum":3691764066,"timestamp":"2024-06-01T17:52:43.087289Z"}]}
{"channel":"book","type":"update","data":[{"symbol":"ETH/EUR","bids":[],"asks":[{"price":3502.60,"qty":26.33075562}],"checksum":2059206987,"timestamp":"2024-06-01T17:52:43.087318Z"}]}
{"channel":"book","type":"update","data":[{"symbol":"ETH/EUR","bids":[{"price":3501.59,"qty":0.00000000},{"price":3501.06,"qty":1.35351043}],"asks":[],"checksum":1401295490,"timestamp":"2024-06-01T17:52:43.092488Z"}]}
{"channel":"book","type":"update","data":[{"symbol":"ETH/EUR","bids":[{"price":3501.09,"qty":0.00000000},{"price":3500.94,"qty":0.66220830}],"asks":[],"checksum":3754374468,"timestamp":"2024-06-01T17:52:43.134007Z"}]}
{"channel":"book","type":"update","data":[{"symbol":"ETH/EUR","bids":[{"price":3501.37,"qty":2.60000000}],"asks":[],"checksum":206577348,"timestamp":"2024-06-01T17:52:43.313916Z"}]}
{"channel":"book","type":"update","data":[{"symbol":"ETH/EUR","bids":[],"asks":[{"price":3502.04,"qty":2.00000000}],"checksum":1206202151,"timestamp":"2024-06-01T17:52:43.313995Z"}]}
{"channel":"book","type":"update","data":[{"symbol":"ETH/EUR","bids":[{"price":3501.36,"qty":0.00000000},{"price":3500.94,"qty":0.66220830}],"asks":[],"checksum":2323452973,"timestamp":"2024-06-01T17:52:43.316565Z"}]}
{"channel":"book","type":"update","data":[{"symbol":"ETH/EUR","bids":[{"price":3501.60,"qty":1.60000000}],"asks":[],"checksum":1399413004,"timestamp":"2024-06-01T17:52:43.316707Z"}]}
{"channel":"book","type":"update","data":[{"symbol":"ETH/EUR","bids":[{"price":3501.38,"qty":2.00000000}],"asks":[],"checksum":3991188192,"timestamp":"2024-06-01T17:52:43.319525Z"}]}
{"channel":"book","type":"update","data":[{"symbol":"ETH/EUR","bids":[{"price":3501.77,"qty":26.32931429}],"asks":[],"checksum":409443342,"timestamp":"2024-06-01T17:52:43.321202Z"}]}
{"channel":"book","type":"update","data":[{"symbol":"ETH/EUR","bids":[],"asks":[{"price":3502.05,"qty":0.00000000},{"price":3502.61,"qty":0.77800000}],"checksum":1062658909,"timestamp":"2024-06-01T17:52:43.383935Z"}]}
{"channel":"book","type":"update","data":[{"symbol":"ETH/EUR","bids":[],"asks":[{"price":3502.10,"qty":26.32687262}],"checksum":32054060,"timestamp":"2024-06-01T17:52:43.387529Z"}]}
{"channel":"book","type":"update","data":[{"symbol":"ETH/EUR","bids":[{"price":3501.81,"qty":26.32901079}],"asks":[],"checksum":2222394109,"timestamp":"2024-06-01T17:52:43.387700Z"}]}
{"channel":"book","type":"update","data":[{"symbol":"ETH/EUR","bids":[{"price":3501.38,"qty":0.00000000},{"price":3501.16,"qty":15.80353051}],"asks":[],"checksum":3315951658,"timestamp":"2024-06-01T17:52:43.388544Z"}]}
{"channel":"book","type":"update","data":[{"symbol":"ETH/EUR","bids":[],"asks":[{"price":3502.10,"qty":0.00000000},{"price":3502.61,"qty":0.77800000}],"checksum":3801716344,"timestamp":"2024-06-01T17:52:43.390629Z"}]}
{"channel":"book","type":"update","data":[{"symbol":"ETH/EUR","bids":[{"price":3501.81,"qty":0.00000000},{"price":3501.10,"qty":0.84644082}],"asks":[],"checksum":3521460351,"timestamp":"2024-06-01T17:52:43.391995Z"}]}
{"channel":"book","type":"update","data":[{"symbol":"ETH/EUR","bids":[{"price":3501.27,"qty":4.00000000}],"asks":[],"checksum":2291425656,"timestamp":"2024-06-01T17:52:43.502349Z"}]}
{"channel":"book","type":"update","data":[{"symbol":"ETH/EUR","bids":[{"price":3501.77,"qty":0.00000000},{"price":3501.10,"qty":0.84644082}],"asks":[],"checksum":2480836075,"timestamp":"2024-06-01T17:52:43.544552Z"}]}
{"channel":"book","type":"update","data":[{"symbol":"ETH/EUR","bids":[],"asks":[{"price":3502.17,"qty":0.00000000},{"price":3502.63,"qty":0.72912968}],"checksum":2891678552,"timestamp":"2024-06-01T17:52:43.544615Z"}]}
{"channel":"book","type":"update","data":[{"symbol":"ETH/EUR","bids":[{"price":3501.37,"qty":0.00000000},{"price":3501.06,"qty":1.35351043}],"asks":[],"checksum":1740088539,"timestamp":"2024-06-01T17:52:43.547233Z"}]}
{"channel":"book","type":"update","data":[{"symbol":"ETH/EUR","bids":[{"price":3501.63,"qty":26.33036159}],"asks":[],"checksum":801368527,"timestamp":"2024-06-01T17:52:43.551125Z"}]}
{"channel":"book","type":"update","data":[{"symbol":"ETH/EUR","bids":[],"asks":[{"price":3502.00,"qty":26.32765620}],"checksum":2734402576,"timestamp":"2024-06-01T17:52:43.551204Z"}]}
{"channel":"book","type":"update","data":[{"symbol":"ETH/EUR","bids":[{"price":3501.38,"qty":2.00000000}],"asks":[],"checksum":2796357155,"timestamp":"2024-06-01T17:52:43.551283Z"}]}
{"channel":"book","type":"update","data":[{"symbol":"ETH/EUR","bids":[{"price":3501.60,"qty":0.00000000},{"price":3501.10,"qty":0.84644082}],"asks":[],"checksum":2587903057,"timestamp":"2024-06-01T17:52:43.553719Z"}]}
{"channel":"book","type":"update","data":[{"symbol":"ETH/EUR","bids":[{"price":3501.68,"qty":1.60000000}],"asks":[],"checksum":2561645166,"timestamp":"2024-06-01T17:52:43.553957Z"}]}
{"channel":"book","type":"update","data":[{"symbol":"ETH/EUR","bids":[],"asks":[{"price":3502.34,"qty":0.00000000},{"price":3502.63,"qty":0.72912968}],"checksum":4204630809,"timestamp":"2024-06-01T17:52:43.560517Z"}]}
{"channel":"book","type":"update","data":[{"symbol":"ETH/EUR","bids":[{"price":3501.63,"qty":0.00000000},{"price":3501.10,"qty":0.84644082}],"asks":[],"checksum":1290966302,"timestamp":"2024-06-01T17:52:43.560567Z"}]}
{"channel":"book","type":"update","data":[{"symbol":"ETH/EUR","bids":[],"asks":[{"price":3502.00,"qty":0.00000000},{"price":3502.83,"qty":0.00220000}],"checksum":1258552031,"timestamp":"2024-06-01T17:52:43.560685Z"}]}
{"channel":"book","type":"update","data":[{"symbol":"ETH/EUR","bids":[],"asks":[{"price":3502.45,"qty":1.60220000}],"checksum":302080802,"timestamp":"2024-06-01T17:52:43.563486Z"}]}
{"channel":"book","type":"update","data":[{"symbol":"ETH/EUR","bids":[],"asks":[{"price":3502.21,"qty":26.32608952}],"checksum":1041422533,"timestamp":"2024-06-01T17:52:43.565775Z"}]}
{"channel":"book","type":"update","data":[{"symbol":"ETH/EUR","bids":[],"asks":[{"price":3502.60,"qty":26.32318062},{"price":3502.43,"qty":0.00757515}],"checksum":1245698837,"timestamp":"2024-06-01T17:52:43.604879Z"}]}
{"channel":"book","type":"update","data":[{"symbol":"ETH/EUR","bids":[{"price":3501.58,"qty":0.00000000},{"price":3500.94,"qty":0.66220830},{"price":3501.69,"qty":0.02855096}],"asks":[],"checksum":642011556,"timestamp":"2024-06-01T17:52:43.605081Z"}]}
{"channel":"book","type":"update","data":[{"symbol":"ETH/EUR","bids":[],"asks":[{"price":3501.98,"qty":26.32779540}],"checksum":258645832,"timestamp":"2024-06-01T17:52:43.612198Z"}]}
{"channel":"book","type":"update","data":[{"symbol":"ETH/EUR","bids":[{"price":3501.69,"qty":26.35850134}],"asks":[],"checksum":1941039527,"timestamp":"2024-06-01T17:52:43.612360Z"}]}
{"channel":"book","type":"update","data":[{"symbol":"ETH/EUR","bids":[{"price":3501.26,"qty":0.00000000},{"price":3500.94,"qty":0.66220830}],"asks":[],"checksum":4030628470,"timestamp":"2024-06-01T17:52:43.614775Z"}]}
{"channel":"book","type":"update","data":[{"symbol":"ETH/EUR","bids":[],"asks":[{"price":3502.43,"qty":0.00000000},{"price":3502.61,"qty":0.77800000},{"price":3502.59,"qty":0.00757515}],"checksum":1963258599,"timestamp":"2024-06-01T17:52:43.673468Z"}]}
{"channel":"book","type":"update","data":[{"symbol":"ETH/EUR","bids":[{"price":3501.69,"qty":0.02855096}],"asks":[],"checksum":3919681173,"timestamp":"2024-06-01T17:52:43.699525Z"}]}
{"channel":"book","type":"update","data":[{"symbol":"ETH/EUR","bids":[{"price":3501.68,"qty":0.00000000},{"price":3500.92,"qty":15.80765248}],"asks":[],"checksum":2230408908,"timestamp":"2024-06-01T17:52:43.702478Z"}]}
{"channel":"book","type":"update","data":[{"symbol":"ETH/EUR","bids":[{"price":3501.44,"qty":1.60000000}],"asks":[],"checksum":2121958665,"timestamp":"2024-06-01T17:52:43.702633Z"}]}
{"channel":"book","type":"update","data":[{"symbol":"ETH/EUR","bids":[],"asks":[{"price":3502.03,"qty":26.32739410}],"checksum":787544590,"timestamp":"2024-06-01T17:52:43.704123Z"}]}
{"channel":"book","type":"update","data":[{"symbol":"ETH/EUR","bids":[{"price":3501.70,"qty":26.32980389}],"asks":[],"checksum":2004043345,"timestamp":"2024-06-01T17:52:43.704231Z"}]}
{"channel":"book","type":"update","data":[{"symbol":"ETH/EUR","bids":[{"price":3501.18,"qty":1.35346404}],"asks":[],"checksum":1611792138,"timestamp":"2024-06-01T17:52:43.744212Z"}]}
{"channel":"book","type":"update","data":[{"symbol":"ETH/EUR","bids":[{"price":3501.70,"qty":0.00000000},{"price":3501.10,"qty":0.84644082}],"asks":[],"checksum":2242620251,"timestamp":"2024-06-01T17:52:43.785913Z"}]}
{"channel":"book","type":"update","data":[{"symbol":"ETH/EUR","bids":[],"asks":[{"price":3501.98,"qty":0.00000000},{"price":3502.60,"qty":26.32318062}],"checksum":2948681066,"timestamp":"2024-06-01T17:52:43.790407Z"}]}
{"channel":"book","type":"update","data":[{"symbol":"ETH/EUR","bids":[],"asks":[{"price":3502.03,"qty":0.00000000},{"price":3502.61,"qty":0.77800000}],"checksum":758901539,"timestamp":"2024-06-01T17:52:43.792483Z"}]}
{"channel":"book","type":"update","data":[{"symbol":"ETH/EUR","bids":[],"asks":[{"price":3502.00,"qty":26.32768445}],"checksum":1610833024,"timestamp":"2024-06-01T17:52:43.798055Z"}]}
{"channel":"book","type":"update","data":[{"symbol":"ETH/EUR","bids":[],"asks":[{"price":3502.10,"qty":26.32690597}],"checksum":529033670,"timestamp":"2024-06-01T17:52:43.798110Z"}]}
{"channel":"book","type":"update","data":[{"symbol":"ETH/EUR","bids":[{"price":3501.74,"qty":26.32952490}],"asks":[],"checksum":4256045736,"timestamp":"2024-06-01T17:52:43.798124Z"}]}
{"channel":"book","type":"update","data":[{"symbol":"ETH/EUR","bids":[],"asks":[{"price":3502.00,"qty":0.00000000},{"price":3502.60,"qty":26.32318062}],"checksum":3683684093,"timestamp":"2024-06-01T17:52:43.827379Z"}]}
{"channel":"book","type":"update","data":[{"symbol":"ETH/EUR","bids":[{"price":3501.74,"qty":0.00000000},{"price":3501.10,"qty":0.84644082}],"asks":[],"checksum":56385224,"timestamp":"2024-06-01T17:52:43.835945Z"}]}
{"channel":"book","type":"update","data":[{"symbol":"ETH/EUR","bids":[{"price":3501.69,"qty":0.00000000},{"price":3500.94,"qty":0.66220830},{"price":3501.58,"qty":0.02855186}],"asks":[],"checksum":3488160729,"timestamp":"2024-06-01T17:52:43.838967Z"}]}
{"channel":"book","type":"update","data":[{"symbol":"ETH/EUR","bids":[{"price":3501.62,"qty":26.33042979}],"asks":[],"checksum":3387095086,"timestamp":"2024-06-01T17:52:43.840370Z"}]}
{"channel":"book","type":"update","data":[{"symbol":"ETH/EUR","bids":[{"price":3501.62,"qty":0.00000000},{"price":3501.10,"qty":0.84644082}],"asks":[],"checksum":3488160729,"timestamp":"2024-06-01T17:52:43.961264Z"}]}
{"channel":"book","type":"update","data":[{"symbol":"ETH/EUR","bids":[{"price":3501.72,"qty":26.32971703}],"asks":[],"checksum":3897788514,"timestamp":"2024-06-01T17:52:43.966276Z"}]}
{"channel":"book","type":"update","data":[{"symbol":"ETH/EUR","bids":[],"asks":[{"price":3502.02,"qty":26.32754029}],"checksum":3514642780,"timestamp":"2024-06-01T17:52:43.966417Z"}]}
{"channel":"book","type":"update","data":[{"symbol":"ETH/EUR","bids":[{"price":3501.75,"qty":3.47500000}],"asks":[],"checksum":1155411056,"timestamp":"2024-06-01T17:52:43.980089Z"}]}
{"channel":"book","type":"update","data":[{"symbol":"ETH/EUR","bids":[{"price":3501.72,"qty":0.00000000},{"price":3501.16,"qty":15.80353051}],"asks":[],"checksum":540666691,"timestamp":"2024-06-01T17:52:44.087431Z"}]}
{"channel":"book","type":"update","data":[{"symbol":"ETH/EUR","bids":[],"asks":[{"price":3502.02,"qty":0.00000000},{"price":3502.60,"qty":26.32318062}],"checksum":221452192,"timestamp":"2024-06-01T17:52:44.087450Z"}]}
{"channel":"book","type":"update","data":[{"symbol":"ETH/EUR","bids":[],"asks":[{"price":3502.10,"qty":0.00000000},{"price":3502.61,"qty":0.77800000}],"checksum":986008549,"timestamp":"2024-06-01T17:52:44.096633Z"}]}
{"channel":"book","type":"update","data":[{"symbol":"ETH/EUR","bids":[],"asks":[{"price":3501.99,"qty":26.32774557}],"checksum":1467717054,"timestamp":"2024-06-01T17:52:44.096645Z"}]}
{"channel":"book","type":"update","data":[{"symbol":"ETH/EUR","bids":[{"price":3501.66,"qty":26.33014987}],"asks":[],"checksum":1902224859,"timestamp":"2024-06-01T17:52:44.096687Z"}]}
{"channel":"book","type":"update","data":[{"symbol":"ETH/EUR","bids":[],"asks":[{"price":3501.98,"qty":2.00000000}],"checksum":4172070923,"timestamp":"2024-06-01T17:52:44.110114Z"}]}
{"channel":"book","type":"update","data":[{"symbol":"ETH/EUR","bids":[],"asks":[{"price":3502.04,"qty":0.00000000},{"price":3502.60,"qty":26.32318062}],"checksum":3718066222,"timestamp":"2024-06-01T17:52:44.110172Z"}]}
{"channel":"book","type":"update","data":[{"symbol":"ETH/EUR","bids":[{"price":3501.75,"qty":0.00000000},{"price":3501.16,"qty":15.80353051}],"asks":[],"checksum":2488830740,"timestamp":"2024-06-01T17:52:44.264476Z"}]}
{"channel":"book","type":"update","data":[{"symbol":"ETH/EUR","bids":[{"price":3501.66,"qty":0.00000000},{"price":3501.10,"qty":0.84644082}],"asks":[],"checksum":3268979468,"timestamp":"2024-06-01T17:52:44.280757Z"}]}
{"channel":"book","type":"update","data":[{"symbol":"ETH/EUR","bids":[],"asks":[{"price":3501.99,"qty":0.00000000},{"price":3502.61,"qty":0.77800000}],"checksum":2650031132,"timestamp":"2024-06-01T17:52:44.280822Z"}]}
{"channel":"book","type":"update","data":[{"symbol":"ETH/EUR","bids":[{"price":3501.25,"qty":0.00000000},{"price":3500.94,"qty":0.66220830}],"asks":[],"checksum":347918707,"timestamp":"2024-06-01T17:52:44.286893Z"}]}
{"channel":"book","type":"update","data":[{"symbol":"ETH/EUR","bids":[{"price":3501.63,"qty":26.33039539}],"asks":[],"checksum":3078689358,"timestamp":"2024-06-01T17:52:44.290956Z"}]}
{"channel":"book","type":"update","data":[{"symbol":"ETH/EUR","bids":[],"asks":[{"price":3501.97,"qty":26.32784517}],"checksum":3566275604,"timestamp":"2024-06-01T17:52:44.291033Z"}]}
{"channel":"book","type":"update","data":[{"symbol":"ETH/EUR","bids":[{"price":3501.59,"qty":26.33070232}],"asks":[],"checksum":3310395241,"timestamp":"2024-06-01T17:52:44.295538Z"}]}
{"channel":"book","type":"update","data":[{"symbol":"ETH/EUR","bids":[],"asks":[{"price":3501.98,"qty":0.00000000},{"price":3502.61,"qty":0.77800000}],"checksum":2519648660,"timestamp":"2024-06-01T17:52:44.302788Z"}]}
{"channel":"book","type":"update","data":[{"symbol":"ETH/EUR","bids":[{"price":3501.63,"qty":0.00000000},{"price":3501.10,"qty":0.84644082}],"asks":[],"checksum":4211314908,"timestamp":"2024-06-01T17:52:44.332975Z"}]}
{"channel":"book","type":"update","data":[{"symbol":"ETH/EUR","bids":[],"asks":[{"price":3501.97,"qty":0.00000000},{"price":3502.63,"qty":0.72912968}],"checksum":3933174849,"timestamp":"2024-06-01T17:52:44.446931Z"}]}
{"channel":"book","type":"update","data":[{"symbol":"ETH/EUR","bids":[{"price":3501.67,"qty":26.33006135}],"asks":[],"checksum":4028817223,"timestamp":"2024-06-01T17:52:44.451364Z"}]}
{"channel":"book","type":"update","data":[{"symbol":"ETH/EUR","bids":[],"asks":[{"price":3502.02,"qty":26.32753327}],"checksum":805839425,"timestamp":"2024-06-01T17:52:44.451383Z"}]}
{"channel":"book","type":"update","data":[{"symbol":"ETH/EUR","bids":[],"asks":[{"price":3502.02,"qty":0.00000000},{"price":3502.63,"qty":0.72912968}],"checksum":4028817223,"timestamp":"2024-06-01T17:52:44.498035Z"}]}
{"channel":"book","type":"update","data":[{"symbol":"ETH/EUR","bids":[],"asks":[{"price":3502.01,"qty":26.32761485}],"checksum":4266369891,"timestamp":"2024-06-01T17:52:44.502261Z"}]}
{"channel":"book","type":"update","data":[{"symbol":"ETH/EUR","bids":[],"asks":[{"price":3502.01,"qty":0.00000000},{"price":3502.63,"qty":0.72912968}],"checksum":4028817223,"timestamp":"2024-06-01T17:52:44.542709Z"}]}
{"channel":"book","type":"update","data":[{"symbol":"ETH/EUR","bids":[{"price":3501.60,"qty":3.34000000}],"asks":[],"checksum":1507304950,"timestamp":"2024-06-01T17:52:44.558781Z"}]}
{"channel":"book","type":"update","data":[{"symbol":"ETH/EUR","bids":[{"price":3501.57,"qty":0.00000000},{"price":3501.16,"qty":15.80353051}],"asks":[],"checksum":2925798791,"timestamp":"2024-06-01T17:52:44.651876Z"}]}
{"channel":"book","type":"update","data":[{"symbol":"ETH/EUR","bids":[],"asks":[{"price":3501.96,"qty":26.32794486}],"checksum":3603466881,"timestamp":"2024-06-01T17:52:44.663461Z"}]}
{"channel":"book","type":"update","data":[{"symbol":"ETH/EUR","bids":[{"price":3501.58,"qty":0.00000000},{"price":3501.10,"qty":0.84644082},{"price":3501.68,"qty":0.02855177}],"asks":[],"checksum":599470208,"timestamp":"2024-06-01T17:52:44.673277Z"}]}
{"channel":"book","type":"update","data":[{"symbol":"ETH/EUR","bids":[],"asks":[{"price":3502.59,"qty":0.00000000},{"price":3502.63,"qty":0.72912968},{"price":3502.20,"qty":0.00757527}],"checksum":2956447564,"timestamp":"2024-06-01T17:52:44.673569Z"}]}
{"channel":"book","type":"update","data":[{"symbol":"ETH/EUR","bids":[{"price":3501.67,"qty":0.00000000},{"price":3501.10,"qty":0.84644082}],"asks":[],"checksum":1071940891,"timestamp":"2024-06-01T17:52:44.744933Z"}]}
{"channel":"book","type":"update","data":[{"symbol":"ETH/EUR","bids":[],"asks":[{"price":3502.03,"qty":26.32739410}],"checksum":3103322621,"timestamp":"2024-06-01T17:52:44.749038Z"}]}
{"channel":"book","type":"update","data":[{"symbol":"ETH/EUR","bids":[{"price":3501.65,"qty":26.33022738}],"asks":[],"checksum":487658385,"timestamp":"2024-06-01T17:52:44.749170Z"}]}
{"channel":"book","type":"update","data":[{"symbol":"ETH/EUR","bids":[{"price":3501.37,"qty":26.33232792}],"asks":[],"checksum":1684390144,"timestamp":"2024-06-01T17:52:44.753103Z"}]}
{"channel":"book","type":"update","data":[{"symbol":"ETH/EUR","bids":[{"price":3501.36,"qty":15.80353051}],"asks":[],"checksum":1415682632,"timestamp":"2024-06-01T17:52:44.791765Z"}]}
{"channel":"book","type":"update","data":[{"symbol":"ETH/EUR","bids":[],"asks":[{"price":3501.96,"qty":0.00000000},{"price":3502.61,"qty":0.77800000}],"checksum":1348643032,"timestamp":"2024-06-01T17:52:44.832176Z"}]}
{"channel":"book","type":"update","data":[{"symbol":"ETH/EUR","bids":[],"asks":[{"price":3502.03,"qty":0.00000000},{"price":3502.63,"qty":0.72912968}],"checksum":43441133,"timestamp":"2024-06-01T17:52:44.837166Z"}]}
