{"channel":"book","type":"snapshot","data":[{"symbol":"ETH/USDT","bids":[{"price":3798.70,"qty":0.73120000},{"price":3798.52,"qty":0.34000000},{"price":3798.51,"qty":1.46240000},{"price":3798.50,"qty":0.26346782},{"price":3798.48,"qty":0.06693358},{"price":3798.25,"qty":0.26346643},{"price":3798.24,"qty":1.31736338},{"price":3798.22,"qty":2.63495112},{"price":3798.09,"qty":0.25000000},{"price":3798.02,"qty":0.29500386}],"asks":[{"price":3799.20,"qty":1.04704630},{"price":3799.31,"qty":2.18400000},{"price":3799.65,"qty":0.25000000},{"price":3799.73,"qty":0.72912968},{"price":3799.85,"qty":2.63382592},{"price":3799.89,"qty":0.00421065},{"price":3799.98,"qty":0.43105261},{"price":3800.02,"qty":0.73120000},{"price":3800.18,"qty":49.94338336},{"price":3800.19,"qty":5.00000000}],"checksum":920171245}]}
{"channel":"book","type":"update","data":[{"symbol":"ETH/USDT","bids":[{"price":3798.71,"qty":0.26346782}],"asks":[],"checksum":1204894442,"timestamp":"2024-06-01T17:51:47.113496Z"}]}
{"channel":"book","type":"update","data":[{"symbol":"ETH/USDT","bids":[{"price":3798.51,"qty":0.73120000}],"asks":[],"checksum":1388748020,"timestamp":"2024-06-01T17:51:47.116987Z"}]}
{"channel":"book","type":"update","data":[{"symbol":"ETH/USDT","bids":[{"price":3798.50,"qty":0.00000000},{"price":3798.02,"qty":0.29500386}],"asks":[],"checksum":2780015752,"timestamp":"2024-06-01T17:51:47.117169Z"}]}
{"channel":"book","type":"update","data":[{"symbol":"ETH/USDT","bids":[{"price":3798.88,"qty":0.73120000}],"asks":[],"checksum":1570065858,"timestamp":"2024-06-01T17:51:47.117365Z"}]}
{"channel":"book","type":"update","data":[{"symbol":"ETH/USDT","bids":[],"asks":[{"price":3799.31,"qty":0.00000000},{"price":3800.20,"qty":0.84627249}],"checksum":2609956063,"timestamp":"2024-06-01T17:51:47.159898Z"}]}
{"channel":"book","type":"update","data":[{"symbol":"ETH/USDT","bids":[{"price":3798.52,"qty":0.00000000},{"price":3798.02,"qty":0.29500386}],"asks":[],"checksum":3442462857,"timestamp":"2024-06-01T17:51:47.190192Z"}]}
{"channel":"book","type":"update","data":[{"symbol":"ETH/USDT","bids":[{"price":3798.71,"qty":0.60346782}],"asks":[],"checksum":415384879,"timestamp":"2024-06-01T17:51:47.190285Z"}]}
{"channel":"book","type":"update","data":[{"symbol":"ETH/USDT","bids":[{"price":3798.72,"qty":0.07902553}],"asks":[],"checksum":566316785,"timestamp":"2024-06-01T17:51:47.225727Z"}]}
{"channel":"book","type":"update","data":[{"symbol":"ETH/USDT","bids":[{"price":3798.71,"qty":0.26346782}],"asks":[],"checksum":438104059,"timestamp":"2024-06-01T17:51:47.228674Z"}]}
{"channel":"book","type":"update","data":[{"symbol":"ETH/USDT","bids":[{"price":3798.73,"qty":0.34000000}],"asks":[],"checksum":2701598229,"timestamp":"2024-06-01T17:51:47.228814Z"}]}
{"channel":"book","type":"update","data":[{"symbol":"ETH/USDT","bids":[{"price":3798.72,"qty":0.00000000},{"price":3798.09,"qty":0.25000000}],"asks":[],"checksum":1155521198,"timestamp":"2024-06-01T17:51:47.230758Z"}]}
{"channel":"book","type":"update","data":[{"symbol":"ETH/USDT","bids":[{"price":3798.89,"qty":0.07902353}],"asks":[],"checksum":102469913,"timestamp":"2024-06-01T17:51:47.234137Z"}]}
{"channel":"book","type":"update","data":[{"symbol":"ETH/USDT","bids":[{"price":3798.89,"qty":0.00000000},{"price":3798.09,"qty":0.25000000}],"asks":[],"checksum":1155521198,"timestamp":"2024-06-01T17:51:47.237906Z"}]}
{"channel":"book","type":"update","data":[{"symbol":"ETH/USDT","bids":[{"price":3798.90,"qty":0.73120000}],"asks":[],"checksum":1453162656,"timestamp":"2024-06-01T17:51:47.239656Z"}]}
{"channel":"book","type":"update","data":[{"symbol":"ETH/USDT","bids":[{"price":3798.22,"qty":0.00000000},{"price":3798.09,"qty":0.25000000}],"asks":[],"checksum":4037934980,"timestamp":"2024-06-01T17:51:47.239894Z"}]}
{"channel":"book","type":"update","data":[{"symbol":"ETH/USDT","bids":[{"price":3798.90,"qty":1.46240000}],"asks":[],"checksum":3814892165,"timestamp":"2024-06-01T17:51:47.243238Z"}]}
{"channel":"book","type":"update","data":[{"symbol":"ETH/USDT","bids":[{"price":3798.70,"qty":0.00000000},{"price":3798.02,"qty":0.29500386}],"asks":[],"checksum":2813670825,"timestamp":"2024-06-01T17:51:47.243554Z"}]}
{"channel":"book","type":"update","data":[{"symbol":"ETH/USDT","bids":[{"price":3798.88,"qty":0.00000000},{"price":3797.92,"qty":0.73120000}],"asks":[],"checksum":142070828,"timestamp":"2024-06-01T17:51:47.243799Z"}]}
{"channel":"book","type":"update","data":[{"symbol":"ETH/USDT","bids":[{"price":3798.90,"qty":0.73120000}],"asks":[],"checksum":465078573,"timestamp":"2024-06-01T17:51:47.244123Z"}]}
{"channel":"book","type":"update","data":[{"symbol":"ETH/USDT","bids":[{"price":3798.57,"qty":2.63471212}],"asks":[],"checksum":2616912938,"timestamp":"2024-06-01T17:51:47.244458Z"}]}
{"channel":"book","type":"update","data":[{"symbol":"ETH/USDT","bids":[{"price":3798.03,"qty":2.79800000}],"asks":[],"checksum":3032229086,"timestamp":"2024-06-01T17:51:47.246804Z"}]}
{"channel":"book","type":"update","data":[{"symbol":"ETH/USDT","bids":[{"price":3798.92,"qty":0.73120000}],"asks":[],"checksum":2252164725,"timestamp":"2024-06-01T17:51:47.247159Z"}]}
{"channel":"book","type":"update","data":[{"symbol":"ETH/USDT","bids":[{"price":3798.99,"qty":0.73120000}],"asks":[],"checksum":3622397662,"timestamp":"2024-06-01T17:51:47.248272Z"}]}
{"channel":"book","type":"update","data":[{"symbol":"ETH/USDT","bids":[{"price":3798.90,"qty":0.00000000},{"price":3798.09,"qty":0.25000000}],"asks":[],"checksum":391120343,"timestamp":"2024-06-01T17:51:47.248332Z"}]}
{"channel":"book","type":"update","data":[{"symbol":"ETH/USDT","bids":[{"price":3798.92,"qty":0.00000000},{"price":3798.03,"qty":2.79800000}],"asks":[],"checksum":2205820483,"timestamp":"2024-06-01T17:51:47.251311Z"}]}
{"channel":"book","type":"update","data":[{"symbol":"ETH/USDT","bids":[{"price":3798.99,"qty":0.00000000},{"price":3798.02,"qty":0.29500386}],"asks":[],"checksum":2343699114,"timestamp":"2024-06-01T17:51:47.270923Z"}]}
{"channel":"book","type":"update","data":[{"symbol":"ETH/USDT","bids":[{"price":3798.91,"qty":0.73120000}],"asks":[],"checksum":72613332,"timestamp":"2024-06-01T17:51:47.275181Z"}]}
{"channel":"book","type":"update","data":[{"symbol":"ETH/USDT","bids":[],"asks":[{"price":3799.67,"qty":2.18400000}],"checksum":1123016069,"timestamp":"2024-06-01T17:51:47.297753Z"}]}
{"channel":"book","type":"update","data":[{"symbol":"ETH/USDT","bids":[{"price":3798.52,"qty":0.29500386}],"asks":[],"checksum":3013107279,"timestamp":"2024-06-01T17:51:47.319942Z"}]}
{"channel":"book","type":"update","data":[{"symbol":"ETH/USDT","bids":[{"price":3798.09,"qty":0.44720752}],"asks":[],"checksum":578010184,"timestamp":"2024-06-01T17:51:47.401785Z"}]}
{"channel":"book","type":"update","data":[{"symbol":"ETH/USDT","bids":[{"price":3798.91,"qty":1.46240000}],"asks":[],"checksum":1240185357,"timestamp":"2024-06-01T17:51:47.858591Z"}]}
{"channel":"book","type":"update","data":[{"symbol":"ETH/USDT","bids":[{"price":3798.09,"qty":0.25000000}],"asks":[],"checksum":3623901194,"timestamp":"2024-06-01T17:51:47.917034Z"}]}
{"channel":"book","type":"update","data":[{"symbol":"ETH/USDT","bids":[],"asks":[{"price":3799.98,"qty":0.00000000},{"price":3800.20,"qty":0.84627249}],"checksum":2825108530,"timestamp":"2024-06-01T17:51:47.933370Z"}]}
{"channel":"book","type":"update","data":[{"symbol":"ETH/USDT","bids":[],"asks":[{"price":3800.17,"qty":0.46030451}],"checksum":3566212322,"timestamp":"2024-06-01T17:51:47.935872Z"}]}
{"channel":"book","type":"update","data":[{"symbol":"ETH/USDT","bids":[{"price":3798.91,"qty":0.73120000}],"asks":[],"checksum":2513407620,"timestamp":"2024-06-01T17:51:47.937630Z"}]}
{"channel":"book","type":"update","data":[{"symbol":"ETH/USDT","bids":[{"price":3798.10,"qty":0.19721832}],"asks":[],"checksum":2345163164,"timestamp":"2024-06-01T17:51:47.957259Z"}]}
{"channel":"book","type":"update","data":[{"symbol":"ETH/USDT","bids":[{"price":3798.91,"qty":1.46240000}],"asks":[],"checksum":3398943738,"timestamp":"2024-06-01T17:51:48.022795Z"}]}
{"channel":"book","type":"update","data":[{"symbol":"ETH/USDT","bids":[{"price":3798.91,"qty":0.73120000}],"asks":[],"checksum":2345163164,"timestamp":"2024-06-01T17:51:48.046054Z"}]}
{"channel":"book","type":"update","data":[{"symbol":"ETH/USDT","bids":[],"asks":[{"price":3799.73,"qty":0.00000000},{"price":3800.20,"qty":0.84627249}],"checksum":834550682,"timestamp":"2024-06-01T17:51:48.071762Z"}]}
{"channel":"book","type":"update","data":[{"symbol":"ETH/USDT","bids":[{"price":3798.91,"qty":1.46240000}],"asks":[],"checksum":592318637,"timestamp":"2024-06-01T17:51:48.144943Z"}]}
{"channel":"book","type":"update","data":[{"symbol":"ETH/USDT","bids":[{"price":3798.91,"qty":0.73120000}],"asks":[],"checksum":834550682,"timestamp":"2024-06-01T17:51:48.147331Z"}]}
{"channel":"book","type":"update","data":[{"symbol":"ETH/USDT","bids":[{"price":3798.91,"qty":0.00000000},{"price":3798.09,"qty":0.25000000}],"asks":[],"checksum":194304344,"timestamp":"2024-06-01T17:51:48.149429Z"}]}
{"channel":"book","type":"update","data":[{"symbol":"ETH/USDT","bids":[{"price":3798.25,"qty":3.06146643}],"asks":[],"checksum":1797085928,"timestamp":"2024-06-01T17:51:48.153176Z"}]}
{"channel":"book","type":"update","data":[{"symbol":"ETH/USDT","bids":[{"price":3798.91,"qty":0.73120000}],"asks":[],"checksum":1357867814,"timestamp":"2024-06-01T17:51:48.153518Z"}]}
{"channel":"book","type":"update","data":[{"symbol":"ETH/USDT","bids":[{"price":3798.91,"qty":1.46240000}],"asks":[],"checksum":3896524290,"timestamp":"2024-06-01T17:51:48.288976Z"}]}
{"channel":"book","type":"update","data":[{"symbol":"ETH/USDT","bids":[],"asks":[{"price":3800.11,"qty":0.72912968}],"checksum":268132678,"timestamp":"2024-06-01T17:51:48.293861Z"}]}
{"channel":"book","type":"update","data":[{"symbol":"ETH/USDT","bids":[{"price":3798.91,"qty":0.73120000}],"asks":[],"checksum":1402808360,"timestamp":"2024-06-01T17:51:48.317204Z"}]}
{"channel":"book","type":"update","data":[{"symbol":"ETH/USDT","bids":[{"price":3798.91,"qty":1.46240000}],"asks":[],"checksum":268132678,"timestamp":"2024-06-01T17:51:48.339970Z"}]}
{"channel":"book","type":"update","data":[{"symbol":"ETH/USDT","bids":[{"price":3798.10,"qty":0.00000000},{"price":3798.09,"qty":0.25000000}],"asks":[],"checksum":301774430,"timestamp":"2024-06-01T17:51:48.413293Z"}]}
{"channel":"book","type":"update","data":[{"symbol":"ETH/USDT","bids":[{"price":3798.13,"qty":0.19720683}],"asks":[],"checksum":279445169,"timestamp":"2024-06-01T17:51:48.906607Z"}]}
{"channel":"book","type":"update","data":[{"symbol":"ETH/USDT","bids":[{"price":3798.13,"qty":0.00000000},{"price":3798.09,"qty":0.25000000}],"asks":[],"checksum":301774430,"timestamp":"2024-06-01T17:51:49.418661Z"}]}
{"channel":"book","type":"update","data":[{"symbol":"ETH/USDT","bids":[{"price":3798.17,"qty":0.19720142}],"asks":[],"checksum":2478229154,"timestamp":"2024-06-01T17:51:49.458582Z"}]}
{"channel":"book","type":"update","data":[{"symbol":"ETH/USDT","bids":[],"asks":[{"price":3800.02,"qty":0.00000000},{"price":3800.20,"qty":0.84627249}],"checksum":248478770,"timestamp":"2024-06-01T17:51:49.575022Z"}]}
{"channel":"book","type":"update","data":[{"symbol":"ETH/USDT","bids":[],"asks":[{"price":3800.19,"qty":0.00000000},{"price":3800.33,"qty":4.83452015}],"checksum":2414680771,"timestamp":"2024-06-01T17:51:49.584336Z"}]}
{"channel":"book","type":"update","data":[{"symbol":"ETH/USDT","bids":[],"asks":[{"price":3800.20,"qty":0.00000000},{"price":3800.34,"qty":0.73120000}],"checksum":362901472,"timestamp":"2024-06-01T17:51:49.584508Z"}]}
{"channel":"book","type":"update","data":[{"symbol":"ETH/USDT","bids":[],"asks":[{"price":3800.33,"qty":0.00000000},{"price":3800.54,"qty":0.01908600}],"checksum":2744746589,"timestamp":"2024-06-01T17:51:49.584812Z"}]}
{"channel":"book","type":"update","data":[{"symbol":"ETH/USDT","bids":[],"asks":[{"price":3799.65,"qty":0.00000000},{"price":3800.55,"qty":5.26600000}],"checksum":2342703404,"timestamp":"2024-06-01T17:51:49.600497Z"}]}
{"channel":"book","type":"update","data":[{"symbol":"ETH/USDT","bids":[],"asks":[{"price":3799.85,"qty":0.00000000},{"price":3800.76,"qty":2.63320011}],"checksum":1953834030,"timestamp":"2024-06-01T17:51:49.603964Z"}]}
{"channel":"book","type":"update","data":[{"symbol":"ETH/USDT","bids":[],"asks":[{"price":3799.96,"qty":0.73120000}],"checksum":1739905008,"timestamp":"2024-06-01T17:51:49.604134Z"}]}
{"channel":"book","type":"update","data":[{"symbol":"ETH/USDT","bids":[{"price":3798.92,"qty":0.07902104}],"asks":[],"checksum":2720234897,"timestamp":"2024-06-01T17:51:49.620226Z"}]}
{"channel":"book","type":"update","data":[{"symbol":"ETH/USDT","bids":[{"price":3798.92,"qty":0.32902104}],"asks":[],"checksum":534320934,"timestamp":"2024-06-01T17:51:49.620263Z"}]}
{"channel":"book","type":"update","data":[{"symbol":"ETH/USDT","bids":[{"price":3798.92,"qty":1.64616579}],"asks":[],"checksum":578310971,"timestamp":"2024-06-01T17:51:49.624306Z"}]}
{"channel":"book","type":"update","data":[{"symbol":"ETH/USDT","bids":[],"asks":[{"price":3799.96,"qty":0.00000000},{"price":3800.61,"qty":3.46342015}],"checksum":1900535822,"timestamp":"2024-06-01T17:51:49.624632Z"}]}
{"channel":"book","type":"update","data":[{"symbol":"ETH/USDT","bids":[{"price":3798.92,"qty":1.90959474}],"asks":[],"checksum":2547654061,"timestamp":"2024-06-01T17:51:49.634136Z"}]}
{"channel":"book","type":"update","data":[{"symbol":"ETH/USDT","bids":[],"asks":[{"price":3800.21,"qty":2.63358236}],"checksum":1750297031,"timestamp":"2024-06-01T17:51:49.642120Z"}]}
{"channel":"book","type":"update","data":[{"symbol":"ETH/USDT","bids":[],"asks":[{"price":3800.54,"qty":0.00000000},{"price":3800.61,"qty":3.46342015}],"checksum":3119983572,"timestamp":"2024-06-01T17:51:49.642355Z"}]}
{"channel":"book","type":"update","data":[{"symbol":"ETH/USDT","bids":[],"asks":[{"price":3799.96,"qty":0.73120000}],"checksum":2187032594,"timestamp":"2024-06-01T17:51:49.645883Z"}]}
{"channel":"book","type":"update","data":[{"symbol":"ETH/USDT","bids":[{"price":3799.10,"qty":0.73120000}],"asks":[],"checksum":4117959024,"timestamp":"2024-06-01T17:51:49.648337Z"}]}
{"channel":"book","type":"update","data":[{"symbol":"ETH/USDT","bids":[],"asks":[{"price":3799.96,"qty":0.00000000},{"price":3800.61,"qty":3.46342015}],"checksum":922754896,"timestamp":"2024-06-01T17:51:49.648842Z"}]}
{"channel":"book","type":"update","data":[{"symbol":"ETH/USDT","bids":[{"price":3798.73,"qty":0.00000000},{"price":3798.24,"qty":1.31736338}],"asks":[],"checksum":332750118,"timestamp":"2024-06-01T17:51:49.653554Z"}]}
{"channel":"book","type":"update","data":[{"symbol":"ETH/USDT","bids":[{"price":3798.92,"qty":2.24959474}],"asks":[],"checksum":203276473,"timestamp":"2024-06-01T17:51:49.653914Z"}]}
{"channel":"book","type":"update","data":[{"symbol":"ETH/USDT","bids":[{"price":3798.92,"qty":2.17057370}],"asks":[],"checksum":1402796530,"timestamp":"2024-06-01T17:51:49.657990Z"}]}
{"channel":"book","type":"update","data":[{"symbol":"ETH/USDT","bids":[{"price":3799.11,"qty":0.07901868}],"asks":[],"checksum":3638514330,"timestamp":"2024-06-01T17:51:49.658009Z"}]}
{"channel":"book","type":"update","data":[{"symbol":"ETH/USDT","bids":[{"price":3798.25,"qty":3.90773892}],"asks":[],"checksum":3394270885,"timestamp":"2024-06-01T17:51:49.665426Z"}]}
{"channel":"book","type":"update","data":[{"symbol":"ETH/USDT","bids":[{"price":3798.93,"qty":1.31714475}],"asks":[],"checksum":3905575080,"timestamp":"2024-06-01T17:51:49.674907Z"}]}
{"channel":"book","type":"update","data":[{"symbol":"ETH/USDT","bids":[{"price":3798.95,"qty":0.34000000}],"asks":[],"checksum":9532810,"timestamp":"2024-06-01T17:51:49.678152Z"}]}
{"channel":"book","type":"update","data":[{"symbol":"ETH/USDT","bids":[{"price":3798.92,"qty":1.83057370}],"asks":[],"checksum":3210523559,"timestamp":"2024-06-01T17:51:49.678175Z"}]}
{"channel":"book","type":"update","data":[{"symbol":"ETH/USDT","bids":[{"price":3798.92,"qty":0.51342895}],"asks":[],"checksum":2642037446,"timestamp":"2024-06-01T17:51:49.680885Z"}]}
{"channel":"book","type":"update","data":[{"symbol":"ETH/USDT","bids":[],"asks":[{"price":3800.61,"qty":0.00000000},{"price":3800.77,"qty":0.73120000}],"checksum":154606738,"timestamp":"2024-06-01T17:51:49.684314Z"}]}
{"channel":"book","type":"update","data":[{"symbol":"ETH/USDT","bids":[{"price":3799.11,"qty":0.00000000},{"price":3798.48,"qty":0.06693358}],"asks":[],"checksum":666837879,"timestamp":"2024-06-01T17:51:49.704325Z"}]}
{"channel":"book","type":"update","data":[{"symbol":"ETH/USDT","bids":[{"price":3798.96,"qty":0.07901790}],"asks":[],"checksum":366408241,"timestamp":"2024-06-01T17:51:49.704550Z"}]}
{"channel":"book","type":"update","data":[{"symbol":"ETH/USDT","bids":[{"price":3798.96,"qty":0.00000000},{"price":3798.48,"qty":0.06693358}],"asks":[],"checksum":666837879,"timestamp":"2024-06-01T17:51:49.710103Z"}]}
{"channel":"book","type":"update","data":[{"symbol":"ETH/USDT","bids":[{"price":3798.97,"qty":0.07901941}],"asks":[],"checksum":1212499725,"timestamp":"2024-06-01T17:51:49.710221Z"}]}
{"channel":"book","type":"update","data":[{"symbol":"ETH/USDT","bids":[{"price":3798.71,"qty":0.00000000},{"price":3798.48,"qty":0.06693358}],"asks":[],"checksum":3751439779,"timestamp":"2024-06-01T17:51:49.712916Z"}]}
{"channel":"book","type":"update","data":[{"symbol":"ETH/USDT","bids":[],"asks":[{"price":3799.20,"qty":0.00000000},{"price":3800.83,"qty":1.99847015}],"checksum":1812840926,"timestamp":"2024-06-01T17:51:49.741353Z"}]}
{"channel":"book","type":"update","data":[{"symbol":"ETH/USDT","bids":[{"price":3799.11,"qty":0.07901690}],"asks":[],"checksum":4156063987,"timestamp":"2024-06-01T17:51:49.746292Z"}]}
{"channel":"book","type":"update","data":[{"symbol":"ETH/USDT","bids":[{"price":3798.97,"qty":0.00000000},{"price":3798.48,"qty":0.06693358}],"asks":[],"checksum":1798056966,"timestamp":"2024-06-01T17:51:49.750095Z"}]}
{"channel":"book","type":"update","data":[{"symbol":"ETH/USDT","bids":[],"asks":[{"price":3800.17,"qty":0.00000000},{"price":3801.02,"qty":0.84627249}],"checksum":4225921130,"timestamp":"2024-06-01T17:51:49.941111Z"}]}
{"channel":"book","type":"update","data":[{"symbol":"ETH/USDT","bids":[],"asks":[{"price":3799.67,"qty":0.00000000},{"price":3801.15,"qty":0.73120000}],"checksum":357509395,"timestamp":"2024-06-01T17:51:50.117616Z"}]}
{"channel":"book","type":"update","data":[{"symbol":"ETH/USDT","bids":[],"asks":[{"price":3800.36,"qty":2.15500000}],"checksum":1854305289,"timestamp":"2024-06-01T17:51:50.119805Z"}]}
{"channel":"book","type":"update","data":[{"symbol":"ETH/USDT","bids":[],"asks":[{"price":3800.09,"qty":0.34000000}],"checksum":2839656845,"timestamp":"2024-06-01T17:51:50.120511Z"}]}
{"channel":"book","type":"update","data":[{"symbol":"ETH/USDT","bids":[{"price":3799.12,"qty":0.26342895}],"asks":[],"checksum":2210883425,"timestamp":"2024-06-01T17:51:50.121701Z"}]}
{"channel":"book","type":"update","data":[{"symbol":"ETH/USDT","bids":[],"asks":[{"price":3800.11,"qty":0.00000000},{"price":3801.02,"qty":0.84627249}],"checksum":3425237228,"timestamp":"2024-06-01T17:51:50.122384Z"}]}
{"channel":"book","type":"update","data":[{"symbol":"ETH/USDT","bids":[],"asks":[{"price":3800.17,"qty":0.72912968}],"checksum":3083442194,"timestamp":"2024-06-01T17:51:50.122554Z"}]}
{"channel":"book","type":"update","data":[{"symbol":"ETH/USDT","bids":[{"price":3799.30,"qty":0.73120000}],"asks":[],"checksum":4055695452,"timestamp":"2024-06-01T17:51:50.125083Z"}]}
{"channel":"book","type":"update","data":[{"symbol":"ETH/USDT","bids":[{"price":3798.91,"qty":0.73120000}],"asks":[],"checksum":4113783905,"timestamp":"2024-06-01T17:51:50.125333Z"}]}
{"channel":"book","type":"update","data":[{"symbol":"ETH/USDT","bids":[{"price":3798.92,"qty":0.25000000}],"asks":[],"checksum":2293580681,"timestamp":"2024-06-01T17:51:50.125483Z"}]}
{"channel":"book","type":"update","data":[{"symbol":"ETH/USDT","bids":[{"price":3799.13,"qty":0.07901683}],"asks":[],"checksum":1197062299,"timestamp":"2024-06-01T17:51:50.126326Z"}]}
{"channel":"book","type":"update","data":[{"symbol":"ETH/USDT","bids":[{"price":3799.11,"qty":0.00000000},{"price":3798.52,"qty":0.29500386}],"asks":[],"checksum":1126314390,"timestamp":"2024-06-01T17:51:50.126813Z"}]}
{"channel":"book","type":"update","data":[{"symbol":"ETH/USDT","bids":[{"price":3799.30,"qty":1.46240000}],"asks":[],"checksum":2896722506,"timestamp":"2024-06-01T17:51:50.161421Z"}]}
{"channel":"book","type":"update","data":[{"symbol":"ETH/USDT","bids":[{"price":3799.13,"qty":0.00000000},{"price":3798.51,"qty":0.73120000}],"asks":[],"checksum":2824480303,"timestamp":"2024-06-01T17:51:50.165308Z"}]}
{"channel":"book","type":"update","data":[{"symbol":"ETH/USDT","bids":[{"price":3799.30,"qty":0.73120000}],"asks":[],"checksum":667955867,"timestamp":"2024-06-01T17:51:50.167878Z"}]}
{"channel":"book","type":"update","data":[{"symbol":"ETH/USDT","bids":[{"price":3799.13,"qty":0.07901649}],"asks":[],"checksum":3129162047,"timestamp":"2024-06-01T17:51:50.172313Z"}]}
{"channel":"book","type":"update","data":[{"symbol":"ETH/USDT","bids":[{"price":3799.30,"qty":1.46240000}],"asks":[],"checksum":1426682595,"timestamp":"2024-06-01T17:51:50.178882Z"}]}
{"channel":"book","type":"update","data":[{"symbol":"ETH/USDT","bids":[{"price":3799.13,"qty":0.00000000},{"price":3798.51,"qty":0.73120000}],"asks":[],"checksum":2824480303,"timestamp":"2024-06-01T17:51:50.183022Z"}]}
{"channel":"book","type":"update","data":[{"symbol":"ETH/USDT","bids":[{"price":3799.30,"qty":0.73120000}],"asks":[],"checksum":667955867,"timestamp":"2024-06-01T17:51:50.266896Z"}]}
{"channel":"book","type":"update","data":[{"symbol":"ETH/USDT","bids":[],"asks":[{"price":3800.08,"qty":0.72912968}],"checksum":1985257742,"timestamp":"2024-06-01T17:51:50.271042Z"}]}
{"channel":"book","type":"update","data":[{"symbol":"ETH/USDT","bids":[{"price":3799.13,"qty":0.07901672}],"asks":[],"checksum":1387034430,"timestamp":"2024-06-01T17:51:50.271604Z"}]}
{"channel":"book","type":"update","data":[{"symbol":"ETH/USDT","bids":[{"price":3799.30,"qty":1.46240000}],"asks":[],"checksum":3056664646,"timestamp":"2024-06-01T17:51:50.341042Z"}]}
{"channel":"book","type":"update","data":[{"symbol":"ETH/USDT","bids":[],"asks":[{"price":3800.17,"qty":0.00000000},{"price":3800.83,"qty":1.99847015}],"checksum":3378335939,"timestamp":"2024-06-01T17:51:50.345167Z"}]}
{"channel":"book","type":"update","data":[{"symbol":"ETH/USDT","bids":[{"price":3799.13,"qty":0.00000000},{"price":3798.51,"qty":0.73120000}],"asks":[],"checksum":3049512584,"timestamp":"2024-06-01T17:51:50.345309Z"}]}
{"channel":"book","type":"update","data":[{"symbol":"ETH/USDT","bids":[{"price":3799.30,"qty":0.73120000}],"asks":[],"checksum":154726795,"timestamp":"2024-06-01T17:51:50.427464Z"}]}
{"channel":"book","type":"update","data":[{"symbol":"ETH/USDT","bids":[{"price":3799.13,"qty":0.07901667}],"asks":[],"checksum":3243277982,"timestamp":"2024-06-01T17:51:50.432649Z"}]}
{"channel":"book","type":"update","data":[{"symbol":"ETH/USDT","bids":[{"price":3798.58,"qty":0.19714722}],"asks":[],"checksum":222931781,"timestamp":"2024-06-01T17:51:50.467682Z"}]}
{"channel":"book","type":"update","data":[{"symbol":"ETH/USDT","bids":[{"price":3799.30,"qty":1.46240000}],"asks":[],"checksum":2430972660,"timestamp":"2024-06-01T17:51:50.481018Z"}]}
{"channel":"book","type":"update","data":[{"symbol":"ETH/USDT","bids":[{"price":3799.13,"qty":0.00000000},{"price":3798.52,"qty":0.29500386}],"asks":[],"checksum":3355370568,"timestamp":"2024-06-01T17:51:50.485774Z"}]}
{"channel":"book","type":"update","data":[{"symbol":"ETH/USDT","bids":[{"price":3799.30,"qty":0.73120000}],"asks":[],"checksum":2063977291,"timestamp":"2024-06-01T17:51:50.485990Z"}]}
{"channel":"book","type":"update","data":[{"symbol":"ETH/USDT","bids":[{"price":3799.13,"qty":0.07901671}],"asks":[],"checksum":1573957226,"timestamp":"2024-06-01T17:51:50.490763Z"}]}
{"channel":"book","type":"update","data":[{"symbol":"ETH/USDT","bids":[{"price":3799.30,"qty":1.46240000}],"asks":[],"checksum":3229399003,"timestamp":"2024-06-01T17:51:50.599103Z"}]}
{"channel":"book","type":"update","data":[{"symbol":"ETH/USDT","bids":[{"price":3799.13,"qty":0.00000000},{"price":3798.52,"qty":0.29500386}],"asks":[],"checksum":3355370568,"timestamp":"2024-06-01T17:51:50.603244Z"}]}
{"channel":"book","type":"update","data":[{"symbol":"ETH/USDT","bids":[{"price":3799.30,"qty":0.73120000}],"asks":[],"checksum":2063977291,"timestamp":"2024-06-01T17:51:50.616054Z"}]}
{"channel":"book","type":"update","data":[{"symbol":"ETH/USDT","bids":[{"price":3799.30,"qty":0.00000000},{"price":3798.51,"qty":0.73120000}],"asks":[],"checksum":3677401449,"timestamp":"2024-06-01T17:51:50.688846Z"}]}
{"channel":"book","type":"update","data":[{"symbol":"ETH/USDT","bids":[{"price":3799.25,"qty":0.73120000}],"asks":[],"checksum":2242083437,"timestamp":"2024-06-01T17:51:50.692370Z"}]}
{"channel":"book","type":"update","data":[{"symbol":"ETH/USDT","bids":[{"price":3798.58,"qty":0.00000000},{"price":3798.51,"qty":0.73120000}],"asks":[],"checksum":4154343597,"timestamp":"2024-06-01T17:51:50.990813Z"}]}
{"channel":"book","type":"update","data":[{"symbol":"ETH/USDT","bids":[{"price":3798.57,"qty":2.83186206}],"asks":[],"checksum":3352753117,"timestamp":"2024-06-01T17:51:51.030724Z"}]}
{"channel":"book","type":"update","data":[{"symbol":"ETH/USDT","bids":[],"asks":[{"price":3800.27,"qty":0.25000000}],"checksum":3101941431,"timestamp":"2024-06-01T17:51:51.087504Z"}]}
{"channel":"book","type":"update","data":[{"symbol":"ETH/USDT","bids":[{"price":3799.25,"qty":0.00000000},{"price":3798.48,"qty":0.06693358}],"asks":[],"checksum":2480787952,"timestamp":"2024-06-01T17:51:51.098804Z"}]}
{"channel":"book","type":"update","data":[{"symbol":"ETH/USDT","bids":[{"price":3799.23,"qty":0.73120000}],"asks":[],"checksum":2892039177,"timestamp":"2024-06-01T17:51:51.102632Z"}]}
{"channel":"book","type":"update","data":[{"symbol":"ETH/USDT","bids":[{"price":3799.24,"qty":0.26342895}],"asks":[],"checksum":3711178264,"timestamp":"2024-06-01T17:51:51.106233Z"}]}
{"channel":"book","type":"update","data":[{"symbol":"ETH/USDT","bids":[{"price":3799.10,"qty":0.00000000},{"price":3798.51,"qty":0.73120000}],"asks":[],"checksum":2874290490,"timestamp":"2024-06-01T17:51:51.109765Z"}]}
{"channel":"book","type":"update","data":[{"symbol":"ETH/USDT","bids":[{"price":3799.26,"qty":0.73120000}],"asks":[],"checksum":1373123011,"timestamp":"2024-06-01T17:51:51.109841Z"}]}
{"channel":"book","type":"update","data":[{"symbol":"ETH/USDT","bids":[{"price":3799.12,"qty":0.00000000},{"price":3798.51,"qty":0.73120000}],"asks":[],"checksum":3166134915,"timestamp":"2024-06-01T17:51:51.110019Z"}]}
{"channel":"book","type":"update","data":[{"symbol":"ETH/USDT","bids":[{"price":3799.24,"qty":0.34244576}],"asks":[],"checksum":3576930944,"timestamp":"2024-06-01T17:51:51.296952Z"}]}
{"channel":"book","type":"update","data":[{"symbol":"ETH/USDT","bids":[{"price":3798.57,"qty":2.63471212}],"asks":[],"checksum":3850047984,"timestamp":"2024-06-01T17:51:51.516381Z"}]}
{"channel":"book","type":"update","data":[{"symbol":"ETH/USDT","bids":[],"asks":[{"price":3800.08,"qty":0.00000000},{"price":3800.83,"qty":1.99847015}],"checksum":1058895816,"timestamp":"2024-06-01T17:51:51.565557Z"}]}
{"channel":"book","type":"update","data":[{"symbol":"ETH/USDT","bids":[{"price":3798.58,"qty":2.79800000}],"asks":[],"checksum":182029665,"timestamp":"2024-06-01T17:51:51.568123Z"}]}
{"channel":"book","type":"update","data":[{"symbol":"ETH/USDT","bids":[{"price":3799.27,"qty":0.07901681}],"asks":[],"checksum":601636377,"timestamp":"2024-06-01T17:51:51.569956Z"}]}
{"channel":"book","type":"update","data":[{"symbol":"ETH/USDT","bids":[{"price":3799.24,"qty":0.26342895}],"asks":[],"checksum":1921102580,"timestamp":"2024-06-01T17:51:51.569977Z"}]}
{"channel":"book","type":"update","data":[{"symbol":"ETH/USDT","bids":[{"price":3798.58,"qty":0.00000000},{"price":3798.52,"qty":0.29500386}],"asks":[],"checksum":2111977427,"timestamp":"2024-06-01T17:51:51.571560Z"}]}
{"channel":"book","type":"update","data":[{"symbol":"ETH/USDT","bids":[{"price":3799.31,"qty":0.73120000}],"asks":[],"checksum":183637599,"timestamp":"2024-06-01T17:51:51.574612Z"}]}
{"channel":"book","type":"update","data":[{"symbol":"ETH/USDT","bids":[{"price":3798.57,"qty":0.00000000},{"price":3798.52,"qty":0.29500386}],"asks":[],"checksum":2550982943,"timestamp":"2024-06-01T17:51:51.574707Z"}]}
{"channel":"book","type":"update","data":[{"symbol":"ETH/USDT","bids":[{"price":3799.31,"qty":1.46240000}],"asks":[],"checksum":972517661,"timestamp":"2024-06-01T17:51:51.579145Z"}]}
{"channel":"book","type":"update","data":[{"symbol":"ETH/USDT","bids":[{"price":3799.23,"qty":0.00000000},{"price":3798.51,"qty":0.73120000}],"asks":[],"checksum":925056899,"timestamp":"2024-06-01T17:51:51.579290Z"}]}
{"channel":"book","type":"update","data":[{"symbol":"ETH/USDT","bids":[{"price":3798.97,"qty":2.63442991}],"asks":[],"checksum":3231663506,"timestamp":"2024-06-01T17:51:51.579497Z"}]}
{"channel":"book","type":"update","data":[{"symbol":"ETH/USDT","bids":[{"price":3799.27,"qty":0.00000000},{"price":3798.51,"qty":0.73120000}],"asks":[],"checksum":2617786323,"timestamp":"2024-06-01T17:51:51.584855Z"}]}
{"channel":"book","type":"update","data":[{"symbol":"ETH/USDT","bids":[{"price":3798.60,"qty":0.19713784}],"asks":[],"checksum":728545351,"timestamp":"2024-06-01T17:51:51.755704Z"}]}
{"channel":"book","type":"update","data":[{"symbol":"ETH/USDT","bids":[{"price":3799.31,"qty":0.73120000}],"asks":[],"checksum":3884867656,"timestamp":"2024-06-01T17:51:51.941566Z"}]}
{"channel":"book","type":"update","data":[{"symbol":"ETH/USDT","bids":[{"price":3799.26,"qty":0.00000000},{"price":3798.51,"qty":0.73120000}],"asks":[],"checksum":3198762094,"timestamp":"2024-06-01T17:51:51.945980Z"}]}
{"channel":"book","type":"update","data":[{"symbol":"ETH/USDT","bids":[],"asks":[{"price":3800.55,"qty":5.99512968}],"checksum":3797906322,"timestamp":"2024-06-01T17:51:51.946128Z"}]}
{"channel":"book","type":"update","data":[{"symbol":"ETH/USDT","bids":[{"price":3798.95,"qty":0.00000000},{"price":3798.48,"qty":0.06693358}],"asks":[],"checksum":2915088823,"timestamp":"2024-06-01T17:51:51.948635Z"}]}
{"channel":"book","type":"update","data":[{"symbol":"ETH/USDT","bids":[{"price":3799.03,"qty":0.34000000}],"asks":[],"checksum":1645133843,"timestamp":"2024-06-01T17:51:51.948778Z"}]}
{"channel":"book","type":"update","data":[{"symbol":"ETH/USDT","bids":[{"price":3798.60,"qty":0.00000000},{"price":3798.48,"qty":0.06693358}],"asks":[],"checksum":2545147233,"timestamp":"2024-06-01T17:51:52.226053Z"}]}
{"channel":"book","type":"update","data":[{"symbol":"ETH/USDT","bids":[{"price":3798.69,"qty":2.79800000}],"asks":[],"checksum":2653355123,"timestamp":"2024-06-01T17:51:52.229076Z"}]}
{"channel":"book","type":"update","data":[{"symbol":"ETH/USDT","bids":[{"price":3799.31,"qty":0.00000000},{"price":3798.48,"qty":0.06693358}],"asks":[],"checksum":1993026383,"timestamp":"2024-06-01T17:51:52.278567Z"}]}
{"channel":"book","type":"update","data":[{"symbol":"ETH/USDT","bids":[{"price":3799.27,"qty":0.73120000}],"asks":[],"checksum":3071005239,"timestamp":"2024-06-01T17:51:52.282423Z"}]}
{"channel":"book","type":"update","data":[{"symbol":"ETH/USDT","bids":[{"price":3799.28,"qty":0.26342895}],"asks":[],"checksum":2146276475,"timestamp":"2024-06-01T17:51:52.286410Z"}]}
{"channel":"book","type":"update","data":[{"symbol":"ETH/USDT","bids":[{"price":3799.24,"qty":0.00000000},{"price":3798.51,"qty":0.73120000}],"asks":[],"checksum":1457265606,"timestamp":"2024-06-01T17:51:52.289906Z"}]}
{"channel":"book","type":"update","data":[{"symbol":"ETH/USDT","bids":[{"price":3799.29,"qty":0.73120000}],"asks":[],"checksum":4118781508,"timestamp":"2024-06-01T17:51:52.335683Z"}]}
{"channel":"book","type":"update","data":[{"symbol":"ETH/USDT","bids":[{"price":3799.27,"qty":0.00000000},{"price":3798.51,"qty":0.73120000}],"asks":[],"checksum":3902133605,"timestamp":"2024-06-01T17:51:52.345072Z"}]}
{"channel":"book","type":"update","data":[{"symbol":"ETH/USDT","bids":[{"price":3799.29,"qty":0.00000000},{"price":3798.48,"qty":0.06693358}],"asks":[],"checksum":1607376435,"timestamp":"2024-06-01T17:51:52.345953Z"}]}
{"channel":"book","type":"update","data":[{"symbol":"ETH/USDT","bids":[{"price":3799.29,"qty":0.73120000}],"asks":[],"checksum":3902133605,"timestamp":"2024-06-01T17:51:52.379502Z"}]}
{"channel":"book","type":"update","data":[{"symbol":"ETH/USDT","bids":[{"price":3799.29,"qty":0.00000000},{"price":3798.48,"qty":0.06693358}],"asks":[],"checksum":1607376435,"timestamp":"2024-06-01T17:51:52.483251Z"}]}
{"channel":"book","type":"update","data":[{"symbol":"ETH/USDT","bids":[{"price":3799.06,"qty":1.31700944}],"asks":[],"checksum":1192101507,"timestamp":"2024-06-01T17:51:52.580877Z"}]}
{"channel":"book","type":"update","data":[{"symbol":"ETH/USDT","bids":[],"asks":[{"price":3800.54,"qty":0.09627468}],"checksum":479089373,"timestamp":"2024-06-01T17:51:52.733762Z"}]}
{"channel":"book","type":"update","data":[{"symbol":"ETH/USDT","bids":[{"price":3799.28,"qty":0.99462895}],"asks":[],"checksum":622016673,"timestamp":"2024-06-01T17:51:52.841284Z"}]}
{"channel":"book","type":"update","data":[{"symbol":"ETH/USDT","bids":[{"price":3799.30,"qty":0.73120000}],"asks":[],"checksum":3897713262,"timestamp":"2024-06-01T17:51:52.961393Z"}]}
{"channel":"book","type":"update","data":[{"symbol":"ETH/USDT","bids":[],"asks":[{"price":3800.18,"qty":0.00000000},{"price":3800.83,"qty":1.99847015}],"checksum":832170863,"timestamp":"2024-06-01T17:51:53.037672Z"}]}
{"channel":"book","type":"update","data":[{"symbol":"ETH/USDT","bids":[],"asks":[{"price":3800.20,"qty":2.60743762}],"checksum":2118769842,"timestamp":"2024-06-01T17:51:53.041999Z"}]}
{"channel":"book","type":"update","data":[{"symbol":"ETH/USDT","bids":[],"asks":[{"price":3800.54,"qty":5.82475547}],"checksum":1991032939,"timestamp":"2024-06-01T17:51:53.042114Z"}]}
{"channel":"book","type":"update","data":[{"symbol":"ETH/USDT","bids":[{"price":3799.30,"qty":1.46240000}],"asks":[],"checksum":3918355696,"timestamp":"2024-06-01T17:51:53.339873Z"}]}
{"channel":"book","type":"update","data":[{"symbol":"ETH/USDT","bids":[{"price":3799.30,"qty":0.73120000}],"asks":[],"checksum":1991032939,"timestamp":"2024-06-01T17:51:53.749769Z"}]}
{"channel":"book","type":"update","data":[{"symbol":"ETH/USDT","bids":[{"price":3799.30,"qty":0.00000000},{"price":3798.51,"qty":0.73120000}],"asks":[],"checksum":3152911012,"timestamp":"2024-06-01T17:51:53.822194Z"}]}
{"channel":"book","type":"update","data":[{"symbol":"ETH/USDT","bids":[{"price":3799.03,"qty":0.00000000},{"price":3798.48,"qty":0.06693358}],"asks":[],"checksum":409618571,"timestamp":"2024-06-01T17:51:53.825107Z"}]}
{"channel":"book","type":"update","data":[{"symbol":"ETH/USDT","bids":[{"price":3799.13,"qty":0.34000000}],"asks":[],"checksum":1231399422,"timestamp":"2024-06-01T17:51:53.825288Z"}]}
{"channel":"book","type":"update","data":[{"symbol":"ETH/USDT","bids":[{"price":3799.28,"qty":0.26342895}],"asks":[],"checksum":1895351170,"timestamp":"2024-06-01T17:51:53.860422Z"}]}
{"channel":"book","type":"update","data":[{"symbol":"ETH/USDT","bids":[],"asks":[{"price":3799.88,"qty":0.73120000}],"checksum":4089342267,"timestamp":"2024-06-01T17:51:53.864197Z"}]}
{"channel":"book","type":"update","data":[{"symbol":"ETH/USDT","bids":[],"asks":[{"price":3799.87,"qty":0.73120000}],"checksum":3962754288,"timestamp":"2024-06-01T17:51:53.865459Z"}]}
{"channel":"book","type":"update","data":[{"symbol":"ETH/USDT","bids":[],"asks":[{"price":3799.88,"qty":0.00000000},{"price":3800.55,"qty":5.99512968}],"checksum":3929553950,"timestamp":"2024-06-01T17:51:53.868336Z"}]}
{"channel":"book","type":"update","data":[{"symbol":"ETH/USDT","bids":[],"asks":[{"price":3799.87,"qty":0.00000000},{"price":3800.77,"qty":0.73120000}],"checksum":1895351170,"timestamp":"2024-06-01T17:51:53.868677Z"}]}
{"channel":"book","type":"update","data":[{"symbol":"ETH/USDT","bids":[{"price":3799.28,"qty":0.99462895}],"asks":[],"checksum":1231399422,"timestamp":"2024-06-01T17:51:53.875567Z"}]}
{"channel":"book","type":"update","data":[{"symbol":"ETH/USDT","bids":[{"price":3799.28,"qty":0.26342895}],"asks":[],"checksum":1895351170,"timestamp":"2024-06-01T17:51:53.879354Z"}]}
{"channel":"book","type":"update","data":[{"symbol":"ETH/USDT","bids":[{"price":3799.29,"qty":0.73120000}],"asks":[],"checksum":1967613593,"timestamp":"2024-06-01T17:51:53.884403Z"}]}
{"channel":"book","type":"update","data":[{"symbol":"ETH/USDT","bids":[{"price":3799.29,"qty":0.00000000},{"price":3798.51,"qty":0.73120000}],"asks":[],"checksum":1895351170,"timestamp":"2024-06-01T17:51:53.887315Z"}]}
{"channel":"book","type":"update","data":[{"symbol":"ETH/USDT","bids":[{"price":3798.61,"qty":2.15500000}],"asks":[],"checksum":2011575608,"timestamp":"2024-06-01T17:51:53.965012Z"}]}
{"channel":"book","type":"update","data":[{"symbol":"ETH/USDT","bids":[],"asks":[{"price":3799.88,"qty":0.73120000}],"checksum":3319298234,"timestamp":"2024-06-01T17:51:53.979268Z"}]}
{"channel":"book","type":"update","data":[{"symbol":"ETH/USDT","bids":[],"asks":[{"price":3799.88,"qty":0.00000000},{"price":3800.77,"qty":0.73120000}],"checksum":2011575608,"timestamp":"2024-06-01T17:51:53.982639Z"}]}
{"channel":"book","type":"update","data":[{"symbol":"ETH/USDT","bids":[],"asks":[{"price":3799.89,"qty":0.73541065}],"checksum":1620045698,"timestamp":"2024-06-01T17:51:53.990469Z"}]}
{"channel":"book","type":"update","data":[{"symbol":"ETH/USDT","bids":[],"asks":[{"price":3799.89,"qty":0.00421065}],"checksum":2011575608,"timestamp":"2024-06-01T17:51:54.041134Z"}]}
{"channel":"book","type":"update","data":[{"symbol":"ETH/USDT","bids":[{"price":3799.30,"qty":0.73120000}],"asks":[],"checksum":2363761044,"timestamp":"2024-06-01T17:51:54.219275Z"}]}
{"channel":"book","type":"update","data":[{"symbol":"ETH/USDT","bids":[{"price":3799.31,"qty":0.26339773}],"asks":[],"checksum":4210289738,"timestamp":"2024-06-01T17:51:54.223082Z"}]}
{"channel":"book","type":"update","data":[{"symbol":"ETH/USDT","bids":[{"price":3799.28,"qty":0.00000000},{"price":3798.61,"qty":2.15500000}],"asks":[],"checksum":320456852,"timestamp":"2024-06-01T17:51:54.226983Z"}]}
{"channel":"book","type":"update","data":[{"symbol":"ETH/USDT","bids":[{"price":3799.30,"qty":0.00000000},{"price":3798.52,"qty":0.29500386}],"asks":[],"checksum":3396753574,"timestamp":"2024-06-01T17:51:54.273865Z"}]}
{"channel":"book","type":"update","data":[{"symbol":"ETH/USDT","bids":[],"asks":[{"price":3800.54,"qty":5.72848079}],"checksum":3871143724,"timestamp":"2024-06-01T17:51:55.078318Z"}]}
{"channel":"book","type":"update","data":[{"symbol":"ETH/USDT","bids":[],"asks":[{"price":3800.54,"qty":0.00000000},{"price":3800.83,"qty":1.99847015}],"checksum":1119496244,"timestamp":"2024-06-01T17:51:55.471041Z"}]}
{"channel":"book","type":"update","data":[{"symbol":"ETH/USDT","bids":[],"asks":[{"price":3800.54,"qty":9.36969783}],"checksum":415491125,"timestamp":"2024-06-01T17:51:55.475667Z"}]}
{"channel":"book","type":"update","data":[{"symbol":"ETH/USDT","bids":[{"price":3799.32,"qty":0.73120000}],"asks":[],"checksum":2390304775,"timestamp":"2024-06-01T17:51:55.480484Z"}]}
{"channel":"book","type":"update","data":[{"symbol":"ETH/USDT","bids":[{"price":3799.33,"qty":0.26339773}],"asks":[],"checksum":3143580647,"timestamp":"2024-06-01T17:51:55.485398Z"}]}
{"channel":"book","type":"update","data":[{"symbol":"ETH/USDT","bids":[{"price":3799.31,"qty":0.00000000},{"price":3798.61,"qty":2.15500000}],"asks":[],"checksum":3097517827,"timestamp":"2024-06-01T17:51:55.489004Z"}]}
{"channel":"book","type":"update","data":[{"symbol":"ETH/USDT","bids":[{"price":3799.32,"qty":0.00000000},{"price":3798.52,"qty":0.29500386}],"asks":[],"checksum":3279154567,"timestamp":"2024-06-01T17:51:55.541251Z"}]}
{"channel":"book","type":"update","data":[{"symbol":"ETH/USDT","bids":[{"price":3799.33,"qty":0.99459773}],"asks":[],"checksum":1744694290,"timestamp":"2024-06-01T17:51:55.541519Z"}]}
{"channel":"book","type":"update","data":[{"symbol":"ETH/USDT","bids":[{"price":3799.33,"qty":0.26339773}],"asks":[],"checksum":3279154567,"timestamp":"2024-06-01T17:51:55.783905Z"}]}
{"channel":"book","type":"update","data":[{"symbol":"ETH/USDT","bids":[{"price":3799.33,"qty":0.99459773}],"asks":[],"checksum":1744694290,"timestamp":"2024-06-01T17:51:55.804250Z"}]}
{"channel":"book","type":"update","data":[{"symbol":"ETH/USDT","bids":[{"price":3799.37,"qty":0.73120000}],"asks":[],"checksum":1449535068,"timestamp":"2024-06-01T17:51:55.933559Z"}]}
{"channel":"book","type":"update","data":[{"symbol":"ETH/USDT","bids":[{"price":3799.33,"qty":0.26339773}],"asks":[],"checksum":755768141,"timestamp":"2024-06-01T17:51:55.936899Z"}]}
{"channel":"book","type":"update","data":[{"symbol":"ETH/USDT","bids":[{"price":3799.37,"qty":0.00000000},{"price":3798.52,"qty":0.29500386}],"asks":[],"checksum":3279154567,"timestamp":"2024-06-01T17:51:55.937771Z"}]}
{"channel":"book","type":"update","data":[{"symbol":"ETH/USDT","bids":[{"price":3799.36,"qty":0.73120000}],"asks":[],"checksum":1087643540,"timestamp":"2024-06-01T17:51:55.945129Z"}]}
{"channel":"book","type":"update","data":[{"symbol":"ETH/USDT","bids":[{"price":3799.43,"qty":0.73120000}],"asks":[],"checksum":2714813441,"timestamp":"2024-06-01T17:51:55.945480Z"}]}
{"channel":"book","type":"update","data":[{"symbol":"ETH/USDT","bids":[{"price":3799.36,"qty":0.00000000},{"price":3798.61,"qty":2.15500000}],"asks":[],"checksum":3500350439,"timestamp":"2024-06-01T17:51:55.949236Z"}]}
{"channel":"book","type":"update","data":[{"symbol":"ETH/USDT","bids":[],"asks":[{"price":3800.34,"qty":0.00000000},{"price":3800.83,"qty":1.99847015}],"checksum":3830409169,"timestamp":"2024-06-01T17:51:55.949749Z"}]}
{"channel":"book","type":"update","data":[{"symbol":"ETH/USDT","bids":[],"asks":[{"price":3800.27,"qty":0.98120000}],"checksum":3635715548,"timestamp":"2024-06-01T17:51:55.954738Z"}]}
{"channel":"book","type":"update","data":[{"symbol":"ETH/USDT","bids":[{"price":3799.43,"qty":1.46240000}],"asks":[],"checksum":1024830809,"timestamp":"2024-06-01T17:51:55.954945Z"}]}
{"channel":"book","type":"update","data":[{"symbol":"ETH/USDT","bids":[{"price":3799.43,"qty":0.73120000}],"asks":[],"checksum":3635715548,"timestamp":"2024-06-01T17:51:55.957873Z"}]}
{"channel":"book","type":"update","data":[{"symbol":"ETH/USDT","bids":[{"price":3799.43,"qty":0.00000000},{"price":3798.52,"qty":0.29500386}],"asks":[],"checksum":3412356028,"timestamp":"2024-06-01T17:51:55.981287Z"}]}
{"channel":"book","type":"update","data":[{"symbol":"ETH/USDT","bids":[{"price":3799.33,"qty":0.99459773}],"asks":[],"checksum":1877633577,"timestamp":"2024-06-01T17:51:55.996146Z"}]}
{"channel":"book","type":"update","data":[{"symbol":"ETH/USDT","bids":[{"price":3799.34,"qty":0.73120000}],"asks":[],"checksum":3893996812,"timestamp":"2024-06-01T17:51:56.003094Z"}]}
{"channel":"book","type":"update","data":[{"symbol":"ETH/USDT","bids":[{"price":3799.34,"qty":1.46240000}],"asks":[],"checksum":2857870691,"timestamp":"2024-06-01T17:51:56.061522Z"}]}
{"channel":"book","type":"update","data":[{"symbol":"ETH/USDT","bids":[{"price":3799.35,"qty":0.26339773}],"asks":[],"checksum":1590028820,"timestamp":"2024-06-01T17:51:56.065279Z"}]}
{"channel":"book","type":"update","data":[{"symbol":"ETH/USDT","bids":[{"price":3799.38,"qty":0.73120000}],"asks":[],"checksum":1513382312,"timestamp":"2024-06-01T17:51:56.068893Z"}]}
{"channel":"book","type":"update","data":[{"symbol":"ETH/USDT","bids":[{"price":3799.33,"qty":0.73120000}],"asks":[],"checksum":475361741,"timestamp":"2024-06-01T17:51:56.069185Z"}]}
{"channel":"book","type":"update","data":[{"symbol":"ETH/USDT","bids":[{"price":3799.34,"qty":0.73120000}],"asks":[],"checksum":2921968933,"timestamp":"2024-06-01T17:51:56.069473Z"}]}
{"channel":"book","type":"update","data":[{"symbol":"ETH/USDT","bids":[{"price":3799.33,"qty":0.00000000},{"price":3798.69,"qty":2.79800000}],"asks":[],"checksum":2327259053,"timestamp":"2024-06-01T17:51:56.069613Z"}]}
{"channel":"book","type":"update","data":[{"symbol":"ETH/USDT","bids":[{"price":3798.98,"qty":0.29500386}],"asks":[],"checksum":1689197169,"timestamp":"2024-06-01T17:51:56.139575Z"}]}
{"channel":"book","type":"update","data":[{"symbol":"ETH/USDT","bids":[{"price":3799.38,"qty":0.00000000},{"price":3798.69,"qty":2.79800000}],"asks":[],"checksum":1123556918,"timestamp":"2024-06-01T17:51:56.273476Z"}]}
{"channel":"book","type":"update","data":[{"symbol":"ETH/USDT","bids":[{"price":3799.34,"qty":0.00000000},{"price":3798.61,"qty":2.15500000}],"asks":[],"checksum":1418962141,"timestamp":"2024-06-01T17:51:56.275203Z"}]}
{"channel":"book","type":"update","data":[{"symbol":"ETH/USDT","bids":[{"price":3798.69,"qty":0.00000000},{"price":3798.51,"qty":0.73120000}],"asks":[],"checksum":2126959606,"timestamp":"2024-06-01T17:51:56.275632Z"}]}
{"channel":"book","type":"update","data":[{"symbol":"ETH/USDT","bids":[{"price":3798.91,"qty":0.00000000},{"price":3798.48,"qty":0.06693358}],"asks":[],"checksum":1287177400,"timestamp":"2024-06-01T17:51:56.278352Z"}]}
{"channel":"book","type":"update","data":[{"symbol":"ETH/USDT","bids":[],"asks":[{"price":3799.87,"qty":0.73120000}],"checksum":3048251058,"timestamp":"2024-06-01T17:51:56.278591Z"}]}
{"channel":"book","type":"update","data":[{"symbol":"ETH/USDT","bids":[{"price":3798.61,"qty":0.00000000},{"price":3798.41,"qty":0.19712225}],"asks":[],"checksum":3395004964,"timestamp":"2024-06-01T17:51:56.278644Z"}]}
{"channel":"book","type":"update","data":[{"symbol":"ETH/USDT","bids":[],"asks":[{"price":3799.87,"qty":1.46240000}],"checksum":623553999,"timestamp":"2024-06-01T17:51:56.278768Z"}]}
{"channel":"book","type":"update","data":[{"symbol":"ETH/USDT","bids":[{"price":3799.35,"qty":0.00000000},{"price":3798.31,"qty":0.39451602}],"asks":[],"checksum":1651416539,"timestamp":"2024-06-01T17:51:56.280662Z"}]}
{"channel":"book","type":"update","data":[{"symbol":"ETH/USDT","bids":[{"price":3798.97,"qty":0.00000000},{"price":3798.27,"qty":0.24772343}],"asks":[],"checksum":305899655,"timestamp":"2024-06-01T17:51:56.281595Z"}]}
{"channel":"book","type":"update","data":[{"symbol":"ETH/USDT","bids":[{"price":3798.37,"qty":2.79800000}],"asks":[],"checksum":2666279992,"timestamp":"2024-06-01T17:51:56.282494Z"}]}
{"channel":"book","type":"update","data":[{"symbol":"ETH/USDT","bids":[{"price":3798.97,"qty":0.73120000}],"asks":[],"checksum":2853861999,"timestamp":"2024-06-01T17:51:56.284541Z"}]}
{"channel":"book","type":"update","data":[{"symbol":"ETH/USDT","bids":[],"asks":[{"price":3799.87,"qty":0.73120000}],"checksum":1164672388,"timestamp":"2024-06-01T17:51:56.284821Z"}]}
{"channel":"book","type":"update","data":[{"symbol":"ETH/USDT","bids":[{"price":3798.57,"qty":2.63471239}],"asks":[],"checksum":3870584464,"timestamp":"2024-06-01T17:51:56.287717Z"}]}
{"channel":"book","type":"update","data":[{"symbol":"ETH/USDT","bids":[],"asks":[{"price":3799.87,"qty":1.46240000}],"checksum":163932539,"timestamp":"2024-06-01T17:51:56.288029Z"}]}
{"channel":"book","type":"update","data":[{"symbol":"ETH/USDT","bids":[],"asks":[{"price":3800.21,"qty":0.00000000},{"price":3800.83,"qty":1.99847015}],"checksum":2112684108,"timestamp":"2024-06-01T17:51:56.291456Z"}]}
{"channel":"book","type":"update","data":[{"symbol":"ETH/USDT","bids":[],"asks":[{"price":3799.86,"qty":2.63381860}],"checksum":3503633526,"timestamp":"2024-06-01T17:51:56.296325Z"}]}
{"channel":"book","type":"update","data":[{"symbol":"ETH/USDT","bids":[],"asks":[{"price":3799.87,"qty":0.73120000}],"checksum":1594070703,"timestamp":"2024-06-01T17:51:56.300658Z"}]}
{"channel":"book","type":"update","data":[{"symbol":"ETH/USDT","bids":[],"asks":[{"price":3799.82,"qty":2.63453990}],"checksum":2027207177,"timestamp":"2024-06-01T17:51:56.301883Z"}]}
{"channel":"book","type":"update","data":[{"symbol":"ETH/USDT","bids":[],"asks":[{"price":3799.83,"qty":0.73120000}],"checksum":2486523603,"timestamp":"2024-06-01T17:51:56.303466Z"}]}
{"channel":"book","type":"update","data":[{"symbol":"ETH/USDT","bids":[{"price":3798.97,"qty":0.00000000},{"price":3798.37,"qty":2.79800000}],"asks":[],"checksum":2843280008,"timestamp":"2024-06-01T17:51:56.304964Z"}]}
{"channel":"book","type":"update","data":[{"symbol":"ETH/USDT","bids":[],"asks":[{"price":3799.83,"qty":0.00000000},{"price":3800.55,"qty":5.99512968}],"checksum":3482572974,"timestamp":"2024-06-01T17:51:56.305897Z"}]}
{"channel":"book","type":"update","data":[{"symbol":"ETH/USDT","bids":[{"price":3799.13,"qty":0.00000000},{"price":3798.31,"qty":0.39451602}],"asks":[],"checksum":3053766905,"timestamp":"2024-06-01T17:51:56.307989Z"}]}
{"channel":"book","type":"update","data":[{"symbol":"ETH/USDT","bids":[{"price":3799.12,"qty":0.73120000}],"asks":[],"checksum":3865519663,"timestamp":"2024-06-01T17:51:56.312128Z"}]}
{"channel":"book","type":"update","data":[{"symbol":"ETH/USDT","bids":[],"asks":[{"price":3799.87,"qty":0.00000000},{"price":3800.77,"qty":0.73120000}],"checksum":3711490244,"timestamp":"2024-06-01T17:51:56.315604Z"}]}
{"channel":"book","type":"update","data":[{"symbol":"ETH/USDT","bids":[{"price":3799.14,"qty":0.41000000}],"asks":[],"checksum":1933340626,"timestamp":"2024-06-01T17:51:56.319680Z"}]}
{"channel":"book","type":"update","data":[{"symbol":"ETH/USDT","bids":[{"price":3798.48,"qty":0.00000000},{"price":3798.37,"qty":2.79800000}],"asks":[],"checksum":1796531391,"timestamp":"2024-06-01T17:51:56.330807Z"}]}
{"channel":"book","type":"update","data":[{"symbol":"ETH/USDT","bids":[],"asks":[{"price":3799.81,"qty":0.73120000}],"checksum":3169119844,"timestamp":"2024-06-01T17:51:56.331814Z"}]}
{"channel":"book","type":"update","data":[{"symbol":"ETH/USDT","bids":[{"price":3799.12,"qty":0.00000000},{"price":3798.31,"qty":0.39451602}],"asks":[],"checksum":2502450453,"timestamp":"2024-06-01T17:51:56.332122Z"}]}
{"channel":"book","type":"update","data":[{"symbol":"ETH/USDT","bids":[],"asks":[{"price":3799.81,"qty":0.00000000},{"price":3800.77,"qty":0.73120000}],"checksum":1121474510,"timestamp":"2024-06-01T17:51:56.335405Z"}]}
{"channel":"book","type":"update","data":[{"symbol":"ETH/USDT","bids":[],"asks":[{"price":3799.80,"qty":0.73120000}],"checksum":174770575,"timestamp":"2024-06-01T17:51:56.338089Z"}]}
{"channel":"book","type":"update","data":[{"symbol":"ETH/USDT","bids":[],"asks":[{"price":3799.79,"qty":0.73120000}],"checksum":3159987335,"timestamp":"2024-06-01T17:51:56.339065Z"}]}
{"channel":"book","type":"update","data":[{"symbol":"ETH/USDT","bids":[],"asks":[{"price":3799.80,"qty":0.00000000},{"price":3800.55,"qty":5.99512968}],"checksum":1206419545,"timestamp":"2024-06-01T17:51:56.345205Z"}]}
{"channel":"book","type":"update","data":[{"symbol":"ETH/USDT","bids":[],"asks":[{"price":3799.79,"qty":1.46240000}],"checksum":3013057994,"timestamp":"2024-06-01T17:51:56.347675Z"}]}
{"channel":"book","type":"update","data":[{"symbol":"ETH/USDT","bids":[],"asks":[{"price":3799.79,"qty":0.73120000}],"checksum":1206419545,"timestamp":"2024-06-01T17:51:56.352739Z"}]}
{"channel":"book","type":"update","data":[{"symbol":"ETH/USDT","bids":[],"asks":[{"price":3799.79,"qty":1.46240000}],"checksum":3013057994,"timestamp":"2024-06-01T17:51:56.381869Z"}]}
{"channel":"book","type":"update","data":[{"symbol":"ETH/USDT","bids":[{"price":3798.42,"qty":2.15500000}],"asks":[],"checksum":3248584789,"timestamp":"2024-06-01T17:51:56.382423Z"}]}
{"channel":"book","type":"update","data":[{"symbol":"ETH/USDT","bids":[],"asks":[{"price":3799.78,"qty":0.72912968}],"checksum":3845802636,"timestamp":"2024-06-01T17:51:56.385815Z"}]}
{"channel":"book","type":"update","data":[{"symbol":"ETH/USDT","bids":[],"asks":[{"price":3799.79,"qty":0.73120000}],"checksum":1809090665,"timestamp":"2024-06-01T17:51:56.390582Z"}]}
{"channel":"book","type":"update","data":[{"symbol":"ETH/USDT","bids":[{"price":3799.06,"qty":0.00000000},{"price":3798.31,"qty":0.39451602}],"asks":[],"checksum":2844392719,"timestamp":"2024-06-01T17:51:56.390872Z"}]}
{"channel":"book","type":"update","data":[{"symbol":"ETH/USDT","bids":[],"asks":[{"price":3799.79,"qty":0.00000000},{"price":3800.55,"qty":5.99512968}],"checksum":2248407015,"timestamp":"2024-06-01T17:51:56.391462Z"}]}
{"channel":"book","type":"update","data":[{"symbol":"ETH/USDT","bids":[],"asks":[{"price":3799.77,"qty":0.73120000}],"checksum":2631164584,"timestamp":"2024-06-01T17:51:56.393580Z"}]}
{"channel":"book","type":"update","data":[{"symbol":"ETH/USDT","bids":[],"asks":[{"price":3799.77,"qty":0.00000000},{"price":3800.55,"qty":5.99512968}],"checksum":2248407015,"timestamp":"2024-06-01T17:51:56.397342Z"}]}
{"channel":"book","type":"update","data":[{"symbol":"ETH/USDT","bids":[],"asks":[{"price":3799.75,"qty":0.73120000}],"checksum":3175422565,"timestamp":"2024-06-01T17:51:56.400262Z"}]}
{"channel":"book","type":"update","data":[{"symbol":"ETH/USDT","bids":[],"asks":[{"price":3799.78,"qty":1.46032968}],"checksum":93831981,"timestamp":"2024-06-01T17:51:56.401149Z"}]}
{"channel":"book","type":"update","data":[{"symbol":"ETH/USDT","bids":[],"asks":[{"price":3799.75,"qty":0.00000000},{"price":3800.55,"qty":5.99512968}],"checksum":2081552275,"timestamp":"2024-06-01T17:51:56.403787Z"}]}
{"channel":"book","type":"update","data":[{"symbol":"ETH/USDT","bids":[],"asks":[{"price":3799.75,"qty":0.73120000}],"checksum":93831981,"timestamp":"2024-06-01T17:51:56.406749Z"}]}
{"channel":"book","type":"update","data":[{"symbol":"ETH/USDT","bids":[],"asks":[{"price":3799.75,"qty":0.00000000},{"price":3800.55,"qty":5.99512968}],"checksum":2081552275,"timestamp":"2024-06-01T17:51:56.410198Z"}]}
{"channel":"book","type":"update","data":[{"symbol":"ETH/USDT","bids":[],"asks":[{"price":3799.76,"qty":0.73120000}],"checksum":2132900034,"timestamp":"2024-06-01T17:51:56.416792Z"}]}
{"channel":"book","type":"update","data":[{"symbol":"ETH/USDT","bids":[],"asks":[{"price":3799.76,"qty":0.00000000},{"price":3800.55,"qty":5.99512968}],"checksum":2081552275,"timestamp":"2024-06-01T17:51:56.420161Z"}]}
{"channel":"book","type":"update","data":[{"symbol":"ETH/USDT","bids":[],"asks":[{"price":3800.55,"qty":5.26600000}],"checksum":3136720901,"timestamp":"2024-06-01T17:51:56.420695Z"}]}
{"channel":"book","type":"update","data":[{"symbol":"ETH/USDT","bids":[],"asks":[{"price":3799.74,"qty":0.73120000}],"checksum":2597672887,"timestamp":"2024-06-01T17:51:56.428209Z"}]}
{"channel":"book","type":"update","data":[{"symbol":"ETH/USDT","bids":[],"asks":[{"price":3799.74,"qty":0.00000000},{"price":3800.55,"qty":5.26600000}],"checksum":3136720901,"timestamp":"2024-06-01T17:51:56.431579Z"}]}
{"channel":"book","type":"update","data":[{"symbol":"ETH/USDT","bids":[],"asks":[{"price":3799.75,"qty":0.73120000}],"checksum":93831981,"timestamp":"2024-06-01T17:51:56.438117Z"}]}
{"channel":"book","type":"update","data":[{"symbol":"ETH/USDT","bids":[],"asks":[{"price":3799.75,"qty":0.00000000},{"price":3800.55,"qty":5.26600000}],"checksum":3136720901,"timestamp":"2024-06-01T17:51:56.441272Z"}]}
{"channel":"book","type":"update","data":[{"symbol":"ETH/USDT","bids":[],"asks":[{"price":3799.77,"qty":0.73120000}],"checksum":3764644952,"timestamp":"2024-06-01T17:51:56.447177Z"}]}
{"channel":"book","type":"update","data":[{"symbol":"ETH/USDT","bids":[],"asks":[{"price":3799.77,"qty":0.00000000},{"price":3800.55,"qty":5.26600000}],"checksum":3136720901,"timestamp":"2024-06-01T17:51:56.450331Z"}]}
{"channel":"book","type":"update","data":[{"symbol":"ETH/USDT","bids":[],"asks":[{"price":3799.77,"qty":0.73120000}],"checksum":3764644952,"timestamp":"2024-06-01T17:51:56.453391Z"}]}
{"channel":"book","type":"update","data":[{"symbol":"ETH/USDT","bids":[],"asks":[{"price":3799.77,"qty":0.00000000},{"price":3800.55,"qty":5.26600000}],"checksum":3136720901,"timestamp":"2024-06-01T17:51:56.456671Z"}]}
{"channel":"book","type":"update","data":[{"symbol":"ETH/USDT","bids":[],"asks":[{"price":3799.77,"qty":0.73120000}],"checksum":3764644952,"timestamp":"2024-06-01T17:51:56.459272Z"}]}
{"channel":"book","type":"update","data":[{"symbol":"ETH/USDT","bids":[],"asks":[{"price":3799.77,"qty":0.00000000},{"price":3800.55,"qty":5.26600000}],"checksum":3136720901,"timestamp":"2024-06-01T17:51:56.462826Z"}]}
{"channel":"book","type":"update","data":[{"symbol":"ETH/USDT","bids":[],"asks":[{"price":3799.77,"qty":0.73120000}],"checksum":3764644952,"timestamp":"2024-06-01T17:51:56.465413Z"}]}
{"channel":"book","type":"update","data":[{"symbol":"ETH/USDT","bids":[],"asks":[{"price":3799.77,"qty":0.00000000},{"price":3800.55,"qty":5.26600000}],"checksum":3136720901,"timestamp":"2024-06-01T17:51:56.468745Z"}]}
{"channel":"book","type":"update","data":[{"symbol":"ETH/USDT","bids":[],"asks":[{"price":3799.77,"qty":0.73120000}],"checksum":3764644952,"timestamp":"2024-06-01T17:51:56.471329Z"}]}
{"channel":"book","type":"update","data":[{"symbol":"ETH/USDT","bids":[],"asks":[{"price":3799.77,"qty":0.00000000},{"price":3800.55,"qty":5.26600000}],"checksum":3136720901,"timestamp":"2024-06-01T17:51:56.474955Z"}]}
{"channel":"book","type":"update","data":[{"symbol":"ETH/USDT","bids":[],"asks":[{"price":3799.77,"qty":0.73120000}],"checksum":3764644952,"timestamp":"2024-06-01T17:51:56.477697Z"}]}
{"channel":"book","type":"update","data":[{"symbol":"ETH/USDT","bids":[],"asks":[{"price":3799.77,"qty":0.00000000},{"price":3800.55,"qty":5.26600000}],"checksum":3136720901,"timestamp":"2024-06-01T17:51:56.481068Z"}]}
{"channel":"book","type":"update","data":[{"symbol":"ETH/USDT","bids":[],"asks":[{"price":3799.75,"qty":0.73120000}],"checksum":93831981,"timestamp":"2024-06-01T17:51:56.484402Z"}]}
{"channel":"book","type":"update","data":[{"symbol":"ETH/USDT","bids":[],"asks":[{"price":3799.75,"qty":0.00000000},{"price":3800.55,"qty":5.26600000}],"checksum":3136720901,"timestamp":"2024-06-01T17:51:56.487726Z"}]}
{"channel":"book","type":"update","data":[{"symbol":"ETH/USDT","bids":[],"asks":[{"price":3799.78,"qty":0.72912968}],"checksum":1088721009,"timestamp":"2024-06-01T17:51:56.489265Z"}]}
{"channel":"book","type":"update","data":[{"symbol":"ETH/USDT","bids":[],"asks":[{"price":3799.77,"qty":0.73120000}],"checksum":2631164584,"timestamp":"2024-06-01T17:51:56.496281Z"}]}
{"channel":"book","type":"update","data":[{"symbol":"ETH/USDT","bids":[],"asks":[{"price":3799.77,"qty":0.00000000},{"price":3800.55,"qty":5.26600000}],"checksum":1088721009,"timestamp":"2024-06-01T17:51:56.500096Z"}]}
{"channel":"book","type":"update","data":[{"symbol":"ETH/USDT","bids":[],"asks":[{"price":3799.78,"qty":1.46032968}],"checksum":3136720901,"timestamp":"2024-06-01T17:51:56.506537Z"}]}
{"channel":"book","type":"update","data":[{"symbol":"ETH/USDT","bids":[{"price":3798.41,"qty":0.00000000},{"price":3798.27,"qty":0.24772343}],"asks":[],"checksum":261301105,"timestamp":"2024-06-01T17:51:56.665425Z"}]}
{"channel":"book","type":"update","data":[{"symbol":"ETH/USDT","bids":[{"price":3798.37,"qty":2.99512939}],"asks":[],"checksum":26146205,"timestamp":"2024-06-01T17:51:56.705950Z"}]}
{"channel":"book","type":"update","data":[{"symbol":"ETH/USDT","bids":[{"price":3798.37,"qty":0.19712939}],"asks":[],"checksum":3210971928,"timestamp":"2024-06-01T17:51:56.720592Z"}]}
{"channel":"book","type":"update","data":[{"symbol":"ETH/USDT","bids":[],"asks":[{"price":3799.78,"qty":0.72912968}],"checksum":2724109318,"timestamp":"2024-06-01T17:51:56.802546Z"}]}
{"channel":"book","type":"update","data":[{"symbol":"ETH/USDT","bids":[],"asks":[{"price":3799.78,"qty":0.00000000},{"price":3800.77,"qty":0.73120000}],"checksum":1916622280,"timestamp":"2024-06-01T17:51:56.806910Z"}]}
{"channel":"book","type":"update","data":[{"symbol":"ETH/USDT","bids":[],"asks":[{"price":3799.81,"qty":0.72912968}],"checksum":2457211494,"timestamp":"2024-06-01T17:51:56.806956Z"}]}
{"channel":"book","type":"update","data":[{"symbol":"ETH/USDT","bids":[],"asks":[{"price":3799.81,"qty":1.46032968}],"checksum":4074881742,"timestamp":"2024-06-01T17:51:56.820438Z"}]}
{"channel":"book","type":"update","data":[{"symbol":"ETH/USDT","bids":[{"price":3798.77,"qty":1.31708923}],"asks":[],"checksum":460128539,"timestamp":"2024-06-01T17:51:56.851075Z"}]}
{"channel":"book","type":"update","data":[{"symbol":"ETH/USDT","bids":[],"asks":[{"price":3799.81,"qty":0.72912968}],"checksum":3271605521,"timestamp":"2024-06-01T17:51:56.944590Z"}]}
{"channel":"book","type":"update","data":[{"symbol":"ETH/USDT","bids":[],"asks":[{"price":3799.80,"qty":0.73120000}],"checksum":1856958552,"timestamp":"2024-06-01T17:51:57.181449Z"}]}
{"channel":"book","type":"update","data":[{"symbol":"ETH/USDT","bids":[],"asks":[{"price":3799.80,"qty":0.00000000},{"price":3800.55,"qty":5.26600000}],"checksum":3271605521,"timestamp":"2024-06-01T17:51:57.184619Z"}]}
{"channel":"book","type":"update","data":[{"symbol":"ETH/USDT","bids":[],"asks":[{"price":3799.79,"qty":0.72912968}],"checksum":994457880,"timestamp":"2024-06-01T17:51:57.186392Z"}]}
{"channel":"book","type":"update","data":[{"symbol":"ETH/USDT","bids":[],"asks":[{"price":3799.79,"qty":1.46032968}],"checksum":1145669082,"timestamp":"2024-06-01T17:51:57.195393Z"}]}
{"channel":"book","type":"update","data":[{"symbol":"ETH/USDT","bids":[{"price":3798.37,"qty":0.00000000},{"price":3798.27,"qty":0.24772343}],"asks":[],"checksum":3503179776,"timestamp":"2024-06-01T17:51:57.280299Z"}]}
{"channel":"book","type":"update","data":[{"symbol":"ETH/USDT","bids":[{"price":3798.30,"qty":2.79800000}],"asks":[],"checksum":3169721386,"timestamp":"2024-06-01T17:51:57.323374Z"}]}
{"channel":"book","type":"update","data":[{"symbol":"ETH/USDT","bids":[],"asks":[{"price":3799.79,"qty":2.19152968}],"checksum":1651347471,"timestamp":"2024-06-01T17:51:57.337625Z"}]}
{"channel":"book","type":"update","data":[{"symbol":"ETH/USDT","bids":[],"asks":[{"price":3799.79,"qty":1.46240000}],"checksum":110054678,"timestamp":"2024-06-01T17:51:57.341606Z"}]}
{"channel":"book","type":"update","data":[{"symbol":"ETH/USDT","bids":[],"asks":[{"price":3799.79,"qty":0.73120000}],"checksum":4075835525,"timestamp":"2024-06-01T17:51:57.408555Z"}]}
{"channel":"book","type":"update","data":[{"symbol":"ETH/USDT","bids":[],"asks":[{"price":3799.78,"qty":0.72912968}],"checksum":1748452657,"timestamp":"2024-06-01T17:51:57.412799Z"}]}
{"channel":"book","type":"update","data":[{"symbol":"ETH/USDT","bids":[],"asks":[{"price":3799.79,"qty":0.00000000},{"price":3800.54,"qty":9.36969783}],"checksum":1454974096,"timestamp":"2024-06-01T17:51:57.417067Z"}]}
{"channel":"book","type":"update","data":[{"symbol":"ETH/USDT","bids":[],"asks":[{"price":3799.78,"qty":1.46032968}],"checksum":2896897252,"timestamp":"2024-06-01T17:51:57.419875Z"}]}
{"channel":"book","type":"update","data":[{"symbol":"ETH/USDT","bids":[],"asks":[{"price":3800.53,"qty":0.35677831}],"checksum":3805180475,"timestamp":"2024-06-01T17:51:57.439800Z"}]}
{"channel":"book","type":"update","data":[{"symbol":"ETH/USDT","bids":[],"asks":[{"price":3799.78,"qty":2.19152968}],"checksum":3671888598,"timestamp":"2024-06-01T17:51:57.572540Z"}]}
{"channel":"book","type":"update","data":[{"symbol":"ETH/USDT","bids":[],"asks":[{"price":3799.78,"qty":1.46240000}],"checksum":1403603919,"timestamp":"2024-06-01T17:51:57.576327Z"}]}
{"channel":"book","type":"update","data":[{"symbol":"ETH/USDT","bids":[],"asks":[{"price":3800.20,"qty":0.00000000},{"price":3800.55,"qty":5.26600000}],"checksum":2344182364,"timestamp":"2024-06-01T17:51:57.800913Z"}]}
{"channel":"book","type":"update","data":[{"symbol":"ETH/USDT","bids":[],"asks":[{"price":3799.77,"qty":1.04696037}],"checksum":1411452550,"timestamp":"2024-06-01T17:51:57.805443Z"}]}
{"channel":"book","type":"update","data":[{"symbol":"ETH/USDT","bids":[],"asks":[{"price":3800.52,"qty":7.80922030}],"checksum":3667962394,"timestamp":"2024-06-01T17:51:57.805608Z"}]}
{"channel":"book","type":"update","data":[{"symbol":"ETH/USDT","bids":[],"asks":[{"price":3799.68,"qty":0.73120000}],"checksum":3256054152,"timestamp":"2024-06-01T17:51:57.809076Z"}]}
{"channel":"book","type":"update","data":[{"symbol":"ETH/USDT","bids":[{"price":3798.31,"qty":0.00000000},{"price":3798.27,"qty":0.24772343}],"asks":[],"checksum":1760773949,"timestamp":"2024-06-01T17:51:58.059773Z"}]}
{"channel":"book","type":"update","data":[{"symbol":"ETH/USDT","bids":[{"price":3798.27,"qty":0.00501163}],"asks":[],"checksum":2284089908,"timestamp":"2024-06-01T17:51:58.415315Z"}]}
{"channel":"book","type":"update","data":[{"symbol":"ETH/USDT","bids":[],"asks":[{"price":3799.68,"qty":0.00000000},{"price":3800.52,"qty":7.80922030}],"checksum":3488067762,"timestamp":"2024-06-01T17:51:58.827104Z"}]}
{"channel":"book","type":"update","data":[{"symbol":"ETH/USDT","bids":[],"asks":[{"price":3799.73,"qty":0.73120000}],"checksum":3559909772,"timestamp":"2024-06-01T17:51:58.830946Z"}]}
{"channel":"book","type":"update","data":[{"symbol":"ETH/USDT","bids":[],"asks":[{"price":3799.73,"qty":0.00000000},{"price":3800.52,"qty":7.80922030}],"checksum":3488067762,"timestamp":"2024-06-01T17:51:59.013171Z"}]}
{"channel":"book","type":"update","data":[{"symbol":"ETH/USDT","bids":[],"asks":[{"price":3799.78,"qty":0.73120000}],"checksum":2016760120,"timestamp":"2024-06-01T17:51:59.016522Z"}]}
{"channel":"book","type":"update","data":[{"symbol":"ETH/USDT","bids":[],"asks":[{"price":3799.75,"qty":0.73120000}],"checksum":63997685,"timestamp":"2024-06-01T17:51:59.019062Z"}]}
{"channel":"book","type":"update","data":[{"symbol":"ETH/USDT","bids":[],"asks":[{"price":3799.75,"qty":0.00000000},{"price":3800.52,"qty":7.80922030}],"checksum":2016760120,"timestamp":"2024-06-01T17:51:59.022533Z"}]}
{"channel":"book","type":"update","data":[{"symbol":"ETH/USDT","bids":[],"asks":[{"price":3799.73,"qty":0.73120000}],"checksum":4234034530,"timestamp":"2024-06-01T17:51:59.038519Z"}]}
{"channel":"book","type":"update","data":[{"symbol":"ETH/USDT","bids":[],"asks":[{"price":3799.73,"qty":0.00000000},{"price":3800.52,"qty":7.80922030}],"checksum":2016760120,"timestamp":"2024-06-01T17:51:59.041802Z"}]}
{"channel":"book","type":"update","data":[{"symbol":"ETH/USDT","bids":[],"asks":[{"price":3799.73,"qty":0.73120000}],"checksum":4234034530,"timestamp":"2024-06-01T17:51:59.060853Z"}]}
{"channel":"book","type":"update","data":[{"symbol":"ETH/USDT","bids":[],"asks":[{"price":3799.73,"qty":0.00000000},{"price":3800.52,"qty":7.80922030}],"checksum":2016760120,"timestamp":"2024-06-01T17:51:59.063914Z"}]}
{"channel":"book","type":"update","data":[{"symbol":"ETH/USDT","bids":[],"asks":[{"price":3799.74,"qty":0.73120000}],"checksum":1912982700,"timestamp":"2024-06-01T17:51:59.073594Z"}]}
{"channel":"book","type":"update","data":[{"symbol":"ETH/USDT","bids":[],"asks":[{"price":3799.74,"qty":0.00000000},{"price":3800.52,"qty":7.80922030}],"checksum":2016760120,"timestamp":"2024-06-01T17:51:59.077041Z"}]}
{"channel":"book","type":"update","data":[{"symbol":"ETH/USDT","bids":[],"asks":[{"price":3799.77,"qty":1.77816037}],"checksum":720494474,"timestamp":"2024-06-01T17:51:59.081967Z"}]}
{"channel":"book","type":"update","data":[{"symbol":"ETH/USDT","bids":[],"asks":[{"price":3799.75,"qty":0.73120000}],"checksum":1293564009,"timestamp":"2024-06-01T17:51:59.082332Z"}]}
{"channel":"book","type":"update","data":[{"symbol":"ETH/USDT","bids":[],"asks":[{"price":3799.75,"qty":0.00000000},{"price":3800.52,"qty":7.80922030}],"checksum":720494474,"timestamp":"2024-06-01T17:51:59.085555Z"}]}
{"channel":"book","type":"update","data":[{"symbol":"ETH/USDT","bids":[],"asks":[{"price":3799.74,"qty":0.73120000}],"checksum":1020228144,"timestamp":"2024-06-01T17:51:59.088719Z"}]}
{"channel":"book","type":"update","data":[{"symbol":"ETH/USDT","bids":[],"asks":[{"price":3799.74,"qty":0.00000000},{"price":3800.52,"qty":7.80922030}],"checksum":720494474,"timestamp":"2024-06-01T17:51:59.091999Z"}]}
{"channel":"book","type":"update","data":[{"symbol":"ETH/USDT","bids":[],"asks":[{"price":3799.74,"qty":0.73120000}],"checksum":1020228144,"timestamp":"2024-06-01T17:51:59.106201Z"}]}
{"channel":"book","type":"update","data":[{"symbol":"ETH/USDT","bids":[],"asks":[{"price":3799.74,"qty":0.00000000},{"price":3800.52,"qty":7.80922030}],"checksum":720494474,"timestamp":"2024-06-01T17:51:59.110488Z"}]}
{"channel":"book","type":"update","data":[{"symbol":"ETH/USDT","bids":[],"asks":[{"price":3799.75,"qty":0.73120000}],"checksum":1293564009,"timestamp":"2024-06-01T17:51:59.121053Z"}]}
{"channel":"book","type":"update","data":[{"symbol":"ETH/USDT","bids":[],"asks":[{"price":3799.75,"qty":0.00000000},{"price":3800.52,"qty":7.80922030}],"checksum":720494474,"timestamp":"2024-06-01T17:51:59.124409Z"}]}
{"channel":"book","type":"update","data":[{"symbol":"ETH/USDT","bids":[],"asks":[{"price":3799.76,"qty":0.73120000}],"checksum":3747997314,"timestamp":"2024-06-01T17:51:59.131684Z"}]}
{"channel":"book","type":"update","data":[{"symbol":"ETH/USDT","bids":[],"asks":[{"price":3799.76,"qty":0.00000000},{"price":3800.52,"qty":7.80922030}],"checksum":720494474,"timestamp":"2024-06-01T17:51:59.134863Z"}]}
{"channel":"book","type":"update","data":[{"symbol":"ETH/USDT","bids":[],"asks":[{"price":3799.75,"qty":0.73120000}],"checksum":1293564009,"timestamp":"2024-06-01T17:51:59.138179Z"}]}
{"channel":"book","type":"update","data":[{"symbol":"ETH/USDT","bids":[],"asks":[{"price":3799.75,"qty":0.00000000},{"price":3800.52,"qty":7.80922030}],"checksum":720494474,"timestamp":"2024-06-01T17:51:59.141422Z"}]}
{"channel":"book","type":"update","data":[{"symbol":"ETH/USDT","bids":[],"asks":[{"price":3799.73,"qty":0.73120000}],"checksum":2996077566,"timestamp":"2024-06-01T17:51:59.151194Z"}]}
{"channel":"book","type":"update","data":[{"symbol":"ETH/USDT","bids":[],"asks":[{"price":3799.73,"qty":0.00000000},{"price":3800.52,"qty":7.80922030}],"checksum":720494474,"timestamp":"2024-06-01T17:51:59.154652Z"}]}
{"channel":"book","type":"update","data":[{"symbol":"ETH/USDT","bids":[],"asks":[{"price":3799.76,"qty":0.73120000}],"checksum":3747997314,"timestamp":"2024-06-01T17:51:59.160319Z"}]}
{"channel":"book","type":"update","data":[{"symbol":"ETH/USDT","bids":[],"asks":[{"price":3799.76,"qty":0.00000000},{"price":3800.52,"qty":7.80922030}],"checksum":720494474,"timestamp":"2024-06-01T17:51:59.163709Z"}]}
{"channel":"book","type":"update","data":[{"symbol":"ETH/USDT","bids":[],"asks":[{"price":3799.74,"qty":0.73120000}],"checksum":1020228144,"timestamp":"2024-06-01T17:51:59.170085Z"}]}
{"channel":"book","type":"update","data":[{"symbol":"ETH/USDT","bids":[],"asks":[{"price":3799.74,"qty":0.00000000},{"price":3800.52,"qty":7.80922030}],"checksum":720494474,"timestamp":"2024-06-01T17:51:59.173452Z"}]}
{"channel":"book","type":"update","data":[{"symbol":"ETH/USDT","bids":[],"asks":[{"price":3799.78,"qty":0.00000000},{"price":3800.53,"qty":0.35677831}],"checksum":1289715773,"timestamp":"2024-06-01T17:51:59.176791Z"}]}
{"channel":"book","type":"update","data":[{"symbol":"ETH/USDT","bids":[],"asks":[{"price":3799.77,"qty":1.04696037}],"checksum":505089679,"timestamp":"2024-06-01T17:51:59.176976Z"}]}
{"channel":"book","type":"update","data":[{"symbol":"ETH/USDT","bids":[],"asks":[{"price":3799.77,"qty":1.77816037}],"checksum":1289715773,"timestamp":"2024-06-01T17:51:59.177529Z"}]}
{"channel":"book","type":"update","data":[{"symbol":"ETH/USDT","bids":[],"asks":[{"price":3799.76,"qty":0.73120000}],"checksum":3365786275,"timestamp":"2024-06-01T17:51:59.180248Z"}]}
{"channel":"book","type":"update","data":[{"symbol":"ETH/USDT","bids":[],"asks":[{"price":3799.77,"qty":2.50936037}],"checksum":3111929441,"timestamp":"2024-06-01T17:51:59.180471Z"}]}
{"channel":"book","type":"update","data":[{"symbol":"ETH/USDT","bids":[],"asks":[{"price":3799.77,"qty":1.77816037}],"checksum":3365786275,"timestamp":"2024-06-01T17:51:59.183714Z"}]}
{"channel":"book","type":"update","data":[{"symbol":"ETH/USDT","bids":[],"asks":[{"price":3799.76,"qty":1.46240000}],"checksum":1116183615,"timestamp":"2024-06-01T17:51:59.186767Z"}]}
{"channel":"book","type":"update","data":[{"symbol":"ETH/USDT","bids":[],"asks":[{"price":3799.76,"qty":0.73120000}],"checksum":3365786275,"timestamp":"2024-06-01T17:51:59.237265Z"}]}
{"channel":"book","type":"update","data":[{"symbol":"ETH/USDT","bids":[],"asks":[{"price":3799.77,"qty":1.04696037}],"checksum":829081458,"timestamp":"2024-06-01T17:51:59.242375Z"}]}
{"channel":"book","type":"update","data":[{"symbol":"ETH/USDT","bids":[],"asks":[{"price":3799.76,"qty":0.00000000},{"price":3800.53,"qty":0.35677831}],"checksum":505089679,"timestamp":"2024-06-01T17:51:59.282683Z"}]}
{"channel":"book","type":"update","data":[{"symbol":"ETH/USDT","bids":[],"asks":[{"price":3799.77,"qty":1.77816037}],"checksum":1289715773,"timestamp":"2024-06-01T17:51:59.291934Z"}]}
{"channel":"book","type":"update","data":[{"symbol":"ETH/USDT","bids":[],"asks":[{"price":3799.77,"qty":1.04696037}],"checksum":505089679,"timestamp":"2024-06-01T17:51:59.484021Z"}]}
{"channel":"book","type":"update","data":[{"symbol":"ETH/USDT","bids":[{"price":3799.14,"qty":1.14120000}],"asks":[],"checksum":1113799112,"timestamp":"2024-06-01T17:51:59.578840Z"}]}
{"channel":"book","type":"update","data":[{"symbol":"ETH/USDT","bids":[{"price":3799.16,"qty":0.73120000}],"asks":[],"checksum":319982036,"timestamp":"2024-06-01T17:51:59.582338Z"}]}
{"channel":"book","type":"update","data":[{"symbol":"ETH/USDT","bids":[{"price":3799.14,"qty":0.73120000}],"asks":[],"checksum":1763114597,"timestamp":"2024-06-01T17:51:59.615669Z"}]}
{"channel":"book","type":"update","data":[{"symbol":"ETH/USDT","bids":[{"price":3799.14,"qty":0.00000000},{"price":3798.27,"qty":0.00501163}],"asks":[],"checksum":2853795616,"timestamp":"2024-06-01T17:51:59.621351Z"}]}
{"channel":"book","type":"update","data":[{"symbol":"ETH/USDT","bids":[{"price":3799.16,"qty":0.00000000},{"price":3798.25,"qty":0.84627249}],"asks":[],"checksum":1444389469,"timestamp":"2024-06-01T17:51:59.693115Z"}]}
{"channel":"book","type":"update","data":[{"symbol":"ETH/USDT","bids":[{"price":3799.08,"qty":0.73120000}],"asks":[],"checksum":3990386264,"timestamp":"2024-06-01T17:51:59.697432Z"}]}
{"channel":"book","type":"update","data":[{"symbol":"ETH/USDT","bids":[{"price":3798.99,"qty":0.25000000}],"asks":[],"checksum":551581897,"timestamp":"2024-06-01T17:51:59.698272Z"}]}
{"channel":"book","type":"update","data":[{"symbol":"ETH/USDT","bids":[],"asks":[{"price":3800.53,"qty":0.00000000},{"price":3800.54,"qty":36.66615105}],"checksum":115872724,"timestamp":"2024-06-01T17:51:59.745836Z"}]}
{"channel":"book","type":"update","data":[{"symbol":"ETH/USDT","bids":[],"asks":[{"price":3800.51,"qty":0.34464071}],"checksum":1691935562,"timestamp":"2024-06-01T17:51:59.747636Z"}]}
{"channel":"book","type":"update","data":[{"symbol":"ETH/USDT","bids":[{"price":3798.99,"qty":0.00000000},{"price":3798.25,"qty":0.84627249}],"asks":[],"checksum":2293056112,"timestamp":"2024-06-01T17:52:00.086465Z"}]}
{"channel":"book","type":"update","data":[{"symbol":"ETH/USDT","bids":[{"price":3799.09,"qty":0.25000000}],"asks":[],"checksum":2773851939,"timestamp":"2024-06-01T17:52:00.086481Z"}]}
{"channel":"book","type":"update","data":[{"symbol":"ETH/USDT","bids":[{"price":3798.92,"qty":0.00000000},{"price":3798.25,"qty":0.84627249}],"asks":[],"checksum":962621120,"timestamp":"2024-06-01T17:52:00.092182Z"}]}
{"channel":"book","type":"update","data":[{"symbol":"ETH/USDT","bids":[],"asks":[{"price":3799.77,"qty":0.00000000},{"price":3800.54,"qty":36.66615105}],"checksum":355812674,"timestamp":"2024-06-01T17:52:00.212903Z"}]}
{"channel":"book","type":"update","data":[{"symbol":"ETH/USDT","bids":[],"asks":[{"price":3800.54,"qty":0.00000000},{"price":3800.55,"qty":5.26600000}],"checksum":2411689006,"timestamp":"2024-06-01T17:52:00.212947Z"}]}
{"channel":"book","type":"update","data":[{"symbol":"ETH/USDT","bids":[],"asks":[{"price":3800.52,"qty":0.00000000},{"price":3800.77,"qty":0.73120000}],"checksum":1868287766,"timestamp":"2024-06-01T17:52:00.213160Z"}]}
{"channel":"book","type":"update","data":[{"symbol":"ETH/USDT","bids":[],"asks":[{"price":3799.80,"qty":1.56714324}],"checksum":2968856398,"timestamp":"2024-06-01T17:52:00.217805Z"}]}
{"channel":"book","type":"update","data":[{"symbol":"ETH/USDT","bids":[],"asks":[{"price":3800.54,"qty":40.58018095}],"checksum":2219626343,"timestamp":"2024-06-01T17:52:00.218136Z"}]}
{"channel":"book","type":"update","data":[{"symbol":"ETH/USDT","bids":[{"price":3799.11,"qty":0.73120000}],"asks":[],"checksum":3454605980,"timestamp":"2024-06-01T17:52:00.284573Z"}]}
{"channel":"book","type":"update","data":[{"symbol":"ETH/USDT","bids":[],"asks":[{"price":3799.79,"qty":0.72912968}],"checksum":2370321300,"timestamp":"2024-06-01T17:52:00.288787Z"}]}
{"channel":"book","type":"update","data":[{"symbol":"ETH/USDT","bids":[{"price":3799.11,"qty":1.46240000}],"asks":[],"checksum":4012902124,"timestamp":"2024-06-01T17:52:00.443590Z"}]}
{"channel":"book","type":"update","data":[{"symbol":"ETH/USDT","bids":[{"price":3799.11,"qty":0.73120000}],"asks":[],"checksum":2370321300,"timestamp":"2024-06-01T17:52:00.446335Z"}]}
{"channel":"book","type":"update","data":[{"symbol":"ETH/USDT","bids":[],"asks":[{"price":3799.81,"qty":0.00000000},{"price":3800.54,"qty":40.58018095}],"checksum":157390978,"timestamp":"2024-06-01T17:52:00.447647Z"}]}
{"channel":"book","type":"update","data":[{"symbol":"ETH/USDT","bids":[],"asks":[{"price":3799.82,"qty":0.00000000},{"price":3800.55,"qty":5.26600000}],"checksum":2510498100,"timestamp":"2024-06-01T17:52:00.465670Z"}]}
{"channel":"book","type":"update","data":[{"symbol":"ETH/USDT","bids":[{"price":3799.11,"qty":1.46240000}],"asks":[],"checksum":972967446,"timestamp":"2024-06-01T17:52:01.000527Z"}]}
{"channel":"book","type":"update","data":[{"symbol":"ETH/USDT","bids":[{"price":3799.11,"qty":0.73120000}],"asks":[],"checksum":2510498100,"timestamp":"2024-06-01T17:52:01.082674Z"}]}
{"channel":"book","type":"update","data":[{"symbol":"ETH/USDT","bids":[{"price":3799.08,"qty":0.00000000},{"price":3798.25,"qty":0.84627249}],"asks":[],"checksum":310809971,"timestamp":"2024-06-01T17:52:01.171850Z"}]}
{"channel":"book","type":"update","data":[{"symbol":"ETH/USDT","bids":[{"price":3799.11,"qty":0.00000000},{"price":3798.24,"qty":0.12668855}],"asks":[],"checksum":3232639153,"timestamp":"2024-06-01T17:52:01.172099Z"}]}
{"channel":"book","type":"update","data":[{"symbol":"ETH/USDT","bids":[],"asks":[{"price":3799.79,"qty":1.46032968}],"checksum":4222950869,"timestamp":"2024-06-01T17:52:01.174254Z"}]}
{"channel":"book","type":"update","data":[{"symbol":"ETH/USDT","bids":[],"asks":[{"price":3799.79,"qty":0.72912968}],"checksum":3232639153,"timestamp":"2024-06-01T17:52:01.176670Z"}]}
{"channel":"book","type":"update","data":[{"symbol":"ETH/USDT","bids":[{"price":3799.09,"qty":0.98120000}],"asks":[],"checksum":2518505917,"timestamp":"2024-06-01T17:52:01.177189Z"}]}
{"channel":"book","type":"update","data":[{"symbol":"ETH/USDT","bids":[],"asks":[{"price":3799.78,"qty":0.73120000}],"checksum":1552775539,"timestamp":"2024-06-01T17:52:01.185213Z"}]}
{"channel":"book","type":"update","data":[{"symbol":"ETH/USDT","bids":[{"price":3799.09,"qty":0.25000000}],"asks":[],"checksum":171837567,"timestamp":"2024-06-01T17:52:01.185309Z"}]}
{"channel":"book","type":"update","data":[{"symbol":"ETH/USDT","bids":[],"asks":[{"price":3799.78,"qty":0.00000000},{"price":3800.55,"qty":5.26600000}],"checksum":3232639153,"timestamp":"2024-06-01T17:52:01.189479Z"}]}
{"channel":"book","type":"update","data":[{"symbol":"ETH/USDT","bids":[],"asks":[{"price":3799.79,"qty":1.46032968}],"checksum":4222950869,"timestamp":"2024-06-01T17:52:01.203894Z"}]}
{"channel":"book","type":"update","data":[{"symbol":"ETH/USDT","bids":[{"price":3799.09,"qty":0.00000000},{"price":3798.23,"qty":5.00000000}],"asks":[],"checksum":1789086691,"timestamp":"2024-06-01T17:52:01.209395Z"}]}
{"channel":"book","type":"update","data":[{"symbol":"ETH/USDT","bids":[{"price":3798.99,"qty":0.25000000}],"asks":[],"checksum":3314676370,"timestamp":"2024-06-01T17:52:01.209544Z"}]}
{"channel":"book","type":"update","data":[{"symbol":"ETH/USDT","bids":[{"price":3799.05,"qty":0.73120000}],"asks":[],"checksum":4286287476,"timestamp":"2024-06-01T17:52:01.212672Z"}]}
{"channel":"book","type":"update","data":[{"symbol":"ETH/USDT","bids":[],"asks":[{"price":3799.79,"qty":0.72912968}],"checksum":3294673680,"timestamp":"2024-06-01T17:52:01.212707Z"}]}
{"channel":"book","type":"update","data":[{"symbol":"ETH/USDT","bids":[],"asks":[{"price":3799.79,"qty":1.46032968}],"checksum":4286287476,"timestamp":"2024-06-01T17:52:01.220664Z"}]}
{"channel":"book","type":"update","data":[{"symbol":"ETH/USDT","bids":[],"asks":[{"price":3800.55,"qty":0.00000000},{"price":3800.77,"qty":0.73120000}],"checksum":3747907545,"timestamp":"2024-06-01T17:52:01.447547Z"}]}
{"channel":"book","type":"update","data":[{"symbol":"ETH/USDT","bids":[],"asks":[{"price":3799.79,"qty":0.72912968}],"checksum":2859543545,"timestamp":"2024-06-01T17:52:01.455869Z"}]}
{"channel":"book","type":"update","data":[{"symbol":"ETH/USDT","bids":[{"price":3799.06,"qty":0.25000000}],"asks":[],"checksum":1654711897,"timestamp":"2024-06-01T17:52:01.461317Z"}]}
{"channel":"book","type":"update","data":[{"symbol":"ETH/USDT","bids":[{"price":3799.06,"qty":0.98120000}],"asks":[],"checksum":873699157,"timestamp":"2024-06-01T17:52:01.465019Z"}]}
{"channel":"book","type":"update","data":[{"symbol":"ETH/USDT","bids":[{"price":3799.05,"qty":0.00000000},{"price":3798.25,"qty":0.84627249}],"asks":[],"checksum":3127523440,"timestamp":"2024-06-01T17:52:01.465264Z"}]}
{"channel":"book","type":"update","data":[{"symbol":"ETH/USDT","bids":[{"price":3799.07,"qty":0.73120000}],"asks":[],"checksum":3953934140,"timestamp":"2024-06-01T17:52:01.468564Z"}]}
{"channel":"book","type":"update","data":[{"symbol":"ETH/USDT","bids":[{"price":3799.08,"qty":0.25000000}],"asks":[],"checksum":2173629253,"timestamp":"2024-06-01T17:52:01.586180Z"}]}
{"channel":"book","type":"update","data":[{"symbol":"ETH/USDT","bids":[{"price":3799.06,"qty":0.73120000}],"asks":[],"checksum":910765722,"timestamp":"2024-06-01T17:52:01.586261Z"}]}
{"channel":"book","type":"update","data":[{"symbol":"ETH/USDT","bids":[{"price":3799.06,"qty":0.00000000},{"price":3798.30,"qty":2.79800000}],"asks":[],"checksum":2946495026,"timestamp":"2024-06-01T17:52:01.589490Z"}]}
{"channel":"book","type":"update","data":[{"symbol":"ETH/USDT","bids":[{"price":3799.11,"qty":0.73120000}],"asks":[],"checksum":699578748,"timestamp":"2024-06-01T17:52:01.589509Z"}]}
{"channel":"book","type":"update","data":[{"symbol":"ETH/USDT","bids":[{"price":3798.99,"qty":0.00000000},{"price":3798.30,"qty":2.79800000}],"asks":[],"checksum":1807007618,"timestamp":"2024-06-01T17:52:01.591944Z"}]}
{"channel":"book","type":"update","data":[{"symbol":"ETH/USDT","bids":[{"price":3799.11,"qty":0.00000000},{"price":3798.25,"qty":0.84627249}],"asks":[],"checksum":1430755364,"timestamp":"2024-06-01T17:52:01.750479Z"}]}
{"channel":"book","type":"update","data":[{"symbol":"ETH/USDT","bids":[],"asks":[{"price":3799.78,"qty":0.73120000}],"checksum":4056295427,"timestamp":"2024-06-01T17:52:01.814951Z"}]}
{"channel":"book","type":"update","data":[{"symbol":"ETH/USDT","bids":[],"asks":[{"price":3799.78,"qty":0.00000000},{"price":3800.77,"qty":0.73120000}],"checksum":1430755364,"timestamp":"2024-06-01T17:52:01.818148Z"}]}
{"channel":"book","type":"update","data":[{"symbol":"ETH/USDT","bids":[],"asks":[{"price":3799.79,"qty":1.46032968}],"checksum":542258180,"timestamp":"2024-06-01T17:52:01.826697Z"}]}
{"channel":"book","type":"update","data":[{"symbol":"ETH/USDT","bids":[{"price":3799.07,"qty":0.00000000},{"price":3798.24,"qty":0.12668855}],"asks":[],"checksum":3060928673,"timestamp":"2024-06-01T17:52:01.879102Z"}]}
{"channel":"book","type":"update","data":[{"symbol":"ETH/USDT","bids":[],"asks":[{"price":3800.51,"qty":0.00000000},{"price":3800.83,"qty":1.99847015}],"checksum":2275787420,"timestamp":"2024-06-01T17:52:02.033524Z"}]}
{"channel":"book","type":"update","data":[{"symbol":"ETH/USDT","bids":[],"asks":[{"price":3800.53,"qty":0.42455135}],"checksum":2777066113,"timestamp":"2024-06-01T17:52:02.035064Z"}]}
{"channel":"book","type":"update","data":[{"symbol":"ETH/USDT","bids":[],"asks":[{"price":3799.78,"qty":0.73120000}],"checksum":477767637,"timestamp":"2024-06-01T17:52:02.123562Z"}]}
{"channel":"book","type":"update","data":[{"symbol":"ETH/USDT","bids":[{"price":3799.08,"qty":0.00000000},{"price":3798.23,"qty":5.00000000}],"asks":[],"checksum":2502309549,"timestamp":"2024-06-01T17:52:02.128859Z"}]}
{"channel":"book","type":"update","data":[{"symbol":"ETH/USDT","bids":[{"price":3798.99,"qty":0.25000000}],"asks":[],"checksum":1334234187,"timestamp":"2024-06-01T17:52:02.128990Z"}]}
{"channel":"book","type":"update","data":[{"symbol":"ETH/USDT","bids":[{"price":3799.02,"qty":0.73120000}],"asks":[],"checksum":2937432291,"timestamp":"2024-06-01T17:52:02.133752Z"}]}
{"channel":"book","type":"update","data":[{"symbol":"ETH/USDT","bids":[],"asks":[{"price":3799.78,"qty":0.00000000},{"price":3800.77,"qty":0.73120000}],"checksum":384378295,"timestamp":"2024-06-01T17:52:02.136143Z"}]}
{"channel":"book","type":"update","data":[{"symbol":"ETH/USDT","bids":[],"asks":[{"price":3799.79,"qty":0.72912968}],"checksum":1677494679,"timestamp":"2024-06-01T17:52:02.137167Z"}]}
{"channel":"book","type":"update","data":[{"symbol":"ETH/USDT","bids":[{"price":3799.02,"qty":0.00000000},{"price":3798.24,"qty":0.12668855}],"asks":[],"checksum":2205150527,"timestamp":"2024-06-01T17:52:02.137540Z"}]}
{"channel":"book","type":"update","data":[{"symbol":"ETH/USDT","bids":[],"asks":[{"price":3799.78,"qty":0.73120000}],"checksum":2725185319,"timestamp":"2024-06-01T17:52:02.139450Z"}]}
{"channel":"book","type":"update","data":[{"symbol":"ETH/USDT","bids":[],"asks":[{"price":3799.78,"qty":1.46240000}],"checksum":3642210016,"timestamp":"2024-06-01T17:52:02.140264Z"}]}
{"channel":"book","type":"update","data":[{"symbol":"ETH/USDT","bids":[],"asks":[{"price":3799.78,"qty":0.73120000}],"checksum":2725185319,"timestamp":"2024-06-01T17:52:02.142835Z"}]}
{"channel":"book","type":"update","data":[{"symbol":"ETH/USDT","bids":[],"asks":[{"price":3799.76,"qty":0.73120000}],"checksum":124046174,"timestamp":"2024-06-01T17:52:02.145398Z"}]}
{"channel":"book","type":"update","data":[{"symbol":"ETH/USDT","bids":[],"asks":[{"price":3799.76,"qty":0.00000000},{"price":3800.54,"qty":40.58018095}],"checksum":2725185319,"timestamp":"2024-06-01T17:52:02.149206Z"}]}
{"channel":"book","type":"update","data":[{"symbol":"ETH/USDT","bids":[],"asks":[{"price":3799.73,"qty":0.73120000}],"checksum":1589249836,"timestamp":"2024-06-01T17:52:02.151640Z"}]}
{"channel":"book","type":"update","data":[{"symbol":"ETH/USDT","bids":[],"asks":[{"price":3799.73,"qty":0.00000000},{"price":3800.54,"qty":40.58018095}],"checksum":2725185319,"timestamp":"2024-06-01T17:52:02.155374Z"}]}
{"channel":"book","type":"update","data":[{"symbol":"ETH/USDT","bids":[{"price":3798.99,"qty":0.98120000}],"asks":[],"checksum":4108088875,"timestamp":"2024-06-01T17:52:02.157080Z"}]}
{"channel":"book","type":"update","data":[{"symbol":"ETH/USDT","bids":[],"asks":[{"price":3799.78,"qty":1.46240000}],"checksum":2409940972,"timestamp":"2024-06-01T17:52:02.160268Z"}]}
{"channel":"book","type":"update","data":[{"symbol":"ETH/USDT","bids":[{"price":3799.03,"qty":0.73120000}],"asks":[],"checksum":4227127321,"timestamp":"2024-06-01T17:52:02.161887Z"}]}
{"channel":"book","type":"update","data":[{"symbol":"ETH/USDT","bids":[],"asks":[{"price":3799.78,"qty":0.73120000}],"checksum":2156685790,"timestamp":"2024-06-01T17:52:02.162398Z"}]}
{"channel":"book","type":"update","data":[{"symbol":"ETH/USDT","bids":[],"asks":[{"price":3799.78,"qty":0.00000000},{"price":3800.77,"qty":0.73120000}],"checksum":2710340550,"timestamp":"2024-06-01T17:52:02.165099Z"}]}
{"channel":"book","type":"update","data":[{"symbol":"ETH/USDT","bids":[],"asks":[{"price":3799.76,"qty":0.73120000}],"checksum":1423159126,"timestamp":"2024-06-01T17:52:02.172589Z"}]}
{"channel":"book","type":"update","data":[{"symbol":"ETH/USDT","bids":[],"asks":[{"price":3799.76,"qty":0.00000000},{"price":3800.77,"qty":0.73120000}],"checksum":2710340550,"timestamp":"2024-06-01T17:52:02.176025Z"}]}
{"channel":"book","type":"update","data":[{"symbol":"ETH/USDT","bids":[],"asks":[{"price":3799.76,"qty":0.73120000}],"checksum":1423159126,"timestamp":"2024-06-01T17:52:02.178666Z"}]}
{"channel":"book","type":"update","data":[{"symbol":"ETH/USDT","bids":[],"asks":[{"price":3799.79,"qty":1.46032968}],"checksum":2396190310,"timestamp":"2024-06-01T17:52:02.180109Z"}]}
{"channel":"book","type":"update","data":[{"symbol":"ETH/USDT","bids":[],"asks":[{"price":3799.76,"qty":0.00000000},{"price":3800.77,"qty":0.73120000}],"checksum":3566809062,"timestamp":"2024-06-01T17:52:02.181871Z"}]}
{"channel":"book","type":"update","data":[{"symbol":"ETH/USDT","bids":[],"asks":[{"price":3799.76,"qty":0.73120000}],"checksum":2396190310,"timestamp":"2024-06-01T17:52:02.183003Z"}]}
{"channel":"book","type":"update","data":[{"symbol":"ETH/USDT","bids":[],"asks":[{"price":3799.79,"qty":0.72912968}],"checksum":1423159126,"timestamp":"2024-06-01T17:52:02.183355Z"}]}
{"channel":"book","type":"update","data":[{"symbol":"ETH/USDT","bids":[{"price":3799.03,"qty":0.00000000},{"price":3798.24,"qty":0.12668855}],"asks":[],"checksum":545501347,"timestamp":"2024-06-01T17:52:02.183662Z"}]}
{"channel":"book","type":"update","data":[{"symbol":"ETH/USDT","bids":[],"asks":[{"price":3799.76,"qty":1.46240000}],"checksum":1813222200,"timestamp":"2024-06-01T17:52:02.185326Z"}]}
{"channel":"book","type":"update","data":[{"symbol":"ETH/USDT","bids":[{"price":3799.00,"qty":0.73120000}],"asks":[],"checksum":2922086822,"timestamp":"2024-06-01T17:52:02.187484Z"}]}
{"channel":"book","type":"update","data":[{"symbol":"ETH/USDT","bids":[],"asks":[{"price":3799.76,"qty":0.73120000}],"checksum":3803947581,"timestamp":"2024-06-01T17:52:02.187797Z"}]}
{"channel":"book","type":"update","data":[{"symbol":"ETH/USDT","bids":[],"asks":[{"price":3799.76,"qty":0.00000000},{"price":3800.77,"qty":0.73120000}],"checksum":400854701,"timestamp":"2024-06-01T17:52:02.188629Z"}]}
{"channel":"book","type":"update","data":[{"symbol":"ETH/USDT","bids":[],"asks":[{"price":3799.76,"qty":0.73120000}],"checksum":3803947581,"timestamp":"2024-06-01T17:52:02.190642Z"}]}
{"channel":"book","type":"update","data":[{"symbol":"ETH/USDT","bids":[{"price":3799.01,"qty":0.25000000}],"asks":[],"checksum":2973929965,"timestamp":"2024-06-01T17:52:02.192340Z"}]}
{"channel":"book","type":"update","data":[{"symbol":"ETH/USDT","bids":[],"asks":[{"price":3799.78,"qty":0.73120000}],"checksum":3222706972,"timestamp":"2024-06-01T17:52:02.192531Z"}]}
{"channel":"book","type":"update","data":[{"symbol":"ETH/USDT","bids":[],"asks":[{"price":3799.76,"qty":0.00000000},{"price":3800.54,"qty":40.58018095}],"checksum":1696421733,"timestamp":"2024-06-01T17:52:02.193167Z"}]}
{"channel":"book","type":"update","data":[{"symbol":"ETH/USDT","bids":[],"asks":[{"price":3799.78,"qty":1.46240000}],"checksum":509994658,"timestamp":"2024-06-01T17:52:02.199552Z"}]}
{"channel":"book","type":"update","data":[{"symbol":"ETH/USDT","bids":[{"price":3798.99,"qty":0.25000000}],"asks":[],"checksum":1040338334,"timestamp":"2024-06-01T17:52:02.219920Z"}]}
{"channel":"book","type":"update","data":[{"symbol":"ETH/USDT","bids":[{"price":3799.02,"qty":0.73120000}],"asks":[],"checksum":2743737227,"timestamp":"2024-06-01T17:52:02.220363Z"}]}
{"channel":"book","type":"update","data":[{"symbol":"ETH/USDT","bids":[],"asks":[{"price":3799.78,"qty":0.73120000}],"checksum":1779462721,"timestamp":"2024-06-01T17:52:02.222119Z"}]}
{"channel":"book","type":"update","data":[{"symbol":"ETH/USDT","bids":[],"asks":[{"price":3799.78,"qty":0.00000000},{"price":3800.77,"qty":0.73120000}],"checksum":3725516661,"timestamp":"2024-06-01T17:52:02.223609Z"}]}
{"channel":"book","type":"update","data":[{"symbol":"ETH/USDT","bids":[{"price":3798.99,"qty":0.00000000},{"price":3798.30,"qty":2.79800000}],"asks":[],"checksum":312458048,"timestamp":"2024-06-01T17:52:02.224490Z"}]}
{"channel":"book","type":"update","data":[{"symbol":"ETH/USDT","bids":[],"asks":[{"price":3799.78,"qty":0.73120000}],"checksum":866079064,"timestamp":"2024-06-01T17:52:02.230678Z"}]}
{"channel":"book","type":"update","data":[{"symbol":"ETH/USDT","bids":[],"asks":[{"price":3799.78,"qty":0.00000000},{"price":3800.77,"qty":0.73120000}],"checksum":312458048,"timestamp":"2024-06-01T17:52:02.233975Z"}]}
{"channel":"book","type":"update","data":[{"symbol":"ETH/USDT","bids":[],"asks":[{"price":3799.78,"qty":0.73120000}],"checksum":866079064,"timestamp":"2024-06-01T17:52:02.237149Z"}]}
{"channel":"book","type":"update","data":[{"symbol":"ETH/USDT","bids":[],"asks":[{"price":3799.78,"qty":0.00000000},{"price":3800.77,"qty":0.73120000}],"checksum":312458048,"timestamp":"2024-06-01T17:52:02.240133Z"}]}
{"channel":"book","type":"update","data":[{"symbol":"ETH/USDT","bids":[],"asks":[{"price":3799.79,"qty":1.46032968}],"checksum":1737103200,"timestamp":"2024-06-01T17:52:02.258598Z"}]}
{"channel":"book","type":"update","data":[{"symbol":"ETH/USDT","bids":[{"price":3799.03,"qty":0.25000000}],"asks":[],"checksum":3091264574,"timestamp":"2024-06-01T17:52:02.263382Z"}]}
{"channel":"book","type":"update","data":[{"symbol":"ETH/USDT","bids":[],"asks":[{"price":3799.79,"qty":0.72912968}],"checksum":3343862012,"timestamp":"2024-06-01T17:52:02.266689Z"}]}
{"channel":"book","type":"update","data":[{"symbol":"ETH/USDT","bids":[{"price":3799.00,"qty":0.00000000},{"price":3798.30,"qty":2.79800000}],"asks":[],"checksum":864026422,"timestamp":"2024-06-01T17:52:02.266837Z"}]}
{"channel":"book","type":"update","data":[{"symbol":"ETH/USDT","bids":[{"price":3799.04,"qty":0.73120000}],"asks":[],"checksum":2335180432,"timestamp":"2024-06-01T17:52:02.266851Z"}]}
{"channel":"book","type":"update","data":[{"symbol":"ETH/USDT","bids":[],"asks":[{"price":3799.79,"qty":1.46032968}],"checksum":4097817170,"timestamp":"2024-06-01T17:52:02.270011Z"}]}
{"channel":"book","type":"update","data":[{"symbol":"ETH/USDT","bids":[],"asks":[{"price":3799.79,"qty":0.72912968}],"checksum":2335180432,"timestamp":"2024-06-01T17:52:02.287929Z"}]}
{"channel":"book","type":"update","data":[{"symbol":"ETH/USDT","bids":[{"price":3799.04,"qty":1.46240000}],"asks":[],"checksum":1961651181,"timestamp":"2024-06-01T17:52:02.289320Z"}]}
{"channel":"book","type":"update","data":[{"symbol":"ETH/USDT","bids":[],"asks":[{"price":3799.79,"qty":1.46032968}],"checksum":33146829,"timestamp":"2024-06-01T17:52:02.293333Z"}]}
{"channel":"book","type":"update","data":[{"symbol":"ETH/USDT","bids":[{"price":3799.04,"qty":0.73120000}],"asks":[],"checksum":4097817170,"timestamp":"2024-06-01T17:52:02.293409Z"}]}
{"channel":"book","type":"update","data":[{"symbol":"ETH/USDT","bids":[{"price":3799.03,"qty":0.00000000},{"price":3798.30,"qty":2.79800000}],"asks":[],"checksum":1825776822,"timestamp":"2024-06-01T17:52:02.294375Z"}]}
{"channel":"book","type":"update","data":[{"symbol":"ETH/USDT","bids":[{"price":3799.05,"qty":0.25000000}],"asks":[],"checksum":3826152805,"timestamp":"2024-06-01T17:52:02.294517Z"}]}
{"channel":"book","type":"update","data":[{"symbol":"ETH/USDT","bids":[],"asks":[{"price":3799.79,"qty":0.72912968}],"checksum":2600585639,"timestamp":"2024-06-01T17:52:02.295884Z"}]}
{"channel":"book","type":"update","data":[{"symbol":"ETH/USDT","bids":[{"price":3799.09,"qty":0.73120000}],"asks":[],"checksum":459660999,"timestamp":"2024-06-01T17:52:02.296038Z"}]}
{"channel":"book","type":"update","data":[{"symbol":"ETH/USDT","bids":[{"price":3799.19,"qty":0.73120000}],"asks":[],"checksum":4039936188,"timestamp":"2024-06-01T17:52:02.297668Z"}]}
{"channel":"book","type":"update","data":[{"symbol":"ETH/USDT","bids":[{"price":3799.02,"qty":0.00000000},{"price":3798.51,"qty":0.73120000}],"asks":[],"checksum":4168868634,"timestamp":"2024-06-01T17:52:02.298233Z"}]}
{"channel":"book","type":"update","data":[{"symbol":"ETH/USDT","bids":[{"price":3799.09,"qty":0.00000000},{"price":3798.42,"qty":2.15500000}],"asks":[],"checksum":2892549602,"timestamp":"2024-06-01T17:52:02.299069Z"}]}
{"channel":"book","type":"update","data":[{"symbol":"ETH/USDT","bids":[{"price":3799.19,"qty":0.00000000},{"price":3798.30,"qty":2.79800000}],"asks":[],"checksum":3094053434,"timestamp":"2024-06-01T17:52:02.304371Z"}]}
{"channel":"book","type":"update","data":[{"symbol":"ETH/USDT","bids":[{"price":3799.15,"qty":0.73120000}],"asks":[],"checksum":2498336030,"timestamp":"2024-06-01T17:52:02.308093Z"}]}
{"channel":"book","type":"update","data":[{"symbol":"ETH/USDT","bids":[{"price":3799.06,"qty":0.73120000}],"asks":[],"checksum":542498872,"timestamp":"2024-06-01T17:52:02.311369Z"}]}
{"channel":"book","type":"update","data":[{"symbol":"ETH/USDT","bids":[{"price":3799.15,"qty":0.00000000},{"price":3798.42,"qty":2.15500000}],"asks":[],"checksum":4145137656,"timestamp":"2024-06-01T17:52:02.312525Z"}]}
{"channel":"book","type":"update","data":[{"symbol":"ETH/USDT","bids":[{"price":3799.06,"qty":0.00000000},{"price":3798.30,"qty":2.79800000}],"asks":[],"checksum":3094053434,"timestamp":"2024-06-01T17:52:02.314312Z"}]}
{"channel":"book","type":"update","data":[{"symbol":"ETH/USDT","bids":[],"asks":[{"price":3799.79,"qty":1.46032968}],"checksum":3447598618,"timestamp":"2024-06-01T17:52:02.314902Z"}]}
{"channel":"book","type":"update","data":[{"symbol":"ETH/USDT","bids":[],"asks":[{"price":3799.79,"qty":0.72912968}],"checksum":3094053434,"timestamp":"2024-06-01T17:52:02.319025Z"}]}
{"channel":"book","type":"update","data":[{"symbol":"ETH/USDT","bids":[{"price":3799.06,"qty":0.73120000}],"asks":[],"checksum":4145137656,"timestamp":"2024-06-01T17:52:02.319549Z"}]}
{"channel":"book","type":"update","data":[{"symbol":"ETH/USDT","bids":[],"asks":[{"price":3799.78,"qty":0.73120000}],"checksum":1125083852,"timestamp":"2024-06-01T17:52:02.367884Z"}]}
{"channel":"book","type":"update","data":[{"symbol":"ETH/USDT","bids":[],"asks":[{"price":3799.78,"qty":0.00000000},{"price":3800.77,"qty":0.73120000}],"checksum":4145137656,"timestamp":"2024-06-01T17:52:02.371965Z"}]}
{"channel":"book","type":"update","data":[{"symbol":"ETH/USDT","bids":[{"price":3799.05,"qty":0.00000000},{"price":3798.30,"qty":2.79800000}],"asks":[],"checksum":4274249919,"timestamp":"2024-06-01T17:52:02.372606Z"}]}
{"channel":"book","type":"update","data":[{"symbol":"ETH/USDT","bids":[{"price":3799.07,"qty":0.25000000}],"asks":[],"checksum":2331412168,"timestamp":"2024-06-01T17:52:02.372742Z"}]}
{"channel":"book","type":"update","data":[{"symbol":"ETH/USDT","bids":[{"price":3799.07,"qty":0.98120000}],"asks":[],"checksum":2319690237,"timestamp":"2024-06-01T17:52:02.375896Z"}]}
{"channel":"book","type":"update","data":[{"symbol":"ETH/USDT","bids":[{"price":3799.04,"qty":0.00000000},{"price":3798.30,"qty":2.79800000}],"asks":[],"checksum":2547308594,"timestamp":"2024-06-01T17:52:02.376443Z"}]}
{"channel":"book","type":"update","data":[{"symbol":"ETH/USDT","bids":[{"price":3799.06,"qty":0.00000000},{"price":3798.25,"qty":0.84627249}],"asks":[],"checksum":1722847136,"timestamp":"2024-06-01T17:52:02.376455Z"}]}
{"channel":"book","type":"update","data":[{"symbol":"ETH/USDT","bids":[{"price":3799.11,"qty":0.73120000}],"asks":[],"checksum":3486316759,"timestamp":"2024-06-01T17:52:02.382381Z"}]}
{"channel":"book","type":"update","data":[{"symbol":"ETH/USDT","bids":[{"price":3799.11,"qty":0.00000000},{"price":3798.25,"qty":0.84627249}],"asks":[],"checksum":1722847136,"timestamp":"2024-06-01T17:52:02.441530Z"}]}
{"channel":"book","type":"update","data":[{"symbol":"ETH/USDT","bids":[{"price":3799.07,"qty":0.73120000}],"asks":[],"checksum":3234042178,"timestamp":"2024-06-01T17:52:02.446228Z"}]}
{"channel":"book","type":"update","data":[{"symbol":"ETH/USDT","bids":[{"price":3799.08,"qty":0.25000000}],"asks":[],"checksum":2455931489,"timestamp":"2024-06-01T17:52:02.586118Z"}]}
{"channel":"book","type":"update","data":[{"symbol":"ETH/USDT","bids":[{"price":3799.08,"qty":0.98120000}],"asks":[],"checksum":3302095725,"timestamp":"2024-06-01T17:52:02.589685Z"}]}
{"channel":"book","type":"update","data":[{"symbol":"ETH/USDT","bids":[{"price":3799.07,"qty":0.00000000},{"price":3798.25,"qty":0.84627249}],"asks":[],"checksum":1693171108,"timestamp":"2024-06-01T17:52:02.589983Z"}]}
{"channel":"book","type":"update","data":[{"symbol":"ETH/USDT","bids":[{"price":3799.01,"qty":0.00000000},{"price":3798.24,"qty":0.12668855}],"asks":[],"checksum":2250274733,"timestamp":"2024-06-01T17:52:02.590849Z"}]}
{"channel":"book","type":"update","data":[{"symbol":"ETH/USDT","bids":[{"price":3799.09,"qty":0.73120000}],"asks":[],"checksum":3067426903,"timestamp":"2024-06-01T17:52:02.593062Z"}]}
{"channel":"book","type":"update","data":[{"symbol":"ETH/USDT","bids":[],"asks":[{"price":3799.80,"qty":0.00000000},{"price":3800.83,"qty":1.99847015}],"checksum":3656750218,"timestamp":"2024-06-01T17:52:02.614731Z"}]}
{"channel":"book","type":"update","data":[{"symbol":"ETH/USDT","bids":[],"asks":[{"price":3800.54,"qty":0.00000000},{"price":3800.96,"qty":2.63306005}],"checksum":1481293409,"timestamp":"2024-06-01T17:52:02.614877Z"}]}
{"channel":"book","type":"update","data":[{"symbol":"ETH/USDT","bids":[],"asks":[{"price":3799.78,"qty":1.04697079}],"checksum":3676283587,"timestamp":"2024-06-01T17:52:02.616932Z"}]}
{"channel":"book","type":"update","data":[{"symbol":"ETH/USDT","bids":[],"asks":[{"price":3800.76,"qty":10.41009983}],"checksum":1907228950,"timestamp":"2024-06-01T17:52:02.617050Z"}]}
{"channel":"book","type":"update","data":[{"symbol":"ETH/USDT","bids":[{"price":3799.10,"qty":0.25000000}],"asks":[],"checksum":3969963556,"timestamp":"2024-06-01T17:52:02.621920Z"}]}
{"channel":"book","type":"update","data":[{"symbol":"ETH/USDT","bids":[{"price":3799.10,"qty":0.98120000}],"asks":[],"checksum":3121850152,"timestamp":"2024-06-01T17:52:02.785217Z"}]}
{"channel":"book","type":"update","data":[{"symbol":"ETH/USDT","bids":[{"price":3799.08,"qty":0.25000000}],"asks":[],"checksum":2591296532,"timestamp":"2024-06-01T17:52:02.786863Z"}]}
{"channel":"book","type":"update","data":[{"symbol":"ETH/USDT","bids":[{"price":3799.09,"qty":0.00000000},{"price":3798.25,"qty":0.84627249}],"asks":[],"checksum":854429083,"timestamp":"2024-06-01T17:52:02.787400Z"}]}
{"channel":"book","type":"update","data":[{"symbol":"ETH/USDT","bids":[{"price":3799.08,"qty":0.00000000},{"price":3798.24,"qty":0.12668855}],"asks":[],"checksum":1713100498,"timestamp":"2024-06-01T17:52:02.790642Z"}]}
{"channel":"book","type":"update","data":[{"symbol":"ETH/USDT","bids":[{"price":3799.11,"qty":0.73120000}],"asks":[],"checksum":1298517854,"timestamp":"2024-06-01T17:52:02.808269Z"}]}
{"channel":"book","type":"update","data":[{"symbol":"ETH/USDT","bids":[{"price":3799.11,"qty":1.46240000}],"asks":[],"checksum":3095342837,"timestamp":"2024-06-01T17:52:03.005212Z"}]}
{"channel":"book","type":"update","data":[{"symbol":"ETH/USDT","bids":[],"asks":[{"price":3800.53,"qty":0.00000000},{"price":3800.82,"qty":48.42643758}],"checksum":2824867656,"timestamp":"2024-06-01T17:52:04.301502Z"}]}
{"channel":"book","type":"update","data":[{"symbol":"ETH/USDT","bids":[],"asks":[{"price":3800.75,"qty":0.48652211}],"checksum":120828151,"timestamp":"2024-06-01T17:52:04.303132Z"}]}
{"channel":"book","type":"update","data":[{"symbol":"ETH/USDT","bids":[{"price":3799.11,"qty":0.73120000}],"asks":[],"checksum":3516586861,"timestamp":"2024-06-01T17:52:04.858505Z"}]}
{"channel":"book","type":"update","data":[{"symbol":"ETH/USDT","bids":[{"price":3799.11,"qty":1.46240000}],"asks":[],"checksum":120828151,"timestamp":"2024-06-01T17:52:04.864429Z"}]}
{"channel":"book","type":"update","data":[{"symbol":"ETH/USDT","bids":[],"asks":[{"price":3800.76,"qty":0.00000000},{"price":3800.82,"qty":48.42643758}],"checksum":2315437478,"timestamp":"2024-06-01T17:52:04.985441Z"}]}
{"channel":"book","type":"update","data":[{"symbol":"ETH/USDT","bids":[],"asks":[{"price":3800.82,"qty":0.00000000},{"price":3800.83,"qty":1.99847015}],"checksum":3532893502,"timestamp":"2024-06-01T17:52:04.985577Z"}]}
{"channel":"book","type":"update","data":[{"symbol":"ETH/USDT","bids":[],"asks":[{"price":3799.78,"qty":0.00000000},{"price":3800.96,"qty":2.63306005}],"checksum":2160596273,"timestamp":"2024-06-01T17:52:04.985623Z"}]}
{"channel":"book","type":"update","data":[{"symbol":"ETH/USDT","bids":[{"price":3799.11,"qty":0.73120000}],"asks":[],"checksum":580702204,"timestamp":"2024-06-01T17:52:04.989866Z"}]}
{"channel":"book","type":"update","data":[{"symbol":"ETH/USDT","bids":[],"asks":[{"price":3799.85,"qty":0.72912968}],"checksum":1825193332,"timestamp":"2024-06-01T17:52:04.990262Z"}]}
{"channel":"book","type":"update","data":[{"symbol":"ETH/USDT","bids":[],"asks":[{"price":3799.79,"qty":0.00000000},{"price":3800.96,"qty":2.63306005}],"checksum":2900791104,"timestamp":"2024-06-01T17:52:04.990340Z"}]}
{"channel":"book","type":"update","data":[{"symbol":"ETH/USDT","bids":[],"asks":[{"price":3800.83,"qty":0.00000000},{"price":3801.01,"qty":5.00000000}],"checksum":764074709,"timestamp":"2024-06-01T17:52:04.990772Z"}]}
{"channel":"book","type":"update","data":[{"symbol":"ETH/USDT","bids":[],"asks":[{"price":3800.74,"qty":1.56710306}],"checksum":1376686814,"timestamp":"2024-06-01T17:52:04.990932Z"}]}
{"channel":"book","type":"update","data":[{"symbol":"ETH/USDT","bids":[],"asks":[{"price":3800.82,"qty":10.41005860}],"checksum":1861120006,"timestamp":"2024-06-01T17:52:04.991039Z"}]}
{"channel":"book","type":"update","data":[{"symbol":"ETH/USDT","bids":[{"price":3799.11,"qty":1.46240000}],"asks":[],"checksum":3723263116,"timestamp":"2024-06-01T17:52:04.993115Z"}]}
{"channel":"book","type":"update","data":[{"symbol":"ETH/USDT","bids":[{"price":3798.42,"qty":0.00000000},{"price":3798.24,"qty":0.12668855}],"asks":[],"checksum":2145767893,"timestamp":"2024-06-01T17:52:05.402720Z"}]}
{"channel":"book","type":"update","data":[{"symbol":"ETH/USDT","bids":[{"price":3799.11,"qty":0.73120000}],"asks":[],"checksum":462648621,"timestamp":"2024-06-01T17:52:05.403008Z"}]}
{"channel":"book","type":"update","data":[{"symbol":"ETH/USDT","bids":[],"asks":[{"price":3799.85,"qty":1.46032968}],"checksum":683609268,"timestamp":"2024-06-01T17:52:05.404107Z"}]}
{"channel":"book","type":"update","data":[{"symbol":"ETH/USDT","bids":[{"price":3799.11,"qty":0.00000000},{"price":3798.23,"qty":5.19713103}],"asks":[],"checksum":1839131814,"timestamp":"2024-06-01T17:52:05.404293Z"}]}
{"channel":"book","type":"update","data":[{"symbol":"ETH/USDT","bids":[],"asks":[{"price":3799.85,"qty":2.19152968}],"checksum":3005046915,"timestamp":"2024-06-01T17:52:05.404331Z"}]}
{"channel":"book","type":"update","data":[{"symbol":"ETH/USDT","bids":[{"price":3798.30,"qty":0.00000000},{"price":3798.22,"qty":0.06693358}],"asks":[],"checksum":1495831233,"timestamp":"2024-06-01T17:52:05.404633Z"}]}
{"channel":"book","type":"update","data":[{"symbol":"ETH/USDT","bids":[{"price":3799.10,"qty":0.25000000}],"asks":[],"checksum":3959924673,"timestamp":"2024-06-01T17:52:05.405065Z"}]}
{"channel":"book","type":"update","data":[{"symbol":"ETH/USDT","bids":[{"price":3798.93,"qty":1.65714475}],"asks":[],"checksum":1183926194,"timestamp":"2024-06-01T17:52:05.408245Z"}]}
{"channel":"book","type":"update","data":[{"symbol":"ETH/USDT","bids":[],"asks":[{"price":3799.67,"qty":0.73120000}],"checksum":809010369,"timestamp":"2024-06-01T17:52:05.408483Z"}]}
{"channel":"book","type":"update","data":[{"symbol":"ETH/USDT","bids":[{"price":3798.93,"qty":0.34000000}],"asks":[],"checksum":194006519,"timestamp":"2024-06-01T17:52:05.410063Z"}]}
{"channel":"book","type":"update","data":[{"symbol":"ETH/USDT","bids":[],"asks":[{"price":3799.67,"qty":0.00000000},{"price":3800.82,"qty":10.41005860}],"checksum":2115153591,"timestamp":"2024-06-01T17:52:05.412961Z"}]}
{"channel":"book","type":"update","data":[{"symbol":"ETH/USDT","bids":[],"asks":[{"price":3799.86,"qty":0.00000000},{"price":3800.83,"qty":6.85624276}],"checksum":723981369,"timestamp":"2024-06-01T17:52:05.416642Z"}]}
{"channel":"book","type":"update","data":[{"symbol":"ETH/USDT","bids":[{"price":3798.57,"qty":0.00000000},{"price":3798.17,"qty":15.47149119}],"asks":[],"checksum":3154589596,"timestamp":"2024-06-01T17:52:05.416968Z"}]}
{"channel":"book","type":"update","data":[{"symbol":"ETH/USDT","bids":[],"asks":[{"price":3799.85,"qty":1.46032968}],"checksum":1982144062,"timestamp":"2024-06-01T17:52:05.417698Z"}]}
{"channel":"book","type":"update","data":[{"symbol":"ETH/USDT","bids":[],"asks":[{"price":3799.84,"qty":0.73120000}],"checksum":3981245637,"timestamp":"2024-06-01T17:52:05.418899Z"}]}
{"channel":"book","type":"update","data":[{"symbol":"ETH/USDT","bids":[],"asks":[{"price":3800.73,"qty":2.79800000}],"checksum":2542095322,"timestamp":"2024-06-01T17:52:05.421304Z"}]}
{"channel":"book","type":"update","data":[{"symbol":"ETH/USDT","bids":[{"price":3798.21,"qty":2.63496099}],"asks":[],"checksum":1805646251,"timestamp":"2024-06-01T17:52:05.421585Z"}]}
{"channel":"book","type":"update","data":[{"symbol":"ETH/USDT","bids":[],"asks":[{"price":3799.66,"qty":2.63395724}],"checksum":2256271653,"timestamp":"2024-06-01T17:52:05.421706Z"}]}
{"channel":"book","type":"update","data":[{"symbol":"ETH/USDT","bids":[],"asks":[{"price":3799.75,"qty":0.73120000}],"checksum":1046870644,"timestamp":"2024-06-01T17:52:05.422268Z"}]}
{"channel":"book","type":"update","data":[{"symbol":"ETH/USDT","bids":[],"asks":[{"price":3799.75,"qty":0.00000000},{"price":3800.75,"qty":0.48652211}],"checksum":2256271653,"timestamp":"2024-06-01T17:52:05.425103Z"}]}
{"channel":"book","type":"update","data":[{"symbol":"ETH/USDT","bids":[],"asks":[{"price":3799.62,"qty":2.63473842}],"checksum":2055753476,"timestamp":"2024-06-01T17:52:05.433022Z"}]}
{"channel":"book","type":"update","data":[{"symbol":"ETH/USDT","bids":[{"price":3798.93,"qty":0.00000000},{"price":3798.17,"qty":15.47149119}],"asks":[],"checksum":1946140232,"timestamp":"2024-06-01T17:52:05.436255Z"}]}
{"channel":"book","type":"update","data":[{"symbol":"ETH/USDT","bids":[{"price":3798.99,"qty":0.25000000}],"asks":[],"checksum":1328667963,"timestamp":"2024-06-01T17:52:05.438842Z"}]}
{"channel":"book","type":"update","data":[{"symbol":"ETH/USDT","bids":[{"price":3799.10,"qty":0.00000000},{"price":3798.17,"qty":15.47149119}],"asks":[],"checksum":2120123595,"timestamp":"2024-06-01T17:52:05.438870Z"}]}
{"channel":"book","type":"update","data":[{"symbol":"ETH/USDT","bids":[],"asks":[{"price":3799.61,"qty":0.72912968}],"checksum":3569997803,"timestamp":"2024-06-01T17:52:05.440502Z"}]}
{"channel":"book","type":"update","data":[{"symbol":"ETH/USDT","bids":[{"price":3799.00,"qty":0.73120000}],"asks":[],"checksum":887838166,"timestamp":"2024-06-01T17:52:05.442397Z"}]}
{"channel":"book","type":"update","data":[{"symbol":"ETH/USDT","bids":[],"asks":[{"price":3799.60,"qty":2.63468685}],"checksum":2156833037,"timestamp":"2024-06-01T17:52:05.443365Z"}]}
{"channel":"book","type":"update","data":[{"symbol":"ETH/USDT","bids":[],"asks":[{"price":3799.62,"qty":0.00000000},{"price":3800.73,"qty":2.79800000}],"checksum":3324413894,"timestamp":"2024-06-01T17:52:05.444363Z"}]}
{"channel":"book","type":"update","data":[{"symbol":"ETH/USDT","bids":[{"price":3798.22,"qty":0.00000000},{"price":3798.17,"qty":15.47149119}],"asks":[],"checksum":107502608,"timestamp":"2024-06-01T17:52:05.460259Z"}]}
{"channel":"book","type":"update","data":[{"symbol":"ETH/USDT","bids":[{"price":3799.00,"qty":0.00000000},{"price":3798.16,"qty":19.08384204}],"asks":[],"checksum":1088758759,"timestamp":"2024-06-01T17:52:05.474820Z"}]}
{"channel":"book","type":"update","data":[{"symbol":"ETH/USDT","bids":[],"asks":[{"price":3799.61,"qty":0.00000000},{"price":3800.74,"qty":1.56710306}],"checksum":2963149967,"timestamp":"2024-06-01T17:52:05.478627Z"}]}
{"channel":"book","type":"update","data":[{"symbol":"ETH/USDT","bids":[{"price":3798.52,"qty":5.00000000}],"asks":[],"checksum":3198062778,"timestamp":"2024-06-01T17:52:05.479971Z"}]}
{"channel":"book","type":"update","data":[{"symbol":"ETH/USDT","bids":[],"asks":[{"price":3799.58,"qty":0.73120000}],"checksum":2660945601,"timestamp":"2024-06-01T17:52:05.484011Z"}]}
{"channel":"book","type":"update","data":[{"symbol":"ETH/USDT","bids":[],"asks":[{"price":3799.58,"qty":0.00000000},{"price":3800.74,"qty":1.56710306}],"checksum":3198062778,"timestamp":"2024-06-01T17:52:05.487313Z"}]}
{"channel":"book","type":"update","data":[{"symbol":"ETH/USDT","bids":[{"price":3798.22,"qty":0.06693358}],"asks":[],"checksum":1790069203,"timestamp":"2024-06-01T17:52:05.489728Z"}]}
{"channel":"book","type":"update","data":[{"symbol":"ETH/USDT","bids":[{"price":3798.60,"qty":1.31708923}],"asks":[],"checksum":1042353644,"timestamp":"2024-06-01T17:52:05.493466Z"}]}
{"channel":"book","type":"update","data":[{"symbol":"ETH/USDT","bids":[],"asks":[{"price":3799.58,"qty":0.73120000}],"checksum":2000191382,"timestamp":"2024-06-01T17:52:05.495873Z"}]}
{"channel":"book","type":"update","data":[{"symbol":"ETH/USDT","bids":[],"asks":[{"price":3799.60,"qty":3.36588685}],"checksum":1237025378,"timestamp":"2024-06-01T17:52:05.499173Z"}]}
{"channel":"book","type":"update","data":[{"symbol":"ETH/USDT","bids":[],"asks":[{"price":3799.85,"qty":0.72912968}],"checksum":3916989840,"timestamp":"2024-06-01T17:52:05.499579Z"}]}
{"channel":"book","type":"update","data":[{"symbol":"ETH/USDT","bids":[],"asks":[{"price":3799.58,"qty":0.00000000},{"price":3800.74,"qty":1.56710306}],"checksum":2616782046,"timestamp":"2024-06-01T17:52:05.499985Z"}]}
{"channel":"book","type":"update","data":[{"symbol":"ETH/USDT","bids":[{"price":3798.29,"qty":2.15500000}],"asks":[],"checksum":3724543913,"timestamp":"2024-06-01T17:52:05.501207Z"}]}
{"channel":"book","type":"update","data":[{"symbol":"ETH/USDT","bids":[],"asks":[{"price":3799.57,"qty":0.73120000}],"checksum":2635242363,"timestamp":"2024-06-01T17:52:05.502570Z"}]}
{"channel":"book","type":"update","data":[{"symbol":"ETH/USDT","bids":[{"price":3798.23,"qty":5.00000000}],"asks":[],"checksum":1849381725,"timestamp":"2024-06-01T17:52:05.504682Z"}]}
{"channel":"book","type":"update","data":[{"symbol":"ETH/USDT","bids":[],"asks":[{"price":3799.84,"qty":0.00000000},{"price":3800.74,"qty":1.56710306}],"checksum":747367630,"timestamp":"2024-06-01T17:52:05.506132Z"}]}
{"channel":"book","type":"update","data":[{"symbol":"ETH/USDT","bids":[],"asks":[{"price":3799.57,"qty":0.00000000},{"price":3800.75,"qty":0.48652211}],"checksum":3400990637,"timestamp":"2024-06-01T17:52:05.506166Z"}]}
{"channel":"book","type":"update","data":[{"symbol":"ETH/USDT","bids":[],"asks":[{"price":3799.59,"qty":0.73120000}],"checksum":4174654022,"timestamp":"2024-06-01T17:52:05.506215Z"}]}
{"channel":"book","type":"update","data":[{"symbol":"ETH/USDT","bids":[],"asks":[{"price":3799.57,"qty":0.73120000}],"checksum":3339487196,"timestamp":"2024-06-01T17:52:05.509029Z"}]}
{"channel":"book","type":"update","data":[{"symbol":"ETH/USDT","bids":[],"asks":[{"price":3799.56,"qty":0.72912968}],"checksum":770269828,"timestamp":"2024-06-01T17:52:05.510537Z"}]}
{"channel":"book","type":"update","data":[{"symbol":"ETH/USDT","bids":[{"price":3798.52,"qty":0.00000000},{"price":3798.22,"qty":0.06693358}],"asks":[],"checksum":1385367857,"timestamp":"2024-06-01T17:52:05.511462Z"}]}
{"channel":"book","type":"update","data":[{"symbol":"ETH/USDT","bids":[{"price":3798.61,"qty":5.00000000}],"asks":[],"checksum":4046147747,"timestamp":"2024-06-01T17:52:05.511547Z"}]}
{"channel":"book","type":"update","data":[{"symbol":"ETH/USDT","bids":[],"asks":[{"price":3799.57,"qty":0.00000000},{"price":3800.73,"qty":2.79800000}],"checksum":2206125469,"timestamp":"2024-06-01T17:52:05.512125Z"}]}
{"channel":"book","type":"update","data":[{"symbol":"ETH/USDT","bids":[],"asks":[{"price":3799.59,"qty":0.00000000},{"price":3800.74,"qty":1.56710306}],"checksum":1409329916,"timestamp":"2024-06-01T17:52:05.514546Z"}]}
{"channel":"book","type":"update","data":[{"symbol":"ETH/USDT","bids":[],"asks":[{"price":3799.60,"qty":2.63468685}],"checksum":3889970791,"timestamp":"2024-06-01T17:52:05.515296Z"}]}
{"channel":"book","type":"update","data":[{"symbol":"ETH/USDT","bids":[{"price":3798.98,"qty":0.00000000},{"price":3798.22,"qty":0.06693358}],"asks":[],"checksum":2412822292,"timestamp":"2024-06-01T17:52:05.543064Z"}]}
{"channel":"book","type":"update","data":[{"symbol":"ETH/USDT","bids":[],"asks":[{"price":3799.85,"qty":0.00000000},{"price":3800.75,"qty":0.48652211}],"checksum":57616952,"timestamp":"2024-06-01T17:52:05.546925Z"}]}
{"channel":"book","type":"update","data":[{"symbol":"ETH/USDT","bids":[{"price":3798.23,"qty":0.00000000},{"price":3798.21,"qty":2.63496099}],"asks":[],"checksum":4149709137,"timestamp":"2024-06-01T17:52:05.547499Z"}]}
{"channel":"book","type":"update","data":[{"symbol":"ETH/USDT","bids":[{"price":3798.99,"qty":0.00000000},{"price":3798.17,"qty":15.47149119}],"asks":[],"checksum":3684025687,"timestamp":"2024-06-01T17:52:05.548027Z"}]}
{"channel":"book","type":"update","data":[{"symbol":"ETH/USDT","bids":[{"price":3798.78,"qty":0.25000000}],"asks":[],"checksum":2637467033,"timestamp":"2024-06-01T17:52:05.548246Z"}]}
{"channel":"book","type":"update","data":[{"symbol":"ETH/USDT","bids":[{"price":3798.82,"qty":0.73120000}],"asks":[],"checksum":183817289,"timestamp":"2024-06-01T17:52:05.552213Z"}]}
{"channel":"book","type":"update","data":[{"symbol":"ETH/USDT","bids":[{"price":3798.83,"qty":0.25000000}],"asks":[],"checksum":577948804,"timestamp":"2024-06-01T17:52:05.583406Z"}]}
{"channel":"book","type":"update","data":[{"symbol":"ETH/USDT","bids":[{"price":3798.86,"qty":0.73120000}],"asks":[],"checksum":1306424224,"timestamp":"2024-06-01T17:52:05.586773Z"}]}
{"channel":"book","type":"update","data":[{"symbol":"ETH/USDT","bids":[{"price":3798.83,"qty":0.50000000}],"asks":[],"checksum":3701779270,"timestamp":"2024-06-01T17:52:05.586832Z"}]}
{"channel":"book","type":"update","data":[{"symbol":"ETH/USDT","bids":[{"price":3798.83,"qty":0.25000000}],"asks":[],"checksum":1306424224,"timestamp":"2024-06-01T17:52:05.614461Z"}]}
{"channel":"book","type":"update","data":[{"symbol":"ETH/USDT","bids":[{"price":3798.64,"qty":0.29500386}],"asks":[],"checksum":2768655613,"timestamp":"2024-06-01T17:52:05.637690Z"}]}
{"channel":"book","type":"update","data":[{"symbol":"ETH/USDT","bids":[{"price":3798.78,"qty":0.68000000}],"asks":[],"checksum":3466031048,"timestamp":"2024-06-01T17:52:05.661752Z"}]}
{"channel":"book","type":"update","data":[{"symbol":"ETH/USDT","bids":[{"price":3798.83,"qty":0.00000000},{"price":3798.25,"qty":0.84627249}],"asks":[],"checksum":4129536236,"timestamp":"2024-06-01T17:52:05.667270Z"}]}
{"channel":"book","type":"update","data":[{"symbol":"ETH/USDT","bids":[{"price":3798.87,"qty":0.25000000}],"asks":[],"checksum":99968220,"timestamp":"2024-06-01T17:52:05.667419Z"}]}
{"channel":"book","type":"update","data":[{"symbol":"ETH/USDT","bids":[{"price":3798.82,"qty":0.00000000},{"price":3798.25,"qty":0.84627249}],"asks":[],"checksum":1374269038,"timestamp":"2024-06-01T17:52:05.670717Z"}]}
{"channel":"book","type":"update","data":[{"symbol":"ETH/USDT","bids":[{"price":3798.88,"qty":0.73120000}],"asks":[],"checksum":2808649058,"timestamp":"2024-06-01T17:52:05.670788Z"}]}
{"channel":"book","type":"update","data":[{"symbol":"ETH/USDT","bids":[{"price":3798.78,"qty":0.25000000}],"asks":[],"checksum":3438915159,"timestamp":"2024-06-01T17:52:05.697411Z"}]}
{"channel":"book","type":"update","data":[{"symbol":"ETH/USDT","bids":[{"price":3798.89,"qty":0.25000000}],"asks":[],"checksum":1432752072,"timestamp":"2024-06-01T17:52:05.702393Z"}]}
{"channel":"book","type":"update","data":[{"symbol":"ETH/USDT","bids":[{"price":3798.87,"qty":0.00000000},{"price":3798.29,"qty":2.15500000}],"asks":[],"checksum":124091758,"timestamp":"2024-06-01T17:52:05.702745Z"}]}
{"channel":"book","type":"update","data":[{"symbol":"ETH/USDT","bids":[{"price":3798.89,"qty":0.98120000}],"asks":[],"checksum":131093083,"timestamp":"2024-06-01T17:52:05.706951Z"}]}
{"channel":"book","type":"update","data":[{"symbol":"ETH/USDT","bids":[{"price":3798.86,"qty":0.00000000},{"price":3798.25,"qty":0.84627249}],"asks":[],"checksum":1149193469,"timestamp":"2024-06-01T17:52:05.707150Z"}]}
{"channel":"book","type":"update","data":[{"symbol":"ETH/USDT","bids":[{"price":3798.88,"qty":0.00000000},{"price":3798.24,"qty":0.12668855}],"asks":[],"checksum":1335250126,"timestamp":"2024-06-01T17:52:05.707528Z"}]}
{"channel":"book","type":"update","data":[{"symbol":"ETH/USDT","bids":[{"price":3798.78,"qty":0.59000000}],"asks":[],"checksum":3503551604,"timestamp":"2024-06-01T17:52:05.713917Z"}]}
{"channel":"book","type":"update","data":[{"symbol":"ETH/USDT","bids":[{"price":3798.90,"qty":0.73120000}],"asks":[],"checksum":2390558392,"timestamp":"2024-06-01T17:52:05.716903Z"}]}
{"channel":"book","type":"update","data":[{"symbol":"ETH/USDT","bids":[{"price":3798.90,"qty":0.00000000},{"price":3798.24,"qty":0.12668855}],"asks":[],"checksum":3503551604,"timestamp":"2024-06-01T17:52:05.756559Z"}]}
{"channel":"book","type":"update","data":[{"symbol":"ETH/USDT","bids":[{"price":3798.89,"qty":0.25000000}],"asks":[],"checksum":3496401729,"timestamp":"2024-06-01T17:52:05.756842Z"}]}
{"channel":"book","type":"update","data":[{"symbol":"ETH/USDT","bids":[{"price":3798.89,"qty":0.00000000},{"price":3798.22,"qty":0.06693358}],"asks":[],"checksum":3641059669,"timestamp":"2024-06-01T17:52:05.761343Z"}]}
{"channel":"book","type":"update","data":[{"symbol":"ETH/USDT","bids":[{"price":3798.85,"qty":0.73120000}],"asks":[],"checksum":656091437,"timestamp":"2024-06-01T17:52:05.765377Z"}]}
{"channel":"book","type":"update","data":[{"symbol":"ETH/USDT","bids":[{"price":3798.86,"qty":0.25000000}],"asks":[],"checksum":3368955528,"timestamp":"2024-06-01T17:52:06.086336Z"}]}
{"channel":"book","type":"update","data":[{"symbol":"ETH/USDT","bids":[],"asks":[{"price":3799.59,"qty":0.72912968}],"checksum":3450667674,"timestamp":"2024-06-01T17:52:06.086921Z"}]}
{"channel":"book","type":"update","data":[{"symbol":"ETH/USDT","bids":[],"asks":[{"price":3799.56,"qty":0.00000000},{"price":3800.75,"qty":0.48652211}],"checksum":3511188397,"timestamp":"2024-06-01T17:52:06.086939Z"}]}
{"channel":"book","type":"update","data":[{"symbol":"ETH/USDT","bids":[{"price":3798.87,"qty":0.73120000}],"asks":[],"checksum":3035908525,"timestamp":"2024-06-01T17:52:06.090041Z"}]}
{"channel":"book","type":"update","data":[{"symbol":"ETH/USDT","bids":[{"price":3798.78,"qty":0.34000000}],"asks":[],"checksum":3122229085,"timestamp":"2024-06-01T17:52:06.091253Z"}]}
{"channel":"book","type":"update","data":[{"symbol":"ETH/USDT","bids":[],"asks":[{"price":3799.59,"qty":1.46032968}],"checksum":6851958,"timestamp":"2024-06-01T17:52:06.351873Z"}]}
{"channel":"book","type":"update","data":[{"symbol":"ETH/USDT","bids":[{"price":3798.88,"qty":0.25000000}],"asks":[],"checksum":65315782,"timestamp":"2024-06-01T17:52:06.357066Z"}]}
{"channel":"book","type":"update","data":[{"symbol":"ETH/USDT","bids":[],"asks":[{"price":3799.59,"qty":0.72912968}],"checksum":2721090866,"timestamp":"2024-06-01T17:52:06.361906Z"}]}
{"channel":"book","type":"update","data":[{"symbol":"ETH/USDT","bids":[],"asks":[{"price":3799.59,"qty":1.46032968}],"checksum":65315782,"timestamp":"2024-06-01T17:52:06.386514Z"}]}
{"channel":"book","type":"update","data":[{"symbol":"ETH/USDT","bids":[{"price":3798.86,"qty":0.00000000},{"price":3798.29,"qty":2.15500000}],"asks":[],"checksum":2510107827,"timestamp":"2024-06-01T17:52:06.391430Z"}]}
{"channel":"book","type":"update","data":[{"symbol":"ETH/USDT","bids":[{"price":3798.85,"qty":0.00000000},{"price":3798.25,"qty":0.84627249}],"asks":[],"checksum":2111865084,"timestamp":"2024-06-01T17:52:06.403399Z"}]}
{"channel":"book","type":"update","data":[{"symbol":"ETH/USDT","bids":[{"price":3798.87,"qty":0.00000000},{"price":3798.22,"qty":0.06693358}],"asks":[],"checksum":2429545733,"timestamp":"2024-06-01T17:52:06.485748Z"}]}
{"channel":"book","type":"update","data":[{"symbol":"ETH/USDT","bids":[{"price":3798.65,"qty":5.00000000}],"asks":[],"checksum":3790828017,"timestamp":"2024-06-01T17:52:06.490761Z"}]}
{"channel":"book","type":"update","data":[{"symbol":"ETH/USDT","bids":[],"asks":[{"price":3799.59,"qty":0.72912968}],"checksum":1307965779,"timestamp":"2024-06-01T17:52:06.641751Z"}]}
{"channel":"book","type":"update","data":[{"symbol":"ETH/USDT","bids":[{"price":3798.61,"qty":0.00000000},{"price":3798.22,"qty":0.06693358}],"asks":[],"checksum":2573145293,"timestamp":"2024-06-01T17:52:06.646761Z"}]}
{"channel":"book","type":"update","data":[{"symbol":"ETH/USDT","bids":[{"price":3798.88,"qty":0.98120000}],"asks":[],"checksum":745546189,"timestamp":"2024-06-01T17:52:06.651826Z"}]}
{"channel":"book","type":"update","data":[{"symbol":"ETH/USDT","bids":[],"asks":[{"price":3800.75,"qty":0.00000000},{"price":3800.77,"qty":0.73120000}],"checksum":3197726515,"timestamp":"2024-06-01T17:52:06.695305Z"}]}
{"channel":"book","type":"update","data":[{"symbol":"ETH/USDT","bids":[],"asks":[{"price":3800.72,"qty":0.45388001}],"checksum":2864796261,"timestamp":"2024-06-01T17:52:06.697942Z"}]}
{"channel":"book","type":"update","data":[{"symbol":"ETH/USDT","bids":[{"price":3798.88,"qty":0.25000000}],"asks":[],"checksum":535717733,"timestamp":"2024-06-01T17:52:07.166306Z"}]}
{"channel":"book","type":"update","data":[{"symbol":"ETH/USDT","bids":[],"asks":[{"price":3799.59,"qty":1.46032968}],"checksum":3191490961,"timestamp":"2024-06-01T17:52:07.166956Z"}]}
{"channel":"book","type":"update","data":[{"symbol":"ETH/USDT","bids":[{"price":3798.88,"qty":0.00000000},{"price":3798.21,"qty":2.63496099}],"asks":[],"checksum":4075085512,"timestamp":"2024-06-01T17:52:07.171684Z"}]}
{"channel":"book","type":"update","data":[{"symbol":"ETH/USDT","bids":[{"price":3798.79,"qty":0.25000000}],"asks":[],"checksum":1761493397,"timestamp":"2024-06-01T17:52:07.171754Z"}]}
{"channel":"book","type":"update","data":[{"symbol":"ETH/USDT","bids":[],"asks":[{"price":3799.59,"qty":0.72912968}],"checksum":3375001441,"timestamp":"2024-06-01T17:52:07.175451Z"}]}
{"channel":"book","type":"update","data":[{"symbol":"ETH/USDT","bids":[{"price":3798.84,"qty":0.73120000}],"asks":[],"checksum":3898729717,"timestamp":"2024-06-01T17:52:07.175887Z"}]}
{"channel":"book","type":"update","data":[{"symbol":"ETH/USDT","bids":[],"asks":[{"price":3799.59,"qty":1.46032968}],"checksum":1376782046,"timestamp":"2024-06-01T17:52:07.179408Z"}]}
{"channel":"book","type":"update","data":[{"symbol":"ETH/USDT","bids":[],"asks":[{"price":3800.74,"qty":0.00000000},{"price":3800.77,"qty":0.73120000}],"checksum":3618235066,"timestamp":"2024-06-01T17:52:07.405089Z"}]}
{"channel":"book","type":"update","data":[{"symbol":"ETH/USDT","bids":[],"asks":[{"price":3800.71,"qty":48.90297358}],"checksum":3870366697,"timestamp":"2024-06-01T17:52:07.407465Z"}]}
{"channel":"book","type":"update","data":[{"symbol":"ETH/USDT","bids":[{"price":3798.85,"qty":0.25000000}],"asks":[],"checksum":4038997344,"timestamp":"2024-06-01T17:52:07.586430Z"}]}
{"channel":"book","type":"update","data":[{"symbol":"ETH/USDT","bids":[],"asks":[{"price":3799.59,"qty":0.72912968}],"checksum":1555611074,"timestamp":"2024-06-01T17:52:07.589930Z"}]}
{"channel":"book","type":"update","data":[{"symbol":"ETH/USDT","bids":[{"price":3798.84,"qty":0.00000000},{"price":3798.25,"qty":0.84627249}],"asks":[],"checksum":2158693326,"timestamp":"2024-06-01T17:52:07.590446Z"}]}
{"channel":"book","type":"update","data":[{"symbol":"ETH/USDT","bids":[{"price":3798.85,"qty":0.98120000}],"asks":[],"checksum":2149459195,"timestamp":"2024-06-01T17:52:07.590595Z"}]}
{"channel":"book","type":"update","data":[{"symbol":"ETH/USDT","bids":[{"price":3798.79,"qty":0.00000000},{"price":3798.22,"qty":0.06693358}],"asks":[],"checksum":2721620003,"timestamp":"2024-06-01T17:52:07.591728Z"}]}
{"channel":"book","type":"update","data":[{"symbol":"ETH/USDT","bids":[{"price":3798.86,"qty":0.73120000}],"asks":[],"checksum":3750842650,"timestamp":"2024-06-01T17:52:07.667166Z"}]}
{"channel":"book","type":"update","data":[{"symbol":"ETH/USDT","bids":[{"price":3798.87,"qty":0.25000000}],"asks":[],"checksum":484793655,"timestamp":"2024-06-01T17:52:07.671726Z"}]}
{"channel":"book","type":"update","data":[{"symbol":"ETH/USDT","bids":[],"asks":[{"price":3799.59,"qty":1.46032968}],"checksum":2967721365,"timestamp":"2024-06-01T17:52:07.750543Z"}]}
{"channel":"book","type":"update","data":[{"symbol":"ETH/USDT","bids":[{"price":3798.85,"qty":0.73120000}],"asks":[],"checksum":119801930,"timestamp":"2024-06-01T17:52:07.754991Z"}]}
{"channel":"book","type":"update","data":[{"symbol":"ETH/USDT","bids":[{"price":3798.85,"qty":0.00000000},{"price":3798.25,"qty":0.84627249}],"asks":[],"checksum":2892323873,"timestamp":"2024-06-01T17:52:07.760605Z"}]}
{"channel":"book","type":"update","data":[{"symbol":"ETH/USDT","bids":[{"price":3798.86,"qty":0.00000000},{"price":3798.22,"qty":0.06693358}],"asks":[],"checksum":3067968711,"timestamp":"2024-06-01T17:52:07.823893Z"}]}
{"channel":"book","type":"update","data":[{"symbol":"ETH/USDT","bids":[],"asks":[{"price":3799.59,"qty":2.19152968}],"checksum":2395970602,"timestamp":"2024-06-01T17:52:07.825109Z"}]}
{"channel":"book","type":"update","data":[{"symbol":"ETH/USDT","bids":[],"asks":[{"price":3799.59,"qty":1.46032968}],"checksum":3067968711,"timestamp":"2024-06-01T17:52:07.830401Z"}]}
{"channel":"book","type":"update","data":[{"symbol":"ETH/USDT","bids":[{"price":3798.87,"qty":0.98120000}],"asks":[],"checksum":66210247,"timestamp":"2024-06-01T17:52:07.853708Z"}]}
{"channel":"book","type":"update","data":[{"symbol":"ETH/USDT","bids":[],"asks":[{"price":3799.59,"qty":0.72912968}],"checksum":3112414188,"timestamp":"2024-06-01T17:52:07.856904Z"}]}
{"channel":"book","type":"update","data":[{"symbol":"ETH/USDT","bids":[{"price":3798.89,"qty":0.73120000}],"asks":[],"checksum":845388794,"timestamp":"2024-06-01T17:52:07.856944Z"}]}
{"channel":"book","type":"update","data":[{"symbol":"ETH/USDT","bids":[{"price":3798.89,"qty":0.00000000},{"price":3798.22,"qty":0.06693358}],"asks":[],"checksum":3112414188,"timestamp":"2024-06-01T17:52:07.888318Z"}]}
{"channel":"book","type":"update","data":[{"symbol":"ETH/USDT","bids":[],"asks":[{"price":3799.59,"qty":1.46032968}],"checksum":66210247,"timestamp":"2024-06-01T17:52:07.888629Z"}]}
{"channel":"book","type":"update","data":[{"symbol":"ETH/USDT","bids":[],"asks":[{"price":3799.59,"qty":0.72912968}],"checksum":3112414188,"timestamp":"2024-06-01T17:52:07.891663Z"}]}
{"channel":"book","type":"update","data":[{"symbol":"ETH/USDT","bids":[],"asks":[{"price":3800.36,"qty":0.00000000},{"price":3800.77,"qty":0.73120000}],"checksum":3950878539,"timestamp":"2024-06-01T17:52:07.950094Z"}]}
{"channel":"book","type":"update","data":[{"symbol":"ETH/USDT","bids":[],"asks":[{"price":3799.99,"qty":2.15500000}],"checksum":2307243157,"timestamp":"2024-06-01T17:52:07.952396Z"}]}
{"channel":"book","type":"update","data":[{"symbol":"ETH/USDT","bids":[],"asks":[{"price":3799.59,"qty":1.46032968}],"checksum":871653054,"timestamp":"2024-06-01T17:52:08.049823Z"}]}
{"channel":"book","type":"update","data":[{"symbol":"ETH/USDT","bids":[],"asks":[{"price":3799.59,"qty":0.72912968}],"checksum":2307243157,"timestamp":"2024-06-01T17:52:08.141453Z"}]}
{"channel":"book","type":"update","data":[{"symbol":"ETH/USDT","bids":[{"price":3798.88,"qty":0.73120000}],"asks":[],"checksum":510289504,"timestamp":"2024-06-01T17:52:08.141862Z"}]}
{"channel":"book","type":"update","data":[{"symbol":"ETH/USDT","bids":[{"price":3798.29,"qty":0.00000000},{"price":3798.22,"qty":0.06693358}],"asks":[],"checksum":3579784203,"timestamp":"2024-06-01T17:52:08.192983Z"}]}
{"channel":"book","type":"update","data":[{"symbol":"ETH/USDT","bids":[],"asks":[{"price":3799.59,"qty":1.46032968}],"checksum":1955267327,"timestamp":"2024-06-01T17:52:08.280932Z"}]}
{"channel":"book","type":"update","data":[{"symbol":"ETH/USDT","bids":[{"price":3798.88,"qty":0.00000000},{"price":3798.21,"qty":2.63496099}],"asks":[],"checksum":2348636571,"timestamp":"2024-06-01T17:52:08.285518Z"}]}
{"channel":"book","type":"update","data":[{"symbol":"ETH/USDT","bids":[{"price":3798.87,"qty":0.25000000}],"asks":[],"checksum":1053977755,"timestamp":"2024-06-01T17:52:08.286019Z"}]}
{"channel":"book","type":"update","data":[{"symbol":"ETH/USDT","bids":[],"asks":[{"price":3799.59,"qty":0.72912968}],"checksum":2225311408,"timestamp":"2024-06-01T17:52:08.289943Z"}]}
{"channel":"book","type":"update","data":[{"symbol":"ETH/USDT","bids":[{"price":3798.89,"qty":0.25000000}],"asks":[],"checksum":2176523368,"timestamp":"2024-06-01T17:52:08.291555Z"}]}
{"channel":"book","type":"update","data":[{"symbol":"ETH/USDT","bids":[{"price":3798.23,"qty":2.15500000}],"asks":[],"checksum":3592178147,"timestamp":"2024-06-01T17:52:08.291573Z"}]}
{"channel":"book","type":"update","data":[{"symbol":"ETH/USDT","bids":[],"asks":[{"price":3799.58,"qty":0.73120000}],"checksum":2070854500,"timestamp":"2024-06-01T17:52:08.293354Z"}]}
{"channel":"book","type":"update","data":[{"symbol":"ETH/USDT","bids":[],"asks":[{"price":3799.58,"qty":0.00000000},{"price":3800.73,"qty":2.79800000}],"checksum":3592178147,"timestamp":"2024-06-01T17:52:08.295874Z"}]}
{"channel":"book","type":"update","data":[{"symbol":"ETH/USDT","bids":[],"asks":[{"price":3799.58,"qty":0.73120000}],"checksum":2070854500,"timestamp":"2024-06-01T17:52:08.307019Z"}]}
{"channel":"book","type":"update","data":[{"symbol":"ETH/USDT","bids":[],"asks":[{"price":3799.58,"qty":0.00000000},{"price":3800.73,"qty":2.79800000}],"checksum":3592178147,"timestamp":"2024-06-01T17:52:08.310895Z"}]}
{"channel":"book","type":"update","data":[{"symbol":"ETH/USDT","bids":[],"asks":[{"price":3799.55,"qty":0.73120000}],"checksum":1132041868,"timestamp":"2024-06-01T17:52:08.340519Z"}]}
{"channel":"book","type":"update","data":[{"symbol":"ETH/USDT","bids":[],"asks":[{"price":3799.55,"qty":0.00000000},{"price":3800.73,"qty":2.79800000}],"checksum":3592178147,"timestamp":"2024-06-01T17:52:08.343972Z"}]}
{"channel":"book","type":"update","data":[{"symbol":"ETH/USDT","bids":[{"price":3798.89,"qty":0.00000000},{"price":3798.22,"qty":0.06693358}],"asks":[],"checksum":2677591458,"timestamp":"2024-06-01T17:52:08.345501Z"}]}
{"channel":"book","type":"update","data":[{"symbol":"ETH/USDT","bids":[{"price":3798.87,"qty":0.98120000}],"asks":[],"checksum":716699810,"timestamp":"2024-06-01T17:52:08.357512Z"}]}
{"channel":"book","type":"update","data":[{"symbol":"ETH/USDT","bids":[{"price":3798.88,"qty":0.73120000}],"asks":[],"checksum":3189052879,"timestamp":"2024-06-01T17:52:08.367538Z"}]}
{"channel":"book","type":"update","data":[{"symbol":"ETH/USDT","bids":[],"asks":[{"price":3799.58,"qty":0.40000000}],"checksum":1092461498,"timestamp":"2024-06-01T17:52:08.464748Z"}]}
{"channel":"book","type":"update","data":[{"symbol":"ETH/USDT","bids":[],"asks":[{"price":3799.57,"qty":0.72912968}],"checksum":2804394253,"timestamp":"2024-06-01T17:52:08.468888Z"}]}
{"channel":"book","type":"update","data":[{"symbol":"ETH/USDT","bids":[{"price":3798.89,"qty":0.25000000}],"asks":[],"checksum":2018757303,"timestamp":"2024-06-01T17:52:08.469649Z"}]}
{"channel":"book","type":"update","data":[{"symbol":"ETH/USDT","bids":[{"price":3798.94,"qty":0.73120000}],"asks":[],"checksum":190402158,"timestamp":"2024-06-01T17:52:08.472874Z"}]}
{"channel":"book","type":"update","data":[{"symbol":"ETH/USDT","bids":[{"price":3798.87,"qty":0.25000000}],"asks":[],"checksum":3982807202,"timestamp":"2024-06-01T17:52:08.473321Z"}]}
{"channel":"book","type":"update","data":[{"symbol":"ETH/USDT","bids":[{"price":3798.89,"qty":0.00000000},{"price":3798.25,"qty":0.84627249}],"asks":[],"checksum":3250689980,"timestamp":"2024-06-01T17:52:08.586501Z"}]}
{"channel":"book","type":"update","data":[{"symbol":"ETH/USDT","bids":[{"price":3798.95,"qty":0.25000000}],"asks":[],"checksum":2014900489,"timestamp":"2024-06-01T17:52:08.586600Z"}]}
{"channel":"book","type":"update","data":[{"symbol":"ETH/USDT","bids":[],"asks":[{"price":3799.59,"qty":0.00000000},{"price":3800.72,"qty":0.45388001}],"checksum":3070427998,"timestamp":"2024-06-01T17:52:08.588056Z"}]}
{"channel":"book","type":"update","data":[{"symbol":"ETH/USDT","bids":[{"price":3798.88,"qty":0.00000000},{"price":3798.25,"qty":0.84627249}],"asks":[],"checksum":892223252,"timestamp":"2024-06-01T17:52:08.590258Z"}]}
{"channel":"book","type":"update","data":[{"symbol":"ETH/USDT","bids":[{"price":3798.87,"qty":0.00000000},{"price":3798.23,"qty":2.15500000}],"asks":[],"checksum":2299706959,"timestamp":"2024-06-01T17:52:08.590999Z"}]}
{"channel":"book","type":"update","data":[{"symbol":"ETH/USDT","bids":[{"price":3798.94,"qty":0.00000000},{"price":3798.22,"qty":0.06693358}],"asks":[],"checksum":273855929,"timestamp":"2024-06-01T17:52:08.592157Z"}]}
{"channel":"book","type":"update","data":[{"symbol":"ETH/USDT","bids":[],"asks":[{"price":3799.58,"qty":0.00000000},{"price":3800.73,"qty":2.79800000}],"checksum":1698012699,"timestamp":"2024-06-01T17:52:08.757752Z"}]}
{"channel":"book","type":"update","data":[{"symbol":"ETH/USDT","bids":[{"price":3798.98,"qty":0.73120000}],"asks":[],"checksum":797623887,"timestamp":"2024-06-01T17:52:08.790681Z"}]}
{"channel":"book","type":"update","data":[{"symbol":"ETH/USDT","bids":[],"asks":[{"price":3799.57,"qty":0.00000000},{"price":3800.77,"qty":0.73120000}],"checksum":228461300,"timestamp":"2024-06-01T17:52:08.795136Z"}]}
{"channel":"book","type":"update","data":[{"symbol":"ETH/USDT","bids":[],"asks":[{"price":3799.59,"qty":0.72912968}],"checksum":4225040583,"timestamp":"2024-06-01T17:52:08.795164Z"}]}
{"channel":"book","type":"update","data":[{"symbol":"ETH/USDT","bids":[{"price":3798.99,"qty":0.25000000}],"asks":[],"checksum":3282428979,"timestamp":"2024-06-01T17:52:08.795350Z"}]}
{"channel":"book","type":"update","data":[{"symbol":"ETH/USDT","bids":[{"price":3798.98,"qty":0.00000000},{"price":3798.23,"qty":2.15500000}],"asks":[],"checksum":835295298,"timestamp":"2024-06-01T17:52:08.798383Z"}]}
{"channel":"book","type":"update","data":[{"symbol":"ETH/USDT","bids":[],"asks":[{"price":3799.58,"qty":0.40000000}],"checksum":3468766775,"timestamp":"2024-06-01T17:52:08.951339Z"}]}
{"channel":"book","type":"update","data":[{"symbol":"ETH/USDT","bids":[],"asks":[{"price":3799.57,"qty":0.72912968}],"checksum":687547520,"timestamp":"2024-06-01T17:52:08.955559Z"}]}
{"channel":"book","type":"update","data":[{"symbol":"ETH/USDT","bids":[{"price":3798.99,"qty":0.00000000},{"price":3798.22,"qty":0.06693358}],"asks":[],"checksum":3746121710,"timestamp":"2024-06-01T17:52:08.955909Z"}]}
{"channel":"book","type":"update","data":[{"symbol":"ETH/USDT","bids":[{"price":3798.95,"qty":0.98120000}],"asks":[],"checksum":1785098990,"timestamp":"2024-06-01T17:52:08.986738Z"}]}
{"channel":"book","type":"update","data":[{"symbol":"ETH/USDT","bids":[],"asks":[{"price":3799.59,"qty":0.00000000},{"price":3800.72,"qty":0.45388001}],"checksum":2776465593,"timestamp":"2024-06-01T17:52:08.990506Z"}]}
{"channel":"book","type":"update","data":[{"symbol":"ETH/USDT","bids":[],"asks":[{"price":3800.72,"qty":0.00000000},{"price":3800.73,"qty":2.79800000}],"checksum":29885892,"timestamp":"2024-06-01T17:52:09.066462Z"}]}
{"channel":"book","type":"update","data":[{"symbol":"ETH/USDT","bids":[],"asks":[{"price":3800.70,"qty":0.49605723}],"checksum":3086262747,"timestamp":"2024-06-01T17:52:09.069974Z"}]}
{"channel":"book","type":"update","data":[{"symbol":"ETH/USDT","bids":[{"price":3798.96,"qty":0.73120000}],"asks":[],"checksum":635245194,"timestamp":"2024-06-01T17:52:09.291424Z"}]}
{"channel":"book","type":"update","data":[{"symbol":"ETH/USDT","bids":[{"price":3798.97,"qty":0.25000000}],"asks":[],"checksum":3030134437,"timestamp":"2024-06-01T17:52:09.297996Z"}]}
{"channel":"book","type":"update","data":[{"symbol":"ETH/USDT","bids":[{"price":3798.96,"qty":0.00000000},{"price":3798.23,"qty":2.15500000}],"asks":[],"checksum":4022438415,"timestamp":"2024-06-01T17:52:09.398514Z"}]}
{"channel":"book","type":"update","data":[{"symbol":"ETH/USDT","bids":[{"price":3798.95,"qty":0.25000000}],"asks":[],"checksum":1305759398,"timestamp":"2024-06-01T17:52:09.401092Z"}]}
{"channel":"book","type":"update","data":[{"symbol":"ETH/USDT","bids":[{"price":3798.97,"qty":0.00000000},{"price":3798.22,"qty":0.06693358}],"asks":[],"checksum":47944923,"timestamp":"2024-06-01T17:52:09.403120Z"}]}
{"channel":"book","type":"update","data":[{"symbol":"ETH/USDT","bids":[],"asks":[{"price":3799.58,"qty":0.00000000},{"price":3800.73,"qty":2.79800000}],"checksum":406499163,"timestamp":"2024-06-01T17:52:09.543302Z"}]}
{"channel":"book","type":"update","data":[{"symbol":"ETH/USDT","bids":[],"asks":[{"price":3799.57,"qty":0.00000000},{"price":3800.77,"qty":0.73120000}],"checksum":2946228083,"timestamp":"2024-06-01T17:52:09.547490Z"}]}
{"channel":"book","type":"update","data":[{"symbol":"ETH/USDT","bids":[],"asks":[{"price":3799.59,"qty":0.72912968}],"checksum":4241278264,"timestamp":"2024-06-01T17:52:09.547695Z"}]}
{"channel":"book","type":"update","data":[{"symbol":"ETH/USDT","bids":[],"asks":[{"price":3799.58,"qty":0.40000000}],"checksum":2492911811,"timestamp":"2024-06-01T17:52:09.746573Z"}]}
{"channel":"book","type":"update","data":[{"symbol":"ETH/USDT","bids":[],"asks":[{"price":3799.57,"qty":0.72912968}],"checksum":3911771167,"timestamp":"2024-06-01T17:52:09.750855Z"}]}
{"channel":"book","type":"update","data":[{"symbol":"ETH/USDT","bids":[],"asks":[{"price":3800.69,"qty":48.90297940}],"checksum":2995187388,"timestamp":"2024-06-01T17:52:09.776391Z"}]}
{"channel":"book","type":"update","data":[{"symbol":"ETH/USDT","bids":[{"price":3798.95,"qty":0.00000000},{"price":3798.21,"qty":2.63496099}],"asks":[],"checksum":946745292,"timestamp":"2024-06-01T17:52:10.086418Z"}]}
{"channel":"book","type":"update","data":[{"symbol":"ETH/USDT","bids":[{"price":3798.79,"qty":0.25000000}],"asks":[],"checksum":3630033608,"timestamp":"2024-06-01T17:52:10.086508Z"}]}
{"channel":"book","type":"update","data":[{"symbol":"ETH/USDT","bids":[],"asks":[{"price":3799.59,"qty":0.00000000},{"price":3800.70,"qty":0.49605723}],"checksum":824061707,"timestamp":"2024-06-01T17:52:10.088487Z"}]}
{"channel":"book","type":"update","data":[{"symbol":"ETH/USDT","bids":[{"price":3798.89,"qty":0.73120000}],"asks":[],"checksum":1627313918,"timestamp":"2024-06-01T17:52:10.090566Z"}]}
{"channel":"book","type":"update","data":[{"symbol":"ETH/USDT","bids":[{"price":3798.65,"qty":0.00000000},{"price":3798.22,"qty":0.06693358}],"asks":[],"checksum":1034915789,"timestamp":"2024-06-01T17:52:10.091483Z"}]}
{"channel":"book","type":"update","data":[{"symbol":"ETH/USDT","bids":[{"price":3798.61,"qty":5.00000000}],"asks":[],"checksum":1809965647,"timestamp":"2024-06-01T17:52:10.091637Z"}]}
{"channel":"book","type":"update","data":[{"symbol":"ETH/USDT","bids":[{"price":3798.89,"qty":0.00000000},{"price":3798.22,"qty":0.06693358}],"asks":[],"checksum":2572875831,"timestamp":"2024-06-01T17:52:10.119856Z"}]}
{"channel":"book","type":"update","data":[{"symbol":"ETH/USDT","bids":[],"asks":[{"price":3799.57,"qty":1.46032968}],"checksum":618517548,"timestamp":"2024-06-01T17:52:10.120402Z"}]}
{"channel":"book","type":"update","data":[{"symbol":"ETH/USDT","bids":[{"price":3798.80,"qty":0.73120000}],"asks":[],"checksum":3419934258,"timestamp":"2024-06-01T17:52:10.123369Z"}]}
{"channel":"book","type":"update","data":[{"symbol":"ETH/USDT","bids":[],"asks":[{"price":3799.57,"qty":0.72912968}],"checksum":1090535666,"timestamp":"2024-06-01T17:52:10.124117Z"}]}
{"channel":"book","type":"update","data":[{"symbol":"ETH/USDT","bids":[{"price":3798.65,"qty":5.00000000}],"asks":[],"checksum":900405798,"timestamp":"2024-06-01T17:52:10.124618Z"}]}
{"channel":"book","type":"update","data":[{"symbol":"ETH/USDT","bids":[],"asks":[{"price":3799.56,"qty":0.73120000}],"checksum":1178404132,"timestamp":"2024-06-01T17:52:10.191239Z"}]}
{"channel":"book","type":"update","data":[{"symbol":"ETH/USDT","bids":[],"asks":[{"price":3799.56,"qty":0.00000000},{"price":3800.70,"qty":0.49605723}],"checksum":900405798,"timestamp":"2024-06-01T17:52:10.194622Z"}]}
{"channel":"book","type":"update","data":[{"symbol":"ETH/USDT","bids":[],"asks":[{"price":3799.55,"qty":0.72912968}],"checksum":4280026511,"timestamp":"2024-06-01T17:52:10.195413Z"}]}
{"channel":"book","type":"update","data":[{"symbol":"ETH/USDT","bids":[{"price":3798.65,"qty":0.00000000},{"price":3798.23,"qty":2.15500000}],"asks":[],"checksum":2344050523,"timestamp":"2024-06-01T17:52:10.195883Z"}]}
{"channel":"book","type":"update","data":[{"symbol":"ETH/USDT","bids":[{"price":3798.81,"qty":0.25000000}],"asks":[],"checksum":3691349948,"timestamp":"2024-06-01T17:52:10.196567Z"}]}
{"channel":"book","type":"update","data":[{"symbol":"ETH/USDT","bids":[{"price":3798.84,"qty":0.73120000}],"asks":[],"checksum":2987728649,"timestamp":"2024-06-01T17:52:10.200997Z"}]}
{"channel":"book","type":"update","data":[{"symbol":"ETH/USDT","bids":[{"price":3798.81,"qty":0.00000000},{"price":3798.25,"qty":0.84627249}],"asks":[],"checksum":1294573523,"timestamp":"2024-06-01T17:52:10.586452Z"}]}
{"channel":"book","type":"update","data":[{"symbol":"ETH/USDT","bids":[{"price":3798.85,"qty":0.25000000}],"asks":[],"checksum":2980939705,"timestamp":"2024-06-01T17:52:10.586630Z"}]}
{"channel":"book","type":"update","data":[{"symbol":"ETH/USDT","bids":[],"asks":[{"price":3799.55,"qty":0.00000000},{"price":3800.70,"qty":0.49605723}],"checksum":3161498696,"timestamp":"2024-06-01T17:52:10.588474Z"}]}
{"channel":"book","type":"update","data":[{"symbol":"ETH/USDT","bids":[{"price":3798.88,"qty":0.73120000}],"asks":[],"checksum":2419775497,"timestamp":"2024-06-01T17:52:10.590108Z"}]}
{"channel":"book","type":"update","data":[{"symbol":"ETH/USDT","bids":[{"price":3798.80,"qty":0.00000000},{"price":3798.51,"qty":0.73120000}],"asks":[],"checksum":1565221796,"timestamp":"2024-06-01T17:52:10.590556Z"}]}
{"channel":"book","type":"update","data":[{"symbol":"ETH/USDT","bids":[{"price":3798.79,"qty":0.00000000},{"price":3798.25,"qty":0.84627249}],"asks":[],"checksum":2669306,"timestamp":"2024-06-01T17:52:10.591008Z"}]}
{"channel":"book","type":"update","data":[{"symbol":"ETH/USDT","bids":[],"asks":[{"price":3799.58,"qty":0.00000000},{"price":3800.73,"qty":2.79800000}],"checksum":2666217679,"timestamp":"2024-06-01T17:52:10.735305Z"}]}
{"channel":"book","type":"update","data":[{"symbol":"ETH/USDT","bids":[],"asks":[{"price":3799.57,"qty":0.00000000},{"price":3800.77,"qty":0.73120000}],"checksum":2586918369,"timestamp":"2024-06-01T17:52:10.739731Z"}]}
{"channel":"book","type":"update","data":[{"symbol":"ETH/USDT","bids":[],"asks":[{"price":3799.59,"qty":0.72912968}],"checksum":2048731820,"timestamp":"2024-06-01T17:52:10.739758Z"}]}
{"channel":"book","type":"update","data":[{"symbol":"ETH/USDT","bids":[{"price":3798.89,"qty":0.25000000}],"asks":[],"checksum":3114056843,"timestamp":"2024-06-01T17:52:10.740165Z"}]}
{"channel":"book","type":"update","data":[{"symbol":"ETH/USDT","bids":[],"asks":[{"price":3799.58,"qty":0.40000000}],"checksum":1441032389,"timestamp":"2024-06-01T17:52:10.748481Z"}]}
{"channel":"book","type":"update","data":[{"symbol":"ETH/USDT","bids":[{"price":3798.85,"qty":0.00000000},{"price":3798.25,"qty":0.84627249}],"asks":[],"checksum":2198388344,"timestamp":"2024-06-01T17:52:11.087602Z"}]}
{"channel":"book","type":"update","data":[{"symbol":"ETH/USDT","bids":[],"asks":[{"price":3799.57,"qty":0.72912968}],"checksum":4228267939,"timestamp":"2024-06-01T17:52:11.087897Z"}]}
{"channel":"book","type":"update","data":[{"symbol":"ETH/USDT","bids":[{"price":3798.84,"qty":0.00000000},{"price":3798.23,"qty":2.15500000}],"asks":[],"checksum":1085896029,"timestamp":"2024-06-01T17:52:11.093859Z"}]}
{"channel":"book","type":"update","data":[{"symbol":"ETH/USDT","bids":[],"asks":[{"price":3799.56,"qty":0.40000000}],"checksum":2159545365,"timestamp":"2024-06-01T17:52:11.186083Z"}]}
{"channel":"book","type":"update","data":[{"symbol":"ETH/USDT","bids":[],"asks":[{"price":3799.57,"qty":0.00000000},{"price":3800.69,"qty":48.90297940}],"checksum":2322811337,"timestamp":"2024-06-01T17:52:11.190181Z"}]}
{"channel":"book","type":"update","data":[{"symbol":"ETH/USDT","bids":[{"price":3798.23,"qty":0.00000000},{"price":3798.22,"qty":0.06693358}],"asks":[],"checksum":1033398342,"timestamp":"2024-06-01T17:52:11.194533Z"}]}
{"channel":"book","type":"update","data":[{"symbol":"ETH/USDT","bids":[{"price":3798.22,"qty":2.22193358}],"asks":[],"checksum":3678885437,"timestamp":"2024-06-01T17:52:11.293163Z"}]}
{"channel":"book","type":"update","data":[{"symbol":"ETH/USDT","bids":[{"price":3798.88,"qty":0.00000000},{"price":3798.21,"qty":2.63496099}],"asks":[],"checksum":50346124,"timestamp":"2024-06-01T17:52:11.334341Z"}]}
{"channel":"book","type":"update","data":[{"symbol":"ETH/USDT","bids":[{"price":3798.89,"qty":0.98120000}],"asks":[],"checksum":1437813120,"timestamp":"2024-06-01T17:52:11.334740Z"}]}
{"channel":"book","type":"update","data":[{"symbol":"ETH/USDT","bids":[],"asks":[{"price":3799.55,"qty":0.72912968}],"checksum":2444773530,"timestamp":"2024-06-01T17:52:11.338736Z"}]}
{"channel":"book","type":"update","data":[{"symbol":"ETH/USDT","bids":[{"price":3798.65,"qty":5.00000000}],"asks":[],"checksum":402983815,"timestamp":"2024-06-01T17:52:11.339510Z"}]}
{"channel":"book","type":"update","data":[{"symbol":"ETH/USDT","bids":[{"price":3798.79,"qty":0.25000000}],"asks":[],"checksum":1913025436,"timestamp":"2024-06-01T17:52:11.339798Z"}]}
{"channel":"book","type":"update","data":[{"symbol":"ETH/USDT","bids":[{"price":3798.89,"qty":0.73120000}],"asks":[],"checksum":3176134201,"timestamp":"2024-06-01T17:52:11.339879Z"}]}
{"channel":"book","type":"update","data":[{"symbol":"ETH/USDT","bids":[],"asks":[{"price":3799.59,"qty":0.00000000},{"price":3800.68,"qty":0.64556918}],"checksum":1987602528,"timestamp":"2024-06-01T17:52:11.587222Z"}]}
{"channel":"book","type":"update","data":[{"symbol":"ETH/USDT","bids":[{"price":3798.90,"qty":0.25000000}],"asks":[],"checksum":1274744888,"timestamp":"2024-06-01T17:52:11.587771Z"}]}
{"channel":"book","type":"update","data":[{"symbol":"ETH/USDT","bids":[{"price":3798.65,"qty":0.00000000},{"price":3798.25,"qty":0.84627249}],"asks":[],"checksum":1654437811,"timestamp":"2024-06-01T17:52:11.591479Z"}]}
{"channel":"book","type":"update","data":[{"symbol":"ETH/USDT","bids":[{"price":3798.91,"qty":0.73120000}],"asks":[],"checksum":2714808414,"timestamp":"2024-06-01T17:52:11.668562Z"}]}
{"channel":"book","type":"update","data":[{"symbol":"ETH/USDT","bids":[{"price":3798.90,"qty":0.00000000},{"price":3798.25,"qty":0.84627249}],"asks":[],"checksum":3301357634,"timestamp":"2024-06-01T17:52:11.683570Z"}]}
{"channel":"book","type":"update","data":[{"symbol":"ETH/USDT","bids":[{"price":3798.92,"qty":0.25000000}],"asks":[],"checksum":2998521652,"timestamp":"2024-06-01T17:52:11.683787Z"}]}
{"channel":"book","type":"update","data":[{"symbol":"ETH/USDT","bids":[{"price":3798.89,"qty":0.00000000},{"price":3798.25,"qty":0.84627249}],"asks":[],"checksum":4024632679,"timestamp":"2024-06-01T17:52:11.687107Z"}]}
{"channel":"book","type":"update","data":[{"symbol":"ETH/USDT","bids":[],"asks":[{"price":3799.58,"qty":0.00000000},{"price":3800.69,"qty":48.90297940}],"checksum":3474146302,"timestamp":"2024-06-01T17:52:11.724170Z"}]}
{"channel":"book","type":"update","data":[{"symbol":"ETH/USDT","bids":[],"asks":[{"price":3799.56,"qty":0.00000000},{"price":3800.73,"qty":2.79800000}],"checksum":1056342551,"timestamp":"2024-06-01T17:52:11.724277Z"}]}
{"channel":"book","type":"update","data":[{"symbol":"ETH/USDT","bids":[{"price":3798.79,"qty":0.00000000},{"price":3798.22,"qty":2.22193358}],"asks":[],"checksum":1827971084,"timestamp":"2024-06-01T17:52:11.729892Z"}]}
{"channel":"book","type":"update","data":[{"symbol":"ETH/USDT","bids":[{"price":3798.91,"qty":0.00000000},{"price":3798.21,"qty":2.63496099}],"asks":[],"checksum":415026285,"timestamp":"2024-06-01T17:52:11.877992Z"}]}
{"channel":"book","type":"update","data":[{"symbol":"ETH/USDT","bids":[{"price":3798.92,"qty":0.98120000}],"asks":[],"checksum":1309654369,"timestamp":"2024-06-01T17:52:11.878042Z"}]}
{"channel":"book","type":"update","data":[{"symbol":"ETH/USDT","bids":[],"asks":[{"price":3799.59,"qty":0.72912968}],"checksum":1832349205,"timestamp":"2024-06-01T17:52:11.883223Z"}]}
{"channel":"book","type":"update","data":[{"symbol":"ETH/USDT","bids":[],"asks":[{"price":3799.55,"qty":0.00000000},{"price":3800.73,"qty":2.79800000}],"checksum":2368903209,"timestamp":"2024-06-01T17:52:11.883264Z"}]}
{"channel":"book","type":"update","data":[{"symbol":"ETH/USDT","bids":[{"price":3798.65,"qty":5.00000000}],"asks":[],"checksum":76536628,"timestamp":"2024-06-01T17:52:11.884560Z"}]}
{"channel":"book","type":"update","data":[{"symbol":"ETH/USDT","bids":[{"price":3798.93,"qty":0.73120000}],"asks":[],"checksum":2805107016,"timestamp":"2024-06-01T17:52:12.135459Z"}]}
{"channel":"book","type":"update","data":[{"symbol":"ETH/USDT","bids":[{"price":3798.97,"qty":0.73120000}],"asks":[],"checksum":1536438264,"timestamp":"2024-06-01T17:52:12.135820Z"}]}
{"channel":"book","type":"update","data":[{"symbol":"ETH/USDT","bids":[{"price":3798.93,"qty":0.00000000},{"price":3798.25,"qty":0.84627249}],"asks":[],"checksum":2964472092,"timestamp":"2024-06-01T17:52:12.139575Z"}]}
{"channel":"book","type":"update","data":[{"symbol":"ETH/USDT","bids":[{"price":3798.94,"qty":0.25000000}],"asks":[],"checksum":2176415818,"timestamp":"2024-06-01T17:52:12.140661Z"}]}
{"channel":"book","type":"update","data":[{"symbol":"ETH/USDT","bids":[{"price":3798.65,"qty":0.00000000},{"price":3798.25,"qty":0.84627249}],"asks":[],"checksum":2587250498,"timestamp":"2024-06-01T17:52:12.141323Z"}]}
{"channel":"book","type":"update","data":[{"symbol":"ETH/USDT","bids":[],"asks":[{"price":3800.69,"qty":0.00000000},{"price":3800.77,"qty":0.73120000}],"checksum":4281494651,"timestamp":"2024-06-01T17:52:12.166862Z"}]}
{"channel":"book","type":"update","data":[{"symbol":"ETH/USDT","bids":[],"asks":[{"price":3799.54,"qty":0.52681703}],"checksum":1310007645,"timestamp":"2024-06-01T17:52:12.171454Z"}]}
{"channel":"book","type":"update","data":[{"symbol":"ETH/USDT","bids":[],"asks":[{"price":3800.72,"qty":61.89175612}],"checksum":2183289140,"timestamp":"2024-06-01T17:52:12.171546Z"}]}
{"channel":"book","type":"update","data":[{"symbol":"ETH/USDT","bids":[],"asks":[{"price":3800.67,"qty":9.36977207}],"checksum":362048621,"timestamp":"2024-06-01T17:52:12.171637Z"}]}
{"channel":"book","type":"update","data":[{"symbol":"ETH/USDT","bids":[{"price":3798.94,"qty":0.00000000},{"price":3798.22,"qty":2.22193358}],"asks":[],"checksum":1047763782,"timestamp":"2024-06-01T17:52:12.176455Z"}]}
{"channel":"book","type":"update","data":[{"symbol":"ETH/USDT","bids":[{"price":3798.98,"qty":0.25000000}],"asks":[],"checksum":3077234319,"timestamp":"2024-06-01T17:52:12.176607Z"}]}
{"channel":"book","type":"update","data":[{"symbol":"ETH/USDT","bids":[],"asks":[{"price":3799.53,"qty":0.72912968}],"checksum":933180425,"timestamp":"2024-06-01T17:52:12.176629Z"}]}
{"channel":"book","type":"update","data":[{"symbol":"ETH/USDT","bids":[{"price":3798.92,"qty":0.25000000}],"asks":[],"checksum":1949133892,"timestamp":"2024-06-01T17:52:12.179836Z"}]}
{"channel":"book","type":"update","data":[{"symbol":"ETH/USDT","bids":[{"price":3798.98,"qty":0.98120000}],"asks":[],"checksum":3238156612,"timestamp":"2024-06-01T17:52:12.180645Z"}]}
{"channel":"book","type":"update","data":[{"symbol":"ETH/USDT","bids":[{"price":3798.97,"qty":0.00000000},{"price":3798.22,"qty":2.22193358}],"asks":[],"checksum":1641351030,"timestamp":"2024-06-01T17:52:12.181723Z"}]}
{"channel":"book","type":"update","data":[{"symbol":"ETH/USDT","bids":[{"price":3798.99,"qty":0.73120000}],"asks":[],"checksum":4227334871,"timestamp":"2024-06-01T17:52:12.193782Z"}]}
{"channel":"book","type":"update","data":[{"symbol":"ETH/USDT","bids":[],"asks":[{"price":3799.52,"qty":0.40000000}],"checksum":4286007292,"timestamp":"2024-06-01T17:52:12.280941Z"}]}
{"channel":"book","type":"update","data":[{"symbol":"ETH/USDT","bids":[],"asks":[{"price":3799.53,"qty":0.00000000},{"price":3800.67,"qty":9.36977207}],"checksum":1863482578,"timestamp":"2024-06-01T17:52:12.285021Z"}]}
{"channel":"book","type":"update","data":[{"symbol":"ETH/USDT","bids":[{"price":3798.98,"qty":0.73120000}],"asks":[],"checksum":3341362736,"timestamp":"2024-06-01T17:52:12.286774Z"}]}
{"channel":"book","type":"update","data":[{"symbol":"ETH/USDT","bids":[{"price":3799.00,"qty":0.25000000}],"asks":[],"checksum":1604285788,"timestamp":"2024-06-01T17:52:12.286854Z"}]}
{"channel":"book","type":"update","data":[{"symbol":"ETH/USDT","bids":[{"price":3798.98,"qty":0.00000000},{"price":3798.25,"qty":0.84627249}],"asks":[],"checksum":1017141772,"timestamp":"2024-06-01T17:52:12.290629Z"}]}
{"channel":"book","type":"update","data":[{"symbol":"ETH/USDT","bids":[{"price":3798.99,"qty":0.00000000},{"price":3798.22,"qty":0.06693358}],"asks":[],"checksum":2511437858,"timestamp":"2024-06-01T17:52:12.573695Z"}]}
{"channel":"book","type":"update","data":[{"symbol":"ETH/USDT","bids":[],"asks":[{"price":3799.51,"qty":0.72912968}],"checksum":2476231106,"timestamp":"2024-06-01T17:52:12.577856Z"}]}
{"channel":"book","type":"update","data":[{"symbol":"ETH/USDT","bids":[{"price":3799.00,"qty":0.00000000},{"price":3798.21,"qty":2.63496099}],"asks":[],"checksum":1069762967,"timestamp":"2024-06-01T17:52:12.578101Z"}]}
{"channel":"book","type":"update","data":[{"symbol":"ETH/USDT","bids":[{"price":3798.92,"qty":0.98120000}],"asks":[],"checksum":2330754199,"timestamp":"2024-06-01T17:52:12.582168Z"}]}
{"channel":"book","type":"update","data":[{"symbol":"ETH/USDT","bids":[],"asks":[{"price":3799.89,"qty":0.73541065}],"checksum":2141230176,"timestamp":"2024-06-01T17:52:12.586352Z"}]}
{"channel":"book","type":"update","data":[{"symbol":"ETH/USDT","bids":[],"asks":[{"price":3799.59,"qty":0.00000000},{"price":3800.67,"qty":9.36977207}],"checksum":4125361890,"timestamp":"2024-06-01T17:52:12.587828Z"}]}
{"channel":"book","type":"update","data":[{"symbol":"ETH/USDT","bids":[{"price":3798.93,"qty":0.73120000}],"asks":[],"checksum":2496403542,"timestamp":"2024-06-01T17:52:12.589303Z"}]}
{"channel":"book","type":"update","data":[{"symbol":"ETH/USDT","bids":[],"asks":[{"price":3799.52,"qty":0.00000000},{"price":3800.68,"qty":0.64556918}],"checksum":30274485,"timestamp":"2024-06-01T17:52:12.647136Z"}]}
{"channel":"book","type":"update","data":[{"symbol":"ETH/USDT","bids":[],"asks":[{"price":3799.50,"qty":0.40000000}],"checksum":3866291075,"timestamp":"2024-06-01T17:52:12.647220Z"}]}
{"channel":"book","type":"update","data":[{"symbol":"ETH/USDT","bids":[{"price":3798.94,"qty":0.25000000}],"asks":[],"checksum":3628775383,"timestamp":"2024-06-01T17:52:12.652357Z"}]}
{"channel":"book","type":"update","data":[{"symbol":"ETH/USDT","bids":[],"asks":[{"price":3799.53,"qty":0.40000000}],"checksum":4123837794,"timestamp":"2024-06-01T17:52:12.967813Z"}]}
{"channel":"book","type":"update","data":[{"symbol":"ETH/USDT","bids":[],"asks":[{"price":3799.49,"qty":0.72912968}],"checksum":2042199508,"timestamp":"2024-06-01T17:52:12.972161Z"}]}
{"channel":"book","type":"update","data":[{"symbol":"ETH/USDT","bids":[{"price":3798.92,"qty":0.73120000}],"asks":[],"checksum":54041002,"timestamp":"2024-06-01T17:52:12.972736Z"}]}
{"channel":"book","type":"update","data":[{"symbol":"ETH/USDT","bids":[{"price":3798.94,"qty":0.98120000}],"asks":[],"checksum":3055004842,"timestamp":"2024-06-01T17:52:12.973424Z"}]}
{"channel":"book","type":"update","data":[{"symbol":"ETH/USDT","bids":[{"price":3798.92,"qty":0.00000000},{"price":3798.22,"qty":0.06693358}],"asks":[],"checksum":581325738,"timestamp":"2024-06-01T17:52:12.975300Z"}]}
{"channel":"book","type":"update","data":[{"symbol":"ETH/USDT","bids":[{"price":3798.93,"qty":0.00000000},{"price":3798.21,"qty":2.63496099}],"asks":[],"checksum":2383497240,"timestamp":"2024-06-01T17:52:12.976372Z"}]}
{"channel":"book","type":"update","data":[{"symbol":"ETH/USDT","bids":[{"price":3798.95,"qty":0.73120000}],"asks":[],"checksum":3569049876,"timestamp":"2024-06-01T17:52:12.991327Z"}]}
{"channel":"book","type":"update","data":[{"symbol":"ETH/USDT","bids":[{"price":3798.96,"qty":0.25000000}],"asks":[],"checksum":2224529946,"timestamp":"2024-06-01T17:52:13.086605Z"}]}
{"channel":"book","type":"update","data":[{"symbol":"ETH/USDT","bids":[],"asks":[{"price":3799.51,"qty":0.00000000},{"price":3800.27,"qty":0.98120000}],"checksum":223078830,"timestamp":"2024-06-01T17:52:13.088244Z"}]}
{"channel":"book","type":"update","data":[{"symbol":"ETH/USDT","bids":[{"price":3798.94,"qty":0.73120000}],"asks":[],"checksum":2009730512,"timestamp":"2024-06-01T17:52:13.091914Z"}]}
{"channel":"book","type":"update","data":[{"symbol":"ETH/USDT","bids":[{"price":3798.94,"qty":0.00000000},{"price":3798.22,"qty":0.06693358}],"asks":[],"checksum":1820372819,"timestamp":"2024-06-01T17:52:13.098328Z"}]}
{"channel":"book","type":"update","data":[{"symbol":"ETH/USDT","bids":[{"price":3798.99,"qty":0.73120000}],"asks":[],"checksum":1649188728,"timestamp":"2024-06-01T17:52:13.289722Z"}]}
{"channel":"book","type":"update","data":[{"symbol":"ETH/USDT","bids":[{"price":3799.00,"qty":0.25000000}],"asks":[],"checksum":2133269291,"timestamp":"2024-06-01T17:52:13.294819Z"}]}
{"channel":"book","type":"update","data":[{"symbol":"ETH/USDT","bids":[{"price":3799.00,"qty":0.98120000}],"asks":[],"checksum":3389533739,"timestamp":"2024-06-01T17:52:13.377482Z"}]}
{"channel":"book","type":"update","data":[{"symbol":"ETH/USDT","bids":[{"price":3798.95,"qty":0.00000000},{"price":3798.25,"qty":0.84627249}],"asks":[],"checksum":941378620,"timestamp":"2024-06-01T17:52:13.377968Z"}]}
{"channel":"book","type":"update","data":[{"symbol":"ETH/USDT","bids":[{"price":3798.99,"qty":0.00000000},{"price":3798.22,"qty":0.06693358}],"asks":[],"checksum":3768670225,"timestamp":"2024-06-01T17:52:13.378962Z"}]}
{"channel":"book","type":"update","data":[{"symbol":"ETH/USDT","bids":[{"price":3799.01,"qty":0.73120000}],"asks":[],"checksum":3949159156,"timestamp":"2024-06-01T17:52:13.381881Z"}]}
{"channel":"book","type":"update","data":[{"symbol":"ETH/USDT","bids":[{"price":3798.96,"qty":0.00000000},{"price":3798.22,"qty":0.06693358}],"asks":[],"checksum":2909747145,"timestamp":"2024-06-01T17:52:13.382181Z"}]}
{"channel":"book","type":"update","data":[{"symbol":"ETH/USDT","bids":[{"price":3799.01,"qty":0.00000000},{"price":3798.21,"qty":2.63496099}],"asks":[],"checksum":2005054038,"timestamp":"2024-06-01T17:52:13.389282Z"}]}
{"channel":"book","type":"update","data":[{"symbol":"ETH/USDT","bids":[{"price":3799.00,"qty":0.25000000}],"asks":[],"checksum":3266152278,"timestamp":"2024-06-01T17:52:13.389537Z"}]}
{"channel":"book","type":"update","data":[{"symbol":"ETH/USDT","bids":[],"asks":[{"price":3799.50,"qty":0.00000000},{"price":3800.67,"qty":9.36977207}],"checksum":3893754155,"timestamp":"2024-06-01T17:52:13.487706Z"}]}
{"channel":"book","type":"update","data":[{"symbol":"ETH/USDT","bids":[],"asks":[{"price":3799.49,"qty":0.00000000},{"price":3800.68,"qty":0.64556918}],"checksum":871651199,"timestamp":"2024-06-01T17:52:13.492143Z"}]}
{"channel":"book","type":"update","data":[{"symbol":"ETH/USDT","bids":[],"asks":[{"price":3799.52,"qty":0.72912968}],"checksum":770951438,"timestamp":"2024-06-01T17:52:13.492178Z"}]}
{"channel":"book","type":"update","data":[{"symbol":"ETH/USDT","bids":[{"price":3798.65,"qty":5.00000000}],"asks":[],"checksum":2753779823,"timestamp":"2024-06-01T17:52:13.492555Z"}]}
{"channel":"book","type":"update","data":[{"symbol":"ETH/USDT","bids":[{"price":3798.33,"qty":0.21756313}],"asks":[],"checksum":1884295466,"timestamp":"2024-06-01T17:52:13.667424Z"}]}
{"channel":"book","type":"update","data":[{"symbol":"ETH/USDT","bids":[{"price":3798.61,"qty":0.00000000},{"price":3798.22,"qty":0.06693358}],"asks":[],"checksum":4000216704,"timestamp":"2024-06-01T17:52:13.707077Z"}]}
{"channel":"book","type":"update","data":[{"symbol":"ETH/USDT","bids":[],"asks":[{"price":3800.66,"qty":0.46843007}],"checksum":3674921609,"timestamp":"2024-06-01T17:52:13.756116Z"}]}
{"channel":"book","type":"update","data":[{"symbol":"ETH/USDT","bids":[{"price":3799.01,"qty":0.73120000}],"asks":[],"checksum":1862631972,"timestamp":"2024-06-01T17:52:14.010913Z"}]}
{"channel":"book","type":"update","data":[{"symbol":"ETH/USDT","bids":[],"asks":[{"price":3799.60,"qty":0.00000000},{"price":3800.67,"qty":9.36977207}],"checksum":4016937691,"timestamp":"2024-06-01T17:52:14.015965Z"}]}
{"channel":"book","type":"update","data":[{"symbol":"ETH/USDT","bids":[{"price":3799.02,"qty":0.25000000}],"asks":[],"checksum":3278246283,"timestamp":"2024-06-01T17:52:14.016467Z"}]}
{"channel":"book","type":"update","data":[{"symbol":"ETH/USDT","bids":[{"price":3799.01,"qty":0.00000000},{"price":3798.25,"qty":0.84627249}],"asks":[],"checksum":1384947429,"timestamp":"2024-06-01T17:52:14.019773Z"}]}
{"channel":"book","type":"update","data":[{"symbol":"ETH/USDT","bids":[{"price":3799.02,"qty":0.98120000}],"asks":[],"checksum":3886263269,"timestamp":"2024-06-01T17:52:14.019929Z"}]}
{"channel":"book","type":"update","data":[{"symbol":"ETH/USDT","bids":[{"price":3799.03,"qty":0.73120000}],"asks":[],"checksum":1359760167,"timestamp":"2024-06-01T17:52:14.023733Z"}]}
{"channel":"book","type":"update","data":[{"symbol":"ETH/USDT","bids":[{"price":3799.03,"qty":1.46240000}],"asks":[],"checksum":3541265409,"timestamp":"2024-06-01T17:52:14.076421Z"}]}
{"channel":"book","type":"update","data":[{"symbol":"ETH/USDT","bids":[{"price":3799.02,"qty":0.73120000}],"asks":[],"checksum":2066233059,"timestamp":"2024-06-01T17:52:14.082282Z"}]}
{"channel":"book","type":"update","data":[{"symbol":"ETH/USDT","bids":[{"price":3799.04,"qty":0.25000000}],"asks":[],"checksum":780448035,"timestamp":"2024-06-01T17:52:14.082426Z"}]}
{"channel":"book","type":"update","data":[{"symbol":"ETH/USDT","bids":[],"asks":[{"price":3799.89,"qty":0.00421065}],"checksum":2996772402,"timestamp":"2024-06-01T17:52:14.085597Z"}]}
{"channel":"book","type":"update","data":[{"symbol":"ETH/USDT","bids":[{"price":3799.03,"qty":0.73120000}],"asks":[],"checksum":674751231,"timestamp":"2024-06-01T17:52:14.085709Z"}]}
{"channel":"book","type":"update","data":[{"symbol":"ETH/USDT","bids":[{"price":3799.10,"qty":0.73120000}],"asks":[],"checksum":2338162945,"timestamp":"2024-06-01T17:52:14.086209Z"}]}
{"channel":"book","type":"update","data":[{"symbol":"ETH/USDT","bids":[{"price":3799.02,"qty":0.00000000},{"price":3798.51,"qty":0.73120000}],"asks":[],"checksum":2785643619,"timestamp":"2024-06-01T17:52:14.086413Z"}]}
{"channel":"book","type":"update","data":[{"symbol":"ETH/USDT","bids":[{"price":3799.10,"qty":0.00000000},{"price":3798.33,"qty":0.21756313}],"asks":[],"checksum":353321012,"timestamp":"2024-06-01T17:52:14.089130Z"}]}
{"channel":"book","type":"update","data":[{"symbol":"ETH/USDT","bids":[{"price":3799.06,"qty":0.73120000}],"asks":[],"checksum":2401542695,"timestamp":"2024-06-01T17:52:14.093091Z"}]}
{"channel":"book","type":"update","data":[{"symbol":"ETH/USDT","bids":[{"price":3799.06,"qty":1.46240000}],"asks":[],"checksum":1190820300,"timestamp":"2024-06-01T17:52:14.550558Z"}]}
{"channel":"book","type":"update","data":[{"symbol":"ETH/USDT","bids":[{"price":3799.07,"qty":0.25000000}],"asks":[],"checksum":2683002518,"timestamp":"2024-06-01T17:52:14.555865Z"}]}
{"channel":"book","type":"update","data":[{"symbol":"ETH/USDT","bids":[{"price":3799.04,"qty":0.00000000},{"price":3798.51,"qty":0.73120000}],"asks":[],"checksum":3858794353,"timestamp":"2024-06-01T17:52:14.556025Z"}]}
{"channel":"book","type":"update","data":[{"symbol":"ETH/USDT","bids":[{"price":3799.06,"qty":0.73120000}],"asks":[],"checksum":469621053,"timestamp":"2024-06-01T17:52:14.559055Z"}]}
{"channel":"book","type":"update","data":[{"symbol":"ETH/USDT","bids":[{"price":3799.03,"qty":0.00000000},{"price":3798.33,"qty":0.21756313}],"asks":[],"checksum":2445106108,"timestamp":"2024-06-01T17:52:14.559429Z"}]}
{"channel":"book","type":"update","data":[{"symbol":"ETH/USDT","bids":[{"price":3799.11,"qty":0.73120000}],"asks":[],"checksum":3714854586,"timestamp":"2024-06-01T17:52:14.559729Z"}]}
{"channel":"book","type":"update","data":[{"symbol":"ETH/USDT","bids":[{"price":3799.07,"qty":0.00000000},{"price":3798.33,"qty":0.21756313}],"asks":[],"checksum":4272913614,"timestamp":"2024-06-01T17:52:14.586810Z"}]}
{"channel":"book","type":"update","data":[{"symbol":"ETH/USDT","bids":[{"price":3799.06,"qty":0.00000000},{"price":3798.25,"qty":0.84627249}],"asks":[],"checksum":4163112970,"timestamp":"2024-06-01T17:52:14.591172Z"}]}
{"channel":"book","type":"update","data":[{"symbol":"ETH/USDT","bids":[],"asks":[{"price":3799.54,"qty":0.00000000},{"price":3800.72,"qty":61.89175612}],"checksum":775366611,"timestamp":"2024-06-01T17:52:14.644742Z"}]}
{"channel":"book","type":"update","data":[{"symbol":"ETH/USDT","bids":[],"asks":[{"price":3800.67,"qty":0.00000000},{"price":3800.73,"qty":2.79800000}],"checksum":2579849491,"timestamp":"2024-06-01T17:52:14.644880Z"}]}
{"channel":"book","type":"update","data":[{"symbol":"ETH/USDT","bids":[],"asks":[{"price":3800.72,"qty":0.00000000},{"price":3800.77,"qty":0.73120000}],"checksum":2609493416,"timestamp":"2024-06-01T17:52:14.645140Z"}]}
{"channel":"book","type":"update","data":[{"symbol":"ETH/USDT","bids":[],"asks":[{"price":3800.65,"qty":1.04699086}],"checksum":1846162761,"timestamp":"2024-06-01T17:52:14.650116Z"}]}
{"channel":"book","type":"update","data":[{"symbol":"ETH/USDT","bids":[],"asks":[{"price":3800.72,"qty":52.02402576}],"checksum":3957361086,"timestamp":"2024-06-01T17:52:14.650230Z"}]}
{"channel":"book","type":"update","data":[{"symbol":"ETH/USDT","bids":[{"price":3799.11,"qty":1.46240000}],"asks":[],"checksum":1087752924,"timestamp":"2024-06-01T17:52:14.683129Z"}]}
{"channel":"book","type":"update","data":[{"symbol":"ETH/USDT","bids":[],"asks":[{"price":3799.53,"qty":0.00000000},{"price":3800.73,"qty":2.79800000}],"checksum":4133149040,"timestamp":"2024-06-01T17:52:14.690742Z"}]}
{"channel":"book","type":"update","data":[{"symbol":"ETH/USDT","bids":[{"price":3799.11,"qty":0.73120000}],"asks":[],"checksum":48109697,"timestamp":"2024-06-01T17:52:14.822353Z"}]}
{"channel":"book","type":"update","data":[{"symbol":"ETH/USDT","bids":[],"asks":[{"price":3799.52,"qty":0.00000000},{"price":3800.77,"qty":0.73120000}],"checksum":2382465535,"timestamp":"2024-06-01T17:52:14.826467Z"}]}
{"channel":"book","type":"update","data":[{"symbol":"ETH/USDT","bids":[],"asks":[{"price":3799.65,"qty":0.72912968}],"checksum":3886749055,"timestamp":"2024-06-01T17:52:14.826545Z"}]}
{"channel":"book","type":"update","data":[{"symbol":"ETH/USDT","bids":[{"price":3799.11,"qty":0.00000000},{"price":3798.22,"qty":0.07220175}],"asks":[],"checksum":2317515930,"timestamp":"2024-06-01T17:52:15.013926Z"}]}
{"channel":"book","type":"update","data":[{"symbol":"ETH/USDT","bids":[{"price":3799.10,"qty":0.73120000}],"asks":[],"checksum":130945976,"timestamp":"2024-06-01T17:52:15.018269Z"}]}
{"channel":"book","type":"update","data":[{"symbol":"ETH/USDT","bids":[{"price":3799.10,"qty":1.46240000}],"asks":[],"checksum":2841264499,"timestamp":"2024-06-01T17:52:15.328264Z"}]}
{"channel":"book","type":"update","data":[{"symbol":"ETH/USDT","bids":[],"asks":[{"price":3800.27,"qty":0.25000000}],"checksum":603919584,"timestamp":"2024-06-01T17:52:15.355901Z"}]}
{"channel":"book","type":"update","data":[{"symbol":"ETH/USDT","bids":[],"asks":[{"price":3800.73,"qty":0.00000000},{"price":3800.77,"qty":0.73120000}],"checksum":1199599363,"timestamp":"2024-06-01T17:52:15.365950Z"}]}
{"channel":"book","type":"update","data":[{"symbol":"ETH/USDT","bids":[],"asks":[{"price":3799.65,"qty":0.00000000},{"price":3800.83,"qty":6.85624276}],"checksum":3847914118,"timestamp":"2024-06-01T17:52:15.369641Z"}]}
{"channel":"book","type":"update","data":[{"symbol":"ETH/USDT","bids":[],"asks":[{"price":3799.66,"qty":0.00000000},{"price":3800.96,"qty":2.63306005}],"checksum":3578485092,"timestamp":"2024-06-01T17:52:15.373285Z"}]}
{"channel":"book","type":"update","data":[{"symbol":"ETH/USDT","bids":[],"asks":[{"price":3800.05,"qty":2.63368998}],"checksum":2312416493,"timestamp":"2024-06-01T17:52:15.380645Z"}]}
{"channel":"book","type":"update","data":[{"symbol":"ETH/USDT","bids":[{"price":3798.62,"qty":2.63467535}],"asks":[],"checksum":2919001887,"timestamp":"2024-06-01T17:52:15.380735Z"}]}
{"channel":"book","type":"update","data":[{"symbol":"ETH/USDT","bids":[{"price":3799.10,"qty":2.77954822}],"asks":[],"checksum":4085364879,"timestamp":"2024-06-01T17:52:15.387738Z"}]}
{"channel":"book","type":"update","data":[{"symbol":"ETH/USDT","bids":[{"price":3798.60,"qty":0.00000000},{"price":3798.25,"qty":0.84627249}],"asks":[],"checksum":3673954910,"timestamp":"2024-06-01T17:52:15.391218Z"}]}
{"channel":"book","type":"update","data":[{"symbol":"ETH/USDT","bids":[{"price":3798.78,"qty":0.00000000},{"price":3798.22,"qty":0.07220175}],"asks":[],"checksum":3239238716,"timestamp":"2024-06-01T17:52:15.397533Z"}]}
{"channel":"book","type":"update","data":[{"symbol":"ETH/USDT","bids":[{"price":3799.11,"qty":0.34000000}],"asks":[],"checksum":2041026682,"timestamp":"2024-06-01T17:52:15.397701Z"}]}
{"channel":"book","type":"update","data":[{"symbol":"ETH/USDT","bids":[{"price":3799.29,"qty":0.73120000}],"asks":[],"checksum":1640900959,"timestamp":"2024-06-01T17:52:15.401909Z"}]}
{"channel":"book","type":"update","data":[{"symbol":"ETH/USDT","bids":[],"asks":[{"price":3800.27,"qty":0.98120000}],"checksum":2580608379,"timestamp":"2024-06-01T17:52:15.405295Z"}]}
{"channel":"book","type":"update","data":[{"symbol":"ETH/USDT","bids":[],"asks":[{"price":3800.83,"qty":0.00000000},{"price":3800.96,"qty":2.63306005}],"checksum":2032495114,"timestamp":"2024-06-01T17:52:15.408205Z"}]}
{"channel":"book","type":"update","data":[{"symbol":"ETH/USDT","bids":[],"asks":[{"price":3800.27,"qty":0.25000000}],"checksum":2168174126,"timestamp":"2024-06-01T17:52:15.414007Z"}]}
{"channel":"book","type":"update","data":[{"symbol":"ETH/USDT","bids":[{"price":3798.33,"qty":0.00000000},{"price":3798.25,"qty":0.84627249}],"asks":[],"checksum":2210105417,"timestamp":"2024-06-01T17:52:15.432125Z"}]}
{"channel":"book","type":"update","data":[{"symbol":"ETH/USDT","bids":[{"price":3798.63,"qty":0.20751112}],"asks":[],"checksum":1284460337,"timestamp":"2024-06-01T17:52:15.433210Z"}]}
{"channel":"book","type":"update","data":[{"symbol":"ETH/USDT","bids":[{"price":3798.65,"qty":5.84627249}],"asks":[],"checksum":2781370838,"timestamp":"2024-06-01T17:52:15.438645Z"}]}
{"channel":"book","type":"update","data":[{"symbol":"ETH/USDT","bids":[{"price":3798.63,"qty":0.00000000},{"price":3798.25,"qty":0.84627249}],"asks":[],"checksum":1794940590,"timestamp":"2024-06-01T17:52:15.439670Z"}]}
{"channel":"book","type":"update","data":[{"symbol":"ETH/USDT","bids":[{"price":3799.30,"qty":0.25000000}],"asks":[],"checksum":2122972692,"timestamp":"2024-06-01T17:52:15.441384Z"}]}
{"channel":"book","type":"update","data":[{"symbol":"ETH/USDT","bids":[{"price":3799.48,"qty":0.73120000}],"asks":[],"checksum":1925707277,"timestamp":"2024-06-01T17:52:15.445052Z"}]}
{"channel":"book","type":"update","data":[{"symbol":"ETH/USDT","bids":[{"price":3799.10,"qty":2.04834822}],"asks":[],"checksum":2805668198,"timestamp":"2024-06-01T17:52:15.446351Z"}]}
{"channel":"book","type":"update","data":[{"symbol":"ETH/USDT","bids":[{"price":3799.50,"qty":0.73120000}],"asks":[],"checksum":831906270,"timestamp":"2024-06-01T17:52:15.448751Z"}]}
{"channel":"book","type":"update","data":[{"symbol":"ETH/USDT","bids":[],"asks":[{"price":3800.09,"qty":0.00000000},{"price":3801.01,"qty":5.00000000}],"checksum":4110310955,"timestamp":"2024-06-01T17:52:15.453170Z"}]}
{"channel":"book","type":"update","data":[{"symbol":"ETH/USDT","bids":[{"price":3799.50,"qty":0.00000000},{"price":3798.62,"qty":2.63467535}],"asks":[],"checksum":1781101642,"timestamp":"2024-06-01T17:52:15.456587Z"}]}
{"channel":"book","type":"update","data":[{"symbol":"ETH/USDT","bids":[{"price":3799.29,"qty":0.00000000},{"price":3798.51,"qty":0.73120000}],"asks":[],"checksum":449304665,"timestamp":"2024-06-01T17:52:15.456778Z"}]}
{"channel":"book","type":"update","data":[{"symbol":"ETH/USDT","bids":[{"price":3799.48,"qty":0.00000000},{"price":3798.22,"qty":0.00526817}],"asks":[],"checksum":1379028069,"timestamp":"2024-06-01T17:52:15.456802Z"}]}
{"channel":"book","type":"update","data":[{"symbol":"ETH/USDT","bids":[{"price":3799.50,"qty":0.73120000}],"asks":[],"checksum":1478380584,"timestamp":"2024-06-01T17:52:15.457016Z"}]}
{"channel":"book","type":"update","data":[{"symbol":"ETH/USDT","bids":[{"price":3799.50,"qty":1.46240000}],"asks":[],"checksum":2088171235,"timestamp":"2024-06-01T17:52:15.463644Z"}]}
{"channel":"book","type":"update","data":[{"symbol":"ETH/USDT","bids":[{"price":3799.53,"qty":0.06693358}],"asks":[],"checksum":3098444627,"timestamp":"2024-06-01T17:52:15.466270Z"}]}
{"channel":"book","type":"update","data":[{"symbol":"ETH/USDT","bids":[{"price":3799.50,"qty":0.73120000}],"asks":[],"checksum":1402675483,"timestamp":"2024-06-01T17:52:15.471051Z"}]}
{"channel":"book","type":"update","data":[{"symbol":"ETH/USDT","bids":[{"price":3799.30,"qty":0.00000000},{"price":3798.51,"qty":0.73120000}],"asks":[],"checksum":1426763717,"timestamp":"2024-06-01T17:52:15.473871Z"}]}
{"channel":"book","type":"update","data":[{"symbol":"ETH/USDT","bids":[],"asks":[{"price":3800.44,"qty":0.72912968}],"checksum":2094462745,"timestamp":"2024-06-01T17:52:15.478473Z"}]}
{"channel":"book","type":"update","data":[{"symbol":"ETH/USDT","bids":[],"asks":[{"price":3800.27,"qty":0.98120000}],"checksum":2847706551,"timestamp":"2024-06-01T17:52:15.498662Z"}]}
{"channel":"book","type":"update","data":[{"symbol":"ETH/USDT","bids":[{"price":3798.64,"qty":0.00000000},{"price":3798.49,"qty":0.39451602}],"asks":[],"checksum":403257770,"timestamp":"2024-06-01T17:52:15.533591Z"}]}
{"channel":"book","type":"update","data":[{"symbol":"ETH/USDT","bids":[{"price":3799.10,"qty":2.34335208}],"asks":[],"checksum":3213782926,"timestamp":"2024-06-01T17:52:15.533679Z"}]}
{"channel":"book","type":"update","data":[{"symbol":"ETH/USDT","bids":[],"asks":[{"price":3800.27,"qty":0.25000000}],"checksum":1793332512,"timestamp":"2024-06-01T17:52:15.577401Z"}]}
{"channel":"book","type":"update","data":[{"symbol":"ETH/USDT","bids":[{"price":3799.53,"qty":0.79813358}],"asks":[],"checksum":4205731717,"timestamp":"2024-06-01T17:52:15.580392Z"}]}
{"channel":"book","type":"update","data":[{"symbol":"ETH/USDT","bids":[{"price":3798.63,"qty":0.19054309}],"asks":[],"checksum":3607939629,"timestamp":"2024-06-01T17:52:15.583205Z"}]}
{"channel":"book","type":"update","data":[{"symbol":"ETH/USDT","bids":[{"price":3798.62,"qty":0.00000000},{"price":3798.49,"qty":0.39451602}],"asks":[],"checksum":446578549,"timestamp":"2024-06-01T17:52:15.583637Z"}]}
{"channel":"book","type":"update","data":[{"symbol":"ETH/USDT","bids":[{"price":3799.59,"qty":0.73120000}],"asks":[],"checksum":1935449637,"timestamp":"2024-06-01T17:52:15.584386Z"}]}
{"channel":"book","type":"update","data":[{"symbol":"ETH/USDT","bids":[{"price":3799.53,"qty":0.06693358}],"asks":[],"checksum":4189244030,"timestamp":"2024-06-01T17:52:15.588471Z"}]}
{"channel":"book","type":"update","data":[{"symbol":"ETH/USDT","bids":[{"price":3799.59,"qty":0.00000000},{"price":3798.49,"qty":0.39451602}],"asks":[],"checksum":4022930298,"timestamp":"2024-06-01T17:52:15.789070Z"}]}
{"channel":"book","type":"update","data":[{"symbol":"ETH/USDT","bids":[],"asks":[{"price":3800.27,"qty":0.98120000}],"checksum":3857858904,"timestamp":"2024-06-01T17:52:15.792105Z"}]}
{"channel":"book","type":"update","data":[{"symbol":"ETH/USDT","bids":[],"asks":[{"price":3800.66,"qty":0.00000000},{"price":3801.01,"qty":5.00000000}],"checksum":3895611505,"timestamp":"2024-06-01T17:52:16.162546Z"}]}
{"channel":"book","type":"update","data":[{"symbol":"ETH/USDT","bids":[],"asks":[{"price":3800.71,"qty":0.32379274}],"checksum":3494855612,"timestamp":"2024-06-01T17:52:16.165068Z"}]}
{"channel":"book","type":"update","data":[{"symbol":"ETH/USDT","bids":[],"asks":[{"price":3800.27,"qty":0.25000000}],"checksum":3665037726,"timestamp":"2024-06-01T17:52:16.412594Z"}]}
{"channel":"book","type":"update","data":[{"symbol":"ETH/USDT","bids":[],"asks":[{"price":3799.99,"qty":0.00000000},{"price":3801.01,"qty":5.00000000}],"checksum":527152614,"timestamp":"2024-06-01T17:52:16.501137Z"}]}
{"channel":"book","type":"update","data":[{"symbol":"ETH/USDT","bids":[{"price":3799.53,"qty":0.79813358}],"asks":[],"checksum":3822535332,"timestamp":"2024-06-01T17:52:16.545010Z"}]}
{"channel":"book","type":"update","data":[{"symbol":"ETH/USDT","bids":[{"price":3799.59,"qty":0.73120000}],"asks":[],"checksum":2316690420,"timestamp":"2024-06-01T17:52:16.548883Z"}]}
{"channel":"book","type":"update","data":[{"symbol":"ETH/USDT","bids":[{"price":3799.53,"qty":0.06693358}],"asks":[],"checksum":152073442,"timestamp":"2024-06-01T17:52:16.552075Z"}]}
{"channel":"book","type":"update","data":[{"symbol":"ETH/USDT","bids":[],"asks":[{"price":3800.51,"qty":2.15500000}],"checksum":762291576,"timestamp":"2024-06-01T17:52:16.599739Z"}]}
{"channel":"book","type":"update","data":[{"symbol":"ETH/USDT","bids":[],"asks":[{"price":3800.05,"qty":0.00000000},{"price":3801.01,"qty":5.00000000}],"checksum":1780223069,"timestamp":"2024-06-01T17:52:16.676193Z"}]}
{"channel":"book","type":"update","data":[{"symbol":"ETH/USDT","bids":[],"asks":[{"price":3800.42,"qty":0.34000000}],"checksum":4145350831,"timestamp":"2024-06-01T17:52:16.678891Z"}]}
{"channel":"book","type":"update","data":[{"symbol":"ETH/USDT","bids":[{"price":3799.59,"qty":0.00000000},{"price":3798.49,"qty":0.39451602}],"asks":[],"checksum":3782134187,"timestamp":"2024-06-01T17:52:16.679827Z"}]}
{"channel":"book","type":"update","data":[{"symbol":"ETH/USDT","bids":[],"asks":[{"price":3800.26,"qty":0.72912968}],"checksum":2848364028,"timestamp":"2024-06-01T17:52:16.680488Z"}]}
{"channel":"book","type":"update","data":[{"symbol":"ETH/USDT","bids":[{"price":3798.96,"qty":2.63443899}],"asks":[],"checksum":3816923729,"timestamp":"2024-06-01T17:52:16.680511Z"}]}
{"channel":"book","type":"update","data":[{"symbol":"ETH/USDT","bids":[],"asks":[{"price":3800.40,"qty":2.63344576}],"checksum":3760487154,"timestamp":"2024-06-01T17:52:16.680583Z"}]}
{"channel":"book","type":"update","data":[{"symbol":"ETH/USDT","bids":[],"asks":[{"price":3800.42,"qty":0.00000000},{"price":3800.77,"qty":0.73120000}],"checksum":2518345771,"timestamp":"2024-06-01T17:52:16.683335Z"}]}
{"channel":"book","type":"update","data":[{"symbol":"ETH/USDT","bids":[],"asks":[{"price":3800.39,"qty":0.34000000}],"checksum":3482422767,"timestamp":"2024-06-01T17:52:16.683634Z"}]}
{"channel":"book","type":"update","data":[{"symbol":"ETH/USDT","bids":[{"price":3799.53,"qty":0.00000000},{"price":3798.49,"qty":0.39451602}],"asks":[],"checksum":2983922398,"timestamp":"2024-06-01T17:52:16.806076Z"}]}
{"channel":"book","type":"update","data":[{"symbol":"ETH/USDT","bids":[],"asks":[{"price":3800.44,"qty":0.00000000},{"price":3800.77,"qty":0.73120000}],"checksum":2923068717,"timestamp":"2024-06-01T17:52:16.810412Z"}]}
{"channel":"book","type":"update","data":[{"symbol":"ETH/USDT","bids":[],"asks":[{"price":3800.27,"qty":0.98120000}],"checksum":1309429362,"timestamp":"2024-06-01T17:52:16.814776Z"}]}
{"channel":"book","type":"update","data":[{"symbol":"ETH/USDT","bids":[{"price":3799.33,"qty":0.06693358}],"asks":[],"checksum":2240523631,"timestamp":"2024-06-01T17:52:16.910522Z"}]}
{"channel":"book","type":"update","data":[{"symbol":"ETH/USDT","bids":[{"price":3798.66,"qty":0.00517990}],"asks":[],"checksum":1917155164,"timestamp":"2024-06-01T17:52:16.985904Z"}]}
{"channel":"book","type":"update","data":[{"symbol":"ETH/USDT","bids":[],"asks":[{"price":3800.65,"qty":0.00000000},{"price":3800.96,"qty":2.63306005}],"checksum":3667802267,"timestamp":"2024-06-01T17:52:17.027045Z"}]}
{"channel":"book","type":"update","data":[{"symbol":"ETH/USDT","bids":[],"asks":[{"price":3800.72,"qty":0.00000000},{"price":3801.01,"qty":5.00000000}],"checksum":1632144472,"timestamp":"2024-06-01T17:52:17.027080Z"}]}
{"channel":"book","type":"update","data":[{"symbol":"ETH/USDT","bids":[],"asks":[{"price":3800.41,"qty":1.04690564}],"checksum":356498644,"timestamp":"2024-06-01T17:52:17.032588Z"}]}
{"channel":"book","type":"update","data":[{"symbol":"ETH/USDT","bids":[],"asks":[{"price":3800.95,"qty":47.86255369}],"checksum":1143490453,"timestamp":"2024-06-01T17:52:17.032722Z"}]}
{"channel":"book","type":"update","data":[{"symbol":"ETH/USDT","bids":[{"price":3799.50,"qty":0.00000000},{"price":3798.51,"qty":0.73120000}],"asks":[],"checksum":1173539838,"timestamp":"2024-06-01T17:52:17.653110Z"}]}
{"channel":"book","type":"update","data":[{"symbol":"ETH/USDT","bids":[],"asks":[{"price":3800.27,"qty":0.25000000}],"checksum":1765689992,"timestamp":"2024-06-01T17:52:17.656553Z"}]}
{"channel":"book","type":"update","data":[{"symbol":"ETH/USDT","bids":[{"price":3799.47,"qty":0.73120000}],"asks":[],"checksum":1691141775,"timestamp":"2024-06-01T17:52:17.656762Z"}]}
{"channel":"book","type":"update","data":[{"symbol":"ETH/USDT","bids":[{"price":3799.34,"qty":0.25000000}],"asks":[],"checksum":3218298316,"timestamp":"2024-06-01T17:52:17.659074Z"}]}
{"channel":"book","type":"update","data":[{"symbol":"ETH/USDT","bids":[],"asks":[{"price":3800.27,"qty":0.98120000}],"checksum":2468336826,"timestamp":"2024-06-01T17:52:17.662756Z"}]}
{"channel":"book","type":"update","data":[{"symbol":"ETH/USDT","bids":[{"price":3799.47,"qty":0.00000000},{"price":3798.63,"qty":0.19054309}],"asks":[],"checksum":2837819638,"timestamp":"2024-06-01T17:52:18.007242Z"}]}
{"channel":"book","type":"update","data":[{"symbol":"ETH/USDT","bids":[{"price":3798.66,"qty":0.00000000},{"price":3798.51,"qty":0.73120000}],"asks":[],"checksum":3563287935,"timestamp":"2024-06-01T17:52:18.011136Z"}]}
{"channel":"book","type":"update","data":[{"symbol":"ETH/USDT","bids":[{"price":3799.42,"qty":0.73120000}],"asks":[],"checksum":297140839,"timestamp":"2024-06-01T17:52:18.011288Z"}]}
{"channel":"book","type":"update","data":[{"symbol":"ETH/USDT","bids":[{"price":3799.00,"qty":0.00000000},{"price":3798.51,"qty":0.73120000}],"asks":[],"checksum":2265707937,"timestamp":"2024-06-01T17:52:18.012274Z"}]}
{"channel":"book","type":"update","data":[{"symbol":"ETH/USDT","bids":[{"price":3799.42,"qty":0.00000000},{"price":3798.49,"qty":0.59158572}],"asks":[],"checksum":809126630,"timestamp":"2024-06-01T17:52:18.248049Z"}]}
{"channel":"book","type":"update","data":[{"symbol":"ETH/USDT","bids":[{"price":3799.10,"qty":1.61215208}],"asks":[],"checksum":4035148852,"timestamp":"2024-06-01T17:52:18.252283Z"}]}
{"channel":"book","type":"update","data":[{"symbol":"ETH/USDT","bids":[],"asks":[{"price":3799.88,"qty":0.73120000}],"checksum":1694176329,"timestamp":"2024-06-01T17:52:18.254426Z"}]}
{"channel":"book","type":"update","data":[{"symbol":"ETH/USDT","bids":[],"asks":[{"price":3799.89,"qty":0.73541065}],"checksum":3571405479,"timestamp":"2024-06-01T17:52:18.255883Z"}]}
{"channel":"book","type":"update","data":[{"symbol":"ETH/USDT","bids":[{"price":3798.96,"qty":3.36563899}],"asks":[],"checksum":3485887377,"timestamp":"2024-06-01T17:52:18.255992Z"}]}
{"channel":"book","type":"update","data":[{"symbol":"ETH/USDT","bids":[],"asks":[{"price":3799.88,"qty":0.00000000},{"price":3800.95,"qty":47.86255369}],"checksum":889003759,"timestamp":"2024-06-01T17:52:18.258443Z"}]}
{"channel":"book","type":"update","data":[{"symbol":"ETH/USDT","bids":[],"asks":[{"price":3799.89,"qty":0.00421065}],"checksum":3952755970,"timestamp":"2024-06-01T17:52:18.259188Z"}]}
{"channel":"book","type":"update","data":[{"symbol":"ETH/USDT","bids":[{"price":3799.33,"qty":0.00000000},{"price":3798.22,"qty":0.24176885}],"asks":[],"checksum":2726278319,"timestamp":"2024-06-01T17:52:18.304321Z"}]}
{"channel":"book","type":"update","data":[{"symbol":"ETH/USDT","bids":[{"price":3799.34,"qty":0.00000000},{"price":3798.21,"qty":2.15500000}],"asks":[],"checksum":1313716146,"timestamp":"2024-06-01T17:52:18.309636Z"}]}
{"channel":"book","type":"update","data":[{"symbol":"ETH/USDT","bids":[{"price":3799.12,"qty":0.25000000}],"asks":[],"checksum":1703874915,"timestamp":"2024-06-01T17:52:18.309706Z"}]}
{"channel":"book","type":"update","data":[{"symbol":"ETH/USDT","bids":[{"price":3799.21,"qty":0.73120000}],"asks":[],"checksum":241173913,"timestamp":"2024-06-01T17:52:18.313638Z"}]}
{"channel":"book","type":"update","data":[{"symbol":"ETH/USDT","bids":[{"price":3799.21,"qty":0.00000000},{"price":3798.22,"qty":0.24176885}],"asks":[],"checksum":1703874915,"timestamp":"2024-06-01T17:52:18.320404Z"}]}
{"channel":"book","type":"update","data":[{"symbol":"ETH/USDT","bids":[{"price":3799.16,"qty":0.73120000}],"asks":[],"checksum":2712180377,"timestamp":"2024-06-01T17:52:18.323806Z"}]}
{"channel":"book","type":"update","data":[{"symbol":"ETH/USDT","bids":[{"price":3799.11,"qty":0.00000000},{"price":3798.22,"qty":0.24176885}],"asks":[],"checksum":631186339,"timestamp":"2024-06-01T17:52:18.326608Z"}]}
{"channel":"book","type":"update","data":[{"symbol":"ETH/USDT","bids":[{"price":3799.20,"qty":0.34000000}],"asks":[],"checksum":120559350,"timestamp":"2024-06-01T17:52:18.326756Z"}]}
{"channel":"book","type":"update","data":[{"symbol":"ETH/USDT","bids":[{"price":3799.12,"qty":0.54000000}],"asks":[],"checksum":1893272316,"timestamp":"2024-06-01T17:52:18.337107Z"}]}
{"channel":"book","type":"update","data":[{"symbol":"ETH/USDT","bids":[],"asks":[{"price":3799.89,"qty":0.73541065}],"checksum":2931684194,"timestamp":"2024-06-01T17:52:18.337496Z"}]}
{"channel":"book","type":"update","data":[{"symbol":"ETH/USDT","bids":[{"price":3799.21,"qty":0.25000000}],"asks":[],"checksum":3443766288,"timestamp":"2024-06-01T17:52:18.342030Z"}]}
{"channel":"book","type":"update","data":[{"symbol":"ETH/USDT","bids":[],"asks":[{"price":3799.89,"qty":0.00421065}],"checksum":321342862,"timestamp":"2024-06-01T17:52:18.346182Z"}]}
{"channel":"book","type":"update","data":[{"symbol":"ETH/USDT","bids":[],"asks":[{"price":3799.89,"qty":0.73541065}],"checksum":3443766288,"timestamp":"2024-06-01T17:52:18.349981Z"}]}
{"channel":"book","type":"update","data":[{"symbol":"ETH/USDT","bids":[{"price":3799.22,"qty":0.17000000}],"asks":[],"checksum":257274069,"timestamp":"2024-06-01T17:52:18.350055Z"}]}
{"channel":"book","type":"update","data":[{"symbol":"ETH/USDT","bids":[],"asks":[{"price":3799.88,"qty":0.72912968}],"checksum":3721629883,"timestamp":"2024-06-01T17:52:18.352185Z"}]}
{"channel":"book","type":"update","data":[{"symbol":"ETH/USDT","bids":[],"asks":[{"price":3799.89,"qty":0.00421065}],"checksum":184806311,"timestamp":"2024-06-01T17:52:18.353355Z"}]}
{"channel":"book","type":"update","data":[{"symbol":"ETH/USDT","bids":[{"price":3798.66,"qty":0.00527030}],"asks":[],"checksum":3105235584,"timestamp":"2024-06-01T17:52:18.357937Z"}]}
{"channel":"book","type":"update","data":[{"symbol":"ETH/USDT","bids":[],"asks":[{"price":3799.88,"qty":1.46032968}],"checksum":4031090604,"timestamp":"2024-06-01T17:52:18.368674Z"}]}
{"channel":"book","type":"update","data":[{"symbol":"ETH/USDT","bids":[{"price":3799.12,"qty":0.25000000}],"asks":[],"checksum":4014616726,"timestamp":"2024-06-01T17:52:18.373108Z"}]}
{"channel":"book","type":"update","data":[{"symbol":"ETH/USDT","bids":[{"price":3799.23,"qty":0.25000000}],"asks":[],"checksum":2337303344,"timestamp":"2024-06-01T17:52:18.373863Z"}]}
{"channel":"book","type":"update","data":[{"symbol":"ETH/USDT","bids":[{"price":3799.21,"qty":0.00000000},{"price":3798.65,"qty":5.84627249}],"asks":[],"checksum":1230176201,"timestamp":"2024-06-01T17:52:18.373972Z"}]}
{"channel":"book","type":"update","data":[{"symbol":"ETH/USDT","bids":[],"asks":[{"price":3799.88,"qty":0.72912968}],"checksum":86757,"timestamp":"2024-06-01T17:52:18.377619Z"}]}
{"channel":"book","type":"update","data":[{"symbol":"ETH/USDT","bids":[],"asks":[{"price":3800.39,"qty":0.00000000},{"price":3800.95,"qty":47.86255369}],"checksum":3291493362,"timestamp":"2024-06-01T17:52:18.380471Z"}]}
{"channel":"book","type":"update","data":[{"symbol":"ETH/USDT","bids":[],"asks":[{"price":3800.26,"qty":1.06912968}],"checksum":3504120447,"timestamp":"2024-06-01T17:52:18.380494Z"}]}
{"channel":"book","type":"update","data":[{"symbol":"ETH/USDT","bids":[],"asks":[{"price":3799.88,"qty":0.00000000},{"price":3800.96,"qty":2.63306005}],"checksum":1665866450,"timestamp":"2024-06-01T17:52:18.381941Z"}]}
{"channel":"book","type":"update","data":[{"symbol":"ETH/USDT","bids":[{"price":3798.91,"qty":0.06693358}],"asks":[],"checksum":3131457998,"timestamp":"2024-06-01T17:52:18.408242Z"}]}
{"channel":"book","type":"update","data":[{"symbol":"ETH/USDT","bids":[],"asks":[{"price":3799.89,"qty":0.73541065}],"checksum":3172101986,"timestamp":"2024-06-01T17:52:18.411656Z"}]}
{"channel":"book","type":"update","data":[{"symbol":"ETH/USDT","bids":[{"price":3799.22,"qty":0.00000000},{"price":3798.65,"qty":5.84627249}],"asks":[],"checksum":3036742133,"timestamp":"2024-06-01T17:52:18.412618Z"}]}
{"channel":"book","type":"update","data":[{"symbol":"ETH/USDT","bids":[],"asks":[{"price":3799.88,"qty":0.72912968}],"checksum":1299489532,"timestamp":"2024-06-01T17:52:18.416050Z"}]}
{"channel":"book","type":"update","data":[{"symbol":"ETH/USDT","bids":[{"price":3799.12,"qty":0.00000000},{"price":3798.63,"qty":0.19054309}],"asks":[],"checksum":3465698709,"timestamp":"2024-06-01T17:52:18.416277Z"}]}
{"channel":"book","type":"update","data":[{"symbol":"ETH/USDT","bids":[{"price":3798.65,"qty":0.84627249}],"asks":[],"checksum":3124203394,"timestamp":"2024-06-01T17:52:18.416662Z"}]}
{"channel":"book","type":"update","data":[{"symbol":"ETH/USDT","bids":[],"asks":[{"price":3799.89,"qty":0.00421065}],"checksum":3169811234,"timestamp":"2024-06-01T17:52:18.420066Z"}]}
{"channel":"book","type":"update","data":[{"symbol":"ETH/USDT","bids":[],"asks":[{"price":3800.71,"qty":0.00000000},{"price":3800.96,"qty":2.63306005}],"checksum":1785427483,"timestamp":"2024-06-01T17:52:18.498572Z"}]}
{"channel":"book","type":"update","data":[{"symbol":"ETH/USDT","bids":[],"asks":[{"price":3800.94,"qty":0.51555815}],"checksum":637427891,"timestamp":"2024-06-01T17:52:18.500885Z"}]}
{"channel":"book","type":"update","data":[{"symbol":"ETH/USDT","bids":[{"price":3798.66,"qty":0.00000000},{"price":3798.51,"qty":0.73120000}],"asks":[],"checksum":1344993498,"timestamp":"2024-06-01T17:52:18.567575Z"}]}
{"channel":"book","type":"update","data":[{"symbol":"ETH/USDT","bids":[],"asks":[{"price":3799.88,"qty":0.00000000},{"price":3800.96,"qty":2.63306005}],"checksum":554389325,"timestamp":"2024-06-01T17:52:18.587493Z"}]}
{"channel":"book","type":"update","data":[{"symbol":"ETH/USDT","bids":[{"price":3799.23,"qty":0.98120000}],"asks":[],"checksum":3740368624,"timestamp":"2024-06-01T17:52:18.620444Z"}]}
{"channel":"book","type":"update","data":[{"symbol":"ETH/USDT","bids":[{"price":3799.24,"qty":0.73120000}],"asks":[],"checksum":764548975,"timestamp":"2024-06-01T17:52:18.624387Z"}]}
{"channel":"book","type":"update","data":[{"symbol":"ETH/USDT","bids":[{"price":3799.16,"qty":0.00000000},{"price":3798.51,"qty":0.73120000}],"asks":[],"checksum":1526368219,"timestamp":"2024-06-01T17:52:18.625822Z"}]}
{"channel":"book","type":"update","data":[{"symbol":"ETH/USDT","bids":[{"price":3798.63,"qty":5.19054309}],"asks":[],"checksum":873739456,"timestamp":"2024-06-01T17:52:18.707590Z"}]}
{"channel":"book","type":"update","data":[{"symbol":"ETH/USDT","bids":[{"price":3798.64,"qty":0.00502641}],"asks":[],"checksum":3805521562,"timestamp":"2024-06-01T17:52:18.898256Z"}]}
{"channel":"book","type":"update","data":[{"symbol":"ETH/USDT","bids":[{"price":3799.25,"qty":0.25000000}],"asks":[],"checksum":4177195979,"timestamp":"2024-06-01T17:52:19.088381Z"}]}
{"channel":"book","type":"update","data":[{"symbol":"ETH/USDT","bids":[{"price":3799.28,"qty":0.73120000}],"asks":[],"checksum":2806462674,"timestamp":"2024-06-01T17:52:19.092254Z"}]}
{"channel":"book","type":"update","data":[{"symbol":"ETH/USDT","bids":[{"price":3799.23,"qty":0.25000000}],"asks":[],"checksum":4186305949,"timestamp":"2024-06-01T17:52:19.092548Z"}]}
{"channel":"book","type":"update","data":[{"symbol":"ETH/USDT","bids":[{"price":3799.23,"qty":0.00000000},{"price":3798.64,"qty":0.00502641}],"asks":[],"checksum":2332760955,"timestamp":"2024-06-01T17:52:19.094070Z"}]}
{"channel":"book","type":"update","data":[{"symbol":"ETH/USDT","bids":[{"price":3799.20,"qty":0.00000000},{"price":3798.63,"qty":5.19054309}],"asks":[],"checksum":3580067012,"timestamp":"2024-06-01T17:52:19.094767Z"}]}
{"channel":"book","type":"update","data":[{"symbol":"ETH/USDT","bids":[{"price":3799.24,"qty":1.07120000}],"asks":[],"checksum":366864326,"timestamp":"2024-06-01T17:52:19.095052Z"}]}
{"channel":"book","type":"update","data":[{"symbol":"ETH/USDT","bids":[{"price":3798.66,"qty":2.15500000}],"asks":[],"checksum":3767076675,"timestamp":"2024-06-01T17:52:19.207537Z"}]}
{"channel":"book","type":"update","data":[{"symbol":"ETH/USDT","bids":[{"price":3799.28,"qty":0.00000000},{"price":3798.63,"qty":5.19054309}],"asks":[],"checksum":3139189674,"timestamp":"2024-06-01T17:52:19.218993Z"}]}
{"channel":"book","type":"update","data":[{"symbol":"ETH/USDT","bids":[{"price":3799.25,"qty":0.98120000}],"asks":[],"checksum":238227114,"timestamp":"2024-06-01T17:52:19.249496Z"}]}
{"channel":"book","type":"update","data":[{"symbol":"ETH/USDT","bids":[{"price":3799.24,"qty":0.34000000}],"asks":[],"checksum":3889934065,"timestamp":"2024-06-01T17:52:19.420642Z"}]}
{"channel":"book","type":"update","data":[{"symbol":"ETH/USDT","bids":[{"price":3799.26,"qty":0.73120000}],"asks":[],"checksum":264733967,"timestamp":"2024-06-01T17:52:19.420724Z"}]}
{"channel":"book","type":"update","data":[{"symbol":"ETH/USDT","bids":[],"asks":[{"price":3800.95,"qty":0.00000000},{"price":3801.01,"qty":5.00000000}],"checksum":2248067005,"timestamp":"2024-06-01T17:52:19.428268Z"}]}
{"channel":"book","type":"update","data":[{"symbol":"ETH/USDT","bids":[],"asks":[{"price":3800.41,"qty":0.00000000},{"price":3801.02,"qty":0.84627249}],"checksum":1355028828,"timestamp":"2024-06-01T17:52:19.428276Z"}]}
{"channel":"book","type":"update","data":[{"symbol":"ETH/USDT","bids":[],"asks":[{"price":3800.25,"qty":2.60745410}],"checksum":299652978,"timestamp":"2024-06-01T17:52:19.432857Z"}]}
{"channel":"book","type":"update","data":[{"symbol":"ETH/USDT","bids":[],"asks":[{"price":3800.93,"qty":48.90292711}],"checksum":4102896694,"timestamp":"2024-06-01T17:52:19.433052Z"}]}
{"channel":"book","type":"update","data":[{"symbol":"ETH/USDT","bids":[{"price":3799.27,"qty":0.25000000}],"asks":[],"checksum":3816017732,"timestamp":"2024-06-01T17:52:19.586440Z"}]}
{"channel":"book","type":"update","data":[{"symbol":"ETH/USDT","bids":[{"price":3799.25,"qty":0.25000000}],"asks":[],"checksum":2697041673,"timestamp":"2024-06-01T17:52:19.590000Z"}]}
{"channel":"book","type":"update","data":[{"symbol":"ETH/USDT","bids":[],"asks":[{"price":3800.24,"qty":0.72912968}],"checksum":1754316961,"timestamp":"2024-06-01T17:52:19.590357Z"}]}
{"channel":"book","type":"update","data":[{"symbol":"ETH/USDT","bids":[{"price":3799.28,"qty":0.73120000}],"asks":[],"checksum":3144651177,"timestamp":"2024-06-01T17:52:19.590818Z"}]}
{"channel":"book","type":"update","data":[{"symbol":"ETH/USDT","bids":[{"price":3799.25,"qty":0.00000000},{"price":3798.65,"qty":0.84627249}],"asks":[],"checksum":430529989,"timestamp":"2024-06-01T17:52:19.591019Z"}]}
