{"channel":"book","type":"snapshot","data":[{"symbol":"EUR/GBP","bids":[{"price":0.85048,"qty":137.53730060},{"price":0.85047,"qty":922.45852290},{"price":0.85043,"qty":250.80000000},{"price":0.85042,"qty":922.52607352},{"price":0.85033,"qty":1383.93100450},{"price":0.85029,"qty":542.30355824},{"price":0.85025,"qty":2306.74101583},{"price":0.85003,"qty":493.66392783},{"price":0.85002,"qty":7239.99817929},{"price":0.85000,"qty":7173.90545623}],"asks":[{"price":0.85056,"qty":863.60911389},{"price":0.85058,"qty":922.36299243},{"price":0.85072,"qty":16.57051619},{"price":0.85073,"qty":1057.75175090},{"price":0.85074,"qty":1383.26529860},{"price":0.85085,"qty":225.72210000},{"price":0.85086,"qty":9989.59951980},{"price":0.85087,"qty":2305.11933298},{"price":0.85097,"qty":625.66181433},{"price":0.85098,"qty":826.02210000}],"checksum":782141213}]}
{"channel":"book","type":"update","data":[{"symbol":"EUR/GBP","bids":[{"price":0.85002,"qty":0.00000000},{"price":0.84999,"qty":1833.00000000}],"asks":[],"checksum":845579006,"timestamp":"2024-06-01T17:51:37.488227Z"}]}
{"channel":"book","type":"update","data":[{"symbol":"EUR/GBP","bids":[{"price":0.85000,"qty":0.00000000},{"price":0.84995,"qty":4615.04081268}],"asks":[],"checksum":1318353696,"timestamp":"2024-06-01T17:51:37.488256Z"}]}
{"channel":"book","type":"update","data":[{"symbol":"EUR/GBP","bids":[{"price":0.85000,"qty":14434.98269170}],"asks":[],"checksum":2993983381,"timestamp":"2024-06-01T17:51:37.488785Z"}]}
{"channel":"book","type":"update","data":[{"symbol":"EUR/GBP","bids":[{"price":0.85000,"qty":0.00000000},{"price":0.84995,"qty":4615.04081268}],"asks":[],"checksum":1318353696,"timestamp":"2024-06-01T17:51:42.470230Z"}]}
{"channel":"book","type":"update","data":[{"symbol":"EUR/GBP","bids":[{"price":0.85000,"qty":16233.72881981}],"asks":[],"checksum":3617281201,"timestamp":"2024-06-01T17:51:42.472429Z"}]}
{"channel":"book","type":"update","data":[{"symbol":"EUR/GBP","bids":[{"price":0.85003,"qty":0.00000000},{"price":0.84995,"qty":4615.04081268}],"asks":[],"checksum":2891163912,"timestamp":"2024-06-01T17:51:46.178493Z"}]}
{"channel":"book","type":"update","data":[{"symbol":"EUR/GBP","bids":[{"price":0.85026,"qty":493.53044844}],"asks":[],"checksum":1327469062,"timestamp":"2024-06-01T17:51:46.178515Z"}]}
{"channel":"book","type":"update","data":[{"symbol":"EUR/GBP","bids":[{"price":0.85000,"qty":0.00000000},{"price":0.84995,"qty":4615.04081268}],"asks":[],"checksum":410153058,"timestamp":"2024-06-01T17:51:49.988427Z"}]}
{"channel":"book","type":"update","data":[{"symbol":"EUR/GBP","bids":[{"price":0.85000,"qty":18032.47494791}],"asks":[],"checksum":502160596,"timestamp":"2024-06-01T17:51:49.989609Z"}]}
{"channel":"book","type":"update","data":[{"symbol":"EUR/GBP","bids":[],"asks":[{"price":0.85056,"qty":0.00000000},{"price":0.85105,"qty":36322.36004162},{"price":0.85058,"qty":0.00000000},{"price":0.85106,"qty":13683.10000000},{"price":0.85072,"qty":0.00000000},{"price":0.85113,"qty":4610.06070893},{"price":0.85073,"qty":812.42086550}],"checksum":1694121508,"timestamp":"2024-06-01T17:51:51.049305Z"}]}
{"channel":"book","type":"update","data":[{"symbol":"EUR/GBP","bids":[],"asks":[{"price":0.85074,"qty":0.00000000},{"price":0.85115,"qty":30832.00000000}],"checksum":3001960712,"timestamp":"2024-06-01T17:51:51.055721Z"}]}
{"channel":"book","type":"update","data":[{"symbol":"EUR/GBP","bids":[],"asks":[{"price":0.85056,"qty":922.38769498}],"checksum":479606212,"timestamp":"2024-06-01T17:51:51.062245Z"}]}
{"channel":"book","type":"update","data":[{"symbol":"EUR/GBP","bids":[],"asks":[{"price":0.85072,"qty":922.21381624}],"checksum":2542218180,"timestamp":"2024-06-01T17:51:51.062313Z"}]}
{"channel":"book","type":"update","data":[{"symbol":"EUR/GBP","bids":[],"asks":[{"price":0.85072,"qty":2305.53454060}],"checksum":2836774815,"timestamp":"2024-06-01T17:51:51.062344Z"}]}
{"channel":"book","type":"update","data":[{"symbol":"EUR/GBP","bids":[{"price":0.85043,"qty":0.00000000},{"price":0.84995,"qty":4615.04081268},{"price":0.85049,"qty":250.80000000}],"asks":[],"checksum":2235269467,"timestamp":"2024-06-01T17:51:51.065043Z"}]}
{"channel":"book","type":"update","data":[{"symbol":"EUR/GBP","bids":[],"asks":[{"price":0.85072,"qty":922.21381624}],"checksum":3148420352,"timestamp":"2024-06-01T17:51:51.068016Z"}]}
{"channel":"book","type":"update","data":[{"symbol":"EUR/GBP","bids":[{"price":0.85050,"qty":137.53730060}],"asks":[],"checksum":368858660,"timestamp":"2024-06-01T17:51:51.233409Z"}]}
{"channel":"book","type":"update","data":[{"symbol":"EUR/GBP","bids":[{"price":0.85048,"qty":0.00000000},{"price":0.84999,"qty":1833.00000000}],"asks":[],"checksum":3973158514,"timestamp":"2024-06-01T17:51:51.427177Z"}]}
{"channel":"book","type":"update","data":[{"symbol":"EUR/GBP","bids":[{"price":0.85049,"qty":0.00000000},{"price":0.84995,"qty":4615.04081268},{"price":0.85043,"qty":250.80000000}],"asks":[],"checksum":2145940359,"timestamp":"2024-06-01T17:51:51.463026Z"}]}
{"channel":"book","type":"update","data":[{"symbol":"EUR/GBP","bids":[{"price":0.85026,"qty":0.00000000},{"price":0.84995,"qty":4615.04081268}],"asks":[],"checksum":531635109,"timestamp":"2024-06-01T17:51:52.036996Z"}]}
{"channel":"book","type":"update","data":[{"symbol":"EUR/GBP","bids":[{"price":0.85001,"qty":493.67548617}],"asks":[],"checksum":3786686907,"timestamp":"2024-06-01T17:51:52.037261Z"}]}
{"channel":"book","type":"update","data":[{"symbol":"EUR/GBP","bids":[{"price":0.85000,"qty":0.00000000},{"price":0.84995,"qty":4615.04081268}],"asks":[],"checksum":4226245433,"timestamp":"2024-06-01T17:51:52.438790Z"}]}
{"channel":"book","type":"update","data":[{"symbol":"EUR/GBP","bids":[{"price":0.85002,"qty":7239.99817929}],"asks":[],"checksum":3858302878,"timestamp":"2024-06-01T17:51:52.439975Z"}]}
{"channel":"book","type":"update","data":[{"symbol":"EUR/GBP","bids":[{"price":0.85000,"qty":10760.85818434}],"asks":[],"checksum":2409624521,"timestamp":"2024-06-01T17:51:52.440215Z"}]}
{"channel":"book","type":"update","data":[{"symbol":"EUR/GBP","bids":[{"price":0.85003,"qty":493.66387068}],"asks":[],"checksum":1241303985,"timestamp":"2024-06-01T17:51:52.443545Z"}]}
{"channel":"book","type":"update","data":[{"symbol":"EUR/GBP","bids":[{"price":0.85001,"qty":0.00000000},{"price":0.85000,"qty":10760.85818434}],"asks":[],"checksum":1547897694,"timestamp":"2024-06-01T17:51:52.443566Z"}]}
{"channel":"book","type":"update","data":[{"symbol":"EUR/GBP","bids":[],"asks":[{"price":0.85061,"qty":922.34379420}],"checksum":2748097150,"timestamp":"2024-06-01T17:51:52.453526Z"}]}
{"channel":"book","type":"update","data":[{"symbol":"EUR/GBP","bids":[{"price":0.85003,"qty":0.00000000},{"price":0.84999,"qty":1833.00000000}],"asks":[],"checksum":1989076669,"timestamp":"2024-06-01T17:51:53.357525Z"}]}
{"channel":"book","type":"update","data":[{"symbol":"EUR/GBP","bids":[{"price":0.85026,"qty":493.53035054}],"asks":[],"checksum":3450087964,"timestamp":"2024-06-01T17:51:53.357537Z"}]}
{"channel":"book","type":"update","data":[{"symbol":"EUR/GBP","bids":[],"asks":[{"price":0.85073,"qty":0.00000000},{"price":0.85106,"qty":13683.10000000}],"checksum":2706791470,"timestamp":"2024-06-01T17:51:53.568764Z"}]}
{"channel":"book","type":"update","data":[{"symbol":"EUR/GBP","bids":[],"asks":[{"price":0.85084,"qty":2676.03450916}],"checksum":457898768,"timestamp":"2024-06-01T17:51:53.571302Z"}]}
{"channel":"book","type":"update","data":[{"symbol":"EUR/GBP","bids":[],"asks":[{"price":0.85085,"qty":0.00000000},{"price":0.85106,"qty":13683.10000000}],"checksum":3593682114,"timestamp":"2024-06-01T17:51:53.590384Z"}]}
{"channel":"book","type":"update","data":[{"symbol":"EUR/GBP","bids":[],"asks":[{"price":0.85083,"qty":225.72210000}],"checksum":2097865071,"timestamp":"2024-06-01T17:51:53.590638Z"}]}
{"channel":"book","type":"update","data":[{"symbol":"EUR/GBP","bids":[{"price":0.85002,"qty":0.00000000},{"price":0.84999,"qty":1833.00000000}],"asks":[],"checksum":2868243632,"timestamp":"2024-06-01T17:51:54.861615Z"}]}
{"channel":"book","type":"update","data":[{"symbol":"EUR/GBP","bids":[{"price":0.85000,"qty":0.00000000},{"price":0.84995,"qty":4615.04081268}],"asks":[],"checksum":1020119129,"timestamp":"2024-06-01T17:51:54.861629Z"}]}
{"channel":"book","type":"update","data":[{"symbol":"EUR/GBP","bids":[{"price":0.85000,"qty":16233.72881981}],"asks":[],"checksum":4264608922,"timestamp":"2024-06-01T17:51:54.862864Z"}]}
{"channel":"book","type":"update","data":[{"symbol":"EUR/GBP","bids":[],"asks":[{"price":0.85086,"qty":0.00000000},{"price":0.85113,"qty":4610.06070893}],"checksum":36781162,"timestamp":"2024-06-01T17:51:55.906776Z"}]}
{"channel":"book","type":"update","data":[{"symbol":"EUR/GBP","bids":[],"asks":[{"price":0.85105,"qty":0.00000000},{"price":0.85122,"qty":962.22788203}],"checksum":1679238203,"timestamp":"2024-06-01T17:51:55.906794Z"}]}
{"channel":"book","type":"update","data":[{"symbol":"EUR/GBP","bids":[],"asks":[{"price":0.85084,"qty":0.00000000},{"price":0.85125,"qty":4607.74676488}],"checksum":153775376,"timestamp":"2024-06-01T17:51:55.906940Z"}]}
{"channel":"book","type":"update","data":[{"symbol":"EUR/GBP","bids":[],"asks":[{"price":0.85086,"qty":8359.57784035}],"checksum":3749555297,"timestamp":"2024-06-01T17:51:55.908844Z"}]}
{"channel":"book","type":"update","data":[{"symbol":"EUR/GBP","bids":[],"asks":[{"price":0.85112,"qty":40644.32398912}],"checksum":1176598415,"timestamp":"2024-06-01T17:51:55.908874Z"}]}
{"channel":"book","type":"update","data":[{"symbol":"EUR/GBP","bids":[{"price":0.85043,"qty":0.00000000},{"price":0.84995,"qty":4615.04081268},{"price":0.85048,"qty":250.80000000}],"asks":[],"checksum":2371250535,"timestamp":"2024-06-01T17:51:55.919771Z"}]}
{"channel":"book","type":"update","data":[{"symbol":"EUR/GBP","bids":[{"price":0.85049,"qty":145.82255869}],"asks":[],"checksum":2736244774,"timestamp":"2024-06-01T17:52:01.031524Z"}]}
{"channel":"book","type":"update","data":[{"symbol":"EUR/GBP","bids":[{"price":0.85050,"qty":0.00000000},{"price":0.84999,"qty":1833.00000000}],"asks":[],"checksum":3370567942,"timestamp":"2024-06-01T17:52:01.203740Z"}]}
{"channel":"book","type":"update","data":[{"symbol":"EUR/GBP","bids":[{"price":0.85026,"qty":0.00000000},{"price":0.84995,"qty":4615.04081268}],"asks":[],"checksum":1441892135,"timestamp":"2024-06-01T17:52:04.237944Z"}]}
{"channel":"book","type":"update","data":[{"symbol":"EUR/GBP","bids":[{"price":0.85001,"qty":493.67548617}],"asks":[],"checksum":3400720550,"timestamp":"2024-06-01T17:52:04.238155Z"}]}
{"channel":"book","type":"update","data":[{"symbol":"EUR/GBP","bids":[{"price":0.85000,"qty":0.00000000},{"price":0.84995,"qty":4615.04081268}],"asks":[],"checksum":3492808752,"timestamp":"2024-06-01T17:52:04.651140Z"}]}
{"channel":"book","type":"update","data":[{"symbol":"EUR/GBP","bids":[{"price":0.85002,"qty":7239.99817929}],"asks":[],"checksum":3459148951,"timestamp":"2024-06-01T17:52:04.652925Z"}]}
{"channel":"book","type":"update","data":[{"symbol":"EUR/GBP","bids":[{"price":0.85000,"qty":10760.85818434}],"asks":[],"checksum":4134050822,"timestamp":"2024-06-01T17:52:04.653175Z"}]}
{"channel":"book","type":"update","data":[{"symbol":"EUR/GBP","bids":[{"price":0.85001,"qty":0.00000000},{"price":0.84999,"qty":1833.00000000}],"asks":[],"checksum":1186816402,"timestamp":"2024-06-01T17:52:04.666249Z"}]}
{"channel":"book","type":"update","data":[{"symbol":"EUR/GBP","bids":[{"price":0.85003,"qty":493.66387068}],"asks":[],"checksum":632579217,"timestamp":"2024-06-01T17:52:04.666348Z"}]}
{"channel":"book","type":"update","data":[{"symbol":"EUR/GBP","bids":[],"asks":[{"price":0.85112,"qty":0.00000000},{"price":0.85122,"qty":962.22788203}],"checksum":3169369983,"timestamp":"2024-06-01T17:52:05.700521Z"}]}
{"channel":"book","type":"update","data":[{"symbol":"EUR/GBP","bids":[],"asks":[{"price":0.85071,"qty":1843.75979497}],"checksum":411389205,"timestamp":"2024-06-01T17:52:05.702586Z"}]}
{"channel":"book","type":"update","data":[{"symbol":"EUR/GBP","bids":[],"asks":[{"price":0.85112,"qty":38804.18893659}],"checksum":3269586644,"timestamp":"2024-06-01T17:52:05.702694Z"}]}
{"channel":"book","type":"update","data":[{"symbol":"EUR/GBP","bids":[{"price":0.85002,"qty":0.00000000},{"price":0.84999,"qty":1833.00000000}],"asks":[],"checksum":354345739,"timestamp":"2024-06-01T17:52:07.137664Z"}]}
{"channel":"book","type":"update","data":[{"symbol":"EUR/GBP","bids":[{"price":0.85000,"qty":0.00000000},{"price":0.84995,"qty":4615.04081268}],"asks":[],"checksum":128148842,"timestamp":"2024-06-01T17:52:07.137675Z"}]}
{"channel":"book","type":"update","data":[{"symbol":"EUR/GBP","bids":[{"price":0.85004,"qty":3642.50592308}],"asks":[],"checksum":1462765441,"timestamp":"2024-06-01T17:52:07.139059Z"}]}
{"channel":"book","type":"update","data":[{"symbol":"EUR/GBP","bids":[{"price":0.85000,"qty":12578.92678062}],"asks":[],"checksum":3442641448,"timestamp":"2024-06-01T17:52:07.139127Z"}]}
{"channel":"book","type":"update","data":[{"symbol":"EUR/GBP","bids":[{"price":0.85005,"qty":493.65225574}],"asks":[],"checksum":1121489646,"timestamp":"2024-06-01T17:52:07.171004Z"}]}
{"channel":"book","type":"update","data":[{"symbol":"EUR/GBP","bids":[{"price":0.85003,"qty":0.00000000},{"price":0.85000,"qty":12578.92678062}],"asks":[],"checksum":2743574089,"timestamp":"2024-06-01T17:52:07.171029Z"}]}
{"channel":"book","type":"update","data":[{"symbol":"EUR/GBP","bids":[{"price":0.85004,"qty":0.00000000},{"price":0.84999,"qty":1833.00000000}],"asks":[],"checksum":2654988263,"timestamp":"2024-06-01T17:52:09.607487Z"}]}
{"channel":"book","type":"update","data":[{"symbol":"EUR/GBP","bids":[{"price":0.85000,"qty":0.00000000},{"price":0.84995,"qty":4615.04081268}],"asks":[],"checksum":3989816682,"timestamp":"2024-06-01T17:52:09.607610Z"}]}
{"channel":"book","type":"update","data":[{"symbol":"EUR/GBP","bids":[{"price":0.85000,"qty":16233.72881981}],"asks":[],"checksum":1093773185,"timestamp":"2024-06-01T17:52:09.608062Z"}]}
{"channel":"book","type":"update","data":[{"symbol":"EUR/GBP","bids":[{"price":0.85005,"qty":0.00000000},{"price":0.84995,"qty":4615.04081268}],"asks":[],"checksum":1403021234,"timestamp":"2024-06-01T17:52:09.611383Z"}]}
{"channel":"book","type":"update","data":[{"symbol":"EUR/GBP","bids":[{"price":0.85001,"qty":493.67548617}],"asks":[],"checksum":770140899,"timestamp":"2024-06-01T17:52:09.611443Z"}]}
{"channel":"book","type":"update","data":[{"symbol":"EUR/GBP","bids":[{"price":0.85000,"qty":0.00000000},{"price":0.84995,"qty":4615.04081268}],"asks":[],"checksum":1033325118,"timestamp":"2024-06-01T17:52:12.100391Z"}]}
{"channel":"book","type":"update","data":[{"symbol":"EUR/GBP","bids":[{"price":0.85000,"qty":8967.38182029}],"asks":[],"checksum":553081165,"timestamp":"2024-06-01T17:52:12.101692Z"}]}
{"channel":"book","type":"update","data":[{"symbol":"EUR/GBP","bids":[{"price":0.85002,"qty":7239.99817929}],"asks":[],"checksum":2451431835,"timestamp":"2024-06-01T17:52:12.101712Z"}]}
{"channel":"book","type":"update","data":[{"symbol":"EUR/GBP","bids":[{"price":0.85001,"qty":0.00000000},{"price":0.84999,"qty":1833.00000000}],"asks":[],"checksum":3985069486,"timestamp":"2024-06-01T17:52:12.121785Z"}]}
{"channel":"book","type":"update","data":[{"symbol":"EUR/GBP","bids":[{"price":0.85003,"qty":493.66387068}],"asks":[],"checksum":2551287292,"timestamp":"2024-06-01T17:52:12.121918Z"}]}
{"channel":"book","type":"update","data":[{"symbol":"EUR/GBP","bids":[],"asks":[{"price":0.85112,"qty":0.00000000},{"price":0.85113,"qty":4610.06070893}],"checksum":2617941143,"timestamp":"2024-06-01T17:52:13.177073Z"}]}
{"channel":"book","type":"update","data":[{"symbol":"EUR/GBP","bids":[],"asks":[{"price":0.85071,"qty":0.00000000},{"price":0.85122,"qty":962.22788203}],"checksum":540842993,"timestamp":"2024-06-01T17:52:13.177175Z"}]}
{"channel":"book","type":"update","data":[{"symbol":"EUR/GBP","bids":[],"asks":[{"price":0.85112,"qty":40648.84333450}],"checksum":2784753352,"timestamp":"2024-06-01T17:52:13.182431Z"}]}
{"channel":"book","type":"update","data":[{"symbol":"EUR/GBP","bids":[{"price":0.85002,"qty":0.00000000},{"price":0.84999,"qty":1833.00000000}],"asks":[],"checksum":657001773,"timestamp":"2024-06-01T17:52:14.591473Z"}]}
{"channel":"book","type":"update","data":[{"symbol":"EUR/GBP","bids":[{"price":0.85000,"qty":0.00000000},{"price":0.84995,"qty":4615.04081268}],"asks":[],"checksum":977870430,"timestamp":"2024-06-01T17:52:14.591639Z"}]}
{"channel":"book","type":"update","data":[{"symbol":"EUR/GBP","bids":[{"price":0.85004,"qty":3642.50592308}],"asks":[],"checksum":1792703669,"timestamp":"2024-06-01T17:52:14.592778Z"}]}
{"channel":"book","type":"update","data":[{"symbol":"EUR/GBP","bids":[{"price":0.85000,"qty":12578.92678062}],"asks":[],"checksum":3971716326,"timestamp":"2024-06-01T17:52:14.592804Z"}]}
{"channel":"book","type":"update","data":[{"symbol":"EUR/GBP","bids":[{"price":0.85003,"qty":0.00000000},{"price":0.84999,"qty":1833.00000000}],"asks":[],"checksum":1291335021,"timestamp":"2024-06-01T17:52:14.609193Z"}]}
{"channel":"book","type":"update","data":[{"symbol":"EUR/GBP","bids":[{"price":0.85005,"qty":493.65230849}],"asks":[],"checksum":1680787967,"timestamp":"2024-06-01T17:52:14.609268Z"}]}
{"channel":"book","type":"update","data":[{"symbol":"EUR/GBP","bids":[{"price":0.85004,"qty":0.00000000},{"price":0.84999,"qty":1833.00000000}],"asks":[],"checksum":1503047761,"timestamp":"2024-06-01T17:52:17.078477Z"}]}
{"channel":"book","type":"update","data":[{"symbol":"EUR/GBP","bids":[{"price":0.85000,"qty":0.00000000},{"price":0.84995,"qty":4615.04081268}],"asks":[],"checksum":2469447441,"timestamp":"2024-06-01T17:52:17.078569Z"}]}
{"channel":"book","type":"update","data":[{"symbol":"EUR/GBP","bids":[{"price":0.85000,"qty":16233.72881981}],"asks":[],"checksum":2258169911,"timestamp":"2024-06-01T17:52:17.079330Z"}]}
{"channel":"book","type":"update","data":[{"symbol":"EUR/GBP","bids":[{"price":0.85005,"qty":0.00000000},{"price":0.84995,"qty":4615.04081268}],"asks":[],"checksum":794624283,"timestamp":"2024-06-01T17:52:17.098106Z"}]}
{"channel":"book","type":"update","data":[{"symbol":"EUR/GBP","bids":[{"price":0.85001,"qty":493.67548617}],"asks":[],"checksum":208565293,"timestamp":"2024-06-01T17:52:17.098120Z"}]}
{"channel":"book","type":"update","data":[{"symbol":"EUR/GBP","bids":[{"price":0.85000,"qty":0.00000000},{"price":0.84995,"qty":4615.04081268}],"asks":[],"checksum":8204554,"timestamp":"2024-06-01T17:52:19.555354Z"}]}
{"channel":"book","type":"update","data":[{"symbol":"EUR/GBP","bids":[{"price":0.85002,"qty":7239.99817929}],"asks":[],"checksum":509826477,"timestamp":"2024-06-01T17:52:19.555906Z"}]}
{"channel":"book","type":"update","data":[{"symbol":"EUR/GBP","bids":[{"price":0.85000,"qty":8967.38182029}],"asks":[],"checksum":2952239791,"timestamp":"2024-06-01T17:52:19.555943Z"}]}
{"channel":"book","type":"update","data":[{"symbol":"EUR/GBP","bids":[{"price":0.85001,"qty":0.00000000},{"price":0.84999,"qty":1833.00000000}],"asks":[],"checksum":3423488864,"timestamp":"2024-06-01T17:52:19.569313Z"}]}
{"channel":"book","type":"update","data":[{"symbol":"EUR/GBP","bids":[{"price":0.85003,"qty":493.66392784}],"asks":[],"checksum":4073136226,"timestamp":"2024-06-01T17:52:19.569506Z"}]}
{"channel":"book","type":"update","data":[{"symbol":"EUR/GBP","bids":[],"asks":[{"price":0.85112,"qty":0.00000000},{"price":0.85122,"qty":962.22788203}],"checksum":1996508507,"timestamp":"2024-06-01T17:52:20.680051Z"}]}
{"channel":"book","type":"update","data":[{"symbol":"EUR/GBP","bids":[],"asks":[{"price":0.85112,"qty":39022.91457749}],"checksum":1325950634,"timestamp":"2024-06-01T17:52:20.682322Z"}]}
{"channel":"book","type":"update","data":[{"symbol":"EUR/GBP","bids":[{"price":0.85002,"qty":0.00000000},{"price":0.84999,"qty":1833.00000000}],"asks":[],"checksum":3453656399,"timestamp":"2024-06-01T17:52:22.070553Z"}]}
{"channel":"book","type":"update","data":[{"symbol":"EUR/GBP","bids":[{"price":0.85000,"qty":0.00000000},{"price":0.84995,"qty":4615.04081268}],"asks":[],"checksum":3501887036,"timestamp":"2024-06-01T17:52:22.070596Z"}]}
{"channel":"book","type":"update","data":[{"symbol":"EUR/GBP","bids":[{"price":0.85004,"qty":3642.50592308}],"asks":[],"checksum":618533015,"timestamp":"2024-06-01T17:52:22.072226Z"}]}
{"channel":"book","type":"update","data":[{"symbol":"EUR/GBP","bids":[{"price":0.85000,"qty":14375.91632071}],"asks":[],"checksum":3834996056,"timestamp":"2024-06-01T17:52:22.072274Z"}]}
{"channel":"book","type":"update","data":[{"symbol":"EUR/GBP","bids":[{"price":0.85005,"qty":493.65225574}],"asks":[],"checksum":2588281817,"timestamp":"2024-06-01T17:52:22.076071Z"}]}
{"channel":"book","type":"update","data":[{"symbol":"EUR/GBP","bids":[{"price":0.85003,"qty":0.00000000},{"price":0.85000,"qty":14375.91632071}],"asks":[],"checksum":3389829493,"timestamp":"2024-06-01T17:52:22.076099Z"}]}
{"channel":"book","type":"update","data":[{"symbol":"EUR/GBP","bids":[{"price":0.85000,"qty":0.00000000},{"price":0.84999,"qty":1833.00000000}],"asks":[],"checksum":151502058,"timestamp":"2024-06-01T17:52:24.570882Z"}]}
{"channel":"book","type":"update","data":[{"symbol":"EUR/GBP","bids":[{"price":0.85004,"qty":0.00000000},{"price":0.84995,"qty":4615.04081268}],"asks":[],"checksum":1844115606,"timestamp":"2024-06-01T17:52:24.571051Z"}]}
{"channel":"book","type":"update","data":[{"symbol":"EUR/GBP","bids":[{"price":0.85000,"qty":18032.47494791}],"asks":[],"checksum":2806772313,"timestamp":"2024-06-01T17:52:24.571525Z"}]}
{"channel":"book","type":"update","data":[{"symbol":"EUR/GBP","bids":[{"price":0.85005,"qty":0.00000000},{"price":0.84995,"qty":4615.04081268}],"asks":[],"checksum":4062360059,"timestamp":"2024-06-01T17:52:24.586393Z"}]}
{"channel":"book","type":"update","data":[{"symbol":"EUR/GBP","bids":[{"price":0.85001,"qty":493.67554775}],"asks":[],"checksum":1418591835,"timestamp":"2024-06-01T17:52:24.586574Z"}]}
{"channel":"book","type":"update","data":[{"symbol":"EUR/GBP","bids":[],"asks":[{"price":0.85112,"qty":0.00000000},{"price":0.85122,"qty":962.22788203}],"checksum":2651796730,"timestamp":"2024-06-01T17:52:25.588987Z"}]}
{"channel":"book","type":"update","data":[{"symbol":"EUR/GBP","bids":[],"asks":[{"price":0.85112,"qty":40648.84333450}],"checksum":3247405983,"timestamp":"2024-06-01T17:52:25.594388Z"}]}
{"channel":"book","type":"update","data":[{"symbol":"EUR/GBP","bids":[{"price":0.85048,"qty":0.00000000},{"price":0.84995,"qty":4615.04081268},{"price":0.85043,"qty":250.80000000}],"asks":[],"checksum":184051063,"timestamp":"2024-06-01T17:52:26.180030Z"}]}
{"channel":"book","type":"update","data":[{"symbol":"EUR/GBP","bids":[{"price":0.85048,"qty":145.82255869}],"asks":[],"checksum":506052667,"timestamp":"2024-06-01T17:52:26.359908Z"}]}
{"channel":"book","type":"update","data":[{"symbol":"EUR/GBP","bids":[{"price":0.85043,"qty":0.00000000},{"price":0.84999,"qty":1833.00000000},{"price":0.85049,"qty":396.62255869}],"asks":[],"checksum":2413248347,"timestamp":"2024-06-01T17:52:26.394105Z"}]}
{"channel":"book","type":"update","data":[{"symbol":"EUR/GBP","bids":[{"price":0.85049,"qty":250.80000000}],"asks":[],"checksum":4239673079,"timestamp":"2024-06-01T17:52:26.535552Z"}]}
{"channel":"book","type":"update","data":[{"symbol":"EUR/GBP","bids":[{"price":0.85000,"qty":0.00000000},{"price":0.84995,"qty":4615.04081268}],"asks":[],"checksum":1290816297,"timestamp":"2024-06-01T17:52:27.052560Z"}]}
{"channel":"book","type":"update","data":[{"symbol":"EUR/GBP","bids":[{"price":0.85002,"qty":7239.99817929}],"asks":[],"checksum":545773587,"timestamp":"2024-06-01T17:52:27.053429Z"}]}
{"channel":"book","type":"update","data":[{"symbol":"EUR/GBP","bids":[{"price":0.85000,"qty":10760.85818434}],"asks":[],"checksum":475230859,"timestamp":"2024-06-01T17:52:27.053647Z"}]}
{"channel":"book","type":"update","data":[{"symbol":"EUR/GBP","bids":[{"price":0.85003,"qty":493.66392784}],"asks":[],"checksum":1444241287,"timestamp":"2024-06-01T17:52:27.057752Z"}]}
{"channel":"book","type":"update","data":[{"symbol":"EUR/GBP","bids":[{"price":0.85001,"qty":0.00000000},{"price":0.85000,"qty":10760.85818434}],"asks":[],"checksum":3892820818,"timestamp":"2024-06-01T17:52:27.057786Z"}]}
{"channel":"book","type":"update","data":[{"symbol":"EUR/GBP","bids":[{"price":0.85049,"qty":0.00000000},{"price":0.84999,"qty":1833.00000000},{"price":0.85043,"qty":250.80000000}],"asks":[],"checksum":3198299793,"timestamp":"2024-06-01T17:52:27.063662Z"}]}
{"channel":"book","type":"update","data":[{"symbol":"EUR/GBP","bids":[{"price":0.85043,"qty":0.00000000},{"price":0.84999,"qty":1833.00000000},{"price":0.85049,"qty":250.80000000}],"asks":[],"checksum":3892820818,"timestamp":"2024-06-01T17:52:27.397142Z"}]}
{"channel":"book","type":"update","data":[{"symbol":"EUR/GBP","bids":[{"price":0.85002,"qty":0.00000000},{"price":0.84999,"qty":1833.00000000}],"asks":[],"checksum":1073264269,"timestamp":"2024-06-01T17:52:29.559631Z"}]}
{"channel":"book","type":"update","data":[{"symbol":"EUR/GBP","bids":[{"price":0.85000,"qty":0.00000000},{"price":0.84995,"qty":4615.04081268}],"asks":[],"checksum":2396878737,"timestamp":"2024-06-01T17:52:29.559823Z"}]}
{"channel":"book","type":"update","data":[{"symbol":"EUR/GBP","bids":[{"price":0.85004,"qty":3642.50592308}],"asks":[],"checksum":2059004218,"timestamp":"2024-06-01T17:52:29.560412Z"}]}
{"channel":"book","type":"update","data":[{"symbol":"EUR/GBP","bids":[{"price":0.85000,"qty":14375.91632071}],"asks":[],"checksum":1286397428,"timestamp":"2024-06-01T17:52:29.560440Z"}]}
{"channel":"book","type":"update","data":[{"symbol":"EUR/GBP","bids":[{"price":0.85003,"qty":0.00000000},{"price":0.84999,"qty":1833.00000000}],"asks":[],"checksum":4215032577,"timestamp":"2024-06-01T17:52:29.578944Z"}]}
{"channel":"book","type":"update","data":[{"symbol":"EUR/GBP","bids":[{"price":0.85005,"qty":493.65230849}],"asks":[],"checksum":2215985313,"timestamp":"2024-06-01T17:52:29.579160Z"}]}
{"channel":"book","type":"update","data":[{"symbol":"EUR/GBP","bids":[],"asks":[{"price":0.85112,"qty":0.00000000},{"price":0.85122,"qty":962.22788203}],"checksum":3683979204,"timestamp":"2024-06-01T17:52:30.626326Z"}]}
{"channel":"book","type":"update","data":[{"symbol":"EUR/GBP","bids":[],"asks":[{"price":0.85071,"qty":1843.75979497}],"checksum":2147024302,"timestamp":"2024-06-01T17:52:30.631482Z"}]}
{"channel":"book","type":"update","data":[{"symbol":"EUR/GBP","bids":[],"asks":[{"price":0.85112,"qty":38820.70975127}],"checksum":68343050,"timestamp":"2024-06-01T17:52:30.631730Z"}]}
{"channel":"book","type":"update","data":[{"symbol":"EUR/GBP","bids":[{"price":0.85004,"qty":0.00000000},{"price":0.84999,"qty":1833.00000000}],"asks":[],"checksum":272282793,"timestamp":"2024-06-01T17:52:31.995988Z"}]}
{"channel":"book","type":"update","data":[{"symbol":"EUR/GBP","bids":[{"price":0.85049,"qty":0.00000000},{"price":0.84995,"qty":4615.04081268},{"price":0.85043,"qty":250.80000000}],"asks":[],"checksum":1184833898,"timestamp":"2024-06-01T17:52:32.011966Z"}]}
{"channel":"book","type":"update","data":[{"symbol":"EUR/GBP","bids":[{"price":0.85005,"qty":0.00000000},{"price":0.84995,"qty":4615.04081268}],"asks":[],"checksum":3494592690,"timestamp":"2024-06-01T17:52:32.012633Z"}]}
{"channel":"book","type":"update","data":[{"symbol":"EUR/GBP","bids":[{"price":0.85001,"qty":493.67548617}],"asks":[],"checksum":3429475696,"timestamp":"2024-06-01T17:52:32.012922Z"}]}
{"channel":"book","type":"update","data":[{"symbol":"EUR/GBP","bids":[{"price":0.85000,"qty":0.00000000},{"price":0.84995,"qty":4615.04081268}],"asks":[],"checksum":2541096655,"timestamp":"2024-06-01T17:52:34.540514Z"}]}
{"channel":"book","type":"update","data":[{"symbol":"EUR/GBP","bids":[{"price":0.85002,"qty":7239.99817929}],"asks":[],"checksum":2305321576,"timestamp":"2024-06-01T17:52:34.542121Z"}]}
{"channel":"book","type":"update","data":[{"symbol":"EUR/GBP","bids":[{"price":0.85000,"qty":8967.38182029}],"asks":[],"checksum":956081514,"timestamp":"2024-06-01T17:52:34.542223Z"}]}
{"channel":"book","type":"update","data":[{"symbol":"EUR/GBP","bids":[{"price":0.85001,"qty":0.00000000},{"price":0.84999,"qty":1833.00000000}],"asks":[],"checksum":664237664,"timestamp":"2024-06-01T17:52:34.564697Z"}]}
{"channel":"book","type":"update","data":[{"symbol":"EUR/GBP","bids":[{"price":0.85003,"qty":493.66392784}],"asks":[],"checksum":1707876263,"timestamp":"2024-06-01T17:52:34.564943Z"}]}
{"channel":"book","type":"update","data":[{"symbol":"EUR/GBP","bids":[],"asks":[{"price":0.85112,"qty":0.00000000},{"price":0.85113,"qty":4610.06070893}],"checksum":1053758829,"timestamp":"2024-06-01T17:52:35.638616Z"}]}
{"channel":"book","type":"update","data":[{"symbol":"EUR/GBP","bids":[],"asks":[{"price":0.85112,"qty":37287.12972150}],"checksum":2060897989,"timestamp":"2024-06-01T17:52:35.640646Z"}]}
{"channel":"book","type":"update","data":[{"symbol":"EUR/GBP","bids":[{"price":0.85000,"qty":0.00000000},{"price":0.84999,"qty":1833.00000000}],"asks":[],"checksum":3410100679,"timestamp":"2024-06-01T17:52:37.068624Z"}]}
{"channel":"book","type":"update","data":[{"symbol":"EUR/GBP","bids":[{"price":0.85002,"qty":0.00000000},{"price":0.84995,"qty":4615.04081268}],"asks":[],"checksum":3848545875,"timestamp":"2024-06-01T17:52:37.068830Z"}]}
{"channel":"book","type":"update","data":[{"symbol":"EUR/GBP","bids":[{"price":0.85004,"qty":3642.50592308}],"asks":[],"checksum":285260024,"timestamp":"2024-06-01T17:52:37.070349Z"}]}
{"channel":"book","type":"update","data":[{"symbol":"EUR/GBP","bids":[{"price":0.85000,"qty":10781.93724053}],"asks":[],"checksum":3194302987,"timestamp":"2024-06-01T17:52:37.070453Z"}]}
{"channel":"book","type":"update","data":[{"symbol":"EUR/GBP","bids":[{"price":0.85005,"qty":493.65232684}],"asks":[],"checksum":3843079564,"timestamp":"2024-06-01T17:52:37.078552Z"}]}
{"channel":"book","type":"update","data":[{"symbol":"EUR/GBP","bids":[{"price":0.85003,"qty":0.00000000},{"price":0.85000,"qty":10781.93724053}],"asks":[],"checksum":2819261625,"timestamp":"2024-06-01T17:52:37.078566Z"}]}
{"channel":"book","type":"update","data":[{"symbol":"EUR/GBP","bids":[],"asks":[{"price":0.85112,"qty":0.00000000},{"price":0.85113,"qty":4610.06070893}],"checksum":1883485880,"timestamp":"2024-06-01T17:52:38.151165Z"}]}
{"channel":"book","type":"update","data":[{"symbol":"EUR/GBP","bids":[],"asks":[{"price":0.85071,"qty":0.00000000},{"price":0.85122,"qty":962.22788203}],"checksum":3559802066,"timestamp":"2024-06-01T17:52:38.151261Z"}]}
{"channel":"book","type":"update","data":[{"symbol":"EUR/GBP","bids":[],"asks":[{"price":0.85112,"qty":39364.77883513}],"checksum":923714769,"timestamp":"2024-06-01T17:52:38.156593Z"}]}
{"channel":"book","type":"update","data":[{"symbol":"EUR/GBP","bids":[{"price":0.85043,"qty":0.00000000},{"price":0.84999,"qty":1833.00000000},{"price":0.85049,"qty":250.80000000}],"asks":[],"checksum":1638617362,"timestamp":"2024-06-01T17:52:38.184200Z"}]}
{"channel":"book","type":"update","data":[{"symbol":"EUR/GBP","bids":[{"price":0.85000,"qty":0.00000000},{"price":0.84999,"qty":1833.00000000}],"asks":[],"checksum":3213648468,"timestamp":"2024-06-01T17:52:39.535997Z"}]}
{"channel":"book","type":"update","data":[{"symbol":"EUR/GBP","bids":[{"price":0.85004,"qty":0.00000000},{"price":0.84995,"qty":4615.04081268}],"asks":[],"checksum":3680577064,"timestamp":"2024-06-01T17:52:39.536013Z"}]}
{"channel":"book","type":"update","data":[{"symbol":"EUR/GBP","bids":[{"price":0.85000,"qty":14434.98269170}],"asks":[],"checksum":3157979898,"timestamp":"2024-06-01T17:52:39.537365Z"}]}
{"channel":"book","type":"update","data":[{"symbol":"EUR/GBP","bids":[{"price":0.85005,"qty":0.00000000},{"price":0.84995,"qty":4615.04081268}],"asks":[],"checksum":201276279,"timestamp":"2024-06-01T17:52:39.540327Z"}]}
{"channel":"book","type":"update","data":[{"symbol":"EUR/GBP","bids":[{"price":0.85000,"qty":14928.66398854}],"asks":[],"checksum":731162773,"timestamp":"2024-06-01T17:52:39.540397Z"}]}
{"channel":"book","type":"update","data":[{"symbol":"EUR/GBP","bids":[{"price":0.85049,"qty":0.00000000},{"price":0.84973,"qty":5579.75590645},{"price":0.85043,"qty":250.80000000}],"asks":[],"checksum":699375114,"timestamp":"2024-06-01T17:52:39.548067Z"}]}
{"channel":"book","type":"update","data":[{"symbol":"EUR/GBP","bids":[{"price":0.85050,"qty":145.82255869}],"asks":[],"checksum":3327150692,"timestamp":"2024-06-01T17:52:39.724935Z"}]}
{"channel":"book","type":"update","data":[{"symbol":"EUR/GBP","bids":[{"price":0.85048,"qty":0.00000000},{"price":0.84995,"qty":4615.04081268}],"asks":[],"checksum":3331514744,"timestamp":"2024-06-01T17:52:39.898739Z"}]}
{"channel":"book","type":"update","data":[{"symbol":"EUR/GBP","bids":[],"asks":[{"price":0.85112,"qty":0.00000000},{"price":0.85122,"qty":962.22788203}],"checksum":1601736770,"timestamp":"2024-06-01T17:52:40.566884Z"}]}
{"channel":"book","type":"update","data":[{"symbol":"EUR/GBP","bids":[],"asks":[{"price":0.85112,"qty":32812.23970546}],"checksum":795447424,"timestamp":"2024-06-01T17:52:40.571804Z"}]}
