{"channel":"book","type":"snapshot","data":[{"symbol":"EUR/USD","bids":[{"price":1.08407,"qty":9.81218143},{"price":1.08406,"qty":1984.80000000},{"price":1.08405,"qty":7469.34013197},{"price":1.08404,"qty":2100.17167651},{"price":1.08383,"qty":631.29992711},{"price":1.08382,"qty":391.52920613},{"price":1.08381,"qty":3711.87884831},{"price":1.08380,"qty":12588.57518312},{"price":1.08378,"qty":4613.45216905},{"price":1.08371,"qty":1607.25727299}],"asks":[{"price":1.08417,"qty":1861.49618094},{"price":1.08418,"qty":451.50191816},{"price":1.08422,"qty":2305.80509490},{"price":1.08433,"qty":47.15107699},{"price":1.08439,"qty":962.24087722},{"price":1.08441,"qty":2236.00627243},{"price":1.08442,"qty":14877.31253327},{"price":1.08443,"qty":18297.70571102},{"price":1.08445,"qty":1152.92653643},{"price":1.08447,"qty":4610.55811950}],"checksum":1579452447}]}
{"channel":"book","type":"update","data":[{"symbol":"EUR/USD","bids":[],"asks":[{"price":1.08443,"qty":18135.70071785}],"checksum":1434536274,"timestamp":"2024-06-01T17:51:40.181397Z"}]}
{"channel":"book","type":"update","data":[{"symbol":"EUR/USD","bids":[],"asks":[{"price":1.08433,"qty":0.00000000},{"price":1.08454,"qty":2830.45000000}],"checksum":1310595146,"timestamp":"2024-06-01T17:51:40.181411Z"}]}
{"channel":"book","type":"update","data":[{"symbol":"EUR/USD","bids":[],"asks":[{"price":1.08445,"qty":0.00000000},{"price":1.08459,"qty":131034.20133752}],"checksum":2494588377,"timestamp":"2024-06-01T17:51:40.181582Z"}]}
{"channel":"book","type":"update","data":[{"symbol":"EUR/USD","bids":[],"asks":[{"price":1.08438,"qty":75.86455604}],"checksum":3586164682,"timestamp":"2024-06-01T17:51:40.186650Z"}]}
{"channel":"book","type":"update","data":[{"symbol":"EUR/USD","bids":[],"asks":[{"price":1.08440,"qty":1232.26811532}],"checksum":3729191006,"timestamp":"2024-06-01T17:51:40.186831Z"}]}
{"channel":"book","type":"update","data":[{"symbol":"EUR/USD","bids":[{"price":1.08406,"qty":0.00000000},{"price":1.08370,"qty":16662.23582757},{"price":1.08408,"qty":1984.80000000}],"asks":[],"checksum":1829045142,"timestamp":"2024-06-01T17:51:40.196842Z"}]}
{"channel":"book","type":"update","data":[{"symbol":"EUR/USD","bids":[],"asks":[{"price":1.08439,"qty":1187.96297722}],"checksum":1154542884,"timestamp":"2024-06-01T17:51:40.202644Z"}]}
{"channel":"book","type":"update","data":[{"symbol":"EUR/USD","bids":[],"asks":[{"price":1.08441,"qty":2010.28417243}],"checksum":731818307,"timestamp":"2024-06-01T17:51:40.202782Z"}]}
{"channel":"book","type":"update","data":[{"symbol":"EUR/USD","bids":[{"price":1.08371,"qty":1630.32617518}],"asks":[],"checksum":2611496183,"timestamp":"2024-06-01T17:51:40.459770Z"}]}
{"channel":"book","type":"update","data":[{"symbol":"EUR/USD","bids":[],"asks":[{"price":1.08443,"qty":0.00000000},{"price":1.08454,"qty":2830.45000000}],"checksum":3802160677,"timestamp":"2024-06-01T17:51:41.038983Z"}]}
{"channel":"book","type":"update","data":[{"symbol":"EUR/USD","bids":[],"asks":[{"price":1.08442,"qty":0.00000000},{"price":1.08459,"qty":131034.20133752}],"checksum":620302820,"timestamp":"2024-06-01T17:51:41.039128Z"}]}
{"channel":"book","type":"update","data":[{"symbol":"EUR/USD","bids":[],"asks":[{"price":1.08459,"qty":0.00000000},{"price":1.08460,"qty":4167.00000000}],"checksum":2136071343,"timestamp":"2024-06-01T17:51:41.039191Z"}]}
{"channel":"book","type":"update","data":[{"symbol":"EUR/USD","bids":[],"asks":[{"price":1.08438,"qty":14216.10845016}],"checksum":3171963240,"timestamp":"2024-06-01T17:51:41.041078Z"}]}
{"channel":"book","type":"update","data":[{"symbol":"EUR/USD","bids":[],"asks":[{"price":1.08459,"qty":38733.21209240}],"checksum":1076901132,"timestamp":"2024-06-01T17:51:41.041093Z"}]}
{"channel":"book","type":"update","data":[{"symbol":"EUR/USD","bids":[],"asks":[{"price":1.08441,"qty":0.00000000},{"price":1.08460,"qty":4167.00000000}],"checksum":3380848062,"timestamp":"2024-06-01T17:51:41.042848Z"}]}
{"channel":"book","type":"update","data":[{"symbol":"EUR/USD","bids":[],"asks":[{"price":1.08437,"qty":2010.28417243}],"checksum":1929306409,"timestamp":"2024-06-01T17:51:41.074632Z"}]}
{"channel":"book","type":"update","data":[{"symbol":"EUR/USD","bids":[{"price":1.08380,"qty":0.00000000},{"price":1.08370,"qty":16662.23582757}],"asks":[],"checksum":1749755059,"timestamp":"2024-06-01T17:51:41.678319Z"}]}
{"channel":"book","type":"update","data":[{"symbol":"EUR/USD","bids":[{"price":1.08381,"qty":0.00000000},{"price":1.08350,"qty":962.24087722},{"price":1.08379,"qty":3711.94734643}],"asks":[],"checksum":1178407351,"timestamp":"2024-06-01T17:51:41.681501Z"}]}
{"channel":"book","type":"update","data":[{"symbol":"EUR/USD","bids":[{"price":1.08370,"qty":0.00000000},{"price":1.08350,"qty":962.24087722}],"asks":[],"checksum":2679375437,"timestamp":"2024-06-01T17:51:41.682040Z"}]}
{"channel":"book","type":"update","data":[{"symbol":"EUR/USD","bids":[{"price":1.08384,"qty":1843.75979497}],"asks":[],"checksum":2113357208,"timestamp":"2024-06-01T17:51:41.683213Z"}]}
{"channel":"book","type":"update","data":[{"symbol":"EUR/USD","bids":[{"price":1.08372,"qty":43479.97312919}],"asks":[],"checksum":2937683723,"timestamp":"2024-06-01T17:51:41.683339Z"}]}
{"channel":"book","type":"update","data":[{"symbol":"EUR/USD","bids":[{"price":1.08382,"qty":12920.56643045}],"asks":[],"checksum":2098822228,"timestamp":"2024-06-01T17:51:41.683351Z"}]}
{"channel":"book","type":"update","data":[{"symbol":"EUR/USD","bids":[{"price":1.08379,"qty":0.00000000},{"price":1.08371,"qty":1630.32617518}],"asks":[],"checksum":777810189,"timestamp":"2024-06-01T17:51:41.685193Z"}]}
{"channel":"book","type":"update","data":[{"symbol":"EUR/USD","bids":[{"price":1.08385,"qty":3711.74185965}],"asks":[],"checksum":571226622,"timestamp":"2024-06-01T17:51:41.690754Z"}]}
{"channel":"book","type":"update","data":[{"symbol":"EUR/USD","bids":[{"price":1.08382,"qty":12529.03722432}],"asks":[],"checksum":1021510050,"timestamp":"2024-06-01T17:51:41.931349Z"}]}
{"channel":"book","type":"update","data":[{"symbol":"EUR/USD","bids":[{"price":1.08382,"qty":12944.82758653}],"asks":[],"checksum":4129057968,"timestamp":"2024-06-01T17:51:41.937848Z"}]}
{"channel":"book","type":"update","data":[{"symbol":"EUR/USD","bids":[],"asks":[{"price":1.08438,"qty":14140.24389412}],"checksum":1779232432,"timestamp":"2024-06-01T17:51:42.270160Z"}]}
{"channel":"book","type":"update","data":[{"symbol":"EUR/USD","bids":[],"asks":[{"price":1.08440,"qty":0.00000000},{"price":1.08460,"qty":4167.00000000}],"checksum":2165114889,"timestamp":"2024-06-01T17:51:42.270486Z"}]}
{"channel":"book","type":"update","data":[{"symbol":"EUR/USD","bids":[],"asks":[{"price":1.08436,"qty":362.99934648}],"checksum":348788092,"timestamp":"2024-06-01T17:51:42.275190Z"}]}
{"channel":"book","type":"update","data":[{"symbol":"EUR/USD","bids":[],"asks":[{"price":1.08458,"qty":936.44076774}],"checksum":4268027349,"timestamp":"2024-06-01T17:51:42.275294Z"}]}
{"channel":"book","type":"update","data":[{"symbol":"EUR/USD","bids":[],"asks":[{"price":1.08439,"qty":962.24087722}],"checksum":1378666466,"timestamp":"2024-06-01T17:51:42.280939Z"}]}
{"channel":"book","type":"update","data":[{"symbol":"EUR/USD","bids":[],"asks":[{"price":1.08446,"qty":225.72210000}],"checksum":2759590117,"timestamp":"2024-06-01T17:51:42.281049Z"}]}
{"channel":"book","type":"update","data":[{"symbol":"EUR/USD","bids":[{"price":1.08408,"qty":0.00000000},{"price":1.08371,"qty":1603.16700381},{"price":1.08406,"qty":1984.80000000}],"asks":[],"checksum":2213236038,"timestamp":"2024-06-01T17:51:42.294758Z"}]}
{"channel":"book","type":"update","data":[{"symbol":"EUR/USD","bids":[{"price":1.08373,"qty":16662.23582757}],"asks":[],"checksum":1437947953,"timestamp":"2024-06-01T17:51:42.297816Z"}]}
{"channel":"book","type":"update","data":[{"symbol":"EUR/USD","bids":[{"price":1.08373,"qty":16685.30430403}],"asks":[],"checksum":3162946418,"timestamp":"2024-06-01T17:51:42.502483Z"}]}
{"channel":"book","type":"update","data":[{"symbol":"EUR/USD","bids":[],"asks":[{"price":1.08438,"qty":0.00000000},{"price":1.08458,"qty":936.44076774}],"checksum":110948111,"timestamp":"2024-06-01T17:51:43.547743Z"}]}
{"channel":"book","type":"update","data":[{"symbol":"EUR/USD","bids":[],"asks":[{"price":1.08437,"qty":0.00000000},{"price":1.08460,"qty":4167.00000000}],"checksum":2482964261,"timestamp":"2024-06-01T17:51:43.550882Z"}]}
{"channel":"book","type":"update","data":[{"symbol":"EUR/USD","bids":[],"asks":[{"price":1.08446,"qty":16732.22872556}],"checksum":351529135,"timestamp":"2024-06-01T17:51:43.552624Z"}]}
{"channel":"book","type":"update","data":[{"symbol":"EUR/USD","bids":[],"asks":[{"price":1.08435,"qty":5102.14797955}],"checksum":321688689,"timestamp":"2024-06-01T17:51:43.552645Z"}]}
{"channel":"book","type":"update","data":[{"symbol":"EUR/USD","bids":[],"asks":[{"price":1.08445,"qty":2010.28417243}],"checksum":1339132943,"timestamp":"2024-06-01T17:51:43.794392Z"}]}
{"channel":"book","type":"update","data":[{"symbol":"EUR/USD","bids":[],"asks":[{"price":1.08446,"qty":16506.50662556}],"checksum":1340470222,"timestamp":"2024-06-01T17:51:43.801404Z"}]}
{"channel":"book","type":"update","data":[{"symbol":"EUR/USD","bids":[],"asks":[{"price":1.08444,"qty":225.72210000}],"checksum":2433182046,"timestamp":"2024-06-01T17:51:43.801554Z"}]}
{"channel":"book","type":"update","data":[{"symbol":"EUR/USD","bids":[],"asks":[{"price":1.08436,"qty":0.00000000},{"price":1.08454,"qty":2830.45000000}],"checksum":1256359928,"timestamp":"2024-06-01T17:51:44.464381Z"}]}
{"channel":"book","type":"update","data":[{"symbol":"EUR/USD","bids":[],"asks":[{"price":1.08434,"qty":126.12345586}],"checksum":3614109993,"timestamp":"2024-06-01T17:51:44.470176Z"}]}
{"channel":"book","type":"update","data":[{"symbol":"EUR/USD","bids":[],"asks":[{"price":1.08444,"qty":1476.53610545}],"checksum":3265529232,"timestamp":"2024-06-01T17:51:44.470249Z"}]}
{"channel":"book","type":"update","data":[{"symbol":"EUR/USD","bids":[{"price":1.08373,"qty":16662.23582757},{"price":1.08374,"qty":23.06826360}],"asks":[],"checksum":1720441885,"timestamp":"2024-06-01T17:51:44.510068Z"}]}
{"channel":"book","type":"update","data":[{"symbol":"EUR/USD","bids":[{"price":1.08382,"qty":12529.03722432}],"asks":[],"checksum":3371925016,"timestamp":"2024-06-01T17:51:44.958543Z"}]}
{"channel":"book","type":"update","data":[{"symbol":"EUR/USD","bids":[{"price":1.08382,"qty":0.00000000},{"price":1.08373,"qty":16662.23582757}],"asks":[],"checksum":3447619514,"timestamp":"2024-06-01T17:51:45.214624Z"}]}
{"channel":"book","type":"update","data":[{"symbol":"EUR/USD","bids":[{"price":1.08384,"qty":0.00000000},{"price":1.08350,"qty":962.24087722}],"asks":[],"checksum":2816078053,"timestamp":"2024-06-01T17:51:45.214881Z"}]}
{"channel":"book","type":"update","data":[{"symbol":"EUR/USD","bids":[{"price":1.08373,"qty":0.00000000},{"price":1.08346,"qty":2830.45000000}],"asks":[],"checksum":381720854,"timestamp":"2024-06-01T17:51:45.217433Z"}]}
{"channel":"book","type":"update","data":[{"symbol":"EUR/USD","bids":[{"price":1.08385,"qty":0.00000000},{"price":1.08343,"qty":4614.93708204},{"price":1.08379,"qty":3711.94734643}],"asks":[],"checksum":4054236732,"timestamp":"2024-06-01T17:51:45.217754Z"}]}
{"channel":"book","type":"update","data":[{"symbol":"EUR/USD","bids":[{"price":1.08386,"qty":7183.75048503}],"asks":[],"checksum":885680654,"timestamp":"2024-06-01T17:51:45.219832Z"}]}
{"channel":"book","type":"update","data":[{"symbol":"EUR/USD","bids":[{"price":1.08379,"qty":28250.66757416}],"asks":[],"checksum":3928227658,"timestamp":"2024-06-01T17:51:45.219927Z"}]}
{"channel":"book","type":"update","data":[{"symbol":"EUR/USD","bids":[{"price":1.08383,"qty":0.00000000},{"price":1.08346,"qty":2830.45000000}],"asks":[],"checksum":3908314733,"timestamp":"2024-06-01T17:51:45.221967Z"}]}
{"channel":"book","type":"update","data":[{"symbol":"EUR/USD","bids":[{"price":1.08380,"qty":631.31740173}],"asks":[],"checksum":1429779960,"timestamp":"2024-06-01T17:51:45.222128Z"}]}
{"channel":"book","type":"update","data":[{"symbol":"EUR/USD","bids":[{"price":1.08379,"qty":24538.72022773},{"price":1.08351,"qty":3712.90658562}],"asks":[],"checksum":299053334,"timestamp":"2024-06-01T17:51:45.224755Z"}]}
{"channel":"book","type":"update","data":[{"symbol":"EUR/USD","bids":[{"price":1.08351,"qty":0.00000000},{"price":1.08350,"qty":962.24087722},{"price":1.08387,"qty":3711.67336912}],"asks":[],"checksum":2790738052,"timestamp":"2024-06-01T17:51:45.227759Z"}]}
{"channel":"book","type":"update","data":[{"symbol":"EUR/USD","bids":[{"price":1.08406,"qty":0.00000000},{"price":1.08350,"qty":962.24087722},{"price":1.08387,"qty":5696.47336912}],"asks":[],"checksum":3992193994,"timestamp":"2024-06-01T17:51:45.234586Z"}]}
{"channel":"book","type":"update","data":[{"symbol":"EUR/USD","bids":[{"price":1.08387,"qty":1984.80000000},{"price":1.08388,"qty":3711.63912480}],"asks":[],"checksum":4055637428,"timestamp":"2024-06-01T17:51:45.237552Z"}]}
{"channel":"book","type":"update","data":[{"symbol":"EUR/USD","bids":[{"price":1.08383,"qty":315.29040280}],"asks":[],"checksum":4060275782,"timestamp":"2024-06-01T17:51:45.274190Z"}]}
{"channel":"book","type":"update","data":[{"symbol":"EUR/USD","bids":[{"price":1.08386,"qty":7331.25451987}],"asks":[],"checksum":1681123852,"timestamp":"2024-06-01T17:51:45.274232Z"}]}
{"channel":"book","type":"update","data":[{"symbol":"EUR/USD","bids":[{"price":1.08387,"qty":0.00000000},{"price":1.08374,"qty":1351.49376263},{"price":1.08406,"qty":1984.80000000}],"asks":[],"checksum":769508183,"timestamp":"2024-06-01T17:51:45.298515Z"}]}
{"channel":"book","type":"update","data":[{"symbol":"EUR/USD","bids":[{"price":1.08388,"qty":0.00000000},{"price":1.08374,"qty":1351.49376263},{"price":1.08387,"qty":3711.67336912}],"asks":[],"checksum":1119695349,"timestamp":"2024-06-01T17:51:45.301663Z"}]}
{"channel":"book","type":"update","data":[{"symbol":"EUR/USD","bids":[{"price":1.08406,"qty":1994.61218143}],"asks":[],"checksum":938275236,"timestamp":"2024-06-01T17:51:45.414551Z"}]}
{"channel":"book","type":"update","data":[{"symbol":"EUR/USD","bids":[{"price":1.08407,"qty":0.00000000},{"price":1.08374,"qty":1351.49376263}],"asks":[],"checksum":2063717249,"timestamp":"2024-06-01T17:51:45.579890Z"}]}
{"channel":"book","type":"update","data":[{"symbol":"EUR/USD","bids":[],"asks":[{"price":1.08435,"qty":0.00000000},{"price":1.08454,"qty":2830.45000000}],"checksum":2204080097,"timestamp":"2024-06-01T17:51:46.015874Z"}]}
{"channel":"book","type":"update","data":[{"symbol":"EUR/USD","bids":[],"asks":[{"price":1.08446,"qty":0.00000000},{"price":1.08460,"qty":4167.00000000}],"checksum":105405579,"timestamp":"2024-06-01T17:51:46.015921Z"}]}
{"channel":"book","type":"update","data":[{"symbol":"EUR/USD","bids":[],"asks":[{"price":1.08445,"qty":0.00000000},{"price":1.08465,"qty":4167.00000000}],"checksum":1304492377,"timestamp":"2024-06-01T17:51:46.019186Z"}]}
{"channel":"book","type":"update","data":[{"symbol":"EUR/USD","bids":[],"asks":[{"price":1.08443,"qty":19764.89481014}],"checksum":2814170889,"timestamp":"2024-06-01T17:51:46.020897Z"}]}
{"channel":"book","type":"update","data":[{"symbol":"EUR/USD","bids":[],"asks":[{"price":1.08459,"qty":39315.22391759}],"checksum":1519017931,"timestamp":"2024-06-01T17:51:46.020994Z"}]}
{"channel":"book","type":"update","data":[{"symbol":"EUR/USD","bids":[],"asks":[{"price":1.08444,"qty":1250.81400545}],"checksum":2511037650,"timestamp":"2024-06-01T17:51:46.038213Z"}]}
{"channel":"book","type":"update","data":[{"symbol":"EUR/USD","bids":[],"asks":[{"price":1.08442,"qty":225.72210000}],"checksum":994095720,"timestamp":"2024-06-01T17:51:46.038283Z"}]}
{"channel":"book","type":"update","data":[{"symbol":"EUR/USD","bids":[],"asks":[{"price":1.08442,"qty":0.00000000},{"price":1.08459,"qty":39315.22391759}],"checksum":2511037650,"timestamp":"2024-06-01T17:51:46.165642Z"}]}
{"channel":"book","type":"update","data":[{"symbol":"EUR/USD","bids":[],"asks":[{"price":1.08453,"qty":225.72210000}],"checksum":3244954075,"timestamp":"2024-06-01T17:51:46.165941Z"}]}
{"channel":"book","type":"update","data":[{"symbol":"EUR/USD","bids":[{"price":1.08387,"qty":0.00000000},{"price":1.08350,"qty":962.24087722},{"price":1.08406,"qty":5705.63501650}],"asks":[],"checksum":2962710987,"timestamp":"2024-06-01T17:51:46.166524Z"}]}
{"channel":"book","type":"update","data":[{"symbol":"EUR/USD","bids":[{"price":1.08406,"qty":1994.61218143},{"price":1.08407,"qty":3710.98860275}],"asks":[],"checksum":2932304057,"timestamp":"2024-06-01T17:51:46.177257Z"}]}
{"channel":"book","type":"update","data":[{"symbol":"EUR/USD","bids":[{"price":1.08406,"qty":9.81218143},{"price":1.08408,"qty":1984.80000000}],"asks":[],"checksum":3485753470,"timestamp":"2024-06-01T17:51:46.214939Z"}]}
{"channel":"book","type":"update","data":[{"symbol":"EUR/USD","bids":[{"price":1.08407,"qty":0.00000000},{"price":1.08374,"qty":1351.49376263},{"price":1.08406,"qty":3720.83501650}],"asks":[],"checksum":92628341,"timestamp":"2024-06-01T17:51:46.218740Z"}]}
{"channel":"book","type":"update","data":[{"symbol":"EUR/USD","bids":[{"price":1.08408,"qty":0.00000000},{"price":1.08350,"qty":962.24087722},{"price":1.08387,"qty":1984.80000000}],"asks":[],"checksum":2127218971,"timestamp":"2024-06-01T17:51:46.550227Z"}]}
{"channel":"book","type":"update","data":[{"symbol":"EUR/USD","bids":[],"asks":[{"price":1.08434,"qty":0.00000000},{"price":1.08459,"qty":39315.22391759}],"checksum":3916459728,"timestamp":"2024-06-01T17:51:46.664689Z"}]}
{"channel":"book","type":"update","data":[{"symbol":"EUR/USD","bids":[],"asks":[{"price":1.08444,"qty":0.00000000},{"price":1.08460,"qty":4167.00000000}],"checksum":3362074233,"timestamp":"2024-06-01T17:51:46.664875Z"}]}
{"channel":"book","type":"update","data":[{"symbol":"EUR/USD","bids":[],"asks":[{"price":1.08442,"qty":1396.68459208}],"checksum":1288554259,"timestamp":"2024-06-01T17:51:46.670869Z"}]}
{"channel":"book","type":"update","data":[{"symbol":"EUR/USD","bids":[{"price":1.08387,"qty":0.00000000},{"price":1.08350,"qty":962.24087722},{"price":1.08407,"qty":1984.80000000}],"asks":[],"checksum":649737424,"timestamp":"2024-06-01T17:51:46.702681Z"}]}
{"channel":"book","type":"update","data":[{"symbol":"EUR/USD","bids":[{"price":1.08406,"qty":9.81218143},{"price":1.08408,"qty":3710.95437107}],"asks":[],"checksum":1434384630,"timestamp":"2024-06-01T17:51:46.707255Z"}]}
{"channel":"book","type":"update","data":[{"symbol":"EUR/USD","bids":[{"price":1.08380,"qty":654.38438825}],"asks":[],"checksum":3601264247,"timestamp":"2024-06-01T17:51:46.708601Z"}]}
{"channel":"book","type":"update","data":[{"symbol":"EUR/USD","bids":[],"asks":[{"price":1.08441,"qty":2010.28417243}],"checksum":3952347397,"timestamp":"2024-06-01T17:51:46.781061Z"}]}
{"channel":"book","type":"update","data":[{"symbol":"EUR/USD","bids":[],"asks":[{"price":1.08438,"qty":451.50191816}],"checksum":1203368005,"timestamp":"2024-06-01T17:51:48.035048Z"}]}
{"channel":"book","type":"update","data":[{"symbol":"EUR/USD","bids":[],"asks":[{"price":1.08418,"qty":0.00000000},{"price":1.08454,"qty":2830.45000000}],"checksum":241596093,"timestamp":"2024-06-01T17:51:48.224566Z"}]}
{"channel":"book","type":"update","data":[{"symbol":"EUR/USD","bids":[],"asks":[{"price":1.08417,"qty":0.00000000},{"price":1.08459,"qty":39315.22391759},{"price":1.08421,"qty":1858.57735647}],"checksum":1794900688,"timestamp":"2024-06-01T17:51:48.228349Z"}]}
{"channel":"book","type":"update","data":[{"symbol":"EUR/USD","bids":[{"price":1.08407,"qty":0.00000000},{"price":1.08374,"qty":1328.42549903},{"price":1.08409,"qty":1984.80000000}],"asks":[],"checksum":1090537199,"timestamp":"2024-06-01T17:51:48.248965Z"}]}
{"channel":"book","type":"update","data":[{"symbol":"EUR/USD","bids":[{"price":1.08408,"qty":0.00000000},{"price":1.08374,"qty":1328.42549903},{"price":1.08410,"qty":3710.88590959}],"asks":[],"checksum":3217212873,"timestamp":"2024-06-01T17:51:48.252872Z"}]}
{"channel":"book","type":"update","data":[{"symbol":"EUR/USD","bids":[],"asks":[{"price":1.08443,"qty":0.00000000},{"price":1.08459,"qty":39315.22391759}],"checksum":2814037093,"timestamp":"2024-06-01T17:51:48.521274Z"}]}
{"channel":"book","type":"update","data":[{"symbol":"EUR/USD","bids":[],"asks":[{"price":1.08459,"qty":0.00000000},{"price":1.08460,"qty":4167.00000000}],"checksum":1320710206,"timestamp":"2024-06-01T17:51:48.521362Z"}]}
{"channel":"book","type":"update","data":[{"symbol":"EUR/USD","bids":[],"asks":[{"price":1.08441,"qty":0.00000000},{"price":1.08465,"qty":4167.00000000}],"checksum":2783762588,"timestamp":"2024-06-01T17:51:48.524748Z"}]}
{"channel":"book","type":"update","data":[{"symbol":"EUR/USD","bids":[],"asks":[{"price":1.08459,"qty":37686.02982530}],"checksum":3171793706,"timestamp":"2024-06-01T17:51:48.526421Z"}]}
{"channel":"book","type":"update","data":[{"symbol":"EUR/USD","bids":[],"asks":[{"price":1.08437,"qty":14877.31253327}],"checksum":1032839116,"timestamp":"2024-06-01T17:51:48.526441Z"}]}
{"channel":"book","type":"update","data":[{"symbol":"EUR/USD","bids":[{"price":1.08409,"qty":0.00000000},{"price":1.08374,"qty":1328.42549903},{"price":1.08411,"qty":1984.80000000}],"asks":[],"checksum":2437521823,"timestamp":"2024-06-01T17:51:48.553437Z"}]}
{"channel":"book","type":"update","data":[{"symbol":"EUR/USD","bids":[],"asks":[{"price":1.08436,"qty":2010.28417243}],"checksum":2952380014,"timestamp":"2024-06-01T17:51:48.555133Z"}]}
{"channel":"book","type":"update","data":[{"symbol":"EUR/USD","bids":[{"price":1.08410,"qty":0.00000000},{"price":1.08374,"qty":1328.42549903},{"price":1.08406,"qty":3720.83501650}],"asks":[],"checksum":3138882344,"timestamp":"2024-06-01T17:51:48.557183Z"}]}
{"channel":"book","type":"update","data":[{"symbol":"EUR/USD","bids":[{"price":1.08386,"qty":147.50403484}],"asks":[],"checksum":2535048533,"timestamp":"2024-06-01T17:51:48.755230Z"}]}
{"channel":"book","type":"update","data":[{"symbol":"EUR/USD","bids":[{"price":1.08379,"qty":0.00000000},{"price":1.08350,"qty":962.24087722}],"asks":[],"checksum":2968682654,"timestamp":"2024-06-01T17:51:48.755417Z"}]}
{"channel":"book","type":"update","data":[{"symbol":"EUR/USD","bids":[{"price":1.08351,"qty":4529.96364201}],"asks":[],"checksum":1134868279,"timestamp":"2024-06-01T17:51:48.760420Z"}]}
{"channel":"book","type":"update","data":[{"symbol":"EUR/USD","bids":[{"price":1.08352,"qty":16662.23582757}],"asks":[],"checksum":2702965508,"timestamp":"2024-06-01T17:51:48.764093Z"}]}
{"channel":"book","type":"update","data":[{"symbol":"EUR/USD","bids":[{"price":1.08411,"qty":0.00000000},{"price":1.08351,"qty":4529.96364201},{"price":1.08407,"qty":1984.80000000}],"asks":[],"checksum":1667062311,"timestamp":"2024-06-01T17:51:48.797042Z"}]}
{"channel":"book","type":"update","data":[{"symbol":"EUR/USD","bids":[{"price":1.08406,"qty":9.81218143},{"price":1.08408,"qty":3710.95437107}],"asks":[],"checksum":893826494,"timestamp":"2024-06-01T17:51:48.800367Z"}]}
{"channel":"book","type":"update","data":[{"symbol":"EUR/USD","bids":[{"price":1.08386,"qty":0.00000000},{"price":1.08352,"qty":16662.23582757}],"asks":[],"checksum":2007252006,"timestamp":"2024-06-01T17:51:49.990651Z"}]}
{"channel":"book","type":"update","data":[{"symbol":"EUR/USD","bids":[{"price":1.08383,"qty":0.00000000},{"price":1.08351,"qty":4529.96364201}],"asks":[],"checksum":1664794553,"timestamp":"2024-06-01T17:51:49.990670Z"}]}
{"channel":"book","type":"update","data":[{"symbol":"EUR/USD","bids":[{"price":1.08374,"qty":0.00000000},{"price":1.08350,"qty":962.24087722}],"asks":[],"checksum":1673410479,"timestamp":"2024-06-01T17:51:49.991058Z"}]}
{"channel":"book","type":"update","data":[{"symbol":"EUR/USD","bids":[{"price":1.08353,"qty":2121.09597548}],"asks":[],"checksum":3611201749,"timestamp":"2024-06-01T17:51:50.000309Z"}]}
{"channel":"book","type":"update","data":[{"symbol":"EUR/USD","bids":[{"price":1.08407,"qty":0.00000000},{"price":1.08350,"qty":962.24087722},{"price":1.08381,"qty":1984.80000000}],"asks":[],"checksum":3508168820,"timestamp":"2024-06-01T17:51:50.039207Z"}]}
{"channel":"book","type":"update","data":[{"symbol":"EUR/USD","bids":[{"price":1.08408,"qty":0.00000000},{"price":1.08350,"qty":962.24087722},{"price":1.08406,"qty":3720.83501650}],"asks":[],"checksum":1635444303,"timestamp":"2024-06-01T17:51:50.042360Z"}]}
{"channel":"book","type":"update","data":[{"symbol":"EUR/USD","bids":[{"price":1.08380,"qty":631.31740173},{"price":1.08352,"qty":16685.30877500}],"asks":[],"checksum":4028611603,"timestamp":"2024-06-01T17:51:50.494265Z"}]}
{"channel":"book","type":"update","data":[{"symbol":"EUR/USD","bids":[],"asks":[{"price":1.08437,"qty":0.00000000},{"price":1.08460,"qty":4167.00000000}],"checksum":2020145161,"timestamp":"2024-06-01T17:51:51.058850Z"}]}
{"channel":"book","type":"update","data":[{"symbol":"EUR/USD","bids":[],"asks":[{"price":1.08435,"qty":6731.34207184}],"checksum":928754608,"timestamp":"2024-06-01T17:51:51.061543Z"}]}
{"channel":"book","type":"update","data":[{"symbol":"EUR/USD","bids":[],"asks":[{"price":1.08446,"qty":13248.11844099}],"checksum":2512071161,"timestamp":"2024-06-01T17:51:51.061605Z"}]}
{"channel":"book","type":"update","data":[{"symbol":"EUR/USD","bids":[],"asks":[{"price":1.08436,"qty":0.00000000},{"price":1.08454,"qty":2830.45000000}],"checksum":1937698655,"timestamp":"2024-06-01T17:51:51.062588Z"}]}
{"channel":"book","type":"update","data":[{"symbol":"EUR/USD","bids":[],"asks":[{"price":1.08445,"qty":2010.28417243}],"checksum":2144821305,"timestamp":"2024-06-01T17:51:51.093339Z"}]}
{"channel":"book","type":"update","data":[{"symbol":"EUR/USD","bids":[],"asks":[{"price":1.08442,"qty":0.00000000},{"price":1.08454,"qty":2830.45000000}],"checksum":4020929167,"timestamp":"2024-06-01T17:51:51.161595Z"}]}
{"channel":"book","type":"update","data":[{"symbol":"EUR/USD","bids":[],"asks":[{"price":1.08435,"qty":6922.06054406}],"checksum":611288732,"timestamp":"2024-06-01T17:51:51.169590Z"}]}
{"channel":"book","type":"update","data":[{"symbol":"EUR/USD","bids":[{"price":1.08351,"qty":0.00000000},{"price":1.08346,"qty":2830.45000000}],"asks":[],"checksum":2283843450,"timestamp":"2024-06-01T17:51:52.396243Z"}]}
{"channel":"book","type":"update","data":[{"symbol":"EUR/USD","bids":[{"price":1.08352,"qty":23.07294743}],"asks":[],"checksum":2291085364,"timestamp":"2024-06-01T17:51:52.399537Z"}]}
{"channel":"book","type":"update","data":[{"symbol":"EUR/USD","bids":[{"price":1.08407,"qty":3186.86171849}],"asks":[],"checksum":1661124626,"timestamp":"2024-06-01T17:51:52.401326Z"}]}
{"channel":"book","type":"update","data":[{"symbol":"EUR/USD","bids":[{"price":1.08354,"qty":83251.98910208}],"asks":[],"checksum":3805709611,"timestamp":"2024-06-01T17:51:52.401593Z"}]}
{"channel":"book","type":"update","data":[{"symbol":"EUR/USD","bids":[{"price":1.08406,"qty":9.81218143},{"price":1.08408,"qty":3710.95437107}],"asks":[],"checksum":3842195943,"timestamp":"2024-06-01T17:51:52.405865Z"}]}
{"channel":"book","type":"update","data":[{"symbol":"EUR/USD","bids":[{"price":1.08355,"qty":16662.23582757}],"asks":[],"checksum":1055601959,"timestamp":"2024-06-01T17:51:52.487002Z"}]}
{"channel":"book","type":"update","data":[{"symbol":"EUR/USD","bids":[{"price":1.08381,"qty":0.00000000},{"price":1.08353,"qty":2121.09597548},{"price":1.08406,"qty":1994.61218143}],"asks":[],"checksum":2044086591,"timestamp":"2024-06-01T17:51:52.502737Z"}]}
{"channel":"book","type":"update","data":[{"symbol":"EUR/USD","bids":[{"price":1.08408,"qty":0.00000000},{"price":1.08352,"qty":23.07294743},{"price":1.08356,"qty":3712.73525655}],"asks":[],"checksum":3161896354,"timestamp":"2024-06-01T17:51:52.930655Z"}]}
{"channel":"book","type":"update","data":[{"symbol":"EUR/USD","bids":[{"price":1.08356,"qty":0.00000000},{"price":1.08352,"qty":23.07294743},{"price":1.08407,"qty":6897.85032124}],"asks":[],"checksum":1835842150,"timestamp":"2024-06-01T17:51:52.933640Z"}]}
{"channel":"book","type":"update","data":[{"symbol":"EUR/USD","bids":[],"asks":[{"price":1.08435,"qty":6731.34207184}],"checksum":2796142197,"timestamp":"2024-06-01T17:51:53.400404Z"}]}
{"channel":"book","type":"update","data":[{"symbol":"EUR/USD","bids":[],"asks":[{"price":1.08434,"qty":133.29151413}],"checksum":2015978732,"timestamp":"2024-06-01T17:51:53.442454Z"}]}
{"channel":"book","type":"update","data":[{"symbol":"EUR/USD","bids":[],"asks":[{"price":1.08444,"qty":1430.06585085}],"checksum":638458046,"timestamp":"2024-06-01T17:51:53.442566Z"}]}
{"channel":"book","type":"update","data":[{"symbol":"EUR/USD","bids":[{"price":1.08406,"qty":9.81218143},{"price":1.08381,"qty":1984.80000000}],"asks":[],"checksum":3706791370,"timestamp":"2024-06-01T17:51:53.474526Z"}]}
{"channel":"book","type":"update","data":[{"symbol":"EUR/USD","bids":[{"price":1.08407,"qty":3186.86171849},{"price":1.08406,"qty":3720.83501650}],"asks":[],"checksum":3087695350,"timestamp":"2024-06-01T17:51:53.477700Z"}]}
{"channel":"book","type":"update","data":[{"symbol":"EUR/USD","bids":[],"asks":[{"price":1.08435,"qty":0.00000000},{"price":1.08453,"qty":225.72210000}],"checksum":953613225,"timestamp":"2024-06-01T17:51:53.568275Z"}]}
{"channel":"book","type":"update","data":[{"symbol":"EUR/USD","bids":[],"asks":[{"price":1.08446,"qty":0.00000000},{"price":1.08454,"qty":2830.45000000}],"checksum":3105255937,"timestamp":"2024-06-01T17:51:53.568461Z"}]}
{"channel":"book","type":"update","data":[{"symbol":"EUR/USD","bids":[],"asks":[{"price":1.08444,"qty":19563.37075927}],"checksum":835123471,"timestamp":"2024-06-01T17:51:53.570991Z"}]}
{"channel":"book","type":"update","data":[{"symbol":"EUR/USD","bids":[],"asks":[{"price":1.08445,"qty":0.00000000},{"price":1.08459,"qty":37680.75904456}],"checksum":3807790627,"timestamp":"2024-06-01T17:51:53.571381Z"}]}
{"channel":"book","type":"update","data":[{"symbol":"EUR/USD","bids":[{"price":1.08406,"qty":9.81218143},{"price":1.08408,"qty":3710.95437107}],"asks":[],"checksum":555169016,"timestamp":"2024-06-01T17:51:53.572825Z"}]}
{"channel":"book","type":"update","data":[{"symbol":"EUR/USD","bids":[{"price":1.08381,"qty":0.00000000},{"price":1.08353,"qty":2121.09597548},{"price":1.08406,"qty":1994.61218143}],"asks":[],"checksum":1377023067,"timestamp":"2024-06-01T17:51:53.597813Z"}]}
{"channel":"book","type":"update","data":[{"symbol":"EUR/USD","bids":[],"asks":[{"price":1.08443,"qty":2010.28417243}],"checksum":4279599780,"timestamp":"2024-06-01T17:51:53.601792Z"}]}
{"channel":"book","type":"update","data":[{"symbol":"EUR/USD","bids":[{"price":1.08408,"qty":3720.76655250}],"asks":[],"checksum":3411334286,"timestamp":"2024-06-01T17:51:53.732131Z"}]}
{"channel":"book","type":"update","data":[{"symbol":"EUR/USD","bids":[{"price":1.08406,"qty":1984.80000000}],"asks":[],"checksum":16493345,"timestamp":"2024-06-01T17:51:53.896066Z"}]}
{"channel":"book","type":"update","data":[{"symbol":"EUR/USD","bids":[{"price":1.08408,"qty":9.81218143},{"price":1.08407,"qty":6897.85032124}],"asks":[],"checksum":2888250119,"timestamp":"2024-06-01T17:51:54.051554Z"}]}
{"channel":"book","type":"update","data":[{"symbol":"EUR/USD","bids":[{"price":1.08356,"qty":23.07209568}],"asks":[],"checksum":151018927,"timestamp":"2024-06-01T17:51:54.513028Z"}]}
{"channel":"book","type":"update","data":[{"symbol":"EUR/USD","bids":[{"price":1.08407,"qty":3186.86171849},{"price":1.08408,"qty":3720.76655250}],"asks":[],"checksum":3639124784,"timestamp":"2024-06-01T17:51:54.679043Z"}]}
{"channel":"book","type":"update","data":[{"symbol":"EUR/USD","bids":[{"price":1.08408,"qty":9.81218143},{"price":1.08407,"qty":6897.85032124}],"asks":[],"checksum":151018927,"timestamp":"2024-06-01T17:51:54.928052Z"}]}
{"channel":"book","type":"update","data":[{"symbol":"EUR/USD","bids":[{"price":1.08407,"qty":3186.86171849},{"price":1.08408,"qty":3720.76655250}],"asks":[],"checksum":3639124784,"timestamp":"2024-06-01T17:51:54.946318Z"}]}
{"channel":"book","type":"update","data":[{"symbol":"EUR/USD","bids":[{"price":1.08408,"qty":9.81218143},{"price":1.08356,"qty":3735.80735223}],"asks":[],"checksum":3454621124,"timestamp":"2024-06-01T17:51:54.950304Z"}]}
{"channel":"book","type":"update","data":[{"symbol":"EUR/USD","bids":[{"price":1.08356,"qty":23.07209568},{"price":1.08408,"qty":3720.76655250}],"asks":[],"checksum":3639124784,"timestamp":"2024-06-01T17:51:54.955790Z"}]}
{"channel":"book","type":"update","data":[{"symbol":"EUR/USD","bids":[{"price":1.08356,"qty":2111.05534080}],"asks":[],"checksum":4244714124,"timestamp":"2024-06-01T17:51:55.482579Z"}]}
{"channel":"book","type":"update","data":[{"symbol":"EUR/USD","bids":[{"price":1.08408,"qty":9.81218143},{"price":1.08407,"qty":6897.85032124}],"asks":[],"checksum":1373481642,"timestamp":"2024-06-01T17:51:55.496083Z"}]}
{"channel":"book","type":"update","data":[{"symbol":"EUR/USD","bids":[{"price":1.08407,"qty":3186.86171849},{"price":1.08408,"qty":3720.76655250}],"asks":[],"checksum":4244714124,"timestamp":"2024-06-01T17:51:55.499415Z"}]}
{"channel":"book","type":"update","data":[{"symbol":"EUR/USD","bids":[],"asks":[{"price":1.08434,"qty":0.00000000},{"price":1.08459,"qty":37680.75904456}],"checksum":3668193936,"timestamp":"2024-06-01T17:51:55.568208Z"}]}
{"channel":"book","type":"update","data":[{"symbol":"EUR/USD","bids":[],"asks":[{"price":1.08444,"qty":18133.30490842}],"checksum":987409020,"timestamp":"2024-06-01T17:51:55.568254Z"}]}
{"channel":"book","type":"update","data":[{"symbol":"EUR/USD","bids":[],"asks":[{"price":1.08442,"qty":492.21000218}],"checksum":630505006,"timestamp":"2024-06-01T17:51:55.572953Z"}]}
{"channel":"book","type":"update","data":[{"symbol":"EUR/USD","bids":[],"asks":[{"price":1.08443,"qty":3055.56416763}],"checksum":1433919569,"timestamp":"2024-06-01T17:51:55.573136Z"}]}
{"channel":"book","type":"update","data":[{"symbol":"EUR/USD","bids":[],"asks":[{"price":1.08444,"qty":0.00000000},{"price":1.08459,"qty":37680.75904456}],"checksum":2199216149,"timestamp":"2024-06-01T17:51:55.906622Z"}]}
{"channel":"book","type":"update","data":[{"symbol":"EUR/USD","bids":[],"asks":[{"price":1.08442,"qty":16996.56039926}],"checksum":1410545330,"timestamp":"2024-06-01T17:51:55.908666Z"}]}
{"channel":"book","type":"update","data":[{"symbol":"EUR/USD","bids":[],"asks":[{"price":1.08443,"qty":1045.27999520},{"price":1.08458,"qty":2010.28417243}],"checksum":620092875,"timestamp":"2024-06-01T17:51:55.910081Z"}]}
{"channel":"book","type":"update","data":[{"symbol":"EUR/USD","bids":[{"price":1.08354,"qty":0.00000000},{"price":1.08350,"qty":962.24087722}],"asks":[],"checksum":2462316666,"timestamp":"2024-06-01T17:51:56.021540Z"}]}
{"channel":"book","type":"update","data":[{"symbol":"EUR/USD","bids":[{"price":1.08407,"qty":0.00000000},{"price":1.08346,"qty":2830.45000000}],"asks":[],"checksum":2563713894,"timestamp":"2024-06-01T17:51:56.021612Z"}]}
{"channel":"book","type":"update","data":[{"symbol":"EUR/USD","bids":[{"price":1.08355,"qty":0.00000000},{"price":1.08343,"qty":4614.93708204}],"asks":[],"checksum":320260989,"timestamp":"2024-06-01T17:51:56.025019Z"}]}
{"channel":"book","type":"update","data":[{"symbol":"EUR/USD","bids":[],"asks":[{"price":1.08458,"qty":0.00000000},{"price":1.08459,"qty":37680.75904456},{"price":1.08438,"qty":2461.78609059}],"checksum":56728583,"timestamp":"2024-06-01T17:51:56.025254Z"}]}
{"channel":"book","type":"update","data":[{"symbol":"EUR/USD","bids":[{"price":1.08408,"qty":9.81218143},{"price":1.08407,"qty":3710.98860275}],"asks":[],"checksum":3868285386,"timestamp":"2024-06-01T17:51:56.025946Z"}]}
{"channel":"book","type":"update","data":[{"symbol":"EUR/USD","bids":[{"price":1.08409,"qty":1843.75979497}],"asks":[],"checksum":1093032679,"timestamp":"2024-06-01T17:51:56.026876Z"}]}
{"channel":"book","type":"update","data":[{"symbol":"EUR/USD","bids":[{"price":1.08356,"qty":85383.37459895}],"asks":[],"checksum":1079872776,"timestamp":"2024-06-01T17:51:56.026907Z"}]}
{"channel":"book","type":"update","data":[{"symbol":"EUR/USD","bids":[{"price":1.08357,"qty":16662.23582757}],"asks":[],"checksum":3028124803,"timestamp":"2024-06-01T17:51:56.056245Z"}]}
{"channel":"book","type":"update","data":[{"symbol":"EUR/USD","bids":[{"price":1.08356,"qty":85360.30250327},{"price":1.08357,"qty":16685.30771032}],"asks":[],"checksum":3874988555,"timestamp":"2024-06-01T17:51:56.680224Z"}]}
{"channel":"book","type":"update","data":[{"symbol":"EUR/USD","bids":[],"asks":[{"price":1.08442,"qty":16504.35039708}],"checksum":3713803136,"timestamp":"2024-06-01T17:51:57.712263Z"}]}
{"channel":"book","type":"update","data":[{"symbol":"EUR/USD","bids":[],"asks":[{"price":1.08443,"qty":0.00000000},{"price":1.08460,"qty":4167.00000000}],"checksum":1518565831,"timestamp":"2024-06-01T17:51:57.712330Z"}]}
{"channel":"book","type":"update","data":[{"symbol":"EUR/USD","bids":[],"asks":[{"price":1.08437,"qty":162.00499317}],"checksum":2539658528,"timestamp":"2024-06-01T17:51:57.717656Z"}]}
{"channel":"book","type":"update","data":[{"symbol":"EUR/USD","bids":[],"asks":[{"price":1.08458,"qty":871.19655368}],"checksum":1617311862,"timestamp":"2024-06-01T17:51:57.717671Z"}]}
{"channel":"book","type":"update","data":[{"symbol":"EUR/USD","bids":[],"asks":[{"price":1.08441,"qty":434.78304409}],"checksum":2884291955,"timestamp":"2024-06-01T17:51:57.717863Z"}]}
{"channel":"book","type":"update","data":[{"symbol":"EUR/USD","bids":[{"price":1.08356,"qty":83272.31925815}],"asks":[],"checksum":3293970096,"timestamp":"2024-06-01T17:51:58.008889Z"}]}
{"channel":"book","type":"update","data":[{"symbol":"EUR/USD","bids":[{"price":1.08358,"qty":2104.53961030}],"asks":[],"checksum":1871616540,"timestamp":"2024-06-01T17:51:58.013096Z"}]}
{"channel":"book","type":"update","data":[{"symbol":"EUR/USD","bids":[{"price":1.08407,"qty":0.00000000},{"price":1.08356,"qty":83272.31925815},{"price":1.08406,"qty":5695.82283507}],"asks":[],"checksum":1234498489,"timestamp":"2024-06-01T17:51:58.218137Z"}]}
{"channel":"book","type":"update","data":[{"symbol":"EUR/USD","bids":[{"price":1.08406,"qty":1984.80000000},{"price":1.08407,"qty":3710.98860275}],"asks":[],"checksum":1871616540,"timestamp":"2024-06-01T17:51:58.280515Z"}]}
{"channel":"book","type":"update","data":[{"symbol":"EUR/USD","bids":[],"asks":[{"price":1.08442,"qty":0.00000000},{"price":1.08458,"qty":871.19655368}],"checksum":2786191936,"timestamp":"2024-06-01T17:51:58.461020Z"}]}
{"channel":"book","type":"update","data":[{"symbol":"EUR/USD","bids":[],"asks":[{"price":1.08437,"qty":6892.62832218}],"checksum":3976664123,"timestamp":"2024-06-01T17:51:58.462967Z"}]}
{"channel":"book","type":"update","data":[{"symbol":"EUR/USD","bids":[],"asks":[{"price":1.08446,"qty":14875.39588573}],"checksum":842461317,"timestamp":"2024-06-01T17:51:58.463179Z"}]}
{"channel":"book","type":"update","data":[{"symbol":"EUR/USD","bids":[],"asks":[{"price":1.08438,"qty":451.50191816}],"checksum":1427180575,"timestamp":"2024-06-01T17:51:58.464286Z"}]}
{"channel":"book","type":"update","data":[{"symbol":"EUR/USD","bids":[],"asks":[{"price":1.08436,"qty":2010.28417243}],"checksum":2327742983,"timestamp":"2024-06-01T17:51:58.513501Z"}]}
{"channel":"book","type":"update","data":[{"symbol":"EUR/USD","bids":[{"price":1.08357,"qty":16662.23582757},{"price":1.08358,"qty":2127.61128013}],"asks":[],"checksum":77802152,"timestamp":"2024-06-01T17:51:58.551808Z"}]}
{"channel":"book","type":"update","data":[{"symbol":"EUR/USD","bids":[{"price":1.08407,"qty":0.00000000},{"price":1.08356,"qty":83272.31925815},{"price":1.08406,"qty":5695.82283507}],"asks":[],"checksum":3064155470,"timestamp":"2024-06-01T17:51:58.568073Z"}]}
{"channel":"book","type":"update","data":[{"symbol":"EUR/USD","bids":[{"price":1.08406,"qty":1984.80000000},{"price":1.08407,"qty":3710.98860275}],"asks":[],"checksum":77802152,"timestamp":"2024-06-01T17:51:58.573060Z"}]}
{"channel":"book","type":"update","data":[{"symbol":"EUR/USD","bids":[{"price":1.08407,"qty":0.00000000},{"price":1.08356,"qty":83272.31925815},{"price":1.08406,"qty":5695.82283507}],"asks":[],"checksum":3064155470,"timestamp":"2024-06-01T17:51:58.845677Z"}]}
{"channel":"book","type":"update","data":[{"symbol":"EUR/USD","bids":[{"price":1.08356,"qty":0.00000000},{"price":1.08350,"qty":962.24087722}],"asks":[],"checksum":2651162114,"timestamp":"2024-06-01T17:51:59.621090Z"}]}
{"channel":"book","type":"update","data":[{"symbol":"EUR/USD","bids":[{"price":1.08409,"qty":0.00000000},{"price":1.08346,"qty":2830.45000000}],"asks":[],"checksum":443038175,"timestamp":"2024-06-01T17:51:59.621136Z"}]}
{"channel":"book","type":"update","data":[{"symbol":"EUR/USD","bids":[{"price":1.08357,"qty":0.00000000},{"price":1.08343,"qty":4614.93708204}],"asks":[],"checksum":3348327059,"timestamp":"2024-06-01T17:51:59.624428Z"}]}
{"channel":"book","type":"update","data":[{"symbol":"EUR/USD","bids":[{"price":1.08359,"qty":79204.32060992}],"asks":[],"checksum":4287303115,"timestamp":"2024-06-01T17:51:59.625832Z"}]}
{"channel":"book","type":"update","data":[{"symbol":"EUR/USD","bids":[{"price":1.08407,"qty":4529.96364201}],"asks":[],"checksum":883475308,"timestamp":"2024-06-01T17:51:59.625894Z"}]}
{"channel":"book","type":"update","data":[{"symbol":"EUR/USD","bids":[{"price":1.08406,"qty":1984.80000000},{"price":1.08360,"qty":3712.59820468}],"asks":[],"checksum":3968182769,"timestamp":"2024-06-01T17:51:59.630086Z"}]}
{"channel":"book","type":"update","data":[{"symbol":"EUR/USD","bids":[{"price":1.08360,"qty":0.00000000},{"price":1.08350,"qty":962.24087722},{"price":1.08406,"qty":5695.82283507}],"asks":[],"checksum":883475308,"timestamp":"2024-06-01T17:51:59.633829Z"}]}
{"channel":"book","type":"update","data":[{"symbol":"EUR/USD","bids":[{"price":1.08406,"qty":1984.80000000},{"price":1.08360,"qty":3712.59820468}],"asks":[],"checksum":3968182769,"timestamp":"2024-06-01T17:51:59.637472Z"}]}
{"channel":"book","type":"update","data":[{"symbol":"EUR/USD","bids":[{"price":1.08408,"qty":0.00000000},{"price":1.08350,"qty":962.24087722},{"price":1.08407,"qty":4448.60847123}],"asks":[],"checksum":2928222636,"timestamp":"2024-06-01T17:51:59.660339Z"}]}
{"channel":"book","type":"update","data":[{"symbol":"EUR/USD","bids":[],"asks":[{"price":1.08453,"qty":0.00000000},{"price":1.08454,"qty":2830.45000000}],"checksum":3118798302,"timestamp":"2024-06-01T17:51:59.660532Z"}]}
{"channel":"book","type":"update","data":[{"symbol":"EUR/USD","bids":[],"asks":[{"price":1.08436,"qty":2236.00627243}],"checksum":2785151342,"timestamp":"2024-06-01T17:51:59.660702Z"}]}
{"channel":"book","type":"update","data":[{"symbol":"EUR/USD","bids":[{"price":1.08361,"qty":16662.23582757}],"asks":[],"checksum":569278106,"timestamp":"2024-06-01T17:51:59.663710Z"}]}
{"channel":"book","type":"update","data":[{"symbol":"EUR/USD","bids":[{"price":1.08360,"qty":0.00000000},{"price":1.08350,"qty":962.24087722},{"price":1.08381,"qty":3711.87884831}],"asks":[],"checksum":2291563801,"timestamp":"2024-06-01T17:51:59.664638Z"}]}
{"channel":"book","type":"update","data":[{"symbol":"EUR/USD","bids":[{"price":1.08407,"qty":4401.75687123}],"asks":[],"checksum":4345568,"timestamp":"2024-06-01T17:51:59.665017Z"}]}
{"channel":"book","type":"update","data":[{"symbol":"EUR/USD","bids":[{"price":1.08380,"qty":0.00000000},{"price":1.08350,"qty":962.24087722}],"asks":[],"checksum":1120972253,"timestamp":"2024-06-01T17:51:59.672769Z"}]}
{"channel":"book","type":"update","data":[{"symbol":"EUR/USD","bids":[],"asks":[{"price":1.08436,"qty":2010.28417243}],"checksum":2987671757,"timestamp":"2024-06-01T17:51:59.672846Z"}]}
{"channel":"book","type":"update","data":[{"symbol":"EUR/USD","bids":[{"price":1.08382,"qty":631.30582304}],"asks":[],"checksum":3773804205,"timestamp":"2024-06-01T17:51:59.672970Z"}]}
{"channel":"book","type":"update","data":[{"symbol":"EUR/USD","bids":[],"asks":[{"price":1.08453,"qty":225.72210000}],"checksum":3696383488,"timestamp":"2024-06-01T17:51:59.673093Z"}]}
{"channel":"book","type":"update","data":[{"symbol":"EUR/USD","bids":[{"price":1.08381,"qty":0.00000000},{"price":1.08350,"qty":962.24087722},{"price":1.08379,"qty":3711.94734643}],"asks":[],"checksum":1444424320,"timestamp":"2024-06-01T17:51:59.676085Z"}]}
{"channel":"book","type":"update","data":[{"symbol":"EUR/USD","bids":[],"asks":[{"price":1.08420,"qty":451.50191816}],"checksum":1783871873,"timestamp":"2024-06-01T17:51:59.788003Z"}]}
{"channel":"book","type":"update","data":[{"symbol":"EUR/USD","bids":[],"asks":[{"price":1.08421,"qty":0.00000000},{"price":1.08453,"qty":225.72210000},{"price":1.08419,"qty":1860.23278117}],"checksum":2340572284,"timestamp":"2024-06-01T17:51:59.797197Z"}]}
{"channel":"book","type":"update","data":[{"symbol":"EUR/USD","bids":[{"price":1.08406,"qty":0.00000000},{"price":1.08350,"qty":962.24087722},{"price":1.08383,"qty":1984.80000000}],"asks":[],"checksum":1153850678,"timestamp":"2024-06-01T17:51:59.821424Z"}]}
{"channel":"book","type":"update","data":[{"symbol":"EUR/USD","bids":[{"price":1.08379,"qty":0.00000000},{"price":1.08350,"qty":962.24087722},{"price":1.08406,"qty":3711.02283507}],"asks":[],"checksum":2161680551,"timestamp":"2024-06-01T17:51:59.824450Z"}]}
{"channel":"book","type":"update","data":[{"symbol":"EUR/USD","bids":[{"price":1.08382,"qty":0.00000000},{"price":1.08350,"qty":962.24087722}],"asks":[],"checksum":1118661710,"timestamp":"2024-06-01T17:51:59.833199Z"}]}
{"channel":"book","type":"update","data":[{"symbol":"EUR/USD","bids":[{"price":1.08379,"qty":631.32327389}],"asks":[],"checksum":1957599636,"timestamp":"2024-06-01T17:51:59.833226Z"}]}
{"channel":"book","type":"update","data":[{"symbol":"EUR/USD","bids":[],"asks":[{"price":1.08441,"qty":0.00000000},{"price":1.08453,"qty":225.72210000}],"checksum":1843835498,"timestamp":"2024-06-01T17:51:59.962164Z"}]}
{"channel":"book","type":"update","data":[{"symbol":"EUR/USD","bids":[],"asks":[{"price":1.08437,"qty":6730.62332901}],"checksum":588962921,"timestamp":"2024-06-01T17:51:59.962181Z"}]}
{"channel":"book","type":"update","data":[{"symbol":"EUR/USD","bids":[],"asks":[{"price":1.08435,"qty":160.77341955}],"checksum":1808298077,"timestamp":"2024-06-01T17:51:59.966910Z"}]}
{"channel":"book","type":"update","data":[{"symbol":"EUR/USD","bids":[],"asks":[{"price":1.08445,"qty":1303.09556675}],"checksum":603415238,"timestamp":"2024-06-01T17:51:59.966922Z"}]}
{"channel":"book","type":"update","data":[{"symbol":"EUR/USD","bids":[],"asks":[{"price":1.08438,"qty":0.00000000},{"price":1.08447,"qty":4610.55811950}],"checksum":1406800432,"timestamp":"2024-06-01T17:51:59.971677Z"}]}
{"channel":"book","type":"update","data":[{"symbol":"EUR/USD","bids":[{"price":1.08406,"qty":0.00000000},{"price":1.08350,"qty":962.24087722},{"price":1.08408,"qty":3710.95437107}],"asks":[],"checksum":2638789689,"timestamp":"2024-06-01T17:52:00.218847Z"}]}
{"channel":"book","type":"update","data":[{"symbol":"EUR/USD","bids":[{"price":1.08358,"qty":23.07166983}],"asks":[],"checksum":3669698414,"timestamp":"2024-06-01T17:52:00.553991Z"}]}
{"channel":"book","type":"update","data":[{"symbol":"EUR/USD","bids":[{"price":1.08362,"qty":2087.98324512}],"asks":[],"checksum":2633018182,"timestamp":"2024-06-01T17:52:00.559506Z"}]}
{"channel":"book","type":"update","data":[{"symbol":"EUR/USD","bids":[{"price":1.08362,"qty":2111.05406330}],"asks":[],"checksum":464108411,"timestamp":"2024-06-01T17:52:00.717308Z"}]}
{"channel":"book","type":"update","data":[{"symbol":"EUR/USD","bids":[],"asks":[{"price":1.08437,"qty":0.00000000},{"price":1.08453,"qty":225.72210000}],"checksum":449128480,"timestamp":"2024-06-01T17:52:00.841066Z"}]}
{"channel":"book","type":"update","data":[{"symbol":"EUR/USD","bids":[],"asks":[{"price":1.08446,"qty":0.00000000},{"price":1.08454,"qty":2830.45000000}],"checksum":698167404,"timestamp":"2024-06-01T17:52:00.841079Z"}]}
{"channel":"book","type":"update","data":[{"symbol":"EUR/USD","bids":[],"asks":[{"price":1.08444,"qty":14876.39750113}],"checksum":766673180,"timestamp":"2024-06-01T17:52:00.842949Z"}]}
{"channel":"book","type":"update","data":[{"symbol":"EUR/USD","bids":[],"asks":[{"price":1.08435,"qty":5262.69264106}],"checksum":1450761218,"timestamp":"2024-06-01T17:52:00.842960Z"}]}
{"channel":"book","type":"update","data":[{"symbol":"EUR/USD","bids":[],"asks":[{"price":1.08436,"qty":0.00000000},{"price":1.08454,"qty":2830.45000000}],"checksum":1419223994,"timestamp":"2024-06-01T17:52:00.844239Z"}]}
{"channel":"book","type":"update","data":[{"symbol":"EUR/USD","bids":[],"asks":[{"price":1.08443,"qty":2010.28417243}],"checksum":2568642474,"timestamp":"2024-06-01T17:52:00.887358Z"}]}
{"channel":"book","type":"update","data":[{"symbol":"EUR/USD","bids":[],"asks":[{"price":1.08435,"qty":5101.91922151}],"checksum":468286052,"timestamp":"2024-06-01T17:52:02.022811Z"}]}
{"channel":"book","type":"update","data":[{"symbol":"EUR/USD","bids":[],"asks":[{"price":1.08445,"qty":0.00000000},{"price":1.08454,"qty":2830.45000000}],"checksum":238133838,"timestamp":"2024-06-01T17:52:02.022985Z"}]}
{"channel":"book","type":"update","data":[{"symbol":"EUR/USD","bids":[],"asks":[{"price":1.08442,"qty":1186.95465620}],"checksum":2933956435,"timestamp":"2024-06-01T17:52:02.028214Z"}]}
{"channel":"book","type":"update","data":[{"symbol":"EUR/USD","bids":[],"asks":[{"price":1.08434,"qty":133.29151413}],"checksum":1534467537,"timestamp":"2024-06-01T17:52:02.028251Z"}]}
{"channel":"book","type":"update","data":[{"symbol":"EUR/USD","bids":[{"price":1.08359,"qty":0.00000000},{"price":1.08350,"qty":962.24087722}],"asks":[],"checksum":953447447,"timestamp":"2024-06-01T17:52:03.221876Z"}]}
{"channel":"book","type":"update","data":[{"symbol":"EUR/USD","bids":[{"price":1.08407,"qty":0.00000000},{"price":1.08346,"qty":2830.45000000}],"asks":[],"checksum":170672589,"timestamp":"2024-06-01T17:52:03.221896Z"}]}
{"channel":"book","type":"update","data":[{"symbol":"EUR/USD","bids":[{"price":1.08361,"qty":0.00000000},{"price":1.08343,"qty":4614.93708204}],"asks":[],"checksum":2662088629,"timestamp":"2024-06-01T17:52:03.225288Z"}]}
{"channel":"book","type":"update","data":[{"symbol":"EUR/USD","bids":[{"price":1.08408,"qty":0.00000000},{"price":1.08336,"qty":16662.23582757},{"price":1.08406,"qty":3711.02283507}],"asks":[],"checksum":3213557138,"timestamp":"2024-06-01T17:52:03.225563Z"}]}
{"channel":"book","type":"update","data":[{"symbol":"EUR/USD","bids":[{"price":1.08384,"qty":4529.83851742}],"asks":[],"checksum":2851536440,"timestamp":"2024-06-01T17:52:03.229500Z"}]}
{"channel":"book","type":"update","data":[{"symbol":"EUR/USD","bids":[{"price":1.08363,"qty":74672.10428123}],"asks":[],"checksum":953850392,"timestamp":"2024-06-01T17:52:03.229617Z"}]}
{"channel":"book","type":"update","data":[{"symbol":"EUR/USD","bids":[{"price":1.08409,"qty":1843.75979497}],"asks":[],"checksum":2923886972,"timestamp":"2024-06-01T17:52:03.230480Z"}]}
{"channel":"book","type":"update","data":[{"symbol":"EUR/USD","bids":[{"price":1.08383,"qty":0.00000000},{"price":1.08350,"qty":962.24087722},{"price":1.08385,"qty":1984.80000000}],"asks":[],"checksum":2695186387,"timestamp":"2024-06-01T17:52:03.246136Z"}]}
{"channel":"book","type":"update","data":[{"symbol":"EUR/USD","bids":[{"price":1.08364,"qty":16662.23582757}],"asks":[],"checksum":2024789501,"timestamp":"2024-06-01T17:52:03.260635Z"}]}
{"channel":"book","type":"update","data":[{"symbol":"EUR/USD","bids":[],"asks":[{"price":1.08435,"qty":0.00000000},{"price":1.08453,"qty":225.72210000}],"checksum":175153472,"timestamp":"2024-06-01T17:52:03.340447Z"}]}
{"channel":"book","type":"update","data":[{"symbol":"EUR/USD","bids":[],"asks":[{"price":1.08444,"qty":0.00000000},{"price":1.08454,"qty":2830.45000000}],"checksum":2374932889,"timestamp":"2024-06-01T17:52:03.340500Z"}]}
{"channel":"book","type":"update","data":[{"symbol":"EUR/USD","bids":[],"asks":[{"price":1.08438,"qty":5101.91922151}],"checksum":1283991092,"timestamp":"2024-06-01T17:52:03.342423Z"}]}
{"channel":"book","type":"update","data":[{"symbol":"EUR/USD","bids":[],"asks":[{"price":1.08441,"qty":14876.39750113}],"checksum":1233321857,"timestamp":"2024-06-01T17:52:03.342514Z"}]}
{"channel":"book","type":"update","data":[{"symbol":"EUR/USD","bids":[],"asks":[{"price":1.08443,"qty":0.00000000},{"price":1.08453,"qty":225.72210000}],"checksum":1521081441,"timestamp":"2024-06-01T17:52:03.343780Z"}]}
{"channel":"book","type":"update","data":[{"symbol":"EUR/USD","bids":[{"price":1.08385,"qty":0.00000000},{"price":1.08362,"qty":2111.05406330},{"price":1.08406,"qty":5695.82283507}],"asks":[],"checksum":713896184,"timestamp":"2024-06-01T17:52:03.369684Z"}]}
{"channel":"book","type":"update","data":[{"symbol":"EUR/USD","bids":[{"price":1.08406,"qty":1984.80000000},{"price":1.08407,"qty":3710.98860275}],"asks":[],"checksum":2309353010,"timestamp":"2024-06-01T17:52:03.372913Z"}]}
{"channel":"book","type":"update","data":[{"symbol":"EUR/USD","bids":[],"asks":[{"price":1.08437,"qty":2010.28417243}],"checksum":1558108379,"timestamp":"2024-06-01T17:52:03.786313Z"}]}
{"channel":"book","type":"update","data":[{"symbol":"EUR/USD","bids":[],"asks":[{"price":1.08434,"qty":0.00000000},{"price":1.08453,"qty":225.72210000}],"checksum":1197358029,"timestamp":"2024-06-01T17:52:04.281813Z"}]}
{"channel":"book","type":"update","data":[{"symbol":"EUR/USD","bids":[],"asks":[{"price":1.08442,"qty":0.00000000},{"price":1.08454,"qty":2830.45000000}],"checksum":2939243067,"timestamp":"2024-06-01T17:52:04.281827Z"}]}
{"channel":"book","type":"update","data":[{"symbol":"EUR/USD","bids":[],"asks":[{"price":1.08437,"qty":2430.71047700}],"checksum":2604779429,"timestamp":"2024-06-01T17:52:04.288349Z"}]}
{"channel":"book","type":"update","data":[{"symbol":"EUR/USD","bids":[{"price":1.08407,"qty":0.00000000},{"price":1.08362,"qty":2111.05406330},{"price":1.08410,"qty":3710.88590959}],"asks":[],"checksum":3106583335,"timestamp":"2024-06-01T17:52:04.538857Z"}]}
{"channel":"book","type":"update","data":[{"symbol":"EUR/USD","bids":[{"price":1.08365,"qty":23.07017948}],"asks":[],"checksum":2611807115,"timestamp":"2024-06-01T17:52:04.632758Z"}]}
{"channel":"book","type":"update","data":[{"symbol":"EUR/USD","bids":[{"price":1.08365,"qty":2084.37759862}],"asks":[],"checksum":3598400337,"timestamp":"2024-06-01T17:52:05.503804Z"}]}
{"channel":"book","type":"update","data":[{"symbol":"EUR/USD","bids":[],"asks":[{"price":1.08441,"qty":0.00000000},{"price":1.08458,"qty":906.26918234}],"checksum":407698657,"timestamp":"2024-06-01T17:52:05.700238Z"}]}
{"channel":"book","type":"update","data":[{"symbol":"EUR/USD","bids":[],"asks":[{"price":1.08438,"qty":0.00000000},{"price":1.08459,"qty":144187.96387732}],"checksum":14028414,"timestamp":"2024-06-01T17:52:05.700293Z"}]}
{"channel":"book","type":"update","data":[{"symbol":"EUR/USD","bids":[],"asks":[{"price":1.08459,"qty":0.00000000},{"price":1.08460,"qty":4167.00000000}],"checksum":897360039,"timestamp":"2024-06-01T17:52:05.700417Z"}]}
{"channel":"book","type":"update","data":[{"symbol":"EUR/USD","bids":[],"asks":[{"price":1.08446,"qty":16505.47721440}],"checksum":2498358683,"timestamp":"2024-06-01T17:52:05.702423Z"}]}
{"channel":"book","type":"update","data":[{"symbol":"EUR/USD","bids":[],"asks":[{"price":1.08436,"qty":5101.91922151}],"checksum":1325347778,"timestamp":"2024-06-01T17:52:05.702724Z"}]}
{"channel":"book","type":"update","data":[{"symbol":"EUR/USD","bids":[],"asks":[{"price":1.08437,"qty":420.42630457}],"checksum":3301699127,"timestamp":"2024-06-01T17:52:05.703729Z"}]}
{"channel":"book","type":"update","data":[{"symbol":"EUR/USD","bids":[],"asks":[{"price":1.08437,"qty":0.00000000},{"price":1.08458,"qty":2916.55335477}],"checksum":3440613044,"timestamp":"2024-06-01T17:52:06.438102Z"}]}
{"channel":"book","type":"update","data":[{"symbol":"EUR/USD","bids":[],"asks":[{"price":1.08458,"qty":2010.28417243}],"checksum":2207021093,"timestamp":"2024-06-01T17:52:06.438175Z"}]}
{"channel":"book","type":"update","data":[{"symbol":"EUR/USD","bids":[],"asks":[{"price":1.08445,"qty":1173.22882809}],"checksum":4053741536,"timestamp":"2024-06-01T17:52:06.443215Z"}]}
{"channel":"book","type":"update","data":[{"symbol":"EUR/USD","bids":[],"asks":[{"price":1.08435,"qty":118.93477461}],"checksum":261856692,"timestamp":"2024-06-01T17:52:06.443423Z"}]}
{"channel":"book","type":"update","data":[{"symbol":"EUR/USD","bids":[{"price":1.08384,"qty":0.00000000},{"price":1.08363,"qty":74672.10428123}],"asks":[],"checksum":299434258,"timestamp":"2024-06-01T17:52:06.899382Z"}]}
{"channel":"book","type":"update","data":[{"symbol":"EUR/USD","bids":[{"price":1.08363,"qty":0.00000000},{"price":1.08350,"qty":962.24087722}],"asks":[],"checksum":70857715,"timestamp":"2024-06-01T17:52:06.899407Z"}]}
{"channel":"book","type":"update","data":[{"symbol":"EUR/USD","bids":[{"price":1.08409,"qty":0.00000000},{"price":1.08346,"qty":2830.45000000}],"asks":[],"checksum":968668305,"timestamp":"2024-06-01T17:52:06.899525Z"}]}
{"channel":"book","type":"update","data":[{"symbol":"EUR/USD","bids":[{"price":1.08410,"qty":0.00000000},{"price":1.08343,"qty":4614.93708204},{"price":1.08407,"qty":3710.98860275}],"asks":[],"checksum":1425775943,"timestamp":"2024-06-01T17:52:06.903254Z"}]}
{"channel":"book","type":"update","data":[{"symbol":"EUR/USD","bids":[{"price":1.08364,"qty":0.00000000},{"price":1.08343,"qty":4614.93708204}],"asks":[],"checksum":1560274017,"timestamp":"2024-06-01T17:52:06.903335Z"}]}
{"channel":"book","type":"update","data":[{"symbol":"EUR/USD","bids":[],"asks":[{"price":1.08435,"qty":2129.21894704}],"checksum":4185644633,"timestamp":"2024-06-01T17:52:06.904064Z"}]}
{"channel":"book","type":"update","data":[{"symbol":"EUR/USD","bids":[{"price":1.08380,"qty":4529.83851742}],"asks":[],"checksum":4170074065,"timestamp":"2024-06-01T17:52:06.904541Z"}]}
{"channel":"book","type":"update","data":[{"symbol":"EUR/USD","bids":[{"price":1.08366,"qty":73831.09691564}],"asks":[],"checksum":1254290397,"timestamp":"2024-06-01T17:52:06.904654Z"}]}
{"channel":"book","type":"update","data":[{"symbol":"EUR/USD","bids":[{"price":1.08379,"qty":0.00000000},{"price":1.08346,"qty":2830.45000000}],"asks":[],"checksum":675226771,"timestamp":"2024-06-01T17:52:06.922004Z"}]}
{"channel":"book","type":"update","data":[{"symbol":"EUR/USD","bids":[{"price":1.08381,"qty":631.31157675}],"asks":[],"checksum":2922388693,"timestamp":"2024-06-01T17:52:06.922187Z"}]}
{"channel":"book","type":"update","data":[{"symbol":"EUR/USD","bids":[{"price":1.08406,"qty":0.00000000},{"price":1.08346,"qty":2830.45000000},{"price":1.08382,"qty":1984.80000000}],"asks":[],"checksum":1878438540,"timestamp":"2024-06-01T17:52:06.945290Z"}]}
{"channel":"book","type":"update","data":[{"symbol":"EUR/USD","bids":[{"price":1.08407,"qty":0.00000000},{"price":1.08346,"qty":2830.45000000},{"price":1.08406,"qty":3711.02283507}],"asks":[],"checksum":1419057987,"timestamp":"2024-06-01T17:52:06.948345Z"}]}
{"channel":"book","type":"update","data":[{"symbol":"EUR/USD","bids":[{"price":1.08367,"qty":16662.23582757}],"asks":[],"checksum":2431056551,"timestamp":"2024-06-01T17:52:06.948372Z"}]}
{"channel":"book","type":"update","data":[{"symbol":"EUR/USD","bids":[{"price":1.08365,"qty":23.07017948}],"asks":[],"checksum":1594389999,"timestamp":"2024-06-01T17:52:08.210832Z"}]}
{"channel":"book","type":"update","data":[{"symbol":"EUR/USD","bids":[{"price":1.08383,"qty":134.33215419}],"asks":[],"checksum":1302724214,"timestamp":"2024-06-01T17:52:08.215113Z"}]}
{"channel":"book","type":"update","data":[{"symbol":"EUR/USD","bids":[{"price":1.08368,"qty":1950.31233174}],"asks":[],"checksum":3764035258,"timestamp":"2024-06-01T17:52:08.215296Z"}]}
{"channel":"book","type":"update","data":[{"symbol":"EUR/USD","bids":[],"asks":[{"price":1.08436,"qty":0.00000000},{"price":1.08454,"qty":2830.45000000}],"checksum":285658531,"timestamp":"2024-06-01T17:52:08.236496Z"}]}
{"channel":"book","type":"update","data":[{"symbol":"EUR/USD","bids":[],"asks":[{"price":1.08446,"qty":0.00000000},{"price":1.08460,"qty":4167.00000000}],"checksum":2398518418,"timestamp":"2024-06-01T17:52:08.236522Z"}]}
{"channel":"book","type":"update","data":[{"symbol":"EUR/USD","bids":[],"asks":[{"price":1.08435,"qty":118.93477461}],"checksum":728909482,"timestamp":"2024-06-01T17:52:08.239900Z"}]}
{"channel":"book","type":"update","data":[{"symbol":"EUR/USD","bids":[],"asks":[{"price":1.08434,"qty":3472.87040868}],"checksum":3761637528,"timestamp":"2024-06-01T17:52:08.241160Z"}]}
{"channel":"book","type":"update","data":[{"symbol":"EUR/USD","bids":[],"asks":[{"price":1.08444,"qty":14876.64470462}],"checksum":134206846,"timestamp":"2024-06-01T17:52:08.241311Z"}]}
{"channel":"book","type":"update","data":[{"symbol":"EUR/USD","bids":[{"price":1.08382,"qty":0.00000000},{"price":1.08366,"qty":73831.09691564},{"price":1.08407,"qty":1984.80000000}],"asks":[],"checksum":3557346053,"timestamp":"2024-06-01T17:52:08.249024Z"}]}
{"channel":"book","type":"update","data":[{"symbol":"EUR/USD","bids":[{"price":1.08406,"qty":0.00000000},{"price":1.08366,"qty":73831.09691564},{"price":1.08408,"qty":3710.95437107}],"asks":[],"checksum":1456614035,"timestamp":"2024-06-01T17:52:08.252721Z"}]}
{"channel":"book","type":"update","data":[{"symbol":"EUR/USD","bids":[],"asks":[{"price":1.08443,"qty":2010.28417243}],"checksum":1900066395,"timestamp":"2024-06-01T17:52:08.286953Z"}]}
{"channel":"book","type":"update","data":[{"symbol":"EUR/USD","bids":[],"asks":[{"price":1.08445,"qty":0.00000000},{"price":1.08453,"qty":225.72210000}],"checksum":905763692,"timestamp":"2024-06-01T17:52:08.691085Z"}]}
{"channel":"book","type":"update","data":[{"symbol":"EUR/USD","bids":[],"asks":[{"price":1.08435,"qty":0.00000000},{"price":1.08454,"qty":2830.45000000}],"checksum":685892806,"timestamp":"2024-06-01T17:52:08.691206Z"}]}
{"channel":"book","type":"update","data":[{"symbol":"EUR/USD","bids":[{"price":1.08407,"qty":0.00000000},{"price":1.08366,"qty":73831.09691564},{"price":1.08409,"qty":1984.80000000}],"asks":[],"checksum":667447926,"timestamp":"2024-06-01T17:52:08.706252Z"}]}
{"channel":"book","type":"update","data":[{"symbol":"EUR/USD","bids":[{"price":1.08408,"qty":0.00000000},{"price":1.08366,"qty":73831.09691564},{"price":1.08410,"qty":3710.88590959}],"asks":[],"checksum":2127306958,"timestamp":"2024-06-01T17:52:08.710876Z"}]}
{"channel":"book","type":"update","data":[{"symbol":"EUR/USD","bids":[],"asks":[{"price":1.08434,"qty":3606.16192304}],"checksum":2016749743,"timestamp":"2024-06-01T17:52:08.733591Z"}]}
{"channel":"book","type":"update","data":[{"symbol":"EUR/USD","bids":[],"asks":[{"price":1.08445,"qty":1215.55597572}],"checksum":1687178050,"timestamp":"2024-06-01T17:52:08.733802Z"}]}
{"channel":"book","type":"update","data":[{"symbol":"EUR/USD","bids":[{"price":1.08368,"qty":1973.38187256}],"asks":[],"checksum":3131387361,"timestamp":"2024-06-01T17:52:08.769329Z"}]}
{"channel":"book","type":"update","data":[{"symbol":"EUR/USD","bids":[{"price":1.08409,"qty":0.00000000},{"price":1.08366,"qty":73831.09691564},{"price":1.08406,"qty":1984.80000000}],"asks":[],"checksum":47854621,"timestamp":"2024-06-01T17:52:08.800767Z"}]}
{"channel":"book","type":"update","data":[{"symbol":"EUR/USD","bids":[{"price":1.08410,"qty":0.00000000},{"price":1.08366,"qty":73831.09691564},{"price":1.08407,"qty":3710.98860275}],"asks":[],"checksum":1872567755,"timestamp":"2024-06-01T17:52:08.804748Z"}]}
{"channel":"book","type":"update","data":[{"symbol":"EUR/USD","bids":[{"price":1.08380,"qty":0.00000000},{"price":1.08366,"qty":73831.09691564}],"asks":[],"checksum":3143181564,"timestamp":"2024-06-01T17:52:10.505024Z"}]}
{"channel":"book","type":"update","data":[{"symbol":"EUR/USD","bids":[{"price":1.08366,"qty":0.00000000},{"price":1.08350,"qty":962.24087722}],"asks":[],"checksum":3118595230,"timestamp":"2024-06-01T17:52:10.505085Z"}]}
{"channel":"book","type":"update","data":[{"symbol":"EUR/USD","bids":[{"price":1.08367,"qty":0.00000000},{"price":1.08346,"qty":2830.45000000}],"asks":[],"checksum":3495620213,"timestamp":"2024-06-01T17:52:10.508725Z"}]}
{"channel":"book","type":"update","data":[{"symbol":"EUR/USD","bids":[{"price":1.08408,"qty":4529.83851742}],"asks":[],"checksum":2672639112,"timestamp":"2024-06-01T17:52:10.509840Z"}]}
{"channel":"book","type":"update","data":[{"symbol":"EUR/USD","bids":[{"price":1.08369,"qty":63898.27924924}],"asks":[],"checksum":576986290,"timestamp":"2024-06-01T17:52:10.509970Z"}]}
{"channel":"book","type":"update","data":[{"symbol":"EUR/USD","bids":[{"price":1.08379,"qty":7215.91723986}],"asks":[],"checksum":3454088772,"timestamp":"2024-06-01T17:52:10.510021Z"}]}
{"channel":"book","type":"update","data":[{"symbol":"EUR/USD","bids":[{"price":1.08407,"qty":0.00000000},{"price":1.08368,"qty":1973.38187256},{"price":1.08409,"qty":3710.92014001}],"asks":[],"checksum":677816480,"timestamp":"2024-06-01T17:52:10.514241Z"}]}
{"channel":"book","type":"update","data":[{"symbol":"EUR/USD","bids":[{"price":1.08370,"qty":16662.23582757}],"asks":[],"checksum":3704114743,"timestamp":"2024-06-01T17:52:10.586520Z"}]}
{"channel":"book","type":"update","data":[{"symbol":"EUR/USD","bids":[],"asks":[{"price":1.08433,"qty":456.40800888}],"checksum":858197947,"timestamp":"2024-06-01T17:52:10.687522Z"}]}
{"channel":"book","type":"update","data":[{"symbol":"EUR/USD","bids":[],"asks":[{"price":1.08434,"qty":133.29151436}],"checksum":3491281795,"timestamp":"2024-06-01T17:52:10.724026Z"}]}
{"channel":"book","type":"update","data":[{"symbol":"EUR/USD","bids":[],"asks":[{"price":1.08444,"qty":0.00000000},{"price":1.08453,"qty":225.72210000}],"checksum":3774191293,"timestamp":"2024-06-01T17:52:10.724041Z"}]}
{"channel":"book","type":"update","data":[{"symbol":"EUR/USD","bids":[],"asks":[{"price":1.08442,"qty":16505.75531833}],"checksum":3434667246,"timestamp":"2024-06-01T17:52:10.725733Z"}]}
{"channel":"book","type":"update","data":[{"symbol":"EUR/USD","bids":[],"asks":[{"price":1.08434,"qty":0.00000000},{"price":1.08453,"qty":225.72210000}],"checksum":2045310027,"timestamp":"2024-06-01T17:52:10.838532Z"}]}
{"channel":"book","type":"update","data":[{"symbol":"EUR/USD","bids":[],"asks":[{"price":1.08445,"qty":0.00000000},{"price":1.08454,"qty":2830.45000000}],"checksum":1699583910,"timestamp":"2024-06-01T17:52:10.838585Z"}]}
{"channel":"book","type":"update","data":[{"symbol":"EUR/USD","bids":[],"asks":[{"price":1.08443,"qty":0.00000000},{"price":1.08459,"qty":37684.19329650},{"price":1.08441,"qty":2010.28417243}],"checksum":54290576,"timestamp":"2024-06-01T17:52:10.841738Z"}]}
{"channel":"book","type":"update","data":[{"symbol":"EUR/USD","bids":[],"asks":[{"price":1.08442,"qty":17868.31365167}],"checksum":1436694314,"timestamp":"2024-06-01T17:52:10.844588Z"}]}
{"channel":"book","type":"update","data":[{"symbol":"EUR/USD","bids":[],"asks":[{"price":1.08433,"qty":503.55908593}],"checksum":2953888444,"timestamp":"2024-06-01T17:52:10.844650Z"}]}
{"channel":"book","type":"update","data":[{"symbol":"EUR/USD","bids":[],"asks":[{"price":1.08420,"qty":0.00000000},{"price":1.08459,"qty":37684.19329650}],"checksum":1049085401,"timestamp":"2024-06-01T17:52:10.853463Z"}]}
{"channel":"book","type":"update","data":[{"symbol":"EUR/USD","bids":[],"asks":[{"price":1.08419,"qty":0.00000000},{"price":1.08460,"qty":4167.00000000},{"price":1.08421,"qty":1864.36823262}],"checksum":1677562343,"timestamp":"2024-06-01T17:52:10.856507Z"}]}
{"channel":"book","type":"update","data":[{"symbol":"EUR/USD","bids":[{"price":1.08406,"qty":0.00000000},{"price":1.08369,"qty":63898.27924924},{"price":1.08410,"qty":1984.80000000}],"asks":[],"checksum":831233232,"timestamp":"2024-06-01T17:52:10.861596Z"}]}
{"channel":"book","type":"update","data":[{"symbol":"EUR/USD","bids":[{"price":1.08409,"qty":0.00000000},{"price":1.08369,"qty":63898.27924924},{"price":1.08411,"qty":3710.85167980}],"asks":[],"checksum":266439205,"timestamp":"2024-06-01T17:52:10.865377Z"}]}
{"channel":"book","type":"update","data":[{"symbol":"EUR/USD","bids":[{"price":1.08410,"qty":1994.61218144}],"asks":[],"checksum":2343923399,"timestamp":"2024-06-01T17:52:10.890295Z"}]}
{"channel":"book","type":"update","data":[{"symbol":"EUR/USD","bids":[{"price":1.08383,"qty":0.00000000},{"price":1.08369,"qty":63898.27924924}],"asks":[],"checksum":1625184682,"timestamp":"2024-06-01T17:52:10.911688Z"}]}
{"channel":"book","type":"update","data":[{"symbol":"EUR/USD","bids":[{"price":1.08382,"qty":51.55032830}],"asks":[],"checksum":1701015283,"timestamp":"2024-06-01T17:52:10.919013Z"}]}
{"channel":"book","type":"update","data":[{"symbol":"EUR/USD","bids":[{"price":1.08381,"qty":715.47579446}],"asks":[],"checksum":1706872445,"timestamp":"2024-06-01T17:52:10.919230Z"}]}
{"channel":"book","type":"update","data":[{"symbol":"EUR/USD","bids":[{"price":1.08410,"qty":9.81218144},{"price":1.08412,"qty":1984.80000000}],"asks":[],"checksum":463429769,"timestamp":"2024-06-01T17:52:10.956807Z"}]}
{"channel":"book","type":"update","data":[{"symbol":"EUR/USD","bids":[{"price":1.08411,"qty":0.00000000},{"price":1.08370,"qty":16662.23582757},{"price":1.08413,"qty":3710.78322211}],"asks":[],"checksum":1872021532,"timestamp":"2024-06-01T17:52:10.959905Z"}]}
{"channel":"book","type":"update","data":[{"symbol":"EUR/USD","bids":[{"price":1.08412,"qty":0.00000000},{"price":1.08371,"qty":23.06890219},{"price":1.08414,"qty":1984.80000000}],"asks":[],"checksum":2333536852,"timestamp":"2024-06-01T17:52:12.741331Z"}]}
{"channel":"book","type":"update","data":[{"symbol":"EUR/USD","bids":[{"price":1.08413,"qty":0.00000000},{"price":1.08371,"qty":23.06890219},{"price":1.08409,"qty":3710.92014001}],"asks":[],"checksum":1225911878,"timestamp":"2024-06-01T17:52:12.745122Z"}]}
{"channel":"book","type":"update","data":[{"symbol":"EUR/USD","bids":[],"asks":[{"price":1.08433,"qty":456.40800888}],"checksum":2635355232,"timestamp":"2024-06-01T17:52:12.910520Z"}]}
{"channel":"book","type":"update","data":[{"symbol":"EUR/USD","bids":[],"asks":[{"price":1.08442,"qty":16505.75531833}],"checksum":1553564044,"timestamp":"2024-06-01T17:52:12.910540Z"}]}
{"channel":"book","type":"update","data":[{"symbol":"EUR/USD","bids":[],"asks":[{"price":1.08438,"qty":61.50781661}],"checksum":3052481386,"timestamp":"2024-06-01T17:52:12.916226Z"}]}
{"channel":"book","type":"update","data":[{"symbol":"EUR/USD","bids":[],"asks":[{"price":1.08440,"qty":449.13978450}],"checksum":2866289524,"timestamp":"2024-06-01T17:52:12.916452Z"}]}
{"channel":"book","type":"update","data":[{"symbol":"EUR/USD","bids":[{"price":1.08414,"qty":0.00000000},{"price":1.08371,"qty":23.06890219},{"price":1.08406,"qty":1984.80000000}],"asks":[],"checksum":1631666350,"timestamp":"2024-06-01T17:52:12.925066Z"}]}
{"channel":"book","type":"update","data":[{"symbol":"EUR/USD","bids":[],"asks":[{"price":1.08442,"qty":0.00000000},{"price":1.08454,"qty":2830.45000000}],"checksum":3778837741,"timestamp":"2024-06-01T17:52:13.176925Z"}]}
{"channel":"book","type":"update","data":[{"symbol":"EUR/USD","bids":[],"asks":[{"price":1.08441,"qty":0.00000000},{"price":1.08458,"qty":872.15694288}],"checksum":3678722226,"timestamp":"2024-06-01T17:52:13.180229Z"}]}
{"channel":"book","type":"update","data":[{"symbol":"EUR/USD","bids":[],"asks":[{"price":1.08438,"qty":6792.59945261}],"checksum":3495880580,"timestamp":"2024-06-01T17:52:13.182148Z"}]}
{"channel":"book","type":"update","data":[{"symbol":"EUR/USD","bids":[],"asks":[{"price":1.08440,"qty":13696.67387519}],"checksum":2370215340,"timestamp":"2024-06-01T17:52:13.182252Z"}]}
{"channel":"book","type":"update","data":[{"symbol":"EUR/USD","bids":[{"price":1.08406,"qty":0.00000000},{"price":1.08371,"qty":23.06890219},{"price":1.08410,"qty":1994.61218144}],"asks":[],"checksum":1143875358,"timestamp":"2024-06-01T17:52:13.199115Z"}]}
{"channel":"book","type":"update","data":[{"symbol":"EUR/USD","bids":[{"price":1.08409,"qty":0.00000000},{"price":1.08370,"qty":16662.23582757},{"price":1.08411,"qty":3710.85167980}],"asks":[],"checksum":706954938,"timestamp":"2024-06-01T17:52:13.202383Z"}]}
{"channel":"book","type":"update","data":[{"symbol":"EUR/USD","bids":[],"asks":[{"price":1.08437,"qty":2010.28417243}],"checksum":1761240203,"timestamp":"2024-06-01T17:52:13.205651Z"}]}
{"channel":"book","type":"update","data":[{"symbol":"EUR/USD","bids":[{"price":1.08382,"qty":0.00000000},{"price":1.08370,"qty":16662.23582757}],"asks":[],"checksum":2788558943,"timestamp":"2024-06-01T17:52:13.666299Z"}]}
{"channel":"book","type":"update","data":[{"symbol":"EUR/USD","bids":[{"price":1.08381,"qty":631.31157675}],"asks":[],"checksum":4008136108,"timestamp":"2024-06-01T17:52:13.666321Z"}]}
{"channel":"book","type":"update","data":[{"symbol":"EUR/USD","bids":[{"price":1.08380,"qty":349.56490150}],"asks":[],"checksum":7560452,"timestamp":"2024-06-01T17:52:13.671104Z"}]}
{"channel":"book","type":"update","data":[{"symbol":"EUR/USD","bids":[{"price":1.08371,"qty":1687.09678079}],"asks":[],"checksum":1116601125,"timestamp":"2024-06-01T17:52:13.671364Z"}]}
{"channel":"book","type":"update","data":[{"symbol":"EUR/USD","bids":[{"price":1.08379,"qty":0.00000000},{"price":1.08370,"qty":16662.23582757}],"asks":[],"checksum":782468497,"timestamp":"2024-06-01T17:52:14.184426Z"}]}
{"channel":"book","type":"update","data":[{"symbol":"EUR/USD","bids":[{"price":1.08408,"qty":0.00000000},{"price":1.08369,"qty":63898.27924924}],"asks":[],"checksum":3763412388,"timestamp":"2024-06-01T17:52:14.184529Z"}]}
{"channel":"book","type":"update","data":[{"symbol":"EUR/USD","bids":[{"price":1.08369,"qty":0.00000000},{"price":1.08350,"qty":962.24087722}],"asks":[],"checksum":2638932515,"timestamp":"2024-06-01T17:52:14.184585Z"}]}
{"channel":"book","type":"update","data":[{"symbol":"EUR/USD","bids":[{"price":1.08379,"qty":9901.99596235}],"asks":[],"checksum":1764955669,"timestamp":"2024-06-01T17:52:14.186683Z"}]}
{"channel":"book","type":"update","data":[{"symbol":"EUR/USD","bids":[{"price":1.08371,"qty":38449.87996771}],"asks":[],"checksum":4085339924,"timestamp":"2024-06-01T17:52:14.186858Z"}]}
{"channel":"book","type":"update","data":[{"symbol":"EUR/USD","bids":[{"price":1.08370,"qty":0.00000000},{"price":1.08350,"qty":962.24087722}],"asks":[],"checksum":280188441,"timestamp":"2024-06-01T17:52:14.187788Z"}]}
{"channel":"book","type":"update","data":[{"symbol":"EUR/USD","bids":[{"price":1.08410,"qty":9.81218144},{"price":1.08406,"qty":1984.80000000}],"asks":[],"checksum":1174622472,"timestamp":"2024-06-01T17:52:14.201127Z"}]}
{"channel":"book","type":"update","data":[{"symbol":"EUR/USD","bids":[{"price":1.08411,"qty":0.00000000},{"price":1.08350,"qty":962.24087722},{"price":1.08407,"qty":3710.98860275}],"asks":[],"checksum":3120028448,"timestamp":"2024-06-01T17:52:14.205261Z"}]}
{"channel":"book","type":"update","data":[{"symbol":"EUR/USD","bids":[{"price":1.08372,"qty":16662.23582757}],"asks":[],"checksum":3912101503,"timestamp":"2024-06-01T17:52:14.286970Z"}]}
{"channel":"book","type":"update","data":[{"symbol":"EUR/USD","bids":[{"price":1.08406,"qty":0.00000000},{"price":1.08371,"qty":38449.87996771},{"price":1.08408,"qty":1984.80000000}],"asks":[],"checksum":3965735972,"timestamp":"2024-06-01T17:52:14.325523Z"}]}
{"channel":"book","type":"update","data":[{"symbol":"EUR/USD","bids":[{"price":1.08407,"qty":0.00000000},{"price":1.08371,"qty":38449.87996771},{"price":1.08409,"qty":3710.92014001}],"asks":[],"checksum":77089279,"timestamp":"2024-06-01T17:52:14.330325Z"}]}
{"channel":"book","type":"update","data":[{"symbol":"EUR/USD","bids":[{"price":1.08373,"qty":23.06847646}],"asks":[],"checksum":1205454810,"timestamp":"2024-06-01T17:52:14.752170Z"}]}
{"channel":"book","type":"update","data":[{"symbol":"EUR/USD","bids":[],"asks":[{"price":1.08440,"qty":13247.53409069}],"checksum":1166162525,"timestamp":"2024-06-01T17:52:15.102951Z"}]}
{"channel":"book","type":"update","data":[{"symbol":"EUR/USD","bids":[],"asks":[{"price":1.08438,"qty":6731.09163600}],"checksum":3488137413,"timestamp":"2024-06-01T17:52:15.103012Z"}]}
{"channel":"book","type":"update","data":[{"symbol":"EUR/USD","bids":[{"price":1.08408,"qty":0.00000000},{"price":1.08372,"qty":16662.23582757},{"price":1.08410,"qty":1994.61218144}],"asks":[],"checksum":1142713321,"timestamp":"2024-06-01T17:52:15.113810Z"}]}
{"channel":"book","type":"update","data":[{"symbol":"EUR/USD","bids":[{"price":1.08409,"qty":0.00000000},{"price":1.08371,"qty":38426.81106552},{"price":1.08411,"qty":3710.85167980}],"asks":[],"checksum":3032624583,"timestamp":"2024-06-01T17:52:15.117289Z"}]}
{"channel":"book","type":"update","data":[{"symbol":"EUR/USD","bids":[],"asks":[{"price":1.08436,"qty":334.28586809}],"checksum":2342679191,"timestamp":"2024-06-01T17:52:15.146504Z"}]}
{"channel":"book","type":"update","data":[{"symbol":"EUR/USD","bids":[],"asks":[{"price":1.08440,"qty":0.00000000},{"price":1.08454,"qty":2830.45000000}],"checksum":406232903,"timestamp":"2024-06-01T17:52:15.658126Z"}]}
{"channel":"book","type":"update","data":[{"symbol":"EUR/USD","bids":[],"asks":[{"price":1.08438,"qty":0.00000000},{"price":1.08458,"qty":1036.78372374}],"checksum":3611286950,"timestamp":"2024-06-01T17:52:15.658376Z"}]}
{"channel":"book","type":"update","data":[{"symbol":"EUR/USD","bids":[],"asks":[{"price":1.08436,"qty":3807.15627674}],"checksum":2660960505,"timestamp":"2024-06-01T17:52:15.660260Z"}]}
{"channel":"book","type":"update","data":[{"symbol":"EUR/USD","bids":[],"asks":[{"price":1.08446,"qty":16505.75531804}],"checksum":3784368001,"timestamp":"2024-06-01T17:52:15.660317Z"}]}
{"channel":"book","type":"update","data":[{"symbol":"EUR/USD","bids":[],"asks":[{"price":1.08437,"qty":0.00000000},{"price":1.08458,"qty":1036.78372374}],"checksum":1407889985,"timestamp":"2024-06-01T17:52:15.661304Z"}]}
{"channel":"book","type":"update","data":[{"symbol":"EUR/USD","bids":[],"asks":[{"price":1.08445,"qty":2010.28417243}],"checksum":873763197,"timestamp":"2024-06-01T17:52:15.718944Z"}]}
{"channel":"book","type":"update","data":[{"symbol":"EUR/USD","bids":[{"price":1.08380,"qty":0.00000000},{"price":1.08371,"qty":36762.78318692}],"asks":[],"checksum":1985490019,"timestamp":"2024-06-01T17:52:16.465423Z"}]}
{"channel":"book","type":"update","data":[{"symbol":"EUR/USD","bids":[{"price":1.08380,"qty":2170.76507101}],"asks":[],"checksum":2947717353,"timestamp":"2024-06-01T17:52:16.471020Z"}]}
{"channel":"book","type":"update","data":[{"symbol":"EUR/USD","bids":[],"asks":[{"price":1.08436,"qty":3472.87040865}],"checksum":4146009110,"timestamp":"2024-06-01T17:52:17.279073Z"}]}
{"channel":"book","type":"update","data":[{"symbol":"EUR/USD","bids":[],"asks":[{"price":1.08444,"qty":1262.15929825}],"checksum":2877159898,"timestamp":"2024-06-01T17:52:17.319440Z"}]}
{"channel":"book","type":"update","data":[{"symbol":"EUR/USD","bids":[],"asks":[{"price":1.08435,"qty":47.15107705}],"checksum":538168152,"timestamp":"2024-06-01T17:52:17.319615Z"}]}
{"channel":"book","type":"update","data":[{"symbol":"EUR/USD","bids":[{"price":1.08379,"qty":0.00000000},{"price":1.08371,"qty":36762.78318692}],"asks":[],"checksum":4294736570,"timestamp":"2024-06-01T17:52:17.715241Z"}]}
{"channel":"book","type":"update","data":[{"symbol":"EUR/USD","bids":[{"price":1.08371,"qty":0.00000000},{"price":1.08350,"qty":962.24087722}],"asks":[],"checksum":325839269,"timestamp":"2024-06-01T17:52:17.715572Z"}]}
{"channel":"book","type":"update","data":[{"symbol":"EUR/USD","bids":[{"price":1.08372,"qty":0.00000000},{"price":1.08346,"qty":2830.45000000},{"price":1.08347,"qty":16662.23582757}],"asks":[],"checksum":1798231631,"timestamp":"2024-06-01T17:52:17.719090Z"}]}
{"channel":"book","type":"update","data":[{"symbol":"EUR/USD","bids":[{"price":1.08381,"qty":33364.97667998}],"asks":[],"checksum":982219193,"timestamp":"2024-06-01T17:52:17.720574Z"}]}
{"channel":"book","type":"update","data":[{"symbol":"EUR/USD","bids":[{"price":1.08382,"qty":11245.03532357}],"asks":[],"checksum":4164026722,"timestamp":"2024-06-01T17:52:17.720639Z"}]}
{"channel":"book","type":"update","data":[{"symbol":"EUR/USD","bids":[{"price":1.08381,"qty":32733.66510323}],"asks":[],"checksum":475199774,"timestamp":"2024-06-01T17:52:17.731667Z"}]}
{"channel":"book","type":"update","data":[{"symbol":"EUR/USD","bids":[{"price":1.08383,"qty":631.29992711}],"asks":[],"checksum":849848920,"timestamp":"2024-06-01T17:52:17.731958Z"}]}
{"channel":"book","type":"update","data":[{"symbol":"EUR/USD","bids":[{"price":1.08410,"qty":9.81218144},{"price":1.08406,"qty":1984.80000000}],"asks":[],"checksum":3168180328,"timestamp":"2024-06-01T17:52:17.750944Z"}]}
{"channel":"book","type":"update","data":[{"symbol":"EUR/USD","bids":[{"price":1.08411,"qty":0.00000000},{"price":1.08373,"qty":23.06847646},{"price":1.08407,"qty":3710.98860275}],"asks":[],"checksum":3974537992,"timestamp":"2024-06-01T17:52:17.754117Z"}]}
{"channel":"book","type":"update","data":[{"symbol":"EUR/USD","bids":[{"price":1.08407,"qty":0.00000000},{"price":1.08373,"qty":23.06847646},{"price":1.08412,"qty":3710.81745064}],"asks":[],"checksum":398264155,"timestamp":"2024-06-01T17:52:17.757352Z"}]}
{"channel":"book","type":"update","data":[{"symbol":"EUR/USD","bids":[{"price":1.08412,"qty":0.00000000},{"price":1.08373,"qty":23.06847646},{"price":1.08407,"qty":3710.98860275}],"asks":[],"checksum":3974537992,"timestamp":"2024-06-01T17:52:17.760483Z"}]}
{"channel":"book","type":"update","data":[{"symbol":"EUR/USD","bids":[{"price":1.08406,"qty":0.00000000},{"price":1.08373,"qty":23.06847646},{"price":1.08408,"qty":1984.80000000}],"asks":[],"checksum":2652731464,"timestamp":"2024-06-01T17:52:18.085811Z"}]}
{"channel":"book","type":"update","data":[{"symbol":"EUR/USD","bids":[{"price":1.08407,"qty":0.00000000},{"price":1.08373,"qty":23.06847646},{"price":1.08409,"qty":3710.92014001}],"asks":[],"checksum":2681725117,"timestamp":"2024-06-01T17:52:18.088954Z"}]}
{"channel":"book","type":"update","data":[{"symbol":"EUR/USD","bids":[],"asks":[{"price":1.08436,"qty":0.00000000},{"price":1.08453,"qty":225.72210000}],"checksum":3607385310,"timestamp":"2024-06-01T17:52:18.166314Z"}]}
{"channel":"book","type":"update","data":[{"symbol":"EUR/USD","bids":[],"asks":[{"price":1.08446,"qty":0.00000000},{"price":1.08454,"qty":2830.45000000}],"checksum":1802990386,"timestamp":"2024-06-01T17:52:18.166392Z"}]}
{"channel":"book","type":"update","data":[{"symbol":"EUR/USD","bids":[],"asks":[{"price":1.08443,"qty":16505.75531804}],"checksum":1024124327,"timestamp":"2024-06-01T17:52:18.168472Z"}]}
{"channel":"book","type":"update","data":[{"symbol":"EUR/USD","bids":[{"price":1.08383,"qty":17293.53575468}],"asks":[],"checksum":3675818982,"timestamp":"2024-06-01T17:52:18.169920Z"}]}
{"channel":"book","type":"update","data":[{"symbol":"EUR/USD","bids":[],"asks":[{"price":1.08445,"qty":0.00000000},{"price":1.08454,"qty":2830.45000000}],"checksum":1257876437,"timestamp":"2024-06-01T17:52:18.169940Z"}]}
{"channel":"book","type":"update","data":[{"symbol":"EUR/USD","bids":[{"price":1.08408,"qty":0.00000000},{"price":1.08373,"qty":23.06847646},{"price":1.08410,"qty":1994.61218144}],"asks":[],"checksum":631014097,"timestamp":"2024-06-01T17:52:18.179781Z"}]}
{"channel":"book","type":"update","data":[{"symbol":"EUR/USD","bids":[{"price":1.08409,"qty":0.00000000},{"price":1.08350,"qty":962.24087722},{"price":1.08411,"qty":3710.85167980}],"asks":[],"checksum":3009458467,"timestamp":"2024-06-01T17:52:18.183125Z"}]}
{"channel":"book","type":"update","data":[{"symbol":"EUR/USD","bids":[],"asks":[{"price":1.08442,"qty":2010.28417243}],"checksum":3210485222,"timestamp":"2024-06-01T17:52:18.819117Z"}]}
{"channel":"book","type":"update","data":[{"symbol":"EUR/USD","bids":[{"price":1.08383,"qty":631.29992711}],"asks":[],"checksum":2552171890,"timestamp":"2024-06-01T17:52:18.819237Z"}]}
{"channel":"book","type":"update","data":[{"symbol":"EUR/USD","bids":[{"price":1.08373,"qty":0.00000000},{"price":1.08350,"qty":962.24087722},{"price":1.08383,"qty":654.36627515}],"asks":[],"checksum":1053252267,"timestamp":"2024-06-01T17:52:18.931228Z"}]}
{"channel":"book","type":"update","data":[{"symbol":"EUR/USD","bids":[{"price":1.08410,"qty":9.81218144},{"price":1.08406,"qty":1984.80000000}],"asks":[],"checksum":606003055,"timestamp":"2024-06-01T17:52:18.938724Z"}]}
{"channel":"book","type":"update","data":[{"symbol":"EUR/USD","bids":[{"price":1.08411,"qty":0.00000000},{"price":1.08350,"qty":962.24087722},{"price":1.08407,"qty":3710.98860275}],"asks":[],"checksum":1949230095,"timestamp":"2024-06-01T17:52:18.941853Z"}]}
{"channel":"book","type":"update","data":[{"symbol":"EUR/USD","bids":[{"price":1.08406,"qty":0.00000000},{"price":1.08350,"qty":962.24087722},{"price":1.08408,"qty":1984.80000000}],"asks":[],"checksum":114638671,"timestamp":"2024-06-01T17:52:19.182828Z"}]}
{"channel":"book","type":"update","data":[{"symbol":"EUR/USD","bids":[{"price":1.08407,"qty":0.00000000},{"price":1.08350,"qty":962.24087722},{"price":1.08409,"qty":3710.92014001}],"asks":[],"checksum":119515066,"timestamp":"2024-06-01T17:52:19.186199Z"}]}
{"channel":"book","type":"update","data":[{"symbol":"EUR/USD","bids":[{"price":1.08380,"qty":0.00000000},{"price":1.08350,"qty":962.24087722}],"asks":[],"checksum":2945930644,"timestamp":"2024-06-01T17:52:19.443030Z"}]}
{"channel":"book","type":"update","data":[{"symbol":"EUR/USD","bids":[],"asks":[{"price":1.08435,"qty":0.00000000},{"price":1.08454,"qty":2830.45000000}],"checksum":209902138,"timestamp":"2024-06-01T17:52:19.494332Z"}]}
{"channel":"book","type":"update","data":[{"symbol":"EUR/USD","bids":[],"asks":[{"price":1.08444,"qty":0.00000000},{"price":1.08459,"qty":37684.19329581}],"checksum":3093738744,"timestamp":"2024-06-01T17:52:19.494423Z"}]}
{"channel":"book","type":"update","data":[{"symbol":"EUR/USD","bids":[],"asks":[{"price":1.08441,"qty":492.21000316}],"checksum":3924083533,"timestamp":"2024-06-01T17:52:19.536607Z"}]}
{"channel":"book","type":"update","data":[{"symbol":"EUR/USD","bids":[],"asks":[{"price":1.08442,"qty":2676.52661725}],"checksum":3962471815,"timestamp":"2024-06-01T17:52:19.536745Z"}]}
{"channel":"book","type":"update","data":[{"symbol":"EUR/USD","bids":[{"price":1.08384,"qty":1740.29957640}],"asks":[],"checksum":938924927,"timestamp":"2024-06-01T17:52:19.792564Z"}]}
{"channel":"book","type":"update","data":[{"symbol":"EUR/USD","bids":[],"asks":[{"price":1.08438,"qty":456.40800888}],"checksum":439355419,"timestamp":"2024-06-01T17:52:19.961560Z"}]}
{"channel":"book","type":"update","data":[{"symbol":"EUR/USD","bids":[],"asks":[{"price":1.08433,"qty":0.00000000},{"price":1.08454,"qty":2830.45000000}],"checksum":973482978,"timestamp":"2024-06-01T17:52:20.134228Z"}]}
{"channel":"book","type":"update","data":[{"symbol":"EUR/USD","bids":[],"asks":[{"price":1.08443,"qty":0.00000000},{"price":1.08460,"qty":4167.00000000}],"checksum":620958056,"timestamp":"2024-06-01T17:52:20.679800Z"}]}
{"channel":"book","type":"update","data":[{"symbol":"EUR/USD","bids":[],"asks":[{"price":1.08437,"qty":8360.20224967}],"checksum":3820134226,"timestamp":"2024-06-01T17:52:20.681955Z"}]}
{"channel":"book","type":"update","data":[{"symbol":"EUR/USD","bids":[],"asks":[{"price":1.08440,"qty":13247.53409069}],"checksum":3704047902,"timestamp":"2024-06-01T17:52:20.681989Z"}]}
{"channel":"book","type":"update","data":[{"symbol":"EUR/USD","bids":[{"price":1.08383,"qty":17316.60210272}],"asks":[],"checksum":1227635775,"timestamp":"2024-06-01T17:52:20.683303Z"}]}
{"channel":"book","type":"update","data":[{"symbol":"EUR/USD","bids":[],"asks":[{"price":1.08442,"qty":666.24244482}],"checksum":1561401260,"timestamp":"2024-06-01T17:52:20.683385Z"}]}
{"channel":"book","type":"update","data":[{"symbol":"EUR/USD","bids":[{"price":1.08383,"qty":17293.53575468},{"price":1.08382,"qty":11268.10188443}],"asks":[],"checksum":2720553891,"timestamp":"2024-06-01T17:52:20.742757Z"}]}
{"channel":"book","type":"update","data":[{"symbol":"EUR/USD","bids":[{"price":1.08383,"qty":631.29992711}],"asks":[],"checksum":945119485,"timestamp":"2024-06-01T17:52:20.986282Z"}]}
{"channel":"book","type":"update","data":[{"symbol":"EUR/USD","bids":[],"asks":[{"price":1.08436,"qty":2010.28417243}],"checksum":774904190,"timestamp":"2024-06-01T17:52:20.986517Z"}]}
{"channel":"book","type":"update","data":[{"symbol":"EUR/USD","bids":[{"price":1.08381,"qty":0.00000000},{"price":1.08350,"qty":962.24087722}],"asks":[],"checksum":2607826143,"timestamp":"2024-06-01T17:52:21.319873Z"}]}
{"channel":"book","type":"update","data":[{"symbol":"EUR/USD","bids":[{"price":1.08382,"qty":23.06656086}],"asks":[],"checksum":2500400864,"timestamp":"2024-06-01T17:52:21.319907Z"}]}
{"channel":"book","type":"update","data":[{"symbol":"EUR/USD","bids":[{"price":1.08410,"qty":3172.14697879}],"asks":[],"checksum":4162500376,"timestamp":"2024-06-01T17:52:21.324631Z"}]}
{"channel":"book","type":"update","data":[{"symbol":"EUR/USD","bids":[{"price":1.08385,"qty":26896.68484021}],"asks":[],"checksum":1233943772,"timestamp":"2024-06-01T17:52:21.324650Z"}]}
{"channel":"book","type":"update","data":[{"symbol":"EUR/USD","bids":[{"price":1.08409,"qty":0.00000000},{"price":1.08350,"qty":962.24087722},{"price":1.08411,"qty":3710.85167980}],"asks":[],"checksum":3563771987,"timestamp":"2024-06-01T17:52:21.328533Z"}]}
{"channel":"book","type":"update","data":[{"symbol":"EUR/USD","bids":[],"asks":[{"price":1.08442,"qty":0.00000000},{"price":1.08453,"qty":225.72210000}],"checksum":3013445603,"timestamp":"2024-06-01T17:52:21.744925Z"}]}
{"channel":"book","type":"update","data":[{"symbol":"EUR/USD","bids":[],"asks":[{"price":1.08441,"qty":0.00000000},{"price":1.08454,"qty":2830.45000000}],"checksum":667252440,"timestamp":"2024-06-01T17:52:21.745121Z"}]}
{"channel":"book","type":"update","data":[{"symbol":"EUR/USD","bids":[],"asks":[{"price":1.08435,"qty":219.43195167}],"checksum":1695052731,"timestamp":"2024-06-01T17:52:21.751310Z"}]}
{"channel":"book","type":"update","data":[{"symbol":"EUR/USD","bids":[],"asks":[{"price":1.08436,"qty":2344.57004052}],"checksum":1436270948,"timestamp":"2024-06-01T17:52:21.751561Z"}]}
{"channel":"book","type":"update","data":[{"symbol":"EUR/USD","bids":[{"price":1.08384,"qty":0.00000000},{"price":1.08350,"qty":962.24087722}],"asks":[],"checksum":1713324600,"timestamp":"2024-06-01T17:52:21.903385Z"}]}
{"channel":"book","type":"update","data":[{"symbol":"EUR/USD","bids":[{"price":1.08383,"qty":2269.57974756}],"asks":[],"checksum":1957418572,"timestamp":"2024-06-01T17:52:21.907353Z"}]}
{"channel":"book","type":"update","data":[{"symbol":"EUR/USD","bids":[{"price":1.08384,"qty":51.55032830}],"asks":[],"checksum":2582599280,"timestamp":"2024-06-01T17:52:21.907399Z"}]}
{"channel":"book","type":"update","data":[{"symbol":"EUR/USD","bids":[{"price":1.08408,"qty":0.00000000},{"price":1.08350,"qty":962.24087722},{"price":1.08386,"qty":1984.80000000}],"asks":[],"checksum":1462345874,"timestamp":"2024-06-01T17:52:21.914067Z"}]}
{"channel":"book","type":"update","data":[{"symbol":"EUR/USD","bids":[{"price":1.08386,"qty":0.00000000},{"price":1.08350,"qty":962.24087722},{"price":1.08406,"qty":1984.80000000}],"asks":[],"checksum":991027965,"timestamp":"2024-06-01T17:52:22.249463Z"}]}
{"channel":"book","type":"update","data":[{"symbol":"EUR/USD","bids":[{"price":1.08382,"qty":0.00000000},{"price":1.08350,"qty":962.24087722},{"price":1.08386,"qty":23.06570959}],"asks":[],"checksum":523535900,"timestamp":"2024-06-01T17:52:22.941537Z"}]}
{"channel":"book","type":"update","data":[{"symbol":"EUR/USD","bids":[{"price":1.08379,"qty":631.32322682}],"asks":[],"checksum":2493912462,"timestamp":"2024-06-01T17:52:22.945312Z"}]}
{"channel":"book","type":"update","data":[{"symbol":"EUR/USD","bids":[{"price":1.08383,"qty":1638.27982045}],"asks":[],"checksum":3883812482,"timestamp":"2024-06-01T17:52:22.945548Z"}]}
{"channel":"book","type":"update","data":[{"symbol":"EUR/USD","bids":[],"asks":[{"price":1.08440,"qty":0.00000000},{"price":1.08454,"qty":2830.45000000}],"checksum":3000282723,"timestamp":"2024-06-01T17:52:23.079222Z"}]}
{"channel":"book","type":"update","data":[{"symbol":"EUR/USD","bids":[],"asks":[{"price":1.08437,"qty":0.00000000},{"price":1.08458,"qty":732.13667149}],"checksum":3557961931,"timestamp":"2024-06-01T17:52:23.079234Z"}]}
{"channel":"book","type":"update","data":[{"symbol":"EUR/USD","bids":[],"asks":[{"price":1.08446,"qty":14506.46898235}],"checksum":1337754098,"timestamp":"2024-06-01T17:52:23.081762Z"}]}
{"channel":"book","type":"update","data":[{"symbol":"EUR/USD","bids":[],"asks":[{"price":1.08435,"qty":5228.86904349}],"checksum":3091474569,"timestamp":"2024-06-01T17:52:23.082015Z"}]}
{"channel":"book","type":"update","data":[{"symbol":"EUR/USD","bids":[],"asks":[{"price":1.08436,"qty":334.28586809}],"checksum":924140391,"timestamp":"2024-06-01T17:52:23.082848Z"}]}
{"channel":"book","type":"update","data":[{"symbol":"EUR/USD","bids":[],"asks":[{"price":1.08445,"qty":2010.28417243}],"checksum":2130634346,"timestamp":"2024-06-01T17:52:23.187133Z"}]}
{"channel":"book","type":"update","data":[{"symbol":"EUR/USD","bids":[{"price":1.08410,"qty":3162.33479735}],"asks":[],"checksum":135424435,"timestamp":"2024-06-01T17:52:23.252902Z"}]}
{"channel":"book","type":"update","data":[{"symbol":"EUR/USD","bids":[],"asks":[{"price":1.08436,"qty":0.00000000},{"price":1.08454,"qty":2830.45000000}],"checksum":1330133662,"timestamp":"2024-06-01T17:52:23.850289Z"}]}
{"channel":"book","type":"update","data":[{"symbol":"EUR/USD","bids":[],"asks":[{"price":1.08435,"qty":5009.43709182}],"checksum":1457438379,"timestamp":"2024-06-01T17:52:23.850447Z"}]}
{"channel":"book","type":"update","data":[{"symbol":"EUR/USD","bids":[],"asks":[{"price":1.08434,"qty":104.57803526}],"checksum":2650540906,"timestamp":"2024-06-01T17:52:23.857300Z"}]}
{"channel":"book","type":"update","data":[{"symbol":"EUR/USD","bids":[],"asks":[{"price":1.08444,"qty":1216.74769727}],"checksum":757340946,"timestamp":"2024-06-01T17:52:23.857624Z"}]}
{"channel":"book","type":"update","data":[{"symbol":"EUR/USD","bids":[{"price":1.08412,"qty":9.81218144}],"asks":[],"checksum":2525987644,"timestamp":"2024-06-01T17:52:24.037729Z"}]}
{"channel":"book","type":"update","data":[{"symbol":"EUR/USD","bids":[{"price":1.08383,"qty":0.00000000},{"price":1.08379,"qty":631.32322682}],"asks":[],"checksum":1573323160,"timestamp":"2024-06-01T17:52:24.453976Z"}]}
{"channel":"book","type":"update","data":[{"symbol":"EUR/USD","bids":[{"price":1.08384,"qty":0.00000000},{"price":1.08378,"qty":4613.45216905}],"asks":[],"checksum":3623140365,"timestamp":"2024-06-01T17:52:24.454101Z"}]}
{"channel":"book","type":"update","data":[{"symbol":"EUR/USD","bids":[{"price":1.08386,"qty":252.51833377}],"asks":[],"checksum":419520312,"timestamp":"2024-06-01T17:52:24.462327Z"}]}
{"channel":"book","type":"update","data":[{"symbol":"EUR/USD","bids":[{"price":1.08385,"qty":0.00000000},{"price":1.08350,"qty":962.24087722}],"asks":[],"checksum":106087436,"timestamp":"2024-06-01T17:52:25.096575Z"}]}
{"channel":"book","type":"update","data":[{"symbol":"EUR/USD","bids":[{"price":1.08410,"qty":0.00000000},{"price":1.08349,"qty":1396.80783251}],"asks":[],"checksum":322184994,"timestamp":"2024-06-01T17:52:25.096673Z"}]}
{"channel":"book","type":"update","data":[{"symbol":"EUR/USD","bids":[{"price":1.08411,"qty":0.00000000},{"price":1.08348,"qty":16662.23582757},{"price":1.08407,"qty":3710.98860275}],"asks":[],"checksum":1221923811,"timestamp":"2024-06-01T17:52:25.100654Z"}]}
{"channel":"book","type":"update","data":[{"symbol":"EUR/USD","bids":[{"price":1.08351,"qty":86455.23955238}],"asks":[],"checksum":4172673091,"timestamp":"2024-06-01T17:52:25.103556Z"}]}
{"channel":"book","type":"update","data":[{"symbol":"EUR/USD","bids":[{"price":1.08352,"qty":16662.23582757}],"asks":[],"checksum":4059998045,"timestamp":"2024-06-01T17:52:25.107288Z"}]}
{"channel":"book","type":"update","data":[{"symbol":"EUR/USD","bids":[],"asks":[{"price":1.08435,"qty":0.00000000},{"price":1.08453,"qty":225.72210000}],"checksum":3049119071,"timestamp":"2024-06-01T17:52:25.588901Z"}]}
{"channel":"book","type":"update","data":[{"symbol":"EUR/USD","bids":[],"asks":[{"price":1.08446,"qty":0.00000000},{"price":1.08454,"qty":2830.45000000}],"checksum":3052630145,"timestamp":"2024-06-01T17:52:25.588933Z"}]}
{"channel":"book","type":"update","data":[{"symbol":"EUR/USD","bids":[],"asks":[{"price":1.08445,"qty":0.00000000},{"price":1.08460,"qty":4167.00000000}],"checksum":145902631,"timestamp":"2024-06-01T17:52:25.592392Z"}]}
{"channel":"book","type":"update","data":[{"symbol":"EUR/USD","bids":[],"asks":[{"price":1.08443,"qty":16505.75531804}],"checksum":451137594,"timestamp":"2024-06-01T17:52:25.594053Z"}]}
{"channel":"book","type":"update","data":[{"symbol":"EUR/USD","bids":[],"asks":[{"price":1.08442,"qty":2010.28417243}],"checksum":1360218046,"timestamp":"2024-06-01T17:52:25.642089Z"}]}
{"channel":"book","type":"update","data":[{"symbol":"EUR/USD","bids":[],"asks":[{"price":1.08444,"qty":0.00000000},{"price":1.08454,"qty":2830.45000000}],"checksum":1580122959,"timestamp":"2024-06-01T17:52:26.007178Z"}]}
{"channel":"book","type":"update","data":[{"symbol":"EUR/USD","bids":[],"asks":[{"price":1.08444,"qty":1245.97642741}],"checksum":3102341123,"timestamp":"2024-06-01T17:52:26.012691Z"}]}
{"channel":"book","type":"update","data":[{"symbol":"EUR/USD","bids":[{"price":1.08386,"qty":23.06570959}],"asks":[],"checksum":183128211,"timestamp":"2024-06-01T17:52:26.934816Z"}]}
{"channel":"book","type":"update","data":[{"symbol":"EUR/USD","bids":[{"price":1.08353,"qty":2121.09597548}],"asks":[],"checksum":69215988,"timestamp":"2024-06-01T17:52:26.938927Z"}]}
{"channel":"book","type":"update","data":[{"symbol":"EUR/USD","bids":[{"price":1.08386,"qty":0.00000000},{"price":1.08351,"qty":86455.23955238},{"price":1.08352,"qty":16685.30877500}],"asks":[],"checksum":371314445,"timestamp":"2024-06-01T17:52:27.029059Z"}]}
{"channel":"book","type":"update","data":[{"symbol":"EUR/USD","bids":[],"asks":[{"price":1.08443,"qty":0.00000000},{"price":1.08454,"qty":2830.45000000}],"checksum":3800046884,"timestamp":"2024-06-01T17:52:28.128983Z"}]}
{"channel":"book","type":"update","data":[{"symbol":"EUR/USD","bids":[],"asks":[{"price":1.08437,"qty":5101.98102232}],"checksum":3744577552,"timestamp":"2024-06-01T17:52:28.131567Z"}]}
{"channel":"book","type":"update","data":[{"symbol":"EUR/USD","bids":[],"asks":[{"price":1.08441,"qty":14876.64470437}],"checksum":1847381454,"timestamp":"2024-06-01T17:52:28.131614Z"}]}
{"channel":"book","type":"update","data":[{"symbol":"EUR/USD","bids":[],"asks":[{"price":1.08442,"qty":0.00000000},{"price":1.08453,"qty":225.72210000}],"checksum":3107301581,"timestamp":"2024-06-01T17:52:28.132256Z"}]}
{"channel":"book","type":"update","data":[{"symbol":"EUR/USD","bids":[],"asks":[{"price":1.08434,"qty":0.00000000},{"price":1.08454,"qty":2830.45000000}],"checksum":1843181924,"timestamp":"2024-06-01T17:52:28.138985Z"}]}
{"channel":"book","type":"update","data":[{"symbol":"EUR/USD","bids":[],"asks":[{"price":1.08444,"qty":0.00000000},{"price":1.08459,"qty":140945.24000825}],"checksum":1303184264,"timestamp":"2024-06-01T17:52:28.139131Z"}]}
{"channel":"book","type":"update","data":[{"symbol":"EUR/USD","bids":[{"price":1.08406,"qty":0.00000000},{"price":1.08350,"qty":962.24087722},{"price":1.08408,"qty":1984.80000000}],"asks":[],"checksum":1062656200,"timestamp":"2024-06-01T17:52:28.161816Z"}]}
{"channel":"book","type":"update","data":[{"symbol":"EUR/USD","bids":[],"asks":[{"price":1.08436,"qty":2010.28417243}],"checksum":2769781482,"timestamp":"2024-06-01T17:52:28.165059Z"}]}
{"channel":"book","type":"update","data":[{"symbol":"EUR/USD","bids":[{"price":1.08407,"qty":0.00000000},{"price":1.08350,"qty":962.24087722},{"price":1.08409,"qty":3710.92014001}],"asks":[],"checksum":2765953567,"timestamp":"2024-06-01T17:52:28.165138Z"}]}
{"channel":"book","type":"update","data":[{"symbol":"EUR/USD","bids":[],"asks":[{"price":1.08437,"qty":5120.41862027}],"checksum":2947455259,"timestamp":"2024-06-01T17:52:28.181670Z"}]}
{"channel":"book","type":"update","data":[{"symbol":"EUR/USD","bids":[],"asks":[{"price":1.08441,"qty":15368.85470753}],"checksum":1179559447,"timestamp":"2024-06-01T17:52:28.181706Z"}]}
{"channel":"book","type":"update","data":[{"symbol":"EUR/USD","bids":[],"asks":[{"price":1.08442,"qty":871.46294033}],"checksum":684535808,"timestamp":"2024-06-01T17:52:28.181742Z"}]}
{"channel":"book","type":"update","data":[{"symbol":"EUR/USD","bids":[{"price":1.08408,"qty":0.00000000},{"price":1.08350,"qty":962.24087722},{"price":1.08380,"qty":1984.80000000}],"asks":[],"checksum":789097408,"timestamp":"2024-06-01T17:52:28.226942Z"}]}
{"channel":"book","type":"update","data":[{"symbol":"EUR/USD","bids":[{"price":1.08409,"qty":0.00000000},{"price":1.08350,"qty":962.24087722},{"price":1.08406,"qty":3711.02283507}],"asks":[],"checksum":3065348799,"timestamp":"2024-06-01T17:52:28.230561Z"}]}
{"channel":"book","type":"update","data":[{"symbol":"EUR/USD","bids":[{"price":1.08351,"qty":0.00000000},{"price":1.08350,"qty":962.24087722}],"asks":[],"checksum":253023027,"timestamp":"2024-06-01T17:52:28.641910Z"}]}
{"channel":"book","type":"update","data":[{"symbol":"EUR/USD","bids":[{"price":1.08352,"qty":23.07294743}],"asks":[],"checksum":1393458623,"timestamp":"2024-06-01T17:52:28.645524Z"}]}
{"channel":"book","type":"update","data":[{"symbol":"EUR/USD","bids":[{"price":1.08408,"qty":4529.83851743}],"asks":[],"checksum":3635570412,"timestamp":"2024-06-01T17:52:28.647362Z"}]}
{"channel":"book","type":"update","data":[{"symbol":"EUR/USD","bids":[{"price":1.08354,"qty":84570.16555831}],"asks":[],"checksum":730893046,"timestamp":"2024-06-01T17:52:28.647526Z"}]}
{"channel":"book","type":"update","data":[{"symbol":"EUR/USD","bids":[{"price":1.08406,"qty":0.00000000},{"price":1.08352,"qty":23.07294743},{"price":1.08409,"qty":3710.92014001}],"asks":[],"checksum":1968352208,"timestamp":"2024-06-01T17:52:28.651024Z"}]}
{"channel":"book","type":"update","data":[{"symbol":"EUR/USD","bids":[{"price":1.08380,"qty":0.00000000},{"price":1.08352,"qty":23.07294743},{"price":1.08407,"qty":1984.80000000}],"asks":[],"checksum":1299171208,"timestamp":"2024-06-01T17:52:28.655646Z"}]}
{"channel":"book","type":"update","data":[{"symbol":"EUR/USD","bids":[{"price":1.08355,"qty":16662.23582757}],"asks":[],"checksum":121066452,"timestamp":"2024-06-01T17:52:28.685024Z"}]}
{"channel":"book","type":"update","data":[{"symbol":"EUR/USD","bids":[],"asks":[{"price":1.08420,"qty":456.40800888}],"checksum":684624301,"timestamp":"2024-06-01T17:52:28.809949Z"}]}
{"channel":"book","type":"update","data":[{"symbol":"EUR/USD","bids":[],"asks":[{"price":1.08421,"qty":0.00000000},{"price":1.08453,"qty":225.72210000},{"price":1.08419,"qty":1868.27997509}],"checksum":1615527869,"timestamp":"2024-06-01T17:52:28.813543Z"}]}
{"channel":"book","type":"update","data":[{"symbol":"EUR/USD","bids":[],"asks":[{"price":1.08438,"qty":0.00000000},{"price":1.08453,"qty":225.72210000}],"checksum":554774500,"timestamp":"2024-06-01T17:52:28.976716Z"}]}
{"channel":"book","type":"update","data":[{"symbol":"EUR/USD","bids":[{"price":1.08356,"qty":2087.98324512}],"asks":[],"checksum":3550985183,"timestamp":"2024-06-01T17:52:29.566848Z"}]}
{"channel":"book","type":"update","data":[{"symbol":"EUR/USD","bids":[],"asks":[{"price":1.08437,"qty":18.43759795}],"checksum":440570526,"timestamp":"2024-06-01T17:52:30.626317Z"}]}
{"channel":"book","type":"update","data":[{"symbol":"EUR/USD","bids":[],"asks":[{"price":1.08441,"qty":492.21000316}],"checksum":1197831447,"timestamp":"2024-06-01T17:52:30.626351Z"}]}
{"channel":"book","type":"update","data":[{"symbol":"EUR/USD","bids":[],"asks":[{"price":1.08436,"qty":0.00000000},{"price":1.08454,"qty":2830.45000000}],"checksum":818301315,"timestamp":"2024-06-01T17:52:30.629424Z"}]}
{"channel":"book","type":"update","data":[{"symbol":"EUR/USD","bids":[],"asks":[{"price":1.08435,"qty":6732.71086701}],"checksum":1890833891,"timestamp":"2024-06-01T17:52:30.631217Z"}]}
{"channel":"book","type":"update","data":[{"symbol":"EUR/USD","bids":[],"asks":[{"price":1.08446,"qty":14880.96265372}],"checksum":3407557565,"timestamp":"2024-06-01T17:52:30.631281Z"}]}
{"channel":"book","type":"update","data":[{"symbol":"EUR/USD","bids":[],"asks":[{"price":1.08445,"qty":2010.28417243}],"checksum":1056548118,"timestamp":"2024-06-01T17:52:30.686822Z"}]}
{"channel":"book","type":"update","data":[{"symbol":"EUR/USD","bids":[{"price":1.08412,"qty":0.00000000},{"price":1.08354,"qty":84570.16555831}],"asks":[],"checksum":3276857219,"timestamp":"2024-06-01T17:52:30.796349Z"}]}
{"channel":"book","type":"update","data":[{"symbol":"EUR/USD","bids":[{"price":1.08407,"qty":0.00000000},{"price":1.08352,"qty":23.07294743},{"price":1.08380,"qty":1984.80000000}],"asks":[],"checksum":3335419463,"timestamp":"2024-06-01T17:52:30.813505Z"}]}
{"channel":"book","type":"update","data":[{"symbol":"EUR/USD","bids":[{"price":1.08409,"qty":3664.87882741}],"asks":[],"checksum":3068303875,"timestamp":"2024-06-01T17:52:30.816948Z"}]}
{"channel":"book","type":"update","data":[{"symbol":"EUR/USD","bids":[{"price":1.08356,"qty":2111.05534080}],"asks":[],"checksum":4163051545,"timestamp":"2024-06-01T17:52:30.904623Z"}]}
{"channel":"book","type":"update","data":[{"symbol":"EUR/USD","bids":[{"price":1.08408,"qty":0.00000000},{"price":1.08350,"qty":962.24087722}],"asks":[],"checksum":2706392878,"timestamp":"2024-06-01T17:52:32.327264Z"}]}
{"channel":"book","type":"update","data":[{"symbol":"EUR/USD","bids":[{"price":1.08354,"qty":0.00000000},{"price":1.08346,"qty":2830.45000000}],"asks":[],"checksum":3942853008,"timestamp":"2024-06-01T17:52:32.327301Z"}]}
{"channel":"book","type":"update","data":[{"symbol":"EUR/USD","bids":[{"price":1.08355,"qty":0.00000000},{"price":1.08343,"qty":4614.93708204}],"asks":[],"checksum":50511610,"timestamp":"2024-06-01T17:52:32.331246Z"}]}
{"channel":"book","type":"update","data":[{"symbol":"EUR/USD","bids":[{"price":1.08409,"qty":0.00000000},{"price":1.08336,"qty":16662.23582757},{"price":1.08406,"qty":3711.02283507}],"asks":[],"checksum":3881047772,"timestamp":"2024-06-01T17:52:32.331414Z"}]}
{"channel":"book","type":"update","data":[{"symbol":"EUR/USD","bids":[{"price":1.08410,"qty":1843.75979497}],"asks":[],"checksum":1111631669,"timestamp":"2024-06-01T17:52:32.334705Z"}]}
{"channel":"book","type":"update","data":[{"symbol":"EUR/USD","bids":[{"price":1.08381,"qty":4395.15093656}],"asks":[],"checksum":3417140815,"timestamp":"2024-06-01T17:52:32.334809Z"}]}
{"channel":"book","type":"update","data":[{"symbol":"EUR/USD","bids":[{"price":1.08357,"qty":59359.72848817}],"asks":[],"checksum":650938140,"timestamp":"2024-06-01T17:52:32.335041Z"}]}
{"channel":"book","type":"update","data":[{"symbol":"EUR/USD","bids":[{"price":1.08406,"qty":0.00000000},{"price":1.08350,"qty":962.24087722},{"price":1.08410,"qty":5554.64570456}],"asks":[],"checksum":2223322652,"timestamp":"2024-06-01T17:52:32.335580Z"}]}
{"channel":"book","type":"update","data":[{"symbol":"EUR/USD","bids":[{"price":1.08410,"qty":1843.75979497},{"price":1.08407,"qty":3710.98860275}],"asks":[],"checksum":1285572686,"timestamp":"2024-06-01T17:52:32.340217Z"}]}
{"channel":"book","type":"update","data":[{"symbol":"EUR/USD","bids":[{"price":1.08382,"qty":631.30575187}],"asks":[],"checksum":949097761,"timestamp":"2024-06-01T17:52:32.342424Z"}]}
{"channel":"book","type":"update","data":[{"symbol":"EUR/USD","bids":[{"price":1.08379,"qty":0.00000000},{"price":1.08356,"qty":2111.05534080}],"asks":[],"checksum":1331733798,"timestamp":"2024-06-01T17:52:32.342470Z"}]}
{"channel":"book","type":"update","data":[{"symbol":"EUR/USD","bids":[{"price":1.08407,"qty":0.00000000},{"price":1.08350,"qty":962.24087722},{"price":1.08411,"qty":3710.85167980}],"asks":[],"checksum":4276739972,"timestamp":"2024-06-01T17:52:32.343362Z"}]}
{"channel":"book","type":"update","data":[{"symbol":"EUR/USD","bids":[{"price":1.08380,"qty":0.00000000},{"price":1.08350,"qty":962.24087722},{"price":1.08383,"qty":1984.80000000}],"asks":[],"checksum":1418501524,"timestamp":"2024-06-01T17:52:32.359733Z"}]}
{"channel":"book","type":"update","data":[{"symbol":"EUR/USD","bids":[{"price":1.08358,"qty":16662.23582757}],"asks":[],"checksum":272470262,"timestamp":"2024-06-01T17:52:32.362645Z"}]}
{"channel":"book","type":"update","data":[{"symbol":"EUR/USD","bids":[],"asks":[{"price":1.08441,"qty":0.00000000},{"price":1.08447,"qty":4610.55811950}],"checksum":1935353333,"timestamp":"2024-06-01T17:52:32.515647Z"}]}
{"channel":"book","type":"update","data":[{"symbol":"EUR/USD","bids":[],"asks":[{"price":1.08442,"qty":0.00000000},{"price":1.08453,"qty":225.72210000}],"checksum":3377518250,"timestamp":"2024-06-01T17:52:32.515953Z"}]}
{"channel":"book","type":"update","data":[{"symbol":"EUR/USD","bids":[],"asks":[{"price":1.08437,"qty":0.00000000},{"price":1.08454,"qty":2830.45000000}],"checksum":3046945887,"timestamp":"2024-06-01T17:52:32.516040Z"}]}
{"channel":"book","type":"update","data":[{"symbol":"EUR/USD","bids":[],"asks":[{"price":1.08434,"qty":147.64825392}],"checksum":656456528,"timestamp":"2024-06-01T17:52:32.521833Z"}]}
{"channel":"book","type":"update","data":[{"symbol":"EUR/USD","bids":[],"asks":[{"price":1.08444,"qty":1014.84903719}],"checksum":183790568,"timestamp":"2024-06-01T17:52:32.521921Z"}]}
{"channel":"book","type":"update","data":[{"symbol":"EUR/USD","bids":[{"price":1.08359,"qty":23.07145691}],"asks":[],"checksum":4023417634,"timestamp":"2024-06-01T17:52:32.929524Z"}]}
{"channel":"book","type":"update","data":[{"symbol":"EUR/USD","bids":[{"price":1.08383,"qty":0.00000000},{"price":1.08357,"qty":59359.72848817},{"price":1.08406,"qty":1984.80000000}],"asks":[],"checksum":3938747817,"timestamp":"2024-06-01T17:52:32.937767Z"}]}
{"channel":"book","type":"update","data":[{"symbol":"EUR/USD","bids":[],"asks":[{"price":1.08435,"qty":0.00000000},{"price":1.08453,"qty":225.72210000}],"checksum":794138162,"timestamp":"2024-06-01T17:52:33.074874Z"}]}
{"channel":"book","type":"update","data":[{"symbol":"EUR/USD","bids":[],"asks":[{"price":1.08446,"qty":0.00000000},{"price":1.08454,"qty":2830.45000000}],"checksum":1956172579,"timestamp":"2024-06-01T17:52:33.075099Z"}]}
{"channel":"book","type":"update","data":[{"symbol":"EUR/USD","bids":[],"asks":[{"price":1.08443,"qty":18173.49307590}],"checksum":1545311847,"timestamp":"2024-06-01T17:52:33.077062Z"}]}
{"channel":"book","type":"update","data":[{"symbol":"EUR/USD","bids":[],"asks":[{"price":1.08445,"qty":0.00000000},{"price":1.08454,"qty":2830.45000000}],"checksum":1972305973,"timestamp":"2024-06-01T17:52:33.078916Z"}]}
{"channel":"book","type":"update","data":[{"symbol":"EUR/USD","bids":[],"asks":[{"price":1.08442,"qty":2010.28417243}],"checksum":2206116316,"timestamp":"2024-06-01T17:52:33.187204Z"}]}
{"channel":"book","type":"update","data":[{"symbol":"EUR/USD","bids":[{"price":1.08412,"qty":9.81218144}],"asks":[],"checksum":1681080811,"timestamp":"2024-06-01T17:52:33.240386Z"}]}
{"channel":"book","type":"update","data":[{"symbol":"EUR/USD","bids":[],"asks":[{"price":1.08444,"qty":0.00000000},{"price":1.08454,"qty":2830.45000000}],"checksum":731421770,"timestamp":"2024-06-01T17:52:34.641439Z"}]}
{"channel":"book","type":"update","data":[{"symbol":"EUR/USD","bids":[],"asks":[{"price":1.08434,"qty":0.00000000},{"price":1.08459,"qty":37769.17301302}],"checksum":4052170182,"timestamp":"2024-06-01T17:52:34.641479Z"}]}
{"channel":"book","type":"update","data":[{"symbol":"EUR/USD","bids":[],"asks":[{"price":1.08438,"qty":47.15107705}],"checksum":142921623,"timestamp":"2024-06-01T17:52:34.683663Z"}]}
{"channel":"book","type":"update","data":[{"symbol":"EUR/USD","bids":[],"asks":[{"price":1.08441,"qty":1247.81657895}],"checksum":2799588951,"timestamp":"2024-06-01T17:52:34.683680Z"}]}
{"channel":"book","type":"update","data":[{"symbol":"EUR/USD","bids":[{"price":1.08359,"qty":2028.27287614}],"asks":[],"checksum":1806627720,"timestamp":"2024-06-01T17:52:35.548883Z"}]}
{"channel":"book","type":"update","data":[{"symbol":"EUR/USD","bids":[],"asks":[{"price":1.08443,"qty":0.00000000},{"price":1.08454,"qty":2830.45000000}],"checksum":1965898057,"timestamp":"2024-06-01T17:52:35.638172Z"}]}
{"channel":"book","type":"update","data":[{"symbol":"EUR/USD","bids":[],"asks":[{"price":1.08438,"qty":14954.69749677}],"checksum":1391532482,"timestamp":"2024-06-01T17:52:35.640378Z"}]}
{"channel":"book","type":"update","data":[{"symbol":"EUR/USD","bids":[],"asks":[{"price":1.08442,"qty":0.00000000},{"price":1.08459,"qty":37769.17301302},{"price":1.08458,"qty":2010.28417243}],"checksum":3624261604,"timestamp":"2024-06-01T17:52:35.642062Z"}]}
{"channel":"book","type":"update","data":[{"symbol":"EUR/USD","bids":[{"price":1.08410,"qty":0.00000000},{"price":1.08358,"qty":16662.23582757}],"asks":[],"checksum":4018486311,"timestamp":"2024-06-01T17:52:35.840074Z"}]}
{"channel":"book","type":"update","data":[{"symbol":"EUR/USD","bids":[{"price":1.08381,"qty":0.00000000},{"price":1.08350,"qty":962.24087722}],"asks":[],"checksum":349516644,"timestamp":"2024-06-01T17:52:35.840280Z"}]}
{"channel":"book","type":"update","data":[{"symbol":"EUR/USD","bids":[{"price":1.08358,"qty":0.00000000},{"price":1.08346,"qty":2830.45000000}],"asks":[],"checksum":492952661,"timestamp":"2024-06-01T17:52:35.843374Z"}]}
{"channel":"book","type":"update","data":[{"symbol":"EUR/USD","bids":[{"price":1.08411,"qty":0.00000000},{"price":1.08343,"qty":4614.93708204},{"price":1.08407,"qty":3710.98860275}],"asks":[],"checksum":4049194823,"timestamp":"2024-06-01T17:52:35.843403Z"}]}
{"channel":"book","type":"update","data":[{"symbol":"EUR/USD","bids":[{"price":1.08382,"qty":0.00000000},{"price":1.08343,"qty":4614.93708204}],"asks":[],"checksum":2479074730,"timestamp":"2024-06-01T17:52:35.846359Z"}]}
{"channel":"book","type":"update","data":[{"symbol":"EUR/USD","bids":[{"price":1.08379,"qty":631.32322682}],"asks":[],"checksum":17565670,"timestamp":"2024-06-01T17:52:35.846390Z"}]}
{"channel":"book","type":"update","data":[{"symbol":"EUR/USD","bids":[{"price":1.08359,"qty":92512.63051221}],"asks":[],"checksum":3793122661,"timestamp":"2024-06-01T17:52:35.846453Z"}]}
{"channel":"book","type":"update","data":[{"symbol":"EUR/USD","bids":[{"price":1.08407,"qty":0.00000000},{"price":1.08343,"qty":4614.93708204},{"price":1.08412,"qty":3720.62963208}],"asks":[],"checksum":1195759112,"timestamp":"2024-06-01T17:52:35.846816Z"}]}
{"channel":"book","type":"update","data":[{"symbol":"EUR/USD","bids":[],"asks":[{"price":1.08458,"qty":0.00000000},{"price":1.08459,"qty":37769.17301302},{"price":1.08437,"qty":2010.28417243}],"checksum":2508113446,"timestamp":"2024-06-01T17:52:35.846897Z"}]}
{"channel":"book","type":"update","data":[{"symbol":"EUR/USD","bids":[{"price":1.08412,"qty":9.81218144},{"price":1.08407,"qty":3710.98860275}],"asks":[],"checksum":1919832367,"timestamp":"2024-06-01T17:52:35.849715Z"}]}
{"channel":"book","type":"update","data":[{"symbol":"EUR/USD","bids":[{"price":1.08406,"qty":0.00000000},{"price":1.08343,"qty":4614.93708204},{"price":1.08380,"qty":1984.80000000}],"asks":[],"checksum":139015151,"timestamp":"2024-06-01T17:52:35.880654Z"}]}
{"channel":"book","type":"update","data":[{"symbol":"EUR/USD","bids":[{"price":1.08407,"qty":0.00000000},{"price":1.08343,"qty":4614.93708204},{"price":1.08406,"qty":3711.02283507}],"asks":[],"checksum":3567686654,"timestamp":"2024-06-01T17:52:35.883956Z"}]}
{"channel":"book","type":"update","data":[{"symbol":"EUR/USD","bids":[{"price":1.08360,"qty":16662.23582757}],"asks":[],"checksum":3316389449,"timestamp":"2024-06-01T17:52:35.884032Z"}]}
{"channel":"book","type":"update","data":[{"symbol":"EUR/USD","bids":[],"asks":[{"price":1.08441,"qty":0.00000000},{"price":1.08459,"qty":37769.17301302}],"checksum":4013598408,"timestamp":"2024-06-01T17:52:36.782126Z"}]}
{"channel":"book","type":"update","data":[{"symbol":"EUR/USD","bids":[],"asks":[{"price":1.08438,"qty":14907.54641972}],"checksum":3084188867,"timestamp":"2024-06-01T17:52:36.782151Z"}]}
{"channel":"book","type":"update","data":[{"symbol":"EUR/USD","bids":[{"price":1.08380,"qty":0.00000000},{"price":1.08346,"qty":2830.45000000},{"price":1.08407,"qty":1984.80000000}],"asks":[],"checksum":2229075200,"timestamp":"2024-06-01T17:52:36.819898Z"}]}
{"channel":"book","type":"update","data":[{"symbol":"EUR/USD","bids":[{"price":1.08406,"qty":0.00000000},{"price":1.08346,"qty":2830.45000000},{"price":1.08408,"qty":3710.95437107}],"asks":[],"checksum":1303641210,"timestamp":"2024-06-01T17:52:36.823002Z"}]}
{"channel":"book","type":"update","data":[{"symbol":"EUR/USD","bids":[],"asks":[{"price":1.08436,"qty":319.92912854}],"checksum":3240309336,"timestamp":"2024-06-01T17:52:36.823585Z"}]}
{"channel":"book","type":"update","data":[{"symbol":"EUR/USD","bids":[{"price":1.08359,"qty":92489.55905530},{"price":1.08360,"qty":16685.30707157}],"asks":[],"checksum":1324804332,"timestamp":"2024-06-01T17:52:36.835916Z"}]}
{"channel":"book","type":"update","data":[{"symbol":"EUR/USD","bids":[{"price":1.08407,"qty":0.00000000},{"price":1.08346,"qty":2830.45000000},{"price":1.08380,"qty":1984.80000000}],"asks":[],"checksum":3490201387,"timestamp":"2024-06-01T17:52:37.155467Z"}]}
{"channel":"book","type":"update","data":[{"symbol":"EUR/USD","bids":[{"price":1.08408,"qty":0.00000000},{"price":1.08346,"qty":2830.45000000},{"price":1.08406,"qty":3711.02283507}],"asks":[],"checksum":3029461077,"timestamp":"2024-06-01T17:52:37.158804Z"}]}
{"channel":"book","type":"update","data":[{"symbol":"EUR/USD","bids":[{"price":1.08359,"qty":90484.35763607}],"asks":[],"checksum":93029459,"timestamp":"2024-06-01T17:52:37.645199Z"}]}
{"channel":"book","type":"update","data":[{"symbol":"EUR/USD","bids":[{"price":1.08361,"qty":2121.09597548}],"asks":[],"checksum":4234492575,"timestamp":"2024-06-01T17:52:37.653708Z"}]}
{"channel":"book","type":"update","data":[{"symbol":"EUR/USD","bids":[{"price":1.08380,"qty":0.00000000},{"price":1.08350,"qty":962.24087722},{"price":1.08407,"qty":1984.80000000}],"asks":[],"checksum":4265320852,"timestamp":"2024-06-01T17:52:37.681597Z"}]}
{"channel":"book","type":"update","data":[{"symbol":"EUR/USD","bids":[{"price":1.08406,"qty":0.00000000},{"price":1.08350,"qty":962.24087722},{"price":1.08408,"qty":3710.95437107}],"asks":[],"checksum":1310873271,"timestamp":"2024-06-01T17:52:37.685226Z"}]}
{"channel":"book","type":"update","data":[{"symbol":"EUR/USD","bids":[],"asks":[{"price":1.08438,"qty":0.00000000},{"price":1.08458,"qty":923.61924787}],"checksum":37469077,"timestamp":"2024-06-01T17:52:38.151002Z"}]}
{"channel":"book","type":"update","data":[{"symbol":"EUR/USD","bids":[],"asks":[{"price":1.08437,"qty":0.00000000},{"price":1.08460,"qty":4167.00000000},{"price":1.08458,"qty":2933.90342030}],"checksum":2813845434,"timestamp":"2024-06-01T17:52:38.155244Z"}]}
{"channel":"book","type":"update","data":[{"symbol":"EUR/USD","bids":[],"asks":[{"price":1.08446,"qty":16615.82452564}],"checksum":3977783285,"timestamp":"2024-06-01T17:52:38.156187Z"}]}
{"channel":"book","type":"update","data":[{"symbol":"EUR/USD","bids":[],"asks":[{"price":1.08436,"qty":3805.02944914}],"checksum":3520665579,"timestamp":"2024-06-01T17:52:38.156324Z"}]}
{"channel":"book","type":"update","data":[{"symbol":"EUR/USD","bids":[],"asks":[{"price":1.08436,"qty":3485.10032060}],"checksum":1177463472,"timestamp":"2024-06-01T17:52:38.851755Z"}]}
{"channel":"book","type":"update","data":[{"symbol":"EUR/USD","bids":[],"asks":[{"price":1.08458,"qty":2010.28417243}],"checksum":11714653,"timestamp":"2024-06-01T17:52:38.851819Z"}]}
{"channel":"book","type":"update","data":[{"symbol":"EUR/USD","bids":[],"asks":[{"price":1.08435,"qty":61.50781661}],"checksum":2779595680,"timestamp":"2024-06-01T17:52:38.858171Z"}]}
{"channel":"book","type":"update","data":[{"symbol":"EUR/USD","bids":[],"asks":[{"price":1.08445,"qty":1060.84247870}],"checksum":1611153650,"timestamp":"2024-06-01T17:52:38.858288Z"}]}
{"channel":"book","type":"update","data":[{"symbol":"EUR/USD","bids":[{"price":1.08359,"qty":0.00000000},{"price":1.08350,"qty":962.24087722}],"asks":[],"checksum":96256908,"timestamp":"2024-06-01T17:52:39.388780Z"}]}
{"channel":"book","type":"update","data":[{"symbol":"EUR/USD","bids":[],"asks":[{"price":1.08444,"qty":2010.28417243}],"checksum":3310203151,"timestamp":"2024-06-01T17:52:39.391820Z"}]}
{"channel":"book","type":"update","data":[{"symbol":"EUR/USD","bids":[{"price":1.08360,"qty":23.07124400}],"asks":[],"checksum":470513116,"timestamp":"2024-06-01T17:52:39.392195Z"}]}
{"channel":"book","type":"update","data":[{"symbol":"EUR/USD","bids":[{"price":1.08362,"qty":75173.48049627}],"asks":[],"checksum":1479618475,"timestamp":"2024-06-01T17:52:39.396580Z"}]}
{"channel":"book","type":"update","data":[{"symbol":"EUR/USD","bids":[{"price":1.08409,"qty":4529.83851743}],"asks":[],"checksum":2907181977,"timestamp":"2024-06-01T17:52:39.396601Z"}]}
{"channel":"book","type":"update","data":[{"symbol":"EUR/USD","bids":[{"price":1.08408,"qty":0.00000000},{"price":1.08360,"qty":23.07124400},{"price":1.08410,"qty":3710.88590959}],"asks":[],"checksum":2311276081,"timestamp":"2024-06-01T17:52:39.401129Z"}]}
{"channel":"book","type":"update","data":[{"symbol":"EUR/USD","bids":[{"price":1.08363,"qty":16662.23582757}],"asks":[],"checksum":2426248245,"timestamp":"2024-06-01T17:52:39.486450Z"}]}
{"channel":"book","type":"update","data":[{"symbol":"EUR/USD","bids":[],"asks":[{"price":1.08446,"qty":0.00000000},{"price":1.08453,"qty":225.72210000}],"checksum":3813681152,"timestamp":"2024-06-01T17:52:40.566700Z"}]}
{"channel":"book","type":"update","data":[{"symbol":"EUR/USD","bids":[],"asks":[{"price":1.08436,"qty":0.00000000},{"price":1.08454,"qty":2830.45000000}],"checksum":2111900498,"timestamp":"2024-06-01T17:52:40.567034Z"}]}
{"channel":"book","type":"update","data":[{"symbol":"EUR/USD","bids":[],"asks":[{"price":1.08444,"qty":0.00000000},{"price":1.08460,"qty":4167.00000000}],"checksum":2894895588,"timestamp":"2024-06-01T17:52:40.570001Z"}]}
{"channel":"book","type":"update","data":[{"symbol":"EUR/USD","bids":[],"asks":[{"price":1.08443,"qty":18257.16505127}],"checksum":3027896761,"timestamp":"2024-06-01T17:52:40.571560Z"}]}
{"channel":"book","type":"update","data":[{"symbol":"EUR/USD","bids":[],"asks":[{"price":1.08442,"qty":2010.28417243}],"checksum":1190283283,"timestamp":"2024-06-01T17:52:40.687315Z"}]}
