{"channel":"book","type":"snapshot","data":[{"symbol":"GBP/USD","bids":[{"price":1.27470,"qty":1430.43988537},{"price":1.27457,"qty":51.90394884},{"price":1.27456,"qty":516.09341852},{"price":1.27455,"qty":2713.00921513},{"price":1.27452,"qty":1961.51341241},{"price":1.27436,"qty":13714.25222622},{"price":1.27435,"qty":536.91827206},{"price":1.27434,"qty":3923.59230089},{"price":1.27418,"qty":509.38310000},{"price":1.27410,"qty":314.60440000}],"asks":[{"price":1.27475,"qty":3037.90028301},{"price":1.27476,"qty":340.67774742},{"price":1.27478,"qty":1961.12270352},{"price":1.27495,"qty":898.24290000},{"price":1.27508,"qty":3100.96483999},{"price":1.27509,"qty":3921.30483545},{"price":1.27534,"qty":419.62910000},{"price":1.27537,"qty":22947.39459316},{"price":1.27538,"qty":29222.00000000},{"price":1.27545,"qty":3920.19258238}],"checksum":2156950146}]}
{"channel":"book","type":"update","data":[{"symbol":"GBP/USD","bids":[{"price":1.27436,"qty":0.00000000},{"price":1.27403,"qty":624.07132809}],"asks":[],"checksum":2731764417,"timestamp":"2024-06-01T17:52:10.504920Z"}]}
{"channel":"book","type":"update","data":[{"symbol":"GBP/USD","bids":[{"price":1.27455,"qty":0.00000000},{"price":1.27391,"qty":3924.89588349}],"asks":[],"checksum":3545726400,"timestamp":"2024-06-01T17:52:10.505045Z"}]}
{"channel":"book","type":"update","data":[{"symbol":"GBP/USD","bids":[{"price":1.27456,"qty":0.00000000},{"price":1.27380,"qty":818.35819418},{"price":1.27453,"qty":516.02338592}],"asks":[],"checksum":2501076016,"timestamp":"2024-06-01T17:52:10.508643Z"}]}
{"channel":"book","type":"update","data":[{"symbol":"GBP/USD","bids":[{"price":1.27457,"qty":1621.54705124}],"asks":[],"checksum":3526150830,"timestamp":"2024-06-01T17:52:10.509422Z"}]}
{"channel":"book","type":"update","data":[{"symbol":"GBP/USD","bids":[{"price":1.27436,"qty":14857.61833896}],"asks":[],"checksum":1557520741,"timestamp":"2024-06-01T17:52:10.509574Z"}]}
{"channel":"book","type":"update","data":[{"symbol":"GBP/USD","bids":[{"price":1.27453,"qty":0.00000000},{"price":1.27391,"qty":3924.89588349},{"price":1.27458,"qty":516.00314304}],"asks":[],"checksum":2969398204,"timestamp":"2024-06-01T17:52:10.516905Z"}]}
{"channel":"book","type":"update","data":[{"symbol":"GBP/USD","bids":[],"asks":[{"price":1.27474,"qty":340.67774742}],"checksum":1558134462,"timestamp":"2024-06-01T17:52:10.677503Z"}]}
{"channel":"book","type":"update","data":[{"symbol":"GBP/USD","bids":[],"asks":[{"price":1.27475,"qty":0.00000000},{"price":1.27545,"qty":3920.19258238},{"price":1.27473,"qty":2962.22154603}],"checksum":696642120,"timestamp":"2024-06-01T17:52:10.681127Z"}]}
{"channel":"book","type":"update","data":[{"symbol":"GBP/USD","bids":[],"asks":[{"price":1.27476,"qty":0.00000000},{"price":1.27545,"qty":3920.19258238}],"checksum":2415057769,"timestamp":"2024-06-01T17:52:10.843911Z"}]}
{"channel":"book","type":"update","data":[{"symbol":"GBP/USD","bids":[],"asks":[{"price":1.27495,"qty":0.00000000},{"price":1.27550,"qty":5341.00000000},{"price":1.27507,"qty":898.24290000}],"checksum":2525398675,"timestamp":"2024-06-01T17:52:11.788698Z"}]}
{"channel":"book","type":"update","data":[{"symbol":"GBP/USD","bids":[],"asks":[{"price":1.27508,"qty":0.00000000},{"price":1.27550,"qty":5341.00000000}],"checksum":1135297389,"timestamp":"2024-06-01T17:52:12.100408Z"}]}
{"channel":"book","type":"update","data":[{"symbol":"GBP/USD","bids":[],"asks":[{"price":1.27537,"qty":0.00000000},{"price":1.27561,"qty":2951.35800255}],"checksum":608751979,"timestamp":"2024-06-01T17:52:12.100422Z"}]}
{"channel":"book","type":"update","data":[{"symbol":"GBP/USD","bids":[],"asks":[{"price":1.27537,"qty":21396.63224757}],"checksum":3900748841,"timestamp":"2024-06-01T17:52:12.101645Z"}]}
{"channel":"book","type":"update","data":[{"symbol":"GBP/USD","bids":[],"asks":[{"price":1.27506,"qty":4632.28657759}],"checksum":4168117887,"timestamp":"2024-06-01T17:52:12.102058Z"}]}
{"channel":"book","type":"update","data":[{"symbol":"GBP/USD","bids":[],"asks":[{"price":1.27507,"qty":0.00000000},{"price":1.27550,"qty":5341.00000000},{"price":1.27505,"qty":898.24290000}],"checksum":252609148,"timestamp":"2024-06-01T17:52:12.123796Z"}]}
{"channel":"book","type":"update","data":[{"symbol":"GBP/USD","bids":[{"price":1.27457,"qty":51.90394884}],"asks":[],"checksum":1305293713,"timestamp":"2024-06-01T17:52:14.184108Z"}]}
{"channel":"book","type":"update","data":[{"symbol":"GBP/USD","bids":[{"price":1.27436,"qty":0.00000000},{"price":1.27391,"qty":3924.89588349}],"asks":[],"checksum":3421856373,"timestamp":"2024-06-01T17:52:14.184273Z"}]}
{"channel":"book","type":"update","data":[{"symbol":"GBP/USD","bids":[{"price":1.27453,"qty":1569.64310240}],"asks":[],"checksum":3723957298,"timestamp":"2024-06-01T17:52:14.186505Z"}]}
{"channel":"book","type":"update","data":[{"symbol":"GBP/USD","bids":[{"price":1.27436,"qty":12574.23581896}],"asks":[],"checksum":4198491775,"timestamp":"2024-06-01T17:52:14.186570Z"}]}
{"channel":"book","type":"update","data":[{"symbol":"GBP/USD","bids":[{"price":1.27458,"qty":0.00000000},{"price":1.27403,"qty":624.07132809},{"price":1.27453,"qty":2086.24062342}],"asks":[],"checksum":2554256751,"timestamp":"2024-06-01T17:52:14.187548Z"}]}
{"channel":"book","type":"update","data":[{"symbol":"GBP/USD","bids":[{"price":1.27453,"qty":1569.64310240},{"price":1.27454,"qty":516.59346782}],"asks":[],"checksum":1112416603,"timestamp":"2024-06-01T17:52:14.190862Z"}]}
{"channel":"book","type":"update","data":[{"symbol":"GBP/USD","bids":[{"price":1.27454,"qty":0.00000000},{"price":1.27403,"qty":624.07132809},{"price":1.27455,"qty":516.58941467}],"asks":[],"checksum":161887598,"timestamp":"2024-06-01T17:52:14.193942Z"}]}
{"channel":"book","type":"update","data":[{"symbol":"GBP/USD","bids":[{"price":1.27455,"qty":0.00000000},{"price":1.27403,"qty":624.07132809},{"price":1.27456,"qty":516.58536159}],"asks":[],"checksum":2379444511,"timestamp":"2024-06-01T17:52:14.197396Z"}]}
{"channel":"book","type":"update","data":[{"symbol":"GBP/USD","bids":[{"price":1.27456,"qty":0.00000000},{"price":1.27403,"qty":624.07132809},{"price":1.27454,"qty":516.59346782}],"asks":[],"checksum":1112416603,"timestamp":"2024-06-01T17:52:14.200788Z"}]}
{"channel":"book","type":"update","data":[{"symbol":"GBP/USD","bids":[],"asks":[{"price":1.27506,"qty":0.00000000},{"price":1.27550,"qty":5341.00000000}],"checksum":1375349392,"timestamp":"2024-06-01T17:52:14.591383Z"}]}
{"channel":"book","type":"update","data":[{"symbol":"GBP/USD","bids":[],"asks":[{"price":1.27537,"qty":0.00000000},{"price":1.27561,"qty":2951.35800255}],"checksum":1892467027,"timestamp":"2024-06-01T17:52:14.591423Z"}]}
{"channel":"book","type":"update","data":[{"symbol":"GBP/USD","bids":[],"asks":[{"price":1.27504,"qty":3100.96483999}],"checksum":2378145203,"timestamp":"2024-06-01T17:52:14.592761Z"}]}
{"channel":"book","type":"update","data":[{"symbol":"GBP/USD","bids":[],"asks":[{"price":1.27537,"qty":22947.39459316}],"checksum":2331235618,"timestamp":"2024-06-01T17:52:14.592792Z"}]}
{"channel":"book","type":"update","data":[{"symbol":"GBP/USD","bids":[],"asks":[{"price":1.27505,"qty":0.00000000},{"price":1.27550,"qty":5341.00000000},{"price":1.27503,"qty":898.24290000}],"checksum":1352076833,"timestamp":"2024-06-01T17:52:14.605017Z"}]}
{"channel":"book","type":"update","data":[{"symbol":"GBP/USD","bids":[],"asks":[{"price":1.27504,"qty":0.00000000},{"price":1.27550,"qty":5341.00000000}],"checksum":3317816816,"timestamp":"2024-06-01T17:52:17.078439Z"}]}
{"channel":"book","type":"update","data":[{"symbol":"GBP/USD","bids":[],"asks":[{"price":1.27508,"qty":3100.96483999}],"checksum":2286274514,"timestamp":"2024-06-01T17:52:17.079409Z"}]}
{"channel":"book","type":"update","data":[{"symbol":"GBP/USD","bids":[{"price":1.27436,"qty":0.00000000},{"price":1.27403,"qty":624.07132809}],"asks":[],"checksum":2621531069,"timestamp":"2024-06-01T17:52:17.715143Z"}]}
{"channel":"book","type":"update","data":[{"symbol":"GBP/USD","bids":[{"price":1.27453,"qty":0.00000000},{"price":1.27391,"qty":3924.89588349}],"asks":[],"checksum":2319652346,"timestamp":"2024-06-01T17:52:17.715222Z"}]}
{"channel":"book","type":"update","data":[{"symbol":"GBP/USD","bids":[{"price":1.27454,"qty":0.00000000},{"price":1.27380,"qty":818.31347145},{"price":1.27453,"qty":516.60389156}],"asks":[],"checksum":545582915,"timestamp":"2024-06-01T17:52:17.719184Z"}]}
{"channel":"book","type":"update","data":[{"symbol":"GBP/USD","bids":[{"price":1.27436,"qty":13714.81051052}],"asks":[],"checksum":3662791867,"timestamp":"2024-06-01T17:52:17.720259Z"}]}
{"channel":"book","type":"update","data":[{"symbol":"GBP/USD","bids":[{"price":1.27455,"qty":1569.64310240}],"asks":[],"checksum":1633118868,"timestamp":"2024-06-01T17:52:17.720327Z"}]}
{"channel":"book","type":"update","data":[{"symbol":"GBP/USD","bids":[{"price":1.27453,"qty":0.00000000},{"price":1.27403,"qty":624.07132809},{"price":1.27456,"qty":516.59173198}],"asks":[],"checksum":3084898999,"timestamp":"2024-06-01T17:52:17.723678Z"}]}
{"channel":"book","type":"update","data":[{"symbol":"GBP/USD","bids":[],"asks":[{"price":1.27473,"qty":0.00000000},{"price":1.27550,"qty":5341.00000000},{"price":1.27477,"qty":2962.13242600}],"checksum":1459787052,"timestamp":"2024-06-01T17:52:21.260289Z"}]}
{"channel":"book","type":"update","data":[{"symbol":"GBP/USD","bids":[{"price":1.27455,"qty":0.00000000},{"price":1.27403,"qty":624.07132809}],"asks":[],"checksum":1487359565,"timestamp":"2024-06-01T17:52:21.319794Z"}]}
{"channel":"book","type":"update","data":[{"symbol":"GBP/USD","bids":[{"price":1.27436,"qty":0.00000000},{"price":1.27391,"qty":3924.89588349}],"asks":[],"checksum":3740981269,"timestamp":"2024-06-01T17:52:21.319919Z"}]}
{"channel":"book","type":"update","data":[{"symbol":"GBP/USD","bids":[{"price":1.27456,"qty":0.00000000},{"price":1.27380,"qty":818.31347145},{"price":1.27453,"qty":516.58577915}],"asks":[],"checksum":3860883052,"timestamp":"2024-06-01T17:52:21.323133Z"}]}
{"channel":"book","type":"update","data":[{"symbol":"GBP/USD","bids":[{"price":1.27453,"qty":2086.22888155}],"asks":[],"checksum":3326067694,"timestamp":"2024-06-01T17:52:21.324320Z"}]}
{"channel":"book","type":"update","data":[{"symbol":"GBP/USD","bids":[{"price":1.27436,"qty":12345.18771643}],"asks":[],"checksum":1968024336,"timestamp":"2024-06-01T17:52:21.324413Z"}]}
{"channel":"book","type":"update","data":[{"symbol":"GBP/USD","bids":[{"price":1.27453,"qty":1569.64310240},{"price":1.27454,"qty":516.58172604}],"asks":[],"checksum":453730055,"timestamp":"2024-06-01T17:52:21.327862Z"}]}
{"channel":"book","type":"update","data":[{"symbol":"GBP/USD","bids":[],"asks":[{"price":1.27476,"qty":340.67774742}],"checksum":2650827262,"timestamp":"2024-06-01T17:52:21.492186Z"}]}
{"channel":"book","type":"update","data":[{"symbol":"GBP/USD","bids":[{"price":1.27436,"qty":12397.09166527}],"asks":[],"checksum":1942064210,"timestamp":"2024-06-01T17:52:21.494698Z"}]}
{"channel":"book","type":"update","data":[{"symbol":"GBP/USD","bids":[],"asks":[{"price":1.27477,"qty":0.00000000},{"price":1.27545,"qty":3920.19258238},{"price":1.27473,"qty":2962.13243377}],"checksum":438422377,"timestamp":"2024-06-01T17:52:21.495767Z"}]}
{"channel":"book","type":"update","data":[{"symbol":"GBP/USD","bids":[],"asks":[{"price":1.27474,"qty":0.00000000},{"price":1.27545,"qty":3920.19258238}],"checksum":4085374214,"timestamp":"2024-06-01T17:52:21.656426Z"}]}
{"channel":"book","type":"update","data":[{"symbol":"GBP/USD","bids":[],"asks":[{"price":1.27473,"qty":0.00000000},{"price":1.27550,"qty":5341.00000000},{"price":1.27475,"qty":2962.13243907}],"checksum":3681448490,"timestamp":"2024-06-01T17:52:21.659941Z"}]}
{"channel":"book","type":"update","data":[{"symbol":"GBP/USD","bids":[],"asks":[{"price":1.27475,"qty":0.00000000},{"price":1.27550,"qty":5341.00000000},{"price":1.27474,"qty":2962.13243907}],"checksum":3373299491,"timestamp":"2024-06-01T17:52:21.667544Z"}]}
{"channel":"book","type":"update","data":[{"symbol":"GBP/USD","bids":[{"price":1.27457,"qty":0.00000000},{"price":1.27403,"qty":624.07132809}],"asks":[],"checksum":1962350063,"timestamp":"2024-06-01T17:52:21.668726Z"}]}
{"channel":"book","type":"update","data":[{"symbol":"GBP/USD","bids":[],"asks":[{"price":1.27474,"qty":0.00000000},{"price":1.27550,"qty":5341.00000000},{"price":1.27473,"qty":2962.13243907}],"checksum":3270394569,"timestamp":"2024-06-01T17:52:21.672252Z"}]}
{"channel":"book","type":"update","data":[{"symbol":"GBP/USD","bids":[],"asks":[{"price":1.27473,"qty":0.00000000},{"price":1.27550,"qty":5341.00000000},{"price":1.27475,"qty":2962.13243907}],"checksum":221893454,"timestamp":"2024-06-01T17:52:21.677899Z"}]}
{"channel":"book","type":"update","data":[{"symbol":"GBP/USD","bids":[],"asks":[{"price":1.27475,"qty":0.00000000},{"price":1.27550,"qty":5341.00000000},{"price":1.27474,"qty":2962.13243907}],"checksum":1962350063,"timestamp":"2024-06-01T17:52:21.683446Z"}]}
{"channel":"book","type":"update","data":[{"symbol":"GBP/USD","bids":[],"asks":[{"price":1.27474,"qty":0.00000000},{"price":1.27550,"qty":5341.00000000},{"price":1.27475,"qty":2962.13243907}],"checksum":221893454,"timestamp":"2024-06-01T17:52:21.687632Z"}]}
{"channel":"book","type":"update","data":[{"symbol":"GBP/USD","bids":[{"price":1.27453,"qty":0.00000000},{"price":1.27391,"qty":3924.89588349}],"asks":[],"checksum":2295657989,"timestamp":"2024-06-01T17:52:25.096491Z"}]}
{"channel":"book","type":"update","data":[{"symbol":"GBP/USD","bids":[{"price":1.27436,"qty":51.90394884}],"asks":[],"checksum":2691704811,"timestamp":"2024-06-01T17:52:25.096536Z"}]}
{"channel":"book","type":"update","data":[{"symbol":"GBP/USD","bids":[{"price":1.27454,"qty":0.00000000},{"price":1.27380,"qty":818.31347145},{"price":1.27453,"qty":516.53566904}],"asks":[],"checksum":3122765791,"timestamp":"2024-06-01T17:52:25.099824Z"}]}
{"channel":"book","type":"update","data":[{"symbol":"GBP/USD","bids":[{"price":1.27436,"qty":11485.56507623}],"asks":[],"checksum":252048573,"timestamp":"2024-06-01T17:52:25.103239Z"}]}
{"channel":"book","type":"update","data":[{"symbol":"GBP/USD","bids":[{"price":1.27455,"qty":2713.00921514}],"asks":[],"checksum":3812079774,"timestamp":"2024-06-01T17:52:25.103410Z"}]}
{"channel":"book","type":"update","data":[{"symbol":"GBP/USD","bids":[{"price":1.27453,"qty":0.00000000},{"price":1.27391,"qty":3924.89588349},{"price":1.27454,"qty":516.53161632}],"asks":[],"checksum":2043990102,"timestamp":"2024-06-01T17:52:25.104888Z"}]}
{"channel":"book","type":"update","data":[{"symbol":"GBP/USD","bids":[{"price":1.27454,"qty":0.00000000},{"price":1.27391,"qty":3924.89588349},{"price":1.27456,"qty":516.52351107}],"asks":[],"checksum":241076333,"timestamp":"2024-06-01T17:52:25.108195Z"}]}
{"channel":"book","type":"update","data":[{"symbol":"GBP/USD","bids":[{"price":1.27455,"qty":0.00000000},{"price":1.27391,"qty":3924.89588349}],"asks":[],"checksum":771456036,"timestamp":"2024-06-01T17:52:28.641590Z"}]}
{"channel":"book","type":"update","data":[{"symbol":"GBP/USD","bids":[{"price":1.27436,"qty":51.90394884}],"asks":[],"checksum":279604910,"timestamp":"2024-06-01T17:52:28.641719Z"}]}
{"channel":"book","type":"update","data":[{"symbol":"GBP/USD","bids":[{"price":1.27456,"qty":0.00000000},{"price":1.27380,"qty":818.31347145},{"price":1.27453,"qty":516.60460579}],"asks":[],"checksum":3238474433,"timestamp":"2024-06-01T17:52:28.646491Z"}]}
{"channel":"book","type":"update","data":[{"symbol":"GBP/USD","bids":[{"price":1.27457,"qty":1569.64310240}],"asks":[],"checksum":2614544575,"timestamp":"2024-06-01T17:52:28.647022Z"}]}
{"channel":"book","type":"update","data":[{"symbol":"GBP/USD","bids":[{"price":1.27436,"qty":14909.52228786}],"asks":[],"checksum":1020718203,"timestamp":"2024-06-01T17:52:28.647261Z"}]}
{"channel":"book","type":"update","data":[{"symbol":"GBP/USD","bids":[{"price":1.27453,"qty":0.00000000},{"price":1.27391,"qty":3924.89588349},{"price":1.27458,"qty":516.58434011}],"asks":[],"checksum":3026328837,"timestamp":"2024-06-01T17:52:28.650646Z"}]}
{"channel":"book","type":"update","data":[{"symbol":"GBP/USD","bids":[{"price":1.27458,"qty":0.00000000},{"price":1.27391,"qty":3924.89588349},{"price":1.27471,"qty":516.06204855}],"asks":[],"checksum":3882781237,"timestamp":"2024-06-01T17:52:31.640663Z"}]}
{"channel":"book","type":"update","data":[{"symbol":"GBP/USD","bids":[{"price":1.27471,"qty":0.00000000},{"price":1.27391,"qty":3924.89588349},{"price":1.27458,"qty":516.11468398}],"asks":[],"checksum":2935985513,"timestamp":"2024-06-01T17:52:31.649075Z"}]}
{"channel":"book","type":"update","data":[{"symbol":"GBP/USD","bids":[{"price":1.27458,"qty":0.00000000},{"price":1.27391,"qty":3924.89588349},{"price":1.27471,"qty":516.06187084}],"asks":[],"checksum":1956642053,"timestamp":"2024-06-01T17:52:31.749973Z"}]}
{"channel":"book","type":"update","data":[{"symbol":"GBP/USD","bids":[{"price":1.27471,"qty":0.00000000},{"price":1.27391,"qty":3924.89588349},{"price":1.27458,"qty":516.11450625}],"asks":[],"checksum":1850020430,"timestamp":"2024-06-01T17:52:31.760257Z"}]}
{"channel":"book","type":"update","data":[{"symbol":"GBP/USD","bids":[{"price":1.27458,"qty":0.00000000},{"price":1.27391,"qty":3924.89588349},{"price":1.27471,"qty":516.06187084}],"asks":[],"checksum":1956642053,"timestamp":"2024-06-01T17:52:31.855146Z"}]}
{"channel":"book","type":"update","data":[{"symbol":"GBP/USD","bids":[{"price":1.27471,"qty":0.00000000},{"price":1.27391,"qty":3924.89588349},{"price":1.27458,"qty":516.11450625}],"asks":[],"checksum":1850020430,"timestamp":"2024-06-01T17:52:31.861504Z"}]}
{"channel":"book","type":"update","data":[{"symbol":"GBP/USD","bids":[{"price":1.27458,"qty":0.00000000},{"price":1.27391,"qty":3924.89588349},{"price":1.27471,"qty":516.06174980}],"asks":[],"checksum":3875073885,"timestamp":"2024-06-01T17:52:31.960013Z"}]}
{"channel":"book","type":"update","data":[{"symbol":"GBP/USD","bids":[],"asks":[{"price":1.27475,"qty":0.00000000},{"price":1.27550,"qty":5341.00000000},{"price":1.27477,"qty":2962.27504921}],"checksum":2460219993,"timestamp":"2024-06-01T17:52:31.960088Z"}]}
{"channel":"book","type":"update","data":[{"symbol":"GBP/USD","bids":[],"asks":[{"price":1.27477,"qty":0.00000000},{"price":1.27550,"qty":5341.00000000},{"price":1.27502,"qty":2962.27504921}],"checksum":3090652162,"timestamp":"2024-06-01T17:52:31.964336Z"}]}
{"channel":"book","type":"update","data":[{"symbol":"GBP/USD","bids":[],"asks":[{"price":1.27503,"qty":0.00000000},{"price":1.27550,"qty":5341.00000000},{"price":1.27501,"qty":898.24290000}],"checksum":1400847724,"timestamp":"2024-06-01T17:52:31.985913Z"}]}
{"channel":"book","type":"update","data":[{"symbol":"GBP/USD","bids":[],"asks":[{"price":1.27502,"qty":0.00000000},{"price":1.27550,"qty":5341.00000000},{"price":1.27500,"qty":2962.27504921}],"checksum":3916031135,"timestamp":"2024-06-01T17:52:31.988945Z"}]}
{"channel":"book","type":"update","data":[{"symbol":"GBP/USD","bids":[],"asks":[{"price":1.27537,"qty":0.00000000},{"price":1.27550,"qty":5341.00000000}],"checksum":2145038239,"timestamp":"2024-06-01T17:52:31.995780Z"}]}
{"channel":"book","type":"update","data":[{"symbol":"GBP/USD","bids":[],"asks":[{"price":1.27508,"qty":0.00000000},{"price":1.27561,"qty":2951.35800255}],"checksum":3010119172,"timestamp":"2024-06-01T17:52:31.995944Z"}]}
{"channel":"book","type":"update","data":[{"symbol":"GBP/USD","bids":[],"asks":[{"price":1.27508,"qty":1569.64310240}],"checksum":1734253624,"timestamp":"2024-06-01T17:52:31.996936Z"}]}
{"channel":"book","type":"update","data":[{"symbol":"GBP/USD","bids":[],"asks":[{"price":1.27537,"qty":19907.18258873}],"checksum":3525782463,"timestamp":"2024-06-01T17:52:31.997026Z"}]}
{"channel":"book","type":"update","data":[{"symbol":"GBP/USD","bids":[],"asks":[{"price":1.27500,"qty":0.00000000},{"price":1.27550,"qty":5341.00000000},{"price":1.27475,"qty":2962.27504921}],"checksum":2914610588,"timestamp":"2024-06-01T17:52:32.004328Z"}]}
{"channel":"book","type":"update","data":[{"symbol":"GBP/USD","bids":[{"price":1.27471,"qty":0.00000000},{"price":1.27391,"qty":3924.89588349},{"price":1.27458,"qty":516.11430276}],"asks":[],"checksum":3664429566,"timestamp":"2024-06-01T17:52:32.125466Z"}]}
{"channel":"book","type":"update","data":[{"symbol":"GBP/USD","bids":[{"price":1.27458,"qty":0.00000000},{"price":1.27391,"qty":3924.89588349},{"price":1.27471,"qty":516.06166736}],"asks":[],"checksum":2651749277,"timestamp":"2024-06-01T17:52:32.294170Z"}]}
{"channel":"book","type":"update","data":[{"symbol":"GBP/USD","bids":[{"price":1.27457,"qty":0.00000000},{"price":1.27391,"qty":3924.89588349}],"asks":[],"checksum":26326659,"timestamp":"2024-06-01T17:52:32.327055Z"}]}
{"channel":"book","type":"update","data":[{"symbol":"GBP/USD","bids":[{"price":1.27436,"qty":51.90394884}],"asks":[],"checksum":1884979071,"timestamp":"2024-06-01T17:52:32.327231Z"}]}
{"channel":"book","type":"update","data":[{"symbol":"GBP/USD","bids":[{"price":1.27453,"qty":1569.64310240}],"asks":[],"checksum":444651885,"timestamp":"2024-06-01T17:52:32.334149Z"}]}
{"channel":"book","type":"update","data":[{"symbol":"GBP/USD","bids":[{"price":1.27436,"qty":10640.74035770}],"asks":[],"checksum":4236584073,"timestamp":"2024-06-01T17:52:32.334319Z"}]}
{"channel":"book","type":"update","data":[{"symbol":"GBP/USD","bids":[{"price":1.27471,"qty":0.00000000},{"price":1.27391,"qty":3924.89588349},{"price":1.27454,"qty":516.11626575}],"asks":[],"checksum":3490276672,"timestamp":"2024-06-01T17:52:32.352084Z"}]}
{"channel":"book","type":"update","data":[{"symbol":"GBP/USD","bids":[{"price":1.27455,"qty":51.90394884}],"asks":[],"checksum":750150997,"timestamp":"2024-06-01T17:52:32.522479Z"}]}
{"channel":"book","type":"update","data":[{"symbol":"GBP/USD","bids":[{"price":1.27436,"qty":10588.83640886}],"asks":[],"checksum":1840784951,"timestamp":"2024-06-01T17:52:32.686029Z"}]}
{"channel":"book","type":"update","data":[{"symbol":"GBP/USD","bids":[{"price":1.27454,"qty":0.00000000},{"price":1.27403,"qty":624.07132809},{"price":1.27471,"qty":516.05142508}],"asks":[],"checksum":1760153943,"timestamp":"2024-06-01T17:52:32.970152Z"}]}
{"channel":"book","type":"update","data":[{"symbol":"GBP/USD","bids":[{"price":1.27471,"qty":0.00000000},{"price":1.27403,"qty":624.07132809},{"price":1.27454,"qty":516.12025677}],"asks":[],"checksum":235373294,"timestamp":"2024-06-01T17:52:33.009333Z"}]}
{"channel":"book","type":"update","data":[{"symbol":"GBP/USD","bids":[{"price":1.27454,"qty":0.00000000},{"price":1.27403,"qty":624.07132809},{"price":1.27471,"qty":516.05202197}],"asks":[],"checksum":2358163314,"timestamp":"2024-06-01T17:52:33.253327Z"}]}
{"channel":"book","type":"update","data":[{"symbol":"GBP/USD","bids":[{"price":1.27471,"qty":0.00000000},{"price":1.27403,"qty":624.07132809},{"price":1.27454,"qty":516.12085374}],"asks":[],"checksum":3071376383,"timestamp":"2024-06-01T17:52:33.257546Z"}]}
{"channel":"book","type":"update","data":[{"symbol":"GBP/USD","bids":[{"price":1.27454,"qty":0.00000000},{"price":1.27403,"qty":624.07132809},{"price":1.27471,"qty":516.05270569}],"asks":[],"checksum":2250054835,"timestamp":"2024-06-01T17:52:33.611106Z"}]}
{"channel":"book","type":"update","data":[{"symbol":"GBP/USD","bids":[{"price":1.27471,"qty":0.00000000},{"price":1.27403,"qty":624.07132809},{"price":1.27454,"qty":516.12172616}],"asks":[],"checksum":1025439277,"timestamp":"2024-06-01T17:52:33.693522Z"}]}
{"channel":"book","type":"update","data":[{"symbol":"GBP/USD","bids":[{"price":1.27454,"qty":0.00000000},{"price":1.27403,"qty":624.07132809},{"price":1.27471,"qty":516.04132865}],"asks":[],"checksum":476834867,"timestamp":"2024-06-01T17:52:34.430604Z"}]}
{"channel":"book","type":"update","data":[{"symbol":"GBP/USD","bids":[{"price":1.27471,"qty":0.00000000},{"price":1.27403,"qty":624.07132809},{"price":1.27454,"qty":516.11015900}],"asks":[],"checksum":4169866594,"timestamp":"2024-06-01T17:52:34.435440Z"}]}
{"channel":"book","type":"update","data":[{"symbol":"GBP/USD","bids":[],"asks":[{"price":1.27508,"qty":0.00000000},{"price":1.27550,"qty":5341.00000000}],"checksum":4278250386,"timestamp":"2024-06-01T17:52:34.540456Z"}]}
{"channel":"book","type":"update","data":[{"symbol":"GBP/USD","bids":[],"asks":[{"price":1.27537,"qty":0.00000000},{"price":1.27561,"qty":2951.35800255}],"checksum":3053449446,"timestamp":"2024-06-01T17:52:34.540531Z"}]}
{"channel":"book","type":"update","data":[{"symbol":"GBP/USD","bids":[],"asks":[{"price":1.27508,"qty":3100.96483999}],"checksum":165805650,"timestamp":"2024-06-01T17:52:34.541893Z"}]}
{"channel":"book","type":"update","data":[{"symbol":"GBP/USD","bids":[],"asks":[{"price":1.27537,"qty":22947.39459316}],"checksum":3630495042,"timestamp":"2024-06-01T17:52:34.542100Z"}]}
{"channel":"book","type":"update","data":[{"symbol":"GBP/USD","bids":[{"price":1.27454,"qty":0.00000000},{"price":1.27403,"qty":624.07132809},{"price":1.27471,"qty":516.04132865}],"asks":[],"checksum":1015284755,"timestamp":"2024-06-01T17:52:34.570541Z"}]}
{"channel":"book","type":"update","data":[{"symbol":"GBP/USD","bids":[{"price":1.27471,"qty":0.00000000},{"price":1.27403,"qty":624.07132809},{"price":1.27454,"qty":516.11015900}],"asks":[],"checksum":3630495042,"timestamp":"2024-06-01T17:52:34.601456Z"}]}
{"channel":"book","type":"update","data":[{"symbol":"GBP/USD","bids":[{"price":1.27453,"qty":0.00000000},{"price":1.27403,"qty":624.07132809}],"asks":[],"checksum":533456198,"timestamp":"2024-06-01T17:52:35.839893Z"}]}
{"channel":"book","type":"update","data":[{"symbol":"GBP/USD","bids":[{"price":1.27436,"qty":0.00000000},{"price":1.27391,"qty":3924.89588349}],"asks":[],"checksum":1133520978,"timestamp":"2024-06-01T17:52:35.839953Z"}]}
{"channel":"book","type":"update","data":[{"symbol":"GBP/USD","bids":[{"price":1.27454,"qty":0.00000000},{"price":1.27380,"qty":818.31347145},{"price":1.27453,"qty":516.11632407}],"asks":[],"checksum":2858734129,"timestamp":"2024-06-01T17:52:35.843346Z"}]}
{"channel":"book","type":"update","data":[{"symbol":"GBP/USD","bids":[{"price":1.27455,"qty":2764.91316398}],"asks":[],"checksum":924556028,"timestamp":"2024-06-01T17:52:35.846176Z"}]}
{"channel":"book","type":"update","data":[{"symbol":"GBP/USD","bids":[{"price":1.27436,"qty":14854.54777573}],"asks":[],"checksum":1487158928,"timestamp":"2024-06-01T17:52:35.846327Z"}]}
{"channel":"book","type":"update","data":[{"symbol":"GBP/USD","bids":[],"asks":[{"price":1.27474,"qty":340.67774742}],"checksum":408496776,"timestamp":"2024-06-01T17:52:36.017423Z"}]}
{"channel":"book","type":"update","data":[{"symbol":"GBP/USD","bids":[],"asks":[{"price":1.27475,"qty":0.00000000},{"price":1.27545,"qty":3920.19258238},{"price":1.27500,"qty":2962.29289720}],"checksum":1226912269,"timestamp":"2024-06-01T17:52:36.021024Z"}]}
{"channel":"book","type":"update","data":[{"symbol":"GBP/USD","bids":[{"price":1.27453,"qty":0.00000000},{"price":1.27391,"qty":3924.89588349},{"price":1.27456,"qty":516.10417596}],"asks":[],"checksum":990964475,"timestamp":"2024-06-01T17:52:36.040926Z"}]}
{"channel":"book","type":"update","data":[{"symbol":"GBP/USD","bids":[],"asks":[{"price":1.27500,"qty":0.00000000},{"price":1.27545,"qty":3920.19258238},{"price":1.27475,"qty":2962.29289720}],"checksum":732094316,"timestamp":"2024-06-01T17:52:36.040975Z"}]}
{"channel":"book","type":"update","data":[{"symbol":"GBP/USD","bids":[],"asks":[{"price":1.27475,"qty":0.00000000},{"price":1.27545,"qty":3920.19258238},{"price":1.27500,"qty":2962.29289720}],"checksum":990964475,"timestamp":"2024-06-01T17:52:36.044382Z"}]}
{"channel":"book","type":"update","data":[{"symbol":"GBP/USD","bids":[],"asks":[{"price":1.27501,"qty":0.00000000},{"price":1.27545,"qty":3920.19258238},{"price":1.27499,"qty":898.24290000}],"checksum":2097148605,"timestamp":"2024-06-01T17:52:36.055868Z"}]}
{"channel":"book","type":"update","data":[{"symbol":"GBP/USD","bids":[],"asks":[{"price":1.27476,"qty":0.00000000},{"price":1.27545,"qty":3920.19258238}],"checksum":114507781,"timestamp":"2024-06-01T17:52:36.183134Z"}]}
{"channel":"book","type":"update","data":[{"symbol":"GBP/USD","bids":[],"asks":[{"price":1.27500,"qty":0.00000000},{"price":1.27550,"qty":5341.00000000},{"price":1.27477,"qty":2962.29289720}],"checksum":765246532,"timestamp":"2024-06-01T17:52:36.339209Z"}]}
{"channel":"book","type":"update","data":[{"symbol":"GBP/USD","bids":[{"price":1.27456,"qty":0.00000000},{"price":1.27391,"qty":3924.89588349},{"price":1.27471,"qty":516.03106124}],"asks":[],"checksum":2846262218,"timestamp":"2024-06-01T17:52:36.711587Z"}]}
{"channel":"book","type":"update","data":[{"symbol":"GBP/USD","bids":[{"price":1.27471,"qty":0.00000000},{"price":1.27391,"qty":3924.89588349},{"price":1.27456,"qty":516.09179174}],"asks":[],"checksum":552815230,"timestamp":"2024-06-01T17:52:36.715597Z"}]}
{"channel":"book","type":"update","data":[{"symbol":"GBP/USD","bids":[],"asks":[{"price":1.27537,"qty":0.00000000},{"price":1.27550,"qty":5341.00000000}],"checksum":1577238071,"timestamp":"2024-06-01T17:52:37.068470Z"}]}
{"channel":"book","type":"update","data":[{"symbol":"GBP/USD","bids":[],"asks":[{"price":1.27508,"qty":0.00000000},{"price":1.27561,"qty":2951.35800255}],"checksum":2461194156,"timestamp":"2024-06-01T17:52:37.068586Z"}]}
{"channel":"book","type":"update","data":[{"symbol":"GBP/USD","bids":[],"asks":[{"price":1.27508,"qty":1569.64310240}],"checksum":1183223184,"timestamp":"2024-06-01T17:52:37.070067Z"}]}
{"channel":"book","type":"update","data":[{"symbol":"GBP/USD","bids":[],"asks":[{"price":1.27537,"qty":21438.50432633}],"checksum":2070534056,"timestamp":"2024-06-01T17:52:37.070179Z"}]}
{"channel":"book","type":"update","data":[{"symbol":"GBP/USD","bids":[{"price":1.27456,"qty":0.00000000},{"price":1.27391,"qty":3924.89588349},{"price":1.27471,"qty":516.03067750}],"asks":[],"checksum":2926484398,"timestamp":"2024-06-01T17:52:37.238303Z"}]}
{"channel":"book","type":"update","data":[{"symbol":"GBP/USD","bids":[{"price":1.27471,"qty":0.00000000},{"price":1.27391,"qty":3924.89588349},{"price":1.27456,"qty":516.09140795}],"asks":[],"checksum":3522724354,"timestamp":"2024-06-01T17:52:37.352582Z"}]}
{"channel":"book","type":"update","data":[{"symbol":"GBP/USD","bids":[{"price":1.27456,"qty":0.00000000},{"price":1.27391,"qty":3924.89588349},{"price":1.27471,"qty":516.03067750}],"asks":[],"checksum":2926484398,"timestamp":"2024-06-01T17:52:37.627009Z"}]}
{"channel":"book","type":"update","data":[{"symbol":"GBP/USD","bids":[{"price":1.27471,"qty":0.00000000},{"price":1.27391,"qty":3924.89588349},{"price":1.27456,"qty":516.09131341}],"asks":[],"checksum":2937499626,"timestamp":"2024-06-01T17:52:37.657720Z"}]}
{"channel":"book","type":"update","data":[{"symbol":"GBP/USD","bids":[{"price":1.27456,"qty":0.00000000},{"price":1.27391,"qty":3924.89588349},{"price":1.27471,"qty":516.03053916}],"asks":[],"checksum":133371706,"timestamp":"2024-06-01T17:52:38.010836Z"}]}
{"channel":"book","type":"update","data":[{"symbol":"GBP/USD","bids":[{"price":1.27471,"qty":0.00000000},{"price":1.27391,"qty":3924.89588349},{"price":1.27456,"qty":516.09126959}],"asks":[],"checksum":2187801154,"timestamp":"2024-06-01T17:52:38.056162Z"}]}
{"channel":"book","type":"update","data":[{"symbol":"GBP/USD","bids":[{"price":1.27456,"qty":0.00000000},{"price":1.27391,"qty":3924.89588349},{"price":1.27471,"qty":516.04332868}],"asks":[],"checksum":1049477933,"timestamp":"2024-06-01T17:52:38.480350Z"}]}
{"channel":"book","type":"update","data":[{"symbol":"GBP/USD","bids":[{"price":1.27471,"qty":0.00000000},{"price":1.27391,"qty":3924.89588349},{"price":1.27456,"qty":516.10406062}],"asks":[],"checksum":1653860522,"timestamp":"2024-06-01T17:52:38.496277Z"}]}
{"channel":"book","type":"update","data":[{"symbol":"GBP/USD","bids":[{"price":1.27456,"qty":0.00000000},{"price":1.27391,"qty":3924.89588349},{"price":1.27471,"qty":516.04196507}],"asks":[],"checksum":2221116932,"timestamp":"2024-06-01T17:52:38.994249Z"}]}
{"channel":"book","type":"update","data":[{"symbol":"GBP/USD","bids":[{"price":1.27471,"qty":0.00000000},{"price":1.27391,"qty":3924.89588349},{"price":1.27456,"qty":516.10232424}],"asks":[],"checksum":1039969256,"timestamp":"2024-06-01T17:52:39.036934Z"}]}
{"channel":"book","type":"update","data":[{"symbol":"GBP/USD","bids":[{"price":1.27455,"qty":51.90394884}],"asks":[],"checksum":3888727483,"timestamp":"2024-06-01T17:52:39.388606Z"}]}
{"channel":"book","type":"update","data":[{"symbol":"GBP/USD","bids":[{"price":1.27436,"qty":0.00000000},{"price":1.27391,"qty":3924.89588349}],"asks":[],"checksum":2315364303,"timestamp":"2024-06-01T17:52:39.388878Z"}]}
{"channel":"book","type":"update","data":[{"symbol":"GBP/USD","bids":[{"price":1.27453,"qty":1569.64310240}],"asks":[],"checksum":2617495944,"timestamp":"2024-06-01T17:52:39.392546Z"}]}
{"channel":"book","type":"update","data":[{"symbol":"GBP/USD","bids":[{"price":1.27436,"qty":12574.23581896}],"asks":[],"checksum":253482886,"timestamp":"2024-06-01T17:52:39.396446Z"}]}
{"channel":"book","type":"update","data":[{"symbol":"GBP/USD","bids":[{"price":1.27456,"qty":0.00000000},{"price":1.27403,"qty":624.07132809},{"price":1.27454,"qty":516.10999824}],"asks":[],"checksum":2620199982,"timestamp":"2024-06-01T17:52:39.430823Z"}]}
{"channel":"book","type":"update","data":[{"symbol":"GBP/USD","bids":[{"price":1.27454,"qty":0.00000000},{"price":1.27403,"qty":624.07132809},{"price":1.27471,"qty":516.04116792}],"asks":[],"checksum":3036401871,"timestamp":"2024-06-01T17:52:39.498643Z"}]}
{"channel":"book","type":"update","data":[{"symbol":"GBP/USD","bids":[],"asks":[{"price":1.27537,"qty":0.00000000},{"price":1.27550,"qty":5341.00000000}],"checksum":2201239466,"timestamp":"2024-06-01T17:52:39.536182Z"}]}
{"channel":"book","type":"update","data":[{"symbol":"GBP/USD","bids":[],"asks":[{"price":1.27537,"qty":19907.18258873}],"checksum":3492279120,"timestamp":"2024-06-01T17:52:39.537290Z"}]}
{"channel":"book","type":"update","data":[{"symbol":"GBP/USD","bids":[{"price":1.27471,"qty":0.00000000},{"price":1.27403,"qty":624.07132809},{"price":1.27454,"qty":516.10988139}],"asks":[],"checksum":1706279427,"timestamp":"2024-06-01T17:52:39.674444Z"}]}
{"channel":"book","type":"update","data":[{"symbol":"GBP/USD","bids":[{"price":1.27454,"qty":0.00000000},{"price":1.27403,"qty":624.07132809},{"price":1.27471,"qty":516.04097158}],"asks":[],"checksum":3043085500,"timestamp":"2024-06-01T17:52:40.104837Z"}]}
{"channel":"book","type":"update","data":[{"symbol":"GBP/USD","bids":[{"price":1.27471,"qty":0.00000000},{"price":1.27403,"qty":624.07132809},{"price":1.27454,"qty":516.05383765}],"asks":[],"checksum":1098461862,"timestamp":"2024-06-01T17:52:40.362226Z"}]}
{"channel":"book","type":"update","data":[{"symbol":"GBP/USD","bids":[{"price":1.27454,"qty":0.00000000},{"price":1.27403,"qty":624.07132809},{"price":1.27471,"qty":515.98476647}],"asks":[],"checksum":3733833009,"timestamp":"2024-06-01T17:52:40.700573Z"}]}
{"channel":"book","type":"update","data":[{"symbol":"GBP/USD","bids":[{"price":1.27471,"qty":0.00000000},{"price":1.27403,"qty":624.07132809},{"price":1.27454,"qty":516.05342682}],"asks":[],"checksum":242896637,"timestamp":"2024-06-01T17:52:40.789960Z"}]}
{"channel":"book","type":"update","data":[{"symbol":"GBP/USD","bids":[{"price":1.27454,"qty":0.00000000},{"price":1.27403,"qty":624.07132809},{"price":1.27471,"qty":515.98442043}],"asks":[],"checksum":2909185296,"timestamp":"2024-06-01T17:52:41.286636Z"}]}
{"channel":"book","type":"update","data":[{"symbol":"GBP/USD","bids":[{"price":1.27471,"qty":0.00000000},{"price":1.27403,"qty":624.07132809},{"price":1.27454,"qty":516.05313493}],"asks":[],"checksum":3818163859,"timestamp":"2024-06-01T17:52:41.734886Z"}]}
{"channel":"book","type":"update","data":[{"symbol":"GBP/USD","bids":[{"price":1.27454,"qty":0.00000000},{"price":1.27403,"qty":624.07132809},{"price":1.27471,"qty":515.98429628}],"asks":[],"checksum":1121789876,"timestamp":"2024-06-01T17:52:41.939717Z"}]}
{"channel":"book","type":"update","data":[{"symbol":"GBP/USD","bids":[{"price":1.27471,"qty":0.00000000},{"price":1.27403,"qty":624.07132809},{"price":1.27454,"qty":516.05311902}],"asks":[],"checksum":2171387315,"timestamp":"2024-06-01T17:52:41.943425Z"}]}
{"channel":"book","type":"update","data":[{"symbol":"GBP/USD","bids":[{"price":1.27454,"qty":0.00000000},{"price":1.27403,"qty":624.07132809},{"price":1.27471,"qty":516.04669131}],"asks":[],"checksum":2939462806,"timestamp":"2024-06-01T17:52:43.081348Z"}]}
{"channel":"book","type":"update","data":[{"symbol":"GBP/USD","bids":[{"price":1.27471,"qty":0.00000000},{"price":1.27403,"qty":624.07132809},{"price":1.27454,"qty":516.11552237}],"asks":[],"checksum":3046228557,"timestamp":"2024-06-01T17:52:43.085431Z"}]}
{"channel":"book","type":"update","data":[{"symbol":"GBP/USD","bids":[{"price":1.27453,"qty":0.00000000},{"price":1.27403,"qty":624.07132809}],"asks":[],"checksum":1061988365,"timestamp":"2024-06-01T17:52:43.114194Z"}]}
{"channel":"book","type":"update","data":[{"symbol":"GBP/USD","bids":[{"price":1.27436,"qty":0.00000000},{"price":1.27391,"qty":3924.89588349}],"asks":[],"checksum":2886748209,"timestamp":"2024-06-01T17:52:43.114408Z"}]}
{"channel":"book","type":"update","data":[{"symbol":"GBP/USD","bids":[{"price":1.27454,"qty":0.00000000},{"price":1.27380,"qty":818.31347145},{"price":1.27453,"qty":516.11957183}],"asks":[],"checksum":58124475,"timestamp":"2024-06-01T17:52:43.117628Z"}]}
{"channel":"book","type":"update","data":[{"symbol":"GBP/USD","bids":[{"price":1.27455,"qty":1621.54705124}],"asks":[],"checksum":1848353260,"timestamp":"2024-06-01T17:52:43.118190Z"}]}
{"channel":"book","type":"update","data":[{"symbol":"GBP/USD","bids":[{"price":1.27436,"qty":13714.81051052}],"asks":[],"checksum":2625033612,"timestamp":"2024-06-01T17:52:43.118265Z"}]}
{"channel":"book","type":"update","data":[{"symbol":"GBP/USD","bids":[{"price":1.27456,"qty":51.90394884}],"asks":[],"checksum":711994016,"timestamp":"2024-06-01T17:52:43.291042Z"}]}
{"channel":"book","type":"update","data":[{"symbol":"GBP/USD","bids":[{"price":1.27455,"qty":1569.64310240}],"asks":[],"checksum":616385995,"timestamp":"2024-06-01T17:52:43.529031Z"}]}
{"channel":"book","type":"update","data":[{"symbol":"GBP/USD","bids":[{"price":1.27453,"qty":0.00000000},{"price":1.27403,"qty":624.07132809},{"price":1.27471,"qty":516.04663162}],"asks":[],"checksum":419754675,"timestamp":"2024-06-01T17:52:43.715299Z"}]}
{"channel":"book","type":"update","data":[{"symbol":"GBP/USD","bids":[{"price":1.27471,"qty":0.00000000},{"price":1.27403,"qty":624.07132809},{"price":1.27456,"qty":568.01131279}],"asks":[],"checksum":639500331,"timestamp":"2024-06-01T17:52:43.721230Z"}]}
{"channel":"book","type":"update","data":[{"symbol":"GBP/USD","bids":[],"asks":[{"price":1.27537,"qty":0.00000000},{"price":1.27550,"qty":5341.00000000}],"checksum":2066024677,"timestamp":"2024-06-01T17:52:44.540905Z"}]}
{"channel":"book","type":"update","data":[{"symbol":"GBP/USD","bids":[],"asks":[{"price":1.27537,"qty":24501.14780152}],"checksum":2108416341,"timestamp":"2024-06-01T17:52:44.542651Z"}]}
{"channel":"book","type":"update","data":[{"symbol":"GBP/USD","bids":[{"price":1.27455,"qty":0.00000000},{"price":1.27391,"qty":3924.89588349}],"asks":[],"checksum":1321929296,"timestamp":"2024-06-01T17:52:46.692003Z"}]}
{"channel":"book","type":"update","data":[{"symbol":"GBP/USD","bids":[{"price":1.27456,"qty":51.90394884},{"price":1.27453,"qty":516.02369082}],"asks":[],"checksum":3555282683,"timestamp":"2024-06-01T17:52:46.696441Z"}]}
{"channel":"book","type":"update","data":[{"symbol":"GBP/USD","bids":[{"price":1.27453,"qty":2085.66679322}],"asks":[],"checksum":1566104162,"timestamp":"2024-06-01T17:52:46.697248Z"}]}
{"channel":"book","type":"update","data":[{"symbol":"GBP/USD","bids":[],"asks":[{"price":1.27476,"qty":340.67774742}],"checksum":618371853,"timestamp":"2024-06-01T17:52:46.863796Z"}]}
{"channel":"book","type":"update","data":[{"symbol":"GBP/USD","bids":[],"asks":[{"price":1.27474,"qty":0.00000000},{"price":1.27545,"qty":3920.19258238}],"checksum":2040844400,"timestamp":"2024-06-01T17:52:47.031605Z"}]}
{"channel":"book","type":"update","data":[{"symbol":"GBP/USD","bids":[{"price":1.27453,"qty":1569.64310240},{"price":1.27454,"qty":516.01964211}],"asks":[],"checksum":4233837411,"timestamp":"2024-06-01T17:52:47.268562Z"}]}
{"channel":"book","type":"update","data":[{"symbol":"GBP/USD","bids":[],"asks":[{"price":1.27477,"qty":0.00000000},{"price":1.27550,"qty":5341.00000000},{"price":1.27475,"qty":2962.25494992}],"checksum":1710851337,"timestamp":"2024-06-01T17:52:47.268679Z"}]}
{"channel":"book","type":"update","data":[{"symbol":"GBP/USD","bids":[],"asks":[{"price":1.27508,"qty":0.00000000},{"price":1.27550,"qty":5341.00000000}],"checksum":1055770832,"timestamp":"2024-06-01T17:52:49.466463Z"}]}
{"channel":"book","type":"update","data":[{"symbol":"GBP/USD","bids":[],"asks":[{"price":1.27537,"qty":0.00000000},{"price":1.27561,"qty":2951.35800255}],"checksum":2362909863,"timestamp":"2024-06-01T17:52:49.466589Z"}]}
{"channel":"book","type":"update","data":[{"symbol":"GBP/USD","bids":[],"asks":[{"price":1.27537,"qty":22947.39459316}],"checksum":1675433140,"timestamp":"2024-06-01T17:52:49.467656Z"}]}
{"channel":"book","type":"update","data":[{"symbol":"GBP/USD","bids":[],"asks":[{"price":1.27508,"qty":3100.96483999}],"checksum":777588374,"timestamp":"2024-06-01T17:52:49.467707Z"}]}
{"channel":"book","type":"update","data":[{"symbol":"GBP/USD","bids":[{"price":1.27453,"qty":0.00000000},{"price":1.27403,"qty":624.07132809}],"asks":[],"checksum":1924388898,"timestamp":"2024-06-01T17:52:50.344039Z"}]}
{"channel":"book","type":"update","data":[{"symbol":"GBP/USD","bids":[{"price":1.27454,"qty":0.00000000},{"price":1.27391,"qty":3924.89588349},{"price":1.27453,"qty":516.13806152}],"asks":[],"checksum":4111015203,"timestamp":"2024-06-01T17:52:50.347477Z"}]}
{"channel":"book","type":"update","data":[{"symbol":"GBP/USD","bids":[{"price":1.27455,"qty":2713.00921514}],"asks":[],"checksum":2539088163,"timestamp":"2024-06-01T17:52:50.350099Z"}]}
{"channel":"book","type":"update","data":[{"symbol":"GBP/USD","bids":[{"price":1.27453,"qty":0.00000000},{"price":1.27403,"qty":624.07132809},{"price":1.27456,"qty":568.02986174}],"asks":[],"checksum":3966179092,"timestamp":"2024-06-01T17:52:50.712482Z"}]}
{"channel":"book","type":"update","data":[{"symbol":"GBP/USD","bids":[{"price":1.27457,"qty":51.90394884}],"asks":[],"checksum":2052876369,"timestamp":"2024-06-01T17:52:54.030826Z"}]}
{"channel":"book","type":"update","data":[{"symbol":"GBP/USD","bids":[{"price":1.27455,"qty":0.00000000},{"price":1.27403,"qty":624.07132809}],"asks":[],"checksum":3190200348,"timestamp":"2024-06-01T17:52:54.070981Z"}]}
{"channel":"book","type":"update","data":[{"symbol":"GBP/USD","bids":[{"price":1.27456,"qty":51.90394884},{"price":1.27453,"qty":514.99638602}],"asks":[],"checksum":1919549835,"timestamp":"2024-06-01T17:52:54.074235Z"}]}
{"channel":"book","type":"update","data":[{"symbol":"GBP/USD","bids":[{"price":1.27457,"qty":1621.54705124}],"asks":[],"checksum":229870077,"timestamp":"2024-06-01T17:52:54.076118Z"}]}
{"channel":"book","type":"update","data":[{"symbol":"GBP/USD","bids":[{"price":1.27456,"qty":0.00000000},{"price":1.27403,"qty":624.07132809}],"asks":[],"checksum":462527259,"timestamp":"2024-06-01T17:52:54.198493Z"}]}
{"channel":"book","type":"update","data":[{"symbol":"GBP/USD","bids":[{"price":1.27453,"qty":0.00000000},{"price":1.27394,"qty":3423.39892740},{"price":1.27458,"qty":514.97618342}],"asks":[],"checksum":928500818,"timestamp":"2024-06-01T17:52:54.276983Z"}]}
{"channel":"book","type":"update","data":[{"symbol":"GBP/USD","bids":[],"asks":[{"price":1.27537,"qty":0.00000000},{"price":1.27550,"qty":5341.00000000}],"checksum":2862296025,"timestamp":"2024-06-01T17:52:54.479612Z"}]}
{"channel":"book","type":"update","data":[{"symbol":"GBP/USD","bids":[],"asks":[{"price":1.27537,"qty":18357.91567453}],"checksum":2365611156,"timestamp":"2024-06-01T17:52:54.480656Z"}]}
{"channel":"book","type":"update","data":[{"symbol":"GBP/USD","bids":[],"asks":[{"price":1.27537,"qty":0.00000000},{"price":1.27550,"qty":5341.00000000}],"checksum":2862296025,"timestamp":"2024-06-01T17:52:56.993872Z"}]}
{"channel":"book","type":"update","data":[{"symbol":"GBP/USD","bids":[],"asks":[{"price":1.27537,"qty":22947.39459316}],"checksum":928500818,"timestamp":"2024-06-01T17:52:56.995624Z"}]}
{"channel":"book","type":"update","data":[{"symbol":"GBP/USD","bids":[{"price":1.27457,"qty":51.90394884}],"asks":[],"checksum":1919293788,"timestamp":"2024-06-01T17:52:57.526540Z"}]}
{"channel":"book","type":"update","data":[{"symbol":"GBP/USD","bids":[{"price":1.27458,"qty":0.00000000},{"price":1.27394,"qty":3423.39892740},{"price":1.27453,"qty":514.87742278}],"asks":[],"checksum":2567783113,"timestamp":"2024-06-01T17:52:57.530126Z"}]}
{"channel":"book","type":"update","data":[{"symbol":"GBP/USD","bids":[{"price":1.27453,"qty":2084.52052518}],"asks":[],"checksum":2609411704,"timestamp":"2024-06-01T17:52:57.531709Z"}]}
{"channel":"book","type":"update","data":[{"symbol":"GBP/USD","bids":[{"price":1.27453,"qty":1569.64310240},{"price":1.27454,"qty":514.87338307}],"asks":[],"checksum":2506036168,"timestamp":"2024-06-01T17:52:57.533916Z"}]}
{"channel":"book","type":"update","data":[{"symbol":"GBP/USD","bids":[{"price":1.27454,"qty":0.00000000},{"price":1.27403,"qty":624.07132809},{"price":1.27455,"qty":514.86934342}],"asks":[],"checksum":1437493546,"timestamp":"2024-06-01T17:52:57.537401Z"}]}
{"channel":"book","type":"update","data":[{"symbol":"GBP/USD","bids":[{"price":1.27455,"qty":0.00000000},{"price":1.27403,"qty":624.07132809},{"price":1.27454,"qty":514.87338307}],"asks":[],"checksum":2506036168,"timestamp":"2024-06-01T17:52:57.541308Z"}]}
{"channel":"book","type":"update","data":[{"symbol":"GBP/USD","bids":[{"price":1.27454,"qty":0.00000000},{"price":1.27403,"qty":624.07132809},{"price":1.27455,"qty":514.86934342}],"asks":[],"checksum":1437493546,"timestamp":"2024-06-01T17:52:57.567038Z"}]}
{"channel":"book","type":"update","data":[{"symbol":"GBP/USD","bids":[{"price":1.27455,"qty":0.00000000},{"price":1.27403,"qty":624.07132809},{"price":1.27454,"qty":514.87338307}],"asks":[],"checksum":2506036168,"timestamp":"2024-06-01T17:52:57.570640Z"}]}
{"channel":"book","type":"update","data":[{"symbol":"GBP/USD","bids":[{"price":1.27454,"qty":0.00000000},{"price":1.27403,"qty":624.07132809},{"price":1.27471,"qty":514.86310890}],"asks":[],"checksum":4077412489,"timestamp":"2024-06-01T17:52:59.033859Z"}]}
{"channel":"book","type":"update","data":[{"symbol":"GBP/USD","bids":[{"price":1.27471,"qty":0.00000000},{"price":1.27403,"qty":624.07132809},{"price":1.27454,"qty":514.93201694}],"asks":[],"checksum":3113742718,"timestamp":"2024-06-01T17:52:59.242478Z"}]}
{"channel":"book","type":"update","data":[{"symbol":"GBP/USD","bids":[{"price":1.27454,"qty":0.00000000},{"price":1.27403,"qty":624.07132809},{"price":1.27471,"qty":514.86361105}],"asks":[],"checksum":1199445220,"timestamp":"2024-06-01T17:52:59.498675Z"}]}
{"channel":"book","type":"update","data":[{"symbol":"GBP/USD","bids":[{"price":1.27471,"qty":0.00000000},{"price":1.27403,"qty":624.07132809},{"price":1.27454,"qty":514.93235789}],"asks":[],"checksum":4141987032,"timestamp":"2024-06-01T17:52:59.671753Z"}]}
{"channel":"book","type":"update","data":[{"symbol":"GBP/USD","bids":[{"price":1.27454,"qty":0.00000000},{"price":1.27403,"qty":624.07132809},{"price":1.27471,"qty":514.86368463}],"asks":[],"checksum":1685446819,"timestamp":"2024-06-01T17:52:59.782107Z"}]}
{"channel":"book","type":"update","data":[{"symbol":"GBP/USD","bids":[{"price":1.27471,"qty":0.00000000},{"price":1.27403,"qty":624.07132809},{"price":1.27454,"qty":514.88976938}],"asks":[],"checksum":1859629562,"timestamp":"2024-06-01T17:53:00.347372Z"}]}
{"channel":"book","type":"update","data":[{"symbol":"GBP/USD","bids":[{"price":1.27454,"qty":0.00000000},{"price":1.27403,"qty":624.07132809},{"price":1.27455,"qty":514.88572960}],"asks":[],"checksum":2062665445,"timestamp":"2024-06-01T17:53:00.525015Z"}]}
{"channel":"book","type":"update","data":[{"symbol":"GBP/USD","bids":[{"price":1.27455,"qty":0.00000000},{"price":1.27403,"qty":624.07132809},{"price":1.27454,"qty":514.88984391}],"asks":[],"checksum":3379213325,"timestamp":"2024-06-01T17:53:00.528462Z"}]}
{"channel":"book","type":"update","data":[{"symbol":"GBP/USD","bids":[{"price":1.27454,"qty":0.00000000},{"price":1.27403,"qty":624.07132809},{"price":1.27471,"qty":514.82125248}],"asks":[],"checksum":3762779301,"timestamp":"2024-06-01T17:53:00.737280Z"}]}
{"channel":"book","type":"update","data":[{"symbol":"GBP/USD","bids":[{"price":1.27471,"qty":0.00000000},{"price":1.27403,"qty":624.07132809},{"price":1.27454,"qty":514.88997909}],"asks":[],"checksum":3879450626,"timestamp":"2024-06-01T17:53:00.931369Z"}]}
{"channel":"book","type":"update","data":[{"symbol":"GBP/USD","bids":[{"price":1.27453,"qty":0.00000000},{"price":1.27403,"qty":624.07132809}],"asks":[],"checksum":472238673,"timestamp":"2024-06-01T17:53:01.247837Z"}]}
{"channel":"book","type":"update","data":[{"symbol":"GBP/USD","bids":[{"price":1.27454,"qty":0.00000000},{"price":1.27393,"qty":14540.74651318},{"price":1.27453,"qty":514.89406114}],"asks":[],"checksum":3542372040,"timestamp":"2024-06-01T17:53:01.251144Z"}]}
{"channel":"book","type":"update","data":[{"symbol":"GBP/USD","bids":[{"price":1.27455,"qty":2713.00921514}],"asks":[],"checksum":3473635508,"timestamp":"2024-06-01T17:53:01.253291Z"}]}
{"channel":"book","type":"update","data":[{"symbol":"GBP/USD","bids":[],"asks":[{"price":1.27474,"qty":340.67774742}],"checksum":1221228685,"timestamp":"2024-06-01T17:53:01.417566Z"}]}
{"channel":"book","type":"update","data":[{"symbol":"GBP/USD","bids":[{"price":1.27453,"qty":0.00000000},{"price":1.27403,"qty":624.07132809},{"price":1.27456,"qty":514.88197114}],"asks":[],"checksum":1895156301,"timestamp":"2024-06-01T17:53:01.521802Z"}]}
{"channel":"book","type":"update","data":[{"symbol":"GBP/USD","bids":[],"asks":[{"price":1.27476,"qty":0.00000000},{"price":1.27545,"qty":3920.19258238}],"checksum":3915227316,"timestamp":"2024-06-01T17:53:01.585990Z"}]}
{"channel":"book","type":"update","data":[{"symbol":"GBP/USD","bids":[],"asks":[{"price":1.27475,"qty":0.00000000},{"price":1.27550,"qty":5341.00000000},{"price":1.27477,"qty":2962.34439083}],"checksum":2143241957,"timestamp":"2024-06-01T17:53:01.589246Z"}]}
{"channel":"book","type":"update","data":[{"symbol":"GBP/USD","bids":[{"price":1.27456,"qty":0.00000000},{"price":1.27403,"qty":624.07132809},{"price":1.27471,"qty":514.82141692}],"asks":[],"checksum":3239359333,"timestamp":"2024-06-01T17:53:01.925611Z"}]}
{"channel":"book","type":"update","data":[{"symbol":"GBP/USD","bids":[{"price":1.27471,"qty":0.00000000},{"price":1.27403,"qty":624.07132809},{"price":1.27456,"qty":514.96163166}],"asks":[],"checksum":963882935,"timestamp":"2024-06-01T17:53:02.665288Z"}]}
{"channel":"book","type":"update","data":[{"symbol":"GBP/USD","bids":[{"price":1.27456,"qty":0.00000000},{"price":1.27403,"qty":624.07132809},{"price":1.27471,"qty":514.90027374}],"asks":[],"checksum":209027032,"timestamp":"2024-06-01T17:53:03.065150Z"}]}
{"channel":"book","type":"update","data":[{"symbol":"GBP/USD","bids":[{"price":1.27471,"qty":0.00000000},{"price":1.27403,"qty":624.07132809},{"price":1.27456,"qty":514.96051679}],"asks":[],"checksum":1527496553,"timestamp":"2024-06-01T17:53:03.531474Z"}]}
{"channel":"book","type":"update","data":[{"symbol":"GBP/USD","bids":[{"price":1.27456,"qty":0.00000000},{"price":1.27403,"qty":624.07132809},{"price":1.27471,"qty":514.89982160}],"asks":[],"checksum":2687599790,"timestamp":"2024-06-01T17:53:03.848837Z"}]}
{"channel":"book","type":"update","data":[{"symbol":"GBP/USD","bids":[{"price":1.27471,"qty":0.00000000},{"price":1.27403,"qty":624.07132809},{"price":1.27456,"qty":514.96041896}],"asks":[],"checksum":1063559888,"timestamp":"2024-06-01T17:53:03.852490Z"}]}
{"channel":"book","type":"update","data":[{"symbol":"GBP/USD","bids":[{"price":1.27456,"qty":0.00000000},{"price":1.27403,"qty":624.07132809},{"price":1.27471,"qty":514.89970963}],"asks":[],"checksum":3752056069,"timestamp":"2024-06-01T17:53:04.123097Z"}]}
{"channel":"book","type":"update","data":[{"symbol":"GBP/USD","bids":[{"price":1.27471,"qty":0.00000000},{"price":1.27403,"qty":624.07132809},{"price":1.27456,"qty":514.96030698}],"asks":[],"checksum":93880355,"timestamp":"2024-06-01T17:53:04.186758Z"}]}
{"channel":"book","type":"update","data":[{"symbol":"GBP/USD","bids":[],"asks":[{"price":1.27508,"qty":0.00000000},{"price":1.27550,"qty":5341.00000000}],"checksum":1209833985,"timestamp":"2024-06-01T17:53:04.594278Z"}]}
{"channel":"book","type":"update","data":[{"symbol":"GBP/USD","bids":[],"asks":[{"price":1.27537,"qty":0.00000000},{"price":1.27561,"qty":2951.35800255}],"checksum":2890617179,"timestamp":"2024-06-01T17:53:04.594295Z"}]}
{"channel":"book","type":"update","data":[{"symbol":"GBP/USD","bids":[],"asks":[{"price":1.27508,"qty":1569.64310240}],"checksum":589401912,"timestamp":"2024-06-01T17:53:04.595946Z"}]}
{"channel":"book","type":"update","data":[{"symbol":"GBP/USD","bids":[],"asks":[{"price":1.27537,"qty":24501.14780152}],"checksum":1312295868,"timestamp":"2024-06-01T17:53:04.595967Z"}]}
{"channel":"book","type":"update","data":[{"symbol":"GBP/USD","bids":[{"price":1.27455,"qty":0.00000000},{"price":1.27403,"qty":624.07132809}],"asks":[],"checksum":3030157685,"timestamp":"2024-06-01T17:53:04.881824Z"}]}
{"channel":"book","type":"update","data":[{"symbol":"GBP/USD","bids":[{"price":1.27456,"qty":0.00000000},{"price":1.27395,"qty":14540.74651318},{"price":1.27471,"qty":514.83510742}],"asks":[],"checksum":1026590185,"timestamp":"2024-06-01T17:53:04.883201Z"}]}
{"channel":"book","type":"update","data":[{"symbol":"GBP/USD","bids":[{"price":1.27453,"qty":1572.15538146}],"asks":[],"checksum":3058106449,"timestamp":"2024-06-01T17:53:04.887450Z"}]}
{"channel":"book","type":"update","data":[{"symbol":"GBP/USD","bids":[{"price":1.27471,"qty":0.00000000},{"price":1.27403,"qty":624.07132809},{"price":1.27454,"qty":514.90377688}],"asks":[],"checksum":3064445900,"timestamp":"2024-06-01T17:53:04.909279Z"}]}
{"channel":"book","type":"update","data":[{"symbol":"GBP/USD","bids":[{"price":1.27453,"qty":1624.05933030}],"asks":[],"checksum":677063707,"timestamp":"2024-06-01T17:53:05.055432Z"}]}
{"channel":"book","type":"update","data":[{"symbol":"GBP/USD","bids":[{"price":1.27454,"qty":0.00000000},{"price":1.27403,"qty":624.07132809},{"price":1.27471,"qty":514.83514074}],"asks":[],"checksum":3151959918,"timestamp":"2024-06-01T17:53:05.214521Z"}]}
{"channel":"book","type":"update","data":[{"symbol":"GBP/USD","bids":[{"price":1.27457,"qty":0.00000000},{"price":1.27403,"qty":624.07132809}],"asks":[],"checksum":2080677531,"timestamp":"2024-06-01T17:53:05.220015Z"}]}
{"channel":"book","type":"update","data":[{"symbol":"GBP/USD","bids":[{"price":1.27471,"qty":0.00000000},{"price":1.27395,"qty":14540.74651318},{"price":1.27454,"qty":514.90387130}],"asks":[],"checksum":2643059970,"timestamp":"2024-06-01T17:53:05.730080Z"}]}
{"channel":"book","type":"update","data":[{"symbol":"GBP/USD","bids":[],"asks":[{"price":1.27499,"qty":0.00000000},{"price":1.27550,"qty":5341.00000000},{"price":1.27507,"qty":898.24290000}],"checksum":2476205423,"timestamp":"2024-06-01T17:53:06.361389Z"}]}
{"channel":"book","type":"update","data":[{"symbol":"GBP/USD","bids":[],"asks":[{"price":1.27537,"qty":0.00000000},{"price":1.27550,"qty":5341.00000000}],"checksum":2998527159,"timestamp":"2024-06-01T17:53:07.091995Z"}]}
{"channel":"book","type":"update","data":[{"symbol":"GBP/USD","bids":[],"asks":[{"price":1.27508,"qty":0.00000000},{"price":1.27561,"qty":2951.35800255}],"checksum":1720565387,"timestamp":"2024-06-01T17:53:07.092016Z"}]}
{"channel":"book","type":"update","data":[{"symbol":"GBP/USD","bids":[],"asks":[{"price":1.27506,"qty":3100.96483999}],"checksum":1442456028,"timestamp":"2024-06-01T17:53:07.092787Z"}]}
{"channel":"book","type":"update","data":[{"symbol":"GBP/USD","bids":[],"asks":[{"price":1.27537,"qty":22947.39459316}],"checksum":1631683164,"timestamp":"2024-06-01T17:53:07.092871Z"}]}
{"channel":"book","type":"update","data":[{"symbol":"GBP/USD","bids":[],"asks":[{"price":1.27507,"qty":0.00000000},{"price":1.27550,"qty":5341.00000000},{"price":1.27505,"qty":898.24290000}],"checksum":3749820298,"timestamp":"2024-06-01T17:53:07.119561Z"}]}
{"channel":"book","type":"update","data":[{"symbol":"GBP/USD","bids":[{"price":1.27453,"qty":51.90394884}],"asks":[],"checksum":607158365,"timestamp":"2024-06-01T17:53:08.619023Z"}]}
{"channel":"book","type":"update","data":[{"symbol":"GBP/USD","bids":[{"price":1.27454,"qty":0.00000000},{"price":1.27395,"qty":14540.74651318},{"price":1.27453,"qty":566.83852940}],"asks":[],"checksum":441803084,"timestamp":"2024-06-01T17:53:08.622984Z"}]}
{"channel":"book","type":"update","data":[{"symbol":"GBP/USD","bids":[{"price":1.27455,"qty":1569.64310240}],"asks":[],"checksum":3345168816,"timestamp":"2024-06-01T17:53:08.627029Z"}]}
{"channel":"book","type":"update","data":[{"symbol":"GBP/USD","bids":[{"price":1.27453,"qty":51.90394884},{"price":1.27456,"qty":514.92246027}],"asks":[],"checksum":309720095,"timestamp":"2024-06-01T17:53:08.858678Z"}]}
{"channel":"book","type":"update","data":[{"symbol":"GBP/USD","bids":[],"asks":[{"price":1.27506,"qty":0.00000000},{"price":1.27550,"qty":5341.00000000}],"checksum":1320978246,"timestamp":"2024-06-01T17:53:09.553675Z"}]}
{"channel":"book","type":"update","data":[{"symbol":"GBP/USD","bids":[],"asks":[{"price":1.27504,"qty":3100.96483999}],"checksum":1870620123,"timestamp":"2024-06-01T17:53:09.554392Z"}]}
{"channel":"book","type":"update","data":[{"symbol":"GBP/USD","bids":[],"asks":[{"price":1.27505,"qty":0.00000000},{"price":1.27550,"qty":5341.00000000},{"price":1.27503,"qty":898.24290000}],"checksum":3038494424,"timestamp":"2024-06-01T17:53:09.571570Z"}]}
{"channel":"book","type":"update","data":[{"symbol":"GBP/USD","bids":[],"asks":[{"price":1.27477,"qty":0.00000000},{"price":1.27550,"qty":5341.00000000},{"price":1.27473,"qty":2962.36583679}],"checksum":176772189,"timestamp":"2024-06-01T17:53:10.819315Z"}]}
{"channel":"book","type":"update","data":[{"symbol":"GBP/USD","bids":[],"asks":[{"price":1.27473,"qty":0.00000000},{"price":1.27550,"qty":5341.00000000},{"price":1.27477,"qty":2962.36583679}],"checksum":4145285277,"timestamp":"2024-06-01T17:53:10.823428Z"}]}
{"channel":"book","type":"update","data":[{"symbol":"GBP/USD","bids":[{"price":1.27456,"qty":0.00000000},{"price":1.27403,"qty":624.07132809},{"price":1.27471,"qty":517.19280655}],"asks":[],"checksum":3366762789,"timestamp":"2024-06-01T17:53:10.968936Z"}]}
{"channel":"book","type":"update","data":[{"symbol":"GBP/USD","bids":[{"price":1.27471,"qty":0.00000000},{"price":1.27403,"qty":624.07132809},{"price":1.27456,"qty":514.88307380}],"asks":[],"checksum":1212600095,"timestamp":"2024-06-01T17:53:10.973906Z"}]}
{"channel":"book","type":"update","data":[{"symbol":"GBP/USD","bids":[],"asks":[{"price":1.27504,"qty":0.00000000},{"price":1.27550,"qty":5341.00000000}],"checksum":3708820686,"timestamp":"2024-06-01T17:53:12.029060Z"}]}
{"channel":"book","type":"update","data":[{"symbol":"GBP/USD","bids":[],"asks":[{"price":1.27537,"qty":0.00000000},{"price":1.27561,"qty":2951.35800255}],"checksum":548659175,"timestamp":"2024-06-01T17:53:12.029147Z"}]}
{"channel":"book","type":"update","data":[{"symbol":"GBP/USD","bids":[],"asks":[{"price":1.27508,"qty":1569.64310240}],"checksum":2950234500,"timestamp":"2024-06-01T17:53:12.029830Z"}]}
{"channel":"book","type":"update","data":[{"symbol":"GBP/USD","bids":[],"asks":[{"price":1.27537,"qty":24501.14780152}],"checksum":3677654387,"timestamp":"2024-06-01T17:53:12.029893Z"}]}
{"channel":"book","type":"update","data":[{"symbol":"GBP/USD","bids":[{"price":1.27455,"qty":0.00000000},{"price":1.27403,"qty":624.07132809}],"asks":[],"checksum":2011113704,"timestamp":"2024-06-01T17:53:12.105409Z"}]}
{"channel":"book","type":"update","data":[{"symbol":"GBP/USD","bids":[],"asks":[{"price":1.27476,"qty":340.67774742}],"checksum":226864820,"timestamp":"2024-06-01T17:53:12.106429Z"}]}
{"channel":"book","type":"update","data":[{"symbol":"GBP/USD","bids":[{"price":1.27456,"qty":0.00000000},{"price":1.27396,"qty":3423.39892740},{"price":1.27453,"qty":566.79920755}],"asks":[],"checksum":2835101329,"timestamp":"2024-06-01T17:53:12.108762Z"}]}
{"channel":"book","type":"update","data":[{"symbol":"GBP/USD","bids":[{"price":1.27453,"qty":2136.44230995}],"asks":[],"checksum":3559710267,"timestamp":"2024-06-01T17:53:12.110831Z"}]}
{"channel":"book","type":"update","data":[{"symbol":"GBP/USD","bids":[],"asks":[{"price":1.27474,"qty":0.00000000},{"price":1.27545,"qty":3920.19258238}],"checksum":3486266243,"timestamp":"2024-06-01T17:53:12.274836Z"}]}
{"channel":"book","type":"update","data":[{"symbol":"GBP/USD","bids":[{"price":1.27453,"qty":1621.54705124},{"price":1.27454,"qty":514.89121886}],"asks":[],"checksum":3623805745,"timestamp":"2024-06-01T17:53:12.315867Z"}]}
{"channel":"book","type":"update","data":[{"symbol":"GBP/USD","bids":[],"asks":[{"price":1.27477,"qty":0.00000000},{"price":1.27550,"qty":5341.00000000},{"price":1.27475,"qty":2966.71851928}],"checksum":496097267,"timestamp":"2024-06-01T17:53:12.316037Z"}]}
{"channel":"book","type":"update","data":[{"symbol":"GBP/USD","bids":[],"asks":[{"price":1.27508,"qty":0.00000000},{"price":1.27550,"qty":5341.00000000}],"checksum":3804604878,"timestamp":"2024-06-01T17:53:14.413909Z"}]}
{"channel":"book","type":"update","data":[{"symbol":"GBP/USD","bids":[],"asks":[{"price":1.27537,"qty":0.00000000},{"price":1.27561,"qty":2951.35800255}],"checksum":586218655,"timestamp":"2024-06-01T17:53:14.414031Z"}]}
