{"channel":"book","type":"snapshot","data":[{"symbol":"LINK/GBP","bids":[{"price":14.562,"qty":30.87976376},{"price":14.560,"qty":5.43492434},{"price":14.558,"qty":13.47190044},{"price":14.553,"qty":28.83454270},{"price":14.552,"qty":9.92843975},{"price":14.550,"qty":40.98000000},{"price":14.549,"qty":18.87252424},{"price":14.546,"qty":42.13000000},{"price":14.538,"qty":85.87000000},{"price":14.534,"qty":26.98929060}],"asks":[{"price":14.578,"qty":13.45427592},{"price":14.579,"qty":138.90854051},{"price":14.587,"qty":18.82471006},{"price":14.589,"qty":5.43492434},{"price":14.595,"qty":70.52987272},{"price":14.601,"qty":100.00000000},{"price":14.605,"qty":0.63527127},{"price":14.609,"qty":9.92843975},{"price":14.613,"qty":90.03000000},{"price":14.618,"qty":26.83641295}],"checksum":638109902}]}
{"channel":"book","type":"update","data":[{"symbol":"LINK/GBP","bids":[],"asks":[{"price":14.579,"qty":0.00000000},{"price":14.621,"qty":28.25000000}],"checksum":1627406583,"timestamp":"2024-06-01T17:52:02.407067Z"}]}
{"channel":"book","type":"update","data":[{"symbol":"LINK/GBP","bids":[{"price":14.558,"qty":0.00000000},{"price":14.532,"qty":20.46792239}],"asks":[],"checksum":2806154428,"timestamp":"2024-06-01T17:52:02.408451Z"}]}
{"channel":"book","type":"update","data":[{"symbol":"LINK/GBP","bids":[],"asks":[{"price":14.580,"qty":126.98854051}],"checksum":1136373513,"timestamp":"2024-06-01T17:52:02.411901Z"}]}
{"channel":"book","type":"update","data":[{"symbol":"LINK/GBP","bids":[{"price":14.562,"qty":44.34866530}],"asks":[],"checksum":2627354292,"timestamp":"2024-06-01T17:52:02.412490Z"}]}
{"channel":"book","type":"update","data":[{"symbol":"LINK/GBP","bids":[],"asks":[{"price":14.578,"qty":0.00000000},{"price":14.621,"qty":28.25000000}],"checksum":3327515342,"timestamp":"2024-06-01T17:52:02.429639Z"}]}
{"channel":"book","type":"update","data":[{"symbol":"LINK/GBP","bids":[],"asks":[{"price":14.580,"qty":0.00000000},{"price":14.627,"qty":88.48792239}],"checksum":2193528824,"timestamp":"2024-06-01T17:52:02.432627Z"}]}
{"channel":"book","type":"update","data":[{"symbol":"LINK/GBP","bids":[],"asks":[{"price":14.589,"qty":0.00000000},{"price":14.630,"qty":40.21993446}],"checksum":1052104041,"timestamp":"2024-06-01T17:52:02.435894Z"}]}
{"channel":"book","type":"update","data":[{"symbol":"LINK/GBP","bids":[],"asks":[{"price":14.583,"qty":172.11441257}],"checksum":2853662912,"timestamp":"2024-06-01T17:52:02.437566Z"}]}
{"channel":"book","type":"update","data":[{"symbol":"LINK/GBP","bids":[],"asks":[{"price":14.595,"qty":75.96479706}],"checksum":2439798196,"timestamp":"2024-06-01T17:52:02.438563Z"}]}
{"channel":"book","type":"update","data":[{"symbol":"LINK/GBP","bids":[],"asks":[{"price":14.601,"qty":0.00000000},{"price":14.630,"qty":40.21993446}],"checksum":176547586,"timestamp":"2024-06-01T17:52:02.837573Z"}]}
{"channel":"book","type":"update","data":[{"symbol":"LINK/GBP","bids":[],"asks":[{"price":14.583,"qty":185.56435460}],"checksum":561018470,"timestamp":"2024-06-01T17:52:03.745268Z"}]}
{"channel":"book","type":"update","data":[{"symbol":"LINK/GBP","bids":[],"asks":[{"price":14.606,"qty":100.00000000}],"checksum":1416638837,"timestamp":"2024-06-01T17:52:04.224539Z"}]}
{"channel":"book","type":"update","data":[{"symbol":"LINK/GBP","bids":[],"asks":[{"price":14.582,"qty":100.00000000}],"checksum":758454999,"timestamp":"2024-06-01T17:52:05.723907Z"}]}
{"channel":"book","type":"update","data":[{"symbol":"LINK/GBP","bids":[],"asks":[{"price":14.583,"qty":172.11441257}],"checksum":3979581612,"timestamp":"2024-06-01T17:52:05.728439Z"}]}
{"channel":"book","type":"update","data":[{"symbol":"LINK/GBP","bids":[],"asks":[{"price":14.606,"qty":0.00000000},{"price":14.627,"qty":88.48792239}],"checksum":3809775589,"timestamp":"2024-06-01T17:52:05.730326Z"}]}
{"channel":"book","type":"update","data":[{"symbol":"LINK/GBP","bids":[],"asks":[{"price":14.581,"qty":13.45150774}],"checksum":3473853764,"timestamp":"2024-06-01T17:52:06.744701Z"}]}
{"channel":"book","type":"update","data":[{"symbol":"LINK/GBP","bids":[],"asks":[{"price":14.580,"qty":100.00000000}],"checksum":3903222644,"timestamp":"2024-06-01T17:52:06.752906Z"}]}
{"channel":"book","type":"update","data":[{"symbol":"LINK/GBP","bids":[],"asks":[{"price":14.581,"qty":0.00000000},{"price":14.621,"qty":28.25000000}],"checksum":1600453556,"timestamp":"2024-06-01T17:52:06.758118Z"}]}
{"channel":"book","type":"update","data":[{"symbol":"LINK/GBP","bids":[],"asks":[{"price":14.580,"qty":0.00000000},{"price":14.627,"qty":88.48792239}],"checksum":3809775589,"timestamp":"2024-06-01T17:52:07.224872Z"}]}
{"channel":"book","type":"update","data":[{"symbol":"LINK/GBP","bids":[],"asks":[{"price":14.579,"qty":13.45335307}],"checksum":1256576997,"timestamp":"2024-06-01T17:52:08.744624Z"}]}
{"channel":"book","type":"update","data":[{"symbol":"LINK/GBP","bids":[{"price":14.562,"qty":13.46890154}],"asks":[],"checksum":819822076,"timestamp":"2024-06-01T17:52:11.421851Z"}]}
{"channel":"book","type":"update","data":[{"symbol":"LINK/GBP","bids":[{"price":14.563,"qty":61.65142275}],"asks":[],"checksum":2242351786,"timestamp":"2024-06-01T17:52:11.426617Z"}]}
{"channel":"book","type":"update","data":[{"symbol":"LINK/GBP","bids":[{"price":14.563,"qty":0.00000000},{"price":14.532,"qty":20.46792239}],"asks":[],"checksum":819822076,"timestamp":"2024-06-01T17:52:14.705597Z"}]}
{"channel":"book","type":"update","data":[{"symbol":"LINK/GBP","bids":[{"price":14.563,"qty":61.65142275}],"asks":[],"checksum":2242351786,"timestamp":"2024-06-01T17:52:14.710461Z"}]}
{"channel":"book","type":"update","data":[{"symbol":"LINK/GBP","bids":[],"asks":[{"price":14.583,"qty":0.00000000},{"price":14.627,"qty":88.48792239}],"checksum":3364562603,"timestamp":"2024-06-01T17:52:23.332353Z"}]}
{"channel":"book","type":"update","data":[{"symbol":"LINK/GBP","bids":[],"asks":[{"price":14.579,"qty":203.87189358}],"checksum":2378450066,"timestamp":"2024-06-01T17:52:23.337183Z"}]}
{"channel":"book","type":"update","data":[{"symbol":"LINK/GBP","bids":[{"price":14.563,"qty":0.00000000},{"price":14.532,"qty":20.46792239}],"asks":[],"checksum":952019908,"timestamp":"2024-06-01T17:52:29.852219Z"}]}
{"channel":"book","type":"update","data":[{"symbol":"LINK/GBP","bids":[{"price":14.563,"qty":61.65142275}],"asks":[],"checksum":2378450066,"timestamp":"2024-06-01T17:52:29.857638Z"}]}
{"channel":"book","type":"update","data":[{"symbol":"LINK/GBP","bids":[],"asks":[{"price":14.595,"qty":70.52987272}],"checksum":1300077659,"timestamp":"2024-06-01T17:52:31.032276Z"}]}
{"channel":"book","type":"update","data":[{"symbol":"LINK/GBP","bids":[{"price":14.552,"qty":0.00000000},{"price":14.532,"qty":20.46792239}],"asks":[],"checksum":3257853787,"timestamp":"2024-06-01T17:52:31.032632Z"}]}
{"channel":"book","type":"update","data":[{"symbol":"LINK/GBP","bids":[{"price":14.539,"qty":9.92843975}],"asks":[],"checksum":1471112383,"timestamp":"2024-06-01T17:52:31.036355Z"}]}
{"channel":"book","type":"update","data":[{"symbol":"LINK/GBP","bids":[],"asks":[{"price":14.588,"qty":5.43492434}],"checksum":1306519177,"timestamp":"2024-06-01T17:52:31.036444Z"}]}
{"channel":"book","type":"update","data":[{"symbol":"LINK/GBP","bids":[{"price":14.551,"qty":28.83850983}],"asks":[],"checksum":3910306986,"timestamp":"2024-06-01T17:52:31.048338Z"}]}
{"channel":"book","type":"update","data":[{"symbol":"LINK/GBP","bids":[{"price":14.553,"qty":0.00000000},{"price":14.534,"qty":26.98929060}],"asks":[],"checksum":726039566,"timestamp":"2024-06-01T17:52:31.048450Z"}]}
{"channel":"book","type":"update","data":[{"symbol":"LINK/GBP","bids":[{"price":14.562,"qty":0.00000000},{"price":14.532,"qty":20.46792239}],"asks":[],"checksum":3444352064,"timestamp":"2024-06-01T17:52:31.067436Z"}]}
{"channel":"book","type":"update","data":[{"symbol":"LINK/GBP","bids":[{"price":14.563,"qty":0.00000000},{"price":14.526,"qty":0.93155066}],"asks":[],"checksum":4035275496,"timestamp":"2024-06-01T17:52:31.069986Z"}]}
{"channel":"book","type":"update","data":[{"symbol":"LINK/GBP","bids":[{"price":14.562,"qty":44.48300592}],"asks":[],"checksum":831615629,"timestamp":"2024-06-01T17:52:31.095885Z"}]}
{"channel":"book","type":"update","data":[{"symbol":"LINK/GBP","bids":[{"price":14.557,"qty":13.47329100}],"asks":[],"checksum":3294278724,"timestamp":"2024-06-01T17:52:31.119626Z"}]}
{"channel":"book","type":"update","data":[{"symbol":"LINK/GBP","bids":[{"price":14.562,"qty":0.00000000},{"price":14.532,"qty":20.46792239}],"asks":[],"checksum":1692119840,"timestamp":"2024-06-01T17:52:31.148834Z"}]}
{"channel":"book","type":"update","data":[{"symbol":"LINK/GBP","bids":[{"price":14.559,"qty":39.58296121}],"asks":[],"checksum":1893048942,"timestamp":"2024-06-01T17:52:31.156732Z"}]}
{"channel":"book","type":"update","data":[{"symbol":"LINK/GBP","bids":[],"asks":[{"price":14.578,"qty":100.00000000}],"checksum":1184747055,"timestamp":"2024-06-01T17:52:31.163955Z"}]}
{"channel":"book","type":"update","data":[{"symbol":"LINK/GBP","bids":[],"asks":[{"price":14.582,"qty":0.00000000},{"price":14.621,"qty":28.25000000}],"checksum":3859726871,"timestamp":"2024-06-01T17:52:31.194366Z"}]}
{"channel":"book","type":"update","data":[{"symbol":"LINK/GBP","bids":[],"asks":[{"price":14.579,"qty":190.41854051}],"checksum":4230358424,"timestamp":"2024-06-01T17:52:31.197988Z"}]}
{"channel":"book","type":"update","data":[{"symbol":"LINK/GBP","bids":[],"asks":[{"price":14.577,"qty":13.45519890}],"checksum":4042804953,"timestamp":"2024-06-01T17:52:31.205988Z"}]}
{"channel":"book","type":"update","data":[{"symbol":"LINK/GBP","bids":[{"price":14.561,"qty":8.39057950}],"asks":[],"checksum":745467226,"timestamp":"2024-06-01T17:52:31.556402Z"}]}
{"channel":"book","type":"update","data":[{"symbol":"LINK/GBP","bids":[{"price":14.560,"qty":0.00000000},{"price":14.534,"qty":26.98929060}],"asks":[],"checksum":766676750,"timestamp":"2024-06-01T17:52:34.081752Z"}]}
{"channel":"book","type":"update","data":[{"symbol":"LINK/GBP","bids":[],"asks":[{"price":14.609,"qty":0.00000000},{"price":14.621,"qty":28.25000000}],"checksum":1038048718,"timestamp":"2024-06-01T17:52:34.082007Z"}]}
{"channel":"book","type":"update","data":[{"symbol":"LINK/GBP","bids":[{"price":14.554,"qty":5.43492434}],"asks":[],"checksum":3475762458,"timestamp":"2024-06-01T17:52:34.084601Z"}]}
{"channel":"book","type":"update","data":[{"symbol":"LINK/GBP","bids":[],"asks":[{"price":14.604,"qty":9.92843975}],"checksum":1624772974,"timestamp":"2024-06-01T17:52:34.084664Z"}]}
{"channel":"book","type":"update","data":[{"symbol":"LINK/GBP","bids":[],"asks":[{"price":14.576,"qty":100.00000000}],"checksum":1351403357,"timestamp":"2024-06-01T17:52:36.723904Z"}]}
{"channel":"book","type":"update","data":[{"symbol":"LINK/GBP","bids":[],"asks":[{"price":14.578,"qty":0.00000000},{"price":14.618,"qty":26.83641295}],"checksum":439538985,"timestamp":"2024-06-01T17:52:37.225321Z"}]}
{"channel":"book","type":"update","data":[{"symbol":"LINK/GBP","bids":[],"asks":[{"price":14.600,"qty":100.00000000}],"checksum":3531195706,"timestamp":"2024-06-01T17:52:38.225094Z"}]}
{"channel":"book","type":"update","data":[{"symbol":"LINK/GBP","bids":[],"asks":[{"price":14.576,"qty":0.00000000},{"price":14.618,"qty":26.83641295}],"checksum":3552871621,"timestamp":"2024-06-01T17:52:38.225114Z"}]}
{"channel":"book","type":"update","data":[{"symbol":"LINK/GBP","bids":[],"asks":[{"price":14.579,"qty":0.00000000},{"price":14.621,"qty":28.25000000}],"checksum":885598802,"timestamp":"2024-06-01T17:52:38.513851Z"}]}
{"channel":"book","type":"update","data":[{"symbol":"LINK/GBP","bids":[],"asks":[{"price":14.576,"qty":190.41854051}],"checksum":2644349628,"timestamp":"2024-06-01T17:52:38.516716Z"}]}
{"channel":"book","type":"update","data":[{"symbol":"LINK/GBP","bids":[],"asks":[{"price":14.576,"qty":290.41854051}],"checksum":2206014136,"timestamp":"2024-06-01T17:52:38.520247Z"}]}
{"channel":"book","type":"update","data":[{"symbol":"LINK/GBP","bids":[],"asks":[{"price":14.600,"qty":0.00000000},{"price":14.621,"qty":28.25000000}],"checksum":2718173454,"timestamp":"2024-06-01T17:52:38.722196Z"}]}
{"channel":"book","type":"update","data":[{"symbol":"LINK/GBP","bids":[],"asks":[{"price":14.617,"qty":20.46792239}],"checksum":1122245788,"timestamp":"2024-06-01T17:52:39.969551Z"}]}
{"channel":"book","type":"update","data":[{"symbol":"LINK/GBP","bids":[{"price":14.559,"qty":0.00000000},{"price":14.534,"qty":26.98929060}],"asks":[],"checksum":1139553456,"timestamp":"2024-06-01T17:52:44.332956Z"}]}
{"channel":"book","type":"update","data":[{"symbol":"LINK/GBP","bids":[{"price":14.551,"qty":0.00000000},{"price":14.532,"qty":20.46792239}],"asks":[],"checksum":1759837418,"timestamp":"2024-06-01T17:52:44.335928Z"}]}
{"channel":"book","type":"update","data":[{"symbol":"LINK/GBP","bids":[{"price":14.555,"qty":28.83058244}],"asks":[],"checksum":3154173741,"timestamp":"2024-06-01T17:52:44.336261Z"}]}
{"channel":"book","type":"update","data":[{"symbol":"LINK/GBP","bids":[{"price":14.558,"qty":63.56409491}],"asks":[],"checksum":2268645770,"timestamp":"2024-06-01T17:52:44.337576Z"}]}
{"channel":"book","type":"update","data":[{"symbol":"LINK/GBP","bids":[],"asks":[{"price":14.577,"qty":0.00000000},{"price":14.621,"qty":28.25000000}],"checksum":2157690435,"timestamp":"2024-06-01T17:52:45.347812Z"}]}
{"channel":"book","type":"update","data":[{"symbol":"LINK/GBP","bids":[],"asks":[{"price":14.575,"qty":13.45704524}],"checksum":2687420538,"timestamp":"2024-06-01T17:52:45.352362Z"}]}
{"channel":"book","type":"update","data":[{"symbol":"LINK/GBP","bids":[],"asks":[{"price":14.618,"qty":0.00000000},{"price":14.621,"qty":28.25000000}],"checksum":3073498370,"timestamp":"2024-06-01T17:52:45.365627Z"}]}
{"channel":"book","type":"update","data":[{"symbol":"LINK/GBP","bids":[],"asks":[{"price":14.600,"qty":26.86800544}],"checksum":2777448979,"timestamp":"2024-06-01T17:52:45.370644Z"}]}
{"channel":"book","type":"update","data":[{"symbol":"LINK/GBP","bids":[],"asks":[{"price":14.574,"qty":100.00000000}],"checksum":944673668,"timestamp":"2024-06-01T17:52:45.724185Z"}]}
{"channel":"book","type":"update","data":[{"symbol":"LINK/GBP","bids":[],"asks":[{"price":14.576,"qty":190.41854051}],"checksum":73163478,"timestamp":"2024-06-01T17:52:46.222330Z"}]}
{"channel":"book","type":"update","data":[{"symbol":"LINK/GBP","bids":[],"asks":[{"price":14.574,"qty":0.00000000},{"price":14.617,"qty":20.46792239}],"checksum":3002598005,"timestamp":"2024-06-01T17:52:46.887765Z"}]}
{"channel":"book","type":"update","data":[{"symbol":"LINK/GBP","bids":[],"asks":[{"price":14.598,"qty":100.00000000}],"checksum":4206305647,"timestamp":"2024-06-01T17:52:47.223701Z"}]}
