{"channel":"book","type":"snapshot","data":[{"symbol":"LINK/EUR","bids":[{"price":17.13676,"qty":70.02006900},{"price":17.13675,"qty":29.82000000},{"price":17.13063,"qty":303.70000000},{"price":17.13062,"qty":243.48672997},{"price":17.12987,"qty":134.55925993},{"price":17.12910,"qty":47.43738600},{"price":17.12622,"qty":467.47688400},{"price":17.12583,"qty":269.27331468},{"price":17.12550,"qty":149.28697600},{"price":17.12443,"qty":269.20397459}],"asks":[{"price":17.13982,"qty":0.95179617},{"price":17.13983,"qty":40.00000000},{"price":17.13986,"qty":200.00000000},{"price":17.13987,"qty":149.90354051},{"price":17.14245,"qty":200.00000000},{"price":17.14526,"qty":243.48672997},{"price":17.14743,"qty":200.00000000},{"price":17.15587,"qty":70.52987272},{"price":17.15588,"qty":14.00000000},{"price":17.16376,"qty":16.80000000}],"checksum":2458965168}]}
{"channel":"book","type":"update","data":[{"symbol":"LINK/EUR","bids":[],"asks":[{"price":17.13986,"qty":0.00000000},{"price":17.16468,"qty":9.48131034}],"checksum":76362000,"timestamp":"2024-06-01T17:51:55.974921Z"}]}
{"channel":"book","type":"update","data":[{"symbol":"LINK/EUR","bids":[],"asks":[{"price":17.13987,"qty":0.00000000},{"price":17.16469,"qty":269.50000000}],"checksum":375567093,"timestamp":"2024-06-01T17:51:55.976511Z"}]}
{"channel":"book","type":"update","data":[{"symbol":"LINK/EUR","bids":[],"asks":[{"price":17.13982,"qty":0.00000000},{"price":17.16470,"qty":47.43738600}],"checksum":4290654888,"timestamp":"2024-06-01T17:51:55.976605Z"}]}
{"channel":"book","type":"update","data":[{"symbol":"LINK/EUR","bids":[{"price":17.12604,"qty":76.90429351}],"asks":[],"checksum":2219176956,"timestamp":"2024-06-01T17:51:55.979207Z"}]}
{"channel":"book","type":"update","data":[{"symbol":"LINK/EUR","bids":[],"asks":[{"price":17.13983,"qty":0.00000000},{"price":17.17044,"qty":29.16000000}],"checksum":3301105482,"timestamp":"2024-06-01T17:51:55.980157Z"}]}
{"channel":"book","type":"update","data":[{"symbol":"LINK/EUR","bids":[],"asks":[{"price":17.13984,"qty":40.00000000}],"checksum":4207835274,"timestamp":"2024-06-01T17:51:55.980269Z"}]}
{"channel":"book","type":"update","data":[{"symbol":"LINK/EUR","bids":[],"asks":[{"price":17.13987,"qty":138.90854051}],"checksum":1506104096,"timestamp":"2024-06-01T17:51:55.981823Z"}]}
{"channel":"book","type":"update","data":[{"symbol":"LINK/EUR","bids":[],"asks":[{"price":17.14228,"qty":9.68963527}],"checksum":1348352559,"timestamp":"2024-06-01T17:51:55.983036Z"}]}
{"channel":"book","type":"update","data":[{"symbol":"LINK/EUR","bids":[{"price":17.13676,"qty":0.00000000},{"price":17.12443,"qty":269.20397459}],"asks":[],"checksum":2900404490,"timestamp":"2024-06-01T17:51:55.983508Z"}]}
{"channel":"book","type":"update","data":[{"symbol":"LINK/EUR","bids":[{"price":17.13677,"qty":70.02006900}],"asks":[],"checksum":687614183,"timestamp":"2024-06-01T17:51:55.986429Z"}]}
{"channel":"book","type":"update","data":[{"symbol":"LINK/EUR","bids":[{"price":17.13104,"qty":21.00000000}],"asks":[],"checksum":4009640422,"timestamp":"2024-06-01T17:51:55.986846Z"}]}
{"channel":"book","type":"update","data":[{"symbol":"LINK/EUR","bids":[],"asks":[{"price":17.14025,"qty":0.95179617}],"checksum":2896050767,"timestamp":"2024-06-01T17:51:56.331352Z"}]}
{"channel":"book","type":"update","data":[{"symbol":"LINK/EUR","bids":[],"asks":[{"price":17.14246,"qty":200.00000000}],"checksum":1645328310,"timestamp":"2024-06-01T17:51:56.336404Z"}]}
{"channel":"book","type":"update","data":[{"symbol":"LINK/EUR","bids":[{"price":17.12604,"qty":0.00000000},{"price":17.12550,"qty":149.28697600}],"asks":[],"checksum":1710479817,"timestamp":"2024-06-01T17:51:56.336708Z"}]}
{"channel":"book","type":"update","data":[{"symbol":"LINK/EUR","bids":[{"price":17.12583,"qty":0.00000000},{"price":17.12512,"qty":76.90843082}],"asks":[],"checksum":365170560,"timestamp":"2024-06-01T17:51:56.385799Z"}]}
{"channel":"book","type":"update","data":[{"symbol":"LINK/EUR","bids":[],"asks":[{"price":17.13986,"qty":200.00000000}],"checksum":4085928252,"timestamp":"2024-06-01T17:51:56.436621Z"}]}
{"channel":"book","type":"update","data":[{"symbol":"LINK/EUR","bids":[],"asks":[{"price":17.14246,"qty":0.00000000},{"price":17.15588,"qty":14.00000000}],"checksum":2755959354,"timestamp":"2024-06-01T17:51:56.441063Z"}]}
{"channel":"book","type":"update","data":[{"symbol":"LINK/EUR","bids":[],"asks":[{"price":17.13983,"qty":40.00000000}],"checksum":217821256,"timestamp":"2024-06-01T17:51:56.441893Z"}]}
{"channel":"book","type":"update","data":[{"symbol":"LINK/EUR","bids":[{"price":17.12602,"qty":269.22406328}],"asks":[],"checksum":688752181,"timestamp":"2024-06-01T17:51:56.535760Z"}]}
{"channel":"book","type":"update","data":[{"symbol":"LINK/EUR","bids":[],"asks":[{"price":17.13984,"qty":0.00000000},{"price":17.15588,"qty":14.00000000}],"checksum":2908348930,"timestamp":"2024-06-01T17:51:56.592608Z"}]}
{"channel":"book","type":"update","data":[{"symbol":"LINK/EUR","bids":[{"price":17.12987,"qty":0.00000000},{"price":17.12512,"qty":76.90843082}],"asks":[],"checksum":1123243646,"timestamp":"2024-06-01T17:51:56.899644Z"}]}
{"channel":"book","type":"update","data":[{"symbol":"LINK/EUR","bids":[{"price":17.13035,"qty":134.55551276}],"asks":[],"checksum":1023551650,"timestamp":"2024-06-01T17:51:56.903750Z"}]}
{"channel":"book","type":"update","data":[{"symbol":"LINK/EUR","bids":[],"asks":[{"price":17.15586,"qty":269.50000000}],"checksum":2851528615,"timestamp":"2024-06-01T17:51:56.988268Z"}]}
{"channel":"book","type":"update","data":[{"symbol":"LINK/EUR","bids":[],"asks":[{"price":17.15587,"qty":0.00000000},{"price":17.15588,"qty":14.00000000}],"checksum":3262384049,"timestamp":"2024-06-01T17:51:56.991499Z"}]}
{"channel":"book","type":"update","data":[{"symbol":"LINK/EUR","bids":[],"asks":[{"price":17.15585,"qty":70.52987272}],"checksum":3485728832,"timestamp":"2024-06-01T17:51:56.991618Z"}]}
{"channel":"book","type":"update","data":[{"symbol":"LINK/EUR","bids":[{"price":17.13035,"qty":0.00000000},{"price":17.12512,"qty":76.90843082}],"asks":[],"checksum":3873176109,"timestamp":"2024-06-01T17:51:57.355028Z"}]}
{"channel":"book","type":"update","data":[{"symbol":"LINK/EUR","bids":[{"price":17.12622,"qty":0.00000000},{"price":17.12443,"qty":269.20397459}],"asks":[],"checksum":287558449,"timestamp":"2024-06-01T17:51:57.507664Z"}]}
{"channel":"book","type":"update","data":[{"symbol":"LINK/EUR","bids":[],"asks":[{"price":17.15586,"qty":0.00000000},{"price":17.15588,"qty":14.00000000},{"price":17.15584,"qty":269.50000000}],"checksum":523820256,"timestamp":"2024-06-01T17:51:57.510438Z"}]}
{"channel":"book","type":"update","data":[{"symbol":"LINK/EUR","bids":[{"price":17.12623,"qty":467.47688400}],"asks":[],"checksum":1747631898,"timestamp":"2024-06-01T17:51:57.510522Z"}]}
{"channel":"book","type":"update","data":[{"symbol":"LINK/EUR","bids":[],"asks":[{"price":17.15585,"qty":0.00000000},{"price":17.15588,"qty":14.00000000}],"checksum":522647241,"timestamp":"2024-06-01T17:51:57.529278Z"}]}
{"channel":"book","type":"update","data":[{"symbol":"LINK/EUR","bids":[],"asks":[{"price":17.15583,"qty":70.52987272}],"checksum":635456291,"timestamp":"2024-06-01T17:51:57.529397Z"}]}
{"channel":"book","type":"update","data":[{"symbol":"LINK/EUR","bids":[{"price":17.12945,"qty":134.56257078}],"asks":[],"checksum":1782818742,"timestamp":"2024-06-01T17:51:57.576993Z"}]}
{"channel":"book","type":"update","data":[{"symbol":"LINK/EUR","bids":[{"price":17.12945,"qty":0.00000000},{"price":17.12512,"qty":76.90843082}],"asks":[],"checksum":635456291,"timestamp":"2024-06-01T17:51:57.678849Z"}]}
{"channel":"book","type":"update","data":[{"symbol":"LINK/EUR","bids":[],"asks":[{"price":17.15584,"qty":0.00000000},{"price":17.15588,"qty":14.00000000},{"price":17.15582,"qty":269.50000000}],"checksum":657191175,"timestamp":"2024-06-01T17:51:58.163860Z"}]}
{"channel":"book","type":"update","data":[{"symbol":"LINK/EUR","bids":[],"asks":[{"price":17.15581,"qty":70.52987272}],"checksum":501949432,"timestamp":"2024-06-01T17:51:58.168624Z"}]}
{"channel":"book","type":"update","data":[{"symbol":"LINK/EUR","bids":[{"price":17.12992,"qty":134.55884693}],"asks":[],"checksum":1169646906,"timestamp":"2024-06-01T17:51:58.704986Z"}]}
{"channel":"book","type":"update","data":[{"symbol":"LINK/EUR","bids":[],"asks":[{"price":17.15582,"qty":0.00000000},{"price":17.15588,"qty":14.00000000},{"price":17.15580,"qty":269.50000000}],"checksum":4284968151,"timestamp":"2024-06-01T17:51:58.707888Z"}]}
{"channel":"book","type":"update","data":[{"symbol":"LINK/EUR","bids":[],"asks":[{"price":17.15579,"qty":70.52987272}],"checksum":1824286428,"timestamp":"2024-06-01T17:51:58.725640Z"}]}
{"channel":"book","type":"update","data":[{"symbol":"LINK/EUR","bids":[{"price":17.13677,"qty":0.00000000},{"price":17.12512,"qty":76.90843082}],"asks":[],"checksum":1107231427,"timestamp":"2024-06-01T17:51:58.987469Z"}]}
{"channel":"book","type":"update","data":[{"symbol":"LINK/EUR","bids":[{"price":17.13678,"qty":70.02006900}],"asks":[],"checksum":2941355559,"timestamp":"2024-06-01T17:51:58.990095Z"}]}
{"channel":"book","type":"update","data":[{"symbol":"LINK/EUR","bids":[{"price":17.13105,"qty":243.48672997}],"asks":[],"checksum":2324603884,"timestamp":"2024-06-01T17:51:58.991472Z"}]}
{"channel":"book","type":"update","data":[{"symbol":"LINK/EUR","bids":[{"price":17.13063,"qty":0.00000000},{"price":17.12550,"qty":149.28697600},{"price":17.13106,"qty":303.70000000}],"asks":[],"checksum":4039643698,"timestamp":"2024-06-01T17:51:58.994299Z"}]}
{"channel":"book","type":"update","data":[{"symbol":"LINK/EUR","bids":[{"price":17.13105,"qty":0.00000000},{"price":17.12550,"qty":149.28697600}],"asks":[],"checksum":3738546557,"timestamp":"2024-06-01T17:51:59.058524Z"}]}
{"channel":"book","type":"update","data":[{"symbol":"LINK/EUR","bids":[],"asks":[{"price":17.15580,"qty":0.00000000},{"price":17.15588,"qty":14.00000000},{"price":17.15578,"qty":269.50000000}],"checksum":2485752748,"timestamp":"2024-06-01T17:51:59.249065Z"}]}
{"channel":"book","type":"update","data":[{"symbol":"LINK/EUR","bids":[],"asks":[{"price":17.15577,"qty":70.52987272}],"checksum":81725521,"timestamp":"2024-06-01T17:51:59.268755Z"}]}
{"channel":"book","type":"update","data":[{"symbol":"LINK/EUR","bids":[],"asks":[{"price":17.14025,"qty":0.00000000},{"price":17.15588,"qty":14.00000000}],"checksum":4259261436,"timestamp":"2024-06-01T17:51:59.597904Z"}]}
{"channel":"book","type":"update","data":[{"symbol":"LINK/EUR","bids":[],"asks":[{"price":17.13982,"qty":0.95179617}],"checksum":356249152,"timestamp":"2024-06-01T17:51:59.722685Z"}]}
{"channel":"book","type":"update","data":[{"symbol":"LINK/EUR","bids":[],"asks":[{"price":17.13982,"qty":0.00000000},{"price":17.15588,"qty":14.00000000}],"checksum":4259261436,"timestamp":"2024-06-01T17:51:59.810067Z"}]}
{"channel":"book","type":"update","data":[{"symbol":"LINK/EUR","bids":[],"asks":[{"price":17.15578,"qty":0.00000000},{"price":17.16376,"qty":16.80000000},{"price":17.15576,"qty":269.50000000}],"checksum":939258856,"timestamp":"2024-06-01T17:51:59.812999Z"}]}
{"channel":"book","type":"update","data":[{"symbol":"LINK/EUR","bids":[],"asks":[{"price":17.15577,"qty":0.00000000},{"price":17.16376,"qty":16.80000000}],"checksum":4285811141,"timestamp":"2024-06-01T17:51:59.824135Z"}]}
{"channel":"book","type":"update","data":[{"symbol":"LINK/EUR","bids":[],"asks":[{"price":17.15575,"qty":70.52987272}],"checksum":3484550814,"timestamp":"2024-06-01T17:51:59.824707Z"}]}
{"channel":"book","type":"update","data":[{"symbol":"LINK/EUR","bids":[{"price":17.12910,"qty":0.00000000},{"price":17.12512,"qty":76.90843082}],"asks":[],"checksum":226125298,"timestamp":"2024-06-01T17:52:00.057642Z"}]}
{"channel":"book","type":"update","data":[{"symbol":"LINK/EUR","bids":[{"price":17.13678,"qty":0.00000000},{"price":17.12443,"qty":269.20397459}],"asks":[],"checksum":2141177443,"timestamp":"2024-06-01T17:52:00.057847Z"}]}
{"channel":"book","type":"update","data":[{"symbol":"LINK/EUR","bids":[{"price":17.13106,"qty":0.00000000},{"price":17.12330,"qty":220.47746800},{"price":17.13063,"qty":303.70000000}],"asks":[],"checksum":3611252847,"timestamp":"2024-06-01T17:52:00.058111Z"}]}
{"channel":"book","type":"update","data":[{"symbol":"LINK/EUR","bids":[{"price":17.13340,"qty":47.43738600}],"asks":[],"checksum":2638611639,"timestamp":"2024-06-01T17:52:00.060368Z"}]}
{"channel":"book","type":"update","data":[{"symbol":"LINK/EUR","bids":[],"asks":[{"price":17.14526,"qty":0.00000000},{"price":17.16376,"qty":16.80000000}],"checksum":224128122,"timestamp":"2024-06-01T17:52:00.060524Z"}]}
{"channel":"book","type":"update","data":[{"symbol":"LINK/EUR","bids":[{"price":17.13679,"qty":70.02006900}],"asks":[],"checksum":831565134,"timestamp":"2024-06-01T17:52:00.060678Z"}]}
{"channel":"book","type":"update","data":[{"symbol":"LINK/EUR","bids":[{"price":17.13104,"qty":0.00000000},{"price":17.12512,"qty":76.90843082}],"asks":[],"checksum":3801914868,"timestamp":"2024-06-01T17:52:00.060744Z"}]}
{"channel":"book","type":"update","data":[{"symbol":"LINK/EUR","bids":[{"price":17.13147,"qty":21.00000000}],"asks":[],"checksum":2814305883,"timestamp":"2024-06-01T17:52:00.060831Z"}]}
{"channel":"book","type":"update","data":[{"symbol":"LINK/EUR","bids":[{"price":17.13107,"qty":243.48672997}],"asks":[],"checksum":1568199429,"timestamp":"2024-06-01T17:52:00.062536Z"}]}
{"channel":"book","type":"update","data":[{"symbol":"LINK/EUR","bids":[{"price":17.13147,"qty":0.00000000},{"price":17.12550,"qty":149.28697600}],"asks":[],"checksum":546311737,"timestamp":"2024-06-01T17:52:00.063021Z"}]}
{"channel":"book","type":"update","data":[{"symbol":"LINK/EUR","bids":[{"price":17.13381,"qty":21.00000000}],"asks":[],"checksum":2991530835,"timestamp":"2024-06-01T17:52:00.063389Z"}]}
{"channel":"book","type":"update","data":[{"symbol":"LINK/EUR","bids":[{"price":17.12992,"qty":0.00000000},{"price":17.12550,"qty":149.28697600}],"asks":[],"checksum":746382341,"timestamp":"2024-06-01T17:52:00.076085Z"}]}
{"channel":"book","type":"update","data":[{"symbol":"LINK/EUR","bids":[{"price":17.13039,"qty":134.55519326}],"asks":[],"checksum":672931446,"timestamp":"2024-06-01T17:52:00.079968Z"}]}
{"channel":"book","type":"update","data":[{"symbol":"LINK/EUR","bids":[],"asks":[{"price":17.14228,"qty":0.00000000},{"price":17.16470,"qty":47.43738600}],"checksum":1043308134,"timestamp":"2024-06-01T17:52:00.085928Z"}]}
{"channel":"book","type":"update","data":[{"symbol":"LINK/EUR","bids":[{"price":17.13039,"qty":0.00000000},{"price":17.12550,"qty":149.28697600}],"asks":[],"checksum":978281493,"timestamp":"2024-06-01T17:52:00.096377Z"}]}
{"channel":"book","type":"update","data":[{"symbol":"LINK/EUR","bids":[{"price":17.13381,"qty":0.00000000},{"price":17.12512,"qty":76.90843082}],"asks":[],"checksum":4171873626,"timestamp":"2024-06-01T17:52:00.138883Z"}]}
{"channel":"book","type":"update","data":[{"symbol":"LINK/EUR","bids":[{"price":17.13676,"qty":21.00000000}],"asks":[],"checksum":229829420,"timestamp":"2024-06-01T17:52:00.139109Z"}]}
{"channel":"book","type":"update","data":[{"symbol":"LINK/EUR","bids":[{"price":17.13062,"qty":0.00000000},{"price":17.12512,"qty":76.90843082}],"asks":[],"checksum":1651790199,"timestamp":"2024-06-01T17:52:00.143050Z"}]}
{"channel":"book","type":"update","data":[{"symbol":"LINK/EUR","bids":[{"price":17.13676,"qty":0.00000000},{"price":17.12443,"qty":269.20397459}],"asks":[],"checksum":2928958992,"timestamp":"2024-06-01T17:52:00.145220Z"}]}
{"channel":"book","type":"update","data":[{"symbol":"LINK/EUR","bids":[{"price":17.13680,"qty":21.00000000}],"asks":[],"checksum":2359551606,"timestamp":"2024-06-01T17:52:00.145293Z"}]}
{"channel":"book","type":"update","data":[{"symbol":"LINK/EUR","bids":[],"asks":[{"price":17.15576,"qty":0.00000000},{"price":17.16999,"qty":5.27893718},{"price":17.15574,"qty":269.50000000}],"checksum":2383618903,"timestamp":"2024-06-01T17:52:00.504132Z"}]}
{"channel":"book","type":"update","data":[{"symbol":"LINK/EUR","bids":[],"asks":[{"price":17.15575,"qty":0.00000000},{"price":17.16999,"qty":5.27893718}],"checksum":2809793777,"timestamp":"2024-06-01T17:52:00.525127Z"}]}
{"channel":"book","type":"update","data":[{"symbol":"LINK/EUR","bids":[],"asks":[{"price":17.15573,"qty":70.52987272}],"checksum":2376545094,"timestamp":"2024-06-01T17:52:00.525202Z"}]}
{"channel":"book","type":"update","data":[{"symbol":"LINK/EUR","bids":[],"asks":[{"price":17.14639,"qty":243.48672997}],"checksum":523912364,"timestamp":"2024-06-01T17:52:00.559745Z"}]}
{"channel":"book","type":"update","data":[{"symbol":"LINK/EUR","bids":[{"price":17.13063,"qty":0.00000000},{"price":17.12443,"qty":269.20397459},{"price":17.13680,"qty":324.70000000}],"asks":[],"checksum":1291033615,"timestamp":"2024-06-01T17:52:00.562606Z"}]}
{"channel":"book","type":"update","data":[{"symbol":"LINK/EUR","bids":[],"asks":[{"price":17.15574,"qty":0.00000000},{"price":17.16470,"qty":47.43738600}],"checksum":3885036245,"timestamp":"2024-06-01T17:52:00.602429Z"}]}
{"channel":"book","type":"update","data":[{"symbol":"LINK/EUR","bids":[],"asks":[{"price":17.14001,"qty":0.95179617}],"checksum":553964815,"timestamp":"2024-06-01T17:52:01.057595Z"}]}
{"channel":"book","type":"update","data":[{"symbol":"LINK/EUR","bids":[],"asks":[{"price":17.15640,"qty":268.90000000}],"checksum":2059201313,"timestamp":"2024-06-01T17:52:01.060469Z"}]}
{"channel":"book","type":"update","data":[{"symbol":"LINK/EUR","bids":[{"price":17.13070,"qty":134.55271581}],"asks":[],"checksum":3040485921,"timestamp":"2024-06-01T17:52:01.092991Z"}]}
{"channel":"book","type":"update","data":[{"symbol":"LINK/EUR","bids":[{"price":17.13680,"qty":303.70000000}],"asks":[],"checksum":727336211,"timestamp":"2024-06-01T17:52:01.737766Z"}]}
{"channel":"book","type":"update","data":[{"symbol":"LINK/EUR","bids":[],"asks":[{"price":17.15640,"qty":0.00000000},{"price":17.16376,"qty":16.80000000},{"price":17.15572,"qty":268.90000000}],"checksum":333213261,"timestamp":"2024-06-01T17:52:01.740585Z"}]}
{"channel":"book","type":"update","data":[{"symbol":"LINK/EUR","bids":[],"asks":[{"price":17.15573,"qty":0.00000000},{"price":17.16376,"qty":16.80000000}],"checksum":1222111537,"timestamp":"2024-06-01T17:52:01.767131Z"}]}
{"channel":"book","type":"update","data":[{"symbol":"LINK/EUR","bids":[],"asks":[{"price":17.15571,"qty":70.52987272}],"checksum":4028341080,"timestamp":"2024-06-01T17:52:01.767171Z"}]}
{"channel":"book","type":"update","data":[{"symbol":"LINK/EUR","bids":[{"price":17.13070,"qty":0.00000000},{"price":17.12443,"qty":269.20397459}],"asks":[],"checksum":1067274840,"timestamp":"2024-06-01T17:52:01.915715Z"}]}
{"channel":"book","type":"update","data":[{"symbol":"LINK/EUR","bids":[{"price":17.13028,"qty":134.55606529}],"asks":[],"checksum":2309023382,"timestamp":"2024-06-01T17:52:01.920942Z"}]}
{"channel":"book","type":"update","data":[{"symbol":"LINK/EUR","bids":[{"price":17.13680,"qty":0.00000000},{"price":17.12443,"qty":269.20397459}],"asks":[],"checksum":1150349210,"timestamp":"2024-06-01T17:52:02.185572Z"}]}
{"channel":"book","type":"update","data":[{"symbol":"LINK/EUR","bids":[],"asks":[{"price":17.13982,"qty":20.63824453}],"checksum":3036436127,"timestamp":"2024-06-01T17:52:02.278064Z"}]}
{"channel":"book","type":"update","data":[{"symbol":"LINK/EUR","bids":[],"asks":[{"price":17.15572,"qty":0.00000000},{"price":17.15588,"qty":14.00000000},{"price":17.15570,"qty":268.90000000}],"checksum":979775792,"timestamp":"2024-06-01T17:52:02.280940Z"}]}
{"channel":"book","type":"update","data":[{"symbol":"LINK/EUR","bids":[{"price":17.13563,"qty":303.70000000}],"asks":[],"checksum":2499514787,"timestamp":"2024-06-01T17:52:02.283702Z"}]}
{"channel":"book","type":"update","data":[{"symbol":"LINK/EUR","bids":[],"asks":[{"price":17.13979,"qty":40.00000000}],"checksum":2257277576,"timestamp":"2024-06-01T17:52:02.285186Z"}]}
{"channel":"book","type":"update","data":[{"symbol":"LINK/EUR","bids":[],"asks":[{"price":17.15569,"qty":70.52987272}],"checksum":3714713222,"timestamp":"2024-06-01T17:52:02.300106Z"}]}
{"channel":"book","type":"update","data":[{"symbol":"LINK/EUR","bids":[],"asks":[{"price":17.13982,"qty":41.28640368}],"checksum":3963732156,"timestamp":"2024-06-01T17:52:02.343290Z"}]}
{"channel":"book","type":"update","data":[{"symbol":"LINK/EUR","bids":[],"asks":[{"price":17.13983,"qty":0.00000000},{"price":17.15570,"qty":268.90000000}],"checksum":814942378,"timestamp":"2024-06-01T17:52:02.349281Z"}]}
{"channel":"book","type":"update","data":[{"symbol":"LINK/EUR","bids":[{"price":17.12623,"qty":0.00000000},{"price":17.12443,"qty":269.20397459}],"asks":[],"checksum":1199663952,"timestamp":"2024-06-01T17:52:02.401270Z"}]}
{"channel":"book","type":"update","data":[{"symbol":"LINK/EUR","bids":[],"asks":[{"price":17.14639,"qty":0.00000000},{"price":17.15588,"qty":14.00000000}],"checksum":3887230710,"timestamp":"2024-06-01T17:52:02.402874Z"}]}
{"channel":"book","type":"update","data":[{"symbol":"LINK/EUR","bids":[{"price":17.12624,"qty":467.47688400}],"asks":[],"checksum":2765471036,"timestamp":"2024-06-01T17:52:02.403935Z"}]}
{"channel":"book","type":"update","data":[{"symbol":"LINK/EUR","bids":[],"asks":[{"price":17.13987,"qty":0.00000000},{"price":17.16376,"qty":16.80000000}],"checksum":1099023117,"timestamp":"2024-06-01T17:52:02.404738Z"}]}
{"channel":"book","type":"update","data":[{"symbol":"LINK/EUR","bids":[],"asks":[{"price":17.13986,"qty":0.00000000},{"price":17.16470,"qty":47.43738600}],"checksum":4055096972,"timestamp":"2024-06-01T17:52:02.405818Z"}]}
{"channel":"book","type":"update","data":[{"symbol":"LINK/EUR","bids":[],"asks":[{"price":17.13979,"qty":0.00000000},{"price":17.16999,"qty":8.43075255}],"checksum":2846302376,"timestamp":"2024-06-01T17:52:02.405932Z"}]}
{"channel":"book","type":"update","data":[{"symbol":"LINK/EUR","bids":[{"price":17.13028,"qty":0.00000000},{"price":17.12443,"qty":269.20397459}],"asks":[],"checksum":948964012,"timestamp":"2024-06-01T17:52:02.408152Z"}]}
{"channel":"book","type":"update","data":[{"symbol":"LINK/EUR","bids":[{"price":17.13693,"qty":21.00000000}],"asks":[],"checksum":1505042253,"timestamp":"2024-06-01T17:52:02.408557Z"}]}
{"channel":"book","type":"update","data":[{"symbol":"LINK/EUR","bids":[{"price":17.13359,"qty":243.48672997}],"asks":[],"checksum":1601876937,"timestamp":"2024-06-01T17:52:02.408743Z"}]}
{"channel":"book","type":"update","data":[{"symbol":"LINK/EUR","bids":[],"asks":[{"price":17.14079,"qty":136.59104051}],"checksum":4015601247,"timestamp":"2024-06-01T17:52:02.409397Z"}]}
{"channel":"book","type":"update","data":[{"symbol":"LINK/EUR","bids":[],"asks":[{"price":17.14001,"qty":0.00000000},{"price":17.16999,"qty":8.43075255}],"checksum":665456159,"timestamp":"2024-06-01T17:52:02.429429Z"}]}
{"channel":"book","type":"update","data":[{"symbol":"LINK/EUR","bids":[],"asks":[{"price":17.14079,"qty":0.00000000},{"price":17.17000,"qty":73.90000000}],"checksum":3074561762,"timestamp":"2024-06-01T17:52:02.430366Z"}]}
{"channel":"book","type":"update","data":[{"symbol":"LINK/EUR","bids":[],"asks":[{"price":17.14171,"qty":218.80354051}],"checksum":1691341316,"timestamp":"2024-06-01T17:52:02.434973Z"}]}
{"channel":"book","type":"update","data":[{"symbol":"LINK/EUR","bids":[{"price":17.13107,"qty":0.00000000},{"price":17.12512,"qty":76.90843082}],"asks":[],"checksum":3832618568,"timestamp":"2024-06-01T17:52:02.438650Z"}]}
{"channel":"book","type":"update","data":[{"symbol":"LINK/EUR","bids":[{"price":17.13314,"qty":134.53360278}],"asks":[],"checksum":2078325428,"timestamp":"2024-06-01T17:52:02.439621Z"}]}
{"channel":"book","type":"update","data":[{"symbol":"LINK/EUR","bids":[{"price":17.12658,"qty":269.17016160}],"asks":[],"checksum":2516946267,"timestamp":"2024-06-01T17:52:02.439656Z"}]}
{"channel":"book","type":"update","data":[{"symbol":"LINK/EUR","bids":[],"asks":[{"price":17.15570,"qty":0.00000000},{"price":17.17000,"qty":73.90000000}],"checksum":2710558981,"timestamp":"2024-06-01T17:52:02.443156Z"}]}
{"channel":"book","type":"update","data":[{"symbol":"LINK/EUR","bids":[{"price":17.12658,"qty":0.00000000},{"price":17.12550,"qty":149.28697600}],"asks":[],"checksum":1282076394,"timestamp":"2024-06-01T17:52:02.450746Z"}]}
{"channel":"book","type":"update","data":[{"symbol":"LINK/EUR","bids":[{"price":17.13314,"qty":0.00000000},{"price":17.12512,"qty":76.90843082}],"asks":[],"checksum":3055464611,"timestamp":"2024-06-01T17:52:02.450842Z"}]}
{"channel":"book","type":"update","data":[{"symbol":"LINK/EUR","bids":[],"asks":[{"price":17.15588,"qty":0.00000000},{"price":17.17044,"qty":29.16000000}],"checksum":2975989803,"timestamp":"2024-06-01T17:52:02.469761Z"}]}
{"channel":"book","type":"update","data":[{"symbol":"LINK/EUR","bids":[],"asks":[{"price":17.16375,"qty":70.52987272}],"checksum":3245320286,"timestamp":"2024-06-01T17:52:02.483185Z"}]}
{"channel":"book","type":"update","data":[{"symbol":"LINK/EUR","bids":[],"asks":[{"price":17.15569,"qty":0.00000000},{"price":17.17044,"qty":29.16000000}],"checksum":1752505204,"timestamp":"2024-06-01T17:52:02.483205Z"}]}
{"channel":"book","type":"update","data":[{"symbol":"LINK/EUR","bids":[],"asks":[{"price":17.14743,"qty":0.00000000},{"price":17.17175,"qty":11.70000000}],"checksum":3715005241,"timestamp":"2024-06-01T17:52:02.522551Z"}]}
{"channel":"book","type":"update","data":[{"symbol":"LINK/EUR","bids":[],"asks":[{"price":17.14731,"qty":243.48672997}],"checksum":3678532060,"timestamp":"2024-06-01T17:52:02.526835Z"}]}
{"channel":"book","type":"update","data":[{"symbol":"LINK/EUR","bids":[],"asks":[{"price":17.14523,"qty":200.00000000}],"checksum":1686152986,"timestamp":"2024-06-01T17:52:02.527600Z"}]}
{"channel":"book","type":"update","data":[{"symbol":"LINK/EUR","bids":[],"asks":[{"price":17.14171,"qty":0.00000000},{"price":17.17044,"qty":29.16000000}],"checksum":559636728,"timestamp":"2024-06-01T17:52:02.553137Z"}]}
{"channel":"book","type":"update","data":[{"symbol":"LINK/EUR","bids":[],"asks":[{"price":17.14263,"qty":158.56104051}],"checksum":3449621548,"timestamp":"2024-06-01T17:52:02.557884Z"}]}
{"channel":"book","type":"update","data":[{"symbol":"LINK/EUR","bids":[],"asks":[{"price":17.14245,"qty":0.00000000},{"price":17.17044,"qty":29.16000000}],"checksum":1816671451,"timestamp":"2024-06-01T17:52:02.590433Z"}]}
{"channel":"book","type":"update","data":[{"symbol":"LINK/EUR","bids":[],"asks":[{"price":17.13982,"qty":20.63824453}],"checksum":651376004,"timestamp":"2024-06-01T17:52:02.594722Z"}]}
{"channel":"book","type":"update","data":[{"symbol":"LINK/EUR","bids":[],"asks":[{"price":17.14245,"qty":0.95179617}],"checksum":3045877026,"timestamp":"2024-06-01T17:52:02.626975Z"}]}
{"channel":"book","type":"update","data":[{"symbol":"LINK/EUR","bids":[],"asks":[{"price":17.14522,"qty":200.00000000}],"checksum":2104853378,"timestamp":"2024-06-01T17:52:02.805341Z"}]}
{"channel":"book","type":"update","data":[{"symbol":"LINK/EUR","bids":[{"price":17.13563,"qty":0.00000000},{"price":17.12453,"qty":200.00000000},{"price":17.13680,"qty":303.70000000}],"asks":[],"checksum":3028663863,"timestamp":"2024-06-01T17:52:02.808082Z"}]}
{"channel":"book","type":"update","data":[{"symbol":"LINK/EUR","bids":[],"asks":[{"price":17.15824,"qty":268.90000000}],"checksum":733489631,"timestamp":"2024-06-01T17:52:02.808178Z"}]}
{"channel":"book","type":"update","data":[{"symbol":"LINK/EUR","bids":[],"asks":[{"price":17.15823,"qty":70.52987272}],"checksum":4206467100,"timestamp":"2024-06-01T17:52:02.831778Z"}]}
{"channel":"book","type":"update","data":[{"symbol":"LINK/EUR","bids":[],"asks":[{"price":17.16375,"qty":0.00000000},{"price":17.16470,"qty":47.43738600}],"checksum":212212279,"timestamp":"2024-06-01T17:52:02.831871Z"}]}
{"channel":"book","type":"update","data":[{"symbol":"LINK/EUR","bids":[],"asks":[{"price":17.14525,"qty":70.02006900}],"checksum":2613207860,"timestamp":"2024-06-01T17:52:02.834203Z"}]}
{"channel":"book","type":"update","data":[{"symbol":"LINK/EUR","bids":[],"asks":[{"price":17.14523,"qty":0.00000000},{"price":17.16470,"qty":47.43738600}],"checksum":146572603,"timestamp":"2024-06-01T17:52:02.837992Z"}]}
{"channel":"book","type":"update","data":[{"symbol":"LINK/EUR","bids":[{"price":17.12647,"qty":12.13741287}],"asks":[],"checksum":2856021175,"timestamp":"2024-06-01T17:52:03.036764Z"}]}
{"channel":"book","type":"update","data":[{"symbol":"LINK/EUR","bids":[{"price":17.12646,"qty":269.17215386}],"asks":[],"checksum":3305329405,"timestamp":"2024-06-01T17:52:03.047574Z"}]}
{"channel":"book","type":"update","data":[{"symbol":"LINK/EUR","bids":[{"price":17.13172,"qty":134.54473889}],"asks":[],"checksum":2498618778,"timestamp":"2024-06-01T17:52:03.047696Z"}]}
{"channel":"book","type":"update","data":[{"symbol":"LINK/EUR","bids":[],"asks":[{"price":17.14525,"qty":0.00000000},{"price":17.16999,"qty":8.43075255}],"checksum":4138040912,"timestamp":"2024-06-01T17:52:03.137524Z"}]}
{"channel":"book","type":"update","data":[{"symbol":"LINK/EUR","bids":[],"asks":[{"price":17.15824,"qty":0.00000000},{"price":17.17000,"qty":73.90000000},{"price":17.15822,"qty":268.90000000}],"checksum":3154151794,"timestamp":"2024-06-01T17:52:03.423374Z"}]}
{"channel":"book","type":"update","data":[{"symbol":"LINK/EUR","bids":[{"price":17.13172,"qty":0.00000000},{"price":17.12602,"qty":269.22406328}],"asks":[],"checksum":3991813653,"timestamp":"2024-06-01T17:52:03.429688Z"}]}
{"channel":"book","type":"update","data":[{"symbol":"LINK/EUR","bids":[],"asks":[{"price":17.15823,"qty":0.00000000},{"price":17.17000,"qty":73.90000000}],"checksum":491197765,"timestamp":"2024-06-01T17:52:03.440876Z"}]}
{"channel":"book","type":"update","data":[{"symbol":"LINK/EUR","bids":[],"asks":[{"price":17.15821,"qty":70.52987272}],"checksum":2627764521,"timestamp":"2024-06-01T17:52:03.441120Z"}]}
{"channel":"book","type":"update","data":[{"symbol":"LINK/EUR","bids":[],"asks":[{"price":17.14815,"qty":158.56104051}],"checksum":2726052004,"timestamp":"2024-06-01T17:52:03.482317Z"}]}
{"channel":"book","type":"update","data":[{"symbol":"LINK/EUR","bids":[],"asks":[{"price":17.15821,"qty":0.00000000},{"price":17.16999,"qty":8.43075255}],"checksum":2687136883,"timestamp":"2024-06-01T17:52:03.493993Z"}]}
{"channel":"book","type":"update","data":[{"symbol":"LINK/EUR","bids":[],"asks":[{"price":17.14814,"qty":9.04342395}],"checksum":1413622138,"timestamp":"2024-06-01T17:52:03.494206Z"}]}
{"channel":"book","type":"update","data":[{"symbol":"LINK/EUR","bids":[],"asks":[{"price":17.13982,"qty":41.28640368}],"checksum":517548069,"timestamp":"2024-06-01T17:52:04.052844Z"}]}
{"channel":"book","type":"update","data":[{"symbol":"LINK/EUR","bids":[],"asks":[{"price":17.14262,"qty":200.00000000}],"checksum":4130061611,"timestamp":"2024-06-01T17:52:04.058076Z"}]}
{"channel":"book","type":"update","data":[{"symbol":"LINK/EUR","bids":[],"asks":[{"price":17.15822,"qty":0.00000000},{"price":17.16470,"qty":47.43738600}],"checksum":3772031613,"timestamp":"2024-06-01T17:52:04.174956Z"}]}
{"channel":"book","type":"update","data":[{"symbol":"LINK/EUR","bids":[{"price":17.12648,"qty":7.78363545}],"asks":[],"checksum":3541165847,"timestamp":"2024-06-01T17:52:04.289729Z"}]}
{"channel":"book","type":"update","data":[{"symbol":"LINK/EUR","bids":[],"asks":[{"price":17.13982,"qty":20.64815915}],"checksum":711136715,"timestamp":"2024-06-01T17:52:04.440402Z"}]}
{"channel":"book","type":"update","data":[{"symbol":"LINK/EUR","bids":[],"asks":[{"price":17.15732,"qty":268.90000000}],"checksum":1232145370,"timestamp":"2024-06-01T17:52:04.443867Z"}]}
{"channel":"book","type":"update","data":[{"symbol":"LINK/EUR","bids":[],"asks":[{"price":17.14814,"qty":0.00000000},{"price":17.16470,"qty":47.43738600}],"checksum":3212625412,"timestamp":"2024-06-01T17:52:04.547323Z"}]}
{"channel":"book","type":"update","data":[{"symbol":"LINK/EUR","bids":[],"asks":[{"price":17.14814,"qty":9.04334231}],"checksum":958095831,"timestamp":"2024-06-01T17:52:04.547362Z"}]}
{"channel":"book","type":"update","data":[{"symbol":"LINK/EUR","bids":[{"price":17.13237,"qty":134.53960002}],"asks":[],"checksum":1788431025,"timestamp":"2024-06-01T17:52:04.706351Z"}]}
{"channel":"book","type":"update","data":[{"symbol":"LINK/EUR","bids":[{"price":17.13679,"qty":0.00000000},{"price":17.12624,"qty":467.47688400}],"asks":[],"checksum":126293606,"timestamp":"2024-06-01T17:52:04.895602Z"}]}
{"channel":"book","type":"update","data":[{"symbol":"LINK/EUR","bids":[{"price":17.13680,"qty":0.00000000},{"price":17.12602,"qty":269.22406328},{"price":17.13676,"qty":303.70000000}],"asks":[],"checksum":4191635037,"timestamp":"2024-06-01T17:52:04.898436Z"}]}
{"channel":"book","type":"update","data":[{"symbol":"LINK/EUR","bids":[{"price":17.13694,"qty":70.02006900}],"asks":[],"checksum":2004722343,"timestamp":"2024-06-01T17:52:04.898457Z"}]}
{"channel":"book","type":"update","data":[{"symbol":"LINK/EUR","bids":[{"price":17.13693,"qty":0.00000000},{"price":17.12624,"qty":467.47688400}],"asks":[],"checksum":1938673245,"timestamp":"2024-06-01T17:52:04.901417Z"}]}
{"channel":"book","type":"update","data":[{"symbol":"LINK/EUR","bids":[{"price":17.13735,"qty":21.00000000}],"asks":[],"checksum":3681336256,"timestamp":"2024-06-01T17:52:04.901447Z"}]}
{"channel":"book","type":"update","data":[{"symbol":"LINK/EUR","bids":[],"asks":[{"price":17.13982,"qty":41.28640368}],"checksum":1425037261,"timestamp":"2024-06-01T17:52:04.919332Z"}]}
{"channel":"book","type":"update","data":[{"symbol":"LINK/EUR","bids":[{"price":17.13359,"qty":0.00000000},{"price":17.12624,"qty":467.47688400}],"asks":[],"checksum":2440609484,"timestamp":"2024-06-01T17:52:05.302970Z"}]}
{"channel":"book","type":"update","data":[{"symbol":"LINK/EUR","bids":[{"price":17.13237,"qty":0.00000000},{"price":17.12602,"qty":269.22406328}],"asks":[],"checksum":953937075,"timestamp":"2024-06-01T17:52:05.307194Z"}]}
{"channel":"book","type":"update","data":[{"symbol":"LINK/EUR","bids":[{"price":17.13160,"qty":134.54563544}],"asks":[],"checksum":2768034922,"timestamp":"2024-06-01T17:52:05.311351Z"}]}
{"channel":"book","type":"update","data":[{"symbol":"LINK/EUR","bids":[{"price":17.12647,"qty":0.00000000},{"price":17.12602,"qty":269.22406328}],"asks":[],"checksum":860894560,"timestamp":"2024-06-01T17:52:05.330447Z"}]}
{"channel":"book","type":"update","data":[{"symbol":"LINK/EUR","bids":[{"price":17.13735,"qty":0.00000000},{"price":17.12550,"qty":149.28697600}],"asks":[],"checksum":1095651744,"timestamp":"2024-06-01T17:52:05.350080Z"}]}
{"channel":"book","type":"update","data":[{"symbol":"LINK/EUR","bids":[{"price":17.13676,"qty":0.00000000},{"price":17.12512,"qty":76.90843082}],"asks":[],"checksum":2753223590,"timestamp":"2024-06-01T17:52:05.411243Z"}]}
{"channel":"book","type":"update","data":[{"symbol":"LINK/EUR","bids":[{"price":17.13160,"qty":0.00000000},{"price":17.12330,"qty":220.47746800}],"asks":[],"checksum":1996750472,"timestamp":"2024-06-01T17:52:05.412530Z"}]}
{"channel":"book","type":"update","data":[{"symbol":"LINK/EUR","bids":[{"price":17.13175,"qty":243.48672997}],"asks":[],"checksum":178699350,"timestamp":"2024-06-01T17:52:05.416932Z"}]}
{"channel":"book","type":"update","data":[{"symbol":"LINK/EUR","bids":[],"asks":[{"price":17.13979,"qty":40.00000000}],"checksum":3585866702,"timestamp":"2024-06-01T17:52:05.417271Z"}]}
{"channel":"book","type":"update","data":[{"symbol":"LINK/EUR","bids":[{"price":17.13471,"qty":303.70000000}],"asks":[],"checksum":906606352,"timestamp":"2024-06-01T17:52:05.419781Z"}]}
{"channel":"book","type":"update","data":[{"symbol":"LINK/EUR","bids":[],"asks":[{"price":17.13979,"qty":0.00000000},{"price":17.16376,"qty":16.80000000}],"checksum":3355619617,"timestamp":"2024-06-01T17:52:05.445596Z"}]}
{"channel":"book","type":"update","data":[{"symbol":"LINK/EUR","bids":[{"price":17.12646,"qty":0.00000000},{"price":17.12512,"qty":76.90843082}],"asks":[],"checksum":851422269,"timestamp":"2024-06-01T17:52:05.494125Z"}]}
{"channel":"book","type":"update","data":[{"symbol":"LINK/EUR","bids":[],"asks":[{"price":17.15732,"qty":0.00000000},{"price":17.16470,"qty":47.43738600},{"price":17.16469,"qty":268.90000000}],"checksum":2990124223,"timestamp":"2024-06-01T17:52:05.573723Z"}]}
{"channel":"book","type":"update","data":[{"symbol":"LINK/EUR","bids":[],"asks":[{"price":17.13979,"qty":40.00000000}],"checksum":2631852899,"timestamp":"2024-06-01T17:52:05.593018Z"}]}
{"channel":"book","type":"update","data":[{"symbol":"LINK/EUR","bids":[{"price":17.13030,"qty":134.55588102}],"asks":[],"checksum":1873674491,"timestamp":"2024-06-01T17:52:06.022102Z"}]}
{"channel":"book","type":"update","data":[{"symbol":"LINK/EUR","bids":[{"price":17.13471,"qty":0.00000000},{"price":17.12512,"qty":76.90843082},{"price":17.13341,"qty":303.70000000}],"asks":[],"checksum":2315287489,"timestamp":"2024-06-01T17:52:06.024936Z"}]}
{"channel":"book","type":"update","data":[{"symbol":"LINK/EUR","bids":[],"asks":[{"price":17.13982,"qty":20.63824453}],"checksum":495558892,"timestamp":"2024-06-01T17:52:06.203841Z"}]}
{"channel":"book","type":"update","data":[{"symbol":"LINK/EUR","bids":[{"price":17.12624,"qty":0.00000000},{"price":17.12512,"qty":76.90843082}],"asks":[],"checksum":898203075,"timestamp":"2024-06-01T17:52:06.334055Z"}]}
{"channel":"book","type":"update","data":[{"symbol":"LINK/EUR","bids":[{"price":17.12649,"qty":467.47688400}],"asks":[],"checksum":678948047,"timestamp":"2024-06-01T17:52:06.336752Z"}]}
{"channel":"book","type":"update","data":[{"symbol":"LINK/EUR","bids":[{"price":17.12648,"qty":0.00000000},{"price":17.12512,"qty":76.90843082}],"asks":[],"checksum":689378287,"timestamp":"2024-06-01T17:52:06.439040Z"}]}
{"channel":"book","type":"update","data":[{"symbol":"LINK/EUR","bids":[{"price":17.13175,"qty":0.00000000},{"price":17.12458,"qty":269.20157044}],"asks":[],"checksum":2011298201,"timestamp":"2024-06-01T17:52:06.549865Z"}]}
{"channel":"book","type":"update","data":[{"symbol":"LINK/EUR","bids":[{"price":17.12602,"qty":0.00000000},{"price":17.12409,"qty":12.13909980}],"asks":[],"checksum":1962085245,"timestamp":"2024-06-01T17:52:06.551268Z"}]}
{"channel":"book","type":"update","data":[{"symbol":"LINK/EUR","bids":[{"price":17.12512,"qty":0.00000000},{"price":17.12330,"qty":220.47746800}],"asks":[],"checksum":3277770134,"timestamp":"2024-06-01T17:52:06.552339Z"}]}
{"channel":"book","type":"update","data":[{"symbol":"LINK/EUR","bids":[{"price":17.13030,"qty":0.00000000},{"price":17.12219,"qty":70.02006900}],"asks":[],"checksum":657867987,"timestamp":"2024-06-01T17:52:06.554741Z"}]}
{"channel":"book","type":"update","data":[{"symbol":"LINK/EUR","bids":[{"price":17.12420,"qty":76.91256857}],"asks":[],"checksum":2881793447,"timestamp":"2024-06-01T17:52:06.557406Z"}]}
{"channel":"book","type":"update","data":[{"symbol":"LINK/EUR","bids":[],"asks":[{"price":17.13695,"qty":134.50369518}],"checksum":1830451520,"timestamp":"2024-06-01T17:52:06.560073Z"}]}
{"channel":"book","type":"update","data":[{"symbol":"LINK/EUR","bids":[{"price":17.12904,"qty":134.56578544}],"asks":[],"checksum":2011518542,"timestamp":"2024-06-01T17:52:06.560158Z"}]}
{"channel":"book","type":"update","data":[{"symbol":"LINK/EUR","bids":[],"asks":[{"price":17.14521,"qty":243.48672997}],"checksum":2330681495,"timestamp":"2024-06-01T17:52:06.561124Z"}]}
{"channel":"book","type":"update","data":[{"symbol":"LINK/EUR","bids":[{"price":17.13694,"qty":0.00000000},{"price":17.12330,"qty":220.47746800}],"asks":[],"checksum":464661210,"timestamp":"2024-06-01T17:52:06.563743Z"}]}
{"channel":"book","type":"update","data":[{"symbol":"LINK/EUR","bids":[{"price":17.13342,"qty":70.02006900}],"asks":[],"checksum":2604517273,"timestamp":"2024-06-01T17:52:06.566581Z"}]}
{"channel":"book","type":"update","data":[{"symbol":"LINK/EUR","bids":[{"price":17.13382,"qty":21.00000000}],"asks":[],"checksum":3203424827,"timestamp":"2024-06-01T17:52:06.566616Z"}]}
{"channel":"book","type":"update","data":[{"symbol":"LINK/EUR","bids":[{"price":17.12458,"qty":0.00000000},{"price":17.12409,"qty":12.13909980}],"asks":[],"checksum":3947705199,"timestamp":"2024-06-01T17:52:06.568575Z"}]}
{"channel":"book","type":"update","data":[{"symbol":"LINK/EUR","bids":[{"price":17.12904,"qty":0.00000000},{"price":17.12330,"qty":220.47746800}],"asks":[],"checksum":125481628,"timestamp":"2024-06-01T17:52:06.568706Z"}]}
{"channel":"book","type":"update","data":[{"symbol":"LINK/EUR","bids":[{"price":17.13341,"qty":0.00000000},{"price":17.12219,"qty":70.02006900},{"price":17.13343,"qty":303.70000000}],"asks":[],"checksum":3008325580,"timestamp":"2024-06-01T17:52:06.569161Z"}]}
{"channel":"book","type":"update","data":[{"symbol":"LINK/EUR","bids":[{"price":17.12409,"qty":0.00000000},{"price":17.12295,"qty":269.22723838}],"asks":[],"checksum":40931925,"timestamp":"2024-06-01T17:52:06.584522Z"}]}
{"channel":"book","type":"update","data":[{"symbol":"LINK/EUR","bids":[],"asks":[{"price":17.13694,"qty":20.64815915}],"checksum":1806162709,"timestamp":"2024-06-01T17:52:06.733001Z"}]}
{"channel":"book","type":"update","data":[{"symbol":"LINK/EUR","bids":[],"asks":[{"price":17.14731,"qty":0.00000000},{"price":17.14814,"qty":9.04334231}],"checksum":4008083521,"timestamp":"2024-06-01T17:52:06.736904Z"}]}
{"channel":"book","type":"update","data":[{"symbol":"LINK/EUR","bids":[{"price":17.12873,"qty":243.48672997}],"asks":[],"checksum":1336602133,"timestamp":"2024-06-01T17:52:06.736926Z"}]}
{"channel":"book","type":"update","data":[{"symbol":"LINK/EUR","bids":[],"asks":[{"price":17.13695,"qty":0.00000000},{"price":17.14815,"qty":158.56104051}],"checksum":3431510425,"timestamp":"2024-06-01T17:52:06.737338Z"}]}
{"channel":"book","type":"update","data":[{"symbol":"LINK/EUR","bids":[],"asks":[{"price":17.14062,"qty":200.00000000}],"checksum":3444343457,"timestamp":"2024-06-01T17:52:06.738210Z"}]}
{"channel":"book","type":"update","data":[{"symbol":"LINK/EUR","bids":[{"price":17.12420,"qty":0.00000000},{"price":17.12295,"qty":269.22723838}],"asks":[],"checksum":2983350498,"timestamp":"2024-06-01T17:52:06.750339Z"}]}
{"channel":"book","type":"update","data":[{"symbol":"LINK/EUR","bids":[],"asks":[{"price":17.14520,"qty":200.00000000}],"checksum":2256346128,"timestamp":"2024-06-01T17:52:06.750419Z"}]}
{"channel":"book","type":"update","data":[{"symbol":"LINK/EUR","bids":[{"price":17.12420,"qty":76.91256857}],"asks":[],"checksum":3124461642,"timestamp":"2024-06-01T17:52:06.755314Z"}]}
{"channel":"book","type":"update","data":[{"symbol":"LINK/EUR","bids":[],"asks":[{"price":17.14262,"qty":0.00000000},{"price":17.14814,"qty":9.04334231}],"checksum":2069372670,"timestamp":"2024-06-01T17:52:06.937678Z"}]}
{"channel":"book","type":"update","data":[{"symbol":"LINK/EUR","bids":[],"asks":[{"price":17.14062,"qty":0.00000000},{"price":17.14815,"qty":158.56104051}],"checksum":80803020,"timestamp":"2024-06-01T17:52:06.937790Z"}]}
{"channel":"book","type":"update","data":[{"symbol":"LINK/EUR","bids":[],"asks":[{"price":17.14337,"qty":243.48672997}],"checksum":761658721,"timestamp":"2024-06-01T17:52:06.942064Z"}]}
{"channel":"book","type":"update","data":[{"symbol":"LINK/EUR","bids":[],"asks":[{"price":17.14262,"qty":200.00000000}],"checksum":1285867415,"timestamp":"2024-06-01T17:52:06.942419Z"}]}
{"channel":"book","type":"update","data":[{"symbol":"LINK/EUR","bids":[],"asks":[{"price":17.14521,"qty":0.00000000},{"price":17.14814,"qty":9.04334231}],"checksum":2210788537,"timestamp":"2024-06-01T17:52:07.058861Z"}]}
{"channel":"book","type":"update","data":[{"symbol":"LINK/EUR","bids":[],"asks":[{"price":17.13982,"qty":0.00000000},{"price":17.14815,"qty":158.56104051}],"checksum":2166713427,"timestamp":"2024-06-01T17:52:07.076394Z"}]}
{"channel":"book","type":"update","data":[{"symbol":"LINK/EUR","bids":[{"price":17.12849,"qty":134.57010623}],"asks":[],"checksum":3281783490,"timestamp":"2024-06-01T17:52:07.759320Z"}]}
{"channel":"book","type":"update","data":[{"symbol":"LINK/EUR","bids":[],"asks":[{"price":17.14522,"qty":0.00000000},{"price":17.16376,"qty":16.80000000}],"checksum":1643747233,"timestamp":"2024-06-01T17:52:07.916672Z"}]}
{"channel":"book","type":"update","data":[{"symbol":"LINK/EUR","bids":[],"asks":[{"price":17.13694,"qty":41.28640368}],"checksum":533166064,"timestamp":"2024-06-01T17:52:07.972699Z"}]}
{"channel":"book","type":"update","data":[{"symbol":"LINK/EUR","bids":[],"asks":[{"price":17.14245,"qty":0.00000000},{"price":17.16468,"qty":11.58242592}],"checksum":1031128213,"timestamp":"2024-06-01T17:52:08.225956Z"}]}
{"channel":"book","type":"update","data":[{"symbol":"LINK/EUR","bids":[],"asks":[{"price":17.13694,"qty":20.63824453}],"checksum":2001862403,"timestamp":"2024-06-01T17:52:08.388853Z"}]}
{"channel":"book","type":"update","data":[{"symbol":"LINK/EUR","bids":[],"asks":[{"price":17.13694,"qty":0.00000000},{"price":17.16469,"qty":268.90000000}],"checksum":1618313702,"timestamp":"2024-06-01T17:52:08.388946Z"}]}
{"channel":"book","type":"update","data":[{"symbol":"LINK/EUR","bids":[],"asks":[{"price":17.13962,"qty":9.69113841}],"checksum":1555137575,"timestamp":"2024-06-01T17:52:08.395745Z"}]}
{"channel":"book","type":"update","data":[{"symbol":"LINK/EUR","bids":[],"asks":[{"price":17.13961,"qty":0.95179617}],"checksum":265035382,"timestamp":"2024-06-01T17:52:08.428818Z"}]}
{"channel":"book","type":"update","data":[{"symbol":"LINK/EUR","bids":[],"asks":[{"price":17.13944,"qty":9.69114704}],"checksum":3752285208,"timestamp":"2024-06-01T17:52:08.431962Z"}]}
{"channel":"book","type":"update","data":[{"symbol":"LINK/EUR","bids":[],"asks":[{"price":17.13979,"qty":0.00000000},{"price":17.16376,"qty":16.80000000}],"checksum":2901591164,"timestamp":"2024-06-01T17:52:08.434940Z"}]}
{"channel":"book","type":"update","data":[{"symbol":"LINK/EUR","bids":[],"asks":[{"price":17.14259,"qty":40.00000000}],"checksum":1116647652,"timestamp":"2024-06-01T17:52:08.434964Z"}]}
{"channel":"book","type":"update","data":[{"symbol":"LINK/EUR","bids":[],"asks":[{"price":17.13962,"qty":0.00000000},{"price":17.16376,"qty":16.80000000}],"checksum":3664733076,"timestamp":"2024-06-01T17:52:08.435297Z"}]}
{"channel":"book","type":"update","data":[{"symbol":"LINK/EUR","bids":[{"price":17.12849,"qty":0.00000000},{"price":17.12330,"qty":220.47746800}],"asks":[],"checksum":2564162821,"timestamp":"2024-06-01T17:52:08.450803Z"}]}
{"channel":"book","type":"update","data":[{"symbol":"LINK/EUR","bids":[{"price":17.12909,"qty":134.56538246}],"asks":[],"checksum":283435888,"timestamp":"2024-06-01T17:52:08.454755Z"}]}
{"channel":"book","type":"update","data":[{"symbol":"LINK/EUR","bids":[],"asks":[{"price":17.14258,"qty":243.48672997}],"checksum":907503004,"timestamp":"2024-06-01T17:52:08.560502Z"}]}
{"channel":"book","type":"update","data":[{"symbol":"LINK/EUR","bids":[],"asks":[{"price":17.14257,"qty":200.00000000}],"checksum":2487546507,"timestamp":"2024-06-01T17:52:08.565350Z"}]}
{"channel":"book","type":"update","data":[{"symbol":"LINK/EUR","bids":[],"asks":[{"price":17.14255,"qty":40.00000000}],"checksum":1642110195,"timestamp":"2024-06-01T17:52:08.565442Z"}]}
{"channel":"book","type":"update","data":[{"symbol":"LINK/EUR","bids":[],"asks":[{"price":17.14254,"qty":40.00000000}],"checksum":1173182165,"timestamp":"2024-06-01T17:52:08.592452Z"}]}
{"channel":"book","type":"update","data":[{"symbol":"LINK/EUR","bids":[],"asks":[{"price":17.14255,"qty":0.00000000},{"price":17.14520,"qty":200.00000000}],"checksum":3379565700,"timestamp":"2024-06-01T17:52:08.592503Z"}]}
{"channel":"book","type":"update","data":[{"symbol":"LINK/EUR","bids":[],"asks":[{"price":17.14258,"qty":0.00000000},{"price":17.14814,"qty":9.04334231}],"checksum":3625079161,"timestamp":"2024-06-01T17:52:08.596313Z"}]}
{"channel":"book","type":"update","data":[{"symbol":"LINK/EUR","bids":[],"asks":[{"price":17.14259,"qty":0.00000000},{"price":17.14815,"qty":158.56104051}],"checksum":168621323,"timestamp":"2024-06-01T17:52:08.596999Z"}]}
{"channel":"book","type":"update","data":[{"symbol":"LINK/EUR","bids":[],"asks":[{"price":17.14262,"qty":0.00000000},{"price":17.16376,"qty":16.80000000}],"checksum":2258664695,"timestamp":"2024-06-01T17:52:08.598032Z"}]}
{"channel":"book","type":"update","data":[{"symbol":"LINK/EUR","bids":[{"price":17.12909,"qty":0.00000000},{"price":17.12330,"qty":220.47746800}],"asks":[],"checksum":244488834,"timestamp":"2024-06-01T17:52:08.799465Z"}]}
{"channel":"book","type":"update","data":[{"symbol":"LINK/EUR","bids":[],"asks":[{"price":17.14253,"qty":200.00000000}],"checksum":2005493639,"timestamp":"2024-06-01T17:52:08.941135Z"}]}
{"channel":"book","type":"update","data":[{"symbol":"LINK/EUR","bids":[],"asks":[{"price":17.14252,"qty":243.48672997}],"checksum":3110532816,"timestamp":"2024-06-01T17:52:08.945152Z"}]}
{"channel":"book","type":"update","data":[{"symbol":"LINK/EUR","bids":[],"asks":[{"price":17.14252,"qty":443.48672997}],"checksum":106616232,"timestamp":"2024-06-01T17:52:08.946099Z"}]}
{"channel":"book","type":"update","data":[{"symbol":"LINK/EUR","bids":[],"asks":[{"price":17.14250,"qty":40.00000000}],"checksum":3789780164,"timestamp":"2024-06-01T17:52:08.946266Z"}]}
{"channel":"book","type":"update","data":[{"symbol":"LINK/EUR","bids":[],"asks":[{"price":17.14252,"qty":200.00000000}],"checksum":2911609669,"timestamp":"2024-06-01T17:52:09.058827Z"}]}
{"channel":"book","type":"update","data":[{"symbol":"LINK/EUR","bids":[],"asks":[{"price":17.14249,"qty":243.48672997}],"checksum":763511979,"timestamp":"2024-06-01T17:52:09.062568Z"}]}
{"channel":"book","type":"update","data":[{"symbol":"LINK/EUR","bids":[],"asks":[{"price":17.14249,"qty":283.48672997}],"checksum":2290811930,"timestamp":"2024-06-01T17:52:09.064770Z"}]}
{"channel":"book","type":"update","data":[{"symbol":"LINK/EUR","bids":[],"asks":[{"price":17.14250,"qty":0.00000000},{"price":17.14520,"qty":200.00000000}],"checksum":2822713086,"timestamp":"2024-06-01T17:52:09.064800Z"}]}
{"channel":"book","type":"update","data":[{"symbol":"LINK/EUR","bids":[],"asks":[{"price":17.14257,"qty":0.00000000},{"price":17.14814,"qty":9.04334231}],"checksum":1181410336,"timestamp":"2024-06-01T17:52:09.065822Z"}]}
{"channel":"book","type":"update","data":[{"symbol":"LINK/EUR","bids":[],"asks":[{"price":17.14254,"qty":0.00000000},{"price":17.14815,"qty":158.56104051}],"checksum":471014570,"timestamp":"2024-06-01T17:52:09.093937Z"}]}
{"channel":"book","type":"update","data":[{"symbol":"LINK/EUR","bids":[],"asks":[{"price":17.14520,"qty":0.00000000},{"price":17.16376,"qty":16.80000000}],"checksum":2957118648,"timestamp":"2024-06-01T17:52:09.136957Z"}]}
{"channel":"book","type":"update","data":[{"symbol":"LINK/EUR","bids":[{"price":17.12928,"qty":134.56386615}],"asks":[],"checksum":4105444225,"timestamp":"2024-06-01T17:52:09.311371Z"}]}
{"channel":"book","type":"update","data":[{"symbol":"LINK/EUR","bids":[],"asks":[{"price":17.14248,"qty":200.00000000}],"checksum":2721501147,"timestamp":"2024-06-01T17:52:09.437109Z"}]}
{"channel":"book","type":"update","data":[{"symbol":"LINK/EUR","bids":[],"asks":[{"price":17.14249,"qty":40.00000000}],"checksum":1690099741,"timestamp":"2024-06-01T17:52:09.440728Z"}]}
{"channel":"book","type":"update","data":[{"symbol":"LINK/EUR","bids":[],"asks":[{"price":17.14245,"qty":40.00000000}],"checksum":603604003,"timestamp":"2024-06-01T17:52:09.442112Z"}]}
{"channel":"book","type":"update","data":[{"symbol":"LINK/EUR","bids":[],"asks":[{"price":17.14252,"qty":0.00000000},{"price":17.14815,"qty":158.56104051}],"checksum":3227526259,"timestamp":"2024-06-01T17:52:09.442468Z"}]}
{"channel":"book","type":"update","data":[{"symbol":"LINK/EUR","bids":[],"asks":[{"price":17.14244,"qty":243.48672997}],"checksum":2868041270,"timestamp":"2024-06-01T17:52:09.559215Z"}]}
{"channel":"book","type":"update","data":[{"symbol":"LINK/EUR","bids":[],"asks":[{"price":17.14337,"qty":0.00000000},{"price":17.14815,"qty":158.56104051}],"checksum":3704062645,"timestamp":"2024-06-01T17:52:09.562624Z"}]}
{"channel":"book","type":"update","data":[{"symbol":"LINK/EUR","bids":[],"asks":[{"price":17.14243,"qty":200.00000000}],"checksum":4096302515,"timestamp":"2024-06-01T17:52:09.564268Z"}]}
{"channel":"book","type":"update","data":[{"symbol":"LINK/EUR","bids":[],"asks":[{"price":17.14245,"qty":0.00000000},{"price":17.14815,"qty":158.56104051}],"checksum":2380835419,"timestamp":"2024-06-01T17:52:09.564285Z"}]}
{"channel":"book","type":"update","data":[{"symbol":"LINK/EUR","bids":[],"asks":[{"price":17.14241,"qty":40.00000000}],"checksum":3508682042,"timestamp":"2024-06-01T17:52:09.564450Z"}]}
{"channel":"book","type":"update","data":[{"symbol":"LINK/EUR","bids":[],"asks":[{"price":17.14240,"qty":40.00000000}],"checksum":1193729469,"timestamp":"2024-06-01T17:52:09.593407Z"}]}
{"channel":"book","type":"update","data":[{"symbol":"LINK/EUR","bids":[],"asks":[{"price":17.14241,"qty":0.00000000},{"price":17.14814,"qty":9.04334231}],"checksum":3830959534,"timestamp":"2024-06-01T17:52:09.593462Z"}]}
{"channel":"book","type":"update","data":[{"symbol":"LINK/EUR","bids":[],"asks":[{"price":17.14239,"qty":243.48672997}],"checksum":3359650637,"timestamp":"2024-06-01T17:52:09.597222Z"}]}
{"channel":"book","type":"update","data":[{"symbol":"LINK/EUR","bids":[],"asks":[{"price":17.14243,"qty":0.00000000},{"price":17.14814,"qty":9.04334231}],"checksum":3225886261,"timestamp":"2024-06-01T17:52:09.597913Z"}]}
{"channel":"book","type":"update","data":[{"symbol":"LINK/EUR","bids":[],"asks":[{"price":17.14249,"qty":0.00000000},{"price":17.14815,"qty":158.56104051}],"checksum":2996462612,"timestamp":"2024-06-01T17:52:09.598055Z"}]}
{"channel":"book","type":"update","data":[{"symbol":"LINK/EUR","bids":[],"asks":[{"price":17.14238,"qty":200.00000000}],"checksum":3318655463,"timestamp":"2024-06-01T17:52:09.937672Z"}]}
{"channel":"book","type":"update","data":[{"symbol":"LINK/EUR","bids":[],"asks":[{"price":17.14239,"qty":0.00000000},{"price":17.14815,"qty":158.56104051}],"checksum":3418930040,"timestamp":"2024-06-01T17:52:09.941240Z"}]}
{"channel":"book","type":"update","data":[{"symbol":"LINK/EUR","bids":[],"asks":[{"price":17.14248,"qty":0.00000000},{"price":17.16376,"qty":16.80000000}],"checksum":2853126455,"timestamp":"2024-06-01T17:52:09.942810Z"}]}
{"channel":"book","type":"update","data":[{"symbol":"LINK/EUR","bids":[],"asks":[{"price":17.14235,"qty":40.00000000}],"checksum":1239521929,"timestamp":"2024-06-01T17:52:09.943331Z"}]}
{"channel":"book","type":"update","data":[{"symbol":"LINK/EUR","bids":[],"asks":[{"price":17.14234,"qty":243.48672997}],"checksum":3718421772,"timestamp":"2024-06-01T17:52:10.060963Z"}]}
{"channel":"book","type":"update","data":[{"symbol":"LINK/EUR","bids":[],"asks":[{"price":17.14244,"qty":0.00000000},{"price":17.14815,"qty":158.56104051}],"checksum":2467719139,"timestamp":"2024-06-01T17:52:10.064439Z"}]}
{"channel":"book","type":"update","data":[{"symbol":"LINK/EUR","bids":[],"asks":[{"price":17.14233,"qty":200.00000000}],"checksum":3503098832,"timestamp":"2024-06-01T17:52:10.065607Z"}]}
{"channel":"book","type":"update","data":[{"symbol":"LINK/EUR","bids":[],"asks":[{"price":17.14235,"qty":0.00000000},{"price":17.14815,"qty":158.56104051}],"checksum":64975151,"timestamp":"2024-06-01T17:52:10.066436Z"}]}
{"channel":"book","type":"update","data":[{"symbol":"LINK/EUR","bids":[],"asks":[{"price":17.14231,"qty":40.00000000}],"checksum":340963885,"timestamp":"2024-06-01T17:52:10.066634Z"}]}
{"channel":"book","type":"update","data":[{"symbol":"LINK/EUR","bids":[],"asks":[{"price":17.14231,"qty":0.00000000},{"price":17.14815,"qty":158.56104051}],"checksum":64975151,"timestamp":"2024-06-01T17:52:10.094612Z"}]}
{"channel":"book","type":"update","data":[{"symbol":"LINK/EUR","bids":[],"asks":[{"price":17.14230,"qty":40.00000000}],"checksum":556221113,"timestamp":"2024-06-01T17:52:10.094694Z"}]}
{"channel":"book","type":"update","data":[{"symbol":"LINK/EUR","bids":[],"asks":[{"price":17.14232,"qty":243.48672997}],"checksum":2482883880,"timestamp":"2024-06-01T17:52:10.098686Z"}]}
{"channel":"book","type":"update","data":[{"symbol":"LINK/EUR","bids":[],"asks":[{"price":17.14238,"qty":0.00000000},{"price":17.14814,"qty":9.04334231}],"checksum":26907523,"timestamp":"2024-06-01T17:52:10.099354Z"}]}
{"channel":"book","type":"update","data":[{"symbol":"LINK/EUR","bids":[],"asks":[{"price":17.14240,"qty":0.00000000},{"price":17.14815,"qty":158.56104051}],"checksum":4006332066,"timestamp":"2024-06-01T17:52:10.099512Z"}]}
{"channel":"book","type":"update","data":[{"symbol":"LINK/EUR","bids":[{"price":17.12928,"qty":0.00000000},{"price":17.12330,"qty":220.47746800}],"asks":[],"checksum":2856178075,"timestamp":"2024-06-01T17:52:10.295041Z"}]}
{"channel":"book","type":"update","data":[{"symbol":"LINK/EUR","bids":[{"price":17.12878,"qty":134.56778341}],"asks":[],"checksum":1696692934,"timestamp":"2024-06-01T17:52:10.298458Z"}]}
{"channel":"book","type":"update","data":[{"symbol":"LINK/EUR","bids":[],"asks":[{"price":17.14231,"qty":200.00000000}],"checksum":1859844559,"timestamp":"2024-06-01T17:52:10.437845Z"}]}
{"channel":"book","type":"update","data":[{"symbol":"LINK/EUR","bids":[],"asks":[{"price":17.14232,"qty":0.00000000},{"price":17.14815,"qty":158.56104051}],"checksum":3855702707,"timestamp":"2024-06-01T17:52:10.441708Z"}]}
{"channel":"book","type":"update","data":[{"symbol":"LINK/EUR","bids":[],"asks":[{"price":17.14233,"qty":0.00000000},{"price":17.16376,"qty":16.80000000}],"checksum":71691711,"timestamp":"2024-06-01T17:52:10.444374Z"}]}
{"channel":"book","type":"update","data":[{"symbol":"LINK/EUR","bids":[],"asks":[{"price":17.14228,"qty":40.00000000}],"checksum":345287605,"timestamp":"2024-06-01T17:52:10.444760Z"}]}
{"channel":"book","type":"update","data":[{"symbol":"LINK/EUR","bids":[],"asks":[{"price":17.14227,"qty":243.48672997}],"checksum":3562866995,"timestamp":"2024-06-01T17:52:10.562347Z"}]}
{"channel":"book","type":"update","data":[{"symbol":"LINK/EUR","bids":[{"price":17.12878,"qty":0.00000000},{"price":17.12330,"qty":220.47746800}],"asks":[],"checksum":457286254,"timestamp":"2024-06-01T17:52:10.566625Z"}]}
{"channel":"book","type":"update","data":[{"symbol":"LINK/EUR","bids":[],"asks":[{"price":17.14226,"qty":200.00000000}],"checksum":653088024,"timestamp":"2024-06-01T17:52:10.567182Z"}]}
{"channel":"book","type":"update","data":[{"symbol":"LINK/EUR","bids":[],"asks":[{"price":17.14228,"qty":0.00000000},{"price":17.14814,"qty":9.04334231}],"checksum":3253170791,"timestamp":"2024-06-01T17:52:10.567203Z"}]}
{"channel":"book","type":"update","data":[{"symbol":"LINK/EUR","bids":[],"asks":[{"price":17.14234,"qty":0.00000000},{"price":17.14815,"qty":158.56104051}],"checksum":2383698091,"timestamp":"2024-06-01T17:52:10.567219Z"}]}
{"channel":"book","type":"update","data":[{"symbol":"LINK/EUR","bids":[],"asks":[{"price":17.14224,"qty":40.00000000}],"checksum":3388223427,"timestamp":"2024-06-01T17:52:10.567337Z"}]}
{"channel":"book","type":"update","data":[{"symbol":"LINK/EUR","bids":[],"asks":[{"price":17.14224,"qty":0.00000000},{"price":17.14815,"qty":158.56104051}],"checksum":2383698091,"timestamp":"2024-06-01T17:52:10.593246Z"}]}
{"channel":"book","type":"update","data":[{"symbol":"LINK/EUR","bids":[],"asks":[{"price":17.14223,"qty":40.00000000}],"checksum":1136524335,"timestamp":"2024-06-01T17:52:10.593331Z"}]}
{"channel":"book","type":"update","data":[{"symbol":"LINK/EUR","bids":[],"asks":[{"price":17.14225,"qty":243.48672997}],"checksum":4033015803,"timestamp":"2024-06-01T17:52:10.597513Z"}]}
{"channel":"book","type":"update","data":[{"symbol":"LINK/EUR","bids":[],"asks":[{"price":17.14231,"qty":0.00000000},{"price":17.14814,"qty":9.04334231}],"checksum":2198594521,"timestamp":"2024-06-01T17:52:10.597817Z"}]}
{"channel":"book","type":"update","data":[{"symbol":"LINK/EUR","bids":[],"asks":[{"price":17.14230,"qty":0.00000000},{"price":17.14815,"qty":158.56104051}],"checksum":2131187261,"timestamp":"2024-06-01T17:52:10.598024Z"}]}
{"channel":"book","type":"update","data":[{"symbol":"LINK/EUR","bids":[{"price":17.13342,"qty":0.00000000},{"price":17.12295,"qty":269.22723838}],"asks":[],"checksum":1396267507,"timestamp":"2024-06-01T17:52:10.803884Z"}]}
{"channel":"book","type":"update","data":[{"symbol":"LINK/EUR","bids":[{"price":17.13383,"qty":70.02006900}],"asks":[],"checksum":3954870733,"timestamp":"2024-06-01T17:52:10.806767Z"}]}
{"channel":"book","type":"update","data":[{"symbol":"LINK/EUR","bids":[{"price":17.13343,"qty":0.00000000},{"price":17.12295,"qty":269.22723838},{"price":17.13341,"qty":303.70000000}],"asks":[],"checksum":2404905455,"timestamp":"2024-06-01T17:52:10.806817Z"}]}
{"channel":"book","type":"update","data":[{"symbol":"LINK/EUR","bids":[],"asks":[{"price":17.14225,"qty":0.00000000},{"price":17.16376,"qty":16.80000000}],"checksum":3397001099,"timestamp":"2024-06-01T17:52:10.807915Z"}]}
{"channel":"book","type":"update","data":[{"symbol":"LINK/EUR","bids":[{"price":17.13382,"qty":0.00000000},{"price":17.12295,"qty":269.22723838}],"asks":[],"checksum":3112123929,"timestamp":"2024-06-01T17:52:10.809218Z"}]}
{"channel":"book","type":"update","data":[{"symbol":"LINK/EUR","bids":[],"asks":[{"price":17.14222,"qty":40.00000000}],"checksum":1911627873,"timestamp":"2024-06-01T17:52:10.809239Z"}]}
{"channel":"book","type":"update","data":[{"symbol":"LINK/EUR","bids":[{"price":17.13407,"qty":21.00000000}],"asks":[],"checksum":1242631936,"timestamp":"2024-06-01T17:52:10.809297Z"}]}
{"channel":"book","type":"update","data":[{"symbol":"LINK/EUR","bids":[],"asks":[{"price":17.14224,"qty":200.00000000}],"checksum":985083818,"timestamp":"2024-06-01T17:52:10.809614Z"}]}
{"channel":"book","type":"update","data":[{"symbol":"LINK/EUR","bids":[],"asks":[{"price":17.14814,"qty":0.00000000},{"price":17.14815,"qty":158.56104051}],"checksum":2676857860,"timestamp":"2024-06-01T17:52:10.872011Z"}]}
{"channel":"book","type":"update","data":[{"symbol":"LINK/EUR","bids":[],"asks":[{"price":17.14814,"qty":9.04326066}],"checksum":3164908029,"timestamp":"2024-06-01T17:52:10.872252Z"}]}
{"channel":"book","type":"update","data":[{"symbol":"LINK/EUR","bids":[{"price":17.12878,"qty":134.56780601}],"asks":[],"checksum":3990336525,"timestamp":"2024-06-01T17:52:10.928226Z"}]}
{"channel":"book","type":"update","data":[{"symbol":"LINK/EUR","bids":[],"asks":[{"price":17.14224,"qty":0.00000000},{"price":17.14815,"qty":158.56104051}],"checksum":3494438441,"timestamp":"2024-06-01T17:52:10.936864Z"}]}
{"channel":"book","type":"update","data":[{"symbol":"LINK/EUR","bids":[],"asks":[{"price":17.14221,"qty":243.48672997}],"checksum":2408128879,"timestamp":"2024-06-01T17:52:10.940768Z"}]}
{"channel":"book","type":"update","data":[{"symbol":"LINK/EUR","bids":[],"asks":[{"price":17.14222,"qty":0.00000000},{"price":17.14815,"qty":158.56104051}],"checksum":1401617286,"timestamp":"2024-06-01T17:52:10.942076Z"}]}
{"channel":"book","type":"update","data":[{"symbol":"LINK/EUR","bids":[],"asks":[{"price":17.14814,"qty":32.65262003}],"checksum":3622584086,"timestamp":"2024-06-01T17:52:10.965280Z"}]}
{"channel":"book","type":"update","data":[{"symbol":"LINK/EUR","bids":[],"asks":[{"price":17.14814,"qty":23.60935937}],"checksum":2972344163,"timestamp":"2024-06-01T17:52:10.965311Z"}]}
{"channel":"book","type":"update","data":[{"symbol":"LINK/EUR","bids":[],"asks":[{"price":17.14222,"qty":1.07691387}],"checksum":3062233452,"timestamp":"2024-06-01T17:52:11.034179Z"}]}
{"channel":"book","type":"update","data":[{"symbol":"LINK/EUR","bids":[],"asks":[{"price":17.14227,"qty":0.00000000},{"price":17.14815,"qty":158.56104051}],"checksum":789452521,"timestamp":"2024-06-01T17:52:11.037646Z"}]}
{"channel":"book","type":"update","data":[{"symbol":"LINK/EUR","bids":[],"asks":[{"price":17.14218,"qty":40.00000000}],"checksum":2370480184,"timestamp":"2024-06-01T17:52:11.039149Z"}]}
{"channel":"book","type":"update","data":[{"symbol":"LINK/EUR","bids":[],"asks":[{"price":17.14220,"qty":200.00000000}],"checksum":1413219132,"timestamp":"2024-06-01T17:52:11.039801Z"}]}
{"channel":"book","type":"update","data":[{"symbol":"LINK/EUR","bids":[],"asks":[{"price":17.14217,"qty":243.48672997}],"checksum":2330839108,"timestamp":"2024-06-01T17:52:11.076481Z"}]}
{"channel":"book","type":"update","data":[{"symbol":"LINK/EUR","bids":[],"asks":[{"price":17.14221,"qty":0.00000000},{"price":17.14263,"qty":158.56104051}],"checksum":303706712,"timestamp":"2024-06-01T17:52:11.080113Z"}]}
{"channel":"book","type":"update","data":[{"symbol":"LINK/EUR","bids":[],"asks":[{"price":17.14226,"qty":0.00000000},{"price":17.14814,"qty":23.60935937}],"checksum":747515938,"timestamp":"2024-06-01T17:52:11.081457Z"}]}
{"channel":"book","type":"update","data":[{"symbol":"LINK/EUR","bids":[],"asks":[{"price":17.14216,"qty":200.00000000}],"checksum":927542791,"timestamp":"2024-06-01T17:52:11.081727Z"}]}
{"channel":"book","type":"update","data":[{"symbol":"LINK/EUR","bids":[],"asks":[{"price":17.14218,"qty":0.00000000},{"price":17.14814,"qty":23.60935937}],"checksum":4153175332,"timestamp":"2024-06-01T17:52:11.081923Z"}]}
{"channel":"book","type":"update","data":[{"symbol":"LINK/EUR","bids":[],"asks":[{"price":17.14214,"qty":40.00000000}],"checksum":3168211169,"timestamp":"2024-06-01T17:52:11.082109Z"}]}
{"channel":"book","type":"update","data":[{"symbol":"LINK/EUR","bids":[],"asks":[{"price":17.14214,"qty":0.00000000},{"price":17.14814,"qty":23.60935937}],"checksum":4153175332,"timestamp":"2024-06-01T17:52:11.095414Z"}]}
{"channel":"book","type":"update","data":[{"symbol":"LINK/EUR","bids":[],"asks":[{"price":17.14213,"qty":40.00000000}],"checksum":916374285,"timestamp":"2024-06-01T17:52:11.095637Z"}]}
{"channel":"book","type":"update","data":[{"symbol":"LINK/EUR","bids":[],"asks":[{"price":17.14220,"qty":400.00000000}],"checksum":43007102,"timestamp":"2024-06-01T17:52:11.217850Z"}]}
{"channel":"book","type":"update","data":[{"symbol":"LINK/EUR","bids":[],"asks":[{"price":17.13943,"qty":20.63824453}],"checksum":3185397440,"timestamp":"2024-06-01T17:52:11.228848Z"}]}
{"channel":"book","type":"update","data":[{"symbol":"LINK/EUR","bids":[],"asks":[{"price":17.13926,"qty":9.69200419}],"checksum":152425197,"timestamp":"2024-06-01T17:52:11.231731Z"}]}
{"channel":"book","type":"update","data":[{"symbol":"LINK/EUR","bids":[],"asks":[{"price":17.14212,"qty":243.48672997}],"checksum":4057437053,"timestamp":"2024-06-01T17:52:11.233267Z"}]}
{"channel":"book","type":"update","data":[{"symbol":"LINK/EUR","bids":[],"asks":[{"price":17.14216,"qty":0.00000000},{"price":17.14223,"qty":40.00000000}],"checksum":2624358039,"timestamp":"2024-06-01T17:52:11.233804Z"}]}
{"channel":"book","type":"update","data":[{"symbol":"LINK/EUR","bids":[],"asks":[{"price":17.13944,"qty":0.00000000},{"price":17.14253,"qty":200.00000000}],"checksum":1696188330,"timestamp":"2024-06-01T17:52:11.234812Z"}]}
{"channel":"book","type":"update","data":[{"symbol":"LINK/EUR","bids":[],"asks":[{"price":17.13940,"qty":40.00000000}],"checksum":3639654742,"timestamp":"2024-06-01T17:52:11.236086Z"}]}
{"channel":"book","type":"update","data":[{"symbol":"LINK/EUR","bids":[],"asks":[{"price":17.14213,"qty":0.00000000},{"price":17.14253,"qty":200.00000000}],"checksum":3802793566,"timestamp":"2024-06-01T17:52:11.236108Z"}]}
{"channel":"book","type":"update","data":[{"symbol":"LINK/EUR","bids":[{"price":17.13407,"qty":0.00000000},{"price":17.12330,"qty":220.47746800}],"asks":[],"checksum":1891764271,"timestamp":"2024-06-01T17:52:11.238550Z"}]}
{"channel":"book","type":"update","data":[{"symbol":"LINK/EUR","bids":[{"price":17.12878,"qty":0.00000000},{"price":17.12295,"qty":269.22723838}],"asks":[],"checksum":1080452762,"timestamp":"2024-06-01T17:52:11.307748Z"}]}
{"channel":"book","type":"update","data":[{"symbol":"LINK/EUR","bids":[],"asks":[{"price":17.14212,"qty":0.00000000},{"price":17.14263,"qty":158.56104051}],"checksum":1132386158,"timestamp":"2024-06-01T17:52:11.312655Z"}]}
{"channel":"book","type":"update","data":[{"symbol":"LINK/EUR","bids":[],"asks":[{"price":17.14211,"qty":200.00000000}],"checksum":180155383,"timestamp":"2024-06-01T17:52:11.312979Z"}]}
{"channel":"book","type":"update","data":[{"symbol":"LINK/EUR","bids":[],"asks":[{"price":17.14223,"qty":0.00000000},{"price":17.14263,"qty":158.56104051}],"checksum":1578992840,"timestamp":"2024-06-01T17:52:11.314719Z"}]}
{"channel":"book","type":"update","data":[{"symbol":"LINK/EUR","bids":[],"asks":[{"price":17.14253,"qty":0.00000000},{"price":17.14814,"qty":23.60935937}],"checksum":596329169,"timestamp":"2024-06-01T17:52:11.390971Z"}]}
{"channel":"book","type":"update","data":[{"symbol":"LINK/EUR","bids":[{"price":17.12420,"qty":0.00000000},{"price":17.12219,"qty":70.02006900}],"asks":[],"checksum":3444188459,"timestamp":"2024-06-01T17:52:11.419299Z"}]}
{"channel":"book","type":"update","data":[{"symbol":"LINK/EUR","bids":[{"price":17.12328,"qty":76.91670677}],"asks":[],"checksum":3885813091,"timestamp":"2024-06-01T17:52:11.424129Z"}]}
{"channel":"book","type":"update","data":[{"symbol":"LINK/EUR","bids":[],"asks":[{"price":17.14211,"qty":0.00000000},{"price":17.14815,"qty":158.56104051}],"checksum":3532065298,"timestamp":"2024-06-01T17:52:11.437991Z"}]}
{"channel":"book","type":"update","data":[{"symbol":"LINK/EUR","bids":[],"asks":[{"price":17.14216,"qty":200.00000000}],"checksum":383597219,"timestamp":"2024-06-01T17:52:11.443046Z"}]}
{"channel":"book","type":"update","data":[{"symbol":"LINK/EUR","bids":[{"price":17.13391,"qty":21.00000000}],"asks":[],"checksum":1828322267,"timestamp":"2024-06-01T17:52:11.460347Z"}]}
{"channel":"book","type":"update","data":[{"symbol":"LINK/EUR","bids":[],"asks":[{"price":17.14216,"qty":0.00000000},{"price":17.14815,"qty":158.56104051}],"checksum":1468264994,"timestamp":"2024-06-01T17:52:11.937097Z"}]}
{"channel":"book","type":"update","data":[{"symbol":"LINK/EUR","bids":[],"asks":[{"price":17.14216,"qty":200.00000000}],"checksum":1828322267,"timestamp":"2024-06-01T17:52:11.942605Z"}]}
{"channel":"book","type":"update","data":[{"symbol":"LINK/EUR","bids":[{"price":17.12868,"qty":134.56860295}],"asks":[],"checksum":401565119,"timestamp":"2024-06-01T17:52:11.981687Z"}]}
{"channel":"book","type":"update","data":[{"symbol":"LINK/EUR","bids":[{"price":17.12649,"qty":0.00000000},{"price":17.12328,"qty":76.91670677}],"asks":[],"checksum":2664862697,"timestamp":"2024-06-01T17:52:12.218651Z"}]}
{"channel":"book","type":"update","data":[{"symbol":"LINK/EUR","bids":[{"price":17.12650,"qty":467.47688400}],"asks":[],"checksum":2482554577,"timestamp":"2024-06-01T17:52:12.223618Z"}]}
{"channel":"book","type":"update","data":[{"symbol":"LINK/EUR","bids":[],"asks":[{"price":17.14216,"qty":0.00000000},{"price":17.14815,"qty":158.56104051}],"checksum":1470297696,"timestamp":"2024-06-01T17:52:12.439102Z"}]}
{"channel":"book","type":"update","data":[{"symbol":"LINK/EUR","bids":[{"price":17.12868,"qty":0.00000000},{"price":17.12328,"qty":76.91670677}],"asks":[],"checksum":1123323757,"timestamp":"2024-06-01T17:52:12.441790Z"}]}
{"channel":"book","type":"update","data":[{"symbol":"LINK/EUR","bids":[],"asks":[{"price":17.14216,"qty":200.00000000}],"checksum":2039383700,"timestamp":"2024-06-01T17:52:12.443667Z"}]}
{"channel":"book","type":"update","data":[{"symbol":"LINK/EUR","bids":[],"asks":[{"price":17.14313,"qty":1077.02371910}],"checksum":3167266070,"timestamp":"2024-06-01T17:52:12.475936Z"}]}
{"channel":"book","type":"update","data":[{"symbol":"LINK/EUR","bids":[],"asks":[{"price":17.13943,"qty":0.00000000},{"price":17.14814,"qty":23.60935937}],"checksum":3256598044,"timestamp":"2024-06-01T17:52:12.558232Z"}]}
{"channel":"book","type":"update","data":[{"symbol":"LINK/EUR","bids":[],"asks":[{"price":17.14220,"qty":200.00000000}],"checksum":186880101,"timestamp":"2024-06-01T17:52:12.563145Z"}]}
{"channel":"book","type":"update","data":[{"symbol":"LINK/EUR","bids":[],"asks":[{"price":17.14213,"qty":40.00000000}],"checksum":4218085223,"timestamp":"2024-06-01T17:52:12.564204Z"}]}
{"channel":"book","type":"update","data":[{"symbol":"LINK/EUR","bids":[],"asks":[{"price":17.13940,"qty":0.00000000},{"price":17.14814,"qty":23.60935937}],"checksum":2669528269,"timestamp":"2024-06-01T17:52:12.564261Z"}]}
{"channel":"book","type":"update","data":[{"symbol":"LINK/EUR","bids":[],"asks":[{"price":17.14814,"qty":0.00000000},{"price":17.16376,"qty":16.80000000}],"checksum":4251948137,"timestamp":"2024-06-01T17:52:12.932945Z"}]}
{"channel":"book","type":"update","data":[{"symbol":"LINK/EUR","bids":[],"asks":[{"price":17.16375,"qty":70.52987272}],"checksum":3793950534,"timestamp":"2024-06-01T17:52:12.933299Z"}]}
{"channel":"book","type":"update","data":[{"symbol":"LINK/EUR","bids":[],"asks":[{"price":17.14212,"qty":243.48672997}],"checksum":2158712359,"timestamp":"2024-06-01T17:52:13.059298Z"}]}
{"channel":"book","type":"update","data":[{"symbol":"LINK/EUR","bids":[],"asks":[{"price":17.14211,"qty":200.00000000}],"checksum":1302432398,"timestamp":"2024-06-01T17:52:13.065642Z"}]}
{"channel":"book","type":"update","data":[{"symbol":"LINK/EUR","bids":[],"asks":[{"price":17.14209,"qty":40.00000000}],"checksum":3887151408,"timestamp":"2024-06-01T17:52:13.065806Z"}]}
{"channel":"book","type":"update","data":[{"symbol":"LINK/EUR","bids":[],"asks":[{"price":17.14208,"qty":40.00000000}],"checksum":2811432279,"timestamp":"2024-06-01T17:52:13.093938Z"}]}
{"channel":"book","type":"update","data":[{"symbol":"LINK/EUR","bids":[],"asks":[{"price":17.14209,"qty":0.00000000},{"price":17.14222,"qty":1.07691387}],"checksum":3536112036,"timestamp":"2024-06-01T17:52:13.093952Z"}]}
{"channel":"book","type":"update","data":[{"symbol":"LINK/EUR","bids":[],"asks":[{"price":17.14212,"qty":0.00000000},{"price":17.14263,"qty":158.56104051}],"checksum":1722932191,"timestamp":"2024-06-01T17:52:13.097710Z"}]}
{"channel":"book","type":"update","data":[{"symbol":"LINK/EUR","bids":[],"asks":[{"price":17.14213,"qty":0.00000000},{"price":17.14313,"qty":1077.02371910}],"checksum":746325242,"timestamp":"2024-06-01T17:52:13.098664Z"}]}
{"channel":"book","type":"update","data":[{"symbol":"LINK/EUR","bids":[],"asks":[{"price":17.14211,"qty":0.00000000},{"price":17.16375,"qty":70.52987272}],"checksum":1598485227,"timestamp":"2024-06-01T17:52:13.098710Z"}]}
{"channel":"book","type":"update","data":[{"symbol":"LINK/EUR","bids":[],"asks":[{"price":17.13995,"qty":40.00000000}],"checksum":3872440348,"timestamp":"2024-06-01T17:52:13.231563Z"}]}
{"channel":"book","type":"update","data":[{"symbol":"LINK/EUR","bids":[],"asks":[{"price":17.13992,"qty":40.00000000}],"checksum":3057320099,"timestamp":"2024-06-01T17:52:13.236661Z"}]}
{"channel":"book","type":"update","data":[{"symbol":"LINK/EUR","bids":[],"asks":[{"price":17.14222,"qty":0.00000000},{"price":17.14313,"qty":1077.02371910}],"checksum":512797210,"timestamp":"2024-06-01T17:52:13.264755Z"}]}
{"channel":"book","type":"update","data":[{"symbol":"LINK/EUR","bids":[],"asks":[{"price":17.14212,"qty":5.27964727}],"checksum":2662892926,"timestamp":"2024-06-01T17:52:13.265224Z"}]}
{"channel":"book","type":"update","data":[{"symbol":"LINK/EUR","bids":[],"asks":[{"price":17.14207,"qty":200.00000000}],"checksum":291972157,"timestamp":"2024-06-01T17:52:13.436041Z"}]}
{"channel":"book","type":"update","data":[{"symbol":"LINK/EUR","bids":[],"asks":[{"price":17.14207,"qty":0.00000000},{"price":17.14263,"qty":158.56104051}],"checksum":2662892926,"timestamp":"2024-06-01T17:52:13.440142Z"}]}
{"channel":"book","type":"update","data":[{"symbol":"LINK/EUR","bids":[],"asks":[{"price":17.14208,"qty":0.00000000},{"price":17.14313,"qty":1077.02371910}],"checksum":1986404308,"timestamp":"2024-06-01T17:52:13.441526Z"}]}
{"channel":"book","type":"update","data":[{"symbol":"LINK/EUR","bids":[],"asks":[{"price":17.14207,"qty":200.00000000}],"checksum":684593857,"timestamp":"2024-06-01T17:52:13.467637Z"}]}
{"channel":"book","type":"update","data":[{"symbol":"LINK/EUR","bids":[],"asks":[{"price":17.14220,"qty":0.00000000},{"price":17.14313,"qty":1077.02371910}],"checksum":3179504548,"timestamp":"2024-06-01T17:52:13.644717Z"}]}
{"channel":"book","type":"update","data":[{"symbol":"LINK/EUR","bids":[{"price":17.12830,"qty":134.57162066}],"asks":[],"checksum":1799734678,"timestamp":"2024-06-01T17:52:13.705858Z"}]}
{"channel":"book","type":"update","data":[{"symbol":"LINK/EUR","bids":[{"price":17.12830,"qty":0.00000000},{"price":17.12328,"qty":76.91670677}],"asks":[],"checksum":3179504548,"timestamp":"2024-06-01T17:52:14.714015Z"}]}
{"channel":"book","type":"update","data":[{"symbol":"LINK/EUR","bids":[{"price":17.12784,"qty":134.57519011}],"asks":[],"checksum":402474218,"timestamp":"2024-06-01T17:52:14.717975Z"}]}
{"channel":"book","type":"update","data":[{"symbol":"LINK/EUR","bids":[{"price":17.12784,"qty":0.00000000},{"price":17.12328,"qty":76.91670677}],"asks":[],"checksum":3179504548,"timestamp":"2024-06-01T17:52:15.176857Z"}]}
{"channel":"book","type":"update","data":[{"symbol":"LINK/EUR","bids":[],"asks":[{"price":17.14212,"qty":0.00000000},{"price":17.16375,"qty":70.52987272}],"checksum":2187084994,"timestamp":"2024-06-01T17:52:15.500198Z"}]}
{"channel":"book","type":"update","data":[{"symbol":"LINK/EUR","bids":[],"asks":[{"price":17.16374,"qty":3.17822008}],"checksum":156018289,"timestamp":"2024-06-01T17:52:15.500792Z"}]}
{"channel":"book","type":"update","data":[{"symbol":"LINK/EUR","bids":[],"asks":[{"price":17.14206,"qty":2.12757751}],"checksum":2466109494,"timestamp":"2024-06-01T17:52:15.500939Z"}]}
{"channel":"book","type":"update","data":[{"symbol":"LINK/EUR","bids":[],"asks":[{"price":17.14216,"qty":0.00000000},{"price":17.16374,"qty":3.17822008}],"checksum":2422101002,"timestamp":"2024-06-01T17:52:15.506640Z"}]}
{"channel":"book","type":"update","data":[{"symbol":"LINK/EUR","bids":[],"asks":[{"price":17.13995,"qty":0.00000000},{"price":17.16375,"qty":70.52987272}],"checksum":2286288446,"timestamp":"2024-06-01T17:52:15.568040Z"}]}
{"channel":"book","type":"update","data":[{"symbol":"LINK/EUR","bids":[],"asks":[{"price":17.13992,"qty":0.00000000},{"price":17.16376,"qty":16.80000000}],"checksum":2179319308,"timestamp":"2024-06-01T17:52:15.572888Z"}]}
{"channel":"book","type":"update","data":[{"symbol":"LINK/EUR","bids":[],"asks":[{"price":17.14204,"qty":40.00000000}],"checksum":3645389413,"timestamp":"2024-06-01T17:52:15.572933Z"}]}
{"channel":"book","type":"update","data":[{"symbol":"LINK/EUR","bids":[{"price":17.12878,"qty":134.56778056}],"asks":[],"checksum":3981036462,"timestamp":"2024-06-01T17:52:15.711323Z"}]}
{"channel":"book","type":"update","data":[{"symbol":"LINK/EUR","bids":[],"asks":[{"price":17.14203,"qty":200.00000000}],"checksum":224791097,"timestamp":"2024-06-01T17:52:15.751676Z"}]}
{"channel":"book","type":"update","data":[{"symbol":"LINK/EUR","bids":[],"asks":[{"price":17.14202,"qty":243.48672997}],"checksum":2831761221,"timestamp":"2024-06-01T17:52:15.755739Z"}]}
{"channel":"book","type":"update","data":[{"symbol":"LINK/EUR","bids":[],"asks":[{"price":17.14200,"qty":40.00000000}],"checksum":244341864,"timestamp":"2024-06-01T17:52:15.756988Z"}]}
{"channel":"book","type":"update","data":[{"symbol":"LINK/EUR","bids":[],"asks":[{"price":17.14202,"qty":443.48672997}],"checksum":3690920901,"timestamp":"2024-06-01T17:52:15.756999Z"}]}
{"channel":"book","type":"update","data":[{"symbol":"LINK/EUR","bids":[],"asks":[{"price":17.14002,"qty":40.00000000}],"checksum":2019968114,"timestamp":"2024-06-01T17:52:15.857438Z"}]}
{"channel":"book","type":"update","data":[{"symbol":"LINK/EUR","bids":[],"asks":[{"price":17.14202,"qty":200.00000000}],"checksum":3096666430,"timestamp":"2024-06-01T17:52:15.860919Z"}]}
{"channel":"book","type":"update","data":[{"symbol":"LINK/EUR","bids":[],"asks":[{"price":17.13999,"qty":40.00000000}],"checksum":1539435894,"timestamp":"2024-06-01T17:52:15.862217Z"}]}
{"channel":"book","type":"update","data":[{"symbol":"LINK/EUR","bids":[],"asks":[{"price":17.14200,"qty":0.00000000},{"price":17.14217,"qty":243.48672997}],"checksum":595869672,"timestamp":"2024-06-01T17:52:15.862403Z"}]}
{"channel":"book","type":"update","data":[{"symbol":"LINK/EUR","bids":[],"asks":[{"price":17.14202,"qty":0.00000000},{"price":17.14263,"qty":158.56104051}],"checksum":2330304871,"timestamp":"2024-06-01T17:52:15.863503Z"}]}
{"channel":"book","type":"update","data":[{"symbol":"LINK/EUR","bids":[],"asks":[{"price":17.14202,"qty":200.00000000}],"checksum":595869672,"timestamp":"2024-06-01T17:52:15.938686Z"}]}
{"channel":"book","type":"update","data":[{"symbol":"LINK/EUR","bids":[],"asks":[{"price":17.14202,"qty":0.00000000},{"price":17.14263,"qty":158.56104051}],"checksum":2330304871,"timestamp":"2024-06-01T17:52:15.944466Z"}]}
{"channel":"book","type":"update","data":[{"symbol":"LINK/EUR","bids":[],"asks":[{"price":17.14204,"qty":0.00000000},{"price":17.14313,"qty":1077.02371910}],"checksum":4151496803,"timestamp":"2024-06-01T17:52:15.944917Z"}]}
{"channel":"book","type":"update","data":[{"symbol":"LINK/EUR","bids":[],"asks":[{"price":17.14207,"qty":0.00000000},{"price":17.16374,"qty":3.17822008}],"checksum":917585420,"timestamp":"2024-06-01T17:52:15.950270Z"}]}
{"channel":"book","type":"update","data":[{"symbol":"LINK/EUR","bids":[],"asks":[{"price":17.14202,"qty":200.00000000}],"checksum":151865676,"timestamp":"2024-06-01T17:52:16.438063Z"}]}
{"channel":"book","type":"update","data":[{"symbol":"LINK/EUR","bids":[],"asks":[{"price":17.14202,"qty":0.00000000},{"price":17.16374,"qty":3.17822008}],"checksum":917585420,"timestamp":"2024-06-01T17:52:16.442232Z"}]}
{"channel":"book","type":"update","data":[{"symbol":"LINK/EUR","bids":[{"price":17.13383,"qty":0.00000000},{"price":17.12328,"qty":76.91670677}],"asks":[],"checksum":1908422493,"timestamp":"2024-06-01T17:52:16.712178Z"}]}
{"channel":"book","type":"update","data":[{"symbol":"LINK/EUR","bids":[{"price":17.13392,"qty":70.02006900}],"asks":[],"checksum":1466590004,"timestamp":"2024-06-01T17:52:16.715059Z"}]}
{"channel":"book","type":"update","data":[{"symbol":"LINK/EUR","bids":[],"asks":[{"price":17.14202,"qty":200.00000000}],"checksum":1758860404,"timestamp":"2024-06-01T17:52:16.717054Z"}]}
{"channel":"book","type":"update","data":[{"symbol":"LINK/EUR","bids":[{"price":17.13391,"qty":0.00000000},{"price":17.12328,"qty":76.91670677}],"asks":[],"checksum":851358323,"timestamp":"2024-06-01T17:52:16.717557Z"}]}
{"channel":"book","type":"update","data":[{"symbol":"LINK/EUR","bids":[{"price":17.13434,"qty":21.00000000}],"asks":[],"checksum":274888087,"timestamp":"2024-06-01T17:52:16.717783Z"}]}
{"channel":"book","type":"update","data":[{"symbol":"LINK/EUR","bids":[],"asks":[{"price":17.14202,"qty":0.00000000},{"price":17.16374,"qty":3.17822008}],"checksum":803078871,"timestamp":"2024-06-01T17:52:16.937612Z"}]}
{"channel":"book","type":"update","data":[{"symbol":"LINK/EUR","bids":[],"asks":[{"price":17.14202,"qty":200.00000000}],"checksum":274888087,"timestamp":"2024-06-01T17:52:16.942929Z"}]}
{"channel":"book","type":"update","data":[{"symbol":"LINK/EUR","bids":[{"price":17.13341,"qty":0.00000000},{"price":17.12328,"qty":76.91670677},{"price":17.13393,"qty":303.70000000}],"asks":[],"checksum":2775190888,"timestamp":"2024-06-01T17:52:17.036224Z"}]}
{"channel":"book","type":"update","data":[{"symbol":"LINK/EUR","bids":[],"asks":[{"price":17.14202,"qty":0.00000000},{"price":17.16374,"qty":3.17822008}],"checksum":2597747240,"timestamp":"2024-06-01T17:52:17.041024Z"}]}
{"channel":"book","type":"update","data":[{"symbol":"LINK/EUR","bids":[],"asks":[{"price":17.13961,"qty":0.00000000},{"price":17.16375,"qty":70.52987272}],"checksum":2237337975,"timestamp":"2024-06-01T17:52:17.066259Z"}]}
{"channel":"book","type":"update","data":[{"symbol":"LINK/EUR","bids":[],"asks":[{"price":17.14202,"qty":200.00000000}],"checksum":3672626090,"timestamp":"2024-06-01T17:52:17.071262Z"}]}
{"channel":"book","type":"update","data":[{"symbol":"LINK/EUR","bids":[],"asks":[{"price":17.14002,"qty":0.00000000},{"price":17.16375,"qty":70.52987272}],"checksum":1968000892,"timestamp":"2024-06-01T17:52:17.171142Z"}]}
{"channel":"book","type":"update","data":[{"symbol":"LINK/EUR","bids":[],"asks":[{"price":17.13999,"qty":0.00000000},{"price":17.16376,"qty":16.80000000}],"checksum":2934177380,"timestamp":"2024-06-01T17:52:17.176707Z"}]}
{"channel":"book","type":"update","data":[{"symbol":"LINK/EUR","bids":[],"asks":[{"price":17.14199,"qty":40.00000000}],"checksum":2784272576,"timestamp":"2024-06-01T17:52:17.176739Z"}]}
{"channel":"book","type":"update","data":[{"symbol":"LINK/EUR","bids":[],"asks":[{"price":17.13925,"qty":0.95179617}],"checksum":4215991613,"timestamp":"2024-06-01T17:52:17.238322Z"}]}
{"channel":"book","type":"update","data":[{"symbol":"LINK/EUR","bids":[],"asks":[{"price":17.13908,"qty":9.69160005}],"checksum":2062155643,"timestamp":"2024-06-01T17:52:17.241151Z"}]}
{"channel":"book","type":"update","data":[{"symbol":"LINK/EUR","bids":[],"asks":[{"price":17.14198,"qty":243.48672997}],"checksum":1185743306,"timestamp":"2024-06-01T17:52:17.242586Z"}]}
{"channel":"book","type":"update","data":[{"symbol":"LINK/EUR","bids":[],"asks":[{"price":17.13926,"qty":0.00000000},{"price":17.14313,"qty":1077.02371910}],"checksum":1753844012,"timestamp":"2024-06-01T17:52:17.244131Z"}]}
{"channel":"book","type":"update","data":[{"symbol":"LINK/EUR","bids":[],"asks":[{"price":17.14197,"qty":200.00000000}],"checksum":3558675696,"timestamp":"2024-06-01T17:52:17.437339Z"}]}
{"channel":"book","type":"update","data":[{"symbol":"LINK/EUR","bids":[],"asks":[{"price":17.14198,"qty":0.00000000},{"price":17.14313,"qty":1077.02371910}],"checksum":3161954012,"timestamp":"2024-06-01T17:52:17.441183Z"}]}
{"channel":"book","type":"update","data":[{"symbol":"LINK/EUR","bids":[],"asks":[{"price":17.14202,"qty":0.00000000},{"price":17.16374,"qty":3.17822008}],"checksum":2258003308,"timestamp":"2024-06-01T17:52:17.442846Z"}]}
{"channel":"book","type":"update","data":[{"symbol":"LINK/EUR","bids":[],"asks":[{"price":17.14194,"qty":40.00000000}],"checksum":2643119745,"timestamp":"2024-06-01T17:52:17.443319Z"}]}
{"channel":"book","type":"update","data":[{"symbol":"LINK/EUR","bids":[],"asks":[{"price":17.14193,"qty":243.48672997}],"checksum":821515450,"timestamp":"2024-06-01T17:52:17.560335Z"}]}
{"channel":"book","type":"update","data":[{"symbol":"LINK/EUR","bids":[],"asks":[{"price":17.14192,"qty":200.00000000}],"checksum":1761771373,"timestamp":"2024-06-01T17:52:17.565606Z"}]}
{"channel":"book","type":"update","data":[{"symbol":"LINK/EUR","bids":[],"asks":[{"price":17.14194,"qty":0.00000000},{"price":17.14263,"qty":158.56104051}],"checksum":3100432828,"timestamp":"2024-06-01T17:52:17.565806Z"}]}
{"channel":"book","type":"update","data":[{"symbol":"LINK/EUR","bids":[],"asks":[{"price":17.14190,"qty":40.00000000}],"checksum":1165951983,"timestamp":"2024-06-01T17:52:17.566302Z"}]}
{"channel":"book","type":"update","data":[{"symbol":"LINK/EUR","bids":[],"asks":[{"price":17.14189,"qty":40.00000000}],"checksum":937058902,"timestamp":"2024-06-01T17:52:17.594165Z"}]}
{"channel":"book","type":"update","data":[{"symbol":"LINK/EUR","bids":[],"asks":[{"price":17.14190,"qty":0.00000000},{"price":17.14217,"qty":243.48672997}],"checksum":3452282201,"timestamp":"2024-06-01T17:52:17.594187Z"}]}
{"channel":"book","type":"update","data":[{"symbol":"LINK/EUR","bids":[],"asks":[{"price":17.13907,"qty":20.63824453}],"checksum":2903856040,"timestamp":"2024-06-01T17:52:17.596041Z"}]}
{"channel":"book","type":"update","data":[{"symbol":"LINK/EUR","bids":[],"asks":[{"price":17.14193,"qty":0.00000000},{"price":17.14217,"qty":243.48672997}],"checksum":3569421973,"timestamp":"2024-06-01T17:52:17.597948Z"}]}
{"channel":"book","type":"update","data":[{"symbol":"LINK/EUR","bids":[],"asks":[{"price":17.14197,"qty":0.00000000},{"price":17.14313,"qty":1077.02371910}],"checksum":2498308941,"timestamp":"2024-06-01T17:52:17.599012Z"}]}
{"channel":"book","type":"update","data":[{"symbol":"LINK/EUR","bids":[],"asks":[{"price":17.13890,"qty":9.69159996}],"checksum":2620079867,"timestamp":"2024-06-01T17:52:17.599040Z"}]}
{"channel":"book","type":"update","data":[{"symbol":"LINK/EUR","bids":[],"asks":[{"price":17.14199,"qty":0.00000000},{"price":17.14313,"qty":1077.02371910}],"checksum":3164200703,"timestamp":"2024-06-01T17:52:17.599077Z"}]}
{"channel":"book","type":"update","data":[{"symbol":"LINK/EUR","bids":[],"asks":[{"price":17.13908,"qty":0.00000000},{"price":17.14563,"qty":200.00000000}],"checksum":1632544296,"timestamp":"2024-06-01T17:52:17.600761Z"}]}
{"channel":"book","type":"update","data":[{"symbol":"LINK/EUR","bids":[],"asks":[{"price":17.13895,"qty":155.60854051}],"checksum":3537477436,"timestamp":"2024-06-01T17:52:17.601578Z"}]}
{"channel":"book","type":"update","data":[{"symbol":"LINK/EUR","bids":[],"asks":[{"price":17.13907,"qty":41.28640368}],"checksum":3716799711,"timestamp":"2024-06-01T17:52:17.717159Z"}]}
{"channel":"book","type":"update","data":[{"symbol":"LINK/EUR","bids":[],"asks":[{"price":17.13892,"qty":40.00000000}],"checksum":4171264383,"timestamp":"2024-06-01T17:52:17.721955Z"}]}
{"channel":"book","type":"update","data":[{"symbol":"LINK/EUR","bids":[],"asks":[{"price":17.13894,"qty":200.00000000}],"checksum":361282194,"timestamp":"2024-06-01T17:52:17.722232Z"}]}
{"channel":"book","type":"update","data":[{"symbol":"LINK/EUR","bids":[],"asks":[{"price":17.14206,"qty":0.00000000},{"price":17.14217,"qty":243.48672997}],"checksum":2958424888,"timestamp":"2024-06-01T17:52:17.777861Z"}]}
{"channel":"book","type":"update","data":[{"symbol":"LINK/EUR","bids":[],"asks":[{"price":17.14193,"qty":4.25703693}],"checksum":1641606185,"timestamp":"2024-06-01T17:52:17.778046Z"}]}
{"channel":"book","type":"update","data":[{"symbol":"LINK/EUR","bids":[],"asks":[{"price":17.13925,"qty":0.00000000},{"price":17.14217,"qty":243.48672997}],"checksum":2469216136,"timestamp":"2024-06-01T17:52:17.837240Z"}]}
{"channel":"book","type":"update","data":[{"symbol":"LINK/EUR","bids":[],"asks":[{"price":17.14192,"qty":0.00000000},{"price":17.14313,"qty":1077.02371910}],"checksum":3306190037,"timestamp":"2024-06-01T17:52:17.938740Z"}]}
{"channel":"book","type":"update","data":[{"symbol":"LINK/EUR","bids":[],"asks":[{"price":17.14188,"qty":200.00000000}],"checksum":3633184265,"timestamp":"2024-06-01T17:52:17.957959Z"}]}
{"channel":"book","type":"update","data":[{"symbol":"LINK/EUR","bids":[],"asks":[{"price":17.13892,"qty":0.00000000},{"price":17.14313,"qty":1077.02371910}],"checksum":2424351889,"timestamp":"2024-06-01T17:52:18.093528Z"}]}
{"channel":"book","type":"update","data":[{"symbol":"LINK/EUR","bids":[],"asks":[{"price":17.13891,"qty":40.00000000}],"checksum":3376731642,"timestamp":"2024-06-01T17:52:18.093768Z"}]}
{"channel":"book","type":"update","data":[{"symbol":"LINK/EUR","bids":[],"asks":[{"price":17.14189,"qty":0.00000000},{"price":17.14313,"qty":1077.02371910}],"checksum":611901950,"timestamp":"2024-06-01T17:52:18.099232Z"}]}
{"channel":"book","type":"update","data":[{"symbol":"LINK/EUR","bids":[{"price":17.12650,"qty":0.00000000},{"price":17.12328,"qty":76.91670677}],"asks":[],"checksum":2746058647,"timestamp":"2024-06-01T17:52:18.102787Z"}]}
{"channel":"book","type":"update","data":[{"symbol":"LINK/EUR","bids":[{"price":17.12651,"qty":467.47688400}],"asks":[],"checksum":432606498,"timestamp":"2024-06-01T17:52:18.105470Z"}]}
{"channel":"book","type":"update","data":[{"symbol":"LINK/EUR","bids":[{"price":17.12878,"qty":0.00000000},{"price":17.12328,"qty":76.91670677}],"asks":[],"checksum":1688780528,"timestamp":"2024-06-01T17:52:18.270708Z"}]}
{"channel":"book","type":"update","data":[{"symbol":"LINK/EUR","bids":[{"price":17.12834,"qty":134.57130041}],"asks":[],"checksum":3635854804,"timestamp":"2024-06-01T17:52:18.275227Z"}]}
{"channel":"book","type":"update","data":[{"symbol":"LINK/EUR","bids":[],"asks":[{"price":17.13889,"qty":0.95179617}],"checksum":2706040065,"timestamp":"2024-06-01T17:52:18.339685Z"}]}
{"channel":"book","type":"update","data":[{"symbol":"LINK/EUR","bids":[],"asks":[{"price":17.13872,"qty":9.69163442}],"checksum":1219083017,"timestamp":"2024-06-01T17:52:18.342560Z"}]}
{"channel":"book","type":"update","data":[{"symbol":"LINK/EUR","bids":[],"asks":[{"price":17.13890,"qty":0.00000000},{"price":17.14217,"qty":243.48672997}],"checksum":3290378838,"timestamp":"2024-06-01T17:52:18.345481Z"}]}
{"channel":"book","type":"update","data":[{"symbol":"LINK/EUR","bids":[{"price":17.12834,"qty":0.00000000},{"price":17.12328,"qty":76.91670677}],"asks":[],"checksum":2705743521,"timestamp":"2024-06-01T17:52:18.800145Z"}]}
{"channel":"book","type":"update","data":[{"symbol":"LINK/EUR","bids":[{"price":17.12872,"qty":134.56830085}],"asks":[],"checksum":3058365663,"timestamp":"2024-06-01T17:52:18.803909Z"}]}
{"channel":"book","type":"update","data":[{"symbol":"LINK/EUR","bids":[],"asks":[{"price":17.14203,"qty":0.00000000},{"price":17.14313,"qty":1077.02371910}],"checksum":4224647937,"timestamp":"2024-06-01T17:52:18.920374Z"}]}
{"channel":"book","type":"update","data":[{"symbol":"LINK/EUR","bids":[],"asks":[{"price":17.13907,"qty":20.64815915}],"checksum":2357288916,"timestamp":"2024-06-01T17:52:19.751955Z"}]}
{"channel":"book","type":"update","data":[{"symbol":"LINK/EUR","bids":[],"asks":[{"price":17.13907,"qty":0.00000000},{"price":17.14563,"qty":200.00000000}],"checksum":2354677770,"timestamp":"2024-06-01T17:52:19.873574Z"}]}
{"channel":"book","type":"update","data":[{"symbol":"LINK/EUR","bids":[],"asks":[{"price":17.14193,"qty":0.00000000},{"price":17.16375,"qty":70.52987272}],"checksum":2963987898,"timestamp":"2024-06-01T17:52:20.031082Z"}]}
{"channel":"book","type":"update","data":[{"symbol":"LINK/EUR","bids":[],"asks":[{"price":17.16374,"qty":2.12753589}],"checksum":2945083965,"timestamp":"2024-06-01T17:52:20.031915Z"}]}
{"channel":"book","type":"update","data":[{"symbol":"LINK/EUR","bids":[],"asks":[{"price":17.13871,"qty":20.63824453}],"checksum":3978401002,"timestamp":"2024-06-01T17:52:20.183432Z"}]}
{"channel":"book","type":"update","data":[{"symbol":"LINK/EUR","bids":[],"asks":[{"price":17.13894,"qty":0.00000000},{"price":17.16374,"qty":2.12753589}],"checksum":2492397136,"timestamp":"2024-06-01T17:52:20.188762Z"}]}
{"channel":"book","type":"update","data":[{"symbol":"LINK/EUR","bids":[],"asks":[{"price":17.13868,"qty":40.00000000}],"checksum":489311256,"timestamp":"2024-06-01T17:52:20.190123Z"}]}
{"channel":"book","type":"update","data":[{"symbol":"LINK/EUR","bids":[],"asks":[{"price":17.14062,"qty":200.00000000}],"checksum":1755017019,"timestamp":"2024-06-01T17:52:20.439796Z"}]}
{"channel":"book","type":"update","data":[{"symbol":"LINK/EUR","bids":[],"asks":[{"price":17.13891,"qty":0.00000000},{"price":17.14563,"qty":200.00000000}],"checksum":3961831469,"timestamp":"2024-06-01T17:52:20.593990Z"}]}
{"channel":"book","type":"update","data":[{"symbol":"LINK/EUR","bids":[],"asks":[{"price":17.13894,"qty":200.00000000}],"checksum":758443972,"timestamp":"2024-06-01T17:52:20.600402Z"}]}
{"channel":"book","type":"update","data":[{"symbol":"LINK/EUR","bids":[],"asks":[{"price":17.14217,"qty":0.00000000},{"price":17.14563,"qty":200.00000000}],"checksum":4065208150,"timestamp":"2024-06-01T17:52:20.923303Z"}]}
{"channel":"book","type":"update","data":[{"symbol":"LINK/EUR","bids":[{"price":17.12872,"qty":0.00000000},{"price":17.12328,"qty":76.91670677}],"asks":[],"checksum":2713232589,"timestamp":"2024-06-01T17:52:20.935750Z"}]}
{"channel":"book","type":"update","data":[{"symbol":"LINK/EUR","bids":[],"asks":[{"price":17.13894,"qty":0.00000000},{"price":17.16374,"qty":2.12753589}],"checksum":1139261925,"timestamp":"2024-06-01T17:52:20.940102Z"}]}
{"channel":"book","type":"update","data":[{"symbol":"LINK/EUR","bids":[{"price":17.12940,"qty":134.56291955}],"asks":[],"checksum":893500855,"timestamp":"2024-06-01T17:52:20.941434Z"}]}
{"channel":"book","type":"update","data":[{"symbol":"LINK/EUR","bids":[],"asks":[{"price":17.13894,"qty":200.00000000}],"checksum":1460776,"timestamp":"2024-06-01T17:52:20.946406Z"}]}
{"channel":"book","type":"update","data":[{"symbol":"LINK/EUR","bids":[],"asks":[{"price":17.14313,"qty":0.00000000},{"price":17.16374,"qty":2.12753589}],"checksum":287013508,"timestamp":"2024-06-01T17:52:20.976139Z"}]}
{"channel":"book","type":"update","data":[{"symbol":"LINK/EUR","bids":[],"asks":[{"price":17.16374,"qty":271.02753589}],"checksum":835198171,"timestamp":"2024-06-01T17:52:20.978934Z"}]}
{"channel":"book","type":"update","data":[{"symbol":"LINK/EUR","bids":[],"asks":[{"price":17.16373,"qty":70.52987272}],"checksum":3687831545,"timestamp":"2024-06-01T17:52:20.985048Z"}]}
{"channel":"book","type":"update","data":[{"symbol":"LINK/EUR","bids":[{"price":17.12940,"qty":0.00000000},{"price":17.12328,"qty":76.91670677}],"asks":[],"checksum":3287065575,"timestamp":"2024-06-01T17:52:21.041176Z"}]}
{"channel":"book","type":"update","data":[{"symbol":"LINK/EUR","bids":[],"asks":[{"price":17.14336,"qty":243.48672997}],"checksum":4188204157,"timestamp":"2024-06-01T17:52:21.077410Z"}]}
{"channel":"book","type":"update","data":[{"symbol":"LINK/EUR","bids":[],"asks":[{"price":17.14563,"qty":0.00000000},{"price":17.16373,"qty":70.52987272}],"checksum":733461628,"timestamp":"2024-06-01T17:52:21.124421Z"}]}
{"channel":"book","type":"update","data":[{"symbol":"LINK/EUR","bids":[],"asks":[{"price":17.13894,"qty":0.00000000},{"price":17.16374,"qty":271.02753589}],"checksum":2298937590,"timestamp":"2024-06-01T17:52:21.438154Z"}]}
{"channel":"book","type":"update","data":[{"symbol":"LINK/EUR","bids":[],"asks":[{"price":17.13894,"qty":200.00000000}],"checksum":733461628,"timestamp":"2024-06-01T17:52:21.442693Z"}]}
{"channel":"book","type":"update","data":[{"symbol":"LINK/EUR","bids":[],"asks":[{"price":17.14057,"qty":40.00000000}],"checksum":1923549794,"timestamp":"2024-06-01T17:52:21.466179Z"}]}
{"channel":"book","type":"update","data":[{"symbol":"LINK/EUR","bids":[],"asks":[{"price":17.13871,"qty":0.00000000},{"price":17.16373,"qty":70.52987272}],"checksum":3954432979,"timestamp":"2024-06-01T17:52:21.587464Z"}]}
{"channel":"book","type":"update","data":[{"symbol":"LINK/EUR","bids":[],"asks":[{"price":17.16372,"qty":268.90000000}],"checksum":1705314693,"timestamp":"2024-06-01T17:52:21.590512Z"}]}
{"channel":"book","type":"update","data":[{"symbol":"LINK/EUR","bids":[],"asks":[{"price":17.14062,"qty":0.00000000},{"price":17.16373,"qty":70.52987272}],"checksum":2354602536,"timestamp":"2024-06-01T17:52:21.593234Z"}]}
{"channel":"book","type":"update","data":[{"symbol":"LINK/EUR","bids":[],"asks":[{"price":17.13868,"qty":0.00000000},{"price":17.16374,"qty":2.12753589}],"checksum":3259071421,"timestamp":"2024-06-01T17:52:21.595012Z"}]}
{"channel":"book","type":"update","data":[{"symbol":"LINK/EUR","bids":[],"asks":[{"price":17.13891,"qty":40.00000000}],"checksum":3073387054,"timestamp":"2024-06-01T17:52:21.595093Z"}]}
{"channel":"book","type":"update","data":[{"symbol":"LINK/EUR","bids":[],"asks":[{"price":17.16373,"qty":0.00000000},{"price":17.16374,"qty":2.12753589}],"checksum":3235383189,"timestamp":"2024-06-01T17:52:21.613014Z"}]}
{"channel":"book","type":"update","data":[{"symbol":"LINK/EUR","bids":[],"asks":[{"price":17.16371,"qty":70.52987272}],"checksum":2404304331,"timestamp":"2024-06-01T17:52:21.613212Z"}]}
{"channel":"book","type":"update","data":[{"symbol":"LINK/EUR","bids":[{"price":17.12331,"qty":1.07687699}],"asks":[],"checksum":2851621643,"timestamp":"2024-06-01T17:52:21.752685Z"}]}
{"channel":"book","type":"update","data":[{"symbol":"LINK/EUR","bids":[],"asks":[{"price":17.14057,"qty":0.00000000},{"price":17.16374,"qty":2.12753589}],"checksum":1298364717,"timestamp":"2024-06-01T17:52:22.054712Z"}]}
{"channel":"book","type":"update","data":[{"symbol":"LINK/EUR","bids":[],"asks":[{"price":17.16374,"qty":0.00000000},{"price":17.16376,"qty":16.80000000}],"checksum":4237922723,"timestamp":"2024-06-01T17:52:22.272221Z"}]}
{"channel":"book","type":"update","data":[{"symbol":"LINK/EUR","bids":[],"asks":[{"price":17.16370,"qty":13.68390959}],"checksum":4234479867,"timestamp":"2024-06-01T17:52:22.274438Z"}]}
{"channel":"book","type":"update","data":[{"symbol":"LINK/EUR","bids":[],"asks":[{"price":17.16372,"qty":0.00000000},{"price":17.16376,"qty":16.80000000},{"price":17.16370,"qty":282.58390959}],"checksum":2274784800,"timestamp":"2024-06-01T17:52:22.275438Z"}]}
{"channel":"book","type":"update","data":[{"symbol":"LINK/EUR","bids":[],"asks":[{"price":17.16371,"qty":0.00000000},{"price":17.16470,"qty":47.43738600}],"checksum":4092821226,"timestamp":"2024-06-01T17:52:22.282348Z"}]}
{"channel":"book","type":"update","data":[{"symbol":"LINK/EUR","bids":[],"asks":[{"price":17.16369,"qty":70.52987272}],"checksum":257592269,"timestamp":"2024-06-01T17:52:22.282461Z"}]}
{"channel":"book","type":"update","data":[{"symbol":"LINK/EUR","bids":[],"asks":[{"price":17.14061,"qty":40.00000000}],"checksum":2808967141,"timestamp":"2024-06-01T17:52:22.452258Z"}]}
{"channel":"book","type":"update","data":[{"symbol":"LINK/EUR","bids":[{"price":17.13392,"qty":0.00000000},{"price":17.12328,"qty":76.91670677}],"asks":[],"checksum":2452933525,"timestamp":"2024-06-01T17:52:22.620830Z"}]}
{"channel":"book","type":"update","data":[{"symbol":"LINK/EUR","bids":[{"price":17.13435,"qty":70.02006900}],"asks":[],"checksum":1535064526,"timestamp":"2024-06-01T17:52:22.623577Z"}]}
{"channel":"book","type":"update","data":[{"symbol":"LINK/EUR","bids":[{"price":17.13393,"qty":0.00000000},{"price":17.12328,"qty":76.91670677},{"price":17.13341,"qty":303.70000000}],"asks":[],"checksum":1858564427,"timestamp":"2024-06-01T17:52:22.623923Z"}]}
{"channel":"book","type":"update","data":[{"symbol":"LINK/EUR","bids":[{"price":17.13434,"qty":0.00000000},{"price":17.12328,"qty":76.91670677}],"asks":[],"checksum":393073341,"timestamp":"2024-06-01T17:52:22.626423Z"}]}
{"channel":"book","type":"update","data":[{"symbol":"LINK/EUR","bids":[{"price":17.13476,"qty":21.00000000}],"asks":[],"checksum":282356203,"timestamp":"2024-06-01T17:52:22.626495Z"}]}
{"channel":"book","type":"update","data":[{"symbol":"LINK/EUR","bids":[{"price":17.12897,"qty":134.56632242}],"asks":[],"checksum":1873879857,"timestamp":"2024-06-01T17:52:22.706389Z"}]}
{"channel":"book","type":"update","data":[{"symbol":"LINK/EUR","bids":[],"asks":[{"price":17.13894,"qty":0.00000000},{"price":17.16376,"qty":16.80000000}],"checksum":756913825,"timestamp":"2024-06-01T17:52:23.331313Z"}]}
{"channel":"book","type":"update","data":[{"symbol":"LINK/EUR","bids":[],"asks":[{"price":17.16370,"qty":13.68390959},{"price":17.16368,"qty":268.90000000}],"checksum":4133864001,"timestamp":"2024-06-01T17:52:23.334341Z"}]}
{"channel":"book","type":"update","data":[{"symbol":"LINK/EUR","bids":[],"asks":[{"price":17.13891,"qty":0.00000000},{"price":17.16376,"qty":16.80000000}],"checksum":658905916,"timestamp":"2024-06-01T17:52:23.336419Z"}]}
{"channel":"book","type":"update","data":[{"symbol":"LINK/EUR","bids":[],"asks":[{"price":17.13892,"qty":40.00000000}],"checksum":1845261944,"timestamp":"2024-06-01T17:52:23.336460Z"}]}
{"channel":"book","type":"update","data":[{"symbol":"LINK/EUR","bids":[],"asks":[{"price":17.16369,"qty":0.00000000},{"price":17.16376,"qty":16.80000000}],"checksum":3353551544,"timestamp":"2024-06-01T17:52:23.346509Z"}]}
{"channel":"book","type":"update","data":[{"symbol":"LINK/EUR","bids":[],"asks":[{"price":17.16367,"qty":70.52987272}],"checksum":703041578,"timestamp":"2024-06-01T17:52:23.346743Z"}]}
{"channel":"book","type":"update","data":[{"symbol":"LINK/EUR","bids":[],"asks":[{"price":17.13889,"qty":0.00000000},{"price":17.16376,"qty":16.80000000}],"checksum":4035333309,"timestamp":"2024-06-01T17:52:23.357042Z"}]}
{"channel":"book","type":"update","data":[{"symbol":"LINK/EUR","bids":[],"asks":[{"price":17.14154,"qty":200.00000000}],"checksum":2603677852,"timestamp":"2024-06-01T17:52:23.442069Z"}]}
{"channel":"book","type":"update","data":[{"symbol":"LINK/EUR","bids":[],"asks":[{"price":17.14061,"qty":0.00000000},{"price":17.16376,"qty":16.80000000}],"checksum":2756234474,"timestamp":"2024-06-01T17:52:23.460695Z"}]}
{"channel":"book","type":"update","data":[{"symbol":"LINK/EUR","bids":[],"asks":[{"price":17.13871,"qty":0.95179617}],"checksum":3897218577,"timestamp":"2024-06-01T17:52:23.480603Z"}]}
{"channel":"book","type":"update","data":[{"symbol":"LINK/EUR","bids":[],"asks":[{"price":17.14105,"qty":40.00000000}],"checksum":3601577406,"timestamp":"2024-06-01T17:52:23.766190Z"}]}
{"channel":"book","type":"update","data":[{"symbol":"LINK/EUR","bids":[{"price":17.12331,"qty":0.00000000},{"price":17.12330,"qty":220.47746800}],"asks":[],"checksum":2362756913,"timestamp":"2024-06-01T17:52:23.851390Z"}]}
{"channel":"book","type":"update","data":[{"symbol":"LINK/EUR","bids":[],"asks":[{"price":17.16368,"qty":0.00000000},{"price":17.16370,"qty":13.68390959},{"price":17.16366,"qty":268.90000000}],"checksum":1201808163,"timestamp":"2024-06-01T17:52:23.854487Z"}]}
{"channel":"book","type":"update","data":[{"symbol":"LINK/EUR","bids":[{"price":17.12331,"qty":5.26923360}],"asks":[],"checksum":1262370886,"timestamp":"2024-06-01T17:52:23.858663Z"}]}
{"channel":"book","type":"update","data":[{"symbol":"LINK/EUR","bids":[],"asks":[{"price":17.16365,"qty":70.52987272}],"checksum":1731266741,"timestamp":"2024-06-01T17:52:23.861461Z"}]}
{"channel":"book","type":"update","data":[{"symbol":"LINK/EUR","bids":[{"price":17.12651,"qty":0.00000000},{"price":17.12330,"qty":220.47746800}],"asks":[],"checksum":336547584,"timestamp":"2024-06-01T17:52:23.987719Z"}]}
{"channel":"book","type":"update","data":[{"symbol":"LINK/EUR","bids":[{"price":17.12652,"qty":467.47688400}],"asks":[],"checksum":3882591232,"timestamp":"2024-06-01T17:52:23.990436Z"}]}
{"channel":"book","type":"update","data":[{"symbol":"LINK/EUR","bids":[{"price":17.12389,"qty":12.13924158}],"asks":[],"checksum":614501595,"timestamp":"2024-06-01T17:52:24.048200Z"}]}
{"channel":"book","type":"update","data":[{"symbol":"LINK/EUR","bids":[],"asks":[{"price":17.14335,"qty":200.00000000}],"checksum":3443573316,"timestamp":"2024-06-01T17:52:24.292383Z"}]}
{"channel":"book","type":"update","data":[{"symbol":"LINK/EUR","bids":[],"asks":[{"price":17.16364,"qty":268.90000000}],"checksum":1639326572,"timestamp":"2024-06-01T17:52:24.362383Z"}]}
{"channel":"book","type":"update","data":[{"symbol":"LINK/EUR","bids":[],"asks":[{"price":17.16363,"qty":70.52987272}],"checksum":3049207936,"timestamp":"2024-06-01T17:52:24.373514Z"}]}
{"channel":"book","type":"update","data":[{"symbol":"LINK/EUR","bids":[],"asks":[{"price":17.14188,"qty":0.00000000},{"price":17.16364,"qty":268.90000000}],"checksum":3052964883,"timestamp":"2024-06-01T17:52:24.478789Z"}]}
{"channel":"book","type":"update","data":[{"symbol":"LINK/EUR","bids":[{"price":17.13341,"qty":0.00000000},{"price":17.12331,"qty":5.26923360},{"price":17.13436,"qty":303.70000000}],"asks":[],"checksum":1113907877,"timestamp":"2024-06-01T17:52:24.510792Z"}]}
{"channel":"book","type":"update","data":[{"symbol":"LINK/EUR","bids":[{"price":17.12897,"qty":0.00000000},{"price":17.12331,"qty":5.26923360}],"asks":[],"checksum":4129291748,"timestamp":"2024-06-01T17:52:24.526270Z"}]}
{"channel":"book","type":"update","data":[{"symbol":"LINK/EUR","bids":[{"price":17.12934,"qty":134.56339492}],"asks":[],"checksum":427220512,"timestamp":"2024-06-01T17:52:24.529661Z"}]}
{"channel":"book","type":"update","data":[{"symbol":"LINK/EUR","bids":[],"asks":[{"price":17.16364,"qty":281.53264389}],"checksum":2658641461,"timestamp":"2024-06-01T17:52:24.531379Z"}]}
{"channel":"book","type":"update","data":[{"symbol":"LINK/EUR","bids":[],"asks":[{"price":17.16364,"qty":12.63264389},{"price":17.16362,"qty":268.90000000}],"checksum":197256496,"timestamp":"2024-06-01T17:52:25.205587Z"}]}
{"channel":"book","type":"update","data":[{"symbol":"LINK/EUR","bids":[],"asks":[{"price":17.16361,"qty":70.52987272}],"checksum":561886971,"timestamp":"2024-06-01T17:52:25.219658Z"}]}
{"channel":"book","type":"update","data":[{"symbol":"LINK/EUR","bids":[],"asks":[{"price":17.16362,"qty":0.00000000},{"price":17.16364,"qty":12.63264389},{"price":17.16360,"qty":268.90000000}],"checksum":826203963,"timestamp":"2024-06-01T17:52:25.969952Z"}]}
{"channel":"book","type":"update","data":[{"symbol":"LINK/EUR","bids":[],"asks":[{"price":17.16361,"qty":0.00000000},{"price":17.16364,"qty":12.63264389}],"checksum":1076976067,"timestamp":"2024-06-01T17:52:25.978774Z"}]}
{"channel":"book","type":"update","data":[{"symbol":"LINK/EUR","bids":[],"asks":[{"price":17.16359,"qty":70.52987272}],"checksum":3602376523,"timestamp":"2024-06-01T17:52:25.978939Z"}]}
{"channel":"book","type":"update","data":[{"symbol":"LINK/EUR","bids":[],"asks":[{"price":17.16360,"qty":0.00000000},{"price":17.16364,"qty":12.63264389},{"price":17.16358,"qty":268.90000000}],"checksum":115213052,"timestamp":"2024-06-01T17:52:26.499333Z"}]}
{"channel":"book","type":"update","data":[{"symbol":"LINK/EUR","bids":[],"asks":[{"price":17.16359,"qty":0.00000000},{"price":17.16364,"qty":12.63264389}],"checksum":3285475138,"timestamp":"2024-06-01T17:52:26.520248Z"}]}
{"channel":"book","type":"update","data":[{"symbol":"LINK/EUR","bids":[],"asks":[{"price":17.16357,"qty":70.52987272}],"checksum":2184969743,"timestamp":"2024-06-01T17:52:26.520442Z"}]}
{"channel":"book","type":"update","data":[{"symbol":"LINK/EUR","bids":[],"asks":[{"price":17.16356,"qty":13.68354149}],"checksum":1355001268,"timestamp":"2024-06-01T17:52:26.832488Z"}]}
{"channel":"book","type":"update","data":[{"symbol":"LINK/EUR","bids":[],"asks":[{"price":17.16356,"qty":282.58354149}],"checksum":3488506094,"timestamp":"2024-06-01T17:52:27.382448Z"}]}
{"channel":"book","type":"update","data":[{"symbol":"LINK/EUR","bids":[],"asks":[{"price":17.16357,"qty":0.00000000},{"price":17.16376,"qty":16.80000000}],"checksum":973610867,"timestamp":"2024-06-01T17:52:27.385984Z"}]}
{"channel":"book","type":"update","data":[{"symbol":"LINK/EUR","bids":[],"asks":[{"price":17.16355,"qty":70.52987272}],"checksum":4275075472,"timestamp":"2024-06-01T17:52:27.386292Z"}]}
{"channel":"book","type":"update","data":[{"symbol":"LINK/EUR","bids":[],"asks":[{"price":17.16356,"qty":13.68354149},{"price":17.16354,"qty":268.90000000}],"checksum":2564595398,"timestamp":"2024-06-01T17:52:28.142968Z"}]}
{"channel":"book","type":"update","data":[{"symbol":"LINK/EUR","bids":[],"asks":[{"price":17.16355,"qty":0.00000000},{"price":17.16356,"qty":13.68354149}],"checksum":1773744229,"timestamp":"2024-06-01T17:52:28.165289Z"}]}
{"channel":"book","type":"update","data":[{"symbol":"LINK/EUR","bids":[],"asks":[{"price":17.16353,"qty":70.52987272}],"checksum":4063047609,"timestamp":"2024-06-01T17:52:28.165638Z"}]}
{"channel":"book","type":"update","data":[{"symbol":"LINK/EUR","bids":[{"price":17.12519,"qty":269.23420180}],"asks":[],"checksum":2623822543,"timestamp":"2024-06-01T17:52:28.352665Z"}]}
{"channel":"book","type":"update","data":[{"symbol":"LINK/EUR","bids":[{"price":17.13435,"qty":0.00000000},{"price":17.12389,"qty":12.13924158}],"asks":[],"checksum":2878001252,"timestamp":"2024-06-01T17:52:28.529465Z"}]}
{"channel":"book","type":"update","data":[{"symbol":"LINK/EUR","bids":[{"price":17.13436,"qty":0.00000000},{"price":17.12331,"qty":3.51486592},{"price":17.13341,"qty":303.70000000}],"asks":[],"checksum":2139623456,"timestamp":"2024-06-01T17:52:28.531980Z"}]}
{"channel":"book","type":"update","data":[{"symbol":"LINK/EUR","bids":[{"price":17.13477,"qty":70.02006900}],"asks":[],"checksum":1549033316,"timestamp":"2024-06-01T17:52:28.532288Z"}]}
{"channel":"book","type":"update","data":[{"symbol":"LINK/EUR","bids":[{"price":17.13476,"qty":0.00000000},{"price":17.12389,"qty":12.13924158}],"asks":[],"checksum":2715201425,"timestamp":"2024-06-01T17:52:28.534659Z"}]}
{"channel":"book","type":"update","data":[{"symbol":"LINK/EUR","bids":[{"price":17.13382,"qty":21.00000000}],"asks":[],"checksum":1320959033,"timestamp":"2024-06-01T17:52:28.534804Z"}]}
{"channel":"book","type":"update","data":[{"symbol":"LINK/EUR","bids":[{"price":17.13382,"qty":0.00000000},{"price":17.12389,"qty":12.13924158}],"asks":[],"checksum":2715201425,"timestamp":"2024-06-01T17:52:28.534850Z"}]}
{"channel":"book","type":"update","data":[{"symbol":"LINK/EUR","bids":[{"price":17.13499,"qty":21.00000000}],"asks":[],"checksum":1771380591,"timestamp":"2024-06-01T17:52:28.534925Z"}]}
{"channel":"book","type":"update","data":[{"symbol":"LINK/EUR","bids":[],"asks":[{"price":17.16352,"qty":13.71637142}],"checksum":2527086608,"timestamp":"2024-06-01T17:52:29.081713Z"}]}
{"channel":"book","type":"update","data":[{"symbol":"LINK/EUR","bids":[],"asks":[{"price":17.16352,"qty":282.61637142}],"checksum":4102351922,"timestamp":"2024-06-01T17:52:29.084025Z"}]}
{"channel":"book","type":"update","data":[{"symbol":"LINK/EUR","bids":[],"asks":[{"price":17.16351,"qty":70.52987272}],"checksum":3139716542,"timestamp":"2024-06-01T17:52:29.107047Z"}]}
{"channel":"book","type":"update","data":[{"symbol":"LINK/EUR","bids":[{"price":17.12652,"qty":0.00000000},{"price":17.12389,"qty":12.13924158}],"asks":[],"checksum":3385110509,"timestamp":"2024-06-01T17:52:29.873034Z"}]}
{"channel":"book","type":"update","data":[{"symbol":"LINK/EUR","bids":[{"price":17.12653,"qty":467.47688400}],"asks":[],"checksum":2257955170,"timestamp":"2024-06-01T17:52:29.875803Z"}]}
{"channel":"book","type":"update","data":[{"symbol":"LINK/EUR","bids":[],"asks":[{"price":17.16352,"qty":13.71637142},{"price":17.16350,"qty":268.90000000}],"checksum":1616192906,"timestamp":"2024-06-01T17:52:29.876409Z"}]}
{"channel":"book","type":"update","data":[{"symbol":"LINK/EUR","bids":[],"asks":[{"price":17.16351,"qty":0.00000000},{"price":17.16352,"qty":13.71637142}],"checksum":812067147,"timestamp":"2024-06-01T17:52:29.884258Z"}]}
{"channel":"book","type":"update","data":[{"symbol":"LINK/EUR","bids":[],"asks":[{"price":17.16349,"qty":70.52987272}],"checksum":4208566193,"timestamp":"2024-06-01T17:52:29.884364Z"}]}
{"channel":"book","type":"update","data":[{"symbol":"LINK/EUR","bids":[],"asks":[{"price":17.14105,"qty":0.00000000},{"price":17.16352,"qty":13.71637142}],"checksum":2438080638,"timestamp":"2024-06-01T17:52:30.390936Z"}]}
{"channel":"book","type":"update","data":[{"symbol":"LINK/EUR","bids":[],"asks":[{"price":17.16350,"qty":0.00000000},{"price":17.16376,"qty":16.80000000},{"price":17.16348,"qty":268.90000000}],"checksum":2341036246,"timestamp":"2024-06-01T17:52:30.394026Z"}]}
{"channel":"book","type":"update","data":[{"symbol":"LINK/EUR","bids":[],"asks":[{"price":17.16347,"qty":70.52987272}],"checksum":1131150060,"timestamp":"2024-06-01T17:52:30.397871Z"}]}
{"channel":"book","type":"update","data":[{"symbol":"LINK/EUR","bids":[],"asks":[{"price":17.16349,"qty":0.00000000},{"price":17.16352,"qty":13.71637142}],"checksum":3724032062,"timestamp":"2024-06-01T17:52:30.398042Z"}]}
{"channel":"book","type":"update","data":[{"symbol":"LINK/EUR","bids":[],"asks":[{"price":17.14104,"qty":40.00000000}],"checksum":1152652295,"timestamp":"2024-06-01T17:52:30.704211Z"}]}
{"channel":"book","type":"update","data":[{"symbol":"LINK/EUR","bids":[{"price":17.12934,"qty":0.00000000},{"price":17.12389,"qty":12.13924158}],"asks":[],"checksum":3981929392,"timestamp":"2024-06-01T17:52:30.795085Z"}]}
{"channel":"book","type":"update","data":[{"symbol":"LINK/EUR","bids":[{"price":17.12984,"qty":134.55949246}],"asks":[],"checksum":3328738691,"timestamp":"2024-06-01T17:52:30.801855Z"}]}
{"channel":"book","type":"update","data":[{"symbol":"LINK/EUR","bids":[],"asks":[{"price":17.13871,"qty":0.00000000},{"price":17.16352,"qty":13.71637142}],"checksum":3261746010,"timestamp":"2024-06-01T17:52:30.819606Z"}]}
{"channel":"book","type":"update","data":[{"symbol":"LINK/EUR","bids":[],"asks":[{"price":17.13871,"qty":0.95179617}],"checksum":3328738691,"timestamp":"2024-06-01T17:52:30.942253Z"}]}
{"channel":"book","type":"update","data":[{"symbol":"LINK/EUR","bids":[],"asks":[{"price":17.16348,"qty":0.00000000},{"price":17.16352,"qty":13.71637142},{"price":17.16346,"qty":268.90000000}],"checksum":1877406006,"timestamp":"2024-06-01T17:52:30.945217Z"}]}
{"channel":"book","type":"update","data":[{"symbol":"LINK/EUR","bids":[],"asks":[{"price":17.16347,"qty":0.00000000},{"price":17.16352,"qty":13.71637142}],"checksum":1724420146,"timestamp":"2024-06-01T17:52:30.955628Z"}]}
{"channel":"book","type":"update","data":[{"symbol":"LINK/EUR","bids":[],"asks":[{"price":17.16345,"qty":70.52987272}],"checksum":1250442818,"timestamp":"2024-06-01T17:52:30.955800Z"}]}
{"channel":"book","type":"update","data":[{"symbol":"LINK/EUR","bids":[{"price":17.12519,"qty":0.00000000},{"price":17.12512,"qty":76.82758129}],"asks":[],"checksum":3321347404,"timestamp":"2024-06-01T17:52:30.996274Z"}]}
{"channel":"book","type":"update","data":[{"symbol":"LINK/EUR","bids":[{"price":17.12984,"qty":0.00000000},{"price":17.12389,"qty":12.13924158}],"asks":[],"checksum":1172389799,"timestamp":"2024-06-01T17:52:30.998545Z"}]}
{"channel":"book","type":"update","data":[{"symbol":"LINK/EUR","bids":[{"price":17.12512,"qty":0.00000000},{"price":17.12330,"qty":220.47746800}],"asks":[],"checksum":2183727028,"timestamp":"2024-06-01T17:52:31.002455Z"}]}
{"channel":"book","type":"update","data":[{"symbol":"LINK/EUR","bids":[],"asks":[{"price":17.14104,"qty":0.00000000},{"price":17.16352,"qty":13.71637142}],"checksum":1104295877,"timestamp":"2024-06-01T17:52:31.003292Z"}]}
{"channel":"book","type":"update","data":[{"symbol":"LINK/EUR","bids":[{"price":17.12873,"qty":0.00000000},{"price":17.12295,"qty":269.22723838}],"asks":[],"checksum":3830945756,"timestamp":"2024-06-01T17:52:31.003847Z"}]}
{"channel":"book","type":"update","data":[{"symbol":"LINK/EUR","bids":[{"price":17.13477,"qty":0.00000000},{"price":17.12219,"qty":70.02006900}],"asks":[],"checksum":1786146285,"timestamp":"2024-06-01T17:52:31.007057Z"}]}
{"channel":"book","type":"update","data":[{"symbol":"LINK/EUR","bids":[{"price":17.13340,"qty":0.00000000},{"price":17.12184,"qty":269.27331468}],"asks":[],"checksum":89324302,"timestamp":"2024-06-01T17:52:31.007515Z"}]}
{"channel":"book","type":"update","data":[{"symbol":"LINK/EUR","bids":[{"price":17.13342,"qty":70.02006900}],"asks":[],"checksum":3495889185,"timestamp":"2024-06-01T17:52:31.010198Z"}]}
{"channel":"book","type":"update","data":[{"symbol":"LINK/EUR","bids":[{"price":17.13050,"qty":47.43738600}],"asks":[],"checksum":487359987,"timestamp":"2024-06-01T17:52:31.010866Z"}]}
{"channel":"book","type":"update","data":[{"symbol":"LINK/EUR","bids":[{"price":17.13341,"qty":0.00000000},{"price":17.12219,"qty":70.02006900}],"asks":[],"checksum":231720660,"timestamp":"2024-06-01T17:52:31.013472Z"}]}
{"channel":"book","type":"update","data":[{"symbol":"LINK/EUR","bids":[{"price":17.12328,"qty":63.35550526}],"asks":[],"checksum":2688624584,"timestamp":"2024-06-01T17:52:31.013974Z"}]}
{"channel":"book","type":"update","data":[{"symbol":"LINK/EUR","bids":[],"asks":[{"price":17.14152,"qty":243.48672997}],"checksum":3254175114,"timestamp":"2024-06-01T17:52:31.014004Z"}]}
{"channel":"book","type":"update","data":[{"symbol":"LINK/EUR","bids":[{"price":17.13499,"qty":0.00000000},{"price":17.12219,"qty":70.02006900}],"asks":[],"checksum":3797013830,"timestamp":"2024-06-01T17:52:31.014309Z"}]}
{"channel":"book","type":"update","data":[{"symbol":"LINK/EUR","bids":[{"price":17.13382,"qty":21.00000000}],"asks":[],"checksum":3049068154,"timestamp":"2024-06-01T17:52:31.014588Z"}]}
{"channel":"book","type":"update","data":[{"symbol":"LINK/EUR","bids":[],"asks":[{"price":17.13872,"qty":0.00000000},{"price":17.16352,"qty":13.71637142}],"checksum":2911223820,"timestamp":"2024-06-01T17:52:31.015693Z"}]}
{"channel":"book","type":"update","data":[{"symbol":"LINK/EUR","bids":[],"asks":[{"price":17.13869,"qty":9.69151527}],"checksum":1753088098,"timestamp":"2024-06-01T17:52:31.015770Z"}]}
{"channel":"book","type":"update","data":[{"symbol":"LINK/EUR","bids":[{"price":17.12389,"qty":0.00000000},{"price":17.12219,"qty":70.02006900}],"asks":[],"checksum":819700941,"timestamp":"2024-06-01T17:52:31.016037Z"}]}
{"channel":"book","type":"update","data":[{"symbol":"LINK/EUR","bids":[{"price":17.12330,"qty":0.00000000},{"price":17.12184,"qty":269.27331468}],"asks":[],"checksum":3646753611,"timestamp":"2024-06-01T17:52:31.031984Z"}]}
{"channel":"book","type":"update","data":[{"symbol":"LINK/EUR","bids":[{"price":17.12653,"qty":0.00000000},{"price":17.12110,"qty":152.64984900}],"asks":[],"checksum":2178570601,"timestamp":"2024-06-01T17:52:31.033398Z"}]}
{"channel":"book","type":"update","data":[{"symbol":"LINK/EUR","bids":[{"price":17.13119,"qty":303.70000000}],"asks":[],"checksum":294353546,"timestamp":"2024-06-01T17:52:31.033629Z"}]}
{"channel":"book","type":"update","data":[{"symbol":"LINK/EUR","bids":[{"price":17.12184,"qty":0.00000000},{"price":17.12110,"qty":152.64984900}],"asks":[],"checksum":1643528711,"timestamp":"2024-06-01T17:52:31.033729Z"}]}
{"channel":"book","type":"update","data":[{"symbol":"LINK/EUR","bids":[{"price":17.13382,"qty":0.00000000},{"price":17.12034,"qty":13.00000000}],"asks":[],"checksum":4028249874,"timestamp":"2024-06-01T17:52:31.037154Z"}]}
{"channel":"book","type":"update","data":[{"symbol":"LINK/EUR","bids":[{"price":17.12390,"qty":467.47688400}],"asks":[],"checksum":4016944137,"timestamp":"2024-06-01T17:52:31.041919Z"}]}
{"channel":"book","type":"update","data":[{"symbol":"LINK/EUR","bids":[{"price":17.12295,"qty":0.00000000},{"price":17.12034,"qty":13.00000000}],"asks":[],"checksum":1283814990,"timestamp":"2024-06-01T17:52:31.044336Z"}]}
{"channel":"book","type":"update","data":[{"symbol":"LINK/EUR","bids":[{"price":17.12328,"qty":0.00000000},{"price":17.11911,"qty":26.89000000}],"asks":[],"checksum":3961060854,"timestamp":"2024-06-01T17:52:31.069912Z"}]}
{"channel":"book","type":"update","data":[{"symbol":"LINK/EUR","bids":[],"asks":[{"price":17.13894,"qty":200.00000000}],"checksum":4037382858,"timestamp":"2024-06-01T17:52:31.070403Z"}]}
{"channel":"book","type":"update","data":[{"symbol":"LINK/EUR","bids":[],"asks":[{"price":17.14336,"qty":0.00000000},{"price":17.16346,"qty":268.90000000}],"checksum":3043435464,"timestamp":"2024-06-01T17:52:31.089578Z"}]}
{"channel":"book","type":"update","data":[{"symbol":"LINK/EUR","bids":[{"price":17.12236,"qty":44.62800139}],"asks":[],"checksum":3569242520,"timestamp":"2024-06-01T17:52:31.095576Z"}]}
{"channel":"book","type":"update","data":[{"symbol":"LINK/EUR","bids":[{"price":17.13119,"qty":0.00000000},{"price":17.11911,"qty":26.89000000}],"asks":[],"checksum":1331292864,"timestamp":"2024-06-01T17:52:31.098260Z"}]}
{"channel":"book","type":"update","data":[{"symbol":"LINK/EUR","bids":[],"asks":[{"price":17.13891,"qty":40.00000000}],"checksum":2300368055,"timestamp":"2024-06-01T17:52:31.105428Z"}]}
{"channel":"book","type":"update","data":[{"symbol":"LINK/EUR","bids":[{"price":17.11911,"qty":0.00000000},{"price":17.11910,"qty":161.46000000}],"asks":[],"checksum":4150679812,"timestamp":"2024-06-01T17:52:31.121871Z"}]}
{"channel":"book","type":"update","data":[{"symbol":"LINK/EUR","bids":[],"asks":[{"price":17.13891,"qty":283.48672997}],"checksum":726382625,"timestamp":"2024-06-01T17:52:31.126187Z"}]}
{"channel":"book","type":"update","data":[{"symbol":"LINK/EUR","bids":[],"asks":[{"price":17.14154,"qty":0.00000000},{"price":17.16346,"qty":268.90000000}],"checksum":1507974373,"timestamp":"2024-06-01T17:52:31.137936Z"}]}
{"channel":"book","type":"update","data":[{"symbol":"LINK/EUR","bids":[{"price":17.12054,"qty":12.14161688}],"asks":[],"checksum":147629906,"timestamp":"2024-06-01T17:52:31.138291Z"}]}
{"channel":"book","type":"update","data":[{"symbol":"LINK/EUR","bids":[],"asks":[{"price":17.13892,"qty":0.00000000},{"price":17.16352,"qty":13.71637142}],"checksum":820208487,"timestamp":"2024-06-01T17:52:31.142510Z"}]}
{"channel":"book","type":"update","data":[{"symbol":"LINK/EUR","bids":[{"price":17.12236,"qty":0.00000000},{"price":17.11910,"qty":161.46000000}],"asks":[],"checksum":1478196949,"timestamp":"2024-06-01T17:52:31.148867Z"}]}
{"channel":"book","type":"update","data":[{"symbol":"LINK/EUR","bids":[{"price":17.12054,"qty":0.00000000},{"price":17.11880,"qty":269.29245531}],"asks":[],"checksum":4043952727,"timestamp":"2024-06-01T17:52:31.155888Z"}]}
{"channel":"book","type":"update","data":[{"symbol":"LINK/EUR","bids":[{"price":17.13050,"qty":0.00000000},{"price":17.11550,"qty":220.47746800}],"asks":[],"checksum":3915492875,"timestamp":"2024-06-01T17:52:31.156400Z"}]}
{"channel":"book","type":"update","data":[{"symbol":"LINK/EUR","bids":[{"price":17.11867,"qty":39.72798589}],"asks":[],"checksum":2652252153,"timestamp":"2024-06-01T17:52:31.156619Z"}]}
{"channel":"book","type":"update","data":[{"symbol":"LINK/EUR","bids":[],"asks":[{"price":17.14152,"qty":0.00000000},{"price":17.16376,"qty":16.80000000}],"checksum":488105646,"timestamp":"2024-06-01T17:52:31.159580Z"}]}
{"channel":"book","type":"update","data":[{"symbol":"LINK/EUR","bids":[],"asks":[{"price":17.13871,"qty":0.00000000},{"price":17.16470,"qty":47.43738600}],"checksum":1665488684,"timestamp":"2024-06-01T17:52:31.161023Z"}]}
{"channel":"book","type":"update","data":[{"symbol":"LINK/EUR","bids":[],"asks":[{"price":17.16470,"qty":0.00000000},{"price":17.16696,"qty":28.85000000}],"checksum":802659570,"timestamp":"2024-06-01T17:52:31.161566Z"}]}
{"channel":"book","type":"update","data":[{"symbol":"LINK/EUR","bids":[],"asks":[{"price":17.14153,"qty":200.00000000}],"checksum":29614590,"timestamp":"2024-06-01T17:52:31.163427Z"}]}
{"channel":"book","type":"update","data":[{"symbol":"LINK/EUR","bids":[],"asks":[{"price":17.15920,"qty":47.43738600}],"checksum":91984475,"timestamp":"2024-06-01T17:52:31.168963Z"}]}
{"channel":"book","type":"update","data":[{"symbol":"LINK/EUR","bids":[{"price":17.13342,"qty":0.00000000},{"price":17.11550,"qty":220.47746800}],"asks":[],"checksum":1942642818,"timestamp":"2024-06-01T17:52:31.172671Z"}]}
{"channel":"book","type":"update","data":[{"symbol":"LINK/EUR","bids":[{"price":17.12780,"qty":47.43738600}],"asks":[],"checksum":1941373961,"timestamp":"2024-06-01T17:52:31.173035Z"}]}
{"channel":"book","type":"update","data":[{"symbol":"LINK/EUR","bids":[],"asks":[{"price":17.13870,"qty":20.64852295}],"checksum":207314143,"timestamp":"2024-06-01T17:52:31.182758Z"}]}
{"channel":"book","type":"update","data":[{"symbol":"LINK/EUR","bids":[{"price":17.13051,"qty":70.02006900}],"asks":[],"checksum":2029539714,"timestamp":"2024-06-01T17:52:31.182994Z"}]}
{"channel":"book","type":"update","data":[{"symbol":"LINK/EUR","bids":[{"price":17.12822,"qty":21.00000000}],"asks":[],"checksum":2206224829,"timestamp":"2024-06-01T17:52:31.195813Z"}]}
{"channel":"book","type":"update","data":[{"symbol":"LINK/EUR","bids":[{"price":17.12592,"qty":21.00000000}],"asks":[],"checksum":2496750214,"timestamp":"2024-06-01T17:52:31.196053Z"}]}
{"channel":"book","type":"update","data":[{"symbol":"LINK/EUR","bids":[{"price":17.12592,"qty":0.00000000},{"price":17.11910,"qty":161.46000000}],"asks":[],"checksum":2206224829,"timestamp":"2024-06-01T17:52:31.200947Z"}]}
{"channel":"book","type":"update","data":[{"symbol":"LINK/EUR","bids":[],"asks":[{"price":17.13868,"qty":20.64921310}],"checksum":147914136,"timestamp":"2024-06-01T17:52:31.228727Z"}]}
{"channel":"book","type":"update","data":[{"symbol":"LINK/EUR","bids":[],"asks":[{"price":17.13851,"qty":9.69443171}],"checksum":1918501186,"timestamp":"2024-06-01T17:52:31.250445Z"}]}
{"channel":"book","type":"update","data":[{"symbol":"LINK/EUR","bids":[],"asks":[{"price":17.13867,"qty":40.00000000}],"checksum":3934560528,"timestamp":"2024-06-01T17:52:31.251529Z"}]}
{"channel":"book","type":"update","data":[{"symbol":"LINK/EUR","bids":[],"asks":[{"price":17.13869,"qty":253.17824524}],"checksum":123610739,"timestamp":"2024-06-01T17:52:31.252546Z"}]}
{"channel":"book","type":"update","data":[{"symbol":"LINK/EUR","bids":[{"price":17.12219,"qty":0.00000000},{"price":17.11880,"qty":269.29245531}],"asks":[],"checksum":105444967,"timestamp":"2024-06-01T17:52:31.254532Z"}]}
{"channel":"book","type":"update","data":[{"symbol":"LINK/EUR","bids":[],"asks":[{"price":17.13869,"qty":243.48672997}],"checksum":3353245077,"timestamp":"2024-06-01T17:52:31.262948Z"}]}
{"channel":"book","type":"update","data":[{"symbol":"LINK/EUR","bids":[],"asks":[{"price":17.13865,"qty":40.00000000}],"checksum":917065623,"timestamp":"2024-06-01T17:52:31.287133Z"}]}
{"channel":"book","type":"update","data":[{"symbol":"LINK/EUR","bids":[],"asks":[{"price":17.13867,"qty":0.00000000},{"price":17.14335,"qty":200.00000000}],"checksum":4279777635,"timestamp":"2024-06-01T17:52:31.287172Z"}]}
{"channel":"book","type":"update","data":[{"symbol":"LINK/EUR","bids":[],"asks":[{"price":17.13869,"qty":0.00000000},{"price":17.15920,"qty":47.43738600}],"checksum":975705313,"timestamp":"2024-06-01T17:52:31.302364Z"}]}
{"channel":"book","type":"update","data":[{"symbol":"LINK/EUR","bids":[{"price":17.11880,"qty":0.00000000},{"price":17.11867,"qty":39.72798589}],"asks":[],"checksum":631461820,"timestamp":"2024-06-01T17:52:31.307516Z"}]}
{"channel":"book","type":"update","data":[{"symbol":"LINK/EUR","bids":[{"price":17.12341,"qty":134.61000281}],"asks":[],"checksum":2575661241,"timestamp":"2024-06-01T17:52:31.315926Z"}]}
{"channel":"book","type":"update","data":[{"symbol":"LINK/EUR","bids":[],"asks":[{"price":17.13891,"qty":243.48672997}],"checksum":3294066977,"timestamp":"2024-06-01T17:52:31.322390Z"}]}
{"channel":"book","type":"update","data":[{"symbol":"LINK/EUR","bids":[{"price":17.12341,"qty":0.00000000},{"price":17.11867,"qty":39.72798589}],"asks":[],"checksum":2679754054,"timestamp":"2024-06-01T17:52:31.322846Z"}]}
{"channel":"book","type":"update","data":[{"symbol":"LINK/EUR","bids":[],"asks":[{"price":17.13890,"qty":200.00000000}],"checksum":1524163646,"timestamp":"2024-06-01T17:52:31.348979Z"}]}
{"channel":"book","type":"update","data":[{"symbol":"LINK/EUR","bids":[],"asks":[{"price":17.13864,"qty":243.48672997}],"checksum":2651616260,"timestamp":"2024-06-01T17:52:31.354052Z"}]}
{"channel":"book","type":"update","data":[{"symbol":"LINK/EUR","bids":[],"asks":[{"price":17.13894,"qty":0.00000000},{"price":17.14285,"qty":1076.93680721}],"checksum":1701801881,"timestamp":"2024-06-01T17:52:31.389236Z"}]}
{"channel":"book","type":"update","data":[{"symbol":"LINK/EUR","bids":[],"asks":[{"price":17.13868,"qty":60.64921310}],"checksum":4242254511,"timestamp":"2024-06-01T17:52:31.391269Z"}]}
{"channel":"book","type":"update","data":[{"symbol":"LINK/EUR","bids":[],"asks":[{"price":17.13891,"qty":0.00000000},{"price":17.14335,"qty":200.00000000}],"checksum":3892563919,"timestamp":"2024-06-01T17:52:31.394732Z"}]}
{"channel":"book","type":"update","data":[{"symbol":"LINK/EUR","bids":[],"asks":[{"price":17.14335,"qty":0.00000000},{"price":17.15920,"qty":47.43738600}],"checksum":2919572404,"timestamp":"2024-06-01T17:52:31.407894Z"}]}
