{"channel":"book","type":"snapshot","data":[{"symbol":"LINK/BTC","bids":[{"price":0.00027460,"qty":459.20875000},{"price":0.00027458,"qty":8.60949764},{"price":0.00027455,"qty":26.92732028},{"price":0.00027450,"qty":5.20000000},{"price":0.00027449,"qty":10.71026548},{"price":0.00027448,"qty":915.42645000},{"price":0.00027447,"qty":26.93093198},{"price":0.00027446,"qty":149.84610000},{"price":0.00027443,"qty":26.94149689},{"price":0.00027442,"qty":200.00000000}],"asks":[{"price":0.00027468,"qty":200.00000000},{"price":0.00027472,"qty":200.00000000},{"price":0.00027476,"qty":8.07205850},{"price":0.00027481,"qty":205.20000000},{"price":0.00027486,"qty":8.06917892},{"price":0.00027507,"qty":8.06396514},{"price":0.00027518,"qty":9.04368050},{"price":0.00027519,"qty":40.00000000},{"price":0.00027523,"qty":88.51378950},{"price":0.00027527,"qty":80.15256053}],"checksum":3483631494}]}
{"channel":"book","type":"update","data":[{"symbol":"LINK/BTC","bids":[],"asks":[{"price":0.00027518,"qty":0.00000000},{"price":0.00027533,"qty":65.49203379}],"checksum":3995179223,"timestamp":"2024-06-01T17:51:55.808241Z"}]}
{"channel":"book","type":"update","data":[{"symbol":"LINK/BTC","bids":[],"asks":[{"price":0.00027518,"qty":9.04357148}],"checksum":601179408,"timestamp":"2024-06-01T17:51:55.808392Z"}]}
{"channel":"book","type":"update","data":[{"symbol":"LINK/BTC","bids":[{"price":0.00027449,"qty":0.00000000},{"price":0.00027440,"qty":217.68605000}],"asks":[],"checksum":2525745408,"timestamp":"2024-06-01T17:51:56.284499Z"}]}
{"channel":"book","type":"update","data":[{"symbol":"LINK/BTC","bids":[{"price":0.00027449,"qty":12.93256341}],"asks":[],"checksum":984383622,"timestamp":"2024-06-01T17:51:56.287507Z"}]}
{"channel":"book","type":"update","data":[{"symbol":"LINK/BTC","bids":[],"asks":[{"price":0.00027471,"qty":200.00000000}],"checksum":281394711,"timestamp":"2024-06-01T17:51:56.720658Z"}]}
{"channel":"book","type":"update","data":[{"symbol":"LINK/BTC","bids":[],"asks":[{"price":0.00027468,"qty":0.00000000},{"price":0.00027527,"qty":80.15256053}],"checksum":124277461,"timestamp":"2024-06-01T17:51:56.913985Z"}]}
{"channel":"book","type":"update","data":[{"symbol":"LINK/BTC","bids":[],"asks":[{"price":0.00027471,"qty":205.20000000}],"checksum":4158124058,"timestamp":"2024-06-01T17:51:56.916818Z"}]}
{"channel":"book","type":"update","data":[{"symbol":"LINK/BTC","bids":[],"asks":[{"price":0.00027470,"qty":200.00000000}],"checksum":260477975,"timestamp":"2024-06-01T17:51:56.919380Z"}]}
{"channel":"book","type":"update","data":[{"symbol":"LINK/BTC","bids":[],"asks":[{"price":0.00027518,"qty":0.00000000},{"price":0.00027527,"qty":80.15256053}],"checksum":2973883459,"timestamp":"2024-06-01T17:51:57.092127Z"}]}
{"channel":"book","type":"update","data":[{"symbol":"LINK/BTC","bids":[],"asks":[{"price":0.00027518,"qty":9.04353514}],"checksum":1210515310,"timestamp":"2024-06-01T17:51:57.092248Z"}]}
{"channel":"book","type":"update","data":[{"symbol":"LINK/BTC","bids":[],"asks":[{"price":0.00027472,"qty":0.00000000},{"price":0.00027527,"qty":80.15256053}],"checksum":1886118881,"timestamp":"2024-06-01T17:51:57.422459Z"}]}
{"channel":"book","type":"update","data":[{"symbol":"LINK/BTC","bids":[],"asks":[{"price":0.00027476,"qty":0.00000000},{"price":0.00027533,"qty":65.49203379}],"checksum":709856610,"timestamp":"2024-06-01T17:51:57.862009Z"}]}
{"channel":"book","type":"update","data":[{"symbol":"LINK/BTC","bids":[],"asks":[{"price":0.00027474,"qty":8.07232850}],"checksum":2456546499,"timestamp":"2024-06-01T17:51:57.866583Z"}]}
{"channel":"book","type":"update","data":[{"symbol":"LINK/BTC","bids":[{"price":0.00027449,"qty":0.00000000},{"price":0.00027440,"qty":217.68605000}],"asks":[],"checksum":2425725811,"timestamp":"2024-06-01T17:51:58.561596Z"}]}
{"channel":"book","type":"update","data":[{"symbol":"LINK/BTC","bids":[{"price":0.00027449,"qty":9.22851427}],"asks":[],"checksum":2293795701,"timestamp":"2024-06-01T17:51:58.564006Z"}]}
{"channel":"book","type":"update","data":[{"symbol":"LINK/BTC","bids":[],"asks":[{"price":0.00027469,"qty":200.00000000}],"checksum":3632902394,"timestamp":"2024-06-01T17:51:58.907934Z"}]}
{"channel":"book","type":"update","data":[{"symbol":"LINK/BTC","bids":[],"asks":[{"price":0.00027471,"qty":5.20000000}],"checksum":185289352,"timestamp":"2024-06-01T17:51:59.085089Z"}]}
{"channel":"book","type":"update","data":[{"symbol":"LINK/BTC","bids":[{"price":0.00027460,"qty":0.00000000},{"price":0.00027440,"qty":217.68605000}],"asks":[],"checksum":1442623387,"timestamp":"2024-06-01T17:52:00.437496Z"}]}
{"channel":"book","type":"update","data":[{"symbol":"LINK/BTC","bids":[],"asks":[{"price":0.00027471,"qty":0.00000000},{"price":0.00027527,"qty":80.15256053}],"checksum":4174013182,"timestamp":"2024-06-01T17:52:00.440086Z"}]}
{"channel":"book","type":"update","data":[{"symbol":"LINK/BTC","bids":[],"asks":[{"price":0.00027468,"qty":5.20000000}],"checksum":1030497635,"timestamp":"2024-06-01T17:52:00.440230Z"}]}
{"channel":"book","type":"update","data":[{"symbol":"LINK/BTC","bids":[{"price":0.00027461,"qty":459.20875000}],"asks":[],"checksum":3063472054,"timestamp":"2024-06-01T17:52:00.440439Z"}]}
{"channel":"book","type":"update","data":[{"symbol":"LINK/BTC","bids":[],"asks":[{"price":0.00027468,"qty":0.00000000},{"price":0.00027527,"qty":80.15256053}],"checksum":1933482027,"timestamp":"2024-06-01T17:52:00.443030Z"}]}
{"channel":"book","type":"update","data":[{"symbol":"LINK/BTC","bids":[{"price":0.00027449,"qty":0.00000000},{"price":0.00027440,"qty":217.68605000}],"asks":[],"checksum":806578673,"timestamp":"2024-06-01T17:52:00.811302Z"}]}
{"channel":"book","type":"update","data":[{"symbol":"LINK/BTC","bids":[{"price":0.00027449,"qty":8.48706234}],"asks":[],"checksum":3884881839,"timestamp":"2024-06-01T17:52:00.816826Z"}]}
{"channel":"book","type":"update","data":[{"symbol":"LINK/BTC","bids":[],"asks":[{"price":0.00027470,"qty":0.00000000},{"price":0.00027533,"qty":65.49203379}],"checksum":3522914821,"timestamp":"2024-06-01T17:52:02.406045Z"}]}
{"channel":"book","type":"update","data":[{"symbol":"LINK/BTC","bids":[],"asks":[{"price":0.00027474,"qty":0.00000000},{"price":0.00027542,"qty":92.02000000}],"checksum":3272043084,"timestamp":"2024-06-01T17:52:02.434472Z"}]}
{"channel":"book","type":"update","data":[{"symbol":"LINK/BTC","bids":[{"price":0.00027455,"qty":0.00000000},{"price":0.00027440,"qty":217.68605000}],"asks":[],"checksum":3909879961,"timestamp":"2024-06-01T17:52:02.434482Z"}]}
{"channel":"book","type":"update","data":[{"symbol":"LINK/BTC","bids":[{"price":0.00027458,"qty":35.53108070}],"asks":[],"checksum":1336775969,"timestamp":"2024-06-01T17:52:02.439187Z"}]}
{"channel":"book","type":"update","data":[{"symbol":"LINK/BTC","bids":[{"price":0.00027445,"qty":200.00000000}],"asks":[],"checksum":714872018,"timestamp":"2024-06-01T17:52:02.443711Z"}]}
{"channel":"book","type":"update","data":[{"symbol":"LINK/BTC","bids":[],"asks":[{"price":0.00027469,"qty":0.00000000},{"price":0.00027553,"qty":6.32946671}],"checksum":4237643036,"timestamp":"2024-06-01T17:52:02.569053Z"}]}
{"channel":"book","type":"update","data":[{"symbol":"LINK/BTC","bids":[{"price":0.00027450,"qty":0.00000000},{"price":0.00027440,"qty":217.68605000}],"asks":[],"checksum":2745515804,"timestamp":"2024-06-01T17:52:02.571802Z"}]}
{"channel":"book","type":"update","data":[{"symbol":"LINK/BTC","bids":[],"asks":[{"price":0.00027480,"qty":5.20000000}],"checksum":3972400561,"timestamp":"2024-06-01T17:52:02.571829Z"}]}
{"channel":"book","type":"update","data":[{"symbol":"LINK/BTC","bids":[],"asks":[{"price":0.00027480,"qty":10.04429889}],"checksum":4181185324,"timestamp":"2024-06-01T17:52:02.571958Z"}]}
{"channel":"book","type":"update","data":[{"symbol":"LINK/BTC","bids":[{"price":0.00027462,"qty":5.20000000}],"asks":[],"checksum":4065131995,"timestamp":"2024-06-01T17:52:02.572034Z"}]}
{"channel":"book","type":"update","data":[{"symbol":"LINK/BTC","bids":[{"price":0.00027461,"qty":0.00000000},{"price":0.00027440,"qty":217.68605000}],"asks":[],"checksum":51064831,"timestamp":"2024-06-01T17:52:02.572228Z"}]}
{"channel":"book","type":"update","data":[{"symbol":"LINK/BTC","bids":[{"price":0.00027442,"qty":0.00000000},{"price":0.00027431,"qty":26.95047772}],"asks":[],"checksum":998791025,"timestamp":"2024-06-01T17:52:02.573342Z"}]}
{"channel":"book","type":"update","data":[{"symbol":"LINK/BTC","bids":[],"asks":[{"price":0.00027480,"qty":210.04429889}],"checksum":878757098,"timestamp":"2024-06-01T17:52:02.573582Z"}]}
{"channel":"book","type":"update","data":[{"symbol":"LINK/BTC","bids":[{"price":0.00027462,"qty":464.40875000}],"asks":[],"checksum":1167739622,"timestamp":"2024-06-01T17:52:02.575245Z"}]}
{"channel":"book","type":"update","data":[{"symbol":"LINK/BTC","bids":[{"price":0.00027462,"qty":459.20875000}],"asks":[],"checksum":1796841708,"timestamp":"2024-06-01T17:52:02.576332Z"}]}
{"channel":"book","type":"update","data":[{"symbol":"LINK/BTC","bids":[{"price":0.00027450,"qty":5.20000000}],"asks":[],"checksum":953396653,"timestamp":"2024-06-01T17:52:02.576344Z"}]}
{"channel":"book","type":"update","data":[{"symbol":"LINK/BTC","bids":[{"price":0.00027450,"qty":0.00000000},{"price":0.00027431,"qty":26.95047772}],"asks":[],"checksum":1796841708,"timestamp":"2024-06-01T17:52:02.577924Z"}]}
{"channel":"book","type":"update","data":[{"symbol":"LINK/BTC","bids":[{"price":0.00027459,"qty":5.20000000}],"asks":[],"checksum":277222758,"timestamp":"2024-06-01T17:52:02.578161Z"}]}
{"channel":"book","type":"update","data":[{"symbol":"LINK/BTC","bids":[],"asks":[{"price":0.00027485,"qty":46.97477950}],"checksum":145316421,"timestamp":"2024-06-01T17:52:02.673872Z"}]}
{"channel":"book","type":"update","data":[{"symbol":"LINK/BTC","bids":[],"asks":[{"price":0.00027484,"qty":31.70462817}],"checksum":3090773266,"timestamp":"2024-06-01T17:52:02.804194Z"}]}
{"channel":"book","type":"update","data":[{"symbol":"LINK/BTC","bids":[],"asks":[{"price":0.00027478,"qty":200.00000000}],"checksum":227219626,"timestamp":"2024-06-01T17:52:02.817056Z"}]}
{"channel":"book","type":"update","data":[{"symbol":"LINK/BTC","bids":[],"asks":[{"price":0.00027480,"qty":204.84429889}],"checksum":2482341175,"timestamp":"2024-06-01T17:52:02.819835Z"}]}
{"channel":"book","type":"update","data":[{"symbol":"LINK/BTC","bids":[],"asks":[{"price":0.00027477,"qty":5.20000000}],"checksum":3144675430,"timestamp":"2024-06-01T17:52:02.820297Z"}]}
{"channel":"book","type":"update","data":[{"symbol":"LINK/BTC","bids":[],"asks":[{"price":0.00027477,"qty":10.04443910}],"checksum":1587646464,"timestamp":"2024-06-01T17:52:02.821393Z"}]}
{"channel":"book","type":"update","data":[{"symbol":"LINK/BTC","bids":[],"asks":[{"price":0.00027480,"qty":200.00000000}],"checksum":3954491562,"timestamp":"2024-06-01T17:52:02.822940Z"}]}
{"channel":"book","type":"update","data":[{"symbol":"LINK/BTC","bids":[],"asks":[{"price":0.00027481,"qty":0.00000000},{"price":0.00027523,"qty":88.51378950}],"checksum":5575088,"timestamp":"2024-06-01T17:52:02.869060Z"}]}
{"channel":"book","type":"update","data":[{"symbol":"LINK/BTC","bids":[],"asks":[{"price":0.00027476,"qty":200.00000000}],"checksum":1546272088,"timestamp":"2024-06-01T17:52:02.873333Z"}]}
{"channel":"book","type":"update","data":[{"symbol":"LINK/BTC","bids":[],"asks":[{"price":0.00027477,"qty":4.84443910}],"checksum":2689734885,"timestamp":"2024-06-01T17:52:02.876103Z"}]}
{"channel":"book","type":"update","data":[{"symbol":"LINK/BTC","bids":[],"asks":[{"price":0.00027475,"qty":4.84446826}],"checksum":1890455794,"timestamp":"2024-06-01T17:52:02.876279Z"}]}
{"channel":"book","type":"update","data":[{"symbol":"LINK/BTC","bids":[],"asks":[{"price":0.00027475,"qty":10.04446826}],"checksum":2604023808,"timestamp":"2024-06-01T17:52:02.876433Z"}]}
{"channel":"book","type":"update","data":[{"symbol":"LINK/BTC","bids":[],"asks":[{"price":0.00027477,"qty":0.00000000},{"price":0.00027519,"qty":40.00000000}],"checksum":3835488783,"timestamp":"2024-06-01T17:52:02.878938Z"}]}
{"channel":"book","type":"update","data":[{"symbol":"LINK/BTC","bids":[],"asks":[{"price":0.00027474,"qty":200.00000000}],"checksum":3703038879,"timestamp":"2024-06-01T17:52:02.922360Z"}]}
{"channel":"book","type":"update","data":[{"symbol":"LINK/BTC","bids":[],"asks":[{"price":0.00027480,"qty":0.00000000},{"price":0.00027519,"qty":40.00000000}],"checksum":3631135582,"timestamp":"2024-06-01T17:52:02.922392Z"}]}
{"channel":"book","type":"update","data":[{"symbol":"LINK/BTC","bids":[],"asks":[{"price":0.00027474,"qty":204.84458262}],"checksum":761936079,"timestamp":"2024-06-01T17:52:02.925347Z"}]}
{"channel":"book","type":"update","data":[{"symbol":"LINK/BTC","bids":[],"asks":[{"price":0.00027475,"qty":5.20000000}],"checksum":2100816810,"timestamp":"2024-06-01T17:52:02.925534Z"}]}
{"channel":"book","type":"update","data":[{"symbol":"LINK/BTC","bids":[],"asks":[{"price":0.00027476,"qty":0.00000000},{"price":0.00027523,"qty":88.51378950}],"checksum":346976102,"timestamp":"2024-06-01T17:52:02.926780Z"}]}
{"channel":"book","type":"update","data":[{"symbol":"LINK/BTC","bids":[{"price":0.00027449,"qty":0.00000000},{"price":0.00027431,"qty":26.95047772}],"asks":[],"checksum":862035665,"timestamp":"2024-06-01T17:52:02.970259Z"}]}
{"channel":"book","type":"update","data":[{"symbol":"LINK/BTC","bids":[{"price":0.00027449,"qty":15.15397105}],"asks":[],"checksum":2036781968,"timestamp":"2024-06-01T17:52:02.975293Z"}]}
{"channel":"book","type":"update","data":[{"symbol":"LINK/BTC","bids":[],"asks":[{"price":0.00027481,"qty":200.00000000}],"checksum":2706032672,"timestamp":"2024-06-01T17:52:03.180840Z"}]}
{"channel":"book","type":"update","data":[{"symbol":"LINK/BTC","bids":[],"asks":[{"price":0.00027477,"qty":8.07123511}],"checksum":2441660184,"timestamp":"2024-06-01T17:52:04.924403Z"}]}
{"channel":"book","type":"update","data":[{"symbol":"LINK/BTC","bids":[],"asks":[{"price":0.00027475,"qty":0.00000000},{"price":0.00027519,"qty":40.00000000}],"checksum":1636956931,"timestamp":"2024-06-01T17:52:04.986597Z"}]}
{"channel":"book","type":"update","data":[{"symbol":"LINK/BTC","bids":[],"asks":[{"price":0.00027473,"qty":5.20000000}],"checksum":3196265557,"timestamp":"2024-06-01T17:52:04.986905Z"}]}
{"channel":"book","type":"update","data":[{"symbol":"LINK/BTC","bids":[],"asks":[{"price":0.00027472,"qty":4.84474022}],"checksum":3596325351,"timestamp":"2024-06-01T17:52:04.989709Z"}]}
{"channel":"book","type":"update","data":[{"symbol":"LINK/BTC","bids":[],"asks":[{"price":0.00027474,"qty":200.00000000}],"checksum":3306729477,"timestamp":"2024-06-01T17:52:04.992771Z"}]}
{"channel":"book","type":"update","data":[{"symbol":"LINK/BTC","bids":[{"price":0.00027449,"qty":0.00000000},{"price":0.00027431,"qty":26.95047772}],"asks":[],"checksum":2401238340,"timestamp":"2024-06-01T17:52:05.141349Z"}]}
{"channel":"book","type":"update","data":[{"symbol":"LINK/BTC","bids":[{"price":0.00027449,"qty":13.67298312}],"asks":[],"checksum":18177095,"timestamp":"2024-06-01T17:52:05.148365Z"}]}
{"channel":"book","type":"update","data":[{"symbol":"LINK/BTC","bids":[],"asks":[{"price":0.00027477,"qty":0.00000000},{"price":0.00027518,"qty":9.04353514}],"checksum":1899176871,"timestamp":"2024-06-01T17:52:05.307224Z"}]}
{"channel":"book","type":"update","data":[{"symbol":"LINK/BTC","bids":[],"asks":[{"price":0.00027472,"qty":204.84474022}],"checksum":1303703671,"timestamp":"2024-06-01T17:52:05.311714Z"}]}
{"channel":"book","type":"update","data":[{"symbol":"LINK/BTC","bids":[],"asks":[{"price":0.00027472,"qty":404.84474022}],"checksum":1482285832,"timestamp":"2024-06-01T17:52:05.315171Z"}]}
{"channel":"book","type":"update","data":[{"symbol":"LINK/BTC","bids":[{"price":0.00027445,"qty":0.00000000},{"price":0.00027431,"qty":26.95047772}],"asks":[],"checksum":1969794065,"timestamp":"2024-06-01T17:52:05.414030Z"}]}
{"channel":"book","type":"update","data":[{"symbol":"LINK/BTC","bids":[],"asks":[{"price":0.00027474,"qty":0.00000000},{"price":0.00027519,"qty":40.00000000}],"checksum":3344386396,"timestamp":"2024-06-01T17:52:05.421798Z"}]}
{"channel":"book","type":"update","data":[{"symbol":"LINK/BTC","bids":[],"asks":[{"price":0.00027473,"qty":0.00000000},{"price":0.00027523,"qty":88.51378950}],"checksum":3603406901,"timestamp":"2024-06-01T17:52:05.424940Z"}]}
{"channel":"book","type":"update","data":[{"symbol":"LINK/BTC","bids":[],"asks":[{"price":0.00027472,"qty":410.04474022}],"checksum":1556301126,"timestamp":"2024-06-01T17:52:05.428593Z"}]}
{"channel":"book","type":"update","data":[{"symbol":"LINK/BTC","bids":[{"price":0.00027458,"qty":8.60949764}],"asks":[],"checksum":696625551,"timestamp":"2024-06-01T17:52:05.450365Z"}]}
{"channel":"book","type":"update","data":[{"symbol":"LINK/BTC","bids":[{"price":0.00027455,"qty":26.92275119}],"asks":[],"checksum":80421910,"timestamp":"2024-06-01T17:52:05.453390Z"}]}
{"channel":"book","type":"update","data":[{"symbol":"LINK/BTC","bids":[],"asks":[{"price":0.00027478,"qty":0.00000000},{"price":0.00027527,"qty":80.15256053}],"checksum":594780441,"timestamp":"2024-06-01T17:52:05.497344Z"}]}
{"channel":"book","type":"update","data":[{"symbol":"LINK/BTC","bids":[{"price":0.00027441,"qty":200.00000000}],"asks":[],"checksum":661831502,"timestamp":"2024-06-01T17:52:05.922929Z"}]}
{"channel":"book","type":"update","data":[{"symbol":"LINK/BTC","bids":[{"price":0.00027462,"qty":0.00000000},{"price":0.00027440,"qty":217.68605000}],"asks":[],"checksum":48450202,"timestamp":"2024-06-01T17:52:06.322016Z"}]}
{"channel":"book","type":"update","data":[{"symbol":"LINK/BTC","bids":[],"asks":[{"price":0.00027472,"qty":404.84474022}],"checksum":1166246468,"timestamp":"2024-06-01T17:52:06.324792Z"}]}
{"channel":"book","type":"update","data":[{"symbol":"LINK/BTC","bids":[{"price":0.00027459,"qty":0.00000000},{"price":0.00027431,"qty":26.95047772}],"asks":[],"checksum":1743796873,"timestamp":"2024-06-01T17:52:06.324807Z"}]}
{"channel":"book","type":"update","data":[{"symbol":"LINK/BTC","bids":[{"price":0.00027463,"qty":459.20875000}],"asks":[],"checksum":3866444138,"timestamp":"2024-06-01T17:52:06.324906Z"}]}
{"channel":"book","type":"update","data":[{"symbol":"LINK/BTC","bids":[],"asks":[{"price":0.00027471,"qty":5.20000000}],"checksum":2472215033,"timestamp":"2024-06-01T17:52:06.325014Z"}]}
{"channel":"book","type":"update","data":[{"symbol":"LINK/BTC","bids":[{"price":0.00027450,"qty":5.20000000}],"asks":[],"checksum":1911941795,"timestamp":"2024-06-01T17:52:06.325118Z"}]}
{"channel":"book","type":"update","data":[{"symbol":"LINK/BTC","bids":[],"asks":[{"price":0.00027472,"qty":400.00000000}],"checksum":745494338,"timestamp":"2024-06-01T17:52:06.328057Z"}]}
{"channel":"book","type":"update","data":[{"symbol":"LINK/BTC","bids":[],"asks":[{"price":0.00027471,"qty":10.04510527}],"checksum":3769357392,"timestamp":"2024-06-01T17:52:06.328090Z"}]}
{"channel":"book","type":"update","data":[{"symbol":"LINK/BTC","bids":[],"asks":[{"price":0.00027470,"qty":200.00000000}],"checksum":3100436685,"timestamp":"2024-06-01T17:52:06.422380Z"}]}
{"channel":"book","type":"update","data":[{"symbol":"LINK/BTC","bids":[{"price":0.00027463,"qty":0.00000000},{"price":0.00027440,"qty":217.68605000}],"asks":[],"checksum":94149001,"timestamp":"2024-06-01T17:52:06.425993Z"}]}
{"channel":"book","type":"update","data":[{"symbol":"LINK/BTC","bids":[],"asks":[{"price":0.00027472,"qty":200.00000000}],"checksum":1247739002,"timestamp":"2024-06-01T17:52:06.427401Z"}]}
{"channel":"book","type":"update","data":[{"symbol":"LINK/BTC","bids":[{"price":0.00027464,"qty":459.20875000}],"asks":[],"checksum":1883288761,"timestamp":"2024-06-01T17:52:06.428645Z"}]}
{"channel":"book","type":"update","data":[{"symbol":"LINK/BTC","bids":[],"asks":[{"price":0.00027471,"qty":4.84510527}],"checksum":1828319071,"timestamp":"2024-06-01T17:52:06.428736Z"}]}
{"channel":"book","type":"update","data":[{"symbol":"LINK/BTC","bids":[],"asks":[{"price":0.00027469,"qty":5.20000000}],"checksum":2949103872,"timestamp":"2024-06-01T17:52:06.428881Z"}]}
{"channel":"book","type":"update","data":[{"symbol":"LINK/BTC","bids":[],"asks":[{"price":0.00027469,"qty":0.00000000},{"price":0.00027519,"qty":40.00000000}],"checksum":1828319071,"timestamp":"2024-06-01T17:52:06.431375Z"}]}
{"channel":"book","type":"update","data":[{"symbol":"LINK/BTC","bids":[{"price":0.00027455,"qty":0.00000000},{"price":0.00027440,"qty":217.68605000}],"asks":[],"checksum":1378622824,"timestamp":"2024-06-01T17:52:06.558456Z"}]}
{"channel":"book","type":"update","data":[{"symbol":"LINK/BTC","bids":[],"asks":[{"price":0.00027471,"qty":12.91769128}],"checksum":2064002126,"timestamp":"2024-06-01T17:52:06.561651Z"}]}
{"channel":"book","type":"update","data":[{"symbol":"LINK/BTC","bids":[],"asks":[{"price":0.00027470,"qty":204.84527773}],"checksum":3918856486,"timestamp":"2024-06-01T17:52:06.573604Z"}]}
{"channel":"book","type":"update","data":[{"symbol":"LINK/BTC","bids":[],"asks":[{"price":0.00027471,"qty":8.07258601}],"checksum":2264126083,"timestamp":"2024-06-01T17:52:06.573902Z"}]}
{"channel":"book","type":"update","data":[{"symbol":"LINK/BTC","bids":[{"price":0.00027458,"qty":0.00000000},{"price":0.00027431,"qty":26.95047772}],"asks":[],"checksum":2124986724,"timestamp":"2024-06-01T17:52:06.580626Z"}]}
{"channel":"book","type":"update","data":[{"symbol":"LINK/BTC","bids":[],"asks":[{"price":0.00027507,"qty":0.00000000},{"price":0.00027523,"qty":88.51378950}],"checksum":667378807,"timestamp":"2024-06-01T17:52:06.757799Z"}]}
{"channel":"book","type":"update","data":[{"symbol":"LINK/BTC","bids":[{"price":0.00027449,"qty":0.00000000},{"price":0.00027426,"qty":91.15437905}],"asks":[],"checksum":3290618471,"timestamp":"2024-06-01T17:52:07.344387Z"}]}
{"channel":"book","type":"update","data":[{"symbol":"LINK/BTC","bids":[],"asks":[{"price":0.00027518,"qty":0.00000000},{"price":0.00027527,"qty":80.15256053}],"checksum":1525077956,"timestamp":"2024-06-01T17:52:07.588302Z"}]}
{"channel":"book","type":"update","data":[{"symbol":"LINK/BTC","bids":[],"asks":[{"price":0.00027518,"qty":56.95552000}],"checksum":1289655770,"timestamp":"2024-06-01T17:52:07.588418Z"}]}
{"channel":"book","type":"update","data":[{"symbol":"LINK/BTC","bids":[],"asks":[{"price":0.00027471,"qty":0.00000000},{"price":0.00027527,"qty":80.15256053}],"checksum":1669026468,"timestamp":"2024-06-01T17:52:07.758452Z"}]}
{"channel":"book","type":"update","data":[{"symbol":"LINK/BTC","bids":[{"price":0.00027452,"qty":26.92594311}],"asks":[],"checksum":3771911140,"timestamp":"2024-06-01T17:52:07.762603Z"}]}
{"channel":"book","type":"update","data":[{"symbol":"LINK/BTC","bids":[],"asks":[{"price":0.00027495,"qty":8.06542260}],"checksum":659046804,"timestamp":"2024-06-01T17:52:07.762620Z"}]}
{"channel":"book","type":"update","data":[{"symbol":"LINK/BTC","bids":[],"asks":[{"price":0.00027471,"qty":200.00000000}],"checksum":3381966625,"timestamp":"2024-06-01T17:52:07.763958Z"}]}
{"channel":"book","type":"update","data":[{"symbol":"LINK/BTC","bids":[],"asks":[{"price":0.00027470,"qty":4.84527773}],"checksum":1220222296,"timestamp":"2024-06-01T17:52:07.764059Z"}]}
{"channel":"book","type":"update","data":[{"symbol":"LINK/BTC","bids":[],"asks":[{"price":0.00027471,"qty":205.20000000}],"checksum":3874597284,"timestamp":"2024-06-01T17:52:07.766950Z"}]}
{"channel":"book","type":"update","data":[{"symbol":"LINK/BTC","bids":[],"asks":[{"price":0.00027469,"qty":200.00000000}],"checksum":2506041461,"timestamp":"2024-06-01T17:52:07.798948Z"}]}
{"channel":"book","type":"update","data":[{"symbol":"LINK/BTC","bids":[],"asks":[{"price":0.00027468,"qty":4.84591942}],"checksum":2462313357,"timestamp":"2024-06-01T17:52:07.801690Z"}]}
{"channel":"book","type":"update","data":[{"symbol":"LINK/BTC","bids":[],"asks":[{"price":0.00027468,"qty":204.84591942}],"checksum":3220154712,"timestamp":"2024-06-01T17:52:07.803338Z"}]}
{"channel":"book","type":"update","data":[{"symbol":"LINK/BTC","bids":[],"asks":[{"price":0.00027470,"qty":0.00000000},{"price":0.00027518,"qty":56.95552000}],"checksum":3955336916,"timestamp":"2024-06-01T17:52:07.804920Z"}]}
{"channel":"book","type":"update","data":[{"symbol":"LINK/BTC","bids":[],"asks":[{"price":0.00027471,"qty":5.20000000}],"checksum":3973472253,"timestamp":"2024-06-01T17:52:07.921293Z"}]}
{"channel":"book","type":"update","data":[{"symbol":"LINK/BTC","bids":[],"asks":[{"price":0.00027518,"qty":0.00000000},{"price":0.00027519,"qty":40.00000000}],"checksum":269159044,"timestamp":"2024-06-01T17:52:08.200052Z"}]}
{"channel":"book","type":"update","data":[{"symbol":"LINK/BTC","bids":[],"asks":[{"price":0.00027518,"qty":23.95566536}],"checksum":513519219,"timestamp":"2024-06-01T17:52:08.200097Z"}]}
{"channel":"book","type":"update","data":[{"symbol":"LINK/BTC","bids":[],"asks":[{"price":0.00027472,"qty":0.00000000},{"price":0.00027519,"qty":40.00000000}],"checksum":1538026816,"timestamp":"2024-06-01T17:52:08.336496Z"}]}
{"channel":"book","type":"update","data":[{"symbol":"LINK/BTC","bids":[],"asks":[{"price":0.00027471,"qty":0.00000000},{"price":0.00027523,"qty":88.51378950}],"checksum":1083288672,"timestamp":"2024-06-01T17:52:08.339182Z"}]}
{"channel":"book","type":"update","data":[{"symbol":"LINK/BTC","bids":[],"asks":[{"price":0.00027468,"qty":4.84591942}],"checksum":1849488543,"timestamp":"2024-06-01T17:52:08.341209Z"}]}
{"channel":"book","type":"update","data":[{"symbol":"LINK/BTC","bids":[],"asks":[{"price":0.00027471,"qty":200.00000000}],"checksum":3980226242,"timestamp":"2024-06-01T17:52:08.341220Z"}]}
{"channel":"book","type":"update","data":[{"symbol":"LINK/BTC","bids":[],"asks":[{"price":0.00027469,"qty":208.07317245}],"checksum":1998919545,"timestamp":"2024-06-01T17:52:08.923441Z"}]}
{"channel":"book","type":"update","data":[{"symbol":"LINK/BTC","bids":[{"price":0.00027449,"qty":1.81798445}],"asks":[],"checksum":2178367236,"timestamp":"2024-06-01T17:52:09.599629Z"}]}
{"channel":"book","type":"update","data":[{"symbol":"LINK/BTC","bids":[],"asks":[{"price":0.00027467,"qty":200.00000000}],"checksum":3658226620,"timestamp":"2024-06-01T17:52:10.059709Z"}]}
{"channel":"book","type":"update","data":[{"symbol":"LINK/BTC","bids":[],"asks":[{"price":0.00027469,"qty":8.07317245}],"checksum":3764163081,"timestamp":"2024-06-01T17:52:10.243909Z"}]}
{"channel":"book","type":"update","data":[{"symbol":"LINK/BTC","bids":[],"asks":[{"price":0.00027467,"qty":204.84592119}],"checksum":2436557735,"timestamp":"2024-06-01T17:52:10.314968Z"}]}
{"channel":"book","type":"update","data":[{"symbol":"LINK/BTC","bids":[],"asks":[{"price":0.00027468,"qty":0.00000000},{"price":0.00027519,"qty":40.00000000}],"checksum":3744145439,"timestamp":"2024-06-01T17:52:10.528965Z"}]}
{"channel":"book","type":"update","data":[{"symbol":"LINK/BTC","bids":[{"price":0.00027441,"qty":0.00000000},{"price":0.00027431,"qty":26.95047772}],"asks":[],"checksum":2115917212,"timestamp":"2024-06-01T17:52:11.422788Z"}]}
{"channel":"book","type":"update","data":[{"symbol":"LINK/BTC","bids":[{"price":0.00027438,"qty":200.00000000}],"asks":[],"checksum":4210507338,"timestamp":"2024-06-01T17:52:11.422987Z"}]}
{"channel":"book","type":"update","data":[{"symbol":"LINK/BTC","bids":[{"price":0.00027449,"qty":0.00000000},{"price":0.00027431,"qty":26.95047772}],"asks":[],"checksum":1591809706,"timestamp":"2024-06-01T17:52:11.811216Z"}]}
{"channel":"book","type":"update","data":[{"symbol":"LINK/BTC","bids":[],"asks":[{"price":0.00027466,"qty":200.00000000}],"checksum":622182895,"timestamp":"2024-06-01T17:52:11.816518Z"}]}
{"channel":"book","type":"update","data":[{"symbol":"LINK/BTC","bids":[],"asks":[{"price":0.00027471,"qty":0.00000000},{"price":0.00027519,"qty":40.00000000}],"checksum":2256772534,"timestamp":"2024-06-01T17:52:11.920942Z"}]}
{"channel":"book","type":"update","data":[{"symbol":"LINK/BTC","bids":[{"price":0.00027464,"qty":0.00000000},{"price":0.00027426,"qty":91.15437905}],"asks":[],"checksum":2777764394,"timestamp":"2024-06-01T17:52:12.206587Z"}]}
{"channel":"book","type":"update","data":[{"symbol":"LINK/BTC","bids":[],"asks":[{"price":0.00027466,"qty":205.20000000}],"checksum":3509300176,"timestamp":"2024-06-01T17:52:12.209501Z"}]}
{"channel":"book","type":"update","data":[{"symbol":"LINK/BTC","bids":[{"price":0.00027440,"qty":0.00000000},{"price":0.00027423,"qty":0.46822733}],"asks":[],"checksum":3531330522,"timestamp":"2024-06-01T17:52:12.210011Z"}]}
{"channel":"book","type":"update","data":[{"symbol":"LINK/BTC","bids":[{"price":0.00027453,"qty":459.20875000}],"asks":[],"checksum":799456397,"timestamp":"2024-06-01T17:52:12.210052Z"}]}
{"channel":"book","type":"update","data":[{"symbol":"LINK/BTC","bids":[{"price":0.00027427,"qty":217.68605000}],"asks":[],"checksum":805330792,"timestamp":"2024-06-01T17:52:12.212843Z"}]}
{"channel":"book","type":"update","data":[{"symbol":"LINK/BTC","bids":[],"asks":[{"price":0.00027465,"qty":200.00000000}],"checksum":3564953991,"timestamp":"2024-06-01T17:52:12.249606Z"}]}
{"channel":"book","type":"update","data":[{"symbol":"LINK/BTC","bids":[],"asks":[{"price":0.00027467,"qty":4.84592119}],"checksum":3617402981,"timestamp":"2024-06-01T17:52:12.429626Z"}]}
{"channel":"book","type":"update","data":[{"symbol":"LINK/BTC","bids":[],"asks":[{"price":0.00027481,"qty":0.00000000},{"price":0.00027519,"qty":40.00000000}],"checksum":2300191354,"timestamp":"2024-06-01T17:52:13.240097Z"}]}
{"channel":"book","type":"update","data":[{"symbol":"LINK/BTC","bids":[],"asks":[{"price":0.00027473,"qty":205.20000000}],"checksum":3946684354,"timestamp":"2024-06-01T17:52:13.542771Z"}]}
{"channel":"book","type":"update","data":[{"symbol":"LINK/BTC","bids":[{"price":0.00027428,"qty":7.74477216}],"asks":[],"checksum":2058852874,"timestamp":"2024-06-01T17:52:14.055303Z"}]}
{"channel":"book","type":"update","data":[{"symbol":"LINK/BTC","bids":[],"asks":[{"price":0.00027486,"qty":0.00000000},{"price":0.00027519,"qty":40.00000000}],"checksum":4184082731,"timestamp":"2024-06-01T17:52:14.709105Z"}]}
{"channel":"book","type":"update","data":[{"symbol":"LINK/BTC","bids":[],"asks":[{"price":0.00027484,"qty":0.00000000},{"price":0.00027523,"qty":88.51378950}],"checksum":2484758146,"timestamp":"2024-06-01T17:52:15.442931Z"}]}
{"channel":"book","type":"update","data":[{"symbol":"LINK/BTC","bids":[{"price":0.00027447,"qty":0.00000000},{"price":0.00027427,"qty":217.68605000}],"asks":[],"checksum":2825675685,"timestamp":"2024-06-01T17:52:15.895965Z"}]}
{"channel":"book","type":"update","data":[{"symbol":"LINK/BTC","bids":[{"price":0.00027428,"qty":0.00000000},{"price":0.00027426,"qty":91.15437905}],"asks":[],"checksum":2248653201,"timestamp":"2024-06-01T17:52:16.205147Z"}]}
{"channel":"book","type":"update","data":[{"symbol":"LINK/BTC","bids":[{"price":0.00027438,"qty":405.20000000}],"asks":[],"checksum":2092923125,"timestamp":"2024-06-01T17:52:16.207499Z"}]}
{"channel":"book","type":"update","data":[{"symbol":"LINK/BTC","bids":[],"asks":[{"price":0.00027518,"qty":0.00000000},{"price":0.00027527,"qty":80.15256053}],"checksum":644751257,"timestamp":"2024-06-01T17:52:16.208195Z"}]}
{"channel":"book","type":"update","data":[{"symbol":"LINK/BTC","bids":[],"asks":[{"price":0.00027518,"qty":45.49138743}],"checksum":2297010900,"timestamp":"2024-06-01T17:52:16.208295Z"}]}
{"channel":"book","type":"update","data":[{"symbol":"LINK/BTC","bids":[],"asks":[{"price":0.00027518,"qty":99.98233878}],"checksum":436966416,"timestamp":"2024-06-01T17:52:16.520735Z"}]}
{"channel":"book","type":"update","data":[{"symbol":"LINK/BTC","bids":[],"asks":[{"price":0.00027518,"qty":54.49095135}],"checksum":3361267677,"timestamp":"2024-06-01T17:52:16.520811Z"}]}
{"channel":"book","type":"update","data":[{"symbol":"LINK/BTC","bids":[],"asks":[{"price":0.00027518,"qty":0.00000000},{"price":0.00027527,"qty":80.15256053}],"checksum":644751257,"timestamp":"2024-06-01T17:52:16.540609Z"}]}
{"channel":"book","type":"update","data":[{"symbol":"LINK/BTC","bids":[],"asks":[{"price":0.00027518,"qty":32.95522928}],"checksum":427348395,"timestamp":"2024-06-01T17:52:16.540770Z"}]}
{"channel":"book","type":"update","data":[{"symbol":"LINK/BTC","bids":[],"asks":[{"price":0.00027518,"qty":0.00000000},{"price":0.00027527,"qty":80.15256053}],"checksum":644751257,"timestamp":"2024-06-01T17:52:16.583909Z"}]}
{"channel":"book","type":"update","data":[{"symbol":"LINK/BTC","bids":[],"asks":[{"price":0.00027518,"qty":23.95566536}],"checksum":2092923125,"timestamp":"2024-06-01T17:52:16.583955Z"}]}
{"channel":"book","type":"update","data":[{"symbol":"LINK/BTC","bids":[],"asks":[{"price":0.00027479,"qty":8.07034657}],"checksum":982909580,"timestamp":"2024-06-01T17:52:16.924849Z"}]}
{"channel":"book","type":"update","data":[{"symbol":"LINK/BTC","bids":[],"asks":[{"price":0.00027473,"qty":0.00000000},{"price":0.00027523,"qty":88.51378950}],"checksum":2627032071,"timestamp":"2024-06-01T17:52:17.160756Z"}]}
{"channel":"book","type":"update","data":[{"symbol":"LINK/BTC","bids":[],"asks":[{"price":0.00027466,"qty":5.20000000}],"checksum":897009564,"timestamp":"2024-06-01T17:52:17.165920Z"}]}
{"channel":"book","type":"update","data":[{"symbol":"LINK/BTC","bids":[],"asks":[{"price":0.00027469,"qty":208.07317245}],"checksum":3325290585,"timestamp":"2024-06-01T17:52:17.165993Z"}]}
{"channel":"book","type":"update","data":[{"symbol":"LINK/BTC","bids":[],"asks":[{"price":0.00027474,"qty":200.00000000}],"checksum":4211480686,"timestamp":"2024-06-01T17:52:17.443488Z"}]}
{"channel":"book","type":"update","data":[{"symbol":"LINK/BTC","bids":[],"asks":[{"price":0.00027518,"qty":0.00000000},{"price":0.00027523,"qty":88.51378950}],"checksum":1660473635,"timestamp":"2024-06-01T17:52:17.612884Z"}]}
{"channel":"book","type":"update","data":[{"symbol":"LINK/BTC","bids":[],"asks":[{"price":0.00027518,"qty":45.49149645}],"checksum":1374288564,"timestamp":"2024-06-01T17:52:17.613085Z"}]}
{"channel":"book","type":"update","data":[{"symbol":"LINK/BTC","bids":[],"asks":[{"price":0.00027515,"qty":65.03905979}],"checksum":3049587796,"timestamp":"2024-06-01T17:52:17.720835Z"}]}
{"channel":"book","type":"update","data":[{"symbol":"LINK/BTC","bids":[{"price":0.00027453,"qty":0.00000000},{"price":0.00027423,"qty":0.46822733}],"asks":[],"checksum":4281995066,"timestamp":"2024-06-01T17:52:18.090785Z"}]}
{"channel":"book","type":"update","data":[{"symbol":"LINK/BTC","bids":[{"price":0.00027454,"qty":459.20875000}],"asks":[],"checksum":2650932638,"timestamp":"2024-06-01T17:52:18.093506Z"}]}
{"channel":"book","type":"update","data":[{"symbol":"LINK/BTC","bids":[],"asks":[{"price":0.00027518,"qty":69.44716181}],"checksum":216610646,"timestamp":"2024-06-01T17:52:18.274779Z"}]}
{"channel":"book","type":"update","data":[{"symbol":"LINK/BTC","bids":[],"asks":[{"price":0.00027518,"qty":23.95566536}],"checksum":131848977,"timestamp":"2024-06-01T17:52:18.274819Z"}]}
{"channel":"book","type":"update","data":[{"symbol":"LINK/BTC","bids":[],"asks":[{"price":0.00027518,"qty":0.00000000},{"price":0.00027519,"qty":40.00000000}],"checksum":155942886,"timestamp":"2024-06-01T17:52:18.290530Z"}]}
{"channel":"book","type":"update","data":[{"symbol":"LINK/BTC","bids":[],"asks":[{"price":0.00027518,"qty":45.49153279}],"checksum":2497019402,"timestamp":"2024-06-01T17:52:18.290772Z"}]}
{"channel":"book","type":"update","data":[{"symbol":"LINK/BTC","bids":[{"price":0.00027428,"qty":7.00657537}],"asks":[],"checksum":4276018542,"timestamp":"2024-06-01T17:52:18.307969Z"}]}
{"channel":"book","type":"update","data":[{"symbol":"LINK/BTC","bids":[{"price":0.00027428,"qty":0.00000000},{"price":0.00027426,"qty":91.15437905}],"asks":[],"checksum":2497019402,"timestamp":"2024-06-01T17:52:20.488675Z"}]}
{"channel":"book","type":"update","data":[{"symbol":"LINK/BTC","bids":[{"price":0.00027428,"qty":6.26531595}],"asks":[],"checksum":3799749390,"timestamp":"2024-06-01T17:52:20.493865Z"}]}
{"channel":"book","type":"update","data":[{"symbol":"LINK/BTC","bids":[],"asks":[{"price":0.00027518,"qty":69.44719815}],"checksum":3009778050,"timestamp":"2024-06-01T17:52:21.065701Z"}]}
{"channel":"book","type":"update","data":[{"symbol":"LINK/BTC","bids":[],"asks":[{"price":0.00027518,"qty":23.95566536}],"checksum":3844150659,"timestamp":"2024-06-01T17:52:21.065765Z"}]}
{"channel":"book","type":"update","data":[{"symbol":"LINK/BTC","bids":[],"asks":[{"price":0.00027518,"qty":0.00000000},{"price":0.00027519,"qty":40.00000000}],"checksum":2920140939,"timestamp":"2024-06-01T17:52:22.599098Z"}]}
{"channel":"book","type":"update","data":[{"symbol":"LINK/BTC","bids":[],"asks":[{"price":0.00027518,"qty":45.49156913}],"checksum":498981235,"timestamp":"2024-06-01T17:52:22.599301Z"}]}
{"channel":"book","type":"update","data":[{"symbol":"LINK/BTC","bids":[{"price":0.00027428,"qty":0.00000000},{"price":0.00027426,"qty":91.15437905}],"asks":[],"checksum":3130963393,"timestamp":"2024-06-01T17:52:22.623684Z"}]}
{"channel":"book","type":"update","data":[{"symbol":"LINK/BTC","bids":[{"price":0.00027428,"qty":7.40829459}],"asks":[],"checksum":1258912952,"timestamp":"2024-06-01T17:52:22.626410Z"}]}
{"channel":"book","type":"update","data":[{"symbol":"LINK/BTC","bids":[],"asks":[{"price":0.00027465,"qty":204.84565113}],"checksum":1408092028,"timestamp":"2024-06-01T17:52:23.291922Z"}]}
{"channel":"book","type":"update","data":[{"symbol":"LINK/BTC","bids":[],"asks":[{"price":0.00027467,"qty":0.00000000},{"price":0.00027519,"qty":40.00000000}],"checksum":2351184696,"timestamp":"2024-06-01T17:52:23.292693Z"}]}
{"channel":"book","type":"update","data":[{"symbol":"LINK/BTC","bids":[],"asks":[{"price":0.00027518,"qty":90.98288388}],"checksum":2951796135,"timestamp":"2024-06-01T17:52:23.305890Z"}]}
{"channel":"book","type":"update","data":[{"symbol":"LINK/BTC","bids":[],"asks":[{"price":0.00027518,"qty":45.49131475}],"checksum":3864306136,"timestamp":"2024-06-01T17:52:23.306031Z"}]}
{"channel":"book","type":"update","data":[{"symbol":"LINK/BTC","bids":[],"asks":[{"price":0.00027518,"qty":0.00000000},{"price":0.00027523,"qty":88.51378950}],"checksum":386846158,"timestamp":"2024-06-01T17:52:23.318819Z"}]}
{"channel":"book","type":"update","data":[{"symbol":"LINK/BTC","bids":[],"asks":[{"price":0.00027518,"qty":45.49127841}],"checksum":1267157082,"timestamp":"2024-06-01T17:52:23.319046Z"}]}
{"channel":"book","type":"update","data":[{"symbol":"LINK/BTC","bids":[{"price":0.00027441,"qty":200.00000000}],"asks":[],"checksum":2528229959,"timestamp":"2024-06-01T17:52:23.422649Z"}]}
{"channel":"book","type":"update","data":[{"symbol":"LINK/BTC","bids":[],"asks":[{"price":0.00027518,"qty":90.98248414}],"checksum":1891939205,"timestamp":"2024-06-01T17:52:23.484283Z"}]}
{"channel":"book","type":"update","data":[{"symbol":"LINK/BTC","bids":[],"asks":[{"price":0.00027518,"qty":45.49120573}],"checksum":3952536412,"timestamp":"2024-06-01T17:52:23.484313Z"}]}
{"channel":"book","type":"update","data":[{"symbol":"LINK/BTC","bids":[{"price":0.00027438,"qty":205.20000000}],"asks":[],"checksum":3203369548,"timestamp":"2024-06-01T17:52:23.920896Z"}]}
{"channel":"book","type":"update","data":[{"symbol":"LINK/BTC","bids":[{"price":0.00027454,"qty":0.00000000},{"price":0.00027427,"qty":217.68605000}],"asks":[],"checksum":2586333683,"timestamp":"2024-06-01T17:52:23.975795Z"}]}
{"channel":"book","type":"update","data":[{"symbol":"LINK/BTC","bids":[{"price":0.00027453,"qty":459.20875000}],"asks":[],"checksum":3451179766,"timestamp":"2024-06-01T17:52:23.978695Z"}]}
{"channel":"book","type":"update","data":[{"symbol":"LINK/BTC","bids":[{"price":0.00027428,"qty":0.00000000},{"price":0.00027427,"qty":217.68605000}],"asks":[],"checksum":2836126607,"timestamp":"2024-06-01T17:52:24.865449Z"}]}
{"channel":"book","type":"update","data":[{"symbol":"LINK/BTC","bids":[{"price":0.00027449,"qty":3.30031379}],"asks":[],"checksum":3075769220,"timestamp":"2024-06-01T17:52:24.868079Z"}]}
{"channel":"book","type":"update","data":[{"symbol":"LINK/BTC","bids":[],"asks":[{"price":0.00027518,"qty":0.00000000},{"price":0.00027523,"qty":88.51378950}],"checksum":2532988683,"timestamp":"2024-06-01T17:52:25.509204Z"}]}
{"channel":"book","type":"update","data":[{"symbol":"LINK/BTC","bids":[],"asks":[{"price":0.00027518,"qty":45.49087867}],"checksum":299716157,"timestamp":"2024-06-01T17:52:25.509506Z"}]}
{"channel":"book","type":"update","data":[{"symbol":"LINK/BTC","bids":[],"asks":[{"price":0.00027518,"qty":90.98146662}],"checksum":316404174,"timestamp":"2024-06-01T17:52:25.594372Z"}]}
{"channel":"book","type":"update","data":[{"symbol":"LINK/BTC","bids":[],"asks":[{"price":0.00027518,"qty":45.49058795}],"checksum":1646051124,"timestamp":"2024-06-01T17:52:25.594501Z"}]}
{"channel":"book","type":"update","data":[{"symbol":"LINK/BTC","bids":[],"asks":[{"price":0.00027518,"qty":0.00000000},{"price":0.00027523,"qty":88.51378950}],"checksum":2532988683,"timestamp":"2024-06-01T17:52:25.818580Z"}]}
{"channel":"book","type":"update","data":[{"symbol":"LINK/BTC","bids":[],"asks":[{"price":0.00027518,"qty":45.49055161}],"checksum":4235867444,"timestamp":"2024-06-01T17:52:25.818596Z"}]}
{"channel":"book","type":"update","data":[{"symbol":"LINK/BTC","bids":[],"asks":[{"price":0.00027518,"qty":0.00000000},{"price":0.00027523,"qty":88.51378950}],"checksum":2532988683,"timestamp":"2024-06-01T17:52:25.845794Z"}]}
{"channel":"book","type":"update","data":[{"symbol":"LINK/BTC","bids":[],"asks":[{"price":0.00027518,"qty":45.49036991}],"checksum":748898509,"timestamp":"2024-06-01T17:52:25.845996Z"}]}
{"channel":"book","type":"update","data":[{"symbol":"LINK/BTC","bids":[],"asks":[{"price":0.00027518,"qty":0.00000000},{"price":0.00027523,"qty":88.51378950}],"checksum":2532988683,"timestamp":"2024-06-01T17:52:26.104735Z"}]}
{"channel":"book","type":"update","data":[{"symbol":"LINK/BTC","bids":[],"asks":[{"price":0.00027518,"qty":45.49029723}],"checksum":1909028118,"timestamp":"2024-06-01T17:52:26.105046Z"}]}
{"channel":"book","type":"update","data":[{"symbol":"LINK/BTC","bids":[],"asks":[{"price":0.00027485,"qty":0.00000000},{"price":0.00027523,"qty":88.51378950}],"checksum":2284058386,"timestamp":"2024-06-01T17:52:27.705544Z"}]}
{"channel":"book","type":"update","data":[{"symbol":"LINK/BTC","bids":[{"price":0.00027449,"qty":0.00000000},{"price":0.00027427,"qty":217.68605000}],"asks":[],"checksum":3648552001,"timestamp":"2024-06-01T17:52:29.285490Z"}]}
{"channel":"book","type":"update","data":[{"symbol":"LINK/BTC","bids":[{"price":0.00027449,"qty":4.04159661}],"asks":[],"checksum":28110102,"timestamp":"2024-06-01T17:52:29.287812Z"}]}
{"channel":"book","type":"update","data":[{"symbol":"LINK/BTC","bids":[{"price":0.00027453,"qty":0.00000000},{"price":0.00027428,"qty":2.21921855}],"asks":[],"checksum":3067682985,"timestamp":"2024-06-01T17:52:29.860946Z"}]}
{"channel":"book","type":"update","data":[{"symbol":"LINK/BTC","bids":[],"asks":[{"price":0.00027466,"qty":0.00000000},{"price":0.00027527,"qty":80.15256053}],"checksum":330604664,"timestamp":"2024-06-01T17:52:29.863995Z"}]}
{"channel":"book","type":"update","data":[{"symbol":"LINK/BTC","bids":[],"asks":[{"price":0.00027464,"qty":5.20000000}],"checksum":1309481823,"timestamp":"2024-06-01T17:52:29.864236Z"}]}
{"channel":"book","type":"update","data":[{"symbol":"LINK/BTC","bids":[{"price":0.00027454,"qty":459.20875000}],"asks":[],"checksum":2166022759,"timestamp":"2024-06-01T17:52:29.864290Z"}]}
{"channel":"book","type":"update","data":[{"symbol":"LINK/BTC","bids":[],"asks":[{"price":0.00027463,"qty":200.00000000}],"checksum":3656649672,"timestamp":"2024-06-01T17:52:30.353462Z"}]}
{"channel":"book","type":"update","data":[{"symbol":"LINK/BTC","bids":[],"asks":[{"price":0.00027465,"qty":4.84565113}],"checksum":874934431,"timestamp":"2024-06-01T17:52:30.537320Z"}]}
{"channel":"book","type":"update","data":[{"symbol":"LINK/BTC","bids":[],"asks":[{"price":0.00027518,"qty":0.00000000},{"price":0.00027523,"qty":88.51378950}],"checksum":3541389954,"timestamp":"2024-06-01T17:52:30.808300Z"}]}
{"channel":"book","type":"update","data":[{"symbol":"LINK/BTC","bids":[],"asks":[{"price":0.00027514,"qty":9.04357781}],"checksum":1837587510,"timestamp":"2024-06-01T17:52:30.809263Z"}]}
{"channel":"book","type":"update","data":[{"symbol":"LINK/BTC","bids":[{"price":0.00027441,"qty":0.00000000},{"price":0.00027428,"qty":2.21921855}],"asks":[],"checksum":3985854313,"timestamp":"2024-06-01T17:52:31.008555Z"}]}
{"channel":"book","type":"update","data":[{"symbol":"LINK/BTC","bids":[{"price":0.00027452,"qty":0.00000000},{"price":0.00027427,"qty":217.68605000}],"asks":[],"checksum":3414760472,"timestamp":"2024-06-01T17:52:31.017750Z"}]}
{"channel":"book","type":"update","data":[{"symbol":"LINK/BTC","bids":[{"price":0.00027449,"qty":30.96919818}],"asks":[],"checksum":2946790972,"timestamp":"2024-06-01T17:52:31.027331Z"}]}
{"channel":"book","type":"update","data":[{"symbol":"LINK/BTC","bids":[{"price":0.00027448,"qty":0.00000000},{"price":0.00027426,"qty":91.15437905}],"asks":[],"checksum":3945740148,"timestamp":"2024-06-01T17:52:31.032328Z"}]}
{"channel":"book","type":"update","data":[{"symbol":"LINK/BTC","bids":[],"asks":[{"price":0.00027465,"qty":0.00000000},{"price":0.00027523,"qty":88.51378950}],"checksum":1401641775,"timestamp":"2024-06-01T17:52:31.032478Z"}]}
{"channel":"book","type":"update","data":[{"symbol":"LINK/BTC","bids":[],"asks":[{"price":0.00027463,"qty":204.84657360}],"checksum":2016680086,"timestamp":"2024-06-01T17:52:31.032577Z"}]}
{"channel":"book","type":"update","data":[{"symbol":"LINK/BTC","bids":[{"price":0.00027446,"qty":0.00000000},{"price":0.00027423,"qty":0.46822733}],"asks":[],"checksum":452667634,"timestamp":"2024-06-01T17:52:31.033214Z"}]}
{"channel":"book","type":"update","data":[{"symbol":"LINK/BTC","bids":[{"price":0.00027454,"qty":0.00000000},{"price":0.00027422,"qty":46.07000000}],"asks":[],"checksum":785964657,"timestamp":"2024-06-01T17:52:31.033319Z"}]}
{"channel":"book","type":"update","data":[{"symbol":"LINK/BTC","bids":[{"price":0.00027435,"qty":149.84610000}],"asks":[],"checksum":4018731706,"timestamp":"2024-06-01T17:52:31.037814Z"}]}
{"channel":"book","type":"update","data":[{"symbol":"LINK/BTC","bids":[{"price":0.00027449,"qty":490.17794818}],"asks":[],"checksum":2946011458,"timestamp":"2024-06-01T17:52:31.037873Z"}]}
{"channel":"book","type":"update","data":[{"symbol":"LINK/BTC","bids":[{"price":0.00027450,"qty":0.00000000},{"price":0.00027422,"qty":46.07000000}],"asks":[],"checksum":543781568,"timestamp":"2024-06-01T17:52:31.050765Z"}]}
{"channel":"book","type":"update","data":[{"symbol":"LINK/BTC","bids":[],"asks":[{"price":0.00027464,"qty":0.00000000},{"price":0.00027527,"qty":80.15256053}],"checksum":309899714,"timestamp":"2024-06-01T17:52:31.050848Z"}]}
{"channel":"book","type":"update","data":[{"symbol":"LINK/BTC","bids":[{"price":0.00027444,"qty":5.20000000}],"asks":[],"checksum":1644766783,"timestamp":"2024-06-01T17:52:31.066152Z"}]}
{"channel":"book","type":"update","data":[{"symbol":"LINK/BTC","bids":[{"price":0.00027443,"qty":0.00000000},{"price":0.00027422,"qty":46.07000000}],"asks":[],"checksum":1533603447,"timestamp":"2024-06-01T17:52:31.067515Z"}]}
{"channel":"book","type":"update","data":[{"symbol":"LINK/BTC","bids":[],"asks":[{"price":0.00027469,"qty":200.00000000}],"checksum":411914724,"timestamp":"2024-06-01T17:52:31.067730Z"}]}
{"channel":"book","type":"update","data":[{"symbol":"LINK/BTC","bids":[{"price":0.00027449,"qty":463.25034661}],"asks":[],"checksum":2168655023,"timestamp":"2024-06-01T17:52:31.068292Z"}]}
{"channel":"book","type":"update","data":[{"symbol":"LINK/BTC","bids":[],"asks":[{"price":0.00027462,"qty":5.20000000}],"checksum":1618653114,"timestamp":"2024-06-01T17:52:31.072094Z"}]}
{"channel":"book","type":"update","data":[{"symbol":"LINK/BTC","bids":[],"asks":[{"price":0.00027463,"qty":200.00000000}],"checksum":1181837700,"timestamp":"2024-06-01T17:52:31.074937Z"}]}
{"channel":"book","type":"update","data":[{"symbol":"LINK/BTC","bids":[{"price":0.00027438,"qty":0.00000000},{"price":0.00027421,"qty":915.42645000}],"asks":[],"checksum":2593523177,"timestamp":"2024-06-01T17:52:31.081765Z"}]}
{"channel":"book","type":"update","data":[{"symbol":"LINK/BTC","bids":[{"price":0.00027444,"qty":0.00000000},{"price":0.00027410,"qty":41.19191098}],"asks":[],"checksum":2088666388,"timestamp":"2024-06-01T17:52:31.086112Z"}]}
{"channel":"book","type":"update","data":[{"symbol":"LINK/BTC","bids":[],"asks":[{"price":0.00027466,"qty":200.00000000}],"checksum":1612302833,"timestamp":"2024-06-01T17:52:31.095847Z"}]}
{"channel":"book","type":"update","data":[{"symbol":"LINK/BTC","bids":[],"asks":[{"price":0.00027508,"qty":80.15256053}],"checksum":3095004210,"timestamp":"2024-06-01T17:52:31.111865Z"}]}
{"channel":"book","type":"update","data":[{"symbol":"LINK/BTC","bids":[{"price":0.00027431,"qty":0.00000000},{"price":0.00027409,"qty":43.63000000}],"asks":[],"checksum":2984630635,"timestamp":"2024-06-01T17:52:31.119870Z"}]}
{"channel":"book","type":"update","data":[{"symbol":"LINK/BTC","bids":[],"asks":[{"price":0.00027466,"qty":208.07371470}],"checksum":2752529551,"timestamp":"2024-06-01T17:52:31.120048Z"}]}
{"channel":"book","type":"update","data":[{"symbol":"LINK/BTC","bids":[{"price":0.00027420,"qty":26.95684789}],"asks":[],"checksum":2478067032,"timestamp":"2024-06-01T17:52:31.120098Z"}]}
{"channel":"book","type":"update","data":[{"symbol":"LINK/BTC","bids":[{"price":0.00027438,"qty":26.94044532}],"asks":[],"checksum":3106718414,"timestamp":"2024-06-01T17:52:31.164107Z"}]}
{"channel":"book","type":"update","data":[{"symbol":"LINK/BTC","bids":[],"asks":[{"price":0.00027469,"qty":0.00000000},{"price":0.00027519,"qty":40.00000000}],"checksum":3434290991,"timestamp":"2024-06-01T17:52:31.180773Z"}]}
{"channel":"book","type":"update","data":[{"symbol":"LINK/BTC","bids":[{"price":0.00027430,"qty":200.00000000}],"asks":[],"checksum":2478439164,"timestamp":"2024-06-01T17:52:31.180927Z"}]}
{"channel":"book","type":"update","data":[{"symbol":"LINK/BTC","bids":[{"price":0.00027426,"qty":0.00000000},{"price":0.00027420,"qty":26.95684789}],"asks":[],"checksum":2864620118,"timestamp":"2024-06-01T17:52:31.185589Z"}]}
{"channel":"book","type":"update","data":[{"symbol":"LINK/BTC","bids":[],"asks":[{"price":0.00027462,"qty":205.20000000}],"checksum":1554410301,"timestamp":"2024-06-01T17:52:31.240643Z"}]}
{"channel":"book","type":"update","data":[{"symbol":"LINK/BTC","bids":[],"asks":[{"price":0.00027514,"qty":51.08675582}],"checksum":2920296535,"timestamp":"2024-06-01T17:52:31.253620Z"}]}
{"channel":"book","type":"update","data":[{"symbol":"LINK/BTC","bids":[],"asks":[{"price":0.00027514,"qty":42.04317801}],"checksum":294026581,"timestamp":"2024-06-01T17:52:31.253805Z"}]}
{"channel":"book","type":"update","data":[{"symbol":"LINK/BTC","bids":[],"asks":[{"price":0.00027514,"qty":51.08704656}],"checksum":3019184654,"timestamp":"2024-06-01T17:52:31.287964Z"}]}
{"channel":"book","type":"update","data":[{"symbol":"LINK/BTC","bids":[],"asks":[{"price":0.00027514,"qty":9.04386855}],"checksum":3503952535,"timestamp":"2024-06-01T17:52:31.288020Z"}]}
{"channel":"book","type":"update","data":[{"symbol":"LINK/BTC","bids":[],"asks":[{"price":0.00027466,"qty":8.07371470}],"checksum":2093616912,"timestamp":"2024-06-01T17:52:31.310506Z"}]}
{"channel":"book","type":"update","data":[{"symbol":"LINK/BTC","bids":[],"asks":[{"price":0.00027503,"qty":88.51378950}],"checksum":4248682412,"timestamp":"2024-06-01T17:52:31.348438Z"}]}
{"channel":"book","type":"update","data":[{"symbol":"LINK/BTC","bids":[{"price":0.00027449,"qty":4.04159661}],"asks":[],"checksum":2429263520,"timestamp":"2024-06-01T17:52:31.355736Z"}]}
{"channel":"book","type":"update","data":[{"symbol":"LINK/BTC","bids":[{"price":0.00027439,"qty":459.20875000}],"asks":[],"checksum":4026164458,"timestamp":"2024-06-01T17:52:31.358610Z"}]}
{"channel":"book","type":"update","data":[{"symbol":"LINK/BTC","bids":[{"price":0.00027439,"qty":464.40875000}],"asks":[],"checksum":3080870206,"timestamp":"2024-06-01T17:52:31.360037Z"}]}
{"channel":"book","type":"update","data":[{"symbol":"LINK/BTC","bids":[{"price":0.00027439,"qty":459.20875000}],"asks":[],"checksum":4026164458,"timestamp":"2024-06-01T17:52:31.362431Z"}]}
{"channel":"book","type":"update","data":[{"symbol":"LINK/BTC","bids":[{"price":0.00027440,"qty":5.20000000}],"asks":[],"checksum":764026505,"timestamp":"2024-06-01T17:52:31.362673Z"}]}
{"channel":"book","type":"update","data":[{"symbol":"LINK/BTC","bids":[{"price":0.00027449,"qty":0.00000000},{"price":0.00027421,"qty":915.42645000}],"asks":[],"checksum":4093243121,"timestamp":"2024-06-01T17:52:31.425260Z"}]}
{"channel":"book","type":"update","data":[{"symbol":"LINK/BTC","bids":[{"price":0.00027428,"qty":0.00000000},{"price":0.00027420,"qty":26.95684789}],"asks":[],"checksum":3309376323,"timestamp":"2024-06-01T17:52:31.428381Z"}]}
{"channel":"book","type":"update","data":[{"symbol":"LINK/BTC","bids":[{"price":0.00027439,"qty":0.00000000},{"price":0.00027413,"qty":91.19760697}],"asks":[],"checksum":3110223625,"timestamp":"2024-06-01T17:52:31.428913Z"}]}
{"channel":"book","type":"update","data":[{"symbol":"LINK/BTC","bids":[{"price":0.00027440,"qty":10.04726810}],"asks":[],"checksum":3728985807,"timestamp":"2024-06-01T17:52:31.429045Z"}]}
{"channel":"book","type":"update","data":[{"symbol":"LINK/BTC","bids":[{"price":0.00027428,"qty":5.27748371}],"asks":[],"checksum":2334141250,"timestamp":"2024-06-01T17:52:31.431551Z"}]}
{"channel":"book","type":"update","data":[{"symbol":"LINK/BTC","bids":[{"price":0.00027441,"qty":459.20875000}],"asks":[],"checksum":1870531562,"timestamp":"2024-06-01T17:52:31.431631Z"}]}
{"channel":"book","type":"update","data":[{"symbol":"LINK/BTC","bids":[{"price":0.00027440,"qty":4.84726810}],"asks":[],"checksum":377579345,"timestamp":"2024-06-01T17:52:31.435500Z"}]}
{"channel":"book","type":"update","data":[{"symbol":"LINK/BTC","bids":[{"price":0.00027442,"qty":5.20000000}],"asks":[],"checksum":3967242541,"timestamp":"2024-06-01T17:52:31.435686Z"}]}
{"channel":"book","type":"update","data":[{"symbol":"LINK/BTC","bids":[],"asks":[{"price":0.00027514,"qty":0.00000000},{"price":0.00027519,"qty":40.00000000}],"checksum":2827066394,"timestamp":"2024-06-01T17:52:31.467009Z"}]}
{"channel":"book","type":"update","data":[{"symbol":"LINK/BTC","bids":[],"asks":[{"price":0.00027514,"qty":55.50974046}],"checksum":1111753708,"timestamp":"2024-06-01T17:52:31.467058Z"}]}
{"channel":"book","type":"update","data":[{"symbol":"LINK/BTC","bids":[],"asks":[{"price":0.00027462,"qty":210.04731284}],"checksum":3938731483,"timestamp":"2024-06-01T17:52:31.468977Z"}]}
{"channel":"book","type":"update","data":[{"symbol":"LINK/BTC","bids":[],"asks":[{"price":0.00027514,"qty":64.55371805}],"checksum":2434882560,"timestamp":"2024-06-01T17:52:31.480083Z"}]}
{"channel":"book","type":"update","data":[{"symbol":"LINK/BTC","bids":[{"price":0.00027433,"qty":208.07317245}],"asks":[],"checksum":3528904056,"timestamp":"2024-06-01T17:52:31.480154Z"}]}
{"channel":"book","type":"update","data":[{"symbol":"LINK/BTC","bids":[],"asks":[{"price":0.00027514,"qty":9.04397759}],"checksum":2679417361,"timestamp":"2024-06-01T17:52:31.480285Z"}]}
{"channel":"book","type":"update","data":[{"symbol":"LINK/BTC","bids":[{"price":0.00027442,"qty":13.81451739}],"asks":[],"checksum":339352411,"timestamp":"2024-06-01T17:52:31.492881Z"}]}
{"channel":"book","type":"update","data":[{"symbol":"LINK/BTC","bids":[{"price":0.00027442,"qty":18.66176170}],"asks":[],"checksum":2318677681,"timestamp":"2024-06-01T17:52:31.559681Z"}]}
{"channel":"book","type":"update","data":[{"symbol":"LINK/BTC","bids":[{"price":0.00027440,"qty":0.00000000},{"price":0.00027422,"qty":46.07000000}],"asks":[],"checksum":3469351897,"timestamp":"2024-06-01T17:52:31.560512Z"}]}
{"channel":"book","type":"update","data":[{"symbol":"LINK/BTC","bids":[],"asks":[{"price":0.00027514,"qty":0.00000000},{"price":0.00027519,"qty":40.00000000}],"checksum":3472996361,"timestamp":"2024-06-01T17:52:31.640588Z"}]}
{"channel":"book","type":"update","data":[{"symbol":"LINK/BTC","bids":[],"asks":[{"price":0.00027514,"qty":9.04394124}],"checksum":3030512359,"timestamp":"2024-06-01T17:52:31.640786Z"}]}
{"channel":"book","type":"update","data":[{"symbol":"LINK/BTC","bids":[{"price":0.00027442,"qty":13.81451739}],"asks":[],"checksum":4108384172,"timestamp":"2024-06-01T17:52:31.663599Z"}]}
{"channel":"book","type":"update","data":[{"symbol":"LINK/BTC","bids":[],"asks":[{"price":0.00027465,"qty":200.00000000}],"checksum":3777158141,"timestamp":"2024-06-01T17:52:31.669009Z"}]}
{"channel":"book","type":"update","data":[{"symbol":"LINK/BTC","bids":[],"asks":[{"price":0.00027462,"qty":10.04731284}],"checksum":2450105962,"timestamp":"2024-06-01T17:52:31.669042Z"}]}
{"channel":"book","type":"update","data":[{"symbol":"LINK/BTC","bids":[{"price":0.00027435,"qty":349.84610000}],"asks":[],"checksum":1424900181,"timestamp":"2024-06-01T17:52:31.669179Z"}]}
{"channel":"book","type":"update","data":[{"symbol":"LINK/BTC","bids":[{"price":0.00027442,"qty":53.81451739}],"asks":[],"checksum":3053466575,"timestamp":"2024-06-01T17:52:31.670899Z"}]}
{"channel":"book","type":"update","data":[{"symbol":"LINK/BTC","bids":[],"asks":[{"price":0.00027514,"qty":18.08751905}],"checksum":3721111657,"timestamp":"2024-06-01T17:52:31.808039Z"}]}
{"channel":"book","type":"update","data":[{"symbol":"LINK/BTC","bids":[],"asks":[{"price":0.00027514,"qty":9.04357781}],"checksum":3418301791,"timestamp":"2024-06-01T17:52:31.808188Z"}]}
{"channel":"book","type":"update","data":[{"symbol":"LINK/BTC","bids":[],"asks":[{"price":0.00027514,"qty":0.00000000},{"price":0.00027515,"qty":65.03905979}],"checksum":3540687121,"timestamp":"2024-06-01T17:52:31.834089Z"}]}
{"channel":"book","type":"update","data":[{"symbol":"LINK/BTC","bids":[],"asks":[{"price":0.00027514,"qty":30.58264882}],"checksum":834155946,"timestamp":"2024-06-01T17:52:31.834552Z"}]}
{"channel":"book","type":"update","data":[{"symbol":"LINK/BTC","bids":[],"asks":[{"price":0.00027514,"qty":39.62622663}],"checksum":3613916541,"timestamp":"2024-06-01T17:52:31.858348Z"}]}
{"channel":"book","type":"update","data":[{"symbol":"LINK/BTC","bids":[],"asks":[{"price":0.00027514,"qty":9.04357781}],"checksum":3418301791,"timestamp":"2024-06-01T17:52:31.858434Z"}]}
{"channel":"book","type":"update","data":[{"symbol":"LINK/BTC","bids":[],"asks":[{"price":0.00027514,"qty":0.00000000},{"price":0.00027515,"qty":65.03905979}],"checksum":3540687121,"timestamp":"2024-06-01T17:52:31.886273Z"}]}
{"channel":"book","type":"update","data":[{"symbol":"LINK/BTC","bids":[],"asks":[{"price":0.00027514,"qty":70.52987272}],"checksum":1135771029,"timestamp":"2024-06-01T17:52:31.886351Z"}]}
{"channel":"book","type":"update","data":[{"symbol":"LINK/BTC","bids":[{"price":0.00027430,"qty":0.00000000},{"price":0.00027421,"qty":915.42645000}],"asks":[],"checksum":2265135429,"timestamp":"2024-06-01T17:52:31.922597Z"}]}
{"channel":"book","type":"update","data":[{"symbol":"LINK/BTC","bids":[],"asks":[{"price":0.00027514,"qty":0.00000000},{"price":0.00027515,"qty":65.03905979}],"checksum":398187969,"timestamp":"2024-06-01T17:52:31.974879Z"}]}
{"channel":"book","type":"update","data":[{"symbol":"LINK/BTC","bids":[],"asks":[{"price":0.00027514,"qty":55.50745074}],"checksum":3093965163,"timestamp":"2024-06-01T17:52:31.974931Z"}]}
{"channel":"book","type":"update","data":[{"symbol":"LINK/BTC","bids":[],"asks":[{"price":0.00027514,"qty":78.01657336}],"checksum":3542975409,"timestamp":"2024-06-01T17:52:31.990042Z"}]}
{"channel":"book","type":"update","data":[{"symbol":"LINK/BTC","bids":[],"asks":[{"price":0.00027514,"qty":22.50912262}],"checksum":3202706897,"timestamp":"2024-06-01T17:52:31.990133Z"}]}
{"channel":"book","type":"update","data":[{"symbol":"LINK/BTC","bids":[{"price":0.00027442,"qty":13.81451739}],"asks":[],"checksum":1544232523,"timestamp":"2024-06-01T17:52:32.187442Z"}]}
{"channel":"book","type":"update","data":[{"symbol":"LINK/BTC","bids":[{"price":0.00027442,"qty":53.81451739}],"asks":[],"checksum":3202706897,"timestamp":"2024-06-01T17:52:32.393790Z"}]}
{"channel":"book","type":"update","data":[{"symbol":"LINK/BTC","bids":[],"asks":[{"price":0.00027461,"qty":200.00000000}],"checksum":655701875,"timestamp":"2024-06-01T17:52:32.535156Z"}]}
{"channel":"book","type":"update","data":[{"symbol":"LINK/BTC","bids":[],"asks":[{"price":0.00027462,"qty":4.84731284}],"checksum":891244826,"timestamp":"2024-06-01T17:52:32.537743Z"}]}
{"channel":"book","type":"update","data":[{"symbol":"LINK/BTC","bids":[],"asks":[{"price":0.00027460,"qty":5.20000000}],"checksum":1502837073,"timestamp":"2024-06-01T17:52:32.538223Z"}]}
{"channel":"book","type":"update","data":[{"symbol":"LINK/BTC","bids":[],"asks":[{"price":0.00027463,"qty":0.00000000},{"price":0.00027508,"qty":80.15256053}],"checksum":2476429470,"timestamp":"2024-06-01T17:52:32.707736Z"}]}
{"channel":"book","type":"update","data":[{"symbol":"LINK/BTC","bids":[{"price":0.00027445,"qty":26.93522894}],"asks":[],"checksum":2756641112,"timestamp":"2024-06-01T17:52:32.923222Z"}]}
{"channel":"book","type":"update","data":[{"symbol":"LINK/BTC","bids":[{"price":0.00027428,"qty":0.00000000},{"price":0.00027421,"qty":915.42645000}],"asks":[],"checksum":1897558128,"timestamp":"2024-06-01T17:52:33.653081Z"}]}
{"channel":"book","type":"update","data":[{"symbol":"LINK/BTC","bids":[{"price":0.00027442,"qty":59.33923633}],"asks":[],"checksum":1743211691,"timestamp":"2024-06-01T17:52:33.658535Z"}]}
{"channel":"book","type":"update","data":[{"symbol":"LINK/BTC","bids":[{"price":0.00027443,"qty":1.81835965}],"asks":[],"checksum":2271800294,"timestamp":"2024-06-01T17:52:33.658608Z"}]}
{"channel":"book","type":"update","data":[{"symbol":"LINK/BTC","bids":[{"price":0.00027436,"qty":5.57264198}],"asks":[],"checksum":2449038651,"timestamp":"2024-06-01T17:52:33.658743Z"}]}
{"channel":"book","type":"update","data":[{"symbol":"LINK/BTC","bids":[{"price":0.00027445,"qty":0.00000000},{"price":0.00027422,"qty":46.07000000}],"asks":[],"checksum":1389773349,"timestamp":"2024-06-01T17:52:34.239586Z"}]}
{"channel":"book","type":"update","data":[{"symbol":"LINK/BTC","bids":[],"asks":[{"price":0.00027459,"qty":200.00000000}],"checksum":1127126002,"timestamp":"2024-06-01T17:52:34.721132Z"}]}
{"channel":"book","type":"update","data":[{"symbol":"LINK/BTC","bids":[],"asks":[{"price":0.00027460,"qty":0.00000000},{"price":0.00027508,"qty":80.15256053}],"checksum":3438405867,"timestamp":"2024-06-01T17:52:34.723946Z"}]}
{"channel":"book","type":"update","data":[{"symbol":"LINK/BTC","bids":[],"asks":[{"price":0.00027458,"qty":5.20000000}],"checksum":3159367496,"timestamp":"2024-06-01T17:52:34.724023Z"}]}
{"channel":"book","type":"update","data":[{"symbol":"LINK/BTC","bids":[{"price":0.00027442,"qty":19.33923633}],"asks":[],"checksum":3971194677,"timestamp":"2024-06-01T17:52:34.726251Z"}]}
{"channel":"book","type":"update","data":[{"symbol":"LINK/BTC","bids":[],"asks":[{"price":0.00027461,"qty":0.00000000},{"price":0.00027508,"qty":80.15256053}],"checksum":1776120491,"timestamp":"2024-06-01T17:52:34.896461Z"}]}
{"channel":"book","type":"update","data":[{"symbol":"LINK/BTC","bids":[{"price":0.00027441,"qty":0.00000000},{"price":0.00027421,"qty":915.42645000}],"asks":[],"checksum":2604138091,"timestamp":"2024-06-01T17:52:35.745934Z"}]}
{"channel":"book","type":"update","data":[{"symbol":"LINK/BTC","bids":[{"price":0.00027444,"qty":459.20875000}],"asks":[],"checksum":1763712144,"timestamp":"2024-06-01T17:52:35.748619Z"}]}
{"channel":"book","type":"update","data":[{"symbol":"LINK/BTC","bids":[{"price":0.00027442,"qty":13.81451739}],"asks":[],"checksum":990046451,"timestamp":"2024-06-01T17:52:35.862288Z"}]}
{"channel":"book","type":"update","data":[{"symbol":"LINK/BTC","bids":[{"price":0.00027436,"qty":0.00000000},{"price":0.00027421,"qty":915.42645000}],"asks":[],"checksum":842429172,"timestamp":"2024-06-01T17:52:35.862348Z"}]}
{"channel":"book","type":"update","data":[{"symbol":"LINK/BTC","bids":[{"price":0.00027443,"qty":0.00000000},{"price":0.00027420,"qty":26.95684789}],"asks":[],"checksum":3080733168,"timestamp":"2024-06-01T17:52:35.862368Z"}]}
{"channel":"book","type":"update","data":[{"symbol":"LINK/BTC","bids":[{"price":0.00027442,"qty":17.11557376}],"asks":[],"checksum":2880941598,"timestamp":"2024-06-01T17:52:35.864792Z"}]}
{"channel":"book","type":"update","data":[{"symbol":"LINK/BTC","bids":[{"price":0.00027436,"qty":9.68331221}],"asks":[],"checksum":3253333335,"timestamp":"2024-06-01T17:52:35.864956Z"}]}
{"channel":"book","type":"update","data":[{"symbol":"LINK/BTC","bids":[{"price":0.00027447,"qty":26.93305878}],"asks":[],"checksum":1436073769,"timestamp":"2024-06-01T17:52:35.923616Z"}]}
{"channel":"book","type":"update","data":[{"symbol":"LINK/BTC","bids":[{"price":0.00027435,"qty":149.84610000}],"asks":[],"checksum":983172280,"timestamp":"2024-06-01T17:52:36.710869Z"}]}
{"channel":"book","type":"update","data":[{"symbol":"LINK/BTC","bids":[{"price":0.00027433,"qty":0.00000000},{"price":0.00027421,"qty":915.42645000}],"asks":[],"checksum":4207134844,"timestamp":"2024-06-01T17:52:36.814685Z"}]}
{"channel":"book","type":"update","data":[{"symbol":"LINK/BTC","bids":[],"asks":[{"price":0.00027458,"qty":205.20000000}],"checksum":1839497808,"timestamp":"2024-06-01T17:52:36.898363Z"}]}
{"channel":"book","type":"update","data":[{"symbol":"LINK/BTC","bids":[],"asks":[{"price":0.00027460,"qty":200.00000000}],"checksum":794395123,"timestamp":"2024-06-01T17:52:36.902951Z"}]}
{"channel":"book","type":"update","data":[{"symbol":"LINK/BTC","bids":[{"price":0.00027430,"qty":200.00000000}],"asks":[],"checksum":1277452243,"timestamp":"2024-06-01T17:52:36.902973Z"}]}
{"channel":"book","type":"update","data":[{"symbol":"LINK/BTC","bids":[],"asks":[{"price":0.00027465,"qty":0.00000000},{"price":0.00027508,"qty":80.15256053}],"checksum":65222767,"timestamp":"2024-06-01T17:52:36.920797Z"}]}
{"channel":"book","type":"update","data":[{"symbol":"LINK/BTC","bids":[{"price":0.00027433,"qty":200.00000000}],"asks":[],"checksum":482573453,"timestamp":"2024-06-01T17:52:37.093471Z"}]}
{"channel":"book","type":"update","data":[{"symbol":"LINK/BTC","bids":[],"asks":[{"price":0.00027459,"qty":0.00000000},{"price":0.00027514,"qty":70.52987272}],"checksum":419154953,"timestamp":"2024-06-01T17:52:37.155622Z"}]}
{"channel":"book","type":"update","data":[{"symbol":"LINK/BTC","bids":[],"asks":[{"price":0.00027466,"qty":0.00000000},{"price":0.00027515,"qty":65.03905979}],"checksum":1505490137,"timestamp":"2024-06-01T17:52:37.718926Z"}]}
{"channel":"book","type":"update","data":[{"symbol":"LINK/BTC","bids":[],"asks":[{"price":0.00027464,"qty":8.07514834}],"checksum":1016078221,"timestamp":"2024-06-01T17:52:37.722474Z"}]}
{"channel":"book","type":"update","data":[{"symbol":"LINK/BTC","bids":[{"price":0.00027442,"qty":13.81451739}],"asks":[],"checksum":3218574735,"timestamp":"2024-06-01T17:52:37.994988Z"}]}
{"channel":"book","type":"update","data":[{"symbol":"LINK/BTC","bids":[{"price":0.00027436,"qty":0.00000000},{"price":0.00027422,"qty":46.07000000}],"asks":[],"checksum":768924260,"timestamp":"2024-06-01T17:52:37.995197Z"}]}
{"channel":"book","type":"update","data":[{"symbol":"LINK/BTC","bids":[{"price":0.00027434,"qty":4.78409701}],"asks":[],"checksum":2768557497,"timestamp":"2024-06-01T17:52:37.998339Z"}]}
{"channel":"book","type":"update","data":[{"symbol":"LINK/BTC","bids":[{"price":0.00027431,"qty":1.87374107}],"asks":[],"checksum":3543408253,"timestamp":"2024-06-01T17:52:37.998411Z"}]}
{"channel":"book","type":"update","data":[{"symbol":"LINK/BTC","bids":[{"price":0.00027436,"qty":4.04272835}],"asks":[],"checksum":3234848272,"timestamp":"2024-06-01T17:52:37.998529Z"}]}
{"channel":"book","type":"update","data":[{"symbol":"LINK/BTC","bids":[{"price":0.00027442,"qty":8.61451739}],"asks":[],"checksum":410555784,"timestamp":"2024-06-01T17:52:38.033026Z"}]}
{"channel":"book","type":"update","data":[{"symbol":"LINK/BTC","bids":[{"price":0.00027445,"qty":5.20000000}],"asks":[],"checksum":940194464,"timestamp":"2024-06-01T17:52:38.033307Z"}]}
{"channel":"book","type":"update","data":[{"symbol":"LINK/BTC","bids":[],"asks":[{"price":0.00027514,"qty":0.00000000},{"price":0.00027515,"qty":65.03905979}],"checksum":3309666845,"timestamp":"2024-06-01T17:52:38.065435Z"}]}
{"channel":"book","type":"update","data":[{"symbol":"LINK/BTC","bids":[],"asks":[{"price":0.00027514,"qty":10.54899323}],"checksum":4110010471,"timestamp":"2024-06-01T17:52:38.065466Z"}]}
{"channel":"book","type":"update","data":[{"symbol":"LINK/BTC","bids":[],"asks":[{"price":0.00027514,"qty":0.00000000},{"price":0.00027515,"qty":65.03905979}],"checksum":3309666845,"timestamp":"2024-06-01T17:52:38.077683Z"}]}
{"channel":"book","type":"update","data":[{"symbol":"LINK/BTC","bids":[],"asks":[{"price":0.00027514,"qty":9.04357781}],"checksum":895772462,"timestamp":"2024-06-01T17:52:38.077948Z"}]}
{"channel":"book","type":"update","data":[{"symbol":"LINK/BTC","bids":[],"asks":[{"price":0.00027460,"qty":0.00000000},{"price":0.00027515,"qty":65.03905979}],"checksum":962604164,"timestamp":"2024-06-01T17:52:38.427674Z"}]}
{"channel":"book","type":"update","data":[{"symbol":"LINK/BTC","bids":[{"price":0.00027433,"qty":400.00000000}],"asks":[],"checksum":1388003362,"timestamp":"2024-06-01T17:52:38.427842Z"}]}
{"channel":"book","type":"update","data":[{"symbol":"LINK/BTC","bids":[],"asks":[{"price":0.00027463,"qty":200.00000000}],"checksum":1654288639,"timestamp":"2024-06-01T17:52:38.427859Z"}]}
{"channel":"book","type":"update","data":[{"symbol":"LINK/BTC","bids":[],"asks":[{"price":0.00027514,"qty":0.00000000},{"price":0.00027515,"qty":65.03905979}],"checksum":1623404383,"timestamp":"2024-06-01T17:52:39.149808Z"}]}
{"channel":"book","type":"update","data":[{"symbol":"LINK/BTC","bids":[],"asks":[{"price":0.00027514,"qty":30.58264882}],"checksum":544694718,"timestamp":"2024-06-01T17:52:39.149928Z"}]}
{"channel":"book","type":"update","data":[{"symbol":"LINK/BTC","bids":[],"asks":[{"price":0.00027514,"qty":0.00000000},{"price":0.00027515,"qty":65.03905979}],"checksum":1623404383,"timestamp":"2024-06-01T17:52:39.547869Z"}]}
{"channel":"book","type":"update","data":[{"symbol":"LINK/BTC","bids":[],"asks":[{"price":0.00027514,"qty":9.04357781}],"checksum":1654288639,"timestamp":"2024-06-01T17:52:39.548035Z"}]}
{"channel":"book","type":"update","data":[{"symbol":"LINK/BTC","bids":[{"price":0.00027434,"qty":0.00000000},{"price":0.00027427,"qty":217.68605000}],"asks":[],"checksum":2122001658,"timestamp":"2024-06-01T17:52:40.058409Z"}]}
{"channel":"book","type":"update","data":[{"symbol":"LINK/BTC","bids":[{"price":0.00027436,"qty":0.00000000},{"price":0.00027423,"qty":0.46822733}],"asks":[],"checksum":2285134376,"timestamp":"2024-06-01T17:52:40.058624Z"}]}
{"channel":"book","type":"update","data":[{"symbol":"LINK/BTC","bids":[{"price":0.00027431,"qty":0.00000000},{"price":0.00027422,"qty":46.07000000}],"asks":[],"checksum":3207390568,"timestamp":"2024-06-01T17:52:40.058658Z"}]}
{"channel":"book","type":"update","data":[{"symbol":"LINK/BTC","bids":[{"price":0.00027436,"qty":4.78372618}],"asks":[],"checksum":4093766227,"timestamp":"2024-06-01T17:52:40.064167Z"}]}
{"channel":"book","type":"update","data":[{"symbol":"LINK/BTC","bids":[{"price":0.00027434,"qty":7.13512689}],"asks":[],"checksum":2837114676,"timestamp":"2024-06-01T17:52:40.064293Z"}]}
{"channel":"book","type":"update","data":[{"symbol":"LINK/BTC","bids":[],"asks":[{"price":0.00027514,"qty":0.00000000},{"price":0.00027515,"qty":65.03905979}],"checksum":4241038817,"timestamp":"2024-06-01T17:52:40.421168Z"}]}
{"channel":"book","type":"update","data":[{"symbol":"LINK/BTC","bids":[],"asks":[{"price":0.00027514,"qty":30.58264882}],"checksum":717812591,"timestamp":"2024-06-01T17:52:40.421582Z"}]}
{"channel":"book","type":"update","data":[{"symbol":"LINK/BTC","bids":[],"asks":[{"price":0.00027514,"qty":39.62622663}],"checksum":3634210526,"timestamp":"2024-06-01T17:52:40.804416Z"}]}
{"channel":"book","type":"update","data":[{"symbol":"LINK/BTC","bids":[],"asks":[{"price":0.00027514,"qty":9.04357781}],"checksum":2837114676,"timestamp":"2024-06-01T17:52:40.804549Z"}]}
{"channel":"book","type":"update","data":[{"symbol":"LINK/BTC","bids":[],"asks":[{"price":0.00027514,"qty":0.00000000},{"price":0.00027515,"qty":65.03905979}],"checksum":4241038817,"timestamp":"2024-06-01T17:52:41.133195Z"}]}
{"channel":"book","type":"update","data":[{"symbol":"LINK/BTC","bids":[],"asks":[{"price":0.00027514,"qty":42.04266918}],"checksum":3344320999,"timestamp":"2024-06-01T17:52:41.133279Z"}]}
{"channel":"book","type":"update","data":[{"symbol":"LINK/BTC","bids":[],"asks":[{"price":0.00027514,"qty":112.57254190}],"checksum":3210611570,"timestamp":"2024-06-01T17:52:41.213745Z"}]}
{"channel":"book","type":"update","data":[{"symbol":"LINK/BTC","bids":[],"asks":[{"price":0.00027514,"qty":70.52987272}],"checksum":1746406373,"timestamp":"2024-06-01T17:52:41.213818Z"}]}
{"channel":"book","type":"update","data":[{"symbol":"LINK/BTC","bids":[{"price":0.00027444,"qty":0.00000000},{"price":0.00027423,"qty":0.46822733}],"asks":[],"checksum":2397566584,"timestamp":"2024-06-01T17:52:41.630408Z"}]}
{"channel":"book","type":"update","data":[{"symbol":"LINK/BTC","bids":[{"price":0.00027445,"qty":464.40875000}],"asks":[],"checksum":2629394205,"timestamp":"2024-06-01T17:52:41.633329Z"}]}
{"channel":"book","type":"update","data":[{"symbol":"LINK/BTC","bids":[],"asks":[{"price":0.00027514,"qty":0.00000000},{"price":0.00027515,"qty":65.03905979}],"checksum":697622420,"timestamp":"2024-06-01T17:52:41.761813Z"}]}
{"channel":"book","type":"update","data":[{"symbol":"LINK/BTC","bids":[],"asks":[{"price":0.00027514,"qty":50.54663079}],"checksum":1600981855,"timestamp":"2024-06-01T17:52:41.761955Z"}]}
{"channel":"book","type":"update","data":[{"symbol":"LINK/BTC","bids":[],"asks":[{"price":0.00027514,"qty":0.00000000},{"price":0.00027515,"qty":65.03905979}],"checksum":697622420,"timestamp":"2024-06-01T17:52:42.060304Z"}]}
{"channel":"book","type":"update","data":[{"symbol":"LINK/BTC","bids":[],"asks":[{"price":0.00027514,"qty":70.52987272}],"checksum":2629394205,"timestamp":"2024-06-01T17:52:42.060516Z"}]}
{"channel":"book","type":"update","data":[{"symbol":"LINK/BTC","bids":[{"price":0.00027436,"qty":0.00000000},{"price":0.00027422,"qty":46.07000000}],"asks":[],"checksum":2772012804,"timestamp":"2024-06-01T17:52:42.339706Z"}]}
{"channel":"book","type":"update","data":[{"symbol":"LINK/BTC","bids":[{"price":0.00027436,"qty":5.52548500}],"asks":[],"checksum":4247913335,"timestamp":"2024-06-01T17:52:42.342350Z"}]}
{"channel":"book","type":"update","data":[{"symbol":"LINK/BTC","bids":[{"price":0.00027433,"qty":200.00000000}],"asks":[],"checksum":2823512679,"timestamp":"2024-06-01T17:52:44.331900Z"}]}
{"channel":"book","type":"update","data":[{"symbol":"LINK/BTC","bids":[],"asks":[{"price":0.00027458,"qty":210.04728873}],"checksum":3578461839,"timestamp":"2024-06-01T17:52:44.352915Z"}]}
{"channel":"book","type":"update","data":[{"symbol":"LINK/BTC","bids":[],"asks":[{"price":0.00027462,"qty":0.00000000},{"price":0.00027515,"qty":65.03905979}],"checksum":870708063,"timestamp":"2024-06-01T17:52:44.354891Z"}]}
{"channel":"book","type":"update","data":[{"symbol":"LINK/BTC","bids":[],"asks":[{"price":0.00027457,"qty":200.00000000}],"checksum":2037184580,"timestamp":"2024-06-01T17:52:44.357364Z"}]}
{"channel":"book","type":"update","data":[{"symbol":"LINK/BTC","bids":[],"asks":[{"price":0.00027457,"qty":204.84761180}],"checksum":917191034,"timestamp":"2024-06-01T17:52:44.360113Z"}]}
{"channel":"book","type":"update","data":[{"symbol":"LINK/BTC","bids":[],"asks":[{"price":0.00027458,"qty":205.20000000}],"checksum":1612332024,"timestamp":"2024-06-01T17:52:44.393320Z"}]}
{"channel":"book","type":"update","data":[{"symbol":"LINK/BTC","bids":[],"asks":[{"price":0.00027463,"qty":0.00000000},{"price":0.00027515,"qty":65.03905979}],"checksum":4220987577,"timestamp":"2024-06-01T17:52:44.397729Z"}]}
{"channel":"book","type":"update","data":[{"symbol":"LINK/BTC","bids":[{"price":0.00027433,"qty":0.00000000},{"price":0.00027422,"qty":46.07000000}],"asks":[],"checksum":3818491792,"timestamp":"2024-06-01T17:52:44.453938Z"}]}
{"channel":"book","type":"update","data":[{"symbol":"LINK/BTC","bids":[{"price":0.00027436,"qty":0.00000000},{"price":0.00027421,"qty":915.42645000}],"asks":[],"checksum":1305144484,"timestamp":"2024-06-01T17:52:44.540311Z"}]}
{"channel":"book","type":"update","data":[{"symbol":"LINK/BTC","bids":[{"price":0.00027434,"qty":0.00000000},{"price":0.00027420,"qty":26.95684789}],"asks":[],"checksum":996742777,"timestamp":"2024-06-01T17:52:44.540469Z"}]}
{"channel":"book","type":"update","data":[{"symbol":"LINK/BTC","bids":[{"price":0.00027436,"qty":6.26654506}],"asks":[],"checksum":1538936408,"timestamp":"2024-06-01T17:52:44.542893Z"}]}
{"channel":"book","type":"update","data":[{"symbol":"LINK/BTC","bids":[{"price":0.00027434,"qty":6.25501927}],"asks":[],"checksum":1841580599,"timestamp":"2024-06-01T17:52:44.542933Z"}]}
{"channel":"book","type":"update","data":[{"symbol":"LINK/BTC","bids":[{"price":0.00027429,"qty":200.00000000}],"asks":[],"checksum":884243670,"timestamp":"2024-06-01T17:52:44.545282Z"}]}
{"channel":"book","type":"update","data":[{"symbol":"LINK/BTC","bids":[],"asks":[{"price":0.00027456,"qty":200.00000000}],"checksum":3629845109,"timestamp":"2024-06-01T17:52:44.612031Z"}]}
{"channel":"book","type":"update","data":[{"symbol":"LINK/BTC","bids":[{"price":0.00027431,"qty":205.20000000}],"asks":[],"checksum":3019261124,"timestamp":"2024-06-01T17:52:44.742643Z"}]}
{"channel":"book","type":"update","data":[{"symbol":"LINK/BTC","bids":[{"price":0.00027447,"qty":0.00000000},{"price":0.00027422,"qty":46.07000000}],"asks":[],"checksum":2162253166,"timestamp":"2024-06-01T17:52:45.347410Z"}]}
{"channel":"book","type":"update","data":[{"symbol":"LINK/BTC","bids":[{"price":0.00027443,"qty":26.93591875}],"asks":[],"checksum":2992230400,"timestamp":"2024-06-01T17:52:45.351831Z"}]}
{"channel":"book","type":"update","data":[{"symbol":"LINK/BTC","bids":[],"asks":[{"price":0.00027458,"qty":5.20000000}],"checksum":2140237490,"timestamp":"2024-06-01T17:52:45.934292Z"}]}
{"channel":"book","type":"update","data":[{"symbol":"LINK/BTC","bids":[],"asks":[{"price":0.00027458,"qty":0.00000000},{"price":0.00027515,"qty":65.03905979}],"checksum":2777452415,"timestamp":"2024-06-01T17:52:45.936863Z"}]}
