{"channel":"book","type":"snapshot","data":[{"symbol":"LINK/USD","bids":[{"price":18.56609,"qty":2483.63333112},{"price":18.56514,"qty":52.94000000},{"price":18.56435,"qty":269.20523663},{"price":18.56423,"qty":31.87500000},{"price":18.56415,"qty":11.80000000},{"price":18.56401,"qty":339.03252319},{"price":18.56400,"qty":75.49689855},{"price":18.56379,"qty":83.14196476},{"price":18.56318,"qty":404.02546511},{"price":18.56167,"qty":31.87500000}],"asks":[{"price":18.56610,"qty":9.04600000},{"price":18.57186,"qty":1.10230934},{"price":18.57210,"qty":0.34717458},{"price":18.57359,"qty":0.34605497},{"price":18.57463,"qty":13.46117995},{"price":18.57464,"qty":1.50546674},{"price":18.57466,"qty":0.40269630},{"price":18.57514,"qty":80.75312393},{"price":18.57651,"qty":21.53589378},{"price":18.57685,"qty":1.31717222}],"checksum":2077745514}]}
{"channel":"book","type":"update","data":[{"symbol":"LINK/USD","bids":[],"asks":[{"price":18.57464,"qty":0.00000000},{"price":18.57726,"qty":31.87500000},{"price":18.57513,"qty":1.50546674}],"checksum":1103211187,"timestamp":"2024-06-01T17:52:00.079353Z"}]}
{"channel":"book","type":"update","data":[{"symbol":"LINK/USD","bids":[],"asks":[{"price":18.57514,"qty":0.00000000},{"price":18.57726,"qty":31.87500000}],"checksum":2867657384,"timestamp":"2024-06-01T17:52:00.128399Z"}]}
{"channel":"book","type":"update","data":[{"symbol":"LINK/USD","bids":[],"asks":[{"price":18.57513,"qty":0.00000000},{"price":18.57856,"qty":6.43107813},{"price":18.57650,"qty":1.50546674}],"checksum":3927303992,"timestamp":"2024-06-01T17:52:00.132752Z"}]}
{"channel":"book","type":"update","data":[{"symbol":"LINK/USD","bids":[],"asks":[{"price":18.57540,"qty":31.87500000}],"checksum":3041314863,"timestamp":"2024-06-01T17:52:00.282802Z"}]}
{"channel":"book","type":"update","data":[{"symbol":"LINK/USD","bids":[],"asks":[{"price":18.57540,"qty":0.00000000},{"price":18.57726,"qty":31.87500000}],"checksum":3927303992,"timestamp":"2024-06-01T17:52:00.285625Z"}]}
{"channel":"book","type":"update","data":[{"symbol":"LINK/USD","bids":[],"asks":[{"price":18.57650,"qty":0.00000000},{"price":18.57856,"qty":6.43107813},{"price":18.57462,"qty":1.50546674}],"checksum":4139941552,"timestamp":"2024-06-01T17:52:00.286090Z"}]}
{"channel":"book","type":"update","data":[{"symbol":"LINK/USD","bids":[],"asks":[{"price":18.57463,"qty":0.00000000},{"price":18.57856,"qty":6.43107813}],"checksum":2158038868,"timestamp":"2024-06-01T17:52:00.289255Z"}]}
{"channel":"book","type":"update","data":[{"symbol":"LINK/USD","bids":[],"asks":[{"price":18.57462,"qty":0.00000000},{"price":18.57912,"qty":31.87500000},{"price":18.57650,"qty":1.50546674}],"checksum":1234463964,"timestamp":"2024-06-01T17:52:00.289913Z"}]}
{"channel":"book","type":"update","data":[{"symbol":"LINK/USD","bids":[],"asks":[{"price":18.57358,"qty":13.46163922}],"checksum":691850486,"timestamp":"2024-06-01T17:52:01.310177Z"}]}
{"channel":"book","type":"update","data":[{"symbol":"LINK/USD","bids":[],"asks":[{"price":18.57358,"qty":0.00000000},{"price":18.57856,"qty":6.43107813}],"checksum":1234463964,"timestamp":"2024-06-01T17:52:01.313722Z"}]}
{"channel":"book","type":"update","data":[{"symbol":"LINK/USD","bids":[],"asks":[{"price":18.57358,"qty":13.46183586}],"checksum":2400694965,"timestamp":"2024-06-01T17:52:01.317375Z"}]}
{"channel":"book","type":"update","data":[{"symbol":"LINK/USD","bids":[],"asks":[{"price":18.57540,"qty":31.87500000}],"checksum":3494157730,"timestamp":"2024-06-01T17:52:01.322768Z"}]}
{"channel":"book","type":"update","data":[{"symbol":"LINK/USD","bids":[],"asks":[{"price":18.57650,"qty":0.00000000},{"price":18.57726,"qty":31.87500000},{"price":18.57539,"qty":1.50546674}],"checksum":763929492,"timestamp":"2024-06-01T17:52:01.325764Z"}]}
{"channel":"book","type":"update","data":[{"symbol":"LINK/USD","bids":[],"asks":[{"price":18.57540,"qty":0.00000000},{"price":18.57693,"qty":80.74531886}],"checksum":2631197635,"timestamp":"2024-06-01T17:52:02.400594Z"}]}
{"channel":"book","type":"update","data":[{"symbol":"LINK/USD","bids":[{"price":18.56401,"qty":0.00000000},{"price":18.56130,"qty":186.96555600},{"price":18.56609,"qty":2822.66585431}],"asks":[],"checksum":916703432,"timestamp":"2024-06-01T17:52:02.403373Z"}]}
{"channel":"book","type":"update","data":[{"symbol":"LINK/USD","bids":[],"asks":[{"price":18.57539,"qty":0.00000000},{"price":18.57726,"qty":31.87500000},{"price":18.57650,"qty":1.50546674}],"checksum":985526999,"timestamp":"2024-06-01T17:52:02.403841Z"}]}
{"channel":"book","type":"update","data":[{"symbol":"LINK/USD","bids":[],"asks":[{"price":18.57358,"qty":0.00000000},{"price":18.57726,"qty":31.87500000}],"checksum":2325888464,"timestamp":"2024-06-01T17:52:02.403954Z"}]}
{"channel":"book","type":"update","data":[{"symbol":"LINK/USD","bids":[],"asks":[{"price":18.57540,"qty":31.87500000}],"checksum":2834154782,"timestamp":"2024-06-01T17:52:02.404700Z"}]}
{"channel":"book","type":"update","data":[{"symbol":"LINK/USD","bids":[],"asks":[{"price":18.57540,"qty":0.00000000},{"price":18.57726,"qty":31.87500000}],"checksum":2325888464,"timestamp":"2024-06-01T17:52:02.407317Z"}]}
{"channel":"book","type":"update","data":[{"symbol":"LINK/USD","bids":[],"asks":[{"price":18.57538,"qty":13.46020950}],"checksum":2181154664,"timestamp":"2024-06-01T17:52:02.407559Z"}]}
{"channel":"book","type":"update","data":[{"symbol":"LINK/USD","bids":[{"price":18.56318,"qty":0.00000000},{"price":18.56059,"qty":33.00000000}],"asks":[],"checksum":394825670,"timestamp":"2024-06-01T17:52:02.408417Z"}]}
{"channel":"book","type":"update","data":[{"symbol":"LINK/USD","bids":[],"asks":[{"price":18.57538,"qty":0.00000000},{"price":18.57726,"qty":31.87500000}],"checksum":3645840011,"timestamp":"2024-06-01T17:52:02.410835Z"}]}
{"channel":"book","type":"update","data":[{"symbol":"LINK/USD","bids":[{"price":18.56609,"qty":3226.62813177}],"asks":[],"checksum":3997173901,"timestamp":"2024-06-01T17:52:02.412140Z"}]}
{"channel":"book","type":"update","data":[{"symbol":"LINK/USD","bids":[],"asks":[{"price":18.57693,"qty":0.00000000},{"price":18.57856,"qty":6.43107813}],"checksum":2851664158,"timestamp":"2024-06-01T17:52:02.430068Z"}]}
{"channel":"book","type":"update","data":[{"symbol":"LINK/USD","bids":[],"asks":[{"price":18.57856,"qty":0.00000000},{"price":18.57912,"qty":31.87500000}],"checksum":2760529913,"timestamp":"2024-06-01T17:52:02.430788Z"}]}
{"channel":"book","type":"update","data":[{"symbol":"LINK/USD","bids":[],"asks":[{"price":18.57650,"qty":0.00000000},{"price":18.58178,"qty":2.07095004}],"checksum":4189890127,"timestamp":"2024-06-01T17:52:02.455789Z"}]}
{"channel":"book","type":"update","data":[{"symbol":"LINK/USD","bids":[{"price":18.56130,"qty":459.82291200}],"asks":[],"checksum":3183055663,"timestamp":"2024-06-01T17:52:02.463656Z"}]}
{"channel":"book","type":"update","data":[{"symbol":"LINK/USD","bids":[],"asks":[{"price":18.57726,"qty":0.00000000},{"price":18.58283,"qty":1.50546674}],"checksum":305667559,"timestamp":"2024-06-01T17:52:02.493150Z"}]}
{"channel":"book","type":"update","data":[{"symbol":"LINK/USD","bids":[],"asks":[{"price":18.57651,"qty":0.00000000},{"price":18.58284,"qty":31.87500000}],"checksum":2578528880,"timestamp":"2024-06-01T17:52:02.528661Z"}]}
{"channel":"book","type":"update","data":[{"symbol":"LINK/USD","bids":[{"price":18.56178,"qty":28.60000000}],"asks":[],"checksum":1847997265,"timestamp":"2024-06-01T17:52:02.610367Z"}]}
{"channel":"book","type":"update","data":[{"symbol":"LINK/USD","bids":[{"price":18.56178,"qty":57.20000000}],"asks":[],"checksum":703616997,"timestamp":"2024-06-01T17:52:02.614644Z"}]}
{"channel":"book","type":"update","data":[{"symbol":"LINK/USD","bids":[],"asks":[{"price":18.58137,"qty":6.43107813}],"checksum":2906607047,"timestamp":"2024-06-01T17:52:02.627330Z"}]}
{"channel":"book","type":"update","data":[{"symbol":"LINK/USD","bids":[],"asks":[{"price":18.57869,"qty":21.53341917}],"checksum":3748973669,"timestamp":"2024-06-01T17:52:02.826902Z"}]}
{"channel":"book","type":"update","data":[{"symbol":"LINK/USD","bids":[],"asks":[{"price":18.57868,"qty":1.50546674}],"checksum":3502298883,"timestamp":"2024-06-01T17:52:02.830133Z"}]}
{"channel":"book","type":"update","data":[{"symbol":"LINK/USD","bids":[{"price":18.56379,"qty":0.00000000},{"price":18.56059,"qty":33.00000000}],"asks":[],"checksum":74035131,"timestamp":"2024-06-01T17:52:02.908582Z"}]}
{"channel":"book","type":"update","data":[{"symbol":"LINK/USD","bids":[{"price":18.56609,"qty":3309.75979676}],"asks":[],"checksum":4048446021,"timestamp":"2024-06-01T17:52:03.047383Z"}]}
{"channel":"book","type":"update","data":[{"symbol":"LINK/USD","bids":[{"price":18.56436,"qty":1.07668207}],"asks":[],"checksum":990634653,"timestamp":"2024-06-01T17:52:03.087677Z"}]}
{"channel":"book","type":"update","data":[{"symbol":"LINK/USD","bids":[],"asks":[{"price":18.57869,"qty":0.00000000},{"price":18.58178,"qty":2.07095004}],"checksum":3236178506,"timestamp":"2024-06-01T17:52:03.136218Z"}]}
{"channel":"book","type":"update","data":[{"symbol":"LINK/USD","bids":[],"asks":[{"price":18.57868,"qty":0.00000000},{"price":18.58284,"qty":31.87500000},{"price":18.58283,"qty":1.50546674}],"checksum":3272578834,"timestamp":"2024-06-01T17:52:03.139693Z"}]}
{"channel":"book","type":"update","data":[{"symbol":"LINK/USD","bids":[],"asks":[{"price":18.57465,"qty":13.46084094}],"checksum":4111421748,"timestamp":"2024-06-01T17:52:03.411571Z"}]}
{"channel":"book","type":"update","data":[{"symbol":"LINK/USD","bids":[],"asks":[{"price":18.57465,"qty":0.00000000},{"price":18.58283,"qty":1.50546674}],"checksum":3272578834,"timestamp":"2024-06-01T17:52:03.414047Z"}]}
{"channel":"book","type":"update","data":[{"symbol":"LINK/USD","bids":[],"asks":[{"price":18.57465,"qty":13.46086921}],"checksum":1474953071,"timestamp":"2024-06-01T17:52:03.417285Z"}]}
{"channel":"book","type":"update","data":[{"symbol":"LINK/USD","bids":[],"asks":[{"price":18.57911,"qty":1.50546674}],"checksum":152399909,"timestamp":"2024-06-01T17:52:03.439453Z"}]}
{"channel":"book","type":"update","data":[{"symbol":"LINK/USD","bids":[],"asks":[{"price":18.57873,"qty":21.53333760}],"checksum":3727673475,"timestamp":"2024-06-01T17:52:03.485020Z"}]}
{"channel":"book","type":"update","data":[{"symbol":"LINK/USD","bids":[],"asks":[{"price":18.57540,"qty":31.87500000}],"checksum":2774805495,"timestamp":"2024-06-01T17:52:03.490390Z"}]}
{"channel":"book","type":"update","data":[{"symbol":"LINK/USD","bids":[],"asks":[{"price":18.57911,"qty":0.00000000},{"price":18.57912,"qty":31.87500000},{"price":18.57872,"qty":1.50546674}],"checksum":1614571724,"timestamp":"2024-06-01T17:52:03.732851Z"}]}
{"channel":"book","type":"update","data":[{"symbol":"LINK/USD","bids":[{"price":18.56609,"qty":2970.72727357},{"price":18.56437,"qty":339.03252319}],"asks":[],"checksum":2871498558,"timestamp":"2024-06-01T17:52:04.510209Z"}]}
{"channel":"book","type":"update","data":[{"symbol":"LINK/USD","bids":[],"asks":[{"price":18.57851,"qty":80.73844756}],"checksum":667753563,"timestamp":"2024-06-01T17:52:04.631048Z"}]}
{"channel":"book","type":"update","data":[{"symbol":"LINK/USD","bids":[],"asks":[{"price":18.57872,"qty":0.00000000},{"price":18.57873,"qty":21.53333760},{"price":18.57850,"qty":1.50546674}],"checksum":1459766212,"timestamp":"2024-06-01T17:52:04.634819Z"}]}
{"channel":"book","type":"update","data":[{"symbol":"LINK/USD","bids":[],"asks":[{"price":18.57465,"qty":0.00000000},{"price":18.57873,"qty":21.53333760}],"checksum":757510459,"timestamp":"2024-06-01T17:52:05.302602Z"}]}
{"channel":"book","type":"update","data":[{"symbol":"LINK/USD","bids":[{"price":18.56609,"qty":2887.59560858}],"asks":[],"checksum":1522291306,"timestamp":"2024-06-01T17:52:05.331575Z"}]}
{"channel":"book","type":"update","data":[{"symbol":"LINK/USD","bids":[],"asks":[{"price":18.57850,"qty":0.00000000},{"price":18.57912,"qty":31.87500000},{"price":18.57539,"qty":1.50546674}],"checksum":2477342223,"timestamp":"2024-06-01T17:52:05.441591Z"}]}
{"channel":"book","type":"update","data":[{"symbol":"LINK/USD","bids":[],"asks":[{"price":18.57539,"qty":0.00000000},{"price":18.57912,"qty":31.87500000},{"price":18.57850,"qty":1.50546674}],"checksum":1522291306,"timestamp":"2024-06-01T17:52:05.469701Z"}]}
{"channel":"book","type":"update","data":[{"symbol":"LINK/USD","bids":[],"asks":[{"price":18.57851,"qty":0.00000000},{"price":18.57912,"qty":31.87500000}],"checksum":752606461,"timestamp":"2024-06-01T17:52:05.493872Z"}]}
{"channel":"book","type":"update","data":[{"symbol":"LINK/USD","bids":[],"asks":[{"price":18.57850,"qty":0.00000000},{"price":18.58178,"qty":2.07095004},{"price":18.57872,"qty":1.50546674}],"checksum":1811828715,"timestamp":"2024-06-01T17:52:05.497398Z"}]}
{"channel":"book","type":"update","data":[{"symbol":"LINK/USD","bids":[{"price":18.56436,"qty":0.00000000},{"price":18.56130,"qty":459.82291200}],"asks":[],"checksum":2451670309,"timestamp":"2024-06-01T17:52:05.498187Z"}]}
{"channel":"book","type":"update","data":[{"symbol":"LINK/USD","bids":[{"price":18.56438,"qty":10.69720415}],"asks":[],"checksum":660323147,"timestamp":"2024-06-01T17:52:05.506035Z"}]}
{"channel":"book","type":"update","data":[{"symbol":"LINK/USD","bids":[{"price":18.56491,"qty":83.13694890}],"asks":[],"checksum":121798148,"timestamp":"2024-06-01T17:52:05.538257Z"}]}
{"channel":"book","type":"update","data":[{"symbol":"LINK/USD","bids":[],"asks":[{"price":18.57753,"qty":6.43107813}],"checksum":2051910020,"timestamp":"2024-06-01T17:52:05.629234Z"}]}
{"channel":"book","type":"update","data":[{"symbol":"LINK/USD","bids":[],"asks":[{"price":18.57872,"qty":0.00000000},{"price":18.57912,"qty":31.87500000},{"price":18.57539,"qty":1.50546674}],"checksum":896350009,"timestamp":"2024-06-01T17:52:05.682594Z"}]}
{"channel":"book","type":"update","data":[{"symbol":"LINK/USD","bids":[],"asks":[{"price":18.57358,"qty":13.46243816}],"checksum":283446084,"timestamp":"2024-06-01T17:52:06.322087Z"}]}
{"channel":"book","type":"update","data":[{"symbol":"LINK/USD","bids":[],"asks":[{"price":18.57358,"qty":0.00000000},{"price":18.57873,"qty":21.53333760}],"checksum":896350009,"timestamp":"2024-06-01T17:52:06.325146Z"}]}
{"channel":"book","type":"update","data":[{"symbol":"LINK/USD","bids":[{"price":18.56437,"qty":0.00000000},{"price":18.56167,"qty":31.87500000},{"price":18.56401,"qty":339.03252319}],"asks":[],"checksum":2895128576,"timestamp":"2024-06-01T17:52:06.325431Z"}]}
{"channel":"book","type":"update","data":[{"symbol":"LINK/USD","bids":[],"asks":[{"price":18.57358,"qty":13.46224502}],"checksum":2122462792,"timestamp":"2024-06-01T17:52:06.328515Z"}]}
{"channel":"book","type":"update","data":[{"symbol":"LINK/USD","bids":[],"asks":[{"price":18.57539,"qty":0.00000000},{"price":18.57873,"qty":21.53333760},{"price":18.57872,"qty":1.50546674}],"checksum":3504071300,"timestamp":"2024-06-01T17:52:06.334700Z"}]}
{"channel":"book","type":"update","data":[{"symbol":"LINK/USD","bids":[],"asks":[{"price":18.57358,"qty":0.00000000},{"price":18.57873,"qty":21.53333760}],"checksum":3820009149,"timestamp":"2024-06-01T17:52:06.549485Z"}]}
{"channel":"book","type":"update","data":[{"symbol":"LINK/USD","bids":[{"price":18.56400,"qty":0.00000000},{"price":18.56167,"qty":31.87500000}],"asks":[],"checksum":4207056638,"timestamp":"2024-06-01T17:52:06.554867Z"}]}
{"channel":"book","type":"update","data":[{"symbol":"LINK/USD","bids":[{"price":18.56609,"qty":2618.32229390}],"asks":[],"checksum":2571078069,"timestamp":"2024-06-01T17:52:06.555185Z"}]}
{"channel":"book","type":"update","data":[{"symbol":"LINK/USD","bids":[{"price":18.56609,"qty":1541.25801112}],"asks":[],"checksum":905125633,"timestamp":"2024-06-01T17:52:06.555384Z"}]}
{"channel":"book","type":"update","data":[{"symbol":"LINK/USD","bids":[{"price":18.56435,"qty":0.00000000},{"price":18.56131,"qty":21.27978704}],"asks":[],"checksum":3175832768,"timestamp":"2024-06-01T17:52:06.557096Z"}]}
{"channel":"book","type":"update","data":[{"symbol":"LINK/USD","bids":[],"asks":[{"price":18.57653,"qty":80.74708771}],"checksum":1467705275,"timestamp":"2024-06-01T17:52:06.559743Z"}]}
{"channel":"book","type":"update","data":[{"symbol":"LINK/USD","bids":[{"price":18.56300,"qty":75.50096561}],"asks":[],"checksum":3778589090,"timestamp":"2024-06-01T17:52:06.559909Z"}]}
{"channel":"book","type":"update","data":[{"symbol":"LINK/USD","bids":[],"asks":[{"price":18.57726,"qty":31.87500000}],"checksum":2239030826,"timestamp":"2024-06-01T17:52:06.569253Z"}]}
{"channel":"book","type":"update","data":[{"symbol":"LINK/USD","bids":[{"price":18.56609,"qty":1137.29573366}],"asks":[],"checksum":2451003429,"timestamp":"2024-06-01T17:52:06.569460Z"}]}
{"channel":"book","type":"update","data":[{"symbol":"LINK/USD","bids":[],"asks":[{"price":18.57653,"qty":0.00000000},{"price":18.57872,"qty":1.50546674}],"checksum":2433236766,"timestamp":"2024-06-01T17:52:06.569498Z"}]}
{"channel":"book","type":"update","data":[{"symbol":"LINK/USD","bids":[{"price":18.56319,"qty":404.02534940}],"asks":[],"checksum":2786145569,"timestamp":"2024-06-01T17:52:06.573744Z"}]}
{"channel":"book","type":"update","data":[{"symbol":"LINK/USD","bids":[{"price":18.56428,"qty":269.21827019}],"asks":[],"checksum":1527375105,"timestamp":"2024-06-01T17:52:06.573808Z"}]}
{"channel":"book","type":"update","data":[{"symbol":"LINK/USD","bids":[{"price":18.56335,"qty":269.21827019}],"asks":[],"checksum":938063841,"timestamp":"2024-06-01T17:52:06.574176Z"}]}
{"channel":"book","type":"update","data":[{"symbol":"LINK/USD","bids":[{"price":18.56491,"qty":0.00000000},{"price":18.56300,"qty":75.50096561}],"asks":[],"checksum":2263547959,"timestamp":"2024-06-01T17:52:06.578721Z"}]}
{"channel":"book","type":"update","data":[{"symbol":"LINK/USD","bids":[],"asks":[{"price":18.57465,"qty":33.00000000}],"checksum":3863514185,"timestamp":"2024-06-01T17:52:06.580640Z"}]}
{"channel":"book","type":"update","data":[{"symbol":"LINK/USD","bids":[{"price":18.56428,"qty":0.00000000},{"price":18.56178,"qty":57.20000000}],"asks":[],"checksum":1004491498,"timestamp":"2024-06-01T17:52:06.595785Z"}]}
{"channel":"book","type":"update","data":[{"symbol":"LINK/USD","bids":[],"asks":[{"price":18.57464,"qty":1.50546674}],"checksum":1784837206,"timestamp":"2024-06-01T17:52:06.633020Z"}]}
{"channel":"book","type":"update","data":[{"symbol":"LINK/USD","bids":[],"asks":[{"price":18.57465,"qty":0.00000000},{"price":18.57753,"qty":6.43107813}],"checksum":434962179,"timestamp":"2024-06-01T17:52:06.635821Z"}]}
{"channel":"book","type":"update","data":[{"symbol":"LINK/USD","bids":[],"asks":[{"price":18.57413,"qty":33.00000000}],"checksum":2205345215,"timestamp":"2024-06-01T17:52:06.635883Z"}]}
{"channel":"book","type":"update","data":[{"symbol":"LINK/USD","bids":[],"asks":[{"price":18.57464,"qty":0.00000000},{"price":18.57753,"qty":6.43107813},{"price":18.57539,"qty":1.50546674}],"checksum":4119038441,"timestamp":"2024-06-01T17:52:06.639026Z"}]}
{"channel":"book","type":"update","data":[{"symbol":"LINK/USD","bids":[{"price":18.56339,"qty":83.14375628}],"asks":[],"checksum":3120483763,"timestamp":"2024-06-01T17:52:06.699360Z"}]}
{"channel":"book","type":"update","data":[{"symbol":"LINK/USD","bids":[{"price":18.56300,"qty":0.00000000},{"price":18.56178,"qty":57.20000000}],"asks":[],"checksum":953346502,"timestamp":"2024-06-01T17:52:06.752777Z"}]}
{"channel":"book","type":"update","data":[{"symbol":"LINK/USD","bids":[{"price":18.56300,"qty":75.50096561}],"asks":[],"checksum":3120483763,"timestamp":"2024-06-01T17:52:06.757815Z"}]}
{"channel":"book","type":"update","data":[{"symbol":"LINK/USD","bids":[{"price":18.56339,"qty":0.00000000},{"price":18.56178,"qty":57.20000000}],"asks":[],"checksum":4119038441,"timestamp":"2024-06-01T17:52:06.775885Z"}]}
{"channel":"book","type":"update","data":[{"symbol":"LINK/USD","bids":[{"price":18.56466,"qty":269.21827019}],"asks":[],"checksum":686615905,"timestamp":"2024-06-01T17:52:06.830222Z"}]}
{"channel":"book","type":"update","data":[{"symbol":"LINK/USD","bids":[],"asks":[{"price":18.57473,"qty":80.75491364}],"checksum":1710748718,"timestamp":"2024-06-01T17:52:06.873265Z"}]}
{"channel":"book","type":"update","data":[{"symbol":"LINK/USD","bids":[{"price":18.56351,"qty":83.14321882}],"asks":[],"checksum":3377276564,"timestamp":"2024-06-01T17:52:06.897557Z"}]}
{"channel":"book","type":"update","data":[{"symbol":"LINK/USD","bids":[],"asks":[{"price":18.57539,"qty":0.00000000},{"price":18.57726,"qty":31.87500000},{"price":18.57412,"qty":1.50546674}],"checksum":2849357409,"timestamp":"2024-06-01T17:52:06.964710Z"}]}
{"channel":"book","type":"update","data":[{"symbol":"LINK/USD","bids":[],"asks":[{"price":18.57413,"qty":0.00000000},{"price":18.57726,"qty":31.87500000}],"checksum":4104125255,"timestamp":"2024-06-01T17:52:06.967550Z"}]}
{"channel":"book","type":"update","data":[{"symbol":"LINK/USD","bids":[],"asks":[{"price":18.57308,"qty":33.00000000}],"checksum":859060893,"timestamp":"2024-06-01T17:52:06.967709Z"}]}
{"channel":"book","type":"update","data":[{"symbol":"LINK/USD","bids":[],"asks":[{"price":18.57412,"qty":0.00000000},{"price":18.57726,"qty":31.87500000},{"price":18.57472,"qty":1.50546674}],"checksum":2531200963,"timestamp":"2024-06-01T17:52:06.971010Z"}]}
{"channel":"book","type":"update","data":[{"symbol":"LINK/USD","bids":[],"asks":[{"price":18.57354,"qty":31.87500000}],"checksum":1614805932,"timestamp":"2024-06-01T17:52:06.977094Z"}]}
{"channel":"book","type":"update","data":[{"symbol":"LINK/USD","bids":[],"asks":[{"price":18.57472,"qty":0.00000000},{"price":18.57685,"qty":1.31717222},{"price":18.57307,"qty":1.50546674}],"checksum":3842808507,"timestamp":"2024-06-01T17:52:07.363634Z"}]}
{"channel":"book","type":"update","data":[{"symbol":"LINK/USD","bids":[{"price":18.56609,"qty":1406.54297183}],"asks":[],"checksum":3349021784,"timestamp":"2024-06-01T17:52:07.381212Z"}]}
{"channel":"book","type":"update","data":[{"symbol":"LINK/USD","bids":[{"price":18.56335,"qty":0.00000000},{"price":18.56300,"qty":75.50096561}],"asks":[],"checksum":589895825,"timestamp":"2024-06-01T17:52:07.385269Z"}]}
{"channel":"book","type":"update","data":[{"symbol":"LINK/USD","bids":[],"asks":[{"price":18.57185,"qty":13.46413748}],"checksum":4191641115,"timestamp":"2024-06-01T17:52:07.578649Z"}]}
{"channel":"book","type":"update","data":[{"symbol":"LINK/USD","bids":[],"asks":[{"price":18.57308,"qty":0.00000000},{"price":18.57540,"qty":31.87500000}],"checksum":207805457,"timestamp":"2024-06-01T17:52:07.581410Z"}]}
{"channel":"book","type":"update","data":[{"symbol":"LINK/USD","bids":[],"asks":[{"price":18.57262,"qty":33.00000000}],"checksum":2647855258,"timestamp":"2024-06-01T17:52:07.581613Z"}]}
{"channel":"book","type":"update","data":[{"symbol":"LINK/USD","bids":[],"asks":[{"price":18.57307,"qty":0.00000000},{"price":18.57540,"qty":31.87500000},{"price":18.57353,"qty":1.50546674}],"checksum":1735915735,"timestamp":"2024-06-01T17:52:07.585000Z"}]}
{"channel":"book","type":"update","data":[{"symbol":"LINK/USD","bids":[],"asks":[{"price":18.57353,"qty":0.00000000},{"price":18.57540,"qty":31.87500000},{"price":18.57472,"qty":1.50546674}],"checksum":1376196797,"timestamp":"2024-06-01T17:52:07.587685Z"}]}
{"channel":"book","type":"update","data":[{"symbol":"LINK/USD","bids":[{"price":18.56600,"qty":1076.98895266}],"asks":[],"checksum":3798095361,"timestamp":"2024-06-01T17:52:07.852438Z"}]}
{"channel":"book","type":"update","data":[{"symbol":"LINK/USD","bids":[{"price":18.56401,"qty":0.00000000},{"price":18.56300,"qty":75.50096561}],"asks":[],"checksum":1341097091,"timestamp":"2024-06-01T17:52:07.855950Z"}]}
{"channel":"book","type":"update","data":[{"symbol":"LINK/USD","bids":[],"asks":[{"price":18.57354,"qty":0.00000000},{"price":18.57540,"qty":31.87500000}],"checksum":190759289,"timestamp":"2024-06-01T17:52:08.089079Z"}]}
{"channel":"book","type":"update","data":[{"symbol":"LINK/USD","bids":[],"asks":[{"price":18.57340,"qty":33.00000000}],"checksum":314883168,"timestamp":"2024-06-01T17:52:08.187453Z"}]}
{"channel":"book","type":"update","data":[{"symbol":"LINK/USD","bids":[],"asks":[{"price":18.57262,"qty":0.00000000},{"price":18.57540,"qty":31.87500000}],"checksum":2230381674,"timestamp":"2024-06-01T17:52:08.187477Z"}]}
{"channel":"book","type":"update","data":[{"symbol":"LINK/USD","bids":[],"asks":[{"price":18.57472,"qty":0.00000000},{"price":18.57685,"qty":1.31717222},{"price":18.57339,"qty":1.50546674}],"checksum":280214956,"timestamp":"2024-06-01T17:52:08.190723Z"}]}
{"channel":"book","type":"update","data":[{"symbol":"LINK/USD","bids":[{"price":18.56438,"qty":0.00000000},{"price":18.56167,"qty":31.87500000}],"asks":[],"checksum":3106096446,"timestamp":"2024-06-01T17:52:08.211788Z"}]}
{"channel":"book","type":"update","data":[{"symbol":"LINK/USD","bids":[],"asks":[{"price":18.57340,"qty":0.00000000},{"price":18.57685,"qty":1.31717222}],"checksum":3685625151,"timestamp":"2024-06-01T17:52:08.253657Z"}]}
{"channel":"book","type":"update","data":[{"symbol":"LINK/USD","bids":[],"asks":[{"price":18.57339,"qty":0.00000000},{"price":18.57726,"qty":31.87500000},{"price":18.57472,"qty":1.50546674}],"checksum":2097261737,"timestamp":"2024-06-01T17:52:08.256996Z"}]}
{"channel":"book","type":"update","data":[{"symbol":"LINK/USD","bids":[],"asks":[{"price":18.57685,"qty":7.74825035}],"checksum":3620978043,"timestamp":"2024-06-01T17:52:08.429502Z"}]}
{"channel":"book","type":"update","data":[{"symbol":"LINK/USD","bids":[{"price":18.56609,"qty":2483.53192449}],"asks":[],"checksum":1905221443,"timestamp":"2024-06-01T17:52:09.351800Z"}]}
{"channel":"book","type":"update","data":[{"symbol":"LINK/USD","bids":[{"price":18.56351,"qty":0.00000000},{"price":18.56130,"qty":186.96555600}],"asks":[],"checksum":1818303928,"timestamp":"2024-06-01T17:52:09.509030Z"}]}
{"channel":"book","type":"update","data":[{"symbol":"LINK/USD","bids":[{"price":18.56392,"qty":83.14138253}],"asks":[],"checksum":4096159693,"timestamp":"2024-06-01T17:52:09.628622Z"}]}
{"channel":"book","type":"update","data":[{"symbol":"LINK/USD","bids":[],"asks":[{"price":18.57353,"qty":33.00000000}],"checksum":470541635,"timestamp":"2024-06-01T17:52:10.219216Z"}]}
{"channel":"book","type":"update","data":[{"symbol":"LINK/USD","bids":[],"asks":[{"price":18.57354,"qty":31.87500000}],"checksum":1488625849,"timestamp":"2024-06-01T17:52:10.224857Z"}]}
{"channel":"book","type":"update","data":[{"symbol":"LINK/USD","bids":[],"asks":[{"price":18.57472,"qty":0.00000000},{"price":18.57540,"qty":31.87500000},{"price":18.57352,"qty":1.50546674}],"checksum":118467322,"timestamp":"2024-06-01T17:52:10.228240Z"}]}
{"channel":"book","type":"update","data":[{"symbol":"LINK/USD","bids":[],"asks":[{"price":18.57353,"qty":0.00000000},{"price":18.57540,"qty":31.87500000}],"checksum":794765788,"timestamp":"2024-06-01T17:52:10.230839Z"}]}
{"channel":"book","type":"update","data":[{"symbol":"LINK/USD","bids":[],"asks":[{"price":18.57315,"qty":33.00000000}],"checksum":385918669,"timestamp":"2024-06-01T17:52:10.231013Z"}]}
{"channel":"book","type":"update","data":[{"symbol":"LINK/USD","bids":[],"asks":[{"price":18.57352,"qty":0.00000000},{"price":18.57540,"qty":31.87500000},{"price":18.57472,"qty":1.50546674}],"checksum":2144308936,"timestamp":"2024-06-01T17:52:10.234388Z"}]}
{"channel":"book","type":"update","data":[{"symbol":"LINK/USD","bids":[{"price":18.56300,"qty":0.00000000},{"price":18.56130,"qty":186.96555600}],"asks":[],"checksum":1669115173,"timestamp":"2024-06-01T17:52:11.421652Z"}]}
{"channel":"book","type":"update","data":[{"symbol":"LINK/USD","bids":[{"price":18.56200,"qty":75.50503312}],"asks":[],"checksum":3746769054,"timestamp":"2024-06-01T17:52:11.426579Z"}]}
{"channel":"book","type":"update","data":[{"symbol":"LINK/USD","bids":[],"asks":[{"price":18.57472,"qty":0.00000000},{"price":18.57540,"qty":31.87500000},{"price":18.57314,"qty":1.50546674}],"checksum":4130186268,"timestamp":"2024-06-01T17:52:11.444693Z"}]}
{"channel":"book","type":"update","data":[{"symbol":"LINK/USD","bids":[],"asks":[{"price":18.57315,"qty":0.00000000},{"price":18.57540,"qty":31.87500000}],"checksum":2830541307,"timestamp":"2024-06-01T17:52:11.447494Z"}]}
{"channel":"book","type":"update","data":[{"symbol":"LINK/USD","bids":[],"asks":[{"price":18.57290,"qty":33.00000000}],"checksum":3997583670,"timestamp":"2024-06-01T17:52:11.447659Z"}]}
{"channel":"book","type":"update","data":[{"symbol":"LINK/USD","bids":[],"asks":[{"price":18.57314,"qty":0.00000000},{"price":18.57540,"qty":31.87500000},{"price":18.57353,"qty":1.50546674}],"checksum":1008519381,"timestamp":"2024-06-01T17:52:11.450722Z"}]}
{"channel":"book","type":"update","data":[{"symbol":"LINK/USD","bids":[],"asks":[{"price":18.57353,"qty":0.00000000},{"price":18.57540,"qty":31.87500000},{"price":18.57289,"qty":1.50546674}],"checksum":1195707632,"timestamp":"2024-06-01T17:52:11.762220Z"}]}
{"channel":"book","type":"update","data":[{"symbol":"LINK/USD","bids":[{"price":18.56600,"qty":0.00000000},{"price":18.56130,"qty":186.96555600}],"asks":[],"checksum":338799951,"timestamp":"2024-06-01T17:52:12.476460Z"}]}
{"channel":"book","type":"update","data":[{"symbol":"LINK/USD","bids":[{"price":18.56609,"qty":1406.54297183}],"asks":[],"checksum":4102353642,"timestamp":"2024-06-01T17:52:12.477081Z"}]}
{"channel":"book","type":"update","data":[{"symbol":"LINK/USD","bids":[],"asks":[{"price":18.57290,"qty":0.00000000},{"price":18.57540,"qty":31.87500000}],"checksum":3267955599,"timestamp":"2024-06-01T17:52:12.479872Z"}]}
{"channel":"book","type":"update","data":[{"symbol":"LINK/USD","bids":[],"asks":[{"price":18.57289,"qty":34.50546674}],"checksum":3490988701,"timestamp":"2024-06-01T17:52:12.480275Z"}]}
{"channel":"book","type":"update","data":[{"symbol":"LINK/USD","bids":[],"asks":[{"price":18.57289,"qty":33.00000000},{"price":18.57353,"qty":1.50546674}],"checksum":3857156716,"timestamp":"2024-06-01T17:52:12.483295Z"}]}
{"channel":"book","type":"update","data":[{"symbol":"LINK/USD","bids":[],"asks":[{"price":18.57353,"qty":0.00000000},{"price":18.57540,"qty":31.87500000},{"price":18.57288,"qty":1.50546674}],"checksum":348079390,"timestamp":"2024-06-01T17:52:12.824159Z"}]}
{"channel":"book","type":"update","data":[{"symbol":"LINK/USD","bids":[],"asks":[{"price":18.57398,"qty":21.53885401}],"checksum":4255782462,"timestamp":"2024-06-01T17:52:13.634332Z"}]}
{"channel":"book","type":"update","data":[{"symbol":"LINK/USD","bids":[],"asks":[{"price":18.57354,"qty":0.00000000},{"price":18.57473,"qty":80.75491364}],"checksum":1031027906,"timestamp":"2024-06-01T17:52:14.103848Z"}]}
{"channel":"book","type":"update","data":[{"symbol":"LINK/USD","bids":[],"asks":[{"price":18.57354,"qty":31.87500000}],"checksum":4255782462,"timestamp":"2024-06-01T17:52:14.186746Z"}]}
{"channel":"book","type":"update","data":[{"symbol":"LINK/USD","bids":[],"asks":[{"price":18.57354,"qty":0.00000000},{"price":18.57473,"qty":80.75491364}],"checksum":1031027906,"timestamp":"2024-06-01T17:52:14.489241Z"}]}
{"channel":"book","type":"update","data":[{"symbol":"LINK/USD","bids":[{"price":18.56609,"qty":1206.54297183}],"asks":[],"checksum":3214921051,"timestamp":"2024-06-01T17:52:14.704630Z"}]}
{"channel":"book","type":"update","data":[{"symbol":"LINK/USD","bids":[],"asks":[{"price":18.57354,"qty":31.87500000}],"checksum":2135025575,"timestamp":"2024-06-01T17:52:14.704902Z"}]}
{"channel":"book","type":"update","data":[{"symbol":"LINK/USD","bids":[{"price":18.56200,"qty":0.00000000},{"price":18.56112,"qty":339.03252319}],"asks":[],"checksum":548570627,"timestamp":"2024-06-01T17:52:14.705611Z"}]}
{"channel":"book","type":"update","data":[{"symbol":"LINK/USD","bids":[{"price":18.56200,"qty":75.50503312}],"asks":[],"checksum":2135025575,"timestamp":"2024-06-01T17:52:14.710336Z"}]}
{"channel":"book","type":"update","data":[{"symbol":"LINK/USD","bids":[{"price":18.56609,"qty":1406.54297183}],"asks":[],"checksum":4255782462,"timestamp":"2024-06-01T17:52:14.891873Z"}]}
{"channel":"book","type":"update","data":[{"symbol":"LINK/USD","bids":[],"asks":[{"price":18.57354,"qty":0.00000000},{"price":18.57473,"qty":80.75491364}],"checksum":1031027906,"timestamp":"2024-06-01T17:52:15.354124Z"}]}
{"channel":"book","type":"update","data":[{"symbol":"LINK/USD","bids":[],"asks":[{"price":18.57354,"qty":31.87500000}],"checksum":4255782462,"timestamp":"2024-06-01T17:52:15.389713Z"}]}
{"channel":"book","type":"update","data":[{"symbol":"LINK/USD","bids":[],"asks":[{"price":18.57354,"qty":0.00000000},{"price":18.57473,"qty":80.75491364}],"checksum":1031027906,"timestamp":"2024-06-01T17:52:15.396940Z"}]}
{"channel":"book","type":"update","data":[{"symbol":"LINK/USD","bids":[],"asks":[{"price":18.57289,"qty":0.00000000},{"price":18.57540,"qty":31.87500000}],"checksum":1812648272,"timestamp":"2024-06-01T17:52:15.418029Z"}]}
{"channel":"book","type":"update","data":[{"symbol":"LINK/USD","bids":[],"asks":[{"price":18.57288,"qty":0.00000000},{"price":18.57685,"qty":7.74825035},{"price":18.57397,"qty":1.50546674}],"checksum":152619087,"timestamp":"2024-06-01T17:52:15.421240Z"}]}
{"channel":"book","type":"update","data":[{"symbol":"LINK/USD","bids":[],"asks":[{"price":18.57398,"qty":0.00000000},{"price":18.57685,"qty":7.74825035}],"checksum":4261215106,"timestamp":"2024-06-01T17:52:15.577573Z"}]}
{"channel":"book","type":"update","data":[{"symbol":"LINK/USD","bids":[],"asks":[{"price":18.57397,"qty":0.00000000},{"price":18.57726,"qty":31.87500000},{"price":18.57472,"qty":1.50546674}],"checksum":1742327794,"timestamp":"2024-06-01T17:52:15.581324Z"}]}
{"channel":"book","type":"update","data":[{"symbol":"LINK/USD","bids":[],"asks":[{"price":18.57353,"qty":33.00000000}],"checksum":4068962997,"timestamp":"2024-06-01T17:52:15.684283Z"}]}
{"channel":"book","type":"update","data":[{"symbol":"LINK/USD","bids":[],"asks":[{"price":18.57472,"qty":0.00000000},{"price":18.57685,"qty":7.74825035},{"price":18.57352,"qty":1.50546674}],"checksum":581969949,"timestamp":"2024-06-01T17:52:15.687572Z"}]}
{"channel":"book","type":"update","data":[{"symbol":"LINK/USD","bids":[],"asks":[{"price":18.57354,"qty":31.87500000}],"checksum":4151161056,"timestamp":"2024-06-01T17:52:15.689775Z"}]}
{"channel":"book","type":"update","data":[{"symbol":"LINK/USD","bids":[],"asks":[{"price":18.57353,"qty":0.00000000},{"price":18.57540,"qty":31.87500000}],"checksum":2773879000,"timestamp":"2024-06-01T17:52:15.767151Z"}]}
{"channel":"book","type":"update","data":[{"symbol":"LINK/USD","bids":[],"asks":[{"price":18.57336,"qty":33.00000000}],"checksum":4094997474,"timestamp":"2024-06-01T17:52:15.767488Z"}]}
{"channel":"book","type":"update","data":[{"symbol":"LINK/USD","bids":[],"asks":[{"price":18.57352,"qty":0.00000000},{"price":18.57540,"qty":31.87500000},{"price":18.57353,"qty":1.50546674}],"checksum":3556748890,"timestamp":"2024-06-01T17:52:15.770684Z"}]}
{"channel":"book","type":"update","data":[{"symbol":"LINK/USD","bids":[],"asks":[{"price":18.57391,"qty":21.53875074}],"checksum":3147047009,"timestamp":"2024-06-01T17:52:15.901743Z"}]}
{"channel":"book","type":"update","data":[{"symbol":"LINK/USD","bids":[],"asks":[{"price":18.57353,"qty":0.00000000},{"price":18.57473,"qty":80.75491364},{"price":18.57335,"qty":1.50546674}],"checksum":419189123,"timestamp":"2024-06-01T17:52:15.932445Z"}]}
{"channel":"book","type":"update","data":[{"symbol":"LINK/USD","bids":[],"asks":[{"price":18.57336,"qty":0.00000000},{"price":18.57473,"qty":80.75491364}],"checksum":150493602,"timestamp":"2024-06-01T17:52:15.935393Z"}]}
{"channel":"book","type":"update","data":[{"symbol":"LINK/USD","bids":[],"asks":[{"price":18.57327,"qty":33.00000000}],"checksum":2286287600,"timestamp":"2024-06-01T17:52:15.935779Z"}]}
{"channel":"book","type":"update","data":[{"symbol":"LINK/USD","bids":[],"asks":[{"price":18.57335,"qty":0.00000000},{"price":18.57473,"qty":80.75491364},{"price":18.57353,"qty":1.50546674}],"checksum":2833276521,"timestamp":"2024-06-01T17:52:15.938542Z"}]}
{"channel":"book","type":"update","data":[{"symbol":"LINK/USD","bids":[],"asks":[{"price":18.57353,"qty":0.00000000},{"price":18.57473,"qty":80.75491364},{"price":18.57326,"qty":1.50546674}],"checksum":3148985339,"timestamp":"2024-06-01T17:52:16.244746Z"}]}
{"channel":"book","type":"update","data":[{"symbol":"LINK/USD","bids":[],"asks":[{"price":18.57391,"qty":0.00000000},{"price":18.57473,"qty":80.75491364}],"checksum":3554295232,"timestamp":"2024-06-01T17:52:16.441658Z"}]}
{"channel":"book","type":"update","data":[{"symbol":"LINK/USD","bids":[],"asks":[{"price":18.57354,"qty":0.00000000},{"price":18.57540,"qty":31.87500000}],"checksum":101164349,"timestamp":"2024-06-01T17:52:16.507674Z"}]}
{"channel":"book","type":"update","data":[{"symbol":"LINK/USD","bids":[],"asks":[{"price":18.57327,"qty":0.00000000},{"price":18.57685,"qty":7.74825035}],"checksum":1555348584,"timestamp":"2024-06-01T17:52:16.582134Z"}]}
{"channel":"book","type":"update","data":[{"symbol":"LINK/USD","bids":[],"asks":[{"price":18.57325,"qty":33.00000000}],"checksum":2733455628,"timestamp":"2024-06-01T17:52:16.582175Z"}]}
{"channel":"book","type":"update","data":[{"symbol":"LINK/USD","bids":[],"asks":[{"price":18.57326,"qty":0.00000000},{"price":18.57685,"qty":7.74825035},{"price":18.57472,"qty":1.50546674}],"checksum":2049808901,"timestamp":"2024-06-01T17:52:16.585408Z"}]}
{"channel":"book","type":"update","data":[{"symbol":"LINK/USD","bids":[],"asks":[{"price":18.57354,"qty":31.87500000}],"checksum":3477410665,"timestamp":"2024-06-01T17:52:16.610978Z"}]}
{"channel":"book","type":"update","data":[{"symbol":"LINK/USD","bids":[],"asks":[{"price":18.57472,"qty":0.00000000},{"price":18.57540,"qty":31.87500000},{"price":18.57324,"qty":1.50546674}],"checksum":3106847126,"timestamp":"2024-06-01T17:52:16.624400Z"}]}
{"channel":"book","type":"update","data":[{"symbol":"LINK/USD","bids":[],"asks":[{"price":18.57407,"qty":21.53875075}],"checksum":108266356,"timestamp":"2024-06-01T17:52:16.746764Z"}]}
{"channel":"book","type":"update","data":[{"symbol":"LINK/USD","bids":[],"asks":[{"price":18.57354,"qty":0.00000000},{"price":18.57473,"qty":80.75491364}],"checksum":1517201655,"timestamp":"2024-06-01T17:52:17.019866Z"}]}
{"channel":"book","type":"update","data":[{"symbol":"LINK/USD","bids":[],"asks":[{"price":18.57354,"qty":31.87500000}],"checksum":108266356,"timestamp":"2024-06-01T17:52:17.024458Z"}]}
{"channel":"book","type":"update","data":[{"symbol":"LINK/USD","bids":[],"asks":[{"price":18.57325,"qty":0.00000000},{"price":18.57473,"qty":80.75491364}],"checksum":459368948,"timestamp":"2024-06-01T17:52:17.067460Z"}]}
{"channel":"book","type":"update","data":[{"symbol":"LINK/USD","bids":[],"asks":[{"price":18.57321,"qty":33.00000000}],"checksum":4072695489,"timestamp":"2024-06-01T17:52:17.067614Z"}]}
{"channel":"book","type":"update","data":[{"symbol":"LINK/USD","bids":[],"asks":[{"price":18.57324,"qty":0.00000000},{"price":18.57473,"qty":80.75491364},{"price":18.57353,"qty":1.50546674}],"checksum":806555459,"timestamp":"2024-06-01T17:52:17.070639Z"}]}
{"channel":"book","type":"update","data":[{"symbol":"LINK/USD","bids":[],"asks":[{"price":18.57353,"qty":0.00000000},{"price":18.57473,"qty":80.75491364},{"price":18.57320,"qty":1.50546674}],"checksum":3550284760,"timestamp":"2024-06-01T17:52:17.074874Z"}]}
{"channel":"book","type":"update","data":[{"symbol":"LINK/USD","bids":[],"asks":[{"price":18.57354,"qty":0.00000000},{"price":18.57473,"qty":80.75491364}],"checksum":2408030299,"timestamp":"2024-06-01T17:52:17.083487Z"}]}
{"channel":"book","type":"update","data":[{"symbol":"LINK/USD","bids":[],"asks":[{"price":18.57407,"qty":0.00000000},{"price":18.57540,"qty":31.87500000}],"checksum":3105499591,"timestamp":"2024-06-01T17:52:17.168688Z"}]}
{"channel":"book","type":"update","data":[{"symbol":"LINK/USD","bids":[],"asks":[{"price":18.57320,"qty":0.00000000},{"price":18.57685,"qty":1.31717222},{"price":18.57472,"qty":1.50546674}],"checksum":257023143,"timestamp":"2024-06-01T17:52:17.171901Z"}]}
{"channel":"book","type":"update","data":[{"symbol":"LINK/USD","bids":[],"asks":[{"price":18.57457,"qty":21.53798274}],"checksum":159567758,"timestamp":"2024-06-01T17:52:17.480618Z"}]}
{"channel":"book","type":"update","data":[{"symbol":"LINK/USD","bids":[],"asks":[{"price":18.57472,"qty":0.00000000},{"price":18.57540,"qty":31.87500000},{"price":18.57456,"qty":1.50546674}],"checksum":2827792943,"timestamp":"2024-06-01T17:52:17.512302Z"}]}
{"channel":"book","type":"update","data":[{"symbol":"LINK/USD","bids":[{"price":18.56392,"qty":0.00000000},{"price":18.56112,"qty":339.03252319}],"asks":[],"checksum":1248653812,"timestamp":"2024-06-01T17:52:18.281848Z"}]}
{"channel":"book","type":"update","data":[{"symbol":"LINK/USD","bids":[],"asks":[{"price":18.57354,"qty":31.87500000}],"checksum":508601643,"timestamp":"2024-06-01T17:52:18.320736Z"}]}
{"channel":"book","type":"update","data":[{"symbol":"LINK/USD","bids":[],"asks":[{"price":18.57456,"qty":0.00000000},{"price":18.57473,"qty":80.75491364},{"price":18.57320,"qty":1.50546674}],"checksum":251958957,"timestamp":"2024-06-01T17:52:18.323773Z"}]}
{"channel":"book","type":"update","data":[{"symbol":"LINK/USD","bids":[],"asks":[{"price":18.57321,"qty":0.00000000},{"price":18.57473,"qty":80.75491364}],"checksum":818281453,"timestamp":"2024-06-01T17:52:18.326377Z"}]}
{"channel":"book","type":"update","data":[{"symbol":"LINK/USD","bids":[],"asks":[{"price":18.57312,"qty":33.00000000}],"checksum":3632409050,"timestamp":"2024-06-01T17:52:18.326581Z"}]}
{"channel":"book","type":"update","data":[{"symbol":"LINK/USD","bids":[],"asks":[{"price":18.57320,"qty":0.00000000},{"price":18.57473,"qty":80.75491364},{"price":18.57353,"qty":1.50546674}],"checksum":2070107825,"timestamp":"2024-06-01T17:52:18.329582Z"}]}
{"channel":"book","type":"update","data":[{"symbol":"LINK/USD","bids":[{"price":18.56385,"qty":83.14169604}],"asks":[],"checksum":4280351242,"timestamp":"2024-06-01T17:52:18.403761Z"}]}
{"channel":"book","type":"update","data":[{"symbol":"LINK/USD","bids":[],"asks":[{"price":18.57354,"qty":0.00000000},{"price":18.57473,"qty":80.75491364}],"checksum":1792141473,"timestamp":"2024-06-01T17:52:18.472903Z"}]}
{"channel":"book","type":"update","data":[{"symbol":"LINK/USD","bids":[],"asks":[{"price":18.57353,"qty":0.00000000},{"price":18.57540,"qty":31.87500000},{"price":18.57456,"qty":1.50546674}],"checksum":2878722748,"timestamp":"2024-06-01T17:52:18.476219Z"}]}
{"channel":"book","type":"update","data":[{"symbol":"LINK/USD","bids":[{"price":18.56609,"qty":2483.53771874}],"asks":[],"checksum":3279578841,"timestamp":"2024-06-01T17:52:20.975574Z"}]}
{"channel":"book","type":"update","data":[{"symbol":"LINK/USD","bids":[],"asks":[{"price":18.57312,"qty":0.00000000},{"price":18.57627,"qty":6.43107813}],"checksum":1185910655,"timestamp":"2024-06-01T17:52:20.978476Z"}]}
{"channel":"book","type":"update","data":[{"symbol":"LINK/USD","bids":[],"asks":[{"price":18.57457,"qty":0.00000000},{"price":18.57685,"qty":1.31717222}],"checksum":2020908068,"timestamp":"2024-06-01T17:52:21.157917Z"}]}
{"channel":"book","type":"update","data":[{"symbol":"LINK/USD","bids":[],"asks":[{"price":18.57456,"qty":0.00000000},{"price":18.57912,"qty":31.87500000},{"price":18.57472,"qty":1.50546674}],"checksum":3386940289,"timestamp":"2024-06-01T17:52:21.161096Z"}]}
{"channel":"book","type":"update","data":[{"symbol":"LINK/USD","bids":[],"asks":[{"price":18.57466,"qty":21.94076261}],"checksum":3639609392,"timestamp":"2024-06-01T17:52:21.472183Z"}]}
{"channel":"book","type":"update","data":[{"symbol":"LINK/USD","bids":[],"asks":[{"price":18.57472,"qty":0.00000000},{"price":18.57912,"qty":31.87500000},{"price":18.57465,"qty":1.50546674}],"checksum":3523708981,"timestamp":"2024-06-01T17:52:21.493323Z"}]}
{"channel":"book","type":"update","data":[{"symbol":"LINK/USD","bids":[],"asks":[{"price":18.57466,"qty":0.40269630}],"checksum":2241776968,"timestamp":"2024-06-01T17:52:22.046327Z"}]}
{"channel":"book","type":"update","data":[{"symbol":"LINK/USD","bids":[],"asks":[{"price":18.57465,"qty":0.00000000},{"price":18.57912,"qty":31.87500000},{"price":18.57472,"qty":1.50546674}],"checksum":3386940289,"timestamp":"2024-06-01T17:52:22.057915Z"}]}
{"channel":"book","type":"update","data":[{"symbol":"LINK/USD","bids":[],"asks":[{"price":18.57469,"qty":21.53802159}],"checksum":836872494,"timestamp":"2024-06-01T17:52:22.397041Z"}]}
{"channel":"book","type":"update","data":[{"symbol":"LINK/USD","bids":[],"asks":[{"price":18.57472,"qty":0.00000000},{"price":18.57685,"qty":1.31717222},{"price":18.57468,"qty":1.50546674}],"checksum":2683909348,"timestamp":"2024-06-01T17:52:22.400337Z"}]}
{"channel":"book","type":"update","data":[{"symbol":"LINK/USD","bids":[],"asks":[{"price":18.57627,"qty":0.00000000},{"price":18.57685,"qty":1.31717222}],"checksum":3321805914,"timestamp":"2024-06-01T17:52:23.356550Z"}]}
{"channel":"book","type":"update","data":[{"symbol":"LINK/USD","bids":[],"asks":[{"price":18.57469,"qty":0.00000000},{"price":18.57912,"qty":31.87500000}],"checksum":2722779201,"timestamp":"2024-06-01T17:52:23.462013Z"}]}
{"channel":"book","type":"update","data":[{"symbol":"LINK/USD","bids":[],"asks":[{"price":18.57468,"qty":0.00000000},{"price":18.58058,"qty":121.09418973},{"price":18.57472,"qty":1.50546674}],"checksum":2023871940,"timestamp":"2024-06-01T17:52:23.466704Z"}]}
{"channel":"book","type":"update","data":[{"symbol":"LINK/USD","bids":[],"asks":[{"price":18.57688,"qty":6.43107813}],"checksum":395902097,"timestamp":"2024-06-01T17:52:23.481173Z"}]}
{"channel":"book","type":"update","data":[{"symbol":"LINK/USD","bids":[],"asks":[{"price":18.57517,"qty":21.53746136}],"checksum":887641750,"timestamp":"2024-06-01T17:52:23.757254Z"}]}
{"channel":"book","type":"update","data":[{"symbol":"LINK/USD","bids":[{"price":18.56385,"qty":0.00000000},{"price":18.56112,"qty":339.03252319}],"asks":[],"checksum":2182168946,"timestamp":"2024-06-01T17:52:23.923863Z"}]}
{"channel":"book","type":"update","data":[{"symbol":"LINK/USD","bids":[{"price":18.56472,"qty":83.13779976}],"asks":[],"checksum":3667714425,"timestamp":"2024-06-01T17:52:24.045760Z"}]}
{"channel":"book","type":"update","data":[{"symbol":"LINK/USD","bids":[{"price":18.56609,"qty":2214.29048057}],"asks":[],"checksum":3620175412,"timestamp":"2024-06-01T17:52:28.356938Z"}]}
{"channel":"book","type":"update","data":[{"symbol":"LINK/USD","bids":[{"price":18.56525,"qty":19.00000000}],"asks":[],"checksum":1292296837,"timestamp":"2024-06-01T17:52:29.397808Z"}]}
{"channel":"book","type":"update","data":[{"symbol":"LINK/USD","bids":[{"price":18.56200,"qty":0.00000000},{"price":18.56130,"qty":186.96555600}],"asks":[],"checksum":3918213379,"timestamp":"2024-06-01T17:52:29.852259Z"}]}
{"channel":"book","type":"update","data":[{"symbol":"LINK/USD","bids":[{"price":18.56400,"qty":75.49689855}],"asks":[],"checksum":2181221303,"timestamp":"2024-06-01T17:52:29.858047Z"}]}
{"channel":"book","type":"update","data":[{"symbol":"LINK/USD","bids":[],"asks":[{"price":18.57517,"qty":0.00000000},{"price":18.57688,"qty":6.43107813}],"checksum":735015744,"timestamp":"2024-06-01T17:52:30.339450Z"}]}
{"channel":"book","type":"update","data":[{"symbol":"LINK/USD","bids":[],"asks":[{"price":18.57517,"qty":21.53746791}],"checksum":219714001,"timestamp":"2024-06-01T17:52:30.649744Z"}]}
{"channel":"book","type":"update","data":[{"symbol":"LINK/USD","bids":[],"asks":[{"price":18.57684,"qty":6.43107813}],"checksum":423037816,"timestamp":"2024-06-01T17:52:30.945460Z"}]}
{"channel":"book","type":"update","data":[{"symbol":"LINK/USD","bids":[],"asks":[{"price":18.57517,"qty":0.00000000},{"price":18.57685,"qty":1.31717222}],"checksum":2288853124,"timestamp":"2024-06-01T17:52:30.962437Z"}]}
{"channel":"book","type":"update","data":[{"symbol":"LINK/USD","bids":[{"price":18.56525,"qty":0.00000000},{"price":18.56130,"qty":186.96555600},{"price":18.56324,"qty":19.00000000}],"asks":[],"checksum":603358270,"timestamp":"2024-06-01T17:52:30.999437Z"}]}
{"channel":"book","type":"update","data":[{"symbol":"LINK/USD","bids":[{"price":18.56609,"qty":2182.41548057}],"asks":[],"checksum":3154395340,"timestamp":"2024-06-01T17:52:30.999645Z"}]}
{"channel":"book","type":"update","data":[{"symbol":"LINK/USD","bids":[{"price":18.56324,"qty":38.00000000}],"asks":[],"checksum":175189623,"timestamp":"2024-06-01T17:52:30.999758Z"}]}
{"channel":"book","type":"update","data":[{"symbol":"LINK/USD","bids":[{"price":18.56609,"qty":2451.64968237}],"asks":[],"checksum":2732920733,"timestamp":"2024-06-01T17:52:31.000094Z"}]}
{"channel":"book","type":"update","data":[{"symbol":"LINK/USD","bids":[{"price":18.56400,"qty":0.00000000},{"price":18.56130,"qty":186.96555600}],"asks":[],"checksum":3437046744,"timestamp":"2024-06-01T17:52:31.002469Z"}]}
{"channel":"book","type":"update","data":[{"symbol":"LINK/USD","bids":[{"price":18.56609,"qty":2483.52468237}],"asks":[],"checksum":2115589892,"timestamp":"2024-06-01T17:52:31.005857Z"}]}
{"channel":"book","type":"update","data":[{"symbol":"LINK/USD","bids":[{"price":18.56609,"qty":2283.52468237}],"asks":[],"checksum":4243760797,"timestamp":"2024-06-01T17:52:31.008880Z"}]}
{"channel":"book","type":"update","data":[{"symbol":"LINK/USD","bids":[{"price":18.56609,"qty":2251.64968237}],"asks":[],"checksum":1312217665,"timestamp":"2024-06-01T17:52:31.013409Z"}]}
{"channel":"book","type":"update","data":[{"symbol":"LINK/USD","bids":[{"price":18.56609,"qty":2219.77468237}],"asks":[],"checksum":1077929071,"timestamp":"2024-06-01T17:52:31.013519Z"}]}
{"channel":"book","type":"update","data":[{"symbol":"LINK/USD","bids":[{"price":18.56200,"qty":63.35776945}],"asks":[],"checksum":436912427,"timestamp":"2024-06-01T17:52:31.013731Z"}]}
{"channel":"book","type":"update","data":[{"symbol":"LINK/USD","bids":[{"price":18.56472,"qty":0.00000000},{"price":18.56130,"qty":186.96555600}],"asks":[],"checksum":3147835626,"timestamp":"2024-06-01T17:52:31.016298Z"}]}
{"channel":"book","type":"update","data":[{"symbol":"LINK/USD","bids":[{"price":18.56609,"qty":2251.64968237}],"asks":[],"checksum":3047757508,"timestamp":"2024-06-01T17:52:31.027544Z"}]}
{"channel":"book","type":"update","data":[{"symbol":"LINK/USD","bids":[{"price":18.56609,"qty":2283.52468237}],"asks":[],"checksum":124611096,"timestamp":"2024-06-01T17:52:31.029450Z"}]}
{"channel":"book","type":"update","data":[{"symbol":"LINK/USD","bids":[{"price":18.56609,"qty":2273.83351179}],"asks":[],"checksum":3883932047,"timestamp":"2024-06-01T17:52:31.032292Z"}]}
{"channel":"book","type":"update","data":[{"symbol":"LINK/USD","bids":[],"asks":[{"price":18.57353,"qty":33.00000000}],"checksum":3788560769,"timestamp":"2024-06-01T17:52:31.037063Z"}]}
{"channel":"book","type":"update","data":[{"symbol":"LINK/USD","bids":[{"price":18.56609,"qty":2241.95851179}],"asks":[],"checksum":756417983,"timestamp":"2024-06-01T17:52:31.044582Z"}]}
{"channel":"book","type":"update","data":[{"symbol":"LINK/USD","bids":[],"asks":[{"price":18.57472,"qty":0.00000000},{"price":18.57685,"qty":1.31717222},{"price":18.57352,"qty":1.50546674}],"checksum":2052741722,"timestamp":"2024-06-01T17:52:31.045753Z"}]}
{"channel":"book","type":"update","data":[{"symbol":"LINK/USD","bids":[{"price":18.56609,"qty":2273.83351179}],"asks":[],"checksum":3063711332,"timestamp":"2024-06-01T17:52:31.050377Z"}]}
{"channel":"book","type":"update","data":[{"symbol":"LINK/USD","bids":[{"price":18.56609,"qty":2004.59930999}],"asks":[],"checksum":713867504,"timestamp":"2024-06-01T17:52:31.051958Z"}]}
{"channel":"book","type":"update","data":[{"symbol":"LINK/USD","bids":[{"price":18.56324,"qty":19.00000000},{"price":18.56188,"qty":19.00000000}],"asks":[],"checksum":3414561608,"timestamp":"2024-06-01T17:52:31.052811Z"}]}
{"channel":"book","type":"update","data":[{"symbol":"LINK/USD","bids":[{"price":18.56324,"qty":0.00000000},{"price":18.56130,"qty":186.96555600}],"asks":[],"checksum":61701034,"timestamp":"2024-06-01T17:52:31.055348Z"}]}
{"channel":"book","type":"update","data":[{"symbol":"LINK/USD","bids":[],"asks":[{"price":18.57354,"qty":31.87500000}],"checksum":1887722020,"timestamp":"2024-06-01T17:52:31.055427Z"}]}
{"channel":"book","type":"update","data":[{"symbol":"LINK/USD","bids":[],"asks":[{"price":18.57353,"qty":0.00000000},{"price":18.57684,"qty":6.43107813}],"checksum":3979242555,"timestamp":"2024-06-01T17:52:31.058682Z"}]}
{"channel":"book","type":"update","data":[{"symbol":"LINK/USD","bids":[{"price":18.56609,"qty":1972.72430999}],"asks":[],"checksum":2825694113,"timestamp":"2024-06-01T17:52:31.067227Z"}]}
{"channel":"book","type":"update","data":[{"symbol":"LINK/USD","bids":[{"price":18.56609,"qty":1940.84930999}],"asks":[],"checksum":4090571798,"timestamp":"2024-06-01T17:52:31.067369Z"}]}
{"channel":"book","type":"update","data":[{"symbol":"LINK/USD","bids":[{"price":18.56319,"qty":0.00000000},{"price":18.56059,"qty":33.00000000}],"asks":[],"checksum":4025597779,"timestamp":"2024-06-01T17:52:31.067392Z"}]}
{"channel":"book","type":"update","data":[{"symbol":"LINK/USD","bids":[{"price":18.56609,"qty":1671.54112502}],"asks":[],"checksum":1776358623,"timestamp":"2024-06-01T17:52:31.067602Z"}]}
{"channel":"book","type":"update","data":[{"symbol":"LINK/USD","bids":[],"asks":[{"price":18.57473,"qty":0.00000000},{"price":18.57685,"qty":1.31717222}],"checksum":53721989,"timestamp":"2024-06-01T17:52:31.067989Z"}]}
{"channel":"book","type":"update","data":[{"symbol":"LINK/USD","bids":[],"asks":[{"price":18.57301,"qty":33.00000000}],"checksum":1841320060,"timestamp":"2024-06-01T17:52:31.068350Z"}]}
{"channel":"book","type":"update","data":[{"symbol":"LINK/USD","bids":[{"price":18.56466,"qty":0.00000000},{"price":18.55981,"qty":31.87500000}],"asks":[],"checksum":1795912003,"timestamp":"2024-06-01T17:52:31.069186Z"}]}
{"channel":"book","type":"update","data":[{"symbol":"LINK/USD","bids":[{"price":18.56200,"qty":0.00000000},{"price":18.55913,"qty":339.03252319}],"asks":[],"checksum":1782295838,"timestamp":"2024-06-01T17:52:31.069687Z"}]}
{"channel":"book","type":"update","data":[{"symbol":"LINK/USD","bids":[{"price":18.56609,"qty":1703.41612502}],"asks":[],"checksum":3360449718,"timestamp":"2024-06-01T17:52:31.076491Z"}]}
{"channel":"book","type":"update","data":[{"symbol":"LINK/USD","bids":[],"asks":[{"price":18.57352,"qty":0.00000000},{"price":18.57685,"qty":1.31717222},{"price":18.57353,"qty":1.50546674}],"checksum":4160430256,"timestamp":"2024-06-01T17:52:31.077800Z"}]}
{"channel":"book","type":"update","data":[{"symbol":"LINK/USD","bids":[{"price":18.56609,"qty":1671.54112502}],"asks":[],"checksum":1435298072,"timestamp":"2024-06-01T17:52:31.082907Z"}]}
{"channel":"book","type":"update","data":[{"symbol":"LINK/USD","bids":[{"price":18.56609,"qty":594.54637811}],"asks":[],"checksum":139452366,"timestamp":"2024-06-01T17:52:31.084071Z"}]}
{"channel":"book","type":"update","data":[{"symbol":"LINK/USD","bids":[],"asks":[{"price":18.57353,"qty":0.00000000},{"price":18.57685,"qty":1.31717222}],"checksum":1170590362,"timestamp":"2024-06-01T17:52:31.084674Z"}]}
{"channel":"book","type":"update","data":[{"symbol":"LINK/USD","bids":[],"asks":[{"price":18.57300,"qty":1.50546674}],"checksum":3060942355,"timestamp":"2024-06-01T17:52:31.090862Z"}]}
{"channel":"book","type":"update","data":[{"symbol":"LINK/USD","bids":[{"price":18.56609,"qty":626.42137811}],"asks":[],"checksum":1823523452,"timestamp":"2024-06-01T17:52:31.094281Z"}]}
{"channel":"book","type":"update","data":[{"symbol":"LINK/USD","bids":[{"price":18.56100,"qty":44.63026569}],"asks":[],"checksum":1857629443,"timestamp":"2024-06-01T17:52:31.095608Z"}]}
{"channel":"book","type":"update","data":[{"symbol":"LINK/USD","bids":[{"price":18.56609,"qty":658.29637811}],"asks":[],"checksum":159874226,"timestamp":"2024-06-01T17:52:31.108300Z"}]}
{"channel":"book","type":"update","data":[{"symbol":"LINK/USD","bids":[{"price":18.56609,"qty":414.80964814}],"asks":[],"checksum":1106209704,"timestamp":"2024-06-01T17:52:31.110676Z"}]}
{"channel":"book","type":"update","data":[{"symbol":"LINK/USD","bids":[{"price":18.56426,"qty":269.33463976}],"asks":[],"checksum":2135506769,"timestamp":"2024-06-01T17:52:31.119446Z"}]}
{"channel":"book","type":"update","data":[{"symbol":"LINK/USD","bids":[],"asks":[{"price":18.57301,"qty":0.00000000},{"price":18.57685,"qty":1.31717222}],"checksum":1343521289,"timestamp":"2024-06-01T17:52:31.120556Z"}]}
{"channel":"book","type":"update","data":[{"symbol":"LINK/USD","bids":[{"price":18.56609,"qty":382.93464814}],"asks":[],"checksum":179564896,"timestamp":"2024-06-01T17:52:31.122664Z"}]}
{"channel":"book","type":"update","data":[{"symbol":"LINK/USD","bids":[],"asks":[{"price":18.57134,"qty":33.00000000}],"checksum":745506856,"timestamp":"2024-06-01T17:52:31.126562Z"}]}
{"channel":"book","type":"update","data":[{"symbol":"LINK/USD","bids":[{"price":18.56609,"qty":351.05964814}],"asks":[],"checksum":3256877715,"timestamp":"2024-06-01T17:52:31.127888Z"}]}
{"channel":"book","type":"update","data":[{"symbol":"LINK/USD","bids":[{"price":18.56097,"qty":83.15459666}],"asks":[],"checksum":1726172215,"timestamp":"2024-06-01T17:52:31.137638Z"}]}
{"channel":"book","type":"update","data":[{"symbol":"LINK/USD","bids":[{"price":18.56609,"qty":382.93464814}],"asks":[],"checksum":2293024396,"timestamp":"2024-06-01T17:52:31.141303Z"}]}
{"channel":"book","type":"update","data":[{"symbol":"LINK/USD","bids":[],"asks":[{"price":18.57300,"qty":0.00000000},{"price":18.57685,"qty":1.31717222}],"checksum":42724140,"timestamp":"2024-06-01T17:52:31.143120Z"}]}
{"channel":"book","type":"update","data":[{"symbol":"LINK/USD","bids":[{"price":18.56609,"qty":351.05964814}],"asks":[],"checksum":3972293015,"timestamp":"2024-06-01T17:52:31.145538Z"}]}
{"channel":"book","type":"update","data":[{"symbol":"LINK/USD","bids":[{"price":18.56100,"qty":0.00000000},{"price":18.56059,"qty":33.00000000}],"asks":[],"checksum":3365843616,"timestamp":"2024-06-01T17:52:31.148769Z"}]}
{"channel":"book","type":"update","data":[{"symbol":"LINK/USD","bids":[],"asks":[{"price":18.57683,"qty":1.50546674}],"checksum":3239377722,"timestamp":"2024-06-01T17:52:31.150817Z"}]}
{"channel":"book","type":"update","data":[{"symbol":"LINK/USD","bids":[{"price":18.56609,"qty":382.93464814}],"asks":[],"checksum":794521985,"timestamp":"2024-06-01T17:52:31.154472Z"}]}
{"channel":"book","type":"update","data":[{"symbol":"LINK/USD","bids":[],"asks":[{"price":18.57185,"qty":0.00000000},{"price":18.57685,"qty":1.31717222}],"checksum":8413139,"timestamp":"2024-06-01T17:52:31.156708Z"}]}
{"channel":"book","type":"update","data":[{"symbol":"LINK/USD","bids":[{"price":18.56609,"qty":31.87500000}],"asks":[],"checksum":3421110660,"timestamp":"2024-06-01T17:52:31.157661Z"}]}
{"channel":"book","type":"update","data":[{"symbol":"LINK/USD","bids":[],"asks":[{"price":18.57684,"qty":0.00000000},{"price":18.57912,"qty":31.87500000}],"checksum":3485318669,"timestamp":"2024-06-01T17:52:31.159399Z"}]}
{"channel":"book","type":"update","data":[{"symbol":"LINK/USD","bids":[{"price":18.56609,"qty":0.00000000},{"price":18.56013,"qty":404.09196026}],"asks":[],"checksum":2542700666,"timestamp":"2024-06-01T17:52:31.159752Z"}]}
{"channel":"book","type":"update","data":[{"symbol":"LINK/USD","bids":[{"price":18.56097,"qty":0.00000000},{"price":18.55981,"qty":31.87500000}],"asks":[],"checksum":2671706469,"timestamp":"2024-06-01T17:52:31.160552Z"}]}
{"channel":"book","type":"update","data":[{"symbol":"LINK/USD","bids":[],"asks":[{"price":18.57133,"qty":13.46572576}],"checksum":120695882,"timestamp":"2024-06-01T17:52:31.161456Z"}]}
{"channel":"book","type":"update","data":[{"symbol":"LINK/USD","bids":[],"asks":[{"price":18.57683,"qty":0.00000000},{"price":18.57912,"qty":31.87500000},{"price":18.57910,"qty":1.50546674}],"checksum":3821526387,"timestamp":"2024-06-01T17:52:31.166171Z"}]}
{"channel":"book","type":"update","data":[{"symbol":"LINK/USD","bids":[{"price":18.56130,"qty":0.00000000},{"price":18.55913,"qty":339.03252319}],"asks":[],"checksum":3997830975,"timestamp":"2024-06-01T17:52:31.172634Z"}]}
{"channel":"book","type":"update","data":[{"symbol":"LINK/USD","bids":[{"price":18.56609,"qty":31.87500000}],"asks":[],"checksum":2879612131,"timestamp":"2024-06-01T17:52:31.178070Z"}]}
{"channel":"book","type":"update","data":[{"symbol":"LINK/USD","bids":[],"asks":[{"price":18.57910,"qty":0.00000000},{"price":18.57912,"qty":31.87500000},{"price":18.57133,"qty":14.97119250}],"checksum":3276523891,"timestamp":"2024-06-01T17:52:31.180834Z"}]}
{"channel":"book","type":"update","data":[{"symbol":"LINK/USD","bids":[{"price":18.56609,"qty":0.00000000},{"price":18.55913,"qty":339.03252319}],"asks":[],"checksum":506295510,"timestamp":"2024-06-01T17:52:31.183468Z"}]}
{"channel":"book","type":"update","data":[{"symbol":"LINK/USD","bids":[],"asks":[{"price":18.57133,"qty":1.50546674}],"checksum":2411075807,"timestamp":"2024-06-01T17:52:31.184975Z"}]}
{"channel":"book","type":"update","data":[{"symbol":"LINK/USD","bids":[{"price":18.56609,"qty":31.87500000}],"asks":[],"checksum":1011570493,"timestamp":"2024-06-01T17:52:31.186401Z"}]}
{"channel":"book","type":"update","data":[{"symbol":"LINK/USD","bids":[{"price":18.56609,"qty":63.75000000}],"asks":[],"checksum":891220519,"timestamp":"2024-06-01T17:52:31.187143Z"}]}
{"channel":"book","type":"update","data":[{"symbol":"LINK/USD","bids":[],"asks":[{"price":18.57132,"qty":13.46640595}],"checksum":4281062305,"timestamp":"2024-06-01T17:52:31.188231Z"}]}
{"channel":"book","type":"update","data":[{"symbol":"LINK/USD","bids":[{"price":18.56609,"qty":31.87500000}],"asks":[],"checksum":4135483067,"timestamp":"2024-06-01T17:52:31.197846Z"}]}
{"channel":"book","type":"update","data":[{"symbol":"LINK/USD","bids":[{"price":18.56609,"qty":0.00000000},{"price":18.55913,"qty":339.03252319}],"asks":[],"checksum":2342980587,"timestamp":"2024-06-01T17:52:31.197879Z"}]}
{"channel":"book","type":"update","data":[{"symbol":"LINK/USD","bids":[{"price":18.56514,"qty":418.33994883}],"asks":[],"checksum":4051804176,"timestamp":"2024-06-01T17:52:31.197919Z"}]}
{"channel":"book","type":"update","data":[{"symbol":"LINK/USD","bids":[{"price":18.56541,"qty":31.87500000}],"asks":[],"checksum":1279249113,"timestamp":"2024-06-01T17:52:31.203939Z"}]}
{"channel":"book","type":"update","data":[{"symbol":"LINK/USD","bids":[],"asks":[{"price":18.57132,"qty":0.00000000},{"price":18.57912,"qty":31.87500000}],"checksum":1211029997,"timestamp":"2024-06-01T17:52:31.206924Z"}]}
{"channel":"book","type":"update","data":[{"symbol":"LINK/USD","bids":[{"price":18.56541,"qty":0.00000000},{"price":18.55913,"qty":339.03252319}],"asks":[],"checksum":3492890038,"timestamp":"2024-06-01T17:52:31.208336Z"}]}
{"channel":"book","type":"update","data":[{"symbol":"LINK/USD","bids":[],"asks":[{"price":18.57131,"qty":13.46606821}],"checksum":1541922438,"timestamp":"2024-06-01T17:52:31.210751Z"}]}
{"channel":"book","type":"update","data":[{"symbol":"LINK/USD","bids":[{"price":18.55913,"qty":0.00000000},{"price":18.55765,"qty":40.00000000}],"asks":[],"checksum":15441548,"timestamp":"2024-06-01T17:52:31.213371Z"}]}
{"channel":"book","type":"update","data":[{"symbol":"LINK/USD","bids":[],"asks":[{"price":18.57132,"qty":40.00000000}],"checksum":4161457777,"timestamp":"2024-06-01T17:52:31.220441Z"}]}
{"channel":"book","type":"update","data":[{"symbol":"LINK/USD","bids":[{"price":18.56515,"qty":243.48672997}],"asks":[],"checksum":2377948901,"timestamp":"2024-06-01T17:52:31.221411Z"}]}
{"channel":"book","type":"update","data":[{"symbol":"LINK/USD","bids":[{"price":18.56423,"qty":0.00000000},{"price":18.55765,"qty":40.00000000}],"asks":[],"checksum":1574816487,"timestamp":"2024-06-01T17:52:31.223176Z"}]}
{"channel":"book","type":"update","data":[{"symbol":"LINK/USD","bids":[],"asks":[{"price":18.57131,"qty":0.00000000},{"price":18.57685,"qty":1.31717222}],"checksum":346954497,"timestamp":"2024-06-01T17:52:31.225271Z"}]}
{"channel":"book","type":"update","data":[{"symbol":"LINK/USD","bids":[],"asks":[{"price":18.57133,"qty":0.00000000},{"price":18.57912,"qty":31.87500000},{"price":18.57130,"qty":1.50546674}],"checksum":2205285517,"timestamp":"2024-06-01T17:52:31.226065Z"}]}
{"channel":"book","type":"update","data":[{"symbol":"LINK/USD","bids":[],"asks":[{"price":18.57351,"qty":200.00000000}],"checksum":3931143168,"timestamp":"2024-06-01T17:52:31.226674Z"}]}
{"channel":"book","type":"update","data":[{"symbol":"LINK/USD","bids":[],"asks":[{"price":18.57130,"qty":14.97169036}],"checksum":3905928078,"timestamp":"2024-06-01T17:52:31.229307Z"}]}
{"channel":"book","type":"update","data":[{"symbol":"LINK/USD","bids":[],"asks":[{"price":18.57130,"qty":1.50546674}],"checksum":3931143168,"timestamp":"2024-06-01T17:52:31.232458Z"}]}
{"channel":"book","type":"update","data":[{"symbol":"LINK/USD","bids":[],"asks":[{"price":18.57130,"qty":14.97168673}],"checksum":491756196,"timestamp":"2024-06-01T17:52:31.235547Z"}]}
{"channel":"book","type":"update","data":[{"symbol":"LINK/USD","bids":[],"asks":[{"price":18.57134,"qty":0.00000000},{"price":18.57685,"qty":1.31717222}],"checksum":776889380,"timestamp":"2024-06-01T17:52:31.238793Z"}]}
{"channel":"book","type":"update","data":[{"symbol":"LINK/USD","bids":[],"asks":[{"price":18.57080,"qty":33.00000000}],"checksum":1061004925,"timestamp":"2024-06-01T17:52:31.238996Z"}]}
{"channel":"book","type":"update","data":[{"symbol":"LINK/USD","bids":[],"asks":[{"price":18.57130,"qty":13.46621999},{"price":18.57131,"qty":1.50546674}],"checksum":2360809222,"timestamp":"2024-06-01T17:52:31.239374Z"}]}
{"channel":"book","type":"update","data":[{"symbol":"LINK/USD","bids":[],"asks":[{"price":18.57168,"qty":31.87500000}],"checksum":3925955124,"timestamp":"2024-06-01T17:52:31.246896Z"}]}
{"channel":"book","type":"update","data":[{"symbol":"LINK/USD","bids":[],"asks":[{"price":18.57130,"qty":0.00000000},{"price":18.57359,"qty":0.34605497}],"checksum":2436410427,"timestamp":"2024-06-01T17:52:31.250911Z"}]}
{"channel":"book","type":"update","data":[{"symbol":"LINK/USD","bids":[],"asks":[{"price":18.57131,"qty":41.50546674}],"checksum":1801757323,"timestamp":"2024-06-01T17:52:31.254128Z"}]}
{"channel":"book","type":"update","data":[{"symbol":"LINK/USD","bids":[],"asks":[{"price":18.57079,"qty":13.46621999}],"checksum":4035573062,"timestamp":"2024-06-01T17:52:31.254193Z"}]}
{"channel":"book","type":"update","data":[{"symbol":"LINK/USD","bids":[{"price":18.56059,"qty":0.00000000},{"price":18.55740,"qty":186.96555600}],"asks":[],"checksum":3838113163,"timestamp":"2024-06-01T17:52:31.257714Z"}]}
{"channel":"book","type":"update","data":[{"symbol":"LINK/USD","bids":[],"asks":[{"price":18.57079,"qty":0.00000000},{"price":18.57359,"qty":0.34605497}],"checksum":25863889,"timestamp":"2024-06-01T17:52:31.263257Z"}]}
{"channel":"book","type":"update","data":[{"symbol":"LINK/USD","bids":[],"asks":[{"price":18.57078,"qty":13.46621999}],"checksum":3932102727,"timestamp":"2024-06-01T17:52:31.266394Z"}]}
{"channel":"book","type":"update","data":[{"symbol":"LINK/USD","bids":[],"asks":[{"price":18.57078,"qty":0.00000000},{"price":18.57359,"qty":0.34605497}],"checksum":25863889,"timestamp":"2024-06-01T17:52:31.276284Z"}]}
{"channel":"book","type":"update","data":[{"symbol":"LINK/USD","bids":[],"asks":[{"price":18.57077,"qty":13.46621999}],"checksum":3074598723,"timestamp":"2024-06-01T17:52:31.279182Z"}]}
{"channel":"book","type":"update","data":[{"symbol":"LINK/USD","bids":[],"asks":[{"price":18.57077,"qty":0.00000000},{"price":18.57359,"qty":0.34605497}],"checksum":25863889,"timestamp":"2024-06-01T17:52:31.288089Z"}]}
{"channel":"book","type":"update","data":[{"symbol":"LINK/USD","bids":[],"asks":[{"price":18.57131,"qty":1.50546674}],"checksum":3390130515,"timestamp":"2024-06-01T17:52:31.289788Z"}]}
{"channel":"book","type":"update","data":[{"symbol":"LINK/USD","bids":[],"asks":[{"price":18.57076,"qty":13.46621999}],"checksum":3793971082,"timestamp":"2024-06-01T17:52:31.291580Z"}]}
{"channel":"book","type":"update","data":[{"symbol":"LINK/USD","bids":[],"asks":[{"price":18.57076,"qty":0.00000000},{"price":18.57359,"qty":0.34605497}],"checksum":3390130515,"timestamp":"2024-06-01T17:52:31.294724Z"}]}
{"channel":"book","type":"update","data":[{"symbol":"LINK/USD","bids":[],"asks":[{"price":18.57079,"qty":13.46621999}],"checksum":2545901936,"timestamp":"2024-06-01T17:52:31.298643Z"}]}
{"channel":"book","type":"update","data":[{"symbol":"LINK/USD","bids":[],"asks":[{"price":18.57079,"qty":0.00000000},{"price":18.57359,"qty":0.34605497}],"checksum":3390130515,"timestamp":"2024-06-01T17:52:31.302279Z"}]}
{"channel":"book","type":"update","data":[{"symbol":"LINK/USD","bids":[],"asks":[{"price":18.57131,"qty":0.00000000},{"price":18.57466,"qty":0.40269630},{"price":18.57079,"qty":1.50546674}],"checksum":3503733494,"timestamp":"2024-06-01T17:52:31.303630Z"}]}
{"channel":"book","type":"update","data":[{"symbol":"LINK/USD","bids":[],"asks":[{"price":18.57078,"qty":13.46621999}],"checksum":3132411280,"timestamp":"2024-06-01T17:52:31.305480Z"}]}
{"channel":"book","type":"update","data":[{"symbol":"LINK/USD","bids":[{"price":18.56426,"qty":0.00000000},{"price":18.55725,"qty":31.87500000}],"asks":[],"checksum":361490066,"timestamp":"2024-06-01T17:52:31.309128Z"}]}
{"channel":"book","type":"update","data":[{"symbol":"LINK/USD","bids":[{"price":18.56013,"qty":0.00000000},{"price":18.55723,"qty":15.50000000}],"asks":[],"checksum":875957550,"timestamp":"2024-06-01T17:52:31.309338Z"}]}
{"channel":"book","type":"update","data":[{"symbol":"LINK/USD","bids":[],"asks":[{"price":18.57299,"qty":200.00000000}],"checksum":269748665,"timestamp":"2024-06-01T17:52:31.314099Z"}]}
{"channel":"book","type":"update","data":[{"symbol":"LINK/USD","bids":[],"asks":[{"price":18.57078,"qty":53.46621999}],"checksum":1352575075,"timestamp":"2024-06-01T17:52:31.320847Z"}]}
{"channel":"book","type":"update","data":[{"symbol":"LINK/USD","bids":[],"asks":[{"price":18.57080,"qty":0.00000000},{"price":18.57354,"qty":31.87500000}],"checksum":2703445098,"timestamp":"2024-06-01T17:52:31.326993Z"}]}
{"channel":"book","type":"update","data":[{"symbol":"LINK/USD","bids":[],"asks":[{"price":18.57027,"qty":33.00000000}],"checksum":673923383,"timestamp":"2024-06-01T17:52:31.327135Z"}]}
{"channel":"book","type":"update","data":[{"symbol":"LINK/USD","bids":[],"asks":[{"price":18.57078,"qty":40.00000000}],"checksum":2155040292,"timestamp":"2024-06-01T17:52:31.332135Z"}]}
{"channel":"book","type":"update","data":[{"symbol":"LINK/USD","bids":[],"asks":[{"price":18.57026,"qty":13.46621999}],"checksum":766734559,"timestamp":"2024-06-01T17:52:31.335590Z"}]}
{"channel":"book","type":"update","data":[{"symbol":"LINK/USD","bids":[],"asks":[{"price":18.57299,"qty":0.00000000},{"price":18.57351,"qty":200.00000000}],"checksum":972628337,"timestamp":"2024-06-01T17:52:31.343789Z"}]}
{"channel":"book","type":"update","data":[{"symbol":"LINK/USD","bids":[],"asks":[{"price":18.57078,"qty":0.00000000},{"price":18.57354,"qty":31.87500000}],"checksum":2981628546,"timestamp":"2024-06-01T17:52:31.353405Z"}]}
{"channel":"book","type":"update","data":[{"symbol":"LINK/USD","bids":[],"asks":[{"price":18.57046,"qty":21.54265602}],"checksum":1159180288,"timestamp":"2024-06-01T17:52:31.359377Z"}]}
{"channel":"book","type":"update","data":[{"symbol":"LINK/USD","bids":[{"price":18.56222,"qty":269.36429296}],"asks":[],"checksum":4197913351,"timestamp":"2024-06-01T17:52:31.378608Z"}]}
{"channel":"book","type":"update","data":[{"symbol":"LINK/USD","bids":[],"asks":[{"price":18.57076,"qty":40.00000000}],"checksum":1938659545,"timestamp":"2024-06-01T17:52:31.384892Z"}]}
{"channel":"book","type":"update","data":[{"symbol":"LINK/USD","bids":[{"price":18.55832,"qty":269.29215086}],"asks":[],"checksum":3577235578,"timestamp":"2024-06-01T17:52:31.402429Z"}]}
{"channel":"book","type":"update","data":[{"symbol":"LINK/USD","bids":[{"price":18.56515,"qty":264.13594307}],"asks":[],"checksum":3775382932,"timestamp":"2024-06-01T17:52:31.405231Z"}]}
{"channel":"book","type":"update","data":[{"symbol":"LINK/USD","bids":[{"price":18.55790,"qty":269.29215086}],"asks":[],"checksum":3670856704,"timestamp":"2024-06-01T17:52:31.410112Z"}]}
{"channel":"book","type":"update","data":[{"symbol":"LINK/USD","bids":[],"asks":[{"price":18.57076,"qty":0.00000000},{"price":18.57351,"qty":200.00000000}],"checksum":3140391256,"timestamp":"2024-06-01T17:52:31.418948Z"}]}
{"channel":"book","type":"update","data":[{"symbol":"LINK/USD","bids":[],"asks":[{"price":18.57126,"qty":6.43107813}],"checksum":2206836814,"timestamp":"2024-06-01T17:52:31.441226Z"}]}
{"channel":"book","type":"update","data":[{"symbol":"LINK/USD","bids":[{"price":18.55821,"qty":83.16696352}],"asks":[],"checksum":1896207744,"timestamp":"2024-06-01T17:52:31.443211Z"}]}
{"channel":"book","type":"update","data":[{"symbol":"LINK/USD","bids":[],"asks":[{"price":18.57079,"qty":0.00000000},{"price":18.57351,"qty":200.00000000},{"price":18.57025,"qty":1.50546674}],"checksum":1410369389,"timestamp":"2024-06-01T17:52:31.448048Z"}]}
{"channel":"book","type":"update","data":[{"symbol":"LINK/USD","bids":[],"asks":[{"price":18.57026,"qty":0.00000000},{"price":18.57351,"qty":200.00000000}],"checksum":868167412,"timestamp":"2024-06-01T17:52:31.451300Z"}]}
{"channel":"book","type":"update","data":[{"symbol":"LINK/USD","bids":[],"asks":[{"price":18.57024,"qty":40.00000000}],"checksum":3029577934,"timestamp":"2024-06-01T17:52:31.452016Z"}]}
{"channel":"book","type":"update","data":[{"symbol":"LINK/USD","bids":[],"asks":[{"price":18.57024,"qty":53.46658211}],"checksum":1500300729,"timestamp":"2024-06-01T17:52:31.454521Z"}]}
{"channel":"book","type":"update","data":[{"symbol":"LINK/USD","bids":[],"asks":[{"price":18.57027,"qty":0.00000000},{"price":18.57351,"qty":200.00000000}],"checksum":2184040738,"timestamp":"2024-06-01T17:52:31.454905Z"}]}
{"channel":"book","type":"update","data":[{"symbol":"LINK/USD","bids":[],"asks":[{"price":18.56973,"qty":33.00000000}],"checksum":2506800361,"timestamp":"2024-06-01T17:52:31.455455Z"}]}
{"channel":"book","type":"update","data":[{"symbol":"LINK/USD","bids":[],"asks":[{"price":18.57025,"qty":0.00000000},{"price":18.57351,"qty":200.00000000},{"price":18.57026,"qty":1.50546674}],"checksum":4024174342,"timestamp":"2024-06-01T17:52:31.455732Z"}]}
{"channel":"book","type":"update","data":[{"symbol":"LINK/USD","bids":[],"asks":[{"price":18.57024,"qty":40.00000000}],"checksum":2640813415,"timestamp":"2024-06-01T17:52:31.458742Z"}]}
{"channel":"book","type":"update","data":[{"symbol":"LINK/USD","bids":[],"asks":[{"price":18.56972,"qty":13.46658211}],"checksum":878519048,"timestamp":"2024-06-01T17:52:31.461636Z"}]}
{"channel":"book","type":"update","data":[{"symbol":"LINK/USD","bids":[],"asks":[{"price":18.56982,"qty":31.87500000}],"checksum":313849149,"timestamp":"2024-06-01T17:52:31.464250Z"}]}
{"channel":"book","type":"update","data":[{"symbol":"LINK/USD","bids":[],"asks":[{"price":18.57024,"qty":0.00000000},{"price":18.57186,"qty":1.10230934}],"checksum":379476488,"timestamp":"2024-06-01T17:52:31.482774Z"}]}
{"channel":"book","type":"update","data":[{"symbol":"LINK/USD","bids":[{"price":18.55821,"qty":0.00000000},{"price":18.55765,"qty":40.00000000}],"asks":[],"checksum":3826395078,"timestamp":"2024-06-01T17:52:31.534920Z"}]}
{"channel":"book","type":"update","data":[{"symbol":"LINK/USD","bids":[{"price":18.55872,"qty":269.31533746}],"asks":[],"checksum":4135825974,"timestamp":"2024-06-01T17:52:31.546910Z"}]}
{"channel":"book","type":"update","data":[{"symbol":"LINK/USD","bids":[],"asks":[{"price":18.57026,"qty":0.00000000},{"price":18.57210,"qty":0.34717458},{"price":18.56971,"qty":1.50546674}],"checksum":3091206505,"timestamp":"2024-06-01T17:52:31.549815Z"}]}
{"channel":"book","type":"update","data":[{"symbol":"LINK/USD","bids":[],"asks":[{"price":18.56972,"qty":0.00000000},{"price":18.57210,"qty":0.34717458}],"checksum":3155734255,"timestamp":"2024-06-01T17:52:31.554009Z"}]}
{"channel":"book","type":"update","data":[{"symbol":"LINK/USD","bids":[],"asks":[{"price":18.56970,"qty":40.00000000}],"checksum":3512467897,"timestamp":"2024-06-01T17:52:31.555549Z"}]}
{"channel":"book","type":"update","data":[{"symbol":"LINK/USD","bids":[],"asks":[{"price":18.56970,"qty":53.46658198}],"checksum":326891897,"timestamp":"2024-06-01T17:52:31.557229Z"}]}
{"channel":"book","type":"update","data":[{"symbol":"LINK/USD","bids":[{"price":18.56515,"qty":296.01094307}],"asks":[],"checksum":3384740524,"timestamp":"2024-06-01T17:52:31.559188Z"}]}
{"channel":"book","type":"update","data":[{"symbol":"LINK/USD","bids":[],"asks":[{"price":18.56971,"qty":0.00000000},{"price":18.57210,"qty":0.34717458},{"price":18.56972,"qty":1.50546674}],"checksum":1906273240,"timestamp":"2024-06-01T17:52:31.559705Z"}]}
{"channel":"book","type":"update","data":[{"symbol":"LINK/USD","bids":[],"asks":[{"price":18.56973,"qty":0.00000000},{"price":18.57210,"qty":0.34717458}],"checksum":2832534964,"timestamp":"2024-06-01T17:52:31.559835Z"}]}
{"channel":"book","type":"update","data":[{"symbol":"LINK/USD","bids":[],"asks":[{"price":18.56919,"qty":33.00000000}],"checksum":10660810,"timestamp":"2024-06-01T17:52:31.560008Z"}]}
{"channel":"book","type":"update","data":[{"symbol":"LINK/USD","bids":[{"price":18.56515,"qty":264.13594307}],"asks":[],"checksum":3664140319,"timestamp":"2024-06-01T17:52:31.561758Z"}]}
{"channel":"book","type":"update","data":[{"symbol":"LINK/USD","bids":[],"asks":[{"price":18.56970,"qty":40.00000000}],"checksum":1450956759,"timestamp":"2024-06-01T17:52:31.564395Z"}]}
{"channel":"book","type":"update","data":[{"symbol":"LINK/USD","bids":[],"asks":[{"price":18.56918,"qty":13.46658198}],"checksum":2523906669,"timestamp":"2024-06-01T17:52:31.567381Z"}]}
{"channel":"book","type":"update","data":[{"symbol":"LINK/USD","bids":[],"asks":[{"price":18.56970,"qty":0.00000000},{"price":18.57186,"qty":1.10230934}],"checksum":57995650,"timestamp":"2024-06-01T17:52:31.607246Z"}]}
{"channel":"book","type":"update","data":[{"symbol":"LINK/USD","bids":[],"asks":[{"price":18.57126,"qty":0.00000000},{"price":18.57210,"qty":0.34717458}],"checksum":1473732303,"timestamp":"2024-06-01T17:52:31.631402Z"}]}
{"channel":"book","type":"update","data":[{"symbol":"LINK/USD","bids":[{"price":18.56526,"qty":31.87500000}],"asks":[],"checksum":458893692,"timestamp":"2024-06-01T17:52:31.639646Z"}]}
{"channel":"book","type":"update","data":[{"symbol":"LINK/USD","bids":[{"price":18.56522,"qty":31.87500000}],"asks":[],"checksum":1396556297,"timestamp":"2024-06-01T17:52:31.640383Z"}]}
{"channel":"book","type":"update","data":[{"symbol":"LINK/USD","bids":[{"price":18.56522,"qty":0.00000000},{"price":18.55832,"qty":269.29215086}],"asks":[],"checksum":458893692,"timestamp":"2024-06-01T17:52:31.644000Z"}]}
{"channel":"book","type":"update","data":[{"symbol":"LINK/USD","bids":[{"price":18.56526,"qty":63.75000000}],"asks":[],"checksum":3264930308,"timestamp":"2024-06-01T17:52:31.644210Z"}]}
{"channel":"book","type":"update","data":[{"symbol":"LINK/USD","bids":[],"asks":[{"price":18.56982,"qty":0.00000000},{"price":18.57354,"qty":31.87500000}],"checksum":2206412714,"timestamp":"2024-06-01T17:52:31.644349Z"}]}
{"channel":"book","type":"update","data":[{"symbol":"LINK/USD","bids":[],"asks":[{"price":18.57132,"qty":0.00000000},{"price":18.57359,"qty":0.34605497}],"checksum":1797625561,"timestamp":"2024-06-01T17:52:31.650897Z"}]}
{"channel":"book","type":"update","data":[{"symbol":"LINK/USD","bids":[],"asks":[{"price":18.56972,"qty":0.00000000},{"price":18.57466,"qty":0.40269630},{"price":18.57353,"qty":1.50546674}],"checksum":2736049168,"timestamp":"2024-06-01T17:52:31.675992Z"}]}
{"channel":"book","type":"update","data":[{"symbol":"LINK/USD","bids":[],"asks":[{"price":18.56919,"qty":0.00000000},{"price":18.57466,"qty":0.40269630}],"checksum":2612850676,"timestamp":"2024-06-01T17:52:31.680933Z"}]}
{"channel":"book","type":"update","data":[{"symbol":"LINK/USD","bids":[],"asks":[{"price":18.56995,"qty":33.00000000}],"checksum":1378488583,"timestamp":"2024-06-01T17:52:31.681326Z"}]}
{"channel":"book","type":"update","data":[{"symbol":"LINK/USD","bids":[{"price":18.56527,"qty":243.48672997}],"asks":[],"checksum":1940654935,"timestamp":"2024-06-01T17:52:31.681411Z"}]}
{"channel":"book","type":"update","data":[{"symbol":"LINK/USD","bids":[],"asks":[{"price":18.57353,"qty":0.00000000},{"price":18.57466,"qty":0.40269630}],"checksum":2062582467,"timestamp":"2024-06-01T17:52:31.684709Z"}]}
{"channel":"book","type":"update","data":[{"symbol":"LINK/USD","bids":[],"asks":[{"price":18.57168,"qty":0.00000000},{"price":18.57684,"qty":1.50546674}],"checksum":1224424691,"timestamp":"2024-06-01T17:52:31.685166Z"}]}
{"channel":"book","type":"update","data":[{"symbol":"LINK/USD","bids":[{"price":18.56609,"qty":31.87500000}],"asks":[],"checksum":3539331621,"timestamp":"2024-06-01T17:52:31.685899Z"}]}
{"channel":"book","type":"update","data":[{"symbol":"LINK/USD","bids":[],"asks":[{"price":18.57684,"qty":0.00000000},{"price":18.57685,"qty":1.31717222}],"checksum":2654494192,"timestamp":"2024-06-01T17:52:31.692583Z"}]}
{"channel":"book","type":"update","data":[{"symbol":"LINK/USD","bids":[{"price":18.56514,"qty":52.94000000}],"asks":[],"checksum":4136376875,"timestamp":"2024-06-01T17:52:31.726425Z"}]}
{"channel":"book","type":"update","data":[{"symbol":"LINK/USD","bids":[],"asks":[{"price":18.56995,"qty":0.00000000},{"price":18.57911,"qty":1.50546674}],"checksum":2897365694,"timestamp":"2024-06-01T17:52:31.729243Z"}]}
{"channel":"book","type":"update","data":[{"symbol":"LINK/USD","bids":[],"asks":[{"price":18.57135,"qty":33.00000000}],"checksum":1263474909,"timestamp":"2024-06-01T17:52:31.729360Z"}]}
{"channel":"book","type":"update","data":[{"symbol":"LINK/USD","bids":[{"price":18.56515,"qty":20.64921310}],"asks":[],"checksum":2907619016,"timestamp":"2024-06-01T17:52:31.729991Z"}]}
{"channel":"book","type":"update","data":[{"symbol":"LINK/USD","bids":[{"price":18.56149,"qty":83.15226708}],"asks":[],"checksum":588881786,"timestamp":"2024-06-01T17:52:31.742876Z"}]}
{"channel":"book","type":"update","data":[{"symbol":"LINK/USD","bids":[],"asks":[{"price":18.57046,"qty":0.00000000},{"price":18.57911,"qty":1.50546674}],"checksum":3184713255,"timestamp":"2024-06-01T17:52:31.747001Z"}]}
{"channel":"book","type":"update","data":[{"symbol":"LINK/USD","bids":[],"asks":[{"price":18.56918,"qty":0.00000000},{"price":18.57912,"qty":31.87500000}],"checksum":2948911888,"timestamp":"2024-06-01T17:52:31.751031Z"}]}
{"channel":"book","type":"update","data":[{"symbol":"LINK/USD","bids":[],"asks":[{"price":18.57333,"qty":6.43107813}],"checksum":99109322,"timestamp":"2024-06-01T17:52:31.752058Z"}]}
{"channel":"book","type":"update","data":[{"symbol":"LINK/USD","bids":[],"asks":[{"price":18.57134,"qty":13.46621170}],"checksum":2583852193,"timestamp":"2024-06-01T17:52:31.754146Z"}]}
{"channel":"book","type":"update","data":[{"symbol":"LINK/USD","bids":[],"asks":[{"price":18.57134,"qty":14.97167844}],"checksum":4056273997,"timestamp":"2024-06-01T17:52:31.756323Z"}]}
{"channel":"book","type":"update","data":[{"symbol":"LINK/USD","bids":[],"asks":[{"price":18.57017,"qty":80.77472831}],"checksum":1641613612,"timestamp":"2024-06-01T17:52:31.867900Z"}]}
{"channel":"book","type":"update","data":[{"symbol":"LINK/USD","bids":[],"asks":[{"price":18.57134,"qty":1.50546674}],"checksum":1357206605,"timestamp":"2024-06-01T17:52:31.871782Z"}]}
{"channel":"book","type":"update","data":[{"symbol":"LINK/USD","bids":[],"asks":[{"price":18.57016,"qty":13.46624472}],"checksum":3373136713,"timestamp":"2024-06-01T17:52:31.875054Z"}]}
{"channel":"book","type":"update","data":[{"symbol":"LINK/USD","bids":[],"asks":[{"price":18.57135,"qty":0.00000000},{"price":18.57466,"qty":0.40269630}],"checksum":52294512,"timestamp":"2024-06-01T17:52:31.877806Z"}]}
{"channel":"book","type":"update","data":[{"symbol":"LINK/USD","bids":[],"asks":[{"price":18.57008,"qty":33.00000000}],"checksum":3160192177,"timestamp":"2024-06-01T17:52:31.878016Z"}]}
{"channel":"book","type":"update","data":[{"symbol":"LINK/USD","bids":[],"asks":[{"price":18.57134,"qty":0.00000000},{"price":18.57466,"qty":0.40269630}],"checksum":4061403826,"timestamp":"2024-06-01T17:52:31.880872Z"}]}
{"channel":"book","type":"update","data":[{"symbol":"LINK/USD","bids":[],"asks":[{"price":18.57016,"qty":0.00000000},{"price":18.57685,"qty":1.31717222}],"checksum":2522309979,"timestamp":"2024-06-01T17:52:31.881377Z"}]}
{"channel":"book","type":"update","data":[{"symbol":"LINK/USD","bids":[{"price":18.56222,"qty":0.00000000},{"price":18.55981,"qty":31.87500000}],"asks":[],"checksum":1676314759,"timestamp":"2024-06-01T17:52:31.882418Z"}]}
{"channel":"book","type":"update","data":[{"symbol":"LINK/USD","bids":[],"asks":[{"price":18.57007,"qty":13.46624477}],"checksum":2886311592,"timestamp":"2024-06-01T17:52:31.885137Z"}]}
{"channel":"book","type":"update","data":[{"symbol":"LINK/USD","bids":[{"price":18.56426,"qty":269.33462914}],"asks":[],"checksum":719780491,"timestamp":"2024-06-01T17:52:31.886550Z"}]}
{"channel":"book","type":"update","data":[{"symbol":"LINK/USD","bids":[],"asks":[{"price":18.57333,"qty":0.00000000},{"price":18.57685,"qty":1.31717222}],"checksum":3613841960,"timestamp":"2024-06-01T17:52:31.928716Z"}]}
{"channel":"book","type":"update","data":[{"symbol":"LINK/USD","bids":[],"asks":[{"price":18.57017,"qty":0.00000000},{"price":18.57911,"qty":1.50546674}],"checksum":1316118721,"timestamp":"2024-06-01T17:52:31.971537Z"}]}
{"channel":"book","type":"update","data":[{"symbol":"LINK/USD","bids":[],"asks":[{"price":18.57008,"qty":0.00000000},{"price":18.57912,"qty":31.87500000}],"checksum":671327487,"timestamp":"2024-06-01T17:52:31.974318Z"}]}
{"channel":"book","type":"update","data":[{"symbol":"LINK/USD","bids":[],"asks":[{"price":18.57143,"qty":33.00000000}],"checksum":1565257958,"timestamp":"2024-06-01T17:52:31.974509Z"}]}
{"channel":"book","type":"update","data":[{"symbol":"LINK/USD","bids":[],"asks":[{"price":18.57350,"qty":6.43107813}],"checksum":1600069364,"timestamp":"2024-06-01T17:52:32.049247Z"}]}
{"channel":"book","type":"update","data":[{"symbol":"LINK/USD","bids":[],"asks":[{"price":18.57158,"qty":33.00000000}],"checksum":2956566132,"timestamp":"2024-06-01T17:52:32.126901Z"}]}
{"channel":"book","type":"update","data":[{"symbol":"LINK/USD","bids":[],"asks":[{"price":18.57142,"qty":1.50546674}],"checksum":509653952,"timestamp":"2024-06-01T17:52:32.129819Z"}]}
{"channel":"book","type":"update","data":[{"symbol":"LINK/USD","bids":[{"price":18.56288,"qty":269.31533746}],"asks":[],"checksum":4224093128,"timestamp":"2024-06-01T17:52:32.190447Z"}]}
{"channel":"book","type":"update","data":[{"symbol":"LINK/USD","bids":[{"price":18.56609,"qty":397.28250394}],"asks":[],"checksum":3989631470,"timestamp":"2024-06-01T17:52:32.410336Z"}]}
{"channel":"book","type":"update","data":[{"symbol":"LINK/USD","bids":[{"price":18.56609,"qty":640.76923391}],"asks":[],"checksum":2657618782,"timestamp":"2024-06-01T17:52:32.414356Z"}]}
{"channel":"book","type":"update","data":[{"symbol":"LINK/USD","bids":[{"price":18.56609,"qty":608.89423391}],"asks":[],"checksum":4252801564,"timestamp":"2024-06-01T17:52:32.536367Z"}]}
{"channel":"book","type":"update","data":[{"symbol":"LINK/USD","bids":[{"price":18.56609,"qty":640.76923391}],"asks":[],"checksum":2657618782,"timestamp":"2024-06-01T17:52:32.539870Z"}]}
{"channel":"book","type":"update","data":[{"symbol":"LINK/USD","bids":[{"price":18.56527,"qty":0.00000000},{"price":18.55981,"qty":31.87500000}],"asks":[],"checksum":912567109,"timestamp":"2024-06-01T17:52:32.540531Z"}]}
{"channel":"book","type":"update","data":[{"symbol":"LINK/USD","bids":[],"asks":[{"price":18.57007,"qty":0.00000000},{"price":18.57466,"qty":0.40269630}],"checksum":119073492,"timestamp":"2024-06-01T17:52:32.958307Z"}]}
{"channel":"book","type":"update","data":[{"symbol":"LINK/USD","bids":[],"asks":[{"price":18.57141,"qty":13.46624132}],"checksum":3782152720,"timestamp":"2024-06-01T17:52:32.962829Z"}]}
{"channel":"book","type":"update","data":[{"symbol":"LINK/USD","bids":[],"asks":[{"price":18.57142,"qty":0.00000000},{"price":18.57466,"qty":0.40269630},{"price":18.57140,"qty":1.50546674}],"checksum":3519853559,"timestamp":"2024-06-01T17:52:32.965880Z"}]}
{"channel":"book","type":"update","data":[{"symbol":"LINK/USD","bids":[],"asks":[{"price":18.57141,"qty":0.00000000},{"price":18.57466,"qty":0.40269630}],"checksum":2370370683,"timestamp":"2024-06-01T17:52:32.966241Z"}]}
{"channel":"book","type":"update","data":[{"symbol":"LINK/USD","bids":[],"asks":[{"price":18.57141,"qty":13.46624132}],"checksum":3519853559,"timestamp":"2024-06-01T17:52:32.969273Z"}]}
{"channel":"book","type":"update","data":[{"symbol":"LINK/USD","bids":[],"asks":[{"price":18.57140,"qty":0.00000000},{"price":18.57466,"qty":0.40269630},{"price":18.57142,"qty":1.50546674}],"checksum":3782152720,"timestamp":"2024-06-01T17:52:32.969817Z"}]}
{"channel":"book","type":"update","data":[{"symbol":"LINK/USD","bids":[],"asks":[{"price":18.57141,"qty":0.00000000},{"price":18.57466,"qty":0.40269630}],"checksum":119073492,"timestamp":"2024-06-01T17:52:32.972525Z"}]}
{"channel":"book","type":"update","data":[{"symbol":"LINK/USD","bids":[],"asks":[{"price":18.57141,"qty":13.46624132}],"checksum":3782152720,"timestamp":"2024-06-01T17:52:32.976518Z"}]}
{"channel":"book","type":"update","data":[{"symbol":"LINK/USD","bids":[],"asks":[{"price":18.57142,"qty":0.00000000},{"price":18.57466,"qty":0.40269630},{"price":18.57140,"qty":1.50546674}],"checksum":3519853559,"timestamp":"2024-06-01T17:52:33.326831Z"}]}
{"channel":"book","type":"update","data":[{"symbol":"LINK/USD","bids":[],"asks":[{"price":18.57141,"qty":0.00000000},{"price":18.57466,"qty":0.40269630}],"checksum":2370370683,"timestamp":"2024-06-01T17:52:33.331155Z"}]}
{"channel":"book","type":"update","data":[{"symbol":"LINK/USD","bids":[],"asks":[{"price":18.57140,"qty":0.00000000},{"price":18.57685,"qty":1.31717222},{"price":18.57142,"qty":1.50546674}],"checksum":119073492,"timestamp":"2024-06-01T17:52:33.334264Z"}]}
{"channel":"book","type":"update","data":[{"symbol":"LINK/USD","bids":[{"price":18.56188,"qty":0.00000000},{"price":18.55884,"qty":83.16414032}],"asks":[],"checksum":3098469875,"timestamp":"2024-06-01T17:52:33.397355Z"}]}
{"channel":"book","type":"update","data":[{"symbol":"LINK/USD","bids":[{"price":18.56515,"qty":0.00000000},{"price":18.55782,"qty":33.00000000}],"asks":[],"checksum":1409029628,"timestamp":"2024-06-01T17:52:33.570388Z"}]}
{"channel":"book","type":"update","data":[{"symbol":"LINK/USD","bids":[{"price":18.56167,"qty":0.00000000},{"price":18.55780,"qty":732.50600000}],"asks":[],"checksum":863867127,"timestamp":"2024-06-01T17:52:33.847728Z"}]}
{"channel":"book","type":"update","data":[{"symbol":"LINK/USD","bids":[],"asks":[{"price":18.57141,"qty":13.46624163}],"checksum":252210622,"timestamp":"2024-06-01T17:52:34.349402Z"}]}
{"channel":"book","type":"update","data":[{"symbol":"LINK/USD","bids":[],"asks":[{"price":18.57141,"qty":0.00000000},{"price":18.57466,"qty":0.40269630}],"checksum":863867127,"timestamp":"2024-06-01T17:52:34.352865Z"}]}
{"channel":"book","type":"update","data":[{"symbol":"LINK/USD","bids":[],"asks":[{"price":18.57142,"qty":0.00000000},{"price":18.57685,"qty":1.31717222},{"price":18.57140,"qty":1.50546674}],"checksum":1973321368,"timestamp":"2024-06-01T17:52:34.353452Z"}]}
{"channel":"book","type":"update","data":[{"symbol":"LINK/USD","bids":[],"asks":[{"price":18.57141,"qty":13.46624164}],"checksum":2161808061,"timestamp":"2024-06-01T17:52:34.356666Z"}]}
{"channel":"book","type":"update","data":[{"symbol":"LINK/USD","bids":[],"asks":[{"price":18.57140,"qty":0.00000000},{"price":18.57466,"qty":0.40269630},{"price":18.57142,"qty":1.50546674}],"checksum":2451125258,"timestamp":"2024-06-01T17:52:34.356919Z"}]}
{"channel":"book","type":"update","data":[{"symbol":"LINK/USD","bids":[],"asks":[{"price":18.57141,"qty":0.00000000},{"price":18.57466,"qty":0.40269630}],"checksum":863867127,"timestamp":"2024-06-01T17:52:34.360273Z"}]}
{"channel":"book","type":"update","data":[{"symbol":"LINK/USD","bids":[],"asks":[{"price":18.57141,"qty":13.46624164}],"checksum":2451125258,"timestamp":"2024-06-01T17:52:34.363929Z"}]}
{"channel":"book","type":"update","data":[{"symbol":"LINK/USD","bids":[{"price":18.56609,"qty":608.89423391}],"asks":[],"checksum":4044203336,"timestamp":"2024-06-01T17:52:34.515543Z"}]}
{"channel":"book","type":"update","data":[{"symbol":"LINK/USD","bids":[{"price":18.56609,"qty":640.76923391}],"asks":[],"checksum":2451125258,"timestamp":"2024-06-01T17:52:34.546127Z"}]}
{"channel":"book","type":"update","data":[{"symbol":"LINK/USD","bids":[{"price":18.56609,"qty":608.89423391}],"asks":[],"checksum":4044203336,"timestamp":"2024-06-01T17:52:34.714117Z"}]}
{"channel":"book","type":"update","data":[{"symbol":"LINK/USD","bids":[],"asks":[{"price":18.57139,"qty":40.00000000}],"checksum":3032481460,"timestamp":"2024-06-01T17:52:34.718698Z"}]}
{"channel":"book","type":"update","data":[{"symbol":"LINK/USD","bids":[{"price":18.56609,"qty":640.76923391}],"asks":[],"checksum":3618336758,"timestamp":"2024-06-01T17:52:34.719713Z"}]}
{"channel":"book","type":"update","data":[{"symbol":"LINK/USD","bids":[],"asks":[{"price":18.57088,"qty":33.00000000}],"checksum":3527185439,"timestamp":"2024-06-01T17:52:34.721446Z"}]}
{"channel":"book","type":"update","data":[{"symbol":"LINK/USD","bids":[],"asks":[{"price":18.57143,"qty":0.00000000},{"price":18.57354,"qty":31.87500000}],"checksum":3821417115,"timestamp":"2024-06-01T17:52:34.721484Z"}]}
{"channel":"book","type":"update","data":[{"symbol":"LINK/USD","bids":[],"asks":[{"price":18.57141,"qty":0.00000000},{"price":18.57359,"qty":0.34605497}],"checksum":2643901402,"timestamp":"2024-06-01T17:52:34.723051Z"}]}
{"channel":"book","type":"update","data":[{"symbol":"LINK/USD","bids":[{"price":18.56609,"qty":608.89423391}],"asks":[],"checksum":4269943448,"timestamp":"2024-06-01T17:52:34.723477Z"}]}
{"channel":"book","type":"update","data":[{"symbol":"LINK/USD","bids":[{"price":18.55884,"qty":0.00000000},{"price":18.55779,"qty":269.31533746}],"asks":[],"checksum":3232357674,"timestamp":"2024-06-01T17:52:34.738496Z"}]}
{"channel":"book","type":"update","data":[{"symbol":"LINK/USD","bids":[],"asks":[{"price":18.57142,"qty":0.00000000},{"price":18.57466,"qty":0.40269630},{"price":18.57087,"qty":1.50546674}],"checksum":1482725567,"timestamp":"2024-06-01T17:52:34.771461Z"}]}
{"channel":"book","type":"update","data":[{"symbol":"LINK/USD","bids":[{"price":18.55932,"qty":83.16198945}],"asks":[],"checksum":1796118492,"timestamp":"2024-06-01T17:52:34.858412Z"}]}
{"channel":"book","type":"update","data":[{"symbol":"LINK/USD","bids":[{"price":18.56609,"qty":640.76923391}],"asks":[],"checksum":135923358,"timestamp":"2024-06-01T17:52:35.102487Z"}]}
{"channel":"book","type":"update","data":[{"symbol":"LINK/USD","bids":[{"price":18.56609,"qty":608.89423391}],"asks":[],"checksum":1796118492,"timestamp":"2024-06-01T17:52:35.137164Z"}]}
{"channel":"book","type":"update","data":[{"symbol":"LINK/USD","bids":[{"price":18.56609,"qty":640.76923391}],"asks":[],"checksum":135923358,"timestamp":"2024-06-01T17:52:35.147072Z"}]}
{"channel":"book","type":"update","data":[{"symbol":"LINK/USD","bids":[{"price":18.55783,"qty":26.22402569}],"asks":[],"checksum":4155201746,"timestamp":"2024-06-01T17:52:35.550435Z"}]}
{"channel":"book","type":"update","data":[{"symbol":"LINK/USD","bids":[],"asks":[{"price":18.57086,"qty":13.46624137}],"checksum":3352638884,"timestamp":"2024-06-01T17:52:35.818925Z"}]}
{"channel":"book","type":"update","data":[{"symbol":"LINK/USD","bids":[],"asks":[{"price":18.57087,"qty":0.00000000},{"price":18.57359,"qty":0.34605497},{"price":18.57085,"qty":1.50546674}],"checksum":3300396265,"timestamp":"2024-06-01T17:52:35.822081Z"}]}
{"channel":"book","type":"update","data":[{"symbol":"LINK/USD","bids":[],"asks":[{"price":18.57086,"qty":0.00000000},{"price":18.57359,"qty":0.34605497}],"checksum":719374325,"timestamp":"2024-06-01T17:52:35.822550Z"}]}
{"channel":"book","type":"update","data":[{"symbol":"LINK/USD","bids":[],"asks":[{"price":18.57085,"qty":0.00000000},{"price":18.57466,"qty":0.40269630},{"price":18.57087,"qty":1.50546674}],"checksum":4155201746,"timestamp":"2024-06-01T17:52:35.826509Z"}]}
{"channel":"book","type":"update","data":[{"symbol":"LINK/USD","bids":[],"asks":[{"price":18.57084,"qty":13.46624137}],"checksum":2107692127,"timestamp":"2024-06-01T17:52:35.826582Z"}]}
{"channel":"book","type":"update","data":[{"symbol":"LINK/USD","bids":[],"asks":[{"price":18.57084,"qty":0.00000000},{"price":18.57359,"qty":0.34605497}],"checksum":4155201746,"timestamp":"2024-06-01T17:52:35.829953Z"}]}
{"channel":"book","type":"update","data":[{"symbol":"LINK/USD","bids":[],"asks":[{"price":18.57083,"qty":13.46624137}],"checksum":3637347278,"timestamp":"2024-06-01T17:52:35.833841Z"}]}
{"channel":"book","type":"update","data":[{"symbol":"LINK/USD","bids":[{"price":18.56609,"qty":608.89423391}],"asks":[],"checksum":3392149715,"timestamp":"2024-06-01T17:52:35.910459Z"}]}
{"channel":"book","type":"update","data":[{"symbol":"LINK/USD","bids":[{"price":18.56609,"qty":640.76923391}],"asks":[],"checksum":3637347278,"timestamp":"2024-06-01T17:52:35.914465Z"}]}
{"channel":"book","type":"update","data":[{"symbol":"LINK/USD","bids":[{"price":18.56609,"qty":608.89423391}],"asks":[],"checksum":3392149715,"timestamp":"2024-06-01T17:52:35.928468Z"}]}
{"channel":"book","type":"update","data":[{"symbol":"LINK/USD","bids":[{"price":18.56609,"qty":243.48672997}],"asks":[],"checksum":3587672574,"timestamp":"2024-06-01T17:52:35.952308Z"}]}
{"channel":"book","type":"update","data":[{"symbol":"LINK/USD","bids":[{"price":18.56527,"qty":243.48672997}],"asks":[],"checksum":1824022265,"timestamp":"2024-06-01T17:52:35.956406Z"}]}
{"channel":"book","type":"update","data":[{"symbol":"LINK/USD","bids":[{"price":18.56609,"qty":0.00000000},{"price":18.55782,"qty":33.00000000}],"asks":[],"checksum":2385197395,"timestamp":"2024-06-01T17:52:35.956448Z"}]}
{"channel":"book","type":"update","data":[{"symbol":"LINK/USD","bids":[{"price":18.56526,"qty":31.87500000}],"asks":[],"checksum":3468218339,"timestamp":"2024-06-01T17:52:35.959948Z"}]}
{"channel":"book","type":"update","data":[{"symbol":"LINK/USD","bids":[{"price":18.56569,"qty":31.87500000}],"asks":[],"checksum":485193626,"timestamp":"2024-06-01T17:52:35.960493Z"}]}
{"channel":"book","type":"update","data":[{"symbol":"LINK/USD","bids":[{"price":18.56566,"qty":31.87500000}],"asks":[],"checksum":613947143,"timestamp":"2024-06-01T17:52:35.963619Z"}]}
{"channel":"book","type":"update","data":[{"symbol":"LINK/USD","bids":[{"price":18.56567,"qty":243.48672997}],"asks":[],"checksum":2195457506,"timestamp":"2024-06-01T17:52:36.080559Z"}]}
{"channel":"book","type":"update","data":[{"symbol":"LINK/USD","bids":[{"price":18.56528,"qty":20.64921310}],"asks":[],"checksum":1547148460,"timestamp":"2024-06-01T17:52:36.109421Z"}]}
{"channel":"book","type":"update","data":[{"symbol":"LINK/USD","bids":[],"asks":[{"price":18.57087,"qty":0.00000000},{"price":18.57359,"qty":0.34605497},{"price":18.57082,"qty":1.50546674}],"checksum":3732198316,"timestamp":"2024-06-01T17:52:36.187342Z"}]}
{"channel":"book","type":"update","data":[{"symbol":"LINK/USD","bids":[],"asks":[{"price":18.57083,"qty":0.00000000},{"price":18.57359,"qty":0.34605497}],"checksum":2318181099,"timestamp":"2024-06-01T17:52:36.191099Z"}]}
{"channel":"book","type":"update","data":[{"symbol":"LINK/USD","bids":[{"price":18.56527,"qty":0.00000000},{"price":18.55981,"qty":31.87500000}],"asks":[],"checksum":1711814585,"timestamp":"2024-06-01T17:52:36.191139Z"}]}
{"channel":"book","type":"update","data":[{"symbol":"LINK/USD","bids":[],"asks":[{"price":18.57082,"qty":0.00000000},{"price":18.57466,"qty":0.40269630},{"price":18.57087,"qty":1.50546674}],"checksum":2230534917,"timestamp":"2024-06-01T17:52:36.194472Z"}]}
{"channel":"book","type":"update","data":[{"symbol":"LINK/USD","bids":[{"price":18.56569,"qty":0.00000000},{"price":18.55932,"qty":83.16198945}],"asks":[],"checksum":2165880135,"timestamp":"2024-06-01T17:52:36.521703Z"}]}
{"channel":"book","type":"update","data":[{"symbol":"LINK/USD","bids":[{"price":18.56567,"qty":0.00000000},{"price":18.55783,"qty":26.22402569}],"asks":[],"checksum":2094425901,"timestamp":"2024-06-01T17:52:36.524004Z"}]}
{"channel":"book","type":"update","data":[{"symbol":"LINK/USD","bids":[{"price":18.56578,"qty":31.87500000}],"asks":[],"checksum":908143978,"timestamp":"2024-06-01T17:52:36.525146Z"}]}
{"channel":"book","type":"update","data":[{"symbol":"LINK/USD","bids":[{"price":18.56566,"qty":0.00000000},{"price":18.55783,"qty":26.22402569}],"asks":[],"checksum":1528155990,"timestamp":"2024-06-01T17:52:36.525264Z"}]}
{"channel":"book","type":"update","data":[{"symbol":"LINK/USD","bids":[{"price":18.56288,"qty":0.00000000},{"price":18.55782,"qty":33.00000000}],"asks":[],"checksum":3243733967,"timestamp":"2024-06-01T17:52:36.528675Z"}]}
{"channel":"book","type":"update","data":[{"symbol":"LINK/USD","bids":[{"price":18.56578,"qty":0.00000000},{"price":18.55779,"qty":269.31533746}],"asks":[],"checksum":3279361553,"timestamp":"2024-06-01T17:52:36.528897Z"}]}
{"channel":"book","type":"update","data":[{"symbol":"LINK/USD","bids":[{"price":18.56526,"qty":0.00000000},{"price":18.55765,"qty":40.00000000}],"asks":[],"checksum":2138369982,"timestamp":"2024-06-01T17:52:36.529776Z"}]}
{"channel":"book","type":"update","data":[{"symbol":"LINK/USD","bids":[{"price":18.56392,"qty":31.87500000}],"asks":[],"checksum":2602494900,"timestamp":"2024-06-01T17:52:36.530461Z"}]}
{"channel":"book","type":"update","data":[{"symbol":"LINK/USD","bids":[{"price":18.56529,"qty":31.87500000}],"asks":[],"checksum":2841204257,"timestamp":"2024-06-01T17:52:36.537353Z"}]}
{"channel":"book","type":"update","data":[{"symbol":"LINK/USD","bids":[{"price":18.56529,"qty":0.00000000},{"price":18.55779,"qty":269.31533746}],"asks":[],"checksum":2602494900,"timestamp":"2024-06-01T17:52:36.578275Z"}]}
{"channel":"book","type":"update","data":[{"symbol":"LINK/USD","bids":[{"price":18.56168,"qty":269.30229451}],"asks":[],"checksum":3734705082,"timestamp":"2024-06-01T17:52:36.592473Z"}]}
{"channel":"book","type":"update","data":[{"symbol":"LINK/USD","bids":[{"price":18.56426,"qty":0.00000000},{"price":18.55779,"qty":269.31533746}],"asks":[],"checksum":1986040763,"timestamp":"2024-06-01T17:52:36.593936Z"}]}
{"channel":"book","type":"update","data":[{"symbol":"LINK/USD","bids":[{"price":18.56245,"qty":269.36096738}],"asks":[],"checksum":2718253174,"timestamp":"2024-06-01T17:52:36.597976Z"}]}
{"channel":"book","type":"update","data":[{"symbol":"LINK/USD","bids":[{"price":18.56529,"qty":365.41399727}],"asks":[],"checksum":1635365952,"timestamp":"2024-06-01T17:52:36.603295Z"}]}
{"channel":"book","type":"update","data":[{"symbol":"LINK/USD","bids":[{"price":18.55932,"qty":0.00000000},{"price":18.55782,"qty":33.00000000}],"asks":[],"checksum":2993273026,"timestamp":"2024-06-01T17:52:36.700159Z"}]}
{"channel":"book","type":"update","data":[{"symbol":"LINK/USD","bids":[{"price":18.56168,"qty":0.00000000},{"price":18.55779,"qty":269.31533746}],"asks":[],"checksum":4044910091,"timestamp":"2024-06-01T17:52:36.751808Z"}]}
{"channel":"book","type":"update","data":[{"symbol":"LINK/USD","bids":[],"asks":[{"price":18.57086,"qty":40.00000000}],"checksum":749337818,"timestamp":"2024-06-01T17:52:36.754053Z"}]}
{"channel":"book","type":"update","data":[{"symbol":"LINK/USD","bids":[],"asks":[{"price":18.57088,"qty":0.00000000},{"price":18.57359,"qty":0.34605497}],"checksum":1077189694,"timestamp":"2024-06-01T17:52:36.756612Z"}]}
{"channel":"book","type":"update","data":[{"symbol":"LINK/USD","bids":[],"asks":[{"price":18.57035,"qty":33.00000000}],"checksum":669989940,"timestamp":"2024-06-01T17:52:36.756703Z"}]}
{"channel":"book","type":"update","data":[{"symbol":"LINK/USD","bids":[{"price":18.56338,"qty":243.48672997}],"asks":[],"checksum":2072490520,"timestamp":"2024-06-01T17:52:36.757839Z"}]}
{"channel":"book","type":"update","data":[{"symbol":"LINK/USD","bids":[],"asks":[{"price":18.57139,"qty":0.00000000},{"price":18.57359,"qty":0.34605497}],"checksum":786177665,"timestamp":"2024-06-01T17:52:36.758052Z"}]}
{"channel":"book","type":"update","data":[{"symbol":"LINK/USD","bids":[],"asks":[{"price":18.57087,"qty":0.00000000},{"price":18.57466,"qty":0.40269630},{"price":18.57034,"qty":1.50546674}],"checksum":2104380203,"timestamp":"2024-06-01T17:52:36.806254Z"}]}
{"channel":"book","type":"update","data":[{"symbol":"LINK/USD","bids":[],"asks":[{"price":18.57033,"qty":40.00000000}],"checksum":4217144102,"timestamp":"2024-06-01T17:52:36.810956Z"}]}
{"channel":"book","type":"update","data":[{"symbol":"LINK/USD","bids":[],"asks":[{"price":18.57035,"qty":0.00000000},{"price":18.57359,"qty":0.34605497}],"checksum":1199433927,"timestamp":"2024-06-01T17:52:36.813525Z"}]}
{"channel":"book","type":"update","data":[{"symbol":"LINK/USD","bids":[],"asks":[{"price":18.56982,"qty":33.00000000}],"checksum":2371245478,"timestamp":"2024-06-01T17:52:36.813645Z"}]}
{"channel":"book","type":"update","data":[{"symbol":"LINK/USD","bids":[],"asks":[{"price":18.56982,"qty":64.87500000}],"checksum":3251967055,"timestamp":"2024-06-01T17:52:36.819293Z"}]}
{"channel":"book","type":"update","data":[{"symbol":"LINK/USD","bids":[{"price":18.55782,"qty":0.00000000},{"price":18.55779,"qty":269.31533746}],"asks":[],"checksum":1795144638,"timestamp":"2024-06-01T17:52:36.824135Z"}]}
{"channel":"book","type":"update","data":[{"symbol":"LINK/USD","bids":[{"price":18.55799,"qty":83.16794944}],"asks":[],"checksum":4055899535,"timestamp":"2024-06-01T17:52:36.846034Z"}]}
{"channel":"book","type":"update","data":[{"symbol":"LINK/USD","bids":[{"price":18.56529,"qty":0.00000000},{"price":18.55779,"qty":269.31533746}],"asks":[],"checksum":1606251105,"timestamp":"2024-06-01T17:52:37.170302Z"}]}
{"channel":"book","type":"update","data":[{"symbol":"LINK/USD","bids":[{"price":18.56392,"qty":0.00000000},{"price":18.55765,"qty":40.00000000}],"asks":[],"checksum":3229045435,"timestamp":"2024-06-01T17:52:37.173915Z"}]}
{"channel":"book","type":"update","data":[{"symbol":"LINK/USD","bids":[{"price":18.56515,"qty":243.48672997}],"asks":[],"checksum":1027245642,"timestamp":"2024-06-01T17:52:37.174092Z"}]}
{"channel":"book","type":"update","data":[{"symbol":"LINK/USD","bids":[],"asks":[{"price":18.57033,"qty":0.00000000},{"price":18.57359,"qty":0.34605497}],"checksum":4048649613,"timestamp":"2024-06-01T17:52:37.175131Z"}]}
{"channel":"book","type":"update","data":[{"symbol":"LINK/USD","bids":[{"price":18.56342,"qty":31.87500000}],"asks":[],"checksum":4182481227,"timestamp":"2024-06-01T17:52:37.177100Z"}]}
{"channel":"book","type":"update","data":[{"symbol":"LINK/USD","bids":[],"asks":[{"price":18.56981,"qty":13.46693598}],"checksum":466411056,"timestamp":"2024-06-01T17:52:37.222967Z"}]}
{"channel":"book","type":"update","data":[{"symbol":"LINK/USD","bids":[],"asks":[{"price":18.56981,"qty":0.00000000},{"price":18.57359,"qty":0.34605497}],"checksum":4182481227,"timestamp":"2024-06-01T17:52:37.226280Z"}]}
{"channel":"book","type":"update","data":[{"symbol":"LINK/USD","bids":[{"price":18.56338,"qty":0.00000000},{"price":18.55779,"qty":269.31533746}],"asks":[],"checksum":2965327554,"timestamp":"2024-06-01T17:52:37.226761Z"}]}
{"channel":"book","type":"update","data":[{"symbol":"LINK/USD","bids":[],"asks":[{"price":18.56979,"qty":40.00000000}],"checksum":1054137641,"timestamp":"2024-06-01T17:52:37.227826Z"}]}
{"channel":"book","type":"update","data":[{"symbol":"LINK/USD","bids":[],"asks":[{"price":18.57034,"qty":0.00000000},{"price":18.57359,"qty":0.34605497},{"price":18.56980,"qty":1.50546674}],"checksum":235594467,"timestamp":"2024-06-01T17:52:37.227853Z"}]}
{"channel":"book","type":"update","data":[{"symbol":"LINK/USD","bids":[],"asks":[{"price":18.56981,"qty":13.46693593}],"checksum":1670140420,"timestamp":"2024-06-01T17:52:37.229967Z"}]}
{"channel":"book","type":"update","data":[{"symbol":"LINK/USD","bids":[],"asks":[{"price":18.56928,"qty":33.00000000}],"checksum":3133655738,"timestamp":"2024-06-01T17:52:37.230577Z"}]}
{"channel":"book","type":"update","data":[{"symbol":"LINK/USD","bids":[],"asks":[{"price":18.56982,"qty":31.87500000}],"checksum":2170800531,"timestamp":"2024-06-01T17:52:37.230620Z"}]}
{"channel":"book","type":"update","data":[{"symbol":"LINK/USD","bids":[],"asks":[{"price":18.56981,"qty":0.00000000},{"price":18.57350,"qty":6.43107813}],"checksum":2751423764,"timestamp":"2024-06-01T17:52:37.233034Z"}]}
{"channel":"book","type":"update","data":[{"symbol":"LINK/USD","bids":[],"asks":[{"price":18.56927,"qty":13.46693642}],"checksum":2335146234,"timestamp":"2024-06-01T17:52:37.236001Z"}]}
{"channel":"book","type":"update","data":[{"symbol":"LINK/USD","bids":[],"asks":[{"price":18.56979,"qty":0.00000000},{"price":18.57350,"qty":6.43107813}],"checksum":2143024090,"timestamp":"2024-06-01T17:52:37.254760Z"}]}
{"channel":"book","type":"update","data":[{"symbol":"LINK/USD","bids":[],"asks":[{"price":18.56925,"qty":40.00000000}],"checksum":3149273795,"timestamp":"2024-06-01T17:52:37.260339Z"}]}
{"channel":"book","type":"update","data":[{"symbol":"LINK/USD","bids":[],"asks":[{"price":18.56928,"qty":0.00000000},{"price":18.57350,"qty":6.43107813}],"checksum":3695268081,"timestamp":"2024-06-01T17:52:37.263026Z"}]}
{"channel":"book","type":"update","data":[{"symbol":"LINK/USD","bids":[],"asks":[{"price":18.56892,"qty":33.00000000}],"checksum":3826679054,"timestamp":"2024-06-01T17:52:37.263240Z"}]}
{"channel":"book","type":"update","data":[{"symbol":"LINK/USD","bids":[],"asks":[{"price":18.56927,"qty":0.00000000},{"price":18.57350,"qty":6.43107813}],"checksum":2245614711,"timestamp":"2024-06-01T17:52:37.264243Z"}]}
{"channel":"book","type":"update","data":[{"symbol":"LINK/USD","bids":[],"asks":[{"price":18.56891,"qty":13.46693610}],"checksum":756669638,"timestamp":"2024-06-01T17:52:37.267228Z"}]}
{"channel":"book","type":"update","data":[{"symbol":"LINK/USD","bids":[{"price":18.56025,"qty":269.32548286}],"asks":[],"checksum":3890160565,"timestamp":"2024-06-01T17:52:37.444335Z"}]}
{"channel":"book","type":"update","data":[{"symbol":"LINK/USD","bids":[{"price":18.55783,"qty":0.00000000},{"price":18.55779,"qty":269.31533746}],"asks":[],"checksum":2340330785,"timestamp":"2024-06-01T17:52:37.646552Z"}]}
{"channel":"book","type":"update","data":[{"symbol":"LINK/USD","bids":[{"price":18.55800,"qty":6.88128717}],"asks":[],"checksum":180464945,"timestamp":"2024-06-01T17:52:37.656263Z"}]}
{"channel":"book","type":"update","data":[{"symbol":"LINK/USD","bids":[],"asks":[{"price":18.56980,"qty":0.00000000},{"price":18.57350,"qty":6.43107813},{"price":18.56890,"qty":1.50546674}],"checksum":747640789,"timestamp":"2024-06-01T17:52:37.685025Z"}]}
{"channel":"book","type":"update","data":[{"symbol":"LINK/USD","bids":[],"asks":[{"price":18.56891,"qty":0.00000000},{"price":18.57350,"qty":6.43107813}],"checksum":1008320168,"timestamp":"2024-06-01T17:52:37.689469Z"}]}
{"channel":"book","type":"update","data":[{"symbol":"LINK/USD","bids":[],"asks":[{"price":18.56925,"qty":0.00000000},{"price":18.57354,"qty":31.87500000}],"checksum":1262184992,"timestamp":"2024-06-01T17:52:37.690057Z"}]}
{"channel":"book","type":"update","data":[{"symbol":"LINK/USD","bids":[],"asks":[{"price":18.56890,"qty":0.00000000},{"price":18.57359,"qty":0.34605497},{"price":18.56891,"qty":1.50546674}],"checksum":433100122,"timestamp":"2024-06-01T17:52:37.693300Z"}]}
{"channel":"book","type":"update","data":[{"symbol":"LINK/USD","bids":[{"price":18.56535,"qty":31.87500000}],"asks":[],"checksum":2465104560,"timestamp":"2024-06-01T17:52:37.968570Z"}]}
{"channel":"book","type":"update","data":[{"symbol":"LINK/USD","bids":[{"price":18.56530,"qty":31.87500000}],"asks":[],"checksum":3643276028,"timestamp":"2024-06-01T17:52:37.968699Z"}]}
{"channel":"book","type":"update","data":[{"symbol":"LINK/USD","bids":[],"asks":[{"price":18.56982,"qty":0.00000000},{"price":18.57359,"qty":0.34605497}],"checksum":3927485391,"timestamp":"2024-06-01T17:52:37.970538Z"}]}
{"channel":"book","type":"update","data":[{"symbol":"LINK/USD","bids":[{"price":18.56535,"qty":63.75000000}],"asks":[],"checksum":393414416,"timestamp":"2024-06-01T17:52:37.972778Z"}]}
{"channel":"book","type":"update","data":[{"symbol":"LINK/USD","bids":[{"price":18.56530,"qty":0.00000000},{"price":18.55800,"qty":6.88128717}],"asks":[],"checksum":2818044359,"timestamp":"2024-06-01T17:52:37.973112Z"}]}
{"channel":"book","type":"update","data":[{"symbol":"LINK/USD","bids":[],"asks":[{"price":18.56892,"qty":0.00000000},{"price":18.57466,"qty":0.40269630}],"checksum":3946646676,"timestamp":"2024-06-01T17:52:37.973780Z"}]}
{"channel":"book","type":"update","data":[{"symbol":"LINK/USD","bids":[],"asks":[{"price":18.57035,"qty":33.00000000}],"checksum":1733064528,"timestamp":"2024-06-01T17:52:37.973959Z"}]}
{"channel":"book","type":"update","data":[{"symbol":"LINK/USD","bids":[],"asks":[{"price":18.56891,"qty":0.00000000},{"price":18.57466,"qty":0.40269630},{"price":18.57085,"qty":1.50546674}],"checksum":519886085,"timestamp":"2024-06-01T17:52:37.977168Z"}]}
{"channel":"book","type":"update","data":[{"symbol":"LINK/USD","bids":[],"asks":[{"price":18.57350,"qty":0.00000000},{"price":18.57466,"qty":0.40269630}],"checksum":4202432069,"timestamp":"2024-06-01T17:52:37.998199Z"}]}
{"channel":"book","type":"update","data":[{"symbol":"LINK/USD","bids":[],"asks":[{"price":18.57086,"qty":0.00000000},{"price":18.57685,"qty":1.31717222}],"checksum":2239605290,"timestamp":"2024-06-01T17:52:38.056192Z"}]}
{"channel":"book","type":"update","data":[{"symbol":"LINK/USD","bids":[],"asks":[{"price":18.57035,"qty":0.00000000},{"price":18.57912,"qty":31.87500000}],"checksum":755660084,"timestamp":"2024-06-01T17:52:38.059896Z"}]}
{"channel":"book","type":"update","data":[{"symbol":"LINK/USD","bids":[],"asks":[{"price":18.57194,"qty":33.00000000}],"checksum":665764682,"timestamp":"2024-06-01T17:52:38.060090Z"}]}
{"channel":"book","type":"update","data":[{"symbol":"LINK/USD","bids":[],"asks":[{"price":18.57085,"qty":0.00000000},{"price":18.57912,"qty":31.87500000},{"price":18.57157,"qty":1.50546674}],"checksum":4280944465,"timestamp":"2024-06-01T17:52:38.069294Z"}]}
{"channel":"book","type":"update","data":[{"symbol":"LINK/USD","bids":[],"asks":[{"price":18.57168,"qty":31.87500000}],"checksum":677456634,"timestamp":"2024-06-01T17:52:38.102918Z"}]}
{"channel":"book","type":"update","data":[{"symbol":"LINK/USD","bids":[],"asks":[{"price":18.57268,"qty":6.43107813}],"checksum":3009666390,"timestamp":"2024-06-01T17:52:38.143920Z"}]}
{"channel":"book","type":"update","data":[{"symbol":"LINK/USD","bids":[],"asks":[{"price":18.57156,"qty":40.00000000}],"checksum":2070489163,"timestamp":"2024-06-01T17:52:38.254599Z"}]}
{"channel":"book","type":"update","data":[{"symbol":"LINK/USD","bids":[],"asks":[{"price":18.57157,"qty":0.00000000},{"price":18.57359,"qty":0.34605497},{"price":18.57155,"qty":1.50546674}],"checksum":1009461364,"timestamp":"2024-06-01T17:52:38.257738Z"}]}
{"channel":"book","type":"update","data":[{"symbol":"LINK/USD","bids":[{"price":18.56528,"qty":0.00000000},{"price":18.55799,"qty":83.16794944}],"asks":[],"checksum":2388908013,"timestamp":"2024-06-01T17:52:38.262228Z"}]}
{"channel":"book","type":"update","data":[{"symbol":"LINK/USD","bids":[{"price":18.56535,"qty":429.16181994}],"asks":[],"checksum":1877197174,"timestamp":"2024-06-01T17:52:38.355861Z"}]}
{"channel":"book","type":"update","data":[{"symbol":"LINK/USD","bids":[{"price":18.56555,"qty":31.87500000}],"asks":[],"checksum":4123807891,"timestamp":"2024-06-01T17:52:38.359908Z"}]}
{"channel":"book","type":"update","data":[{"symbol":"LINK/USD","bids":[{"price":18.56555,"qty":0.00000000},{"price":18.55780,"qty":11.71798172}],"asks":[],"checksum":3635126063,"timestamp":"2024-06-01T17:52:38.550205Z"}]}
{"channel":"book","type":"update","data":[{"symbol":"LINK/USD","bids":[{"price":18.56535,"qty":397.28681994}],"asks":[],"checksum":718899225,"timestamp":"2024-06-01T17:52:38.554318Z"}]}
{"channel":"book","type":"update","data":[{"symbol":"LINK/USD","bids":[{"price":18.56535,"qty":429.16181994}],"asks":[],"checksum":3635126063,"timestamp":"2024-06-01T17:52:38.569049Z"}]}
{"channel":"book","type":"update","data":[{"symbol":"LINK/USD","bids":[{"price":18.56535,"qty":397.28681994}],"asks":[],"checksum":718899225,"timestamp":"2024-06-01T17:52:38.570418Z"}]}
{"channel":"book","type":"update","data":[{"symbol":"LINK/USD","bids":[{"price":18.56535,"qty":429.16181994}],"asks":[],"checksum":3635126063,"timestamp":"2024-06-01T17:52:38.595714Z"}]}
{"channel":"book","type":"update","data":[{"symbol":"LINK/USD","bids":[{"price":18.56535,"qty":397.28681994}],"asks":[],"checksum":718899225,"timestamp":"2024-06-01T17:52:38.599500Z"}]}
{"channel":"book","type":"update","data":[{"symbol":"LINK/USD","bids":[{"price":18.56535,"qty":365.41181994}],"asks":[],"checksum":2977477759,"timestamp":"2024-06-01T17:52:38.600110Z"}]}
{"channel":"book","type":"update","data":[{"symbol":"LINK/USD","bids":[{"price":18.56537,"qty":31.87500000}],"asks":[],"checksum":1291462735,"timestamp":"2024-06-01T17:52:38.656188Z"}]}
{"channel":"book","type":"update","data":[{"symbol":"LINK/USD","bids":[{"price":18.55847,"qty":83.16579836}],"asks":[],"checksum":2213107675,"timestamp":"2024-06-01T17:52:38.656974Z"}]}
{"channel":"book","type":"update","data":[{"symbol":"LINK/USD","bids":[{"price":18.56537,"qty":0.00000000},{"price":18.55800,"qty":6.88128717}],"asks":[],"checksum":4088511340,"timestamp":"2024-06-01T17:52:38.659409Z"}]}
{"channel":"book","type":"update","data":[{"symbol":"LINK/USD","bids":[{"price":18.56537,"qty":31.87500000}],"asks":[],"checksum":2213107675,"timestamp":"2024-06-01T17:52:38.659624Z"}]}
{"channel":"book","type":"update","data":[{"symbol":"LINK/USD","bids":[{"price":18.56537,"qty":63.75000000}],"asks":[],"checksum":2507731762,"timestamp":"2024-06-01T17:52:38.662901Z"}]}
{"channel":"book","type":"update","data":[{"symbol":"LINK/USD","bids":[{"price":18.56537,"qty":31.87500000}],"asks":[],"checksum":2213107675,"timestamp":"2024-06-01T17:52:38.699085Z"}]}
{"channel":"book","type":"update","data":[{"symbol":"LINK/USD","bids":[],"asks":[{"price":18.57154,"qty":13.46687083}],"checksum":1812163111,"timestamp":"2024-06-01T17:52:38.703441Z"}]}
{"channel":"book","type":"update","data":[{"symbol":"LINK/USD","bids":[{"price":18.56537,"qty":63.75000000}],"asks":[],"checksum":2056441550,"timestamp":"2024-06-01T17:52:38.703544Z"}]}
{"channel":"book","type":"update","data":[{"symbol":"LINK/USD","bids":[],"asks":[{"price":18.57154,"qty":0.00000000},{"price":18.57354,"qty":31.87500000}],"checksum":2507731762,"timestamp":"2024-06-01T17:52:38.706893Z"}]}
{"channel":"book","type":"update","data":[{"symbol":"LINK/USD","bids":[],"asks":[{"price":18.57154,"qty":13.46686890}],"checksum":233008954,"timestamp":"2024-06-01T17:52:38.709870Z"}]}
{"channel":"book","type":"update","data":[{"symbol":"LINK/USD","bids":[],"asks":[{"price":18.57268,"qty":0.00000000},{"price":18.57354,"qty":31.87500000}],"checksum":1263492631,"timestamp":"2024-06-01T17:52:38.748102Z"}]}
{"channel":"book","type":"update","data":[{"symbol":"LINK/USD","bids":[],"asks":[{"price":18.57152,"qty":40.00000000}],"checksum":1942087093,"timestamp":"2024-06-01T17:52:38.753952Z"}]}
{"channel":"book","type":"update","data":[{"symbol":"LINK/USD","bids":[],"asks":[{"price":18.57156,"qty":0.00000000},{"price":18.57354,"qty":31.87500000}],"checksum":3855032166,"timestamp":"2024-06-01T17:52:38.757962Z"}]}
{"channel":"book","type":"update","data":[{"symbol":"LINK/USD","bids":[{"price":18.56536,"qty":20.64921310}],"asks":[],"checksum":2805554510,"timestamp":"2024-06-01T17:52:38.761037Z"}]}
{"channel":"book","type":"update","data":[{"symbol":"LINK/USD","bids":[],"asks":[{"price":18.57154,"qty":0.00000000},{"price":18.57359,"qty":0.34605497}],"checksum":278830216,"timestamp":"2024-06-01T17:52:38.787242Z"}]}
{"channel":"book","type":"update","data":[{"symbol":"LINK/USD","bids":[],"asks":[{"price":18.57151,"qty":13.46686791}],"checksum":2435727406,"timestamp":"2024-06-01T17:52:38.789871Z"}]}
{"channel":"book","type":"update","data":[{"symbol":"LINK/USD","bids":[],"asks":[{"price":18.57155,"qty":0.00000000},{"price":18.57359,"qty":0.34605497},{"price":18.57150,"qty":1.50546674}],"checksum":1559506937,"timestamp":"2024-06-01T17:52:38.805100Z"}]}
{"channel":"book","type":"update","data":[{"symbol":"LINK/USD","bids":[],"asks":[{"price":18.57151,"qty":0.00000000},{"price":18.57359,"qty":0.34605497}],"checksum":496922633,"timestamp":"2024-06-01T17:52:38.809582Z"}]}
{"channel":"book","type":"update","data":[{"symbol":"LINK/USD","bids":[],"asks":[{"price":18.57150,"qty":0.00000000},{"price":18.57466,"qty":0.40269630},{"price":18.57151,"qty":1.50546674}],"checksum":2904294356,"timestamp":"2024-06-01T17:52:38.812595Z"}]}
{"channel":"book","type":"update","data":[{"symbol":"LINK/USD","bids":[],"asks":[{"price":18.57149,"qty":13.46686789}],"checksum":3548524199,"timestamp":"2024-06-01T17:52:38.813029Z"}]}
{"channel":"book","type":"update","data":[{"symbol":"LINK/USD","bids":[{"price":18.56535,"qty":0.00000000},{"price":18.55847,"qty":83.16579836}],"asks":[],"checksum":3957606826,"timestamp":"2024-06-01T17:52:38.996066Z"}]}
{"channel":"book","type":"update","data":[{"symbol":"LINK/USD","bids":[],"asks":[{"price":18.57147,"qty":40.00000000}],"checksum":91080919,"timestamp":"2024-06-01T17:52:39.000969Z"}]}
{"channel":"book","type":"update","data":[{"symbol":"LINK/USD","bids":[],"asks":[{"price":18.57149,"qty":0.00000000},{"price":18.57354,"qty":31.87500000}],"checksum":1819371966,"timestamp":"2024-06-01T17:52:39.005138Z"}]}
{"channel":"book","type":"update","data":[{"symbol":"LINK/USD","bids":[],"asks":[{"price":18.57146,"qty":13.46688221}],"checksum":1546110424,"timestamp":"2024-06-01T17:52:39.008918Z"}]}
{"channel":"book","type":"update","data":[{"symbol":"LINK/USD","bids":[{"price":18.56537,"qty":429.16558890}],"asks":[],"checksum":2779761664,"timestamp":"2024-06-01T17:52:39.036488Z"}]}
{"channel":"book","type":"update","data":[{"symbol":"LINK/USD","bids":[{"price":18.56609,"qty":31.87500000}],"asks":[],"checksum":1270690030,"timestamp":"2024-06-01T17:52:39.040554Z"}]}
{"channel":"book","type":"update","data":[{"symbol":"LINK/USD","bids":[],"asks":[{"price":18.57147,"qty":0.00000000},{"price":18.57354,"qty":31.87500000}],"checksum":311953354,"timestamp":"2024-06-01T17:52:39.041248Z"}]}
{"channel":"book","type":"update","data":[{"symbol":"LINK/USD","bids":[{"price":18.56609,"qty":0.00000000},{"price":18.55847,"qty":83.16579836}],"asks":[],"checksum":4236966692,"timestamp":"2024-06-01T17:52:39.142165Z"}]}
{"channel":"book","type":"update","data":[{"symbol":"LINK/USD","bids":[{"price":18.56609,"qty":31.87500000}],"asks":[],"checksum":311953354,"timestamp":"2024-06-01T17:52:39.145574Z"}]}
{"channel":"book","type":"update","data":[{"symbol":"LINK/USD","bids":[],"asks":[{"price":18.57144,"qty":40.00000000}],"checksum":3268395005,"timestamp":"2024-06-01T17:52:39.146960Z"}]}
{"channel":"book","type":"update","data":[{"symbol":"LINK/USD","bids":[],"asks":[{"price":18.57146,"qty":0.00000000},{"price":18.57354,"qty":31.87500000}],"checksum":847501716,"timestamp":"2024-06-01T17:52:39.150249Z"}]}
{"channel":"book","type":"update","data":[{"symbol":"LINK/USD","bids":[],"asks":[{"price":18.57173,"qty":6.43107813}],"checksum":2167766017,"timestamp":"2024-06-01T17:52:39.152101Z"}]}
{"channel":"book","type":"update","data":[{"symbol":"LINK/USD","bids":[],"asks":[{"price":18.57144,"qty":0.00000000},{"price":18.57354,"qty":31.87500000}],"checksum":734934224,"timestamp":"2024-06-01T17:52:39.254297Z"}]}
{"channel":"book","type":"update","data":[{"symbol":"LINK/USD","bids":[{"price":18.56609,"qty":0.00000000},{"price":18.55847,"qty":83.16579836}],"asks":[],"checksum":3319580734,"timestamp":"2024-06-01T17:52:39.301643Z"}]}
{"channel":"book","type":"update","data":[{"symbol":"LINK/USD","bids":[{"price":18.56581,"qty":31.87500000}],"asks":[],"checksum":3035120754,"timestamp":"2024-06-01T17:52:39.305649Z"}]}
{"channel":"book","type":"update","data":[{"symbol":"LINK/USD","bids":[{"price":18.56581,"qty":0.00000000},{"price":18.55847,"qty":83.16579836}],"asks":[],"checksum":3319580734,"timestamp":"2024-06-01T17:52:39.319430Z"}]}
{"channel":"book","type":"update","data":[{"symbol":"LINK/USD","bids":[{"price":18.56579,"qty":31.87500000}],"asks":[],"checksum":1841961202,"timestamp":"2024-06-01T17:52:39.322951Z"}]}
{"channel":"book","type":"update","data":[{"symbol":"LINK/USD","bids":[{"price":18.56579,"qty":0.00000000},{"price":18.55847,"qty":83.16579836}],"asks":[],"checksum":3319580734,"timestamp":"2024-06-01T17:52:39.523746Z"}]}
{"channel":"book","type":"update","data":[{"symbol":"LINK/USD","bids":[{"price":18.56578,"qty":31.87500000}],"asks":[],"checksum":3155508181,"timestamp":"2024-06-01T17:52:39.527130Z"}]}
{"channel":"book","type":"update","data":[{"symbol":"LINK/USD","bids":[{"price":18.56578,"qty":0.00000000},{"price":18.55847,"qty":83.16579836}],"asks":[],"checksum":3319580734,"timestamp":"2024-06-01T17:52:39.559909Z"}]}
{"channel":"book","type":"update","data":[{"symbol":"LINK/USD","bids":[{"price":18.56537,"qty":397.29058890}],"asks":[],"checksum":4132991071,"timestamp":"2024-06-01T17:52:39.563741Z"}]}
{"channel":"book","type":"update","data":[{"symbol":"LINK/USD","bids":[{"price":18.56567,"qty":31.87500000}],"asks":[],"checksum":705870847,"timestamp":"2024-06-01T17:52:39.563770Z"}]}
{"channel":"book","type":"update","data":[{"symbol":"LINK/USD","bids":[{"price":18.56563,"qty":31.87500000}],"asks":[],"checksum":1428136974,"timestamp":"2024-06-01T17:52:39.566276Z"}]}
{"channel":"book","type":"update","data":[{"symbol":"LINK/USD","bids":[],"asks":[{"price":18.57152,"qty":0.00000000},{"price":18.57359,"qty":0.34605497}],"checksum":3052951402,"timestamp":"2024-06-01T17:52:39.753562Z"}]}
{"channel":"book","type":"update","data":[{"symbol":"LINK/USD","bids":[],"asks":[{"price":18.57156,"qty":40.00000000}],"checksum":3587529434,"timestamp":"2024-06-01T17:52:39.753587Z"}]}
{"channel":"book","type":"update","data":[{"symbol":"LINK/USD","bids":[],"asks":[{"price":18.57151,"qty":0.00000000},{"price":18.57359,"qty":0.34605497},{"price":18.57157,"qty":1.50546674}],"checksum":3634465614,"timestamp":"2024-06-01T17:52:39.756975Z"}]}
{"channel":"book","type":"update","data":[{"symbol":"LINK/USD","bids":[],"asks":[{"price":18.57155,"qty":13.46680976}],"checksum":1182309297,"timestamp":"2024-06-01T17:52:40.202863Z"}]}
{"channel":"book","type":"update","data":[{"symbol":"LINK/USD","bids":[],"asks":[{"price":18.57155,"qty":0.00000000},{"price":18.57354,"qty":31.87500000}],"checksum":3634465614,"timestamp":"2024-06-01T17:52:40.206166Z"}]}
{"channel":"book","type":"update","data":[{"symbol":"LINK/USD","bids":[],"asks":[{"price":18.57153,"qty":40.00000000}],"checksum":1984696591,"timestamp":"2024-06-01T17:52:40.208111Z"}]}
{"channel":"book","type":"update","data":[{"symbol":"LINK/USD","bids":[],"asks":[{"price":18.57153,"qty":0.00000000},{"price":18.57354,"qty":31.87500000}],"checksum":3634465614,"timestamp":"2024-06-01T17:52:40.253970Z"}]}
{"channel":"book","type":"update","data":[{"symbol":"LINK/USD","bids":[{"price":18.56567,"qty":0.00000000},{"price":18.55981,"qty":31.87500000}],"asks":[],"checksum":1446122657,"timestamp":"2024-06-01T17:52:40.301676Z"}]}
{"channel":"book","type":"update","data":[{"symbol":"LINK/USD","bids":[{"price":18.56563,"qty":0.00000000},{"price":18.55847,"qty":83.16579836}],"asks":[],"checksum":2078695199,"timestamp":"2024-06-01T17:52:40.305476Z"}]}
{"channel":"book","type":"update","data":[{"symbol":"LINK/USD","bids":[{"price":18.56559,"qty":31.87500000}],"asks":[],"checksum":598600266,"timestamp":"2024-06-01T17:52:40.309680Z"}]}
{"channel":"book","type":"update","data":[{"symbol":"LINK/USD","bids":[{"price":18.56557,"qty":31.87500000}],"asks":[],"checksum":1024002006,"timestamp":"2024-06-01T17:52:40.312798Z"}]}
{"channel":"book","type":"update","data":[{"symbol":"LINK/USD","bids":[{"price":18.56559,"qty":0.00000000},{"price":18.55981,"qty":31.87500000}],"asks":[],"checksum":2461019174,"timestamp":"2024-06-01T17:52:40.314986Z"}]}
{"channel":"book","type":"update","data":[{"symbol":"LINK/USD","bids":[{"price":18.56557,"qty":0.00000000},{"price":18.55847,"qty":83.16579836}],"asks":[],"checksum":2078695199,"timestamp":"2024-06-01T17:52:40.318010Z"}]}
{"channel":"book","type":"update","data":[{"symbol":"LINK/USD","bids":[{"price":18.56550,"qty":31.87500000}],"asks":[],"checksum":3393113872,"timestamp":"2024-06-01T17:52:40.321534Z"}]}
{"channel":"book","type":"update","data":[{"symbol":"LINK/USD","bids":[{"price":18.56550,"qty":63.75000000}],"asks":[],"checksum":3702483961,"timestamp":"2024-06-01T17:52:40.328125Z"}]}
{"channel":"book","type":"update","data":[{"symbol":"LINK/USD","bids":[],"asks":[{"price":18.57157,"qty":0.00000000},{"price":18.57359,"qty":0.34605497},{"price":18.57155,"qty":1.50546674}],"checksum":2221999751,"timestamp":"2024-06-01T17:52:40.328727Z"}]}
{"channel":"book","type":"update","data":[{"symbol":"LINK/USD","bids":[{"price":18.56550,"qty":31.87500000}],"asks":[],"checksum":2464195182,"timestamp":"2024-06-01T17:52:40.362592Z"}]}
{"channel":"book","type":"update","data":[{"symbol":"LINK/USD","bids":[{"price":18.56550,"qty":63.75000000}],"asks":[],"checksum":2221999751,"timestamp":"2024-06-01T17:52:40.401975Z"}]}
{"channel":"book","type":"update","data":[{"symbol":"LINK/USD","bids":[{"price":18.56550,"qty":31.87500000}],"asks":[],"checksum":2464195182,"timestamp":"2024-06-01T17:52:40.781083Z"}]}
{"channel":"book","type":"update","data":[{"symbol":"LINK/USD","bids":[{"price":18.56537,"qty":365.41558890}],"asks":[],"checksum":1557411069,"timestamp":"2024-06-01T17:52:40.781574Z"}]}
{"channel":"book","type":"update","data":[{"symbol":"LINK/USD","bids":[{"price":18.56550,"qty":0.00000000},{"price":18.55847,"qty":83.16579836}],"asks":[],"checksum":2076051679,"timestamp":"2024-06-01T17:52:40.781872Z"}]}
{"channel":"book","type":"update","data":[{"symbol":"LINK/USD","bids":[{"price":18.56544,"qty":31.87500000}],"asks":[],"checksum":143777451,"timestamp":"2024-06-01T17:52:40.786619Z"}]}
{"channel":"book","type":"update","data":[{"symbol":"LINK/USD","bids":[{"price":18.56537,"qty":397.29058890}],"asks":[],"checksum":3332720696,"timestamp":"2024-06-01T17:52:40.787057Z"}]}
{"channel":"book","type":"update","data":[{"symbol":"LINK/USD","bids":[{"price":18.56540,"qty":31.87500000}],"asks":[],"checksum":868064442,"timestamp":"2024-06-01T17:52:40.787473Z"}]}
{"channel":"book","type":"update","data":[{"symbol":"LINK/USD","bids":[{"price":18.56540,"qty":0.00000000},{"price":18.55981,"qty":31.87500000}],"asks":[],"checksum":3332720696,"timestamp":"2024-06-01T17:52:40.790173Z"}]}
{"channel":"book","type":"update","data":[{"symbol":"LINK/USD","bids":[{"price":18.56544,"qty":63.75000000}],"asks":[],"checksum":3493129425,"timestamp":"2024-06-01T17:52:40.793445Z"}]}
{"channel":"book","type":"update","data":[{"symbol":"LINK/USD","bids":[{"price":18.56544,"qty":31.87500000}],"asks":[],"checksum":3332720696,"timestamp":"2024-06-01T17:52:40.812005Z"}]}
{"channel":"book","type":"update","data":[{"symbol":"LINK/USD","bids":[{"price":18.56537,"qty":365.41558890}],"asks":[],"checksum":143777451,"timestamp":"2024-06-01T17:52:40.812558Z"}]}
{"channel":"book","type":"update","data":[{"symbol":"LINK/USD","bids":[{"price":18.56544,"qty":0.00000000},{"price":18.55847,"qty":83.16579836}],"asks":[],"checksum":2076051679,"timestamp":"2024-06-01T17:52:40.812592Z"}]}
{"channel":"book","type":"update","data":[{"symbol":"LINK/USD","bids":[{"price":18.56549,"qty":31.87500000}],"asks":[],"checksum":278690799,"timestamp":"2024-06-01T17:52:40.814907Z"}]}
{"channel":"book","type":"update","data":[{"symbol":"LINK/USD","bids":[{"price":18.56551,"qty":31.87500000}],"asks":[],"checksum":2634136575,"timestamp":"2024-06-01T17:52:40.816524Z"}]}
{"channel":"book","type":"update","data":[{"symbol":"LINK/USD","bids":[{"price":18.56549,"qty":0.00000000},{"price":18.55981,"qty":31.87500000}],"asks":[],"checksum":2366314458,"timestamp":"2024-06-01T17:52:40.818221Z"}]}
{"channel":"book","type":"update","data":[{"symbol":"LINK/USD","bids":[{"price":18.56551,"qty":63.75000000}],"asks":[],"checksum":2610606899,"timestamp":"2024-06-01T17:52:40.821626Z"}]}
{"channel":"book","type":"update","data":[{"symbol":"LINK/USD","bids":[{"price":18.56551,"qty":31.87500000}],"asks":[],"checksum":2366314458,"timestamp":"2024-06-01T17:52:40.838031Z"}]}
{"channel":"book","type":"update","data":[{"symbol":"LINK/USD","bids":[{"price":18.56551,"qty":0.00000000},{"price":18.55847,"qty":83.16579836}],"asks":[],"checksum":2076051679,"timestamp":"2024-06-01T17:52:40.840421Z"}]}
{"channel":"book","type":"update","data":[{"symbol":"LINK/USD","bids":[{"price":18.56538,"qty":31.87500000}],"asks":[],"checksum":245449650,"timestamp":"2024-06-01T17:52:40.848361Z"}]}
{"channel":"book","type":"update","data":[{"symbol":"LINK/USD","bids":[{"price":18.56537,"qty":397.29058890}],"asks":[],"checksum":3231044897,"timestamp":"2024-06-01T17:52:40.850237Z"}]}
{"channel":"book","type":"update","data":[{"symbol":"LINK/USD","bids":[{"price":18.56538,"qty":0.00000000},{"price":18.55847,"qty":83.16579836}],"asks":[],"checksum":590885473,"timestamp":"2024-06-01T17:52:40.851466Z"}]}
{"channel":"book","type":"update","data":[{"symbol":"LINK/USD","bids":[{"price":18.56537,"qty":365.41558890}],"asks":[],"checksum":2076051679,"timestamp":"2024-06-01T17:52:40.853680Z"}]}
{"channel":"book","type":"update","data":[{"symbol":"LINK/USD","bids":[{"price":18.56539,"qty":31.87500000}],"asks":[],"checksum":3749601429,"timestamp":"2024-06-01T17:52:40.860847Z"}]}
{"channel":"book","type":"update","data":[{"symbol":"LINK/USD","bids":[{"price":18.56543,"qty":31.87500000}],"asks":[],"checksum":101168429,"timestamp":"2024-06-01T17:52:40.861362Z"}]}
{"channel":"book","type":"update","data":[{"symbol":"LINK/USD","bids":[{"price":18.56543,"qty":0.00000000},{"price":18.55981,"qty":31.87500000}],"asks":[],"checksum":3749601429,"timestamp":"2024-06-01T17:52:40.864050Z"}]}
{"channel":"book","type":"update","data":[{"symbol":"LINK/USD","bids":[{"price":18.56539,"qty":0.00000000},{"price":18.55847,"qty":83.16579836}],"asks":[],"checksum":2076051679,"timestamp":"2024-06-01T17:52:40.872696Z"}]}
{"channel":"book","type":"update","data":[{"symbol":"LINK/USD","bids":[{"price":18.56541,"qty":31.87500000}],"asks":[],"checksum":684752274,"timestamp":"2024-06-01T17:52:40.881224Z"}]}
{"channel":"book","type":"update","data":[{"symbol":"LINK/USD","bids":[{"price":18.56537,"qty":397.29058890}],"asks":[],"checksum":3873762049,"timestamp":"2024-06-01T17:52:40.881760Z"}]}
{"channel":"book","type":"update","data":[{"symbol":"LINK/USD","bids":[{"price":18.56551,"qty":31.87500000}],"asks":[],"checksum":804222404,"timestamp":"2024-06-01T17:52:40.882392Z"}]}
{"channel":"book","type":"update","data":[{"symbol":"LINK/USD","bids":[{"price":18.56541,"qty":0.00000000},{"price":18.55981,"qty":31.87500000}],"asks":[],"checksum":1128235337,"timestamp":"2024-06-01T17:52:40.884222Z"}]}
{"channel":"book","type":"update","data":[{"symbol":"LINK/USD","bids":[{"price":18.56537,"qty":365.41558890}],"asks":[],"checksum":2366314458,"timestamp":"2024-06-01T17:52:40.885239Z"}]}
{"channel":"book","type":"update","data":[{"symbol":"LINK/USD","bids":[{"price":18.56551,"qty":0.00000000},{"price":18.55847,"qty":83.16579836}],"asks":[],"checksum":2076051679,"timestamp":"2024-06-01T17:52:40.885985Z"}]}
{"channel":"book","type":"update","data":[{"symbol":"LINK/USD","bids":[{"price":18.56536,"qty":0.00000000},{"price":18.55780,"qty":17.35151544}],"asks":[],"checksum":4267890356,"timestamp":"2024-06-01T17:52:40.918798Z"}]}
{"channel":"book","type":"update","data":[{"symbol":"LINK/USD","bids":[{"price":18.56537,"qty":397.29058890}],"asks":[],"checksum":2800020490,"timestamp":"2024-06-01T17:52:41.004927Z"}]}
{"channel":"book","type":"update","data":[{"symbol":"LINK/USD","bids":[{"price":18.56537,"qty":429.16558890}],"asks":[],"checksum":2506118251,"timestamp":"2024-06-01T17:52:41.009624Z"}]}
{"channel":"book","type":"update","data":[{"symbol":"LINK/USD","bids":[{"price":18.56539,"qty":31.87500000}],"asks":[],"checksum":851452838,"timestamp":"2024-06-01T17:52:41.072272Z"}]}
{"channel":"book","type":"update","data":[{"symbol":"LINK/USD","bids":[{"price":18.56537,"qty":397.29058890}],"asks":[],"checksum":1641950351,"timestamp":"2024-06-01T17:52:41.075888Z"}]}
{"channel":"book","type":"update","data":[{"symbol":"LINK/USD","bids":[{"price":18.56539,"qty":63.75000000}],"asks":[],"checksum":2001700966,"timestamp":"2024-06-01T17:52:41.078539Z"}]}
{"channel":"book","type":"update","data":[{"symbol":"LINK/USD","bids":[{"price":18.56539,"qty":31.87500000}],"asks":[],"checksum":1641950351,"timestamp":"2024-06-01T17:52:41.097692Z"}]}
{"channel":"book","type":"update","data":[{"symbol":"LINK/USD","bids":[{"price":18.56537,"qty":365.41558890}],"asks":[],"checksum":2951395868,"timestamp":"2024-06-01T17:52:41.098175Z"}]}
{"channel":"book","type":"update","data":[{"symbol":"LINK/USD","bids":[{"price":18.56539,"qty":0.00000000},{"price":18.55780,"qty":17.35151544}],"asks":[],"checksum":4267890356,"timestamp":"2024-06-01T17:52:41.098378Z"}]}
{"channel":"book","type":"update","data":[{"symbol":"LINK/USD","bids":[],"asks":[{"price":18.57194,"qty":0.00000000},{"price":18.57359,"qty":0.34605497}],"checksum":3182150057,"timestamp":"2024-06-01T17:52:41.101456Z"}]}
{"channel":"book","type":"update","data":[{"symbol":"LINK/USD","bids":[],"asks":[{"price":18.57104,"qty":33.00000000}],"checksum":3639841053,"timestamp":"2024-06-01T17:52:41.101698Z"}]}
{"channel":"book","type":"update","data":[{"symbol":"LINK/USD","bids":[{"price":18.56544,"qty":31.87500000}],"asks":[],"checksum":1586774923,"timestamp":"2024-06-01T17:52:41.105078Z"}]}
{"channel":"book","type":"update","data":[{"symbol":"LINK/USD","bids":[],"asks":[{"price":18.57155,"qty":0.00000000},{"price":18.57359,"qty":0.34605497},{"price":18.57103,"qty":1.50546674}],"checksum":2135266059,"timestamp":"2024-06-01T17:52:41.105557Z"}]}
{"channel":"book","type":"update","data":[{"symbol":"LINK/USD","bids":[{"price":18.56543,"qty":31.87500000}],"asks":[],"checksum":123399174,"timestamp":"2024-06-01T17:52:41.105779Z"}]}
{"channel":"book","type":"update","data":[{"symbol":"LINK/USD","bids":[{"price":18.56543,"qty":0.00000000},{"price":18.55847,"qty":83.16579836}],"asks":[],"checksum":2135266059,"timestamp":"2024-06-01T17:52:41.108239Z"}]}
{"channel":"book","type":"update","data":[{"symbol":"LINK/USD","bids":[{"price":18.56544,"qty":0.00000000},{"price":18.55780,"qty":17.35151544}],"asks":[],"checksum":4179771805,"timestamp":"2024-06-01T17:52:41.108375Z"}]}
{"channel":"book","type":"update","data":[{"symbol":"LINK/USD","bids":[],"asks":[{"price":18.57102,"qty":40.00000000}],"checksum":1811672973,"timestamp":"2024-06-01T17:52:41.109724Z"}]}
{"channel":"book","type":"update","data":[{"symbol":"LINK/USD","bids":[],"asks":[{"price":18.57104,"qty":0.00000000},{"price":18.57354,"qty":31.87500000}],"checksum":1086879619,"timestamp":"2024-06-01T17:52:41.112589Z"}]}
{"channel":"book","type":"update","data":[{"symbol":"LINK/USD","bids":[],"asks":[{"price":18.57051,"qty":33.00000000}],"checksum":4067837787,"timestamp":"2024-06-01T17:52:41.112930Z"}]}
{"channel":"book","type":"update","data":[{"symbol":"LINK/USD","bids":[{"price":18.56537,"qty":0.00000000},{"price":18.55779,"qty":269.31533746}],"asks":[],"checksum":19241691,"timestamp":"2024-06-01T17:52:41.138400Z"}]}
{"channel":"book","type":"update","data":[{"symbol":"LINK/USD","bids":[],"asks":[{"price":18.57102,"qty":0.00000000},{"price":18.57354,"qty":31.87500000}],"checksum":203975189,"timestamp":"2024-06-01T17:52:41.142815Z"}]}
{"channel":"book","type":"update","data":[{"symbol":"LINK/USD","bids":[{"price":18.56515,"qty":608.90428727}],"asks":[],"checksum":1817155262,"timestamp":"2024-06-01T17:52:41.178631Z"}]}
{"channel":"book","type":"update","data":[{"symbol":"LINK/USD","bids":[],"asks":[{"price":18.57049,"qty":40.00000000}],"checksum":1658603741,"timestamp":"2024-06-01T17:52:41.183631Z"}]}
{"channel":"book","type":"update","data":[{"symbol":"LINK/USD","bids":[],"asks":[{"price":18.57048,"qty":13.46694486}],"checksum":1734067353,"timestamp":"2024-06-01T17:52:41.251806Z"}]}
{"channel":"book","type":"update","data":[{"symbol":"LINK/USD","bids":[],"asks":[{"price":18.57051,"qty":0.00000000},{"price":18.57210,"qty":0.34717458}],"checksum":3586812154,"timestamp":"2024-06-01T17:52:41.254479Z"}]}
{"channel":"book","type":"update","data":[{"symbol":"LINK/USD","bids":[],"asks":[{"price":18.56997,"qty":33.00000000}],"checksum":2364805420,"timestamp":"2024-06-01T17:52:41.254946Z"}]}
{"channel":"book","type":"update","data":[{"symbol":"LINK/USD","bids":[],"asks":[{"price":18.57156,"qty":0.00000000},{"price":18.57210,"qty":0.34717458}],"checksum":2430798927,"timestamp":"2024-06-01T17:52:41.255587Z"}]}
{"channel":"book","type":"update","data":[{"symbol":"LINK/USD","bids":[],"asks":[{"price":18.57048,"qty":0.00000000},{"price":18.57354,"qty":31.87500000}],"checksum":3195318939,"timestamp":"2024-06-01T17:52:41.258574Z"}]}
{"channel":"book","type":"update","data":[{"symbol":"LINK/USD","bids":[],"asks":[{"price":18.56996,"qty":13.46694486}],"checksum":62820621,"timestamp":"2024-06-01T17:52:41.261401Z"}]}
{"channel":"book","type":"update","data":[{"symbol":"LINK/USD","bids":[{"price":18.56516,"qty":31.87500000}],"asks":[],"checksum":243609072,"timestamp":"2024-06-01T17:52:41.261881Z"}]}
{"channel":"book","type":"update","data":[{"symbol":"LINK/USD","bids":[{"price":18.56516,"qty":0.00000000},{"price":18.55779,"qty":269.31533746}],"asks":[],"checksum":62820621,"timestamp":"2024-06-01T17:52:41.268480Z"}]}
{"channel":"book","type":"update","data":[{"symbol":"LINK/USD","bids":[{"price":18.56519,"qty":31.87500000}],"asks":[],"checksum":2096018287,"timestamp":"2024-06-01T17:52:41.307334Z"}]}
{"channel":"book","type":"update","data":[{"symbol":"LINK/USD","bids":[{"price":18.56519,"qty":0.00000000},{"price":18.55779,"qty":269.31533746}],"asks":[],"checksum":62820621,"timestamp":"2024-06-01T17:52:41.317027Z"}]}
{"channel":"book","type":"update","data":[{"symbol":"LINK/USD","bids":[{"price":18.56516,"qty":20.64921310}],"asks":[],"checksum":2894949230,"timestamp":"2024-06-01T17:52:41.386986Z"}]}
{"channel":"book","type":"update","data":[{"symbol":"LINK/USD","bids":[{"price":18.56516,"qty":52.52421310}],"asks":[],"checksum":3761764617,"timestamp":"2024-06-01T17:52:41.402367Z"}]}
{"channel":"book","type":"update","data":[{"symbol":"LINK/USD","bids":[{"price":18.56519,"qty":31.87500000}],"asks":[],"checksum":2679438096,"timestamp":"2024-06-01T17:52:41.410131Z"}]}
{"channel":"book","type":"update","data":[{"symbol":"LINK/USD","bids":[{"price":18.56516,"qty":20.64921310}],"asks":[],"checksum":1886012699,"timestamp":"2024-06-01T17:52:41.493955Z"}]}
{"channel":"book","type":"update","data":[{"symbol":"LINK/USD","bids":[{"price":18.56519,"qty":0.00000000},{"price":18.55780,"qty":17.35151544}],"asks":[],"checksum":2894949230,"timestamp":"2024-06-01T17:52:41.494154Z"}]}
{"channel":"book","type":"update","data":[{"symbol":"LINK/USD","bids":[{"price":18.56517,"qty":243.48672997}],"asks":[],"checksum":3666103577,"timestamp":"2024-06-01T17:52:41.497941Z"}]}
{"channel":"book","type":"update","data":[{"symbol":"LINK/USD","bids":[{"price":18.56517,"qty":0.00000000},{"price":18.55780,"qty":17.35151544}],"asks":[],"checksum":2894949230,"timestamp":"2024-06-01T17:52:41.555190Z"}]}
{"channel":"book","type":"update","data":[{"symbol":"LINK/USD","bids":[{"price":18.56530,"qty":31.87500000}],"asks":[],"checksum":4163201554,"timestamp":"2024-06-01T17:52:41.590095Z"}]}
{"channel":"book","type":"update","data":[{"symbol":"LINK/USD","bids":[],"asks":[{"price":18.57103,"qty":0.00000000},{"price":18.57354,"qty":31.87500000},{"price":18.56995,"qty":1.50546674}],"checksum":2818006485,"timestamp":"2024-06-01T17:52:41.590174Z"}]}
{"channel":"book","type":"update","data":[{"symbol":"LINK/USD","bids":[{"price":18.56525,"qty":31.87500000}],"asks":[],"checksum":1189833328,"timestamp":"2024-06-01T17:52:41.590508Z"}]}
{"channel":"book","type":"update","data":[{"symbol":"LINK/USD","bids":[{"price":18.56530,"qty":0.00000000},{"price":18.55847,"qty":83.16579836}],"asks":[],"checksum":1477375111,"timestamp":"2024-06-01T17:52:41.593847Z"}]}
{"channel":"book","type":"update","data":[{"symbol":"LINK/USD","bids":[{"price":18.56517,"qty":243.48672997}],"asks":[],"checksum":3727111683,"timestamp":"2024-06-01T17:52:41.594262Z"}]}
{"channel":"book","type":"update","data":[{"symbol":"LINK/USD","bids":[],"asks":[{"price":18.56996,"qty":0.00000000},{"price":18.57354,"qty":31.87500000}],"checksum":3587766737,"timestamp":"2024-06-01T17:52:41.594631Z"}]}
{"channel":"book","type":"update","data":[{"symbol":"LINK/USD","bids":[],"asks":[{"price":18.56995,"qty":0.00000000},{"price":18.57359,"qty":0.34605497},{"price":18.56996,"qty":1.50546674}],"checksum":132090814,"timestamp":"2024-06-01T17:52:41.597661Z"}]}
{"channel":"book","type":"update","data":[{"symbol":"LINK/USD","bids":[{"price":18.56525,"qty":0.00000000},{"price":18.55847,"qty":83.16579836}],"asks":[],"checksum":102987136,"timestamp":"2024-06-01T17:52:41.604121Z"}]}
{"channel":"book","type":"update","data":[{"symbol":"LINK/USD","bids":[{"price":18.56536,"qty":31.87500000}],"asks":[],"checksum":185893598,"timestamp":"2024-06-01T17:52:41.607250Z"}]}
{"channel":"book","type":"update","data":[{"symbol":"LINK/USD","bids":[{"price":18.56529,"qty":31.87500000}],"asks":[],"checksum":2263785247,"timestamp":"2024-06-01T17:52:41.608633Z"}]}
{"channel":"book","type":"update","data":[{"symbol":"LINK/USD","bids":[{"price":18.56529,"qty":0.00000000},{"price":18.55981,"qty":31.87500000}],"asks":[],"checksum":185893598,"timestamp":"2024-06-01T17:52:41.611242Z"}]}
{"channel":"book","type":"update","data":[{"symbol":"LINK/USD","bids":[{"price":18.56536,"qty":63.75000000}],"asks":[],"checksum":495265335,"timestamp":"2024-06-01T17:52:41.613959Z"}]}
{"channel":"book","type":"update","data":[{"symbol":"LINK/USD","bids":[{"price":18.56536,"qty":31.87500000}],"asks":[],"checksum":185893598,"timestamp":"2024-06-01T17:52:41.682411Z"}]}
{"channel":"book","type":"update","data":[{"symbol":"LINK/USD","bids":[{"price":18.56536,"qty":0.00000000},{"price":18.55847,"qty":83.16579836}],"asks":[],"checksum":102987136,"timestamp":"2024-06-01T17:52:41.684988Z"}]}
{"channel":"book","type":"update","data":[{"symbol":"LINK/USD","bids":[],"asks":[{"price":18.56995,"qty":40.00000000}],"checksum":3676427905,"timestamp":"2024-06-01T17:52:41.686950Z"}]}
{"channel":"book","type":"update","data":[{"symbol":"LINK/USD","bids":[{"price":18.56515,"qty":365.41755730}],"asks":[],"checksum":1537687371,"timestamp":"2024-06-01T17:52:41.686989Z"}]}
{"channel":"book","type":"update","data":[{"symbol":"LINK/USD","bids":[{"price":18.56523,"qty":31.87500000}],"asks":[],"checksum":1089442836,"timestamp":"2024-06-01T17:52:41.702688Z"}]}
{"channel":"book","type":"update","data":[{"symbol":"LINK/USD","bids":[{"price":18.56523,"qty":0.00000000},{"price":18.55847,"qty":83.16579836}],"asks":[],"checksum":1537687371,"timestamp":"2024-06-01T17:52:41.709547Z"}]}
{"channel":"book","type":"update","data":[{"symbol":"LINK/USD","bids":[],"asks":[{"price":18.57049,"qty":0.00000000},{"price":18.57354,"qty":31.87500000}],"checksum":934094730,"timestamp":"2024-06-01T17:52:41.753427Z"}]}
{"channel":"book","type":"update","data":[{"symbol":"LINK/USD","bids":[],"asks":[{"price":18.56997,"qty":0.00000000},{"price":18.57359,"qty":0.34605497}],"checksum":97839136,"timestamp":"2024-06-01T17:52:41.756246Z"}]}
{"channel":"book","type":"update","data":[{"symbol":"LINK/USD","bids":[],"asks":[{"price":18.57107,"qty":33.00000000}],"checksum":2285753301,"timestamp":"2024-06-01T17:52:41.756288Z"}]}
{"channel":"book","type":"update","data":[{"symbol":"LINK/USD","bids":[{"price":18.56557,"qty":31.87500000}],"asks":[],"checksum":2903106542,"timestamp":"2024-06-01T17:52:41.844334Z"}]}
{"channel":"book","type":"update","data":[{"symbol":"LINK/USD","bids":[{"price":18.56552,"qty":31.87500000}],"asks":[],"checksum":707638372,"timestamp":"2024-06-01T17:52:41.844769Z"}]}
{"channel":"book","type":"update","data":[{"symbol":"LINK/USD","bids":[{"price":18.56557,"qty":0.00000000},{"price":18.55981,"qty":31.87500000}],"asks":[],"checksum":2370322647,"timestamp":"2024-06-01T17:52:41.847430Z"}]}
{"channel":"book","type":"update","data":[{"symbol":"LINK/USD","bids":[{"price":18.56552,"qty":0.00000000},{"price":18.55847,"qty":83.16579836}],"asks":[],"checksum":2285753301,"timestamp":"2024-06-01T17:52:41.847994Z"}]}
{"channel":"book","type":"update","data":[{"symbol":"LINK/USD","bids":[{"price":18.56518,"qty":31.87500000}],"asks":[],"checksum":926262598,"timestamp":"2024-06-01T17:52:41.851502Z"}]}
{"channel":"book","type":"update","data":[{"symbol":"LINK/USD","bids":[{"price":18.56518,"qty":0.00000000},{"price":18.55847,"qty":83.16579836}],"asks":[],"checksum":2285753301,"timestamp":"2024-06-01T17:52:42.109461Z"}]}
{"channel":"book","type":"update","data":[{"symbol":"LINK/USD","bids":[],"asks":[{"price":18.56996,"qty":0.00000000},{"price":18.57359,"qty":0.34605497},{"price":18.56994,"qty":1.50546674}],"checksum":334187857,"timestamp":"2024-06-01T17:52:42.109482Z"}]}
{"channel":"book","type":"update","data":[{"symbol":"LINK/USD","bids":[{"price":18.56026,"qty":30.61793353}],"asks":[],"checksum":2952977119,"timestamp":"2024-06-01T17:52:42.112668Z"}]}
{"channel":"book","type":"update","data":[{"symbol":"LINK/USD","bids":[],"asks":[{"price":18.56609,"qty":31.80802482}],"checksum":1195772697,"timestamp":"2024-06-01T17:52:42.112913Z"}]}
{"channel":"book","type":"update","data":[{"symbol":"LINK/USD","bids":[{"price":18.56517,"qty":0.00000000},{"price":18.55847,"qty":83.16579836}],"asks":[],"checksum":683365592,"timestamp":"2024-06-01T17:52:42.113616Z"}]}
{"channel":"book","type":"update","data":[{"symbol":"LINK/USD","bids":[{"price":18.56516,"qty":264.13594307}],"asks":[],"checksum":3392723363,"timestamp":"2024-06-01T17:52:42.113801Z"}]}
{"channel":"book","type":"update","data":[{"symbol":"LINK/USD","bids":[],"asks":[{"price":18.56981,"qty":31.87500000}],"checksum":1491670329,"timestamp":"2024-06-01T17:52:42.117329Z"}]}
{"channel":"book","type":"update","data":[{"symbol":"LINK/USD","bids":[],"asks":[{"price":18.57107,"qty":0.00000000},{"price":18.57210,"qty":0.34717458}],"checksum":129484853,"timestamp":"2024-06-01T17:52:42.120002Z"}]}
{"channel":"book","type":"update","data":[{"symbol":"LINK/USD","bids":[],"asks":[{"price":18.56988,"qty":33.00000000}],"checksum":919921522,"timestamp":"2024-06-01T17:52:42.120171Z"}]}
{"channel":"book","type":"update","data":[{"symbol":"LINK/USD","bids":[{"price":18.56515,"qty":0.00000000},{"price":18.55780,"qty":17.35151544}],"asks":[],"checksum":89689032,"timestamp":"2024-06-01T17:52:42.243142Z"}]}
{"channel":"book","type":"update","data":[{"symbol":"LINK/USD","bids":[],"asks":[{"price":18.56988,"qty":0.00000000},{"price":18.57210,"qty":0.34717458}],"checksum":150807398,"timestamp":"2024-06-01T17:52:42.245914Z"}]}
{"channel":"book","type":"update","data":[{"symbol":"LINK/USD","bids":[],"asks":[{"price":18.56960,"qty":33.00000000}],"checksum":3675663710,"timestamp":"2024-06-01T17:52:42.245932Z"}]}
{"channel":"book","type":"update","data":[{"symbol":"LINK/USD","bids":[{"price":18.56516,"qty":20.64921310}],"asks":[],"checksum":699297280,"timestamp":"2024-06-01T17:52:42.247196Z"}]}
{"channel":"book","type":"update","data":[{"symbol":"LINK/USD","bids":[{"price":18.56515,"qty":243.48672997}],"asks":[],"checksum":1461699403,"timestamp":"2024-06-01T17:52:42.247432Z"}]}
{"channel":"book","type":"update","data":[{"symbol":"LINK/USD","bids":[{"price":18.56516,"qty":386.06693125}],"asks":[],"checksum":3317496032,"timestamp":"2024-06-01T17:52:42.283364Z"}]}
{"channel":"book","type":"update","data":[{"symbol":"LINK/USD","bids":[{"price":18.56517,"qty":243.48672997}],"asks":[],"checksum":2764147121,"timestamp":"2024-06-01T17:52:42.287629Z"}]}
{"channel":"book","type":"update","data":[{"symbol":"LINK/USD","bids":[{"price":18.56521,"qty":31.87500000}],"asks":[],"checksum":120439168,"timestamp":"2024-06-01T17:52:42.302254Z"}]}
{"channel":"book","type":"update","data":[{"symbol":"LINK/USD","bids":[{"price":18.56531,"qty":31.87500000}],"asks":[],"checksum":3030731389,"timestamp":"2024-06-01T17:52:42.302811Z"}]}
{"channel":"book","type":"update","data":[{"symbol":"LINK/USD","bids":[{"price":18.56521,"qty":0.00000000},{"price":18.56025,"qty":269.32548286}],"asks":[],"checksum":2140132168,"timestamp":"2024-06-01T17:52:42.305914Z"}]}
{"channel":"book","type":"update","data":[{"symbol":"LINK/USD","bids":[{"price":18.56531,"qty":0.00000000},{"price":18.55981,"qty":31.87500000}],"asks":[],"checksum":2764147121,"timestamp":"2024-06-01T17:52:42.306489Z"}]}
{"channel":"book","type":"update","data":[{"symbol":"LINK/USD","bids":[],"asks":[{"price":18.56609,"qty":0.00000000},{"price":18.57210,"qty":0.34717458}],"checksum":1404396890,"timestamp":"2024-06-01T17:52:42.363925Z"}]}
{"channel":"book","type":"update","data":[{"symbol":"LINK/USD","bids":[],"asks":[{"price":18.56959,"qty":31.80802482}],"checksum":1414734973,"timestamp":"2024-06-01T17:52:42.367064Z"}]}
{"channel":"book","type":"update","data":[{"symbol":"LINK/USD","bids":[{"price":18.56515,"qty":0.00000000},{"price":18.55847,"qty":83.16579836}],"asks":[],"checksum":1718527054,"timestamp":"2024-06-01T17:52:42.367615Z"}]}
{"channel":"book","type":"update","data":[{"symbol":"LINK/USD","bids":[],"asks":[{"price":18.56958,"qty":13.46693757}],"checksum":582298964,"timestamp":"2024-06-01T17:52:42.610799Z"}]}
{"channel":"book","type":"update","data":[{"symbol":"LINK/USD","bids":[],"asks":[{"price":18.56958,"qty":0.00000000},{"price":18.57186,"qty":1.10230934}],"checksum":1718527054,"timestamp":"2024-06-01T17:52:42.615156Z"}]}
{"channel":"book","type":"update","data":[{"symbol":"LINK/USD","bids":[],"asks":[{"price":18.56994,"qty":0.00000000},{"price":18.57210,"qty":0.34717458},{"price":18.56958,"qty":1.50546674}],"checksum":187405795,"timestamp":"2024-06-01T17:52:42.618689Z"}]}
{"channel":"book","type":"update","data":[{"symbol":"LINK/USD","bids":[],"asks":[{"price":18.56959,"qty":0.00000000},{"price":18.57210,"qty":0.34717458}],"checksum":1575238826,"timestamp":"2024-06-01T17:52:42.745822Z"}]}
{"channel":"book","type":"update","data":[{"symbol":"LINK/USD","bids":[],"asks":[{"price":18.56958,"qty":0.00000000},{"price":18.57354,"qty":31.87500000},{"price":18.56959,"qty":1.50546674}],"checksum":2771783856,"timestamp":"2024-06-01T17:52:42.749015Z"}]}
{"channel":"book","type":"update","data":[{"symbol":"LINK/USD","bids":[],"asks":[{"price":18.56609,"qty":31.80802482}],"checksum":2011432276,"timestamp":"2024-06-01T17:52:42.996710Z"}]}
{"channel":"book","type":"update","data":[{"symbol":"LINK/USD","bids":[{"price":18.56531,"qty":31.87500000}],"asks":[],"checksum":2467990074,"timestamp":"2024-06-01T17:52:43.071188Z"}]}
{"channel":"book","type":"update","data":[{"symbol":"LINK/USD","bids":[{"price":18.56535,"qty":31.87500000}],"asks":[],"checksum":1460672573,"timestamp":"2024-06-01T17:52:43.071578Z"}]}
{"channel":"book","type":"update","data":[{"symbol":"LINK/USD","bids":[{"price":18.56531,"qty":0.00000000},{"price":18.55981,"qty":31.87500000}],"asks":[],"checksum":1652820516,"timestamp":"2024-06-01T17:52:43.074260Z"}]}
{"channel":"book","type":"update","data":[{"symbol":"LINK/USD","bids":[{"price":18.56535,"qty":0.00000000},{"price":18.55847,"qty":83.16579836}],"asks":[],"checksum":2011432276,"timestamp":"2024-06-01T17:52:43.074577Z"}]}
{"channel":"book","type":"update","data":[{"symbol":"LINK/USD","bids":[{"price":18.56516,"qty":365.41771815}],"asks":[],"checksum":743591040,"timestamp":"2024-06-01T17:52:43.537932Z"}]}
{"channel":"book","type":"update","data":[{"symbol":"LINK/USD","bids":[],"asks":[{"price":18.56608,"qty":13.46693866}],"checksum":2333196192,"timestamp":"2024-06-01T17:52:43.741721Z"}]}
{"channel":"book","type":"update","data":[{"symbol":"LINK/USD","bids":[],"asks":[{"price":18.56608,"qty":0.00000000},{"price":18.57186,"qty":1.10230934}],"checksum":743591040,"timestamp":"2024-06-01T17:52:43.745156Z"}]}
{"channel":"book","type":"update","data":[{"symbol":"LINK/USD","bids":[{"price":18.56518,"qty":20.64921310}],"asks":[],"checksum":371688874,"timestamp":"2024-06-01T17:52:44.196220Z"}]}
{"channel":"book","type":"update","data":[{"symbol":"LINK/USD","bids":[{"price":18.56026,"qty":0.00000000},{"price":18.55847,"qty":83.16579836}],"asks":[],"checksum":3050181156,"timestamp":"2024-06-01T17:52:44.326474Z"}]}
{"channel":"book","type":"update","data":[{"symbol":"LINK/USD","bids":[],"asks":[{"price":18.56795,"qty":31.87500000}],"checksum":2851546110,"timestamp":"2024-06-01T17:52:44.356993Z"}]}
{"channel":"book","type":"update","data":[{"symbol":"LINK/USD","bids":[{"price":18.55847,"qty":0.00000000},{"price":18.55780,"qty":17.35151544}],"asks":[],"checksum":4260402382,"timestamp":"2024-06-01T17:52:44.357719Z"}]}
{"channel":"book","type":"update","data":[{"symbol":"LINK/USD","bids":[],"asks":[{"price":18.56959,"qty":0.00000000},{"price":18.57186,"qty":1.10230934},{"price":18.56794,"qty":1.50546674}],"checksum":2120583074,"timestamp":"2024-06-01T17:52:44.361357Z"}]}
{"channel":"book","type":"update","data":[{"symbol":"LINK/USD","bids":[],"asks":[{"price":18.56795,"qty":0.00000000},{"price":18.57186,"qty":1.10230934}],"checksum":1165977064,"timestamp":"2024-06-01T17:52:44.424266Z"}]}
{"channel":"book","type":"update","data":[{"symbol":"LINK/USD","bids":[],"asks":[{"price":18.56794,"qty":0.00000000},{"price":18.57210,"qty":0.34717458},{"price":18.56959,"qty":1.50546674}],"checksum":3788088596,"timestamp":"2024-06-01T17:52:44.427425Z"}]}
{"channel":"book","type":"update","data":[{"symbol":"LINK/USD","bids":[],"asks":[{"price":18.57173,"qty":0.00000000},{"price":18.57210,"qty":0.34717458}],"checksum":3575386969,"timestamp":"2024-06-01T17:52:44.433322Z"}]}
{"channel":"book","type":"update","data":[{"symbol":"LINK/USD","bids":[],"asks":[{"price":18.56795,"qty":31.87500000}],"checksum":1703156457,"timestamp":"2024-06-01T17:52:44.434051Z"}]}
{"channel":"book","type":"update","data":[{"symbol":"LINK/USD","bids":[],"asks":[{"price":18.56795,"qty":0.00000000},{"price":18.57210,"qty":0.34717458}],"checksum":3575386969,"timestamp":"2024-06-01T17:52:44.466011Z"}]}
{"channel":"book","type":"update","data":[{"symbol":"LINK/USD","bids":[],"asks":[{"price":18.56795,"qty":31.87500000}],"checksum":1703156457,"timestamp":"2024-06-01T17:52:44.495020Z"}]}
{"channel":"book","type":"update","data":[{"symbol":"LINK/USD","bids":[],"asks":[{"price":18.56795,"qty":0.00000000},{"price":18.57210,"qty":0.34717458}],"checksum":3575386969,"timestamp":"2024-06-01T17:52:44.503908Z"}]}
{"channel":"book","type":"update","data":[{"symbol":"LINK/USD","bids":[],"asks":[{"price":18.57026,"qty":6.43107813}],"checksum":3274901483,"timestamp":"2024-06-01T17:52:44.552903Z"}]}
{"channel":"book","type":"update","data":[{"symbol":"LINK/USD","bids":[{"price":18.55781,"qty":30.61793353}],"asks":[],"checksum":3839119727,"timestamp":"2024-06-01T17:52:44.690793Z"}]}
{"channel":"book","type":"update","data":[{"symbol":"LINK/USD","bids":[{"price":18.56516,"qty":0.00000000},{"price":18.55780,"qty":17.35151544}],"asks":[],"checksum":2254959324,"timestamp":"2024-06-01T17:52:44.713838Z"}]}
{"channel":"book","type":"update","data":[{"symbol":"LINK/USD","bids":[{"price":18.56517,"qty":0.00000000},{"price":18.55779,"qty":269.31533746}],"asks":[],"checksum":3673599005,"timestamp":"2024-06-01T17:52:44.718119Z"}]}
{"channel":"book","type":"update","data":[{"symbol":"LINK/USD","bids":[{"price":18.56515,"qty":243.48672997}],"asks":[],"checksum":3757416091,"timestamp":"2024-06-01T17:52:44.718338Z"}]}
{"channel":"book","type":"update","data":[{"symbol":"LINK/USD","bids":[],"asks":[{"price":18.56608,"qty":13.46694455}],"checksum":1249790970,"timestamp":"2024-06-01T17:52:44.753434Z"}]}
{"channel":"book","type":"update","data":[{"symbol":"LINK/USD","bids":[],"asks":[{"price":18.56608,"qty":0.00000000},{"price":18.57186,"qty":1.10230934}],"checksum":3757416091,"timestamp":"2024-06-01T17:52:44.756691Z"}]}
{"channel":"book","type":"update","data":[{"symbol":"LINK/USD","bids":[],"asks":[{"price":18.56608,"qty":13.46694455}],"checksum":1249790970,"timestamp":"2024-06-01T17:52:44.759968Z"}]}
{"channel":"book","type":"update","data":[{"symbol":"LINK/USD","bids":[{"price":18.55780,"qty":0.00000000},{"price":18.55779,"qty":269.31533746}],"asks":[],"checksum":2194656314,"timestamp":"2024-06-01T17:52:45.511798Z"}]}
{"channel":"book","type":"update","data":[{"symbol":"LINK/USD","bids":[{"price":18.55782,"qty":9.78383046}],"asks":[],"checksum":4039014631,"timestamp":"2024-06-01T17:52:45.521299Z"}]}
{"channel":"book","type":"update","data":[{"symbol":"LINK/USD","bids":[],"asks":[{"price":18.56794,"qty":31.87500000}],"checksum":980245979,"timestamp":"2024-06-01T17:52:45.544794Z"}]}
{"channel":"book","type":"update","data":[{"symbol":"LINK/USD","bids":[{"price":18.55781,"qty":0.00000000},{"price":18.55779,"qty":269.31533746}],"asks":[],"checksum":606367517,"timestamp":"2024-06-01T17:52:45.546277Z"}]}
{"channel":"book","type":"update","data":[{"symbol":"LINK/USD","bids":[],"asks":[{"price":18.56959,"qty":0.00000000},{"price":18.57168,"qty":31.87500000},{"price":18.56607,"qty":1.50546674}],"checksum":3975425880,"timestamp":"2024-06-01T17:52:45.547822Z"}]}
{"channel":"book","type":"update","data":[{"symbol":"LINK/USD","bids":[],"asks":[{"price":18.56608,"qty":0.00000000},{"price":18.57168,"qty":31.87500000}],"checksum":39044213,"timestamp":"2024-06-01T17:52:45.551021Z"}]}
{"channel":"book","type":"update","data":[{"symbol":"LINK/USD","bids":[],"asks":[{"price":18.56794,"qty":0.00000000},{"price":18.57186,"qty":1.10230934}],"checksum":3133407541,"timestamp":"2024-06-01T17:52:45.551949Z"}]}
{"channel":"book","type":"update","data":[{"symbol":"LINK/USD","bids":[{"price":18.56342,"qty":0.00000000},{"price":18.55765,"qty":40.00000000}],"asks":[],"checksum":1326852980,"timestamp":"2024-06-01T17:52:45.551980Z"}]}
{"channel":"book","type":"update","data":[{"symbol":"LINK/USD","bids":[],"asks":[{"price":18.56607,"qty":0.00000000},{"price":18.57210,"qty":0.34717458},{"price":18.56793,"qty":1.50546674}],"checksum":3963719922,"timestamp":"2024-06-01T17:52:45.554226Z"}]}
{"channel":"book","type":"update","data":[{"symbol":"LINK/USD","bids":[{"price":18.56332,"qty":31.87500000}],"asks":[],"checksum":3191584062,"timestamp":"2024-06-01T17:52:45.555137Z"}]}
{"channel":"book","type":"update","data":[{"symbol":"LINK/USD","bids":[],"asks":[{"price":18.56793,"qty":33.38046674}],"checksum":4287817891,"timestamp":"2024-06-01T17:52:45.556596Z"}]}
{"channel":"book","type":"update","data":[{"symbol":"LINK/USD","bids":[],"asks":[{"price":18.56793,"qty":31.87500000},{"price":18.56959,"qty":1.50546674}],"checksum":552783474,"timestamp":"2024-06-01T17:52:45.556905Z"}]}
{"channel":"book","type":"update","data":[{"symbol":"LINK/USD","bids":[{"price":18.56332,"qty":0.00000000},{"price":18.55765,"qty":40.00000000}],"asks":[],"checksum":1921575870,"timestamp":"2024-06-01T17:52:45.557747Z"}]}
{"channel":"book","type":"update","data":[{"symbol":"LINK/USD","bids":[{"price":18.56332,"qty":31.87500000}],"asks":[],"checksum":552783474,"timestamp":"2024-06-01T17:52:45.563960Z"}]}
{"channel":"book","type":"update","data":[{"symbol":"LINK/USD","bids":[],"asks":[{"price":18.56793,"qty":0.00000000},{"price":18.57186,"qty":1.10230934}],"checksum":966924883,"timestamp":"2024-06-01T17:52:45.693563Z"}]}
{"channel":"book","type":"update","data":[{"symbol":"LINK/USD","bids":[{"price":18.55783,"qty":33.11971188}],"asks":[],"checksum":3643173493,"timestamp":"2024-06-01T17:52:45.697025Z"}]}
{"channel":"book","type":"update","data":[{"symbol":"LINK/USD","bids":[],"asks":[{"price":18.56795,"qty":31.87500000}],"checksum":627817309,"timestamp":"2024-06-01T17:52:46.161370Z"}]}
{"channel":"book","type":"update","data":[{"symbol":"LINK/USD","bids":[],"asks":[{"price":18.56959,"qty":0.00000000},{"price":18.57186,"qty":1.10230934},{"price":18.56794,"qty":1.50546674}],"checksum":3665745394,"timestamp":"2024-06-01T17:52:46.165334Z"}]}
{"channel":"book","type":"update","data":[{"symbol":"LINK/USD","bids":[{"price":18.56332,"qty":0.00000000},{"price":18.55779,"qty":269.31533746}],"asks":[],"checksum":193676849,"timestamp":"2024-06-01T17:52:46.240841Z"}]}
{"channel":"book","type":"update","data":[{"symbol":"LINK/USD","bids":[{"price":18.56332,"qty":31.87500000}],"asks":[],"checksum":3665745394,"timestamp":"2024-06-01T17:52:46.337648Z"}]}
{"channel":"book","type":"update","data":[{"symbol":"LINK/USD","bids":[{"price":18.56518,"qty":0.00000000},{"price":18.55779,"qty":269.31533746}],"asks":[],"checksum":1584065260,"timestamp":"2024-06-01T17:52:46.354245Z"}]}
{"channel":"book","type":"update","data":[{"symbol":"LINK/USD","bids":[{"price":18.56332,"qty":0.00000000},{"price":18.55765,"qty":40.00000000}],"asks":[],"checksum":2445617918,"timestamp":"2024-06-01T17:52:46.357628Z"}]}
{"channel":"book","type":"update","data":[{"symbol":"LINK/USD","bids":[],"asks":[{"price":18.56609,"qty":0.00000000},{"price":18.57186,"qty":1.10230934}],"checksum":2755261766,"timestamp":"2024-06-01T17:52:46.543267Z"}]}
{"channel":"book","type":"update","data":[{"symbol":"LINK/USD","bids":[{"price":18.56329,"qty":31.87500000}],"asks":[],"checksum":3659143604,"timestamp":"2024-06-01T17:52:46.545200Z"}]}
{"channel":"book","type":"update","data":[{"symbol":"LINK/USD","bids":[],"asks":[{"price":18.57157,"qty":32.71843926}],"checksum":4052918207,"timestamp":"2024-06-01T17:52:46.546381Z"}]}
{"channel":"book","type":"update","data":[{"symbol":"LINK/USD","bids":[],"asks":[{"price":18.56795,"qty":0.00000000},{"price":18.57186,"qty":1.10230934}],"checksum":1157940275,"timestamp":"2024-06-01T17:52:46.546945Z"}]}
{"channel":"book","type":"update","data":[{"symbol":"LINK/USD","bids":[],"asks":[{"price":18.56794,"qty":0.00000000},{"price":18.57210,"qty":0.34717458},{"price":18.56959,"qty":1.50546674}],"checksum":3859490372,"timestamp":"2024-06-01T17:52:46.550179Z"}]}
{"channel":"book","type":"update","data":[{"symbol":"LINK/USD","bids":[],"asks":[{"price":18.56958,"qty":13.46694876}],"checksum":3582791721,"timestamp":"2024-06-01T17:52:46.559592Z"}]}
{"channel":"book","type":"update","data":[{"symbol":"LINK/USD","bids":[],"asks":[{"price":18.56958,"qty":0.00000000},{"price":18.57186,"qty":1.10230934}],"checksum":3859490372,"timestamp":"2024-06-01T17:52:46.563148Z"}]}
{"channel":"book","type":"update","data":[{"symbol":"LINK/USD","bids":[],"asks":[{"price":18.56958,"qty":13.46694876}],"checksum":3582791721,"timestamp":"2024-06-01T17:52:46.567529Z"}]}
{"channel":"book","type":"update","data":[{"symbol":"LINK/USD","bids":[],"asks":[{"price":18.56996,"qty":80.77565650}],"checksum":420717282,"timestamp":"2024-06-01T17:52:46.630678Z"}]}
{"channel":"book","type":"update","data":[{"symbol":"LINK/USD","bids":[],"asks":[{"price":18.56959,"qty":0.00000000},{"price":18.57168,"qty":31.87500000},{"price":18.56957,"qty":1.50546674}],"checksum":2156885587,"timestamp":"2024-06-01T17:52:46.636615Z"}]}
{"channel":"book","type":"update","data":[{"symbol":"LINK/USD","bids":[],"asks":[{"price":18.56958,"qty":0.00000000},{"price":18.57168,"qty":31.87500000}],"checksum":2914744879,"timestamp":"2024-06-01T17:52:46.640359Z"}]}
{"channel":"book","type":"update","data":[{"symbol":"LINK/USD","bids":[],"asks":[{"price":18.56956,"qty":40.00000000}],"checksum":2716855168,"timestamp":"2024-06-01T17:52:46.641412Z"}]}
{"channel":"book","type":"update","data":[{"symbol":"LINK/USD","bids":[],"asks":[{"price":18.56957,"qty":0.00000000},{"price":18.57168,"qty":31.87500000},{"price":18.56959,"qty":1.50546674}],"checksum":1425695917,"timestamp":"2024-06-01T17:52:46.643456Z"}]}
{"channel":"book","type":"update","data":[{"symbol":"LINK/USD","bids":[],"asks":[{"price":18.56960,"qty":0.00000000},{"price":18.57168,"qty":31.87500000}],"checksum":238419821,"timestamp":"2024-06-01T17:52:46.644132Z"}]}
{"channel":"book","type":"update","data":[{"symbol":"LINK/USD","bids":[],"asks":[{"price":18.56905,"qty":33.00000000}],"checksum":3666751825,"timestamp":"2024-06-01T17:52:46.644432Z"}]}
{"channel":"book","type":"update","data":[{"symbol":"LINK/USD","bids":[],"asks":[{"price":18.57157,"qty":0.00000000},{"price":18.57168,"qty":31.87500000}],"checksum":2643798996,"timestamp":"2024-06-01T17:52:46.647763Z"}]}
{"channel":"book","type":"update","data":[{"symbol":"LINK/USD","bids":[{"price":18.55783,"qty":0.00000000},{"price":18.55765,"qty":40.00000000}],"asks":[],"checksum":2384010310,"timestamp":"2024-06-01T17:52:46.647774Z"}]}
{"channel":"book","type":"update","data":[{"symbol":"LINK/USD","bids":[],"asks":[{"price":18.56956,"qty":0.00000000},{"price":18.57186,"qty":1.10230934}],"checksum":3584717926,"timestamp":"2024-06-01T17:52:46.753765Z"}]}
{"channel":"book","type":"update","data":[{"symbol":"LINK/USD","bids":[{"price":18.56246,"qty":33.11971188}],"asks":[],"checksum":1217047844,"timestamp":"2024-06-01T17:52:46.756800Z"}]}
{"channel":"book","type":"update","data":[{"symbol":"LINK/USD","bids":[],"asks":[{"price":18.56904,"qty":32.71843926}],"checksum":942840788,"timestamp":"2024-06-01T17:52:46.757127Z"}]}
{"channel":"book","type":"update","data":[{"symbol":"LINK/USD","bids":[],"asks":[{"price":18.56903,"qty":40.00000000}],"checksum":824832405,"timestamp":"2024-06-01T17:52:46.758067Z"}]}
{"channel":"book","type":"update","data":[{"symbol":"LINK/USD","bids":[],"asks":[{"price":18.56905,"qty":0.00000000},{"price":18.57168,"qty":31.87500000}],"checksum":1121960166,"timestamp":"2024-06-01T17:52:46.760029Z"}]}
{"channel":"book","type":"update","data":[{"symbol":"LINK/USD","bids":[],"asks":[{"price":18.56886,"qty":33.00000000}],"checksum":685578331,"timestamp":"2024-06-01T17:52:46.760245Z"}]}
{"channel":"book","type":"update","data":[{"symbol":"LINK/USD","bids":[{"price":18.56516,"qty":20.64921310}],"asks":[],"checksum":3453006140,"timestamp":"2024-06-01T17:52:46.828812Z"}]}
{"channel":"book","type":"update","data":[{"symbol":"LINK/USD","bids":[],"asks":[{"price":18.56903,"qty":0.00000000},{"price":18.57168,"qty":31.87500000}],"checksum":3283268828,"timestamp":"2024-06-01T17:52:46.833656Z"}]}
{"channel":"book","type":"update","data":[{"symbol":"LINK/USD","bids":[],"asks":[{"price":18.57026,"qty":0.00000000},{"price":18.57186,"qty":1.10230934}],"checksum":2923815227,"timestamp":"2024-06-01T17:52:46.911887Z"}]}
{"channel":"book","type":"update","data":[{"symbol":"LINK/USD","bids":[{"price":18.56246,"qty":0.00000000},{"price":18.55779,"qty":269.31533746}],"asks":[],"checksum":556217377,"timestamp":"2024-06-01T17:52:46.933419Z"}]}
{"channel":"book","type":"update","data":[{"symbol":"LINK/USD","bids":[{"price":18.55783,"qty":33.11971188}],"asks":[],"checksum":3947851682,"timestamp":"2024-06-01T17:52:47.036302Z"}]}
{"channel":"book","type":"update","data":[{"symbol":"LINK/USD","bids":[],"asks":[{"price":18.56904,"qty":0.00000000},{"price":18.57210,"qty":0.34717458}],"checksum":1440267292,"timestamp":"2024-06-01T17:52:47.036570Z"}]}
{"channel":"book","type":"update","data":[{"symbol":"LINK/USD","bids":[],"asks":[{"price":18.56959,"qty":0.00000000},{"price":18.57346,"qty":121.14061191},{"price":18.56885,"qty":1.50546674}],"checksum":1343112762,"timestamp":"2024-06-01T17:52:47.175178Z"}]}
{"channel":"book","type":"update","data":[{"symbol":"LINK/USD","bids":[{"price":18.55783,"qty":0.00000000},{"price":18.55779,"qty":269.31533746}],"asks":[],"checksum":3746066046,"timestamp":"2024-06-01T17:52:47.178263Z"}]}
{"channel":"book","type":"update","data":[{"symbol":"LINK/USD","bids":[],"asks":[{"price":18.56609,"qty":32.71843926}],"checksum":1317264601,"timestamp":"2024-06-01T17:52:47.178533Z"}]}
{"channel":"book","type":"update","data":[{"symbol":"LINK/USD","bids":[{"price":18.55982,"qty":33.11971188}],"asks":[],"checksum":1160541213,"timestamp":"2024-06-01T17:52:47.317689Z"}]}
{"channel":"book","type":"update","data":[{"symbol":"LINK/USD","bids":[{"price":18.56516,"qty":0.27889096}],"asks":[],"checksum":2767708990,"timestamp":"2024-06-01T17:52:47.403347Z"}]}
{"channel":"book","type":"update","data":[{"symbol":"LINK/USD","bids":[{"price":18.56531,"qty":31.87500000}],"asks":[],"checksum":2517635250,"timestamp":"2024-06-01T17:52:47.610059Z"}]}
{"channel":"book","type":"update","data":[{"symbol":"LINK/USD","bids":[{"price":18.56527,"qty":31.87500000}],"asks":[],"checksum":3491443910,"timestamp":"2024-06-01T17:52:47.610588Z"}]}
{"channel":"book","type":"update","data":[{"symbol":"LINK/USD","bids":[{"price":18.56531,"qty":0.00000000},{"price":18.55981,"qty":31.87500000}],"asks":[],"checksum":3745329187,"timestamp":"2024-06-01T17:52:47.612953Z"}]}
{"channel":"book","type":"update","data":[{"symbol":"LINK/USD","bids":[{"price":18.56527,"qty":0.00000000},{"price":18.55782,"qty":9.78383046}],"asks":[],"checksum":2767708990,"timestamp":"2024-06-01T17:52:47.613891Z"}]}
{"channel":"book","type":"update","data":[{"symbol":"LINK/USD","bids":[{"price":18.56531,"qty":31.87500000}],"asks":[],"checksum":2517635250,"timestamp":"2024-06-01T17:52:47.615256Z"}]}
{"channel":"book","type":"update","data":[{"symbol":"LINK/USD","bids":[{"price":18.56531,"qty":63.75000000}],"asks":[],"checksum":1979261374,"timestamp":"2024-06-01T17:52:47.615766Z"}]}
{"channel":"book","type":"update","data":[{"symbol":"LINK/USD","bids":[{"price":18.56531,"qty":31.87500000}],"asks":[],"checksum":2517635250,"timestamp":"2024-06-01T17:52:47.618554Z"}]}
{"channel":"book","type":"update","data":[{"symbol":"LINK/USD","bids":[{"price":18.56531,"qty":0.00000000},{"price":18.55782,"qty":9.78383046}],"asks":[],"checksum":2767708990,"timestamp":"2024-06-01T17:52:47.619126Z"}]}
{"channel":"book","type":"update","data":[{"symbol":"LINK/USD","bids":[{"price":18.56534,"qty":31.87500000}],"asks":[],"checksum":3278567038,"timestamp":"2024-06-01T17:52:47.667258Z"}]}
{"channel":"book","type":"update","data":[{"symbol":"LINK/USD","bids":[{"price":18.56539,"qty":31.87500000}],"asks":[],"checksum":3741434038,"timestamp":"2024-06-01T17:52:47.667891Z"}]}
{"channel":"book","type":"update","data":[{"symbol":"LINK/USD","bids":[],"asks":[{"price":18.56981,"qty":0.00000000},{"price":18.57210,"qty":0.34717458}],"checksum":186778912,"timestamp":"2024-06-01T17:52:47.667959Z"}]}
{"channel":"book","type":"update","data":[{"symbol":"LINK/USD","bids":[],"asks":[{"price":18.56608,"qty":13.46692750}],"checksum":1495334622,"timestamp":"2024-06-01T17:52:47.671513Z"}]}
{"channel":"book","type":"update","data":[{"symbol":"LINK/USD","bids":[{"price":18.56534,"qty":0.00000000},{"price":18.55981,"qty":31.87500000}],"asks":[],"checksum":2566250298,"timestamp":"2024-06-01T17:52:47.671743Z"}]}
{"channel":"book","type":"update","data":[{"symbol":"LINK/USD","bids":[{"price":18.56539,"qty":63.75000000}],"asks":[],"checksum":2065493558,"timestamp":"2024-06-01T17:52:47.671954Z"}]}
{"channel":"book","type":"update","data":[{"symbol":"LINK/USD","bids":[{"price":18.56539,"qty":31.87500000}],"asks":[],"checksum":2566250298,"timestamp":"2024-06-01T17:52:47.706162Z"}]}
{"channel":"book","type":"update","data":[{"symbol":"LINK/USD","bids":[{"price":18.56539,"qty":0.00000000},{"price":18.55782,"qty":9.78383046}],"asks":[],"checksum":1444634606,"timestamp":"2024-06-01T17:52:47.706540Z"}]}
{"channel":"book","type":"update","data":[{"symbol":"LINK/USD","bids":[{"price":18.56522,"qty":31.87500000}],"asks":[],"checksum":208070791,"timestamp":"2024-06-01T17:52:47.710105Z"}]}
{"channel":"book","type":"update","data":[{"symbol":"LINK/USD","bids":[],"asks":[{"price":18.56980,"qty":31.87500000}],"checksum":1259760323,"timestamp":"2024-06-01T17:52:47.712710Z"}]}
{"channel":"book","type":"update","data":[{"symbol":"LINK/USD","bids":[{"price":18.56522,"qty":63.75000000}],"asks":[],"checksum":2835307471,"timestamp":"2024-06-01T17:52:47.712941Z"}]}
{"channel":"book","type":"update","data":[{"symbol":"LINK/USD","bids":[],"asks":[{"price":18.56980,"qty":0.00000000},{"price":18.57186,"qty":1.10230934}],"checksum":4019181963,"timestamp":"2024-06-01T17:52:47.738524Z"}]}
{"channel":"book","type":"update","data":[{"symbol":"LINK/USD","bids":[],"asks":[{"price":18.56980,"qty":31.87500000}],"checksum":2835307471,"timestamp":"2024-06-01T17:52:47.763026Z"}]}
{"channel":"book","type":"update","data":[{"symbol":"LINK/USD","bids":[{"price":18.56532,"qty":20.64921310}],"asks":[],"checksum":2347748897,"timestamp":"2024-06-01T17:52:47.766074Z"}]}
{"channel":"book","type":"update","data":[{"symbol":"LINK/USD","bids":[],"asks":[{"price":18.56980,"qty":0.00000000},{"price":18.57186,"qty":1.10230934}],"checksum":3432991845,"timestamp":"2024-06-01T17:52:47.769403Z"}]}
{"channel":"book","type":"update","data":[{"symbol":"LINK/USD","bids":[{"price":18.56547,"qty":31.87500000}],"asks":[],"checksum":1784235585,"timestamp":"2024-06-01T17:52:47.769943Z"}]}
{"channel":"book","type":"update","data":[{"symbol":"LINK/USD","bids":[{"price":18.56523,"qty":243.48672997}],"asks":[],"checksum":2744264,"timestamp":"2024-06-01T17:52:47.771324Z"}]}
{"channel":"book","type":"update","data":[{"symbol":"LINK/USD","bids":[],"asks":[{"price":18.56886,"qty":0.00000000},{"price":18.57210,"qty":0.34717458}],"checksum":538284914,"timestamp":"2024-06-01T17:52:47.776628Z"}]}
{"channel":"book","type":"update","data":[{"symbol":"LINK/USD","bids":[],"asks":[{"price":18.56963,"qty":33.00000000}],"checksum":1028196329,"timestamp":"2024-06-01T17:52:47.776947Z"}]}
{"channel":"book","type":"update","data":[{"symbol":"LINK/USD","bids":[],"asks":[{"price":18.56885,"qty":0.00000000},{"price":18.57210,"qty":0.34717458},{"price":18.56994,"qty":1.50546674}],"checksum":736436054,"timestamp":"2024-06-01T17:52:47.780121Z"}]}
{"channel":"book","type":"update","data":[{"symbol":"LINK/USD","bids":[],"asks":[{"price":18.56609,"qty":0.00000000},{"price":18.57210,"qty":0.34717458}],"checksum":690319671,"timestamp":"2024-06-01T17:52:47.820230Z"}]}
{"channel":"book","type":"update","data":[{"symbol":"LINK/USD","bids":[],"asks":[{"price":18.56962,"qty":32.71843926}],"checksum":3599213518,"timestamp":"2024-06-01T17:52:47.823364Z"}]}
{"channel":"book","type":"update","data":[{"symbol":"LINK/USD","bids":[{"price":18.56523,"qty":0.00000000},{"price":18.56025,"qty":269.32548286}],"asks":[],"checksum":3170318919,"timestamp":"2024-06-01T17:52:47.823869Z"}]}
{"channel":"book","type":"update","data":[{"symbol":"LINK/USD","bids":[],"asks":[{"price":18.56608,"qty":0.00000000},{"price":18.57210,"qty":0.34717458}],"checksum":2152249723,"timestamp":"2024-06-01T17:52:47.824117Z"}]}
{"channel":"book","type":"update","data":[{"symbol":"LINK/USD","bids":[],"asks":[{"price":18.56961,"qty":13.46688344}],"checksum":2235647521,"timestamp":"2024-06-01T17:52:47.827777Z"}]}
{"channel":"book","type":"update","data":[{"symbol":"LINK/USD","bids":[],"asks":[{"price":18.56961,"qty":46.46688344}],"checksum":1483535512,"timestamp":"2024-06-01T17:52:47.845594Z"}]}
{"channel":"book","type":"update","data":[{"symbol":"LINK/USD","bids":[],"asks":[{"price":18.56963,"qty":0.00000000},{"price":18.57210,"qty":0.34717458}],"checksum":796546870,"timestamp":"2024-06-01T17:52:47.845609Z"}]}
{"channel":"book","type":"update","data":[{"symbol":"LINK/USD","bids":[],"asks":[{"price":18.56982,"qty":31.87500000}],"checksum":2821597366,"timestamp":"2024-06-01T17:52:47.922887Z"}]}
{"channel":"book","type":"update","data":[{"symbol":"LINK/USD","bids":[{"price":18.56547,"qty":0.00000000},{"price":18.55981,"qty":31.87500000}],"asks":[],"checksum":2147307783,"timestamp":"2024-06-01T17:52:47.934196Z"}]}
{"channel":"book","type":"update","data":[{"symbol":"LINK/USD","bids":[{"price":18.56522,"qty":31.87500000}],"asks":[],"checksum":855672813,"timestamp":"2024-06-01T17:52:47.937799Z"}]}
{"channel":"book","type":"update","data":[{"symbol":"LINK/USD","bids":[],"asks":[{"price":18.56982,"qty":0.00000000},{"price":18.57210,"qty":0.34717458}],"checksum":3025467501,"timestamp":"2024-06-01T17:52:47.938302Z"}]}
{"channel":"book","type":"update","data":[{"symbol":"LINK/USD","bids":[{"price":18.56522,"qty":0.00000000},{"price":18.55783,"qty":33.11971188}],"asks":[],"checksum":75838943,"timestamp":"2024-06-01T17:52:47.940861Z"}]}
{"channel":"book","type":"update","data":[{"symbol":"LINK/USD","bids":[{"price":18.56532,"qty":52.52421310}],"asks":[],"checksum":1346957240,"timestamp":"2024-06-01T17:52:47.940869Z"}]}
{"channel":"book","type":"update","data":[{"symbol":"LINK/USD","bids":[{"price":18.56539,"qty":31.87500000}],"asks":[],"checksum":3531841998,"timestamp":"2024-06-01T17:52:47.941362Z"}]}
{"channel":"book","type":"update","data":[{"symbol":"LINK/USD","bids":[],"asks":[{"price":18.56982,"qty":31.87500000}],"checksum":1440210510,"timestamp":"2024-06-01T17:52:47.942698Z"}]}
{"channel":"book","type":"update","data":[{"symbol":"LINK/USD","bids":[{"price":18.56539,"qty":0.00000000},{"price":18.55783,"qty":33.11971188}],"asks":[],"checksum":3608973368,"timestamp":"2024-06-01T17:52:47.945057Z"}]}
{"channel":"book","type":"update","data":[{"symbol":"LINK/USD","bids":[{"price":18.56539,"qty":31.87500000}],"asks":[],"checksum":1440210510,"timestamp":"2024-06-01T17:52:47.948251Z"}]}
{"channel":"book","type":"update","data":[{"symbol":"LINK/USD","bids":[],"asks":[{"price":18.56982,"qty":0.00000000},{"price":18.57210,"qty":0.34717458}],"checksum":3531841998,"timestamp":"2024-06-01T17:52:47.948301Z"}]}
{"channel":"book","type":"update","data":[{"symbol":"LINK/USD","bids":[{"price":18.56536,"qty":31.87500000}],"asks":[],"checksum":4041952392,"timestamp":"2024-06-01T17:52:47.949102Z"}]}
{"channel":"book","type":"update","data":[{"symbol":"LINK/USD","bids":[{"price":18.56539,"qty":0.00000000},{"price":18.55981,"qty":31.87500000}],"asks":[],"checksum":755796634,"timestamp":"2024-06-01T17:52:47.951220Z"}]}
{"channel":"book","type":"update","data":[{"symbol":"LINK/USD","bids":[],"asks":[{"price":18.56982,"qty":31.87500000}],"checksum":2857956634,"timestamp":"2024-06-01T17:52:47.953438Z"}]}
{"channel":"book","type":"update","data":[{"symbol":"LINK/USD","bids":[{"price":18.56536,"qty":63.75000000}],"asks":[],"checksum":1236386838,"timestamp":"2024-06-01T17:52:47.971111Z"}]}
{"channel":"book","type":"update","data":[{"symbol":"LINK/USD","bids":[{"price":18.56536,"qty":31.87500000}],"asks":[],"checksum":2857956634,"timestamp":"2024-06-01T17:52:48.014934Z"}]}
{"channel":"book","type":"update","data":[{"symbol":"LINK/USD","bids":[{"price":18.56532,"qty":20.64921310}],"asks":[],"checksum":3752237013,"timestamp":"2024-06-01T17:52:48.018064Z"}]}
{"channel":"book","type":"update","data":[{"symbol":"LINK/USD","bids":[{"price":18.56536,"qty":0.00000000},{"price":18.55783,"qty":33.11971188}],"asks":[],"checksum":2211531359,"timestamp":"2024-06-01T17:52:48.143966Z"}]}
{"channel":"book","type":"update","data":[{"symbol":"LINK/USD","bids":[],"asks":[{"price":18.56962,"qty":0.00000000},{"price":18.57210,"qty":0.34717458}],"checksum":2756959698,"timestamp":"2024-06-01T17:52:48.146924Z"}]}
{"channel":"book","type":"update","data":[{"symbol":"LINK/USD","bids":[],"asks":[{"price":18.57144,"qty":6.43107813}],"checksum":2162705376,"timestamp":"2024-06-01T17:52:48.154976Z"}]}
{"channel":"book","type":"update","data":[{"symbol":"LINK/USD","bids":[{"price":18.56533,"qty":31.87500000}],"asks":[],"checksum":2313517222,"timestamp":"2024-06-01T17:52:48.204344Z"}]}
{"channel":"book","type":"update","data":[{"symbol":"LINK/USD","bids":[{"price":18.56533,"qty":0.00000000},{"price":18.55783,"qty":33.11971188}],"asks":[],"checksum":2162705376,"timestamp":"2024-06-01T17:52:48.207892Z"}]}
{"channel":"book","type":"update","data":[{"symbol":"LINK/USD","bids":[],"asks":[{"price":18.56982,"qty":0.00000000},{"price":18.57210,"qty":0.34717458}],"checksum":1821395434,"timestamp":"2024-06-01T17:52:48.211052Z"}]}
{"channel":"book","type":"update","data":[{"symbol":"LINK/USD","bids":[{"price":18.56534,"qty":31.87500000}],"asks":[],"checksum":316057624,"timestamp":"2024-06-01T17:52:48.213965Z"}]}
{"channel":"book","type":"update","data":[{"symbol":"LINK/USD","bids":[{"price":18.56534,"qty":63.75000000}],"asks":[],"checksum":4047477012,"timestamp":"2024-06-01T17:52:48.214574Z"}]}
{"channel":"book","type":"update","data":[{"symbol":"LINK/USD","bids":[],"asks":[{"price":18.56982,"qty":31.87500000}],"checksum":491229982,"timestamp":"2024-06-01T17:52:48.215107Z"}]}
{"channel":"book","type":"update","data":[{"symbol":"LINK/USD","bids":[{"price":18.56534,"qty":31.87500000}],"asks":[],"checksum":4272857618,"timestamp":"2024-06-01T17:52:48.217345Z"}]}
{"channel":"book","type":"update","data":[{"symbol":"LINK/USD","bids":[{"price":18.56534,"qty":63.75000000}],"asks":[],"checksum":491229982,"timestamp":"2024-06-01T17:52:48.221139Z"}]}
{"channel":"book","type":"update","data":[{"symbol":"LINK/USD","bids":[{"price":18.56534,"qty":31.87500000}],"asks":[],"checksum":4272857618,"timestamp":"2024-06-01T17:52:48.281868Z"}]}
{"channel":"book","type":"update","data":[{"symbol":"LINK/USD","bids":[{"price":18.56534,"qty":0.00000000},{"price":18.55783,"qty":33.11971188}],"asks":[],"checksum":2162705376,"timestamp":"2024-06-01T17:52:48.282341Z"}]}
{"channel":"book","type":"update","data":[{"symbol":"LINK/USD","bids":[{"price":18.55783,"qty":0.00000000},{"price":18.55782,"qty":9.78383046}],"asks":[],"checksum":2377604507,"timestamp":"2024-06-01T17:52:48.285090Z"}]}
{"channel":"book","type":"update","data":[{"symbol":"LINK/USD","bids":[],"asks":[{"price":18.56960,"qty":31.06600217}],"checksum":3156301717,"timestamp":"2024-06-01T17:52:48.285531Z"}]}
{"channel":"book","type":"update","data":[{"symbol":"LINK/USD","bids":[],"asks":[{"price":18.56961,"qty":13.46688344}],"checksum":1889743843,"timestamp":"2024-06-01T17:52:48.288379Z"}]}
{"channel":"book","type":"update","data":[{"symbol":"LINK/USD","bids":[],"asks":[{"price":18.56934,"qty":33.00000000}],"checksum":2675233663,"timestamp":"2024-06-01T17:52:48.288455Z"}]}
{"channel":"book","type":"update","data":[{"symbol":"LINK/USD","bids":[],"asks":[{"price":18.56961,"qty":0.00000000},{"price":18.57168,"qty":31.87500000}],"checksum":3575273202,"timestamp":"2024-06-01T17:52:48.289168Z"}]}
{"channel":"book","type":"update","data":[{"symbol":"LINK/USD","bids":[],"asks":[{"price":18.56933,"qty":13.46693711}],"checksum":3544072156,"timestamp":"2024-06-01T17:52:48.293139Z"}]}
{"channel":"book","type":"update","data":[{"symbol":"LINK/USD","bids":[{"price":18.56534,"qty":31.87500000}],"asks":[],"checksum":373882691,"timestamp":"2024-06-01T17:52:48.307744Z"}]}
{"channel":"book","type":"update","data":[{"symbol":"LINK/USD","bids":[{"price":18.56534,"qty":0.00000000},{"price":18.55782,"qty":9.78383046}],"asks":[],"checksum":3544072156,"timestamp":"2024-06-01T17:52:48.311138Z"}]}
{"channel":"book","type":"update","data":[{"symbol":"LINK/USD","bids":[],"asks":[{"price":18.56994,"qty":0.00000000},{"price":18.57168,"qty":31.87500000},{"price":18.56932,"qty":1.50546674}],"checksum":3049206963,"timestamp":"2024-06-01T17:52:48.342210Z"}]}
{"channel":"book","type":"update","data":[{"symbol":"LINK/USD","bids":[],"asks":[{"price":18.56933,"qty":0.00000000},{"price":18.57168,"qty":31.87500000}],"checksum":2676589478,"timestamp":"2024-06-01T17:52:48.346721Z"}]}
{"channel":"book","type":"update","data":[{"symbol":"LINK/USD","bids":[],"asks":[{"price":18.56932,"qty":0.00000000},{"price":18.57186,"qty":1.10230934},{"price":18.56933,"qty":1.50546674}],"checksum":789311611,"timestamp":"2024-06-01T17:52:48.349760Z"}]}
{"channel":"book","type":"update","data":[{"symbol":"LINK/USD","bids":[{"price":18.55782,"qty":0.00000000},{"price":18.55779,"qty":269.31533746}],"asks":[],"checksum":1362169385,"timestamp":"2024-06-01T17:52:48.435254Z"}]}
{"channel":"book","type":"update","data":[{"symbol":"LINK/USD","bids":[{"price":18.56026,"qty":30.56129084}],"asks":[],"checksum":1734729053,"timestamp":"2024-06-01T17:52:48.438958Z"}]}
{"channel":"book","type":"update","data":[{"symbol":"LINK/USD","bids":[],"asks":[{"price":18.56960,"qty":0.00000000},{"price":18.57186,"qty":1.10230934}],"checksum":1843599107,"timestamp":"2024-06-01T17:52:48.439243Z"}]}
{"channel":"book","type":"update","data":[{"symbol":"LINK/USD","bids":[],"asks":[{"price":18.56609,"qty":31.06600217}],"checksum":2788906993,"timestamp":"2024-06-01T17:52:48.790863Z"}]}
{"channel":"book","type":"update","data":[{"symbol":"LINK/USD","bids":[{"price":18.56516,"qty":0.00000000},{"price":18.55780,"qty":20.42293274}],"asks":[],"checksum":3347147720,"timestamp":"2024-06-01T17:52:48.978237Z"}]}
{"channel":"book","type":"update","data":[{"symbol":"LINK/USD","bids":[{"price":18.56026,"qty":0.00000000},{"price":18.55779,"qty":269.31533746}],"asks":[],"checksum":2525879391,"timestamp":"2024-06-01T17:52:49.090406Z"}]}
{"channel":"book","type":"update","data":[{"symbol":"LINK/USD","bids":[],"asks":[{"price":18.56795,"qty":31.87500000}],"checksum":795157536,"timestamp":"2024-06-01T17:52:49.122209Z"}]}
{"channel":"book","type":"update","data":[{"symbol":"LINK/USD","bids":[],"asks":[{"price":18.56795,"qty":0.00000000},{"price":18.57168,"qty":31.87500000}],"checksum":2525879391,"timestamp":"2024-06-01T17:52:49.157279Z"}]}
{"channel":"book","type":"update","data":[{"symbol":"LINK/USD","bids":[{"price":18.56533,"qty":31.87500000}],"asks":[],"checksum":4261952337,"timestamp":"2024-06-01T17:52:49.306434Z"}]}
{"channel":"book","type":"update","data":[{"symbol":"LINK/USD","bids":[{"price":18.56532,"qty":52.52421310}],"asks":[],"checksum":299271514,"timestamp":"2024-06-01T17:52:49.308387Z"}]}
{"channel":"book","type":"update","data":[{"symbol":"LINK/USD","bids":[],"asks":[{"price":18.56982,"qty":0.00000000},{"price":18.57186,"qty":1.10230934}],"checksum":2704230455,"timestamp":"2024-06-01T17:52:49.309634Z"}]}
{"channel":"book","type":"update","data":[{"symbol":"LINK/USD","bids":[{"price":18.56533,"qty":0.00000000},{"price":18.55779,"qty":269.31533746}],"asks":[],"checksum":1990489630,"timestamp":"2024-06-01T17:52:49.309791Z"}]}
{"channel":"book","type":"update","data":[{"symbol":"LINK/USD","bids":[],"asks":[{"price":18.56981,"qty":31.87500000}],"checksum":673639146,"timestamp":"2024-06-01T17:52:49.312870Z"}]}
{"channel":"book","type":"update","data":[{"symbol":"LINK/USD","bids":[{"price":18.56533,"qty":31.87500000}],"asks":[],"checksum":4249530959,"timestamp":"2024-06-01T17:52:49.326372Z"}]}
{"channel":"book","type":"update","data":[{"symbol":"LINK/USD","bids":[{"price":18.56533,"qty":0.00000000},{"price":18.55779,"qty":269.31533746}],"asks":[],"checksum":673639146,"timestamp":"2024-06-01T17:52:49.329937Z"}]}
{"channel":"book","type":"update","data":[{"symbol":"LINK/USD","bids":[{"price":18.56536,"qty":31.87500000}],"asks":[],"checksum":3547084858,"timestamp":"2024-06-01T17:52:49.370107Z"}]}
{"channel":"book","type":"update","data":[{"symbol":"LINK/USD","bids":[{"price":18.56535,"qty":31.87500000}],"asks":[],"checksum":4166669453,"timestamp":"2024-06-01T17:52:49.370492Z"}]}
{"channel":"book","type":"update","data":[{"symbol":"LINK/USD","bids":[{"price":18.56536,"qty":0.00000000},{"price":18.55780,"qty":20.42293274}],"asks":[],"checksum":2141275094,"timestamp":"2024-06-01T17:52:49.374077Z"}]}
{"channel":"book","type":"update","data":[{"symbol":"LINK/USD","bids":[],"asks":[{"price":18.56981,"qty":0.00000000},{"price":18.57186,"qty":1.10230934}],"checksum":600095150,"timestamp":"2024-06-01T17:52:49.377749Z"}]}
{"channel":"book","type":"update","data":[{"symbol":"LINK/USD","bids":[{"price":18.56532,"qty":20.64921310}],"asks":[],"checksum":3424257957,"timestamp":"2024-06-01T17:52:49.380027Z"}]}
{"channel":"book","type":"update","data":[{"symbol":"LINK/USD","bids":[{"price":18.56535,"qty":0.00000000},{"price":18.55779,"qty":269.31533746}],"asks":[],"checksum":2772318327,"timestamp":"2024-06-01T17:52:49.380365Z"}]}
{"channel":"book","type":"update","data":[{"symbol":"LINK/USD","bids":[],"asks":[{"price":18.56981,"qty":31.87500000}],"checksum":4223444099,"timestamp":"2024-06-01T17:52:49.381726Z"}]}
{"channel":"book","type":"update","data":[{"symbol":"LINK/USD","bids":[{"price":18.56534,"qty":31.87500000}],"asks":[],"checksum":4097518457,"timestamp":"2024-06-01T17:52:49.397028Z"}]}
{"channel":"book","type":"update","data":[{"symbol":"LINK/USD","bids":[{"price":18.56534,"qty":0.00000000},{"price":18.55779,"qty":269.31533746}],"asks":[],"checksum":4223444099,"timestamp":"2024-06-01T17:52:49.400097Z"}]}
{"channel":"book","type":"update","data":[{"symbol":"LINK/USD","bids":[{"price":18.56533,"qty":31.87500000}],"asks":[],"checksum":311692356,"timestamp":"2024-06-01T17:52:49.407283Z"}]}
{"channel":"book","type":"update","data":[{"symbol":"LINK/USD","bids":[{"price":18.56026,"qty":30.56129084}],"asks":[],"checksum":2424471995,"timestamp":"2024-06-01T17:52:49.410594Z"}]}
{"channel":"book","type":"update","data":[{"symbol":"LINK/USD","bids":[{"price":18.56533,"qty":0.00000000},{"price":18.55780,"qty":20.42293274}],"asks":[],"checksum":723344605,"timestamp":"2024-06-01T17:52:49.411081Z"}]}
{"channel":"book","type":"update","data":[{"symbol":"LINK/USD","bids":[{"price":18.56539,"qty":31.87500000}],"asks":[],"checksum":3436156241,"timestamp":"2024-06-01T17:52:49.430094Z"}]}
{"channel":"book","type":"update","data":[{"symbol":"LINK/USD","bids":[{"price":18.56535,"qty":31.87500000}],"asks":[],"checksum":3915321622,"timestamp":"2024-06-01T17:52:49.430133Z"}]}
{"channel":"book","type":"update","data":[{"symbol":"LINK/USD","bids":[{"price":18.56539,"qty":0.00000000},{"price":18.55981,"qty":31.87500000}],"asks":[],"checksum":308899874,"timestamp":"2024-06-01T17:52:49.433935Z"}]}
{"channel":"book","type":"update","data":[{"symbol":"LINK/USD","bids":[],"asks":[{"price":18.56981,"qty":0.00000000},{"price":18.57186,"qty":1.10230934}],"checksum":1309444698,"timestamp":"2024-06-01T17:52:49.437076Z"}]}
{"channel":"book","type":"update","data":[{"symbol":"LINK/USD","bids":[],"asks":[{"price":18.56981,"qty":31.87500000}],"checksum":308899874,"timestamp":"2024-06-01T17:52:49.445178Z"}]}
{"channel":"book","type":"update","data":[{"symbol":"LINK/USD","bids":[{"price":18.56535,"qty":0.00000000},{"price":18.55780,"qty":20.42293274}],"asks":[],"checksum":723344605,"timestamp":"2024-06-01T17:52:49.510765Z"}]}
{"channel":"book","type":"update","data":[{"symbol":"LINK/USD","bids":[{"price":18.56532,"qty":0.00000000},{"price":18.55779,"qty":269.31533746}],"asks":[],"checksum":290760414,"timestamp":"2024-06-01T17:52:49.920513Z"}]}
{"channel":"book","type":"update","data":[{"symbol":"LINK/USD","bids":[{"price":18.56538,"qty":31.87500000}],"asks":[],"checksum":3579317929,"timestamp":"2024-06-01T17:52:49.988156Z"}]}
{"channel":"book","type":"update","data":[{"symbol":"LINK/USD","bids":[{"price":18.56533,"qty":31.87500000}],"asks":[],"checksum":309365903,"timestamp":"2024-06-01T17:52:49.988192Z"}]}
{"channel":"book","type":"update","data":[{"symbol":"LINK/USD","bids":[],"asks":[{"price":18.56981,"qty":0.00000000},{"price":18.57186,"qty":1.10230934}],"checksum":1310029559,"timestamp":"2024-06-01T17:52:49.991975Z"}]}
{"channel":"book","type":"update","data":[{"symbol":"LINK/USD","bids":[{"price":18.56533,"qty":0.00000000},{"price":18.55780,"qty":20.42293274}],"asks":[],"checksum":2302538961,"timestamp":"2024-06-01T17:52:49.992407Z"}]}
{"channel":"book","type":"update","data":[{"symbol":"LINK/USD","bids":[{"price":18.56538,"qty":0.00000000},{"price":18.55779,"qty":269.31533746}],"asks":[],"checksum":1339439658,"timestamp":"2024-06-01T17:52:49.992608Z"}]}
{"channel":"book","type":"update","data":[{"symbol":"LINK/USD","bids":[],"asks":[{"price":18.56981,"qty":31.87500000}],"checksum":290760414,"timestamp":"2024-06-01T17:52:49.995576Z"}]}
{"channel":"book","type":"update","data":[{"symbol":"LINK/USD","bids":[{"price":18.56519,"qty":31.87500000}],"asks":[],"checksum":3386087426,"timestamp":"2024-06-01T17:52:49.996283Z"}]}
{"channel":"book","type":"update","data":[{"symbol":"LINK/USD","bids":[{"price":18.56519,"qty":0.00000000},{"price":18.55779,"qty":269.31533746}],"asks":[],"checksum":290760414,"timestamp":"2024-06-01T17:52:50.000252Z"}]}
{"channel":"book","type":"update","data":[{"symbol":"LINK/USD","bids":[],"asks":[{"price":18.56608,"qty":13.46695129}],"checksum":1434182668,"timestamp":"2024-06-01T17:52:50.347832Z"}]}
{"channel":"book","type":"update","data":[{"symbol":"LINK/USD","bids":[],"asks":[{"price":18.56608,"qty":0.00000000},{"price":18.57168,"qty":31.87500000}],"checksum":290760414,"timestamp":"2024-06-01T17:52:50.350887Z"}]}
{"channel":"book","type":"update","data":[{"symbol":"LINK/USD","bids":[],"asks":[{"price":18.56608,"qty":13.46695129}],"checksum":1434182668,"timestamp":"2024-06-01T17:52:50.354173Z"}]}
{"channel":"book","type":"update","data":[{"symbol":"LINK/USD","bids":[{"price":18.56516,"qty":20.64921310}],"asks":[],"checksum":853533039,"timestamp":"2024-06-01T17:52:50.450637Z"}]}
{"channel":"book","type":"update","data":[{"symbol":"LINK/USD","bids":[{"price":18.55780,"qty":0.00000000},{"price":18.55779,"qty":269.31533746}],"asks":[],"checksum":3023248533,"timestamp":"2024-06-01T17:52:50.947554Z"}]}
{"channel":"book","type":"update","data":[{"symbol":"LINK/USD","bids":[{"price":18.55780,"qty":19.45579109}],"asks":[],"checksum":1322444839,"timestamp":"2024-06-01T17:52:50.952823Z"}]}
{"channel":"book","type":"update","data":[{"symbol":"LINK/USD","bids":[{"price":18.56516,"qty":52.52421310}],"asks":[],"checksum":40401472,"timestamp":"2024-06-01T17:52:51.431813Z"}]}
{"channel":"book","type":"update","data":[{"symbol":"LINK/USD","bids":[{"price":18.56517,"qty":243.48672997}],"asks":[],"checksum":3026012337,"timestamp":"2024-06-01T17:52:51.436045Z"}]}
{"channel":"book","type":"update","data":[{"symbol":"LINK/USD","bids":[{"price":18.56516,"qty":20.64921310}],"asks":[],"checksum":1535375034,"timestamp":"2024-06-01T17:52:51.440110Z"}]}
{"channel":"book","type":"update","data":[{"symbol":"LINK/USD","bids":[{"price":18.56517,"qty":0.00000000},{"price":18.55780,"qty":19.45579109}],"asks":[],"checksum":1322444839,"timestamp":"2024-06-01T17:52:51.558854Z"}]}
{"channel":"book","type":"update","data":[{"symbol":"LINK/USD","bids":[{"price":18.56522,"qty":31.87500000}],"asks":[],"checksum":1437813637,"timestamp":"2024-06-01T17:52:51.941853Z"}]}
{"channel":"book","type":"update","data":[{"symbol":"LINK/USD","bids":[{"price":18.56518,"qty":31.87500000}],"asks":[],"checksum":1410855305,"timestamp":"2024-06-01T17:52:51.941898Z"}]}
{"channel":"book","type":"update","data":[{"symbol":"LINK/USD","bids":[],"asks":[{"price":18.56981,"qty":0.00000000},{"price":18.57168,"qty":31.87500000}],"checksum":1367015360,"timestamp":"2024-06-01T17:52:51.942910Z"}]}
{"channel":"book","type":"update","data":[{"symbol":"LINK/USD","bids":[{"price":18.56519,"qty":243.48672997}],"asks":[],"checksum":95108004,"timestamp":"2024-06-01T17:52:51.946797Z"}]}
{"channel":"book","type":"update","data":[{"symbol":"LINK/USD","bids":[{"price":18.56518,"qty":0.00000000},{"price":18.56025,"qty":269.32548286}],"asks":[],"checksum":2755500031,"timestamp":"2024-06-01T17:52:51.946860Z"}]}
{"channel":"book","type":"update","data":[{"symbol":"LINK/USD","bids":[{"price":18.56522,"qty":0.00000000},{"price":18.55981,"qty":31.87500000}],"asks":[],"checksum":3852182764,"timestamp":"2024-06-01T17:52:51.947422Z"}]}
{"channel":"book","type":"update","data":[{"symbol":"LINK/USD","bids":[{"price":18.56522,"qty":31.87500000}],"asks":[],"checksum":2755500031,"timestamp":"2024-06-01T17:52:51.947452Z"}]}
{"channel":"book","type":"update","data":[{"symbol":"LINK/USD","bids":[],"asks":[{"price":18.56980,"qty":31.87500000}],"checksum":2831285158,"timestamp":"2024-06-01T17:52:51.949562Z"}]}
{"channel":"book","type":"update","data":[{"symbol":"LINK/USD","bids":[{"price":18.56522,"qty":63.75000000}],"asks":[],"checksum":3192938319,"timestamp":"2024-06-01T17:52:51.951075Z"}]}
