{"channel":"book","type":"snapshot","data":[{"symbol":"LINK/USDT","bids":[{"price":18.58717,"qty":243.48672997},{"price":18.58716,"qty":80.65039072},{"price":18.58540,"qty":9.40000000},{"price":18.58525,"qty":243.48672997},{"price":18.58524,"qty":53.84992331},{"price":18.58512,"qty":9.00000000},{"price":18.58227,"qty":4.84505257},{"price":18.58208,"qty":8.39079195},{"price":18.58140,"qty":40.32519536},{"price":18.58000,"qty":112.86162126}],"asks":[{"price":18.59377,"qty":9.00000000},{"price":18.59380,"qty":9.40000000},{"price":18.59415,"qty":0.45562989},{"price":18.59536,"qty":51.08000000},{"price":18.59600,"qty":169.57854051},{"price":18.59622,"qty":53.81815402},{"price":18.59800,"qty":33.73844400},{"price":18.60211,"qty":243.48672997},{"price":18.60278,"qty":107.59836175},{"price":18.60811,"qty":79.42722785}],"checksum":1800509787}]}
{"channel":"book","type":"update","data":[{"symbol":"LINK/USDT","bids":[{"price":18.58140,"qty":0.00000000},{"price":18.57855,"qty":134.67333740}],"asks":[],"checksum":3550852275,"timestamp":"2024-06-01T17:51:56.735306Z"}]}
{"channel":"book","type":"update","data":[{"symbol":"LINK/USDT","bids":[{"price":18.58067,"qty":40.33025964}],"asks":[],"checksum":1502315087,"timestamp":"2024-06-01T17:51:56.775365Z"}]}
{"channel":"book","type":"update","data":[{"symbol":"LINK/USDT","bids":[{"price":18.58524,"qty":0.00000000},{"price":18.57855,"qty":134.67333740}],"asks":[],"checksum":1173092957,"timestamp":"2024-06-01T17:51:56.897863Z"}]}
{"channel":"book","type":"update","data":[{"symbol":"LINK/USDT","bids":[{"price":18.58525,"qty":0.00000000},{"price":18.57640,"qty":33.73844400}],"asks":[],"checksum":2391040444,"timestamp":"2024-06-01T17:51:56.901630Z"}]}
{"channel":"book","type":"update","data":[{"symbol":"LINK/USDT","bids":[{"price":18.58577,"qty":53.84840253}],"asks":[],"checksum":2240004325,"timestamp":"2024-06-01T17:51:56.902307Z"}]}
{"channel":"book","type":"update","data":[{"symbol":"LINK/USDT","bids":[{"price":18.58716,"qty":0.00000000},{"price":18.57640,"qty":33.73844400}],"asks":[],"checksum":2896735280,"timestamp":"2024-06-01T17:51:56.945599Z"}]}
{"channel":"book","type":"update","data":[{"symbol":"LINK/USDT","bids":[{"price":18.58717,"qty":0.00000000},{"price":18.57615,"qty":47.16000000}],"asks":[],"checksum":3025431162,"timestamp":"2024-06-01T17:51:56.949628Z"}]}
{"channel":"book","type":"update","data":[{"symbol":"LINK/USDT","bids":[{"price":18.58654,"qty":80.65882795}],"asks":[],"checksum":2200431436,"timestamp":"2024-06-01T17:51:56.985930Z"}]}
{"channel":"book","type":"update","data":[{"symbol":"LINK/USDT","bids":[{"price":18.58067,"qty":0.00000000},{"price":18.57615,"qty":47.16000000}],"asks":[],"checksum":1223127432,"timestamp":"2024-06-01T17:51:57.341416Z"}]}
{"channel":"book","type":"update","data":[{"symbol":"LINK/USDT","bids":[{"price":18.58577,"qty":0.00000000},{"price":18.57396,"qty":45.37000000}],"asks":[],"checksum":1367262168,"timestamp":"2024-06-01T17:51:57.354756Z"}]}
{"channel":"book","type":"update","data":[{"symbol":"LINK/USDT","bids":[{"price":18.58092,"qty":40.32941397}],"asks":[],"checksum":1379403317,"timestamp":"2024-06-01T17:51:57.381707Z"}]}
{"channel":"book","type":"update","data":[{"symbol":"LINK/USDT","bids":[{"price":18.58654,"qty":0.00000000},{"price":18.57396,"qty":45.37000000}],"asks":[],"checksum":3159891078,"timestamp":"2024-06-01T17:51:57.552531Z"}]}
{"channel":"book","type":"update","data":[{"symbol":"LINK/USDT","bids":[{"price":18.58655,"qty":243.48672997}],"asks":[],"checksum":589696884,"timestamp":"2024-06-01T17:51:57.560036Z"}]}
{"channel":"book","type":"update","data":[{"symbol":"LINK/USDT","bids":[{"price":18.58479,"qty":53.85122791}],"asks":[],"checksum":2789941817,"timestamp":"2024-06-01T17:51:57.576629Z"}]}
{"channel":"book","type":"update","data":[{"symbol":"LINK/USDT","bids":[{"price":18.58666,"qty":80.65882795}],"asks":[],"checksum":2473710926,"timestamp":"2024-06-01T17:51:57.592832Z"}]}
{"channel":"book","type":"update","data":[{"symbol":"LINK/USDT","bids":[{"price":18.58479,"qty":0.00000000},{"price":18.57640,"qty":33.73844400}],"asks":[],"checksum":4133310721,"timestamp":"2024-06-01T17:51:57.678652Z"}]}
{"channel":"book","type":"update","data":[{"symbol":"LINK/USDT","bids":[{"price":18.58092,"qty":0.00000000},{"price":18.57615,"qty":47.16000000}],"asks":[],"checksum":2746313459,"timestamp":"2024-06-01T17:51:57.948415Z"}]}
{"channel":"book","type":"update","data":[{"symbol":"LINK/USDT","bids":[{"price":18.58079,"qty":40.33101628}],"asks":[],"checksum":2144840689,"timestamp":"2024-06-01T17:51:57.988992Z"}]}
{"channel":"book","type":"update","data":[{"symbol":"LINK/USDT","bids":[{"price":18.58666,"qty":0.00000000},{"price":18.57615,"qty":47.16000000}],"asks":[],"checksum":2392552225,"timestamp":"2024-06-01T17:51:58.088261Z"}]}
{"channel":"book","type":"update","data":[{"symbol":"LINK/USDT","bids":[{"price":18.58531,"qty":53.84973693}],"asks":[],"checksum":3230635557,"timestamp":"2024-06-01T17:51:58.092995Z"}]}
{"channel":"book","type":"update","data":[{"symbol":"LINK/USDT","bids":[{"price":18.58079,"qty":0.00000000},{"price":18.57615,"qty":47.16000000}],"asks":[],"checksum":485054247,"timestamp":"2024-06-01T17:51:58.484825Z"}]}
{"channel":"book","type":"update","data":[{"symbol":"LINK/USDT","bids":[{"price":18.58532,"qty":243.48672997}],"asks":[],"checksum":907555858,"timestamp":"2024-06-01T17:51:58.558675Z"}]}
{"channel":"book","type":"update","data":[{"symbol":"LINK/USDT","bids":[{"price":18.58655,"qty":0.00000000},{"price":18.57615,"qty":47.16000000}],"asks":[],"checksum":2033302043,"timestamp":"2024-06-01T17:51:58.558695Z"}]}
{"channel":"book","type":"update","data":[{"symbol":"LINK/USDT","bids":[{"price":18.58662,"qty":80.66272956}],"asks":[],"checksum":3947504061,"timestamp":"2024-06-01T17:51:58.700871Z"}]}
{"channel":"book","type":"update","data":[{"symbol":"LINK/USDT","bids":[{"price":18.58663,"qty":243.48672997}],"asks":[],"checksum":629119630,"timestamp":"2024-06-01T17:51:58.704853Z"}]}
{"channel":"book","type":"update","data":[{"symbol":"LINK/USDT","bids":[{"price":18.58532,"qty":0.00000000},{"price":18.57640,"qty":33.73844400}],"asks":[],"checksum":2254609844,"timestamp":"2024-06-01T17:51:59.058311Z"}]}
{"channel":"book","type":"update","data":[{"symbol":"LINK/USDT","bids":[{"price":18.58088,"qty":40.33136478}],"asks":[],"checksum":2337620644,"timestamp":"2024-06-01T17:51:59.092525Z"}]}
{"channel":"book","type":"update","data":[{"symbol":"LINK/USDT","bids":[{"price":18.58662,"qty":0.00000000},{"price":18.57640,"qty":33.73844400}],"asks":[],"checksum":4066028187,"timestamp":"2024-06-01T17:51:59.268614Z"}]}
{"channel":"book","type":"update","data":[{"symbol":"LINK/USDT","bids":[{"price":18.58663,"qty":0.00000000},{"price":18.57615,"qty":47.16000000}],"asks":[],"checksum":1471012089,"timestamp":"2024-06-01T17:51:59.272973Z"}]}
{"channel":"book","type":"update","data":[{"symbol":"LINK/USDT","bids":[{"price":18.57684,"qty":50.49000000}],"asks":[],"checksum":2335894214,"timestamp":"2024-06-01T17:51:59.308668Z"}]}
{"channel":"book","type":"update","data":[{"symbol":"LINK/USDT","bids":[{"price":18.58683,"qty":80.66103823}],"asks":[],"checksum":3915325027,"timestamp":"2024-06-01T17:51:59.308868Z"}]}
{"channel":"book","type":"update","data":[{"symbol":"LINK/USDT","bids":[{"price":18.58684,"qty":243.48672997}],"asks":[],"checksum":615044498,"timestamp":"2024-06-01T17:51:59.559825Z"}]}
{"channel":"book","type":"update","data":[{"symbol":"LINK/USDT","bids":[{"price":18.58088,"qty":0.00000000},{"price":18.57684,"qty":50.49000000}],"asks":[],"checksum":328743816,"timestamp":"2024-06-01T17:51:59.658479Z"}]}
{"channel":"book","type":"update","data":[{"symbol":"LINK/USDT","bids":[{"price":18.58121,"qty":40.32912090}],"asks":[],"checksum":4130063876,"timestamp":"2024-06-01T17:51:59.698774Z"}]}
{"channel":"book","type":"update","data":[{"symbol":"LINK/USDT","bids":[{"price":18.58683,"qty":0.00000000},{"price":18.57684,"qty":50.49000000}],"asks":[],"checksum":223450451,"timestamp":"2024-06-01T17:51:59.875611Z"}]}
{"channel":"book","type":"update","data":[{"symbol":"LINK/USDT","bids":[{"price":18.58684,"qty":0.00000000},{"price":18.57640,"qty":33.73844400}],"asks":[],"checksum":3234924076,"timestamp":"2024-06-01T17:51:59.879772Z"}]}
{"channel":"book","type":"update","data":[{"symbol":"LINK/USDT","bids":[{"price":18.58708,"qty":80.65655052}],"asks":[],"checksum":696888973,"timestamp":"2024-06-01T17:51:59.915734Z"}]}
{"channel":"book","type":"update","data":[{"symbol":"LINK/USDT","bids":[],"asks":[{"price":18.60211,"qty":0.00000000},{"price":18.60812,"qty":48.75805200}],"checksum":3411121238,"timestamp":"2024-06-01T17:52:00.060383Z"}]}
{"channel":"book","type":"update","data":[{"symbol":"LINK/USDT","bids":[{"price":18.58531,"qty":0.00000000},{"price":18.57640,"qty":33.73844400}],"asks":[],"checksum":1604703984,"timestamp":"2024-06-01T17:52:00.075982Z"}]}
{"channel":"book","type":"update","data":[{"symbol":"LINK/USDT","bids":[{"price":18.58581,"qty":53.84827499}],"asks":[],"checksum":1558558620,"timestamp":"2024-06-01T17:52:00.080198Z"}]}
{"channel":"book","type":"update","data":[{"symbol":"LINK/USDT","bids":[],"asks":[{"price":18.59380,"qty":0.00000000},{"price":18.60918,"qty":107.56137192}],"checksum":707787347,"timestamp":"2024-06-01T17:52:00.096097Z"}]}
{"channel":"book","type":"update","data":[{"symbol":"LINK/USDT","bids":[{"price":18.58581,"qty":0.00000000},{"price":18.57640,"qty":33.73844400}],"asks":[],"checksum":695180095,"timestamp":"2024-06-01T17:52:00.096410Z"}]}
{"channel":"book","type":"update","data":[{"symbol":"LINK/USDT","bids":[],"asks":[{"price":18.59377,"qty":0.00000000},{"price":18.61255,"qty":225.99000000}],"checksum":2536642931,"timestamp":"2024-06-01T17:52:00.106036Z"}]}
{"channel":"book","type":"update","data":[{"symbol":"LINK/USDT","bids":[],"asks":[{"price":18.59412,"qty":9.00000000}],"checksum":822266246,"timestamp":"2024-06-01T17:52:00.106259Z"}]}
{"channel":"book","type":"update","data":[{"symbol":"LINK/USDT","bids":[{"price":18.58121,"qty":0.00000000},{"price":18.57615,"qty":47.16000000}],"asks":[],"checksum":3356458329,"timestamp":"2024-06-01T17:52:00.195190Z"}]}
{"channel":"book","type":"update","data":[{"symbol":"LINK/USDT","bids":[{"price":18.58159,"qty":40.32658402}],"asks":[],"checksum":2472487887,"timestamp":"2024-06-01T17:52:00.235148Z"}]}
{"channel":"book","type":"update","data":[{"symbol":"LINK/USDT","bids":[{"price":18.58708,"qty":0.00000000},{"price":18.57615,"qty":47.16000000}],"asks":[],"checksum":3095945298,"timestamp":"2024-06-01T17:52:00.455374Z"}]}
{"channel":"book","type":"update","data":[{"symbol":"LINK/USDT","bids":[{"price":18.58160,"qty":243.48672997}],"asks":[],"checksum":830293150,"timestamp":"2024-06-01T17:52:00.459564Z"}]}
{"channel":"book","type":"update","data":[{"symbol":"LINK/USDT","bids":[{"price":18.58571,"qty":53.84857655}],"asks":[],"checksum":1556240537,"timestamp":"2024-06-01T17:52:00.591327Z"}]}
{"channel":"book","type":"update","data":[{"symbol":"LINK/USDT","bids":[{"price":18.58540,"qty":0.00000000},{"price":18.57640,"qty":33.73844400}],"asks":[],"checksum":4055803310,"timestamp":"2024-06-01T17:52:00.594002Z"}]}
{"channel":"book","type":"update","data":[{"symbol":"LINK/USDT","bids":[{"price":18.58619,"qty":9.40000000}],"asks":[],"checksum":2428612948,"timestamp":"2024-06-01T17:52:00.594190Z"}]}
{"channel":"book","type":"update","data":[{"symbol":"LINK/USDT","bids":[{"price":18.58159,"qty":0.00000000},{"price":18.57640,"qty":33.73844400}],"asks":[],"checksum":539017568,"timestamp":"2024-06-01T17:52:00.895383Z"}]}
{"channel":"book","type":"update","data":[{"symbol":"LINK/USDT","bids":[],"asks":[{"price":18.59534,"qty":9.40000000}],"checksum":2427126264,"timestamp":"2024-06-01T17:52:00.910666Z"}]}
{"channel":"book","type":"update","data":[{"symbol":"LINK/USDT","bids":[{"price":18.58134,"qty":40.32882782}],"asks":[],"checksum":547528398,"timestamp":"2024-06-01T17:52:00.935664Z"}]}
{"channel":"book","type":"update","data":[{"symbol":"LINK/USDT","bids":[{"price":18.58571,"qty":0.00000000},{"price":18.57640,"qty":33.73844400}],"asks":[],"checksum":1868745862,"timestamp":"2024-06-01T17:52:01.092579Z"}]}
{"channel":"book","type":"update","data":[{"symbol":"LINK/USDT","bids":[],"asks":[{"price":18.59015,"qty":21.53429211}],"checksum":3288088311,"timestamp":"2024-06-01T17:52:01.096682Z"}]}
{"channel":"book","type":"update","data":[{"symbol":"LINK/USDT","bids":[{"price":18.58616,"qty":53.84728159}],"asks":[],"checksum":20448818,"timestamp":"2024-06-01T17:52:01.096740Z"}]}
{"channel":"book","type":"update","data":[{"symbol":"LINK/USDT","bids":[{"price":18.58708,"qty":80.65765565}],"asks":[],"checksum":1310726407,"timestamp":"2024-06-01T17:52:01.119042Z"}]}
{"channel":"book","type":"update","data":[{"symbol":"LINK/USDT","bids":[],"asks":[{"price":18.59012,"qty":9.00000000}],"checksum":128808180,"timestamp":"2024-06-01T17:52:01.128860Z"}]}
{"channel":"book","type":"update","data":[{"symbol":"LINK/USDT","bids":[],"asks":[{"price":18.59015,"qty":0.00000000},{"price":18.60811,"qty":79.42722785}],"checksum":2885584748,"timestamp":"2024-06-01T17:52:01.133001Z"}]}
{"channel":"book","type":"update","data":[{"symbol":"LINK/USDT","bids":[{"price":18.58709,"qty":243.48672997}],"asks":[],"checksum":467467844,"timestamp":"2024-06-01T17:52:01.561834Z"}]}
{"channel":"book","type":"update","data":[{"symbol":"LINK/USDT","bids":[],"asks":[{"price":18.59012,"qty":0.00000000},{"price":18.60812,"qty":48.75805200}],"checksum":1385992798,"timestamp":"2024-06-01T17:52:01.566663Z"}]}
{"channel":"book","type":"update","data":[{"symbol":"LINK/USDT","bids":[{"price":18.58134,"qty":0.00000000},{"price":18.57855,"qty":134.67333740}],"asks":[],"checksum":333076652,"timestamp":"2024-06-01T17:52:01.574026Z"}]}
{"channel":"book","type":"update","data":[{"symbol":"LINK/USDT","bids":[{"price":18.58708,"qty":0.00000000},{"price":18.57684,"qty":50.49000000}],"asks":[],"checksum":4279516537,"timestamp":"2024-06-01T17:52:01.757986Z"}]}
{"channel":"book","type":"update","data":[{"symbol":"LINK/USDT","bids":[{"price":18.58160,"qty":0.00000000},{"price":18.57640,"qty":33.73844400}],"asks":[],"checksum":961445041,"timestamp":"2024-06-01T17:52:01.762144Z"}]}
{"channel":"book","type":"update","data":[{"symbol":"LINK/USDT","bids":[{"price":18.58685,"qty":80.66103823}],"asks":[],"checksum":2726468019,"timestamp":"2024-06-01T17:52:01.798331Z"}]}
{"channel":"book","type":"update","data":[{"symbol":"LINK/USDT","bids":[],"asks":[{"price":18.60311,"qty":243.48672997}],"checksum":3677662484,"timestamp":"2024-06-01T17:52:01.801928Z"}]}
{"channel":"book","type":"update","data":[{"symbol":"LINK/USDT","bids":[{"price":18.58616,"qty":0.00000000},{"price":18.57640,"qty":33.73844400}],"asks":[],"checksum":2741533256,"timestamp":"2024-06-01T17:52:01.915729Z"}]}
{"channel":"book","type":"update","data":[{"symbol":"LINK/USDT","bids":[{"price":18.58709,"qty":0.00000000},{"price":18.57615,"qty":47.16000000}],"asks":[],"checksum":2395069816,"timestamp":"2024-06-01T17:52:01.920068Z"}]}
{"channel":"book","type":"update","data":[{"symbol":"LINK/USDT","bids":[{"price":18.58569,"qty":53.84862149}],"asks":[],"checksum":622721653,"timestamp":"2024-06-01T17:52:01.920312Z"}]}
{"channel":"book","type":"update","data":[{"symbol":"LINK/USDT","bids":[{"price":18.58112,"qty":40.33051911}],"asks":[],"checksum":253074591,"timestamp":"2024-06-01T17:52:02.173587Z"}]}
{"channel":"book","type":"update","data":[{"symbol":"LINK/USDT","bids":[{"price":18.58685,"qty":0.00000000},{"price":18.57640,"qty":33.73844400}],"asks":[],"checksum":3913309374,"timestamp":"2024-06-01T17:52:02.357283Z"}]}
{"channel":"book","type":"update","data":[{"symbol":"LINK/USDT","bids":[{"price":18.58686,"qty":80.66144637}],"asks":[],"checksum":2559640361,"timestamp":"2024-06-01T17:52:02.397516Z"}]}
{"channel":"book","type":"update","data":[{"symbol":"LINK/USDT","bids":[{"price":18.58687,"qty":243.48672997}],"asks":[],"checksum":526030694,"timestamp":"2024-06-01T17:52:02.401626Z"}]}
{"channel":"book","type":"update","data":[{"symbol":"LINK/USDT","bids":[],"asks":[{"price":18.60311,"qty":0.00000000},{"price":18.60812,"qty":48.75805200}],"checksum":1726784449,"timestamp":"2024-06-01T17:52:02.402964Z"}]}
{"channel":"book","type":"update","data":[{"symbol":"LINK/USDT","bids":[],"asks":[{"price":18.59600,"qty":0.00000000},{"price":18.60918,"qty":107.56137192}],"checksum":3461096498,"timestamp":"2024-06-01T17:52:02.407093Z"}]}
{"channel":"book","type":"update","data":[{"symbol":"LINK/USDT","bids":[{"price":18.58569,"qty":0.00000000},{"price":18.57684,"qty":50.49000000}],"asks":[],"checksum":2711219133,"timestamp":"2024-06-01T17:52:02.408107Z"}]}
{"channel":"book","type":"update","data":[{"symbol":"LINK/USDT","bids":[],"asks":[{"price":18.59700,"qty":126.98854051}],"checksum":1261048633,"timestamp":"2024-06-01T17:52:02.411974Z"}]}
{"channel":"book","type":"update","data":[{"symbol":"LINK/USDT","bids":[{"price":18.58706,"qty":4.84365379}],"asks":[],"checksum":2959298604,"timestamp":"2024-06-01T17:52:02.429035Z"}]}
{"channel":"book","type":"update","data":[{"symbol":"LINK/USDT","bids":[{"price":18.57855,"qty":0.00000000},{"price":18.57684,"qty":50.49000000}],"asks":[],"checksum":3710994853,"timestamp":"2024-06-01T17:52:02.429664Z"}]}
{"channel":"book","type":"update","data":[{"symbol":"LINK/USDT","bids":[{"price":18.58227,"qty":0.00000000},{"price":18.57640,"qty":33.73844400}],"asks":[],"checksum":3014224693,"timestamp":"2024-06-01T17:52:02.430525Z"}]}
{"channel":"book","type":"update","data":[{"symbol":"LINK/USDT","bids":[],"asks":[{"price":18.59700,"qty":0.00000000},{"price":18.60918,"qty":107.56137192}],"checksum":3575043761,"timestamp":"2024-06-01T17:52:02.432587Z"}]}
{"channel":"book","type":"update","data":[{"symbol":"LINK/USDT","bids":[],"asks":[{"price":18.59622,"qty":0.00000000},{"price":18.61255,"qty":225.99000000}],"checksum":1593248639,"timestamp":"2024-06-01T17:52:02.434188Z"}]}
{"channel":"book","type":"update","data":[{"symbol":"LINK/USDT","bids":[{"price":18.58713,"qty":53.84446378}],"asks":[],"checksum":2596585005,"timestamp":"2024-06-01T17:52:02.434262Z"}]}
{"channel":"book","type":"update","data":[{"symbol":"LINK/USDT","bids":[{"price":18.58168,"qty":134.65057450}],"asks":[],"checksum":3829277496,"timestamp":"2024-06-01T17:52:02.434456Z"}]}
{"channel":"book","type":"update","data":[{"symbol":"LINK/USDT","bids":[{"price":18.58732,"qty":4.84372269}],"asks":[],"checksum":3427353128,"timestamp":"2024-06-01T17:52:02.437144Z"}]}
{"channel":"book","type":"update","data":[{"symbol":"LINK/USDT","bids":[],"asks":[{"price":18.59800,"qty":252.54198451}],"checksum":901423667,"timestamp":"2024-06-01T17:52:02.437578Z"}]}
{"channel":"book","type":"update","data":[{"symbol":"LINK/USDT","bids":[{"price":18.58713,"qty":0.00000000},{"price":18.58000,"qty":112.86162126}],"asks":[],"checksum":422808394,"timestamp":"2024-06-01T17:52:02.438749Z"}]}
{"channel":"book","type":"update","data":[{"symbol":"LINK/USDT","bids":[{"price":18.58706,"qty":0.00000000},{"price":18.57684,"qty":50.49000000}],"asks":[],"checksum":2713099631,"timestamp":"2024-06-01T17:52:02.440146Z"}]}
{"channel":"book","type":"update","data":[{"symbol":"LINK/USDT","bids":[],"asks":[{"price":18.60278,"qty":0.00000000},{"price":18.61475,"qty":0.45497187}],"checksum":2656194403,"timestamp":"2024-06-01T17:52:02.450034Z"}]}
{"channel":"book","type":"update","data":[{"symbol":"LINK/USDT","bids":[{"price":18.58619,"qty":0.00000000},{"price":18.57664,"qty":269.37425608}],"asks":[],"checksum":344633566,"timestamp":"2024-06-01T17:52:02.467357Z"}]}
{"channel":"book","type":"update","data":[{"symbol":"LINK/USDT","bids":[{"price":18.58705,"qty":9.40000000}],"asks":[],"checksum":2117432497,"timestamp":"2024-06-01T17:52:02.467411Z"}]}
{"channel":"book","type":"update","data":[{"symbol":"LINK/USDT","bids":[],"asks":[{"price":18.59534,"qty":0.00000000},{"price":18.61514,"qty":0.45293610}],"checksum":1539228795,"timestamp":"2024-06-01T17:52:02.499052Z"}]}
{"channel":"book","type":"update","data":[{"symbol":"LINK/USDT","bids":[{"price":18.58735,"qty":9.00000000}],"asks":[],"checksum":2189906727,"timestamp":"2024-06-01T17:52:02.503881Z"}]}
{"channel":"book","type":"update","data":[{"symbol":"LINK/USDT","bids":[{"price":18.58705,"qty":0.00000000},{"price":18.57684,"qty":50.49000000}],"asks":[],"checksum":1184683776,"timestamp":"2024-06-01T17:52:02.506689Z"}]}
{"channel":"book","type":"update","data":[{"symbol":"LINK/USDT","bids":[{"price":18.58773,"qty":9.40000000}],"asks":[],"checksum":3581085016,"timestamp":"2024-06-01T17:52:02.506731Z"}]}
{"channel":"book","type":"update","data":[{"symbol":"LINK/USDT","bids":[],"asks":[{"price":18.59800,"qty":33.73844400}],"checksum":3004931230,"timestamp":"2024-06-01T17:52:02.555486Z"}]}
{"channel":"book","type":"update","data":[{"symbol":"LINK/USDT","bids":[],"asks":[{"price":18.59900,"qty":158.56104051}],"checksum":2576503805,"timestamp":"2024-06-01T17:52:02.560605Z"}]}
{"channel":"book","type":"update","data":[{"symbol":"LINK/USDT","bids":[{"price":18.58735,"qty":0.00000000},{"price":18.57684,"qty":50.49000000}],"asks":[],"checksum":308855845,"timestamp":"2024-06-01T17:52:02.560798Z"}]}
{"channel":"book","type":"update","data":[{"symbol":"LINK/USDT","bids":[{"price":18.58776,"qty":9.00000000}],"asks":[],"checksum":2934385266,"timestamp":"2024-06-01T17:52:02.560869Z"}]}
{"channel":"book","type":"update","data":[{"symbol":"LINK/USDT","bids":[{"price":18.58512,"qty":0.00000000},{"price":18.57684,"qty":50.49000000}],"asks":[],"checksum":3590594342,"timestamp":"2024-06-01T17:52:02.584464Z"}]}
{"channel":"book","type":"update","data":[{"symbol":"LINK/USDT","bids":[{"price":18.58732,"qty":0.00000000},{"price":18.57664,"qty":269.37425608}],"asks":[],"checksum":895489698,"timestamp":"2024-06-01T17:52:02.610928Z"}]}
{"channel":"book","type":"update","data":[{"symbol":"LINK/USDT","bids":[{"price":18.58112,"qty":0.00000000},{"price":18.57640,"qty":33.73844400}],"asks":[],"checksum":4167951648,"timestamp":"2024-06-01T17:52:02.811824Z"}]}
{"channel":"book","type":"update","data":[{"symbol":"LINK/USDT","bids":[{"price":18.58366,"qty":40.31499716}],"asks":[],"checksum":4197588748,"timestamp":"2024-06-01T17:52:02.852147Z"}]}
{"channel":"book","type":"update","data":[{"symbol":"LINK/USDT","bids":[{"price":18.58782,"qty":53.84245633}],"asks":[],"checksum":4009478568,"timestamp":"2024-06-01T17:52:02.939817Z"}]}
{"channel":"book","type":"update","data":[{"symbol":"LINK/USDT","bids":[{"price":18.58785,"qty":9.00000000}],"asks":[],"checksum":2440735792,"timestamp":"2024-06-01T17:52:02.946705Z"}]}
{"channel":"book","type":"update","data":[{"symbol":"LINK/USDT","bids":[{"price":18.58782,"qty":0.00000000},{"price":18.57684,"qty":50.49000000}],"asks":[],"checksum":2843896162,"timestamp":"2024-06-01T17:52:03.009954Z"}]}
{"channel":"book","type":"update","data":[{"symbol":"LINK/USDT","bids":[],"asks":[{"price":18.60918,"qty":0.00000000},{"price":18.61514,"qty":0.45293610}],"checksum":3418552239,"timestamp":"2024-06-01T17:52:03.010047Z"}]}
{"channel":"book","type":"update","data":[{"symbol":"LINK/USDT","bids":[{"price":18.58785,"qty":0.00000000},{"price":18.57664,"qty":269.37425608}],"asks":[],"checksum":2479974924,"timestamp":"2024-06-01T17:52:03.015063Z"}]}
{"channel":"book","type":"update","data":[{"symbol":"LINK/USDT","bids":[{"price":18.58686,"qty":0.00000000},{"price":18.57640,"qty":33.73844400}],"asks":[],"checksum":1291586633,"timestamp":"2024-06-01T17:52:03.037895Z"}]}
{"channel":"book","type":"update","data":[{"symbol":"LINK/USDT","bids":[{"price":18.58970,"qty":80.62392079}],"asks":[],"checksum":3496060996,"timestamp":"2024-06-01T17:52:03.078118Z"}]}
{"channel":"book","type":"update","data":[{"symbol":"LINK/USDT","bids":[{"price":18.58366,"qty":0.00000000},{"price":18.57640,"qty":33.73844400}],"asks":[],"checksum":3527299688,"timestamp":"2024-06-01T17:52:03.490888Z"}]}
{"channel":"book","type":"update","data":[{"symbol":"LINK/USDT","bids":[{"price":18.58971,"qty":243.48672997}],"asks":[],"checksum":2128678832,"timestamp":"2024-06-01T17:52:03.495013Z"}]}
{"channel":"book","type":"update","data":[{"symbol":"LINK/USDT","bids":[{"price":18.58402,"qty":40.31250917}],"asks":[],"checksum":3393743748,"timestamp":"2024-06-01T17:52:03.531035Z"}]}
{"channel":"book","type":"update","data":[{"symbol":"LINK/USDT","bids":[{"price":18.58687,"qty":0.00000000},{"price":18.57664,"qty":269.37425608}],"asks":[],"checksum":494667117,"timestamp":"2024-06-01T17:52:03.560381Z"}]}
{"channel":"book","type":"update","data":[{"symbol":"LINK/USDT","bids":[{"price":18.58773,"qty":0.00000000},{"price":18.57640,"qty":33.73844400}],"asks":[],"checksum":3129070048,"timestamp":"2024-06-01T17:52:03.563102Z"}]}
{"channel":"book","type":"update","data":[{"symbol":"LINK/USDT","bids":[{"price":18.58970,"qty":0.00000000},{"price":18.57615,"qty":47.16000000}],"asks":[],"checksum":482021899,"timestamp":"2024-06-01T17:52:03.716546Z"}]}
{"channel":"book","type":"update","data":[{"symbol":"LINK/USDT","bids":[{"price":18.58923,"qty":80.63218033}],"asks":[],"checksum":938040148,"timestamp":"2024-06-01T17:52:03.756715Z"}]}
{"channel":"book","type":"update","data":[{"symbol":"LINK/USDT","bids":[],"asks":[{"price":18.59408,"qty":21.52974210}],"checksum":4046203374,"timestamp":"2024-06-01T17:52:04.024536Z"}]}
{"channel":"book","type":"update","data":[{"symbol":"LINK/USDT","bids":[],"asks":[{"price":18.61459,"qty":107.53011601}],"checksum":591404433,"timestamp":"2024-06-01T17:52:04.024635Z"}]}
{"channel":"book","type":"update","data":[{"symbol":"LINK/USDT","bids":[],"asks":[{"price":18.59895,"qty":53.81026383}],"checksum":372960818,"timestamp":"2024-06-01T17:52:04.024669Z"}]}
{"channel":"book","type":"update","data":[{"symbol":"LINK/USDT","bids":[],"asks":[{"price":18.60420,"qty":107.59016987}],"checksum":3453520160,"timestamp":"2024-06-01T17:52:04.024694Z"}]}
{"channel":"book","type":"update","data":[{"symbol":"LINK/USDT","bids":[{"price":18.58797,"qty":53.84203071}],"asks":[],"checksum":3676321783,"timestamp":"2024-06-01T17:52:04.024707Z"}]}
{"channel":"book","type":"update","data":[{"symbol":"LINK/USDT","bids":[{"price":18.58971,"qty":0.00000000},{"price":18.57640,"qty":33.73844400}],"asks":[],"checksum":787626582,"timestamp":"2024-06-01T17:52:04.029127Z"}]}
{"channel":"book","type":"update","data":[{"symbol":"LINK/USDT","bids":[],"asks":[{"price":18.59405,"qty":9.00000000}],"checksum":714133863,"timestamp":"2024-06-01T17:52:04.029632Z"}]}
{"channel":"book","type":"update","data":[{"symbol":"LINK/USDT","bids":[],"asks":[{"price":18.59408,"qty":0.00000000},{"price":18.60812,"qty":48.75805200}],"checksum":1272578099,"timestamp":"2024-06-01T17:52:04.029660Z"}]}
{"channel":"book","type":"update","data":[{"symbol":"LINK/USDT","bids":[],"asks":[{"price":18.59536,"qty":0.00000000},{"price":18.61255,"qty":225.99000000}],"checksum":881669645,"timestamp":"2024-06-01T17:52:04.035137Z"}]}
{"channel":"book","type":"update","data":[{"symbol":"LINK/USDT","bids":[],"asks":[{"price":18.59729,"qty":9.40000000}],"checksum":2093870050,"timestamp":"2024-06-01T17:52:04.037866Z"}]}
{"channel":"book","type":"update","data":[{"symbol":"LINK/USDT","bids":[],"asks":[{"price":18.60103,"qty":50.49000000}],"checksum":2468803514,"timestamp":"2024-06-01T17:52:04.037972Z"}]}
{"channel":"book","type":"update","data":[{"symbol":"LINK/USDT","bids":[],"asks":[{"price":18.59405,"qty":0.00000000},{"price":18.60812,"qty":48.75805200}],"checksum":2504301829,"timestamp":"2024-06-01T17:52:04.086445Z"}]}
{"channel":"book","type":"update","data":[{"symbol":"LINK/USDT","bids":[{"price":18.58402,"qty":0.00000000},{"price":18.57615,"qty":47.16000000}],"asks":[],"checksum":2834914360,"timestamp":"2024-06-01T17:52:04.089333Z"}]}
{"channel":"book","type":"update","data":[{"symbol":"LINK/USDT","bids":[{"price":18.58344,"qty":40.31641887}],"asks":[],"checksum":2321339750,"timestamp":"2024-06-01T17:52:04.129613Z"}]}
{"channel":"book","type":"update","data":[{"symbol":"LINK/USDT","bids":[{"price":18.58344,"qty":0.00000000},{"price":18.57615,"qty":47.16000000}],"asks":[],"checksum":2834914360,"timestamp":"2024-06-01T17:52:04.215060Z"}]}
{"channel":"book","type":"update","data":[{"symbol":"LINK/USDT","bids":[{"price":18.58923,"qty":0.00000000},{"price":18.57396,"qty":45.37000000}],"asks":[],"checksum":4141488344,"timestamp":"2024-06-01T17:52:04.316375Z"}]}
{"channel":"book","type":"update","data":[{"symbol":"LINK/USDT","bids":[{"price":18.58800,"qty":9.00000000}],"asks":[],"checksum":3901026245,"timestamp":"2024-06-01T17:52:04.321236Z"}]}
{"channel":"book","type":"update","data":[{"symbol":"LINK/USDT","bids":[{"price":18.58797,"qty":0.00000000},{"price":18.57396,"qty":45.37000000}],"asks":[],"checksum":530453541,"timestamp":"2024-06-01T17:52:04.325272Z"}]}
{"channel":"book","type":"update","data":[{"symbol":"LINK/USDT","bids":[{"price":18.58279,"qty":9.40000000}],"asks":[],"checksum":2976966381,"timestamp":"2024-06-01T17:52:04.328111Z"}]}
{"channel":"book","type":"update","data":[{"symbol":"LINK/USDT","bids":[{"price":18.58919,"qty":80.63283774}],"asks":[],"checksum":761506026,"timestamp":"2024-06-01T17:52:04.356530Z"}]}
{"channel":"book","type":"update","data":[{"symbol":"LINK/USDT","bids":[{"price":18.58800,"qty":0.00000000},{"price":18.57615,"qty":47.16000000}],"asks":[],"checksum":3395887979,"timestamp":"2024-06-01T17:52:04.361056Z"}]}
{"channel":"book","type":"update","data":[{"symbol":"LINK/USDT","bids":[{"price":18.58920,"qty":243.48672997}],"asks":[],"checksum":2388051486,"timestamp":"2024-06-01T17:52:04.560014Z"}]}
{"channel":"book","type":"update","data":[{"symbol":"LINK/USDT","bids":[],"asks":[{"price":18.59408,"qty":21.52974915}],"checksum":273722164,"timestamp":"2024-06-01T17:52:04.564741Z"}]}
{"channel":"book","type":"update","data":[{"symbol":"LINK/USDT","bids":[{"price":18.58761,"qty":53.84307749}],"asks":[],"checksum":1840240625,"timestamp":"2024-06-01T17:52:04.564862Z"}]}
{"channel":"book","type":"update","data":[{"symbol":"LINK/USDT","bids":[],"asks":[{"price":18.59408,"qty":0.00000000},{"price":18.60812,"qty":48.75805200}],"checksum":4087986907,"timestamp":"2024-06-01T17:52:04.568945Z"}]}
{"channel":"book","type":"update","data":[{"symbol":"LINK/USDT","bids":[{"price":18.58345,"qty":40.31641887}],"asks":[],"checksum":186882645,"timestamp":"2024-06-01T17:52:04.884064Z"}]}
{"channel":"book","type":"update","data":[{"symbol":"LINK/USDT","bids":[{"price":18.58920,"qty":0.00000000},{"price":18.57664,"qty":269.37425608}],"asks":[],"checksum":2092013953,"timestamp":"2024-06-01T17:52:05.302875Z"}]}
{"channel":"book","type":"update","data":[{"symbol":"LINK/USDT","bids":[{"price":18.58776,"qty":0.00000000},{"price":18.57640,"qty":33.73844400}],"asks":[],"checksum":4277181324,"timestamp":"2024-06-01T17:52:05.304640Z"}]}
{"channel":"book","type":"update","data":[{"symbol":"LINK/USDT","bids":[{"price":18.58761,"qty":0.00000000},{"price":18.57615,"qty":47.16000000}],"asks":[],"checksum":1240916014,"timestamp":"2024-06-01T17:52:05.307259Z"}]}
{"channel":"book","type":"update","data":[{"symbol":"LINK/USDT","bids":[{"price":18.58713,"qty":53.84444560}],"asks":[],"checksum":3100129136,"timestamp":"2024-06-01T17:52:05.311534Z"}]}
{"channel":"book","type":"update","data":[{"symbol":"LINK/USDT","bids":[{"price":18.58713,"qty":0.00000000},{"price":18.57615,"qty":47.16000000}],"asks":[],"checksum":1240916014,"timestamp":"2024-06-01T17:52:05.411880Z"}]}
{"channel":"book","type":"update","data":[{"symbol":"LINK/USDT","bids":[],"asks":[{"price":18.59895,"qty":0.00000000},{"price":18.61255,"qty":225.99000000}],"checksum":3519083916,"timestamp":"2024-06-01T17:52:05.493935Z"}]}
{"channel":"book","type":"update","data":[{"symbol":"LINK/USDT","bids":[],"asks":[{"price":18.60311,"qty":243.48672997}],"checksum":2232362630,"timestamp":"2024-06-01T17:52:05.498325Z"}]}
{"channel":"book","type":"update","data":[{"symbol":"LINK/USDT","bids":[{"price":18.58723,"qty":243.48672997}],"asks":[],"checksum":589765216,"timestamp":"2024-06-01T17:52:05.498381Z"}]}
{"channel":"book","type":"update","data":[{"symbol":"LINK/USDT","bids":[],"asks":[{"price":18.59728,"qty":65.00000000}],"checksum":1414408417,"timestamp":"2024-06-01T17:52:05.498947Z"}]}
{"channel":"book","type":"update","data":[{"symbol":"LINK/USDT","bids":[],"asks":[{"price":18.59729,"qty":0.00000000},{"price":18.60812,"qty":48.75805200}],"checksum":2345915218,"timestamp":"2024-06-01T17:52:05.502198Z"}]}
{"channel":"book","type":"update","data":[{"symbol":"LINK/USDT","bids":[],"asks":[{"price":18.59657,"qty":9.40000000}],"checksum":2228123751,"timestamp":"2024-06-01T17:52:05.502427Z"}]}
{"channel":"book","type":"update","data":[{"symbol":"LINK/USDT","bids":[{"price":18.58345,"qty":0.00000000},{"price":18.57615,"qty":47.16000000}],"asks":[],"checksum":2760831161,"timestamp":"2024-06-01T17:52:05.527163Z"}]}
{"channel":"book","type":"update","data":[{"symbol":"LINK/USDT","bids":[],"asks":[{"price":18.59728,"qty":0.00000000},{"price":18.60812,"qty":48.75805200}],"checksum":2488937106,"timestamp":"2024-06-01T17:52:05.531999Z"}]}
{"channel":"book","type":"update","data":[{"symbol":"LINK/USDT","bids":[{"price":18.58249,"qty":40.32294998}],"asks":[],"checksum":3128351292,"timestamp":"2024-06-01T17:52:05.567541Z"}]}
{"channel":"book","type":"update","data":[{"symbol":"LINK/USDT","bids":[{"price":18.58168,"qty":0.00000000},{"price":18.57615,"qty":47.16000000}],"asks":[],"checksum":2854327193,"timestamp":"2024-06-01T17:52:05.570570Z"}]}
{"channel":"book","type":"update","data":[{"symbol":"LINK/USDT","bids":[{"price":18.57906,"qty":134.66959087}],"asks":[],"checksum":3892009948,"timestamp":"2024-06-01T17:52:05.574723Z"}]}
{"channel":"book","type":"update","data":[{"symbol":"LINK/USDT","bids":[{"price":18.58919,"qty":0.00000000},{"price":18.57615,"qty":47.16000000}],"asks":[],"checksum":141935398,"timestamp":"2024-06-01T17:52:05.698848Z"}]}
{"channel":"book","type":"update","data":[{"symbol":"LINK/USDT","bids":[{"price":18.58723,"qty":0.00000000},{"price":18.57396,"qty":45.37000000}],"asks":[],"checksum":1038714279,"timestamp":"2024-06-01T17:52:05.702960Z"}]}
{"channel":"book","type":"update","data":[{"symbol":"LINK/USDT","bids":[{"price":18.58208,"qty":0.00000000},{"price":18.57011,"qty":68.59000000},{"price":18.58291,"qty":8.39041718}],"asks":[],"checksum":912234390,"timestamp":"2024-06-01T17:52:05.711086Z"}]}
{"channel":"book","type":"update","data":[{"symbol":"LINK/USDT","bids":[{"price":18.58785,"qty":80.65037823}],"asks":[],"checksum":3840258075,"timestamp":"2024-06-01T17:52:05.739099Z"}]}
{"channel":"book","type":"update","data":[{"symbol":"LINK/USDT","bids":[{"price":18.58524,"qty":53.84994622}],"asks":[],"checksum":738755695,"timestamp":"2024-06-01T17:52:05.981407Z"}]}
{"channel":"book","type":"update","data":[{"symbol":"LINK/USDT","bids":[{"price":18.58524,"qty":0.00000000},{"price":18.57615,"qty":47.16000000}],"asks":[],"checksum":3840258075,"timestamp":"2024-06-01T17:52:06.021752Z"}]}
{"channel":"book","type":"update","data":[{"symbol":"LINK/USDT","bids":[],"asks":[{"price":18.60811,"qty":10.83722785},{"price":18.60419,"qty":68.59000000}],"checksum":2052763265,"timestamp":"2024-06-01T17:52:06.169110Z"}]}
{"channel":"book","type":"update","data":[{"symbol":"LINK/USDT","bids":[{"price":18.58249,"qty":0.00000000},{"price":18.57396,"qty":45.37000000}],"asks":[],"checksum":3330635849,"timestamp":"2024-06-01T17:52:06.218045Z"}]}
{"channel":"book","type":"update","data":[{"symbol":"LINK/USDT","bids":[{"price":18.58122,"qty":40.34060215}],"asks":[],"checksum":2566633489,"timestamp":"2024-06-01T17:52:06.258173Z"}]}
{"channel":"book","type":"update","data":[{"symbol":"LINK/USDT","bids":[{"price":18.58785,"qty":0.00000000},{"price":18.57396,"qty":45.37000000}],"asks":[],"checksum":569523528,"timestamp":"2024-06-01T17:52:06.303473Z"}]}
{"channel":"book","type":"update","data":[{"symbol":"LINK/USDT","bids":[{"price":18.58294,"qty":9.00000000}],"asks":[],"checksum":2370707791,"timestamp":"2024-06-01T17:52:06.308362Z"}]}
{"channel":"book","type":"update","data":[{"symbol":"LINK/USDT","bids":[{"price":18.58279,"qty":0.00000000},{"price":18.57396,"qty":45.37000000}],"asks":[],"checksum":2740773090,"timestamp":"2024-06-01T17:52:06.311014Z"}]}
{"channel":"book","type":"update","data":[{"symbol":"LINK/USDT","bids":[{"price":18.58365,"qty":9.40000000}],"asks":[],"checksum":3540617797,"timestamp":"2024-06-01T17:52:06.311160Z"}]}
{"channel":"book","type":"update","data":[{"symbol":"LINK/USDT","bids":[],"asks":[{"price":18.60811,"qty":35.13605367}],"checksum":4002714166,"timestamp":"2024-06-01T17:52:06.333957Z"}]}
{"channel":"book","type":"update","data":[{"symbol":"LINK/USDT","bids":[],"asks":[{"price":18.60811,"qty":24.29882582}],"checksum":353326123,"timestamp":"2024-06-01T17:52:06.334069Z"}]}
{"channel":"book","type":"update","data":[{"symbol":"LINK/USDT","bids":[{"price":18.58696,"qty":80.68120389}],"asks":[],"checksum":1213256224,"timestamp":"2024-06-01T17:52:06.344399Z"}]}
{"channel":"book","type":"update","data":[{"symbol":"LINK/USDT","bids":[{"price":18.58294,"qty":0.00000000},{"price":18.57615,"qty":47.16000000}],"asks":[],"checksum":3809849418,"timestamp":"2024-06-01T17:52:06.350015Z"}]}
{"channel":"book","type":"update","data":[{"symbol":"LINK/USDT","bids":[],"asks":[{"price":18.58964,"qty":21.53488365}],"checksum":3032039745,"timestamp":"2024-06-01T17:52:06.495809Z"}]}
{"channel":"book","type":"update","data":[{"symbol":"LINK/USDT","bids":[{"price":18.58561,"qty":53.84886490}],"asks":[],"checksum":3560526999,"timestamp":"2024-06-01T17:52:06.495876Z"}]}
{"channel":"book","type":"update","data":[{"symbol":"LINK/USDT","bids":[{"price":18.58697,"qty":243.48672997}],"asks":[],"checksum":1272847855,"timestamp":"2024-06-01T17:52:06.499945Z"}]}
{"channel":"book","type":"update","data":[{"symbol":"LINK/USDT","bids":[{"price":18.58561,"qty":0.00000000},{"price":18.57640,"qty":33.73844400}],"asks":[],"checksum":3021683153,"timestamp":"2024-06-01T17:52:06.554604Z"}]}
{"channel":"book","type":"update","data":[{"symbol":"LINK/USDT","bids":[],"asks":[{"price":18.58964,"qty":0.00000000},{"price":18.60811,"qty":24.29882582}],"checksum":597576872,"timestamp":"2024-06-01T17:52:06.554684Z"}]}
{"channel":"book","type":"update","data":[{"symbol":"LINK/USDT","bids":[{"price":18.58000,"qty":0.00000000},{"price":18.57615,"qty":47.16000000}],"asks":[],"checksum":4184692011,"timestamp":"2024-06-01T17:52:06.554836Z"}]}
{"channel":"book","type":"update","data":[{"symbol":"LINK/USDT","bids":[{"price":18.57664,"qty":0.00000000},{"price":18.57396,"qty":45.37000000}],"asks":[],"checksum":1135369896,"timestamp":"2024-06-01T17:52:06.558532Z"}]}
{"channel":"book","type":"update","data":[{"symbol":"LINK/USDT","bids":[{"price":18.57900,"qty":194.28655460}],"asks":[],"checksum":1273346225,"timestamp":"2024-06-01T17:52:06.559875Z"}]}
{"channel":"book","type":"update","data":[{"symbol":"LINK/USDT","bids":[{"price":18.58697,"qty":0.00000000},{"price":18.57396,"qty":45.37000000}],"asks":[],"checksum":201731288,"timestamp":"2024-06-01T17:52:06.560980Z"}]}
{"channel":"book","type":"update","data":[{"symbol":"LINK/USDT","bids":[],"asks":[{"price":18.59588,"qty":53.81914573}],"checksum":4158413234,"timestamp":"2024-06-01T17:52:06.562521Z"}]}
{"channel":"book","type":"update","data":[{"symbol":"LINK/USDT","bids":[],"asks":[{"price":18.59657,"qty":0.00000000},{"price":18.60811,"qty":24.29882582}],"checksum":3186810189,"timestamp":"2024-06-01T17:52:06.565132Z"}]}
{"channel":"book","type":"update","data":[{"symbol":"LINK/USDT","bids":[],"asks":[{"price":18.59517,"qty":9.40000000}],"checksum":523147931,"timestamp":"2024-06-01T17:52:06.565298Z"}]}
{"channel":"book","type":"update","data":[{"symbol":"LINK/USDT","bids":[],"asks":[{"price":18.59588,"qty":0.00000000},{"price":18.60811,"qty":10.83722785}],"checksum":3873316099,"timestamp":"2024-06-01T17:52:06.568102Z"}]}
{"channel":"book","type":"update","data":[{"symbol":"LINK/USDT","bids":[],"asks":[{"price":18.60419,"qty":0.00000000},{"price":18.60812,"qty":48.75805200},{"price":18.60310,"qty":68.59000000}],"checksum":3796642024,"timestamp":"2024-06-01T17:52:06.570387Z"}]}
{"channel":"book","type":"update","data":[{"symbol":"LINK/USDT","bids":[],"asks":[{"price":18.59729,"qty":9.40000000}],"checksum":694272309,"timestamp":"2024-06-01T17:52:06.570779Z"}]}
{"channel":"book","type":"update","data":[{"symbol":"LINK/USDT","bids":[],"asks":[{"price":18.59517,"qty":0.00000000},{"price":18.60811,"qty":10.83722785}],"checksum":2049369630,"timestamp":"2024-06-01T17:52:06.570802Z"}]}
{"channel":"book","type":"update","data":[{"symbol":"LINK/USDT","bids":[],"asks":[{"price":18.59393,"qty":4.84597749}],"checksum":553071818,"timestamp":"2024-06-01T17:52:06.580930Z"}]}
{"channel":"book","type":"update","data":[{"symbol":"LINK/USDT","bids":[],"asks":[{"price":18.59390,"qty":9.00000000}],"checksum":2071263526,"timestamp":"2024-06-01T17:52:06.587528Z"}]}
{"channel":"book","type":"update","data":[{"symbol":"LINK/USDT","bids":[],"asks":[{"price":18.59729,"qty":0.00000000},{"price":18.60420,"qty":107.59016987}],"checksum":857029856,"timestamp":"2024-06-01T17:52:06.589087Z"}]}
{"channel":"book","type":"update","data":[{"symbol":"LINK/USDT","bids":[],"asks":[{"price":18.59383,"qty":9.40000000}],"checksum":2628385747,"timestamp":"2024-06-01T17:52:06.589203Z"}]}
{"channel":"book","type":"update","data":[{"symbol":"LINK/USDT","bids":[{"price":18.57900,"qty":0.00000000},{"price":18.57010,"qty":48.75805200}],"asks":[],"checksum":2740449353,"timestamp":"2024-06-01T17:52:06.752810Z"}]}
{"channel":"book","type":"update","data":[{"symbol":"LINK/USDT","bids":[{"price":18.57900,"qty":126.60155460}],"asks":[],"checksum":2610532401,"timestamp":"2024-06-01T17:52:06.757992Z"}]}
{"channel":"book","type":"update","data":[{"symbol":"LINK/USDT","bids":[{"price":18.58122,"qty":0.00000000},{"price":18.57010,"qty":48.75805200}],"asks":[],"checksum":787612350,"timestamp":"2024-06-01T17:52:06.817683Z"}]}
{"channel":"book","type":"update","data":[{"symbol":"LINK/USDT","bids":[],"asks":[{"price":18.59390,"qty":0.00000000},{"price":18.60420,"qty":107.59016987}],"checksum":3907757684,"timestamp":"2024-06-01T17:52:06.822462Z"}]}
{"channel":"book","type":"update","data":[{"symbol":"LINK/USDT","bids":[],"asks":[{"price":18.59380,"qty":9.00000000}],"checksum":3058532154,"timestamp":"2024-06-01T17:52:06.822655Z"}]}
{"channel":"book","type":"update","data":[{"symbol":"LINK/USDT","bids":[{"price":18.57906,"qty":0.00000000},{"price":18.56767,"qty":147.27745500}],"asks":[],"checksum":2343991113,"timestamp":"2024-06-01T17:52:06.883333Z"}]}
{"channel":"book","type":"update","data":[{"symbol":"LINK/USDT","bids":[{"price":18.57661,"qty":134.68740171}],"asks":[],"checksum":3672130952,"timestamp":"2024-06-01T17:52:06.886666Z"}]}
{"channel":"book","type":"update","data":[{"symbol":"LINK/USDT","bids":[],"asks":[{"price":18.59412,"qty":0.00000000},{"price":18.60420,"qty":107.59016987}],"checksum":236047702,"timestamp":"2024-06-01T17:52:06.888170Z"}]}
{"channel":"book","type":"update","data":[{"symbol":"LINK/USDT","bids":[{"price":18.58696,"qty":0.00000000},{"price":18.56767,"qty":147.27745500}],"asks":[],"checksum":829804440,"timestamp":"2024-06-01T17:52:06.988905Z"}]}
{"channel":"book","type":"update","data":[{"symbol":"LINK/USDT","bids":[{"price":18.56808,"qty":68.59000000}],"asks":[],"checksum":1353676048,"timestamp":"2024-06-01T17:52:06.992305Z"}]}
{"channel":"book","type":"update","data":[{"symbol":"LINK/USDT","bids":[{"price":18.58368,"qty":9.00000000}],"asks":[],"checksum":2104071635,"timestamp":"2024-06-01T17:52:06.994108Z"}]}
{"channel":"book","type":"update","data":[{"symbol":"LINK/USDT","bids":[{"price":18.58598,"qty":80.70367045}],"asks":[],"checksum":1202469385,"timestamp":"2024-06-01T17:52:07.029303Z"}]}
{"channel":"book","type":"update","data":[{"symbol":"LINK/USDT","bids":[{"price":18.58368,"qty":0.00000000},{"price":18.57010,"qty":48.75805200}],"asks":[],"checksum":2998304040,"timestamp":"2024-06-01T17:52:07.034349Z"}]}
{"channel":"book","type":"update","data":[{"symbol":"LINK/USDT","bids":[],"asks":[{"price":18.58674,"qty":21.53824801}],"checksum":444748480,"timestamp":"2024-06-01T17:52:07.042040Z"}]}
{"channel":"book","type":"update","data":[{"symbol":"LINK/USDT","bids":[{"price":18.58287,"qty":53.85680709}],"asks":[],"checksum":3831958707,"timestamp":"2024-06-01T17:52:07.042114Z"}]}
{"channel":"book","type":"update","data":[{"symbol":"LINK/USDT","bids":[{"price":18.58034,"qty":40.35128723}],"asks":[],"checksum":257052585,"timestamp":"2024-06-01T17:52:07.497346Z"}]}
{"channel":"book","type":"update","data":[{"symbol":"LINK/USDT","bids":[{"price":18.58599,"qty":243.48672997}],"asks":[],"checksum":1390870844,"timestamp":"2024-06-01T17:52:07.501570Z"}]}
{"channel":"book","type":"update","data":[{"symbol":"LINK/USDT","bids":[{"price":18.58598,"qty":0.00000000},{"price":18.57615,"qty":47.16000000}],"asks":[],"checksum":1190144404,"timestamp":"2024-06-01T17:52:07.668115Z"}]}
{"channel":"book","type":"update","data":[{"symbol":"LINK/USDT","bids":[{"price":18.58599,"qty":0.00000000},{"price":18.57396,"qty":45.37000000}],"asks":[],"checksum":4049189270,"timestamp":"2024-06-01T17:52:07.672355Z"}]}
{"channel":"book","type":"update","data":[{"symbol":"LINK/USDT","bids":[{"price":18.58608,"qty":80.70543032}],"asks":[],"checksum":2335376779,"timestamp":"2024-06-01T17:52:07.708477Z"}]}
{"channel":"book","type":"update","data":[{"symbol":"LINK/USDT","bids":[{"price":18.58423,"qty":243.48672997}],"asks":[],"checksum":2086677793,"timestamp":"2024-06-01T17:52:07.712802Z"}]}
{"channel":"book","type":"update","data":[{"symbol":"LINK/USDT","bids":[],"asks":[{"price":18.58674,"qty":0.00000000},{"price":18.60420,"qty":107.59016987}],"checksum":3524883268,"timestamp":"2024-06-01T17:52:07.739683Z"}]}
{"channel":"book","type":"update","data":[{"symbol":"LINK/USDT","bids":[],"asks":[{"price":18.58721,"qty":21.53770784}],"checksum":1477186679,"timestamp":"2024-06-01T17:52:07.743966Z"}]}
{"channel":"book","type":"update","data":[{"symbol":"LINK/USDT","bids":[],"asks":[{"price":18.59377,"qty":53.82527359}],"checksum":947494789,"timestamp":"2024-06-01T17:52:07.744201Z"}]}
{"channel":"book","type":"update","data":[{"symbol":"LINK/USDT","bids":[],"asks":[{"price":18.59383,"qty":0.00000000},{"price":18.60311,"qty":243.48672997}],"checksum":3774176333,"timestamp":"2024-06-01T17:52:07.746896Z"}]}
{"channel":"book","type":"update","data":[{"symbol":"LINK/USDT","bids":[],"asks":[{"price":18.59306,"qty":9.40000000}],"checksum":1391031320,"timestamp":"2024-06-01T17:52:07.747106Z"}]}
{"channel":"book","type":"update","data":[{"symbol":"LINK/USDT","bids":[{"price":18.58287,"qty":0.00000000},{"price":18.57615,"qty":47.16000000}],"asks":[],"checksum":3432903886,"timestamp":"2024-06-01T17:52:07.758275Z"}]}
{"channel":"book","type":"update","data":[{"symbol":"LINK/USDT","bids":[],"asks":[{"price":18.58721,"qty":0.00000000},{"price":18.60311,"qty":243.48672997}],"checksum":1271003956,"timestamp":"2024-06-01T17:52:07.758360Z"}]}
{"channel":"book","type":"update","data":[{"symbol":"LINK/USDT","bids":[{"price":18.58375,"qty":53.85425159}],"asks":[],"checksum":314690044,"timestamp":"2024-06-01T17:52:07.762924Z"}]}
{"channel":"book","type":"update","data":[{"symbol":"LINK/USDT","bids":[],"asks":[{"price":18.59303,"qty":9.00000000}],"checksum":23003026,"timestamp":"2024-06-01T17:52:08.084322Z"}]}
{"channel":"book","type":"update","data":[{"symbol":"LINK/USDT","bids":[{"price":18.58034,"qty":0.00000000},{"price":18.57615,"qty":47.16000000}],"asks":[],"checksum":3879286220,"timestamp":"2024-06-01T17:52:08.136327Z"}]}
{"channel":"book","type":"update","data":[{"symbol":"LINK/USDT","bids":[{"price":18.58030,"qty":40.35425503}],"asks":[],"checksum":2673143623,"timestamp":"2024-06-01T17:52:08.176697Z"}]}
{"channel":"book","type":"update","data":[{"symbol":"LINK/USDT","bids":[],"asks":[{"price":18.59297,"qty":21.53103547}],"checksum":733647821,"timestamp":"2024-06-01T17:52:08.305570Z"}]}
{"channel":"book","type":"update","data":[{"symbol":"LINK/USDT","bids":[],"asks":[{"price":18.59297,"qty":0.00000000},{"price":18.60310,"qty":68.59000000}],"checksum":2673143623,"timestamp":"2024-06-01T17:52:08.309679Z"}]}
{"channel":"book","type":"update","data":[{"symbol":"LINK/USDT","bids":[{"price":18.58608,"qty":0.00000000},{"price":18.57615,"qty":47.16000000}],"asks":[],"checksum":526067535,"timestamp":"2024-06-01T17:52:08.348068Z"}]}
{"channel":"book","type":"update","data":[{"symbol":"LINK/USDT","bids":[{"price":18.58365,"qty":0.00000000},{"price":18.57396,"qty":45.37000000}],"asks":[],"checksum":1033611132,"timestamp":"2024-06-01T17:52:08.350858Z"}]}
{"channel":"book","type":"update","data":[{"symbol":"LINK/USDT","bids":[{"price":18.58484,"qty":9.40000000}],"asks":[],"checksum":1848401814,"timestamp":"2024-06-01T17:52:08.350875Z"}]}
{"channel":"book","type":"update","data":[{"symbol":"LINK/USDT","bids":[{"price":18.58423,"qty":0.00000000},{"price":18.57396,"qty":45.37000000}],"asks":[],"checksum":4015200392,"timestamp":"2024-06-01T17:52:08.352509Z"}]}
{"channel":"book","type":"update","data":[{"symbol":"LINK/USDT","bids":[],"asks":[{"price":18.59380,"qty":0.00000000},{"price":18.60311,"qty":243.48672997}],"checksum":1352005216,"timestamp":"2024-06-01T17:52:08.353032Z"}]}
{"channel":"book","type":"update","data":[{"symbol":"LINK/USDT","bids":[{"price":18.58426,"qty":9.00000000}],"asks":[],"checksum":3420163876,"timestamp":"2024-06-01T17:52:08.353091Z"}]}
{"channel":"book","type":"update","data":[{"symbol":"LINK/USDT","bids":[{"price":18.58628,"qty":80.70733634}],"asks":[],"checksum":2547357674,"timestamp":"2024-06-01T17:52:08.388251Z"}]}
{"channel":"book","type":"update","data":[{"symbol":"LINK/USDT","bids":[{"price":18.58426,"qty":0.00000000},{"price":18.57615,"qty":47.16000000}],"asks":[],"checksum":2483894309,"timestamp":"2024-06-01T17:52:08.392850Z"}]}
{"channel":"book","type":"update","data":[{"symbol":"LINK/USDT","bids":[{"price":18.58375,"qty":0.00000000},{"price":18.57396,"qty":45.37000000}],"asks":[],"checksum":2741442672,"timestamp":"2024-06-01T17:52:08.450594Z"}]}
{"channel":"book","type":"update","data":[{"symbol":"LINK/USDT","bids":[{"price":18.58440,"qty":53.85236053}],"asks":[],"checksum":4019379390,"timestamp":"2024-06-01T17:52:08.454190Z"}]}
{"channel":"book","type":"update","data":[{"symbol":"LINK/USDT","bids":[{"price":18.58423,"qty":243.48672997}],"asks":[],"checksum":2961987581,"timestamp":"2024-06-01T17:52:08.455569Z"}]}
{"channel":"book","type":"update","data":[{"symbol":"LINK/USDT","bids":[],"asks":[{"price":18.59306,"qty":0.00000000},{"price":18.60420,"qty":107.59016987}],"checksum":3382579466,"timestamp":"2024-06-01T17:52:08.482009Z"}]}
{"channel":"book","type":"update","data":[{"symbol":"LINK/USDT","bids":[{"price":18.58030,"qty":0.00000000},{"price":18.57615,"qty":47.16000000}],"asks":[],"checksum":2985544577,"timestamp":"2024-06-01T17:52:08.736759Z"}]}
{"channel":"book","type":"update","data":[{"symbol":"LINK/USDT","bids":[],"asks":[{"price":18.60103,"qty":0.00000000},{"price":18.60811,"qty":24.29946584}],"checksum":2693876107,"timestamp":"2024-06-01T17:52:08.764400Z"}]}
{"channel":"book","type":"update","data":[{"symbol":"LINK/USDT","bids":[],"asks":[{"price":18.59717,"qty":50.49000000}],"checksum":849722143,"timestamp":"2024-06-01T17:52:08.767212Z"}]}
{"channel":"book","type":"update","data":[{"symbol":"LINK/USDT","bids":[],"asks":[{"price":18.59303,"qty":0.00000000},{"price":18.60811,"qty":24.29946584}],"checksum":2844741141,"timestamp":"2024-06-01T17:52:08.772144Z"}]}
{"channel":"book","type":"update","data":[{"symbol":"LINK/USDT","bids":[],"asks":[{"price":18.59374,"qty":9.00000000}],"checksum":3339837313,"timestamp":"2024-06-01T17:52:08.772362Z"}]}
{"channel":"book","type":"update","data":[{"symbol":"LINK/USDT","bids":[{"price":18.58108,"qty":40.35038687}],"asks":[],"checksum":3221195705,"timestamp":"2024-06-01T17:52:08.776970Z"}]}
{"channel":"book","type":"update","data":[{"symbol":"LINK/USDT","bids":[{"price":18.58440,"qty":0.00000000},{"price":18.57615,"qty":47.16000000}],"asks":[],"checksum":672463627,"timestamp":"2024-06-01T17:52:08.799014Z"}]}
{"channel":"book","type":"update","data":[{"symbol":"LINK/USDT","bids":[{"price":18.58628,"qty":0.00000000},{"price":18.57396,"qty":45.37000000}],"asks":[],"checksum":2360741287,"timestamp":"2024-06-01T17:52:08.947714Z"}]}
{"channel":"book","type":"update","data":[{"symbol":"LINK/USDT","bids":[{"price":18.58423,"qty":0.00000000},{"price":18.57010,"qty":48.75805200}],"asks":[],"checksum":893619758,"timestamp":"2024-06-01T17:52:08.952182Z"}]}
{"channel":"book","type":"update","data":[{"symbol":"LINK/USDT","bids":[{"price":18.58487,"qty":9.00000000}],"asks":[],"checksum":483931772,"timestamp":"2024-06-01T17:52:08.952521Z"}]}
{"channel":"book","type":"update","data":[{"symbol":"LINK/USDT","bids":[{"price":18.58682,"qty":80.70083838}],"asks":[],"checksum":891156025,"timestamp":"2024-06-01T17:52:08.987790Z"}]}
{"channel":"book","type":"update","data":[{"symbol":"LINK/USDT","bids":[{"price":18.58487,"qty":0.00000000},{"price":18.57396,"qty":45.37000000}],"asks":[],"checksum":3982945512,"timestamp":"2024-06-01T17:52:08.992194Z"}]}
{"channel":"book","type":"update","data":[{"symbol":"LINK/USDT","bids":[{"price":18.58395,"qty":53.85366381}],"asks":[],"checksum":731229847,"timestamp":"2024-06-01T17:52:09.055296Z"}]}
{"channel":"book","type":"update","data":[{"symbol":"LINK/USDT","bids":[{"price":18.58395,"qty":0.00000000},{"price":18.57396,"qty":45.37000000}],"asks":[],"checksum":3982945512,"timestamp":"2024-06-01T17:52:09.311055Z"}]}
{"channel":"book","type":"update","data":[{"symbol":"LINK/USDT","bids":[{"price":18.58108,"qty":0.00000000},{"price":18.57010,"qty":48.75805200}],"asks":[],"checksum":1032519128,"timestamp":"2024-06-01T17:52:09.417820Z"}]}
{"channel":"book","type":"update","data":[{"symbol":"LINK/USDT","bids":[{"price":18.58423,"qty":243.48672997}],"asks":[],"checksum":3534004218,"timestamp":"2024-06-01T17:52:09.423708Z"}]}
{"channel":"book","type":"update","data":[{"symbol":"LINK/USDT","bids":[{"price":18.58110,"qty":40.34860791}],"asks":[],"checksum":3139199828,"timestamp":"2024-06-01T17:52:09.458160Z"}]}
{"channel":"book","type":"update","data":[{"symbol":"LINK/USDT","bids":[{"price":18.58682,"qty":0.00000000},{"price":18.57396,"qty":45.37000000}],"asks":[],"checksum":2871718772,"timestamp":"2024-06-01T17:52:09.698969Z"}]}
{"channel":"book","type":"update","data":[{"symbol":"LINK/USDT","bids":[{"price":18.58423,"qty":0.00000000},{"price":18.57010,"qty":48.75805200}],"asks":[],"checksum":3538050693,"timestamp":"2024-06-01T17:52:09.703793Z"}]}
{"channel":"book","type":"update","data":[{"symbol":"LINK/USDT","bids":[{"price":18.58461,"qty":53.85175417}],"asks":[],"checksum":1408617710,"timestamp":"2024-06-01T17:52:09.703824Z"}]}
{"channel":"book","type":"update","data":[{"symbol":"LINK/USDT","bids":[{"price":18.58487,"qty":9.00000000}],"asks":[],"checksum":459217142,"timestamp":"2024-06-01T17:52:09.704526Z"}]}
{"channel":"book","type":"update","data":[{"symbol":"LINK/USDT","bids":[],"asks":[{"price":18.59333,"qty":9.40000000}],"checksum":855865016,"timestamp":"2024-06-01T17:52:09.706526Z"}]}
{"channel":"book","type":"update","data":[{"symbol":"LINK/USDT","bids":[{"price":18.58672,"qty":80.69849922}],"asks":[],"checksum":821336490,"timestamp":"2024-06-01T17:52:09.739324Z"}]}
{"channel":"book","type":"update","data":[{"symbol":"LINK/USDT","bids":[{"price":18.58487,"qty":0.00000000},{"price":18.57615,"qty":47.16000000}],"asks":[],"checksum":2397945427,"timestamp":"2024-06-01T17:52:09.744281Z"}]}
{"channel":"book","type":"update","data":[{"symbol":"LINK/USDT","bids":[],"asks":[{"price":18.59330,"qty":9.00000000}],"checksum":3868588667,"timestamp":"2024-06-01T17:52:09.744524Z"}]}
{"channel":"book","type":"update","data":[{"symbol":"LINK/USDT","bids":[],"asks":[{"price":18.59374,"qty":0.00000000},{"price":18.60311,"qty":243.48672997}],"checksum":1715606352,"timestamp":"2024-06-01T17:52:10.083487Z"}]}
{"channel":"book","type":"update","data":[{"symbol":"LINK/USDT","bids":[{"price":18.58110,"qty":0.00000000},{"price":18.57396,"qty":45.37000000}],"asks":[],"checksum":268103678,"timestamp":"2024-06-01T17:52:10.097667Z"}]}
{"channel":"book","type":"update","data":[{"symbol":"LINK/USDT","bids":[{"price":18.58099,"qty":40.35402614}],"asks":[],"checksum":3633447186,"timestamp":"2024-06-01T17:52:10.138308Z"}]}
{"channel":"book","type":"update","data":[{"symbol":"LINK/USDT","bids":[{"price":18.58461,"qty":0.00000000},{"price":18.57396,"qty":45.37000000}],"asks":[],"checksum":2374289304,"timestamp":"2024-06-01T17:52:10.295214Z"}]}
{"channel":"book","type":"update","data":[{"symbol":"LINK/USDT","bids":[{"price":18.58407,"qty":53.85332229}],"asks":[],"checksum":2900658999,"timestamp":"2024-06-01T17:52:10.299047Z"}]}
{"channel":"book","type":"update","data":[{"symbol":"LINK/USDT","bids":[{"price":18.58672,"qty":0.00000000},{"price":18.57396,"qty":45.37000000}],"asks":[],"checksum":1156443691,"timestamp":"2024-06-01T17:52:10.377334Z"}]}
{"channel":"book","type":"update","data":[{"symbol":"LINK/USDT","bids":[{"price":18.58648,"qty":80.71083955}],"asks":[],"checksum":4196365618,"timestamp":"2024-06-01T17:52:10.417708Z"}]}
{"channel":"book","type":"update","data":[{"symbol":"LINK/USDT","bids":[{"price":18.58423,"qty":243.48672997}],"asks":[],"checksum":1275727366,"timestamp":"2024-06-01T17:52:10.421915Z"}]}
{"channel":"book","type":"update","data":[{"symbol":"LINK/USDT","bids":[],"asks":[{"price":18.60011,"qty":243.48672997}],"checksum":221914368,"timestamp":"2024-06-01T17:52:10.422034Z"}]}
{"channel":"book","type":"update","data":[{"symbol":"LINK/USDT","bids":[],"asks":[{"price":18.60310,"qty":0.00000000},{"price":18.60420,"qty":107.59016987},{"price":18.60419,"qty":68.59000000}],"checksum":3041045622,"timestamp":"2024-06-01T17:52:10.565918Z"}]}
{"channel":"book","type":"update","data":[{"symbol":"LINK/USDT","bids":[{"price":18.58407,"qty":0.00000000},{"price":18.57615,"qty":47.16000000}],"asks":[],"checksum":1155739206,"timestamp":"2024-06-01T17:52:10.566389Z"}]}
{"channel":"book","type":"update","data":[{"symbol":"LINK/USDT","bids":[{"price":18.58099,"qty":0.00000000},{"price":18.57396,"qty":45.37000000}],"asks":[],"checksum":2475409578,"timestamp":"2024-06-01T17:52:10.696249Z"}]}
{"channel":"book","type":"update","data":[{"symbol":"LINK/USDT","bids":[{"price":18.57983,"qty":40.36153943}],"asks":[],"checksum":1268875582,"timestamp":"2024-06-01T17:52:10.736435Z"}]}
{"channel":"book","type":"update","data":[{"symbol":"LINK/USDT","bids":[{"price":18.58407,"qty":53.85333135}],"asks":[],"checksum":2190468063,"timestamp":"2024-06-01T17:52:10.928682Z"}]}
{"channel":"book","type":"update","data":[{"symbol":"LINK/USDT","bids":[{"price":18.58648,"qty":0.00000000},{"price":18.57615,"qty":47.16000000}],"asks":[],"checksum":111811092,"timestamp":"2024-06-01T17:52:10.976552Z"}]}
{"channel":"book","type":"update","data":[{"symbol":"LINK/USDT","bids":[{"price":18.58423,"qty":0.00000000},{"price":18.57396,"qty":45.37000000}],"asks":[],"checksum":3548727899,"timestamp":"2024-06-01T17:52:10.980733Z"}]}
{"channel":"book","type":"update","data":[{"symbol":"LINK/USDT","bids":[{"price":18.58407,"qty":0.00000000},{"price":18.57010,"qty":48.75805200}],"asks":[],"checksum":4239365551,"timestamp":"2024-06-01T17:52:11.307552Z"}]}
{"channel":"book","type":"update","data":[{"symbol":"LINK/USDT","bids":[{"price":18.57983,"qty":0.00000000},{"price":18.56768,"qty":68.59000000}],"asks":[],"checksum":1443546338,"timestamp":"2024-06-01T17:52:11.375050Z"}]}
{"channel":"book","type":"update","data":[{"symbol":"LINK/USDT","bids":[{"price":18.58484,"qty":0.00000000},{"price":18.56767,"qty":147.27745500}],"asks":[],"checksum":107208560,"timestamp":"2024-06-01T17:52:11.378288Z"}]}
{"channel":"book","type":"update","data":[{"symbol":"LINK/USDT","bids":[{"price":18.57971,"qty":9.40000000}],"asks":[],"checksum":1650211894,"timestamp":"2024-06-01T17:52:11.378542Z"}]}
{"channel":"book","type":"update","data":[{"symbol":"LINK/USDT","bids":[{"price":18.57966,"qty":40.36251250}],"asks":[],"checksum":1711194590,"timestamp":"2024-06-01T17:52:11.415479Z"}]}
{"channel":"book","type":"update","data":[{"symbol":"LINK/USDT","bids":[{"price":18.57967,"qty":243.48672997}],"asks":[],"checksum":348135130,"timestamp":"2024-06-01T17:52:11.419987Z"}]}
{"channel":"book","type":"update","data":[{"symbol":"LINK/USDT","bids":[{"price":18.58294,"qty":9.00000000}],"asks":[],"checksum":495588806,"timestamp":"2024-06-01T17:52:11.420248Z"}]}
{"channel":"book","type":"update","data":[{"symbol":"LINK/USDT","bids":[{"price":18.57900,"qty":0.00000000},{"price":18.57396,"qty":45.37000000}],"asks":[],"checksum":1624455757,"timestamp":"2024-06-01T17:52:11.421717Z"}]}
{"channel":"book","type":"update","data":[{"symbol":"LINK/USDT","bids":[{"price":18.57971,"qty":0.00000000},{"price":18.57010,"qty":48.75805200}],"asks":[],"checksum":1459952307,"timestamp":"2024-06-01T17:52:11.423392Z"}]}
{"channel":"book","type":"update","data":[{"symbol":"LINK/USDT","bids":[{"price":18.58295,"qty":9.40000000}],"asks":[],"checksum":934206957,"timestamp":"2024-06-01T17:52:11.423619Z"}]}
{"channel":"book","type":"update","data":[{"symbol":"LINK/USDT","bids":[{"price":18.57800,"qty":118.56398794}],"asks":[],"checksum":1912879195,"timestamp":"2024-06-01T17:52:11.426644Z"}]}
{"channel":"book","type":"update","data":[{"symbol":"LINK/USDT","bids":[{"price":18.58305,"qty":53.85628790}],"asks":[],"checksum":1874364161,"timestamp":"2024-06-01T17:52:11.432355Z"}]}
{"channel":"book","type":"update","data":[{"symbol":"LINK/USDT","bids":[{"price":18.58295,"qty":0.00000000},{"price":18.57615,"qty":47.16000000}],"asks":[],"checksum":4240136808,"timestamp":"2024-06-01T17:52:11.434962Z"}]}
{"channel":"book","type":"update","data":[{"symbol":"LINK/USDT","bids":[{"price":18.58308,"qty":9.40000000}],"asks":[],"checksum":2800176570,"timestamp":"2024-06-01T17:52:11.435131Z"}]}
{"channel":"book","type":"update","data":[{"symbol":"LINK/USDT","bids":[{"price":18.58305,"qty":0.00000000},{"price":18.57615,"qty":47.16000000}],"asks":[],"checksum":2009978609,"timestamp":"2024-06-01T17:52:11.436577Z"}]}
{"channel":"book","type":"update","data":[{"symbol":"LINK/USDT","bids":[{"price":18.58294,"qty":0.00000000},{"price":18.57396,"qty":45.37000000}],"asks":[],"checksum":503867789,"timestamp":"2024-06-01T17:52:11.585160Z"}]}
{"channel":"book","type":"update","data":[{"symbol":"LINK/USDT","bids":[{"price":18.58311,"qty":9.00000000}],"asks":[],"checksum":2315430467,"timestamp":"2024-06-01T17:52:11.585356Z"}]}
{"channel":"book","type":"update","data":[{"symbol":"LINK/USDT","bids":[{"price":18.58503,"qty":80.73008096}],"asks":[],"checksum":740135395,"timestamp":"2024-06-01T17:52:11.654951Z"}]}
{"channel":"book","type":"update","data":[{"symbol":"LINK/USDT","bids":[{"price":18.58311,"qty":0.00000000},{"price":18.57615,"qty":47.16000000}],"asks":[],"checksum":510830029,"timestamp":"2024-06-01T17:52:11.669873Z"}]}
{"channel":"book","type":"update","data":[{"symbol":"LINK/USDT","bids":[{"price":18.58396,"qty":53.85364829}],"asks":[],"checksum":1503342447,"timestamp":"2024-06-01T17:52:11.981410Z"}]}
{"channel":"book","type":"update","data":[{"symbol":"LINK/USDT","bids":[{"price":18.57966,"qty":0.00000000},{"price":18.57615,"qty":47.16000000}],"asks":[],"checksum":1754874357,"timestamp":"2024-06-01T17:52:12.052950Z"}]}
{"channel":"book","type":"update","data":[{"symbol":"LINK/USDT","bids":[{"price":18.58503,"qty":0.00000000},{"price":18.57396,"qty":45.37000000}],"asks":[],"checksum":2961656373,"timestamp":"2024-06-01T17:52:12.292080Z"}]}
{"channel":"book","type":"update","data":[{"symbol":"LINK/USDT","bids":[{"price":18.58501,"qty":80.74761882}],"asks":[],"checksum":290381342,"timestamp":"2024-06-01T17:52:12.332175Z"}]}
{"channel":"book","type":"update","data":[{"symbol":"LINK/USDT","bids":[{"price":18.58396,"qty":0.00000000},{"price":18.57396,"qty":45.37000000}],"asks":[],"checksum":934108982,"timestamp":"2024-06-01T17:52:12.441576Z"}]}
{"channel":"book","type":"update","data":[{"symbol":"LINK/USDT","bids":[{"price":18.58502,"qty":243.48672997}],"asks":[],"checksum":4118643505,"timestamp":"2024-06-01T17:52:12.445389Z"}]}
{"channel":"book","type":"update","data":[{"symbol":"LINK/USDT","bids":[{"price":18.57967,"qty":0.00000000},{"price":18.57396,"qty":45.37000000}],"asks":[],"checksum":3958432051,"timestamp":"2024-06-01T17:52:12.559416Z"}]}
{"channel":"book","type":"update","data":[{"symbol":"LINK/USDT","bids":[{"price":18.57932,"qty":40.37294126}],"asks":[],"checksum":3162704062,"timestamp":"2024-06-01T17:52:12.652112Z"}]}
{"channel":"book","type":"update","data":[{"symbol":"LINK/USDT","bids":[{"price":18.58501,"qty":0.00000000},{"price":18.57396,"qty":45.37000000}],"asks":[],"checksum":610452243,"timestamp":"2024-06-01T17:52:12.892060Z"}]}
{"channel":"book","type":"update","data":[{"symbol":"LINK/USDT","bids":[{"price":18.58502,"qty":0.00000000},{"price":18.57010,"qty":48.75805200}],"asks":[],"checksum":3061251217,"timestamp":"2024-06-01T17:52:12.896404Z"}]}
{"channel":"book","type":"update","data":[{"symbol":"LINK/USDT","bids":[{"price":18.58506,"qty":80.74588252}],"asks":[],"checksum":1386870555,"timestamp":"2024-06-01T17:52:12.932444Z"}]}
{"channel":"book","type":"update","data":[{"symbol":"LINK/USDT","bids":[{"price":18.57932,"qty":0.00000000},{"price":18.57010,"qty":48.75805200}],"asks":[],"checksum":2119937538,"timestamp":"2024-06-01T17:52:13.296724Z"}]}
{"channel":"book","type":"update","data":[{"symbol":"LINK/USDT","bids":[{"price":18.57929,"qty":40.37314517}],"asks":[],"checksum":1165337945,"timestamp":"2024-06-01T17:52:13.337562Z"}]}
{"channel":"book","type":"update","data":[{"symbol":"LINK/USDT","bids":[{"price":18.58507,"qty":243.48672997}],"asks":[],"checksum":1778444681,"timestamp":"2024-06-01T17:52:13.559218Z"}]}
{"channel":"book","type":"update","data":[{"symbol":"LINK/USDT","bids":[{"price":18.58506,"qty":0.00000000},{"price":18.57396,"qty":45.37000000}],"asks":[],"checksum":1724151709,"timestamp":"2024-06-01T17:52:13.570039Z"}]}
{"channel":"book","type":"update","data":[{"symbol":"LINK/USDT","bids":[{"price":18.58354,"qty":53.85485584}],"asks":[],"checksum":547891350,"timestamp":"2024-06-01T17:52:13.593635Z"}]}
{"channel":"book","type":"update","data":[{"symbol":"LINK/USDT","bids":[{"price":18.58507,"qty":0.00000000},{"price":18.57396,"qty":45.37000000}],"asks":[],"checksum":3523783334,"timestamp":"2024-06-01T17:52:13.598276Z"}]}
{"channel":"book","type":"update","data":[{"symbol":"LINK/USDT","bids":[{"price":18.58498,"qty":80.74471375}],"asks":[],"checksum":2930817879,"timestamp":"2024-06-01T17:52:13.609433Z"}]}
{"channel":"book","type":"update","data":[{"symbol":"LINK/USDT","bids":[{"price":18.58499,"qty":243.48672997}],"asks":[],"checksum":2411961703,"timestamp":"2024-06-01T17:52:14.059426Z"}]}
{"channel":"book","type":"update","data":[{"symbol":"LINK/USDT","bids":[{"price":18.58498,"qty":0.00000000},{"price":18.57615,"qty":47.16000000}],"asks":[],"checksum":629606858,"timestamp":"2024-06-01T17:52:14.249713Z"}]}
{"channel":"book","type":"update","data":[{"symbol":"LINK/USDT","bids":[{"price":18.58499,"qty":0.00000000},{"price":18.57396,"qty":45.37000000}],"asks":[],"checksum":3523783334,"timestamp":"2024-06-01T17:52:14.253735Z"}]}
{"channel":"book","type":"update","data":[{"symbol":"LINK/USDT","bids":[{"price":18.58507,"qty":80.74385491}],"asks":[],"checksum":2332986955,"timestamp":"2024-06-01T17:52:14.288902Z"}]}
{"channel":"book","type":"update","data":[{"symbol":"LINK/USDT","bids":[{"price":18.58508,"qty":243.48672997}],"asks":[],"checksum":2350558778,"timestamp":"2024-06-01T17:52:14.559356Z"}]}
{"channel":"book","type":"update","data":[{"symbol":"LINK/USDT","bids":[{"price":18.57929,"qty":0.00000000},{"price":18.57615,"qty":47.16000000}],"asks":[],"checksum":4235545714,"timestamp":"2024-06-01T17:52:14.611211Z"}]}
{"channel":"book","type":"update","data":[{"symbol":"LINK/USDT","bids":[{"price":18.57934,"qty":40.37191883}],"asks":[],"checksum":1439615982,"timestamp":"2024-06-01T17:52:14.651800Z"}]}
{"channel":"book","type":"update","data":[{"symbol":"LINK/USDT","bids":[{"price":18.57800,"qty":0.00000000},{"price":18.57615,"qty":47.16000000}],"asks":[],"checksum":3739721391,"timestamp":"2024-06-01T17:52:14.705641Z"}]}
{"channel":"book","type":"update","data":[{"symbol":"LINK/USDT","bids":[{"price":18.57800,"qty":118.56398794}],"asks":[],"checksum":1439615982,"timestamp":"2024-06-01T17:52:14.710443Z"}]}
{"channel":"book","type":"update","data":[{"symbol":"LINK/USDT","bids":[{"price":18.58354,"qty":0.00000000},{"price":18.57615,"qty":47.16000000}],"asks":[],"checksum":2084176631,"timestamp":"2024-06-01T17:52:14.714139Z"}]}
{"channel":"book","type":"update","data":[{"symbol":"LINK/USDT","bids":[],"asks":[{"price":18.59377,"qty":0.00000000},{"price":18.60420,"qty":107.59016987}],"checksum":1052824573,"timestamp":"2024-06-01T17:52:14.714196Z"}]}
{"channel":"book","type":"update","data":[{"symbol":"LINK/USDT","bids":[{"price":18.58305,"qty":53.85628468}],"asks":[],"checksum":1349421131,"timestamp":"2024-06-01T17:52:14.718076Z"}]}
{"channel":"book","type":"update","data":[{"symbol":"LINK/USDT","bids":[{"price":18.58507,"qty":0.00000000},{"price":18.57615,"qty":47.16000000}],"asks":[],"checksum":3207577849,"timestamp":"2024-06-01T17:52:14.849172Z"}]}
{"channel":"book","type":"update","data":[{"symbol":"LINK/USDT","bids":[{"price":18.58508,"qty":0.00000000},{"price":18.57396,"qty":45.37000000}],"asks":[],"checksum":2311426117,"timestamp":"2024-06-01T17:52:14.853431Z"}]}
{"channel":"book","type":"update","data":[{"symbol":"LINK/USDT","bids":[{"price":18.58305,"qty":0.00000000},{"price":18.57010,"qty":48.75805200}],"asks":[],"checksum":3673494587,"timestamp":"2024-06-01T17:52:14.857421Z"}]}
{"channel":"book","type":"update","data":[{"symbol":"LINK/USDT","bids":[{"price":18.58512,"qty":80.74318630}],"asks":[],"checksum":2369717698,"timestamp":"2024-06-01T17:52:14.889406Z"}]}
{"channel":"book","type":"update","data":[{"symbol":"LINK/USDT","bids":[{"price":18.57934,"qty":0.00000000},{"price":18.57010,"qty":48.75805200}],"asks":[],"checksum":1079376967,"timestamp":"2024-06-01T17:52:15.263047Z"}]}
{"channel":"book","type":"update","data":[{"symbol":"LINK/USDT","bids":[{"price":18.57938,"qty":40.37154326}],"asks":[],"checksum":791293491,"timestamp":"2024-06-01T17:52:15.303279Z"}]}
{"channel":"book","type":"update","data":[{"symbol":"LINK/USDT","bids":[{"price":18.58318,"qty":53.85591331}],"asks":[],"checksum":577604767,"timestamp":"2024-06-01T17:52:15.383374Z"}]}
{"channel":"book","type":"update","data":[{"symbol":"LINK/USDT","bids":[{"price":18.58318,"qty":0.00000000},{"price":18.57396,"qty":45.37000000}],"asks":[],"checksum":791293491,"timestamp":"2024-06-01T17:52:15.391511Z"}]}
{"channel":"book","type":"update","data":[{"symbol":"LINK/USDT","bids":[{"price":18.58513,"qty":243.48672997}],"asks":[],"checksum":2984245242,"timestamp":"2024-06-01T17:52:15.556827Z"}]}
{"channel":"book","type":"update","data":[{"symbol":"LINK/USDT","bids":[{"price":18.58512,"qty":0.00000000},{"price":18.57396,"qty":45.37000000}],"asks":[],"checksum":460546897,"timestamp":"2024-06-01T17:52:15.583851Z"}]}
{"channel":"book","type":"update","data":[{"symbol":"LINK/USDT","bids":[{"price":18.58595,"qty":80.73911592}],"asks":[],"checksum":3245973505,"timestamp":"2024-06-01T17:52:15.624097Z"}]}
{"channel":"book","type":"update","data":[{"symbol":"LINK/USDT","bids":[{"price":18.58596,"qty":243.48672997}],"asks":[],"checksum":2810825956,"timestamp":"2024-06-01T17:52:15.627952Z"}]}
{"channel":"book","type":"update","data":[{"symbol":"LINK/USDT","bids":[{"price":18.57938,"qty":0.00000000},{"price":18.57615,"qty":47.16000000}],"asks":[],"checksum":1564775587,"timestamp":"2024-06-01T17:52:15.913190Z"}]}
{"channel":"book","type":"update","data":[{"symbol":"LINK/USDT","bids":[{"price":18.57945,"qty":40.37156558}],"asks":[],"checksum":253635536,"timestamp":"2024-06-01T17:52:15.953707Z"}]}
{"channel":"book","type":"update","data":[{"symbol":"LINK/USDT","bids":[{"price":18.58513,"qty":0.00000000},{"price":18.57615,"qty":47.16000000}],"asks":[],"checksum":3342776158,"timestamp":"2024-06-01T17:52:16.150851Z"}]}
{"channel":"book","type":"update","data":[{"symbol":"LINK/USDT","bids":[{"price":18.58595,"qty":0.00000000},{"price":18.57396,"qty":45.37000000}],"asks":[],"checksum":1925520915,"timestamp":"2024-06-01T17:52:16.192741Z"}]}
{"channel":"book","type":"update","data":[{"symbol":"LINK/USDT","bids":[{"price":18.58596,"qty":0.00000000},{"price":18.57010,"qty":48.75805200}],"asks":[],"checksum":2056409054,"timestamp":"2024-06-01T17:52:16.196708Z"}]}
{"channel":"book","type":"update","data":[{"symbol":"LINK/USDT","bids":[],"asks":[{"price":18.58803,"qty":21.53675535}],"checksum":371129201,"timestamp":"2024-06-01T17:52:16.201502Z"}]}
{"channel":"book","type":"update","data":[{"symbol":"LINK/USDT","bids":[{"price":18.58318,"qty":53.85592052}],"asks":[],"checksum":529126305,"timestamp":"2024-06-01T17:52:16.201553Z"}]}
{"channel":"book","type":"update","data":[{"symbol":"LINK/USDT","bids":[{"price":18.58308,"qty":0.00000000},{"price":18.57010,"qty":48.75805200}],"asks":[],"checksum":3048722794,"timestamp":"2024-06-01T17:52:16.204328Z"}]}
{"channel":"book","type":"update","data":[{"symbol":"LINK/USDT","bids":[{"price":18.58365,"qty":9.40000000}],"asks":[],"checksum":1674219858,"timestamp":"2024-06-01T17:52:16.204411Z"}]}
{"channel":"book","type":"update","data":[{"symbol":"LINK/USDT","bids":[{"price":18.58318,"qty":0.00000000},{"price":18.57010,"qty":48.75805200}],"asks":[],"checksum":3274070678,"timestamp":"2024-06-01T17:52:16.205995Z"}]}
{"channel":"book","type":"update","data":[{"symbol":"LINK/USDT","bids":[{"price":18.57945,"qty":0.00000000},{"price":18.56768,"qty":68.59000000}],"asks":[],"checksum":1423757944,"timestamp":"2024-06-01T17:52:16.512293Z"}]}
{"channel":"book","type":"update","data":[{"symbol":"LINK/USDT","bids":[],"asks":[{"price":18.58800,"qty":9.00000000}],"checksum":1927419284,"timestamp":"2024-06-01T17:52:16.517510Z"}]}
{"channel":"book","type":"update","data":[{"symbol":"LINK/USDT","bids":[{"price":18.57801,"qty":243.48672997}],"asks":[],"checksum":2442376385,"timestamp":"2024-06-01T17:52:16.518340Z"}]}
{"channel":"book","type":"update","data":[{"symbol":"LINK/USDT","bids":[],"asks":[{"price":18.58803,"qty":0.00000000},{"price":18.60419,"qty":68.59000000}],"checksum":54121447,"timestamp":"2024-06-01T17:52:16.521810Z"}]}
{"channel":"book","type":"update","data":[{"symbol":"LINK/USDT","bids":[{"price":18.57931,"qty":40.37220750}],"asks":[],"checksum":3535987966,"timestamp":"2024-06-01T17:52:16.552087Z"}]}
{"channel":"book","type":"update","data":[{"symbol":"LINK/USDT","bids":[],"asks":[{"price":18.58800,"qty":0.00000000},{"price":18.60420,"qty":107.59016987}],"checksum":2952208769,"timestamp":"2024-06-01T17:52:16.556865Z"}]}
{"channel":"book","type":"update","data":[{"symbol":"LINK/USDT","bids":[{"price":18.58551,"qty":80.74331069}],"asks":[],"checksum":2818852163,"timestamp":"2024-06-01T17:52:16.791187Z"}]}
{"channel":"book","type":"update","data":[{"symbol":"LINK/USDT","bids":[{"price":18.58551,"qty":0.00000000},{"price":18.57396,"qty":45.37000000}],"asks":[],"checksum":2952208769,"timestamp":"2024-06-01T17:52:17.281099Z"}]}
{"channel":"book","type":"update","data":[{"symbol":"LINK/USDT","bids":[{"price":18.58368,"qty":9.00000000}],"asks":[],"checksum":3995309970,"timestamp":"2024-06-01T17:52:17.286494Z"}]}
{"channel":"book","type":"update","data":[{"symbol":"LINK/USDT","bids":[{"price":18.58601,"qty":80.73987606}],"asks":[],"checksum":2758412684,"timestamp":"2024-06-01T17:52:17.321652Z"}]}
{"channel":"book","type":"update","data":[{"symbol":"LINK/USDT","bids":[{"price":18.58368,"qty":0.00000000},{"price":18.57615,"qty":47.16000000}],"asks":[],"checksum":2145676864,"timestamp":"2024-06-01T17:52:17.326507Z"}]}
{"channel":"book","type":"update","data":[{"symbol":"LINK/USDT","bids":[{"price":18.58602,"qty":243.48672997}],"asks":[],"checksum":3830277400,"timestamp":"2024-06-01T17:52:17.560446Z"}]}
{"channel":"book","type":"update","data":[{"symbol":"LINK/USDT","bids":[],"asks":[{"price":18.59900,"qty":0.00000000},{"price":18.60811,"qty":57.29723514}],"checksum":1416603960,"timestamp":"2024-06-01T17:52:17.563609Z"}]}
{"channel":"book","type":"update","data":[{"symbol":"LINK/USDT","bids":[],"asks":[{"price":18.59400,"qty":155.60854051}],"checksum":3141976217,"timestamp":"2024-06-01T17:52:17.566600Z"}]}
{"channel":"book","type":"update","data":[{"symbol":"LINK/USDT","bids":[{"price":18.57801,"qty":0.00000000},{"price":18.57615,"qty":47.16000000}],"asks":[],"checksum":4107145594,"timestamp":"2024-06-01T17:52:17.566619Z"}]}
{"channel":"book","type":"update","data":[{"symbol":"LINK/USDT","bids":[],"asks":[{"price":18.58809,"qty":21.53668544}],"checksum":237508230,"timestamp":"2024-06-01T17:52:17.592969Z"}]}
{"channel":"book","type":"update","data":[{"symbol":"LINK/USDT","bids":[{"price":18.58392,"qty":53.85376790}],"asks":[],"checksum":2698224627,"timestamp":"2024-06-01T17:52:17.593081Z"}]}
{"channel":"book","type":"update","data":[{"symbol":"LINK/USDT","bids":[{"price":18.57931,"qty":0.00000000},{"price":18.57615,"qty":47.16000000}],"asks":[],"checksum":827664711,"timestamp":"2024-06-01T17:52:17.602751Z"}]}
{"channel":"book","type":"update","data":[{"symbol":"LINK/USDT","bids":[{"price":18.57980,"qty":40.36903766}],"asks":[],"checksum":3625440405,"timestamp":"2024-06-01T17:52:17.643097Z"}]}
{"channel":"book","type":"update","data":[{"symbol":"LINK/USDT","bids":[{"price":18.57980,"qty":0.00000000},{"price":18.57615,"qty":47.16000000}],"asks":[],"checksum":827664711,"timestamp":"2024-06-01T17:52:18.200873Z"}]}
{"channel":"book","type":"update","data":[{"symbol":"LINK/USDT","bids":[{"price":18.57684,"qty":0.00000000},{"price":18.57396,"qty":45.37000000}],"asks":[],"checksum":2301083917,"timestamp":"2024-06-01T17:52:18.223196Z"}]}
{"channel":"book","type":"update","data":[{"symbol":"LINK/USDT","bids":[{"price":18.57527,"qty":50.49000000}],"asks":[],"checksum":1718696235,"timestamp":"2024-06-01T17:52:18.226187Z"}]}
{"channel":"book","type":"update","data":[{"symbol":"LINK/USDT","bids":[{"price":18.57992,"qty":40.36874402}],"asks":[],"checksum":4168213196,"timestamp":"2024-06-01T17:52:18.241017Z"}]}
{"channel":"book","type":"update","data":[{"symbol":"LINK/USDT","bids":[],"asks":[{"price":18.58809,"qty":0.00000000},{"price":18.60420,"qty":107.59016987}],"checksum":43509040,"timestamp":"2024-06-01T17:52:18.270536Z"}]}
{"channel":"book","type":"update","data":[{"symbol":"LINK/USDT","bids":[],"asks":[{"price":18.58756,"qty":21.53730726}],"checksum":2635160364,"timestamp":"2024-06-01T17:52:18.275274Z"}]}
{"channel":"book","type":"update","data":[{"symbol":"LINK/USDT","bids":[{"price":18.58392,"qty":0.00000000},{"price":18.57527,"qty":50.49000000}],"asks":[],"checksum":3381364165,"timestamp":"2024-06-01T17:52:18.361877Z"}]}
{"channel":"book","type":"update","data":[{"symbol":"LINK/USDT","bids":[{"price":18.58345,"qty":53.85512814}],"asks":[],"checksum":113368014,"timestamp":"2024-06-01T17:52:18.365314Z"}]}
{"channel":"book","type":"update","data":[{"symbol":"LINK/USDT","bids":[{"price":18.58601,"qty":0.00000000},{"price":18.57527,"qty":50.49000000}],"asks":[],"checksum":484845229,"timestamp":"2024-06-01T17:52:18.441028Z"}]}
{"channel":"book","type":"update","data":[{"symbol":"LINK/USDT","bids":[{"price":18.58602,"qty":0.00000000},{"price":18.57396,"qty":45.37000000}],"asks":[],"checksum":761588222,"timestamp":"2024-06-01T17:52:18.445060Z"}]}
{"channel":"book","type":"update","data":[{"symbol":"LINK/USDT","bids":[{"price":18.58346,"qty":243.48672997}],"asks":[],"checksum":3884084639,"timestamp":"2024-06-01T17:52:18.445256Z"}]}
{"channel":"book","type":"update","data":[{"symbol":"LINK/USDT","bids":[{"price":18.58600,"qty":80.73807533}],"asks":[],"checksum":3591547877,"timestamp":"2024-06-01T17:52:18.481165Z"}]}
{"channel":"book","type":"update","data":[{"symbol":"LINK/USDT","bids":[{"price":18.58601,"qty":243.48672997}],"asks":[],"checksum":2799147606,"timestamp":"2024-06-01T17:52:18.485780Z"}]}
{"channel":"book","type":"update","data":[{"symbol":"LINK/USDT","bids":[{"price":18.58345,"qty":0.00000000},{"price":18.57615,"qty":47.16000000}],"asks":[],"checksum":1958985269,"timestamp":"2024-06-01T17:52:18.486288Z"}]}
{"channel":"book","type":"update","data":[{"symbol":"LINK/USDT","bids":[{"price":18.58346,"qty":0.00000000},{"price":18.57527,"qty":50.49000000}],"asks":[],"checksum":98208162,"timestamp":"2024-06-01T17:52:18.557980Z"}]}
{"channel":"book","type":"update","data":[{"symbol":"LINK/USDT","bids":[{"price":18.57992,"qty":0.00000000},{"price":18.57396,"qty":45.37000000}],"asks":[],"checksum":3813808394,"timestamp":"2024-06-01T17:52:18.730029Z"}]}
{"channel":"book","type":"update","data":[{"symbol":"LINK/USDT","bids":[{"price":18.57973,"qty":40.37011962}],"asks":[],"checksum":1150915877,"timestamp":"2024-06-01T17:52:18.770401Z"}]}
{"channel":"book","type":"update","data":[{"symbol":"LINK/USDT","bids":[],"asks":[{"price":18.58756,"qty":0.00000000},{"price":18.60420,"qty":107.59016987}],"checksum":3676252985,"timestamp":"2024-06-01T17:52:18.799956Z"}]}
{"channel":"book","type":"update","data":[{"symbol":"LINK/USDT","bids":[],"asks":[{"price":18.58797,"qty":21.53682697}],"checksum":801018541,"timestamp":"2024-06-01T17:52:18.803956Z"}]}
{"channel":"book","type":"update","data":[{"symbol":"LINK/USDT","bids":[{"price":18.58600,"qty":0.00000000},{"price":18.57396,"qty":45.37000000}],"asks":[],"checksum":326018666,"timestamp":"2024-06-01T17:52:18.971826Z"}]}
{"channel":"book","type":"update","data":[{"symbol":"LINK/USDT","bids":[{"price":18.58601,"qty":0.00000000},{"price":18.57010,"qty":48.75805200}],"asks":[],"checksum":4270189581,"timestamp":"2024-06-01T17:52:18.976653Z"}]}
{"channel":"book","type":"update","data":[{"symbol":"LINK/USDT","bids":[{"price":18.58605,"qty":80.73854765}],"asks":[],"checksum":3535773969,"timestamp":"2024-06-01T17:52:19.012150Z"}]}
{"channel":"book","type":"update","data":[{"symbol":"LINK/USDT","bids":[{"price":18.58411,"qty":53.85321593}],"asks":[],"checksum":2006562140,"timestamp":"2024-06-01T17:52:19.217986Z"}]}
{"channel":"book","type":"update","data":[{"symbol":"LINK/USDT","bids":[{"price":18.57973,"qty":0.00000000},{"price":18.57396,"qty":45.37000000}],"asks":[],"checksum":3495049587,"timestamp":"2024-06-01T17:52:19.328820Z"}]}
{"channel":"book","type":"update","data":[{"symbol":"LINK/USDT","bids":[{"price":18.57974,"qty":40.37011962}],"asks":[],"checksum":3098565048,"timestamp":"2024-06-01T17:52:19.369448Z"}]}
{"channel":"book","type":"update","data":[{"symbol":"LINK/USDT","bids":[{"price":18.58606,"qty":243.48672997}],"asks":[],"checksum":3904572805,"timestamp":"2024-06-01T17:52:19.561444Z"}]}
{"channel":"book","type":"update","data":[{"symbol":"LINK/USDT","bids":[{"price":18.58605,"qty":0.00000000},{"price":18.57527,"qty":50.49000000}],"asks":[],"checksum":237667447,"timestamp":"2024-06-01T17:52:19.571797Z"}]}
{"channel":"book","type":"update","data":[{"symbol":"LINK/USDT","bids":[{"price":18.58600,"qty":80.73958744}],"asks":[],"checksum":2544262116,"timestamp":"2024-06-01T17:52:19.612291Z"}]}
{"channel":"book","type":"update","data":[{"symbol":"LINK/USDT","bids":[{"price":18.58606,"qty":0.00000000},{"price":18.57527,"qty":50.49000000}],"asks":[],"checksum":3551301253,"timestamp":"2024-06-01T17:52:19.616499Z"}]}
{"channel":"book","type":"update","data":[{"symbol":"LINK/USDT","bids":[{"price":18.57974,"qty":0.00000000},{"price":18.57396,"qty":45.37000000}],"asks":[],"checksum":3142512206,"timestamp":"2024-06-01T17:52:20.015806Z"}]}
{"channel":"book","type":"update","data":[{"symbol":"LINK/USDT","bids":[{"price":18.57980,"qty":40.36979372}],"asks":[],"checksum":3422833969,"timestamp":"2024-06-01T17:52:20.056141Z"}]}
{"channel":"book","type":"update","data":[{"symbol":"LINK/USDT","bids":[{"price":18.58600,"qty":0.00000000},{"price":18.57396,"qty":45.37000000}],"asks":[],"checksum":180759277,"timestamp":"2024-06-01T17:52:20.247128Z"}]}
{"channel":"book","type":"update","data":[{"symbol":"LINK/USDT","bids":[{"price":18.58606,"qty":80.73785120}],"asks":[],"checksum":3108193224,"timestamp":"2024-06-01T17:52:20.287236Z"}]}
{"channel":"book","type":"update","data":[{"symbol":"LINK/USDT","bids":[{"price":18.57980,"qty":0.00000000},{"price":18.57396,"qty":45.37000000}],"asks":[],"checksum":3456753847,"timestamp":"2024-06-01T17:52:20.548492Z"}]}
{"channel":"book","type":"update","data":[{"symbol":"LINK/USDT","bids":[{"price":18.58607,"qty":243.48672997}],"asks":[],"checksum":1517933797,"timestamp":"2024-06-01T17:52:20.560350Z"}]}
{"channel":"book","type":"update","data":[{"symbol":"LINK/USDT","bids":[{"price":18.57985,"qty":40.36927382}],"asks":[],"checksum":3404984360,"timestamp":"2024-06-01T17:52:20.589000Z"}]}
{"channel":"book","type":"update","data":[{"symbol":"LINK/USDT","bids":[{"price":18.58606,"qty":0.00000000},{"price":18.57527,"qty":50.49000000}],"asks":[],"checksum":1656088177,"timestamp":"2024-06-01T17:52:20.781781Z"}]}
{"channel":"book","type":"update","data":[{"symbol":"LINK/USDT","bids":[{"price":18.58607,"qty":0.00000000},{"price":18.57396,"qty":45.37000000}],"asks":[],"checksum":1063423437,"timestamp":"2024-06-01T17:52:20.785857Z"}]}
{"channel":"book","type":"update","data":[{"symbol":"LINK/USDT","bids":[],"asks":[{"price":18.58797,"qty":0.00000000},{"price":18.60420,"qty":107.59016987}],"checksum":1248741595,"timestamp":"2024-06-01T17:52:20.935640Z"}]}
{"channel":"book","type":"update","data":[{"symbol":"LINK/USDT","bids":[{"price":18.58411,"qty":0.00000000},{"price":18.57010,"qty":48.75805200}],"asks":[],"checksum":2745978684,"timestamp":"2024-06-01T17:52:20.935654Z"}]}
{"channel":"book","type":"update","data":[{"symbol":"LINK/USDT","bids":[],"asks":[{"price":18.58871,"qty":21.53596565}],"checksum":1303182298,"timestamp":"2024-06-01T17:52:20.940542Z"}]}
{"channel":"book","type":"update","data":[{"symbol":"LINK/USDT","bids":[{"price":18.58475,"qty":53.85136945}],"asks":[],"checksum":3310199496,"timestamp":"2024-06-01T17:52:20.940658Z"}]}
{"channel":"book","type":"update","data":[{"symbol":"LINK/USDT","bids":[{"price":18.58475,"qty":0.00000000},{"price":18.57010,"qty":48.75805200}],"asks":[],"checksum":1303182298,"timestamp":"2024-06-01T17:52:21.040918Z"}]}
{"channel":"book","type":"update","data":[{"symbol":"LINK/USDT","bids":[],"asks":[{"price":18.58871,"qty":0.00000000},{"price":18.60420,"qty":107.59016987}],"checksum":2745978684,"timestamp":"2024-06-01T17:52:21.041048Z"}]}
{"channel":"book","type":"update","data":[{"symbol":"LINK/USDT","bids":[{"price":18.58368,"qty":9.00000000}],"asks":[],"checksum":4191821705,"timestamp":"2024-06-01T17:52:21.046643Z"}]}
{"channel":"book","type":"update","data":[{"symbol":"LINK/USDT","bids":[{"price":18.57985,"qty":0.00000000},{"price":18.57010,"qty":48.75805200}],"asks":[],"checksum":1207236188,"timestamp":"2024-06-01T17:52:21.170881Z"}]}
{"channel":"book","type":"update","data":[{"symbol":"LINK/USDT","bids":[{"price":18.57981,"qty":40.36903766}],"asks":[],"checksum":337081973,"timestamp":"2024-06-01T17:52:21.211373Z"}]}
{"channel":"book","type":"update","data":[{"symbol":"LINK/USDT","bids":[{"price":18.58626,"qty":80.73579650}],"asks":[],"checksum":601862716,"timestamp":"2024-06-01T17:52:21.398212Z"}]}
{"channel":"book","type":"update","data":[{"symbol":"LINK/USDT","bids":[{"price":18.58423,"qty":243.48672997}],"asks":[],"checksum":246511811,"timestamp":"2024-06-01T17:52:21.402528Z"}]}
{"channel":"book","type":"update","data":[{"symbol":"LINK/USDT","bids":[{"price":18.57981,"qty":0.00000000},{"price":18.57527,"qty":50.49000000}],"asks":[],"checksum":1868445203,"timestamp":"2024-06-01T17:52:21.786231Z"}]}
{"channel":"book","type":"update","data":[{"symbol":"LINK/USDT","bids":[{"price":18.58417,"qty":53.85304098}],"asks":[],"checksum":3877137540,"timestamp":"2024-06-01T17:52:22.593687Z"}]}
{"channel":"book","type":"update","data":[{"symbol":"LINK/USDT","bids":[],"asks":[{"price":18.58827,"qty":21.53647475}],"checksum":3574296669,"timestamp":"2024-06-01T17:52:22.593775Z"}]}
{"channel":"book","type":"update","data":[{"symbol":"LINK/USDT","bids":[{"price":18.58626,"qty":0.00000000},{"price":18.57527,"qty":50.49000000}],"asks":[],"checksum":572854038,"timestamp":"2024-06-01T17:52:22.770608Z"}]}
{"channel":"book","type":"update","data":[{"symbol":"LINK/USDT","bids":[{"price":18.58365,"qty":0.00000000},{"price":18.57396,"qty":45.37000000}],"asks":[],"checksum":2157351736,"timestamp":"2024-06-01T17:52:22.773463Z"}]}
{"channel":"book","type":"update","data":[{"symbol":"LINK/USDT","bids":[{"price":18.58441,"qty":9.40000000}],"asks":[],"checksum":24843756,"timestamp":"2024-06-01T17:52:22.773558Z"}]}
{"channel":"book","type":"update","data":[{"symbol":"LINK/USDT","bids":[{"price":18.58423,"qty":0.00000000},{"price":18.57396,"qty":45.37000000}],"asks":[],"checksum":1604054560,"timestamp":"2024-06-01T17:52:22.775086Z"}]}
{"channel":"book","type":"update","data":[{"symbol":"LINK/USDT","bids":[{"price":18.58418,"qty":243.48672997}],"asks":[],"checksum":2273667154,"timestamp":"2024-06-01T17:52:22.775095Z"}]}
{"channel":"book","type":"update","data":[{"symbol":"LINK/USDT","bids":[{"price":18.58677,"qty":80.72963609}],"asks":[],"checksum":4153759721,"timestamp":"2024-06-01T17:52:22.810919Z"}]}
{"channel":"book","type":"update","data":[{"symbol":"LINK/USDT","bids":[{"price":18.58069,"qty":40.36397232}],"asks":[],"checksum":2508649633,"timestamp":"2024-06-01T17:52:23.113291Z"}]}
{"channel":"book","type":"update","data":[{"symbol":"LINK/USDT","bids":[{"price":18.58677,"qty":0.00000000},{"price":18.57615,"qty":47.16000000}],"asks":[],"checksum":3242631540,"timestamp":"2024-06-01T17:52:23.313935Z"}]}
{"channel":"book","type":"update","data":[{"symbol":"LINK/USDT","bids":[],"asks":[{"price":18.59400,"qty":0.00000000},{"price":18.60420,"qty":107.59016987}],"checksum":2253909821,"timestamp":"2024-06-01T17:52:23.332373Z"}]}
{"channel":"book","type":"update","data":[{"symbol":"LINK/USDT","bids":[],"asks":[{"price":18.59500,"qty":127.50104051}],"checksum":2464104141,"timestamp":"2024-06-01T17:52:23.337231Z"}]}
{"channel":"book","type":"update","data":[{"symbol":"LINK/USDT","bids":[{"price":18.58680,"qty":80.72853180}],"asks":[],"checksum":2577008709,"timestamp":"2024-06-01T17:52:23.354228Z"}]}
{"channel":"book","type":"update","data":[{"symbol":"LINK/USDT","bids":[{"price":18.58680,"qty":0.00000000},{"price":18.57615,"qty":47.16000000}],"asks":[],"checksum":2464104141,"timestamp":"2024-06-01T17:52:23.432624Z"}]}
{"channel":"book","type":"update","data":[{"symbol":"LINK/USDT","bids":[{"price":18.58444,"qty":9.00000000}],"asks":[],"checksum":2566726867,"timestamp":"2024-06-01T17:52:23.438959Z"}]}
{"channel":"book","type":"update","data":[{"symbol":"LINK/USDT","bids":[{"price":18.58718,"qty":80.72347659}],"asks":[],"checksum":3963123448,"timestamp":"2024-06-01T17:52:23.472731Z"}]}
{"channel":"book","type":"update","data":[{"symbol":"LINK/USDT","bids":[{"price":18.58444,"qty":0.00000000},{"price":18.57640,"qty":33.73844400}],"asks":[],"checksum":3816891481,"timestamp":"2024-06-01T17:52:23.477235Z"}]}
{"channel":"book","type":"update","data":[{"symbol":"LINK/USDT","bids":[{"price":18.58069,"qty":0.00000000},{"price":18.57615,"qty":47.16000000}],"asks":[],"checksum":2173863697,"timestamp":"2024-06-01T17:52:23.616077Z"}]}
{"channel":"book","type":"update","data":[{"symbol":"LINK/USDT","bids":[{"price":18.58122,"qty":40.36059908}],"asks":[],"checksum":1748803293,"timestamp":"2024-06-01T17:52:23.656120Z"}]}
{"channel":"book","type":"update","data":[{"symbol":"LINK/USDT","bids":[{"price":18.58718,"qty":0.00000000},{"price":18.57615,"qty":47.16000000}],"asks":[],"checksum":2959620024,"timestamp":"2024-06-01T17:52:23.975932Z"}]}
{"channel":"book","type":"update","data":[{"symbol":"LINK/USDT","bids":[{"price":18.58444,"qty":9.00000000}],"asks":[],"checksum":323001943,"timestamp":"2024-06-01T17:52:23.980903Z"}]}
{"channel":"book","type":"update","data":[{"symbol":"LINK/USDT","bids":[{"price":18.58738,"qty":80.72183004}],"asks":[],"checksum":3831837040,"timestamp":"2024-06-01T17:52:24.016176Z"}]}
{"channel":"book","type":"update","data":[{"symbol":"LINK/USDT","bids":[{"price":18.58444,"qty":0.00000000},{"price":18.57640,"qty":33.73844400}],"asks":[],"checksum":3266108260,"timestamp":"2024-06-01T17:52:24.021492Z"}]}
{"channel":"book","type":"update","data":[{"symbol":"LINK/USDT","bids":[{"price":18.58122,"qty":0.00000000},{"price":18.57615,"qty":47.16000000}],"asks":[],"checksum":721601192,"timestamp":"2024-06-01T17:52:24.232877Z"}]}
{"channel":"book","type":"update","data":[{"symbol":"LINK/USDT","bids":[{"price":18.58124,"qty":40.36091502}],"asks":[],"checksum":3438946518,"timestamp":"2024-06-01T17:52:24.272853Z"}]}
{"channel":"book","type":"update","data":[{"symbol":"LINK/USDT","bids":[{"price":18.58417,"qty":0.00000000},{"price":18.57615,"qty":47.16000000}],"asks":[],"checksum":2175575652,"timestamp":"2024-06-01T17:52:24.335444Z"}]}
{"channel":"book","type":"update","data":[{"symbol":"LINK/USDT","bids":[{"price":18.58462,"qty":53.85175166}],"asks":[],"checksum":544443522,"timestamp":"2024-06-01T17:52:24.339062Z"}]}
{"channel":"book","type":"update","data":[{"symbol":"LINK/USDT","bids":[{"price":18.58738,"qty":0.00000000},{"price":18.57615,"qty":47.16000000}],"asks":[],"checksum":2445500213,"timestamp":"2024-06-01T17:52:24.592244Z"}]}
{"channel":"book","type":"update","data":[{"symbol":"LINK/USDT","bids":[{"price":18.58463,"qty":243.48672997}],"asks":[],"checksum":1330831371,"timestamp":"2024-06-01T17:52:24.596603Z"}]}
{"channel":"book","type":"update","data":[{"symbol":"LINK/USDT","bids":[{"price":18.58465,"qty":9.00000000}],"asks":[],"checksum":3127621662,"timestamp":"2024-06-01T17:52:24.600821Z"}]}
{"channel":"book","type":"update","data":[{"symbol":"LINK/USDT","bids":[{"price":18.58124,"qty":0.00000000},{"price":18.57640,"qty":33.73844400}],"asks":[],"checksum":1536993982,"timestamp":"2024-06-01T17:52:24.849135Z"}]}
{"channel":"book","type":"update","data":[{"symbol":"LINK/USDT","bids":[{"price":18.58129,"qty":40.36135513}],"asks":[],"checksum":172710343,"timestamp":"2024-06-01T17:52:24.957644Z"}]}
{"channel":"book","type":"update","data":[{"symbol":"LINK/USDT","bids":[{"price":18.58418,"qty":0.00000000},{"price":18.57640,"qty":33.73844400}],"asks":[],"checksum":3187225369,"timestamp":"2024-06-01T17:52:25.059358Z"}]}
{"channel":"book","type":"update","data":[{"symbol":"LINK/USDT","bids":[{"price":18.58465,"qty":0.00000000},{"price":18.57615,"qty":47.16000000}],"asks":[],"checksum":2167529397,"timestamp":"2024-06-01T17:52:25.070282Z"}]}
{"channel":"book","type":"update","data":[{"symbol":"LINK/USDT","bids":[{"price":18.58466,"qty":9.00000000}],"asks":[],"checksum":1836305122,"timestamp":"2024-06-01T17:52:25.070427Z"}]}
{"channel":"book","type":"update","data":[{"symbol":"LINK/USDT","bids":[{"price":18.58368,"qty":0.00000000},{"price":18.57615,"qty":47.16000000}],"asks":[],"checksum":3602297619,"timestamp":"2024-06-01T17:52:25.084528Z"}]}
{"channel":"book","type":"update","data":[{"symbol":"LINK/USDT","bids":[],"asks":[{"price":18.58827,"qty":0.00000000},{"price":18.60420,"qty":107.59016987}],"checksum":27990152,"timestamp":"2024-06-01T17:52:25.188562Z"}]}
{"channel":"book","type":"update","data":[{"symbol":"LINK/USDT","bids":[{"price":18.58462,"qty":0.00000000},{"price":18.57527,"qty":50.49000000}],"asks":[],"checksum":2305517799,"timestamp":"2024-06-01T17:52:25.188620Z"}]}
{"channel":"book","type":"update","data":[{"symbol":"LINK/USDT","bids":[{"price":18.58441,"qty":0.00000000},{"price":18.57396,"qty":45.37000000}],"asks":[],"checksum":2982898473,"timestamp":"2024-06-01T17:52:25.191229Z"}]}
{"channel":"book","type":"update","data":[{"symbol":"LINK/USDT","bids":[{"price":18.58474,"qty":9.40000000}],"asks":[],"checksum":3892717741,"timestamp":"2024-06-01T17:52:25.191521Z"}]}
{"channel":"book","type":"update","data":[{"symbol":"LINK/USDT","bids":[],"asks":[{"price":18.58868,"qty":21.53600492}],"checksum":3124547260,"timestamp":"2024-06-01T17:52:25.192576Z"}]}
{"channel":"book","type":"update","data":[{"symbol":"LINK/USDT","bids":[{"price":18.58469,"qty":53.85153829}],"asks":[],"checksum":3723179667,"timestamp":"2024-06-01T17:52:25.192665Z"}]}
{"channel":"book","type":"update","data":[{"symbol":"LINK/USDT","bids":[{"price":18.58754,"qty":80.74973342}],"asks":[],"checksum":2328796662,"timestamp":"2024-06-01T17:52:25.313716Z"}]}
{"channel":"book","type":"update","data":[{"symbol":"LINK/USDT","bids":[{"price":18.58129,"qty":0.00000000},{"price":18.57615,"qty":47.16000000}],"asks":[],"checksum":2544869406,"timestamp":"2024-06-01T17:52:25.461924Z"}]}
{"channel":"book","type":"update","data":[{"symbol":"LINK/USDT","bids":[{"price":18.58113,"qty":40.37655783}],"asks":[],"checksum":267777173,"timestamp":"2024-06-01T17:52:25.501776Z"}]}
{"channel":"book","type":"update","data":[{"symbol":"LINK/USDT","bids":[{"price":18.58754,"qty":0.00000000},{"price":18.57615,"qty":47.16000000}],"asks":[],"checksum":204292064,"timestamp":"2024-06-01T17:52:25.821659Z"}]}
{"channel":"book","type":"update","data":[{"symbol":"LINK/USDT","bids":[{"price":18.58470,"qty":243.48672997}],"asks":[],"checksum":4032747458,"timestamp":"2024-06-01T17:52:25.825806Z"}]}
{"channel":"book","type":"update","data":[{"symbol":"LINK/USDT","bids":[{"price":18.58477,"qty":9.00000000}],"asks":[],"checksum":3192275985,"timestamp":"2024-06-01T17:52:25.827140Z"}]}
{"channel":"book","type":"update","data":[{"symbol":"LINK/USDT","bids":[{"price":18.58733,"qty":80.76014701}],"asks":[],"checksum":171375895,"timestamp":"2024-06-01T17:52:25.863703Z"}]}
{"channel":"book","type":"update","data":[{"symbol":"LINK/USDT","bids":[{"price":18.58470,"qty":0.00000000},{"price":18.57661,"qty":134.68740171}],"asks":[],"checksum":1929595302,"timestamp":"2024-06-01T17:52:25.867471Z"}]}
{"channel":"book","type":"update","data":[{"symbol":"LINK/USDT","bids":[{"price":18.58477,"qty":0.00000000},{"price":18.57640,"qty":33.73844400}],"asks":[],"checksum":2281986919,"timestamp":"2024-06-01T17:52:25.868197Z"}]}
{"channel":"book","type":"update","data":[{"symbol":"LINK/USDT","bids":[{"price":18.58113,"qty":0.00000000},{"price":18.57615,"qty":47.16000000}],"asks":[],"checksum":274599916,"timestamp":"2024-06-01T17:52:26.084458Z"}]}
{"channel":"book","type":"update","data":[{"symbol":"LINK/USDT","bids":[{"price":18.58128,"qty":40.38072532}],"asks":[],"checksum":646878235,"timestamp":"2024-06-01T17:52:26.124571Z"}]}
{"channel":"book","type":"update","data":[{"symbol":"LINK/USDT","bids":[{"price":18.58733,"qty":0.00000000},{"price":18.57615,"qty":47.16000000}],"asks":[],"checksum":2917968609,"timestamp":"2024-06-01T17:52:26.446197Z"}]}
{"channel":"book","type":"update","data":[{"symbol":"LINK/USDT","bids":[{"price":18.58470,"qty":243.48672997}],"asks":[],"checksum":1590958270,"timestamp":"2024-06-01T17:52:26.450395Z"}]}
{"channel":"book","type":"update","data":[{"symbol":"LINK/USDT","bids":[{"price":18.58477,"qty":9.00000000}],"asks":[],"checksum":2202826949,"timestamp":"2024-06-01T17:52:26.451409Z"}]}
{"channel":"book","type":"update","data":[{"symbol":"LINK/USDT","bids":[{"price":18.58765,"qty":80.76081399}],"asks":[],"checksum":331259658,"timestamp":"2024-06-01T17:52:26.486473Z"}]}
{"channel":"book","type":"update","data":[{"symbol":"LINK/USDT","bids":[{"price":18.58470,"qty":0.00000000},{"price":18.57661,"qty":134.68740171}],"asks":[],"checksum":3280557570,"timestamp":"2024-06-01T17:52:26.490243Z"}]}
{"channel":"book","type":"update","data":[{"symbol":"LINK/USDT","bids":[{"price":18.58477,"qty":0.00000000},{"price":18.57640,"qty":33.73844400}],"asks":[],"checksum":1980130564,"timestamp":"2024-06-01T17:52:26.491425Z"}]}
{"channel":"book","type":"update","data":[{"symbol":"LINK/USDT","bids":[{"price":18.58128,"qty":0.00000000},{"price":18.57615,"qty":47.16000000}],"asks":[],"checksum":1087831795,"timestamp":"2024-06-01T17:52:26.705645Z"}]}
{"channel":"book","type":"update","data":[{"symbol":"LINK/USDT","bids":[{"price":18.58107,"qty":40.38130109}],"asks":[],"checksum":2728577020,"timestamp":"2024-06-01T17:52:26.746061Z"}]}
{"channel":"book","type":"update","data":[{"symbol":"LINK/USDT","bids":[{"price":18.58765,"qty":0.00000000},{"price":18.57615,"qty":47.16000000}],"asks":[],"checksum":2823574316,"timestamp":"2024-06-01T17:52:27.068343Z"}]}
{"channel":"book","type":"update","data":[{"symbol":"LINK/USDT","bids":[{"price":18.58470,"qty":243.48672997}],"asks":[],"checksum":2322643526,"timestamp":"2024-06-01T17:52:27.072273Z"}]}
{"channel":"book","type":"update","data":[{"symbol":"LINK/USDT","bids":[{"price":18.58477,"qty":9.00000000}],"asks":[],"checksum":3625751062,"timestamp":"2024-06-01T17:52:27.073685Z"}]}
{"channel":"book","type":"update","data":[{"symbol":"LINK/USDT","bids":[{"price":18.58466,"qty":0.00000000},{"price":18.57640,"qty":33.73844400}],"asks":[],"checksum":3995748854,"timestamp":"2024-06-01T17:52:27.084556Z"}]}
{"channel":"book","type":"update","data":[{"symbol":"LINK/USDT","bids":[{"price":18.58729,"qty":80.76249653}],"asks":[],"checksum":223163523,"timestamp":"2024-06-01T17:52:27.108726Z"}]}
{"channel":"book","type":"update","data":[{"symbol":"LINK/USDT","bids":[{"price":18.58470,"qty":0.00000000},{"price":18.57640,"qty":33.73844400}],"asks":[],"checksum":1831420269,"timestamp":"2024-06-01T17:52:27.112286Z"}]}
{"channel":"book","type":"update","data":[{"symbol":"LINK/USDT","bids":[{"price":18.58107,"qty":0.00000000},{"price":18.57615,"qty":47.16000000}],"asks":[],"checksum":2405267554,"timestamp":"2024-06-01T17:52:27.260530Z"}]}
{"channel":"book","type":"update","data":[{"symbol":"LINK/USDT","bids":[{"price":18.58106,"qty":40.38135958}],"asks":[],"checksum":3743268690,"timestamp":"2024-06-01T17:52:27.300755Z"}]}
{"channel":"book","type":"update","data":[{"symbol":"LINK/USDT","bids":[{"price":18.58729,"qty":0.00000000},{"price":18.57615,"qty":47.16000000}],"asks":[],"checksum":2269822235,"timestamp":"2024-06-01T17:52:27.618889Z"}]}
{"channel":"book","type":"update","data":[{"symbol":"LINK/USDT","bids":[{"price":18.58470,"qty":243.48672997}],"asks":[],"checksum":1545517001,"timestamp":"2024-06-01T17:52:27.623231Z"}]}
{"channel":"book","type":"update","data":[{"symbol":"LINK/USDT","bids":[{"price":18.58463,"qty":0.00000000},{"price":18.57615,"qty":47.16000000}],"asks":[],"checksum":1476141958,"timestamp":"2024-06-01T17:52:28.059753Z"}]}
{"channel":"book","type":"update","data":[{"symbol":"LINK/USDT","bids":[{"price":18.58728,"qty":80.76271916}],"asks":[],"checksum":3935509536,"timestamp":"2024-06-01T17:52:28.240493Z"}]}
{"channel":"book","type":"update","data":[{"symbol":"LINK/USDT","bids":[{"price":18.58106,"qty":0.00000000},{"price":18.57615,"qty":47.16000000}],"asks":[],"checksum":3134446352,"timestamp":"2024-06-01T17:52:28.464718Z"}]}
{"channel":"book","type":"update","data":[{"symbol":"LINK/USDT","bids":[{"price":18.58108,"qty":40.38135958}],"asks":[],"checksum":3695215858,"timestamp":"2024-06-01T17:52:28.504917Z"}]}
{"channel":"book","type":"update","data":[{"symbol":"LINK/USDT","bids":[{"price":18.58728,"qty":0.00000000},{"price":18.57615,"qty":47.16000000}],"asks":[],"checksum":954579447,"timestamp":"2024-06-01T17:52:29.330662Z"}]}
{"channel":"book","type":"update","data":[{"symbol":"LINK/USDT","bids":[{"price":18.58733,"qty":80.76271916}],"asks":[],"checksum":726449531,"timestamp":"2024-06-01T17:52:29.370903Z"}]}
{"channel":"book","type":"update","data":[{"symbol":"LINK/USDT","bids":[{"price":18.58108,"qty":0.00000000},{"price":18.57615,"qty":47.16000000}],"asks":[],"checksum":1306518169,"timestamp":"2024-06-01T17:52:29.602536Z"}]}
{"channel":"book","type":"update","data":[{"symbol":"LINK/USDT","bids":[{"price":18.58113,"qty":40.38135958}],"asks":[],"checksum":1124591181,"timestamp":"2024-06-01T17:52:29.642831Z"}]}
{"channel":"book","type":"update","data":[{"symbol":"LINK/USDT","bids":[{"price":18.58113,"qty":0.00000000},{"price":18.57615,"qty":47.16000000}],"asks":[],"checksum":1306518169,"timestamp":"2024-06-01T17:52:30.272183Z"}]}
{"channel":"book","type":"update","data":[{"symbol":"LINK/USDT","bids":[{"price":18.58115,"qty":40.38135958}],"asks":[],"checksum":3613067185,"timestamp":"2024-06-01T17:52:30.312345Z"}]}
{"channel":"book","type":"update","data":[{"symbol":"LINK/USDT","bids":[{"price":18.58733,"qty":0.00000000},{"price":18.57615,"qty":47.16000000}],"asks":[],"checksum":685737814,"timestamp":"2024-06-01T17:52:30.564423Z"}]}
{"channel":"book","type":"update","data":[{"symbol":"LINK/USDT","bids":[{"price":18.57800,"qty":0.00000000},{"price":18.57527,"qty":50.49000000}],"asks":[],"checksum":1786426101,"timestamp":"2024-06-01T17:52:30.567605Z"}]}
{"channel":"book","type":"update","data":[{"symbol":"LINK/USDT","bids":[{"price":18.58000,"qty":102.35162126}],"asks":[],"checksum":551364611,"timestamp":"2024-06-01T17:52:30.572458Z"}]}
{"channel":"book","type":"update","data":[{"symbol":"LINK/USDT","bids":[{"price":18.58763,"qty":80.76152733}],"asks":[],"checksum":1355059083,"timestamp":"2024-06-01T17:52:30.604691Z"}]}
{"channel":"book","type":"update","data":[{"symbol":"LINK/USDT","bids":[{"price":18.57661,"qty":0.00000000},{"price":18.57615,"qty":47.16000000}],"asks":[],"checksum":176969301,"timestamp":"2024-06-01T17:52:30.795025Z"}]}
{"channel":"book","type":"update","data":[{"symbol":"LINK/USDT","bids":[{"price":18.58469,"qty":0.00000000},{"price":18.57527,"qty":50.49000000}],"asks":[],"checksum":31890444,"timestamp":"2024-06-01T17:52:30.795144Z"}]}
{"channel":"book","type":"update","data":[{"symbol":"LINK/USDT","bids":[],"asks":[{"price":18.58868,"qty":0.00000000},{"price":18.60420,"qty":107.59016987}],"checksum":1407368127,"timestamp":"2024-06-01T17:52:30.795384Z"}]}
{"channel":"book","type":"update","data":[{"symbol":"LINK/USDT","bids":[],"asks":[{"price":18.58914,"qty":21.53546577}],"checksum":312866166,"timestamp":"2024-06-01T17:52:30.801841Z"}]}
{"channel":"book","type":"update","data":[{"symbol":"LINK/USDT","bids":[{"price":18.57906,"qty":134.66963501}],"asks":[],"checksum":1998213437,"timestamp":"2024-06-01T17:52:30.801914Z"}]}
{"channel":"book","type":"update","data":[{"symbol":"LINK/USDT","bids":[{"price":18.58519,"qty":53.85008008}],"asks":[],"checksum":716858477,"timestamp":"2024-06-01T17:52:30.801926Z"}]}
{"channel":"book","type":"update","data":[{"symbol":"LINK/USDT","bids":[{"price":18.58115,"qty":0.00000000},{"price":18.57615,"qty":47.16000000}],"asks":[],"checksum":2951763339,"timestamp":"2024-06-01T17:52:30.901351Z"}]}
{"channel":"book","type":"update","data":[{"symbol":"LINK/USDT","bids":[{"price":18.58143,"qty":40.38076366}],"asks":[],"checksum":1503529310,"timestamp":"2024-06-01T17:52:30.941668Z"}]}
{"channel":"book","type":"update","data":[{"symbol":"LINK/USDT","bids":[{"price":18.58477,"qty":0.00000000},{"price":18.57615,"qty":47.16000000}],"asks":[],"checksum":928066442,"timestamp":"2024-06-01T17:52:30.998534Z"}]}
{"channel":"book","type":"update","data":[{"symbol":"LINK/USDT","bids":[{"price":18.58519,"qty":0.00000000},{"price":18.57527,"qty":50.49000000}],"asks":[],"checksum":3022955493,"timestamp":"2024-06-01T17:52:30.998715Z"}]}
{"channel":"book","type":"update","data":[{"symbol":"LINK/USDT","bids":[],"asks":[{"price":18.58914,"qty":0.00000000},{"price":18.60420,"qty":107.59016987}],"checksum":1064493618,"timestamp":"2024-06-01T17:52:30.998725Z"}]}
{"channel":"book","type":"update","data":[{"symbol":"LINK/USDT","bids":[{"price":18.58000,"qty":0.00000000},{"price":18.57396,"qty":45.37000000}],"asks":[],"checksum":3751762018,"timestamp":"2024-06-01T17:52:31.002555Z"}]}
{"channel":"book","type":"update","data":[{"symbol":"LINK/USDT","bids":[{"price":18.58470,"qty":0.00000000},{"price":18.57010,"qty":48.75805200}],"asks":[],"checksum":4214504207,"timestamp":"2024-06-01T17:52:31.003740Z"}]}
{"channel":"book","type":"update","data":[{"symbol":"LINK/USDT","bids":[{"price":18.57800,"qty":62.18898794}],"asks":[],"checksum":992562518,"timestamp":"2024-06-01T17:52:31.013788Z"}]}
{"channel":"book","type":"update","data":[{"symbol":"LINK/USDT","bids":[{"price":18.57906,"qty":0.00000000},{"price":18.57010,"qty":48.75805200}],"asks":[],"checksum":4256815243,"timestamp":"2024-06-01T17:52:31.027359Z"}]}
{"channel":"book","type":"update","data":[{"symbol":"LINK/USDT","bids":[],"asks":[{"price":18.59311,"qty":4.84643000}],"checksum":3866374304,"timestamp":"2024-06-01T17:52:31.032340Z"}]}
{"channel":"book","type":"update","data":[{"symbol":"LINK/USDT","bids":[],"asks":[{"price":18.59393,"qty":0.00000000},{"price":18.60420,"qty":107.59016987}],"checksum":71364459,"timestamp":"2024-06-01T17:52:31.032441Z"}]}
{"channel":"book","type":"update","data":[{"symbol":"LINK/USDT","bids":[],"asks":[{"price":18.59333,"qty":0.00000000},{"price":18.60811,"qty":81.59726570}],"checksum":945937707,"timestamp":"2024-06-01T17:52:31.049209Z"}]}
{"channel":"book","type":"update","data":[{"symbol":"LINK/USDT","bids":[],"asks":[{"price":18.60811,"qty":57.29779986}],"checksum":1211368712,"timestamp":"2024-06-01T17:52:31.049289Z"}]}
{"channel":"book","type":"update","data":[{"symbol":"LINK/USDT","bids":[],"asks":[{"price":18.59249,"qty":9.40000000}],"checksum":3887800439,"timestamp":"2024-06-01T17:52:31.049536Z"}]}
{"channel":"book","type":"update","data":[{"symbol":"LINK/USDT","bids":[],"asks":[{"price":18.60419,"qty":0.00000000},{"price":18.60811,"qty":57.29779986},{"price":18.60010,"qty":68.59000000}],"checksum":815291815,"timestamp":"2024-06-01T17:52:31.050024Z"}]}
{"channel":"book","type":"update","data":[{"symbol":"LINK/USDT","bids":[{"price":18.58474,"qty":0.00000000},{"price":18.56767,"qty":120.84006900}],"asks":[],"checksum":2546429606,"timestamp":"2024-06-01T17:52:31.068233Z"}]}
{"channel":"book","type":"update","data":[{"symbol":"LINK/USDT","bids":[{"price":18.57800,"qty":0.00000000},{"price":18.56766,"qty":269.50450617}],"asks":[],"checksum":1709193470,"timestamp":"2024-06-01T17:52:31.069978Z"}]}
{"channel":"book","type":"update","data":[{"symbol":"LINK/USDT","bids":[],"asks":[{"price":18.59230,"qty":4.84649166}],"checksum":3992752750,"timestamp":"2024-06-01T17:52:31.074854Z"}]}
{"channel":"book","type":"update","data":[{"symbol":"LINK/USDT","bids":[],"asks":[{"price":18.59311,"qty":0.00000000},{"price":18.60420,"qty":107.59016987}],"checksum":2306499212,"timestamp":"2024-06-01T17:52:31.074868Z"}]}
{"channel":"book","type":"update","data":[{"symbol":"LINK/USDT","bids":[],"asks":[{"price":18.59246,"qty":9.00000000}],"checksum":4266739364,"timestamp":"2024-06-01T17:52:31.085620Z"}]}
{"channel":"book","type":"update","data":[{"symbol":"LINK/USDT","bids":[],"asks":[{"price":18.59499,"qty":243.48672997}],"checksum":518172330,"timestamp":"2024-06-01T17:52:31.089928Z"}]}
{"channel":"book","type":"update","data":[{"symbol":"LINK/USDT","bids":[{"price":18.57700,"qty":43.46142127}],"asks":[],"checksum":3345515240,"timestamp":"2024-06-01T17:52:31.095975Z"}]}
{"channel":"book","type":"update","data":[{"symbol":"LINK/USDT","bids":[],"asks":[{"price":18.59330,"qty":0.00000000},{"price":18.60011,"qty":243.48672997}],"checksum":2938838704,"timestamp":"2024-06-01T17:52:31.104500Z"}]}
{"channel":"book","type":"update","data":[{"symbol":"LINK/USDT","bids":[{"price":18.58065,"qty":243.48672997}],"asks":[],"checksum":3293663697,"timestamp":"2024-06-01T17:52:31.107674Z"}]}
{"channel":"book","type":"update","data":[{"symbol":"LINK/USDT","bids":[],"asks":[{"price":18.59249,"qty":0.00000000},{"price":18.60420,"qty":107.59016987}],"checksum":925434767,"timestamp":"2024-06-01T17:52:31.120340Z"}]}
{"channel":"book","type":"update","data":[{"symbol":"LINK/USDT","bids":[],"asks":[{"price":18.59159,"qty":9.40000000}],"checksum":4213826902,"timestamp":"2024-06-01T17:52:31.120456Z"}]}
{"channel":"book","type":"update","data":[{"symbol":"LINK/USDT","bids":[{"price":18.58763,"qty":0.00000000},{"price":18.56767,"qty":99.84006900}],"asks":[],"checksum":7677068,"timestamp":"2024-06-01T17:52:31.136420Z"}]}
{"channel":"book","type":"update","data":[{"symbol":"LINK/USDT","bids":[],"asks":[{"price":18.59499,"qty":0.00000000},{"price":18.60420,"qty":107.59016987}],"checksum":2726909878,"timestamp":"2024-06-01T17:52:31.137610Z"}]}
{"channel":"book","type":"update","data":[{"symbol":"LINK/USDT","bids":[{"price":18.57700,"qty":0.00000000},{"price":18.56766,"qty":269.50450617}],"asks":[],"checksum":2825041541,"timestamp":"2024-06-01T17:52:31.148728Z"}]}
{"channel":"book","type":"update","data":[{"symbol":"LINK/USDT","bids":[],"asks":[{"price":18.59230,"qty":0.00000000},{"price":18.60811,"qty":57.29779986}],"checksum":2449587741,"timestamp":"2024-06-01T17:52:31.154321Z"}]}
{"channel":"book","type":"update","data":[{"symbol":"LINK/USDT","bids":[],"asks":[{"price":18.59140,"qty":4.84686193}],"checksum":1113578420,"timestamp":"2024-06-01T17:52:31.154354Z"}]}
{"channel":"book","type":"update","data":[{"symbol":"LINK/USDT","bids":[{"price":18.57300,"qty":38.56115452}],"asks":[],"checksum":1141461745,"timestamp":"2024-06-01T17:52:31.154373Z"}]}
{"channel":"book","type":"update","data":[{"symbol":"LINK/USDT","bids":[{"price":18.57640,"qty":0.00000000},{"price":18.56766,"qty":269.50450617}],"asks":[],"checksum":3353970757,"timestamp":"2024-06-01T17:52:31.156215Z"}]}
{"channel":"book","type":"update","data":[{"symbol":"LINK/USDT","bids":[{"price":18.57010,"qty":0.00000000},{"price":18.56580,"qty":134.65619580}],"asks":[],"checksum":1761837371,"timestamp":"2024-06-01T17:52:31.156228Z"}]}
{"channel":"book","type":"update","data":[{"symbol":"LINK/USDT","bids":[],"asks":[{"price":18.59800,"qty":0.00000000},{"price":18.60811,"qty":57.29779986}],"checksum":2628857072,"timestamp":"2024-06-01T17:52:31.157838Z"}]}
{"channel":"book","type":"update","data":[{"symbol":"LINK/USDT","bids":[{"price":18.57240,"qty":33.73844400}],"asks":[],"checksum":1273555925,"timestamp":"2024-06-01T17:52:31.159032Z"}]}
{"channel":"book","type":"update","data":[{"symbol":"LINK/USDT","bids":[],"asks":[{"price":18.59200,"qty":33.73844400}],"checksum":3434371734,"timestamp":"2024-06-01T17:52:31.161649Z"}]}
{"channel":"book","type":"update","data":[{"symbol":"LINK/USDT","bids":[{"price":18.58550,"qty":80.76715186}],"asks":[],"checksum":225994064,"timestamp":"2024-06-01T17:52:31.172844Z"}]}
{"channel":"book","type":"update","data":[{"symbol":"LINK/USDT","bids":[],"asks":[{"price":18.59227,"qty":9.00000000}],"checksum":1905200352,"timestamp":"2024-06-01T17:52:31.173351Z"}]}
{"channel":"book","type":"update","data":[{"symbol":"LINK/USDT","bids":[{"price":18.56767,"qty":129.66006900}],"asks":[],"checksum":4177481882,"timestamp":"2024-06-01T17:52:31.204072Z"}]}
{"channel":"book","type":"update","data":[{"symbol":"LINK/USDT","bids":[],"asks":[{"price":18.59552,"qty":243.48672997}],"checksum":3744566759,"timestamp":"2024-06-01T17:52:31.204228Z"}]}
{"channel":"book","type":"update","data":[{"symbol":"LINK/USDT","bids":[{"price":18.56767,"qty":29.82000000}],"asks":[],"checksum":211382543,"timestamp":"2024-06-01T17:52:31.204256Z"}]}
{"channel":"book","type":"update","data":[{"symbol":"LINK/USDT","bids":[],"asks":[{"price":18.59227,"qty":0.00000000},{"price":18.60011,"qty":243.48672997}],"checksum":4281641861,"timestamp":"2024-06-01T17:52:31.206648Z"}]}
{"channel":"book","type":"update","data":[{"symbol":"LINK/USDT","bids":[],"asks":[{"price":18.59156,"qty":9.00000000}],"checksum":2163811048,"timestamp":"2024-06-01T17:52:31.206703Z"}]}
{"channel":"book","type":"update","data":[{"symbol":"LINK/USDT","bids":[],"asks":[{"price":18.59245,"qty":65.00000000}],"checksum":2161294274,"timestamp":"2024-06-01T17:52:31.208673Z"}]}
{"channel":"book","type":"update","data":[{"symbol":"LINK/USDT","bids":[],"asks":[{"price":18.59069,"qty":9.40000000}],"checksum":2949015573,"timestamp":"2024-06-01T17:52:31.227208Z"}]}
{"channel":"book","type":"update","data":[{"symbol":"LINK/USDT","bids":[],"asks":[{"price":18.59159,"qty":0.00000000},{"price":18.59717,"qty":50.49000000}],"checksum":3673977988,"timestamp":"2024-06-01T17:52:31.227223Z"}]}
{"channel":"book","type":"update","data":[{"symbol":"LINK/USDT","bids":[{"price":18.58291,"qty":0.00000000},{"price":18.56766,"qty":269.50450617}],"asks":[],"checksum":4081125917,"timestamp":"2024-06-01T17:52:31.232827Z"}]}
{"channel":"book","type":"update","data":[{"symbol":"LINK/USDT","bids":[],"asks":[{"price":18.59245,"qty":0.00000000},{"price":18.60010,"qty":68.59000000}],"checksum":368700926,"timestamp":"2024-06-01T17:52:31.234555Z"}]}
{"channel":"book","type":"update","data":[{"symbol":"LINK/USDT","bids":[],"asks":[{"price":18.59229,"qty":65.00000000}],"checksum":3103695344,"timestamp":"2024-06-01T17:52:31.234636Z"}]}
{"channel":"book","type":"update","data":[{"symbol":"LINK/USDT","bids":[],"asks":[{"price":18.59156,"qty":0.00000000},{"price":18.60010,"qty":68.59000000}],"checksum":2014859691,"timestamp":"2024-06-01T17:52:31.238128Z"}]}
{"channel":"book","type":"update","data":[{"symbol":"LINK/USDT","bids":[],"asks":[{"price":18.59137,"qty":9.00000000}],"checksum":2896318402,"timestamp":"2024-06-01T17:52:31.238189Z"}]}
{"channel":"book","type":"update","data":[{"symbol":"LINK/USDT","bids":[],"asks":[{"price":18.59050,"qty":4.84720836}],"checksum":2860336442,"timestamp":"2024-06-01T17:52:31.249271Z"}]}
{"channel":"book","type":"update","data":[{"symbol":"LINK/USDT","bids":[],"asks":[{"price":18.59140,"qty":0.00000000},{"price":18.59717,"qty":50.49000000}],"checksum":2413235243,"timestamp":"2024-06-01T17:52:31.253510Z"}]}
{"channel":"book","type":"update","data":[{"symbol":"LINK/USDT","bids":[{"price":18.58550,"qty":0.00000000},{"price":18.56580,"qty":134.65619580}],"asks":[],"checksum":4226066522,"timestamp":"2024-06-01T17:52:31.259042Z"}]}
{"channel":"book","type":"update","data":[{"symbol":"LINK/USDT","bids":[],"asks":[{"price":18.59246,"qty":0.00000000},{"price":18.60010,"qty":68.59000000}],"checksum":3422538638,"timestamp":"2024-06-01T17:52:31.277817Z"}]}
{"channel":"book","type":"update","data":[{"symbol":"LINK/USDT","bids":[{"price":18.58481,"qty":80.77493520}],"asks":[],"checksum":4146576771,"timestamp":"2024-06-01T17:52:31.289320Z"}]}
{"channel":"book","type":"update","data":[{"symbol":"LINK/USDT","bids":[],"asks":[{"price":18.59158,"qty":65.00000000}],"checksum":2561999144,"timestamp":"2024-06-01T17:52:31.299137Z"}]}
{"channel":"book","type":"update","data":[{"symbol":"LINK/USDT","bids":[{"price":18.56766,"qty":0.00000000},{"price":18.56580,"qty":134.65619580}],"asks":[],"checksum":3063142001,"timestamp":"2024-06-01T17:52:31.307399Z"}]}
{"channel":"book","type":"update","data":[{"symbol":"LINK/USDT","bids":[],"asks":[{"price":18.59066,"qty":9.00000000}],"checksum":1256444320,"timestamp":"2024-06-01T17:52:31.307677Z"}]}
{"channel":"book","type":"update","data":[{"symbol":"LINK/USDT","bids":[{"price":18.57393,"qty":134.70685335}],"asks":[],"checksum":234014782,"timestamp":"2024-06-01T17:52:31.314134Z"}]}
{"channel":"book","type":"update","data":[{"symbol":"LINK/USDT","bids":[{"price":18.57826,"qty":53.87017886}],"asks":[],"checksum":166568787,"timestamp":"2024-06-01T17:52:31.314180Z"}]}
{"channel":"book","type":"update","data":[{"symbol":"LINK/USDT","bids":[],"asks":[{"price":18.59045,"qty":21.53395595}],"checksum":2329453784,"timestamp":"2024-06-01T17:52:31.314302Z"}]}
{"channel":"book","type":"update","data":[{"symbol":"LINK/USDT","bids":[],"asks":[{"price":18.59069,"qty":0.00000000},{"price":18.59552,"qty":243.48672997}],"checksum":3058190140,"timestamp":"2024-06-01T17:52:31.315002Z"}]}
{"channel":"book","type":"update","data":[{"symbol":"LINK/USDT","bids":[],"asks":[{"price":18.58979,"qty":9.40000000}],"checksum":3578986063,"timestamp":"2024-06-01T17:52:31.315187Z"}]}
{"channel":"book","type":"update","data":[{"symbol":"LINK/USDT","bids":[{"price":18.57826,"qty":0.00000000},{"price":18.56581,"qty":99.84006900}],"asks":[],"checksum":18846634,"timestamp":"2024-06-01T17:52:31.322511Z"}]}
{"channel":"book","type":"update","data":[{"symbol":"LINK/USDT","bids":[],"asks":[{"price":18.59045,"qty":0.00000000},{"price":18.59552,"qty":243.48672997}],"checksum":1973671080,"timestamp":"2024-06-01T17:52:31.322521Z"}]}
{"channel":"book","type":"update","data":[{"symbol":"LINK/USDT","bids":[],"asks":[{"price":18.59026,"qty":4.84720077}],"checksum":1180142468,"timestamp":"2024-06-01T17:52:31.328615Z"}]}
{"channel":"book","type":"update","data":[{"symbol":"LINK/USDT","bids":[],"asks":[{"price":18.59050,"qty":0.00000000},{"price":18.59552,"qty":243.48672997}],"checksum":3000393706,"timestamp":"2024-06-01T17:52:31.329137Z"}]}
{"channel":"book","type":"update","data":[{"symbol":"LINK/USDT","bids":[],"asks":[{"price":18.59158,"qty":0.00000000},{"price":18.59717,"qty":50.49000000}],"checksum":2530260485,"timestamp":"2024-06-01T17:52:31.330336Z"}]}
{"channel":"book","type":"update","data":[{"symbol":"LINK/USDT","bids":[],"asks":[{"price":18.59155,"qty":65.00000000}],"checksum":1528799216,"timestamp":"2024-06-01T17:52:31.330351Z"}]}
{"channel":"book","type":"update","data":[{"symbol":"LINK/USDT","bids":[],"asks":[{"price":18.58960,"qty":4.84720077}],"checksum":1279724528,"timestamp":"2024-06-01T17:52:31.331982Z"}]}
{"channel":"book","type":"update","data":[{"symbol":"LINK/USDT","bids":[],"asks":[{"price":18.59026,"qty":0.00000000},{"price":18.59552,"qty":243.48672997}],"checksum":3510293938,"timestamp":"2024-06-01T17:52:31.334441Z"}]}
{"channel":"book","type":"update","data":[{"symbol":"LINK/USDT","bids":[{"price":18.58065,"qty":0.00000000},{"price":18.56580,"qty":134.65619580}],"asks":[],"checksum":1615482443,"timestamp":"2024-06-01T17:52:31.352880Z"}]}
{"channel":"book","type":"update","data":[{"symbol":"LINK/USDT","bids":[{"price":18.57393,"qty":0.00000000},{"price":18.56321,"qty":269.56923869}],"asks":[],"checksum":137961668,"timestamp":"2024-06-01T17:52:31.377034Z"}]}
{"channel":"book","type":"update","data":[{"symbol":"LINK/USDT","bids":[],"asks":[{"price":18.58976,"qty":9.00000000}],"checksum":4216804328,"timestamp":"2024-06-01T17:52:31.388716Z"}]}
{"channel":"book","type":"update","data":[{"symbol":"LINK/USDT","bids":[],"asks":[{"price":18.59066,"qty":0.00000000},{"price":18.59552,"qty":243.48672997}],"checksum":2850666464,"timestamp":"2024-06-01T17:52:31.388832Z"}]}
{"channel":"book","type":"update","data":[{"symbol":"LINK/USDT","bids":[],"asks":[{"price":18.58979,"qty":0.00000000},{"price":18.59717,"qty":50.49000000}],"checksum":3885427109,"timestamp":"2024-06-01T17:52:31.392250Z"}]}
{"channel":"book","type":"update","data":[{"symbol":"LINK/USDT","bids":[],"asks":[{"price":18.58889,"qty":9.40000000}],"checksum":3923923442,"timestamp":"2024-06-01T17:52:31.392284Z"}]}
{"channel":"book","type":"update","data":[{"symbol":"LINK/USDT","bids":[],"asks":[{"price":18.58889,"qty":14.24728959}],"checksum":477477732,"timestamp":"2024-06-01T17:52:31.407520Z"}]}
{"channel":"book","type":"update","data":[{"symbol":"LINK/USDT","bids":[],"asks":[{"price":18.59155,"qty":0.00000000},{"price":18.59717,"qty":50.49000000}],"checksum":3518665361,"timestamp":"2024-06-01T17:52:31.421372Z"}]}
{"channel":"book","type":"update","data":[{"symbol":"LINK/USDT","bids":[],"asks":[{"price":18.59068,"qty":65.00000000}],"checksum":3978441284,"timestamp":"2024-06-01T17:52:31.421458Z"}]}
{"channel":"book","type":"update","data":[{"symbol":"LINK/USDT","bids":[],"asks":[{"price":18.58960,"qty":0.00000000},{"price":18.59717,"qty":50.49000000}],"checksum":2373093057,"timestamp":"2024-06-01T17:52:31.424857Z"}]}
{"channel":"book","type":"update","data":[{"symbol":"LINK/USDT","bids":[],"asks":[{"price":18.58976,"qty":0.00000000},{"price":18.60010,"qty":68.59000000}],"checksum":2410142936,"timestamp":"2024-06-01T17:52:31.425150Z"}]}
{"channel":"book","type":"update","data":[{"symbol":"LINK/USDT","bids":[],"asks":[{"price":18.58957,"qty":9.00000000}],"checksum":2926802434,"timestamp":"2024-06-01T17:52:31.425170Z"}]}
{"channel":"book","type":"update","data":[{"symbol":"LINK/USDT","bids":[],"asks":[{"price":18.59044,"qty":65.00000000}],"checksum":2507217702,"timestamp":"2024-06-01T17:52:31.454367Z"}]}
{"channel":"book","type":"update","data":[{"symbol":"LINK/USDT","bids":[],"asks":[{"price":18.59068,"qty":0.00000000},{"price":18.59717,"qty":50.49000000}],"checksum":2850667507,"timestamp":"2024-06-01T17:52:31.454548Z"}]}
{"channel":"book","type":"update","data":[{"symbol":"LINK/USDT","bids":[],"asks":[{"price":18.59716,"qty":68.59000000}],"checksum":3803150858,"timestamp":"2024-06-01T17:52:31.457572Z"}]}
{"channel":"book","type":"update","data":[{"symbol":"LINK/USDT","bids":[{"price":18.57865,"qty":243.48672997}],"asks":[],"checksum":3988680528,"timestamp":"2024-06-01T17:52:31.458428Z"}]}
{"channel":"book","type":"update","data":[{"symbol":"LINK/USDT","bids":[],"asks":[{"price":18.58886,"qty":9.00000000}],"checksum":3129339193,"timestamp":"2024-06-01T17:52:31.461394Z"}]}
{"channel":"book","type":"update","data":[{"symbol":"LINK/USDT","bids":[],"asks":[{"price":18.58957,"qty":0.00000000},{"price":18.59716,"qty":68.59000000}],"checksum":584171686,"timestamp":"2024-06-01T17:52:31.461428Z"}]}
{"channel":"book","type":"update","data":[{"symbol":"LINK/USDT","bids":[],"asks":[{"price":18.58880,"qty":4.84731284}],"checksum":237265135,"timestamp":"2024-06-01T17:52:31.464357Z"}]}
{"channel":"book","type":"update","data":[{"symbol":"LINK/USDT","bids":[],"asks":[{"price":18.58889,"qty":4.84728959}],"checksum":4018966592,"timestamp":"2024-06-01T17:52:31.467461Z"}]}
{"channel":"book","type":"update","data":[{"symbol":"LINK/USDT","bids":[],"asks":[{"price":18.58889,"qty":0.00000000},{"price":18.59716,"qty":68.59000000}],"checksum":3475258426,"timestamp":"2024-06-01T17:52:31.467633Z"}]}
{"channel":"book","type":"update","data":[{"symbol":"LINK/USDT","bids":[],"asks":[{"price":18.58836,"qty":9.40000000}],"checksum":2429751980,"timestamp":"2024-06-01T17:52:31.467741Z"}]}
{"channel":"book","type":"update","data":[{"symbol":"LINK/USDT","bids":[{"price":18.58143,"qty":0.00000000},{"price":18.56321,"qty":269.56923869}],"asks":[],"checksum":3824025827,"timestamp":"2024-06-01T17:52:31.468082Z"}]}
{"channel":"book","type":"update","data":[{"symbol":"LINK/USDT","bids":[],"asks":[{"price":18.59044,"qty":0.00000000},{"price":18.59716,"qty":68.59000000}],"checksum":1400103632,"timestamp":"2024-06-01T17:52:31.500376Z"}]}
{"channel":"book","type":"update","data":[{"symbol":"LINK/USDT","bids":[],"asks":[{"price":18.58833,"qty":9.00000000}],"checksum":1505821238,"timestamp":"2024-06-01T17:52:31.506428Z"}]}
{"channel":"book","type":"update","data":[{"symbol":"LINK/USDT","bids":[],"asks":[{"price":18.58886,"qty":0.00000000},{"price":18.59716,"qty":68.59000000}],"checksum":3330322999,"timestamp":"2024-06-01T17:52:31.506540Z"}]}
{"channel":"book","type":"update","data":[{"symbol":"LINK/USDT","bids":[{"price":18.57756,"qty":40.38964220}],"asks":[],"checksum":3119354138,"timestamp":"2024-06-01T17:52:31.508418Z"}]}
{"channel":"book","type":"update","data":[{"symbol":"LINK/USDT","bids":[],"asks":[{"price":18.59137,"qty":0.00000000},{"price":18.59717,"qty":50.49000000}],"checksum":4192698188,"timestamp":"2024-06-01T17:52:31.584027Z"}]}
{"channel":"book","type":"update","data":[{"symbol":"LINK/USDT","bids":[],"asks":[{"price":18.58877,"qty":53.83976446}],"checksum":3988984603,"timestamp":"2024-06-01T17:52:31.611684Z"}]}
{"channel":"book","type":"update","data":[{"symbol":"LINK/USDT","bids":[],"asks":[{"price":18.59229,"qty":0.00000000},{"price":18.59717,"qty":50.49000000}],"checksum":855962300,"timestamp":"2024-06-01T17:52:31.651087Z"}]}
{"channel":"book","type":"update","data":[{"symbol":"LINK/USDT","bids":[],"asks":[{"price":18.59716,"qty":0.00000000},{"price":18.59840,"qty":107.62376872}],"checksum":2213756007,"timestamp":"2024-06-01T17:52:31.667708Z"}]}
{"channel":"book","type":"update","data":[{"symbol":"LINK/USDT","bids":[],"asks":[{"price":18.58880,"qty":0.00000000},{"price":18.60419,"qty":48.75805200}],"checksum":3411189003,"timestamp":"2024-06-01T17:52:31.670757Z"}]}
{"channel":"book","type":"update","data":[{"symbol":"LINK/USDT","bids":[],"asks":[{"price":18.58836,"qty":0.00000000},{"price":18.60420,"qty":107.59016987}],"checksum":616379947,"timestamp":"2024-06-01T17:52:31.706142Z"}]}
{"channel":"book","type":"update","data":[{"symbol":"LINK/USDT","bids":[{"price":18.58481,"qty":0.00000000},{"price":18.56321,"qty":269.56923869}],"asks":[],"checksum":904230964,"timestamp":"2024-06-01T17:52:31.815497Z"}]}
{"channel":"book","type":"update","data":[{"symbol":"LINK/USDT","bids":[{"price":18.57936,"qty":9.40000000}],"asks":[],"checksum":3006973021,"timestamp":"2024-06-01T17:52:31.818310Z"}]}
{"channel":"book","type":"update","data":[{"symbol":"LINK/USDT","bids":[{"price":18.57865,"qty":0.00000000},{"price":18.56321,"qty":269.56923869}],"asks":[],"checksum":2130744664,"timestamp":"2024-06-01T17:52:31.819433Z"}]}
{"channel":"book","type":"update","data":[{"symbol":"LINK/USDT","bids":[{"price":18.57757,"qty":243.48672997}],"asks":[],"checksum":1685435444,"timestamp":"2024-06-01T17:52:31.819561Z"}]}
{"channel":"book","type":"update","data":[{"symbol":"LINK/USDT","bids":[{"price":18.57868,"qty":9.00000000}],"asks":[],"checksum":985016619,"timestamp":"2024-06-01T17:52:31.820810Z"}]}
{"channel":"book","type":"update","data":[{"symbol":"LINK/USDT","bids":[],"asks":[{"price":18.58421,"qty":21.54118075}],"checksum":2658631972,"timestamp":"2024-06-01T17:52:31.831176Z"}]}
{"channel":"book","type":"update","data":[{"symbol":"LINK/USDT","bids":[{"price":18.57090,"qty":134.72884299}],"asks":[],"checksum":3950758686,"timestamp":"2024-06-01T17:52:31.831237Z"}]}
{"channel":"book","type":"update","data":[{"symbol":"LINK/USDT","bids":[{"price":18.57978,"qty":53.86576938}],"asks":[],"checksum":2484300463,"timestamp":"2024-06-01T17:52:31.831313Z"}]}
{"channel":"book","type":"update","data":[{"symbol":"LINK/USDT","bids":[{"price":18.57936,"qty":0.00000000},{"price":18.57090,"qty":134.72884299}],"asks":[],"checksum":2755800937,"timestamp":"2024-06-01T17:52:31.834249Z"}]}
{"channel":"book","type":"update","data":[{"symbol":"LINK/USDT","bids":[{"price":18.58035,"qty":9.40000000}],"asks":[],"checksum":3813070881,"timestamp":"2024-06-01T17:52:31.834537Z"}]}
{"channel":"book","type":"update","data":[{"symbol":"LINK/USDT","bids":[],"asks":[{"price":18.58421,"qty":0.00000000},{"price":18.60420,"qty":107.59016987}],"checksum":1200058414,"timestamp":"2024-06-01T17:52:31.852484Z"}]}
{"channel":"book","type":"update","data":[{"symbol":"LINK/USDT","bids":[{"price":18.58472,"qty":80.77484502}],"asks":[],"checksum":2065903657,"timestamp":"2024-06-01T17:52:31.855655Z"}]}
{"channel":"book","type":"update","data":[{"symbol":"LINK/USDT","bids":[{"price":18.57979,"qty":243.48672997}],"asks":[],"checksum":589126862,"timestamp":"2024-06-01T17:52:31.856764Z"}]}
{"channel":"book","type":"update","data":[{"symbol":"LINK/USDT","bids":[{"price":18.57868,"qty":0.00000000},{"price":18.57300,"qty":38.56115452}],"asks":[],"checksum":3873654127,"timestamp":"2024-06-01T17:52:31.858011Z"}]}
{"channel":"book","type":"update","data":[{"symbol":"LINK/USDT","bids":[{"price":18.58038,"qty":9.00000000}],"asks":[],"checksum":2402675324,"timestamp":"2024-06-01T17:52:31.858212Z"}]}
{"channel":"book","type":"update","data":[{"symbol":"LINK/USDT","bids":[],"asks":[{"price":18.60098,"qty":68.59000000}],"checksum":1293067291,"timestamp":"2024-06-01T17:52:31.858669Z"}]}
{"channel":"book","type":"update","data":[{"symbol":"LINK/USDT","bids":[],"asks":[{"price":18.58877,"qty":0.00000000},{"price":18.60420,"qty":107.59016987}],"checksum":883998890,"timestamp":"2024-06-01T17:52:31.882101Z"}]}
{"channel":"book","type":"update","data":[{"symbol":"LINK/USDT","bids":[{"price":18.57978,"qty":0.00000000},{"price":18.57300,"qty":38.56115452}],"asks":[],"checksum":3413078188,"timestamp":"2024-06-01T17:52:31.882625Z"}]}
{"channel":"book","type":"update","data":[{"symbol":"LINK/USDT","bids":[],"asks":[{"price":18.59129,"qty":9.40000000}],"checksum":3940504584,"timestamp":"2024-06-01T17:52:31.885010Z"}]}
{"channel":"book","type":"update","data":[{"symbol":"LINK/USDT","bids":[{"price":18.57979,"qty":0.00000000},{"price":18.57240,"qty":33.73844400}],"asks":[],"checksum":70960486,"timestamp":"2024-06-01T17:52:31.886494Z"}]}
{"channel":"book","type":"update","data":[{"symbol":"LINK/USDT","bids":[{"price":18.58038,"qty":0.00000000},{"price":18.56581,"qty":99.84006900}],"asks":[],"checksum":3335293705,"timestamp":"2024-06-01T17:52:31.889383Z"}]}
{"channel":"book","type":"update","data":[{"symbol":"LINK/USDT","bids":[{"price":18.56581,"qty":0.00000000},{"price":18.56580,"qty":134.65619580}],"asks":[],"checksum":3888593613,"timestamp":"2024-06-01T17:52:32.066768Z"}]}
{"channel":"book","type":"update","data":[{"symbol":"LINK/USDT","bids":[{"price":18.56581,"qty":161.25260094}],"asks":[],"checksum":412225644,"timestamp":"2024-06-01T17:52:32.066784Z"}]}
{"channel":"book","type":"update","data":[{"symbol":"LINK/USDT","bids":[],"asks":[{"price":18.58833,"qty":0.00000000},{"price":18.60420,"qty":107.59016987}],"checksum":875859505,"timestamp":"2024-06-01T17:52:32.084342Z"}]}
{"channel":"book","type":"update","data":[{"symbol":"LINK/USDT","bids":[],"asks":[{"price":18.59126,"qty":9.00000000}],"checksum":1307459427,"timestamp":"2024-06-01T17:52:32.084410Z"}]}
{"channel":"book","type":"update","data":[{"symbol":"LINK/USDT","bids":[{"price":18.57756,"qty":0.00000000},{"price":18.56580,"qty":134.65619580}],"asks":[],"checksum":383235725,"timestamp":"2024-06-01T17:52:32.108338Z"}]}
{"channel":"book","type":"update","data":[{"symbol":"LINK/USDT","bids":[{"price":18.57820,"qty":40.38818036}],"asks":[],"checksum":2495021023,"timestamp":"2024-06-01T17:52:32.148647Z"}]}
{"channel":"book","type":"update","data":[{"symbol":"LINK/USDT","bids":[],"asks":[{"price":18.59155,"qty":53.83170071}],"checksum":3690862715,"timestamp":"2024-06-01T17:52:32.189074Z"}]}
{"channel":"book","type":"update","data":[{"symbol":"LINK/USDT","bids":[],"asks":[{"price":18.59107,"qty":4.84678443}],"checksum":113644374,"timestamp":"2024-06-01T17:52:32.208396Z"}]}
{"channel":"book","type":"update","data":[{"symbol":"LINK/USDT","bids":[],"asks":[{"price":18.59129,"qty":0.00000000},{"price":18.60098,"qty":68.59000000}],"checksum":1013311429,"timestamp":"2024-06-01T17:52:32.211045Z"}]}
{"channel":"book","type":"update","data":[{"symbol":"LINK/USDT","bids":[],"asks":[{"price":18.59053,"qty":9.40000000}],"checksum":2930094202,"timestamp":"2024-06-01T17:52:32.211218Z"}]}
{"channel":"book","type":"update","data":[{"symbol":"LINK/USDT","bids":[],"asks":[{"price":18.59050,"qty":9.00000000}],"checksum":2187726452,"timestamp":"2024-06-01T17:52:32.217532Z"}]}
{"channel":"book","type":"update","data":[{"symbol":"LINK/USDT","bids":[{"price":18.58472,"qty":0.00000000},{"price":18.56580,"qty":134.65619580}],"asks":[],"checksum":1602965847,"timestamp":"2024-06-01T17:52:32.455338Z"}]}
{"channel":"book","type":"update","data":[{"symbol":"LINK/USDT","bids":[{"price":18.57821,"qty":243.48672997}],"asks":[],"checksum":2487527564,"timestamp":"2024-06-01T17:52:32.459454Z"}]}
{"channel":"book","type":"update","data":[{"symbol":"LINK/USDT","bids":[],"asks":[{"price":18.59126,"qty":0.00000000},{"price":18.59840,"qty":107.62376872}],"checksum":3984752762,"timestamp":"2024-06-01T17:52:32.460157Z"}]}
{"channel":"book","type":"update","data":[{"symbol":"LINK/USDT","bids":[{"price":18.58038,"qty":9.00000000}],"asks":[],"checksum":1737133576,"timestamp":"2024-06-01T17:52:32.460168Z"}]}
{"channel":"book","type":"update","data":[{"symbol":"LINK/USDT","bids":[{"price":18.58442,"qty":80.77636073}],"asks":[],"checksum":3450245573,"timestamp":"2024-06-01T17:52:32.495226Z"}]}
{"channel":"book","type":"update","data":[{"symbol":"LINK/USDT","bids":[{"price":18.57757,"qty":0.00000000},{"price":18.57240,"qty":33.73844400}],"asks":[],"checksum":4246315469,"timestamp":"2024-06-01T17:52:32.498815Z"}]}
{"channel":"book","type":"update","data":[{"symbol":"LINK/USDT","bids":[{"price":18.58038,"qty":0.00000000},{"price":18.56581,"qty":161.25260094}],"asks":[],"checksum":3473336232,"timestamp":"2024-06-01T17:52:32.500220Z"}]}
{"channel":"book","type":"update","data":[{"symbol":"LINK/USDT","bids":[{"price":18.57970,"qty":53.86601903}],"asks":[],"checksum":2668677589,"timestamp":"2024-06-01T17:52:32.500244Z"}]}
{"channel":"book","type":"update","data":[{"symbol":"LINK/USDT","bids":[{"price":18.57360,"qty":134.70925970}],"asks":[],"checksum":2674231615,"timestamp":"2024-06-01T17:52:32.500382Z"}]}
{"channel":"book","type":"update","data":[{"symbol":"LINK/USDT","bids":[{"price":18.57820,"qty":0.00000000},{"price":18.57240,"qty":33.73844400}],"asks":[],"checksum":2779339623,"timestamp":"2024-06-01T17:52:32.748010Z"}]}
{"channel":"book","type":"update","data":[{"symbol":"LINK/USDT","bids":[{"price":18.57822,"qty":40.38818036}],"asks":[],"checksum":3104624230,"timestamp":"2024-06-01T17:52:32.788260Z"}]}
{"channel":"book","type":"update","data":[{"symbol":"LINK/USDT","bids":[{"price":18.58442,"qty":0.00000000},{"price":18.57240,"qty":33.73844400}],"asks":[],"checksum":3792097778,"timestamp":"2024-06-01T17:52:33.093943Z"}]}
{"channel":"book","type":"update","data":[{"symbol":"LINK/USDT","bids":[{"price":18.57971,"qty":243.48672997}],"asks":[],"checksum":1176188498,"timestamp":"2024-06-01T17:52:33.098021Z"}]}
{"channel":"book","type":"update","data":[{"symbol":"LINK/USDT","bids":[],"asks":[{"price":18.58445,"qty":21.54090205}],"checksum":240121725,"timestamp":"2024-06-01T17:52:33.098070Z"}]}
{"channel":"book","type":"update","data":[{"symbol":"LINK/USDT","bids":[{"price":18.58038,"qty":9.00000000}],"asks":[],"checksum":424910731,"timestamp":"2024-06-01T17:52:33.099022Z"}]}
{"channel":"book","type":"update","data":[{"symbol":"LINK/USDT","bids":[{"price":18.58429,"qty":80.77695686}],"asks":[],"checksum":3174757059,"timestamp":"2024-06-01T17:52:33.134140Z"}]}
{"channel":"book","type":"update","data":[{"symbol":"LINK/USDT","bids":[{"price":18.57971,"qty":0.00000000},{"price":18.57360,"qty":134.70925970}],"asks":[],"checksum":1668841728,"timestamp":"2024-06-01T17:52:33.137517Z"}]}
{"channel":"book","type":"update","data":[{"symbol":"LINK/USDT","bids":[{"price":18.58038,"qty":0.00000000},{"price":18.57300,"qty":38.56115452}],"asks":[],"checksum":1477327779,"timestamp":"2024-06-01T17:52:33.138894Z"}]}
{"channel":"book","type":"update","data":[{"symbol":"LINK/USDT","bids":[{"price":18.57822,"qty":0.00000000},{"price":18.57240,"qty":33.73844400}],"asks":[],"checksum":1152102050,"timestamp":"2024-06-01T17:52:33.311941Z"}]}
{"channel":"book","type":"update","data":[{"symbol":"LINK/USDT","bids":[{"price":18.57825,"qty":40.38806901}],"asks":[],"checksum":228731789,"timestamp":"2024-06-01T17:52:33.352354Z"}]}
{"channel":"book","type":"update","data":[{"symbol":"LINK/USDT","bids":[{"price":18.58429,"qty":0.00000000},{"price":18.57240,"qty":33.73844400}],"asks":[],"checksum":2907603862,"timestamp":"2024-06-01T17:52:33.657237Z"}]}
{"channel":"book","type":"update","data":[{"symbol":"LINK/USDT","bids":[{"price":18.57971,"qty":243.48672997}],"asks":[],"checksum":1541662547,"timestamp":"2024-06-01T17:52:33.661438Z"}]}
{"channel":"book","type":"update","data":[{"symbol":"LINK/USDT","bids":[{"price":18.58038,"qty":9.00000000}],"asks":[],"checksum":3637493057,"timestamp":"2024-06-01T17:52:33.663660Z"}]}
{"channel":"book","type":"update","data":[{"symbol":"LINK/USDT","bids":[{"price":18.57825,"qty":0.00000000},{"price":18.57300,"qty":38.56115452}],"asks":[],"checksum":2221341577,"timestamp":"2024-06-01T17:52:33.950748Z"}]}
{"channel":"book","type":"update","data":[{"symbol":"LINK/USDT","bids":[{"price":18.57821,"qty":0.00000000},{"price":18.57240,"qty":33.73844400}],"asks":[],"checksum":1692839278,"timestamp":"2024-06-01T17:52:33.954710Z"}]}
{"channel":"book","type":"update","data":[{"symbol":"LINK/USDT","bids":[{"price":18.57834,"qty":40.38806901}],"asks":[],"checksum":1460561004,"timestamp":"2024-06-01T17:52:33.991175Z"}]}
{"channel":"book","type":"update","data":[{"symbol":"LINK/USDT","bids":[{"price":18.57834,"qty":0.00000000},{"price":18.57240,"qty":33.73844400}],"asks":[],"checksum":1692839278,"timestamp":"2024-06-01T17:52:34.661958Z"}]}
{"channel":"book","type":"update","data":[{"symbol":"LINK/USDT","bids":[{"price":18.57832,"qty":40.38836707}],"asks":[],"checksum":1682802861,"timestamp":"2024-06-01T17:52:34.702329Z"}]}
{"channel":"book","type":"update","data":[{"symbol":"LINK/USDT","bids":[{"price":18.58038,"qty":0.00000000},{"price":18.57240,"qty":33.73844400}],"asks":[],"checksum":315021156,"timestamp":"2024-06-01T17:52:34.707473Z"}]}
{"channel":"book","type":"update","data":[{"symbol":"LINK/USDT","bids":[{"price":18.58399,"qty":80.77926276}],"asks":[],"checksum":42161937,"timestamp":"2024-06-01T17:52:35.054724Z"}]}
{"channel":"book","type":"update","data":[{"symbol":"LINK/USDT","bids":[{"price":18.57832,"qty":0.00000000},{"price":18.57240,"qty":33.73844400}],"asks":[],"checksum":36205266,"timestamp":"2024-06-01T17:52:35.230466Z"}]}
{"channel":"book","type":"update","data":[{"symbol":"LINK/USDT","bids":[{"price":18.58399,"qty":0.00000000},{"price":18.56585,"qty":99.84006900}],"asks":[],"checksum":1659806625,"timestamp":"2024-06-01T17:52:35.582132Z"}]}
{"channel":"book","type":"update","data":[{"symbol":"LINK/USDT","bids":[{"price":18.58408,"qty":80.77933477}],"asks":[],"checksum":2753043405,"timestamp":"2024-06-01T17:52:35.622399Z"}]}
{"channel":"book","type":"update","data":[{"symbol":"LINK/USDT","bids":[{"price":18.57763,"qty":40.39026356}],"asks":[],"checksum":2390413294,"timestamp":"2024-06-01T17:52:35.876216Z"}]}
{"channel":"book","type":"update","data":[{"symbol":"LINK/USDT","bids":[{"price":18.58408,"qty":0.00000000},{"price":18.57240,"qty":33.73844400}],"asks":[],"checksum":453098004,"timestamp":"2024-06-01T17:52:36.192991Z"}]}
{"channel":"book","type":"update","data":[{"symbol":"LINK/USDT","bids":[],"asks":[{"price":18.58445,"qty":0.00000000},{"price":18.59839,"qty":68.59000000}],"checksum":207382004,"timestamp":"2024-06-01T17:52:36.197373Z"}]}
{"channel":"book","type":"update","data":[{"symbol":"LINK/USDT","bids":[],"asks":[{"price":18.59031,"qty":4.84705122}],"checksum":1450374550,"timestamp":"2024-06-01T17:52:36.200604Z"}]}
{"channel":"book","type":"update","data":[{"symbol":"LINK/USDT","bids":[],"asks":[{"price":18.59155,"qty":0.00000000},{"price":18.59839,"qty":68.59000000}],"checksum":3084273382,"timestamp":"2024-06-01T17:52:36.201808Z"}]}
{"channel":"book","type":"update","data":[{"symbol":"LINK/USDT","bids":[],"asks":[{"price":18.58377,"qty":21.54170155}],"checksum":2379280532,"timestamp":"2024-06-01T17:52:36.201982Z"}]}
{"channel":"book","type":"update","data":[{"symbol":"LINK/USDT","bids":[],"asks":[{"price":18.59053,"qty":0.00000000},{"price":18.59839,"qty":68.59000000}],"checksum":2003472635,"timestamp":"2024-06-01T17:52:36.203344Z"}]}
{"channel":"book","type":"update","data":[{"symbol":"LINK/USDT","bids":[],"asks":[{"price":18.58987,"qty":9.40000000}],"checksum":885529639,"timestamp":"2024-06-01T17:52:36.203413Z"}]}
{"channel":"book","type":"update","data":[{"symbol":"LINK/USDT","bids":[],"asks":[{"price":18.59107,"qty":0.00000000},{"price":18.59839,"qty":68.59000000}],"checksum":3872426524,"timestamp":"2024-06-01T17:52:36.203493Z"}]}
{"channel":"book","type":"update","data":[{"symbol":"LINK/USDT","bids":[{"price":18.57763,"qty":0.00000000},{"price":18.56585,"qty":99.84006900}],"asks":[],"checksum":2671743913,"timestamp":"2024-06-01T17:52:36.443707Z"}]}
{"channel":"book","type":"update","data":[{"symbol":"LINK/USDT","bids":[{"price":18.57769,"qty":40.39035409}],"asks":[],"checksum":2287956108,"timestamp":"2024-06-01T17:52:36.484253Z"}]}
{"channel":"book","type":"update","data":[{"symbol":"LINK/USDT","bids":[{"price":18.57971,"qty":0.00000000},{"price":18.56585,"qty":99.84006900}],"asks":[],"checksum":2900293544,"timestamp":"2024-06-01T17:52:36.523809Z"}]}
{"channel":"book","type":"update","data":[{"symbol":"LINK/USDT","bids":[],"asks":[{"price":18.59839,"qty":0.00000000},{"price":18.59840,"qty":107.62376872},{"price":18.59716,"qty":68.59000000}],"checksum":3548283765,"timestamp":"2024-06-01T17:52:36.527609Z"}]}
{"channel":"book","type":"update","data":[{"symbol":"LINK/USDT","bids":[{"price":18.57970,"qty":0.00000000},{"price":18.56580,"qty":134.65619580}],"asks":[],"checksum":524996294,"timestamp":"2024-06-01T17:52:36.545668Z"}]}
{"channel":"book","type":"update","data":[{"symbol":"LINK/USDT","bids":[],"asks":[{"price":18.58377,"qty":0.00000000},{"price":18.59840,"qty":107.62376872}],"checksum":1582130213,"timestamp":"2024-06-01T17:52:36.545727Z"}]}
{"channel":"book","type":"update","data":[{"symbol":"LINK/USDT","bids":[],"asks":[{"price":18.58968,"qty":4.84712503}],"checksum":716027580,"timestamp":"2024-06-01T17:52:36.548595Z"}]}
{"channel":"book","type":"update","data":[{"symbol":"LINK/USDT","bids":[{"price":18.57882,"qty":53.86854737}],"asks":[],"checksum":469699603,"timestamp":"2024-06-01T17:52:36.550360Z"}]}
{"channel":"book","type":"update","data":[{"symbol":"LINK/USDT","bids":[],"asks":[{"price":18.59031,"qty":0.00000000},{"price":18.59840,"qty":107.62376872}],"checksum":3326052670,"timestamp":"2024-06-01T17:52:36.550388Z"}]}
{"channel":"book","type":"update","data":[{"symbol":"LINK/USDT","bids":[],"asks":[{"price":18.59199,"qty":243.48672997}],"checksum":3250100067,"timestamp":"2024-06-01T17:52:36.561230Z"}]}
{"channel":"book","type":"update","data":[{"symbol":"LINK/USDT","bids":[],"asks":[{"price":18.58965,"qty":9.00000000}],"checksum":1277082407,"timestamp":"2024-06-01T17:52:36.566370Z"}]}
{"channel":"book","type":"update","data":[{"symbol":"LINK/USDT","bids":[],"asks":[{"price":18.58987,"qty":0.00000000},{"price":18.59717,"qty":50.49000000}],"checksum":2392636578,"timestamp":"2024-06-01T17:52:36.569161Z"}]}
{"channel":"book","type":"update","data":[{"symbol":"LINK/USDT","bids":[],"asks":[{"price":18.58896,"qty":9.40000000}],"checksum":4061910286,"timestamp":"2024-06-01T17:52:36.569342Z"}]}
{"channel":"book","type":"update","data":[{"symbol":"LINK/USDT","bids":[],"asks":[{"price":18.58893,"qty":9.00000000}],"checksum":697207028,"timestamp":"2024-06-01T17:52:36.583060Z"}]}
{"channel":"book","type":"update","data":[{"symbol":"LINK/USDT","bids":[],"asks":[{"price":18.58965,"qty":0.00000000},{"price":18.59716,"qty":68.59000000}],"checksum":1242636908,"timestamp":"2024-06-01T17:52:36.583139Z"}]}
{"channel":"book","type":"update","data":[{"symbol":"LINK/USDT","bids":[{"price":18.57882,"qty":0.00000000},{"price":18.56580,"qty":134.65619580}],"asks":[],"checksum":3930469439,"timestamp":"2024-06-01T17:52:36.610484Z"}]}
{"channel":"book","type":"update","data":[{"symbol":"LINK/USDT","bids":[{"price":18.56581,"qty":29.82000000}],"asks":[],"checksum":2602757405,"timestamp":"2024-06-01T17:52:36.614895Z"}]}
{"channel":"book","type":"update","data":[{"symbol":"LINK/USDT","bids":[{"price":18.56585,"qty":0.00000000},{"price":18.56580,"qty":134.65619580}],"asks":[],"checksum":291177967,"timestamp":"2024-06-01T17:52:36.615036Z"}]}
{"channel":"book","type":"update","data":[{"symbol":"LINK/USDT","bids":[],"asks":[{"price":18.58883,"qty":4.84730503}],"checksum":3094720678,"timestamp":"2024-06-01T17:52:36.615837Z"}]}
{"channel":"book","type":"update","data":[{"symbol":"LINK/USDT","bids":[],"asks":[{"price":18.59050,"qty":0.00000000},{"price":18.59716,"qty":68.59000000}],"checksum":605183541,"timestamp":"2024-06-01T17:52:36.616370Z"}]}
{"channel":"book","type":"update","data":[{"symbol":"LINK/USDT","bids":[],"asks":[{"price":18.58968,"qty":0.00000000},{"price":18.59717,"qty":50.49000000}],"checksum":3558621530,"timestamp":"2024-06-01T17:52:36.617638Z"}]}
{"channel":"book","type":"update","data":[{"symbol":"LINK/USDT","bids":[],"asks":[{"price":18.58896,"qty":0.00000000},{"price":18.59840,"qty":107.62376872}],"checksum":1646695982,"timestamp":"2024-06-01T17:52:36.618845Z"}]}
{"channel":"book","type":"update","data":[{"symbol":"LINK/USDT","bids":[],"asks":[{"price":18.58813,"qty":9.40000000}],"checksum":45758863,"timestamp":"2024-06-01T17:52:36.618937Z"}]}
{"channel":"book","type":"update","data":[{"symbol":"LINK/USDT","bids":[],"asks":[{"price":18.59552,"qty":0.00000000},{"price":18.59840,"qty":107.62376872}],"checksum":4115823431,"timestamp":"2024-06-01T17:52:36.621060Z"}]}
{"channel":"book","type":"update","data":[{"symbol":"LINK/USDT","bids":[{"price":18.56581,"qty":0.00000000},{"price":18.56321,"qty":269.56923869}],"asks":[],"checksum":1755627980,"timestamp":"2024-06-01T17:52:36.632048Z"}]}
{"channel":"book","type":"update","data":[{"symbol":"LINK/USDT","bids":[{"price":18.56581,"qty":99.84006900}],"asks":[],"checksum":1495345222,"timestamp":"2024-06-01T17:52:36.632385Z"}]}
{"channel":"book","type":"update","data":[{"symbol":"LINK/USDT","bids":[],"asks":[{"price":18.58959,"qty":53.83737558}],"checksum":403640139,"timestamp":"2024-06-01T17:52:36.710277Z"}]}
{"channel":"book","type":"update","data":[{"symbol":"LINK/USDT","bids":[],"asks":[{"price":18.58300,"qty":21.54259169}],"checksum":1946738343,"timestamp":"2024-06-01T17:52:36.710424Z"}]}
{"channel":"book","type":"update","data":[{"symbol":"LINK/USDT","bids":[],"asks":[{"price":18.58300,"qty":0.00000000},{"price":18.59717,"qty":50.49000000}],"checksum":403640139,"timestamp":"2024-06-01T17:52:36.714567Z"}]}
{"channel":"book","type":"update","data":[{"symbol":"LINK/USDT","bids":[{"price":18.58346,"qty":80.78267116}],"asks":[],"checksum":3727104355,"timestamp":"2024-06-01T17:52:36.843752Z"}]}
{"channel":"book","type":"update","data":[{"symbol":"LINK/USDT","bids":[{"price":18.57765,"qty":243.48672997}],"asks":[],"checksum":1031096097,"timestamp":"2024-06-01T17:52:36.847690Z"}]}
{"channel":"book","type":"update","data":[{"symbol":"LINK/USDT","bids":[],"asks":[{"price":18.58810,"qty":9.00000000}],"checksum":3981941837,"timestamp":"2024-06-01T17:52:36.849012Z"}]}
{"channel":"book","type":"update","data":[{"symbol":"LINK/USDT","bids":[{"price":18.57769,"qty":0.00000000},{"price":18.56581,"qty":99.84006900}],"asks":[],"checksum":3060266827,"timestamp":"2024-06-01T17:52:36.980114Z"}]}
{"channel":"book","type":"update","data":[{"symbol":"LINK/USDT","bids":[],"asks":[{"price":18.58893,"qty":0.00000000},{"price":18.59717,"qty":50.49000000}],"checksum":2313047931,"timestamp":"2024-06-01T17:52:36.984792Z"}]}
{"channel":"book","type":"update","data":[{"symbol":"LINK/USDT","bids":[{"price":18.57676,"qty":40.39252470}],"asks":[],"checksum":907257530,"timestamp":"2024-06-01T17:52:37.020558Z"}]}
{"channel":"book","type":"update","data":[{"symbol":"LINK/USDT","bids":[{"price":18.58346,"qty":0.00000000},{"price":18.56581,"qty":99.84006900}],"asks":[],"checksum":4156085652,"timestamp":"2024-06-01T17:52:37.339735Z"}]}
{"channel":"book","type":"update","data":[{"symbol":"LINK/USDT","bids":[{"price":18.57765,"qty":0.00000000},{"price":18.56580,"qty":134.65619580}],"asks":[],"checksum":648610461,"timestamp":"2024-06-01T17:52:37.343797Z"}]}
{"channel":"book","type":"update","data":[{"symbol":"LINK/USDT","bids":[{"price":18.57677,"qty":243.48672997}],"asks":[],"checksum":2387611876,"timestamp":"2024-06-01T17:52:37.343835Z"}]}
{"channel":"book","type":"update","data":[{"symbol":"LINK/USDT","bids":[],"asks":[{"price":18.58282,"qty":21.54279285}],"checksum":1868689395,"timestamp":"2024-06-01T17:52:37.344145Z"}]}
{"channel":"book","type":"update","data":[{"symbol":"LINK/USDT","bids":[{"price":18.57838,"qty":53.86983557}],"asks":[],"checksum":2121801076,"timestamp":"2024-06-01T17:52:37.344274Z"}]}
{"channel":"book","type":"update","data":[{"symbol":"LINK/USDT","bids":[{"price":18.58035,"qty":0.00000000},{"price":18.56581,"qty":99.84006900}],"asks":[],"checksum":559858164,"timestamp":"2024-06-01T17:52:37.346300Z"}]}
{"channel":"book","type":"update","data":[{"symbol":"LINK/USDT","bids":[{"price":18.57747,"qty":9.40000000}],"asks":[],"checksum":1243578149,"timestamp":"2024-06-01T17:52:37.346511Z"}]}
{"channel":"book","type":"update","data":[{"symbol":"LINK/USDT","bids":[{"price":18.57747,"qty":0.00000000},{"price":18.56581,"qty":99.84006900}],"asks":[],"checksum":559858164,"timestamp":"2024-06-01T17:52:37.347010Z"}]}
{"channel":"book","type":"update","data":[{"symbol":"LINK/USDT","bids":[{"price":18.57843,"qty":9.40000000}],"asks":[],"checksum":542521690,"timestamp":"2024-06-01T17:52:37.347051Z"}]}
{"channel":"book","type":"update","data":[{"symbol":"LINK/USDT","bids":[{"price":18.57838,"qty":0.00000000},{"price":18.56581,"qty":99.84006900}],"asks":[],"checksum":827313117,"timestamp":"2024-06-01T17:52:37.352415Z"}]}
{"channel":"book","type":"update","data":[{"symbol":"LINK/USDT","bids":[{"price":18.57676,"qty":0.00000000},{"price":18.56580,"qty":134.65619580}],"asks":[],"checksum":2558811355,"timestamp":"2024-06-01T17:52:37.593883Z"}]}
{"channel":"book","type":"update","data":[{"symbol":"LINK/USDT","bids":[{"price":18.57677,"qty":0.00000000},{"price":18.56321,"qty":269.56923869}],"asks":[],"checksum":2277952207,"timestamp":"2024-06-01T17:52:37.597861Z"}]}
{"channel":"book","type":"update","data":[{"symbol":"LINK/USDT","bids":[{"price":18.57616,"qty":243.48672997}],"asks":[],"checksum":3148293496,"timestamp":"2024-06-01T17:52:37.597893Z"}]}
{"channel":"book","type":"update","data":[{"symbol":"LINK/USDT","bids":[],"asks":[{"price":18.58282,"qty":0.00000000},{"price":18.59717,"qty":50.49000000}],"checksum":949326144,"timestamp":"2024-06-01T17:52:37.719036Z"}]}
{"channel":"book","type":"update","data":[{"symbol":"LINK/USDT","bids":[],"asks":[{"price":18.58801,"qty":21.53678192}],"checksum":3105706241,"timestamp":"2024-06-01T17:52:37.990427Z"}]}
{"channel":"book","type":"update","data":[{"symbol":"LINK/USDT","bids":[{"price":18.57801,"qty":53.87089583}],"asks":[],"checksum":1425255864,"timestamp":"2024-06-01T17:52:37.990552Z"}]}
{"channel":"book","type":"update","data":[{"symbol":"LINK/USDT","bids":[],"asks":[{"price":18.58801,"qty":0.00000000},{"price":18.59717,"qty":50.49000000}],"checksum":1646600556,"timestamp":"2024-06-01T17:52:37.996306Z"}]}
{"channel":"book","type":"update","data":[{"symbol":"LINK/USDT","bids":[{"price":18.57801,"qty":0.00000000},{"price":18.56580,"qty":134.65619580}],"asks":[],"checksum":949326144,"timestamp":"2024-06-01T17:52:37.997537Z"}]}
{"channel":"book","type":"update","data":[{"symbol":"LINK/USDT","bids":[],"asks":[{"price":18.58883,"qty":0.00000000},{"price":18.59840,"qty":107.62376872}],"checksum":1812353536,"timestamp":"2024-06-01T17:52:38.079873Z"}]}
{"channel":"book","type":"update","data":[{"symbol":"LINK/USDT","bids":[{"price":18.57846,"qty":9.00000000}],"asks":[],"checksum":3827772410,"timestamp":"2024-06-01T17:52:38.083905Z"}]}
{"channel":"book","type":"update","data":[{"symbol":"LINK/USDT","bids":[],"asks":[{"price":18.59716,"qty":0.00000000},{"price":18.60419,"qty":48.75805200}],"checksum":3626965267,"timestamp":"2024-06-01T17:52:38.105625Z"}]}
{"channel":"book","type":"update","data":[{"symbol":"LINK/USDT","bids":[{"price":18.57826,"qty":40.38923869}],"asks":[],"checksum":3456138682,"timestamp":"2024-06-01T17:52:38.202050Z"}]}
{"channel":"book","type":"update","data":[{"symbol":"LINK/USDT","bids":[],"asks":[{"price":18.59698,"qty":68.59000000}],"checksum":1053063076,"timestamp":"2024-06-01T17:52:38.206536Z"}]}
{"channel":"book","type":"update","data":[{"symbol":"LINK/USDT","bids":[{"price":18.57827,"qty":243.48672997}],"asks":[],"checksum":2529902725,"timestamp":"2024-06-01T17:52:38.207662Z"}]}
{"channel":"book","type":"update","data":[{"symbol":"LINK/USDT","bids":[{"price":18.57940,"qty":53.86688723}],"asks":[],"checksum":635788992,"timestamp":"2024-06-01T17:52:38.513666Z"}]}
{"channel":"book","type":"update","data":[{"symbol":"LINK/USDT","bids":[],"asks":[{"price":18.58801,"qty":21.53678236}],"checksum":4177203713,"timestamp":"2024-06-01T17:52:38.513804Z"}]}
{"channel":"book","type":"update","data":[{"symbol":"LINK/USDT","bids":[],"asks":[{"price":18.59500,"qty":0.00000000},{"price":18.59840,"qty":107.62376872}],"checksum":1409995187,"timestamp":"2024-06-01T17:52:38.514010Z"}]}
{"channel":"book","type":"update","data":[{"symbol":"LINK/USDT","bids":[{"price":18.57843,"qty":0.00000000},{"price":18.57300,"qty":38.56115452}],"asks":[],"checksum":1576877908,"timestamp":"2024-06-01T17:52:38.516330Z"}]}
{"channel":"book","type":"update","data":[{"symbol":"LINK/USDT","bids":[{"price":18.57982,"qty":9.40000000}],"asks":[],"checksum":1329122718,"timestamp":"2024-06-01T17:52:38.516766Z"}]}
{"channel":"book","type":"update","data":[{"symbol":"LINK/USDT","bids":[],"asks":[{"price":18.58801,"qty":0.00000000},{"price":18.60419,"qty":48.75805200}],"checksum":2054638291,"timestamp":"2024-06-01T17:52:38.518219Z"}]}
{"channel":"book","type":"update","data":[{"symbol":"LINK/USDT","bids":[],"asks":[{"price":18.58900,"qty":111.88604051}],"checksum":687705658,"timestamp":"2024-06-01T17:52:38.519118Z"}]}
{"channel":"book","type":"update","data":[{"symbol":"LINK/USDT","bids":[{"price":18.58445,"qty":80.77898302}],"asks":[],"checksum":4004871425,"timestamp":"2024-06-01T17:52:38.554560Z"}]}
{"channel":"book","type":"update","data":[{"symbol":"LINK/USDT","bids":[{"price":18.57616,"qty":0.00000000},{"price":18.57360,"qty":134.70925970}],"asks":[],"checksum":966910992,"timestamp":"2024-06-01T17:52:38.561481Z"}]}
{"channel":"book","type":"update","data":[{"symbol":"LINK/USDT","bids":[{"price":18.57940,"qty":0.00000000},{"price":18.57300,"qty":38.56115452}],"asks":[],"checksum":4216312300,"timestamp":"2024-06-01T17:52:38.739073Z"}]}
{"channel":"book","type":"update","data":[{"symbol":"LINK/USDT","bids":[{"price":18.57826,"qty":0.00000000},{"price":18.57240,"qty":33.73844400}],"asks":[],"checksum":4215666726,"timestamp":"2024-06-01T17:52:38.768215Z"}]}
{"channel":"book","type":"update","data":[{"symbol":"LINK/USDT","bids":[{"price":18.57773,"qty":40.39072126}],"asks":[],"checksum":1116832834,"timestamp":"2024-06-01T17:52:38.808234Z"}]}
{"channel":"book","type":"update","data":[{"symbol":"LINK/USDT","bids":[{"price":18.58445,"qty":0.00000000},{"price":18.57240,"qty":33.73844400}],"asks":[],"checksum":4134473357,"timestamp":"2024-06-01T17:52:39.130422Z"}]}
{"channel":"book","type":"update","data":[{"symbol":"LINK/USDT","bids":[{"price":18.57827,"qty":0.00000000},{"price":18.56581,"qty":99.84006900}],"asks":[],"checksum":1943716915,"timestamp":"2024-06-01T17:52:39.134483Z"}]}
{"channel":"book","type":"update","data":[{"symbol":"LINK/USDT","bids":[{"price":18.57774,"qty":243.48672997}],"asks":[],"checksum":765415374,"timestamp":"2024-06-01T17:52:39.134669Z"}]}
{"channel":"book","type":"update","data":[{"symbol":"LINK/USDT","bids":[],"asks":[{"price":18.58347,"qty":21.54204702}],"checksum":625324935,"timestamp":"2024-06-01T17:52:39.135418Z"}]}
{"channel":"book","type":"update","data":[{"symbol":"LINK/USDT","bids":[{"price":18.57886,"qty":53.86843328}],"asks":[],"checksum":554952450,"timestamp":"2024-06-01T17:52:39.135526Z"}]}
{"channel":"book","type":"update","data":[{"symbol":"LINK/USDT","bids":[{"price":18.57773,"qty":0.00000000},{"price":18.57240,"qty":33.73844400}],"asks":[],"checksum":2563218278,"timestamp":"2024-06-01T17:52:39.358849Z"}]}
{"channel":"book","type":"update","data":[{"symbol":"LINK/USDT","bids":[],"asks":[{"price":18.59698,"qty":0.00000000},{"price":18.59840,"qty":107.62376872},{"price":18.59716,"qty":68.59000000}],"checksum":535434017,"timestamp":"2024-06-01T17:52:39.362086Z"}]}
{"channel":"book","type":"update","data":[{"symbol":"LINK/USDT","bids":[{"price":18.57887,"qty":243.48672997}],"asks":[],"checksum":3451158338,"timestamp":"2024-06-01T17:52:39.362778Z"}]}
{"channel":"book","type":"update","data":[{"symbol":"LINK/USDT","bids":[{"price":18.57798,"qty":40.39035051}],"asks":[],"checksum":199984331,"timestamp":"2024-06-01T17:52:39.399322Z"}]}
{"channel":"book","type":"update","data":[{"symbol":"LINK/USDT","bids":[{"price":18.57774,"qty":0.00000000},{"price":18.57300,"qty":38.56115452}],"asks":[],"checksum":967945351,"timestamp":"2024-06-01T17:52:39.403701Z"}]}
{"channel":"book","type":"update","data":[{"symbol":"LINK/USDT","bids":[],"asks":[{"price":18.58347,"qty":0.00000000},{"price":18.59840,"qty":107.62376872}],"checksum":2055921790,"timestamp":"2024-06-01T17:52:39.527085Z"}]}
{"channel":"book","type":"update","data":[{"symbol":"LINK/USDT","bids":[{"price":18.58404,"qty":80.78135154}],"asks":[],"checksum":4039093838,"timestamp":"2024-06-01T17:52:39.823583Z"}]}
{"channel":"book","type":"update","data":[{"symbol":"LINK/USDT","bids":[],"asks":[{"price":18.58806,"qty":21.53671853}],"checksum":2294127788,"timestamp":"2024-06-01T17:52:39.828263Z"}]}
{"channel":"book","type":"update","data":[{"symbol":"LINK/USDT","bids":[],"asks":[{"price":18.58806,"qty":0.00000000},{"price":18.59840,"qty":107.62376872}],"checksum":4039093838,"timestamp":"2024-06-01T17:52:39.832156Z"}]}
{"channel":"book","type":"update","data":[{"symbol":"LINK/USDT","bids":[{"price":18.57798,"qty":0.00000000},{"price":18.57300,"qty":38.56115452}],"asks":[],"checksum":2856884904,"timestamp":"2024-06-01T17:52:39.965560Z"}]}
{"channel":"book","type":"update","data":[{"symbol":"LINK/USDT","bids":[{"price":18.57784,"qty":40.39067577}],"asks":[],"checksum":3962904708,"timestamp":"2024-06-01T17:52:40.006110Z"}]}
{"channel":"book","type":"update","data":[{"symbol":"LINK/USDT","bids":[{"price":18.58404,"qty":0.00000000},{"price":18.57300,"qty":38.56115452}],"asks":[],"checksum":3067914888,"timestamp":"2024-06-01T17:52:40.392039Z"}]}
{"channel":"book","type":"update","data":[{"symbol":"LINK/USDT","bids":[],"asks":[{"price":18.58298,"qty":21.54260892}],"checksum":3263227613,"timestamp":"2024-06-01T17:52:40.396287Z"}]}
{"channel":"book","type":"update","data":[{"symbol":"LINK/USDT","bids":[{"price":18.57784,"qty":0.00000000},{"price":18.57240,"qty":33.73844400}],"asks":[],"checksum":3954623203,"timestamp":"2024-06-01T17:52:40.576028Z"}]}
{"channel":"book","type":"update","data":[{"symbol":"LINK/USDT","bids":[{"price":18.57886,"qty":0.00000000},{"price":18.56581,"qty":99.84006900}],"asks":[],"checksum":471618780,"timestamp":"2024-06-01T17:52:40.800616Z"}]}
{"channel":"book","type":"update","data":[{"symbol":"LINK/USDT","bids":[],"asks":[{"price":18.58298,"qty":0.00000000},{"price":18.59840,"qty":107.62376872}],"checksum":1749031049,"timestamp":"2024-06-01T17:52:40.800678Z"}]}
{"channel":"book","type":"update","data":[{"symbol":"LINK/USDT","bids":[{"price":18.57887,"qty":0.00000000},{"price":18.56580,"qty":134.65619580}],"asks":[],"checksum":2320196924,"timestamp":"2024-06-01T17:52:40.805028Z"}]}
{"channel":"book","type":"update","data":[{"symbol":"LINK/USDT","bids":[{"price":18.57616,"qty":243.48672997}],"asks":[],"checksum":410993608,"timestamp":"2024-06-01T17:52:40.805218Z"}]}
{"channel":"book","type":"update","data":[{"symbol":"LINK/USDT","bids":[{"price":18.57808,"qty":53.87072010}],"asks":[],"checksum":3611796609,"timestamp":"2024-06-01T17:52:40.810143Z"}]}
{"channel":"book","type":"update","data":[{"symbol":"LINK/USDT","bids":[],"asks":[{"price":18.58802,"qty":21.53676841}],"checksum":3968239683,"timestamp":"2024-06-01T17:52:40.987257Z"}]}
{"channel":"book","type":"update","data":[{"symbol":"LINK/USDT","bids":[],"asks":[{"price":18.58802,"qty":0.00000000},{"price":18.59840,"qty":107.62376872}],"checksum":3611796609,"timestamp":"2024-06-01T17:52:40.991235Z"}]}
{"channel":"book","type":"update","data":[{"symbol":"LINK/USDT","bids":[{"price":18.57809,"qty":243.48672997}],"asks":[],"checksum":1933148417,"timestamp":"2024-06-01T17:52:40.991660Z"}]}
{"channel":"book","type":"update","data":[{"symbol":"LINK/USDT","bids":[],"asks":[{"price":18.58799,"qty":9.00000000}],"checksum":2566555984,"timestamp":"2024-06-01T17:52:40.992320Z"}]}
{"channel":"book","type":"update","data":[{"symbol":"LINK/USDT","bids":[{"price":18.58384,"qty":80.78267976}],"asks":[],"checksum":3197419919,"timestamp":"2024-06-01T17:52:41.018891Z"}]}
{"channel":"book","type":"update","data":[{"symbol":"LINK/USDT","bids":[{"price":18.57616,"qty":0.00000000},{"price":18.57300,"qty":38.56115452}],"asks":[],"checksum":3504375102,"timestamp":"2024-06-01T17:52:41.022476Z"}]}
{"channel":"book","type":"update","data":[{"symbol":"LINK/USDT","bids":[],"asks":[{"price":18.58799,"qty":0.00000000},{"price":18.59840,"qty":107.62376872}],"checksum":501148667,"timestamp":"2024-06-01T17:52:41.023749Z"}]}
{"channel":"book","type":"update","data":[{"symbol":"LINK/USDT","bids":[{"price":18.57764,"qty":40.39133535}],"asks":[],"checksum":23863232,"timestamp":"2024-06-01T17:52:41.082727Z"}]}
{"channel":"book","type":"update","data":[{"symbol":"LINK/USDT","bids":[{"price":18.58384,"qty":0.00000000},{"price":18.57300,"qty":38.56115452}],"asks":[],"checksum":3558620010,"timestamp":"2024-06-01T17:52:41.478148Z"}]}
{"channel":"book","type":"update","data":[{"symbol":"LINK/USDT","bids":[{"price":18.58403,"qty":80.78216502}],"asks":[],"checksum":3304345576,"timestamp":"2024-06-01T17:52:41.518561Z"}]}
{"channel":"book","type":"update","data":[{"symbol":"LINK/USDT","bids":[],"asks":[{"price":18.58806,"qty":21.53672022}],"checksum":1930961747,"timestamp":"2024-06-01T17:52:41.524613Z"}]}
{"channel":"book","type":"update","data":[{"symbol":"LINK/USDT","bids":[],"asks":[{"price":18.58806,"qty":0.00000000},{"price":18.59840,"qty":107.62376872}],"checksum":3304345576,"timestamp":"2024-06-01T17:52:41.528791Z"}]}
{"channel":"book","type":"update","data":[{"symbol":"LINK/USDT","bids":[{"price":18.57764,"qty":0.00000000},{"price":18.57300,"qty":38.56115452}],"asks":[],"checksum":3628514259,"timestamp":"2024-06-01T17:52:41.609112Z"}]}
{"channel":"book","type":"update","data":[{"symbol":"LINK/USDT","bids":[{"price":18.57783,"qty":40.39105761}],"asks":[],"checksum":1831998967,"timestamp":"2024-06-01T17:52:41.649565Z"}]}
{"channel":"book","type":"update","data":[{"symbol":"LINK/USDT","bids":[{"price":18.58403,"qty":0.00000000},{"price":18.57300,"qty":38.56115452}],"asks":[],"checksum":2145572036,"timestamp":"2024-06-01T17:52:42.044830Z"}]}
{"channel":"book","type":"update","data":[{"symbol":"LINK/USDT","bids":[],"asks":[{"price":18.58268,"qty":21.54296575}],"checksum":329445640,"timestamp":"2024-06-01T17:52:42.049623Z"}]}
{"channel":"book","type":"update","data":[{"symbol":"LINK/USDT","bids":[{"price":18.57783,"qty":0.00000000},{"price":18.57240,"qty":33.73844400}],"asks":[],"checksum":2375911074,"timestamp":"2024-06-01T17:52:42.175256Z"}]}
{"channel":"book","type":"update","data":[{"symbol":"LINK/USDT","bids":[{"price":18.57766,"qty":40.39108773}],"asks":[],"checksum":1440246744,"timestamp":"2024-06-01T17:52:42.676556Z"}]}
{"channel":"book","type":"update","data":[{"symbol":"LINK/USDT","bids":[{"price":18.57808,"qty":0.00000000},{"price":18.57240,"qty":33.73844400}],"asks":[],"checksum":77317882,"timestamp":"2024-06-01T17:52:43.089771Z"}]}
{"channel":"book","type":"update","data":[{"symbol":"LINK/USDT","bids":[{"price":18.57857,"qty":53.86929456}],"asks":[],"checksum":1446365234,"timestamp":"2024-06-01T17:52:43.092845Z"}]}
{"channel":"book","type":"update","data":[{"symbol":"LINK/USDT","bids":[{"price":18.57809,"qty":0.00000000},{"price":18.57240,"qty":33.73844400}],"asks":[],"checksum":3569366647,"timestamp":"2024-06-01T17:52:43.094016Z"}]}
{"channel":"book","type":"update","data":[{"symbol":"LINK/USDT","bids":[{"price":18.57767,"qty":243.48672997}],"asks":[],"checksum":4283028911,"timestamp":"2024-06-01T17:52:43.094027Z"}]}
{"channel":"book","type":"update","data":[{"symbol":"LINK/USDT","bids":[{"price":18.57766,"qty":0.00000000},{"price":18.57240,"qty":33.73844400}],"asks":[],"checksum":655112405,"timestamp":"2024-06-01T17:52:43.248919Z"}]}
{"channel":"book","type":"update","data":[{"symbol":"LINK/USDT","bids":[{"price":18.57858,"qty":243.48672997}],"asks":[],"checksum":2136201870,"timestamp":"2024-06-01T17:52:43.262301Z"}]}
{"channel":"book","type":"update","data":[{"symbol":"LINK/USDT","bids":[{"price":18.57762,"qty":40.39138817}],"asks":[],"checksum":3989124811,"timestamp":"2024-06-01T17:52:43.357223Z"}]}
{"channel":"book","type":"update","data":[{"symbol":"LINK/USDT","bids":[{"price":18.57767,"qty":0.00000000},{"price":18.57300,"qty":38.56115452}],"asks":[],"checksum":3176182333,"timestamp":"2024-06-01T17:52:43.558476Z"}]}
{"channel":"book","type":"update","data":[{"symbol":"LINK/USDT","bids":[{"price":18.57846,"qty":0.00000000},{"price":18.57240,"qty":33.73844400}],"asks":[],"checksum":2852862447,"timestamp":"2024-06-01T17:52:44.332098Z"}]}
{"channel":"book","type":"update","data":[{"symbol":"LINK/USDT","bids":[{"price":18.57300,"qty":0.00000000},{"price":18.56581,"qty":99.84006900}],"asks":[],"checksum":1804116653,"timestamp":"2024-06-01T17:52:44.332706Z"}]}
{"channel":"book","type":"update","data":[{"symbol":"LINK/USDT","bids":[{"price":18.57200,"qty":108.46358782}],"asks":[],"checksum":1045498867,"timestamp":"2024-06-01T17:52:44.337517Z"}]}
{"channel":"book","type":"update","data":[{"symbol":"LINK/USDT","bids":[{"price":18.57857,"qty":0.00000000},{"price":18.56581,"qty":99.84006900}],"asks":[],"checksum":4108536158,"timestamp":"2024-06-01T17:52:44.395119Z"}]}
{"channel":"book","type":"update","data":[{"symbol":"LINK/USDT","bids":[{"price":18.57807,"qty":53.87074106}],"asks":[],"checksum":2439884581,"timestamp":"2024-06-01T17:52:44.398835Z"}]}
{"channel":"book","type":"update","data":[{"symbol":"LINK/USDT","bids":[{"price":18.57858,"qty":0.00000000},{"price":18.56581,"qty":99.84006900}],"asks":[],"checksum":4222225953,"timestamp":"2024-06-01T17:52:44.399234Z"}]}
{"channel":"book","type":"update","data":[{"symbol":"LINK/USDT","bids":[{"price":18.57763,"qty":243.48672997}],"asks":[],"checksum":2538578597,"timestamp":"2024-06-01T17:52:44.399247Z"}]}
{"channel":"book","type":"update","data":[{"symbol":"LINK/USDT","bids":[],"asks":[{"price":18.58265,"qty":9.00000000}],"checksum":2179851988,"timestamp":"2024-06-01T17:52:44.399929Z"}]}
{"channel":"book","type":"update","data":[{"symbol":"LINK/USDT","bids":[],"asks":[{"price":18.58268,"qty":0.00000000},{"price":18.59717,"qty":50.49000000}],"checksum":776475529,"timestamp":"2024-06-01T17:52:44.403583Z"}]}
{"channel":"book","type":"update","data":[{"symbol":"LINK/USDT","bids":[],"asks":[{"price":18.58263,"qty":21.54302533}],"checksum":361601846,"timestamp":"2024-06-01T17:52:44.406661Z"}]}
{"channel":"book","type":"update","data":[{"symbol":"LINK/USDT","bids":[],"asks":[{"price":18.58265,"qty":0.00000000},{"price":18.59717,"qty":50.49000000}],"checksum":1247172697,"timestamp":"2024-06-01T17:52:44.409487Z"}]}
{"channel":"book","type":"update","data":[{"symbol":"LINK/USDT","bids":[{"price":18.57982,"qty":0.00000000},{"price":18.56581,"qty":99.84006900}],"asks":[],"checksum":270204879,"timestamp":"2024-06-01T17:52:44.432651Z"}]}
{"channel":"book","type":"update","data":[{"symbol":"LINK/USDT","bids":[{"price":18.57808,"qty":243.48672997}],"asks":[],"checksum":2172902399,"timestamp":"2024-06-01T17:52:44.450789Z"}]}
{"channel":"book","type":"update","data":[{"symbol":"LINK/USDT","bids":[{"price":18.57807,"qty":0.00000000},{"price":18.56581,"qty":99.84006900}],"asks":[],"checksum":2866783446,"timestamp":"2024-06-01T17:52:44.455920Z"}]}
{"channel":"book","type":"update","data":[{"symbol":"LINK/USDT","bids":[{"price":18.57762,"qty":0.00000000},{"price":18.56580,"qty":134.65619580}],"asks":[],"checksum":1498429748,"timestamp":"2024-06-01T17:52:44.543721Z"}]}
{"channel":"book","type":"update","data":[{"symbol":"LINK/USDT","bids":[{"price":18.57808,"qty":0.00000000},{"price":18.56321,"qty":269.56923869}],"asks":[],"checksum":2671524686,"timestamp":"2024-06-01T17:52:44.549296Z"}]}
{"channel":"book","type":"update","data":[{"symbol":"LINK/USDT","bids":[],"asks":[{"price":18.58260,"qty":9.00000000}],"checksum":2859317715,"timestamp":"2024-06-01T17:52:44.549644Z"}]}
{"channel":"book","type":"update","data":[{"symbol":"LINK/USDT","bids":[{"price":18.57775,"qty":9.40000000}],"asks":[],"checksum":2153659173,"timestamp":"2024-06-01T17:52:44.552345Z"}]}
