{"channel":"book","type":"update","data":[{"symbol":"LINK/USD","bids":[],"asks":[{"price":18.56980,"qty":0.00000000},{"price":18.57168,"qty":31.87500000}],"checksum":2997629718,"timestamp":"2024-06-01T17:52:51.953402Z"}]}
{"channel":"book","type":"update","data":[{"symbol":"LINK/USD","bids":[],"asks":[{"price":18.57144,"qty":0.00000000},{"price":18.57186,"qty":1.10230934}],"checksum":2668392151,"timestamp":"2024-06-01T17:52:51.968091Z"}]}
{"channel":"book","type":"update","data":[{"symbol":"LINK/USD","bids":[],"asks":[{"price":18.56934,"qty":0.00000000},{"price":18.57210,"qty":0.34717458}],"checksum":2834027301,"timestamp":"2024-06-01T17:52:51.991075Z"}]}
{"channel":"book","type":"update","data":[{"symbol":"LINK/USD","bids":[],"asks":[{"price":18.56933,"qty":0.00000000},{"price":18.57346,"qty":121.14061191},{"price":18.56994,"qty":1.50546674}],"checksum":1617397645,"timestamp":"2024-06-01T17:52:51.995127Z"}]}
{"channel":"book","type":"update","data":[{"symbol":"LINK/USD","bids":[{"price":18.56519,"qty":0.00000000},{"price":18.55981,"qty":31.87500000}],"asks":[],"checksum":1803849525,"timestamp":"2024-06-01T17:52:51.995147Z"}]}
{"channel":"book","type":"update","data":[{"symbol":"LINK/USD","bids":[],"asks":[{"price":18.56988,"qty":33.00000000}],"checksum":3724222925,"timestamp":"2024-06-01T17:52:52.000422Z"}]}
{"channel":"book","type":"update","data":[{"symbol":"LINK/USD","bids":[{"price":18.56523,"qty":243.48672997}],"asks":[],"checksum":2920926240,"timestamp":"2024-06-01T17:52:52.059853Z"}]}
{"channel":"book","type":"update","data":[{"symbol":"LINK/USD","bids":[{"price":18.56606,"qty":31.87500000}],"asks":[],"checksum":2409661940,"timestamp":"2024-06-01T17:52:52.063817Z"}]}
{"channel":"book","type":"update","data":[{"symbol":"LINK/USD","bids":[{"price":18.56606,"qty":0.00000000},{"price":18.56025,"qty":269.32548286}],"asks":[],"checksum":2920926240,"timestamp":"2024-06-01T17:52:52.101179Z"}]}
{"channel":"book","type":"update","data":[{"symbol":"LINK/USD","bids":[{"price":18.56582,"qty":31.87500000}],"asks":[],"checksum":3365038017,"timestamp":"2024-06-01T17:52:52.104962Z"}]}
{"channel":"book","type":"update","data":[{"symbol":"LINK/USD","bids":[{"price":18.56515,"qty":0.00000000},{"price":18.56025,"qty":269.32548286}],"asks":[],"checksum":3088213054,"timestamp":"2024-06-01T17:52:52.105220Z"}]}
{"channel":"book","type":"update","data":[{"symbol":"LINK/USD","bids":[],"asks":[{"price":18.57147,"qty":6.43107813}],"checksum":514064222,"timestamp":"2024-06-01T17:52:52.261443Z"}]}
{"channel":"book","type":"update","data":[{"symbol":"LINK/USD","bids":[{"price":18.56582,"qty":0.00000000},{"price":18.55981,"qty":31.87500000}],"asks":[],"checksum":2395096551,"timestamp":"2024-06-01T17:52:52.292985Z"}]}
{"channel":"book","type":"update","data":[{"symbol":"LINK/USD","bids":[{"price":18.56567,"qty":31.87500000}],"asks":[],"checksum":2174268231,"timestamp":"2024-06-01T17:52:52.296368Z"}]}
{"channel":"book","type":"update","data":[{"symbol":"LINK/USD","bids":[{"price":18.56567,"qty":0.00000000},{"price":18.55981,"qty":31.87500000}],"asks":[],"checksum":2395096551,"timestamp":"2024-06-01T17:52:52.307774Z"}]}
{"channel":"book","type":"update","data":[{"symbol":"LINK/USD","bids":[],"asks":[{"price":18.56980,"qty":31.87500000}],"checksum":780701211,"timestamp":"2024-06-01T17:52:52.308867Z"}]}
{"channel":"book","type":"update","data":[{"symbol":"LINK/USD","bids":[{"price":18.56522,"qty":31.87500000}],"asks":[],"checksum":1847294123,"timestamp":"2024-06-01T17:52:52.310802Z"}]}
{"channel":"book","type":"update","data":[{"symbol":"LINK/USD","bids":[{"price":18.56549,"qty":31.87500000}],"asks":[],"checksum":2786633740,"timestamp":"2024-06-01T17:52:52.310919Z"}]}
{"channel":"book","type":"update","data":[{"symbol":"LINK/USD","bids":[],"asks":[{"price":18.56988,"qty":0.00000000},{"price":18.57168,"qty":31.87500000}],"checksum":2432785222,"timestamp":"2024-06-01T17:52:52.311695Z"}]}
{"channel":"book","type":"update","data":[{"symbol":"LINK/USD","bids":[],"asks":[{"price":18.56946,"qty":33.00000000}],"checksum":3501055435,"timestamp":"2024-06-01T17:52:52.311984Z"}]}
{"channel":"book","type":"update","data":[{"symbol":"LINK/USD","bids":[],"asks":[{"price":18.56980,"qty":0.00000000},{"price":18.57168,"qty":31.87500000}],"checksum":2636235683,"timestamp":"2024-06-01T17:52:52.314042Z"}]}
{"channel":"book","type":"update","data":[{"symbol":"LINK/USD","bids":[{"price":18.56544,"qty":31.87500000}],"asks":[],"checksum":2037696325,"timestamp":"2024-06-01T17:52:52.314315Z"}]}
{"channel":"book","type":"update","data":[{"symbol":"LINK/USD","bids":[],"asks":[{"price":18.56980,"qty":31.87500000}],"checksum":1191966501,"timestamp":"2024-06-01T17:52:52.317970Z"}]}
{"channel":"book","type":"update","data":[{"symbol":"LINK/USD","bids":[{"price":18.56549,"qty":0.00000000},{"price":18.56025,"qty":269.32548286}],"asks":[],"checksum":1783623196,"timestamp":"2024-06-01T17:52:52.348102Z"}]}
{"channel":"book","type":"update","data":[{"symbol":"LINK/USD","bids":[],"asks":[{"price":18.56994,"qty":0.00000000},{"price":18.57168,"qty":31.87500000},{"price":18.56945,"qty":1.50546674}],"checksum":3783595463,"timestamp":"2024-06-01T17:52:52.350054Z"}]}
{"channel":"book","type":"update","data":[{"symbol":"LINK/USD","bids":[{"price":18.56544,"qty":0.00000000},{"price":18.55981,"qty":31.87500000}],"asks":[],"checksum":2472867511,"timestamp":"2024-06-01T17:52:52.351707Z"}]}
{"channel":"book","type":"update","data":[{"symbol":"LINK/USD","bids":[{"price":18.56533,"qty":31.87500000}],"asks":[],"checksum":1604637132,"timestamp":"2024-06-01T17:52:52.354875Z"}]}
{"channel":"book","type":"update","data":[{"symbol":"LINK/USD","bids":[],"asks":[{"price":18.56980,"qty":0.00000000},{"price":18.57168,"qty":31.87500000}],"checksum":1434440367,"timestamp":"2024-06-01T17:52:52.354926Z"}]}
{"channel":"book","type":"update","data":[{"symbol":"LINK/USD","bids":[{"price":18.56534,"qty":31.87500000}],"asks":[],"checksum":1691561544,"timestamp":"2024-06-01T17:52:52.358200Z"}]}
{"channel":"book","type":"update","data":[{"symbol":"LINK/USD","bids":[{"price":18.56534,"qty":0.00000000},{"price":18.56025,"qty":269.32548286}],"asks":[],"checksum":1434440367,"timestamp":"2024-06-01T17:52:52.361943Z"}]}
{"channel":"book","type":"update","data":[{"symbol":"LINK/USD","bids":[],"asks":[{"price":18.56980,"qty":31.87500000}],"checksum":1604637132,"timestamp":"2024-06-01T17:52:52.364823Z"}]}
{"channel":"book","type":"update","data":[{"symbol":"LINK/USD","bids":[{"price":18.56533,"qty":63.75000000}],"asks":[],"checksum":2731506963,"timestamp":"2024-06-01T17:52:52.368200Z"}]}
{"channel":"book","type":"update","data":[{"symbol":"LINK/USD","bids":[{"price":18.56533,"qty":31.87500000}],"asks":[],"checksum":1604637132,"timestamp":"2024-06-01T17:52:52.421953Z"}]}
{"channel":"book","type":"update","data":[{"symbol":"LINK/USD","bids":[{"price":18.56533,"qty":0.00000000},{"price":18.55981,"qty":31.87500000}],"asks":[],"checksum":2472867511,"timestamp":"2024-06-01T17:52:52.472354Z"}]}
{"channel":"book","type":"update","data":[{"symbol":"LINK/USD","bids":[{"price":18.56522,"qty":0.00000000},{"price":18.55910,"qty":83.16297525}],"asks":[],"checksum":1932816897,"timestamp":"2024-06-01T17:52:52.473064Z"}]}
{"channel":"book","type":"update","data":[{"symbol":"LINK/USD","bids":[{"price":18.56526,"qty":31.87500000}],"asks":[],"checksum":1487786444,"timestamp":"2024-06-01T17:52:52.476438Z"}]}
{"channel":"book","type":"update","data":[{"symbol":"LINK/USD","bids":[{"price":18.56523,"qty":0.00000000},{"price":18.55910,"qty":83.16297525}],"asks":[],"checksum":1373251102,"timestamp":"2024-06-01T17:52:52.477064Z"}]}
{"channel":"book","type":"update","data":[{"symbol":"LINK/USD","bids":[{"price":18.56517,"qty":243.48672997}],"asks":[],"checksum":2594205458,"timestamp":"2024-06-01T17:52:52.477172Z"}]}
{"channel":"book","type":"update","data":[{"symbol":"LINK/USD","bids":[{"price":18.56526,"qty":63.75000000}],"asks":[],"checksum":1741407181,"timestamp":"2024-06-01T17:52:52.488640Z"}]}
{"channel":"book","type":"update","data":[{"symbol":"LINK/USD","bids":[{"price":18.56526,"qty":31.87500000}],"asks":[],"checksum":2594205458,"timestamp":"2024-06-01T17:52:52.552508Z"}]}
{"channel":"book","type":"update","data":[{"symbol":"LINK/USD","bids":[{"price":18.56516,"qty":0.00000000},{"price":18.55910,"qty":83.16297525}],"asks":[],"checksum":2615166418,"timestamp":"2024-06-01T17:52:52.610858Z"}]}
{"channel":"book","type":"update","data":[{"symbol":"LINK/USD","bids":[{"price":18.56515,"qty":243.48672997}],"asks":[],"checksum":57588667,"timestamp":"2024-06-01T17:52:52.614995Z"}]}
{"channel":"book","type":"update","data":[{"symbol":"LINK/USD","bids":[{"price":18.56517,"qty":0.00000000},{"price":18.55910,"qty":83.16297525}],"asks":[],"checksum":3262261653,"timestamp":"2024-06-01T17:52:52.615008Z"}]}
{"channel":"book","type":"update","data":[{"symbol":"LINK/USD","bids":[{"price":18.56526,"qty":0.00000000},{"price":18.55780,"qty":19.45579109}],"asks":[],"checksum":40036837,"timestamp":"2024-06-01T17:52:52.618501Z"}]}
{"channel":"book","type":"update","data":[{"symbol":"LINK/USD","bids":[{"price":18.56515,"qty":275.36172997}],"asks":[],"checksum":733778814,"timestamp":"2024-06-01T17:52:52.687507Z"}]}
{"channel":"book","type":"update","data":[{"symbol":"LINK/USD","bids":[{"price":18.56522,"qty":31.87500000}],"asks":[],"checksum":723685509,"timestamp":"2024-06-01T17:52:52.709512Z"}]}
{"channel":"book","type":"update","data":[{"symbol":"LINK/USD","bids":[{"price":18.56515,"qty":243.48672997}],"asks":[],"checksum":2282779972,"timestamp":"2024-06-01T17:52:52.713670Z"}]}
{"channel":"book","type":"update","data":[{"symbol":"LINK/USD","bids":[{"price":18.56522,"qty":63.75000000}],"asks":[],"checksum":1971050907,"timestamp":"2024-06-01T17:52:52.718041Z"}]}
{"channel":"book","type":"update","data":[{"symbol":"LINK/USD","bids":[{"price":18.56523,"qty":243.48672997}],"asks":[],"checksum":1861879871,"timestamp":"2024-06-01T17:52:52.721840Z"}]}
{"channel":"book","type":"update","data":[{"symbol":"LINK/USD","bids":[{"price":18.56522,"qty":31.87500000}],"asks":[],"checksum":2782603333,"timestamp":"2024-06-01T17:52:52.725490Z"}]}
{"channel":"book","type":"update","data":[{"symbol":"LINK/USD","bids":[{"price":18.56524,"qty":31.87500000}],"asks":[],"checksum":3317859835,"timestamp":"2024-06-01T17:52:52.729198Z"}]}
{"channel":"book","type":"update","data":[{"symbol":"LINK/USD","bids":[{"price":18.56524,"qty":0.00000000},{"price":18.55981,"qty":31.87500000}],"asks":[],"checksum":2782603333,"timestamp":"2024-06-01T17:52:52.732981Z"}]}
{"channel":"book","type":"update","data":[{"symbol":"LINK/USD","bids":[{"price":18.56526,"qty":31.87500000}],"asks":[],"checksum":3171796468,"timestamp":"2024-06-01T17:52:52.736568Z"}]}
{"channel":"book","type":"update","data":[{"symbol":"LINK/USD","bids":[{"price":18.56526,"qty":0.00000000},{"price":18.55981,"qty":31.87500000}],"asks":[],"checksum":2782603333,"timestamp":"2024-06-01T17:52:52.782864Z"}]}
{"channel":"book","type":"update","data":[{"symbol":"LINK/USD","bids":[{"price":18.56523,"qty":0.00000000},{"price":18.55910,"qty":83.16297525}],"asks":[],"checksum":2282779972,"timestamp":"2024-06-01T17:52:52.786725Z"}]}
{"channel":"book","type":"update","data":[{"symbol":"LINK/USD","bids":[{"price":18.56522,"qty":63.75000000}],"asks":[],"checksum":1971050907,"timestamp":"2024-06-01T17:52:52.809760Z"}]}
{"channel":"book","type":"update","data":[{"symbol":"LINK/USD","bids":[{"price":18.56523,"qty":20.64921310}],"asks":[],"checksum":1878927221,"timestamp":"2024-06-01T17:52:53.047458Z"}]}
{"channel":"book","type":"update","data":[{"symbol":"LINK/USD","bids":[{"price":18.56537,"qty":31.87500000}],"asks":[],"checksum":2349041021,"timestamp":"2024-06-01T17:52:53.051025Z"}]}
{"channel":"book","type":"update","data":[{"symbol":"LINK/USD","bids":[],"asks":[{"price":18.56980,"qty":0.00000000},{"price":18.57168,"qty":31.87500000}],"checksum":2262337054,"timestamp":"2024-06-01T17:52:53.051210Z"}]}
{"channel":"book","type":"update","data":[{"symbol":"LINK/USD","bids":[{"price":18.56522,"qty":31.87500000}],"asks":[],"checksum":4068507228,"timestamp":"2024-06-01T17:52:53.051328Z"}]}
{"channel":"book","type":"update","data":[{"symbol":"LINK/USD","bids":[{"price":18.56539,"qty":31.87500000}],"asks":[],"checksum":2944197188,"timestamp":"2024-06-01T17:52:53.054804Z"}]}
{"channel":"book","type":"update","data":[{"symbol":"LINK/USD","bids":[{"price":18.56523,"qty":264.13594307}],"asks":[],"checksum":3486142672,"timestamp":"2024-06-01T17:52:53.058075Z"}]}
{"channel":"book","type":"update","data":[{"symbol":"LINK/USD","bids":[{"price":18.56539,"qty":0.00000000},{"price":18.56025,"qty":269.32548286}],"asks":[],"checksum":4233632333,"timestamp":"2024-06-01T17:52:53.058142Z"}]}
{"channel":"book","type":"update","data":[{"symbol":"LINK/USD","bids":[],"asks":[{"price":18.56980,"qty":31.87500000}],"checksum":686420396,"timestamp":"2024-06-01T17:52:53.060669Z"}]}
{"channel":"book","type":"update","data":[{"symbol":"LINK/USD","bids":[{"price":18.56537,"qty":0.00000000},{"price":18.55981,"qty":31.87500000}],"asks":[],"checksum":4103027244,"timestamp":"2024-06-01T17:52:53.061103Z"}]}
{"channel":"book","type":"update","data":[{"symbol":"LINK/USD","bids":[{"price":18.56530,"qty":31.87500000}],"asks":[],"checksum":1885803162,"timestamp":"2024-06-01T17:52:53.090157Z"}]}
{"channel":"book","type":"update","data":[{"symbol":"LINK/USD","bids":[{"price":18.56536,"qty":31.87500000}],"asks":[],"checksum":2629684454,"timestamp":"2024-06-01T17:52:53.090873Z"}]}
{"channel":"book","type":"update","data":[{"symbol":"LINK/USD","bids":[{"price":18.56536,"qty":0.00000000},{"price":18.56025,"qty":269.32548286}],"asks":[],"checksum":1885803162,"timestamp":"2024-06-01T17:52:53.093461Z"}]}
{"channel":"book","type":"update","data":[{"symbol":"LINK/USD","bids":[{"price":18.56523,"qty":20.64921310}],"asks":[],"checksum":519330306,"timestamp":"2024-06-01T17:52:53.093890Z"}]}
{"channel":"book","type":"update","data":[{"symbol":"LINK/USD","bids":[],"asks":[{"price":18.56980,"qty":0.00000000},{"price":18.57168,"qty":31.87500000}],"checksum":338647393,"timestamp":"2024-06-01T17:52:53.097414Z"}]}
{"channel":"book","type":"update","data":[{"symbol":"LINK/USD","bids":[{"price":18.56530,"qty":63.75000000}],"asks":[],"checksum":3913610686,"timestamp":"2024-06-01T17:52:53.098931Z"}]}
{"channel":"book","type":"update","data":[{"symbol":"LINK/USD","bids":[],"asks":[{"price":18.56980,"qty":31.87500000}],"checksum":3818911453,"timestamp":"2024-06-01T17:52:53.101124Z"}]}
{"channel":"book","type":"update","data":[{"symbol":"LINK/USD","bids":[],"asks":[{"price":18.56609,"qty":0.00000000},{"price":18.57168,"qty":31.87500000}],"checksum":1276444093,"timestamp":"2024-06-01T17:52:53.195852Z"}]}
{"channel":"book","type":"update","data":[{"symbol":"LINK/USD","bids":[],"asks":[{"price":18.57146,"qty":32.47017576}],"checksum":1400135247,"timestamp":"2024-06-01T17:52:53.199095Z"}]}
{"channel":"book","type":"update","data":[{"symbol":"LINK/USD","bids":[],"asks":[{"price":18.56608,"qty":0.00000000},{"price":18.57168,"qty":31.87500000}],"checksum":1255342968,"timestamp":"2024-06-01T17:52:53.200307Z"}]}
{"channel":"book","type":"update","data":[{"symbol":"LINK/USD","bids":[],"asks":[{"price":18.56980,"qty":0.00000000},{"price":18.57186,"qty":1.10230934}],"checksum":3049401115,"timestamp":"2024-06-01T17:52:53.203584Z"}]}
{"channel":"book","type":"update","data":[{"symbol":"LINK/USD","bids":[],"asks":[{"price":18.56944,"qty":13.46690837}],"checksum":1884160484,"timestamp":"2024-06-01T17:52:53.203598Z"}]}
{"channel":"book","type":"update","data":[{"symbol":"LINK/USD","bids":[],"asks":[{"price":18.56944,"qty":0.00000000},{"price":18.57186,"qty":1.10230934}],"checksum":3049401115,"timestamp":"2024-06-01T17:52:53.206662Z"}]}
{"channel":"book","type":"update","data":[{"symbol":"LINK/USD","bids":[],"asks":[{"price":18.56945,"qty":0.00000000},{"price":18.57210,"qty":0.34717458},{"price":18.56943,"qty":1.50546674}],"checksum":3574454828,"timestamp":"2024-06-01T17:52:53.206904Z"}]}
{"channel":"book","type":"update","data":[{"symbol":"LINK/USD","bids":[],"asks":[{"price":18.56982,"qty":31.87500000}],"checksum":194460824,"timestamp":"2024-06-01T17:52:53.207264Z"}]}
{"channel":"book","type":"update","data":[{"symbol":"LINK/USD","bids":[],"asks":[{"price":18.56943,"qty":0.00000000},{"price":18.57186,"qty":1.10230934},{"price":18.56944,"qty":1.50546674}],"checksum":834615436,"timestamp":"2024-06-01T17:52:53.210159Z"}]}
{"channel":"book","type":"update","data":[{"symbol":"LINK/USD","bids":[],"asks":[{"price":18.56944,"qty":0.00000000},{"price":18.57186,"qty":1.10230934},{"price":18.56945,"qty":1.50546674}],"checksum":3007993446,"timestamp":"2024-06-01T17:52:53.213034Z"}]}
{"channel":"book","type":"update","data":[{"symbol":"LINK/USD","bids":[{"price":18.56060,"qty":19.00000000}],"asks":[],"checksum":3330854755,"timestamp":"2024-06-01T17:52:53.397590Z"}]}
{"channel":"book","type":"update","data":[{"symbol":"LINK/USD","bids":[{"price":18.56026,"qty":0.00000000},{"price":18.56025,"qty":269.32548286}],"asks":[],"checksum":1827950239,"timestamp":"2024-06-01T17:52:53.400758Z"}]}
{"channel":"book","type":"update","data":[{"symbol":"LINK/USD","bids":[],"asks":[{"price":18.57146,"qty":0.00000000},{"price":18.57186,"qty":1.10230934}],"checksum":595703124,"timestamp":"2024-06-01T17:52:53.401262Z"}]}
{"channel":"book","type":"update","data":[{"symbol":"LINK/USD","bids":[],"asks":[{"price":18.56982,"qty":0.00000000},{"price":18.57210,"qty":0.34717458}],"checksum":2645618630,"timestamp":"2024-06-01T17:52:53.413667Z"}]}
{"channel":"book","type":"update","data":[{"symbol":"LINK/USD","bids":[],"asks":[{"price":18.56982,"qty":31.87500000}],"checksum":595703124,"timestamp":"2024-06-01T17:52:53.435052Z"}]}
{"channel":"book","type":"update","data":[{"symbol":"LINK/USD","bids":[],"asks":[{"price":18.56982,"qty":0.00000000},{"price":18.57210,"qty":0.34717458}],"checksum":2645618630,"timestamp":"2024-06-01T17:52:53.449798Z"}]}
{"channel":"book","type":"update","data":[{"symbol":"LINK/USD","bids":[],"asks":[{"price":18.56982,"qty":31.87500000}],"checksum":595703124,"timestamp":"2024-06-01T17:52:53.469349Z"}]}
{"channel":"book","type":"update","data":[{"symbol":"LINK/USD","bids":[],"asks":[{"price":18.56982,"qty":0.00000000},{"price":18.57210,"qty":0.34717458}],"checksum":2645618630,"timestamp":"2024-06-01T17:52:53.577406Z"}]}
{"channel":"book","type":"update","data":[{"symbol":"LINK/USD","bids":[{"price":18.56026,"qty":32.61107525}],"asks":[],"checksum":573176829,"timestamp":"2024-06-01T17:52:53.580933Z"}]}
{"channel":"book","type":"update","data":[{"symbol":"LINK/USD","bids":[],"asks":[{"price":18.56944,"qty":32.47017576}],"checksum":3576031196,"timestamp":"2024-06-01T17:52:53.581184Z"}]}
{"channel":"book","type":"update","data":[{"symbol":"LINK/USD","bids":[],"asks":[{"price":18.56946,"qty":0.00000000},{"price":18.57210,"qty":0.34717458}],"checksum":3951380380,"timestamp":"2024-06-01T17:52:53.584132Z"}]}
{"channel":"book","type":"update","data":[{"symbol":"LINK/USD","bids":[],"asks":[{"price":18.56927,"qty":33.00000000}],"checksum":2790830153,"timestamp":"2024-06-01T17:52:53.584579Z"}]}
{"channel":"book","type":"update","data":[{"symbol":"LINK/USD","bids":[],"asks":[{"price":18.56945,"qty":0.00000000},{"price":18.57210,"qty":0.34717458},{"price":18.56943,"qty":1.50546674}],"checksum":1738923461,"timestamp":"2024-06-01T17:52:53.584674Z"}]}
{"channel":"book","type":"update","data":[{"symbol":"LINK/USD","bids":[],"asks":[{"price":18.57147,"qty":0.00000000},{"price":18.57210,"qty":0.34717458}],"checksum":1880435719,"timestamp":"2024-06-01T17:52:53.602126Z"}]}
{"channel":"book","type":"update","data":[{"symbol":"LINK/USD","bids":[],"asks":[{"price":18.57168,"qty":0.00000000},{"price":18.57346,"qty":121.14061191}],"checksum":1068706385,"timestamp":"2024-06-01T17:52:53.634395Z"}]}
{"channel":"book","type":"update","data":[{"symbol":"LINK/USD","bids":[],"asks":[{"price":18.56995,"qty":0.00000000},{"price":18.57354,"qty":31.87500000}],"checksum":586628129,"timestamp":"2024-06-01T17:52:53.634684Z"}]}
{"channel":"book","type":"update","data":[{"symbol":"LINK/USD","bids":[],"asks":[{"price":18.56927,"qty":0.00000000},{"price":18.57359,"qty":0.34605497}],"checksum":1972301089,"timestamp":"2024-06-01T17:52:53.638096Z"}]}
{"channel":"book","type":"update","data":[{"symbol":"LINK/USD","bids":[{"price":18.56239,"qty":1077.24975568}],"asks":[],"checksum":4213405626,"timestamp":"2024-06-01T17:52:53.639437Z"}]}
{"channel":"book","type":"update","data":[{"symbol":"LINK/USD","bids":[{"price":18.56531,"qty":243.48672997}],"asks":[],"checksum":598415632,"timestamp":"2024-06-01T17:52:53.640103Z"}]}
{"channel":"book","type":"update","data":[{"symbol":"LINK/USD","bids":[],"asks":[{"price":18.57346,"qty":0.00000000},{"price":18.57466,"qty":0.40269630}],"checksum":676155423,"timestamp":"2024-06-01T17:52:53.643045Z"}]}
{"channel":"book","type":"update","data":[{"symbol":"LINK/USD","bids":[{"price":18.56245,"qty":0.00000000},{"price":18.56060,"qty":19.00000000}],"asks":[],"checksum":2434764662,"timestamp":"2024-06-01T17:52:53.643058Z"}]}
{"channel":"book","type":"update","data":[{"symbol":"LINK/USD","bids":[{"price":18.56609,"qty":31.87500000}],"asks":[],"checksum":3376666665,"timestamp":"2024-06-01T17:52:53.643789Z"}]}
{"channel":"book","type":"update","data":[{"symbol":"LINK/USD","bids":[{"price":18.56522,"qty":0.00000000},{"price":18.56060,"qty":19.00000000}],"asks":[],"checksum":1490040604,"timestamp":"2024-06-01T17:52:53.644233Z"}]}
{"channel":"book","type":"update","data":[{"symbol":"LINK/USD","bids":[{"price":18.56408,"qty":269.31243892}],"asks":[],"checksum":1961275658,"timestamp":"2024-06-01T17:52:53.645904Z"}]}
{"channel":"book","type":"update","data":[{"symbol":"LINK/USD","bids":[{"price":18.56457,"qty":269.33010431}],"asks":[],"checksum":3993182029,"timestamp":"2024-06-01T17:52:53.647334Z"}]}
{"channel":"book","type":"update","data":[{"symbol":"LINK/USD","bids":[],"asks":[{"price":18.56996,"qty":0.00000000},{"price":18.57685,"qty":1.31717222}],"checksum":30246540,"timestamp":"2024-06-01T17:52:53.656478Z"}]}
{"channel":"book","type":"update","data":[{"symbol":"LINK/USD","bids":[],"asks":[{"price":18.57123,"qty":33.00000000}],"checksum":877657413,"timestamp":"2024-06-01T17:52:53.659686Z"}]}
{"channel":"book","type":"update","data":[{"symbol":"LINK/USD","bids":[],"asks":[{"price":18.56943,"qty":0.00000000},{"price":18.57685,"qty":1.31717222}],"checksum":2864779604,"timestamp":"2024-06-01T17:52:53.659714Z"}]}
{"channel":"book","type":"update","data":[{"symbol":"LINK/USD","bids":[],"asks":[{"price":18.57123,"qty":0.00000000},{"price":18.57899,"qty":1.50546674}],"checksum":592363658,"timestamp":"2024-06-01T17:52:53.665947Z"}]}
{"channel":"book","type":"update","data":[{"symbol":"LINK/USD","bids":[{"price":18.56515,"qty":0.00000000},{"price":18.56239,"qty":1077.24975568}],"asks":[],"checksum":1813384657,"timestamp":"2024-06-01T17:52:53.670172Z"}]}
{"channel":"book","type":"update","data":[{"symbol":"LINK/USD","bids":[],"asks":[{"price":18.57345,"qty":6.43107813}],"checksum":2256943796,"timestamp":"2024-06-01T17:52:53.721947Z"}]}
{"channel":"book","type":"update","data":[{"symbol":"LINK/USD","bids":[{"price":18.56609,"qty":397.28269012}],"asks":[],"checksum":3444031265,"timestamp":"2024-06-01T17:52:53.773542Z"}]}
{"channel":"book","type":"update","data":[{"symbol":"LINK/USD","bids":[{"price":18.56609,"qty":640.76942009}],"asks":[],"checksum":4218365510,"timestamp":"2024-06-01T17:52:53.777983Z"}]}
{"channel":"book","type":"update","data":[{"symbol":"LINK/USD","bids":[{"price":18.56330,"qty":32.61107525}],"asks":[],"checksum":2904397507,"timestamp":"2024-06-01T17:52:53.842454Z"}]}
{"channel":"book","type":"update","data":[{"symbol":"LINK/USD","bids":[],"asks":[{"price":18.57345,"qty":0.00000000},{"price":18.57899,"qty":1.50546674}],"checksum":3899509319,"timestamp":"2024-06-01T17:52:53.859610Z"}]}
{"channel":"book","type":"update","data":[{"symbol":"LINK/USD","bids":[],"asks":[{"price":18.57158,"qty":0.00000000},{"price":18.57900,"qty":143.48604051}],"checksum":186785106,"timestamp":"2024-06-01T17:52:53.861901Z"}]}
{"channel":"book","type":"update","data":[{"symbol":"LINK/USD","bids":[],"asks":[{"price":18.57316,"qty":33.00000000}],"checksum":3861966684,"timestamp":"2024-06-01T17:52:53.864684Z"}]}
{"channel":"book","type":"update","data":[{"symbol":"LINK/USD","bids":[{"price":18.56531,"qty":0.00000000},{"price":18.56239,"qty":1077.24975568}],"asks":[],"checksum":1631663063,"timestamp":"2024-06-01T17:52:53.865535Z"}]}
{"channel":"book","type":"update","data":[{"symbol":"LINK/USD","bids":[],"asks":[{"price":18.57168,"qty":31.87500000}],"checksum":546059830,"timestamp":"2024-06-01T17:52:53.868894Z"}]}
{"channel":"book","type":"update","data":[{"symbol":"LINK/USD","bids":[],"asks":[{"price":18.57413,"qty":6.43107813}],"checksum":2299198974,"timestamp":"2024-06-01T17:52:53.980447Z"}]}
{"channel":"book","type":"update","data":[{"symbol":"LINK/USD","bids":[],"asks":[{"price":18.57167,"qty":1.50546674}],"checksum":3246735717,"timestamp":"2024-06-01T17:52:53.983555Z"}]}
{"channel":"book","type":"update","data":[{"symbol":"LINK/USD","bids":[{"price":18.56330,"qty":0.00000000},{"price":18.56194,"qty":38.00000000}],"asks":[],"checksum":1532837764,"timestamp":"2024-06-01T17:52:54.102976Z"}]}
{"channel":"book","type":"update","data":[{"symbol":"LINK/USD","bids":[],"asks":[{"price":18.57204,"qty":32.47017576}],"checksum":3149894183,"timestamp":"2024-06-01T17:52:54.178167Z"}]}
{"channel":"book","type":"update","data":[{"symbol":"LINK/USD","bids":[{"price":18.56330,"qty":30.99858996}],"asks":[],"checksum":989842898,"timestamp":"2024-06-01T17:52:54.215371Z"}]}
{"channel":"book","type":"update","data":[{"symbol":"LINK/USD","bids":[],"asks":[{"price":18.56943,"qty":13.46537225}],"checksum":1123132309,"timestamp":"2024-06-01T17:52:54.220004Z"}]}
{"channel":"book","type":"update","data":[{"symbol":"LINK/USD","bids":[],"asks":[{"price":18.57234,"qty":80.76529365}],"checksum":3297942894,"timestamp":"2024-06-01T17:52:54.630270Z"}]}
{"channel":"book","type":"update","data":[{"symbol":"LINK/USD","bids":[],"asks":[{"price":18.57168,"qty":0.00000000},{"price":18.57354,"qty":31.87500000}],"checksum":1095486909,"timestamp":"2024-06-01T17:52:54.680792Z"}]}
{"channel":"book","type":"update","data":[{"symbol":"LINK/USD","bids":[],"asks":[{"price":18.57167,"qty":0.00000000},{"price":18.57359,"qty":0.34605497},{"price":18.57203,"qty":1.50546674}],"checksum":1462446164,"timestamp":"2024-06-01T17:52:54.684017Z"}]}
{"channel":"book","type":"update","data":[{"symbol":"LINK/USD","bids":[{"price":18.56330,"qty":0.00000000},{"price":18.56194,"qty":19.00000000}],"asks":[],"checksum":3320165343,"timestamp":"2024-06-01T17:52:54.879815Z"}]}
{"channel":"book","type":"update","data":[{"symbol":"LINK/USD","bids":[],"asks":[{"price":18.57168,"qty":31.87500000}],"checksum":2057996032,"timestamp":"2024-06-01T17:52:55.041037Z"}]}
{"channel":"book","type":"update","data":[{"symbol":"LINK/USD","bids":[{"price":18.56458,"qty":30.99858996}],"asks":[],"checksum":3840627872,"timestamp":"2024-06-01T17:52:55.044101Z"}]}
{"channel":"book","type":"update","data":[{"symbol":"LINK/USD","bids":[],"asks":[{"price":18.57203,"qty":0.00000000},{"price":18.57354,"qty":31.87500000},{"price":18.57167,"qty":1.50546674}],"checksum":3357398341,"timestamp":"2024-06-01T17:52:55.078106Z"}]}
{"channel":"book","type":"update","data":[{"symbol":"LINK/USD","bids":[],"asks":[{"price":18.57168,"qty":0.00000000},{"price":18.57354,"qty":31.87500000}],"checksum":1304724886,"timestamp":"2024-06-01T17:52:55.201849Z"}]}
{"channel":"book","type":"update","data":[{"symbol":"LINK/USD","bids":[{"price":18.56458,"qty":0.00000000},{"price":18.56194,"qty":19.00000000}],"asks":[],"checksum":3548730934,"timestamp":"2024-06-01T17:52:55.203160Z"}]}
{"channel":"book","type":"update","data":[{"symbol":"LINK/USD","bids":[],"asks":[{"price":18.56944,"qty":0.00000000},{"price":18.57359,"qty":0.34605497}],"checksum":1426940007,"timestamp":"2024-06-01T17:52:55.203251Z"}]}
{"channel":"book","type":"update","data":[{"symbol":"LINK/USD","bids":[],"asks":[{"price":18.57167,"qty":0.00000000},{"price":18.57413,"qty":6.43107813},{"price":18.57203,"qty":1.50546674}],"checksum":1226661556,"timestamp":"2024-06-01T17:52:55.205117Z"}]}
{"channel":"book","type":"update","data":[{"symbol":"LINK/USD","bids":[],"asks":[{"price":18.56943,"qty":0.00000000},{"price":18.57413,"qty":6.43107813}],"checksum":1628107336,"timestamp":"2024-06-01T17:52:55.207154Z"}]}
{"channel":"book","type":"update","data":[{"symbol":"LINK/USD","bids":[{"price":18.56523,"qty":0.00000000},{"price":18.56043,"qty":404.08536050}],"asks":[],"checksum":2242608959,"timestamp":"2024-06-01T17:52:55.207406Z"}]}
{"channel":"book","type":"update","data":[{"symbol":"LINK/USD","bids":[],"asks":[{"price":18.57185,"qty":13.46531513}],"checksum":4098255960,"timestamp":"2024-06-01T17:52:55.210899Z"}]}
{"channel":"book","type":"update","data":[{"symbol":"LINK/USD","bids":[],"asks":[{"price":18.57185,"qty":0.00000000},{"price":18.57413,"qty":6.43107813}],"checksum":2242608959,"timestamp":"2024-06-01T17:52:55.214717Z"}]}
{"channel":"book","type":"update","data":[{"symbol":"LINK/USD","bids":[],"asks":[{"price":18.57413,"qty":0.00000000},{"price":18.57466,"qty":0.40269630}],"checksum":2359752922,"timestamp":"2024-06-01T17:52:55.233657Z"}]}
{"channel":"book","type":"update","data":[{"symbol":"LINK/USD","bids":[],"asks":[{"price":18.57204,"qty":0.00000000},{"price":18.57649,"qty":121.12089661}],"checksum":2946795625,"timestamp":"2024-06-01T17:52:55.299472Z"}]}
{"channel":"book","type":"update","data":[{"symbol":"LINK/USD","bids":[],"asks":[{"price":18.57203,"qty":0.00000000},{"price":18.57685,"qty":1.31717222},{"price":18.57233,"qty":1.50546674}],"checksum":128232191,"timestamp":"2024-06-01T17:52:55.302553Z"}]}
{"channel":"book","type":"update","data":[{"symbol":"LINK/USD","bids":[{"price":18.56531,"qty":30.99858996}],"asks":[],"checksum":1452875749,"timestamp":"2024-06-01T17:52:55.306045Z"}]}
{"channel":"book","type":"update","data":[{"symbol":"LINK/USD","bids":[],"asks":[{"price":18.57185,"qty":31.11381528}],"checksum":3464118635,"timestamp":"2024-06-01T17:52:55.306171Z"}]}
{"channel":"book","type":"update","data":[{"symbol":"LINK/USD","bids":[],"asks":[{"price":18.57233,"qty":0.00000000},{"price":18.57473,"qty":6.43107813},{"price":18.57184,"qty":1.50546674}],"checksum":3939116701,"timestamp":"2024-06-01T17:52:55.505502Z"}]}
{"channel":"book","type":"update","data":[{"symbol":"LINK/USD","bids":[],"asks":[{"price":18.57248,"qty":31.11381528}],"checksum":2133777528,"timestamp":"2024-06-01T17:52:55.605145Z"}]}
{"channel":"book","type":"update","data":[{"symbol":"LINK/USD","bids":[{"price":18.56531,"qty":0.00000000},{"price":18.56043,"qty":404.08536050}],"asks":[],"checksum":2301883077,"timestamp":"2024-06-01T17:52:55.630072Z"}]}
{"channel":"book","type":"update","data":[{"symbol":"LINK/USD","bids":[{"price":18.56330,"qty":30.99858996}],"asks":[],"checksum":2335662841,"timestamp":"2024-06-01T17:52:55.633340Z"}]}
{"channel":"book","type":"update","data":[{"symbol":"LINK/USD","bids":[{"price":18.56330,"qty":0.00000000},{"price":18.56043,"qty":404.08536050}],"asks":[],"checksum":2301883077,"timestamp":"2024-06-01T17:52:55.932365Z"}]}
{"channel":"book","type":"update","data":[{"symbol":"LINK/USD","bids":[{"price":18.56240,"qty":5.91267538}],"asks":[],"checksum":3110203420,"timestamp":"2024-06-01T17:52:56.346609Z"}]}
{"channel":"book","type":"update","data":[{"symbol":"LINK/USD","bids":[],"asks":[{"price":18.57183,"qty":13.46586248}],"checksum":492446236,"timestamp":"2024-06-01T17:52:56.351278Z"}]}
{"channel":"book","type":"update","data":[{"symbol":"LINK/USD","bids":[],"asks":[{"price":18.57184,"qty":0.00000000},{"price":18.57359,"qty":0.34605497},{"price":18.57182,"qty":1.50546674}],"checksum":2794515272,"timestamp":"2024-06-01T17:52:56.354344Z"}]}
{"channel":"book","type":"update","data":[{"symbol":"LINK/USD","bids":[],"asks":[{"price":18.57183,"qty":0.00000000},{"price":18.57359,"qty":0.34605497}],"checksum":2895041616,"timestamp":"2024-06-01T17:52:56.354831Z"}]}
{"channel":"book","type":"update","data":[{"symbol":"LINK/USD","bids":[],"asks":[{"price":18.57182,"qty":0.00000000},{"price":18.57466,"qty":0.40269630},{"price":18.57184,"qty":1.50546674}],"checksum":3110203420,"timestamp":"2024-06-01T17:52:56.358014Z"}]}
{"channel":"book","type":"update","data":[{"symbol":"LINK/USD","bids":[],"asks":[{"price":18.57181,"qty":13.46586248}],"checksum":1025471217,"timestamp":"2024-06-01T17:52:56.358848Z"}]}
{"channel":"book","type":"update","data":[{"symbol":"LINK/USD","bids":[{"price":18.56531,"qty":30.99858996}],"asks":[],"checksum":870668771,"timestamp":"2024-06-01T17:52:56.587605Z"}]}
{"channel":"book","type":"update","data":[{"symbol":"LINK/USD","bids":[],"asks":[{"price":18.57184,"qty":0.00000000},{"price":18.57359,"qty":0.34605497},{"price":18.57180,"qty":1.50546674}],"checksum":621313422,"timestamp":"2024-06-01T17:52:56.841073Z"}]}
{"channel":"book","type":"update","data":[{"symbol":"LINK/USD","bids":[],"asks":[{"price":18.57181,"qty":0.00000000},{"price":18.57359,"qty":0.34605497}],"checksum":402726585,"timestamp":"2024-06-01T17:52:56.845689Z"}]}
{"channel":"book","type":"update","data":[{"symbol":"LINK/USD","bids":[],"asks":[{"price":18.57180,"qty":0.00000000},{"price":18.57466,"qty":0.40269630},{"price":18.57184,"qty":1.50546674}],"checksum":3080444686,"timestamp":"2024-06-01T17:52:56.848913Z"}]}
{"channel":"book","type":"update","data":[{"symbol":"LINK/USD","bids":[],"asks":[{"price":18.57183,"qty":13.46589457}],"checksum":2898333168,"timestamp":"2024-06-01T17:52:57.970894Z"}]}
{"channel":"book","type":"update","data":[{"symbol":"LINK/USD","bids":[],"asks":[{"price":18.57184,"qty":0.00000000},{"price":18.57359,"qty":0.34605497},{"price":18.57182,"qty":1.50546674}],"checksum":3014731250,"timestamp":"2024-06-01T17:52:57.974110Z"}]}
{"channel":"book","type":"update","data":[{"symbol":"LINK/USD","bids":[],"asks":[{"price":18.57183,"qty":0.00000000},{"price":18.57359,"qty":0.34605497}],"checksum":2725576514,"timestamp":"2024-06-01T17:52:57.974695Z"}]}
{"channel":"book","type":"update","data":[{"symbol":"LINK/USD","bids":[],"asks":[{"price":18.57182,"qty":0.00000000},{"price":18.57466,"qty":0.40269630},{"price":18.57184,"qty":1.50546674}],"checksum":3080444686,"timestamp":"2024-06-01T17:52:57.977626Z"}]}
{"channel":"book","type":"update","data":[{"symbol":"LINK/USD","bids":[],"asks":[{"price":18.57181,"qty":13.46589457}],"checksum":2357484829,"timestamp":"2024-06-01T17:52:57.977937Z"}]}
{"channel":"book","type":"update","data":[{"symbol":"LINK/USD","bids":[],"asks":[{"price":18.57184,"qty":0.00000000},{"price":18.57359,"qty":0.34605497},{"price":18.57180,"qty":1.50546674}],"checksum":1054054438,"timestamp":"2024-06-01T17:52:58.440232Z"}]}
{"channel":"book","type":"update","data":[{"symbol":"LINK/USD","bids":[],"asks":[{"price":18.57181,"qty":0.00000000},{"price":18.57359,"qty":0.34605497}],"checksum":402726585,"timestamp":"2024-06-01T17:52:58.443914Z"}]}
{"channel":"book","type":"update","data":[{"symbol":"LINK/USD","bids":[],"asks":[{"price":18.57180,"qty":0.00000000},{"price":18.57466,"qty":0.40269630},{"price":18.57184,"qty":1.50546674}],"checksum":3080444686,"timestamp":"2024-06-01T17:52:58.446987Z"}]}
{"channel":"book","type":"update","data":[{"symbol":"LINK/USD","bids":[],"asks":[{"price":18.57179,"qty":13.46589498}],"checksum":1183776782,"timestamp":"2024-06-01T17:52:58.447015Z"}]}
{"channel":"book","type":"update","data":[{"symbol":"LINK/USD","bids":[],"asks":[{"price":18.57179,"qty":0.00000000},{"price":18.57359,"qty":0.34605497}],"checksum":3080444686,"timestamp":"2024-06-01T17:52:58.450903Z"}]}
{"channel":"book","type":"update","data":[{"symbol":"LINK/USD","bids":[],"asks":[{"price":18.57178,"qty":13.46589498}],"checksum":3138726744,"timestamp":"2024-06-01T17:52:58.453830Z"}]}
{"channel":"book","type":"update","data":[{"symbol":"LINK/USD","bids":[{"price":18.56240,"qty":0.00000000},{"price":18.56194,"qty":19.00000000}],"asks":[],"checksum":4247430729,"timestamp":"2024-06-01T17:52:58.694007Z"}]}
{"channel":"book","type":"update","data":[{"symbol":"LINK/USD","bids":[],"asks":[{"price":18.57184,"qty":0.00000000},{"price":18.57359,"qty":0.34605497},{"price":18.57177,"qty":1.50546674}],"checksum":731660551,"timestamp":"2024-06-01T17:52:58.973793Z"}]}
{"channel":"book","type":"update","data":[{"symbol":"LINK/USD","bids":[],"asks":[{"price":18.57178,"qty":0.00000000},{"price":18.57359,"qty":0.34605497}],"checksum":2976462786,"timestamp":"2024-06-01T17:52:58.977867Z"}]}
{"channel":"book","type":"update","data":[{"symbol":"LINK/USD","bids":[],"asks":[{"price":18.57177,"qty":0.00000000},{"price":18.57466,"qty":0.40269630},{"price":18.57184,"qty":1.50546674}],"checksum":2133777528,"timestamp":"2024-06-01T17:52:58.981139Z"}]}
{"channel":"book","type":"update","data":[{"symbol":"LINK/USD","bids":[{"price":18.56240,"qty":4.94558122}],"asks":[],"checksum":260516082,"timestamp":"2024-06-01T17:52:58.995173Z"}]}
{"channel":"book","type":"update","data":[{"symbol":"LINK/USD","bids":[],"asks":[{"price":18.57316,"qty":0.00000000},{"price":18.57466,"qty":0.40269630}],"checksum":153577891,"timestamp":"2024-06-01T17:52:59.214774Z"}]}
{"channel":"book","type":"update","data":[{"symbol":"LINK/USD","bids":[],"asks":[{"price":18.57210,"qty":33.34717458}],"checksum":879747306,"timestamp":"2024-06-01T17:52:59.214983Z"}]}
{"channel":"book","type":"update","data":[{"symbol":"LINK/USD","bids":[],"asks":[{"price":18.57210,"qty":0.34717458}],"checksum":153577891,"timestamp":"2024-06-01T17:52:59.353020Z"}]}
{"channel":"book","type":"update","data":[{"symbol":"LINK/USD","bids":[],"asks":[{"price":18.57184,"qty":34.50546674}],"checksum":3067730186,"timestamp":"2024-06-01T17:52:59.353304Z"}]}
{"channel":"book","type":"update","data":[{"symbol":"LINK/USD","bids":[],"asks":[{"price":18.57184,"qty":33.00000000},{"price":18.57183,"qty":1.50546674}],"checksum":1974511258,"timestamp":"2024-06-01T17:52:59.497234Z"}]}
{"channel":"book","type":"update","data":[{"symbol":"LINK/USD","bids":[{"price":18.56531,"qty":0.00000000},{"price":18.56194,"qty":19.00000000}],"asks":[],"checksum":944667242,"timestamp":"2024-06-01T17:52:59.522975Z"}]}
{"channel":"book","type":"update","data":[{"symbol":"LINK/USD","bids":[{"price":18.56330,"qty":32.52292563}],"asks":[],"checksum":3008668292,"timestamp":"2024-06-01T17:52:59.613520Z"}]}
{"channel":"book","type":"update","data":[{"symbol":"LINK/USD","bids":[],"asks":[{"price":18.57182,"qty":13.46589615}],"checksum":975783643,"timestamp":"2024-06-01T17:53:00.087874Z"}]}
{"channel":"book","type":"update","data":[{"symbol":"LINK/USD","bids":[],"asks":[{"price":18.57183,"qty":0.00000000},{"price":18.57359,"qty":0.34605497},{"price":18.57181,"qty":1.50546674}],"checksum":3521232015,"timestamp":"2024-06-01T17:53:00.090927Z"}]}
{"channel":"book","type":"update","data":[{"symbol":"LINK/USD","bids":[],"asks":[{"price":18.57182,"qty":0.00000000},{"price":18.57359,"qty":0.34605497}],"checksum":153174911,"timestamp":"2024-06-01T17:53:00.091786Z"}]}
{"channel":"book","type":"update","data":[{"symbol":"LINK/USD","bids":[],"asks":[{"price":18.57181,"qty":0.00000000},{"price":18.57466,"qty":0.40269630},{"price":18.57183,"qty":1.50546674}],"checksum":3008668292,"timestamp":"2024-06-01T17:53:00.094871Z"}]}
{"channel":"book","type":"update","data":[{"symbol":"LINK/USD","bids":[],"asks":[{"price":18.57180,"qty":13.46589690}],"checksum":1928389682,"timestamp":"2024-06-01T17:53:00.095247Z"}]}
{"channel":"book","type":"update","data":[{"symbol":"LINK/USD","bids":[{"price":18.56609,"qty":608.89442009}],"asks":[],"checksum":300184944,"timestamp":"2024-06-01T17:53:00.248829Z"}]}
{"channel":"book","type":"update","data":[{"symbol":"LINK/USD","bids":[{"price":18.56609,"qty":640.76942009}],"asks":[],"checksum":1928389682,"timestamp":"2024-06-01T17:53:00.266293Z"}]}
{"channel":"book","type":"update","data":[{"symbol":"LINK/USD","bids":[],"asks":[{"price":18.57183,"qty":0.00000000},{"price":18.57359,"qty":0.34605497},{"price":18.57179,"qty":1.50546674}],"checksum":3942356318,"timestamp":"2024-06-01T17:53:00.638585Z"}]}
{"channel":"book","type":"update","data":[{"symbol":"LINK/USD","bids":[],"asks":[{"price":18.57180,"qty":0.00000000},{"price":18.57359,"qty":0.34605497}],"checksum":2711451905,"timestamp":"2024-06-01T17:53:00.642654Z"}]}
