{"channel":"book","type":"snapshot","data":[{"symbol":"LINK/AUD","bids":[{"price":27.919,"qty":111.66962816},{"price":27.875,"qty":152.78339724},{"price":27.874,"qty":1.05652315},{"price":27.480,"qty":48.07660761},{"price":27.479,"qty":32.27896180},{"price":27.471,"qty":5.47881644},{"price":27.439,"qty":399.42746466},{"price":27.401,"qty":96.18636693},{"price":27.204,"qty":172.38343128},{"price":27.161,"qty":553.22087219}],"asks":[{"price":27.987,"qty":66.02683384},{"price":27.988,"qty":565.48604051},{"price":28.000,"qty":0.58050951},{"price":28.332,"qty":169.04532089},{"price":28.686,"qty":14.45373581},{"price":28.703,"qty":280.25905556},{"price":29.175,"qty":14.49148407},{"price":29.419,"qty":139.98930653},{"price":29.420,"qty":280.45931655},{"price":29.683,"qty":8.79324682}],"checksum":3797232056}]}
{"channel":"book","type":"update","data":[{"symbol":"LINK/AUD","bids":[{"price":27.874,"qty":0.00000000},{"price":27.132,"qty":56.59953183}],"asks":[],"checksum":3099020668,"timestamp":"2024-06-01T17:51:56.343013Z"}]}
{"channel":"book","type":"update","data":[{"symbol":"LINK/AUD","bids":[{"price":27.875,"qty":0.00000000},{"price":26.756,"qty":57.39492068}],"asks":[],"checksum":1346991259,"timestamp":"2024-06-01T17:51:56.356156Z"}]}
{"channel":"book","type":"update","data":[{"symbol":"LINK/AUD","bids":[{"price":27.481,"qty":154.97387649}],"asks":[],"checksum":1692183587,"timestamp":"2024-06-01T17:51:56.356203Z"}]}
{"channel":"book","type":"update","data":[{"symbol":"LINK/AUD","bids":[{"price":27.879,"qty":1.05698084}],"asks":[],"checksum":2925707383,"timestamp":"2024-06-01T17:51:56.440190Z"}]}
{"channel":"book","type":"update","data":[{"symbol":"LINK/AUD","bids":[{"price":27.479,"qty":0.00000000},{"price":27.132,"qty":56.59953183},{"price":27.482,"qty":32.27543815}],"asks":[],"checksum":3541475106,"timestamp":"2024-06-01T17:51:57.016042Z"}]}
{"channel":"book","type":"update","data":[{"symbol":"LINK/AUD","bids":[{"price":27.880,"qty":152.75599662}],"asks":[],"checksum":2972249134,"timestamp":"2024-06-01T17:51:57.039853Z"}]}
{"channel":"book","type":"update","data":[{"symbol":"LINK/AUD","bids":[{"price":27.481,"qty":0.00000000},{"price":27.161,"qty":553.22087219}],"asks":[],"checksum":20453541,"timestamp":"2024-06-01T17:51:57.039932Z"}]}
{"channel":"book","type":"update","data":[{"symbol":"LINK/AUD","bids":[],"asks":[{"price":29.419,"qty":0.00000000},{"price":29.709,"qty":14.45791686}],"checksum":3956597386,"timestamp":"2024-06-01T17:51:57.679634Z"}]}
{"channel":"book","type":"update","data":[{"symbol":"LINK/AUD","bids":[],"asks":[{"price":27.987,"qty":109.18107683}],"checksum":2376306059,"timestamp":"2024-06-01T17:51:59.639165Z"}]}
{"channel":"book","type":"update","data":[{"symbol":"LINK/AUD","bids":[],"asks":[{"price":27.987,"qty":43.15424299}],"checksum":3563570088,"timestamp":"2024-06-01T17:51:59.639281Z"}]}
{"channel":"book","type":"update","data":[{"symbol":"LINK/AUD","bids":[],"asks":[{"price":27.987,"qty":0.00000000},{"price":29.972,"qty":159.85687688}],"checksum":3438877628,"timestamp":"2024-06-01T17:52:00.065325Z"}]}
{"channel":"book","type":"update","data":[{"symbol":"LINK/AUD","bids":[],"asks":[{"price":27.987,"qty":29.69221778}],"checksum":1177868712,"timestamp":"2024-06-01T17:52:00.065637Z"}]}
{"channel":"book","type":"update","data":[{"symbol":"LINK/AUD","bids":[],"asks":[{"price":27.987,"qty":49.98498582}],"checksum":3645260580,"timestamp":"2024-06-01T17:52:00.111270Z"}]}
{"channel":"book","type":"update","data":[{"symbol":"LINK/AUD","bids":[],"asks":[{"price":27.987,"qty":20.29276804}],"checksum":3756356967,"timestamp":"2024-06-01T17:52:00.111290Z"}]}
{"channel":"book","type":"update","data":[{"symbol":"LINK/AUD","bids":[],"asks":[{"price":27.987,"qty":0.00000000},{"price":29.972,"qty":159.85687688}],"checksum":3438877628,"timestamp":"2024-06-01T17:52:00.139353Z"}]}
{"channel":"book","type":"update","data":[{"symbol":"LINK/AUD","bids":[],"asks":[{"price":27.987,"qty":20.29247147}],"checksum":2829161623,"timestamp":"2024-06-01T17:52:00.139612Z"}]}
{"channel":"book","type":"update","data":[{"symbol":"LINK/AUD","bids":[],"asks":[{"price":27.987,"qty":0.00000000},{"price":29.972,"qty":159.85687688}],"checksum":3438877628,"timestamp":"2024-06-01T17:52:01.100446Z"}]}
{"channel":"book","type":"update","data":[{"symbol":"LINK/AUD","bids":[],"asks":[{"price":27.987,"qty":41.82209594}],"checksum":4081443918,"timestamp":"2024-06-01T17:52:01.100591Z"}]}
{"channel":"book","type":"update","data":[{"symbol":"LINK/AUD","bids":[],"asks":[{"price":27.987,"qty":71.11285233}],"checksum":3576527988,"timestamp":"2024-06-01T17:52:01.138832Z"}]}
{"channel":"book","type":"update","data":[{"symbol":"LINK/AUD","bids":[],"asks":[{"price":27.987,"qty":29.29075639}],"checksum":2945065528,"timestamp":"2024-06-01T17:52:01.138872Z"}]}
{"channel":"book","type":"update","data":[{"symbol":"LINK/AUD","bids":[],"asks":[{"price":27.987,"qty":0.00000000},{"price":29.972,"qty":159.85687688}],"checksum":3438877628,"timestamp":"2024-06-01T17:52:01.793370Z"}]}
{"channel":"book","type":"update","data":[{"symbol":"LINK/AUD","bids":[],"asks":[{"price":27.987,"qty":67.53533064}],"checksum":3078323304,"timestamp":"2024-06-01T17:52:01.793543Z"}]}
{"channel":"book","type":"update","data":[{"symbol":"LINK/AUD","bids":[],"asks":[{"price":27.987,"qty":0.00000000},{"price":29.972,"qty":159.85687688}],"checksum":3438877628,"timestamp":"2024-06-01T17:52:02.068828Z"}]}
{"channel":"book","type":"update","data":[{"symbol":"LINK/AUD","bids":[],"asks":[{"price":27.987,"qty":33.75453600}],"checksum":2460921135,"timestamp":"2024-06-01T17:52:02.068997Z"}]}
{"channel":"book","type":"update","data":[{"symbol":"LINK/AUD","bids":[],"asks":[{"price":27.988,"qty":0.00000000},{"price":29.972,"qty":159.85687688}],"checksum":3637387696,"timestamp":"2024-06-01T17:52:02.407080Z"}]}
{"channel":"book","type":"update","data":[{"symbol":"LINK/AUD","bids":[],"asks":[{"price":27.986,"qty":540.09854051}],"checksum":3275098268,"timestamp":"2024-06-01T17:52:02.411944Z"}]}
{"channel":"book","type":"update","data":[{"symbol":"LINK/AUD","bids":[],"asks":[{"price":27.987,"qty":0.00000000},{"price":29.972,"qty":159.85687688}],"checksum":163917275,"timestamp":"2024-06-01T17:52:02.425766Z"}]}
{"channel":"book","type":"update","data":[{"symbol":"LINK/AUD","bids":[],"asks":[{"price":27.985,"qty":10.83770589}],"checksum":1789218600,"timestamp":"2024-06-01T17:52:02.425964Z"}]}
{"channel":"book","type":"update","data":[{"symbol":"LINK/AUD","bids":[],"asks":[{"price":27.985,"qty":0.00000000},{"price":29.972,"qty":159.85687688}],"checksum":163917275,"timestamp":"2024-06-01T17:52:02.974088Z"}]}
{"channel":"book","type":"update","data":[{"symbol":"LINK/AUD","bids":[],"asks":[{"price":27.985,"qty":10.83754151}],"checksum":4127914025,"timestamp":"2024-06-01T17:52:02.974161Z"}]}
{"channel":"book","type":"update","data":[{"symbol":"LINK/AUD","bids":[],"asks":[{"price":27.985,"qty":0.00000000},{"price":29.972,"qty":159.85687688}],"checksum":163917275,"timestamp":"2024-06-01T17:52:03.568876Z"}]}
{"channel":"book","type":"update","data":[{"symbol":"LINK/AUD","bids":[],"asks":[{"price":27.985,"qty":10.83721634}],"checksum":2679830738,"timestamp":"2024-06-01T17:52:03.568954Z"}]}
{"channel":"book","type":"update","data":[{"symbol":"LINK/AUD","bids":[{"price":27.919,"qty":5.74263669}],"asks":[],"checksum":3916244901,"timestamp":"2024-06-01T17:52:05.303334Z"}]}
{"channel":"book","type":"update","data":[{"symbol":"LINK/AUD","bids":[{"price":27.919,"qty":111.66962816}],"asks":[],"checksum":2679830738,"timestamp":"2024-06-01T17:52:05.306299Z"}]}
{"channel":"book","type":"update","data":[{"symbol":"LINK/AUD","bids":[],"asks":[{"price":27.985,"qty":35.53796670}],"checksum":2309574405,"timestamp":"2024-06-01T17:52:06.334018Z"}]}
{"channel":"book","type":"update","data":[{"symbol":"LINK/AUD","bids":[],"asks":[{"price":27.985,"qty":24.70075036}],"checksum":3683775623,"timestamp":"2024-06-01T17:52:06.334134Z"}]}
{"channel":"book","type":"update","data":[{"symbol":"LINK/AUD","bids":[],"asks":[{"price":27.985,"qty":0.00000000},{"price":29.972,"qty":159.85687688}],"checksum":163917275,"timestamp":"2024-06-01T17:52:06.521855Z"}]}
{"channel":"book","type":"update","data":[{"symbol":"LINK/AUD","bids":[],"asks":[{"price":27.985,"qty":46.23148825}],"checksum":2539679591,"timestamp":"2024-06-01T17:52:06.521911Z"}]}
{"channel":"book","type":"update","data":[{"symbol":"LINK/AUD","bids":[],"asks":[{"price":27.985,"qty":57.47105584}],"checksum":1305883753,"timestamp":"2024-06-01T17:52:06.567269Z"}]}
{"channel":"book","type":"update","data":[{"symbol":"LINK/AUD","bids":[],"asks":[{"price":27.985,"qty":11.23956759}],"checksum":2605729169,"timestamp":"2024-06-01T17:52:06.567583Z"}]}
{"channel":"book","type":"update","data":[{"symbol":"LINK/AUD","bids":[],"asks":[{"price":27.985,"qty":0.00000000},{"price":29.972,"qty":159.85687688}],"checksum":163917275,"timestamp":"2024-06-01T17:52:06.600052Z"}]}
{"channel":"book","type":"update","data":[{"symbol":"LINK/AUD","bids":[],"asks":[{"price":27.985,"qty":44.23887793}],"checksum":4091700589,"timestamp":"2024-06-01T17:52:06.600265Z"}]}
{"channel":"book","type":"update","data":[{"symbol":"LINK/AUD","bids":[],"asks":[{"price":27.985,"qty":0.00000000},{"price":29.972,"qty":159.85687688}],"checksum":163917275,"timestamp":"2024-06-01T17:52:06.667811Z"}]}
{"channel":"book","type":"update","data":[{"symbol":"LINK/AUD","bids":[],"asks":[{"price":27.985,"qty":44.23795243}],"checksum":3565518327,"timestamp":"2024-06-01T17:52:06.668195Z"}]}
{"channel":"book","type":"update","data":[{"symbol":"LINK/AUD","bids":[],"asks":[{"price":27.985,"qty":0.00000000},{"price":29.972,"qty":159.85687688}],"checksum":163917275,"timestamp":"2024-06-01T17:52:06.914578Z"}]}
{"channel":"book","type":"update","data":[{"symbol":"LINK/AUD","bids":[],"asks":[{"price":27.985,"qty":70.52987272}],"checksum":2107305434,"timestamp":"2024-06-01T17:52:06.914718Z"}]}
{"channel":"book","type":"update","data":[{"symbol":"LINK/AUD","bids":[],"asks":[{"price":27.985,"qty":0.00000000},{"price":29.972,"qty":159.85687688}],"checksum":163917275,"timestamp":"2024-06-01T17:52:17.722961Z"}]}
{"channel":"book","type":"update","data":[{"symbol":"LINK/AUD","bids":[],"asks":[{"price":27.985,"qty":45.48607823}],"checksum":2952807029,"timestamp":"2024-06-01T17:52:17.723041Z"}]}
{"channel":"book","type":"update","data":[{"symbol":"LINK/AUD","bids":[],"asks":[{"price":27.985,"qty":0.00000000},{"price":29.972,"qty":159.85687688}],"checksum":163917275,"timestamp":"2024-06-01T17:52:18.243092Z"}]}
{"channel":"book","type":"update","data":[{"symbol":"LINK/AUD","bids":[],"asks":[{"price":27.985,"qty":45.48573161}],"checksum":4079756519,"timestamp":"2024-06-01T17:52:18.243137Z"}]}
{"channel":"book","type":"update","data":[{"symbol":"LINK/AUD","bids":[],"asks":[{"price":27.986,"qty":0.00000000},{"price":29.972,"qty":159.85687688}],"checksum":272541116,"timestamp":"2024-06-01T17:52:18.246116Z"}]}
{"channel":"book","type":"update","data":[{"symbol":"LINK/AUD","bids":[],"asks":[{"price":27.985,"qty":399.94427212}],"checksum":3100560483,"timestamp":"2024-06-01T17:52:18.249374Z"}]}
{"channel":"book","type":"update","data":[{"symbol":"LINK/AUD","bids":[],"asks":[{"price":27.984,"qty":23.95584618}],"checksum":129874650,"timestamp":"2024-06-01T17:52:18.274760Z"}]}
{"channel":"book","type":"update","data":[{"symbol":"LINK/AUD","bids":[],"asks":[{"price":27.985,"qty":354.45854051}],"checksum":3823595827,"timestamp":"2024-06-01T17:52:18.274805Z"}]}
{"channel":"book","type":"update","data":[{"symbol":"LINK/AUD","bids":[],"asks":[{"price":27.984,"qty":69.44321037}],"checksum":418931488,"timestamp":"2024-06-01T17:52:18.291051Z"}]}
{"channel":"book","type":"update","data":[{"symbol":"LINK/AUD","bids":[],"asks":[{"price":27.984,"qty":45.48736419}],"checksum":1623801870,"timestamp":"2024-06-01T17:52:18.291065Z"}]}
{"channel":"book","type":"update","data":[{"symbol":"LINK/AUD","bids":[],"asks":[{"price":27.984,"qty":0.00000000},{"price":29.972,"qty":159.85687688}],"checksum":3248294703,"timestamp":"2024-06-01T17:52:18.648715Z"}]}
{"channel":"book","type":"update","data":[{"symbol":"LINK/AUD","bids":[],"asks":[{"price":27.984,"qty":45.48667808}],"checksum":1805133750,"timestamp":"2024-06-01T17:52:18.648922Z"}]}
{"channel":"book","type":"update","data":[{"symbol":"LINK/AUD","bids":[],"asks":[{"price":27.984,"qty":0.00000000},{"price":29.972,"qty":159.85687688}],"checksum":3248294703,"timestamp":"2024-06-01T17:52:18.666089Z"}]}
{"channel":"book","type":"update","data":[{"symbol":"LINK/AUD","bids":[],"asks":[{"price":27.984,"qty":44.03857918}],"checksum":3978037042,"timestamp":"2024-06-01T17:52:18.666304Z"}]}
{"channel":"book","type":"update","data":[{"symbol":"LINK/AUD","bids":[],"asks":[{"price":28.331,"qty":125.10904821}],"checksum":778518442,"timestamp":"2024-06-01T17:52:18.799832Z"}]}
{"channel":"book","type":"update","data":[{"symbol":"LINK/AUD","bids":[],"asks":[{"price":29.174,"qty":139.47703278}],"checksum":1917335952,"timestamp":"2024-06-01T17:52:18.799880Z"}]}
{"channel":"book","type":"update","data":[{"symbol":"LINK/AUD","bids":[],"asks":[{"price":27.984,"qty":0.00000000},{"price":29.683,"qty":8.79324682}],"checksum":3059768041,"timestamp":"2024-06-01T17:52:18.813202Z"}]}
{"channel":"book","type":"update","data":[{"symbol":"LINK/AUD","bids":[],"asks":[{"price":27.984,"qty":44.03857560}],"checksum":2146436888,"timestamp":"2024-06-01T17:52:18.813314Z"}]}
{"channel":"book","type":"update","data":[{"symbol":"LINK/AUD","bids":[],"asks":[{"price":27.984,"qty":0.00000000},{"price":29.683,"qty":8.79324682}],"checksum":3059768041,"timestamp":"2024-06-01T17:52:19.974274Z"}]}
{"channel":"book","type":"update","data":[{"symbol":"LINK/AUD","bids":[],"asks":[{"price":27.984,"qty":70.52987272}],"checksum":3324938153,"timestamp":"2024-06-01T17:52:19.974546Z"}]}
{"channel":"book","type":"update","data":[{"symbol":"LINK/AUD","bids":[],"asks":[{"price":27.984,"qty":0.00000000},{"price":29.683,"qty":8.79324682}],"checksum":3059768041,"timestamp":"2024-06-01T17:52:20.984847Z"}]}
{"channel":"book","type":"update","data":[{"symbol":"LINK/AUD","bids":[],"asks":[{"price":27.984,"qty":45.83182531}],"checksum":3279076606,"timestamp":"2024-06-01T17:52:20.984935Z"}]}
{"channel":"book","type":"update","data":[{"symbol":"LINK/AUD","bids":[{"price":27.919,"qty":5.74263669}],"asks":[],"checksum":1986933359,"timestamp":"2024-06-01T17:52:20.987555Z"}]}
{"channel":"book","type":"update","data":[{"symbol":"LINK/AUD","bids":[{"price":27.919,"qty":111.66962816}],"asks":[],"checksum":3279076606,"timestamp":"2024-06-01T17:52:20.994213Z"}]}
{"channel":"book","type":"update","data":[{"symbol":"LINK/AUD","bids":[],"asks":[{"price":27.984,"qty":0.00000000},{"price":29.683,"qty":8.79324682}],"checksum":3059768041,"timestamp":"2024-06-01T17:52:21.066400Z"}]}
{"channel":"book","type":"update","data":[{"symbol":"LINK/AUD","bids":[],"asks":[{"price":27.984,"qty":24.30031445}],"checksum":3224603501,"timestamp":"2024-06-01T17:52:21.066418Z"}]}
{"channel":"book","type":"update","data":[{"symbol":"LINK/AUD","bids":[],"asks":[{"price":27.984,"qty":0.00000000},{"price":29.683,"qty":8.79324682}],"checksum":3059768041,"timestamp":"2024-06-01T17:52:21.340930Z"}]}
{"channel":"book","type":"update","data":[{"symbol":"LINK/AUD","bids":[],"asks":[{"price":27.984,"qty":24.29994280}],"checksum":326805381,"timestamp":"2024-06-01T17:52:21.341076Z"}]}
{"channel":"book","type":"update","data":[{"symbol":"LINK/AUD","bids":[],"asks":[{"price":27.984,"qty":0.00000000},{"price":29.683,"qty":8.79324682}],"checksum":3059768041,"timestamp":"2024-06-01T17:52:21.671071Z"}]}
{"channel":"book","type":"update","data":[{"symbol":"LINK/AUD","bids":[],"asks":[{"price":27.984,"qty":24.29957829}],"checksum":692493760,"timestamp":"2024-06-01T17:52:21.671340Z"}]}
{"channel":"book","type":"update","data":[{"symbol":"LINK/AUD","bids":[],"asks":[{"price":27.984,"qty":0.00000000},{"price":29.683,"qty":8.79324682}],"checksum":3059768041,"timestamp":"2024-06-01T17:52:22.599432Z"}]}
{"channel":"book","type":"update","data":[{"symbol":"LINK/AUD","bids":[],"asks":[{"price":27.984,"qty":45.83108915}],"checksum":2058257017,"timestamp":"2024-06-01T17:52:22.599488Z"}]}
{"channel":"book","type":"update","data":[{"symbol":"LINK/AUD","bids":[],"asks":[{"price":27.984,"qty":0.00000000},{"price":29.683,"qty":8.79324682}],"checksum":3059768041,"timestamp":"2024-06-01T17:52:24.470289Z"}]}
{"channel":"book","type":"update","data":[{"symbol":"LINK/AUD","bids":[],"asks":[{"price":27.984,"qty":45.83104269}],"checksum":2675921789,"timestamp":"2024-06-01T17:52:24.470306Z"}]}
{"channel":"book","type":"update","data":[{"symbol":"LINK/AUD","bids":[],"asks":[{"price":27.984,"qty":0.00000000},{"price":29.683,"qty":8.79324682}],"checksum":3059768041,"timestamp":"2024-06-01T17:52:25.124053Z"}]}
{"channel":"book","type":"update","data":[{"symbol":"LINK/AUD","bids":[],"asks":[{"price":27.984,"qty":45.83072467}],"checksum":1197666828,"timestamp":"2024-06-01T17:52:25.124300Z"}]}
{"channel":"book","type":"update","data":[{"symbol":"LINK/AUD","bids":[{"price":27.161,"qty":0.00000000},{"price":27.132,"qty":56.59953183}],"asks":[],"checksum":1186561790,"timestamp":"2024-06-01T17:52:29.256576Z"}]}
{"channel":"book","type":"update","data":[{"symbol":"LINK/AUD","bids":[{"price":27.160,"qty":553.97978216}],"asks":[],"checksum":3189130828,"timestamp":"2024-06-01T17:52:29.296872Z"}]}
{"channel":"book","type":"update","data":[{"symbol":"LINK/AUD","bids":[],"asks":[{"price":27.984,"qty":116.36059739}],"checksum":127532801,"timestamp":"2024-06-01T17:52:30.807140Z"}]}
{"channel":"book","type":"update","data":[{"symbol":"LINK/AUD","bids":[],"asks":[{"price":27.984,"qty":70.52987272}],"checksum":1062876137,"timestamp":"2024-06-01T17:52:30.808353Z"}]}
{"channel":"book","type":"update","data":[{"symbol":"LINK/AUD","bids":[],"asks":[{"price":27.984,"qty":0.00000000},{"price":29.683,"qty":8.79324682}],"checksum":1326771881,"timestamp":"2024-06-01T17:52:31.082299Z"}]}
{"channel":"book","type":"update","data":[{"symbol":"LINK/AUD","bids":[],"asks":[{"price":27.984,"qty":67.47770151}],"checksum":2936527796,"timestamp":"2024-06-01T17:52:31.082718Z"}]}
{"channel":"book","type":"update","data":[{"symbol":"LINK/AUD","bids":[],"asks":[{"price":27.985,"qty":0.00000000},{"price":29.683,"qty":8.79324682}],"checksum":2293766996,"timestamp":"2024-06-01T17:52:34.709260Z"}]}
{"channel":"book","type":"update","data":[{"symbol":"LINK/AUD","bids":[],"asks":[{"price":27.983,"qty":664.24354051}],"checksum":832894225,"timestamp":"2024-06-01T17:52:34.713978Z"}]}
{"channel":"book","type":"update","data":[{"symbol":"LINK/AUD","bids":[],"asks":[{"price":27.982,"qty":70.52987272}],"checksum":2539251008,"timestamp":"2024-06-01T17:52:34.718426Z"}]}
{"channel":"book","type":"update","data":[{"symbol":"LINK/AUD","bids":[],"asks":[{"price":27.984,"qty":0.00000000},{"price":29.420,"qty":280.45931655}],"checksum":2443101695,"timestamp":"2024-06-01T17:52:34.718510Z"}]}
{"channel":"book","type":"update","data":[{"symbol":"LINK/AUD","bids":[],"asks":[{"price":27.982,"qty":124.35241219}],"checksum":911826807,"timestamp":"2024-06-01T17:52:35.851988Z"}]}
{"channel":"book","type":"update","data":[{"symbol":"LINK/AUD","bids":[],"asks":[{"price":27.982,"qty":53.82253947}],"checksum":2886201454,"timestamp":"2024-06-01T17:52:35.852020Z"}]}
{"channel":"book","type":"update","data":[{"symbol":"LINK/AUD","bids":[],"asks":[{"price":27.982,"qty":0.00000000},{"price":29.683,"qty":8.79324682}],"checksum":4219051051,"timestamp":"2024-06-01T17:52:36.203144Z"}]}
{"channel":"book","type":"update","data":[{"symbol":"LINK/AUD","bids":[],"asks":[{"price":27.982,"qty":32.28961117}],"checksum":3234614745,"timestamp":"2024-06-01T17:52:36.203286Z"}]}
{"channel":"book","type":"update","data":[{"symbol":"LINK/AUD","bids":[{"price":27.919,"qty":5.74263669}],"asks":[],"checksum":1294280343,"timestamp":"2024-06-01T17:52:36.206028Z"}]}
{"channel":"book","type":"update","data":[{"symbol":"LINK/AUD","bids":[{"price":27.919,"qty":97.97210419}],"asks":[],"checksum":1895681160,"timestamp":"2024-06-01T17:52:36.209100Z"}]}
{"channel":"book","type":"update","data":[{"symbol":"LINK/AUD","bids":[],"asks":[{"price":27.982,"qty":0.00000000},{"price":29.683,"qty":8.79324682}],"checksum":2869753512,"timestamp":"2024-06-01T17:52:36.233557Z"}]}
{"channel":"book","type":"update","data":[{"symbol":"LINK/AUD","bids":[],"asks":[{"price":27.982,"qty":53.82240367}],"checksum":1892195416,"timestamp":"2024-06-01T17:52:36.233666Z"}]}
{"channel":"book","type":"update","data":[{"symbol":"LINK/AUD","bids":[{"price":27.483,"qty":38.47371304}],"asks":[],"checksum":2807445718,"timestamp":"2024-06-01T17:52:36.478283Z"}]}
{"channel":"book","type":"update","data":[{"symbol":"LINK/AUD","bids":[{"price":27.480,"qty":9.61532152}],"asks":[],"checksum":3017846455,"timestamp":"2024-06-01T17:52:36.479176Z"}]}
{"channel":"book","type":"update","data":[{"symbol":"LINK/AUD","bids":[{"price":27.480,"qty":0.00000000},{"price":27.160,"qty":553.97978216}],"asks":[],"checksum":907790479,"timestamp":"2024-06-01T17:52:36.479846Z"}]}
{"channel":"book","type":"update","data":[{"symbol":"LINK/AUD","bids":[{"price":27.472,"qty":9.61841790}],"asks":[],"checksum":449644202,"timestamp":"2024-06-01T17:52:36.480012Z"}]}
{"channel":"book","type":"update","data":[{"symbol":"LINK/AUD","bids":[],"asks":[{"price":27.982,"qty":0.00000000},{"price":29.683,"qty":8.79324682}],"checksum":3555104742,"timestamp":"2024-06-01T17:52:36.733090Z"}]}
{"channel":"book","type":"update","data":[{"symbol":"LINK/AUD","bids":[],"asks":[{"price":27.982,"qty":70.52987272}],"checksum":1104789309,"timestamp":"2024-06-01T17:52:36.733285Z"}]}
{"channel":"book","type":"update","data":[{"symbol":"LINK/AUD","bids":[{"price":27.482,"qty":0.00000000},{"price":27.160,"qty":553.97978216},{"price":27.484,"qty":32.27308947}],"asks":[],"checksum":496908900,"timestamp":"2024-06-01T17:52:43.525435Z"}]}
{"channel":"book","type":"update","data":[{"symbol":"LINK/AUD","bids":[],"asks":[{"price":28.331,"qty":0.00000000},{"price":29.683,"qty":8.79324682}],"checksum":1584723232,"timestamp":"2024-06-01T17:52:45.645703Z"}]}
{"channel":"book","type":"update","data":[{"symbol":"LINK/AUD","bids":[],"asks":[{"price":29.174,"qty":0.00000000},{"price":29.709,"qty":14.45791686}],"checksum":716410928,"timestamp":"2024-06-01T17:52:45.645722Z"}]}
{"channel":"book","type":"update","data":[{"symbol":"LINK/AUD","bids":[],"asks":[{"price":27.983,"qty":0.00000000},{"price":29.972,"qty":159.85687688}],"checksum":1197652649,"timestamp":"2024-06-01T17:52:51.917238Z"}]}
{"channel":"book","type":"update","data":[{"symbol":"LINK/AUD","bids":[{"price":27.919,"qty":5.74263669}],"asks":[],"checksum":1110861143,"timestamp":"2024-06-01T17:52:51.917288Z"}]}
{"channel":"book","type":"update","data":[{"symbol":"LINK/AUD","bids":[],"asks":[{"price":27.982,"qty":734.77341323}],"checksum":2676164470,"timestamp":"2024-06-01T17:52:51.921656Z"}]}
{"channel":"book","type":"update","data":[{"symbol":"LINK/AUD","bids":[{"price":27.919,"qty":97.97210419}],"asks":[],"checksum":198582165,"timestamp":"2024-06-01T17:52:51.922023Z"}]}
{"channel":"book","type":"update","data":[{"symbol":"LINK/AUD","bids":[],"asks":[{"price":27.982,"qty":664.24354051}],"checksum":1973797194,"timestamp":"2024-06-01T17:52:55.210342Z"}]}
{"channel":"book","type":"update","data":[{"symbol":"LINK/AUD","bids":[],"asks":[{"price":27.981,"qty":9.04392265}],"checksum":3335620161,"timestamp":"2024-06-01T17:52:55.210472Z"}]}
{"channel":"book","type":"update","data":[{"symbol":"LINK/AUD","bids":[],"asks":[{"price":29.420,"qty":0.00000000},{"price":29.972,"qty":159.85687688}],"checksum":2075203241,"timestamp":"2024-06-01T17:52:55.236261Z"}]}
{"channel":"book","type":"update","data":[{"symbol":"LINK/AUD","bids":[],"asks":[{"price":29.396,"qty":279.41071600}],"checksum":1643077964,"timestamp":"2024-06-01T17:52:55.276397Z"}]}
{"channel":"book","type":"update","data":[{"symbol":"LINK/AUD","bids":[],"asks":[{"price":27.981,"qty":0.00000000},{"price":29.972,"qty":159.85687688}],"checksum":3850191071,"timestamp":"2024-06-01T17:52:55.486965Z"}]}
