{"channel":"book","type":"snapshot","data":[{"symbol":"LINK/ETH","bids":[{"price":0.00489103,"qty":4.84477431},{"price":0.00489098,"qty":131.75171000},{"price":0.00489049,"qty":26.92967047},{"price":0.00488968,"qty":21.54021854},{"price":0.00488940,"qty":71.53689000},{"price":0.00488851,"qty":26.94094096},{"price":0.00488546,"qty":438.16674000},{"price":0.00488545,"qty":26.96042794},{"price":0.00488493,"qty":0.51861120},{"price":0.00486827,"qty":42.55533458}],"asks":[{"price":0.00489363,"qty":8.07373589},{"price":0.00489441,"qty":21.53911780},{"price":0.00489567,"qty":8.07207320},{"price":0.00489789,"qty":8.07005820},{"price":0.00490596,"qty":70.52987272},{"price":0.00490597,"qty":71.53689000},{"price":0.00490808,"qty":0.51224694},{"price":0.00491908,"qty":131.75171000},{"price":0.00491974,"qty":224.04881200},{"price":0.00491975,"qty":438.16674000}],"checksum":3011023929}]}
{"channel":"book","type":"update","data":[{"symbol":"LINK/ETH","bids":[],"asks":[{"price":0.00491908,"qty":0.00000000},{"price":0.00492260,"qty":101.61891050}],"checksum":1946565529,"timestamp":"2024-06-01T17:51:54.577007Z"}]}
{"channel":"book","type":"update","data":[{"symbol":"LINK/ETH","bids":[{"price":0.00489098,"qty":0.00000000},{"price":0.00486826,"qty":263.85422000}],"asks":[],"checksum":4150503764,"timestamp":"2024-06-01T17:51:54.577146Z"}]}
{"channel":"book","type":"update","data":[{"symbol":"LINK/ETH","bids":[{"price":0.00486826,"qty":0.00000000},{"price":0.00486824,"qty":807.74508336}],"asks":[],"checksum":3363536658,"timestamp":"2024-06-01T17:51:54.577374Z"}]}
{"channel":"book","type":"update","data":[{"symbol":"LINK/ETH","bids":[],"asks":[{"price":0.00491907,"qty":131.75171000}],"checksum":1436136729,"timestamp":"2024-06-01T17:51:54.579635Z"}]}
{"channel":"book","type":"update","data":[{"symbol":"LINK/ETH","bids":[{"price":0.00489104,"qty":131.75171000}],"asks":[],"checksum":1233307103,"timestamp":"2024-06-01T17:51:54.579941Z"}]}
{"channel":"book","type":"update","data":[{"symbol":"LINK/ETH","bids":[{"price":0.00486828,"qty":263.85422000}],"asks":[],"checksum":1379337605,"timestamp":"2024-06-01T17:51:54.580734Z"}]}
{"channel":"book","type":"update","data":[{"symbol":"LINK/ETH","bids":[{"price":0.00489109,"qty":4.84496314}],"asks":[],"checksum":2896138234,"timestamp":"2024-06-01T17:51:54.582686Z"}]}
{"channel":"book","type":"update","data":[{"symbol":"LINK/ETH","bids":[{"price":0.00489103,"qty":0.00000000},{"price":0.00486828,"qty":263.85422000}],"asks":[],"checksum":1633539674,"timestamp":"2024-06-01T17:51:54.583301Z"}]}
{"channel":"book","type":"update","data":[{"symbol":"LINK/ETH","bids":[{"price":0.00486829,"qty":42.55515977}],"asks":[],"checksum":2277520456,"timestamp":"2024-06-01T17:51:54.591585Z"}]}
{"channel":"book","type":"update","data":[{"symbol":"LINK/ETH","bids":[{"price":0.00489049,"qty":0.00000000},{"price":0.00486828,"qty":1030.95571463}],"asks":[],"checksum":2040095271,"timestamp":"2024-06-01T17:51:56.339588Z"}]}
{"channel":"book","type":"update","data":[{"symbol":"LINK/ETH","bids":[],"asks":[{"price":0.00489363,"qty":0.00000000},{"price":0.00492260,"qty":101.61891050}],"checksum":3972252013,"timestamp":"2024-06-01T17:51:56.339693Z"}]}
{"channel":"book","type":"update","data":[{"symbol":"LINK/ETH","bids":[{"price":0.00489095,"qty":26.92819698}],"asks":[],"checksum":1839307651,"timestamp":"2024-06-01T17:51:56.342993Z"}]}
{"channel":"book","type":"update","data":[{"symbol":"LINK/ETH","bids":[],"asks":[{"price":0.00491974,"qty":0.00000000},{"price":0.00492897,"qty":283.29663722}],"checksum":1166864134,"timestamp":"2024-06-01T17:51:58.391771Z"}]}
{"channel":"book","type":"update","data":[{"symbol":"LINK/ETH","bids":[],"asks":[{"price":0.00492259,"qty":223.88496910}],"checksum":3451803080,"timestamp":"2024-06-01T17:51:58.431971Z"}]}
{"channel":"book","type":"update","data":[{"symbol":"LINK/ETH","bids":[],"asks":[{"price":0.00489406,"qty":8.07334131}],"checksum":503498571,"timestamp":"2024-06-01T17:51:58.780574Z"}]}
{"channel":"book","type":"update","data":[{"symbol":"LINK/ETH","bids":[],"asks":[{"price":0.00491907,"qty":0.00000000},{"price":0.00492260,"qty":101.61891050}],"checksum":181691804,"timestamp":"2024-06-01T17:52:00.461672Z"}]}
{"channel":"book","type":"update","data":[{"symbol":"LINK/ETH","bids":[{"price":0.00489104,"qty":0.00000000},{"price":0.00486828,"qty":767.10149463}],"asks":[],"checksum":3487810675,"timestamp":"2024-06-01T17:52:00.461808Z"}]}
{"channel":"book","type":"update","data":[{"symbol":"LINK/ETH","bids":[{"price":0.00486830,"qty":263.85422000}],"asks":[],"checksum":990887773,"timestamp":"2024-06-01T17:52:00.464405Z"}]}
{"channel":"book","type":"update","data":[{"symbol":"LINK/ETH","bids":[{"price":0.00489110,"qty":131.75171000}],"asks":[],"checksum":197988171,"timestamp":"2024-06-01T17:52:00.464630Z"}]}
{"channel":"book","type":"update","data":[{"symbol":"LINK/ETH","bids":[],"asks":[{"price":0.00491906,"qty":131.75171000}],"checksum":3305051979,"timestamp":"2024-06-01T17:52:00.464731Z"}]}
{"channel":"book","type":"update","data":[{"symbol":"LINK/ETH","bids":[{"price":0.00489115,"qty":4.84448076}],"asks":[],"checksum":3100033059,"timestamp":"2024-06-01T17:52:00.467426Z"}]}
{"channel":"book","type":"update","data":[{"symbol":"LINK/ETH","bids":[{"price":0.00489109,"qty":0.00000000},{"price":0.00486830,"qty":263.85422000}],"asks":[],"checksum":3083818999,"timestamp":"2024-06-01T17:52:00.467493Z"}]}
{"channel":"book","type":"update","data":[{"symbol":"LINK/ETH","bids":[{"price":0.00486831,"qty":42.55498493}],"asks":[],"checksum":1536314261,"timestamp":"2024-06-01T17:52:00.468045Z"}]}
{"channel":"book","type":"update","data":[{"symbol":"LINK/ETH","bids":[{"price":0.00489095,"qty":0.00000000},{"price":0.00486830,"qty":263.85422000}],"asks":[],"checksum":4203538078,"timestamp":"2024-06-01T17:52:02.408404Z"}]}
{"channel":"book","type":"update","data":[{"symbol":"LINK/ETH","bids":[{"price":0.00489126,"qty":26.92647898}],"asks":[],"checksum":3534059635,"timestamp":"2024-06-01T17:52:02.411957Z"}]}
{"channel":"book","type":"update","data":[{"symbol":"LINK/ETH","bids":[{"price":0.00489131,"qty":4.84472319}],"asks":[],"checksum":1698385568,"timestamp":"2024-06-01T17:52:02.415102Z"}]}
{"channel":"book","type":"update","data":[{"symbol":"LINK/ETH","bids":[{"price":0.00489115,"qty":0.00000000},{"price":0.00486831,"qty":42.55498493}],"asks":[],"checksum":2386834338,"timestamp":"2024-06-01T17:52:02.417776Z"}]}
{"channel":"book","type":"update","data":[{"symbol":"LINK/ETH","bids":[{"price":0.00489132,"qty":7.37538501}],"asks":[],"checksum":4177401100,"timestamp":"2024-06-01T17:52:02.431370Z"}]}
{"channel":"book","type":"update","data":[{"symbol":"LINK/ETH","bids":[{"price":0.00489137,"qty":4.84364130}],"asks":[],"checksum":3981608372,"timestamp":"2024-06-01T17:52:02.434092Z"}]}
{"channel":"book","type":"update","data":[{"symbol":"LINK/ETH","bids":[],"asks":[{"price":0.00489406,"qty":0.00000000},{"price":0.00492260,"qty":101.61891050}],"checksum":3638564162,"timestamp":"2024-06-01T17:52:02.434120Z"}]}
{"channel":"book","type":"update","data":[{"symbol":"LINK/ETH","bids":[{"price":0.00489131,"qty":0.00000000},{"price":0.00488493,"qty":0.51861120}],"asks":[],"checksum":3809576,"timestamp":"2024-06-01T17:52:02.434131Z"}]}
{"channel":"book","type":"update","data":[{"symbol":"LINK/ETH","bids":[{"price":0.00489126,"qty":0.00000000},{"price":0.00486831,"qty":42.55498493}],"asks":[],"checksum":2612699387,"timestamp":"2024-06-01T17:52:02.434318Z"}]}
{"channel":"book","type":"update","data":[{"symbol":"LINK/ETH","bids":[{"price":0.00488545,"qty":0.00000000},{"price":0.00486830,"qty":263.85422000}],"asks":[],"checksum":1302844632,"timestamp":"2024-06-01T17:52:02.450513Z"}]}
{"channel":"book","type":"update","data":[{"symbol":"LINK/ETH","bids":[{"price":0.00488988,"qty":26.93410739}],"asks":[],"checksum":1530844832,"timestamp":"2024-06-01T17:52:02.453868Z"}]}
{"channel":"book","type":"update","data":[{"symbol":"LINK/ETH","bids":[],"asks":[{"price":0.00489460,"qty":8.07244467}],"checksum":1478859681,"timestamp":"2024-06-01T17:52:04.781050Z"}]}
{"channel":"book","type":"update","data":[{"symbol":"LINK/ETH","bids":[{"price":0.00489151,"qty":26.92510350}],"asks":[],"checksum":3442391925,"timestamp":"2024-06-01T17:52:04.781113Z"}]}
{"channel":"book","type":"update","data":[{"symbol":"LINK/ETH","bids":[{"price":0.00489137,"qty":0.00000000},{"price":0.00486831,"qty":42.55498493}],"asks":[],"checksum":2830877279,"timestamp":"2024-06-01T17:52:05.329937Z"}]}
{"channel":"book","type":"update","data":[{"symbol":"LINK/ETH","bids":[],"asks":[{"price":0.00489460,"qty":0.00000000},{"price":0.00492260,"qty":101.61891050}],"checksum":3753896324,"timestamp":"2024-06-01T17:52:05.407194Z"}]}
{"channel":"book","type":"update","data":[{"symbol":"LINK/ETH","bids":[{"price":0.00489156,"qty":4.84520523}],"asks":[],"checksum":845728652,"timestamp":"2024-06-01T17:52:05.430119Z"}]}
{"channel":"book","type":"update","data":[{"symbol":"LINK/ETH","bids":[],"asks":[{"price":0.00491906,"qty":0.00000000},{"price":0.00492897,"qty":283.29663722}],"checksum":1556073245,"timestamp":"2024-06-01T17:52:06.345939Z"}]}
{"channel":"book","type":"update","data":[{"symbol":"LINK/ETH","bids":[{"price":0.00489110,"qty":0.00000000},{"price":0.00486831,"qty":42.55498493}],"asks":[],"checksum":2828434921,"timestamp":"2024-06-01T17:52:06.346121Z"}]}
{"channel":"book","type":"update","data":[{"symbol":"LINK/ETH","bids":[],"asks":[{"price":0.00491905,"qty":131.75171000}],"checksum":3048208085,"timestamp":"2024-06-01T17:52:06.348716Z"}]}
{"channel":"book","type":"update","data":[{"symbol":"LINK/ETH","bids":[{"price":0.00489157,"qty":131.75171000}],"asks":[],"checksum":2354988839,"timestamp":"2024-06-01T17:52:06.348810Z"}]}
{"channel":"book","type":"update","data":[{"symbol":"LINK/ETH","bids":[{"price":0.00489162,"qty":4.84510527}],"asks":[],"checksum":1934769185,"timestamp":"2024-06-01T17:52:06.351858Z"}]}
{"channel":"book","type":"update","data":[{"symbol":"LINK/ETH","bids":[{"price":0.00489156,"qty":0.00000000},{"price":0.00488493,"qty":0.51861120}],"asks":[],"checksum":1992386646,"timestamp":"2024-06-01T17:52:06.354848Z"}]}
{"channel":"book","type":"update","data":[{"symbol":"LINK/ETH","bids":[{"price":0.00489151,"qty":0.00000000},{"price":0.00486833,"qty":42.55481012}],"asks":[],"checksum":135200084,"timestamp":"2024-06-01T17:52:06.554778Z"}]}
{"channel":"book","type":"update","data":[{"symbol":"LINK/ETH","bids":[{"price":0.00488988,"qty":0.00000000},{"price":0.00486832,"qty":263.85422000}],"asks":[],"checksum":2943860899,"timestamp":"2024-06-01T17:52:06.558557Z"}]}
{"channel":"book","type":"update","data":[{"symbol":"LINK/ETH","bids":[{"price":0.00489109,"qty":26.92875038}],"asks":[],"checksum":1230556286,"timestamp":"2024-06-01T17:52:06.563170Z"}]}
{"channel":"book","type":"update","data":[{"symbol":"LINK/ETH","bids":[],"asks":[{"price":0.00489434,"qty":8.07266305}],"checksum":432134703,"timestamp":"2024-06-01T17:52:06.563198Z"}]}
{"channel":"book","type":"update","data":[{"symbol":"LINK/ETH","bids":[{"price":0.00488637,"qty":26.95475674}],"asks":[],"checksum":4171807663,"timestamp":"2024-06-01T17:52:06.563211Z"}]}
{"channel":"book","type":"update","data":[{"symbol":"LINK/ETH","bids":[{"price":0.00489162,"qty":0.00000000},{"price":0.00486833,"qty":42.55481012}],"asks":[],"checksum":4036260800,"timestamp":"2024-06-01T17:52:06.580526Z"}]}
{"channel":"book","type":"update","data":[{"symbol":"LINK/ETH","bids":[],"asks":[{"price":0.00489434,"qty":0.00000000},{"price":0.00492260,"qty":101.61891050}],"checksum":3970468788,"timestamp":"2024-06-01T17:52:06.754041Z"}]}
{"channel":"book","type":"update","data":[{"symbol":"LINK/ETH","bids":[{"price":0.00489109,"qty":0.00000000},{"price":0.00486832,"qty":263.85422000}],"asks":[],"checksum":2836089947,"timestamp":"2024-06-01T17:52:06.754059Z"}]}
{"channel":"book","type":"update","data":[{"symbol":"LINK/ETH","bids":[{"price":0.00489070,"qty":26.93091032}],"asks":[],"checksum":1646672422,"timestamp":"2024-06-01T17:52:08.780980Z"}]}
{"channel":"book","type":"update","data":[{"symbol":"LINK/ETH","bids":[],"asks":[{"price":0.00489379,"qty":8.07418109}],"checksum":4174825091,"timestamp":"2024-06-01T17:52:08.781028Z"}]}
{"channel":"book","type":"update","data":[{"symbol":"LINK/ETH","bids":[],"asks":[{"price":0.00492259,"qty":0.00000000},{"price":0.00492260,"qty":101.61891050}],"checksum":1918173707,"timestamp":"2024-06-01T17:52:10.122857Z"}]}
{"channel":"book","type":"update","data":[{"symbol":"LINK/ETH","bids":[],"asks":[{"price":0.00491974,"qty":224.02800330}],"checksum":836153082,"timestamp":"2024-06-01T17:52:10.163149Z"}]}
{"channel":"book","type":"update","data":[{"symbol":"LINK/ETH","bids":[],"asks":[{"price":0.00491905,"qty":0.00000000},{"price":0.00492260,"qty":101.61891050}],"checksum":738962146,"timestamp":"2024-06-01T17:52:12.230621Z"}]}
{"channel":"book","type":"update","data":[{"symbol":"LINK/ETH","bids":[{"price":0.00489157,"qty":0.00000000},{"price":0.00486830,"qty":767.02784150}],"asks":[],"checksum":529120379,"timestamp":"2024-06-01T17:52:12.230900Z"}]}
{"channel":"book","type":"update","data":[{"symbol":"LINK/ETH","bids":[{"price":0.00486834,"qty":263.85422000}],"asks":[],"checksum":3930857737,"timestamp":"2024-06-01T17:52:12.233401Z"}]}
{"channel":"book","type":"update","data":[{"symbol":"LINK/ETH","bids":[],"asks":[{"price":0.00491904,"qty":131.75171000}],"checksum":1808408304,"timestamp":"2024-06-01T17:52:12.233474Z"}]}
{"channel":"book","type":"update","data":[{"symbol":"LINK/ETH","bids":[{"price":0.00489071,"qty":131.75171000}],"asks":[],"checksum":2673011318,"timestamp":"2024-06-01T17:52:12.233591Z"}]}
{"channel":"book","type":"update","data":[{"symbol":"LINK/ETH","bids":[{"price":0.00486835,"qty":42.55463528}],"asks":[],"checksum":3827445257,"timestamp":"2024-06-01T17:52:12.258722Z"}]}
{"channel":"book","type":"update","data":[{"symbol":"LINK/ETH","bids":[{"price":0.00489070,"qty":0.00000000},{"price":0.00486834,"qty":263.85422000}],"asks":[],"checksum":1030881645,"timestamp":"2024-06-01T17:52:15.365256Z"}]}
{"channel":"book","type":"update","data":[{"symbol":"LINK/ETH","bids":[{"price":0.00489031,"qty":26.93179402}],"asks":[],"checksum":818453464,"timestamp":"2024-06-01T17:52:15.369695Z"}]}
{"channel":"book","type":"update","data":[{"symbol":"LINK/ETH","bids":[],"asks":[{"price":0.00489379,"qty":0.00000000},{"price":0.00492260,"qty":101.61891050}],"checksum":2801447492,"timestamp":"2024-06-01T17:52:15.371663Z"}]}
{"channel":"book","type":"update","data":[{"symbol":"LINK/ETH","bids":[],"asks":[{"price":0.00489436,"qty":4.84582950}],"checksum":293238543,"timestamp":"2024-06-01T17:52:15.375297Z"}]}
{"channel":"book","type":"update","data":[{"symbol":"LINK/ETH","bids":[{"price":0.00489031,"qty":0.00000000},{"price":0.00486834,"qty":263.85422000}],"asks":[],"checksum":635761910,"timestamp":"2024-06-01T17:52:15.388120Z"}]}
{"channel":"book","type":"update","data":[{"symbol":"LINK/ETH","bids":[{"price":0.00489132,"qty":0.00000000},{"price":0.00486830,"qty":767.02784150}],"asks":[],"checksum":1255766010,"timestamp":"2024-06-01T17:52:15.408214Z"}]}
{"channel":"book","type":"update","data":[{"symbol":"LINK/ETH","bids":[{"price":0.00488968,"qty":0.00000000},{"price":0.00486721,"qty":175.83850000}],"asks":[],"checksum":4008641827,"timestamp":"2024-06-01T17:52:15.483659Z"}]}
{"channel":"book","type":"update","data":[{"symbol":"LINK/ETH","bids":[{"price":0.00488927,"qty":21.53911780}],"asks":[],"checksum":3481371447,"timestamp":"2024-06-01T17:52:15.813140Z"}]}
{"channel":"book","type":"update","data":[{"symbol":"LINK/ETH","bids":[{"price":0.00488927,"qty":0.00000000},{"price":0.00486721,"qty":175.83850000}],"asks":[],"checksum":4008641827,"timestamp":"2024-06-01T17:52:16.113496Z"}]}
{"channel":"book","type":"update","data":[{"symbol":"LINK/ETH","bids":[{"price":0.00488923,"qty":21.53911780}],"asks":[],"checksum":3303763746,"timestamp":"2024-06-01T17:52:16.396750Z"}]}
{"channel":"book","type":"update","data":[{"symbol":"LINK/ETH","bids":[{"price":0.00486830,"qty":0.00000000},{"price":0.00486721,"qty":175.83850000}],"asks":[],"checksum":1917757573,"timestamp":"2024-06-01T17:52:17.304798Z"}]}
{"channel":"book","type":"update","data":[{"symbol":"LINK/ETH","bids":[{"price":0.00486834,"qty":1034.56361251}],"asks":[],"checksum":619444840,"timestamp":"2024-06-01T17:52:17.345051Z"}]}
{"channel":"book","type":"update","data":[{"symbol":"LINK/ETH","bids":[],"asks":[{"price":0.00489295,"qty":8.07439624}],"checksum":928209160,"timestamp":"2024-06-01T17:52:17.780341Z"}]}
{"channel":"book","type":"update","data":[{"symbol":"LINK/ETH","bids":[{"price":0.00488991,"qty":26.93186886}],"asks":[],"checksum":1524920742,"timestamp":"2024-06-01T17:52:17.780565Z"}]}
{"channel":"book","type":"update","data":[{"symbol":"LINK/ETH","bids":[{"price":0.00486834,"qty":770.70939251}],"asks":[],"checksum":3804776022,"timestamp":"2024-06-01T17:52:18.114841Z"}]}
{"channel":"book","type":"update","data":[{"symbol":"LINK/ETH","bids":[{"price":0.00489071,"qty":0.00000000},{"price":0.00486721,"qty":175.83850000}],"asks":[],"checksum":3435770572,"timestamp":"2024-06-01T17:52:18.114930Z"}]}
{"channel":"book","type":"update","data":[{"symbol":"LINK/ETH","bids":[],"asks":[{"price":0.00491904,"qty":0.00000000},{"price":0.00491975,"qty":438.16674000}],"checksum":3620372039,"timestamp":"2024-06-01T17:52:18.114941Z"}]}
{"channel":"book","type":"update","data":[{"symbol":"LINK/ETH","bids":[{"price":0.00486836,"qty":263.85422000}],"asks":[],"checksum":1727709972,"timestamp":"2024-06-01T17:52:18.117441Z"}]}
{"channel":"book","type":"update","data":[{"symbol":"LINK/ETH","bids":[],"asks":[{"price":0.00491903,"qty":131.75171000}],"checksum":554056472,"timestamp":"2024-06-01T17:52:18.117477Z"}]}
{"channel":"book","type":"update","data":[{"symbol":"LINK/ETH","bids":[{"price":0.00488991,"qty":31.77762070}],"asks":[],"checksum":308236283,"timestamp":"2024-06-01T17:52:18.117785Z"}]}
{"channel":"book","type":"update","data":[{"symbol":"LINK/ETH","bids":[{"price":0.00489072,"qty":131.75171000}],"asks":[],"checksum":1624136810,"timestamp":"2024-06-01T17:52:18.118261Z"}]}
{"channel":"book","type":"update","data":[{"symbol":"LINK/ETH","bids":[{"price":0.00486837,"qty":42.55446046}],"asks":[],"checksum":1494332441,"timestamp":"2024-06-01T17:52:18.151254Z"}]}
{"channel":"book","type":"update","data":[{"symbol":"LINK/ETH","bids":[{"price":0.00489077,"qty":4.84575281}],"asks":[],"checksum":4182702590,"timestamp":"2024-06-01T17:52:18.277060Z"}]}
{"channel":"book","type":"update","data":[{"symbol":"LINK/ETH","bids":[{"price":0.00488991,"qty":26.93186886}],"asks":[],"checksum":2969283057,"timestamp":"2024-06-01T17:52:18.277109Z"}]}
{"channel":"book","type":"update","data":[{"symbol":"LINK/ETH","bids":[{"price":0.00489077,"qty":0.00000000},{"price":0.00486836,"qty":263.85422000}],"asks":[],"checksum":159557880,"timestamp":"2024-06-01T17:52:20.383163Z"}]}
{"channel":"book","type":"update","data":[{"symbol":"LINK/ETH","bids":[],"asks":[{"price":0.00491903,"qty":0.00000000},{"price":0.00491975,"qty":438.16674000}],"checksum":1316901108,"timestamp":"2024-06-01T17:52:23.999664Z"}]}
{"channel":"book","type":"update","data":[{"symbol":"LINK/ETH","bids":[{"price":0.00486836,"qty":0.00000000},{"price":0.00486834,"qty":770.70939251}],"asks":[],"checksum":3511592203,"timestamp":"2024-06-01T17:52:23.999678Z"}]}
{"channel":"book","type":"update","data":[{"symbol":"LINK/ETH","bids":[{"price":0.00489072,"qty":0.00000000},{"price":0.00486721,"qty":175.83850000}],"asks":[],"checksum":558649935,"timestamp":"2024-06-01T17:52:23.999825Z"}]}
{"channel":"book","type":"update","data":[{"symbol":"LINK/ETH","bids":[{"price":0.00488992,"qty":131.75171000}],"asks":[],"checksum":3760711773,"timestamp":"2024-06-01T17:52:24.002547Z"}]}
{"channel":"book","type":"update","data":[{"symbol":"LINK/ETH","bids":[{"price":0.00486838,"qty":263.85422000}],"asks":[],"checksum":3967828366,"timestamp":"2024-06-01T17:52:24.002713Z"}]}
{"channel":"book","type":"update","data":[{"symbol":"LINK/ETH","bids":[],"asks":[{"price":0.00491902,"qty":131.75171000}],"checksum":2063926830,"timestamp":"2024-06-01T17:52:24.002757Z"}]}
{"channel":"book","type":"update","data":[{"symbol":"LINK/ETH","bids":[{"price":0.00486837,"qty":0.00000000},{"price":0.00486834,"qty":770.70939251}],"asks":[],"checksum":2366571199,"timestamp":"2024-06-01T17:52:24.020805Z"}]}
{"channel":"book","type":"update","data":[{"symbol":"LINK/ETH","bids":[{"price":0.00486839,"qty":42.55428564}],"asks":[],"checksum":4066673895,"timestamp":"2024-06-01T17:52:24.021044Z"}]}
{"channel":"book","type":"update","data":[{"symbol":"LINK/ETH","bids":[{"price":0.00488991,"qty":0.00000000},{"price":0.00486834,"qty":770.70939251}],"asks":[],"checksum":351196540,"timestamp":"2024-06-01T17:52:26.688589Z"}]}
{"channel":"book","type":"update","data":[{"symbol":"LINK/ETH","bids":[{"price":0.00488999,"qty":26.92978659}],"asks":[],"checksum":139119409,"timestamp":"2024-06-01T17:52:26.692025Z"}]}
{"channel":"book","type":"update","data":[{"symbol":"LINK/ETH","bids":[{"price":0.00486838,"qty":1037.68390775}],"asks":[],"checksum":710457692,"timestamp":"2024-06-01T17:52:28.381405Z"}]}
{"channel":"book","type":"update","data":[{"symbol":"LINK/ETH","bids":[],"asks":[{"price":0.00491902,"qty":0.00000000},{"price":0.00491975,"qty":438.16674000}],"checksum":4229537779,"timestamp":"2024-06-01T17:52:29.884975Z"}]}
{"channel":"book","type":"update","data":[{"symbol":"LINK/ETH","bids":[{"price":0.00488940,"qty":0.00000000},{"price":0.00486721,"qty":175.83850000}],"asks":[],"checksum":1890402034,"timestamp":"2024-06-01T17:52:29.885144Z"}]}
{"channel":"book","type":"update","data":[{"symbol":"LINK/ETH","bids":[{"price":0.00488992,"qty":0.00000000},{"price":0.00485763,"qty":9.62058391}],"asks":[],"checksum":1421569498,"timestamp":"2024-06-01T17:52:29.885399Z"}]}
{"channel":"book","type":"update","data":[{"symbol":"LINK/ETH","bids":[{"price":0.00486838,"qty":773.82968775}],"asks":[],"checksum":3027627603,"timestamp":"2024-06-01T17:52:29.885507Z"}]}
{"channel":"book","type":"update","data":[{"symbol":"LINK/ETH","bids":[],"asks":[{"price":0.00491901,"qty":131.75171000}],"checksum":3373279863,"timestamp":"2024-06-01T17:52:29.887706Z"}]}
{"channel":"book","type":"update","data":[{"symbol":"LINK/ETH","bids":[{"price":0.00486082,"qty":5.84896026}],"asks":[],"checksum":2603798908,"timestamp":"2024-06-01T17:52:29.887781Z"}]}
{"channel":"book","type":"update","data":[{"symbol":"LINK/ETH","bids":[{"price":0.00488777,"qty":71.53689000}],"asks":[],"checksum":2686668654,"timestamp":"2024-06-01T17:52:29.888113Z"}]}
{"channel":"book","type":"update","data":[{"symbol":"LINK/ETH","bids":[{"price":0.00489000,"qty":131.75171000}],"asks":[],"checksum":554767753,"timestamp":"2024-06-01T17:52:29.888213Z"}]}
{"channel":"book","type":"update","data":[{"symbol":"LINK/ETH","bids":[{"price":0.00486840,"qty":263.85422000}],"asks":[],"checksum":4149659264,"timestamp":"2024-06-01T17:52:29.888516Z"}]}
{"channel":"book","type":"update","data":[{"symbol":"LINK/ETH","bids":[{"price":0.00486839,"qty":0.00000000},{"price":0.00486838,"qty":773.82968775}],"asks":[],"checksum":187558280,"timestamp":"2024-06-01T17:52:29.897990Z"}]}
{"channel":"book","type":"update","data":[{"symbol":"LINK/ETH","bids":[{"price":0.00486841,"qty":42.55411082}],"asks":[],"checksum":3498639771,"timestamp":"2024-06-01T17:52:29.898054Z"}]}
{"channel":"book","type":"update","data":[{"symbol":"LINK/ETH","bids":[{"price":0.00488923,"qty":0.00000000},{"price":0.00486838,"qty":773.82968775}],"asks":[],"checksum":3603547997,"timestamp":"2024-06-01T17:52:30.658833Z"}]}
{"channel":"book","type":"update","data":[{"symbol":"LINK/ETH","bids":[],"asks":[{"price":0.00489567,"qty":0.00000000},{"price":0.00491975,"qty":438.16674000}],"checksum":545608055,"timestamp":"2024-06-01T17:52:30.775062Z"}]}
{"channel":"book","type":"update","data":[{"symbol":"LINK/ETH","bids":[{"price":0.00488999,"qty":0.00000000},{"price":0.00486721,"qty":175.83850000}],"asks":[],"checksum":271006309,"timestamp":"2024-06-01T17:52:30.775117Z"}]}
{"channel":"book","type":"update","data":[{"symbol":"LINK/ETH","bids":[{"price":0.00488926,"qty":26.92982296}],"asks":[],"checksum":3905179232,"timestamp":"2024-06-01T17:52:30.783714Z"}]}
{"channel":"book","type":"update","data":[{"symbol":"LINK/ETH","bids":[],"asks":[{"price":0.00489238,"qty":8.07380521}],"checksum":3422678256,"timestamp":"2024-06-01T17:52:30.783812Z"}]}
{"channel":"book","type":"update","data":[{"symbol":"LINK/ETH","bids":[{"price":0.00489000,"qty":0.00000000},{"price":0.00486721,"qty":175.83850000}],"asks":[],"checksum":826897289,"timestamp":"2024-06-01T17:52:30.788173Z"}]}
{"channel":"book","type":"update","data":[{"symbol":"LINK/ETH","bids":[],"asks":[{"price":0.00491901,"qty":0.00000000},{"price":0.00492260,"qty":101.61891050}],"checksum":680031221,"timestamp":"2024-06-01T17:52:30.788226Z"}]}
{"channel":"book","type":"update","data":[{"symbol":"LINK/ETH","bids":[{"price":0.00486840,"qty":0.00000000},{"price":0.00486082,"qty":5.84896026}],"asks":[],"checksum":3537433028,"timestamp":"2024-06-01T17:52:30.788637Z"}]}
{"channel":"book","type":"update","data":[{"symbol":"LINK/ETH","bids":[],"asks":[{"price":0.00491900,"qty":438.16674000}],"checksum":1588315673,"timestamp":"2024-06-01T17:52:30.790850Z"}]}
{"channel":"book","type":"update","data":[{"symbol":"LINK/ETH","bids":[],"asks":[{"price":0.00491900,"qty":569.91845000}],"checksum":4154640927,"timestamp":"2024-06-01T17:52:30.791232Z"}]}
{"channel":"book","type":"update","data":[{"symbol":"LINK/ETH","bids":[{"price":0.00489001,"qty":131.75171000}],"asks":[],"checksum":628975641,"timestamp":"2024-06-01T17:52:30.791391Z"}]}
{"channel":"book","type":"update","data":[{"symbol":"LINK/ETH","bids":[{"price":0.00486842,"qty":263.85422000}],"asks":[],"checksum":930768249,"timestamp":"2024-06-01T17:52:30.792235Z"}]}
{"channel":"book","type":"update","data":[{"symbol":"LINK/ETH","bids":[{"price":0.00486843,"qty":42.55393601}],"asks":[],"checksum":1315571236,"timestamp":"2024-06-01T17:52:30.806301Z"}]}
{"channel":"book","type":"update","data":[{"symbol":"LINK/ETH","bids":[{"price":0.00486841,"qty":0.00000000},{"price":0.00486838,"qty":773.82968775}],"asks":[],"checksum":1104062590,"timestamp":"2024-06-01T17:52:30.809205Z"}]}
{"channel":"book","type":"update","data":[{"symbol":"LINK/ETH","bids":[],"asks":[{"price":0.00489295,"qty":0.00000000},{"price":0.00492260,"qty":101.61891050}],"checksum":68750828,"timestamp":"2024-06-01T17:52:30.988788Z"}]}
{"channel":"book","type":"update","data":[{"symbol":"LINK/ETH","bids":[{"price":0.00488926,"qty":0.00000000},{"price":0.00486721,"qty":175.83850000}],"asks":[],"checksum":370420054,"timestamp":"2024-06-01T17:52:30.992401Z"}]}
{"channel":"book","type":"update","data":[{"symbol":"LINK/ETH","bids":[],"asks":[{"price":0.00489238,"qty":0.00000000},{"price":0.00492873,"qty":9.52504690}],"checksum":2372930040,"timestamp":"2024-06-01T17:52:30.992498Z"}]}
{"channel":"book","type":"update","data":[{"symbol":"LINK/ETH","bids":[{"price":0.00489001,"qty":0.00000000},{"price":0.00486082,"qty":5.84896026}],"asks":[],"checksum":2459413680,"timestamp":"2024-06-01T17:52:30.996923Z"}]}
{"channel":"book","type":"update","data":[{"symbol":"LINK/ETH","bids":[],"asks":[{"price":0.00491900,"qty":438.16674000}],"checksum":464725794,"timestamp":"2024-06-01T17:52:30.997052Z"}]}
{"channel":"book","type":"update","data":[{"symbol":"LINK/ETH","bids":[{"price":0.00486842,"qty":0.00000000},{"price":0.00485763,"qty":9.62058391}],"asks":[],"checksum":3438818743,"timestamp":"2024-06-01T17:52:30.998440Z"}]}
{"channel":"book","type":"update","data":[{"symbol":"LINK/ETH","bids":[],"asks":[{"price":0.00489439,"qty":8.07091821}],"checksum":3323244171,"timestamp":"2024-06-01T17:52:30.999026Z"}]}
{"channel":"book","type":"update","data":[{"symbol":"LINK/ETH","bids":[{"price":0.00489002,"qty":131.75171000}],"asks":[],"checksum":2432829650,"timestamp":"2024-06-01T17:52:30.999858Z"}]}
{"channel":"book","type":"update","data":[{"symbol":"LINK/ETH","bids":[],"asks":[{"price":0.00491899,"qty":131.75171000}],"checksum":4152395677,"timestamp":"2024-06-01T17:52:30.999939Z"}]}
{"channel":"book","type":"update","data":[{"symbol":"LINK/ETH","bids":[{"price":0.00488856,"qty":4.84572259}],"asks":[],"checksum":1316914812,"timestamp":"2024-06-01T17:52:31.001802Z"}]}
{"channel":"book","type":"update","data":[{"symbol":"LINK/ETH","bids":[{"price":0.00486844,"qty":263.85422000}],"asks":[],"checksum":2631176346,"timestamp":"2024-06-01T17:52:31.002740Z"}]}
{"channel":"book","type":"update","data":[{"symbol":"LINK/ETH","bids":[{"price":0.00489004,"qty":4.84572259}],"asks":[],"checksum":3334542937,"timestamp":"2024-06-01T17:52:31.005660Z"}]}
{"channel":"book","type":"update","data":[{"symbol":"LINK/ETH","bids":[{"price":0.00488856,"qty":0.00000000},{"price":0.00486838,"qty":773.82968775}],"asks":[],"checksum":1582504365,"timestamp":"2024-06-01T17:52:31.006438Z"}]}
{"channel":"book","type":"update","data":[{"symbol":"LINK/ETH","bids":[{"price":0.00486845,"qty":42.55376119}],"asks":[],"checksum":3465545409,"timestamp":"2024-06-01T17:52:31.009692Z"}]}
{"channel":"book","type":"update","data":[{"symbol":"LINK/ETH","bids":[{"price":0.00486843,"qty":0.00000000},{"price":0.00486838,"qty":773.82968775}],"asks":[],"checksum":779380786,"timestamp":"2024-06-01T17:52:31.013331Z"}]}
{"channel":"book","type":"update","data":[{"symbol":"LINK/ETH","bids":[],"asks":[{"price":0.00489436,"qty":0.00000000},{"price":0.00492260,"qty":101.61891050}],"checksum":342645590,"timestamp":"2024-06-01T17:52:31.013989Z"}]}
{"channel":"book","type":"update","data":[{"symbol":"LINK/ETH","bids":[],"asks":[{"price":0.00489439,"qty":0.00000000},{"price":0.00492873,"qty":9.52504690}],"checksum":4176431086,"timestamp":"2024-06-01T17:52:31.019541Z"}]}
{"channel":"book","type":"update","data":[{"symbol":"LINK/ETH","bids":[{"price":0.00489002,"qty":0.00000000},{"price":0.00486721,"qty":175.83850000}],"asks":[],"checksum":4223302498,"timestamp":"2024-06-01T17:52:31.032196Z"}]}
{"channel":"book","type":"update","data":[{"symbol":"LINK/ETH","bids":[],"asks":[{"price":0.00491899,"qty":0.00000000},{"price":0.00492897,"qty":283.29663722}],"checksum":2135789427,"timestamp":"2024-06-01T17:52:31.033291Z"}]}
{"channel":"book","type":"update","data":[{"symbol":"LINK/ETH","bids":[{"price":0.00488852,"qty":131.75171000}],"asks":[],"checksum":1326495050,"timestamp":"2024-06-01T17:52:31.035905Z"}]}
{"channel":"book","type":"update","data":[{"symbol":"LINK/ETH","bids":[],"asks":[{"price":0.00491898,"qty":131.75171000}],"checksum":3155643483,"timestamp":"2024-06-01T17:52:31.036852Z"}]}
{"channel":"book","type":"update","data":[{"symbol":"LINK/ETH","bids":[{"price":0.00488880,"qty":21.53911780}],"asks":[],"checksum":329450715,"timestamp":"2024-06-01T17:52:31.046621Z"}]}
{"channel":"book","type":"update","data":[{"symbol":"LINK/ETH","bids":[],"asks":[{"price":0.00489436,"qty":4.84710272}],"checksum":3682725677,"timestamp":"2024-06-01T17:52:31.206818Z"}]}
{"channel":"book","type":"update","data":[{"symbol":"LINK/ETH","bids":[],"asks":[{"price":0.00489436,"qty":0.00000000},{"price":0.00492873,"qty":9.52504690}],"checksum":329450715,"timestamp":"2024-06-01T17:52:31.231672Z"}]}
{"channel":"book","type":"update","data":[{"symbol":"LINK/ETH","bids":[],"asks":[{"price":0.00489989,"qty":8.06676988}],"checksum":27723117,"timestamp":"2024-06-01T17:52:31.266043Z"}]}
{"channel":"book","type":"update","data":[{"symbol":"LINK/ETH","bids":[{"price":0.00489015,"qty":7.37714961}],"asks":[],"checksum":1237028053,"timestamp":"2024-06-01T17:52:31.509995Z"}]}
{"channel":"book","type":"update","data":[{"symbol":"LINK/ETH","bids":[{"price":0.00489020,"qty":4.84728168}],"asks":[],"checksum":1290056005,"timestamp":"2024-06-01T17:52:31.513112Z"}]}
{"channel":"book","type":"update","data":[{"symbol":"LINK/ETH","bids":[{"price":0.00489004,"qty":0.00000000},{"price":0.00486845,"qty":42.55376119}],"asks":[],"checksum":2728256823,"timestamp":"2024-06-01T17:52:31.516013Z"}]}
{"channel":"book","type":"update","data":[{"symbol":"LINK/ETH","bids":[],"asks":[{"price":0.00489789,"qty":0.00000000},{"price":0.00492873,"qty":9.52504690}],"checksum":1624630589,"timestamp":"2024-06-01T17:52:31.764173Z"}]}
{"channel":"book","type":"update","data":[{"symbol":"LINK/ETH","bids":[],"asks":[{"price":0.00489441,"qty":26.38571528}],"checksum":1572461759,"timestamp":"2024-06-01T17:52:31.805901Z"}]}
{"channel":"book","type":"update","data":[{"symbol":"LINK/ETH","bids":[],"asks":[{"price":0.00491974,"qty":0.00000000},{"price":0.00492897,"qty":283.29663722}],"checksum":879661398,"timestamp":"2024-06-01T17:52:32.393180Z"}]}
{"channel":"book","type":"update","data":[{"symbol":"LINK/ETH","bids":[],"asks":[{"price":0.00492259,"qty":223.67586130}],"checksum":314548705,"timestamp":"2024-06-01T17:52:32.433363Z"}]}
{"channel":"book","type":"update","data":[{"symbol":"LINK/ETH","bids":[],"asks":[{"price":0.00492872,"qty":283.29663722}],"checksum":3730972141,"timestamp":"2024-06-01T17:52:32.668035Z"}]}
{"channel":"book","type":"update","data":[{"symbol":"LINK/ETH","bids":[],"asks":[{"price":0.00489439,"qty":8.07484774}],"checksum":3082422677,"timestamp":"2024-06-01T17:52:32.781338Z"}]}
{"channel":"book","type":"update","data":[{"symbol":"LINK/ETH","bids":[{"price":0.00489054,"qty":26.93731037}],"asks":[],"checksum":4245974310,"timestamp":"2024-06-01T17:52:32.781370Z"}]}
{"channel":"book","type":"update","data":[{"symbol":"LINK/ETH","bids":[],"asks":[{"price":0.00489643,"qty":8.07178026}],"checksum":770029422,"timestamp":"2024-06-01T17:52:32.781483Z"}]}
{"channel":"book","type":"update","data":[{"symbol":"LINK/ETH","bids":[],"asks":[{"price":0.00489434,"qty":4.84677931}],"checksum":3384840947,"timestamp":"2024-06-01T17:52:32.784238Z"}]}
{"channel":"book","type":"update","data":[{"symbol":"LINK/ETH","bids":[],"asks":[{"price":0.00489441,"qty":21.53911780}],"checksum":3392120892,"timestamp":"2024-06-01T17:52:32.784365Z"}]}
{"channel":"book","type":"update","data":[{"symbol":"LINK/ETH","bids":[],"asks":[{"price":0.00489439,"qty":0.00000000},{"price":0.00492259,"qty":223.67586130}],"checksum":2499839730,"timestamp":"2024-06-01T17:52:32.788626Z"}]}
{"channel":"book","type":"update","data":[{"symbol":"LINK/ETH","bids":[{"price":0.00489058,"qty":4.84688266}],"asks":[],"checksum":54493380,"timestamp":"2024-06-01T17:52:34.533189Z"}]}
{"channel":"book","type":"update","data":[{"symbol":"LINK/ETH","bids":[{"price":0.00489020,"qty":0.00000000},{"price":0.00488493,"qty":0.51861120}],"asks":[],"checksum":43968359,"timestamp":"2024-06-01T17:52:34.535894Z"}]}
{"channel":"book","type":"update","data":[{"symbol":"LINK/ETH","bids":[{"price":0.00489054,"qty":0.00000000},{"price":0.00486845,"qty":42.55376119}],"asks":[],"checksum":1100833659,"timestamp":"2024-06-01T17:52:34.537267Z"}]}
{"channel":"book","type":"update","data":[{"symbol":"LINK/ETH","bids":[{"price":0.00489077,"qty":26.93419548}],"asks":[],"checksum":2239039737,"timestamp":"2024-06-01T17:52:34.540683Z"}]}
{"channel":"book","type":"update","data":[{"symbol":"LINK/ETH","bids":[],"asks":[{"price":0.00489401,"qty":8.07483348}],"checksum":216181394,"timestamp":"2024-06-01T17:52:34.540810Z"}]}
{"channel":"book","type":"update","data":[{"symbol":"LINK/ETH","bids":[],"asks":[{"price":0.00491898,"qty":0.00000000},{"price":0.00492259,"qty":223.67586130}],"checksum":3912448461,"timestamp":"2024-06-01T17:52:35.769900Z"}]}
{"channel":"book","type":"update","data":[{"symbol":"LINK/ETH","bids":[{"price":0.00488852,"qty":0.00000000},{"price":0.00486845,"qty":42.55376119}],"asks":[],"checksum":3375847824,"timestamp":"2024-06-01T17:52:35.770004Z"}]}
{"channel":"book","type":"update","data":[{"symbol":"LINK/ETH","bids":[{"price":0.00489078,"qty":131.75171000}],"asks":[],"checksum":3665590615,"timestamp":"2024-06-01T17:52:35.772620Z"}]}
{"channel":"book","type":"update","data":[{"symbol":"LINK/ETH","bids":[],"asks":[{"price":0.00491897,"qty":131.75171000}],"checksum":2143248742,"timestamp":"2024-06-01T17:52:35.772799Z"}]}
{"channel":"book","type":"update","data":[{"symbol":"LINK/ETH","bids":[{"price":0.00489077,"qty":0.00000000},{"price":0.00486847,"qty":42.55358638}],"asks":[],"checksum":3458859925,"timestamp":"2024-06-01T17:52:37.977631Z"}]}
{"channel":"book","type":"update","data":[{"symbol":"LINK/ETH","bids":[],"asks":[{"price":0.00489989,"qty":0.00000000},{"price":0.00492259,"qty":223.67586130}],"checksum":2791806828,"timestamp":"2024-06-01T17:52:37.979064Z"}]}
{"channel":"book","type":"update","data":[{"symbol":"LINK/ETH","bids":[],"asks":[{"price":0.00489330,"qty":8.07555501}],"checksum":1422826543,"timestamp":"2024-06-01T17:52:37.983378Z"}]}
{"channel":"book","type":"update","data":[{"symbol":"LINK/ETH","bids":[{"price":0.00488987,"qty":26.93734032}],"asks":[],"checksum":1479541932,"timestamp":"2024-06-01T17:52:37.983489Z"}]}
{"channel":"book","type":"update","data":[{"symbol":"LINK/ETH","bids":[],"asks":[{"price":0.00489325,"qty":4.84715797}],"checksum":1933532894,"timestamp":"2024-06-01T17:52:37.994786Z"}]}
{"channel":"book","type":"update","data":[{"symbol":"LINK/ETH","bids":[],"asks":[{"price":0.00489434,"qty":0.00000000},{"price":0.00491900,"qty":438.16674000}],"checksum":3798160826,"timestamp":"2024-06-01T17:52:37.995144Z"}]}
{"channel":"book","type":"update","data":[{"symbol":"LINK/ETH","bids":[{"price":0.00488987,"qty":0.00000000},{"price":0.00486847,"qty":42.55358638}],"asks":[],"checksum":4003319097,"timestamp":"2024-06-01T17:52:37.997505Z"}]}
{"channel":"book","type":"update","data":[{"symbol":"LINK/ETH","bids":[{"price":0.00489058,"qty":0.00000000},{"price":0.00486846,"qty":263.85422000}],"asks":[],"checksum":1610191815,"timestamp":"2024-06-01T17:52:37.998363Z"}]}
{"channel":"book","type":"update","data":[{"symbol":"LINK/ETH","bids":[],"asks":[{"price":0.00489330,"qty":0.00000000},{"price":0.00492259,"qty":223.67586130}],"checksum":1264525247,"timestamp":"2024-06-01T17:52:38.001109Z"}]}
{"channel":"book","type":"update","data":[{"symbol":"LINK/ETH","bids":[{"price":0.00488851,"qty":0.00000000},{"price":0.00486838,"qty":773.82968775}],"asks":[],"checksum":2709001716,"timestamp":"2024-06-01T17:52:38.018051Z"}]}
{"channel":"book","type":"update","data":[{"symbol":"LINK/ETH","bids":[{"price":0.00488453,"qty":26.96301055}],"asks":[],"checksum":2372024505,"timestamp":"2024-06-01T17:52:38.023987Z"}]}
{"channel":"book","type":"update","data":[{"symbol":"LINK/ETH","bids":[{"price":0.00489015,"qty":0.00000000},{"price":0.00486838,"qty":773.82968775}],"asks":[],"checksum":4216711550,"timestamp":"2024-06-01T17:52:38.048675Z"}]}
{"channel":"book","type":"update","data":[{"symbol":"LINK/ETH","bids":[{"price":0.00488880,"qty":0.00000000},{"price":0.00486721,"qty":175.83850000}],"asks":[],"checksum":1226428767,"timestamp":"2024-06-01T17:52:38.126496Z"}]}
{"channel":"book","type":"update","data":[{"symbol":"LINK/ETH","bids":[{"price":0.00488866,"qty":21.54283062}],"asks":[],"checksum":2441508033,"timestamp":"2024-06-01T17:52:38.406116Z"}]}
{"channel":"book","type":"update","data":[{"symbol":"LINK/ETH","bids":[{"price":0.00488866,"qty":0.00000000},{"price":0.00486721,"qty":175.83850000}],"asks":[],"checksum":1226428767,"timestamp":"2024-06-01T17:52:38.719286Z"}]}
{"channel":"book","type":"update","data":[{"symbol":"LINK/ETH","bids":[{"price":0.00488824,"qty":21.54368436}],"asks":[],"checksum":197214165,"timestamp":"2024-06-01T17:52:39.017546Z"}]}
{"channel":"book","type":"update","data":[{"symbol":"LINK/ETH","bids":[{"price":0.00486838,"qty":0.00000000},{"price":0.00486721,"qty":175.83850000}],"asks":[],"checksum":1402873117,"timestamp":"2024-06-01T17:52:39.286463Z"}]}
{"channel":"book","type":"update","data":[{"symbol":"LINK/ETH","bids":[{"price":0.00486846,"qty":1071.65987234}],"asks":[],"checksum":2997089945,"timestamp":"2024-06-01T17:52:39.326561Z"}]}
{"channel":"book","type":"update","data":[{"symbol":"LINK/ETH","bids":[{"price":0.00488900,"qty":26.93691991}],"asks":[],"checksum":3661438123,"timestamp":"2024-06-01T17:52:39.780748Z"}]}
{"channel":"book","type":"update","data":[{"symbol":"LINK/ETH","bids":[],"asks":[{"price":0.00489245,"qty":8.07546770}],"checksum":427616680,"timestamp":"2024-06-01T17:52:39.780802Z"}]}
{"channel":"book","type":"update","data":[{"symbol":"LINK/ETH","bids":[{"price":0.00488824,"qty":0.00000000},{"price":0.00486721,"qty":175.83850000}],"asks":[],"checksum":2044165130,"timestamp":"2024-06-01T17:52:40.185917Z"}]}
{"channel":"book","type":"update","data":[{"symbol":"LINK/ETH","bids":[{"price":0.00488823,"qty":21.54367824}],"asks":[],"checksum":3014020754,"timestamp":"2024-06-01T17:52:40.501995Z"}]}
{"channel":"book","type":"update","data":[{"symbol":"LINK/ETH","bids":[],"asks":[{"price":0.00489441,"qty":0.00000000},{"price":0.00492259,"qty":223.67586130}],"checksum":940435454,"timestamp":"2024-06-01T17:52:41.349227Z"}]}
{"channel":"book","type":"update","data":[{"symbol":"LINK/ETH","bids":[],"asks":[{"price":0.00489245,"qty":29.61924967}],"checksum":1566071829,"timestamp":"2024-06-01T17:52:41.647189Z"}]}
{"channel":"book","type":"update","data":[{"symbol":"LINK/ETH","bids":[{"price":0.00489078,"qty":0.00000000},{"price":0.00486721,"qty":175.83850000}],"asks":[],"checksum":2008657017,"timestamp":"2024-06-01T17:52:41.654319Z"}]}
{"channel":"book","type":"update","data":[{"symbol":"LINK/ETH","bids":[],"asks":[{"price":0.00491897,"qty":0.00000000},{"price":0.00492260,"qty":101.61891050}],"checksum":1251938234,"timestamp":"2024-06-01T17:52:41.654506Z"}]}
{"channel":"book","type":"update","data":[{"symbol":"LINK/ETH","bids":[],"asks":[{"price":0.00491900,"qty":0.00000000},{"price":0.00492872,"qty":283.29663722}],"checksum":3787565799,"timestamp":"2024-06-01T17:52:41.654598Z"}]}
{"channel":"book","type":"update","data":[{"symbol":"LINK/ETH","bids":[],"asks":[{"price":0.00491896,"qty":131.75171000}],"checksum":347058508,"timestamp":"2024-06-01T17:52:41.657004Z"}]}
{"channel":"book","type":"update","data":[{"symbol":"LINK/ETH","bids":[{"price":0.00488901,"qty":131.75171000}],"asks":[],"checksum":890858726,"timestamp":"2024-06-01T17:52:41.657326Z"}]}
{"channel":"book","type":"update","data":[{"symbol":"LINK/ETH","bids":[],"asks":[{"price":0.00491896,"qty":569.91845000}],"checksum":2191339728,"timestamp":"2024-06-01T17:52:41.657751Z"}]}
{"channel":"book","type":"update","data":[{"symbol":"LINK/ETH","bids":[{"price":0.00488900,"qty":0.00000000},{"price":0.00486721,"qty":175.83850000}],"asks":[],"checksum":895402760,"timestamp":"2024-06-01T17:52:41.661621Z"}]}
{"channel":"book","type":"update","data":[{"symbol":"LINK/ETH","bids":[{"price":0.00488903,"qty":26.93802634}],"asks":[],"checksum":693096370,"timestamp":"2024-06-01T17:52:41.665112Z"}]}
{"channel":"book","type":"update","data":[{"symbol":"LINK/ETH","bids":[],"asks":[{"price":0.00492259,"qty":0.00000000},{"price":0.00492872,"qty":283.29663722}],"checksum":1965002691,"timestamp":"2024-06-01T17:52:42.477330Z"}]}
{"channel":"book","type":"update","data":[{"symbol":"LINK/ETH","bids":[],"asks":[{"price":0.00491895,"qty":161.39662998}],"checksum":1348454640,"timestamp":"2024-06-01T17:52:42.517493Z"}]}
{"channel":"book","type":"update","data":[{"symbol":"LINK/ETH","bids":[],"asks":[{"price":0.00489241,"qty":4.84711415}],"checksum":787294723,"timestamp":"2024-06-01T17:52:43.097015Z"}]}
{"channel":"book","type":"update","data":[{"symbol":"LINK/ETH","bids":[],"asks":[{"price":0.00489325,"qty":0.00000000},{"price":0.00492260,"qty":101.61891050}],"checksum":3142795698,"timestamp":"2024-06-01T17:52:43.098176Z"}]}
{"channel":"book","type":"update","data":[{"symbol":"LINK/ETH","bids":[],"asks":[{"price":0.00489245,"qty":21.54378197}],"checksum":4152209400,"timestamp":"2024-06-01T17:52:43.100977Z"}]}
{"channel":"book","type":"update","data":[{"symbol":"LINK/ETH","bids":[],"asks":[{"price":0.00489222,"qty":8.07606600}],"checksum":775748954,"timestamp":"2024-06-01T17:52:43.104246Z"}]}
{"channel":"book","type":"update","data":[{"symbol":"LINK/ETH","bids":[{"price":0.00488901,"qty":0.00000000},{"price":0.00486721,"qty":175.83850000}],"asks":[],"checksum":2867037876,"timestamp":"2024-06-01T17:52:43.107346Z"}]}
{"channel":"book","type":"update","data":[{"symbol":"LINK/ETH","bids":[],"asks":[{"price":0.00491896,"qty":131.75171000}],"checksum":710842608,"timestamp":"2024-06-01T17:52:43.107390Z"}]}
{"channel":"book","type":"update","data":[{"symbol":"LINK/ETH","bids":[],"asks":[{"price":0.00491896,"qty":0.00000000},{"price":0.00492260,"qty":101.61891050}],"checksum":3252975877,"timestamp":"2024-06-01T17:52:43.107494Z"}]}
{"channel":"book","type":"update","data":[{"symbol":"LINK/ETH","bids":[{"price":0.00488904,"qty":131.75171000}],"asks":[],"checksum":2213844896,"timestamp":"2024-06-01T17:52:43.110234Z"}]}
{"channel":"book","type":"update","data":[{"symbol":"LINK/ETH","bids":[],"asks":[{"price":0.00491894,"qty":438.16674000}],"checksum":4142130935,"timestamp":"2024-06-01T17:52:43.110257Z"}]}
{"channel":"book","type":"update","data":[{"symbol":"LINK/ETH","bids":[],"asks":[{"price":0.00491894,"qty":569.91845000}],"checksum":2836374611,"timestamp":"2024-06-01T17:52:43.110764Z"}]}
{"channel":"book","type":"update","data":[{"symbol":"LINK/ETH","bids":[{"price":0.00488823,"qty":0.00000000},{"price":0.00486721,"qty":175.83850000}],"asks":[],"checksum":2511218630,"timestamp":"2024-06-01T17:52:43.371779Z"}]}
{"channel":"book","type":"update","data":[{"symbol":"LINK/ETH","bids":[{"price":0.00488821,"qty":21.54378197}],"asks":[],"checksum":3291667345,"timestamp":"2024-06-01T17:52:43.667408Z"}]}
{"channel":"book","type":"update","data":[{"symbol":"LINK/ETH","bids":[],"asks":[{"price":0.00489222,"qty":12.92363076}],"checksum":2764685883,"timestamp":"2024-06-01T17:52:44.359355Z"}]}
{"channel":"book","type":"update","data":[{"symbol":"LINK/ETH","bids":[],"asks":[{"price":0.00489241,"qty":0.00000000},{"price":0.00492260,"qty":101.61891050}],"checksum":3857648059,"timestamp":"2024-06-01T17:52:44.393646Z"}]}
{"channel":"book","type":"update","data":[{"symbol":"LINK/ETH","bids":[{"price":0.00488821,"qty":0.00000000},{"price":0.00486721,"qty":175.83850000}],"asks":[],"checksum":1312043970,"timestamp":"2024-06-01T17:52:44.447020Z"}]}
{"channel":"book","type":"update","data":[{"symbol":"LINK/ETH","bids":[],"asks":[{"price":0.00491894,"qty":438.16674000}],"checksum":658824018,"timestamp":"2024-06-01T17:52:44.590661Z"}]}
{"channel":"book","type":"update","data":[{"symbol":"LINK/ETH","bids":[{"price":0.00488904,"qty":0.00000000},{"price":0.00485763,"qty":9.62058391}],"asks":[],"checksum":1925864149,"timestamp":"2024-06-01T17:52:44.590732Z"}]}
{"channel":"book","type":"update","data":[{"symbol":"LINK/ETH","bids":[],"asks":[{"price":0.00491894,"qty":0.00000000},{"price":0.00492872,"qty":283.29663722}],"checksum":2277326635,"timestamp":"2024-06-01T17:52:44.590960Z"}]}
{"channel":"book","type":"update","data":[{"symbol":"LINK/ETH","bids":[{"price":0.00485987,"qty":5.85113244}],"asks":[],"checksum":785623664,"timestamp":"2024-06-01T17:52:44.593118Z"}]}
{"channel":"book","type":"update","data":[{"symbol":"LINK/ETH","bids":[],"asks":[{"price":0.00491893,"qty":131.75171000}],"checksum":3121728589,"timestamp":"2024-06-01T17:52:44.593471Z"}]}
{"channel":"book","type":"update","data":[{"symbol":"LINK/ETH","bids":[{"price":0.00488905,"qty":131.75171000}],"asks":[],"checksum":3058898747,"timestamp":"2024-06-01T17:52:44.593634Z"}]}
{"channel":"book","type":"update","data":[{"symbol":"LINK/ETH","bids":[],"asks":[{"price":0.00491893,"qty":569.91845000}],"checksum":2036205310,"timestamp":"2024-06-01T17:52:44.594003Z"}]}
{"channel":"book","type":"update","data":[{"symbol":"LINK/ETH","bids":[{"price":0.00488790,"qty":21.54522629}],"asks":[],"checksum":2872408431,"timestamp":"2024-06-01T17:52:44.753404Z"}]}
{"channel":"book","type":"update","data":[{"symbol":"LINK/ETH","bids":[{"price":0.00488790,"qty":0.00000000},{"price":0.00486721,"qty":175.83850000}],"asks":[],"checksum":2036205310,"timestamp":"2024-06-01T17:52:45.233783Z"}]}
{"channel":"book","type":"update","data":[{"symbol":"LINK/ETH","bids":[{"price":0.00488903,"qty":0.00000000},{"price":0.00485987,"qty":5.85113244}],"asks":[],"checksum":126367590,"timestamp":"2024-06-01T17:52:45.347385Z"}]}
{"channel":"book","type":"update","data":[{"symbol":"LINK/ETH","bids":[{"price":0.00488858,"qty":26.93933527}],"asks":[],"checksum":2006676569,"timestamp":"2024-06-01T17:52:45.352401Z"}]}
{"channel":"book","type":"update","data":[{"symbol":"LINK/ETH","bids":[{"price":0.00488789,"qty":21.54532238}],"asks":[],"checksum":1577733489,"timestamp":"2024-06-01T17:52:45.525647Z"}]}
{"channel":"book","type":"update","data":[{"symbol":"LINK/ETH","bids":[],"asks":[{"price":0.00489222,"qty":8.07606600}],"checksum":1854525737,"timestamp":"2024-06-01T17:52:46.912724Z"}]}
{"channel":"book","type":"update","data":[{"symbol":"LINK/ETH","bids":[],"asks":[{"price":0.00489222,"qty":0.00000000},{"price":0.00492872,"qty":283.29663722}],"checksum":2005232551,"timestamp":"2024-06-01T17:52:47.725941Z"}]}
{"channel":"book","type":"update","data":[{"symbol":"LINK/ETH","bids":[],"asks":[{"price":0.00489178,"qty":8.07642903}],"checksum":308987604,"timestamp":"2024-06-01T17:52:47.729505Z"}]}
{"channel":"book","type":"update","data":[{"symbol":"LINK/ETH","bids":[{"price":0.00488910,"qty":4.84713665}],"asks":[],"checksum":3169570185,"timestamp":"2024-06-01T17:52:49.042121Z"}]}
{"channel":"book","type":"update","data":[{"symbol":"LINK/ETH","bids":[{"price":0.00488858,"qty":0.00000000},{"price":0.00486846,"qty":1071.65987234}],"asks":[],"checksum":2391635902,"timestamp":"2024-06-01T17:52:49.112233Z"}]}
{"channel":"book","type":"update","data":[{"symbol":"LINK/ETH","bids":[],"asks":[{"price":0.00489178,"qty":0.00000000},{"price":0.00492872,"qty":283.29663722}],"checksum":3522806502,"timestamp":"2024-06-01T17:52:49.112250Z"}]}
{"channel":"book","type":"update","data":[{"symbol":"LINK/ETH","bids":[{"price":0.00488901,"qty":26.93821391}],"asks":[],"checksum":1203701008,"timestamp":"2024-06-01T17:52:49.117127Z"}]}
{"channel":"book","type":"update","data":[{"symbol":"LINK/ETH","bids":[],"asks":[{"price":0.00490808,"qty":0.00000000},{"price":0.00492873,"qty":9.52504690}],"checksum":1526930737,"timestamp":"2024-06-01T17:52:49.643646Z"}]}
{"channel":"book","type":"update","data":[{"symbol":"LINK/ETH","bids":[],"asks":[{"price":0.00490454,"qty":0.51309328}],"checksum":2493089483,"timestamp":"2024-06-01T17:52:49.709715Z"}]}
{"channel":"book","type":"update","data":[{"symbol":"LINK/ETH","bids":[{"price":0.00488901,"qty":0.00000000},{"price":0.00486846,"qty":1071.65987234}],"asks":[],"checksum":3347373966,"timestamp":"2024-06-01T17:52:50.112902Z"}]}
{"channel":"book","type":"update","data":[{"symbol":"LINK/ETH","bids":[],"asks":[{"price":0.00489226,"qty":8.07610029}],"checksum":1759113239,"timestamp":"2024-06-01T17:52:50.116700Z"}]}
{"channel":"book","type":"update","data":[{"symbol":"LINK/ETH","bids":[],"asks":[{"price":0.00491893,"qty":131.75171000}],"checksum":1373240681,"timestamp":"2024-06-01T17:52:50.480148Z"}]}
{"channel":"book","type":"update","data":[{"symbol":"LINK/ETH","bids":[{"price":0.00488905,"qty":0.00000000},{"price":0.00486721,"qty":175.83850000}],"asks":[],"checksum":3542679426,"timestamp":"2024-06-01T17:52:50.480250Z"}]}
{"channel":"book","type":"update","data":[{"symbol":"LINK/ETH","bids":[],"asks":[{"price":0.00491893,"qty":0.00000000},{"price":0.00492848,"qty":30.95796982}],"checksum":1502087037,"timestamp":"2024-06-01T17:52:50.480309Z"}]}
{"channel":"book","type":"update","data":[{"symbol":"LINK/ETH","bids":[],"asks":[{"price":0.00491892,"qty":438.16674000}],"checksum":3932767854,"timestamp":"2024-06-01T17:52:50.482930Z"}]}
{"channel":"book","type":"update","data":[{"symbol":"LINK/ETH","bids":[{"price":0.00488911,"qty":131.75171000}],"asks":[],"checksum":3199608349,"timestamp":"2024-06-01T17:52:50.482961Z"}]}
{"channel":"book","type":"update","data":[{"symbol":"LINK/ETH","bids":[],"asks":[{"price":0.00491892,"qty":569.91845000}],"checksum":1217996125,"timestamp":"2024-06-01T17:52:50.483135Z"}]}
{"channel":"book","type":"update","data":[{"symbol":"LINK/ETH","bids":[{"price":0.00488916,"qty":4.84713195}],"asks":[],"checksum":2649616246,"timestamp":"2024-06-01T17:52:50.485785Z"}]}
{"channel":"book","type":"update","data":[{"symbol":"LINK/ETH","bids":[{"price":0.00488910,"qty":0.00000000},{"price":0.00486846,"qty":1071.65987234}],"asks":[],"checksum":434158071,"timestamp":"2024-06-01T17:52:50.488460Z"}]}
{"channel":"book","type":"update","data":[{"symbol":"LINK/ETH","bids":[{"price":0.00488926,"qty":26.93826097}],"asks":[],"checksum":1127255494,"timestamp":"2024-06-01T17:52:51.780559Z"}]}
{"channel":"book","type":"update","data":[{"symbol":"LINK/ETH","bids":[{"price":0.00488931,"qty":4.84719328}],"asks":[],"checksum":390574505,"timestamp":"2024-06-01T17:52:51.783345Z"}]}
{"channel":"book","type":"update","data":[{"symbol":"LINK/ETH","bids":[{"price":0.00488916,"qty":0.00000000},{"price":0.00486847,"qty":42.55358638}],"asks":[],"checksum":1187110947,"timestamp":"2024-06-01T17:52:51.786062Z"}]}
{"channel":"book","type":"update","data":[{"symbol":"LINK/ETH","bids":[{"price":0.00488926,"qty":0.00000000},{"price":0.00486846,"qty":1071.65987234}],"asks":[],"checksum":4086620438,"timestamp":"2024-06-01T17:52:51.786926Z"}]}
{"channel":"book","type":"update","data":[{"symbol":"LINK/ETH","bids":[{"price":0.00488931,"qty":0.00000000},{"price":0.00486721,"qty":175.83850000}],"asks":[],"checksum":1268434080,"timestamp":"2024-06-01T17:52:52.064224Z"}]}
{"channel":"book","type":"update","data":[{"symbol":"LINK/ETH","bids":[],"asks":[{"price":0.00491895,"qty":0.00000000},{"price":0.00492847,"qty":283.29663722}],"checksum":4039406071,"timestamp":"2024-06-01T17:52:52.668086Z"}]}
{"channel":"book","type":"update","data":[{"symbol":"LINK/ETH","bids":[],"asks":[{"price":0.00491891,"qty":161.32255818}],"checksum":505839211,"timestamp":"2024-06-01T17:52:52.708161Z"}]}
{"channel":"book","type":"update","data":[{"symbol":"LINK/ETH","bids":[{"price":0.00488896,"qty":26.93814795}],"asks":[],"checksum":777348120,"timestamp":"2024-06-01T17:52:53.584166Z"}]}
{"channel":"book","type":"update","data":[{"symbol":"LINK/ETH","bids":[],"asks":[{"price":0.00489226,"qty":0.00000000},{"price":0.00492847,"qty":283.29663722}],"checksum":1864741111,"timestamp":"2024-06-01T17:52:53.591558Z"}]}
{"channel":"book","type":"update","data":[{"symbol":"LINK/ETH","bids":[],"asks":[{"price":0.00489185,"qty":8.07611823}],"checksum":2162010345,"timestamp":"2024-06-01T17:52:53.596384Z"}]}
{"channel":"book","type":"update","data":[{"symbol":"LINK/ETH","bids":[{"price":0.00488896,"qty":0.00000000},{"price":0.00486721,"qty":175.83850000}],"asks":[],"checksum":3560059949,"timestamp":"2024-06-01T17:52:53.614274Z"}]}
{"channel":"book","type":"update","data":[{"symbol":"LINK/ETH","bids":[{"price":0.00488493,"qty":0.00000000},{"price":0.00485763,"qty":9.62058391}],"asks":[],"checksum":2800197719,"timestamp":"2024-06-01T17:52:53.658295Z"}]}
{"channel":"book","type":"update","data":[{"symbol":"LINK/ETH","bids":[{"price":0.00485995,"qty":5.85124189}],"asks":[],"checksum":3234329968,"timestamp":"2024-06-01T17:52:53.660815Z"}]}
{"channel":"book","type":"update","data":[{"symbol":"LINK/ETH","bids":[{"price":0.00488916,"qty":4.84642104}],"asks":[],"checksum":3150668792,"timestamp":"2024-06-01T17:52:53.661410Z"}]}
{"channel":"book","type":"update","data":[{"symbol":"LINK/ETH","bids":[{"price":0.00488150,"qty":0.51939336}],"asks":[],"checksum":51597962,"timestamp":"2024-06-01T17:52:53.746238Z"}]}
{"channel":"book","type":"update","data":[{"symbol":"LINK/ETH","bids":[],"asks":[{"price":0.00489185,"qty":0.00000000},{"price":0.00492847,"qty":283.29663722}],"checksum":773547721,"timestamp":"2024-06-01T17:52:54.651153Z"}]}
{"channel":"book","type":"update","data":[{"symbol":"LINK/ETH","bids":[],"asks":[{"price":0.00489229,"qty":8.07534317}],"checksum":1932406505,"timestamp":"2024-06-01T17:52:55.557026Z"}]}
{"channel":"book","type":"update","data":[{"symbol":"LINK/ETH","bids":[{"price":0.00488923,"qty":26.93538738}],"asks":[],"checksum":438499911,"timestamp":"2024-06-01T17:52:55.557048Z"}]}
{"channel":"book","type":"update","data":[{"symbol":"LINK/ETH","bids":[{"price":0.00488928,"qty":4.84612327}],"asks":[],"checksum":3913416560,"timestamp":"2024-06-01T17:52:55.560151Z"}]}
{"channel":"book","type":"update","data":[{"symbol":"LINK/ETH","bids":[{"price":0.00488916,"qty":0.00000000},{"price":0.00486847,"qty":42.55358638}],"asks":[],"checksum":3582955029,"timestamp":"2024-06-01T17:52:55.566158Z"}]}
