{"channel":"book","type":"snapshot","data":[{"symbol":"LINK/JPY","bids":[{"price":2917.8,"qty":42.88900000},{"price":2912.4,"qty":42.72053907},{"price":2912.3,"qty":80.33850000},{"price":2912.2,"qty":219.16400000},{"price":2910.9,"qty":11209.80310230},{"price":2895.1,"qty":167.16150000},{"price":2894.7,"qty":3358.41182759},{"price":2894.0,"qty":108.24000000},{"price":2853.0,"qty":161.98600000},{"price":2852.8,"qty":27.45050000}],"asks":[{"price":2924.5,"qty":42.88900000},{"price":2931.7,"qty":150.86837272},{"price":2931.8,"qty":219.16400000},{"price":2932.0,"qty":8.07080788},{"price":2945.0,"qty":2.45081509},{"price":2945.1,"qty":167.16150000},{"price":2948.2,"qty":108.24000000},{"price":2952.3,"qty":108.24000000},{"price":2952.4,"qty":3363.25641005},{"price":2995.5,"qty":53.74600000}],"checksum":1524206381}]}
{"channel":"book","type":"update","data":[{"symbol":"LINK/JPY","bids":[],"asks":[{"price":2952.4,"qty":0.00000000},{"price":2995.7,"qty":0.38899606}],"checksum":135328537,"timestamp":"2024-06-01T17:51:53.408890Z"}]}
{"channel":"book","type":"update","data":[{"symbol":"LINK/JPY","bids":[],"asks":[{"price":2950.3,"qty":3365.08577287}],"checksum":1578505315,"timestamp":"2024-06-01T17:51:53.449079Z"}]}
{"channel":"book","type":"update","data":[{"symbol":"LINK/JPY","bids":[{"price":2912.3,"qty":0.00000000},{"price":2852.4,"qty":4.27881707}],"asks":[],"checksum":4129200796,"timestamp":"2024-06-01T17:51:53.781300Z"}]}
{"channel":"book","type":"update","data":[{"symbol":"LINK/JPY","bids":[],"asks":[{"price":2995.5,"qty":0.00000000},{"price":2995.7,"qty":0.38899606}],"checksum":4126262597,"timestamp":"2024-06-01T17:51:53.781346Z"}]}
{"channel":"book","type":"update","data":[{"symbol":"LINK/JPY","bids":[],"asks":[{"price":2945.1,"qty":0.00000000},{"price":2995.9,"qty":27.45050000}],"checksum":3932884782,"timestamp":"2024-06-01T17:51:53.781513Z"}]}
{"channel":"book","type":"update","data":[{"symbol":"LINK/JPY","bids":[{"price":2895.1,"qty":0.00000000},{"price":2833.0,"qty":0.60071655}],"asks":[],"checksum":3955516662,"timestamp":"2024-06-01T17:51:53.781605Z"}]}
{"channel":"book","type":"update","data":[{"symbol":"LINK/JPY","bids":[],"asks":[{"price":2931.7,"qty":70.52987272}],"checksum":4197119110,"timestamp":"2024-06-01T17:51:53.781733Z"}]}
{"channel":"book","type":"update","data":[{"symbol":"LINK/JPY","bids":[{"price":2853.0,"qty":53.74600000}],"asks":[],"checksum":4136481445,"timestamp":"2024-06-01T17:51:53.781779Z"}]}
{"channel":"book","type":"update","data":[{"symbol":"LINK/JPY","bids":[{"price":2853.0,"qty":0.00000000},{"price":2832.9,"qty":27.45050000}],"asks":[],"checksum":1234241928,"timestamp":"2024-06-01T17:51:53.781859Z"}]}
{"channel":"book","type":"update","data":[{"symbol":"LINK/JPY","bids":[{"price":2912.5,"qty":80.33850000}],"asks":[],"checksum":3601568880,"timestamp":"2024-06-01T17:51:53.784139Z"}]}
{"channel":"book","type":"update","data":[{"symbol":"LINK/JPY","bids":[],"asks":[{"price":2944.9,"qty":167.16150000}],"checksum":3956027604,"timestamp":"2024-06-01T17:51:53.784159Z"}]}
{"channel":"book","type":"update","data":[{"symbol":"LINK/JPY","bids":[],"asks":[{"price":2995.4,"qty":53.74600000}],"checksum":2601619907,"timestamp":"2024-06-01T17:51:53.784241Z"}]}
{"channel":"book","type":"update","data":[{"symbol":"LINK/JPY","bids":[{"price":2895.2,"qty":167.16150000}],"asks":[],"checksum":962767232,"timestamp":"2024-06-01T17:51:53.784319Z"}]}
{"channel":"book","type":"update","data":[{"symbol":"LINK/JPY","bids":[{"price":2853.1,"qty":108.24000000}],"asks":[],"checksum":3974716087,"timestamp":"2024-06-01T17:51:53.784427Z"}]}
{"channel":"book","type":"update","data":[{"symbol":"LINK/JPY","bids":[{"price":2853.1,"qty":161.98600000}],"asks":[],"checksum":2979636565,"timestamp":"2024-06-01T17:51:53.784539Z"}]}
{"channel":"book","type":"update","data":[{"symbol":"LINK/JPY","bids":[],"asks":[{"price":2931.6,"qty":80.33850000}],"checksum":2550294710,"timestamp":"2024-06-01T17:51:53.784666Z"}]}
{"channel":"book","type":"update","data":[{"symbol":"LINK/JPY","bids":[],"asks":[{"price":2931.7,"qty":0.00000000},{"price":2995.4,"qty":53.74600000}],"checksum":2454437740,"timestamp":"2024-06-01T17:51:53.789766Z"}]}
{"channel":"book","type":"update","data":[{"symbol":"LINK/JPY","bids":[{"price":2912.6,"qty":42.71760282}],"asks":[],"checksum":1050775856,"timestamp":"2024-06-01T17:51:53.789950Z"}]}
{"channel":"book","type":"update","data":[{"symbol":"LINK/JPY","bids":[],"asks":[{"price":2945.0,"qty":0.00000000},{"price":2995.7,"qty":0.38899606},{"price":2944.8,"qty":2.45098154}],"checksum":3647725568,"timestamp":"2024-06-01T17:51:53.789992Z"}]}
{"channel":"book","type":"update","data":[{"symbol":"LINK/JPY","bids":[],"asks":[{"price":2931.5,"qty":70.52987272}],"checksum":2385392213,"timestamp":"2024-06-01T17:51:53.790034Z"}]}
{"channel":"book","type":"update","data":[{"symbol":"LINK/JPY","bids":[{"price":2912.4,"qty":0.00000000},{"price":2852.8,"qty":27.45050000}],"asks":[],"checksum":3298586328,"timestamp":"2024-06-01T17:51:53.790221Z"}]}
{"channel":"book","type":"update","data":[{"symbol":"LINK/JPY","bids":[{"price":2910.9,"qty":0.00000000},{"price":2852.4,"qty":4.27881707}],"asks":[],"checksum":1294235827,"timestamp":"2024-06-01T17:51:59.379821Z"}]}
{"channel":"book","type":"update","data":[{"symbol":"LINK/JPY","bids":[{"price":2911.3,"qty":11205.45896198}],"asks":[],"checksum":1178971652,"timestamp":"2024-06-01T17:51:59.420228Z"}]}
{"channel":"book","type":"update","data":[{"symbol":"LINK/JPY","bids":[{"price":2853.1,"qty":53.74600000}],"asks":[],"checksum":152830906,"timestamp":"2024-06-01T17:51:59.665741Z"}]}
{"channel":"book","type":"update","data":[{"symbol":"LINK/JPY","bids":[],"asks":[{"price":2944.9,"qty":0.00000000},{"price":2995.7,"qty":0.38899606}],"checksum":3826737999,"timestamp":"2024-06-01T17:51:59.665770Z"}]}
{"channel":"book","type":"update","data":[{"symbol":"LINK/JPY","bids":[],"asks":[{"price":2931.6,"qty":0.00000000},{"price":2995.9,"qty":27.45050000}],"checksum":3957970414,"timestamp":"2024-06-01T17:51:59.665806Z"}]}
{"channel":"book","type":"update","data":[{"symbol":"LINK/JPY","bids":[{"price":2895.2,"qty":0.00000000},{"price":2852.4,"qty":4.27881707}],"asks":[],"checksum":3931839776,"timestamp":"2024-06-01T17:51:59.665901Z"}]}
{"channel":"book","type":"update","data":[{"symbol":"LINK/JPY","bids":[{"price":2853.1,"qty":0.00000000},{"price":2833.0,"qty":0.60071655}],"asks":[],"checksum":1997928483,"timestamp":"2024-06-01T17:51:59.665913Z"}]}
{"channel":"book","type":"update","data":[{"symbol":"LINK/JPY","bids":[{"price":2912.5,"qty":0.00000000},{"price":2832.9,"qty":27.45050000}],"asks":[],"checksum":3637406006,"timestamp":"2024-06-01T17:51:59.666210Z"}]}
{"channel":"book","type":"update","data":[{"symbol":"LINK/JPY","bids":[],"asks":[{"price":2995.3,"qty":53.74600000}],"checksum":3583507035,"timestamp":"2024-06-01T17:51:59.668441Z"}]}
{"channel":"book","type":"update","data":[{"symbol":"LINK/JPY","bids":[],"asks":[{"price":2944.7,"qty":167.16150000}],"checksum":2301744284,"timestamp":"2024-06-01T17:51:59.668824Z"}]}
{"channel":"book","type":"update","data":[{"symbol":"LINK/JPY","bids":[{"price":2912.7,"qty":80.33850000}],"asks":[],"checksum":1234253616,"timestamp":"2024-06-01T17:51:59.668947Z"}]}
{"channel":"book","type":"update","data":[{"symbol":"LINK/JPY","bids":[{"price":2853.2,"qty":108.24000000}],"asks":[],"checksum":3328882174,"timestamp":"2024-06-01T17:51:59.669098Z"}]}
{"channel":"book","type":"update","data":[{"symbol":"LINK/JPY","bids":[],"asks":[{"price":2931.4,"qty":80.33850000}],"checksum":4015403620,"timestamp":"2024-06-01T17:51:59.669115Z"}]}
{"channel":"book","type":"update","data":[{"symbol":"LINK/JPY","bids":[{"price":2853.2,"qty":161.98600000}],"asks":[],"checksum":2870479731,"timestamp":"2024-06-01T17:51:59.669270Z"}]}
{"channel":"book","type":"update","data":[{"symbol":"LINK/JPY","bids":[{"price":2895.3,"qty":167.16150000}],"asks":[],"checksum":1100133582,"timestamp":"2024-06-01T17:51:59.669601Z"}]}
{"channel":"book","type":"update","data":[{"symbol":"LINK/JPY","bids":[],"asks":[{"price":2944.8,"qty":0.00000000},{"price":2995.3,"qty":53.74600000},{"price":2944.6,"qty":2.45114801}],"checksum":4210807311,"timestamp":"2024-06-01T17:51:59.674113Z"}]}
{"channel":"book","type":"update","data":[{"symbol":"LINK/JPY","bids":[{"price":2912.8,"qty":42.71466973}],"asks":[],"checksum":3378467606,"timestamp":"2024-06-01T17:51:59.679861Z"}]}
{"channel":"book","type":"update","data":[{"symbol":"LINK/JPY","bids":[{"price":2912.6,"qty":0.00000000},{"price":2852.8,"qty":27.45050000}],"asks":[],"checksum":375874253,"timestamp":"2024-06-01T17:51:59.679878Z"}]}
{"channel":"book","type":"update","data":[{"symbol":"LINK/JPY","bids":[],"asks":[{"price":2931.3,"qty":70.52987272}],"checksum":3206913265,"timestamp":"2024-06-01T17:51:59.679967Z"}]}
{"channel":"book","type":"update","data":[{"symbol":"LINK/JPY","bids":[],"asks":[{"price":2931.5,"qty":0.00000000},{"price":2952.3,"qty":108.24000000}],"checksum":3351177106,"timestamp":"2024-06-01T17:51:59.680013Z"}]}
{"channel":"book","type":"update","data":[{"symbol":"LINK/JPY","bids":[{"price":2853.2,"qty":53.74600000}],"asks":[],"checksum":1279481966,"timestamp":"2024-06-01T17:52:05.550322Z"}]}
{"channel":"book","type":"update","data":[{"symbol":"LINK/JPY","bids":[{"price":2895.3,"qty":0.00000000},{"price":2852.4,"qty":4.27881707}],"asks":[],"checksum":332541819,"timestamp":"2024-06-01T17:52:05.550398Z"}]}
{"channel":"book","type":"update","data":[{"symbol":"LINK/JPY","bids":[{"price":2853.2,"qty":0.00000000},{"price":2833.0,"qty":0.60071655}],"asks":[],"checksum":1647742379,"timestamp":"2024-06-01T17:52:05.550415Z"}]}
{"channel":"book","type":"update","data":[{"symbol":"LINK/JPY","bids":[{"price":2894.8,"qty":167.16150000}],"asks":[],"checksum":2194721633,"timestamp":"2024-06-01T17:52:05.553018Z"}]}
{"channel":"book","type":"update","data":[{"symbol":"LINK/JPY","bids":[{"price":2852.9,"qty":53.74600000}],"asks":[],"checksum":1532189023,"timestamp":"2024-06-01T17:52:05.553230Z"}]}
{"channel":"book","type":"update","data":[{"symbol":"LINK/JPY","bids":[{"price":2852.9,"qty":161.98600000}],"asks":[],"checksum":2524444585,"timestamp":"2024-06-01T17:52:05.553296Z"}]}
{"channel":"book","type":"update","data":[{"symbol":"LINK/JPY","bids":[],"asks":[{"price":2944.7,"qty":0.00000000},{"price":2995.6,"qty":53.74600000}],"checksum":3524279137,"timestamp":"2024-06-01T17:52:11.434779Z"}]}
{"channel":"book","type":"update","data":[{"symbol":"LINK/JPY","bids":[{"price":2912.7,"qty":0.00000000},{"price":2852.4,"qty":4.27881707}],"asks":[],"checksum":2541923635,"timestamp":"2024-06-01T17:52:11.434889Z"}]}
{"channel":"book","type":"update","data":[{"symbol":"LINK/JPY","bids":[],"asks":[{"price":2931.4,"qty":0.00000000},{"price":2995.7,"qty":0.38899606}],"checksum":2546072076,"timestamp":"2024-06-01T17:52:11.434906Z"}]}
{"channel":"book","type":"update","data":[{"symbol":"LINK/JPY","bids":[],"asks":[{"price":2944.5,"qty":167.16150000}],"checksum":3863160591,"timestamp":"2024-06-01T17:52:11.437484Z"}]}
{"channel":"book","type":"update","data":[{"symbol":"LINK/JPY","bids":[{"price":2912.9,"qty":80.33850000}],"asks":[],"checksum":3282145334,"timestamp":"2024-06-01T17:52:11.437572Z"}]}
{"channel":"book","type":"update","data":[{"symbol":"LINK/JPY","bids":[],"asks":[{"price":2931.2,"qty":80.33850000}],"checksum":3592712556,"timestamp":"2024-06-01T17:52:11.437906Z"}]}
{"channel":"book","type":"update","data":[{"symbol":"LINK/JPY","bids":[],"asks":[{"price":2944.6,"qty":0.00000000},{"price":2995.6,"qty":53.74600000},{"price":2944.4,"qty":2.45131450}],"checksum":1164559250,"timestamp":"2024-06-01T17:52:11.442891Z"}]}
{"channel":"book","type":"update","data":[{"symbol":"LINK/JPY","bids":[],"asks":[{"price":2931.3,"qty":0.00000000},{"price":2995.6,"qty":53.74600000}],"checksum":1844475567,"timestamp":"2024-06-01T17:52:11.447782Z"}]}
{"channel":"book","type":"update","data":[{"symbol":"LINK/JPY","bids":[{"price":2913.0,"qty":42.71173704}],"asks":[],"checksum":3332477934,"timestamp":"2024-06-01T17:52:11.447931Z"}]}
{"channel":"book","type":"update","data":[{"symbol":"LINK/JPY","bids":[],"asks":[{"price":2931.1,"qty":70.52987272}],"checksum":1576246642,"timestamp":"2024-06-01T17:52:11.448012Z"}]}
{"channel":"book","type":"update","data":[{"symbol":"LINK/JPY","bids":[{"price":2912.8,"qty":0.00000000},{"price":2852.8,"qty":27.45050000}],"asks":[],"checksum":1392432874,"timestamp":"2024-06-01T17:52:11.448125Z"}]}
{"channel":"book","type":"update","data":[{"symbol":"LINK/JPY","bids":[],"asks":[{"price":2944.4,"qty":0.00000000},{"price":2995.6,"qty":53.74600000}],"checksum":2754393886,"timestamp":"2024-06-01T17:52:15.373999Z"}]}
{"channel":"book","type":"update","data":[{"symbol":"LINK/JPY","bids":[],"asks":[{"price":2944.4,"qty":2.45490135}],"checksum":504776711,"timestamp":"2024-06-01T17:52:15.377376Z"}]}
{"channel":"book","type":"update","data":[{"symbol":"LINK/JPY","bids":[{"price":2911.3,"qty":0.00000000},{"price":2852.4,"qty":4.27881707}],"asks":[],"checksum":3834600571,"timestamp":"2024-06-01T17:52:16.074266Z"}]}
{"channel":"book","type":"update","data":[{"symbol":"LINK/JPY","bids":[{"price":2911.2,"qty":11215.75892593}],"asks":[],"checksum":2773108099,"timestamp":"2024-06-01T17:52:16.114626Z"}]}
{"channel":"book","type":"update","data":[{"symbol":"LINK/JPY","bids":[{"price":2894.8,"qty":0.00000000},{"price":2852.4,"qty":4.27881707}],"asks":[],"checksum":2336928269,"timestamp":"2024-06-01T17:52:17.318832Z"}]}
{"channel":"book","type":"update","data":[{"symbol":"LINK/JPY","bids":[{"price":2852.9,"qty":108.24000000}],"asks":[],"checksum":3473181466,"timestamp":"2024-06-01T17:52:17.318980Z"}]}
{"channel":"book","type":"update","data":[{"symbol":"LINK/JPY","bids":[{"price":2852.9,"qty":0.00000000},{"price":2833.0,"qty":0.60071655}],"asks":[],"checksum":1934284068,"timestamp":"2024-06-01T17:52:17.319135Z"}]}
{"channel":"book","type":"update","data":[{"symbol":"LINK/JPY","bids":[{"price":2894.9,"qty":167.16150000}],"asks":[],"checksum":2754059485,"timestamp":"2024-06-01T17:52:17.321694Z"}]}
{"channel":"book","type":"update","data":[{"symbol":"LINK/JPY","bids":[{"price":2853.0,"qty":53.74600000}],"asks":[],"checksum":1159381445,"timestamp":"2024-06-01T17:52:17.321751Z"}]}
{"channel":"book","type":"update","data":[{"symbol":"LINK/JPY","bids":[{"price":2853.0,"qty":161.98600000}],"asks":[],"checksum":2259928171,"timestamp":"2024-06-01T17:52:17.321851Z"}]}
{"channel":"book","type":"update","data":[{"symbol":"LINK/JPY","bids":[{"price":2894.9,"qty":0.00000000},{"price":2852.4,"qty":4.27881707}],"asks":[],"checksum":4011604558,"timestamp":"2024-06-01T17:52:23.203760Z"}]}
{"channel":"book","type":"update","data":[{"symbol":"LINK/JPY","bids":[{"price":2853.0,"qty":108.24000000}],"asks":[],"checksum":2874278745,"timestamp":"2024-06-01T17:52:23.203786Z"}]}
{"channel":"book","type":"update","data":[{"symbol":"LINK/JPY","bids":[{"price":2853.0,"qty":0.00000000},{"price":2833.0,"qty":0.60071655}],"asks":[],"checksum":1934284068,"timestamp":"2024-06-01T17:52:23.203816Z"}]}
{"channel":"book","type":"update","data":[{"symbol":"LINK/JPY","bids":[],"asks":[{"price":2944.5,"qty":0.00000000},{"price":2995.5,"qty":53.74600000}],"checksum":1882720124,"timestamp":"2024-06-01T17:52:23.203856Z"}]}
{"channel":"book","type":"update","data":[{"symbol":"LINK/JPY","bids":[],"asks":[{"price":2931.2,"qty":0.00000000},{"price":2995.7,"qty":0.38899606}],"checksum":470314198,"timestamp":"2024-06-01T17:52:23.203885Z"}]}
{"channel":"book","type":"update","data":[{"symbol":"LINK/JPY","bids":[],"asks":[{"price":2995.5,"qty":0.00000000},{"price":2995.9,"qty":27.45050000}],"checksum":3858254428,"timestamp":"2024-06-01T17:52:23.203893Z"}]}
{"channel":"book","type":"update","data":[{"symbol":"LINK/JPY","bids":[{"price":2912.9,"qty":0.00000000},{"price":2832.9,"qty":27.45050000}],"asks":[],"checksum":1069723794,"timestamp":"2024-06-01T17:52:23.203902Z"}]}
{"channel":"book","type":"update","data":[{"symbol":"LINK/JPY","bids":[{"price":2852.9,"qty":108.24000000}],"asks":[],"checksum":2049847415,"timestamp":"2024-06-01T17:52:23.206518Z"}]}
{"channel":"book","type":"update","data":[{"symbol":"LINK/JPY","bids":[],"asks":[{"price":2995.6,"qty":53.74600000}],"checksum":1761068376,"timestamp":"2024-06-01T17:52:23.206549Z"}]}
{"channel":"book","type":"update","data":[{"symbol":"LINK/JPY","bids":[],"asks":[{"price":2931.0,"qty":80.33850000}],"checksum":3494930551,"timestamp":"2024-06-01T17:52:23.206567Z"}]}
{"channel":"book","type":"update","data":[{"symbol":"LINK/JPY","bids":[{"price":2894.8,"qty":167.16150000}],"asks":[],"checksum":3872804464,"timestamp":"2024-06-01T17:52:23.206637Z"}]}
{"channel":"book","type":"update","data":[{"symbol":"LINK/JPY","bids":[],"asks":[{"price":2944.3,"qty":167.16150000}],"checksum":4110520418,"timestamp":"2024-06-01T17:52:23.206657Z"}]}
{"channel":"book","type":"update","data":[{"symbol":"LINK/JPY","bids":[{"price":2852.9,"qty":161.98600000}],"asks":[],"checksum":2974787957,"timestamp":"2024-06-01T17:52:23.206742Z"}]}
{"channel":"book","type":"update","data":[{"symbol":"LINK/JPY","bids":[{"price":2913.1,"qty":80.33850000}],"asks":[],"checksum":1859698417,"timestamp":"2024-06-01T17:52:23.206917Z"}]}
{"channel":"book","type":"update","data":[{"symbol":"LINK/JPY","bids":[{"price":2913.2,"qty":42.70880612}],"asks":[],"checksum":93846862,"timestamp":"2024-06-01T17:52:23.210183Z"}]}
{"channel":"book","type":"update","data":[{"symbol":"LINK/JPY","bids":[],"asks":[{"price":2931.1,"qty":0.00000000},{"price":2995.6,"qty":53.74600000}],"checksum":1244805980,"timestamp":"2024-06-01T17:52:23.210383Z"}]}
{"channel":"book","type":"update","data":[{"symbol":"LINK/JPY","bids":[{"price":2913.0,"qty":0.00000000},{"price":2852.8,"qty":27.45050000}],"asks":[],"checksum":4251090416,"timestamp":"2024-06-01T17:52:23.210394Z"}]}
{"channel":"book","type":"update","data":[{"symbol":"LINK/JPY","bids":[],"asks":[{"price":2930.9,"qty":70.52987272}],"checksum":2489634841,"timestamp":"2024-06-01T17:52:23.210530Z"}]}
{"channel":"book","type":"update","data":[{"symbol":"LINK/JPY","bids":[],"asks":[{"price":2944.4,"qty":0.00000000},{"price":2995.6,"qty":53.74600000},{"price":2944.2,"qty":2.45506812}],"checksum":3804872930,"timestamp":"2024-06-01T17:52:23.212218Z"}]}
{"channel":"book","type":"update","data":[{"symbol":"LINK/JPY","bids":[],"asks":[{"price":2944.2,"qty":0.00000000},{"price":2995.6,"qty":53.74600000}],"checksum":1897461595,"timestamp":"2024-06-01T17:52:30.787180Z"}]}
{"channel":"book","type":"update","data":[{"symbol":"LINK/JPY","bids":[],"asks":[{"price":2944.2,"qty":2.45489795}],"checksum":14885199,"timestamp":"2024-06-01T17:52:30.793449Z"}]}
{"channel":"book","type":"update","data":[{"symbol":"LINK/JPY","bids":[{"price":2894.8,"qty":0.00000000},{"price":2852.4,"qty":4.27881707}],"asks":[],"checksum":3874349423,"timestamp":"2024-06-01T17:52:31.032246Z"}]}
{"channel":"book","type":"update","data":[{"symbol":"LINK/JPY","bids":[],"asks":[{"price":2944.3,"qty":0.00000000},{"price":2995.7,"qty":0.38899606}],"checksum":3946133966,"timestamp":"2024-06-01T17:52:31.032492Z"}]}
{"channel":"book","type":"update","data":[{"symbol":"LINK/JPY","bids":[{"price":2852.9,"qty":108.24000000}],"asks":[],"checksum":2944073945,"timestamp":"2024-06-01T17:52:31.032556Z"}]}
{"channel":"book","type":"update","data":[{"symbol":"LINK/JPY","bids":[{"price":2852.9,"qty":0.00000000},{"price":2833.0,"qty":0.60071655}],"asks":[],"checksum":539882775,"timestamp":"2024-06-01T17:52:31.032622Z"}]}
{"channel":"book","type":"update","data":[{"symbol":"LINK/JPY","bids":[],"asks":[{"price":2931.0,"qty":0.00000000},{"price":2995.9,"qty":27.45050000}],"checksum":1503634299,"timestamp":"2024-06-01T17:52:31.032798Z"}]}
{"channel":"book","type":"update","data":[{"symbol":"LINK/JPY","bids":[{"price":2853.0,"qty":108.24000000}],"asks":[],"checksum":1131320021,"timestamp":"2024-06-01T17:52:31.036013Z"}]}
{"channel":"book","type":"update","data":[{"symbol":"LINK/JPY","bids":[{"price":2853.0,"qty":161.98600000}],"asks":[],"checksum":119581634,"timestamp":"2024-06-01T17:52:31.036298Z"}]}
{"channel":"book","type":"update","data":[{"symbol":"LINK/JPY","bids":[{"price":2913.1,"qty":0.00000000},{"price":2833.0,"qty":0.60071655}],"asks":[],"checksum":1032375293,"timestamp":"2024-06-01T17:52:31.041361Z"}]}
{"channel":"book","type":"update","data":[{"symbol":"LINK/JPY","bids":[],"asks":[{"price":2944.2,"qty":169.61639795}],"checksum":2174619728,"timestamp":"2024-06-01T17:52:31.041598Z"}]}
{"channel":"book","type":"update","data":[{"symbol":"LINK/JPY","bids":[{"price":2894.9,"qty":167.16150000}],"asks":[],"checksum":1121444840,"timestamp":"2024-06-01T17:52:31.041626Z"}]}
{"channel":"book","type":"update","data":[{"symbol":"LINK/JPY","bids":[],"asks":[{"price":2995.5,"qty":53.74600000}],"checksum":741221600,"timestamp":"2024-06-01T17:52:31.041739Z"}]}
{"channel":"book","type":"update","data":[{"symbol":"LINK/JPY","bids":[],"asks":[{"price":2930.8,"qty":80.33850000}],"checksum":3048083224,"timestamp":"2024-06-01T17:52:31.044744Z"}]}
{"channel":"book","type":"update","data":[{"symbol":"LINK/JPY","bids":[],"asks":[{"price":2931.7,"qty":70.52987272}],"checksum":1401036527,"timestamp":"2024-06-01T17:52:31.048299Z"}]}
{"channel":"book","type":"update","data":[{"symbol":"LINK/JPY","bids":[],"asks":[{"price":2930.9,"qty":0.00000000},{"price":2995.5,"qty":53.74600000}],"checksum":3577097274,"timestamp":"2024-06-01T17:52:31.049471Z"}]}
{"channel":"book","type":"update","data":[{"symbol":"LINK/JPY","bids":[],"asks":[{"price":2944.2,"qty":167.16150000},{"price":2948.1,"qty":2.45165040}],"checksum":971405406,"timestamp":"2024-06-01T17:52:31.055281Z"}]}
{"channel":"book","type":"update","data":[{"symbol":"LINK/JPY","bids":[{"price":2913.3,"qty":80.33850000}],"asks":[],"checksum":585875445,"timestamp":"2024-06-01T17:52:31.055919Z"}]}
{"channel":"book","type":"update","data":[{"symbol":"LINK/JPY","bids":[{"price":2913.2,"qty":0.00000000},{"price":2852.4,"qty":4.27881707}],"asks":[],"checksum":1772366033,"timestamp":"2024-06-01T17:52:31.064949Z"}]}
{"channel":"book","type":"update","data":[{"symbol":"LINK/JPY","bids":[],"asks":[{"price":2931.7,"qty":0.00000000},{"price":2995.5,"qty":53.74600000}],"checksum":1519258767,"timestamp":"2024-06-01T17:52:31.067218Z"}]}
{"channel":"book","type":"update","data":[{"symbol":"LINK/JPY","bids":[{"price":2912.3,"qty":42.72200528}],"asks":[],"checksum":3971383138,"timestamp":"2024-06-01T17:52:31.067292Z"}]}
{"channel":"book","type":"update","data":[{"symbol":"LINK/JPY","bids":[],"asks":[{"price":2930.7,"qty":70.52987272}],"checksum":355725876,"timestamp":"2024-06-01T17:52:31.071603Z"}]}
{"channel":"book","type":"update","data":[{"symbol":"LINK/JPY","bids":[{"price":2913.4,"qty":42.70587560}],"asks":[],"checksum":204567198,"timestamp":"2024-06-01T17:52:31.082641Z"}]}
{"channel":"book","type":"update","data":[{"symbol":"LINK/JPY","bids":[{"price":2912.3,"qty":0.00000000},{"price":2852.8,"qty":27.45050000}],"asks":[],"checksum":1096301338,"timestamp":"2024-06-01T17:52:31.087044Z"}]}
{"channel":"book","type":"update","data":[{"symbol":"LINK/JPY","bids":[{"price":2911.2,"qty":0.00000000},{"price":2852.4,"qty":4.27881707}],"asks":[],"checksum":2444846494,"timestamp":"2024-06-01T17:52:33.263028Z"}]}
{"channel":"book","type":"update","data":[{"symbol":"LINK/JPY","bids":[{"price":2911.1,"qty":11218.92104030}],"asks":[],"checksum":2212705134,"timestamp":"2024-06-01T17:52:33.303353Z"}]}
{"channel":"book","type":"update","data":[{"symbol":"LINK/JPY","bids":[],"asks":[{"price":2948.1,"qty":0.00000000},{"price":2995.5,"qty":53.74600000},{"price":2944.1,"qty":2.45498133}],"checksum":260487478,"timestamp":"2024-06-01T17:52:33.448474Z"}]}
{"channel":"book","type":"update","data":[{"symbol":"LINK/JPY","bids":[{"price":2853.0,"qty":108.24000000}],"asks":[],"checksum":1391871700,"timestamp":"2024-06-01T17:52:34.974159Z"}]}
{"channel":"book","type":"update","data":[{"symbol":"LINK/JPY","bids":[{"price":2894.9,"qty":0.00000000},{"price":2852.4,"qty":4.27881707}],"asks":[],"checksum":2662570774,"timestamp":"2024-06-01T17:52:34.974170Z"}]}
{"channel":"book","type":"update","data":[{"symbol":"LINK/JPY","bids":[{"price":2853.0,"qty":0.00000000},{"price":2833.0,"qty":0.60071655}],"asks":[],"checksum":2670333734,"timestamp":"2024-06-01T17:52:34.974190Z"}]}
{"channel":"book","type":"update","data":[{"symbol":"LINK/JPY","bids":[],"asks":[{"price":2944.2,"qty":0.00000000},{"price":2995.5,"qty":53.74600000}],"checksum":3151142137,"timestamp":"2024-06-01T17:52:34.974201Z"}]}
{"channel":"book","type":"update","data":[{"symbol":"LINK/JPY","bids":[],"asks":[{"price":2995.5,"qty":0.00000000},{"price":2995.7,"qty":0.38899606}],"checksum":200909204,"timestamp":"2024-06-01T17:52:34.974211Z"}]}
{"channel":"book","type":"update","data":[{"symbol":"LINK/JPY","bids":[{"price":2852.9,"qty":108.24000000}],"asks":[],"checksum":325135286,"timestamp":"2024-06-01T17:52:34.976886Z"}]}
{"channel":"book","type":"update","data":[{"symbol":"LINK/JPY","bids":[{"price":2894.8,"qty":167.16150000}],"asks":[],"checksum":744371721,"timestamp":"2024-06-01T17:52:34.977045Z"}]}
{"channel":"book","type":"update","data":[{"symbol":"LINK/JPY","bids":[],"asks":[{"price":2995.6,"qty":53.74600000}],"checksum":377918824,"timestamp":"2024-06-01T17:52:34.977108Z"}]}
{"channel":"book","type":"update","data":[{"symbol":"LINK/JPY","bids":[{"price":2852.9,"qty":161.98600000}],"asks":[],"checksum":1274440330,"timestamp":"2024-06-01T17:52:34.977128Z"}]}
{"channel":"book","type":"update","data":[{"symbol":"LINK/JPY","bids":[],"asks":[{"price":2948.1,"qty":167.16150000}],"checksum":1352979776,"timestamp":"2024-06-01T17:52:34.977307Z"}]}
{"channel":"book","type":"update","data":[{"symbol":"LINK/JPY","bids":[{"price":2894.7,"qty":0.00000000},{"price":2852.4,"qty":4.27881707}],"asks":[],"checksum":964083676,"timestamp":"2024-06-01T17:52:39.574409Z"}]}
{"channel":"book","type":"update","data":[{"symbol":"LINK/JPY","bids":[{"price":2893.6,"qty":3365.86273149}],"asks":[],"checksum":155872801,"timestamp":"2024-06-01T17:52:39.614538Z"}]}
{"channel":"book","type":"update","data":[{"symbol":"LINK/JPY","bids":[],"asks":[{"price":2948.1,"qty":0.00000000},{"price":2995.6,"qty":53.74600000}],"checksum":303616491,"timestamp":"2024-06-01T17:52:40.858673Z"}]}
{"channel":"book","type":"update","data":[{"symbol":"LINK/JPY","bids":[],"asks":[{"price":2930.8,"qty":0.00000000},{"price":2995.7,"qty":0.38899606}],"checksum":1633485704,"timestamp":"2024-06-01T17:52:40.858756Z"}]}
{"channel":"book","type":"update","data":[{"symbol":"LINK/JPY","bids":[{"price":2894.8,"qty":0.00000000},{"price":2852.4,"qty":4.27881707}],"asks":[],"checksum":1183485732,"timestamp":"2024-06-01T17:52:40.858878Z"}]}
{"channel":"book","type":"update","data":[{"symbol":"LINK/JPY","bids":[{"price":2852.9,"qty":53.74600000}],"asks":[],"checksum":1704622182,"timestamp":"2024-06-01T17:52:40.859217Z"}]}
{"channel":"book","type":"update","data":[{"symbol":"LINK/JPY","bids":[{"price":2852.9,"qty":0.00000000},{"price":2833.0,"qty":0.60071655}],"asks":[],"checksum":2759899258,"timestamp":"2024-06-01T17:52:40.859307Z"}]}
{"channel":"book","type":"update","data":[{"symbol":"LINK/JPY","bids":[],"asks":[{"price":2995.6,"qty":0.00000000},{"price":2995.9,"qty":27.45050000}],"checksum":3399272227,"timestamp":"2024-06-01T17:52:40.859353Z"}]}
{"channel":"book","type":"update","data":[{"symbol":"LINK/JPY","bids":[],"asks":[{"price":2930.6,"qty":80.33850000}],"checksum":2020685399,"timestamp":"2024-06-01T17:52:40.861374Z"}]}
{"channel":"book","type":"update","data":[{"symbol":"LINK/JPY","bids":[],"asks":[{"price":2944.0,"qty":167.16150000}],"checksum":3216111178,"timestamp":"2024-06-01T17:52:40.861496Z"}]}
{"channel":"book","type":"update","data":[{"symbol":"LINK/JPY","bids":[{"price":2894.9,"qty":167.16150000}],"asks":[],"checksum":1872392871,"timestamp":"2024-06-01T17:52:40.861516Z"}]}
{"channel":"book","type":"update","data":[{"symbol":"LINK/JPY","bids":[{"price":2853.0,"qty":53.74600000}],"asks":[],"checksum":4110541833,"timestamp":"2024-06-01T17:52:40.861889Z"}]}
{"channel":"book","type":"update","data":[{"symbol":"LINK/JPY","bids":[{"price":2853.0,"qty":161.98600000}],"asks":[],"checksum":349262293,"timestamp":"2024-06-01T17:52:40.862107Z"}]}
{"channel":"book","type":"update","data":[{"symbol":"LINK/JPY","bids":[],"asks":[{"price":2944.1,"qty":0.00000000},{"price":2995.5,"qty":53.74600000},{"price":2943.9,"qty":2.45514812}],"checksum":4035656439,"timestamp":"2024-06-01T17:52:40.867097Z"}]}
{"channel":"book","type":"update","data":[{"symbol":"LINK/JPY","bids":[],"asks":[{"price":2930.7,"qty":0.00000000},{"price":2995.5,"qty":53.74600000}],"checksum":336175412,"timestamp":"2024-06-01T17:52:40.880327Z"}]}
{"channel":"book","type":"update","data":[{"symbol":"LINK/JPY","bids":[],"asks":[{"price":2930.5,"qty":70.52987272}],"checksum":1128300886,"timestamp":"2024-06-01T17:52:40.880531Z"}]}
{"channel":"book","type":"update","data":[{"symbol":"LINK/JPY","bids":[],"asks":[{"price":2943.9,"qty":0.00000000},{"price":2995.5,"qty":53.74600000}],"checksum":652437588,"timestamp":"2024-06-01T17:52:44.758862Z"}]}
{"channel":"book","type":"update","data":[{"symbol":"LINK/JPY","bids":[],"asks":[{"price":2944.0,"qty":0.00000000},{"price":2995.7,"qty":0.38899606}],"checksum":1485718293,"timestamp":"2024-06-01T17:52:46.742777Z"}]}
{"channel":"book","type":"update","data":[{"symbol":"LINK/JPY","bids":[{"price":2894.9,"qty":0.00000000},{"price":2852.4,"qty":4.27881707}],"asks":[],"checksum":944199671,"timestamp":"2024-06-01T17:52:46.742801Z"}]}
{"channel":"book","type":"update","data":[{"symbol":"LINK/JPY","bids":[],"asks":[{"price":2995.5,"qty":0.00000000},{"price":2995.9,"qty":27.45050000}],"checksum":2860955744,"timestamp":"2024-06-01T17:52:46.742843Z"}]}
{"channel":"book","type":"update","data":[{"symbol":"LINK/JPY","bids":[],"asks":[{"price":2930.6,"qty":0.00000000},{"price":3015.1,"qty":27.45050000}],"checksum":2440671761,"timestamp":"2024-06-01T17:52:46.742890Z"}]}
{"channel":"book","type":"update","data":[{"symbol":"LINK/JPY","bids":[{"price":2853.0,"qty":53.74600000}],"asks":[],"checksum":2608178055,"timestamp":"2024-06-01T17:52:46.742947Z"}]}
{"channel":"book","type":"update","data":[{"symbol":"LINK/JPY","bids":[{"price":2853.0,"qty":0.00000000},{"price":2833.0,"qty":0.60071655}],"asks":[],"checksum":2119689351,"timestamp":"2024-06-01T17:52:46.743032Z"}]}
{"channel":"book","type":"update","data":[{"symbol":"LINK/JPY","bids":[],"asks":[{"price":2948.1,"qty":2.45489967}],"checksum":3231055410,"timestamp":"2024-06-01T17:52:46.745035Z"}]}
{"channel":"book","type":"update","data":[{"symbol":"LINK/JPY","bids":[{"price":2895.0,"qty":167.16150000}],"asks":[],"checksum":2366116083,"timestamp":"2024-06-01T17:52:46.745415Z"}]}
{"channel":"book","type":"update","data":[{"symbol":"LINK/JPY","bids":[],"asks":[{"price":2943.9,"qty":167.16150000}],"checksum":2527474923,"timestamp":"2024-06-01T17:52:46.745521Z"}]}
{"channel":"book","type":"update","data":[{"symbol":"LINK/JPY","bids":[{"price":2853.1,"qty":53.74600000}],"asks":[],"checksum":1838117731,"timestamp":"2024-06-01T17:52:46.745628Z"}]}
{"channel":"book","type":"update","data":[{"symbol":"LINK/JPY","bids":[],"asks":[{"price":2995.4,"qty":53.74600000}],"checksum":7550412,"timestamp":"2024-06-01T17:52:46.745642Z"}]}
{"channel":"book","type":"update","data":[{"symbol":"LINK/JPY","bids":[],"asks":[{"price":2930.4,"qty":80.33850000}],"checksum":2211410694,"timestamp":"2024-06-01T17:52:46.745695Z"}]}
{"channel":"book","type":"update","data":[{"symbol":"LINK/JPY","bids":[{"price":2853.1,"qty":161.98600000}],"asks":[],"checksum":2216198867,"timestamp":"2024-06-01T17:52:46.745754Z"}]}
{"channel":"book","type":"update","data":[{"symbol":"LINK/JPY","bids":[],"asks":[{"price":2930.5,"qty":0.00000000},{"price":2995.4,"qty":53.74600000}],"checksum":3707244290,"timestamp":"2024-06-01T17:52:46.747383Z"}]}
{"channel":"book","type":"update","data":[{"symbol":"LINK/JPY","bids":[],"asks":[{"price":2931.7,"qty":70.52987272}],"checksum":1012033538,"timestamp":"2024-06-01T17:52:46.747452Z"}]}
{"channel":"book","type":"update","data":[{"symbol":"LINK/JPY","bids":[],"asks":[{"price":2930.3,"qty":70.52987272}],"checksum":614839963,"timestamp":"2024-06-01T17:52:46.775951Z"}]}
{"channel":"book","type":"update","data":[{"symbol":"LINK/JPY","bids":[],"asks":[{"price":2931.7,"qty":0.00000000},{"price":2952.3,"qty":108.24000000}],"checksum":1438713740,"timestamp":"2024-06-01T17:52:46.776070Z"}]}
{"channel":"book","type":"update","data":[{"symbol":"LINK/JPY","bids":[],"asks":[{"price":2948.1,"qty":0.00000000},{"price":2995.4,"qty":53.74600000},{"price":2943.8,"qty":2.45848553}],"checksum":3401653004,"timestamp":"2024-06-01T17:52:49.138970Z"}]}
{"channel":"book","type":"update","data":[{"symbol":"LINK/JPY","bids":[],"asks":[{"price":2943.9,"qty":0.00000000},{"price":2995.4,"qty":53.74600000}],"checksum":1504643464,"timestamp":"2024-06-01T17:52:52.626172Z"}]}
{"channel":"book","type":"update","data":[{"symbol":"LINK/JPY","bids":[{"price":2853.1,"qty":53.74600000}],"asks":[],"checksum":960029033,"timestamp":"2024-06-01T17:52:52.626227Z"}]}
{"channel":"book","type":"update","data":[{"symbol":"LINK/JPY","bids":[{"price":2895.0,"qty":0.00000000},{"price":2852.4,"qty":4.27881707}],"asks":[],"checksum":1015105347,"timestamp":"2024-06-01T17:52:52.626349Z"}]}
{"channel":"book","type":"update","data":[{"symbol":"LINK/JPY","bids":[],"asks":[{"price":2995.4,"qty":0.00000000},{"price":2995.7,"qty":0.38899606}],"checksum":2024637054,"timestamp":"2024-06-01T17:52:52.626391Z"}]}
{"channel":"book","type":"update","data":[{"symbol":"LINK/JPY","bids":[{"price":2853.1,"qty":0.00000000},{"price":2833.0,"qty":0.60071655}],"asks":[],"checksum":3530789584,"timestamp":"2024-06-01T17:52:52.626546Z"}]}
{"channel":"book","type":"update","data":[{"symbol":"LINK/JPY","bids":[],"asks":[{"price":2948.1,"qty":167.16150000}],"checksum":2494889710,"timestamp":"2024-06-01T17:52:52.628798Z"}]}
{"channel":"book","type":"update","data":[{"symbol":"LINK/JPY","bids":[{"price":2852.9,"qty":108.24000000}],"asks":[],"checksum":2135538201,"timestamp":"2024-06-01T17:52:52.628993Z"}]}
{"channel":"book","type":"update","data":[{"symbol":"LINK/JPY","bids":[{"price":2894.1,"qty":167.16150000}],"asks":[],"checksum":2105617580,"timestamp":"2024-06-01T17:52:52.629150Z"}]}
{"channel":"book","type":"update","data":[{"symbol":"LINK/JPY","bids":[{"price":2852.9,"qty":161.98600000}],"asks":[],"checksum":552719182,"timestamp":"2024-06-01T17:52:52.629175Z"}]}
{"channel":"book","type":"update","data":[{"symbol":"LINK/JPY","bids":[],"asks":[{"price":2943.8,"qty":0.00000000},{"price":2995.6,"qty":53.74600000},{"price":2948.0,"qty":2.45498294}],"checksum":1075372407,"timestamp":"2024-06-01T17:52:53.208759Z"}]}
