{"channel":"book","type":"update","data":[{"symbol":"LTC/USDT","bids":[{"price":83.23794,"qty":23.85306512}],"asks":[],"checksum":204723662,"timestamp":"2024-06-01T17:52:56.507004Z"}]}
{"channel":"book","type":"update","data":[{"symbol":"LTC/USDT","bids":[{"price":83.23877,"qty":16.22445457}],"asks":[],"checksum":1179551490,"timestamp":"2024-06-01T17:52:56.509702Z"}]}
{"channel":"book","type":"update","data":[{"symbol":"LTC/USDT","bids":[],"asks":[{"price":83.27935,"qty":1.99000000}],"checksum":1914526603,"timestamp":"2024-06-01T17:52:56.511974Z"}]}
{"channel":"book","type":"update","data":[{"symbol":"LTC/USDT","bids":[{"price":83.23793,"qty":0.00000000},{"price":83.20979,"qty":2.55000000}],"asks":[],"checksum":3798326598,"timestamp":"2024-06-01T17:52:56.512594Z"}]}
{"channel":"book","type":"update","data":[{"symbol":"LTC/USDT","bids":[],"asks":[{"price":83.27955,"qty":0.00000000},{"price":83.32787,"qty":36.00236031}],"checksum":607753766,"timestamp":"2024-06-01T17:52:56.514460Z"}]}
{"channel":"book","type":"update","data":[{"symbol":"LTC/USDT","bids":[],"asks":[{"price":83.27700,"qty":1.80000000}],"checksum":2817415000,"timestamp":"2024-06-01T17:52:56.514734Z"}]}
{"channel":"book","type":"update","data":[{"symbol":"LTC/USDT","bids":[],"asks":[{"price":83.27935,"qty":0.00000000},{"price":83.32787,"qty":36.00236031}],"checksum":3296249044,"timestamp":"2024-06-01T17:52:56.586593Z"}]}
{"channel":"book","type":"update","data":[{"symbol":"LTC/USDT","bids":[{"price":83.23878,"qty":23.85306512}],"asks":[],"checksum":981394550,"timestamp":"2024-06-01T17:52:56.590632Z"}]}
{"channel":"book","type":"update","data":[{"symbol":"LTC/USDT","bids":[{"price":83.23955,"qty":16.22431819}],"asks":[],"checksum":293334063,"timestamp":"2024-06-01T17:52:56.593570Z"}]}
{"channel":"book","type":"update","data":[{"symbol":"LTC/USDT","bids":[{"price":83.23877,"qty":0.00000000},{"price":83.21003,"qty":3.02951062}],"asks":[],"checksum":3706485449,"timestamp":"2024-06-01T17:52:56.596472Z"}]}
{"channel":"book","type":"update","data":[{"symbol":"LTC/USDT","bids":[{"price":83.25625,"qty":18.02892205}],"asks":[],"checksum":2779445816,"timestamp":"2024-06-01T17:52:56.653652Z"}]}
{"channel":"book","type":"update","data":[{"symbol":"LTC/USDT","bids":[{"price":83.23794,"qty":0.00000000},{"price":83.21003,"qty":3.02951062}],"asks":[],"checksum":4211944857,"timestamp":"2024-06-01T17:52:56.657545Z"}]}
{"channel":"book","type":"update","data":[{"symbol":"LTC/USDT","bids":[{"price":83.25117,"qty":9.01446102}],"asks":[],"checksum":2975389660,"timestamp":"2024-06-01T17:52:56.683118Z"}]}
{"channel":"book","type":"update","data":[{"symbol":"LTC/USDT","bids":[{"price":83.25625,"qty":0.00000000},{"price":83.21003,"qty":3.02951062}],"asks":[],"checksum":473474178,"timestamp":"2024-06-01T17:52:57.101046Z"}]}
{"channel":"book","type":"update","data":[{"symbol":"LTC/USDT","bids":[{"price":83.25118,"qty":23.85306512}],"asks":[],"checksum":2855382498,"timestamp":"2024-06-01T17:52:57.104798Z"}]}
{"channel":"book","type":"update","data":[{"symbol":"LTC/USDT","bids":[{"price":83.25117,"qty":0.00000000},{"price":83.21003,"qty":3.02951062}],"asks":[],"checksum":3764672423,"timestamp":"2024-06-01T17:52:57.128677Z"}]}
{"channel":"book","type":"update","data":[{"symbol":"LTC/USDT","bids":[{"price":83.25666,"qty":18.02892323}],"asks":[],"checksum":1416663227,"timestamp":"2024-06-01T17:52:57.142141Z"}]}
{"channel":"book","type":"update","data":[{"symbol":"LTC/USDT","bids":[{"price":83.23878,"qty":0.00000000},{"price":83.21003,"qty":3.02951062}],"asks":[],"checksum":2425101984,"timestamp":"2024-06-01T17:52:57.145876Z"}]}
{"channel":"book","type":"update","data":[{"symbol":"LTC/USDT","bids":[{"price":83.25158,"qty":9.01446161}],"asks":[],"checksum":429340747,"timestamp":"2024-06-01T17:52:57.168941Z"}]}
{"channel":"book","type":"update","data":[{"symbol":"LTC/USDT","bids":[{"price":83.25158,"qty":0.00000000},{"price":83.21003,"qty":3.02951062}],"asks":[],"checksum":2425101984,"timestamp":"2024-06-01T17:52:57.315532Z"}]}
{"channel":"book","type":"update","data":[{"symbol":"LTC/USDT","bids":[],"asks":[{"price":83.27680,"qty":1.99000000}],"checksum":537439360,"timestamp":"2024-06-01T17:52:57.586313Z"}]}
{"channel":"book","type":"update","data":[{"symbol":"LTC/USDT","bids":[],"asks":[{"price":83.28080,"qty":0.00000000},{"price":83.32787,"qty":36.00236031}],"checksum":2802351489,"timestamp":"2024-06-01T17:52:57.591271Z"}]}
{"channel":"book","type":"update","data":[{"symbol":"LTC/USDT","bids":[],"asks":[{"price":83.28722,"qty":1.80000000}],"checksum":727172112,"timestamp":"2024-06-01T17:52:57.594002Z"}]}
{"channel":"book","type":"update","data":[{"symbol":"LTC/USDT","bids":[],"asks":[{"price":83.27700,"qty":0.00000000},{"price":83.32787,"qty":36.00236031}],"checksum":4136996469,"timestamp":"2024-06-01T17:52:57.594033Z"}]}
{"channel":"book","type":"update","data":[{"symbol":"LTC/USDT","bids":[],"asks":[{"price":83.28710,"qty":10.00000000}],"checksum":429896316,"timestamp":"2024-06-01T17:52:57.711308Z"}]}
{"channel":"book","type":"update","data":[{"symbol":"LTC/USDT","bids":[],"asks":[{"price":83.28988,"qty":0.00000000},{"price":83.32787,"qty":36.00236031}],"checksum":4209090440,"timestamp":"2024-06-01T17:52:57.715720Z"}]}
{"channel":"book","type":"update","data":[{"symbol":"LTC/USDT","bids":[{"price":83.25666,"qty":0.00000000},{"price":83.20979,"qty":2.55000000}],"asks":[],"checksum":1438392336,"timestamp":"2024-06-01T17:52:57.736900Z"}]}
{"channel":"book","type":"update","data":[{"symbol":"LTC/USDT","bids":[{"price":83.25634,"qty":18.02901786}],"asks":[],"checksum":4177676639,"timestamp":"2024-06-01T17:52:57.777043Z"}]}
{"channel":"book","type":"update","data":[{"symbol":"LTC/USDT","bids":[{"price":83.25126,"qty":9.01450895}],"asks":[],"checksum":4277659061,"timestamp":"2024-06-01T17:52:57.866245Z"}]}
{"channel":"book","type":"update","data":[{"symbol":"LTC/USDT","bids":[],"asks":[{"price":83.28722,"qty":0.00000000},{"price":83.32816,"qty":3.02951062}],"checksum":707992345,"timestamp":"2024-06-01T17:52:57.970928Z"}]}
{"channel":"book","type":"update","data":[{"symbol":"LTC/USDT","bids":[],"asks":[{"price":83.28444,"qty":1.80000000}],"checksum":53231280,"timestamp":"2024-06-01T17:52:57.971160Z"}]}
{"channel":"book","type":"update","data":[{"symbol":"LTC/USDT","bids":[{"price":83.25634,"qty":0.00000000},{"price":83.21003,"qty":3.02951062}],"asks":[],"checksum":1710746502,"timestamp":"2024-06-01T17:52:58.290479Z"}]}
{"channel":"book","type":"update","data":[{"symbol":"LTC/USDT","bids":[{"price":83.25127,"qty":23.85306512}],"asks":[],"checksum":3066806802,"timestamp":"2024-06-01T17:52:58.294528Z"}]}
{"channel":"book","type":"update","data":[{"symbol":"LTC/USDT","bids":[],"asks":[{"price":83.27680,"qty":0.00000000},{"price":83.32816,"qty":3.02951062}],"checksum":4206226527,"timestamp":"2024-06-01T17:52:58.295737Z"}]}
{"channel":"book","type":"update","data":[{"symbol":"LTC/USDT","bids":[{"price":83.25126,"qty":0.00000000},{"price":83.21003,"qty":3.02951062}],"asks":[],"checksum":4248846517,"timestamp":"2024-06-01T17:52:58.377631Z"}]}
{"channel":"book","type":"update","data":[{"symbol":"LTC/USDT","bids":[{"price":83.25127,"qty":0.00000000},{"price":83.20979,"qty":2.55000000}],"asks":[],"checksum":4221586475,"timestamp":"2024-06-01T17:52:58.381307Z"}]}
{"channel":"book","type":"update","data":[{"symbol":"LTC/USDT","bids":[],"asks":[{"price":83.28710,"qty":0.00000000},{"price":83.34094,"qty":2.34609048}],"checksum":2002301643,"timestamp":"2024-06-01T17:52:58.382328Z"}]}
{"channel":"book","type":"update","data":[{"symbol":"LTC/USDT","bids":[],"asks":[{"price":83.28988,"qty":10.00000000}],"checksum":3410236675,"timestamp":"2024-06-01T17:52:58.382482Z"}]}
{"channel":"book","type":"update","data":[{"symbol":"LTC/USDT","bids":[],"asks":[{"price":83.28424,"qty":1.99000000}],"checksum":787979119,"timestamp":"2024-06-01T17:52:58.383065Z"}]}
{"channel":"book","type":"update","data":[{"symbol":"LTC/USDT","bids":[],"asks":[{"price":83.28444,"qty":0.00000000},{"price":83.32816,"qty":3.02951062}],"checksum":807217930,"timestamp":"2024-06-01T17:52:58.767213Z"}]}
{"channel":"book","type":"update","data":[{"symbol":"LTC/USDT","bids":[],"asks":[{"price":83.28158,"qty":1.80000000}],"checksum":997020757,"timestamp":"2024-06-01T17:52:58.767531Z"}]}
{"channel":"book","type":"update","data":[{"symbol":"LTC/USDT","bids":[{"price":83.25118,"qty":0.00000000},{"price":83.20924,"qty":8.37200000}],"asks":[],"checksum":2865295249,"timestamp":"2024-06-01T17:52:58.771313Z"}]}
{"channel":"book","type":"update","data":[{"symbol":"LTC/USDT","bids":[],"asks":[{"price":83.28424,"qty":0.00000000},{"price":83.32816,"qty":3.02951062}],"checksum":2428142615,"timestamp":"2024-06-01T17:52:58.772361Z"}]}
{"channel":"book","type":"update","data":[{"symbol":"LTC/USDT","bids":[],"asks":[{"price":83.28158,"qty":0.00000000},{"price":83.34094,"qty":2.34609048}],"checksum":2514905506,"timestamp":"2024-06-01T17:52:58.775030Z"}]}
{"channel":"book","type":"update","data":[{"symbol":"LTC/USDT","bids":[{"price":83.21671,"qty":3.60586406}],"asks":[],"checksum":311345650,"timestamp":"2024-06-01T17:52:58.776195Z"}]}
{"channel":"book","type":"update","data":[{"symbol":"LTC/USDT","bids":[{"price":83.25721,"qty":18.02894746}],"asks":[],"checksum":923895295,"timestamp":"2024-06-01T17:52:58.777905Z"}]}
{"channel":"book","type":"update","data":[{"symbol":"LTC/USDT","bids":[{"price":83.21671,"qty":0.00000000},{"price":83.20979,"qty":2.55000000}],"asks":[],"checksum":724651555,"timestamp":"2024-06-01T17:52:58.782861Z"}]}
{"channel":"book","type":"update","data":[{"symbol":"LTC/USDT","bids":[{"price":83.25213,"qty":9.01447373}],"asks":[],"checksum":3102984421,"timestamp":"2024-06-01T17:52:58.927685Z"}]}
{"channel":"book","type":"update","data":[{"symbol":"LTC/USDT","bids":[],"asks":[{"price":83.28968,"qty":1.99000000}],"checksum":702980815,"timestamp":"2024-06-01T17:52:58.932724Z"}]}
{"channel":"book","type":"update","data":[{"symbol":"LTC/USDT","bids":[{"price":83.24599,"qty":23.85306512}],"asks":[],"checksum":474930408,"timestamp":"2024-06-01T17:52:59.021013Z"}]}
{"channel":"book","type":"update","data":[{"symbol":"LTC/USDT","bids":[],"asks":[{"price":83.30493,"qty":0.00000000},{"price":83.34094,"qty":2.34609048}],"checksum":2024481549,"timestamp":"2024-06-01T17:52:59.211978Z"}]}
{"channel":"book","type":"update","data":[{"symbol":"LTC/USDT","bids":[{"price":83.25721,"qty":0.00000000},{"price":83.21003,"qty":3.02951062}],"asks":[],"checksum":1571228489,"timestamp":"2024-06-01T17:52:59.289539Z"}]}
{"channel":"book","type":"update","data":[{"symbol":"LTC/USDT","bids":[{"price":83.25214,"qty":23.85306512}],"asks":[],"checksum":147348734,"timestamp":"2024-06-01T17:52:59.294575Z"}]}
{"channel":"book","type":"update","data":[{"symbol":"LTC/USDT","bids":[{"price":83.25777,"qty":18.02887221}],"asks":[],"checksum":2169925418,"timestamp":"2024-06-01T17:52:59.329787Z"}]}
{"channel":"book","type":"update","data":[{"symbol":"LTC/USDT","bids":[{"price":83.25214,"qty":0.00000000},{"price":83.21015,"qty":9.76343889}],"asks":[],"checksum":2417686092,"timestamp":"2024-06-01T17:52:59.333769Z"}]}
{"channel":"book","type":"update","data":[{"symbol":"LTC/USDT","bids":[{"price":83.25213,"qty":0.00000000},{"price":83.21003,"qty":3.02951062}],"asks":[],"checksum":2548515573,"timestamp":"2024-06-01T17:52:59.373854Z"}]}
{"channel":"book","type":"update","data":[{"symbol":"LTC/USDT","bids":[{"price":83.25212,"qty":9.01447334}],"asks":[],"checksum":3941803816,"timestamp":"2024-06-01T17:52:59.414058Z"}]}
{"channel":"book","type":"update","data":[{"symbol":"LTC/USDT","bids":[],"asks":[{"price":83.30783,"qty":0.00000000},{"price":83.34690,"qty":13.36927600}],"checksum":4180420140,"timestamp":"2024-06-01T17:52:59.498008Z"}]}
{"channel":"book","type":"update","data":[{"symbol":"LTC/USDT","bids":[],"asks":[{"price":83.30970,"qty":8.37200000}],"checksum":1309184400,"timestamp":"2024-06-01T17:52:59.500375Z"}]}
{"channel":"book","type":"update","data":[{"symbol":"LTC/USDT","bids":[],"asks":[{"price":83.31237,"qty":20.17645256}],"checksum":3860554838,"timestamp":"2024-06-01T17:52:59.504999Z"}]}
{"channel":"book","type":"update","data":[{"symbol":"LTC/USDT","bids":[{"price":83.25777,"qty":0.00000000},{"price":83.21003,"qty":3.02951062}],"asks":[],"checksum":3057239754,"timestamp":"2024-06-01T17:52:59.842850Z"}]}
{"channel":"book","type":"update","data":[{"symbol":"LTC/USDT","bids":[{"price":83.25212,"qty":0.00000000},{"price":83.20979,"qty":2.55000000}],"asks":[],"checksum":3551905894,"timestamp":"2024-06-01T17:52:59.927855Z"}]}
{"channel":"book","type":"update","data":[{"symbol":"LTC/USDT","bids":[{"price":83.25805,"qty":18.02883589}],"asks":[],"checksum":3720367330,"timestamp":"2024-06-01T17:53:00.332456Z"}]}
{"channel":"book","type":"update","data":[{"symbol":"LTC/USDT","bids":[{"price":83.25297,"qty":9.01441794}],"asks":[],"checksum":1849729026,"timestamp":"2024-06-01T17:53:00.480162Z"}]}
{"channel":"book","type":"update","data":[{"symbol":"LTC/USDT","bids":[],"asks":[{"price":83.28702,"qty":1.80000000}],"checksum":1948295805,"timestamp":"2024-06-01T17:53:00.482930Z"}]}
{"channel":"book","type":"update","data":[{"symbol":"LTC/USDT","bids":[],"asks":[{"price":83.28682,"qty":1.99000000}],"checksum":3754440053,"timestamp":"2024-06-01T17:53:00.588770Z"}]}
{"channel":"book","type":"update","data":[{"symbol":"LTC/USDT","bids":[],"asks":[{"price":83.28968,"qty":0.00000000},{"price":83.32787,"qty":36.00236031}],"checksum":1526873433,"timestamp":"2024-06-01T17:53:00.593462Z"}]}
{"channel":"book","type":"update","data":[{"symbol":"LTC/USDT","bids":[],"asks":[{"price":83.28690,"qty":10.00000000}],"checksum":2724708533,"timestamp":"2024-06-01T17:53:00.593694Z"}]}
{"channel":"book","type":"update","data":[{"symbol":"LTC/USDT","bids":[],"asks":[{"price":83.28988,"qty":0.00000000},{"price":83.32787,"qty":36.00236031}],"checksum":2466075703,"timestamp":"2024-06-01T17:53:00.711702Z"}]}
{"channel":"book","type":"update","data":[{"symbol":"LTC/USDT","bids":[],"asks":[{"price":83.28670,"qty":1.99000000}],"checksum":2923532946,"timestamp":"2024-06-01T17:53:00.717596Z"}]}
{"channel":"book","type":"update","data":[{"symbol":"LTC/USDT","bids":[],"asks":[{"price":83.31237,"qty":0.00000000},{"price":83.32787,"qty":36.00236031}],"checksum":3247404766,"timestamp":"2024-06-01T17:53:00.843217Z"}]}
{"channel":"book","type":"update","data":[{"symbol":"LTC/USDT","bids":[{"price":83.25805,"qty":0.00000000},{"price":83.21003,"qty":3.02951062}],"asks":[],"checksum":2822722196,"timestamp":"2024-06-01T17:53:00.898485Z"}]}
{"channel":"book","type":"update","data":[{"symbol":"LTC/USDT","bids":[{"price":83.25298,"qty":23.85306512}],"asks":[],"checksum":3772135153,"timestamp":"2024-06-01T17:53:00.902653Z"}]}
{"channel":"book","type":"update","data":[{"symbol":"LTC/USDT","bids":[],"asks":[{"price":83.28670,"qty":11.99000000}],"checksum":1725491413,"timestamp":"2024-06-01T17:53:00.903700Z"}]}
{"channel":"book","type":"update","data":[{"symbol":"LTC/USDT","bids":[],"asks":[{"price":83.28682,"qty":0.00000000},{"price":83.32816,"qty":3.02951062}],"checksum":2555735268,"timestamp":"2024-06-01T17:53:00.904592Z"}]}
{"channel":"book","type":"update","data":[{"symbol":"LTC/USDT","bids":[{"price":83.25936,"qty":18.02866192}],"asks":[],"checksum":957746445,"timestamp":"2024-06-01T17:53:00.938616Z"}]}
{"channel":"book","type":"update","data":[{"symbol":"LTC/USDT","bids":[{"price":83.25298,"qty":0.00000000},{"price":83.21015,"qty":9.76343889}],"asks":[],"checksum":4098240879,"timestamp":"2024-06-01T17:53:00.942303Z"}]}
{"channel":"book","type":"update","data":[{"symbol":"LTC/USDT","bids":[],"asks":[{"price":83.28670,"qty":1.99000000}],"checksum":1917382475,"timestamp":"2024-06-01T17:53:00.943691Z"}]}
{"channel":"book","type":"update","data":[{"symbol":"LTC/USDT","bids":[{"price":83.25297,"qty":0.00000000},{"price":83.21003,"qty":3.02951062}],"asks":[],"checksum":3251110827,"timestamp":"2024-06-01T17:53:01.004006Z"}]}
{"channel":"book","type":"update","data":[{"symbol":"LTC/USDT","bids":[{"price":83.25428,"qty":9.01433096}],"asks":[],"checksum":794584781,"timestamp":"2024-06-01T17:53:01.044223Z"}]}
{"channel":"book","type":"update","data":[{"symbol":"LTC/USDT","bids":[],"asks":[{"price":83.30503,"qty":10.00000000}],"checksum":2948414164,"timestamp":"2024-06-01T17:53:01.145775Z"}]}
{"channel":"book","type":"update","data":[{"symbol":"LTC/USDT","bids":[{"price":83.25936,"qty":0.00000000},{"price":83.21003,"qty":3.02951062}],"asks":[],"checksum":1941585957,"timestamp":"2024-06-01T17:53:01.454185Z"}]}
{"channel":"book","type":"update","data":[{"symbol":"LTC/USDT","bids":[{"price":83.25429,"qty":23.85306512}],"asks":[],"checksum":3852991914,"timestamp":"2024-06-01T17:53:01.458494Z"}]}
{"channel":"book","type":"update","data":[{"symbol":"LTC/USDT","bids":[{"price":83.24599,"qty":0.00000000},{"price":83.21003,"qty":3.02951062}],"asks":[],"checksum":2031652691,"timestamp":"2024-06-01T17:53:01.506465Z"}]}
{"channel":"book","type":"update","data":[{"symbol":"LTC/USDT","bids":[{"price":83.25428,"qty":0.00000000},{"price":83.20979,"qty":2.55000000}],"asks":[],"checksum":3769557907,"timestamp":"2024-06-01T17:53:01.560307Z"}]}
{"channel":"book","type":"update","data":[{"symbol":"LTC/USDT","bids":[{"price":83.25445,"qty":9.01426810}],"asks":[],"checksum":3393315766,"timestamp":"2024-06-01T17:53:01.600567Z"}]}
{"channel":"book","type":"update","data":[{"symbol":"LTC/USDT","bids":[{"price":83.25953,"qty":18.02853582}],"asks":[],"checksum":3853283362,"timestamp":"2024-06-01T17:53:01.945424Z"}]}
{"channel":"book","type":"update","data":[{"symbol":"LTC/USDT","bids":[{"price":83.25445,"qty":0.00000000},{"price":83.21003,"qty":3.02951062}],"asks":[],"checksum":1018652406,"timestamp":"2024-06-01T17:53:02.116221Z"}]}
{"channel":"book","type":"update","data":[{"symbol":"LTC/USDT","bids":[{"price":83.25953,"qty":0.00000000},{"price":83.20979,"qty":2.55000000}],"asks":[],"checksum":3769557907,"timestamp":"2024-06-01T17:53:02.457872Z"}]}
{"channel":"book","type":"update","data":[{"symbol":"LTC/USDT","bids":[{"price":83.23956,"qty":23.85306512}],"asks":[],"checksum":3184600322,"timestamp":"2024-06-01T17:53:02.461869Z"}]}
{"channel":"book","type":"update","data":[{"symbol":"LTC/USDT","bids":[{"price":83.25429,"qty":0.00000000},{"price":83.20979,"qty":2.55000000}],"asks":[],"checksum":247836802,"timestamp":"2024-06-01T17:53:02.461906Z"}]}
{"channel":"book","type":"update","data":[{"symbol":"LTC/USDT","bids":[{"price":83.25957,"qty":18.02853693}],"asks":[],"checksum":2190407601,"timestamp":"2024-06-01T17:53:02.497941Z"}]}
{"channel":"book","type":"update","data":[{"symbol":"LTC/USDT","bids":[{"price":83.25531,"qty":9.01421398}],"asks":[],"checksum":297951481,"timestamp":"2024-06-01T17:53:02.604859Z"}]}
{"channel":"book","type":"update","data":[{"symbol":"LTC/USDT","bids":[],"asks":[{"price":83.28702,"qty":0.00000000},{"price":83.32816,"qty":3.02951062}],"checksum":1050367230,"timestamp":"2024-06-01T17:53:02.919296Z"}]}
{"channel":"book","type":"update","data":[{"symbol":"LTC/USDT","bids":[],"asks":[{"price":83.28404,"qty":1.80000000}],"checksum":1527540638,"timestamp":"2024-06-01T17:53:02.919454Z"}]}
{"channel":"book","type":"update","data":[{"symbol":"LTC/USDT","bids":[],"asks":[{"price":83.28658,"qty":10.00000000}],"checksum":3786469483,"timestamp":"2024-06-01T17:53:02.925488Z"}]}
{"channel":"book","type":"update","data":[{"symbol":"LTC/USDT","bids":[],"asks":[{"price":83.28384,"qty":1.99000000}],"checksum":2294916612,"timestamp":"2024-06-01T17:53:02.926349Z"}]}
{"channel":"book","type":"update","data":[{"symbol":"LTC/USDT","bids":[{"price":83.25957,"qty":0.00000000},{"price":83.21003,"qty":3.02951062}],"asks":[],"checksum":153963141,"timestamp":"2024-06-01T17:53:03.011437Z"}]}
{"channel":"book","type":"update","data":[{"symbol":"LTC/USDT","bids":[],"asks":[{"price":83.28658,"qty":0.00000000},{"price":83.32262,"qty":23.85306512}],"checksum":2076083396,"timestamp":"2024-06-01T17:53:03.016229Z"}]}
{"channel":"book","type":"update","data":[{"symbol":"LTC/USDT","bids":[],"asks":[{"price":83.28670,"qty":0.00000000},{"price":83.32787,"qty":36.00236031}],"checksum":1913159633,"timestamp":"2024-06-01T17:53:03.018316Z"}]}
{"channel":"book","type":"update","data":[{"symbol":"LTC/USDT","bids":[],"asks":[{"price":83.30503,"qty":0.00000000},{"price":83.32816,"qty":3.02951062}],"checksum":3779800090,"timestamp":"2024-06-01T17:53:03.080639Z"}]}
{"channel":"book","type":"update","data":[{"symbol":"LTC/USDT","bids":[{"price":83.25531,"qty":0.00000000},{"price":83.20979,"qty":2.55000000}],"asks":[],"checksum":3828650270,"timestamp":"2024-06-01T17:53:03.115503Z"}]}
{"channel":"book","type":"update","data":[{"symbol":"LTC/USDT","bids":[{"price":83.24039,"qty":16.22412270}],"asks":[],"checksum":1910132495,"timestamp":"2024-06-01T17:53:03.118607Z"}]}
{"channel":"book","type":"update","data":[{"symbol":"LTC/USDT","bids":[{"price":83.23976,"qty":1.99000000}],"asks":[],"checksum":1212871375,"timestamp":"2024-06-01T17:53:03.120569Z"}]}
{"channel":"book","type":"update","data":[{"symbol":"LTC/USDT","bids":[{"price":83.23955,"qty":0.00000000},{"price":83.21003,"qty":3.02951062}],"asks":[],"checksum":1906792657,"timestamp":"2024-06-01T17:53:03.121127Z"}]}
{"channel":"book","type":"update","data":[{"symbol":"LTC/USDT","bids":[{"price":83.25500,"qty":9.01426129}],"asks":[],"checksum":1729681820,"timestamp":"2024-06-01T17:53:03.155336Z"}]}
{"channel":"book","type":"update","data":[{"symbol":"LTC/USDT","bids":[{"price":83.23976,"qty":0.00000000},{"price":83.21003,"qty":3.02951062}],"asks":[],"checksum":3753670413,"timestamp":"2024-06-01T17:53:03.160241Z"}]}
{"channel":"book","type":"update","data":[{"symbol":"LTC/USDT","bids":[],"asks":[{"price":83.30503,"qty":10.00000000}],"checksum":1291789510,"timestamp":"2024-06-01T17:53:03.337287Z"}]}
{"channel":"book","type":"update","data":[{"symbol":"LTC/USDT","bids":[{"price":83.26002,"qty":18.02851868}],"asks":[],"checksum":4153960323,"timestamp":"2024-06-01T17:53:03.498235Z"}]}
{"channel":"book","type":"update","data":[{"symbol":"LTC/USDT","bids":[{"price":83.26002,"qty":0.00000000},{"price":83.21003,"qty":3.02951062}],"asks":[],"checksum":1291789510,"timestamp":"2024-06-01T17:53:03.567642Z"}]}
{"channel":"book","type":"update","data":[{"symbol":"LTC/USDT","bids":[{"price":83.25500,"qty":0.00000000},{"price":83.20979,"qty":2.55000000}],"asks":[],"checksum":2094113093,"timestamp":"2024-06-01T17:53:03.668892Z"}]}
{"channel":"book","type":"update","data":[{"symbol":"LTC/USDT","bids":[{"price":83.24040,"qty":23.85306512}],"asks":[],"checksum":1985302674,"timestamp":"2024-06-01T17:53:03.672805Z"}]}
{"channel":"book","type":"update","data":[{"symbol":"LTC/USDT","bids":[{"price":83.24059,"qty":1.99000000}],"asks":[],"checksum":1081781943,"timestamp":"2024-06-01T17:53:03.673651Z"}]}
{"channel":"book","type":"update","data":[{"symbol":"LTC/USDT","bids":[{"price":83.24077,"qty":16.22408003}],"asks":[],"checksum":1565372126,"timestamp":"2024-06-01T17:53:03.677007Z"}]}
{"channel":"book","type":"update","data":[{"symbol":"LTC/USDT","bids":[{"price":83.24039,"qty":0.00000000},{"price":83.21015,"qty":9.76343889}],"asks":[],"checksum":2786550657,"timestamp":"2024-06-01T17:53:03.677027Z"}]}
{"channel":"book","type":"update","data":[{"symbol":"LTC/USDT","bids":[{"price":83.23956,"qty":0.00000000},{"price":83.21003,"qty":3.02951062}],"asks":[],"checksum":3975094648,"timestamp":"2024-06-01T17:53:04.019440Z"}]}
{"channel":"book","type":"update","data":[{"symbol":"LTC/USDT","bids":[{"price":83.24078,"qty":23.85306512}],"asks":[],"checksum":3102108112,"timestamp":"2024-06-01T17:53:04.024682Z"}]}
{"channel":"book","type":"update","data":[{"symbol":"LTC/USDT","bids":[{"price":83.24097,"qty":1.99000000}],"asks":[],"checksum":1558509522,"timestamp":"2024-06-01T17:53:04.025418Z"}]}
{"channel":"book","type":"update","data":[{"symbol":"LTC/USDT","bids":[{"price":83.24059,"qty":0.00000000},{"price":83.21015,"qty":9.76343889}],"asks":[],"checksum":4092049429,"timestamp":"2024-06-01T17:53:04.025437Z"}]}
{"channel":"book","type":"update","data":[{"symbol":"LTC/USDT","bids":[{"price":83.25920,"qty":18.02862804}],"asks":[],"checksum":2228911018,"timestamp":"2024-06-01T17:53:04.055663Z"}]}
{"channel":"book","type":"update","data":[{"symbol":"LTC/USDT","bids":[{"price":83.24040,"qty":0.00000000},{"price":83.21015,"qty":9.76343889}],"asks":[],"checksum":516138664,"timestamp":"2024-06-01T17:53:04.059706Z"}]}
{"channel":"book","type":"update","data":[{"symbol":"LTC/USDT","bids":[{"price":83.24097,"qty":0.00000000},{"price":83.21003,"qty":3.02951062}],"asks":[],"checksum":1660944336,"timestamp":"2024-06-01T17:53:04.061046Z"}]}
{"channel":"book","type":"update","data":[{"symbol":"LTC/USDT","bids":[{"price":83.25411,"qty":9.01431402}],"asks":[],"checksum":765903219,"timestamp":"2024-06-01T17:53:04.163735Z"}]}
{"channel":"book","type":"update","data":[{"symbol":"LTC/USDT","bids":[{"price":83.24078,"qty":24.21800713}],"asks":[],"checksum":1012964145,"timestamp":"2024-06-01T17:53:04.440763Z"}]}
{"channel":"book","type":"update","data":[{"symbol":"LTC/USDT","bids":[],"asks":[{"price":83.28404,"qty":0.00000000},{"price":83.32816,"qty":3.02951062}],"checksum":56989110,"timestamp":"2024-06-01T17:53:04.489284Z"}]}
{"channel":"book","type":"update","data":[{"symbol":"LTC/USDT","bids":[],"asks":[{"price":83.28118,"qty":1.80000000}],"checksum":1587552356,"timestamp":"2024-06-01T17:53:04.489442Z"}]}
{"channel":"book","type":"update","data":[{"symbol":"LTC/USDT","bids":[],"asks":[{"price":83.28690,"qty":0.00000000},{"price":83.32816,"qty":3.02951062}],"checksum":2523785076,"timestamp":"2024-06-01T17:53:04.494408Z"}]}
{"channel":"book","type":"update","data":[{"symbol":"LTC/USDT","bids":[],"asks":[{"price":83.28988,"qty":10.00000000}],"checksum":2631179694,"timestamp":"2024-06-01T17:53:04.494422Z"}]}
{"channel":"book","type":"update","data":[{"symbol":"LTC/USDT","bids":[],"asks":[{"price":83.28098,"qty":1.99000000}],"checksum":3529624970,"timestamp":"2024-06-01T17:53:04.499275Z"}]}
{"channel":"book","type":"update","data":[{"symbol":"LTC/USDT","bids":[],"asks":[{"price":83.28384,"qty":0.00000000},{"price":83.32787,"qty":36.00236031}],"checksum":2437844592,"timestamp":"2024-06-01T17:53:04.586591Z"}]}
{"channel":"book","type":"update","data":[{"symbol":"LTC/USDT","bids":[{"price":83.25920,"qty":0.00000000},{"price":83.21003,"qty":3.02951062}],"asks":[],"checksum":2777829924,"timestamp":"2024-06-01T17:53:04.589277Z"}]}
{"channel":"book","type":"update","data":[{"symbol":"LTC/USDT","bids":[],"asks":[{"price":83.28118,"qty":0.00000000},{"price":83.32816,"qty":3.02951062}],"checksum":1534833306,"timestamp":"2024-06-01T17:53:04.589529Z"}]}
{"channel":"book","type":"update","data":[{"symbol":"LTC/USDT","bids":[{"price":83.25919,"qty":18.02862804}],"asks":[],"checksum":4034257506,"timestamp":"2024-06-01T17:53:04.629438Z"}]}
{"channel":"book","type":"update","data":[{"symbol":"LTC/USDT","bids":[],"asks":[{"price":83.28098,"qty":0.00000000},{"price":83.34094,"qty":2.34609048}],"checksum":85552782,"timestamp":"2024-06-01T17:53:05.086917Z"}]}
{"channel":"book","type":"update","data":[{"symbol":"LTC/USDT","bids":[],"asks":[{"price":83.28722,"qty":1.80000000}],"checksum":1509035936,"timestamp":"2024-06-01T17:53:05.090223Z"}]}
{"channel":"book","type":"update","data":[{"symbol":"LTC/USDT","bids":[],"asks":[{"price":83.28968,"qty":1.99000000}],"checksum":4071603914,"timestamp":"2024-06-01T17:53:05.092902Z"}]}
{"channel":"book","type":"update","data":[{"symbol":"LTC/USDT","bids":[{"price":83.25919,"qty":0.00000000},{"price":83.21003,"qty":3.02951062}],"asks":[],"checksum":3971223641,"timestamp":"2024-06-01T17:53:05.208122Z"}]}
{"channel":"book","type":"update","data":[{"symbol":"LTC/USDT","bids":[{"price":83.25412,"qty":23.85306512}],"asks":[],"checksum":3877227672,"timestamp":"2024-06-01T17:53:05.212119Z"}]}
{"channel":"book","type":"update","data":[{"symbol":"LTC/USDT","bids":[],"asks":[{"price":83.28956,"qty":10.00000000}],"checksum":1184137843,"timestamp":"2024-06-01T17:53:05.212707Z"}]}
{"channel":"book","type":"update","data":[{"symbol":"LTC/USDT","bids":[{"price":83.25411,"qty":0.00000000},{"price":83.21003,"qty":3.02951062}],"asks":[],"checksum":198869205,"timestamp":"2024-06-01T17:53:05.273590Z"}]}
{"channel":"book","type":"update","data":[{"symbol":"LTC/USDT","bids":[{"price":83.25412,"qty":0.00000000},{"price":83.20979,"qty":2.55000000}],"asks":[],"checksum":2065868064,"timestamp":"2024-06-01T17:53:05.277289Z"}]}
{"channel":"book","type":"update","data":[{"symbol":"LTC/USDT","bids":[],"asks":[{"price":83.28988,"qty":0.00000000},{"price":83.32787,"qty":36.00236031}],"checksum":2223581027,"timestamp":"2024-06-01T17:53:05.277992Z"}]}
{"channel":"book","type":"update","data":[{"symbol":"LTC/USDT","bids":[{"price":83.24081,"qty":16.22407232}],"asks":[],"checksum":4098147202,"timestamp":"2024-06-01T17:53:05.280147Z"}]}
{"channel":"book","type":"update","data":[{"symbol":"LTC/USDT","bids":[{"price":83.24077,"qty":0.00000000},{"price":83.20979,"qty":2.55000000}],"asks":[],"checksum":1677497083,"timestamp":"2024-06-01T17:53:05.280917Z"}]}
{"channel":"book","type":"update","data":[{"symbol":"LTC/USDT","bids":[{"price":83.25413,"qty":9.01429922}],"asks":[],"checksum":159888384,"timestamp":"2024-06-01T17:53:05.313796Z"}]}
{"channel":"book","type":"update","data":[{"symbol":"LTC/USDT","bids":[{"price":83.25414,"qty":23.85306512}],"asks":[],"checksum":582846658,"timestamp":"2024-06-01T17:53:05.318011Z"}]}
{"channel":"book","type":"update","data":[{"symbol":"LTC/USDT","bids":[],"asks":[{"price":83.30503,"qty":0.00000000},{"price":83.32816,"qty":3.02951062}],"checksum":1075923357,"timestamp":"2024-06-01T17:53:05.356758Z"}]}
{"channel":"book","type":"update","data":[{"symbol":"LTC/USDT","bids":[{"price":83.24078,"qty":0.36494201}],"asks":[],"checksum":1531291880,"timestamp":"2024-06-01T17:53:05.506604Z"}]}
{"channel":"book","type":"update","data":[{"symbol":"LTC/USDT","bids":[],"asks":[{"price":83.28702,"qty":1.99000000}],"checksum":3295567760,"timestamp":"2024-06-01T17:53:05.511306Z"}]}
{"channel":"book","type":"update","data":[{"symbol":"LTC/USDT","bids":[],"asks":[{"price":83.28722,"qty":0.00000000},{"price":83.32816,"qty":3.02951062}],"checksum":2969427726,"timestamp":"2024-06-01T17:53:05.513976Z"}]}
{"channel":"book","type":"update","data":[{"symbol":"LTC/USDT","bids":[],"asks":[{"price":83.28436,"qty":1.80000000}],"checksum":1446770937,"timestamp":"2024-06-01T17:53:05.514132Z"}]}
{"channel":"book","type":"update","data":[{"symbol":"LTC/USDT","bids":[],"asks":[{"price":83.28702,"qty":0.00000000},{"price":83.32816,"qty":3.02951062}],"checksum":2088656787,"timestamp":"2024-06-01T17:53:05.587972Z"}]}
{"channel":"book","type":"update","data":[{"symbol":"LTC/USDT","bids":[],"asks":[{"price":83.30503,"qty":10.00000000}],"checksum":1146029824,"timestamp":"2024-06-01T17:53:05.621877Z"}]}
{"channel":"book","type":"update","data":[{"symbol":"LTC/USDT","bids":[{"price":83.26088,"qty":18.02834224}],"asks":[],"checksum":2221850999,"timestamp":"2024-06-01T17:53:05.696642Z"}]}
{"channel":"book","type":"update","data":[{"symbol":"LTC/USDT","bids":[{"price":83.25413,"qty":0.00000000},{"price":83.21015,"qty":9.76343889}],"asks":[],"checksum":1603850821,"timestamp":"2024-06-01T17:53:05.828161Z"}]}
{"channel":"book","type":"update","data":[{"symbol":"LTC/USDT","bids":[{"price":83.25581,"qty":9.01416695}],"asks":[],"checksum":3858314936,"timestamp":"2024-06-01T17:53:05.868529Z"}]}
{"channel":"book","type":"update","data":[{"symbol":"LTC/USDT","bids":[],"asks":[{"price":83.30503,"qty":0.00000000},{"price":83.32816,"qty":3.02951062}],"checksum":2361902366,"timestamp":"2024-06-01T17:53:05.877661Z"}]}
{"channel":"book","type":"update","data":[{"symbol":"LTC/USDT","bids":[],"asks":[{"price":83.30503,"qty":10.00000000}],"checksum":3858314936,"timestamp":"2024-06-01T17:53:06.165353Z"}]}
{"channel":"book","type":"update","data":[{"symbol":"LTC/USDT","bids":[{"price":83.26088,"qty":0.00000000},{"price":83.21015,"qty":9.76343889}],"asks":[],"checksum":949298348,"timestamp":"2024-06-01T17:53:06.224179Z"}]}
{"channel":"book","type":"update","data":[{"symbol":"LTC/USDT","bids":[{"price":83.25896,"qty":18.02863999}],"asks":[],"checksum":3993922554,"timestamp":"2024-06-01T17:53:06.264426Z"}]}
{"channel":"book","type":"update","data":[{"symbol":"LTC/USDT","bids":[{"price":83.25581,"qty":0.00000000},{"price":83.21015,"qty":9.76343889}],"asks":[],"checksum":1416597255,"timestamp":"2024-06-01T17:53:06.331630Z"}]}
{"channel":"book","type":"update","data":[{"symbol":"LTC/USDT","bids":[{"price":83.25387,"qty":9.01431999}],"asks":[],"checksum":53036974,"timestamp":"2024-06-01T17:53:06.371922Z"}]}
{"channel":"book","type":"update","data":[{"symbol":"LTC/USDT","bids":[],"asks":[{"price":83.28416,"qty":1.99000000}],"checksum":1602051836,"timestamp":"2024-06-01T17:53:06.586365Z"}]}
{"channel":"book","type":"update","data":[{"symbol":"LTC/USDT","bids":[],"asks":[{"price":83.28436,"qty":0.00000000},{"price":83.32787,"qty":36.00236031}],"checksum":3312196835,"timestamp":"2024-06-01T17:53:06.588989Z"}]}
{"channel":"book","type":"update","data":[{"symbol":"LTC/USDT","bids":[],"asks":[{"price":83.28151,"qty":1.80000000}],"checksum":3007177421,"timestamp":"2024-06-01T17:53:06.589123Z"}]}
{"channel":"book","type":"update","data":[{"symbol":"LTC/USDT","bids":[],"asks":[{"price":83.28968,"qty":0.00000000},{"price":83.32787,"qty":36.00236031}],"checksum":484267770,"timestamp":"2024-06-01T17:53:06.590844Z"}]}
{"channel":"book","type":"update","data":[{"symbol":"LTC/USDT","bids":[{"price":83.25896,"qty":0.00000000},{"price":83.21015,"qty":9.76343889}],"asks":[],"checksum":2252554441,"timestamp":"2024-06-01T17:53:06.797516Z"}]}
{"channel":"book","type":"update","data":[{"symbol":"LTC/USDT","bids":[{"price":83.25414,"qty":0.00000000},{"price":83.21003,"qty":3.02951062}],"asks":[],"checksum":4184192734,"timestamp":"2024-06-01T17:53:06.801773Z"}]}
{"channel":"book","type":"update","data":[{"symbol":"LTC/USDT","bids":[{"price":83.25388,"qty":23.85306512}],"asks":[],"checksum":2017061447,"timestamp":"2024-06-01T17:53:06.801829Z"}]}
{"channel":"book","type":"update","data":[{"symbol":"LTC/USDT","bids":[],"asks":[{"price":83.28131,"qty":1.99000000}],"checksum":1441881575,"timestamp":"2024-06-01T17:53:06.802643Z"}]}
{"channel":"book","type":"update","data":[{"symbol":"LTC/USDT","bids":[],"asks":[{"price":83.28151,"qty":0.00000000},{"price":83.32787,"qty":36.00236031}],"checksum":4115367448,"timestamp":"2024-06-01T17:53:06.805162Z"}]}
{"channel":"book","type":"update","data":[{"symbol":"LTC/USDT","bids":[],"asks":[{"price":83.28105,"qty":1.80000000}],"checksum":3662911237,"timestamp":"2024-06-01T17:53:06.805524Z"}]}
{"channel":"book","type":"update","data":[{"symbol":"LTC/USDT","bids":[{"price":83.24078,"qty":0.00000000},{"price":83.21003,"qty":3.02951062}],"asks":[],"checksum":53205232,"timestamp":"2024-06-01T17:53:06.889952Z"}]}
{"channel":"book","type":"update","data":[{"symbol":"LTC/USDT","bids":[],"asks":[{"price":83.28131,"qty":0.00000000},{"price":83.32787,"qty":36.00236031}],"checksum":1844477249,"timestamp":"2024-06-01T17:53:06.895871Z"}]}
{"channel":"book","type":"update","data":[{"symbol":"LTC/USDT","bids":[{"price":83.25387,"qty":0.00000000},{"price":83.20979,"qty":2.55000000}],"asks":[],"checksum":130629118,"timestamp":"2024-06-01T17:53:06.901093Z"}]}
{"channel":"book","type":"update","data":[{"symbol":"LTC/USDT","bids":[{"price":83.25405,"qty":9.01429501}],"asks":[],"checksum":3085250355,"timestamp":"2024-06-01T17:53:06.941381Z"}]}
{"channel":"book","type":"update","data":[{"symbol":"LTC/USDT","bids":[{"price":83.25406,"qty":23.85306512}],"asks":[],"checksum":1779835237,"timestamp":"2024-06-01T17:53:06.945938Z"}]}
{"channel":"book","type":"update","data":[{"symbol":"LTC/USDT","bids":[{"price":83.25388,"qty":0.00000000},{"price":83.21003,"qty":3.02951062}],"asks":[],"checksum":2230048730,"timestamp":"2024-06-01T17:53:07.010236Z"}]}
{"channel":"book","type":"update","data":[{"symbol":"LTC/USDT","bids":[{"price":83.25916,"qty":18.02859002}],"asks":[],"checksum":1453059200,"timestamp":"2024-06-01T17:53:07.299813Z"}]}
{"channel":"book","type":"update","data":[{"symbol":"LTC/USDT","bids":[{"price":83.25405,"qty":0.00000000},{"price":83.21003,"qty":3.02951062}],"asks":[],"checksum":2010406342,"timestamp":"2024-06-01T17:53:07.468852Z"}]}
{"channel":"book","type":"update","data":[{"symbol":"LTC/USDT","bids":[],"asks":[{"price":83.28085,"qty":1.99000000}],"checksum":1673019680,"timestamp":"2024-06-01T17:53:07.473916Z"}]}
{"channel":"book","type":"update","data":[{"symbol":"LTC/USDT","bids":[],"asks":[{"price":83.28416,"qty":0.00000000},{"price":83.32787,"qty":36.00236031}],"checksum":750976966,"timestamp":"2024-06-01T17:53:07.589676Z"}]}
{"channel":"book","type":"update","data":[{"symbol":"LTC/USDT","bids":[],"asks":[{"price":83.28105,"qty":0.00000000},{"price":83.32816,"qty":3.02951062}],"checksum":1672723671,"timestamp":"2024-06-01T17:53:07.592240Z"}]}
{"channel":"book","type":"update","data":[{"symbol":"LTC/USDT","bids":[],"asks":[{"price":83.28691,"qty":1.80000000}],"checksum":3532977320,"timestamp":"2024-06-01T17:53:07.592462Z"}]}
{"channel":"book","type":"update","data":[{"symbol":"LTC/USDT","bids":[],"asks":[{"price":83.28679,"qty":10.00000000}],"checksum":2939324919,"timestamp":"2024-06-01T17:53:07.711582Z"}]}
{"channel":"book","type":"update","data":[{"symbol":"LTC/USDT","bids":[],"asks":[{"price":83.28691,"qty":0.00000000},{"price":83.32787,"qty":36.00236031}],"checksum":2743279698,"timestamp":"2024-06-01T17:53:07.714273Z"}]}
{"channel":"book","type":"update","data":[{"symbol":"LTC/USDT","bids":[],"asks":[{"price":83.28414,"qty":1.80000000}],"checksum":1428693853,"timestamp":"2024-06-01T17:53:07.714404Z"}]}
{"channel":"book","type":"update","data":[{"symbol":"LTC/USDT","bids":[],"asks":[{"price":83.28956,"qty":0.00000000},{"price":83.32787,"qty":36.00236031}],"checksum":1249748633,"timestamp":"2024-06-01T17:53:07.715626Z"}]}
{"channel":"book","type":"update","data":[{"symbol":"LTC/USDT","bids":[{"price":83.25441,"qty":9.01424030}],"asks":[],"checksum":3131688248,"timestamp":"2024-06-01T17:53:07.969891Z"}]}
{"channel":"book","type":"update","data":[{"symbol":"LTC/USDT","bids":[],"asks":[{"price":83.28085,"qty":0.00000000},{"price":83.32816,"qty":3.02951062}],"checksum":3920057756,"timestamp":"2024-06-01T17:53:08.089383Z"}]}
{"channel":"book","type":"update","data":[{"symbol":"LTC/USDT","bids":[{"price":83.25916,"qty":0.00000000},{"price":83.21003,"qty":3.02951062}],"asks":[],"checksum":1725224403,"timestamp":"2024-06-01T17:53:08.356579Z"}]}
{"channel":"book","type":"update","data":[{"symbol":"LTC/USDT","bids":[],"asks":[{"price":83.28679,"qty":0.00000000},{"price":83.34094,"qty":2.34609048}],"checksum":2882504333,"timestamp":"2024-06-01T17:53:08.361491Z"}]}
{"channel":"book","type":"update","data":[{"symbol":"LTC/USDT","bids":[],"asks":[{"price":83.28988,"qty":10.00000000}],"checksum":4250069917,"timestamp":"2024-06-01T17:53:08.361607Z"}]}
{"channel":"book","type":"update","data":[{"symbol":"LTC/USDT","bids":[{"price":83.25948,"qty":18.02856935}],"asks":[],"checksum":3473746045,"timestamp":"2024-06-01T17:53:08.396728Z"}]}
{"channel":"book","type":"update","data":[{"symbol":"LTC/USDT","bids":[{"price":83.25441,"qty":0.00000000},{"price":83.21003,"qty":3.02951062}],"asks":[],"checksum":1071205340,"timestamp":"2024-06-01T17:53:08.498324Z"}]}
{"channel":"book","type":"update","data":[{"symbol":"LTC/USDT","bids":[],"asks":[{"price":83.28394,"qty":1.99000000}],"checksum":2475904014,"timestamp":"2024-06-01T17:53:08.503430Z"}]}
{"channel":"book","type":"update","data":[{"symbol":"LTC/USDT","bids":[{"price":83.25440,"qty":9.01428467}],"asks":[],"checksum":3512303864,"timestamp":"2024-06-01T17:53:08.538621Z"}]}
{"channel":"book","type":"update","data":[{"symbol":"LTC/USDT","bids":[{"price":83.25948,"qty":0.00000000},{"price":83.21003,"qty":3.02951062}],"asks":[],"checksum":3332395136,"timestamp":"2024-06-01T17:53:08.856707Z"}]}
{"channel":"book","type":"update","data":[{"symbol":"LTC/USDT","bids":[{"price":83.25915,"qty":18.02866397}],"asks":[],"checksum":2491355814,"timestamp":"2024-06-01T17:53:08.896957Z"}]}
{"channel":"book","type":"update","data":[{"symbol":"LTC/USDT","bids":[{"price":83.25440,"qty":0.00000000},{"price":83.21003,"qty":3.02951062}],"asks":[],"checksum":3602243152,"timestamp":"2024-06-01T17:53:09.068975Z"}]}
{"channel":"book","type":"update","data":[{"symbol":"LTC/USDT","bids":[{"price":83.25407,"qty":9.01433198}],"asks":[],"checksum":2708848530,"timestamp":"2024-06-01T17:53:09.109347Z"}]}
{"channel":"book","type":"update","data":[{"symbol":"LTC/USDT","bids":[{"price":83.25915,"qty":0.00000000},{"price":83.21003,"qty":3.02951062}],"asks":[],"checksum":295985514,"timestamp":"2024-06-01T17:53:09.425067Z"}]}
{"channel":"book","type":"update","data":[{"symbol":"LTC/USDT","bids":[{"price":83.25408,"qty":23.85306512}],"asks":[],"checksum":1076557060,"timestamp":"2024-06-01T17:53:09.429042Z"}]}
{"channel":"book","type":"update","data":[{"symbol":"LTC/USDT","bids":[{"price":83.25916,"qty":18.02866995}],"asks":[],"checksum":4166963163,"timestamp":"2024-06-01T17:53:09.465378Z"}]}
{"channel":"book","type":"update","data":[{"symbol":"LTC/USDT","bids":[{"price":83.25408,"qty":0.00000000},{"price":83.21015,"qty":9.76343889}],"asks":[],"checksum":916542761,"timestamp":"2024-06-01T17:53:09.472814Z"}]}
{"channel":"book","type":"update","data":[{"symbol":"LTC/USDT","bids":[{"price":83.25407,"qty":0.00000000},{"price":83.21003,"qty":3.02951062}],"asks":[],"checksum":1096889579,"timestamp":"2024-06-01T17:53:10.163342Z"}]}
{"channel":"book","type":"update","data":[{"symbol":"LTC/USDT","bids":[{"price":83.25406,"qty":32.86740009}],"asks":[],"checksum":2762533544,"timestamp":"2024-06-01T17:53:10.203436Z"}]}
{"channel":"book","type":"update","data":[{"symbol":"LTC/USDT","bids":[{"price":83.25916,"qty":0.00000000},{"price":83.20924,"qty":8.37200000}],"asks":[],"checksum":3915149175,"timestamp":"2024-06-01T17:53:10.505990Z"}]}
{"channel":"book","type":"update","data":[{"symbol":"LTC/USDT","bids":[{"price":83.25917,"qty":18.02867022}],"asks":[],"checksum":513982764,"timestamp":"2024-06-01T17:53:10.546316Z"}]}
{"channel":"book","type":"update","data":[{"symbol":"LTC/USDT","bids":[{"price":83.25406,"qty":23.85306512}],"asks":[],"checksum":4218101615,"timestamp":"2024-06-01T17:53:10.732938Z"}]}
{"channel":"book","type":"update","data":[{"symbol":"LTC/USDT","bids":[{"price":83.25409,"qty":9.01433511}],"asks":[],"checksum":35363170,"timestamp":"2024-06-01T17:53:10.773121Z"}]}
{"channel":"book","type":"update","data":[{"symbol":"LTC/USDT","bids":[{"price":83.25409,"qty":0.00000000},{"price":83.21003,"qty":3.02951062}],"asks":[],"checksum":4218101615,"timestamp":"2024-06-01T17:53:11.220380Z"}]}
{"channel":"book","type":"update","data":[{"symbol":"LTC/USDT","bids":[{"price":83.25917,"qty":0.00000000},{"price":83.20924,"qty":8.37200000}],"asks":[],"checksum":481135242,"timestamp":"2024-06-01T17:53:11.583622Z"}]}
{"channel":"book","type":"update","data":[{"symbol":"LTC/USDT","bids":[],"asks":[{"price":83.28414,"qty":0.00000000},{"price":83.32816,"qty":3.02951062}],"checksum":495536295,"timestamp":"2024-06-01T17:53:11.586439Z"}]}
{"channel":"book","type":"update","data":[{"symbol":"LTC/USDT","bids":[],"asks":[{"price":83.28129,"qty":1.80000000}],"checksum":1483036477,"timestamp":"2024-06-01T17:53:11.586605Z"}]}
{"channel":"book","type":"update","data":[{"symbol":"LTC/USDT","bids":[{"price":83.22000,"qty":0.00000000},{"price":83.20870,"qty":7.87361491}],"asks":[],"checksum":1710382103,"timestamp":"2024-06-01T17:53:11.586641Z"}]}
{"channel":"book","type":"update","data":[{"symbol":"LTC/USDT","bids":[{"price":83.24082,"qty":23.85306512}],"asks":[],"checksum":3953908420,"timestamp":"2024-06-01T17:53:11.587614Z"}]}
{"channel":"book","type":"update","data":[{"symbol":"LTC/USDT","bids":[{"price":83.25406,"qty":0.00000000},{"price":83.20870,"qty":7.87361491}],"asks":[],"checksum":3474225760,"timestamp":"2024-06-01T17:53:11.587643Z"}]}
{"channel":"book","type":"update","data":[{"symbol":"LTC/USDT","bids":[{"price":83.22000,"qty":31.84426505}],"asks":[],"checksum":590768464,"timestamp":"2024-06-01T17:53:11.589680Z"}]}
{"channel":"book","type":"update","data":[{"symbol":"LTC/USDT","bids":[{"price":83.25919,"qty":18.02866983}],"asks":[],"checksum":1628969286,"timestamp":"2024-06-01T17:53:11.623852Z"}]}
{"channel":"book","type":"update","data":[{"symbol":"LTC/USDT","bids":[],"asks":[{"price":83.28109,"qty":1.99000000}],"checksum":1370018030,"timestamp":"2024-06-01T17:53:11.630961Z"}]}
{"channel":"book","type":"update","data":[{"symbol":"LTC/USDT","bids":[{"price":83.21003,"qty":0.00000000},{"price":83.20924,"qty":8.37200000}],"asks":[],"checksum":1460337063,"timestamp":"2024-06-01T17:53:11.656824Z"}]}
{"channel":"book","type":"update","data":[{"symbol":"LTC/USDT","bids":[{"price":83.22843,"qty":3.02951062}],"asks":[],"checksum":1863927649,"timestamp":"2024-06-01T17:53:11.760559Z"}]}
{"channel":"book","type":"update","data":[{"symbol":"LTC/USDT","bids":[{"price":83.25411,"qty":9.01433491}],"asks":[],"checksum":820779533,"timestamp":"2024-06-01T17:53:11.778485Z"}]}
{"channel":"book","type":"update","data":[{"symbol":"LTC/USDT","bids":[],"asks":[{"price":83.28394,"qty":0.00000000},{"price":83.32787,"qty":36.00236031}],"checksum":4288746207,"timestamp":"2024-06-01T17:53:11.783135Z"}]}
{"channel":"book","type":"update","data":[{"symbol":"LTC/USDT","bids":[],"asks":[{"price":83.28129,"qty":0.00000000},{"price":83.32816,"qty":3.02951062}],"checksum":4080826299,"timestamp":"2024-06-01T17:53:11.785780Z"}]}
{"channel":"book","type":"update","data":[{"symbol":"LTC/USDT","bids":[{"price":83.25919,"qty":0.00000000},{"price":83.21015,"qty":9.76343889}],"asks":[],"checksum":1320296603,"timestamp":"2024-06-01T17:53:12.136556Z"}]}
{"channel":"book","type":"update","data":[{"symbol":"LTC/USDT","bids":[{"price":83.25412,"qty":23.85306512}],"asks":[],"checksum":1449808535,"timestamp":"2024-06-01T17:53:12.140576Z"}]}
{"channel":"book","type":"update","data":[{"symbol":"LTC/USDT","bids":[],"asks":[{"price":83.28109,"qty":0.00000000},{"price":83.34094,"qty":2.34609048}],"checksum":2498763035,"timestamp":"2024-06-01T17:53:12.141496Z"}]}
{"channel":"book","type":"update","data":[{"symbol":"LTC/USDT","bids":[],"asks":[{"price":83.28968,"qty":1.99000000}],"checksum":2559368457,"timestamp":"2024-06-01T17:53:12.141598Z"}]}
{"channel":"book","type":"update","data":[{"symbol":"LTC/USDT","bids":[{"price":83.25918,"qty":18.02867022}],"asks":[],"checksum":2146600783,"timestamp":"2024-06-01T17:53:12.176586Z"}]}
{"channel":"book","type":"update","data":[{"symbol":"LTC/USDT","bids":[{"price":83.25412,"qty":0.00000000},{"price":83.21670,"qty":13.36451721}],"asks":[],"checksum":4121217712,"timestamp":"2024-06-01T17:53:12.180122Z"}]}
{"channel":"book","type":"update","data":[{"symbol":"LTC/USDT","bids":[{"price":83.25411,"qty":0.00000000},{"price":83.21015,"qty":9.76343889}],"asks":[],"checksum":2857474012,"timestamp":"2024-06-01T17:53:12.291156Z"}]}
{"channel":"book","type":"update","data":[{"symbol":"LTC/USDT","bids":[{"price":83.25412,"qty":9.01433511}],"asks":[],"checksum":267010668,"timestamp":"2024-06-01T17:53:12.331614Z"}]}
{"channel":"book","type":"update","data":[{"symbol":"LTC/USDT","bids":[{"price":83.25918,"qty":0.00000000},{"price":83.21015,"qty":9.76343889}],"asks":[],"checksum":3518133836,"timestamp":"2024-06-01T17:53:12.624679Z"}]}
{"channel":"book","type":"update","data":[{"symbol":"LTC/USDT","bids":[{"price":83.25413,"qty":23.85306512}],"asks":[],"checksum":3257656214,"timestamp":"2024-06-01T17:53:12.628791Z"}]}
{"channel":"book","type":"update","data":[{"symbol":"LTC/USDT","bids":[{"price":83.25902,"qty":18.02872137}],"asks":[],"checksum":4122009657,"timestamp":"2024-06-01T17:53:12.664812Z"}]}
{"channel":"book","type":"update","data":[{"symbol":"LTC/USDT","bids":[{"price":83.25413,"qty":0.00000000},{"price":83.21670,"qty":13.36451721}],"asks":[],"checksum":245958114,"timestamp":"2024-06-01T17:53:12.669675Z"}]}
{"channel":"book","type":"update","data":[{"symbol":"LTC/USDT","bids":[{"price":83.25412,"qty":0.00000000},{"price":83.21015,"qty":9.76343889}],"asks":[],"checksum":2870136914,"timestamp":"2024-06-01T17:53:12.844883Z"}]}
