{"channel":"book","type":"snapshot","data":[{"symbol":"LTC/BTC","bids":[{"price":0.001229,"qty":231.02655422},{"price":0.001228,"qty":295.28522609},{"price":0.001227,"qty":361.56071625},{"price":0.001226,"qty":492.66960660},{"price":0.001225,"qty":11.36779707},{"price":0.001224,"qty":146.18598529},{"price":0.001223,"qty":92.37444917},{"price":0.001222,"qty":68.55972214},{"price":0.001220,"qty":138.52990000},{"price":0.001219,"qty":776.49706821}],"asks":[{"price":0.001231,"qty":83.59515336},{"price":0.001232,"qty":39.22628963},{"price":0.001233,"qty":98.59497638},{"price":0.001234,"qty":384.02595555},{"price":0.001235,"qty":253.12997436},{"price":0.001236,"qty":9.66243375},{"price":0.001238,"qty":14.23275247},{"price":0.001239,"qty":143.17045089},{"price":0.001240,"qty":89.76490000},{"price":0.001241,"qty":80.76937076}],"checksum":3369935555}]}
{"channel":"book","type":"update","data":[{"symbol":"LTC/BTC","bids":[],"asks":[{"price":0.001233,"qty":96.72431916}],"checksum":2191311932,"timestamp":"2024-06-01T17:52:06.375085Z"}]}
{"channel":"book","type":"update","data":[{"symbol":"LTC/BTC","bids":[],"asks":[{"price":0.001233,"qty":98.36114423}],"checksum":2944243065,"timestamp":"2024-06-01T17:52:06.375603Z"}]}
{"channel":"book","type":"update","data":[{"symbol":"LTC/BTC","bids":[{"price":0.001229,"qty":226.48490004}],"asks":[],"checksum":3570320852,"timestamp":"2024-06-01T17:52:07.344050Z"}]}
{"channel":"book","type":"update","data":[{"symbol":"LTC/BTC","bids":[{"price":0.001229,"qty":230.69588411}],"asks":[],"checksum":3029258281,"timestamp":"2024-06-01T17:52:07.349073Z"}]}
{"channel":"book","type":"update","data":[{"symbol":"LTC/BTC","bids":[{"price":0.001222,"qty":90.06973950}],"asks":[],"checksum":4163310167,"timestamp":"2024-06-01T17:52:07.571100Z"}]}
{"channel":"book","type":"update","data":[{"symbol":"LTC/BTC","bids":[{"price":0.001223,"qty":90.22417990}],"asks":[],"checksum":900339201,"timestamp":"2024-06-01T17:52:07.571208Z"}]}
{"channel":"book","type":"update","data":[{"symbol":"LTC/BTC","bids":[{"price":0.001222,"qty":68.56340610}],"asks":[],"checksum":2161150375,"timestamp":"2024-06-01T17:52:07.571566Z"}]}
{"channel":"book","type":"update","data":[{"symbol":"LTC/BTC","bids":[{"price":0.001223,"qty":78.39600000}],"asks":[],"checksum":2362530287,"timestamp":"2024-06-01T17:52:07.571849Z"}]}
{"channel":"book","type":"update","data":[{"symbol":"LTC/BTC","bids":[{"price":0.001224,"qty":158.01526190}],"asks":[],"checksum":2728233631,"timestamp":"2024-06-01T17:52:07.571981Z"}]}
{"channel":"book","type":"update","data":[{"symbol":"LTC/BTC","bids":[{"price":0.001224,"qty":160.16603946}],"asks":[],"checksum":1791388340,"timestamp":"2024-06-01T17:52:07.572223Z"}]}
{"channel":"book","type":"update","data":[{"symbol":"LTC/BTC","bids":[{"price":0.001228,"qty":247.24245913}],"asks":[],"checksum":597703122,"timestamp":"2024-06-01T17:52:09.596294Z"}]}
{"channel":"book","type":"update","data":[{"symbol":"LTC/BTC","bids":[{"price":0.001228,"qty":295.28522807}],"asks":[],"checksum":211815825,"timestamp":"2024-06-01T17:52:09.854130Z"}]}
{"channel":"book","type":"update","data":[{"symbol":"LTC/BTC","bids":[{"price":0.001228,"qty":247.24245913}],"asks":[],"checksum":597703122,"timestamp":"2024-06-01T17:52:10.117066Z"}]}
{"channel":"book","type":"update","data":[{"symbol":"LTC/BTC","bids":[{"price":0.001228,"qty":295.28522514}],"asks":[],"checksum":3679363940,"timestamp":"2024-06-01T17:52:10.377446Z"}]}
{"channel":"book","type":"update","data":[{"symbol":"LTC/BTC","bids":[{"price":0.001228,"qty":247.24245913}],"asks":[],"checksum":597703122,"timestamp":"2024-06-01T17:52:10.623373Z"}]}
{"channel":"book","type":"update","data":[{"symbol":"LTC/BTC","bids":[{"price":0.001228,"qty":295.28522501}],"asks":[],"checksum":1247852927,"timestamp":"2024-06-01T17:52:10.892179Z"}]}
{"channel":"book","type":"update","data":[{"symbol":"LTC/BTC","bids":[{"price":0.001228,"qty":247.24245913}],"asks":[],"checksum":597703122,"timestamp":"2024-06-01T17:52:11.140380Z"}]}
{"channel":"book","type":"update","data":[{"symbol":"LTC/BTC","bids":[{"price":0.001228,"qty":295.28522535}],"asks":[],"checksum":1010611177,"timestamp":"2024-06-01T17:52:11.401019Z"}]}
{"channel":"book","type":"update","data":[{"symbol":"LTC/BTC","bids":[{"price":0.001220,"qty":46.98720000}],"asks":[],"checksum":1377376343,"timestamp":"2024-06-01T17:52:11.616996Z"}]}
{"channel":"book","type":"update","data":[{"symbol":"LTC/BTC","bids":[],"asks":[{"price":0.001240,"qty":4.97940000}],"checksum":4255729518,"timestamp":"2024-06-01T17:52:11.617787Z"}]}
{"channel":"book","type":"update","data":[{"symbol":"LTC/BTC","bids":[],"asks":[{"price":0.001240,"qty":0.00000000},{"price":0.001242,"qty":421.81628211}],"checksum":650481821,"timestamp":"2024-06-01T17:52:11.679086Z"}]}
{"channel":"book","type":"update","data":[{"symbol":"LTC/BTC","bids":[{"price":0.001228,"qty":247.24245913}],"asks":[],"checksum":1624032590,"timestamp":"2024-06-01T17:52:11.680650Z"}]}
{"channel":"book","type":"update","data":[{"symbol":"LTC/BTC","bids":[{"price":0.001220,"qty":39.92400000}],"asks":[],"checksum":1800022464,"timestamp":"2024-06-01T17:52:11.688068Z"}]}
{"channel":"book","type":"update","data":[{"symbol":"LTC/BTC","bids":[{"price":0.001228,"qty":238.03248922}],"asks":[],"checksum":2735977389,"timestamp":"2024-06-01T17:52:11.762146Z"}]}
{"channel":"book","type":"update","data":[{"symbol":"LTC/BTC","bids":[{"price":0.001229,"qty":226.48490004}],"asks":[],"checksum":1401461554,"timestamp":"2024-06-01T17:52:11.810922Z"}]}
{"channel":"book","type":"update","data":[{"symbol":"LTC/BTC","bids":[{"price":0.001229,"qty":230.86132071}],"asks":[],"checksum":285764226,"timestamp":"2024-06-01T17:52:11.815809Z"}]}
{"channel":"book","type":"update","data":[{"symbol":"LTC/BTC","bids":[{"price":0.001228,"qty":247.24245913}],"asks":[],"checksum":3646025967,"timestamp":"2024-06-01T17:52:11.864267Z"}]}
{"channel":"book","type":"update","data":[{"symbol":"LTC/BTC","bids":[{"price":0.001228,"qty":295.28526065}],"asks":[],"checksum":1453740441,"timestamp":"2024-06-01T17:52:11.975374Z"}]}
{"channel":"book","type":"update","data":[{"symbol":"LTC/BTC","bids":[{"price":0.001228,"qty":247.24245913}],"asks":[],"checksum":3646025967,"timestamp":"2024-06-01T17:52:12.236792Z"}]}
{"channel":"book","type":"update","data":[{"symbol":"LTC/BTC","bids":[{"price":0.001228,"qty":295.28526064}],"asks":[],"checksum":4168524725,"timestamp":"2024-06-01T17:52:12.512499Z"}]}
{"channel":"book","type":"update","data":[{"symbol":"LTC/BTC","bids":[{"price":0.001220,"qty":130.35550000}],"asks":[],"checksum":3334092655,"timestamp":"2024-06-01T17:52:12.698922Z"}]}
{"channel":"book","type":"update","data":[{"symbol":"LTC/BTC","bids":[],"asks":[{"price":0.001240,"qty":84.60530000}],"checksum":963024740,"timestamp":"2024-06-01T17:52:12.701721Z"}]}
{"channel":"book","type":"update","data":[{"symbol":"LTC/BTC","bids":[{"price":0.001220,"qty":137.62780000}],"asks":[],"checksum":2753417924,"timestamp":"2024-06-01T17:52:12.746314Z"}]}
{"channel":"book","type":"update","data":[{"symbol":"LTC/BTC","bids":[{"price":0.001228,"qty":247.24245913}],"asks":[],"checksum":797068669,"timestamp":"2024-06-01T17:52:12.767258Z"}]}
{"channel":"book","type":"update","data":[{"symbol":"LTC/BTC","bids":[{"price":0.001228,"qty":295.28526098}],"asks":[],"checksum":151904016,"timestamp":"2024-06-01T17:52:13.040538Z"}]}
{"channel":"book","type":"update","data":[{"symbol":"LTC/BTC","bids":[{"price":0.001228,"qty":247.24245913}],"asks":[],"checksum":797068669,"timestamp":"2024-06-01T17:52:13.307117Z"}]}
{"channel":"book","type":"update","data":[{"symbol":"LTC/BTC","bids":[{"price":0.001228,"qty":295.28526097}],"asks":[],"checksum":3733458350,"timestamp":"2024-06-01T17:52:13.569287Z"}]}
{"channel":"book","type":"update","data":[{"symbol":"LTC/BTC","bids":[{"price":0.001227,"qty":427.56071625}],"asks":[],"checksum":1833502101,"timestamp":"2024-06-01T17:52:13.727941Z"}]}
{"channel":"book","type":"update","data":[{"symbol":"LTC/BTC","bids":[{"price":0.001228,"qty":247.24245913}],"asks":[],"checksum":2621654342,"timestamp":"2024-06-01T17:52:13.830049Z"}]}
{"channel":"book","type":"update","data":[{"symbol":"LTC/BTC","bids":[{"price":0.001227,"qty":353.56071625}],"asks":[],"checksum":2340862497,"timestamp":"2024-06-01T17:52:13.857200Z"}]}
{"channel":"book","type":"update","data":[{"symbol":"LTC/BTC","bids":[{"price":0.001228,"qty":295.28526097}],"asks":[],"checksum":2056059634,"timestamp":"2024-06-01T17:52:14.128913Z"}]}
{"channel":"book","type":"update","data":[{"symbol":"LTC/BTC","bids":[{"price":0.001228,"qty":247.24245913}],"asks":[],"checksum":2340862497,"timestamp":"2024-06-01T17:52:14.427861Z"}]}
{"channel":"book","type":"update","data":[{"symbol":"LTC/BTC","bids":[{"price":0.001228,"qty":295.28526056}],"asks":[],"checksum":3681724264,"timestamp":"2024-06-01T17:52:14.716667Z"}]}
{"channel":"book","type":"update","data":[{"symbol":"LTC/BTC","bids":[{"price":0.001227,"qty":325.20444013}],"asks":[],"checksum":1310864430,"timestamp":"2024-06-01T17:52:14.830690Z"}]}
{"channel":"book","type":"update","data":[{"symbol":"LTC/BTC","bids":[{"price":0.001227,"qty":353.56071625}],"asks":[],"checksum":3681724264,"timestamp":"2024-06-01T17:52:14.931012Z"}]}
{"channel":"book","type":"update","data":[{"symbol":"LTC/BTC","bids":[{"price":0.001228,"qty":247.24245913}],"asks":[],"checksum":2340862497,"timestamp":"2024-06-01T17:52:14.973449Z"}]}
{"channel":"book","type":"update","data":[{"symbol":"LTC/BTC","bids":[{"price":0.001228,"qty":295.28526038}],"asks":[],"checksum":2600286754,"timestamp":"2024-06-01T17:52:15.227716Z"}]}
{"channel":"book","type":"update","data":[{"symbol":"LTC/BTC","bids":[],"asks":[{"price":0.001233,"qty":88.66693006}],"checksum":737775002,"timestamp":"2024-06-01T17:52:15.450486Z"}]}
{"channel":"book","type":"update","data":[{"symbol":"LTC/BTC","bids":[],"asks":[{"price":0.001232,"qty":48.92050380}],"checksum":1668990276,"timestamp":"2024-06-01T17:52:15.450725Z"}]}
{"channel":"book","type":"update","data":[{"symbol":"LTC/BTC","bids":[{"price":0.001228,"qty":247.24245913}],"asks":[],"checksum":1912685895,"timestamp":"2024-06-01T17:52:15.508970Z"}]}
{"channel":"book","type":"update","data":[{"symbol":"LTC/BTC","bids":[],"asks":[{"price":0.001240,"qty":89.93860000}],"checksum":548634195,"timestamp":"2024-06-01T17:52:15.823837Z"}]}
{"channel":"book","type":"update","data":[{"symbol":"LTC/BTC","bids":[{"price":0.001228,"qty":295.28515261}],"asks":[],"checksum":588233638,"timestamp":"2024-06-01T17:52:15.832027Z"}]}
{"channel":"book","type":"update","data":[{"symbol":"LTC/BTC","bids":[{"price":0.001228,"qty":247.24245913}],"asks":[],"checksum":548634195,"timestamp":"2024-06-01T17:52:16.104340Z"}]}
{"channel":"book","type":"update","data":[{"symbol":"LTC/BTC","bids":[{"price":0.001229,"qty":226.48490004}],"asks":[],"checksum":3952102702,"timestamp":"2024-06-01T17:52:16.205099Z"}]}
{"channel":"book","type":"update","data":[{"symbol":"LTC/BTC","bids":[{"price":0.001229,"qty":231.19226964}],"asks":[],"checksum":1121012863,"timestamp":"2024-06-01T17:52:16.209931Z"}]}
{"channel":"book","type":"update","data":[{"symbol":"LTC/BTC","bids":[{"price":0.001228,"qty":295.28524395}],"asks":[],"checksum":3183525469,"timestamp":"2024-06-01T17:52:16.372391Z"}]}
{"channel":"book","type":"update","data":[{"symbol":"LTC/BTC","bids":[{"price":0.001228,"qty":247.24245913}],"asks":[],"checksum":1121012863,"timestamp":"2024-06-01T17:52:16.633665Z"}]}
{"channel":"book","type":"update","data":[{"symbol":"LTC/BTC","bids":[{"price":0.001228,"qty":295.28515275}],"asks":[],"checksum":3795136384,"timestamp":"2024-06-01T17:52:16.903177Z"}]}
{"channel":"book","type":"update","data":[{"symbol":"LTC/BTC","bids":[{"price":0.001228,"qty":247.24245913}],"asks":[],"checksum":1121012863,"timestamp":"2024-06-01T17:52:17.186576Z"}]}
{"channel":"book","type":"update","data":[{"symbol":"LTC/BTC","bids":[],"asks":[{"price":0.001233,"qty":87.03010499}],"checksum":3840130672,"timestamp":"2024-06-01T17:52:17.301074Z"}]}
{"channel":"book","type":"update","data":[{"symbol":"LTC/BTC","bids":[],"asks":[{"price":0.001233,"qty":88.90060922}],"checksum":3990541193,"timestamp":"2024-06-01T17:52:17.302254Z"}]}
{"channel":"book","type":"update","data":[{"symbol":"LTC/BTC","bids":[{"price":0.001228,"qty":295.28520721}],"asks":[],"checksum":2867256234,"timestamp":"2024-06-01T17:52:17.457477Z"}]}
{"channel":"book","type":"update","data":[{"symbol":"LTC/BTC","bids":[{"price":0.001228,"qty":247.24245913}],"asks":[],"checksum":3990541193,"timestamp":"2024-06-01T17:52:17.729867Z"}]}
{"channel":"book","type":"update","data":[{"symbol":"LTC/BTC","bids":[],"asks":[{"price":0.001234,"qty":336.35395555}],"checksum":2335669210,"timestamp":"2024-06-01T17:52:17.777248Z"}]}
{"channel":"book","type":"update","data":[{"symbol":"LTC/BTC","bids":[],"asks":[{"price":0.001233,"qty":136.57260922}],"checksum":917414518,"timestamp":"2024-06-01T17:52:17.780084Z"}]}
{"channel":"book","type":"update","data":[{"symbol":"LTC/BTC","bids":[{"price":0.001228,"qty":295.28515120}],"asks":[],"checksum":511619561,"timestamp":"2024-06-01T17:52:17.986112Z"}]}
{"channel":"book","type":"update","data":[{"symbol":"LTC/BTC","bids":[{"price":0.001224,"qty":148.33676285}],"asks":[],"checksum":1798268901,"timestamp":"2024-06-01T17:52:18.033258Z"}]}
{"channel":"book","type":"update","data":[{"symbol":"LTC/BTC","bids":[{"price":0.001223,"qty":80.54678074}],"asks":[],"checksum":1437698595,"timestamp":"2024-06-01T17:52:18.033274Z"}]}
{"channel":"book","type":"update","data":[{"symbol":"LTC/BTC","bids":[{"price":0.001222,"qty":47.05338874}],"asks":[],"checksum":590692722,"timestamp":"2024-06-01T17:52:18.033672Z"}]}
{"channel":"book","type":"update","data":[{"symbol":"LTC/BTC","bids":[{"price":0.001223,"qty":102.05682991}],"asks":[],"checksum":2307051895,"timestamp":"2024-06-01T17:52:18.033924Z"}]}
{"channel":"book","type":"update","data":[{"symbol":"LTC/BTC","bids":[{"price":0.001224,"qty":146.18598529}],"asks":[],"checksum":2082362309,"timestamp":"2024-06-01T17:52:18.034064Z"}]}
{"channel":"book","type":"update","data":[{"symbol":"LTC/BTC","bids":[{"price":0.001223,"qty":113.88612401}],"asks":[],"checksum":3147655878,"timestamp":"2024-06-01T17:52:18.034178Z"}]}
{"channel":"book","type":"update","data":[{"symbol":"LTC/BTC","bids":[{"price":0.001228,"qty":247.24245913}],"asks":[],"checksum":3674551296,"timestamp":"2024-06-01T17:52:18.278316Z"}]}
{"channel":"book","type":"update","data":[{"symbol":"LTC/BTC","bids":[{"price":0.001229,"qty":226.48490004}],"asks":[],"checksum":3351254115,"timestamp":"2024-06-01T17:52:18.305548Z"}]}
{"channel":"book","type":"update","data":[{"symbol":"LTC/BTC","bids":[{"price":0.001229,"qty":230.86162242}],"asks":[],"checksum":1382714028,"timestamp":"2024-06-01T17:52:18.307915Z"}]}
{"channel":"book","type":"update","data":[{"symbol":"LTC/BTC","bids":[{"price":0.001228,"qty":295.28520660}],"asks":[],"checksum":1603460247,"timestamp":"2024-06-01T17:52:18.535217Z"}]}
{"channel":"book","type":"update","data":[{"symbol":"LTC/BTC","bids":[{"price":0.001228,"qty":247.24245913}],"asks":[],"checksum":1382714028,"timestamp":"2024-06-01T17:52:18.799204Z"}]}
{"channel":"book","type":"update","data":[{"symbol":"LTC/BTC","bids":[{"price":0.001228,"qty":295.28521348}],"asks":[],"checksum":948306610,"timestamp":"2024-06-01T17:52:19.069844Z"}]}
{"channel":"book","type":"update","data":[{"symbol":"LTC/BTC","bids":[{"price":0.001228,"qty":247.24245913}],"asks":[],"checksum":1382714028,"timestamp":"2024-06-01T17:52:19.357910Z"}]}
{"channel":"book","type":"update","data":[{"symbol":"LTC/BTC","bids":[],"asks":[{"price":0.001232,"qty":47.97655807}],"checksum":1973107353,"timestamp":"2024-06-01T17:52:19.479121Z"}]}
{"channel":"book","type":"update","data":[{"symbol":"LTC/BTC","bids":[],"asks":[{"price":0.001233,"qty":134.70210499}],"checksum":814010613,"timestamp":"2024-06-01T17:52:19.479173Z"}]}
{"channel":"book","type":"update","data":[{"symbol":"LTC/BTC","bids":[],"asks":[{"price":0.001233,"qty":135.87012064}],"checksum":2848158609,"timestamp":"2024-06-01T17:52:19.480364Z"}]}
{"channel":"book","type":"update","data":[{"symbol":"LTC/BTC","bids":[],"asks":[{"price":0.001232,"qty":49.15502302}],"checksum":4206856819,"timestamp":"2024-06-01T17:52:19.480518Z"}]}
{"channel":"book","type":"update","data":[{"symbol":"LTC/BTC","bids":[{"price":0.001228,"qty":295.28520921}],"asks":[],"checksum":1433483326,"timestamp":"2024-06-01T17:52:19.625864Z"}]}
{"channel":"book","type":"update","data":[{"symbol":"LTC/BTC","bids":[{"price":0.001228,"qty":247.24245913}],"asks":[],"checksum":4206856819,"timestamp":"2024-06-01T17:52:19.916028Z"}]}
{"channel":"book","type":"update","data":[{"symbol":"LTC/BTC","bids":[{"price":0.001228,"qty":295.28520916}],"asks":[],"checksum":4092438679,"timestamp":"2024-06-01T17:52:20.199131Z"}]}
{"channel":"book","type":"update","data":[{"symbol":"LTC/BTC","bids":[{"price":0.001228,"qty":247.24245913}],"asks":[],"checksum":4206856819,"timestamp":"2024-06-01T17:52:20.445415Z"}]}
{"channel":"book","type":"update","data":[{"symbol":"LTC/BTC","bids":[{"price":0.001229,"qty":226.48490004}],"asks":[],"checksum":1863652540,"timestamp":"2024-06-01T17:52:20.488324Z"}]}
{"channel":"book","type":"update","data":[{"symbol":"LTC/BTC","bids":[{"price":0.001229,"qty":230.69609502}],"asks":[],"checksum":1651763878,"timestamp":"2024-06-01T17:52:20.493651Z"}]}
{"channel":"book","type":"update","data":[{"symbol":"LTC/BTC","bids":[{"price":0.001228,"qty":295.28520901}],"asks":[],"checksum":886145832,"timestamp":"2024-06-01T17:52:20.707147Z"}]}
{"channel":"book","type":"update","data":[{"symbol":"LTC/BTC","bids":[{"price":0.001228,"qty":247.24245913}],"asks":[],"checksum":1651763878,"timestamp":"2024-06-01T17:52:20.965773Z"}]}
{"channel":"book","type":"update","data":[{"symbol":"LTC/BTC","bids":[{"price":0.001228,"qty":295.28518682}],"asks":[],"checksum":1252579641,"timestamp":"2024-06-01T17:52:21.226127Z"}]}
{"channel":"book","type":"update","data":[{"symbol":"LTC/BTC","bids":[{"price":0.001229,"qty":226.48490004}],"asks":[],"checksum":1204692771,"timestamp":"2024-06-01T17:52:22.623702Z"}]}
{"channel":"book","type":"update","data":[{"symbol":"LTC/BTC","bids":[{"price":0.001229,"qty":230.96531906}],"asks":[],"checksum":3214852117,"timestamp":"2024-06-01T17:52:22.626299Z"}]}
{"channel":"book","type":"update","data":[{"symbol":"LTC/BTC","bids":[],"asks":[{"price":0.001232,"qty":39.46080885}],"checksum":930148897,"timestamp":"2024-06-01T17:52:23.619771Z"}]}
{"channel":"book","type":"update","data":[{"symbol":"LTC/BTC","bids":[],"asks":[{"price":0.001232,"qty":49.15502302}],"checksum":3214852117,"timestamp":"2024-06-01T17:52:23.656598Z"}]}
{"channel":"book","type":"update","data":[{"symbol":"LTC/BTC","bids":[],"asks":[{"price":0.001234,"qty":307.99767943}],"checksum":4101212912,"timestamp":"2024-06-01T17:52:26.308221Z"}]}
{"channel":"book","type":"update","data":[{"symbol":"LTC/BTC","bids":[],"asks":[{"price":0.001233,"qty":164.22639676}],"checksum":1916341450,"timestamp":"2024-06-01T17:52:26.406484Z"}]}
{"channel":"book","type":"update","data":[{"symbol":"LTC/BTC","bids":[],"asks":[{"price":0.001241,"qty":499.63780120}],"checksum":1308574725,"timestamp":"2024-06-01T17:52:26.748253Z"}]}
{"channel":"book","type":"update","data":[{"symbol":"LTC/BTC","bids":[{"price":0.001228,"qty":273.10530108},{"price":0.001228,"qty":293.24651521}],"asks":[],"checksum":2926067039,"timestamp":"2024-06-01T17:52:27.858515Z"}]}
{"channel":"book","type":"update","data":[{"symbol":"LTC/BTC","bids":[],"asks":[{"price":0.001233,"qty":163.05838111}],"checksum":3266878967,"timestamp":"2024-06-01T17:52:28.288231Z"}]}
{"channel":"book","type":"update","data":[{"symbol":"LTC/BTC","bids":[],"asks":[{"price":0.001232,"qty":47.97655807}],"checksum":2364498522,"timestamp":"2024-06-01T17:52:28.288283Z"}]}
{"channel":"book","type":"update","data":[{"symbol":"LTC/BTC","bids":[],"asks":[{"price":0.001232,"qty":50.23955140}],"checksum":3804802504,"timestamp":"2024-06-01T17:52:28.288444Z"}]}
{"channel":"book","type":"update","data":[{"symbol":"LTC/BTC","bids":[{"price":0.001223,"qty":111.73534327}],"asks":[],"checksum":432513120,"timestamp":"2024-06-01T17:52:28.487743Z"}]}
{"channel":"book","type":"update","data":[{"symbol":"LTC/BTC","bids":[{"price":0.001222,"qty":68.56576404}],"asks":[],"checksum":1375585128,"timestamp":"2024-06-01T17:52:28.487849Z"}]}
{"channel":"book","type":"update","data":[{"symbol":"LTC/BTC","bids":[{"price":0.001223,"qty":90.22529410}],"asks":[],"checksum":4223017011,"timestamp":"2024-06-01T17:52:28.488177Z"}]}
{"channel":"book","type":"update","data":[{"symbol":"LTC/BTC","bids":[{"price":0.001223,"qty":78.39600000}],"asks":[],"checksum":539833239,"timestamp":"2024-06-01T17:52:28.488211Z"}]}
{"channel":"book","type":"update","data":[{"symbol":"LTC/BTC","bids":[{"price":0.001224,"qty":158.01526190}],"asks":[],"checksum":241295591,"timestamp":"2024-06-01T17:52:28.488259Z"}]}
{"channel":"book","type":"update","data":[{"symbol":"LTC/BTC","bids":[{"price":0.001224,"qty":160.16603946}],"asks":[],"checksum":3325690060,"timestamp":"2024-06-01T17:52:28.488751Z"}]}
{"channel":"book","type":"update","data":[{"symbol":"LTC/BTC","bids":[],"asks":[{"price":0.001231,"qty":68.14278528}],"checksum":4139184777,"timestamp":"2024-06-01T17:52:30.843003Z"}]}
{"channel":"book","type":"update","data":[{"symbol":"LTC/BTC","bids":[],"asks":[{"price":0.001232,"qty":40.54533723}],"checksum":2106118899,"timestamp":"2024-06-01T17:52:30.957333Z"}]}
{"channel":"book","type":"update","data":[{"symbol":"LTC/BTC","bids":[],"asks":[{"price":0.001231,"qty":83.59515336}],"checksum":1292116150,"timestamp":"2024-06-01T17:52:30.965647Z"}]}
{"channel":"book","type":"update","data":[{"symbol":"LTC/BTC","bids":[],"asks":[{"price":0.001233,"qty":172.75259528}],"checksum":3454352066,"timestamp":"2024-06-01T17:52:31.067634Z"}]}
{"channel":"book","type":"update","data":[{"symbol":"LTC/BTC","bids":[{"price":0.001228,"qty":284.03654530}],"asks":[],"checksum":2717602515,"timestamp":"2024-06-01T17:52:31.113026Z"}]}
{"channel":"book","type":"update","data":[{"symbol":"LTC/BTC","bids":[{"price":0.001229,"qty":240.17528897}],"asks":[],"checksum":31218387,"timestamp":"2024-06-01T17:52:31.113144Z"}]}
{"channel":"book","type":"update","data":[{"symbol":"LTC/BTC","bids":[{"price":0.001228,"qty":276.22800339}],"asks":[],"checksum":2724862739,"timestamp":"2024-06-01T17:52:31.135438Z"}]}
{"channel":"book","type":"update","data":[{"symbol":"LTC/BTC","bids":[],"asks":[{"price":0.001232,"qty":36.91464172}],"checksum":2182974536,"timestamp":"2024-06-01T17:52:31.135497Z"}]}
{"channel":"book","type":"update","data":[{"symbol":"LTC/BTC","bids":[],"asks":[{"price":0.001232,"qty":33.28465080}],"checksum":1912870757,"timestamp":"2024-06-01T17:52:31.135544Z"}]}
{"channel":"book","type":"update","data":[{"symbol":"LTC/BTC","bids":[],"asks":[{"price":0.001233,"qty":181.58396964}],"checksum":2046731844,"timestamp":"2024-06-01T17:52:31.157303Z"}]}
{"channel":"book","type":"update","data":[{"symbol":"LTC/BTC","bids":[],"asks":[{"price":0.001235,"qty":244.29860000}],"checksum":231754608,"timestamp":"2024-06-01T17:52:31.173151Z"}]}
{"channel":"book","type":"update","data":[{"symbol":"LTC/BTC","bids":[],"asks":[{"price":0.001231,"qty":35.55236808}],"checksum":3821919687,"timestamp":"2024-06-01T17:52:31.196847Z"}]}
{"channel":"book","type":"update","data":[{"symbol":"LTC/BTC","bids":[{"price":0.001229,"qty":233.87946334}],"asks":[],"checksum":2709211608,"timestamp":"2024-06-01T17:52:31.229339Z"}]}
{"channel":"book","type":"update","data":[{"symbol":"LTC/BTC","bids":[{"price":0.001229,"qty":241.68800525}],"asks":[],"checksum":3742954468,"timestamp":"2024-06-01T17:52:31.246838Z"}]}
{"channel":"book","type":"update","data":[{"symbol":"LTC/BTC","bids":[],"asks":[{"price":0.001233,"qty":188.84465607}],"checksum":743053769,"timestamp":"2024-06-01T17:52:31.247114Z"}]}
{"channel":"book","type":"update","data":[{"symbol":"LTC/BTC","bids":[],"asks":[{"price":0.001233,"qty":180.01328171}],"checksum":4066019652,"timestamp":"2024-06-01T17:52:31.261715Z"}]}
{"channel":"book","type":"update","data":[{"symbol":"LTC/BTC","bids":[],"asks":[{"price":0.001234,"qty":316.82905379}],"checksum":2925335401,"timestamp":"2024-06-01T17:52:31.261845Z"}]}
{"channel":"book","type":"update","data":[{"symbol":"LTC/BTC","bids":[{"price":0.001228,"qty":282.52382902}],"asks":[],"checksum":3567175716,"timestamp":"2024-06-01T17:52:31.335099Z"}]}
{"channel":"book","type":"update","data":[{"symbol":"LTC/BTC","bids":[{"price":0.001229,"qty":237.20758623}],"asks":[],"checksum":2458181059,"timestamp":"2024-06-01T17:52:31.428305Z"}]}
{"channel":"book","type":"update","data":[{"symbol":"LTC/BTC","bids":[{"price":0.001229,"qty":241.51060679}],"asks":[],"checksum":3367643039,"timestamp":"2024-06-01T17:52:31.431404Z"}]}
{"channel":"book","type":"update","data":[{"symbol":"LTC/BTC","bids":[],"asks":[{"price":0.001232,"qty":81.32500215}],"checksum":1933670543,"timestamp":"2024-06-01T17:52:31.554613Z"}]}
{"channel":"book","type":"update","data":[{"symbol":"LTC/BTC","bids":[],"asks":[{"price":0.001233,"qty":172.75259528}],"checksum":1442427662,"timestamp":"2024-06-01T17:52:31.728081Z"}]}
{"channel":"book","type":"update","data":[{"symbol":"LTC/BTC","bids":[{"price":0.001229,"qty":233.70206488}],"asks":[],"checksum":1198438607,"timestamp":"2024-06-01T17:52:31.754642Z"}]}
{"channel":"book","type":"update","data":[{"symbol":"LTC/BTC","bids":[{"price":0.001228,"qty":290.33237093}],"asks":[],"checksum":3895406875,"timestamp":"2024-06-01T17:52:31.869018Z"}]}
{"channel":"book","type":"update","data":[{"symbol":"LTC/BTC","bids":[],"asks":[{"price":0.001232,"qty":76.19506309}],"checksum":2648624079,"timestamp":"2024-06-01T17:52:31.938146Z"}]}
{"channel":"book","type":"update","data":[{"symbol":"LTC/BTC","bids":[{"price":0.001228,"qty":284.03654530}],"asks":[],"checksum":3958036630,"timestamp":"2024-06-01T17:52:31.938233Z"}]}
{"channel":"book","type":"update","data":[{"symbol":"LTC/BTC","bids":[{"price":0.001229,"qty":239.99789051}],"asks":[],"checksum":1547778894,"timestamp":"2024-06-01T17:52:31.941025Z"}]}
{"channel":"book","type":"update","data":[{"symbol":"LTC/BTC","bids":[],"asks":[{"price":0.001233,"qty":177.88253434}],"checksum":1917503363,"timestamp":"2024-06-01T17:52:32.041975Z"}]}
{"channel":"book","type":"update","data":[{"symbol":"LTC/BTC","bids":[],"asks":[{"price":0.001240,"qty":91.94924239}],"checksum":1220955382,"timestamp":"2024-06-01T17:52:32.053088Z"}]}
{"channel":"book","type":"update","data":[{"symbol":"LTC/BTC","bids":[],"asks":[{"price":0.001232,"qty":83.45574952}],"checksum":2809607400,"timestamp":"2024-06-01T17:52:32.300229Z"}]}
{"channel":"book","type":"update","data":[{"symbol":"LTC/BTC","bids":[{"price":0.001229,"qty":420.32427329}],"asks":[],"checksum":3254976924,"timestamp":"2024-06-01T17:52:33.498576Z"}]}
{"channel":"book","type":"update","data":[{"symbol":"LTC/BTC","bids":[{"price":0.001228,"qty":235.99381761}],"asks":[],"checksum":2179351954,"timestamp":"2024-06-01T17:52:33.741710Z"}]}
{"channel":"book","type":"update","data":[{"symbol":"LTC/BTC","bids":[{"price":0.001228,"qty":284.03376099}],"asks":[],"checksum":3267011596,"timestamp":"2024-06-01T17:52:34.004229Z"}]}
{"channel":"book","type":"update","data":[{"symbol":"LTC/BTC","bids":[{"price":0.001228,"qty":235.99381761}],"asks":[],"checksum":2179351954,"timestamp":"2024-06-01T17:52:34.294822Z"}]}
{"channel":"book","type":"update","data":[{"symbol":"LTC/BTC","bids":[{"price":0.001228,"qty":284.03375932}],"asks":[],"checksum":3341294286,"timestamp":"2024-06-01T17:52:34.584985Z"}]}
{"channel":"book","type":"update","data":[{"symbol":"LTC/BTC","bids":[{"price":0.001228,"qty":235.99381761}],"asks":[],"checksum":2179351954,"timestamp":"2024-06-01T17:52:34.877085Z"}]}
{"channel":"book","type":"update","data":[{"symbol":"LTC/BTC","bids":[],"asks":[{"price":0.001232,"qty":81.19275619}],"checksum":3766248041,"timestamp":"2024-06-01T17:52:34.886237Z"}]}
{"channel":"book","type":"update","data":[{"symbol":"LTC/BTC","bids":[],"asks":[{"price":0.001232,"qty":83.89544916}],"checksum":3051487668,"timestamp":"2024-06-01T17:52:34.887134Z"}]}
{"channel":"book","type":"update","data":[{"symbol":"LTC/BTC","bids":[{"price":0.001228,"qty":284.03376199}],"asks":[],"checksum":1739591403,"timestamp":"2024-06-01T17:52:35.140583Z"}]}
{"channel":"book","type":"update","data":[{"symbol":"LTC/BTC","bids":[{"price":0.001228,"qty":235.99381761}],"asks":[],"checksum":3051487668,"timestamp":"2024-06-01T17:52:35.436490Z"}]}
{"channel":"book","type":"update","data":[{"symbol":"LTC/BTC","bids":[{"price":0.001228,"qty":284.03377415}],"asks":[],"checksum":1342834010,"timestamp":"2024-06-01T17:52:35.701496Z"}]}
{"channel":"book","type":"update","data":[{"symbol":"LTC/BTC","bids":[{"price":0.001229,"qty":416.02125273}],"asks":[],"checksum":1556436088,"timestamp":"2024-06-01T17:52:35.862179Z"}]}
{"channel":"book","type":"update","data":[{"symbol":"LTC/BTC","bids":[{"price":0.001229,"qty":418.74308579}],"asks":[],"checksum":1413775603,"timestamp":"2024-06-01T17:52:35.864547Z"}]}
{"channel":"book","type":"update","data":[{"symbol":"LTC/BTC","bids":[{"price":0.001228,"qty":235.99381761}],"asks":[],"checksum":2980873245,"timestamp":"2024-06-01T17:52:35.950713Z"}]}
{"channel":"book","type":"update","data":[{"symbol":"LTC/BTC","bids":[{"price":0.001228,"qty":284.03376028}],"asks":[],"checksum":2649791922,"timestamp":"2024-06-01T17:52:36.199574Z"}]}
{"channel":"book","type":"update","data":[{"symbol":"LTC/BTC","bids":[{"price":0.001228,"qty":235.99381761}],"asks":[],"checksum":2980873245,"timestamp":"2024-06-01T17:52:36.448892Z"}]}
{"channel":"book","type":"update","data":[{"symbol":"LTC/BTC","bids":[{"price":0.001228,"qty":284.03376001}],"asks":[],"checksum":843475958,"timestamp":"2024-06-01T17:52:36.707486Z"}]}
{"channel":"book","type":"update","data":[{"symbol":"LTC/BTC","bids":[],"asks":[{"price":0.001232,"qty":81.19275619}],"checksum":1742211115,"timestamp":"2024-06-01T17:52:36.972884Z"}]}
{"channel":"book","type":"update","data":[{"symbol":"LTC/BTC","bids":[{"price":0.001228,"qty":235.99381761}],"asks":[],"checksum":3828541376,"timestamp":"2024-06-01T17:52:36.985755Z"}]}
{"channel":"book","type":"update","data":[{"symbol":"LTC/BTC","bids":[],"asks":[{"price":0.001232,"qty":83.66094269}],"checksum":4263739140,"timestamp":"2024-06-01T17:52:37.013572Z"}]}
{"channel":"book","type":"update","data":[{"symbol":"LTC/BTC","bids":[{"price":0.001229,"qty":409.53311588}],"asks":[],"checksum":291906260,"timestamp":"2024-06-01T17:52:37.120809Z"}]}
{"channel":"book","type":"update","data":[{"symbol":"LTC/BTC","bids":[{"price":0.001228,"qty":245.20378752}],"asks":[],"checksum":1242324564,"timestamp":"2024-06-01T17:52:37.219866Z"}]}
{"channel":"book","type":"update","data":[{"symbol":"LTC/BTC","bids":[{"price":0.001228,"qty":293.24372950}],"asks":[],"checksum":2705820624,"timestamp":"2024-06-01T17:52:37.263842Z"}]}
{"channel":"book","type":"update","data":[{"symbol":"LTC/BTC","bids":[],"asks":[{"price":0.001233,"qty":168.18832017}],"checksum":184786284,"timestamp":"2024-06-01T17:52:37.325564Z"}]}
{"channel":"book","type":"update","data":[{"symbol":"LTC/BTC","bids":[],"asks":[{"price":0.001232,"qty":93.35515686}],"checksum":2717713287,"timestamp":"2024-06-01T17:52:37.326701Z"}]}
{"channel":"book","type":"update","data":[{"symbol":"LTC/BTC","bids":[{"price":0.001228,"qty":245.20378752}],"asks":[],"checksum":1253496323,"timestamp":"2024-06-01T17:52:37.528799Z"}]}
{"channel":"book","type":"update","data":[{"symbol":"LTC/BTC","bids":[{"price":0.001228,"qty":293.24373330}],"asks":[],"checksum":1129231591,"timestamp":"2024-06-01T17:52:37.829374Z"}]}
{"channel":"book","type":"update","data":[{"symbol":"LTC/BTC","bids":[{"price":0.001228,"qty":245.20378752}],"asks":[],"checksum":1253496323,"timestamp":"2024-06-01T17:52:38.119937Z"}]}
{"channel":"book","type":"update","data":[{"symbol":"LTC/BTC","bids":[],"asks":[{"price":0.001232,"qty":103.04937103}],"checksum":1729256082,"timestamp":"2024-06-01T17:52:38.355877Z"}]}
{"channel":"book","type":"update","data":[{"symbol":"LTC/BTC","bids":[],"asks":[{"price":0.001232,"qty":93.35515686}],"checksum":1253496323,"timestamp":"2024-06-01T17:52:38.355900Z"}]}
{"channel":"book","type":"update","data":[{"symbol":"LTC/BTC","bids":[{"price":0.001228,"qty":293.24367400}],"asks":[],"checksum":762875180,"timestamp":"2024-06-01T17:52:38.390290Z"}]}
{"channel":"book","type":"update","data":[{"symbol":"LTC/BTC","bids":[{"price":0.001228,"qty":245.20378752}],"asks":[],"checksum":1253496323,"timestamp":"2024-06-01T17:52:38.661673Z"}]}
{"channel":"book","type":"update","data":[{"symbol":"LTC/BTC","bids":[{"price":0.001228,"qty":293.24366755}],"asks":[],"checksum":1237188996,"timestamp":"2024-06-01T17:52:38.913428Z"}]}
{"channel":"book","type":"update","data":[{"symbol":"LTC/BTC","bids":[{"price":0.001223,"qty":80.54714532}],"asks":[],"checksum":3929505053,"timestamp":"2024-06-01T17:52:38.924300Z"}]}
{"channel":"book","type":"update","data":[{"symbol":"LTC/BTC","bids":[{"price":0.001224,"qty":158.01526190}],"asks":[],"checksum":577543478,"timestamp":"2024-06-01T17:52:38.924402Z"}]}
{"channel":"book","type":"update","data":[{"symbol":"LTC/BTC","bids":[{"price":0.001222,"qty":47.05338874}],"asks":[],"checksum":1784086078,"timestamp":"2024-06-01T17:52:38.924726Z"}]}
{"channel":"book","type":"update","data":[{"symbol":"LTC/BTC","bids":[{"price":0.001223,"qty":102.06197890}],"asks":[],"checksum":745465008,"timestamp":"2024-06-01T17:52:38.924930Z"}]}
{"channel":"book","type":"update","data":[{"symbol":"LTC/BTC","bids":[{"price":0.001224,"qty":146.18598529}],"asks":[],"checksum":2084952415,"timestamp":"2024-06-01T17:52:38.925460Z"}]}
{"channel":"book","type":"update","data":[{"symbol":"LTC/BTC","bids":[{"price":0.001223,"qty":113.89513737}],"asks":[],"checksum":2125111110,"timestamp":"2024-06-01T17:52:38.925532Z"}]}
{"channel":"book","type":"update","data":[{"symbol":"LTC/BTC","bids":[{"price":0.001228,"qty":245.20378752}],"asks":[],"checksum":225804562,"timestamp":"2024-06-01T17:52:39.160187Z"}]}
{"channel":"book","type":"update","data":[{"symbol":"LTC/BTC","bids":[{"price":0.001228,"qty":293.24371608}],"asks":[],"checksum":948216118,"timestamp":"2024-06-01T17:52:39.408235Z"}]}
{"channel":"book","type":"update","data":[{"symbol":"LTC/BTC","bids":[{"price":0.001228,"qty":245.20378752}],"asks":[],"checksum":225804562,"timestamp":"2024-06-01T17:52:39.668292Z"}]}
{"channel":"book","type":"update","data":[{"symbol":"LTC/BTC","bids":[{"price":0.001228,"qty":293.24371731}],"asks":[],"checksum":879132736,"timestamp":"2024-06-01T17:52:39.956113Z"}]}
{"channel":"book","type":"update","data":[{"symbol":"LTC/BTC","bids":[{"price":0.001229,"qty":406.81128282}],"asks":[],"checksum":2293111215,"timestamp":"2024-06-01T17:52:40.058395Z"}]}
{"channel":"book","type":"update","data":[{"symbol":"LTC/BTC","bids":[{"price":0.001229,"qty":409.36777975}],"asks":[],"checksum":3703767672,"timestamp":"2024-06-01T17:52:40.063965Z"}]}
{"channel":"book","type":"update","data":[{"symbol":"LTC/BTC","bids":[{"price":0.001228,"qty":245.20378752}],"asks":[],"checksum":3855614762,"timestamp":"2024-06-01T17:52:40.246319Z"}]}
{"channel":"book","type":"update","data":[{"symbol":"LTC/BTC","bids":[{"price":0.001228,"qty":293.24371952}],"asks":[],"checksum":3194973593,"timestamp":"2024-06-01T17:52:40.528179Z"}]}
{"channel":"book","type":"update","data":[{"symbol":"LTC/BTC","bids":[{"price":0.001228,"qty":245.20378752}],"asks":[],"checksum":3855614762,"timestamp":"2024-06-01T17:52:40.816437Z"}]}
{"channel":"book","type":"update","data":[{"symbol":"LTC/BTC","bids":[{"price":0.001228,"qty":293.24373011}],"asks":[],"checksum":1060524989,"timestamp":"2024-06-01T17:52:41.099485Z"}]}
{"channel":"book","type":"update","data":[{"symbol":"LTC/BTC","bids":[{"price":0.001228,"qty":245.20378752}],"asks":[],"checksum":3855614762,"timestamp":"2024-06-01T17:52:41.376449Z"}]}
{"channel":"book","type":"update","data":[{"symbol":"LTC/BTC","bids":[{"price":0.001228,"qty":293.24374745}],"asks":[],"checksum":1107266177,"timestamp":"2024-06-01T17:52:41.664805Z"}]}
{"channel":"book","type":"update","data":[{"symbol":"LTC/BTC","bids":[{"price":0.001228,"qty":245.20378752}],"asks":[],"checksum":3855614762,"timestamp":"2024-06-01T17:52:41.927045Z"}]}
{"channel":"book","type":"update","data":[{"symbol":"LTC/BTC","bids":[{"price":0.001228,"qty":293.24374926}],"asks":[],"checksum":592700768,"timestamp":"2024-06-01T17:52:42.192083Z"}]}
{"channel":"book","type":"update","data":[{"symbol":"LTC/BTC","bids":[{"price":0.001229,"qty":406.81128282}],"asks":[],"checksum":2000617143,"timestamp":"2024-06-01T17:52:42.339400Z"}]}
{"channel":"book","type":"update","data":[{"symbol":"LTC/BTC","bids":[{"price":0.001229,"qty":409.53323886}],"asks":[],"checksum":2769652485,"timestamp":"2024-06-01T17:52:42.342038Z"}]}
{"channel":"book","type":"update","data":[{"symbol":"LTC/BTC","bids":[{"price":0.001228,"qty":245.20378752}],"asks":[],"checksum":1670802767,"timestamp":"2024-06-01T17:52:42.462478Z"}]}
{"channel":"book","type":"update","data":[{"symbol":"LTC/BTC","bids":[{"price":0.001228,"qty":293.24374914}],"asks":[],"checksum":410194587,"timestamp":"2024-06-01T17:52:42.713578Z"}]}
{"channel":"book","type":"update","data":[{"symbol":"LTC/BTC","bids":[{"price":0.001228,"qty":245.20378752}],"asks":[],"checksum":1670802767,"timestamp":"2024-06-01T17:52:42.973765Z"}]}
{"channel":"book","type":"update","data":[{"symbol":"LTC/BTC","bids":[{"price":0.001228,"qty":293.24375761}],"asks":[],"checksum":3674134560,"timestamp":"2024-06-01T17:52:43.227807Z"}]}
{"channel":"book","type":"update","data":[{"symbol":"LTC/BTC","bids":[{"price":0.001228,"qty":245.20378752}],"asks":[],"checksum":1670802767,"timestamp":"2024-06-01T17:52:43.476429Z"}]}
{"channel":"book","type":"update","data":[{"symbol":"LTC/BTC","bids":[{"price":0.001228,"qty":293.24374924}],"asks":[],"checksum":1880172441,"timestamp":"2024-06-01T17:52:43.821482Z"}]}
{"channel":"book","type":"update","data":[{"symbol":"LTC/BTC","bids":[{"price":0.001228,"qty":245.20378752}],"asks":[],"checksum":1670802767,"timestamp":"2024-06-01T17:52:44.066299Z"}]}
{"channel":"book","type":"update","data":[{"symbol":"LTC/BTC","bids":[{"price":0.001228,"qty":293.24374722}],"asks":[],"checksum":3649252171,"timestamp":"2024-06-01T17:52:44.351373Z"}]}
{"channel":"book","type":"update","data":[{"symbol":"LTC/BTC","bids":[{"price":0.001228,"qty":245.20378752}],"asks":[],"checksum":1670802767,"timestamp":"2024-06-01T17:52:44.640377Z"}]}
{"channel":"book","type":"update","data":[{"symbol":"LTC/BTC","bids":[{"price":0.001227,"qty":287.56071625}],"asks":[],"checksum":1778628238,"timestamp":"2024-06-01T17:52:44.800196Z"}]}
{"channel":"book","type":"update","data":[{"symbol":"LTC/BTC","bids":[{"price":0.001227,"qty":369.56071625}],"asks":[],"checksum":1432351710,"timestamp":"2024-06-01T17:52:44.804245Z"}]}
{"channel":"book","type":"update","data":[{"symbol":"LTC/BTC","bids":[{"price":0.001228,"qty":293.24374998}],"asks":[],"checksum":3999469071,"timestamp":"2024-06-01T17:52:44.927580Z"}]}
{"channel":"book","type":"update","data":[{"symbol":"LTC/BTC","bids":[{"price":0.001228,"qty":245.20378752}],"asks":[],"checksum":1432351710,"timestamp":"2024-06-01T17:52:45.167534Z"}]}
{"channel":"book","type":"update","data":[{"symbol":"LTC/BTC","bids":[{"price":0.001228,"qty":293.24374736}],"asks":[],"checksum":255591522,"timestamp":"2024-06-01T17:52:45.456550Z"}]}
{"channel":"book","type":"update","data":[{"symbol":"LTC/BTC","bids":[{"price":0.001228,"qty":245.20378752}],"asks":[],"checksum":1432351710,"timestamp":"2024-06-01T17:52:45.706144Z"}]}
{"channel":"book","type":"update","data":[{"symbol":"LTC/BTC","bids":[{"price":0.001228,"qty":293.24374576}],"asks":[],"checksum":603998836,"timestamp":"2024-06-01T17:52:46.005538Z"}]}
{"channel":"book","type":"update","data":[{"symbol":"LTC/BTC","bids":[{"price":0.001228,"qty":245.20378752}],"asks":[],"checksum":1432351710,"timestamp":"2024-06-01T17:52:46.293245Z"}]}
{"channel":"book","type":"update","data":[{"symbol":"LTC/BTC","bids":[{"price":0.001228,"qty":293.24374735}],"asks":[],"checksum":2965044912,"timestamp":"2024-06-01T17:52:46.577493Z"}]}
{"channel":"book","type":"update","data":[{"symbol":"LTC/BTC","bids":[],"asks":[{"price":0.001234,"qty":316.72532610}],"checksum":3991368652,"timestamp":"2024-06-01T17:52:46.621305Z"}]}
{"channel":"book","type":"update","data":[{"symbol":"LTC/BTC","bids":[],"asks":[{"price":0.001234,"qty":316.82897493}],"checksum":3324279221,"timestamp":"2024-06-01T17:52:46.697882Z"}]}
{"channel":"book","type":"update","data":[{"symbol":"LTC/BTC","bids":[{"price":0.001228,"qty":245.20378752}],"asks":[],"checksum":599880923,"timestamp":"2024-06-01T17:52:46.860365Z"}]}
{"channel":"book","type":"update","data":[{"symbol":"LTC/BTC","bids":[{"price":0.001228,"qty":293.24374382}],"asks":[],"checksum":918582576,"timestamp":"2024-06-01T17:52:47.147921Z"}]}
{"channel":"book","type":"update","data":[{"symbol":"LTC/BTC","bids":[{"price":0.001228,"qty":245.20378752}],"asks":[],"checksum":599880923,"timestamp":"2024-06-01T17:52:47.401863Z"}]}
{"channel":"book","type":"update","data":[{"symbol":"LTC/BTC","bids":[{"price":0.001228,"qty":293.24373948}],"asks":[],"checksum":793940090,"timestamp":"2024-06-01T17:52:47.698382Z"}]}
{"channel":"book","type":"update","data":[{"symbol":"LTC/BTC","bids":[{"price":0.001228,"qty":245.20378752}],"asks":[],"checksum":599880923,"timestamp":"2024-06-01T17:52:47.960151Z"}]}
{"channel":"book","type":"update","data":[{"symbol":"LTC/BTC","bids":[{"price":0.001228,"qty":293.24366838}],"asks":[],"checksum":2563552433,"timestamp":"2024-06-01T17:52:48.226968Z"}]}
{"channel":"book","type":"update","data":[{"symbol":"LTC/BTC","bids":[{"price":0.001228,"qty":245.20378752}],"asks":[],"checksum":599880923,"timestamp":"2024-06-01T17:52:48.476888Z"}]}
{"channel":"book","type":"update","data":[{"symbol":"LTC/BTC","bids":[{"price":0.001228,"qty":293.24374060}],"asks":[],"checksum":2386023231,"timestamp":"2024-06-01T17:52:48.755891Z"}]}
{"channel":"book","type":"update","data":[{"symbol":"LTC/BTC","bids":[{"price":0.001228,"qty":245.20378752}],"asks":[],"checksum":599880923,"timestamp":"2024-06-01T17:52:49.047655Z"}]}
{"channel":"book","type":"update","data":[{"symbol":"LTC/BTC","bids":[{"price":0.001223,"qty":102.06197890}],"asks":[],"checksum":556675778,"timestamp":"2024-06-01T17:52:49.151063Z"}]}
{"channel":"book","type":"update","data":[{"symbol":"LTC/BTC","bids":[{"price":0.001222,"qty":68.56822232}],"asks":[],"checksum":955872295,"timestamp":"2024-06-01T17:52:49.151122Z"}]}
{"channel":"book","type":"update","data":[{"symbol":"LTC/BTC","bids":[{"price":0.001223,"qty":99.91083358}],"asks":[],"checksum":4064323816,"timestamp":"2024-06-01T17:52:49.151659Z"}]}
{"channel":"book","type":"update","data":[{"symbol":"LTC/BTC","bids":[{"price":0.001223,"qty":111.74399205}],"asks":[],"checksum":59091147,"timestamp":"2024-06-01T17:52:49.151765Z"}]}
{"channel":"book","type":"update","data":[{"symbol":"LTC/BTC","bids":[{"price":0.001224,"qty":148.33713061}],"asks":[],"checksum":2384225064,"timestamp":"2024-06-01T17:52:49.151810Z"}]}
{"channel":"book","type":"update","data":[{"symbol":"LTC/BTC","bids":[{"price":0.001223,"qty":90.22915847}],"asks":[],"checksum":3197224024,"timestamp":"2024-06-01T17:52:49.151938Z"}]}
{"channel":"book","type":"update","data":[{"symbol":"LTC/BTC","bids":[{"price":0.001228,"qty":293.24445610}],"asks":[],"checksum":180992413,"timestamp":"2024-06-01T17:52:49.326395Z"}]}
{"channel":"book","type":"update","data":[{"symbol":"LTC/BTC","bids":[{"price":0.001228,"qty":245.20378752}],"asks":[],"checksum":3197224024,"timestamp":"2024-06-01T17:52:49.625531Z"}]}
{"channel":"book","type":"update","data":[{"symbol":"LTC/BTC","bids":[{"price":0.001228,"qty":293.24374506}],"asks":[],"checksum":2656256695,"timestamp":"2024-06-01T17:52:49.904174Z"}]}
{"channel":"book","type":"update","data":[{"symbol":"LTC/BTC","bids":[{"price":0.001228,"qty":245.20378752}],"asks":[],"checksum":3197224024,"timestamp":"2024-06-01T17:52:50.157532Z"}]}
{"channel":"book","type":"update","data":[{"symbol":"LTC/BTC","bids":[{"price":0.001228,"qty":293.24374653}],"asks":[],"checksum":375861975,"timestamp":"2024-06-01T17:52:50.453868Z"}]}
{"channel":"book","type":"update","data":[{"symbol":"LTC/BTC","bids":[{"price":0.001227,"qty":369.46464254}],"asks":[],"checksum":3255191113,"timestamp":"2024-06-01T17:52:50.652375Z"}]}
{"channel":"book","type":"update","data":[{"symbol":"LTC/BTC","bids":[{"price":0.001228,"qty":245.20378752}],"asks":[],"checksum":1794158790,"timestamp":"2024-06-01T17:52:50.701953Z"}]}
{"channel":"book","type":"update","data":[{"symbol":"LTC/BTC","bids":[{"price":0.001225,"qty":11.46380469}],"asks":[],"checksum":1698516235,"timestamp":"2024-06-01T17:52:50.743565Z"}]}
{"channel":"book","type":"update","data":[{"symbol":"LTC/BTC","bids":[{"price":0.001228,"qty":293.24372134}],"asks":[],"checksum":2961307808,"timestamp":"2024-06-01T17:52:50.964781Z"}]}
{"channel":"book","type":"update","data":[{"symbol":"LTC/BTC","bids":[{"price":0.001228,"qty":245.20378752}],"asks":[],"checksum":1698516235,"timestamp":"2024-06-01T17:52:51.230065Z"}]}
{"channel":"book","type":"update","data":[{"symbol":"LTC/BTC","bids":[{"price":0.001228,"qty":293.24373211}],"asks":[],"checksum":448385443,"timestamp":"2024-06-01T17:52:51.497453Z"}]}
{"channel":"book","type":"update","data":[{"symbol":"LTC/BTC","bids":[{"price":0.001228,"qty":245.20378752}],"asks":[],"checksum":1698516235,"timestamp":"2024-06-01T17:52:51.777142Z"}]}
{"channel":"book","type":"update","data":[{"symbol":"LTC/BTC","bids":[{"price":0.001228,"qty":293.24372126}],"asks":[],"checksum":3203323596,"timestamp":"2024-06-01T17:52:52.064930Z"}]}
{"channel":"book","type":"update","data":[{"symbol":"LTC/BTC","bids":[],"asks":[{"price":0.001232,"qty":90.88697036}],"checksum":2388262049,"timestamp":"2024-06-01T17:52:52.352744Z"}]}
{"channel":"book","type":"update","data":[{"symbol":"LTC/BTC","bids":[],"asks":[{"price":0.001232,"qty":93.22337396}],"checksum":2245070464,"timestamp":"2024-06-01T17:52:52.353410Z"}]}
{"channel":"book","type":"update","data":[{"symbol":"LTC/BTC","bids":[{"price":0.001228,"qty":245.20378752}],"asks":[],"checksum":1577227591,"timestamp":"2024-06-01T17:52:52.362256Z"}]}
{"channel":"book","type":"update","data":[{"symbol":"LTC/BTC","bids":[{"price":0.001228,"qty":293.24365417}],"asks":[],"checksum":3466285952,"timestamp":"2024-06-01T17:52:52.629511Z"}]}
{"channel":"book","type":"update","data":[{"symbol":"LTC/BTC","bids":[{"price":0.001228,"qty":245.20378752}],"asks":[],"checksum":1577227591,"timestamp":"2024-06-01T17:52:52.900303Z"}]}
{"channel":"book","type":"update","data":[{"symbol":"LTC/BTC","bids":[{"price":0.001228,"qty":293.24371818}],"asks":[],"checksum":4087157931,"timestamp":"2024-06-01T17:52:53.161436Z"}]}
{"channel":"book","type":"update","data":[{"symbol":"LTC/BTC","bids":[{"price":0.001228,"qty":245.20378752}],"asks":[],"checksum":1577227591,"timestamp":"2024-06-01T17:52:53.462303Z"}]}
{"channel":"book","type":"update","data":[{"symbol":"LTC/BTC","bids":[{"price":0.001228,"qty":293.24371666}],"asks":[],"checksum":1527109157,"timestamp":"2024-06-01T17:52:53.709185Z"}]}
{"channel":"book","type":"update","data":[{"symbol":"LTC/BTC","bids":[{"price":0.001228,"qty":245.20378752}],"asks":[],"checksum":1577227591,"timestamp":"2024-06-01T17:52:53.984398Z"}]}
{"channel":"book","type":"update","data":[{"symbol":"LTC/BTC","bids":[{"price":0.001228,"qty":293.24364529}],"asks":[],"checksum":3910325748,"timestamp":"2024-06-01T17:52:54.248641Z"}]}
{"channel":"book","type":"update","data":[{"symbol":"LTC/BTC","bids":[{"price":0.001228,"qty":245.20378752}],"asks":[],"checksum":1577227591,"timestamp":"2024-06-01T17:52:54.505451Z"}]}
{"channel":"book","type":"update","data":[{"symbol":"LTC/BTC","bids":[{"price":0.001228,"qty":293.24367899}],"asks":[],"checksum":2985668165,"timestamp":"2024-06-01T17:52:54.794549Z"}]}
{"channel":"book","type":"update","data":[{"symbol":"LTC/BTC","bids":[{"price":0.001228,"qty":245.20378752}],"asks":[],"checksum":1577227591,"timestamp":"2024-06-01T17:52:55.072978Z"}]}
{"channel":"book","type":"update","data":[{"symbol":"LTC/BTC","bids":[{"price":0.001228,"qty":293.24368392}],"asks":[],"checksum":1971706316,"timestamp":"2024-06-01T17:52:55.326267Z"}]}
{"channel":"book","type":"update","data":[{"symbol":"LTC/BTC","bids":[{"price":0.001228,"qty":245.20378752}],"asks":[],"checksum":1577227591,"timestamp":"2024-06-01T17:52:55.616732Z"}]}
{"channel":"book","type":"update","data":[{"symbol":"LTC/BTC","bids":[{"price":0.001228,"qty":293.24368478}],"asks":[],"checksum":1592430325,"timestamp":"2024-06-01T17:52:55.908773Z"}]}
{"channel":"book","type":"update","data":[{"symbol":"LTC/BTC","bids":[{"price":0.001228,"qty":245.20378752}],"asks":[],"checksum":1577227591,"timestamp":"2024-06-01T17:52:56.195231Z"}]}
{"channel":"book","type":"update","data":[{"symbol":"LTC/BTC","bids":[{"price":0.001228,"qty":293.24372013}],"asks":[],"checksum":1358255814,"timestamp":"2024-06-01T17:52:56.476774Z"}]}
{"channel":"book","type":"update","data":[{"symbol":"LTC/BTC","bids":[{"price":0.001228,"qty":245.20378752}],"asks":[],"checksum":1577227591,"timestamp":"2024-06-01T17:52:56.752192Z"}]}
{"channel":"book","type":"update","data":[{"symbol":"LTC/BTC","bids":[],"asks":[{"price":0.001232,"qty":90.88697036}],"checksum":1435133798,"timestamp":"2024-06-01T17:52:56.834776Z"}]}
{"channel":"book","type":"update","data":[{"symbol":"LTC/BTC","bids":[{"price":0.001228,"qty":293.24371924}],"asks":[],"checksum":1468261396,"timestamp":"2024-06-01T17:52:57.037112Z"}]}
{"channel":"book","type":"update","data":[{"symbol":"LTC/BTC","bids":[{"price":0.001228,"qty":245.20378752}],"asks":[],"checksum":1435133798,"timestamp":"2024-06-01T17:52:57.332209Z"}]}
{"channel":"book","type":"update","data":[{"symbol":"LTC/BTC","bids":[{"price":0.001228,"qty":293.24371896}],"asks":[],"checksum":4279645911,"timestamp":"2024-06-01T17:52:57.593349Z"}]}
{"channel":"book","type":"update","data":[{"symbol":"LTC/BTC","bids":[{"price":0.001228,"qty":245.20378752}],"asks":[],"checksum":1435133798,"timestamp":"2024-06-01T17:52:57.852740Z"}]}
{"channel":"book","type":"update","data":[{"symbol":"LTC/BTC","bids":[{"price":0.001228,"qty":293.24371932}],"asks":[],"checksum":2419472956,"timestamp":"2024-06-01T17:52:58.140865Z"}]}
{"channel":"book","type":"update","data":[{"symbol":"LTC/BTC","bids":[{"price":0.001228,"qty":245.20378752}],"asks":[],"checksum":1435133798,"timestamp":"2024-06-01T17:52:58.427014Z"}]}
{"channel":"book","type":"update","data":[{"symbol":"LTC/BTC","bids":[{"price":0.001228,"qty":293.24371775}],"asks":[],"checksum":4254750904,"timestamp":"2024-06-01T17:52:58.712432Z"}]}
{"channel":"book","type":"update","data":[{"symbol":"LTC/BTC","bids":[{"price":0.001228,"qty":245.20378752}],"asks":[],"checksum":1435133798,"timestamp":"2024-06-01T17:52:59.003657Z"}]}
{"channel":"book","type":"update","data":[{"symbol":"LTC/BTC","bids":[],"asks":[{"price":0.001232,"qty":93.22337396}],"checksum":1577227591,"timestamp":"2024-06-01T17:52:59.104665Z"}]}
{"channel":"book","type":"update","data":[{"symbol":"LTC/BTC","bids":[{"price":0.001228,"qty":293.24365403}],"asks":[],"checksum":1841558922,"timestamp":"2024-06-01T17:52:59.289336Z"}]}
{"channel":"book","type":"update","data":[{"symbol":"LTC/BTC","bids":[{"price":0.001229,"qty":229.20685608}],"asks":[],"checksum":1176843152,"timestamp":"2024-06-01T17:52:59.291233Z"}]}
{"channel":"book","type":"update","data":[{"symbol":"LTC/BTC","bids":[{"price":0.001228,"qty":245.20378752}],"asks":[],"checksum":1977897821,"timestamp":"2024-06-01T17:52:59.581899Z"}]}
{"channel":"book","type":"update","data":[{"symbol":"LTC/BTC","bids":[{"price":0.001224,"qty":146.18598529}],"asks":[],"checksum":3827451202,"timestamp":"2024-06-01T17:52:59.670357Z"}]}
{"channel":"book","type":"update","data":[{"symbol":"LTC/BTC","bids":[{"price":0.001223,"qty":92.38051123}],"asks":[],"checksum":2900809056,"timestamp":"2024-06-01T17:52:59.670865Z"}]}
{"channel":"book","type":"update","data":[{"symbol":"LTC/BTC","bids":[{"price":0.001228,"qty":293.24365365}],"asks":[],"checksum":3617999595,"timestamp":"2024-06-01T17:52:59.877566Z"}]}
{"channel":"book","type":"update","data":[{"symbol":"LTC/BTC","bids":[{"price":0.001229,"qty":226.48490004}],"asks":[],"checksum":3983975735,"timestamp":"2024-06-01T17:53:00.035432Z"}]}
{"channel":"book","type":"update","data":[{"symbol":"LTC/BTC","bids":[{"price":0.001229,"qty":230.86127023}],"asks":[],"checksum":3419409186,"timestamp":"2024-06-01T17:53:00.040471Z"}]}
{"channel":"book","type":"update","data":[{"symbol":"LTC/BTC","bids":[{"price":0.001228,"qty":245.20378752}],"asks":[],"checksum":2962265257,"timestamp":"2024-06-01T17:53:00.163208Z"}]}
{"channel":"book","type":"update","data":[{"symbol":"LTC/BTC","bids":[{"price":0.001228,"qty":293.24366175}],"asks":[],"checksum":3059254710,"timestamp":"2024-06-01T17:53:00.412442Z"}]}
{"channel":"book","type":"update","data":[{"symbol":"LTC/BTC","bids":[{"price":0.001228,"qty":245.20378752}],"asks":[],"checksum":2962265257,"timestamp":"2024-06-01T17:53:00.683907Z"}]}
{"channel":"book","type":"update","data":[{"symbol":"LTC/BTC","bids":[{"price":0.001225,"qty":2.46380469}],"asks":[],"checksum":4110394895,"timestamp":"2024-06-01T17:53:00.698074Z"}]}
{"channel":"book","type":"update","data":[{"symbol":"LTC/BTC","bids":[{"price":0.001224,"qty":155.18598529}],"asks":[],"checksum":3715175556,"timestamp":"2024-06-01T17:53:00.727970Z"}]}
{"channel":"book","type":"update","data":[{"symbol":"LTC/BTC","bids":[{"price":0.001228,"qty":293.24362006}],"asks":[],"checksum":1472124682,"timestamp":"2024-06-01T17:53:00.968345Z"}]}
{"channel":"book","type":"update","data":[{"symbol":"LTC/BTC","bids":[{"price":0.001228,"qty":245.20378752}],"asks":[],"checksum":3715175556,"timestamp":"2024-06-01T17:53:01.269475Z"}]}
{"channel":"book","type":"update","data":[{"symbol":"LTC/BTC","bids":[{"price":0.001228,"qty":293.24361924}],"asks":[],"checksum":1435734159,"timestamp":"2024-06-01T17:53:01.520691Z"}]}
{"channel":"book","type":"update","data":[{"symbol":"LTC/BTC","bids":[{"price":0.001228,"qty":245.20378752}],"asks":[],"checksum":3715175556,"timestamp":"2024-06-01T17:53:01.769310Z"}]}
{"channel":"book","type":"update","data":[{"symbol":"LTC/BTC","bids":[{"price":0.001228,"qty":293.24362261}],"asks":[],"checksum":3512541622,"timestamp":"2024-06-01T17:53:02.027408Z"}]}
{"channel":"book","type":"update","data":[{"symbol":"LTC/BTC","bids":[{"price":0.001228,"qty":245.20378752}],"asks":[],"checksum":3715175556,"timestamp":"2024-06-01T17:53:02.282935Z"}]}
{"channel":"book","type":"update","data":[{"symbol":"LTC/BTC","bids":[{"price":0.001228,"qty":293.24361912}],"asks":[],"checksum":1393063126,"timestamp":"2024-06-01T17:53:02.537386Z"}]}
{"channel":"book","type":"update","data":[{"symbol":"LTC/BTC","bids":[{"price":0.001228,"qty":245.20378752}],"asks":[],"checksum":3715175556,"timestamp":"2024-06-01T17:53:02.832709Z"}]}
{"channel":"book","type":"update","data":[{"symbol":"LTC/BTC","bids":[{"price":0.001228,"qty":293.24356327}],"asks":[],"checksum":3855291656,"timestamp":"2024-06-01T17:53:03.129499Z"}]}
{"channel":"book","type":"update","data":[{"symbol":"LTC/BTC","bids":[{"price":0.001228,"qty":245.20378752}],"asks":[],"checksum":3715175556,"timestamp":"2024-06-01T17:53:03.386013Z"}]}
{"channel":"book","type":"update","data":[{"symbol":"LTC/BTC","bids":[],"asks":[{"price":0.001232,"qty":90.88697036}],"checksum":2388399179,"timestamp":"2024-06-01T17:53:03.486163Z"}]}
{"channel":"book","type":"update","data":[{"symbol":"LTC/BTC","bids":[],"asks":[{"price":0.001232,"qty":93.07679945}],"checksum":2966045513,"timestamp":"2024-06-01T17:53:03.486576Z"}]}
{"channel":"book","type":"update","data":[{"symbol":"LTC/BTC","bids":[{"price":0.001228,"qty":293.24362425}],"asks":[],"checksum":126924713,"timestamp":"2024-06-01T17:53:03.639445Z"}]}
{"channel":"book","type":"update","data":[{"symbol":"LTC/BTC","bids":[{"price":0.001228,"qty":245.20378752}],"asks":[],"checksum":2966045513,"timestamp":"2024-06-01T17:53:03.901662Z"}]}
{"channel":"book","type":"update","data":[{"symbol":"LTC/BTC","bids":[{"price":0.001228,"qty":293.24363404}],"asks":[],"checksum":1554240358,"timestamp":"2024-06-01T17:53:04.192929Z"}]}
{"channel":"book","type":"update","data":[{"symbol":"LTC/BTC","bids":[{"price":0.001229,"qty":411.18765301}],"asks":[],"checksum":2562515145,"timestamp":"2024-06-01T17:53:04.291367Z"}]}
{"channel":"book","type":"update","data":[{"symbol":"LTC/BTC","bids":[{"price":0.001228,"qty":245.20378752}],"asks":[],"checksum":1960145126,"timestamp":"2024-06-01T17:53:04.478932Z"}]}
{"channel":"book","type":"update","data":[{"symbol":"LTC/BTC","bids":[{"price":0.001228,"qty":293.24362136}],"asks":[],"checksum":3254984981,"timestamp":"2024-06-01T17:53:04.732628Z"}]}
{"channel":"book","type":"update","data":[{"symbol":"LTC/BTC","bids":[{"price":0.001228,"qty":245.20378752}],"asks":[],"checksum":1960145126,"timestamp":"2024-06-01T17:53:04.994806Z"}]}
{"channel":"book","type":"update","data":[{"symbol":"LTC/BTC","bids":[{"price":0.001228,"qty":293.24362333}],"asks":[],"checksum":1862778326,"timestamp":"2024-06-01T17:53:05.259818Z"}]}
{"channel":"book","type":"update","data":[{"symbol":"LTC/BTC","bids":[{"price":0.001228,"qty":245.20378752}],"asks":[],"checksum":1960145126,"timestamp":"2024-06-01T17:53:05.528821Z"}]}
{"channel":"book","type":"update","data":[{"symbol":"LTC/BTC","bids":[{"price":0.001228,"qty":293.24362252}],"asks":[],"checksum":107123154,"timestamp":"2024-06-01T17:53:05.799323Z"}]}
{"channel":"book","type":"update","data":[{"symbol":"LTC/BTC","bids":[{"price":0.001228,"qty":245.20378752}],"asks":[],"checksum":1960145126,"timestamp":"2024-06-01T17:53:06.091006Z"}]}
{"channel":"book","type":"update","data":[{"symbol":"LTC/BTC","bids":[{"price":0.001228,"qty":293.24361985}],"asks":[],"checksum":2127468586,"timestamp":"2024-06-01T17:53:06.364326Z"}]}
{"channel":"book","type":"update","data":[{"symbol":"LTC/BTC","bids":[{"price":0.001228,"qty":245.20378752}],"asks":[],"checksum":1960145126,"timestamp":"2024-06-01T17:53:06.607840Z"}]}
{"channel":"book","type":"update","data":[{"symbol":"LTC/BTC","bids":[{"price":0.001229,"qty":406.81128282}],"asks":[],"checksum":3507088018,"timestamp":"2024-06-01T17:53:06.706065Z"}]}
{"channel":"book","type":"update","data":[{"symbol":"LTC/BTC","bids":[{"price":0.001229,"qty":409.53322821}],"asks":[],"checksum":1893000697,"timestamp":"2024-06-01T17:53:06.708243Z"}]}
{"channel":"book","type":"update","data":[{"symbol":"LTC/BTC","bids":[{"price":0.001228,"qty":293.24362118}],"asks":[],"checksum":2218749669,"timestamp":"2024-06-01T17:53:06.869142Z"}]}
{"channel":"book","type":"update","data":[{"symbol":"LTC/BTC","bids":[{"price":0.001228,"qty":245.20378752}],"asks":[],"checksum":1893000697,"timestamp":"2024-06-01T17:53:07.129655Z"}]}
{"channel":"book","type":"update","data":[{"symbol":"LTC/BTC","bids":[{"price":0.001228,"qty":293.24362682}],"asks":[],"checksum":3228823848,"timestamp":"2024-06-01T17:53:07.410921Z"}]}
{"channel":"book","type":"update","data":[{"symbol":"LTC/BTC","bids":[{"price":0.001228,"qty":245.20378752}],"asks":[],"checksum":1893000697,"timestamp":"2024-06-01T17:53:07.679296Z"}]}
{"channel":"book","type":"update","data":[{"symbol":"LTC/BTC","bids":[{"price":0.001228,"qty":293.24362345}],"asks":[],"checksum":2756132052,"timestamp":"2024-06-01T17:53:07.958657Z"}]}
{"channel":"book","type":"update","data":[{"symbol":"LTC/BTC","bids":[{"price":0.001227,"qty":346.86080002}],"asks":[],"checksum":2481478802,"timestamp":"2024-06-01T17:53:08.196585Z"}]}
{"channel":"book","type":"update","data":[{"symbol":"LTC/BTC","bids":[{"price":0.001228,"qty":245.20378752}],"asks":[],"checksum":1199277503,"timestamp":"2024-06-01T17:53:08.245621Z"}]}
{"channel":"book","type":"update","data":[{"symbol":"LTC/BTC","bids":[{"price":0.001227,"qty":369.46464254}],"asks":[],"checksum":1893000697,"timestamp":"2024-06-01T17:53:08.296819Z"}]}
{"channel":"book","type":"update","data":[{"symbol":"LTC/BTC","bids":[{"price":0.001228,"qty":293.24362119}],"asks":[],"checksum":720346313,"timestamp":"2024-06-01T17:53:08.499698Z"}]}
{"channel":"book","type":"update","data":[{"symbol":"LTC/BTC","bids":[{"price":0.001228,"qty":245.20378752}],"asks":[],"checksum":1893000697,"timestamp":"2024-06-01T17:53:08.753100Z"}]}
{"channel":"book","type":"update","data":[{"symbol":"LTC/BTC","bids":[],"asks":[{"price":0.001232,"qty":90.04728883}],"checksum":3742675594,"timestamp":"2024-06-01T17:53:08.880757Z"}]}
{"channel":"book","type":"update","data":[{"symbol":"LTC/BTC","bids":[],"asks":[{"price":0.001232,"qty":93.07679945}],"checksum":1893000697,"timestamp":"2024-06-01T17:53:08.983154Z"}]}
{"channel":"book","type":"update","data":[{"symbol":"LTC/BTC","bids":[{"price":0.001229,"qty":406.81128282}],"asks":[],"checksum":3507088018,"timestamp":"2024-06-01T17:53:08.989779Z"}]}
{"channel":"book","type":"update","data":[{"symbol":"LTC/BTC","bids":[{"price":0.001229,"qty":409.36779243}],"asks":[],"checksum":4163761797,"timestamp":"2024-06-01T17:53:08.992915Z"}]}
{"channel":"book","type":"update","data":[{"symbol":"LTC/BTC","bids":[{"price":0.001228,"qty":293.24362110}],"asks":[],"checksum":2048327486,"timestamp":"2024-06-01T17:53:09.012261Z"}]}
{"channel":"book","type":"update","data":[{"symbol":"LTC/BTC","bids":[{"price":0.001228,"qty":245.20378752}],"asks":[],"checksum":4163761797,"timestamp":"2024-06-01T17:53:09.304951Z"}]}
{"channel":"book","type":"update","data":[{"symbol":"LTC/BTC","bids":[{"price":0.001228,"qty":293.24362133}],"asks":[],"checksum":922457897,"timestamp":"2024-06-01T17:53:09.558140Z"}]}
{"channel":"book","type":"update","data":[{"symbol":"LTC/BTC","bids":[{"price":0.001229,"qty":406.33828181}],"asks":[],"checksum":1080743344,"timestamp":"2024-06-01T17:53:09.642476Z"}]}
{"channel":"book","type":"update","data":[{"symbol":"LTC/BTC","bids":[{"price":0.001229,"qty":409.36779243}],"asks":[],"checksum":922457897,"timestamp":"2024-06-01T17:53:09.744824Z"}]}
{"channel":"book","type":"update","data":[{"symbol":"LTC/BTC","bids":[{"price":0.001228,"qty":245.20378752}],"asks":[],"checksum":4163761797,"timestamp":"2024-06-01T17:53:09.818177Z"}]}
{"channel":"book","type":"update","data":[{"symbol":"LTC/BTC","bids":[{"price":0.001228,"qty":293.24362132}],"asks":[],"checksum":2552980741,"timestamp":"2024-06-01T17:53:10.111064Z"}]}
{"channel":"book","type":"update","data":[{"symbol":"LTC/BTC","bids":[{"price":0.001224,"qty":157.33733805}],"asks":[],"checksum":3028636505,"timestamp":"2024-06-01T17:53:10.165191Z"}]}
{"channel":"book","type":"update","data":[{"symbol":"LTC/BTC","bids":[{"price":0.001223,"qty":80.54735276}],"asks":[],"checksum":2010752082,"timestamp":"2024-06-01T17:53:10.165262Z"}]}
{"channel":"book","type":"update","data":[{"symbol":"LTC/BTC","bids":[{"price":0.001223,"qty":78.39600000}],"asks":[],"checksum":782408180,"timestamp":"2024-06-01T17:53:10.165508Z"}]}
{"channel":"book","type":"update","data":[{"symbol":"LTC/BTC","bids":[{"price":0.001224,"qty":169.16977823}],"asks":[],"checksum":741647837,"timestamp":"2024-06-01T17:53:10.165662Z"}]}
{"channel":"book","type":"update","data":[{"symbol":"LTC/BTC","bids":[{"price":0.001222,"qty":47.05338874}],"asks":[],"checksum":904127288,"timestamp":"2024-06-01T17:53:10.165729Z"}]}
{"channel":"book","type":"update","data":[{"symbol":"LTC/BTC","bids":[{"price":0.001223,"qty":99.90952760}],"asks":[],"checksum":794967533,"timestamp":"2024-06-01T17:53:10.165749Z"}]}
{"channel":"book","type":"update","data":[{"symbol":"LTC/BTC","bids":[{"price":0.001229,"qty":229.04140965}],"asks":[],"checksum":3745356535,"timestamp":"2024-06-01T17:53:10.262959Z"}]}
{"channel":"book","type":"update","data":[{"symbol":"LTC/BTC","bids":[{"price":0.001228,"qty":245.20378752}],"asks":[],"checksum":3208317303,"timestamp":"2024-06-01T17:53:10.411431Z"}]}
{"channel":"book","type":"update","data":[{"symbol":"LTC/BTC","bids":[{"price":0.001228,"qty":293.24362132}],"asks":[],"checksum":3745356535,"timestamp":"2024-06-01T17:53:10.698435Z"}]}
{"channel":"book","type":"update","data":[{"symbol":"LTC/BTC","bids":[{"price":0.001228,"qty":245.20378752}],"asks":[],"checksum":3208317303,"timestamp":"2024-06-01T17:53:10.978098Z"}]}
{"channel":"book","type":"update","data":[{"symbol":"LTC/BTC","bids":[{"price":0.001229,"qty":226.48490004}],"asks":[],"checksum":2015208081,"timestamp":"2024-06-01T17:53:11.145558Z"}]}
{"channel":"book","type":"update","data":[{"symbol":"LTC/BTC","bids":[{"price":0.001229,"qty":230.69576074}],"asks":[],"checksum":3446248277,"timestamp":"2024-06-01T17:53:11.146653Z"}]}
{"channel":"book","type":"update","data":[{"symbol":"LTC/BTC","bids":[],"asks":[{"price":0.001233,"qty":145.58447765}],"checksum":1544074654,"timestamp":"2024-06-01T17:53:11.205641Z"}]}
{"channel":"book","type":"update","data":[{"symbol":"LTC/BTC","bids":[{"price":0.001228,"qty":293.24362132}],"asks":[],"checksum":1007560222,"timestamp":"2024-06-01T17:53:11.263256Z"}]}
{"channel":"book","type":"update","data":[{"symbol":"LTC/BTC","bids":[],"asks":[{"price":0.001233,"qty":168.18832017}],"checksum":2909733077,"timestamp":"2024-06-01T17:53:11.308144Z"}]}
{"channel":"book","type":"update","data":[{"symbol":"LTC/BTC","bids":[{"price":0.001228,"qty":245.20378752}],"asks":[],"checksum":3446248277,"timestamp":"2024-06-01T17:53:11.556276Z"}]}
{"channel":"book","type":"update","data":[{"symbol":"LTC/BTC","bids":[{"price":0.001228,"qty":293.24362132}],"asks":[],"checksum":2909733077,"timestamp":"2024-06-01T17:53:11.844231Z"}]}
{"channel":"book","type":"update","data":[{"symbol":"LTC/BTC","bids":[{"price":0.001228,"qty":245.20378752}],"asks":[],"checksum":3446248277,"timestamp":"2024-06-01T17:53:12.125286Z"}]}
{"channel":"book","type":"update","data":[{"symbol":"LTC/BTC","bids":[{"price":0.001228,"qty":293.24362326}],"asks":[],"checksum":2630734379,"timestamp":"2024-06-01T17:53:12.416469Z"}]}
{"channel":"book","type":"update","data":[{"symbol":"LTC/BTC","bids":[{"price":0.001228,"qty":245.20378752}],"asks":[],"checksum":3446248277,"timestamp":"2024-06-01T17:53:12.669597Z"}]}
{"channel":"book","type":"update","data":[{"symbol":"LTC/BTC","bids":[{"price":0.001228,"qty":293.24362084}],"asks":[],"checksum":2310165515,"timestamp":"2024-06-01T17:53:12.951134Z"}]}
{"channel":"book","type":"update","data":[{"symbol":"LTC/BTC","bids":[{"price":0.001228,"qty":245.20378752}],"asks":[],"checksum":3446248277,"timestamp":"2024-06-01T17:53:13.219362Z"}]}
{"channel":"book","type":"update","data":[{"symbol":"LTC/BTC","bids":[{"price":0.001228,"qty":293.24361747}],"asks":[],"checksum":2251342362,"timestamp":"2024-06-01T17:53:13.517596Z"}]}
{"channel":"book","type":"update","data":[{"symbol":"LTC/BTC","bids":[{"price":0.001228,"qty":245.20378752}],"asks":[],"checksum":3446248277,"timestamp":"2024-06-01T17:53:13.810468Z"}]}
{"channel":"book","type":"update","data":[{"symbol":"LTC/BTC","bids":[{"price":0.001227,"qty":352.32599549}],"asks":[],"checksum":3088082522,"timestamp":"2024-06-01T17:53:14.051930Z"}]}
{"channel":"book","type":"update","data":[{"symbol":"LTC/BTC","bids":[{"price":0.001228,"qty":293.24361711}],"asks":[],"checksum":1491426090,"timestamp":"2024-06-01T17:53:14.082108Z"}]}
{"channel":"book","type":"update","data":[{"symbol":"LTC/BTC","bids":[{"price":0.001227,"qty":369.46464254}],"asks":[],"checksum":765242917,"timestamp":"2024-06-01T17:53:14.159802Z"}]}
