{"channel":"book","type":"snapshot","data":[{"symbol":"LTC/USDT","bids":[{"price":83.24753,"qty":23.85306512},{"price":83.24752,"qty":18.03006121},{"price":83.24360,"qty":9.01503060},{"price":83.22836,"qty":16.22633762},{"price":83.22040,"qty":1.99000000},{"price":83.21194,"qty":1.36137350},{"price":83.21187,"qty":11.51486853},{"price":83.21170,"qty":2.61000000},{"price":83.21068,"qty":10.00000000},{"price":83.21037,"qty":7.87361491}],"asks":[{"price":83.27330,"qty":1.99000000},{"price":83.27429,"qty":1.80000000},{"price":83.27667,"qty":10.00000000},{"price":83.28000,"qty":6.06620256},{"price":83.29163,"qty":13.36451721},{"price":83.29632,"qty":8.29100000},{"price":83.30000,"qty":10.00000000},{"price":83.30957,"qty":3.02415302},{"price":83.31121,"qty":3.12000000},{"price":83.32787,"qty":36.00236031}],"checksum":1803916617}]}
{"channel":"book","type":"update","data":[{"symbol":"LTC/USDT","bids":[],"asks":[{"price":83.27330,"qty":0.00000000},{"price":83.34094,"qty":2.34609048}],"checksum":816302979,"timestamp":"2024-06-01T17:52:07.087508Z"}]}
{"channel":"book","type":"update","data":[{"symbol":"LTC/USDT","bids":[],"asks":[{"price":83.27409,"qty":1.99000000}],"checksum":2343685450,"timestamp":"2024-06-01T17:52:07.087649Z"}]}
{"channel":"book","type":"update","data":[{"symbol":"LTC/USDT","bids":[{"price":83.24752,"qty":0.00000000},{"price":83.21003,"qty":3.02951062}],"asks":[],"checksum":2597933861,"timestamp":"2024-06-01T17:52:07.572420Z"}]}
{"channel":"book","type":"update","data":[{"symbol":"LTC/USDT","bids":[{"price":83.24753,"qty":0.00000000},{"price":83.21000,"qty":38.46256908}],"asks":[],"checksum":3364125757,"timestamp":"2024-06-01T17:52:07.577440Z"}]}
{"channel":"book","type":"update","data":[{"symbol":"LTC/USDT","bids":[{"price":83.21195,"qty":3.60582137}],"asks":[],"checksum":2191490888,"timestamp":"2024-06-01T17:52:07.577787Z"}]}
{"channel":"book","type":"update","data":[{"symbol":"LTC/USDT","bids":[],"asks":[{"price":83.27429,"qty":0.00000000},{"price":83.34094,"qty":2.34609048}],"checksum":2197568297,"timestamp":"2024-06-01T17:52:07.580392Z"}]}
{"channel":"book","type":"update","data":[{"symbol":"LTC/USDT","bids":[],"asks":[{"price":83.27230,"qty":1.80000000}],"checksum":2436360307,"timestamp":"2024-06-01T17:52:07.580420Z"}]}
{"channel":"book","type":"update","data":[{"symbol":"LTC/USDT","bids":[],"asks":[{"price":83.27647,"qty":1.99000000}],"checksum":1787990162,"timestamp":"2024-06-01T17:52:07.586374Z"}]}
{"channel":"book","type":"update","data":[{"symbol":"LTC/USDT","bids":[],"asks":[{"price":83.27409,"qty":0.00000000},{"price":83.32787,"qty":36.00236031}],"checksum":1249807090,"timestamp":"2024-06-01T17:52:07.586396Z"}]}
{"channel":"book","type":"update","data":[{"symbol":"LTC/USDT","bids":[{"price":83.24747,"qty":18.03006492}],"asks":[],"checksum":3224022980,"timestamp":"2024-06-01T17:52:07.612719Z"}]}
{"channel":"book","type":"update","data":[{"symbol":"LTC/USDT","bids":[{"price":83.24748,"qty":23.85306512}],"asks":[],"checksum":1241741252,"timestamp":"2024-06-01T17:52:07.616769Z"}]}
{"channel":"book","type":"update","data":[{"symbol":"LTC/USDT","bids":[],"asks":[{"price":83.27210,"qty":1.99000000}],"checksum":633120141,"timestamp":"2024-06-01T17:52:07.617479Z"}]}
{"channel":"book","type":"update","data":[{"symbol":"LTC/USDT","bids":[],"asks":[{"price":83.27635,"qty":10.00000000}],"checksum":4258428055,"timestamp":"2024-06-01T17:52:07.617579Z"}]}
{"channel":"book","type":"update","data":[{"symbol":"LTC/USDT","bids":[{"price":83.24360,"qty":0.00000000},{"price":83.21037,"qty":7.87361491}],"asks":[],"checksum":2132186562,"timestamp":"2024-06-01T17:52:07.617836Z"}]}
{"channel":"book","type":"update","data":[{"symbol":"LTC/USDT","bids":[{"price":83.21195,"qty":0.00000000},{"price":83.21003,"qty":3.02951062}],"asks":[],"checksum":699037624,"timestamp":"2024-06-01T17:52:07.620845Z"}]}
{"channel":"book","type":"update","data":[{"symbol":"LTC/USDT","bids":[{"price":83.24355,"qty":9.01503246}],"asks":[],"checksum":2579195940,"timestamp":"2024-06-01T17:52:07.658198Z"}]}
{"channel":"book","type":"update","data":[{"symbol":"LTC/USDT","bids":[],"asks":[{"price":83.27635,"qty":0.00000000},{"price":83.31121,"qty":3.12000000}],"checksum":1104525630,"timestamp":"2024-06-01T17:52:07.662469Z"}]}
{"channel":"book","type":"update","data":[{"symbol":"LTC/USDT","bids":[],"asks":[{"price":83.27647,"qty":0.00000000},{"price":83.32787,"qty":36.00236031}],"checksum":4050108462,"timestamp":"2024-06-01T17:52:07.662529Z"}]}
{"channel":"book","type":"update","data":[{"symbol":"LTC/USDT","bids":[{"price":83.24747,"qty":0.00000000},{"price":83.21003,"qty":3.02951062}],"asks":[],"checksum":2921907881,"timestamp":"2024-06-01T17:52:08.172543Z"}]}
{"channel":"book","type":"update","data":[{"symbol":"LTC/USDT","bids":[{"price":83.24748,"qty":0.00000000},{"price":83.21000,"qty":38.46256908}],"asks":[],"checksum":4167239479,"timestamp":"2024-06-01T17:52:08.176734Z"}]}
{"channel":"book","type":"update","data":[{"symbol":"LTC/USDT","bids":[{"price":83.21195,"qty":3.60589334}],"asks":[],"checksum":1702523814,"timestamp":"2024-06-01T17:52:08.177602Z"}]}
{"channel":"book","type":"update","data":[{"symbol":"LTC/USDT","bids":[{"price":83.24792,"qty":18.02999273}],"asks":[],"checksum":3103410687,"timestamp":"2024-06-01T17:52:08.212729Z"}]}
{"channel":"book","type":"update","data":[{"symbol":"LTC/USDT","bids":[{"price":83.24793,"qty":23.85306512}],"asks":[],"checksum":2594455130,"timestamp":"2024-06-01T17:52:08.217083Z"}]}
{"channel":"book","type":"update","data":[{"symbol":"LTC/USDT","bids":[{"price":83.21195,"qty":0.00000000},{"price":83.21037,"qty":7.87361491}],"asks":[],"checksum":2000971599,"timestamp":"2024-06-01T17:52:08.222792Z"}]}
{"channel":"book","type":"update","data":[{"symbol":"LTC/USDT","bids":[{"price":83.24355,"qty":0.00000000},{"price":83.21003,"qty":3.02951062}],"asks":[],"checksum":3344267475,"timestamp":"2024-06-01T17:52:08.297880Z"}]}
{"channel":"book","type":"update","data":[{"symbol":"LTC/USDT","bids":[{"price":83.24349,"qty":9.01503246}],"asks":[],"checksum":2422334493,"timestamp":"2024-06-01T17:52:08.338120Z"}]}
{"channel":"book","type":"update","data":[{"symbol":"LTC/USDT","bids":[{"price":83.24792,"qty":0.00000000},{"price":83.21003,"qty":3.02951062}],"asks":[],"checksum":1688642881,"timestamp":"2024-06-01T17:52:08.855077Z"}]}
{"channel":"book","type":"update","data":[{"symbol":"LTC/USDT","bids":[{"price":83.24793,"qty":0.00000000},{"price":83.21000,"qty":38.46256908}],"asks":[],"checksum":4045128909,"timestamp":"2024-06-01T17:52:08.859026Z"}]}
{"channel":"book","type":"update","data":[{"symbol":"LTC/USDT","bids":[{"price":83.21195,"qty":3.60589729}],"asks":[],"checksum":3626742612,"timestamp":"2024-06-01T17:52:08.860139Z"}]}
{"channel":"book","type":"update","data":[{"symbol":"LTC/USDT","bids":[{"price":83.24708,"qty":18.03016037}],"asks":[],"checksum":1905443548,"timestamp":"2024-06-01T17:52:08.895390Z"}]}
{"channel":"book","type":"update","data":[{"symbol":"LTC/USDT","bids":[{"price":83.24349,"qty":0.00000000},{"price":83.21003,"qty":3.02951062}],"asks":[],"checksum":553988181,"timestamp":"2024-06-01T17:52:08.895891Z"}]}
{"channel":"book","type":"update","data":[{"symbol":"LTC/USDT","bids":[{"price":83.21194,"qty":0.00000000},{"price":83.21000,"qty":38.46256908}],"asks":[],"checksum":1721052851,"timestamp":"2024-06-01T17:52:08.927090Z"}]}
{"channel":"book","type":"update","data":[{"symbol":"LTC/USDT","bids":[{"price":83.21188,"qty":0.99446242}],"asks":[],"checksum":3419614434,"timestamp":"2024-06-01T17:52:08.930369Z"}]}
{"channel":"book","type":"update","data":[{"symbol":"LTC/USDT","bids":[{"price":83.24315,"qty":9.01508018}],"asks":[],"checksum":3817272156,"timestamp":"2024-06-01T17:52:08.936440Z"}]}
{"channel":"book","type":"update","data":[{"symbol":"LTC/USDT","bids":[{"price":83.24709,"qty":23.85306512}],"asks":[],"checksum":1553039919,"timestamp":"2024-06-01T17:52:09.019570Z"}]}
{"channel":"book","type":"update","data":[{"symbol":"LTC/USDT","bids":[{"price":83.21195,"qty":0.00000000},{"price":83.21037,"qty":7.87361491}],"asks":[],"checksum":837953192,"timestamp":"2024-06-01T17:52:09.024429Z"}]}
{"channel":"book","type":"update","data":[{"symbol":"LTC/USDT","bids":[{"price":83.24708,"qty":0.00000000},{"price":83.21003,"qty":3.02951062}],"asks":[],"checksum":2555764350,"timestamp":"2024-06-01T17:52:09.534712Z"}]}
{"channel":"book","type":"update","data":[{"symbol":"LTC/USDT","bids":[{"price":83.24709,"qty":0.00000000},{"price":83.21000,"qty":38.46256908}],"asks":[],"checksum":980952133,"timestamp":"2024-06-01T17:52:09.538693Z"}]}
{"channel":"book","type":"update","data":[{"symbol":"LTC/USDT","bids":[{"price":83.21189,"qty":3.60589792}],"asks":[],"checksum":1100639346,"timestamp":"2024-06-01T17:52:09.539512Z"}]}
{"channel":"book","type":"update","data":[{"symbol":"LTC/USDT","bids":[{"price":83.24740,"qty":18.03007715}],"asks":[],"checksum":620808152,"timestamp":"2024-06-01T17:52:09.575039Z"}]}
{"channel":"book","type":"update","data":[{"symbol":"LTC/USDT","bids":[{"price":83.24315,"qty":0.00000000},{"price":83.21003,"qty":3.02951062}],"asks":[],"checksum":1595379691,"timestamp":"2024-06-01T17:52:09.576373Z"}]}
{"channel":"book","type":"update","data":[{"symbol":"LTC/USDT","bids":[{"price":83.24741,"qty":23.85306512}],"asks":[],"checksum":2620908207,"timestamp":"2024-06-01T17:52:09.578831Z"}]}
{"channel":"book","type":"update","data":[{"symbol":"LTC/USDT","bids":[{"price":83.21189,"qty":0.00000000},{"price":83.21003,"qty":3.02951062}],"asks":[],"checksum":738294687,"timestamp":"2024-06-01T17:52:09.582914Z"}]}
{"channel":"book","type":"update","data":[{"symbol":"LTC/USDT","bids":[{"price":83.24348,"qty":9.01503857}],"asks":[],"checksum":950248341,"timestamp":"2024-06-01T17:52:09.616720Z"}]}
{"channel":"book","type":"update","data":[{"symbol":"LTC/USDT","bids":[{"price":83.24740,"qty":0.00000000},{"price":83.21003,"qty":3.02951062}],"asks":[],"checksum":626796882,"timestamp":"2024-06-01T17:52:10.205206Z"}]}
{"channel":"book","type":"update","data":[{"symbol":"LTC/USDT","bids":[{"price":83.24741,"qty":0.00000000},{"price":83.21000,"qty":38.46256908}],"asks":[],"checksum":2893527038,"timestamp":"2024-06-01T17:52:10.209868Z"}]}
{"channel":"book","type":"update","data":[{"symbol":"LTC/USDT","bids":[{"price":83.21189,"qty":3.60590969}],"asks":[],"checksum":269939467,"timestamp":"2024-06-01T17:52:10.210710Z"}]}
{"channel":"book","type":"update","data":[{"symbol":"LTC/USDT","bids":[{"price":83.24758,"qty":18.03000152}],"asks":[],"checksum":1370811541,"timestamp":"2024-06-01T17:52:10.245194Z"}]}
{"channel":"book","type":"update","data":[{"symbol":"LTC/USDT","bids":[{"price":83.24759,"qty":23.85306512}],"asks":[],"checksum":3356119,"timestamp":"2024-06-01T17:52:10.249666Z"}]}
{"channel":"book","type":"update","data":[{"symbol":"LTC/USDT","bids":[{"price":83.21189,"qty":0.00000000},{"price":83.21037,"qty":7.87361491}],"asks":[],"checksum":4213354362,"timestamp":"2024-06-01T17:52:10.254304Z"}]}
{"channel":"book","type":"update","data":[{"symbol":"LTC/USDT","bids":[{"price":83.24348,"qty":0.00000000},{"price":83.21003,"qty":3.02951062}],"asks":[],"checksum":4018173808,"timestamp":"2024-06-01T17:52:10.271858Z"}]}
{"channel":"book","type":"update","data":[{"symbol":"LTC/USDT","bids":[{"price":83.24365,"qty":9.01500076}],"asks":[],"checksum":698663158,"timestamp":"2024-06-01T17:52:10.312063Z"}]}
{"channel":"book","type":"update","data":[{"symbol":"LTC/USDT","bids":[{"price":83.24758,"qty":0.00000000},{"price":83.21003,"qty":3.02951062}],"asks":[],"checksum":2843026488,"timestamp":"2024-06-01T17:52:10.813883Z"}]}
{"channel":"book","type":"update","data":[{"symbol":"LTC/USDT","bids":[{"price":83.24759,"qty":0.00000000},{"price":83.21000,"qty":38.46256908}],"asks":[],"checksum":1861014562,"timestamp":"2024-06-01T17:52:10.818905Z"}]}
{"channel":"book","type":"update","data":[{"symbol":"LTC/USDT","bids":[{"price":83.21189,"qty":3.60591189}],"asks":[],"checksum":1551686073,"timestamp":"2024-06-01T17:52:10.819055Z"}]}
{"channel":"book","type":"update","data":[{"symbol":"LTC/USDT","bids":[{"price":83.24710,"qty":18.03013563}],"asks":[],"checksum":2979926063,"timestamp":"2024-06-01T17:52:10.854262Z"}]}
{"channel":"book","type":"update","data":[{"symbol":"LTC/USDT","bids":[{"price":83.24365,"qty":0.00000000},{"price":83.21003,"qty":3.02951062}],"asks":[],"checksum":3929159742,"timestamp":"2024-06-01T17:52:10.870612Z"}]}
{"channel":"book","type":"update","data":[{"symbol":"LTC/USDT","bids":[{"price":83.24318,"qty":9.01506746}],"asks":[],"checksum":1592705995,"timestamp":"2024-06-01T17:52:10.910928Z"}]}
{"channel":"book","type":"update","data":[{"symbol":"LTC/USDT","bids":[{"price":83.24710,"qty":0.00000000},{"price":83.21003,"qty":3.02951062}],"asks":[],"checksum":1595150980,"timestamp":"2024-06-01T17:52:11.495636Z"}]}
{"channel":"book","type":"update","data":[{"symbol":"LTC/USDT","bids":[],"asks":[{"price":83.27230,"qty":0.00000000},{"price":83.34094,"qty":2.34609048}],"checksum":1202595801,"timestamp":"2024-06-01T17:52:11.498285Z"}]}
{"channel":"book","type":"update","data":[{"symbol":"LTC/USDT","bids":[],"asks":[{"price":83.27197,"qty":1.80000000}],"checksum":1391580024,"timestamp":"2024-06-01T17:52:11.498484Z"}]}
{"channel":"book","type":"update","data":[{"symbol":"LTC/USDT","bids":[{"price":83.24319,"qty":23.85306512}],"asks":[],"checksum":837150344,"timestamp":"2024-06-01T17:52:11.499716Z"}]}
{"channel":"book","type":"update","data":[{"symbol":"LTC/USDT","bids":[{"price":83.24753,"qty":18.03001463}],"asks":[],"checksum":2887524428,"timestamp":"2024-06-01T17:52:11.536014Z"}]}
{"channel":"book","type":"update","data":[{"symbol":"LTC/USDT","bids":[{"price":83.21189,"qty":0.00000000},{"price":83.21037,"qty":7.87361491}],"asks":[],"checksum":894003483,"timestamp":"2024-06-01T17:52:11.540027Z"}]}
{"channel":"book","type":"update","data":[{"symbol":"LTC/USDT","bids":[],"asks":[{"price":83.27177,"qty":1.99000000}],"checksum":240491909,"timestamp":"2024-06-01T17:52:11.541552Z"}]}
{"channel":"book","type":"update","data":[{"symbol":"LTC/USDT","bids":[{"price":83.24318,"qty":0.00000000},{"price":83.21003,"qty":3.02951062}],"asks":[],"checksum":3323149988,"timestamp":"2024-06-01T17:52:11.558459Z"}]}
{"channel":"book","type":"update","data":[{"symbol":"LTC/USDT","bids":[],"asks":[{"price":83.27210,"qty":0.00000000},{"price":83.32787,"qty":36.00236031}],"checksum":398132703,"timestamp":"2024-06-01T17:52:11.587746Z"}]}
{"channel":"book","type":"update","data":[{"symbol":"LTC/USDT","bids":[{"price":83.24365,"qty":9.01500737}],"asks":[],"checksum":2137916024,"timestamp":"2024-06-01T17:52:11.598811Z"}]}
{"channel":"book","type":"update","data":[{"symbol":"LTC/USDT","bids":[{"price":83.21188,"qty":0.00000000},{"price":83.21003,"qty":3.02951062}],"asks":[],"checksum":2597708028,"timestamp":"2024-06-01T17:52:11.637266Z"}]}
{"channel":"book","type":"update","data":[{"symbol":"LTC/USDT","bids":[{"price":83.21190,"qty":1.08063579}],"asks":[],"checksum":3691734545,"timestamp":"2024-06-01T17:52:11.638898Z"}]}
{"channel":"book","type":"update","data":[{"symbol":"LTC/USDT","bids":[{"price":83.24754,"qty":23.85306512}],"asks":[],"checksum":1334940665,"timestamp":"2024-06-01T17:52:12.008744Z"}]}
{"channel":"book","type":"update","data":[{"symbol":"LTC/USDT","bids":[{"price":83.24753,"qty":0.00000000},{"price":83.21037,"qty":7.87361491}],"asks":[],"checksum":308805063,"timestamp":"2024-06-01T17:52:12.176889Z"}]}
{"channel":"book","type":"update","data":[{"symbol":"LTC/USDT","bids":[{"price":83.24319,"qty":0.00000000},{"price":83.21003,"qty":3.02951062}],"asks":[],"checksum":2615834212,"timestamp":"2024-06-01T17:52:12.180587Z"}]}
{"channel":"book","type":"update","data":[{"symbol":"LTC/USDT","bids":[{"price":83.24704,"qty":18.03005098}],"asks":[],"checksum":1982155551,"timestamp":"2024-06-01T17:52:12.216769Z"}]}
{"channel":"book","type":"update","data":[{"symbol":"LTC/USDT","bids":[{"price":83.24365,"qty":0.00000000},{"price":83.21003,"qty":3.02951062}],"asks":[],"checksum":3794150741,"timestamp":"2024-06-01T17:52:12.239174Z"}]}
{"channel":"book","type":"update","data":[{"symbol":"LTC/USDT","bids":[{"price":83.24312,"qty":9.01506158}],"asks":[],"checksum":2082163963,"timestamp":"2024-06-01T17:52:12.279209Z"}]}
{"channel":"book","type":"update","data":[{"symbol":"LTC/USDT","bids":[{"price":83.24754,"qty":0.00000000},{"price":83.21003,"qty":3.02951062}],"asks":[],"checksum":43777490,"timestamp":"2024-06-01T17:52:12.508861Z"}]}
{"channel":"book","type":"update","data":[{"symbol":"LTC/USDT","bids":[{"price":83.21191,"qty":3.60591175}],"asks":[],"checksum":504206196,"timestamp":"2024-06-01T17:52:12.549476Z"}]}
{"channel":"book","type":"update","data":[{"symbol":"LTC/USDT","bids":[{"price":83.24705,"qty":23.85306512}],"asks":[],"checksum":4201843325,"timestamp":"2024-06-01T17:52:12.553386Z"}]}
{"channel":"book","type":"update","data":[{"symbol":"LTC/USDT","bids":[{"price":83.21191,"qty":0.00000000},{"price":83.21037,"qty":7.87361491}],"asks":[],"checksum":2479711889,"timestamp":"2024-06-01T17:52:12.558092Z"}]}
{"channel":"book","type":"update","data":[{"symbol":"LTC/USDT","bids":[{"price":83.24704,"qty":0.00000000},{"price":83.21003,"qty":3.02951062}],"asks":[],"checksum":3897451227,"timestamp":"2024-06-01T17:52:13.418662Z"}]}
{"channel":"book","type":"update","data":[{"symbol":"LTC/USDT","bids":[{"price":83.24705,"qty":0.00000000},{"price":83.21000,"qty":38.46256908}],"asks":[],"checksum":1317692602,"timestamp":"2024-06-01T17:52:13.423739Z"}]}
{"channel":"book","type":"update","data":[{"symbol":"LTC/USDT","bids":[{"price":83.21191,"qty":3.60590865}],"asks":[],"checksum":534844096,"timestamp":"2024-06-01T17:52:13.425148Z"}]}
{"channel":"book","type":"update","data":[{"symbol":"LTC/USDT","bids":[{"price":83.24705,"qty":18.03012278}],"asks":[],"checksum":895788446,"timestamp":"2024-06-01T17:52:13.459475Z"}]}
{"channel":"book","type":"update","data":[{"symbol":"LTC/USDT","bids":[{"price":83.24706,"qty":23.85306512}],"asks":[],"checksum":282378480,"timestamp":"2024-06-01T17:52:13.463459Z"}]}
{"channel":"book","type":"update","data":[{"symbol":"LTC/USDT","bids":[{"price":83.21191,"qty":0.00000000},{"price":83.21037,"qty":7.87361491}],"asks":[],"checksum":2393541772,"timestamp":"2024-06-01T17:52:13.467726Z"}]}
{"channel":"book","type":"update","data":[{"symbol":"LTC/USDT","bids":[{"price":83.24312,"qty":0.00000000},{"price":83.21003,"qty":3.02951062}],"asks":[],"checksum":278390050,"timestamp":"2024-06-01T17:52:13.481156Z"}]}
{"channel":"book","type":"update","data":[{"symbol":"LTC/USDT","bids":[{"price":83.24313,"qty":9.01506139}],"asks":[],"checksum":1596173119,"timestamp":"2024-06-01T17:52:13.521217Z"}]}
{"channel":"book","type":"update","data":[{"symbol":"LTC/USDT","bids":[{"price":83.24705,"qty":0.00000000},{"price":83.21003,"qty":3.02951062}],"asks":[],"checksum":3302890375,"timestamp":"2024-06-01T17:52:14.099759Z"}]}
{"channel":"book","type":"update","data":[{"symbol":"LTC/USDT","bids":[{"price":83.24706,"qty":0.00000000},{"price":83.21000,"qty":38.46256908}],"asks":[],"checksum":1549598886,"timestamp":"2024-06-01T17:52:14.103575Z"}]}
{"channel":"book","type":"update","data":[{"symbol":"LTC/USDT","bids":[{"price":83.21191,"qty":3.60590396}],"asks":[],"checksum":3612423960,"timestamp":"2024-06-01T17:52:14.104535Z"}]}
{"channel":"book","type":"update","data":[{"symbol":"LTC/USDT","bids":[{"price":83.24764,"qty":18.03004818}],"asks":[],"checksum":4267811572,"timestamp":"2024-06-01T17:52:14.139988Z"}]}
{"channel":"book","type":"update","data":[{"symbol":"LTC/USDT","bids":[{"price":83.24765,"qty":23.85306512}],"asks":[],"checksum":1796802090,"timestamp":"2024-06-01T17:52:14.143720Z"}]}
{"channel":"book","type":"update","data":[{"symbol":"LTC/USDT","bids":[{"price":83.21191,"qty":0.00000000},{"price":83.21037,"qty":7.87361491}],"asks":[],"checksum":2096831906,"timestamp":"2024-06-01T17:52:14.148367Z"}]}
{"channel":"book","type":"update","data":[{"symbol":"LTC/USDT","bids":[{"price":83.24313,"qty":0.00000000},{"price":83.21003,"qty":3.02951062}],"asks":[],"checksum":860836799,"timestamp":"2024-06-01T17:52:14.160507Z"}]}
{"channel":"book","type":"update","data":[{"symbol":"LTC/USDT","bids":[{"price":83.24371,"qty":9.01502409}],"asks":[],"checksum":969521923,"timestamp":"2024-06-01T17:52:14.200853Z"}]}
{"channel":"book","type":"update","data":[{"symbol":"LTC/USDT","bids":[{"price":83.21190,"qty":0.00000000},{"price":83.21003,"qty":3.02951062}],"asks":[],"checksum":2132229614,"timestamp":"2024-06-01T17:52:14.452448Z"}]}
{"channel":"book","type":"update","data":[{"symbol":"LTC/USDT","bids":[{"price":83.21188,"qty":1.11226563}],"asks":[],"checksum":960189462,"timestamp":"2024-06-01T17:52:14.456112Z"}]}
{"channel":"book","type":"update","data":[{"symbol":"LTC/USDT","bids":[{"price":83.24764,"qty":0.00000000},{"price":83.21003,"qty":3.02951062}],"asks":[],"checksum":862128610,"timestamp":"2024-06-01T17:52:14.700648Z"}]}
{"channel":"book","type":"update","data":[{"symbol":"LTC/USDT","bids":[{"price":83.24765,"qty":0.00000000},{"price":83.21000,"qty":38.46256908}],"asks":[],"checksum":3992394069,"timestamp":"2024-06-01T17:52:14.704889Z"}]}
{"channel":"book","type":"update","data":[{"symbol":"LTC/USDT","bids":[{"price":83.21189,"qty":3.60589950}],"asks":[],"checksum":1224191195,"timestamp":"2024-06-01T17:52:14.705654Z"}]}
{"channel":"book","type":"update","data":[{"symbol":"LTC/USDT","bids":[{"price":83.24793,"qty":18.02995351}],"asks":[],"checksum":2338850456,"timestamp":"2024-06-01T17:52:14.741016Z"}]}
{"channel":"book","type":"update","data":[{"symbol":"LTC/USDT","bids":[{"price":83.24371,"qty":0.00000000},{"price":83.21003,"qty":3.02951062}],"asks":[],"checksum":2086762700,"timestamp":"2024-06-01T17:52:14.845571Z"}]}
{"channel":"book","type":"update","data":[{"symbol":"LTC/USDT","bids":[{"price":83.24400,"qty":9.01497675}],"asks":[],"checksum":3925112304,"timestamp":"2024-06-01T17:52:14.885638Z"}]}
{"channel":"book","type":"update","data":[{"symbol":"LTC/USDT","bids":[{"price":83.24794,"qty":23.85306512}],"asks":[],"checksum":90779431,"timestamp":"2024-06-01T17:52:15.009192Z"}]}
{"channel":"book","type":"update","data":[{"symbol":"LTC/USDT","bids":[{"price":83.21189,"qty":0.00000000},{"price":83.21037,"qty":7.87361491}],"asks":[],"checksum":102291769,"timestamp":"2024-06-01T17:52:15.014492Z"}]}
{"channel":"book","type":"update","data":[{"symbol":"LTC/USDT","bids":[],"asks":[{"price":83.27197,"qty":0.00000000},{"price":83.34094,"qty":2.34609048}],"checksum":2555300336,"timestamp":"2024-06-01T17:52:15.369773Z"}]}
{"channel":"book","type":"update","data":[{"symbol":"LTC/USDT","bids":[],"asks":[{"price":83.27618,"qty":1.80000000}],"checksum":2255079058,"timestamp":"2024-06-01T17:52:15.370142Z"}]}
{"channel":"book","type":"update","data":[{"symbol":"LTC/USDT","bids":[],"asks":[{"price":83.27606,"qty":10.00000000}],"checksum":895547924,"timestamp":"2024-06-01T17:52:15.380132Z"}]}
{"channel":"book","type":"update","data":[{"symbol":"LTC/USDT","bids":[],"asks":[{"price":83.27177,"qty":0.00000000},{"price":83.32787,"qty":36.00236031}],"checksum":127524882,"timestamp":"2024-06-01T17:52:15.380240Z"}]}
{"channel":"book","type":"update","data":[{"symbol":"LTC/USDT","bids":[],"asks":[{"price":83.27647,"qty":1.99000000}],"checksum":1021954950,"timestamp":"2024-06-01T17:52:15.380416Z"}]}
{"channel":"book","type":"update","data":[{"symbol":"LTC/USDT","bids":[],"asks":[{"price":83.27618,"qty":0.00000000},{"price":83.32787,"qty":36.00236031}],"checksum":2635315251,"timestamp":"2024-06-01T17:52:15.383390Z"}]}
{"channel":"book","type":"update","data":[{"symbol":"LTC/USDT","bids":[],"asks":[{"price":83.27552,"qty":1.80000000}],"checksum":1545390386,"timestamp":"2024-06-01T17:52:15.383693Z"}]}
{"channel":"book","type":"update","data":[{"symbol":"LTC/USDT","bids":[{"price":83.24793,"qty":0.00000000},{"price":83.21003,"qty":3.02951062}],"asks":[],"checksum":1604148518,"timestamp":"2024-06-01T17:52:15.415454Z"}]}
{"channel":"book","type":"update","data":[{"symbol":"LTC/USDT","bids":[{"price":83.24794,"qty":0.00000000},{"price":83.21000,"qty":38.46256908}],"asks":[],"checksum":2915081028,"timestamp":"2024-06-01T17:52:15.419510Z"}]}
{"channel":"book","type":"update","data":[{"symbol":"LTC/USDT","bids":[],"asks":[{"price":83.27667,"qty":0.00000000},{"price":83.32787,"qty":36.00236031}],"checksum":2147513967,"timestamp":"2024-06-01T17:52:15.436145Z"}]}
{"channel":"book","type":"update","data":[{"symbol":"LTC/USDT","bids":[],"asks":[{"price":83.27532,"qty":1.99000000}],"checksum":561642120,"timestamp":"2024-06-01T17:52:15.442332Z"}]}
{"channel":"book","type":"update","data":[{"symbol":"LTC/USDT","bids":[],"asks":[{"price":83.27552,"qty":0.00000000},{"price":83.32787,"qty":36.00236031}],"checksum":2875776160,"timestamp":"2024-06-01T17:52:15.445008Z"}]}
{"channel":"book","type":"update","data":[{"symbol":"LTC/USDT","bids":[],"asks":[{"price":83.27445,"qty":1.80000000}],"checksum":49259387,"timestamp":"2024-06-01T17:52:15.445226Z"}]}
{"channel":"book","type":"update","data":[{"symbol":"LTC/USDT","bids":[{"price":83.24401,"qty":23.85306512}],"asks":[],"checksum":2801260596,"timestamp":"2024-06-01T17:52:15.449390Z"}]}
{"channel":"book","type":"update","data":[{"symbol":"LTC/USDT","bids":[{"price":83.21187,"qty":0.00000000},{"price":83.21000,"qty":38.46256908}],"asks":[],"checksum":3080540764,"timestamp":"2024-06-01T17:52:15.450644Z"}]}
{"channel":"book","type":"update","data":[{"symbol":"LTC/USDT","bids":[{"price":83.24791,"qty":18.02994455}],"asks":[],"checksum":8966279,"timestamp":"2024-06-01T17:52:15.456052Z"}]}
{"channel":"book","type":"update","data":[{"symbol":"LTC/USDT","bids":[],"asks":[{"price":83.27532,"qty":0.00000000},{"price":83.32787,"qty":36.00236031}],"checksum":12048016,"timestamp":"2024-06-01T17:52:15.473934Z"}]}
{"channel":"book","type":"update","data":[{"symbol":"LTC/USDT","bids":[],"asks":[{"price":83.27425,"qty":1.99000000}],"checksum":1867891544,"timestamp":"2024-06-01T17:52:15.474230Z"}]}
{"channel":"book","type":"update","data":[{"symbol":"LTC/USDT","bids":[{"price":83.24400,"qty":0.00000000},{"price":83.21000,"qty":38.46256908}],"asks":[],"checksum":542589042,"timestamp":"2024-06-01T17:52:15.494287Z"}]}
{"channel":"book","type":"update","data":[{"symbol":"LTC/USDT","bids":[],"asks":[{"price":83.27647,"qty":0.00000000},{"price":83.32787,"qty":36.00236031}],"checksum":1037433041,"timestamp":"2024-06-01T17:52:15.502505Z"}]}
{"channel":"book","type":"update","data":[{"symbol":"LTC/USDT","bids":[{"price":83.24455,"qty":9.01493497}],"asks":[],"checksum":39501388,"timestamp":"2024-06-01T17:52:15.534106Z"}]}
{"channel":"book","type":"update","data":[{"symbol":"LTC/USDT","bids":[],"asks":[{"price":83.30000,"qty":0.00000000},{"price":83.34094,"qty":2.34609048}],"checksum":820045107,"timestamp":"2024-06-01T17:52:15.645317Z"}]}
{"channel":"book","type":"update","data":[{"symbol":"LTC/USDT","bids":[],"asks":[{"price":83.29988,"qty":10.00000000}],"checksum":2861584646,"timestamp":"2024-06-01T17:52:15.932547Z"}]}
{"channel":"book","type":"update","data":[{"symbol":"LTC/USDT","bids":[{"price":83.24792,"qty":23.85306512}],"asks":[],"checksum":3562730917,"timestamp":"2024-06-01T17:52:16.011203Z"}]}
{"channel":"book","type":"update","data":[{"symbol":"LTC/USDT","bids":[{"price":83.24791,"qty":0.00000000},{"price":83.21003,"qty":3.02951062}],"asks":[],"checksum":2138252475,"timestamp":"2024-06-01T17:52:16.043977Z"}]}
{"channel":"book","type":"update","data":[{"symbol":"LTC/USDT","bids":[{"price":83.24401,"qty":0.00000000},{"price":83.21000,"qty":38.46256908}],"asks":[],"checksum":2077764610,"timestamp":"2024-06-01T17:52:16.047543Z"}]}
{"channel":"book","type":"update","data":[{"symbol":"LTC/USDT","bids":[{"price":83.21189,"qty":3.60586078}],"asks":[],"checksum":1585747815,"timestamp":"2024-06-01T17:52:16.052804Z"}]}
{"channel":"book","type":"update","data":[{"symbol":"LTC/USDT","bids":[{"price":83.24905,"qty":18.02962429}],"asks":[],"checksum":543244211,"timestamp":"2024-06-01T17:52:16.084293Z"}]}
{"channel":"book","type":"update","data":[{"symbol":"LTC/USDT","bids":[{"price":83.21189,"qty":0.00000000},{"price":83.21003,"qty":3.02951062}],"asks":[],"checksum":3796881632,"timestamp":"2024-06-01T17:52:16.088601Z"}]}
{"channel":"book","type":"update","data":[{"symbol":"LTC/USDT","bids":[{"price":83.24455,"qty":0.00000000},{"price":83.21000,"qty":38.46256908}],"asks":[],"checksum":4152726745,"timestamp":"2024-06-01T17:52:16.114373Z"}]}
{"channel":"book","type":"update","data":[{"symbol":"LTC/USDT","bids":[{"price":83.24516,"qty":9.01481214}],"asks":[],"checksum":3579333510,"timestamp":"2024-06-01T17:52:16.154259Z"}]}
{"channel":"book","type":"update","data":[{"symbol":"LTC/USDT","bids":[],"asks":[{"price":83.29988,"qty":0.00000000},{"price":83.34094,"qty":2.34609048}],"checksum":1328086963,"timestamp":"2024-06-01T17:52:16.382274Z"}]}
{"channel":"book","type":"update","data":[{"symbol":"LTC/USDT","bids":[{"price":83.24905,"qty":0.00000000},{"price":83.21000,"qty":38.46256908}],"asks":[],"checksum":3288399559,"timestamp":"2024-06-01T17:52:16.574982Z"}]}
{"channel":"book","type":"update","data":[{"symbol":"LTC/USDT","bids":[{"price":83.21189,"qty":3.60586113}],"asks":[],"checksum":1683828348,"timestamp":"2024-06-01T17:52:16.579762Z"}]}
{"channel":"book","type":"update","data":[{"symbol":"LTC/USDT","bids":[{"price":83.24992,"qty":18.02949386}],"asks":[],"checksum":2618070863,"timestamp":"2024-06-01T17:52:16.615327Z"}]}
{"channel":"book","type":"update","data":[{"symbol":"LTC/USDT","bids":[{"price":83.21189,"qty":0.00000000},{"price":83.21003,"qty":3.02951062}],"asks":[],"checksum":1520246902,"timestamp":"2024-06-01T17:52:16.619543Z"}]}
{"channel":"book","type":"update","data":[{"symbol":"LTC/USDT","bids":[],"asks":[{"price":83.29996,"qty":10.00000000}],"checksum":1948698052,"timestamp":"2024-06-01T17:52:16.638292Z"}]}
{"channel":"book","type":"update","data":[{"symbol":"LTC/USDT","bids":[{"price":83.24516,"qty":0.00000000},{"price":83.21000,"qty":38.46256908}],"asks":[],"checksum":1878444779,"timestamp":"2024-06-01T17:52:16.715157Z"}]}
{"channel":"book","type":"update","data":[{"symbol":"LTC/USDT","bids":[{"price":83.24545,"qty":9.01474687}],"asks":[],"checksum":3439055705,"timestamp":"2024-06-01T17:52:16.755632Z"}]}
{"channel":"book","type":"update","data":[{"symbol":"LTC/USDT","bids":[],"asks":[{"price":83.29632,"qty":0.00000000},{"price":83.34094,"qty":2.34609048}],"checksum":4153450375,"timestamp":"2024-06-01T17:52:16.933921Z"}]}
{"channel":"book","type":"update","data":[{"symbol":"LTC/USDT","bids":[],"asks":[{"price":83.30948,"qty":8.19000000}],"checksum":3925566448,"timestamp":"2024-06-01T17:52:16.936561Z"}]}
{"channel":"book","type":"update","data":[{"symbol":"LTC/USDT","bids":[],"asks":[{"price":83.29996,"qty":0.00000000},{"price":83.34094,"qty":2.34609048}],"checksum":731309856,"timestamp":"2024-06-01T17:52:16.946223Z"}]}
{"channel":"book","type":"update","data":[{"symbol":"LTC/USDT","bids":[{"price":83.21188,"qty":0.00000000},{"price":83.21000,"qty":38.46256908}],"asks":[],"checksum":2912116555,"timestamp":"2024-06-01T17:52:17.141205Z"}]}
{"channel":"book","type":"update","data":[{"symbol":"LTC/USDT","bids":[{"price":83.21069,"qty":1.11220517}],"asks":[],"checksum":1796156899,"timestamp":"2024-06-01T17:52:17.145806Z"}]}
{"channel":"book","type":"update","data":[{"symbol":"LTC/USDT","bids":[{"price":83.21171,"qty":0.61401650}],"asks":[],"checksum":4177682932,"timestamp":"2024-06-01T17:52:17.145963Z"}]}
{"channel":"book","type":"update","data":[{"symbol":"LTC/USDT","bids":[{"price":83.24992,"qty":0.00000000},{"price":83.21003,"qty":3.02951062}],"asks":[],"checksum":1820647377,"timestamp":"2024-06-01T17:52:17.175288Z"}]}
{"channel":"book","type":"update","data":[{"symbol":"LTC/USDT","bids":[{"price":83.21172,"qty":3.60586033}],"asks":[],"checksum":3562163589,"timestamp":"2024-06-01T17:52:17.179896Z"}]}
{"channel":"book","type":"update","data":[{"symbol":"LTC/USDT","bids":[{"price":83.25016,"qty":18.02966090}],"asks":[],"checksum":1154955955,"timestamp":"2024-06-01T17:52:17.215607Z"}]}
{"channel":"book","type":"update","data":[{"symbol":"LTC/USDT","bids":[{"price":83.25017,"qty":23.85306512}],"asks":[],"checksum":948474252,"timestamp":"2024-06-01T17:52:17.219659Z"}]}
{"channel":"book","type":"update","data":[{"symbol":"LTC/USDT","bids":[{"price":83.21172,"qty":0.00000000},{"price":83.21068,"qty":10.00000000}],"asks":[],"checksum":2503409580,"timestamp":"2024-06-01T17:52:17.220151Z"}]}
{"channel":"book","type":"update","data":[{"symbol":"LTC/USDT","bids":[],"asks":[{"price":83.29992,"qty":10.00000000}],"checksum":1451539272,"timestamp":"2024-06-01T17:52:17.243250Z"}]}
{"channel":"book","type":"update","data":[{"symbol":"LTC/USDT","bids":[{"price":83.24545,"qty":0.00000000},{"price":83.21037,"qty":7.87361491}],"asks":[],"checksum":2734817809,"timestamp":"2024-06-01T17:52:17.246037Z"}]}
{"channel":"book","type":"update","data":[{"symbol":"LTC/USDT","bids":[{"price":83.24792,"qty":0.00000000},{"price":83.21003,"qty":3.02951062}],"asks":[],"checksum":328991840,"timestamp":"2024-06-01T17:52:17.249927Z"}]}
{"channel":"book","type":"update","data":[{"symbol":"LTC/USDT","bids":[{"price":83.24505,"qty":9.01483990}],"asks":[],"checksum":4113630812,"timestamp":"2024-06-01T17:52:17.285872Z"}]}
{"channel":"book","type":"update","data":[{"symbol":"LTC/USDT","bids":[{"price":83.25016,"qty":0.00000000},{"price":83.21003,"qty":3.02951062}],"asks":[],"checksum":254477781,"timestamp":"2024-06-01T17:52:17.774014Z"}]}
{"channel":"book","type":"update","data":[{"symbol":"LTC/USDT","bids":[{"price":83.25017,"qty":0.00000000},{"price":83.21000,"qty":38.46256908}],"asks":[],"checksum":3130114398,"timestamp":"2024-06-01T17:52:17.778029Z"}]}
{"channel":"book","type":"update","data":[{"symbol":"LTC/USDT","bids":[{"price":83.21172,"qty":3.60585536}],"asks":[],"checksum":3683655236,"timestamp":"2024-06-01T17:52:17.779381Z"}]}
{"channel":"book","type":"update","data":[{"symbol":"LTC/USDT","bids":[{"price":83.25080,"qty":18.03001598}],"asks":[],"checksum":3125960198,"timestamp":"2024-06-01T17:52:17.814154Z"}]}
{"channel":"book","type":"update","data":[{"symbol":"LTC/USDT","bids":[{"price":83.24505,"qty":0.00000000},{"price":83.21003,"qty":3.02951062}],"asks":[],"checksum":2493176405,"timestamp":"2024-06-01T17:52:17.843386Z"}]}
{"channel":"book","type":"update","data":[{"symbol":"LTC/USDT","bids":[],"asks":[{"price":83.29992,"qty":0.00000000},{"price":83.34094,"qty":2.34609048}],"checksum":1439643431,"timestamp":"2024-06-01T17:52:17.941537Z"}]}
{"channel":"book","type":"update","data":[{"symbol":"LTC/USDT","bids":[{"price":83.25081,"qty":23.85306512}],"asks":[],"checksum":1681580278,"timestamp":"2024-06-01T17:52:18.010265Z"}]}
{"channel":"book","type":"update","data":[{"symbol":"LTC/USDT","bids":[{"price":83.21172,"qty":0.00000000},{"price":83.21003,"qty":3.02951062}],"asks":[],"checksum":752868363,"timestamp":"2024-06-01T17:52:18.015225Z"}]}
{"channel":"book","type":"update","data":[{"symbol":"LTC/USDT","bids":[],"asks":[{"price":83.29997,"qty":10.00000000}],"checksum":3780421303,"timestamp":"2024-06-01T17:52:18.236612Z"}]}
{"channel":"book","type":"update","data":[{"symbol":"LTC/USDT","bids":[{"price":83.25080,"qty":0.00000000},{"price":83.21000,"qty":38.46256908}],"asks":[],"checksum":1121531109,"timestamp":"2024-06-01T17:52:18.304491Z"}]}
{"channel":"book","type":"update","data":[{"symbol":"LTC/USDT","bids":[{"price":83.25081,"qty":0.00000000},{"price":83.20977,"qty":8.19100000}],"asks":[],"checksum":422764098,"timestamp":"2024-06-01T17:52:18.308892Z"}]}
{"channel":"book","type":"update","data":[{"symbol":"LTC/USDT","bids":[{"price":83.21172,"qty":3.60585765}],"asks":[],"checksum":965827684,"timestamp":"2024-06-01T17:52:18.308942Z"}]}
{"channel":"book","type":"update","data":[{"symbol":"LTC/USDT","bids":[],"asks":[{"price":83.27445,"qty":0.00000000},{"price":83.34094,"qty":2.34609048}],"checksum":2754301776,"timestamp":"2024-06-01T17:52:18.311505Z"}]}
{"channel":"book","type":"update","data":[{"symbol":"LTC/USDT","bids":[],"asks":[{"price":83.27249,"qty":1.80000000}],"checksum":3223505637,"timestamp":"2024-06-01T17:52:18.311657Z"}]}
{"channel":"book","type":"update","data":[{"symbol":"LTC/USDT","bids":[{"price":83.24275,"qty":9.01509886}],"asks":[],"checksum":4119701414,"timestamp":"2024-06-01T17:52:18.444531Z"}]}
{"channel":"book","type":"update","data":[{"symbol":"LTC/USDT","bids":[{"price":83.24276,"qty":23.85306512}],"asks":[],"checksum":1083016788,"timestamp":"2024-06-01T17:52:18.448513Z"}]}
{"channel":"book","type":"update","data":[{"symbol":"LTC/USDT","bids":[],"asks":[{"price":83.27229,"qty":1.99000000}],"checksum":4130572021,"timestamp":"2024-06-01T17:52:18.450600Z"}]}
{"channel":"book","type":"update","data":[{"symbol":"LTC/USDT","bids":[],"asks":[{"price":83.27425,"qty":0.00000000},{"price":83.32787,"qty":36.00236031}],"checksum":2307416430,"timestamp":"2024-06-01T17:52:18.587505Z"}]}
{"channel":"book","type":"update","data":[{"symbol":"LTC/USDT","bids":[{"price":83.24895,"qty":18.03003403}],"asks":[],"checksum":1707724083,"timestamp":"2024-06-01T17:52:18.916235Z"}]}
{"channel":"book","type":"update","data":[{"symbol":"LTC/USDT","bids":[{"price":83.21172,"qty":0.00000000},{"price":83.21037,"qty":7.87361491}],"asks":[],"checksum":1286584003,"timestamp":"2024-06-01T17:52:18.921103Z"}]}
{"channel":"book","type":"update","data":[{"symbol":"LTC/USDT","bids":[{"price":83.24275,"qty":0.00000000},{"price":83.21003,"qty":3.02951062}],"asks":[],"checksum":1147001313,"timestamp":"2024-06-01T17:52:18.935588Z"}]}
{"channel":"book","type":"update","data":[{"symbol":"LTC/USDT","bids":[{"price":83.24387,"qty":9.01501701}],"asks":[],"checksum":3184412726,"timestamp":"2024-06-01T17:52:18.975533Z"}]}
{"channel":"book","type":"update","data":[{"symbol":"LTC/USDT","bids":[{"price":83.24896,"qty":23.85306512}],"asks":[],"checksum":3196062218,"timestamp":"2024-06-01T17:52:19.021621Z"}]}
{"channel":"book","type":"update","data":[{"symbol":"LTC/USDT","bids":[{"price":83.24276,"qty":0.00000000},{"price":83.21037,"qty":7.87361491}],"asks":[],"checksum":3578815162,"timestamp":"2024-06-01T17:52:19.025979Z"}]}
{"channel":"book","type":"update","data":[{"symbol":"LTC/USDT","bids":[{"price":83.24387,"qty":0.00000000},{"price":83.21003,"qty":3.02951062}],"asks":[],"checksum":3283379587,"timestamp":"2024-06-01T17:52:19.050366Z"}]}
{"channel":"book","type":"update","data":[{"symbol":"LTC/USDT","bids":[{"price":83.24895,"qty":0.00000000},{"price":83.21000,"qty":38.46256908}],"asks":[],"checksum":4161156622,"timestamp":"2024-06-01T17:52:19.477785Z"}]}
{"channel":"book","type":"update","data":[{"symbol":"LTC/USDT","bids":[{"price":83.24896,"qty":0.00000000},{"price":83.20977,"qty":8.19100000}],"asks":[],"checksum":696561657,"timestamp":"2024-06-01T17:52:19.481948Z"}]}
{"channel":"book","type":"update","data":[{"symbol":"LTC/USDT","bids":[{"price":83.24904,"qty":18.02999831}],"asks":[],"checksum":3775985163,"timestamp":"2024-06-01T17:52:19.518115Z"}]}
{"channel":"book","type":"update","data":[{"symbol":"LTC/USDT","bids":[{"price":83.24396,"qty":9.01499915}],"asks":[],"checksum":1719506190,"timestamp":"2024-06-01T17:52:19.579900Z"}]}
{"channel":"book","type":"update","data":[{"symbol":"LTC/USDT","bids":[{"price":83.21069,"qty":0.00000000},{"price":83.21000,"qty":38.46256908}],"asks":[],"checksum":1931850550,"timestamp":"2024-06-01T17:52:19.795311Z"}]}
{"channel":"book","type":"update","data":[{"symbol":"LTC/USDT","bids":[{"price":83.21069,"qty":1.23681956}],"asks":[],"checksum":318203761,"timestamp":"2024-06-01T17:52:19.799875Z"}]}
{"channel":"book","type":"update","data":[{"symbol":"LTC/USDT","bids":[{"price":83.21172,"qty":3.60589752}],"asks":[],"checksum":248154544,"timestamp":"2024-06-01T17:52:20.127347Z"}]}
{"channel":"book","type":"update","data":[{"symbol":"LTC/USDT","bids":[{"price":83.24905,"qty":23.85306512}],"asks":[],"checksum":952533834,"timestamp":"2024-06-01T17:52:20.131822Z"}]}
{"channel":"book","type":"update","data":[{"symbol":"LTC/USDT","bids":[],"asks":[{"price":83.28000,"qty":0.00000000},{"price":83.34094,"qty":2.34609048}],"checksum":1606261772,"timestamp":"2024-06-01T17:52:20.135104Z"}]}
{"channel":"book","type":"update","data":[{"symbol":"LTC/USDT","bids":[{"price":83.21172,"qty":0.00000000},{"price":83.21037,"qty":7.87361491}],"asks":[],"checksum":3987700774,"timestamp":"2024-06-01T17:52:20.136282Z"}]}
{"channel":"book","type":"update","data":[{"symbol":"LTC/USDT","bids":[],"asks":[{"price":83.27249,"qty":0.00000000},{"price":83.34690,"qty":13.36927600}],"checksum":3829780534,"timestamp":"2024-06-01T17:52:20.137782Z"}]}
{"channel":"book","type":"update","data":[{"symbol":"LTC/USDT","bids":[],"asks":[{"price":83.28000,"qty":5.18245256}],"checksum":635179533,"timestamp":"2024-06-01T17:52:20.138131Z"}]}
{"channel":"book","type":"update","data":[{"symbol":"LTC/USDT","bids":[],"asks":[{"price":83.27600,"qty":1.80000000}],"checksum":2272246656,"timestamp":"2024-06-01T17:52:20.140911Z"}]}
{"channel":"book","type":"update","data":[{"symbol":"LTC/USDT","bids":[{"price":83.24904,"qty":0.00000000},{"price":83.21003,"qty":3.02951062}],"asks":[],"checksum":1001714103,"timestamp":"2024-06-01T17:52:20.167704Z"}]}
{"channel":"book","type":"update","data":[{"symbol":"LTC/USDT","bids":[{"price":83.24905,"qty":0.00000000},{"price":83.21000,"qty":38.46256908}],"asks":[],"checksum":2783869088,"timestamp":"2024-06-01T17:52:20.171714Z"}]}
{"channel":"book","type":"update","data":[{"symbol":"LTC/USDT","bids":[],"asks":[{"price":83.27588,"qty":10.00000000}],"checksum":3515605349,"timestamp":"2024-06-01T17:52:20.172240Z"}]}
{"channel":"book","type":"update","data":[{"symbol":"LTC/USDT","bids":[{"price":83.21172,"qty":3.60589746}],"asks":[],"checksum":2905834203,"timestamp":"2024-06-01T17:52:20.172633Z"}]}
{"channel":"book","type":"update","data":[{"symbol":"LTC/USDT","bids":[],"asks":[{"price":83.27229,"qty":0.00000000},{"price":83.32787,"qty":36.00236031}],"checksum":814659036,"timestamp":"2024-06-01T17:52:20.172968Z"}]}
{"channel":"book","type":"update","data":[{"symbol":"LTC/USDT","bids":[],"asks":[{"price":83.27580,"qty":1.99000000}],"checksum":2702042560,"timestamp":"2024-06-01T17:52:20.172990Z"}]}
{"channel":"book","type":"update","data":[{"symbol":"LTC/USDT","bids":[],"asks":[{"price":83.27600,"qty":0.00000000},{"price":83.32787,"qty":36.00236031}],"checksum":1132012040,"timestamp":"2024-06-01T17:52:20.174808Z"}]}
{"channel":"book","type":"update","data":[{"symbol":"LTC/USDT","bids":[],"asks":[{"price":83.27320,"qty":1.80000000}],"checksum":2333400236,"timestamp":"2024-06-01T17:52:20.175027Z"}]}
{"channel":"book","type":"update","data":[{"symbol":"LTC/USDT","bids":[{"price":83.24855,"qty":18.03007050}],"asks":[],"checksum":142081294,"timestamp":"2024-06-01T17:52:20.208218Z"}]}
{"channel":"book","type":"update","data":[{"symbol":"LTC/USDT","bids":[],"asks":[{"price":83.27588,"qty":0.00000000},{"price":83.32787,"qty":36.00236031}],"checksum":2990059166,"timestamp":"2024-06-01T17:52:20.212047Z"}]}
{"channel":"book","type":"update","data":[{"symbol":"LTC/USDT","bids":[],"asks":[{"price":83.27568,"qty":10.00000000}],"checksum":664614682,"timestamp":"2024-06-01T17:52:20.212122Z"}]}
{"channel":"book","type":"update","data":[{"symbol":"LTC/USDT","bids":[],"asks":[{"price":83.27300,"qty":1.99000000}],"checksum":3685279128,"timestamp":"2024-06-01T17:52:20.213268Z"}]}
{"channel":"book","type":"update","data":[{"symbol":"LTC/USDT","bids":[{"price":83.24396,"qty":0.00000000},{"price":83.21003,"qty":3.02951062}],"asks":[],"checksum":1769402138,"timestamp":"2024-06-01T17:52:20.220166Z"}]}
{"channel":"book","type":"update","data":[{"symbol":"LTC/USDT","bids":[{"price":83.24346,"qty":9.01503525}],"asks":[],"checksum":2968239476,"timestamp":"2024-06-01T17:52:20.260481Z"}]}
{"channel":"book","type":"update","data":[{"symbol":"LTC/USDT","bids":[],"asks":[{"price":83.27568,"qty":0.00000000},{"price":83.31121,"qty":3.12000000}],"checksum":4239180499,"timestamp":"2024-06-01T17:52:20.265769Z"}]}
{"channel":"book","type":"update","data":[{"symbol":"LTC/USDT","bids":[],"asks":[{"price":83.27580,"qty":0.00000000},{"price":83.32787,"qty":36.00236031}],"checksum":2923843539,"timestamp":"2024-06-01T17:52:20.269507Z"}]}
{"channel":"book","type":"update","data":[{"symbol":"LTC/USDT","bids":[{"price":83.24855,"qty":0.00000000},{"price":83.21003,"qty":3.02951062}],"asks":[],"checksum":2039763584,"timestamp":"2024-06-01T17:52:20.702956Z"}]}
{"channel":"book","type":"update","data":[{"symbol":"LTC/USDT","bids":[{"price":83.24346,"qty":0.00000000},{"price":83.21000,"qty":38.46256908}],"asks":[],"checksum":1889899861,"timestamp":"2024-06-01T17:52:20.828914Z"}]}
{"channel":"book","type":"update","data":[{"symbol":"LTC/USDT","bids":[{"price":83.22856,"qty":1.99000000}],"asks":[],"checksum":216627575,"timestamp":"2024-06-01T17:52:20.833961Z"}]}
{"channel":"book","type":"update","data":[{"symbol":"LTC/USDT","bids":[{"price":83.22939,"qty":16.22609240}],"asks":[],"checksum":2099028869,"timestamp":"2024-06-01T17:52:20.836801Z"}]}
{"channel":"book","type":"update","data":[{"symbol":"LTC/USDT","bids":[{"price":83.22836,"qty":0.00000000},{"price":83.21003,"qty":3.02951062}],"asks":[],"checksum":1401135179,"timestamp":"2024-06-01T17:52:20.839425Z"}]}
{"channel":"book","type":"update","data":[{"symbol":"LTC/USDT","bids":[{"price":83.22959,"qty":1.99000000}],"asks":[],"checksum":595559047,"timestamp":"2024-06-01T17:52:21.087133Z"}]}
{"channel":"book","type":"update","data":[{"symbol":"LTC/USDT","bids":[{"price":83.22856,"qty":0.00000000},{"price":83.21003,"qty":3.02951062}],"asks":[],"checksum":313451389,"timestamp":"2024-06-01T17:52:21.087183Z"}]}
{"channel":"book","type":"update","data":[{"symbol":"LTC/USDT","bids":[{"price":83.22939,"qty":0.00000000},{"price":83.21000,"qty":38.46256908}],"asks":[],"checksum":1545387842,"timestamp":"2024-06-01T17:52:21.090103Z"}]}
{"channel":"book","type":"update","data":[{"symbol":"LTC/USDT","bids":[{"price":83.23042,"qty":16.22607388}],"asks":[],"checksum":3864641790,"timestamp":"2024-06-01T17:52:21.090193Z"}]}
{"channel":"book","type":"update","data":[{"symbol":"LTC/USDT","bids":[{"price":83.22940,"qty":23.85306512}],"asks":[],"checksum":3477334601,"timestamp":"2024-06-01T17:52:21.091214Z"}]}
{"channel":"book","type":"update","data":[{"symbol":"LTC/USDT","bids":[{"price":83.22040,"qty":0.00000000},{"price":83.21003,"qty":3.02951062}],"asks":[],"checksum":2523185564,"timestamp":"2024-06-01T17:52:21.091590Z"}]}
{"channel":"book","type":"update","data":[{"symbol":"LTC/USDT","bids":[],"asks":[{"price":83.27320,"qty":0.00000000},{"price":83.34094,"qty":2.34609048}],"checksum":546728313,"timestamp":"2024-06-01T17:52:21.092746Z"}]}
{"channel":"book","type":"update","data":[{"symbol":"LTC/USDT","bids":[],"asks":[{"price":83.27222,"qty":1.80000000}],"checksum":3840308978,"timestamp":"2024-06-01T17:52:21.093198Z"}]}
{"channel":"book","type":"update","data":[{"symbol":"LTC/USDT","bids":[{"price":83.24915,"qty":18.02998033}],"asks":[],"checksum":3226109154,"timestamp":"2024-06-01T17:52:21.321444Z"}]}
{"channel":"book","type":"update","data":[{"symbol":"LTC/USDT","bids":[{"price":83.24916,"qty":23.85306512}],"asks":[],"checksum":4026809292,"timestamp":"2024-06-01T17:52:21.326121Z"}]}
{"channel":"book","type":"update","data":[{"symbol":"LTC/USDT","bids":[{"price":83.21172,"qty":0.00000000},{"price":83.21037,"qty":7.87361491}],"asks":[],"checksum":1707423650,"timestamp":"2024-06-01T17:52:21.326135Z"}]}
{"channel":"book","type":"update","data":[{"symbol":"LTC/USDT","bids":[],"asks":[{"price":83.27202,"qty":1.99000000}],"checksum":1174067813,"timestamp":"2024-06-01T17:52:21.326678Z"}]}
{"channel":"book","type":"update","data":[{"symbol":"LTC/USDT","bids":[],"asks":[{"price":83.27222,"qty":0.00000000},{"price":83.32787,"qty":36.00236031}],"checksum":1110560669,"timestamp":"2024-06-01T17:52:21.328771Z"}]}
{"channel":"book","type":"update","data":[{"symbol":"LTC/USDT","bids":[{"price":83.24407,"qty":9.01499016}],"asks":[],"checksum":3370319749,"timestamp":"2024-06-01T17:52:21.374132Z"}]}
{"channel":"book","type":"update","data":[{"symbol":"LTC/USDT","bids":[{"price":83.22940,"qty":0.00000000},{"price":83.21037,"qty":7.87361491}],"asks":[],"checksum":3100432027,"timestamp":"2024-06-01T17:52:21.377625Z"}]}
{"channel":"book","type":"update","data":[{"symbol":"LTC/USDT","bids":[],"asks":[{"price":83.27202,"qty":0.00000000},{"price":83.34094,"qty":2.34609048}],"checksum":886794589,"timestamp":"2024-06-01T17:52:21.378568Z"}]}
{"channel":"book","type":"update","data":[{"symbol":"LTC/USDT","bids":[],"asks":[{"price":83.27988,"qty":10.00000000}],"checksum":54448733,"timestamp":"2024-06-01T17:52:21.711873Z"}]}
{"channel":"book","type":"update","data":[{"symbol":"LTC/USDT","bids":[],"asks":[{"price":83.27606,"qty":0.00000000},{"price":83.34094,"qty":2.34609048}],"checksum":527060297,"timestamp":"2024-06-01T17:52:21.711887Z"}]}
{"channel":"book","type":"update","data":[{"symbol":"LTC/USDT","bids":[],"asks":[{"price":83.27721,"qty":1.80000000}],"checksum":816044139,"timestamp":"2024-06-01T17:52:21.714852Z"}]}
{"channel":"book","type":"update","data":[{"symbol":"LTC/USDT","bids":[],"asks":[{"price":83.29997,"qty":0.00000000},{"price":83.34094,"qty":2.34609048}],"checksum":2857104351,"timestamp":"2024-06-01T17:52:22.040442Z"}]}
{"channel":"book","type":"update","data":[{"symbol":"LTC/USDT","bids":[],"asks":[{"price":83.27300,"qty":0.00000000},{"price":83.34690,"qty":13.36927600}],"checksum":3826751827,"timestamp":"2024-06-01T17:52:22.085557Z"}]}
{"channel":"book","type":"update","data":[{"symbol":"LTC/USDT","bids":[],"asks":[{"price":83.27701,"qty":1.99000000}],"checksum":2392452824,"timestamp":"2024-06-01T17:52:22.085705Z"}]}
{"channel":"book","type":"update","data":[{"symbol":"LTC/USDT","bids":[{"price":83.21171,"qty":0.00000000},{"price":83.21003,"qty":3.02951062}],"asks":[],"checksum":2192887546,"timestamp":"2024-06-01T17:52:22.168654Z"}]}
{"channel":"book","type":"update","data":[{"symbol":"LTC/USDT","bids":[{"price":83.21069,"qty":0.00000000},{"price":83.21000,"qty":38.46256908}],"asks":[],"checksum":165653047,"timestamp":"2024-06-01T17:52:22.168817Z"}]}
{"channel":"book","type":"update","data":[{"symbol":"LTC/USDT","bids":[{"price":83.21171,"qty":0.47862381}],"asks":[],"checksum":1805048803,"timestamp":"2024-06-01T17:52:22.174069Z"}]}
{"channel":"book","type":"update","data":[{"symbol":"LTC/USDT","bids":[{"price":83.21069,"qty":0.95509530}],"asks":[],"checksum":654484447,"timestamp":"2024-06-01T17:52:22.174116Z"}]}
{"channel":"book","type":"update","data":[{"symbol":"LTC/USDT","bids":[],"asks":[{"price":83.27709,"qty":10.00000000}],"checksum":3541496319,"timestamp":"2024-06-01T17:52:22.213113Z"}]}
{"channel":"book","type":"update","data":[{"symbol":"LTC/USDT","bids":[],"asks":[{"price":83.27988,"qty":0.00000000},{"price":83.34094,"qty":2.34609048}],"checksum":2604354744,"timestamp":"2024-06-01T17:52:22.219527Z"}]}
{"channel":"book","type":"update","data":[{"symbol":"LTC/USDT","bids":[],"asks":[{"price":83.27689,"qty":1.99000000}],"checksum":4078979986,"timestamp":"2024-06-01T17:52:22.233475Z"}]}
{"channel":"book","type":"update","data":[{"symbol":"LTC/USDT","bids":[],"asks":[{"price":83.29991,"qty":10.00000000}],"checksum":705344235,"timestamp":"2024-06-01T17:52:22.387891Z"}]}
{"channel":"book","type":"update","data":[{"symbol":"LTC/USDT","bids":[],"asks":[{"price":83.27701,"qty":0.00000000},{"price":83.32787,"qty":36.00236031}],"checksum":376180591,"timestamp":"2024-06-01T17:52:22.588428Z"}]}
{"channel":"book","type":"update","data":[{"symbol":"LTC/USDT","bids":[],"asks":[{"price":83.29991,"qty":0.00000000},{"price":83.34094,"qty":2.34609048}],"checksum":306515221,"timestamp":"2024-06-01T17:52:22.672349Z"}]}
{"channel":"book","type":"update","data":[{"symbol":"LTC/USDT","bids":[{"price":83.24915,"qty":0.00000000},{"price":83.21003,"qty":3.02951062}],"asks":[],"checksum":1082334152,"timestamp":"2024-06-01T17:52:22.704936Z"}]}
{"channel":"book","type":"update","data":[{"symbol":"LTC/USDT","bids":[{"price":83.24916,"qty":0.00000000},{"price":83.21000,"qty":38.46256908}],"asks":[],"checksum":3131427613,"timestamp":"2024-06-01T17:52:22.708971Z"}]}
{"channel":"book","type":"update","data":[{"symbol":"LTC/USDT","bids":[{"price":83.21172,"qty":3.60585442}],"asks":[],"checksum":2000450112,"timestamp":"2024-06-01T17:52:22.709768Z"}]}
{"channel":"book","type":"update","data":[{"symbol":"LTC/USDT","bids":[],"asks":[{"price":83.27721,"qty":0.00000000},{"price":83.34690,"qty":13.36927600}],"checksum":714327688,"timestamp":"2024-06-01T17:52:22.711878Z"}]}
{"channel":"book","type":"update","data":[{"symbol":"LTC/USDT","bids":[],"asks":[{"price":83.27548,"qty":1.80000000}],"checksum":139127356,"timestamp":"2024-06-01T17:52:22.712086Z"}]}
{"channel":"book","type":"update","data":[{"symbol":"LTC/USDT","bids":[{"price":83.24950,"qty":18.02990818}],"asks":[],"checksum":4229804510,"timestamp":"2024-06-01T17:52:22.745163Z"}]}
{"channel":"book","type":"update","data":[{"symbol":"LTC/USDT","bids":[{"price":83.24951,"qty":23.85306512}],"asks":[],"checksum":4198553186,"timestamp":"2024-06-01T17:52:22.749158Z"}]}
{"channel":"book","type":"update","data":[{"symbol":"LTC/USDT","bids":[],"asks":[{"price":83.27677,"qty":10.00000000}],"checksum":3391599140,"timestamp":"2024-06-01T17:52:22.749921Z"}]}
{"channel":"book","type":"update","data":[{"symbol":"LTC/USDT","bids":[],"asks":[{"price":83.27528,"qty":1.99000000}],"checksum":3913147835,"timestamp":"2024-06-01T17:52:22.751081Z"}]}
{"channel":"book","type":"update","data":[{"symbol":"LTC/USDT","bids":[{"price":83.21172,"qty":0.00000000},{"price":83.21037,"qty":7.87361491}],"asks":[],"checksum":640463400,"timestamp":"2024-06-01T17:52:22.753919Z"}]}
{"channel":"book","type":"update","data":[{"symbol":"LTC/USDT","bids":[{"price":83.24407,"qty":0.00000000},{"price":83.21003,"qty":3.02951062}],"asks":[],"checksum":2321866795,"timestamp":"2024-06-01T17:52:22.777242Z"}]}
{"channel":"book","type":"update","data":[{"symbol":"LTC/USDT","bids":[],"asks":[{"price":83.27689,"qty":0.00000000},{"price":83.32787,"qty":36.00236031}],"checksum":3927755660,"timestamp":"2024-06-01T17:52:22.781691Z"}]}
{"channel":"book","type":"update","data":[{"symbol":"LTC/USDT","bids":[],"asks":[{"price":83.27536,"qty":10.00000000}],"checksum":3024112705,"timestamp":"2024-06-01T17:52:22.782133Z"}]}
{"channel":"book","type":"update","data":[{"symbol":"LTC/USDT","bids":[],"asks":[{"price":83.27677,"qty":0.00000000},{"price":83.32787,"qty":36.00236031}],"checksum":2583207196,"timestamp":"2024-06-01T17:52:22.782154Z"}]}
{"channel":"book","type":"update","data":[{"symbol":"LTC/USDT","bids":[{"price":83.24497,"qty":9.01491751}],"asks":[],"checksum":3010632133,"timestamp":"2024-06-01T17:52:22.817511Z"}]}
{"channel":"book","type":"update","data":[{"symbol":"LTC/USDT","bids":[],"asks":[{"price":83.27709,"qty":0.00000000},{"price":83.34094,"qty":2.34609048}],"checksum":1163969612,"timestamp":"2024-06-01T17:52:22.822698Z"}]}
{"channel":"book","type":"update","data":[{"symbol":"LTC/USDT","bids":[],"asks":[{"price":83.27516,"qty":1.99000000}],"checksum":3234649970,"timestamp":"2024-06-01T17:52:22.823071Z"}]}
{"channel":"book","type":"update","data":[{"symbol":"LTC/USDT","bids":[],"asks":[{"price":83.30000,"qty":10.00000000}],"checksum":2212923001,"timestamp":"2024-06-01T17:52:22.954843Z"}]}
{"channel":"book","type":"update","data":[{"symbol":"LTC/USDT","bids":[],"asks":[{"price":83.27528,"qty":0.00000000},{"price":83.32787,"qty":36.00236031}],"checksum":3303927855,"timestamp":"2024-06-01T17:52:23.086178Z"}]}
{"channel":"book","type":"update","data":[{"symbol":"LTC/USDT","bids":[],"asks":[{"price":83.30000,"qty":0.00000000},{"price":83.34094,"qty":2.34609048}],"checksum":1661813482,"timestamp":"2024-06-01T17:52:23.233948Z"}]}
{"channel":"book","type":"update","data":[{"symbol":"LTC/USDT","bids":[{"price":83.24950,"qty":0.00000000},{"price":83.21003,"qty":3.02951062}],"asks":[],"checksum":2221751305,"timestamp":"2024-06-01T17:52:23.249951Z"}]}
{"channel":"book","type":"update","data":[{"symbol":"LTC/USDT","bids":[{"price":83.24951,"qty":0.00000000},{"price":83.21000,"qty":38.46256908}],"asks":[],"checksum":4183288145,"timestamp":"2024-06-01T17:52:23.253906Z"}]}
{"channel":"book","type":"update","data":[{"symbol":"LTC/USDT","bids":[{"price":83.21172,"qty":3.60583933}],"asks":[],"checksum":136956643,"timestamp":"2024-06-01T17:52:23.254524Z"}]}
{"channel":"book","type":"update","data":[{"symbol":"LTC/USDT","bids":[{"price":83.24999,"qty":18.02990921}],"asks":[],"checksum":1347780022,"timestamp":"2024-06-01T17:52:23.290061Z"}]}
{"channel":"book","type":"update","data":[{"symbol":"LTC/USDT","bids":[{"price":83.25000,"qty":23.85306512}],"asks":[],"checksum":1791308659,"timestamp":"2024-06-01T17:52:23.294753Z"}]}
{"channel":"book","type":"update","data":[{"symbol":"LTC/USDT","bids":[{"price":83.21172,"qty":0.00000000},{"price":83.21037,"qty":7.87361491}],"asks":[],"checksum":269668622,"timestamp":"2024-06-01T17:52:23.299160Z"}]}
{"channel":"book","type":"update","data":[{"symbol":"LTC/USDT","bids":[{"price":83.24497,"qty":0.00000000},{"price":83.21003,"qty":3.02951062}],"asks":[],"checksum":983094743,"timestamp":"2024-06-01T17:52:23.393896Z"}]}
{"channel":"book","type":"update","data":[{"symbol":"LTC/USDT","bids":[{"price":83.24656,"qty":9.01473793}],"asks":[],"checksum":2464217135,"timestamp":"2024-06-01T17:52:23.434211Z"}]}
{"channel":"book","type":"update","data":[{"symbol":"LTC/USDT","bids":[],"asks":[{"price":83.27548,"qty":0.00000000},{"price":83.34690,"qty":13.36927600}],"checksum":401141961,"timestamp":"2024-06-01T17:52:23.594401Z"}]}
{"channel":"book","type":"update","data":[{"symbol":"LTC/USDT","bids":[],"asks":[{"price":83.27536,"qty":0.00000000},{"price":83.37561,"qty":31.24000000}],"checksum":2462543337,"timestamp":"2024-06-01T17:52:23.599484Z"}]}
{"channel":"book","type":"update","data":[{"symbol":"LTC/USDT","bids":[],"asks":[{"price":83.27988,"qty":10.00000000}],"checksum":1996527989,"timestamp":"2024-06-01T17:52:23.599518Z"}]}
{"channel":"book","type":"update","data":[{"symbol":"LTC/USDT","bids":[],"asks":[{"price":83.28896,"qty":1.80000000}],"checksum":534426838,"timestamp":"2024-06-01T17:52:23.602437Z"}]}
{"channel":"book","type":"update","data":[{"symbol":"LTC/USDT","bids":[],"asks":[{"price":83.28896,"qty":0.00000000},{"price":83.34690,"qty":13.36927600}],"checksum":1996527989,"timestamp":"2024-06-01T17:52:23.602467Z"}]}
{"channel":"book","type":"update","data":[{"symbol":"LTC/USDT","bids":[],"asks":[{"price":83.27970,"qty":1.80000000}],"checksum":854081423,"timestamp":"2024-06-01T17:52:23.602473Z"}]}
{"channel":"book","type":"update","data":[{"symbol":"LTC/USDT","bids":[],"asks":[{"price":83.30022,"qty":10.00000000}],"checksum":966578566,"timestamp":"2024-06-01T17:52:23.640330Z"}]}
{"channel":"book","type":"update","data":[{"symbol":"LTC/USDT","bids":[],"asks":[{"price":83.27958,"qty":10.00000000}],"checksum":2973520818,"timestamp":"2024-06-01T17:52:23.710855Z"}]}
{"channel":"book","type":"update","data":[{"symbol":"LTC/USDT","bids":[],"asks":[{"price":83.27970,"qty":0.00000000},{"price":83.32787,"qty":36.00236031}],"checksum":479194809,"timestamp":"2024-06-01T17:52:23.713484Z"}]}
{"channel":"book","type":"update","data":[{"symbol":"LTC/USDT","bids":[],"asks":[{"price":83.27882,"qty":1.80000000}],"checksum":649614539,"timestamp":"2024-06-01T17:52:23.713696Z"}]}
{"channel":"book","type":"update","data":[{"symbol":"LTC/USDT","bids":[],"asks":[{"price":83.27938,"qty":1.99000000}],"checksum":2713899969,"timestamp":"2024-06-01T17:52:23.715872Z"}]}
{"channel":"book","type":"update","data":[{"symbol":"LTC/USDT","bids":[],"asks":[{"price":83.27516,"qty":0.00000000},{"price":83.31121,"qty":3.12000000}],"checksum":868515632,"timestamp":"2024-06-01T17:52:23.715943Z"}]}
{"channel":"book","type":"update","data":[{"symbol":"LTC/USDT","bids":[],"asks":[{"price":83.27988,"qty":0.00000000},{"price":83.32787,"qty":36.00236031}],"checksum":4065531301,"timestamp":"2024-06-01T17:52:23.716030Z"}]}
{"channel":"book","type":"update","data":[{"symbol":"LTC/USDT","bids":[{"price":83.24999,"qty":0.00000000},{"price":83.21003,"qty":3.02951062}],"asks":[],"checksum":2831094159,"timestamp":"2024-06-01T17:52:23.866886Z"}]}
{"channel":"book","type":"update","data":[{"symbol":"LTC/USDT","bids":[{"price":83.25000,"qty":0.00000000},{"price":83.21000,"qty":38.46256908}],"asks":[],"checksum":537585699,"timestamp":"2024-06-01T17:52:23.871583Z"}]}
{"channel":"book","type":"update","data":[{"symbol":"LTC/USDT","bids":[{"price":83.21172,"qty":3.60583314}],"asks":[],"checksum":769526065,"timestamp":"2024-06-01T17:52:23.872098Z"}]}
{"channel":"book","type":"update","data":[{"symbol":"LTC/USDT","bids":[],"asks":[{"price":83.27862,"qty":1.99000000}],"checksum":1447239774,"timestamp":"2024-06-01T17:52:23.872683Z"}]}
{"channel":"book","type":"update","data":[{"symbol":"LTC/USDT","bids":[],"asks":[{"price":83.27926,"qty":10.00000000}],"checksum":4020120984,"timestamp":"2024-06-01T17:52:23.873981Z"}]}
{"channel":"book","type":"update","data":[{"symbol":"LTC/USDT","bids":[],"asks":[{"price":83.27882,"qty":0.00000000},{"price":83.31121,"qty":3.12000000}],"checksum":1069269528,"timestamp":"2024-06-01T17:52:23.875149Z"}]}
{"channel":"book","type":"update","data":[{"symbol":"LTC/USDT","bids":[],"asks":[{"price":83.27623,"qty":1.80000000}],"checksum":2358873299,"timestamp":"2024-06-01T17:52:23.875457Z"}]}
{"channel":"book","type":"update","data":[{"symbol":"LTC/USDT","bids":[{"price":83.25250,"qty":18.02924116}],"asks":[],"checksum":1808945982,"timestamp":"2024-06-01T17:52:23.906787Z"}]}
{"channel":"book","type":"update","data":[{"symbol":"LTC/USDT","bids":[],"asks":[{"price":83.27603,"qty":1.99000000}],"checksum":3296216454,"timestamp":"2024-06-01T17:52:23.911701Z"}]}
{"channel":"book","type":"update","data":[{"symbol":"LTC/USDT","bids":[],"asks":[{"price":83.27862,"qty":0.00000000},{"price":83.30957,"qty":3.02415302}],"checksum":2038984667,"timestamp":"2024-06-01T17:52:23.911753Z"}]}
{"channel":"book","type":"update","data":[{"symbol":"LTC/USDT","bids":[],"asks":[{"price":83.27926,"qty":0.00000000},{"price":83.31121,"qty":3.12000000}],"checksum":1993564701,"timestamp":"2024-06-01T17:52:23.912521Z"}]}
{"channel":"book","type":"update","data":[{"symbol":"LTC/USDT","bids":[],"asks":[{"price":83.27850,"qty":10.00000000}],"checksum":1772783100,"timestamp":"2024-06-01T17:52:23.912595Z"}]}
{"channel":"book","type":"update","data":[{"symbol":"LTC/USDT","bids":[],"asks":[{"price":83.30022,"qty":0.00000000},{"price":83.31121,"qty":3.12000000}],"checksum":2232526361,"timestamp":"2024-06-01T17:52:23.916670Z"}]}
{"channel":"book","type":"update","data":[{"symbol":"LTC/USDT","bids":[{"price":83.24656,"qty":0.00000000},{"price":83.21003,"qty":3.02951062}],"asks":[],"checksum":2538364421,"timestamp":"2024-06-01T17:52:23.938547Z"}]}
{"channel":"book","type":"update","data":[{"symbol":"LTC/USDT","bids":[],"asks":[{"price":83.27938,"qty":0.00000000},{"price":83.32787,"qty":36.00236031}],"checksum":940704020,"timestamp":"2024-06-01T17:52:23.943330Z"}]}
{"channel":"book","type":"update","data":[{"symbol":"LTC/USDT","bids":[],"asks":[{"price":83.27850,"qty":0.00000000},{"price":83.34094,"qty":2.34609048}],"checksum":2551340381,"timestamp":"2024-06-01T17:52:23.943340Z"}]}
{"channel":"book","type":"update","data":[{"symbol":"LTC/USDT","bids":[],"asks":[{"price":83.27611,"qty":10.00000000}],"checksum":3056010838,"timestamp":"2024-06-01T17:52:23.943382Z"}]}
{"channel":"book","type":"update","data":[{"symbol":"LTC/USDT","bids":[{"price":83.24740,"qty":9.01460944}],"asks":[],"checksum":244428230,"timestamp":"2024-06-01T17:52:23.978506Z"}]}
{"channel":"book","type":"update","data":[{"symbol":"LTC/USDT","bids":[],"asks":[{"price":83.27591,"qty":1.99000000}],"checksum":1306914045,"timestamp":"2024-06-01T17:52:23.983341Z"}]}
{"channel":"book","type":"update","data":[{"symbol":"LTC/USDT","bids":[],"asks":[{"price":83.27958,"qty":0.00000000},{"price":83.32787,"qty":36.00236031}],"checksum":2562308064,"timestamp":"2024-06-01T17:52:23.983590Z"}]}
{"channel":"book","type":"update","data":[{"symbol":"LTC/USDT","bids":[{"price":83.25251,"qty":23.85306512}],"asks":[],"checksum":3663193761,"timestamp":"2024-06-01T17:52:24.023514Z"}]}
{"channel":"book","type":"update","data":[{"symbol":"LTC/USDT","bids":[],"asks":[{"price":83.27603,"qty":0.00000000},{"price":83.34094,"qty":2.34609048}],"checksum":1394885888,"timestamp":"2024-06-01T17:52:24.028242Z"}]}
{"channel":"book","type":"update","data":[{"symbol":"LTC/USDT","bids":[],"asks":[{"price":83.27591,"qty":11.99000000}],"checksum":491674751,"timestamp":"2024-06-01T17:52:24.028498Z"}]}
{"channel":"book","type":"update","data":[{"symbol":"LTC/USDT","bids":[{"price":83.21172,"qty":0.00000000},{"price":83.21037,"qty":7.87361491}],"asks":[],"checksum":391703011,"timestamp":"2024-06-01T17:52:24.028514Z"}]}
{"channel":"book","type":"update","data":[{"symbol":"LTC/USDT","bids":[],"asks":[{"price":83.30011,"qty":10.00000000}],"checksum":1450877707,"timestamp":"2024-06-01T17:52:24.181306Z"}]}
{"channel":"book","type":"update","data":[{"symbol":"LTC/USDT","bids":[],"asks":[{"price":83.27591,"qty":1.99000000}],"checksum":2525930943,"timestamp":"2024-06-01T17:52:24.211070Z"}]}
{"channel":"book","type":"update","data":[{"symbol":"LTC/USDT","bids":[{"price":83.25250,"qty":0.00000000},{"price":83.21003,"qty":3.02951062}],"asks":[],"checksum":3532959205,"timestamp":"2024-06-01T17:52:24.482626Z"}]}
{"channel":"book","type":"update","data":[{"symbol":"LTC/USDT","bids":[{"price":83.25251,"qty":0.00000000},{"price":83.21000,"qty":38.46256908}],"asks":[],"checksum":286253351,"timestamp":"2024-06-01T17:52:24.486666Z"}]}
{"channel":"book","type":"update","data":[{"symbol":"LTC/USDT","bids":[{"price":83.21172,"qty":3.60583936}],"asks":[],"checksum":4245371372,"timestamp":"2024-06-01T17:52:24.487538Z"}]}
{"channel":"book","type":"update","data":[{"symbol":"LTC/USDT","bids":[{"price":83.24741,"qty":23.85306512}],"asks":[],"checksum":2806063871,"timestamp":"2024-06-01T17:52:24.507647Z"}]}
{"channel":"book","type":"update","data":[{"symbol":"LTC/USDT","bids":[{"price":83.25372,"qty":18.02903132}],"asks":[],"checksum":1065042295,"timestamp":"2024-06-01T17:52:24.523047Z"}]}
{"channel":"book","type":"update","data":[{"symbol":"LTC/USDT","bids":[{"price":83.21172,"qty":0.00000000},{"price":83.21037,"qty":7.87361491}],"asks":[],"checksum":2615030280,"timestamp":"2024-06-01T17:52:24.527026Z"}]}
{"channel":"book","type":"update","data":[{"symbol":"LTC/USDT","bids":[{"price":83.24740,"qty":0.00000000},{"price":83.21003,"qty":3.02951062}],"asks":[],"checksum":522372498,"timestamp":"2024-06-01T17:52:24.554756Z"}]}
{"channel":"book","type":"update","data":[{"symbol":"LTC/USDT","bids":[{"price":83.24864,"qty":9.01451566}],"asks":[],"checksum":1739308976,"timestamp":"2024-06-01T17:52:24.595189Z"}]}
{"channel":"book","type":"update","data":[{"symbol":"LTC/USDT","bids":[],"asks":[{"price":83.30011,"qty":0.00000000},{"price":83.34094,"qty":2.34609048}],"checksum":2820139667,"timestamp":"2024-06-01T17:52:24.678986Z"}]}
{"channel":"book","type":"update","data":[{"symbol":"LTC/USDT","bids":[{"price":83.21069,"qty":0.00000000},{"price":83.21003,"qty":3.02951062}],"asks":[],"checksum":343130897,"timestamp":"2024-06-01T17:52:24.734087Z"}]}
{"channel":"book","type":"update","data":[{"symbol":"LTC/USDT","bids":[{"price":83.21069,"qty":1.17840090}],"asks":[],"checksum":3350315318,"timestamp":"2024-06-01T17:52:24.739493Z"}]}
{"channel":"book","type":"update","data":[{"symbol":"LTC/USDT","bids":[],"asks":[{"price":83.30022,"qty":10.00000000}],"checksum":4254141190,"timestamp":"2024-06-01T17:52:24.970453Z"}]}
{"channel":"book","type":"update","data":[{"symbol":"LTC/USDT","bids":[{"price":83.25372,"qty":0.00000000},{"price":83.21003,"qty":3.02951062}],"asks":[],"checksum":3898584773,"timestamp":"2024-06-01T17:52:25.157986Z"}]}
{"channel":"book","type":"update","data":[{"symbol":"LTC/USDT","bids":[{"price":83.24865,"qty":23.85306512}],"asks":[],"checksum":356108186,"timestamp":"2024-06-01T17:52:25.161831Z"}]}
{"channel":"book","type":"update","data":[{"symbol":"LTC/USDT","bids":[{"price":83.21172,"qty":3.60582460}],"asks":[],"checksum":2869722944,"timestamp":"2024-06-01T17:52:25.162434Z"}]}
{"channel":"book","type":"update","data":[{"symbol":"LTC/USDT","bids":[{"price":83.21172,"qty":0.00000000},{"price":83.21037,"qty":7.87361491}],"asks":[],"checksum":356108186,"timestamp":"2024-06-01T17:52:25.166338Z"}]}
{"channel":"book","type":"update","data":[{"symbol":"LTC/USDT","bids":[{"price":83.25351,"qty":18.02902452}],"asks":[],"checksum":2251289223,"timestamp":"2024-06-01T17:52:25.198095Z"}]}
{"channel":"book","type":"update","data":[{"symbol":"LTC/USDT","bids":[{"price":83.24865,"qty":0.00000000},{"price":83.21037,"qty":7.87361491}],"asks":[],"checksum":56652928,"timestamp":"2024-06-01T17:52:25.201607Z"}]}
{"channel":"book","type":"update","data":[{"symbol":"LTC/USDT","bids":[{"price":83.24864,"qty":0.00000000},{"price":83.21003,"qty":3.02951062}],"asks":[],"checksum":3889478426,"timestamp":"2024-06-01T17:52:25.304134Z"}]}
{"channel":"book","type":"update","data":[{"symbol":"LTC/USDT","bids":[{"price":83.24884,"qty":9.01447568}],"asks":[],"checksum":1246954839,"timestamp":"2024-06-01T17:52:25.344486Z"}]}
{"channel":"book","type":"update","data":[{"symbol":"LTC/USDT","bids":[],"asks":[{"price":83.30022,"qty":0.00000000},{"price":83.34094,"qty":2.34609048}],"checksum":1886637927,"timestamp":"2024-06-01T17:52:25.478394Z"}]}
{"channel":"book","type":"update","data":[{"symbol":"LTC/USDT","bids":[{"price":83.25351,"qty":0.00000000},{"price":83.21003,"qty":3.02951062}],"asks":[],"checksum":1183938089,"timestamp":"2024-06-01T17:52:25.776717Z"}]}
{"channel":"book","type":"update","data":[{"symbol":"LTC/USDT","bids":[{"price":83.21172,"qty":3.60585108}],"asks":[],"checksum":3941874750,"timestamp":"2024-06-01T17:52:25.781403Z"}]}
{"channel":"book","type":"update","data":[{"symbol":"LTC/USDT","bids":[],"asks":[{"price":83.30035,"qty":10.00000000}],"checksum":2696685467,"timestamp":"2024-06-01T17:52:25.787373Z"}]}
{"channel":"book","type":"update","data":[{"symbol":"LTC/USDT","bids":[{"price":83.25393,"qty":18.02895175}],"asks":[],"checksum":4122953525,"timestamp":"2024-06-01T17:52:25.817416Z"}]}
{"channel":"book","type":"update","data":[{"symbol":"LTC/USDT","bids":[{"price":83.21172,"qty":0.00000000},{"price":83.21037,"qty":7.87361491}],"asks":[],"checksum":3454936078,"timestamp":"2024-06-01T17:52:25.821701Z"}]}
{"channel":"book","type":"update","data":[{"symbol":"LTC/USDT","bids":[{"price":83.24884,"qty":0.00000000},{"price":83.21003,"qty":3.02951062}],"asks":[],"checksum":1617533507,"timestamp":"2024-06-01T17:52:25.850025Z"}]}
{"channel":"book","type":"update","data":[{"symbol":"LTC/USDT","bids":[{"price":83.24885,"qty":9.01447587}],"asks":[],"checksum":2144896226,"timestamp":"2024-06-01T17:52:25.890520Z"}]}
{"channel":"book","type":"update","data":[{"symbol":"LTC/USDT","bids":[{"price":83.25393,"qty":0.00000000},{"price":83.21003,"qty":3.02951062}],"asks":[],"checksum":2623431267,"timestamp":"2024-06-01T17:52:26.401183Z"}]}
{"channel":"book","type":"update","data":[{"symbol":"LTC/USDT","bids":[{"price":83.24886,"qty":23.85306512}],"asks":[],"checksum":3568594369,"timestamp":"2024-06-01T17:52:26.405175Z"}]}
{"channel":"book","type":"update","data":[{"symbol":"LTC/USDT","bids":[{"price":83.21172,"qty":3.60584882}],"asks":[],"checksum":2445215430,"timestamp":"2024-06-01T17:52:26.406171Z"}]}
{"channel":"book","type":"update","data":[{"symbol":"LTC/USDT","bids":[{"price":83.21172,"qty":0.00000000},{"price":83.21037,"qty":7.87361491}],"asks":[],"checksum":3568594369,"timestamp":"2024-06-01T17:52:26.410724Z"}]}
{"channel":"book","type":"update","data":[{"symbol":"LTC/USDT","bids":[{"price":83.25383,"qty":18.02895175}],"asks":[],"checksum":382416909,"timestamp":"2024-06-01T17:52:26.441631Z"}]}
{"channel":"book","type":"update","data":[{"symbol":"LTC/USDT","bids":[{"price":83.24886,"qty":0.00000000},{"price":83.21037,"qty":7.87361491}],"asks":[],"checksum":2534538249,"timestamp":"2024-06-01T17:52:26.445400Z"}]}
{"channel":"book","type":"update","data":[{"symbol":"LTC/USDT","bids":[{"price":83.24885,"qty":0.00000000},{"price":83.21003,"qty":3.02951062}],"asks":[],"checksum":2292245160,"timestamp":"2024-06-01T17:52:26.475460Z"}]}
{"channel":"book","type":"update","data":[{"symbol":"LTC/USDT","bids":[{"price":83.24717,"qty":9.01458070}],"asks":[],"checksum":2923551124,"timestamp":"2024-06-01T17:52:26.515787Z"}]}
{"channel":"book","type":"update","data":[{"symbol":"LTC/USDT","bids":[{"price":83.25383,"qty":0.00000000},{"price":83.21003,"qty":3.02951062}],"asks":[],"checksum":862674719,"timestamp":"2024-06-01T17:52:26.952057Z"}]}
{"channel":"book","type":"update","data":[{"symbol":"LTC/USDT","bids":[{"price":83.24741,"qty":0.00000000},{"price":83.21000,"qty":38.46256908}],"asks":[],"checksum":122035902,"timestamp":"2024-06-01T17:52:26.956137Z"}]}
{"channel":"book","type":"update","data":[{"symbol":"LTC/USDT","bids":[{"price":83.21172,"qty":3.60583798}],"asks":[],"checksum":3618693285,"timestamp":"2024-06-01T17:52:26.956952Z"}]}
{"channel":"book","type":"update","data":[{"symbol":"LTC/USDT","bids":[{"price":83.25226,"qty":18.02916129}],"asks":[],"checksum":1570791430,"timestamp":"2024-06-01T17:52:26.992562Z"}]}
{"channel":"book","type":"update","data":[{"symbol":"LTC/USDT","bids":[{"price":83.25226,"qty":0.00000000},{"price":83.21003,"qty":3.02951062}],"asks":[],"checksum":3618693285,"timestamp":"2024-06-01T17:52:27.071056Z"}]}
{"channel":"book","type":"update","data":[{"symbol":"LTC/USDT","bids":[{"price":83.24718,"qty":23.85306512}],"asks":[],"checksum":577821881,"timestamp":"2024-06-01T17:52:27.074953Z"}]}
{"channel":"book","type":"update","data":[{"symbol":"LTC/USDT","bids":[{"price":83.24717,"qty":0.00000000},{"price":83.21003,"qty":3.02951062}],"asks":[],"checksum":1692959232,"timestamp":"2024-06-01T17:52:27.098278Z"}]}
{"channel":"book","type":"update","data":[{"symbol":"LTC/USDT","bids":[{"price":83.24874,"qty":9.01448170}],"asks":[],"checksum":2340349519,"timestamp":"2024-06-01T17:52:27.138519Z"}]}
{"channel":"book","type":"update","data":[{"symbol":"LTC/USDT","bids":[{"price":83.24875,"qty":23.85306512}],"asks":[],"checksum":1923425807,"timestamp":"2024-06-01T17:52:27.142309Z"}]}
{"channel":"book","type":"update","data":[{"symbol":"LTC/USDT","bids":[{"price":83.21172,"qty":0.00000000},{"price":83.21037,"qty":7.87361491}],"asks":[],"checksum":1029278159,"timestamp":"2024-06-01T17:52:27.146842Z"}]}
{"channel":"book","type":"update","data":[{"symbol":"LTC/USDT","bids":[{"price":83.21171,"qty":0.00000000},{"price":83.21003,"qty":3.02951062}],"asks":[],"checksum":2115519754,"timestamp":"2024-06-01T17:52:27.396052Z"}]}
{"channel":"book","type":"update","data":[{"symbol":"LTC/USDT","bids":[{"price":83.21171,"qty":0.61401650}],"asks":[],"checksum":1306739704,"timestamp":"2024-06-01T17:52:27.400844Z"}]}
{"channel":"book","type":"update","data":[{"symbol":"LTC/USDT","bids":[{"price":83.24718,"qty":0.00000000},{"price":83.21003,"qty":3.02951062}],"asks":[],"checksum":2665918018,"timestamp":"2024-06-01T17:52:27.509569Z"}]}
{"channel":"book","type":"update","data":[{"symbol":"LTC/USDT","bids":[{"price":83.21172,"qty":3.60584563}],"asks":[],"checksum":440960136,"timestamp":"2024-06-01T17:52:27.514464Z"}]}
{"channel":"book","type":"update","data":[{"symbol":"LTC/USDT","bids":[{"price":83.25370,"qty":18.02896341}],"asks":[],"checksum":2128152768,"timestamp":"2024-06-01T17:52:27.622611Z"}]}
{"channel":"book","type":"update","data":[{"symbol":"LTC/USDT","bids":[{"price":83.21172,"qty":0.00000000},{"price":83.21037,"qty":7.87361491}],"asks":[],"checksum":2038637398,"timestamp":"2024-06-01T17:52:27.627005Z"}]}
{"channel":"book","type":"update","data":[{"symbol":"LTC/USDT","bids":[{"price":83.24874,"qty":0.00000000},{"price":83.21003,"qty":3.02951062}],"asks":[],"checksum":3214243403,"timestamp":"2024-06-01T17:52:27.648681Z"}]}
{"channel":"book","type":"update","data":[{"symbol":"LTC/USDT","bids":[{"price":83.24828,"qty":9.01452903}],"asks":[],"checksum":1348564247,"timestamp":"2024-06-01T17:52:27.688632Z"}]}
{"channel":"book","type":"update","data":[{"symbol":"LTC/USDT","bids":[{"price":83.25370,"qty":0.00000000},{"price":83.21003,"qty":3.02951062}],"asks":[],"checksum":1756896402,"timestamp":"2024-06-01T17:52:28.204817Z"}]}
{"channel":"book","type":"update","data":[{"symbol":"LTC/USDT","bids":[{"price":83.21172,"qty":3.60584009}],"asks":[],"checksum":707685887,"timestamp":"2024-06-01T17:52:28.209888Z"}]}
{"channel":"book","type":"update","data":[{"symbol":"LTC/USDT","bids":[{"price":83.24828,"qty":0.00000000},{"price":83.21003,"qty":3.02951062}],"asks":[],"checksum":2694440645,"timestamp":"2024-06-01T17:52:28.276725Z"}]}
{"channel":"book","type":"update","data":[{"symbol":"LTC/USDT","bids":[{"price":83.24875,"qty":0.00000000},{"price":83.21000,"qty":38.46256908}],"asks":[],"checksum":530234366,"timestamp":"2024-06-01T17:52:28.506765Z"}]}
{"channel":"book","type":"update","data":[{"symbol":"LTC/USDT","bids":[],"asks":[{"price":83.27623,"qty":0.00000000},{"price":83.34094,"qty":2.34609048}],"checksum":1715223135,"timestamp":"2024-06-01T17:52:28.509425Z"}]}
{"channel":"book","type":"update","data":[{"symbol":"LTC/USDT","bids":[],"asks":[{"price":83.27549,"qty":1.80000000}],"checksum":285295888,"timestamp":"2024-06-01T17:52:28.509549Z"}]}
{"channel":"book","type":"update","data":[{"symbol":"LTC/USDT","bids":[{"price":83.23062,"qty":1.99000000}],"asks":[],"checksum":3481371460,"timestamp":"2024-06-01T17:52:28.511822Z"}]}
{"channel":"book","type":"update","data":[{"symbol":"LTC/USDT","bids":[{"price":83.23145,"qty":16.22552891}],"asks":[],"checksum":1388005739,"timestamp":"2024-06-01T17:52:28.514729Z"}]}
{"channel":"book","type":"update","data":[{"symbol":"LTC/USDT","bids":[{"price":83.23042,"qty":0.00000000},{"price":83.21003,"qty":3.02951062}],"asks":[],"checksum":2676007831,"timestamp":"2024-06-01T17:52:28.517466Z"}]}
{"channel":"book","type":"update","data":[{"symbol":"LTC/USDT","bids":[{"price":83.23062,"qty":0.00000000},{"price":83.21000,"qty":38.46256908}],"asks":[],"checksum":1466364086,"timestamp":"2024-06-01T17:52:28.586005Z"}]}
{"channel":"book","type":"update","data":[{"symbol":"LTC/USDT","bids":[],"asks":[{"price":83.27529,"qty":1.99000000}],"checksum":3298796648,"timestamp":"2024-06-01T17:52:28.586045Z"}]}
{"channel":"book","type":"update","data":[{"symbol":"LTC/USDT","bids":[{"price":83.23146,"qty":23.85306512}],"asks":[],"checksum":3139748839,"timestamp":"2024-06-01T17:52:28.590028Z"}]}
{"channel":"book","type":"update","data":[{"symbol":"LTC/USDT","bids":[],"asks":[{"price":83.27591,"qty":0.00000000},{"price":83.32787,"qty":36.00236031}],"checksum":3548511290,"timestamp":"2024-06-01T17:52:28.590887Z"}]}
{"channel":"book","type":"update","data":[{"symbol":"LTC/USDT","bids":[{"price":83.23229,"qty":16.22552896}],"asks":[],"checksum":2882106824,"timestamp":"2024-06-01T17:52:28.596405Z"}]}
{"channel":"book","type":"update","data":[{"symbol":"LTC/USDT","bids":[{"price":83.23145,"qty":0.00000000},{"price":83.21003,"qty":3.02951062}],"asks":[],"checksum":3492824302,"timestamp":"2024-06-01T17:52:28.596482Z"}]}
{"channel":"book","type":"update","data":[{"symbol":"LTC/USDT","bids":[],"asks":[{"price":83.27579,"qty":10.00000000}],"checksum":3510466912,"timestamp":"2024-06-01T17:52:28.596493Z"}]}
{"channel":"book","type":"update","data":[{"symbol":"LTC/USDT","bids":[],"asks":[{"price":83.27537,"qty":10.00000000}],"checksum":3761490941,"timestamp":"2024-06-01T17:52:28.711214Z"}]}
{"channel":"book","type":"update","data":[{"symbol":"LTC/USDT","bids":[],"asks":[{"price":83.27579,"qty":0.00000000},{"price":83.31121,"qty":3.12000000}],"checksum":1713714773,"timestamp":"2024-06-01T17:52:28.711508Z"}]}
{"channel":"book","type":"update","data":[{"symbol":"LTC/USDT","bids":[],"asks":[{"price":83.27611,"qty":0.00000000},{"price":83.32787,"qty":36.00236031}],"checksum":3651169075,"timestamp":"2024-06-01T17:52:28.715920Z"}]}
{"channel":"book","type":"update","data":[{"symbol":"LTC/USDT","bids":[],"asks":[{"price":83.27517,"qty":1.99000000}],"checksum":2256585995,"timestamp":"2024-06-01T17:52:28.717600Z"}]}
{"channel":"book","type":"update","data":[{"symbol":"LTC/USDT","bids":[{"price":83.25227,"qty":18.02915680}],"asks":[],"checksum":1793586953,"timestamp":"2024-06-01T17:52:28.825757Z"}]}
{"channel":"book","type":"update","data":[{"symbol":"LTC/USDT","bids":[{"price":83.21172,"qty":0.00000000},{"price":83.21003,"qty":3.02951062}],"asks":[],"checksum":678528612,"timestamp":"2024-06-01T17:52:28.830543Z"}]}
{"channel":"book","type":"update","data":[{"symbol":"LTC/USDT","bids":[],"asks":[{"price":83.27517,"qty":11.99000000}],"checksum":245506366,"timestamp":"2024-06-01T17:52:28.830572Z"}]}
{"channel":"book","type":"update","data":[{"symbol":"LTC/USDT","bids":[],"asks":[{"price":83.27529,"qty":0.00000000},{"price":83.32787,"qty":36.00236031}],"checksum":1999793678,"timestamp":"2024-06-01T17:52:28.831429Z"}]}
{"channel":"book","type":"update","data":[{"symbol":"LTC/USDT","bids":[{"price":83.24876,"qty":9.01447357}],"asks":[],"checksum":1893378260,"timestamp":"2024-06-01T17:52:28.898456Z"}]}
{"channel":"book","type":"update","data":[{"symbol":"LTC/USDT","bids":[],"asks":[{"price":83.27517,"qty":1.99000000}],"checksum":4215456665,"timestamp":"2024-06-01T17:52:28.903022Z"}]}
{"channel":"book","type":"update","data":[{"symbol":"LTC/USDT","bids":[{"price":83.25228,"qty":23.85306512}],"asks":[],"checksum":2240713484,"timestamp":"2024-06-01T17:52:29.018408Z"}]}
{"channel":"book","type":"update","data":[{"symbol":"LTC/USDT","bids":[],"asks":[{"price":83.27549,"qty":0.00000000},{"price":83.34094,"qty":2.34609048}],"checksum":3088155010,"timestamp":"2024-06-01T17:52:29.021106Z"}]}
{"channel":"book","type":"update","data":[{"symbol":"LTC/USDT","bids":[{"price":83.23146,"qty":0.00000000},{"price":83.21037,"qty":7.87361491}],"asks":[],"checksum":4144296144,"timestamp":"2024-06-01T17:52:29.022482Z"}]}
{"channel":"book","type":"update","data":[{"symbol":"LTC/USDT","bids":[],"asks":[{"price":83.30957,"qty":0.00000000},{"price":83.34690,"qty":13.36927600}],"checksum":2074490652,"timestamp":"2024-06-01T17:52:29.147941Z"}]}
{"channel":"book","type":"update","data":[{"symbol":"LTC/USDT","bids":[{"price":83.25227,"qty":0.00000000},{"price":83.21003,"qty":3.02951062}],"asks":[],"checksum":327925726,"timestamp":"2024-06-01T17:52:29.335101Z"}]}
{"channel":"book","type":"update","data":[{"symbol":"LTC/USDT","bids":[{"price":83.25228,"qty":0.00000000},{"price":83.21000,"qty":38.46256908}],"asks":[],"checksum":3737759441,"timestamp":"2024-06-01T17:52:29.339318Z"}]}
{"channel":"book","type":"update","data":[{"symbol":"LTC/USDT","bids":[{"price":83.21172,"qty":3.60581529}],"asks":[],"checksum":4078993840,"timestamp":"2024-06-01T17:52:29.340364Z"}]}
{"channel":"book","type":"update","data":[{"symbol":"LTC/USDT","bids":[],"asks":[{"price":83.27988,"qty":10.00000000}],"checksum":4003326898,"timestamp":"2024-06-01T17:52:29.341877Z"}]}
{"channel":"book","type":"update","data":[{"symbol":"LTC/USDT","bids":[],"asks":[{"price":83.27537,"qty":0.00000000},{"price":83.34690,"qty":13.36927600}],"checksum":2709035824,"timestamp":"2024-06-01T17:52:29.342041Z"}]}
{"channel":"book","type":"update","data":[{"symbol":"LTC/USDT","bids":[],"asks":[{"price":83.27721,"qty":1.80000000}],"checksum":1868984504,"timestamp":"2024-06-01T17:52:29.344790Z"}]}
{"channel":"book","type":"update","data":[{"symbol":"LTC/USDT","bids":[{"price":83.25384,"qty":18.02894642}],"asks":[],"checksum":3576136297,"timestamp":"2024-06-01T17:52:29.375336Z"}]}
{"channel":"book","type":"update","data":[{"symbol":"LTC/USDT","bids":[],"asks":[{"price":83.27709,"qty":10.00000000}],"checksum":3115540711,"timestamp":"2024-06-01T17:52:29.380237Z"}]}
{"channel":"book","type":"update","data":[{"symbol":"LTC/USDT","bids":[],"asks":[{"price":83.27517,"qty":0.00000000},{"price":83.34094,"qty":2.34609048}],"checksum":2198530767,"timestamp":"2024-06-01T17:52:29.380264Z"}]}
{"channel":"book","type":"update","data":[{"symbol":"LTC/USDT","bids":[],"asks":[{"price":83.27701,"qty":1.99000000}],"checksum":4129393211,"timestamp":"2024-06-01T17:52:29.380308Z"}]}
{"channel":"book","type":"update","data":[{"symbol":"LTC/USDT","bids":[],"asks":[{"price":83.30035,"qty":0.00000000},{"price":83.34094,"qty":2.34609048}],"checksum":2622952890,"timestamp":"2024-06-01T17:52:29.402805Z"}]}
{"channel":"book","type":"update","data":[{"symbol":"LTC/USDT","bids":[{"price":83.24876,"qty":0.00000000},{"price":83.21003,"qty":3.02951062}],"asks":[],"checksum":1059928718,"timestamp":"2024-06-01T17:52:29.480888Z"}]}
{"channel":"book","type":"update","data":[{"symbol":"LTC/USDT","bids":[],"asks":[{"price":83.27988,"qty":0.00000000},{"price":83.34690,"qty":13.36927600}],"checksum":796333140,"timestamp":"2024-06-01T17:52:29.485389Z"}]}
{"channel":"book","type":"update","data":[{"symbol":"LTC/USDT","bids":[],"asks":[{"price":83.27689,"qty":1.99000000}],"checksum":521896163,"timestamp":"2024-06-01T17:52:29.485858Z"}]}
{"channel":"book","type":"update","data":[{"symbol":"LTC/USDT","bids":[{"price":83.24875,"qty":9.01447579}],"asks":[],"checksum":549242302,"timestamp":"2024-06-01T17:52:29.521337Z"}]}
{"channel":"book","type":"update","data":[{"symbol":"LTC/USDT","bids":[],"asks":[{"price":83.27701,"qty":0.00000000},{"price":83.34690,"qty":13.36927600}],"checksum":3091132445,"timestamp":"2024-06-01T17:52:29.526423Z"}]}
{"channel":"book","type":"update","data":[{"symbol":"LTC/USDT","bids":[],"asks":[{"price":83.27689,"qty":11.99000000}],"checksum":788244720,"timestamp":"2024-06-01T17:52:29.527494Z"}]}
{"channel":"book","type":"update","data":[{"symbol":"LTC/USDT","bids":[],"asks":[{"price":83.30156,"qty":10.00000000}],"checksum":3232904768,"timestamp":"2024-06-01T17:52:29.664848Z"}]}
{"channel":"book","type":"update","data":[{"symbol":"LTC/USDT","bids":[],"asks":[{"price":83.27689,"qty":1.99000000}],"checksum":1450667693,"timestamp":"2024-06-01T17:52:29.711272Z"}]}
{"channel":"book","type":"update","data":[{"symbol":"LTC/USDT","bids":[{"price":83.21171,"qty":0.00000000},{"price":83.21003,"qty":3.02951062}],"asks":[],"checksum":1694659676,"timestamp":"2024-06-01T17:52:29.952441Z"}]}
{"channel":"book","type":"update","data":[{"symbol":"LTC/USDT","bids":[{"price":83.21069,"qty":0.00000000},{"price":83.21000,"qty":38.46256908}],"asks":[],"checksum":55790069,"timestamp":"2024-06-01T17:52:29.952654Z"}]}
{"channel":"book","type":"update","data":[{"symbol":"LTC/USDT","bids":[{"price":83.21173,"qty":1.61039384}],"asks":[],"checksum":2814463927,"timestamp":"2024-06-01T17:52:29.955214Z"}]}
{"channel":"book","type":"update","data":[{"symbol":"LTC/USDT","bids":[{"price":83.21172,"qty":0.00000000},{"price":83.21000,"qty":38.46256908}],"asks":[],"checksum":2947230396,"timestamp":"2024-06-01T17:52:29.960072Z"}]}
{"channel":"book","type":"update","data":[{"symbol":"LTC/USDT","bids":[{"price":83.21174,"qty":3.60582548}],"asks":[],"checksum":3173653845,"timestamp":"2024-06-01T17:52:29.960430Z"}]}
{"channel":"book","type":"update","data":[{"symbol":"LTC/USDT","bids":[{"price":83.21174,"qty":0.00000000},{"price":83.21000,"qty":38.46256908}],"asks":[],"checksum":2947230396,"timestamp":"2024-06-01T17:52:29.968575Z"}]}
{"channel":"book","type":"update","data":[{"symbol":"LTC/USDT","bids":[{"price":83.25385,"qty":23.85306512}],"asks":[],"checksum":151384726,"timestamp":"2024-06-01T17:52:30.010123Z"}]}
{"channel":"book","type":"update","data":[{"symbol":"LTC/USDT","bids":[{"price":83.25384,"qty":0.00000000},{"price":83.21000,"qty":38.46256908}],"asks":[],"checksum":36303015,"timestamp":"2024-06-01T17:52:30.032761Z"}]}
{"channel":"book","type":"update","data":[{"symbol":"LTC/USDT","bids":[{"price":83.25390,"qty":18.02895519}],"asks":[],"checksum":3260238217,"timestamp":"2024-06-01T17:52:30.072801Z"}]}
{"channel":"book","type":"update","data":[{"symbol":"LTC/USDT","bids":[{"price":83.25391,"qty":23.85306512}],"asks":[],"checksum":3227045987,"timestamp":"2024-06-01T17:52:30.076843Z"}]}
{"channel":"book","type":"update","data":[{"symbol":"LTC/USDT","bids":[{"price":83.24875,"qty":0.00000000},{"price":83.21003,"qty":3.02951062}],"asks":[],"checksum":2268708329,"timestamp":"2024-06-01T17:52:30.105777Z"}]}
{"channel":"book","type":"update","data":[{"symbol":"LTC/USDT","bids":[{"price":83.25385,"qty":0.00000000},{"price":83.21000,"qty":38.46256908}],"asks":[],"checksum":663641805,"timestamp":"2024-06-01T17:52:30.109287Z"}]}
{"channel":"book","type":"update","data":[{"symbol":"LTC/USDT","bids":[{"price":83.24895,"qty":9.01447759}],"asks":[],"checksum":1457691224,"timestamp":"2024-06-01T17:52:30.145748Z"}]}
{"channel":"book","type":"update","data":[{"symbol":"LTC/USDT","bids":[],"asks":[{"price":83.30156,"qty":0.00000000},{"price":83.34690,"qty":13.36927600}],"checksum":2777703658,"timestamp":"2024-06-01T17:52:30.457861Z"}]}
{"channel":"book","type":"update","data":[{"symbol":"LTC/USDT","bids":[{"price":83.25390,"qty":0.00000000},{"price":83.21000,"qty":38.46256908}],"asks":[],"checksum":1010847914,"timestamp":"2024-06-01T17:52:30.658736Z"}]}
{"channel":"book","type":"update","data":[{"symbol":"LTC/USDT","bids":[{"price":83.25391,"qty":0.00000000},{"price":83.20977,"qty":8.19100000}],"asks":[],"checksum":743697927,"timestamp":"2024-06-01T17:52:30.662765Z"}]}
{"channel":"book","type":"update","data":[{"symbol":"LTC/USDT","bids":[{"price":83.25393,"qty":18.02895542}],"asks":[],"checksum":1925446790,"timestamp":"2024-06-01T17:52:30.699013Z"}]}
{"channel":"book","type":"update","data":[{"symbol":"LTC/USDT","bids":[],"asks":[{"price":83.30161,"qty":10.00000000}],"checksum":52809664,"timestamp":"2024-06-01T17:52:30.728090Z"}]}
{"channel":"book","type":"update","data":[{"symbol":"LTC/USDT","bids":[{"price":83.24895,"qty":0.00000000},{"price":83.20977,"qty":8.19100000}],"asks":[],"checksum":138979465,"timestamp":"2024-06-01T17:52:30.732284Z"}]}
{"channel":"book","type":"update","data":[{"symbol":"LTC/USDT","bids":[{"price":83.24885,"qty":9.01447771}],"asks":[],"checksum":854535785,"timestamp":"2024-06-01T17:52:30.772345Z"}]}
{"channel":"book","type":"update","data":[{"symbol":"LTC/USDT","bids":[],"asks":[{"price":83.29163,"qty":0.00000000},{"price":83.34690,"qty":13.36927600}],"checksum":1443120161,"timestamp":"2024-06-01T17:52:30.842608Z"}]}
{"channel":"book","type":"update","data":[{"symbol":"LTC/USDT","bids":[],"asks":[{"price":83.27709,"qty":0.00000000},{"price":83.37561,"qty":31.24000000}],"checksum":243452640,"timestamp":"2024-06-01T17:52:30.842749Z"}]}
{"channel":"book","type":"update","data":[{"symbol":"LTC/USDT","bids":[],"asks":[{"price":83.28000,"qty":0.00000000},{"price":83.40436,"qty":8.83137436}],"checksum":1621560935,"timestamp":"2024-06-01T17:52:30.843385Z"}]}
{"channel":"book","type":"update","data":[{"symbol":"LTC/USDT","bids":[],"asks":[{"price":83.27721,"qty":0.00000000},{"price":83.40437,"qty":0.30485159}],"checksum":3914620959,"timestamp":"2024-06-01T17:52:30.846323Z"}]}
{"channel":"book","type":"update","data":[{"symbol":"LTC/USDT","bids":[],"asks":[{"price":83.29894,"qty":1.80000000}],"checksum":2334045426,"timestamp":"2024-06-01T17:52:30.846550Z"}]}
{"channel":"book","type":"update","data":[{"symbol":"LTC/USDT","bids":[],"asks":[{"price":83.29000,"qty":35.23445256}],"checksum":122203311,"timestamp":"2024-06-01T17:52:30.847361Z"}]}
{"channel":"book","type":"update","data":[{"symbol":"LTC/USDT","bids":[],"asks":[{"price":83.29894,"qty":0.00000000},{"price":83.40436,"qty":8.83137436}],"checksum":2160537506,"timestamp":"2024-06-01T17:52:30.850518Z"}]}
{"channel":"book","type":"update","data":[{"symbol":"LTC/USDT","bids":[],"asks":[{"price":83.28733,"qty":1.80000000}],"checksum":3037297625,"timestamp":"2024-06-01T17:52:30.850689Z"}]}
{"channel":"book","type":"update","data":[{"symbol":"LTC/USDT","bids":[],"asks":[{"price":83.27689,"qty":0.00000000},{"price":83.40436,"qty":8.83137436}],"checksum":1205686858,"timestamp":"2024-06-01T17:52:30.882077Z"}]}
{"channel":"book","type":"update","data":[{"symbol":"LTC/USDT","bids":[],"asks":[{"price":83.27701,"qty":1.99000000}],"checksum":1585984010,"timestamp":"2024-06-01T17:52:30.882185Z"}]}
{"channel":"book","type":"update","data":[{"symbol":"LTC/USDT","bids":[],"asks":[{"price":83.31121,"qty":0.00000000},{"price":83.40436,"qty":8.83137436}],"checksum":3936234607,"timestamp":"2024-06-01T17:52:30.909959Z"}]}
{"channel":"book","type":"update","data":[{"symbol":"LTC/USDT","bids":[{"price":83.22469,"qty":10.00000000}],"asks":[],"checksum":3210906363,"timestamp":"2024-06-01T17:52:30.912009Z"}]}
{"channel":"book","type":"update","data":[{"symbol":"LTC/USDT","bids":[{"price":83.21670,"qty":13.36451721}],"asks":[],"checksum":2207767349,"timestamp":"2024-06-01T17:52:30.916853Z"}]}
{"channel":"book","type":"update","data":[{"symbol":"LTC/USDT","bids":[],"asks":[{"price":83.27701,"qty":0.00000000},{"price":83.40437,"qty":0.30485159}],"checksum":1389307106,"timestamp":"2024-06-01T17:52:30.937882Z"}]}
{"channel":"book","type":"update","data":[{"symbol":"LTC/USDT","bids":[],"asks":[{"price":83.28713,"qty":1.99000000}],"checksum":3641237187,"timestamp":"2024-06-01T17:52:30.937953Z"}]}
{"channel":"book","type":"update","data":[{"symbol":"LTC/USDT","bids":[],"asks":[{"price":83.28446,"qty":1.80000000}],"checksum":2228279817,"timestamp":"2024-06-01T17:52:30.941033Z"}]}
{"channel":"book","type":"update","data":[{"symbol":"LTC/USDT","bids":[],"asks":[{"price":83.28733,"qty":0.00000000},{"price":83.40436,"qty":8.83137436}],"checksum":3171160380,"timestamp":"2024-06-01T17:52:30.941095Z"}]}
{"channel":"book","type":"update","data":[{"symbol":"LTC/USDT","bids":[],"asks":[{"price":83.30163,"qty":13.36451721}],"checksum":1711166328,"timestamp":"2024-06-01T17:52:30.954634Z"}]}
{"channel":"book","type":"update","data":[{"symbol":"LTC/USDT","bids":[{"price":83.21068,"qty":0.00000000},{"price":83.21003,"qty":3.02951062}],"asks":[],"checksum":1495461762,"timestamp":"2024-06-01T17:52:30.957082Z"}]}
{"channel":"book","type":"update","data":[{"symbol":"LTC/USDT","bids":[{"price":83.21671,"qty":3.60571516}],"asks":[],"checksum":2399430511,"timestamp":"2024-06-01T17:52:30.977371Z"}]}
{"channel":"book","type":"update","data":[{"symbol":"LTC/USDT","bids":[],"asks":[{"price":83.30161,"qty":0.00000000},{"price":83.40436,"qty":8.83137436}],"checksum":1964549998,"timestamp":"2024-06-01T17:52:30.979685Z"}]}
{"channel":"book","type":"update","data":[{"symbol":"LTC/USDT","bids":[{"price":83.21037,"qty":0.00000000},{"price":83.21003,"qty":3.02951062}],"asks":[],"checksum":3330521108,"timestamp":"2024-06-01T17:52:31.028679Z"}]}
{"channel":"book","type":"update","data":[{"symbol":"LTC/USDT","bids":[{"price":83.23351,"qty":7.87361491}],"asks":[],"checksum":2911031733,"timestamp":"2024-06-01T17:52:31.034377Z"}]}
{"channel":"book","type":"update","data":[{"symbol":"LTC/USDT","bids":[{"price":83.21671,"qty":0.00000000},{"price":83.21003,"qty":3.02951062}],"asks":[],"checksum":1179186595,"timestamp":"2024-06-01T17:52:31.042639Z"}]}
{"channel":"book","type":"update","data":[{"symbol":"LTC/USDT","bids":[{"price":83.25394,"qty":23.85306512}],"asks":[],"checksum":2781903261,"timestamp":"2024-06-01T17:52:31.043089Z"}]}
{"channel":"book","type":"update","data":[{"symbol":"LTC/USDT","bids":[],"asks":[{"price":83.32816,"qty":3.02951062}],"checksum":3357084593,"timestamp":"2024-06-01T17:52:31.047281Z"}]}
{"channel":"book","type":"update","data":[{"symbol":"LTC/USDT","bids":[],"asks":[{"price":83.28426,"qty":1.99000000}],"checksum":3793261125,"timestamp":"2024-06-01T17:52:31.056189Z"}]}
{"channel":"book","type":"update","data":[{"symbol":"LTC/USDT","bids":[],"asks":[{"price":83.31387,"qty":2.61000000}],"checksum":1379457879,"timestamp":"2024-06-01T17:52:31.064132Z"}]}
{"channel":"book","type":"update","data":[{"symbol":"LTC/USDT","bids":[],"asks":[{"price":83.28446,"qty":0.00000000},{"price":83.34690,"qty":13.36927600}],"checksum":878769879,"timestamp":"2024-06-01T17:52:31.084091Z"}]}
{"channel":"book","type":"update","data":[{"symbol":"LTC/USDT","bids":[],"asks":[{"price":83.28159,"qty":1.80000000}],"checksum":2676822384,"timestamp":"2024-06-01T17:52:31.084365Z"}]}
{"channel":"book","type":"update","data":[{"symbol":"LTC/USDT","bids":[],"asks":[{"price":83.28713,"qty":0.00000000},{"price":83.34690,"qty":13.36927600}],"checksum":907510184,"timestamp":"2024-06-01T17:52:31.091419Z"}]}
{"channel":"book","type":"update","data":[{"symbol":"LTC/USDT","bids":[{"price":83.21170,"qty":0.00000000},{"price":83.21003,"qty":3.02951062}],"asks":[],"checksum":1615141737,"timestamp":"2024-06-01T17:52:31.100029Z"}]}
{"channel":"book","type":"update","data":[{"symbol":"LTC/USDT","bids":[],"asks":[{"price":83.28139,"qty":1.99000000}],"checksum":481168417,"timestamp":"2024-06-01T17:52:31.121660Z"}]}
{"channel":"book","type":"update","data":[{"symbol":"LTC/USDT","bids":[{"price":83.23351,"qty":0.00000000},{"price":83.21000,"qty":38.46256908}],"asks":[],"checksum":1037016048,"timestamp":"2024-06-01T17:52:31.137573Z"}]}
{"channel":"book","type":"update","data":[{"symbol":"LTC/USDT","bids":[],"asks":[{"price":83.27872,"qty":1.80000000}],"checksum":2186997630,"timestamp":"2024-06-01T17:52:31.150881Z"}]}
{"channel":"book","type":"update","data":[{"symbol":"LTC/USDT","bids":[],"asks":[{"price":83.28159,"qty":0.00000000},{"price":83.34094,"qty":2.34609048}],"checksum":1069800010,"timestamp":"2024-06-01T17:52:31.151150Z"}]}
{"channel":"book","type":"update","data":[{"symbol":"LTC/USDT","bids":[],"asks":[{"price":83.28426,"qty":0.00000000},{"price":83.34690,"qty":13.36927600}],"checksum":2928843324,"timestamp":"2024-06-01T17:52:31.176025Z"}]}
{"channel":"book","type":"update","data":[{"symbol":"LTC/USDT","bids":[{"price":83.25393,"qty":0.00000000},{"price":83.20977,"qty":8.19100000}],"asks":[],"checksum":8880200,"timestamp":"2024-06-01T17:52:31.245251Z"}]}
{"channel":"book","type":"update","data":[{"symbol":"LTC/USDT","bids":[],"asks":[{"price":83.27852,"qty":1.99000000}],"checksum":1315127807,"timestamp":"2024-06-01T17:52:31.252326Z"}]}
{"channel":"book","type":"update","data":[{"symbol":"LTC/USDT","bids":[{"price":83.25394,"qty":0.00000000},{"price":83.20955,"qty":2.29000000}],"asks":[],"checksum":2390105023,"timestamp":"2024-06-01T17:52:31.256202Z"}]}
{"channel":"book","type":"update","data":[{"symbol":"LTC/USDT","bids":[],"asks":[{"price":83.27872,"qty":0.00000000},{"price":83.34690,"qty":13.36927600}],"checksum":1237319778,"timestamp":"2024-06-01T17:52:31.260901Z"}]}
{"channel":"book","type":"update","data":[{"symbol":"LTC/USDT","bids":[],"asks":[{"price":83.27585,"qty":1.80000000}],"checksum":2451957352,"timestamp":"2024-06-01T17:52:31.265137Z"}]}
{"channel":"book","type":"update","data":[{"symbol":"LTC/USDT","bids":[{"price":83.21671,"qty":3.60589189}],"asks":[],"checksum":4281747637,"timestamp":"2024-06-01T17:52:31.266499Z"}]}
{"channel":"book","type":"update","data":[{"symbol":"LTC/USDT","bids":[],"asks":[{"price":83.31027,"qty":18.02895542}],"checksum":2177967648,"timestamp":"2024-06-01T17:52:31.293843Z"}]}
{"channel":"book","type":"update","data":[{"symbol":"LTC/USDT","bids":[],"asks":[{"price":83.28139,"qty":0.00000000},{"price":83.34094,"qty":2.34609048}],"checksum":129339596,"timestamp":"2024-06-01T17:52:31.313369Z"}]}
{"channel":"book","type":"update","data":[{"symbol":"LTC/USDT","bids":[{"price":83.24885,"qty":0.00000000},{"price":83.20955,"qty":2.29000000}],"asks":[],"checksum":2103144162,"timestamp":"2024-06-01T17:52:31.375186Z"}]}
{"channel":"book","type":"update","data":[{"symbol":"LTC/USDT","bids":[],"asks":[{"price":83.27565,"qty":1.99000000}],"checksum":707753478,"timestamp":"2024-06-01T17:52:31.377923Z"}]}
{"channel":"book","type":"update","data":[{"symbol":"LTC/USDT","bids":[],"asks":[{"price":83.27585,"qty":0.00000000},{"price":83.34094,"qty":2.34609048}],"checksum":1326145997,"timestamp":"2024-06-01T17:52:31.381875Z"}]}
{"channel":"book","type":"update","data":[{"symbol":"LTC/USDT","bids":[],"asks":[{"price":83.27298,"qty":1.80000000}],"checksum":624360287,"timestamp":"2024-06-01T17:52:31.381985Z"}]}
{"channel":"book","type":"update","data":[{"symbol":"LTC/USDT","bids":[{"price":83.21671,"qty":0.00000000},{"price":83.20815,"qty":10.00000000}],"asks":[],"checksum":3966317054,"timestamp":"2024-06-01T17:52:31.399195Z"}]}
{"channel":"book","type":"update","data":[{"symbol":"LTC/USDT","bids":[{"price":83.21174,"qty":3.60590598}],"asks":[],"checksum":4090097240,"timestamp":"2024-06-01T17:52:31.399346Z"}]}
{"channel":"book","type":"update","data":[{"symbol":"LTC/USDT","bids":[],"asks":[{"price":83.27852,"qty":0.00000000},{"price":83.34094,"qty":2.34609048}],"checksum":3403130222,"timestamp":"2024-06-01T17:52:31.417312Z"}]}
{"channel":"book","type":"update","data":[{"symbol":"LTC/USDT","bids":[{"price":83.23249,"qty":1.99000000}],"asks":[],"checksum":1982351981,"timestamp":"2024-06-01T17:52:31.417427Z"}]}
{"channel":"book","type":"update","data":[{"symbol":"LTC/USDT","bids":[{"price":83.23321,"qty":16.22555380}],"asks":[],"checksum":1092870132,"timestamp":"2024-06-01T17:52:31.420316Z"}]}
{"channel":"book","type":"update","data":[{"symbol":"LTC/USDT","bids":[{"price":83.23229,"qty":0.00000000},{"price":83.20977,"qty":8.19100000}],"asks":[],"checksum":1709462193,"timestamp":"2024-06-01T17:52:31.423301Z"}]}
{"channel":"book","type":"update","data":[{"symbol":"LTC/USDT","bids":[{"price":83.21174,"qty":0.00000000},{"price":83.20955,"qty":2.29000000}],"asks":[],"checksum":1687558304,"timestamp":"2024-06-01T17:52:31.424545Z"}]}
{"channel":"book","type":"update","data":[{"symbol":"LTC/USDT","bids":[{"price":83.21175,"qty":3.60592240}],"asks":[],"checksum":1310887868,"timestamp":"2024-06-01T17:52:31.428521Z"}]}
{"channel":"book","type":"update","data":[{"symbol":"LTC/USDT","bids":[{"price":83.21174,"qty":3.60592240}],"asks":[],"checksum":1634716608,"timestamp":"2024-06-01T17:52:31.429017Z"}]}
{"channel":"book","type":"update","data":[{"symbol":"LTC/USDT","bids":[{"price":83.21175,"qty":0.00000000},{"price":83.20977,"qty":8.19100000}],"asks":[],"checksum":2994489377,"timestamp":"2024-06-01T17:52:31.432295Z"}]}
{"channel":"book","type":"update","data":[{"symbol":"LTC/USDT","bids":[{"price":83.23241,"qty":10.00000000}],"asks":[],"checksum":95427627,"timestamp":"2024-06-01T17:52:31.490980Z"}]}
{"channel":"book","type":"update","data":[{"symbol":"LTC/USDT","bids":[{"price":83.21174,"qty":0.00000000},{"price":83.20977,"qty":8.19100000}],"asks":[],"checksum":721246295,"timestamp":"2024-06-01T17:52:31.495009Z"}]}
{"channel":"book","type":"update","data":[{"symbol":"LTC/USDT","bids":[{"price":83.23249,"qty":0.00000000},{"price":83.20815,"qty":10.00000000}],"asks":[],"checksum":1421741931,"timestamp":"2024-06-01T17:52:31.496931Z"}]}
{"channel":"book","type":"update","data":[{"symbol":"LTC/USDT","bids":[{"price":83.23341,"qty":1.99000000}],"asks":[],"checksum":4178020934,"timestamp":"2024-06-01T17:52:31.496998Z"}]}
{"channel":"book","type":"update","data":[{"symbol":"LTC/USDT","bids":[],"asks":[{"price":83.27278,"qty":1.99000000}],"checksum":4183001650,"timestamp":"2024-06-01T17:52:31.497178Z"}]}
{"channel":"book","type":"update","data":[{"symbol":"LTC/USDT","bids":[],"asks":[{"price":83.27298,"qty":0.00000000},{"price":83.34094,"qty":2.34609048}],"checksum":1390733072,"timestamp":"2024-06-01T17:52:31.500236Z"}]}
{"channel":"book","type":"update","data":[{"symbol":"LTC/USDT","bids":[],"asks":[{"price":83.27039,"qty":1.80000000}],"checksum":19125153,"timestamp":"2024-06-01T17:52:31.500468Z"}]}
{"channel":"book","type":"update","data":[{"symbol":"LTC/USDT","bids":[{"price":83.21671,"qty":3.60591692}],"asks":[],"checksum":131941015,"timestamp":"2024-06-01T17:52:31.501369Z"}]}
{"channel":"book","type":"update","data":[{"symbol":"LTC/USDT","bids":[{"price":83.21671,"qty":0.00000000},{"price":83.20977,"qty":8.19100000}],"asks":[],"checksum":19125153,"timestamp":"2024-06-01T17:52:31.505545Z"}]}
{"channel":"book","type":"update","data":[{"symbol":"LTC/USDT","bids":[{"price":83.23241,"qty":0.00000000},{"price":83.20815,"qty":10.00000000}],"asks":[],"checksum":229182323,"timestamp":"2024-06-01T17:52:31.521193Z"}]}
{"channel":"book","type":"update","data":[{"symbol":"LTC/USDT","bids":[{"price":83.21174,"qty":3.60593168}],"asks":[],"checksum":1103254603,"timestamp":"2024-06-01T17:52:31.525497Z"}]}
{"channel":"book","type":"update","data":[{"symbol":"LTC/USDT","bids":[{"price":83.21174,"qty":0.00000000},{"price":83.20815,"qty":10.00000000}],"asks":[],"checksum":229182323,"timestamp":"2024-06-01T17:52:31.538353Z"}]}
{"channel":"book","type":"update","data":[{"symbol":"LTC/USDT","bids":[{"price":83.21671,"qty":3.60593168}],"asks":[],"checksum":2461931094,"timestamp":"2024-06-01T17:52:31.538701Z"}]}
{"channel":"book","type":"update","data":[{"symbol":"LTC/USDT","bids":[{"price":83.21015,"qty":9.76343889}],"asks":[],"checksum":1762280594,"timestamp":"2024-06-01T17:52:31.540784Z"}]}
{"channel":"book","type":"update","data":[{"symbol":"LTC/USDT","bids":[],"asks":[{"price":83.27278,"qty":0.00000000},{"price":83.34094,"qty":2.34609048}],"checksum":4289020274,"timestamp":"2024-06-01T17:52:31.545062Z"}]}
{"channel":"book","type":"update","data":[{"symbol":"LTC/USDT","bids":[{"price":83.22959,"qty":0.00000000},{"price":83.20977,"qty":8.19100000}],"asks":[],"checksum":1462751113,"timestamp":"2024-06-01T17:52:31.545112Z"}]}
{"channel":"book","type":"update","data":[{"symbol":"LTC/USDT","bids":[{"price":83.21671,"qty":0.00000000},{"price":83.20815,"qty":10.00000000}],"asks":[],"checksum":1130960904,"timestamp":"2024-06-01T17:52:31.549138Z"}]}
{"channel":"book","type":"update","data":[{"symbol":"LTC/USDT","bids":[{"price":83.21174,"qty":3.60591865}],"asks":[],"checksum":1505709482,"timestamp":"2024-06-01T17:52:31.549389Z"}]}
{"channel":"book","type":"update","data":[{"symbol":"LTC/USDT","bids":[],"asks":[{"price":83.31027,"qty":0.00000000},{"price":83.34690,"qty":13.36927600}],"checksum":3175907690,"timestamp":"2024-06-01T17:52:31.554066Z"}]}
{"channel":"book","type":"update","data":[{"symbol":"LTC/USDT","bids":[{"price":83.21174,"qty":0.00000000},{"price":83.20815,"qty":10.00000000}],"asks":[],"checksum":3639159156,"timestamp":"2024-06-01T17:52:31.559292Z"}]}
{"channel":"book","type":"update","data":[{"symbol":"LTC/USDT","bids":[{"price":83.21671,"qty":3.60591800}],"asks":[],"checksum":102214600,"timestamp":"2024-06-01T17:52:31.559556Z"}]}
{"channel":"book","type":"update","data":[{"symbol":"LTC/USDT","bids":[{"price":83.23424,"qty":16.22534911}],"asks":[],"checksum":2496528688,"timestamp":"2024-06-01T17:52:31.635260Z"}]}
{"channel":"book","type":"update","data":[{"symbol":"LTC/USDT","bids":[{"price":83.23321,"qty":0.00000000},{"price":83.20977,"qty":8.19100000}],"asks":[],"checksum":2793726968,"timestamp":"2024-06-01T17:52:31.638347Z"}]}
{"channel":"book","type":"update","data":[{"symbol":"LTC/USDT","bids":[],"asks":[{"price":83.27039,"qty":0.00000000},{"price":83.38235,"qty":31.23800000}],"checksum":3194085387,"timestamp":"2024-06-01T17:52:31.703700Z"}]}
{"channel":"book","type":"update","data":[{"symbol":"LTC/USDT","bids":[],"asks":[{"price":83.27458,"qty":1.80000000}],"checksum":2148615868,"timestamp":"2024-06-01T17:52:31.703821Z"}]}
{"channel":"book","type":"update","data":[{"symbol":"LTC/USDT","bids":[{"price":83.25570,"qty":18.02841396}],"asks":[],"checksum":3301669127,"timestamp":"2024-06-01T17:52:31.867081Z"}]}
{"channel":"book","type":"update","data":[{"symbol":"LTC/USDT","bids":[{"price":83.24863,"qty":9.01428758}],"asks":[],"checksum":1974331766,"timestamp":"2024-06-01T17:52:31.942135Z"}]}
{"channel":"book","type":"update","data":[{"symbol":"LTC/USDT","bids":[],"asks":[{"price":83.30935,"qty":16.22552896}],"checksum":337023096,"timestamp":"2024-06-01T17:52:31.949327Z"}]}
{"channel":"book","type":"update","data":[{"symbol":"LTC/USDT","bids":[],"asks":[{"price":83.29297,"qty":10.00000000}],"checksum":2272570149,"timestamp":"2024-06-01T17:52:32.211767Z"}]}
{"channel":"book","type":"update","data":[{"symbol":"LTC/USDT","bids":[{"price":83.24599,"qty":23.85306512}],"asks":[],"checksum":2511205501,"timestamp":"2024-06-01T17:52:32.215576Z"}]}
{"channel":"book","type":"update","data":[{"symbol":"LTC/USDT","bids":[{"price":83.21671,"qty":0.00000000},{"price":83.21003,"qty":3.02951062}],"asks":[],"checksum":1514228576,"timestamp":"2024-06-01T17:52:32.219212Z"}]}
{"channel":"book","type":"update","data":[{"symbol":"LTC/USDT","bids":[],"asks":[{"price":83.30935,"qty":0.00000000},{"price":83.34094,"qty":2.34609048}],"checksum":869396779,"timestamp":"2024-06-01T17:52:32.231420Z"}]}
{"channel":"book","type":"update","data":[{"symbol":"LTC/USDT","bids":[{"price":83.25570,"qty":0.00000000},{"price":83.21000,"qty":38.46256908}],"asks":[],"checksum":1028658555,"timestamp":"2024-06-01T17:52:32.466845Z"}]}
{"channel":"book","type":"update","data":[{"symbol":"LTC/USDT","bids":[],"asks":[{"price":83.27438,"qty":1.99000000}],"checksum":3781291397,"timestamp":"2024-06-01T17:52:32.472737Z"}]}
{"channel":"book","type":"update","data":[{"symbol":"LTC/USDT","bids":[{"price":83.25404,"qty":18.02859391}],"asks":[],"checksum":3276315054,"timestamp":"2024-06-01T17:52:32.507269Z"}]}
{"channel":"book","type":"update","data":[{"symbol":"LTC/USDT","bids":[],"asks":[{"price":83.27565,"qty":0.00000000},{"price":83.34094,"qty":2.34609048}],"checksum":1212161250,"timestamp":"2024-06-01T17:52:32.512327Z"}]}
{"channel":"book","type":"update","data":[{"symbol":"LTC/USDT","bids":[],"asks":[{"price":83.27458,"qty":0.00000000},{"price":83.34690,"qty":13.36927600}],"checksum":1627685063,"timestamp":"2024-06-01T17:52:32.515035Z"}]}
{"channel":"book","type":"update","data":[{"symbol":"LTC/USDT","bids":[],"asks":[{"price":83.28733,"qty":1.80000000}],"checksum":91304893,"timestamp":"2024-06-01T17:52:32.515179Z"}]}
{"channel":"book","type":"update","data":[{"symbol":"LTC/USDT","bids":[{"price":83.24863,"qty":0.00000000},{"price":83.21000,"qty":38.46256908}],"asks":[],"checksum":4214200437,"timestamp":"2024-06-01T17:52:32.541715Z"}]}
{"channel":"book","type":"update","data":[{"symbol":"LTC/USDT","bids":[],"asks":[{"price":83.28721,"qty":10.00000000}],"checksum":357668701,"timestamp":"2024-06-01T17:52:32.546334Z"}]}
{"channel":"book","type":"update","data":[{"symbol":"LTC/USDT","bids":[],"asks":[{"price":83.28733,"qty":0.00000000},{"price":83.34094,"qty":2.34609048}],"checksum":4260481407,"timestamp":"2024-06-01T17:52:32.548946Z"}]}
{"channel":"book","type":"update","data":[{"symbol":"LTC/USDT","bids":[],"asks":[{"price":83.28454,"qty":1.80000000}],"checksum":1588631081,"timestamp":"2024-06-01T17:52:32.549083Z"}]}
{"channel":"book","type":"update","data":[{"symbol":"LTC/USDT","bids":[],"asks":[{"price":83.31501,"qty":23.85306512}],"checksum":1265640860,"timestamp":"2024-06-01T17:52:32.560474Z"}]}
{"channel":"book","type":"update","data":[{"symbol":"LTC/USDT","bids":[{"price":83.24897,"qty":9.01433419}],"asks":[],"checksum":1301248883,"timestamp":"2024-06-01T17:52:32.582816Z"}]}
{"channel":"book","type":"update","data":[{"symbol":"LTC/USDT","bids":[],"asks":[{"price":83.28721,"qty":0.00000000},{"price":83.32816,"qty":3.02951062}],"checksum":224294278,"timestamp":"2024-06-01T17:52:32.587309Z"}]}
{"channel":"book","type":"update","data":[{"symbol":"LTC/USDT","bids":[],"asks":[{"price":83.31501,"qty":0.00000000},{"price":83.34094,"qty":2.34609048}],"checksum":3001573176,"timestamp":"2024-06-01T17:52:32.848315Z"}]}
{"channel":"book","type":"update","data":[{"symbol":"LTC/USDT","bids":[{"price":83.21173,"qty":0.00000000},{"price":83.21000,"qty":38.46256908}],"asks":[],"checksum":399531643,"timestamp":"2024-06-01T17:52:33.005001Z"}]}
{"channel":"book","type":"update","data":[{"symbol":"LTC/USDT","bids":[{"price":83.21016,"qty":0.86311084}],"asks":[],"checksum":1953409808,"timestamp":"2024-06-01T17:52:33.006501Z"}]}
{"channel":"book","type":"update","data":[{"symbol":"LTC/USDT","bids":[{"price":83.25405,"qty":23.85306512}],"asks":[],"checksum":4194862619,"timestamp":"2024-06-01T17:52:33.012592Z"}]}
{"channel":"book","type":"update","data":[{"symbol":"LTC/USDT","bids":[],"asks":[{"price":83.27438,"qty":0.00000000},{"price":83.34690,"qty":13.36927600}],"checksum":3742449891,"timestamp":"2024-06-01T17:52:33.021388Z"}]}
{"channel":"book","type":"update","data":[{"symbol":"LTC/USDT","bids":[{"price":83.25404,"qty":0.00000000},{"price":83.21003,"qty":3.02951062}],"asks":[],"checksum":1821440939,"timestamp":"2024-06-01T17:52:33.032421Z"}]}
{"channel":"book","type":"update","data":[{"symbol":"LTC/USDT","bids":[{"price":83.25275,"qty":18.02884286}],"asks":[],"checksum":2107339161,"timestamp":"2024-06-01T17:52:33.072643Z"}]}
{"channel":"book","type":"update","data":[{"symbol":"LTC/USDT","bids":[{"price":83.24599,"qty":0.00000000},{"price":83.21003,"qty":3.02951062}],"asks":[],"checksum":1916015669,"timestamp":"2024-06-01T17:52:33.076784Z"}]}
{"channel":"book","type":"update","data":[{"symbol":"LTC/USDT","bids":[],"asks":[{"price":83.28988,"qty":10.00000000}],"checksum":3926831600,"timestamp":"2024-06-01T17:52:33.077376Z"}]}
{"channel":"book","type":"update","data":[{"symbol":"LTC/USDT","bids":[],"asks":[{"price":83.28434,"qty":1.99000000}],"checksum":1052530725,"timestamp":"2024-06-01T17:52:33.077416Z"}]}
{"channel":"book","type":"update","data":[{"symbol":"LTC/USDT","bids":[],"asks":[{"price":83.28454,"qty":0.00000000},{"price":83.34094,"qty":2.34609048}],"checksum":3791521403,"timestamp":"2024-06-01T17:52:33.080434Z"}]}
{"channel":"book","type":"update","data":[{"symbol":"LTC/USDT","bids":[],"asks":[{"price":83.28167,"qty":1.80000000}],"checksum":3490126003,"timestamp":"2024-06-01T17:52:33.080778Z"}]}
{"channel":"book","type":"update","data":[{"symbol":"LTC/USDT","bids":[],"asks":[{"price":83.28434,"qty":0.00000000},{"price":83.34094,"qty":2.34609048}],"checksum":2954365111,"timestamp":"2024-06-01T17:52:33.086796Z"}]}
{"channel":"book","type":"update","data":[{"symbol":"LTC/USDT","bids":[],"asks":[{"price":83.28167,"qty":0.00000000},{"price":83.34690,"qty":13.36927600}],"checksum":1858733979,"timestamp":"2024-06-01T17:52:33.090256Z"}]}
{"channel":"book","type":"update","data":[{"symbol":"LTC/USDT","bids":[],"asks":[{"price":83.31490,"qty":23.85306512}],"checksum":1584508348,"timestamp":"2024-06-01T17:52:33.178902Z"}]}
{"channel":"book","type":"update","data":[{"symbol":"LTC/USDT","bids":[{"price":83.24897,"qty":0.00000000},{"price":83.21000,"qty":38.46256908}],"asks":[],"checksum":1344669450,"timestamp":"2024-06-01T17:52:33.182225Z"}]}
{"channel":"book","type":"update","data":[{"symbol":"LTC/USDT","bids":[],"asks":[{"price":83.32262,"qty":23.85306512}],"checksum":2158862890,"timestamp":"2024-06-01T17:52:33.186088Z"}]}
{"channel":"book","type":"update","data":[{"symbol":"LTC/USDT","bids":[],"asks":[{"price":83.29297,"qty":0.00000000},{"price":83.34094,"qty":2.34609048}],"checksum":2633964763,"timestamp":"2024-06-01T17:52:33.188220Z"}]}
{"channel":"book","type":"update","data":[{"symbol":"LTC/USDT","bids":[{"price":83.24813,"qty":9.01438600}],"asks":[],"checksum":4109773202,"timestamp":"2024-06-01T17:52:33.222175Z"}]}
{"channel":"book","type":"update","data":[{"symbol":"LTC/USDT","bids":[{"price":83.25405,"qty":0.00000000},{"price":83.21000,"qty":38.46256908}],"asks":[],"checksum":1037755414,"timestamp":"2024-06-01T17:52:33.509145Z"}]}
{"channel":"book","type":"update","data":[{"symbol":"LTC/USDT","bids":[],"asks":[{"price":83.28968,"qty":1.99000000}],"checksum":936463194,"timestamp":"2024-06-01T17:52:33.513917Z"}]}
{"channel":"book","type":"update","data":[{"symbol":"LTC/USDT","bids":[{"price":83.21671,"qty":3.60584494}],"asks":[],"checksum":2450691941,"timestamp":"2024-06-01T17:52:33.513977Z"}]}
{"channel":"book","type":"update","data":[{"symbol":"LTC/USDT","bids":[{"price":83.25275,"qty":0.00000000},{"price":83.21000,"qty":38.46256908}],"asks":[],"checksum":4010003043,"timestamp":"2024-06-01T17:52:33.672543Z"}]}
{"channel":"book","type":"update","data":[{"symbol":"LTC/USDT","bids":[{"price":83.25322,"qty":18.02878647}],"asks":[],"checksum":269641851,"timestamp":"2024-06-01T17:52:33.712878Z"}]}
{"channel":"book","type":"update","data":[{"symbol":"LTC/USDT","bids":[],"asks":[{"price":83.28701,"qty":1.80000000}],"checksum":1495968605,"timestamp":"2024-06-01T17:52:33.715662Z"}]}
{"channel":"book","type":"update","data":[{"symbol":"LTC/USDT","bids":[{"price":83.24813,"qty":0.00000000},{"price":83.21000,"qty":38.46256908}],"asks":[],"checksum":2334167908,"timestamp":"2024-06-01T17:52:33.747855Z"}]}
{"channel":"book","type":"update","data":[{"symbol":"LTC/USDT","bids":[],"asks":[{"price":83.28956,"qty":10.00000000}],"checksum":91581838,"timestamp":"2024-06-01T17:52:33.752885Z"}]}
{"channel":"book","type":"update","data":[{"symbol":"LTC/USDT","bids":[{"price":83.24814,"qty":9.01439256}],"asks":[],"checksum":601019538,"timestamp":"2024-06-01T17:52:33.788464Z"}]}
{"channel":"book","type":"update","data":[{"symbol":"LTC/USDT","bids":[],"asks":[{"price":83.28988,"qty":0.00000000},{"price":83.32787,"qty":36.00236031}],"checksum":4221792357,"timestamp":"2024-06-01T17:52:33.792682Z"}]}
{"channel":"book","type":"update","data":[{"symbol":"LTC/USDT","bids":[{"price":83.25323,"qty":23.85306512}],"asks":[],"checksum":1536119844,"timestamp":"2024-06-01T17:52:34.020546Z"}]}
{"channel":"book","type":"update","data":[{"symbol":"LTC/USDT","bids":[{"price":83.21671,"qty":0.00000000},{"price":83.21003,"qty":3.02951062}],"asks":[],"checksum":3580027318,"timestamp":"2024-06-01T17:52:34.025423Z"}]}
{"channel":"book","type":"update","data":[{"symbol":"LTC/USDT","bids":[{"price":83.25322,"qty":0.00000000},{"price":83.21000,"qty":38.46256908}],"asks":[],"checksum":1797260862,"timestamp":"2024-06-01T17:52:34.408914Z"}]}
{"channel":"book","type":"update","data":[{"symbol":"LTC/USDT","bids":[{"price":83.25323,"qty":0.00000000},{"price":83.20977,"qty":8.19100000}],"asks":[],"checksum":3634257681,"timestamp":"2024-06-01T17:52:34.412946Z"}]}
{"channel":"book","type":"update","data":[{"symbol":"LTC/USDT","bids":[{"price":83.21671,"qty":3.60589161}],"asks":[],"checksum":2103939591,"timestamp":"2024-06-01T17:52:34.417239Z"}]}
{"channel":"book","type":"update","data":[{"symbol":"LTC/USDT","bids":[{"price":83.25222,"qty":18.02889661}],"asks":[],"checksum":2678076868,"timestamp":"2024-06-01T17:52:34.449197Z"}]}
{"channel":"book","type":"update","data":[{"symbol":"LTC/USDT","bids":[{"price":83.24814,"qty":0.00000000},{"price":83.21000,"qty":38.46256908}],"asks":[],"checksum":2119597926,"timestamp":"2024-06-01T17:52:34.485691Z"}]}
{"channel":"book","type":"update","data":[{"symbol":"LTC/USDT","bids":[],"asks":[{"price":83.28681,"qty":1.99000000}],"checksum":2017960347,"timestamp":"2024-06-01T17:52:34.490342Z"}]}
{"channel":"book","type":"update","data":[{"symbol":"LTC/USDT","bids":[],"asks":[{"price":83.28701,"qty":0.00000000},{"price":83.32787,"qty":36.00236031}],"checksum":2409151910,"timestamp":"2024-06-01T17:52:34.493120Z"}]}
{"channel":"book","type":"update","data":[{"symbol":"LTC/USDT","bids":[],"asks":[{"price":83.28414,"qty":1.80000000}],"checksum":2330613887,"timestamp":"2024-06-01T17:52:34.493293Z"}]}
{"channel":"book","type":"update","data":[{"symbol":"LTC/USDT","bids":[{"price":83.24713,"qty":9.01444947}],"asks":[],"checksum":4006536647,"timestamp":"2024-06-01T17:52:34.525936Z"}]}
{"channel":"book","type":"update","data":[{"symbol":"LTC/USDT","bids":[],"asks":[{"price":83.28681,"qty":0.00000000},{"price":83.32787,"qty":36.00236031}],"checksum":3167578140,"timestamp":"2024-06-01T17:52:34.530764Z"}]}
{"channel":"book","type":"update","data":[{"symbol":"LTC/USDT","bids":[],"asks":[{"price":83.28669,"qty":10.00000000}],"checksum":1357044624,"timestamp":"2024-06-01T17:52:34.531105Z"}]}
{"channel":"book","type":"update","data":[{"symbol":"LTC/USDT","bids":[],"asks":[{"price":83.28669,"qty":0.00000000},{"price":83.32787,"qty":36.00236031}],"checksum":3167578140,"timestamp":"2024-06-01T17:52:34.711302Z"}]}
{"channel":"book","type":"update","data":[{"symbol":"LTC/USDT","bids":[{"price":83.25222,"qty":0.00000000},{"price":83.21000,"qty":38.46256908}],"asks":[],"checksum":2819239617,"timestamp":"2024-06-01T17:52:34.979310Z"}]}
{"channel":"book","type":"update","data":[{"symbol":"LTC/USDT","bids":[{"price":83.24713,"qty":0.00000000},{"price":83.20977,"qty":8.19100000}],"asks":[],"checksum":2257488345,"timestamp":"2024-06-01T17:52:35.129680Z"}]}
{"channel":"book","type":"update","data":[{"symbol":"LTC/USDT","bids":[{"price":83.23425,"qty":23.85306512}],"asks":[],"checksum":3690868458,"timestamp":"2024-06-01T17:52:35.133192Z"}]}
{"channel":"book","type":"update","data":[{"symbol":"LTC/USDT","bids":[{"price":83.23453,"qty":16.22529612}],"asks":[],"checksum":2096399888,"timestamp":"2024-06-01T17:52:35.135975Z"}]}
{"channel":"book","type":"update","data":[{"symbol":"LTC/USDT","bids":[{"price":83.23424,"qty":0.00000000},{"price":83.21000,"qty":38.46256908}],"asks":[],"checksum":1350214083,"timestamp":"2024-06-01T17:52:35.138650Z"}]}
{"channel":"book","type":"update","data":[{"symbol":"LTC/USDT","bids":[{"price":83.21671,"qty":0.00000000},{"price":83.20977,"qty":8.19100000}],"asks":[],"checksum":4119030997,"timestamp":"2024-06-01T17:52:35.140253Z"}]}
{"channel":"book","type":"update","data":[{"symbol":"LTC/USDT","bids":[{"price":83.21671,"qty":3.60589452}],"asks":[],"checksum":861265149,"timestamp":"2024-06-01T17:52:35.144390Z"}]}
{"channel":"book","type":"update","data":[{"symbol":"LTC/USDT","bids":[{"price":83.21016,"qty":0.00000000},{"price":83.20977,"qty":8.19100000}],"asks":[],"checksum":2381360835,"timestamp":"2024-06-01T17:52:35.551405Z"}]}
{"channel":"book","type":"update","data":[{"symbol":"LTC/USDT","bids":[{"price":83.21672,"qty":0.86311084}],"asks":[],"checksum":3060663353,"timestamp":"2024-06-01T17:52:35.554102Z"}]}
{"channel":"book","type":"update","data":[{"symbol":"LTC/USDT","bids":[{"price":83.21016,"qty":3.61116098}],"asks":[],"checksum":2658483158,"timestamp":"2024-06-01T17:52:35.554118Z"}]}
{"channel":"book","type":"update","data":[{"symbol":"LTC/USDT","bids":[{"price":83.23425,"qty":24.09344012}],"asks":[],"checksum":1060417625,"timestamp":"2024-06-01T17:52:35.554207Z"}]}
{"channel":"book","type":"update","data":[{"symbol":"LTC/USDT","bids":[{"price":83.21673,"qty":3.60588800}],"asks":[],"checksum":2859989325,"timestamp":"2024-06-01T17:52:35.559628Z"}]}
{"channel":"book","type":"update","data":[{"symbol":"LTC/USDT","bids":[{"price":83.21671,"qty":0.00000000},{"price":83.21003,"qty":3.02951062}],"asks":[],"checksum":3537034249,"timestamp":"2024-06-01T17:52:35.559646Z"}]}
{"channel":"book","type":"update","data":[{"symbol":"LTC/USDT","bids":[],"asks":[{"price":83.28394,"qty":1.99000000}],"checksum":3454000865,"timestamp":"2024-06-01T17:52:35.560409Z"}]}
{"channel":"book","type":"update","data":[{"symbol":"LTC/USDT","bids":[{"price":83.23473,"qty":1.99000000}],"asks":[],"checksum":1176092358,"timestamp":"2024-06-01T17:52:35.560433Z"}]}
{"channel":"book","type":"update","data":[{"symbol":"LTC/USDT","bids":[],"asks":[{"price":83.28414,"qty":0.00000000},{"price":83.32787,"qty":36.00236031}],"checksum":2008649434,"timestamp":"2024-06-01T17:52:35.563050Z"}]}
{"channel":"book","type":"update","data":[{"symbol":"LTC/USDT","bids":[{"price":83.23473,"qty":18.21525642}],"asks":[],"checksum":3159887314,"timestamp":"2024-06-01T17:52:35.563335Z"}]}
{"channel":"book","type":"update","data":[{"symbol":"LTC/USDT","bids":[],"asks":[{"price":83.28127,"qty":1.80000000}],"checksum":2985551774,"timestamp":"2024-06-01T17:52:35.563412Z"}]}
{"channel":"book","type":"update","data":[{"symbol":"LTC/USDT","bids":[{"price":83.23453,"qty":0.00000000},{"price":83.21003,"qty":3.02951062}],"asks":[],"checksum":1793249207,"timestamp":"2024-06-01T17:52:35.565741Z"}]}
{"channel":"book","type":"update","data":[{"symbol":"LTC/USDT","bids":[{"price":83.21673,"qty":0.00000000},{"price":83.21000,"qty":38.46256908}],"asks":[],"checksum":1303071882,"timestamp":"2024-06-01T17:52:35.567991Z"}]}
{"channel":"book","type":"update","data":[{"symbol":"LTC/USDT","bids":[{"price":83.21674,"qty":3.60588801}],"asks":[],"checksum":3282403962,"timestamp":"2024-06-01T17:52:35.572288Z"}]}
{"channel":"book","type":"update","data":[{"symbol":"LTC/USDT","bids":[{"price":83.21673,"qty":3.60588801}],"asks":[],"checksum":3057648029,"timestamp":"2024-06-01T17:52:35.572471Z"}]}
{"channel":"book","type":"update","data":[{"symbol":"LTC/USDT","bids":[{"price":83.21674,"qty":0.00000000},{"price":83.21003,"qty":3.02951062}],"asks":[],"checksum":119737540,"timestamp":"2024-06-01T17:52:35.576196Z"}]}
{"channel":"book","type":"update","data":[{"symbol":"LTC/USDT","bids":[],"asks":[{"price":83.28394,"qty":0.00000000},{"price":83.32787,"qty":36.00236031}],"checksum":3038311933,"timestamp":"2024-06-01T17:52:35.587858Z"}]}
{"channel":"book","type":"update","data":[{"symbol":"LTC/USDT","bids":[{"price":83.23341,"qty":0.00000000},{"price":83.21000,"qty":38.46256908}],"asks":[],"checksum":93926779,"timestamp":"2024-06-01T17:52:35.587870Z"}]}
{"channel":"book","type":"update","data":[{"symbol":"LTC/USDT","bids":[],"asks":[{"price":83.28127,"qty":0.00000000},{"price":83.32816,"qty":3.02951062}],"checksum":4091048271,"timestamp":"2024-06-01T17:52:35.590495Z"}]}
{"channel":"book","type":"update","data":[{"symbol":"LTC/USDT","bids":[],"asks":[{"price":83.28689,"qty":1.80000000}],"checksum":396745246,"timestamp":"2024-06-01T17:52:35.590716Z"}]}
{"channel":"book","type":"update","data":[{"symbol":"LTC/USDT","bids":[{"price":83.25196,"qty":18.02896214}],"asks":[],"checksum":4135904713,"timestamp":"2024-06-01T17:52:35.630401Z"}]}
{"channel":"book","type":"update","data":[{"symbol":"LTC/USDT","bids":[{"price":83.21673,"qty":0.00000000},{"price":83.21000,"qty":38.46256908}],"asks":[],"checksum":871077854,"timestamp":"2024-06-01T17:52:35.634862Z"}]}
{"channel":"book","type":"update","data":[{"symbol":"LTC/USDT","bids":[{"price":83.24688,"qty":9.01448107}],"asks":[],"checksum":1197502754,"timestamp":"2024-06-01T17:52:35.697191Z"}]}
{"channel":"book","type":"update","data":[{"symbol":"LTC/USDT","bids":[{"price":83.25196,"qty":0.00000000},{"price":83.21000,"qty":38.46256908}],"asks":[],"checksum":918705940,"timestamp":"2024-06-01T17:52:36.202180Z"}]}
{"channel":"book","type":"update","data":[{"symbol":"LTC/USDT","bids":[{"price":83.24689,"qty":23.85306512}],"asks":[],"checksum":1895582590,"timestamp":"2024-06-01T17:52:36.206166Z"}]}
{"channel":"book","type":"update","data":[{"symbol":"LTC/USDT","bids":[{"price":83.25234,"qty":18.02889718}],"asks":[],"checksum":1525152949,"timestamp":"2024-06-01T17:52:36.242499Z"}]}
{"channel":"book","type":"update","data":[{"symbol":"LTC/USDT","bids":[{"price":83.23425,"qty":0.24037500}],"asks":[],"checksum":2874556771,"timestamp":"2024-06-01T17:52:36.246905Z"}]}
{"channel":"book","type":"update","data":[{"symbol":"LTC/USDT","bids":[{"price":83.24688,"qty":0.00000000},{"price":83.21003,"qty":3.02951062}],"asks":[],"checksum":2934902570,"timestamp":"2024-06-01T17:52:36.270526Z"}]}
{"channel":"book","type":"update","data":[{"symbol":"LTC/USDT","bids":[{"price":83.24808,"qty":9.01440131}],"asks":[],"checksum":2771990859,"timestamp":"2024-06-01T17:52:36.311052Z"}]}
{"channel":"book","type":"update","data":[{"symbol":"LTC/USDT","bids":[{"price":83.25235,"qty":23.85306512}],"asks":[],"checksum":1159301123,"timestamp":"2024-06-01T17:52:36.315023Z"}]}
{"channel":"book","type":"update","data":[{"symbol":"LTC/USDT","bids":[{"price":83.24689,"qty":0.00000000},{"price":83.21015,"qty":9.76343889}],"asks":[],"checksum":1520968470,"timestamp":"2024-06-01T17:52:36.507601Z"}]}
{"channel":"book","type":"update","data":[{"symbol":"LTC/USDT","bids":[],"asks":[{"price":83.28669,"qty":1.99000000}],"checksum":991942181,"timestamp":"2024-06-01T17:52:36.514277Z"}]}
{"channel":"book","type":"update","data":[{"symbol":"LTC/USDT","bids":[],"asks":[{"price":83.28968,"qty":0.00000000},{"price":83.32787,"qty":36.00236031}],"checksum":3310526740,"timestamp":"2024-06-01T17:52:36.585993Z"}]}
{"channel":"book","type":"update","data":[{"symbol":"LTC/USDT","bids":[],"asks":[{"price":83.28677,"qty":10.00000000}],"checksum":2045395870,"timestamp":"2024-06-01T17:52:36.590723Z"}]}
{"channel":"book","type":"update","data":[{"symbol":"LTC/USDT","bids":[],"asks":[{"price":83.28956,"qty":0.00000000},{"price":83.32787,"qty":36.00236031}],"checksum":3455434150,"timestamp":"2024-06-01T17:52:36.710899Z"}]}
{"channel":"book","type":"update","data":[{"symbol":"LTC/USDT","bids":[{"price":83.25234,"qty":0.00000000},{"price":83.21003,"qty":3.02951062}],"asks":[],"checksum":2261461984,"timestamp":"2024-06-01T17:52:36.809379Z"}]}
{"channel":"book","type":"update","data":[{"symbol":"LTC/USDT","bids":[{"price":83.25235,"qty":0.00000000},{"price":83.21000,"qty":38.46256908}],"asks":[],"checksum":1212466658,"timestamp":"2024-06-01T17:52:36.813472Z"}]}
{"channel":"book","type":"update","data":[{"symbol":"LTC/USDT","bids":[{"price":83.21673,"qty":3.60590222}],"asks":[],"checksum":2651007083,"timestamp":"2024-06-01T17:52:36.818574Z"}]}
{"channel":"book","type":"update","data":[{"symbol":"LTC/USDT","bids":[{"price":83.25316,"qty":18.02874418}],"asks":[],"checksum":1505920769,"timestamp":"2024-06-01T17:52:36.849608Z"}]}
{"channel":"book","type":"update","data":[{"symbol":"LTC/USDT","bids":[{"price":83.25316,"qty":0.00000000},{"price":83.21003,"qty":3.02951062}],"asks":[],"checksum":2651007083,"timestamp":"2024-06-01T17:52:37.346903Z"}]}
{"channel":"book","type":"update","data":[{"symbol":"LTC/USDT","bids":[{"price":83.24809,"qty":23.85306512}],"asks":[],"checksum":458404785,"timestamp":"2024-06-01T17:52:37.350849Z"}]}
{"channel":"book","type":"update","data":[{"symbol":"LTC/USDT","bids":[{"price":83.21673,"qty":0.00000000},{"price":83.21003,"qty":3.02951062}],"asks":[],"checksum":2650526554,"timestamp":"2024-06-01T17:52:37.354725Z"}]}
{"channel":"book","type":"update","data":[{"symbol":"LTC/USDT","bids":[{"price":83.24808,"qty":0.00000000},{"price":83.21000,"qty":38.46256908}],"asks":[],"checksum":392997725,"timestamp":"2024-06-01T17:52:37.446940Z"}]}
{"channel":"book","type":"update","data":[{"symbol":"LTC/USDT","bids":[{"price":83.24809,"qty":0.00000000},{"price":83.20977,"qty":8.19100000}],"asks":[],"checksum":4090326825,"timestamp":"2024-06-01T17:52:37.450782Z"}]}
{"channel":"book","type":"update","data":[{"symbol":"LTC/USDT","bids":[{"price":83.21673,"qty":3.60589321}],"asks":[],"checksum":3614015044,"timestamp":"2024-06-01T17:52:37.452083Z"}]}
{"channel":"book","type":"update","data":[{"symbol":"LTC/USDT","bids":[{"price":83.24776,"qty":9.01442684}],"asks":[],"checksum":635679310,"timestamp":"2024-06-01T17:52:37.486943Z"}]}
{"channel":"book","type":"update","data":[{"symbol":"LTC/USDT","bids":[],"asks":[{"price":83.28657,"qty":1.99000000}],"checksum":2174568824,"timestamp":"2024-06-01T17:52:37.492025Z"}]}
{"channel":"book","type":"update","data":[{"symbol":"LTC/USDT","bids":[],"asks":[{"price":83.28669,"qty":0.00000000},{"price":83.32787,"qty":36.00236031}],"checksum":3647318361,"timestamp":"2024-06-01T17:52:37.588559Z"}]}
{"channel":"book","type":"update","data":[{"symbol":"LTC/USDT","bids":[{"price":83.25278,"qty":18.02888846}],"asks":[],"checksum":1586516732,"timestamp":"2024-06-01T17:52:37.955565Z"}]}
{"channel":"book","type":"update","data":[{"symbol":"LTC/USDT","bids":[{"price":83.24776,"qty":0.00000000},{"price":83.21003,"qty":3.02951062}],"asks":[],"checksum":4144062855,"timestamp":"2024-06-01T17:52:37.983474Z"}]}
{"channel":"book","type":"update","data":[{"symbol":"LTC/USDT","bids":[{"price":83.25279,"qty":23.85306512}],"asks":[],"checksum":3133336592,"timestamp":"2024-06-01T17:52:38.012038Z"}]}
{"channel":"book","type":"update","data":[{"symbol":"LTC/USDT","bids":[{"price":83.21673,"qty":0.00000000},{"price":83.21003,"qty":3.02951062}],"asks":[],"checksum":3293818884,"timestamp":"2024-06-01T17:52:38.018257Z"}]}
{"channel":"book","type":"update","data":[{"symbol":"LTC/USDT","bids":[{"price":83.24770,"qty":9.01432505}],"asks":[],"checksum":3967177370,"timestamp":"2024-06-01T17:52:38.023767Z"}]}
{"channel":"book","type":"update","data":[{"symbol":"LTC/USDT","bids":[],"asks":[{"price":83.31040,"qty":12.12017386}],"checksum":2421937124,"timestamp":"2024-06-01T17:52:38.033253Z"}]}
{"channel":"book","type":"update","data":[{"symbol":"LTC/USDT","bids":[],"asks":[{"price":83.31490,"qty":0.00000000},{"price":83.32787,"qty":36.00236031}],"checksum":1337453741,"timestamp":"2024-06-01T17:52:38.117197Z"}]}
{"channel":"book","type":"update","data":[{"symbol":"LTC/USDT","bids":[{"price":83.21672,"qty":0.00000000},{"price":83.21003,"qty":3.02951062}],"asks":[],"checksum":3385921224,"timestamp":"2024-06-01T17:52:38.236269Z"}]}
{"channel":"book","type":"update","data":[{"symbol":"LTC/USDT","bids":[{"price":83.21016,"qty":0.00000000},{"price":83.21000,"qty":38.46256908}],"asks":[],"checksum":1278647663,"timestamp":"2024-06-01T17:52:38.236411Z"}]}
{"channel":"book","type":"update","data":[{"symbol":"LTC/USDT","bids":[{"price":83.23425,"qty":0.00000000},{"price":83.20977,"qty":8.19100000}],"asks":[],"checksum":2105253241,"timestamp":"2024-06-01T17:52:38.236571Z"}]}
{"channel":"book","type":"update","data":[{"symbol":"LTC/USDT","bids":[{"price":83.21674,"qty":0.61401650}],"asks":[],"checksum":2930053880,"timestamp":"2024-06-01T17:52:38.241461Z"}]}
{"channel":"book","type":"update","data":[{"symbol":"LTC/USDT","bids":[{"price":83.23474,"qty":0.24037500}],"asks":[],"checksum":955438443,"timestamp":"2024-06-01T17:52:38.241496Z"}]}
{"channel":"book","type":"update","data":[{"symbol":"LTC/USDT","bids":[],"asks":[{"price":83.31040,"qty":0.00000000},{"price":83.32816,"qty":3.02951062}],"checksum":277437264,"timestamp":"2024-06-01T17:52:38.314327Z"}]}
{"channel":"book","type":"update","data":[{"symbol":"LTC/USDT","bids":[],"asks":[{"price":83.30489,"qty":10.00000000}],"checksum":1681964484,"timestamp":"2024-06-01T17:52:38.397769Z"}]}
{"channel":"book","type":"update","data":[{"symbol":"LTC/USDT","bids":[{"price":83.25278,"qty":0.00000000},{"price":83.21000,"qty":38.46256908}],"asks":[],"checksum":772695848,"timestamp":"2024-06-01T17:52:38.522821Z"}]}
{"channel":"book","type":"update","data":[{"symbol":"LTC/USDT","bids":[{"price":83.25279,"qty":0.00000000},{"price":83.20977,"qty":8.19100000}],"asks":[],"checksum":766493490,"timestamp":"2024-06-01T17:52:38.526822Z"}]}
{"channel":"book","type":"update","data":[{"symbol":"LTC/USDT","bids":[{"price":83.25414,"qty":18.02860463}],"asks":[],"checksum":2360542077,"timestamp":"2024-06-01T17:52:38.563103Z"}]}
{"channel":"book","type":"update","data":[{"symbol":"LTC/USDT","bids":[{"price":83.25415,"qty":23.85306512}],"asks":[],"checksum":1413094863,"timestamp":"2024-06-01T17:52:38.567223Z"}]}
{"channel":"book","type":"update","data":[{"symbol":"LTC/USDT","bids":[{"price":83.24770,"qty":0.00000000},{"price":83.21000,"qty":38.46256908}],"asks":[],"checksum":1757074436,"timestamp":"2024-06-01T17:52:38.589847Z"}]}
{"channel":"book","type":"update","data":[{"symbol":"LTC/USDT","bids":[{"price":83.24903,"qty":9.01427262}],"asks":[],"checksum":312522691,"timestamp":"2024-06-01T17:52:38.629765Z"}]}
{"channel":"book","type":"update","data":[{"symbol":"LTC/USDT","bids":[],"asks":[{"price":83.28689,"qty":0.00000000},{"price":83.32816,"qty":3.02951062}],"checksum":720234119,"timestamp":"2024-06-01T17:52:38.632539Z"}]}
{"channel":"book","type":"update","data":[{"symbol":"LTC/USDT","bids":[],"asks":[{"price":83.28390,"qty":1.80000000}],"checksum":3486709775,"timestamp":"2024-06-01T17:52:38.632749Z"}]}
{"channel":"book","type":"update","data":[{"symbol":"LTC/USDT","bids":[],"asks":[{"price":83.30489,"qty":0.00000000},{"price":83.32816,"qty":3.02951062}],"checksum":425350200,"timestamp":"2024-06-01T17:52:38.667169Z"}]}
{"channel":"book","type":"update","data":[{"symbol":"LTC/USDT","bids":[],"asks":[{"price":83.28645,"qty":10.00000000}],"checksum":3123657115,"timestamp":"2024-06-01T17:52:38.711051Z"}]}
{"channel":"book","type":"update","data":[{"symbol":"LTC/USDT","bids":[],"asks":[{"price":83.28677,"qty":0.00000000},{"price":83.32816,"qty":3.02951062}],"checksum":1796625447,"timestamp":"2024-06-01T17:52:38.715495Z"}]}
{"channel":"book","type":"update","data":[{"symbol":"LTC/USDT","bids":[],"asks":[{"price":83.28370,"qty":1.99000000}],"checksum":1656998090,"timestamp":"2024-06-01T17:52:38.716151Z"}]}
{"channel":"book","type":"update","data":[{"symbol":"LTC/USDT","bids":[],"asks":[{"price":83.30485,"qty":10.00000000}],"checksum":1643953114,"timestamp":"2024-06-01T17:52:38.972215Z"}]}
{"channel":"book","type":"update","data":[{"symbol":"LTC/USDT","bids":[],"asks":[{"price":83.28657,"qty":0.00000000},{"price":83.32787,"qty":36.00236031}],"checksum":570071270,"timestamp":"2024-06-01T17:52:39.086084Z"}]}
{"channel":"book","type":"update","data":[{"symbol":"LTC/USDT","bids":[{"price":83.25414,"qty":0.00000000},{"price":83.21000,"qty":38.46256908}],"asks":[],"checksum":1751923762,"timestamp":"2024-06-01T17:52:39.143164Z"}]}
{"channel":"book","type":"update","data":[{"symbol":"LTC/USDT","bids":[{"price":83.25415,"qty":0.00000000},{"price":83.20977,"qty":8.19100000}],"asks":[],"checksum":3274147158,"timestamp":"2024-06-01T17:52:39.147040Z"}]}
{"channel":"book","type":"update","data":[{"symbol":"LTC/USDT","bids":[{"price":83.21675,"qty":3.60587662}],"asks":[],"checksum":1746304145,"timestamp":"2024-06-01T17:52:39.151578Z"}]}
{"channel":"book","type":"update","data":[{"symbol":"LTC/USDT","bids":[{"price":83.25235,"qty":18.02909861}],"asks":[],"checksum":3542168270,"timestamp":"2024-06-01T17:52:39.183396Z"}]}
{"channel":"book","type":"update","data":[{"symbol":"LTC/USDT","bids":[{"price":83.25236,"qty":23.85306512}],"asks":[],"checksum":259018883,"timestamp":"2024-06-01T17:52:39.187455Z"}]}
{"channel":"book","type":"update","data":[{"symbol":"LTC/USDT","bids":[{"price":83.21675,"qty":0.00000000},{"price":83.21003,"qty":3.02951062}],"asks":[],"checksum":524052879,"timestamp":"2024-06-01T17:52:39.192519Z"}]}
{"channel":"book","type":"update","data":[{"symbol":"LTC/USDT","bids":[{"price":83.24903,"qty":0.00000000},{"price":83.21000,"qty":38.46256908}],"asks":[],"checksum":400377185,"timestamp":"2024-06-01T17:52:39.273937Z"}]}
{"channel":"book","type":"update","data":[{"symbol":"LTC/USDT","bids":[{"price":83.24727,"qty":9.01455673}],"asks":[],"checksum":164263591,"timestamp":"2024-06-01T17:52:39.314097Z"}]}
{"channel":"book","type":"update","data":[{"symbol":"LTC/USDT","bids":[{"price":83.25235,"qty":0.00000000},{"price":83.21000,"qty":38.46256908}],"asks":[],"checksum":385294755,"timestamp":"2024-06-01T17:52:39.752697Z"}]}
{"channel":"book","type":"update","data":[{"symbol":"LTC/USDT","bids":[],"asks":[{"price":83.28390,"qty":0.00000000},{"price":83.32816,"qty":3.02951062}],"checksum":1146261235,"timestamp":"2024-06-01T17:52:39.755417Z"}]}
{"channel":"book","type":"update","data":[{"symbol":"LTC/USDT","bids":[],"asks":[{"price":83.28103,"qty":1.80000000}],"checksum":1959083740,"timestamp":"2024-06-01T17:52:39.755516Z"}]}
{"channel":"book","type":"update","data":[{"symbol":"LTC/USDT","bids":[{"price":83.25236,"qty":0.00000000},{"price":83.20977,"qty":8.19100000}],"asks":[],"checksum":1239101757,"timestamp":"2024-06-01T17:52:39.756583Z"}]}
{"channel":"book","type":"update","data":[{"symbol":"LTC/USDT","bids":[{"price":83.21675,"qty":3.60587668}],"asks":[],"checksum":1457658204,"timestamp":"2024-06-01T17:52:39.762280Z"}]}
{"channel":"book","type":"update","data":[{"symbol":"LTC/USDT","bids":[{"price":83.25201,"qty":18.02915080}],"asks":[],"checksum":3825713631,"timestamp":"2024-06-01T17:52:39.793091Z"}]}
{"channel":"book","type":"update","data":[{"symbol":"LTC/USDT","bids":[],"asks":[{"price":83.28083,"qty":1.99000000}],"checksum":4171871026,"timestamp":"2024-06-01T17:52:39.798540Z"}]}
{"channel":"book","type":"update","data":[{"symbol":"LTC/USDT","bids":[{"price":83.24727,"qty":0.00000000},{"price":83.21000,"qty":38.46256908}],"asks":[],"checksum":3887739878,"timestamp":"2024-06-01T17:52:39.810484Z"}]}
{"channel":"book","type":"update","data":[{"symbol":"LTC/USDT","bids":[{"price":83.24692,"qty":9.01457540}],"asks":[],"checksum":708029023,"timestamp":"2024-06-01T17:52:39.850563Z"}]}
{"channel":"book","type":"update","data":[{"symbol":"LTC/USDT","bids":[],"asks":[{"price":83.28370,"qty":0.00000000},{"price":83.32787,"qty":36.00236031}],"checksum":3965181409,"timestamp":"2024-06-01T17:52:39.855871Z"}]}
{"channel":"book","type":"update","data":[{"symbol":"LTC/USDT","bids":[{"price":83.25202,"qty":23.85306512}],"asks":[],"checksum":1483263444,"timestamp":"2024-06-01T17:52:40.010090Z"}]}
{"channel":"book","type":"update","data":[{"symbol":"LTC/USDT","bids":[{"price":83.21675,"qty":0.00000000},{"price":83.21003,"qty":3.02951062}],"asks":[],"checksum":738378145,"timestamp":"2024-06-01T17:52:40.015054Z"}]}
{"channel":"book","type":"update","data":[{"symbol":"LTC/USDT","bids":[{"price":83.25201,"qty":0.00000000},{"price":83.21000,"qty":38.46256908}],"asks":[],"checksum":1246010186,"timestamp":"2024-06-01T17:52:40.371525Z"}]}
{"channel":"book","type":"update","data":[{"symbol":"LTC/USDT","bids":[{"price":83.25202,"qty":0.00000000},{"price":83.20977,"qty":8.19100000}],"asks":[],"checksum":3790209538,"timestamp":"2024-06-01T17:52:40.375811Z"}]}
{"channel":"book","type":"update","data":[{"symbol":"LTC/USDT","bids":[{"price":83.21675,"qty":3.60587624}],"asks":[],"checksum":2314462560,"timestamp":"2024-06-01T17:52:40.380650Z"}]}
{"channel":"book","type":"update","data":[{"symbol":"LTC/USDT","bids":[{"price":83.24692,"qty":0.00000000},{"price":83.20977,"qty":8.19100000}],"asks":[],"checksum":853376794,"timestamp":"2024-06-01T17:52:40.418513Z"}]}
{"channel":"book","type":"update","data":[{"symbol":"LTC/USDT","bids":[{"price":83.23557,"qty":16.22485299}],"asks":[],"checksum":3522774791,"timestamp":"2024-06-01T17:52:40.421556Z"}]}
{"channel":"book","type":"update","data":[{"symbol":"LTC/USDT","bids":[{"price":83.23494,"qty":1.99000000}],"asks":[],"checksum":2947364231,"timestamp":"2024-06-01T17:52:40.423781Z"}]}
{"channel":"book","type":"update","data":[{"symbol":"LTC/USDT","bids":[{"price":83.23473,"qty":1.99000000}],"asks":[],"checksum":3640754043,"timestamp":"2024-06-01T17:52:40.424187Z"}]}
{"channel":"book","type":"update","data":[{"symbol":"LTC/USDT","bids":[{"price":83.23494,"qty":0.00000000},{"price":83.21000,"qty":38.46256908}],"asks":[],"checksum":334686374,"timestamp":"2024-06-01T17:52:40.590547Z"}]}
{"channel":"book","type":"update","data":[{"symbol":"LTC/USDT","bids":[{"price":83.23577,"qty":1.99000000}],"asks":[],"checksum":852686841,"timestamp":"2024-06-01T17:52:40.590597Z"}]}
{"channel":"book","type":"update","data":[{"symbol":"LTC/USDT","bids":[{"price":83.23660,"qty":16.22485713}],"asks":[],"checksum":2704409161,"timestamp":"2024-06-01T17:52:40.593435Z"}]}
{"channel":"book","type":"update","data":[{"symbol":"LTC/USDT","bids":[{"price":83.23473,"qty":0.00000000},{"price":83.21003,"qty":3.02951062}],"asks":[],"checksum":3207582792,"timestamp":"2024-06-01T17:52:40.595479Z"}]}
{"channel":"book","type":"update","data":[{"symbol":"LTC/USDT","bids":[{"price":83.23557,"qty":0.00000000},{"price":83.21000,"qty":38.46256908}],"asks":[],"checksum":606517955,"timestamp":"2024-06-01T17:52:40.596182Z"}]}
{"channel":"book","type":"update","data":[{"symbol":"LTC/USDT","bids":[{"price":83.21675,"qty":0.00000000},{"price":83.20977,"qty":8.19100000}],"asks":[],"checksum":1279221153,"timestamp":"2024-06-01T17:52:40.597609Z"}]}
{"channel":"book","type":"update","data":[{"symbol":"LTC/USDT","bids":[{"price":83.21676,"qty":3.60587219}],"asks":[],"checksum":2717746669,"timestamp":"2024-06-01T17:52:40.601724Z"}]}
{"channel":"book","type":"update","data":[{"symbol":"LTC/USDT","bids":[{"price":83.21675,"qty":3.60587219}],"asks":[],"checksum":3817834210,"timestamp":"2024-06-01T17:52:40.602317Z"}]}
{"channel":"book","type":"update","data":[{"symbol":"LTC/USDT","bids":[{"price":83.21676,"qty":0.00000000},{"price":83.21000,"qty":38.46256908}],"asks":[],"checksum":979844866,"timestamp":"2024-06-01T17:52:40.605894Z"}]}
{"channel":"book","type":"update","data":[{"symbol":"LTC/USDT","bids":[{"price":83.21675,"qty":0.00000000},{"price":83.20977,"qty":8.19100000}],"asks":[],"checksum":1279221153,"timestamp":"2024-06-01T17:52:40.610303Z"}]}
{"channel":"book","type":"update","data":[{"symbol":"LTC/USDT","bids":[{"price":83.21677,"qty":3.60587219}],"asks":[],"checksum":1638198903,"timestamp":"2024-06-01T17:52:40.610329Z"}]}
{"channel":"book","type":"update","data":[{"symbol":"LTC/USDT","bids":[{"price":83.23474,"qty":0.00000000},{"price":83.20977,"qty":8.19100000}],"asks":[],"checksum":590635788,"timestamp":"2024-06-01T17:52:40.795945Z"}]}
{"channel":"book","type":"update","data":[{"symbol":"LTC/USDT","bids":[{"price":83.21674,"qty":0.00000000},{"price":83.20870,"qty":7.87361491}],"asks":[],"checksum":2856009930,"timestamp":"2024-06-01T17:52:40.796070Z"}]}
{"channel":"book","type":"update","data":[{"symbol":"LTC/USDT","bids":[{"price":83.23680,"qty":1.99000000}],"asks":[],"checksum":2021920143,"timestamp":"2024-06-01T17:52:40.802543Z"}]}
{"channel":"book","type":"update","data":[{"symbol":"LTC/USDT","bids":[{"price":83.23709,"qty":16.22479590}],"asks":[],"checksum":3114629084,"timestamp":"2024-06-01T17:52:40.810245Z"}]}
{"channel":"book","type":"update","data":[{"symbol":"LTC/USDT","bids":[{"price":83.23660,"qty":0.00000000},{"price":83.20977,"qty":8.19100000}],"asks":[],"checksum":2850416497,"timestamp":"2024-06-01T17:52:40.813588Z"}]}
{"channel":"book","type":"update","data":[{"symbol":"LTC/USDT","bids":[{"price":83.25186,"qty":18.02922928}],"asks":[],"checksum":1584252222,"timestamp":"2024-06-01T17:52:40.894369Z"}]}
{"channel":"book","type":"update","data":[{"symbol":"LTC/USDT","bids":[{"price":83.23680,"qty":0.00000000},{"price":83.20977,"qty":8.19100000}],"asks":[],"checksum":3677793699,"timestamp":"2024-06-01T17:52:40.898797Z"}]}
{"channel":"book","type":"update","data":[{"symbol":"LTC/USDT","bids":[],"asks":[{"price":83.28103,"qty":0.00000000},{"price":83.32816,"qty":3.02951062}],"checksum":3523229177,"timestamp":"2024-06-01T17:52:40.901492Z"}]}
{"channel":"book","type":"update","data":[{"symbol":"LTC/USDT","bids":[],"asks":[{"price":83.27816,"qty":1.80000000}],"checksum":4156758989,"timestamp":"2024-06-01T17:52:40.901750Z"}]}
{"channel":"book","type":"update","data":[{"symbol":"LTC/USDT","bids":[{"price":83.24678,"qty":9.01459459}],"asks":[],"checksum":3187513527,"timestamp":"2024-06-01T17:52:41.001881Z"}]}
{"channel":"book","type":"update","data":[{"symbol":"LTC/USDT","bids":[{"price":83.25186,"qty":0.00000000},{"price":83.20977,"qty":8.19100000}],"asks":[],"checksum":4247521698,"timestamp":"2024-06-01T17:52:41.421502Z"}]}
{"channel":"book","type":"update","data":[{"symbol":"LTC/USDT","bids":[{"price":83.21000,"qty":0.00000000},{"price":83.20870,"qty":7.87361491}],"asks":[],"checksum":3332107221,"timestamp":"2024-06-01T17:52:41.424174Z"}]}
{"channel":"book","type":"update","data":[{"symbol":"LTC/USDT","bids":[{"price":83.24679,"qty":23.85306512}],"asks":[],"checksum":4188914886,"timestamp":"2024-06-01T17:52:41.425667Z"}]}
{"channel":"book","type":"update","data":[{"symbol":"LTC/USDT","bids":[{"price":83.22000,"qty":20.55801505}],"asks":[],"checksum":1138312556,"timestamp":"2024-06-01T17:52:41.427588Z"}]}
{"channel":"book","type":"update","data":[{"symbol":"LTC/USDT","bids":[{"price":83.21677,"qty":0.00000000},{"price":83.20977,"qty":8.19100000}],"asks":[],"checksum":999771959,"timestamp":"2024-06-01T17:52:41.429919Z"}]}
{"channel":"book","type":"update","data":[{"symbol":"LTC/USDT","bids":[{"price":83.24678,"qty":0.00000000},{"price":83.20870,"qty":7.87361491}],"asks":[],"checksum":3171775592,"timestamp":"2024-06-01T17:52:41.461780Z"}]}
{"channel":"book","type":"update","data":[{"symbol":"LTC/USDT","bids":[{"price":83.25211,"qty":18.02908958}],"asks":[],"checksum":2252258693,"timestamp":"2024-06-01T17:52:41.461957Z"}]}
{"channel":"book","type":"update","data":[{"symbol":"LTC/USDT","bids":[{"price":83.24679,"qty":0.00000000},{"price":83.20870,"qty":7.87361491}],"asks":[],"checksum":1776021284,"timestamp":"2024-06-01T17:52:41.465822Z"}]}
{"channel":"book","type":"update","data":[{"symbol":"LTC/USDT","bids":[],"asks":[{"price":83.27796,"qty":1.99000000}],"checksum":2173495257,"timestamp":"2024-06-01T17:52:41.466829Z"}]}
{"channel":"book","type":"update","data":[{"symbol":"LTC/USDT","bids":[],"asks":[{"price":83.27816,"qty":0.00000000},{"price":83.32787,"qty":36.00236031}],"checksum":2883878456,"timestamp":"2024-06-01T17:52:41.469492Z"}]}
{"channel":"book","type":"update","data":[{"symbol":"LTC/USDT","bids":[],"asks":[{"price":83.27529,"qty":1.80000000}],"checksum":4103775526,"timestamp":"2024-06-01T17:52:41.469976Z"}]}
{"channel":"book","type":"update","data":[{"symbol":"LTC/USDT","bids":[{"price":83.24702,"qty":9.01454479}],"asks":[],"checksum":924475054,"timestamp":"2024-06-01T17:52:41.502045Z"}]}
{"channel":"book","type":"update","data":[{"symbol":"LTC/USDT","bids":[{"price":83.25212,"qty":23.85306512}],"asks":[],"checksum":3019311333,"timestamp":"2024-06-01T17:52:41.507132Z"}]}
{"channel":"book","type":"update","data":[{"symbol":"LTC/USDT","bids":[],"asks":[{"price":83.27796,"qty":0.00000000},{"price":83.32787,"qty":36.00236031}],"checksum":2619052810,"timestamp":"2024-06-01T17:52:41.507291Z"}]}
{"channel":"book","type":"update","data":[{"symbol":"LTC/USDT","bids":[{"price":83.25211,"qty":0.00000000},{"price":83.20977,"qty":8.19100000}],"asks":[],"checksum":2091356311,"timestamp":"2024-06-01T17:52:41.987941Z"}]}
{"channel":"book","type":"update","data":[{"symbol":"LTC/USDT","bids":[{"price":83.25212,"qty":0.00000000},{"price":83.20870,"qty":7.87361491}],"asks":[],"checksum":1048419413,"timestamp":"2024-06-01T17:52:41.992176Z"}]}
{"channel":"book","type":"update","data":[{"symbol":"LTC/USDT","bids":[{"price":83.21671,"qty":3.60587198}],"asks":[],"checksum":2696826572,"timestamp":"2024-06-01T17:52:41.996581Z"}]}
{"channel":"book","type":"update","data":[{"symbol":"LTC/USDT","bids":[{"price":83.25227,"qty":18.02899940}],"asks":[],"checksum":1895976306,"timestamp":"2024-06-01T17:52:42.028101Z"}]}
{"channel":"book","type":"update","data":[{"symbol":"LTC/USDT","bids":[{"price":83.24702,"qty":0.00000000},{"price":83.20977,"qty":8.19100000}],"asks":[],"checksum":569436772,"timestamp":"2024-06-01T17:52:42.029171Z"}]}
{"channel":"book","type":"update","data":[{"symbol":"LTC/USDT","bids":[{"price":83.25228,"qty":23.85306512}],"asks":[],"checksum":144051583,"timestamp":"2024-06-01T17:52:42.032611Z"}]}
{"channel":"book","type":"update","data":[{"symbol":"LTC/USDT","bids":[{"price":83.21671,"qty":0.00000000},{"price":83.20977,"qty":8.19100000}],"asks":[],"checksum":86475640,"timestamp":"2024-06-01T17:52:42.033007Z"}]}
{"channel":"book","type":"update","data":[{"symbol":"LTC/USDT","bids":[{"price":83.24718,"qty":9.01456254}],"asks":[],"checksum":1786145111,"timestamp":"2024-06-01T17:52:42.069294Z"}]}
{"channel":"book","type":"update","data":[{"symbol":"LTC/USDT","bids":[{"price":83.25227,"qty":0.00000000},{"price":83.20977,"qty":8.19100000}],"asks":[],"checksum":512839578,"timestamp":"2024-06-01T17:52:42.489271Z"}]}
{"channel":"book","type":"update","data":[{"symbol":"LTC/USDT","bids":[{"price":83.25228,"qty":0.00000000},{"price":83.20870,"qty":7.87361491}],"asks":[],"checksum":3214017508,"timestamp":"2024-06-01T17:52:42.493153Z"}]}
{"channel":"book","type":"update","data":[{"symbol":"LTC/USDT","bids":[],"asks":[{"price":83.27509,"qty":1.99000000}],"checksum":2506856457,"timestamp":"2024-06-01T17:52:42.494065Z"}]}
{"channel":"book","type":"update","data":[{"symbol":"LTC/USDT","bids":[],"asks":[{"price":83.27529,"qty":0.00000000},{"price":83.32787,"qty":36.00236031}],"checksum":1412068354,"timestamp":"2024-06-01T17:52:42.496538Z"}]}
{"channel":"book","type":"update","data":[{"symbol":"LTC/USDT","bids":[],"asks":[{"price":83.27414,"qty":1.80000000}],"checksum":4090560866,"timestamp":"2024-06-01T17:52:42.496758Z"}]}
{"channel":"book","type":"update","data":[{"symbol":"LTC/USDT","bids":[{"price":83.21671,"qty":3.60586691}],"asks":[],"checksum":870428172,"timestamp":"2024-06-01T17:52:42.497887Z"}]}
{"channel":"book","type":"update","data":[{"symbol":"LTC/USDT","bids":[],"asks":[{"price":83.27509,"qty":0.00000000},{"price":83.32787,"qty":36.00236031}],"checksum":281738961,"timestamp":"2024-06-01T17:52:42.588413Z"}]}
{"channel":"book","type":"update","data":[{"symbol":"LTC/USDT","bids":[],"asks":[{"price":83.27414,"qty":0.00000000},{"price":83.32816,"qty":3.02951062}],"checksum":1955491498,"timestamp":"2024-06-01T17:52:42.591129Z"}]}
{"channel":"book","type":"update","data":[{"symbol":"LTC/USDT","bids":[],"asks":[{"price":83.27816,"qty":1.80000000}],"checksum":3631413784,"timestamp":"2024-06-01T17:52:42.591223Z"}]}
{"channel":"book","type":"update","data":[{"symbol":"LTC/USDT","bids":[{"price":83.24718,"qty":0.00000000},{"price":83.20870,"qty":7.87361491}],"asks":[],"checksum":1040876953,"timestamp":"2024-06-01T17:52:42.596978Z"}]}
{"channel":"book","type":"update","data":[{"symbol":"LTC/USDT","bids":[{"price":83.23710,"qty":23.85306512}],"asks":[],"checksum":1336113496,"timestamp":"2024-06-01T17:52:43.008856Z"}]}
{"channel":"book","type":"update","data":[{"symbol":"LTC/USDT","bids":[{"price":83.21671,"qty":0.00000000},{"price":83.20870,"qty":7.87361491}],"asks":[],"checksum":2408830518,"timestamp":"2024-06-01T17:52:43.014093Z"}]}
{"channel":"book","type":"update","data":[{"symbol":"LTC/USDT","bids":[{"price":83.25200,"qty":18.02918716}],"asks":[],"checksum":3402692333,"timestamp":"2024-06-01T17:52:43.063186Z"}]}
{"channel":"book","type":"update","data":[{"symbol":"LTC/USDT","bids":[{"price":83.24692,"qty":9.01457890}],"asks":[],"checksum":508349324,"timestamp":"2024-06-01T17:52:43.098481Z"}]}
{"channel":"book","type":"update","data":[{"symbol":"LTC/USDT","bids":[{"price":83.24692,"qty":0.00000000},{"price":83.20977,"qty":8.19100000}],"asks":[],"checksum":3402692333,"timestamp":"2024-06-01T17:52:43.218915Z"}]}
{"channel":"book","type":"update","data":[{"symbol":"LTC/USDT","bids":[{"price":83.23711,"qty":0.36494201}],"asks":[],"checksum":2476523568,"timestamp":"2024-06-01T17:52:43.496566Z"}]}
{"channel":"book","type":"update","data":[{"symbol":"LTC/USDT","bids":[],"asks":[{"price":83.27796,"qty":1.99000000}],"checksum":2076952781,"timestamp":"2024-06-01T17:52:43.502175Z"}]}
{"channel":"book","type":"update","data":[{"symbol":"LTC/USDT","bids":[],"asks":[{"price":83.27816,"qty":0.00000000},{"price":83.32787,"qty":36.00236031}],"checksum":1369657644,"timestamp":"2024-06-01T17:52:43.504938Z"}]}
{"channel":"book","type":"update","data":[{"symbol":"LTC/USDT","bids":[],"asks":[{"price":83.27543,"qty":1.80000000}],"checksum":3298514925,"timestamp":"2024-06-01T17:52:43.505033Z"}]}
{"channel":"book","type":"update","data":[{"symbol":"LTC/USDT","bids":[],"asks":[{"price":83.27796,"qty":0.00000000},{"price":83.32787,"qty":36.00236031}],"checksum":2610719638,"timestamp":"2024-06-01T17:52:43.587804Z"}]}
{"channel":"book","type":"update","data":[{"symbol":"LTC/USDT","bids":[],"asks":[{"price":83.27523,"qty":1.99000000}],"checksum":1488917018,"timestamp":"2024-06-01T17:52:43.593139Z"}]}
{"channel":"book","type":"update","data":[{"symbol":"LTC/USDT","bids":[],"asks":[{"price":83.27543,"qty":0.00000000},{"price":83.32787,"qty":36.00236031}],"checksum":384698313,"timestamp":"2024-06-01T17:52:43.595981Z"}]}
{"channel":"book","type":"update","data":[{"symbol":"LTC/USDT","bids":[],"asks":[{"price":83.27509,"qty":1.80000000}],"checksum":3335384482,"timestamp":"2024-06-01T17:52:43.596029Z"}]}
{"channel":"book","type":"update","data":[{"symbol":"LTC/USDT","bids":[],"asks":[{"price":83.30485,"qty":0.00000000},{"price":83.32787,"qty":36.00236031}],"checksum":1157880906,"timestamp":"2024-06-01T17:52:43.851323Z"}]}
{"channel":"book","type":"update","data":[{"symbol":"LTC/USDT","bids":[{"price":83.25200,"qty":0.00000000},{"price":83.20977,"qty":8.19100000}],"asks":[],"checksum":918906267,"timestamp":"2024-06-01T17:52:43.869917Z"}]}
{"channel":"book","type":"update","data":[{"symbol":"LTC/USDT","bids":[],"asks":[{"price":83.27523,"qty":0.00000000},{"price":83.32816,"qty":3.02951062}],"checksum":1999943430,"timestamp":"2024-06-01T17:52:43.875037Z"}]}
{"channel":"book","type":"update","data":[{"symbol":"LTC/USDT","bids":[{"price":83.25528,"qty":18.02875201}],"asks":[],"checksum":2440077823,"timestamp":"2024-06-01T17:52:43.910139Z"}]}
{"channel":"book","type":"update","data":[{"symbol":"LTC/USDT","bids":[{"price":83.25019,"qty":9.01437853}],"asks":[],"checksum":1914417045,"timestamp":"2024-06-01T17:52:43.950859Z"}]}
{"channel":"book","type":"update","data":[{"symbol":"LTC/USDT","bids":[{"price":83.24599,"qty":23.85306512}],"asks":[],"checksum":2862483255,"timestamp":"2024-06-01T17:52:44.020546Z"}]}
{"channel":"book","type":"update","data":[{"symbol":"LTC/USDT","bids":[{"price":83.23710,"qty":0.00000000},{"price":83.21015,"qty":9.76343889}],"asks":[],"checksum":1756758558,"timestamp":"2024-06-01T17:52:44.025927Z"}]}
{"channel":"book","type":"update","data":[{"symbol":"LTC/USDT","bids":[],"asks":[{"price":83.30111,"qty":4.80398912}],"checksum":3017021429,"timestamp":"2024-06-01T17:52:44.115902Z"}]}
{"channel":"book","type":"update","data":[{"symbol":"LTC/USDT","bids":[{"price":83.25528,"qty":0.00000000},{"price":83.21003,"qty":3.02951062}],"asks":[],"checksum":491581386,"timestamp":"2024-06-01T17:52:44.438705Z"}]}
{"channel":"book","type":"update","data":[{"symbol":"LTC/USDT","bids":[{"price":83.25020,"qty":23.85306512}],"asks":[],"checksum":3782855643,"timestamp":"2024-06-01T17:52:44.442865Z"}]}
{"channel":"book","type":"update","data":[{"symbol":"LTC/USDT","bids":[{"price":83.25019,"qty":0.00000000},{"price":83.21003,"qty":3.02951062}],"asks":[],"checksum":1398814151,"timestamp":"2024-06-01T17:52:44.478093Z"}]}
{"channel":"book","type":"update","data":[{"symbol":"LTC/USDT","bids":[{"price":83.25145,"qty":18.02919681}],"asks":[],"checksum":4269490592,"timestamp":"2024-06-01T17:52:44.478689Z"}]}
{"channel":"book","type":"update","data":[{"symbol":"LTC/USDT","bids":[{"price":83.25020,"qty":0.00000000},{"price":83.21003,"qty":3.02951062}],"asks":[],"checksum":3082232323,"timestamp":"2024-06-01T17:52:44.481916Z"}]}
{"channel":"book","type":"update","data":[{"symbol":"LTC/USDT","bids":[],"asks":[{"price":83.27489,"qty":1.99000000}],"checksum":4028251795,"timestamp":"2024-06-01T17:52:44.487725Z"}]}
{"channel":"book","type":"update","data":[{"symbol":"LTC/USDT","bids":[{"price":83.24637,"qty":9.01459840}],"asks":[],"checksum":2157606451,"timestamp":"2024-06-01T17:52:44.518232Z"}]}
{"channel":"book","type":"update","data":[{"symbol":"LTC/USDT","bids":[],"asks":[{"price":83.28083,"qty":0.00000000},{"price":83.32787,"qty":36.00236031}],"checksum":2827360617,"timestamp":"2024-06-01T17:52:44.522897Z"}]}
{"channel":"book","type":"update","data":[{"symbol":"LTC/USDT","bids":[],"asks":[{"price":83.27509,"qty":0.00000000},{"price":83.32816,"qty":3.02951062}],"checksum":2400814515,"timestamp":"2024-06-01T17:52:44.525529Z"}]}
{"channel":"book","type":"update","data":[{"symbol":"LTC/USDT","bids":[],"asks":[{"price":83.28378,"qty":1.80000000}],"checksum":355763256,"timestamp":"2024-06-01T17:52:44.525721Z"}]}
{"channel":"book","type":"update","data":[{"symbol":"LTC/USDT","bids":[{"price":83.25145,"qty":0.00000000},{"price":83.21003,"qty":3.02951062}],"asks":[],"checksum":2400606866,"timestamp":"2024-06-01T17:52:44.939134Z"}]}
{"channel":"book","type":"update","data":[{"symbol":"LTC/USDT","bids":[{"price":83.24638,"qty":23.85306512}],"asks":[],"checksum":3953359497,"timestamp":"2024-06-01T17:52:45.011183Z"}]}
{"channel":"book","type":"update","data":[{"symbol":"LTC/USDT","bids":[],"asks":[{"price":83.27489,"qty":0.00000000},{"price":83.32816,"qty":3.02951062}],"checksum":963525234,"timestamp":"2024-06-01T17:52:45.017207Z"}]}
{"channel":"book","type":"update","data":[{"symbol":"LTC/USDT","bids":[],"asks":[{"price":83.28645,"qty":0.00000000},{"price":83.34094,"qty":2.34609048}],"checksum":983067814,"timestamp":"2024-06-01T17:52:45.213042Z"}]}
{"channel":"book","type":"update","data":[{"symbol":"LTC/USDT","bids":[],"asks":[{"price":83.28988,"qty":10.00000000}],"checksum":562111776,"timestamp":"2024-06-01T17:52:45.213065Z"}]}
{"channel":"book","type":"update","data":[{"symbol":"LTC/USDT","bids":[{"price":83.24599,"qty":0.00000000},{"price":83.21003,"qty":3.02951062}],"asks":[],"checksum":987820485,"timestamp":"2024-06-01T17:52:45.216966Z"}]}
{"channel":"book","type":"update","data":[{"symbol":"LTC/USDT","bids":[],"asks":[{"price":83.30948,"qty":0.00000000},{"price":83.34094,"qty":2.34609048}],"checksum":2508444010,"timestamp":"2024-06-01T17:52:45.310125Z"}]}
{"channel":"book","type":"update","data":[{"symbol":"LTC/USDT","bids":[],"asks":[{"price":83.30783,"qty":8.13800000}],"checksum":2548562951,"timestamp":"2024-06-01T17:52:45.312861Z"}]}
{"channel":"book","type":"update","data":[{"symbol":"LTC/USDT","bids":[{"price":83.24637,"qty":0.00000000},{"price":83.20977,"qty":8.19100000}],"asks":[],"checksum":3743724457,"timestamp":"2024-06-01T17:52:45.507543Z"}]}
{"channel":"book","type":"update","data":[{"symbol":"LTC/USDT","bids":[{"price":83.25158,"qty":18.02919792}],"asks":[],"checksum":4268863253,"timestamp":"2024-06-01T17:52:45.507814Z"}]}
{"channel":"book","type":"update","data":[{"symbol":"LTC/USDT","bids":[],"asks":[{"price":83.28358,"qty":1.99000000}],"checksum":2642160306,"timestamp":"2024-06-01T17:52:45.512638Z"}]}
{"channel":"book","type":"update","data":[{"symbol":"LTC/USDT","bids":[],"asks":[{"price":83.28378,"qty":0.00000000},{"price":83.32816,"qty":3.02951062}],"checksum":365549811,"timestamp":"2024-06-01T17:52:45.515710Z"}]}
{"channel":"book","type":"update","data":[{"symbol":"LTC/USDT","bids":[],"asks":[{"price":83.28091,"qty":1.80000000}],"checksum":1320868483,"timestamp":"2024-06-01T17:52:45.515739Z"}]}
{"channel":"book","type":"update","data":[{"symbol":"LTC/USDT","bids":[{"price":83.24650,"qty":9.01459896}],"asks":[],"checksum":592314385,"timestamp":"2024-06-01T17:52:45.547481Z"}]}
{"channel":"book","type":"update","data":[{"symbol":"LTC/USDT","bids":[{"price":83.25158,"qty":0.00000000},{"price":83.21003,"qty":3.02951062}],"asks":[],"checksum":1870774623,"timestamp":"2024-06-01T17:52:46.026399Z"}]}
{"channel":"book","type":"update","data":[{"symbol":"LTC/USDT","bids":[],"asks":[{"price":83.29000,"qty":0.00000000},{"price":83.32816,"qty":3.02951062}],"checksum":1457533423,"timestamp":"2024-06-01T17:52:46.029336Z"}]}
{"channel":"book","type":"update","data":[{"symbol":"LTC/USDT","bids":[{"price":83.24651,"qty":23.85306512}],"asks":[],"checksum":1715282641,"timestamp":"2024-06-01T17:52:46.030432Z"}]}
{"channel":"book","type":"update","data":[{"symbol":"LTC/USDT","bids":[],"asks":[{"price":83.28071,"qty":1.99000000}],"checksum":1646003898,"timestamp":"2024-06-01T17:52:46.031300Z"}]}
{"channel":"book","type":"update","data":[{"symbol":"LTC/USDT","bids":[],"asks":[{"price":83.29000,"qty":20.17645256}],"checksum":3972710039,"timestamp":"2024-06-01T17:52:46.032301Z"}]}
{"channel":"book","type":"update","data":[{"symbol":"LTC/USDT","bids":[],"asks":[{"price":83.28091,"qty":0.00000000},{"price":83.32787,"qty":36.00236031}],"checksum":1986604904,"timestamp":"2024-06-01T17:52:46.033792Z"}]}
{"channel":"book","type":"update","data":[{"symbol":"LTC/USDT","bids":[],"asks":[{"price":83.27804,"qty":1.80000000}],"checksum":2281444922,"timestamp":"2024-06-01T17:52:46.034032Z"}]}
{"channel":"book","type":"update","data":[{"symbol":"LTC/USDT","bids":[{"price":83.24650,"qty":0.00000000},{"price":83.21003,"qty":3.02951062}],"asks":[],"checksum":3926445224,"timestamp":"2024-06-01T17:52:46.064689Z"}]}
{"channel":"book","type":"update","data":[{"symbol":"LTC/USDT","bids":[{"price":83.25214,"qty":18.02912345}],"asks":[],"checksum":850000810,"timestamp":"2024-06-01T17:52:46.066797Z"}]}
{"channel":"book","type":"update","data":[{"symbol":"LTC/USDT","bids":[{"price":83.24651,"qty":0.00000000},{"price":83.21003,"qty":3.02951062}],"asks":[],"checksum":1549833146,"timestamp":"2024-06-01T17:52:46.068395Z"}]}
{"channel":"book","type":"update","data":[{"symbol":"LTC/USDT","bids":[],"asks":[{"price":83.28071,"qty":0.00000000},{"price":83.32787,"qty":36.00236031}],"checksum":4263912528,"timestamp":"2024-06-01T17:52:46.069567Z"}]}
{"channel":"book","type":"update","data":[{"symbol":"LTC/USDT","bids":[{"price":83.24706,"qty":9.01456172}],"asks":[],"checksum":2356970595,"timestamp":"2024-06-01T17:52:46.105178Z"}]}
{"channel":"book","type":"update","data":[{"symbol":"LTC/USDT","bids":[{"price":83.23711,"qty":0.00000000},{"price":83.21003,"qty":3.02951062}],"asks":[],"checksum":2697182418,"timestamp":"2024-06-01T17:52:46.224156Z"}]}
{"channel":"book","type":"update","data":[{"symbol":"LTC/USDT","bids":[{"price":83.25214,"qty":0.00000000},{"price":83.20977,"qty":8.19100000}],"asks":[],"checksum":2071437060,"timestamp":"2024-06-01T17:52:46.515812Z"}]}
{"channel":"book","type":"update","data":[{"symbol":"LTC/USDT","bids":[],"asks":[{"price":83.27784,"qty":1.99000000}],"checksum":2720297687,"timestamp":"2024-06-01T17:52:46.520363Z"}]}
{"channel":"book","type":"update","data":[{"symbol":"LTC/USDT","bids":[],"asks":[{"price":83.27804,"qty":0.00000000},{"price":83.32787,"qty":36.00236031}],"checksum":2467898552,"timestamp":"2024-06-01T17:52:46.522941Z"}]}
{"channel":"book","type":"update","data":[{"symbol":"LTC/USDT","bids":[],"asks":[{"price":83.27550,"qty":1.80000000}],"checksum":570249304,"timestamp":"2024-06-01T17:52:46.523232Z"}]}
{"channel":"book","type":"update","data":[{"symbol":"LTC/USDT","bids":[{"price":83.25174,"qty":18.02919792}],"asks":[],"checksum":627550531,"timestamp":"2024-06-01T17:52:46.555850Z"}]}
{"channel":"book","type":"update","data":[{"symbol":"LTC/USDT","bids":[],"asks":[{"price":83.27784,"qty":0.00000000},{"price":83.32787,"qty":36.00236031}],"checksum":491430683,"timestamp":"2024-06-01T17:52:46.560951Z"}]}
{"channel":"book","type":"update","data":[{"symbol":"LTC/USDT","bids":[],"asks":[{"price":83.27550,"qty":0.00000000},{"price":83.32816,"qty":3.02951062}],"checksum":836141130,"timestamp":"2024-06-01T17:52:46.563576Z"}]}
{"channel":"book","type":"update","data":[{"symbol":"LTC/USDT","bids":[{"price":83.24706,"qty":0.00000000},{"price":83.20977,"qty":8.19100000}],"asks":[],"checksum":3520605499,"timestamp":"2024-06-01T17:52:46.616366Z"}]}
{"channel":"book","type":"update","data":[{"symbol":"LTC/USDT","bids":[{"price":83.24666,"qty":9.01459896}],"asks":[],"checksum":1144769000,"timestamp":"2024-06-01T17:52:46.656620Z"}]}
{"channel":"book","type":"update","data":[{"symbol":"LTC/USDT","bids":[{"price":83.25175,"qty":23.85306512}],"asks":[],"checksum":2805476058,"timestamp":"2024-06-01T17:52:47.011919Z"}]}
{"channel":"book","type":"update","data":[{"symbol":"LTC/USDT","bids":[],"asks":[{"price":83.28358,"qty":0.00000000},{"price":83.34094,"qty":2.34609048}],"checksum":90822273,"timestamp":"2024-06-01T17:52:47.086957Z"}]}
{"channel":"book","type":"update","data":[{"symbol":"LTC/USDT","bids":[{"price":83.24638,"qty":0.00000000},{"price":83.21003,"qty":3.02951062}],"asks":[],"checksum":3639517494,"timestamp":"2024-06-01T17:52:47.090796Z"}]}
{"channel":"book","type":"update","data":[{"symbol":"LTC/USDT","bids":[{"price":83.22289,"qty":20.17645256}],"asks":[],"checksum":3055969810,"timestamp":"2024-06-01T17:52:47.317248Z"}]}
{"channel":"book","type":"update","data":[{"symbol":"LTC/USDT","bids":[{"price":83.25174,"qty":0.00000000},{"price":83.21003,"qty":3.02951062}],"asks":[],"checksum":3284168474,"timestamp":"2024-06-01T17:52:47.580089Z"}]}
{"channel":"book","type":"update","data":[{"symbol":"LTC/USDT","bids":[{"price":83.25175,"qty":0.00000000},{"price":83.20977,"qty":8.19100000}],"asks":[],"checksum":873985030,"timestamp":"2024-06-01T17:52:47.584351Z"}]}
{"channel":"book","type":"update","data":[{"symbol":"LTC/USDT","bids":[],"asks":[{"price":83.28968,"qty":1.99000000}],"checksum":2430242951,"timestamp":"2024-06-01T17:52:47.588292Z"}]}
{"channel":"book","type":"update","data":[{"symbol":"LTC/USDT","bids":[{"price":83.24666,"qty":0.00000000},{"price":83.20870,"qty":7.87361491}],"asks":[],"checksum":1090135518,"timestamp":"2024-06-01T17:52:47.616762Z"}]}
{"channel":"book","type":"update","data":[{"symbol":"LTC/USDT","bids":[{"price":83.25251,"qty":18.02912345}],"asks":[],"checksum":3894854769,"timestamp":"2024-06-01T17:52:47.620256Z"}]}
{"channel":"book","type":"update","data":[{"symbol":"LTC/USDT","bids":[{"price":83.23710,"qty":23.85306512}],"asks":[],"checksum":4249651667,"timestamp":"2024-06-01T17:52:47.620950Z"}]}
{"channel":"book","type":"update","data":[{"symbol":"LTC/USDT","bids":[{"price":83.24743,"qty":9.01456172}],"asks":[],"checksum":3534772385,"timestamp":"2024-06-01T17:52:47.656647Z"}]}
{"channel":"book","type":"update","data":[{"symbol":"LTC/USDT","bids":[],"asks":[{"price":83.31130,"qty":12.12017386}],"checksum":1605204503,"timestamp":"2024-06-01T17:52:47.677995Z"}]}
{"channel":"book","type":"update","data":[{"symbol":"LTC/USDT","bids":[],"asks":[{"price":83.30111,"qty":0.00000000},{"price":83.32816,"qty":3.02951062}],"checksum":412450269,"timestamp":"2024-06-01T17:52:47.828588Z"}]}
{"channel":"book","type":"update","data":[{"symbol":"LTC/USDT","bids":[{"price":83.25251,"qty":0.00000000},{"price":83.21003,"qty":3.02951062}],"asks":[],"checksum":766727423,"timestamp":"2024-06-01T17:52:48.069210Z"}]}
{"channel":"book","type":"update","data":[{"symbol":"LTC/USDT","bids":[{"price":83.24744,"qty":23.85306512}],"asks":[],"checksum":2258849531,"timestamp":"2024-06-01T17:52:48.073052Z"}]}
{"channel":"book","type":"update","data":[{"symbol":"LTC/USDT","bids":[{"price":83.25299,"qty":18.02898071}],"asks":[],"checksum":2852076431,"timestamp":"2024-06-01T17:52:48.109799Z"}]}
{"channel":"book","type":"update","data":[{"symbol":"LTC/USDT","bids":[{"price":83.23710,"qty":0.00000000},{"price":83.21015,"qty":9.76343889}],"asks":[],"checksum":1341331159,"timestamp":"2024-06-01T17:52:48.113440Z"}]}
{"channel":"book","type":"update","data":[{"symbol":"LTC/USDT","bids":[],"asks":[{"price":83.31229,"qty":20.17645256}],"checksum":1004497288,"timestamp":"2024-06-01T17:52:48.135058Z"}]}
{"channel":"book","type":"update","data":[{"symbol":"LTC/USDT","bids":[{"price":83.24743,"qty":0.00000000},{"price":83.21003,"qty":3.02951062}],"asks":[],"checksum":1931471841,"timestamp":"2024-06-01T17:52:48.166399Z"}]}
{"channel":"book","type":"update","data":[{"symbol":"LTC/USDT","bids":[{"price":83.24811,"qty":9.01449035}],"asks":[],"checksum":3437881553,"timestamp":"2024-06-01T17:52:48.278778Z"}]}
{"channel":"book","type":"update","data":[{"symbol":"LTC/USDT","bids":[],"asks":[{"price":83.28701,"qty":1.80000000}],"checksum":1735725334,"timestamp":"2024-06-01T17:52:48.311701Z"}]}
{"channel":"book","type":"update","data":[{"symbol":"LTC/USDT","bids":[],"asks":[{"price":83.28956,"qty":10.00000000}],"checksum":4098863404,"timestamp":"2024-06-01T17:52:48.317157Z"}]}
{"channel":"book","type":"update","data":[{"symbol":"LTC/USDT","bids":[],"asks":[{"price":83.28681,"qty":1.99000000}],"checksum":256643183,"timestamp":"2024-06-01T17:52:48.586978Z"}]}
{"channel":"book","type":"update","data":[{"symbol":"LTC/USDT","bids":[],"asks":[{"price":83.28701,"qty":0.00000000},{"price":83.31387,"qty":2.61000000}],"checksum":3773857254,"timestamp":"2024-06-01T17:52:48.589811Z"}]}
{"channel":"book","type":"update","data":[{"symbol":"LTC/USDT","bids":[],"asks":[{"price":83.28414,"qty":1.80000000}],"checksum":2757681099,"timestamp":"2024-06-01T17:52:48.589881Z"}]}
{"channel":"book","type":"update","data":[{"symbol":"LTC/USDT","bids":[],"asks":[{"price":83.28968,"qty":0.00000000},{"price":83.31387,"qty":2.61000000}],"checksum":280445878,"timestamp":"2024-06-01T17:52:48.592112Z"}]}
{"channel":"book","type":"update","data":[{"symbol":"LTC/USDT","bids":[],"asks":[{"price":83.28956,"qty":0.00000000},{"price":83.32262,"qty":23.85306512}],"checksum":3246776142,"timestamp":"2024-06-01T17:52:48.592394Z"}]}
{"channel":"book","type":"update","data":[{"symbol":"LTC/USDT","bids":[],"asks":[{"price":83.28689,"qty":10.00000000}],"checksum":4119408812,"timestamp":"2024-06-01T17:52:48.592467Z"}]}
{"channel":"book","type":"update","data":[{"symbol":"LTC/USDT","bids":[{"price":83.25299,"qty":0.00000000},{"price":83.21003,"qty":3.02951062}],"asks":[],"checksum":573954279,"timestamp":"2024-06-01T17:52:48.681991Z"}]}
{"channel":"book","type":"update","data":[{"symbol":"LTC/USDT","bids":[],"asks":[{"price":83.28394,"qty":1.99000000}],"checksum":3271534207,"timestamp":"2024-06-01T17:52:48.686665Z"}]}
{"channel":"book","type":"update","data":[{"symbol":"LTC/USDT","bids":[],"asks":[{"price":83.28669,"qty":10.00000000}],"checksum":3790494802,"timestamp":"2024-06-01T17:52:48.687872Z"}]}
{"channel":"book","type":"update","data":[{"symbol":"LTC/USDT","bids":[],"asks":[{"price":83.28689,"qty":0.00000000},{"price":83.31229,"qty":20.17645256}],"checksum":2866405858,"timestamp":"2024-06-01T17:52:48.687917Z"}]}
{"channel":"book","type":"update","data":[{"symbol":"LTC/USDT","bids":[],"asks":[{"price":83.28414,"qty":0.00000000},{"price":83.31387,"qty":2.61000000}],"checksum":1456691176,"timestamp":"2024-06-01T17:52:48.689568Z"}]}
{"channel":"book","type":"update","data":[{"symbol":"LTC/USDT","bids":[],"asks":[{"price":83.28127,"qty":1.80000000}],"checksum":4155589929,"timestamp":"2024-06-01T17:52:48.689705Z"}]}
{"channel":"book","type":"update","data":[{"symbol":"LTC/USDT","bids":[],"asks":[{"price":83.28669,"qty":0.00000000},{"price":83.31387,"qty":2.61000000}],"checksum":3335942918,"timestamp":"2024-06-01T17:52:48.710593Z"}]}
{"channel":"book","type":"update","data":[{"symbol":"LTC/USDT","bids":[{"price":83.24811,"qty":0.00000000},{"price":83.20977,"qty":8.19100000}],"asks":[],"checksum":1061316102,"timestamp":"2024-06-01T17:52:48.732721Z"}]}
{"channel":"book","type":"update","data":[{"symbol":"LTC/USDT","bids":[],"asks":[{"price":83.28394,"qty":0.00000000},{"price":83.32262,"qty":23.85306512}],"checksum":227665969,"timestamp":"2024-06-01T17:52:48.738776Z"}]}
{"channel":"book","type":"update","data":[{"symbol":"LTC/USDT","bids":[{"price":83.24812,"qty":9.01448698}],"asks":[],"checksum":436921559,"timestamp":"2024-06-01T17:52:48.772892Z"}]}
{"channel":"book","type":"update","data":[{"symbol":"LTC/USDT","bids":[],"asks":[{"price":83.28669,"qty":10.00000000}],"checksum":4211090871,"timestamp":"2024-06-01T17:52:48.778103Z"}]}
{"channel":"book","type":"update","data":[{"symbol":"LTC/USDT","bids":[],"asks":[{"price":83.31130,"qty":0.00000000},{"price":83.32262,"qty":23.85306512}],"checksum":1898669379,"timestamp":"2024-06-01T17:52:48.866381Z"}]}
{"channel":"book","type":"update","data":[{"symbol":"LTC/USDT","bids":[{"price":83.22289,"qty":0.00000000},{"price":83.20977,"qty":8.19100000}],"asks":[],"checksum":971185906,"timestamp":"2024-06-01T17:52:48.965794Z"}]}
{"channel":"book","type":"update","data":[{"symbol":"LTC/USDT","bids":[{"price":83.24813,"qty":23.85306512}],"asks":[],"checksum":690599176,"timestamp":"2024-06-01T17:52:49.021759Z"}]}
{"channel":"book","type":"update","data":[{"symbol":"LTC/USDT","bids":[],"asks":[{"price":83.28988,"qty":0.00000000},{"price":83.32787,"qty":36.00236031}],"checksum":1137048999,"timestamp":"2024-06-01T17:52:49.026703Z"}]}
{"channel":"book","type":"update","data":[{"symbol":"LTC/USDT","bids":[{"price":83.22909,"qty":10.00000000}],"asks":[],"checksum":725713230,"timestamp":"2024-06-01T17:52:49.223015Z"}]}
{"channel":"book","type":"update","data":[{"symbol":"LTC/USDT","bids":[{"price":83.25243,"qty":18.02916158}],"asks":[],"checksum":1683285548,"timestamp":"2024-06-01T17:52:49.238202Z"}]}
{"channel":"book","type":"update","data":[{"symbol":"LTC/USDT","bids":[{"price":83.24813,"qty":0.00000000},{"price":83.21015,"qty":9.76343889}],"asks":[],"checksum":1307029235,"timestamp":"2024-06-01T17:52:49.241922Z"}]}
{"channel":"book","type":"update","data":[{"symbol":"LTC/USDT","bids":[{"price":83.24812,"qty":0.00000000},{"price":83.21003,"qty":3.02951062}],"asks":[],"checksum":2377947919,"timestamp":"2024-06-01T17:52:49.288888Z"}]}
{"channel":"book","type":"update","data":[{"symbol":"LTC/USDT","bids":[],"asks":[{"price":83.28107,"qty":1.99000000}],"checksum":1067023294,"timestamp":"2024-06-01T17:52:49.588831Z"}]}
{"channel":"book","type":"update","data":[{"symbol":"LTC/USDT","bids":[],"asks":[{"price":83.28681,"qty":0.00000000},{"price":83.32787,"qty":36.00236031}],"checksum":3111361881,"timestamp":"2024-06-01T17:52:49.593499Z"}]}
{"channel":"book","type":"update","data":[{"symbol":"LTC/USDT","bids":[],"asks":[{"price":83.28127,"qty":0.00000000},{"price":83.32816,"qty":3.02951062}],"checksum":761838431,"timestamp":"2024-06-01T17:52:49.628368Z"}]}
{"channel":"book","type":"update","data":[{"symbol":"LTC/USDT","bids":[],"asks":[{"price":83.27840,"qty":1.80000000}],"checksum":851216738,"timestamp":"2024-06-01T17:52:49.628501Z"}]}
{"channel":"book","type":"update","data":[{"symbol":"LTC/USDT","bids":[],"asks":[{"price":83.28669,"qty":0.00000000},{"price":83.32816,"qty":3.02951062}],"checksum":3657747699,"timestamp":"2024-06-01T17:52:49.639306Z"}]}
{"channel":"book","type":"update","data":[{"symbol":"LTC/USDT","bids":[],"asks":[{"price":83.28988,"qty":10.00000000}],"checksum":593608354,"timestamp":"2024-06-01T17:52:49.639479Z"}]}
{"channel":"book","type":"update","data":[{"symbol":"LTC/USDT","bids":[{"price":83.25243,"qty":0.00000000},{"price":83.20977,"qty":8.19100000}],"asks":[],"checksum":1255389692,"timestamp":"2024-06-01T17:52:49.691454Z"}]}
{"channel":"book","type":"update","data":[{"symbol":"LTC/USDT","bids":[{"price":83.25298,"qty":18.02909724}],"asks":[],"checksum":148561515,"timestamp":"2024-06-01T17:52:49.731769Z"}]}
{"channel":"book","type":"update","data":[{"symbol":"LTC/USDT","bids":[{"price":83.24789,"qty":9.01454862}],"asks":[],"checksum":1211153954,"timestamp":"2024-06-01T17:52:49.841777Z"}]}
{"channel":"book","type":"update","data":[{"symbol":"LTC/USDT","bids":[{"price":83.21054,"qty":8.13800000}],"asks":[],"checksum":2799898116,"timestamp":"2024-06-01T17:52:50.042002Z"}]}
{"channel":"book","type":"update","data":[{"symbol":"LTC/USDT","bids":[{"price":83.25298,"qty":0.00000000},{"price":83.21015,"qty":9.76343889}],"asks":[],"checksum":1339867416,"timestamp":"2024-06-01T17:52:50.249759Z"}]}
{"channel":"book","type":"update","data":[{"symbol":"LTC/USDT","bids":[{"price":83.24790,"qty":23.85306512}],"asks":[],"checksum":3818740357,"timestamp":"2024-06-01T17:52:50.253850Z"}]}
{"channel":"book","type":"update","data":[{"symbol":"LTC/USDT","bids":[{"price":83.24789,"qty":0.00000000},{"price":83.21015,"qty":9.76343889}],"asks":[],"checksum":2445825204,"timestamp":"2024-06-01T17:52:50.288786Z"}]}
{"channel":"book","type":"update","data":[{"symbol":"LTC/USDT","bids":[{"price":83.25276,"qty":18.02917171}],"asks":[],"checksum":1737907356,"timestamp":"2024-06-01T17:52:50.290071Z"}]}
{"channel":"book","type":"update","data":[{"symbol":"LTC/USDT","bids":[{"price":83.24790,"qty":0.00000000},{"price":83.21015,"qty":9.76343889}],"asks":[],"checksum":667596995,"timestamp":"2024-06-01T17:52:50.292266Z"}]}
{"channel":"book","type":"update","data":[{"symbol":"LTC/USDT","bids":[{"price":83.24768,"qty":9.01458585}],"asks":[],"checksum":365946883,"timestamp":"2024-06-01T17:52:50.328919Z"}]}
{"channel":"book","type":"update","data":[{"symbol":"LTC/USDT","bids":[{"price":83.25277,"qty":23.85306512}],"asks":[],"checksum":4198087290,"timestamp":"2024-06-01T17:52:50.332301Z"}]}
{"channel":"book","type":"update","data":[{"symbol":"LTC/USDT","bids":[{"price":83.24744,"qty":0.00000000},{"price":83.21054,"qty":8.13800000}],"asks":[],"checksum":1242083816,"timestamp":"2024-06-01T17:52:50.508217Z"}]}
{"channel":"book","type":"update","data":[{"symbol":"LTC/USDT","bids":[],"asks":[{"price":83.27820,"qty":1.99000000}],"checksum":455396538,"timestamp":"2024-06-01T17:52:50.512952Z"}]}
{"channel":"book","type":"update","data":[{"symbol":"LTC/USDT","bids":[],"asks":[{"price":83.27840,"qty":0.00000000},{"price":83.32787,"qty":36.00236031}],"checksum":858738802,"timestamp":"2024-06-01T17:52:50.515624Z"}]}
{"channel":"book","type":"update","data":[{"symbol":"LTC/USDT","bids":[],"asks":[{"price":83.27743,"qty":1.80000000}],"checksum":2221308362,"timestamp":"2024-06-01T17:52:50.515804Z"}]}
{"channel":"book","type":"update","data":[{"symbol":"LTC/USDT","bids":[],"asks":[{"price":83.27820,"qty":0.00000000},{"price":83.32787,"qty":36.00236031}],"checksum":3922371059,"timestamp":"2024-06-01T17:52:50.589072Z"}]}
{"channel":"book","type":"update","data":[{"symbol":"LTC/USDT","bids":[{"price":83.25276,"qty":0.00000000},{"price":83.21015,"qty":9.76343889}],"asks":[],"checksum":525368547,"timestamp":"2024-06-01T17:52:50.802106Z"}]}
{"channel":"book","type":"update","data":[{"symbol":"LTC/USDT","bids":[{"price":83.25277,"qty":0.00000000},{"price":83.21003,"qty":3.02951062}],"asks":[],"checksum":1248751618,"timestamp":"2024-06-01T17:52:50.806569Z"}]}
{"channel":"book","type":"update","data":[{"symbol":"LTC/USDT","bids":[{"price":83.24768,"qty":0.00000000},{"price":83.20870,"qty":7.87361491}],"asks":[],"checksum":967751344,"timestamp":"2024-06-01T17:52:50.846695Z"}]}
{"channel":"book","type":"update","data":[{"symbol":"LTC/USDT","bids":[{"price":83.21671,"qty":3.60587690}],"asks":[],"checksum":2003147932,"timestamp":"2024-06-01T17:52:50.851744Z"}]}
{"channel":"book","type":"update","data":[{"symbol":"LTC/USDT","bids":[{"price":83.25319,"qty":18.02917171}],"asks":[],"checksum":3869961270,"timestamp":"2024-06-01T17:52:51.356243Z"}]}
{"channel":"book","type":"update","data":[{"symbol":"LTC/USDT","bids":[{"price":83.25320,"qty":23.85306512}],"asks":[],"checksum":3947607537,"timestamp":"2024-06-01T17:52:51.360473Z"}]}
{"channel":"book","type":"update","data":[{"symbol":"LTC/USDT","bids":[{"price":83.21671,"qty":0.00000000},{"price":83.21015,"qty":9.76343889}],"asks":[],"checksum":1762271579,"timestamp":"2024-06-01T17:52:51.360912Z"}]}
{"channel":"book","type":"update","data":[{"symbol":"LTC/USDT","bids":[{"price":83.24811,"qty":9.01458585}],"asks":[],"checksum":3446795547,"timestamp":"2024-06-01T17:52:51.400266Z"}]}
{"channel":"book","type":"update","data":[{"symbol":"LTC/USDT","bids":[],"asks":[{"price":83.27723,"qty":1.99000000}],"checksum":1175746525,"timestamp":"2024-06-01T17:52:51.586814Z"}]}
{"channel":"book","type":"update","data":[{"symbol":"LTC/USDT","bids":[],"asks":[{"price":83.27743,"qty":0.00000000},{"price":83.32787,"qty":36.00236031}],"checksum":3025538177,"timestamp":"2024-06-01T17:52:51.589661Z"}]}
{"channel":"book","type":"update","data":[{"symbol":"LTC/USDT","bids":[],"asks":[{"price":83.27711,"qty":1.80000000}],"checksum":450698056,"timestamp":"2024-06-01T17:52:51.589899Z"}]}
{"channel":"book","type":"update","data":[{"symbol":"LTC/USDT","bids":[],"asks":[{"price":83.28107,"qty":0.00000000},{"price":83.32787,"qty":36.00236031}],"checksum":379652418,"timestamp":"2024-06-01T17:52:51.592440Z"}]}
{"channel":"book","type":"update","data":[{"symbol":"LTC/USDT","bids":[],"asks":[{"price":83.27691,"qty":1.99000000}],"checksum":2841912189,"timestamp":"2024-06-01T17:52:52.086751Z"}]}
{"channel":"book","type":"update","data":[{"symbol":"LTC/USDT","bids":[],"asks":[{"price":83.27723,"qty":0.00000000},{"price":83.32787,"qty":36.00236031}],"checksum":1094695398,"timestamp":"2024-06-01T17:52:52.091129Z"}]}
{"channel":"book","type":"update","data":[{"symbol":"LTC/USDT","bids":[],"asks":[{"price":83.27711,"qty":0.00000000},{"price":83.32816,"qty":3.02951062}],"checksum":2011643210,"timestamp":"2024-06-01T17:52:52.094211Z"}]}
{"channel":"book","type":"update","data":[{"symbol":"LTC/USDT","bids":[],"asks":[{"price":83.28722,"qty":1.80000000}],"checksum":1996207730,"timestamp":"2024-06-01T17:52:52.094222Z"}]}
{"channel":"book","type":"update","data":[{"symbol":"LTC/USDT","bids":[],"asks":[{"price":83.28710,"qty":10.00000000}],"checksum":1015870910,"timestamp":"2024-06-01T17:52:52.211598Z"}]}
{"channel":"book","type":"update","data":[{"symbol":"LTC/USDT","bids":[],"asks":[{"price":83.28722,"qty":0.00000000},{"price":83.32787,"qty":36.00236031}],"checksum":2883351104,"timestamp":"2024-06-01T17:52:52.214404Z"}]}
{"channel":"book","type":"update","data":[{"symbol":"LTC/USDT","bids":[],"asks":[{"price":83.28444,"qty":1.80000000}],"checksum":3243716283,"timestamp":"2024-06-01T17:52:52.214671Z"}]}
{"channel":"book","type":"update","data":[{"symbol":"LTC/USDT","bids":[],"asks":[{"price":83.28988,"qty":0.00000000},{"price":83.32787,"qty":36.00236031}],"checksum":2270461066,"timestamp":"2024-06-01T17:52:52.217257Z"}]}
{"channel":"book","type":"update","data":[{"symbol":"LTC/USDT","bids":[{"price":83.25319,"qty":0.00000000},{"price":83.21015,"qty":9.76343889}],"asks":[],"checksum":615554124,"timestamp":"2024-06-01T17:52:52.316911Z"}]}
{"channel":"book","type":"update","data":[{"symbol":"LTC/USDT","bids":[{"price":83.25320,"qty":0.00000000},{"price":83.21003,"qty":3.02951062}],"asks":[],"checksum":840831074,"timestamp":"2024-06-01T17:52:52.321131Z"}]}
{"channel":"book","type":"update","data":[{"symbol":"LTC/USDT","bids":[{"price":83.24812,"qty":23.85306512}],"asks":[],"checksum":116409054,"timestamp":"2024-06-01T17:52:52.321270Z"}]}
{"channel":"book","type":"update","data":[{"symbol":"LTC/USDT","bids":[{"price":83.25543,"qty":18.02867460}],"asks":[],"checksum":3902596771,"timestamp":"2024-06-01T17:52:52.357104Z"}]}
{"channel":"book","type":"update","data":[{"symbol":"LTC/USDT","bids":[{"price":83.24811,"qty":0.00000000},{"price":83.21015,"qty":9.76343889}],"asks":[],"checksum":1290218211,"timestamp":"2024-06-01T17:52:52.359885Z"}]}
{"channel":"book","type":"update","data":[{"symbol":"LTC/USDT","bids":[],"asks":[{"price":83.31229,"qty":0.00000000},{"price":83.32816,"qty":3.02951062}],"checksum":2751480111,"timestamp":"2024-06-01T17:52:52.360144Z"}]}
{"channel":"book","type":"update","data":[{"symbol":"LTC/USDT","bids":[{"price":83.25035,"qty":9.01446186}],"asks":[],"checksum":2075264350,"timestamp":"2024-06-01T17:52:52.400002Z"}]}
{"channel":"book","type":"update","data":[{"symbol":"LTC/USDT","bids":[],"asks":[{"price":83.30485,"qty":10.00000000}],"checksum":932978026,"timestamp":"2024-06-01T17:52:52.630685Z"}]}
{"channel":"book","type":"update","data":[{"symbol":"LTC/USDT","bids":[{"price":83.25543,"qty":0.00000000},{"price":83.21015,"qty":9.76343889}],"asks":[],"checksum":4053277570,"timestamp":"2024-06-01T17:52:52.822692Z"}]}
{"channel":"book","type":"update","data":[{"symbol":"LTC/USDT","bids":[],"asks":[{"price":83.27691,"qty":0.00000000},{"price":83.32816,"qty":3.02951062}],"checksum":213011489,"timestamp":"2024-06-01T17:52:52.828044Z"}]}
{"channel":"book","type":"update","data":[{"symbol":"LTC/USDT","bids":[{"price":83.25543,"qty":18.02892373}],"asks":[],"checksum":4258627522,"timestamp":"2024-06-01T17:52:53.056237Z"}]}
{"channel":"book","type":"update","data":[{"symbol":"LTC/USDT","bids":[],"asks":[{"price":83.28988,"qty":10.00000000}],"checksum":3805610894,"timestamp":"2024-06-01T17:52:53.061011Z"}]}
{"channel":"book","type":"update","data":[{"symbol":"LTC/USDT","bids":[],"asks":[{"price":83.28710,"qty":0.00000000},{"price":83.32816,"qty":3.02951062}],"checksum":3360699233,"timestamp":"2024-06-01T17:52:53.061151Z"}]}
{"channel":"book","type":"update","data":[{"symbol":"LTC/USDT","bids":[],"asks":[{"price":83.28424,"qty":1.99000000}],"checksum":2630444286,"timestamp":"2024-06-01T17:52:53.061382Z"}]}
{"channel":"book","type":"update","data":[{"symbol":"LTC/USDT","bids":[],"asks":[{"price":83.28444,"qty":0.00000000},{"price":83.32816,"qty":3.02951062}],"checksum":2977420027,"timestamp":"2024-06-01T17:52:53.064231Z"}]}
{"channel":"book","type":"update","data":[{"symbol":"LTC/USDT","bids":[],"asks":[{"price":83.28158,"qty":1.80000000}],"checksum":1523591043,"timestamp":"2024-06-01T17:52:53.064380Z"}]}
{"channel":"book","type":"update","data":[{"symbol":"LTC/USDT","bids":[],"asks":[{"price":83.30485,"qty":0.00000000},{"price":83.32816,"qty":3.02951062}],"checksum":1636681908,"timestamp":"2024-06-01T17:52:53.383733Z"}]}
{"channel":"book","type":"update","data":[{"symbol":"LTC/USDT","bids":[{"price":83.25543,"qty":0.00000000},{"price":83.21015,"qty":9.76343889}],"asks":[],"checksum":1560515557,"timestamp":"2024-06-01T17:52:53.503858Z"}]}
{"channel":"book","type":"update","data":[{"symbol":"LTC/USDT","bids":[{"price":83.25035,"qty":0.00000000},{"price":83.21003,"qty":3.02951062}],"asks":[],"checksum":3176491051,"timestamp":"2024-06-01T17:52:53.504189Z"}]}
{"channel":"book","type":"update","data":[{"symbol":"LTC/USDT","bids":[],"asks":[{"price":83.28138,"qty":1.99000000}],"checksum":1598569927,"timestamp":"2024-06-01T17:52:53.509274Z"}]}
{"channel":"book","type":"update","data":[{"symbol":"LTC/USDT","bids":[],"asks":[{"price":83.28158,"qty":0.00000000},{"price":83.32816,"qty":3.02951062}],"checksum":807863412,"timestamp":"2024-06-01T17:52:53.511773Z"}]}
{"channel":"book","type":"update","data":[{"symbol":"LTC/USDT","bids":[],"asks":[{"price":83.27892,"qty":1.80000000}],"checksum":196298605,"timestamp":"2024-06-01T17:52:53.512104Z"}]}
{"channel":"book","type":"update","data":[{"symbol":"LTC/USDT","bids":[{"price":83.24812,"qty":0.00000000},{"price":83.20979,"qty":2.55000000}],"asks":[],"checksum":2499483927,"timestamp":"2024-06-01T17:52:53.514527Z"}]}
{"channel":"book","type":"update","data":[{"symbol":"LTC/USDT","bids":[{"price":83.23710,"qty":23.85306512}],"asks":[],"checksum":1659460158,"timestamp":"2024-06-01T17:52:53.514550Z"}]}
{"channel":"book","type":"update","data":[{"symbol":"LTC/USDT","bids":[{"price":83.23793,"qty":16.22423823}],"asks":[],"checksum":779872858,"timestamp":"2024-06-01T17:52:53.517446Z"}]}
{"channel":"book","type":"update","data":[{"symbol":"LTC/USDT","bids":[{"price":83.23709,"qty":0.00000000},{"price":83.21003,"qty":3.02951062}],"asks":[],"checksum":2235769611,"timestamp":"2024-06-01T17:52:53.520432Z"}]}
{"channel":"book","type":"update","data":[{"symbol":"LTC/USDT","bids":[{"price":83.24982,"qty":9.01450429}],"asks":[],"checksum":164612819,"timestamp":"2024-06-01T17:52:53.544101Z"}]}
{"channel":"book","type":"update","data":[{"symbol":"LTC/USDT","bids":[{"price":83.25490,"qty":18.02900858}],"asks":[],"checksum":2822046581,"timestamp":"2024-06-01T17:52:53.544254Z"}]}
{"channel":"book","type":"update","data":[{"symbol":"LTC/USDT","bids":[{"price":83.24983,"qty":23.85306512}],"asks":[],"checksum":1154955308,"timestamp":"2024-06-01T17:52:53.548311Z"}]}
{"channel":"book","type":"update","data":[{"symbol":"LTC/USDT","bids":[],"asks":[{"price":83.28138,"qty":0.00000000},{"price":83.32816,"qty":3.02951062}],"checksum":1581637688,"timestamp":"2024-06-01T17:52:53.549670Z"}]}
{"channel":"book","type":"update","data":[{"symbol":"LTC/USDT","bids":[],"asks":[{"price":83.27892,"qty":0.00000000},{"price":83.34094,"qty":2.34609048}],"checksum":1161642486,"timestamp":"2024-06-01T17:52:53.648245Z"}]}
{"channel":"book","type":"update","data":[{"symbol":"LTC/USDT","bids":[],"asks":[{"price":83.28304,"qty":1.80000000}],"checksum":923327022,"timestamp":"2024-06-01T17:52:53.648417Z"}]}
{"channel":"book","type":"update","data":[{"symbol":"LTC/USDT","bids":[{"price":83.23710,"qty":0.00000000},{"price":83.21054,"qty":8.13800000}],"asks":[],"checksum":2209049488,"timestamp":"2024-06-01T17:52:53.652229Z"}]}
{"channel":"book","type":"update","data":[{"symbol":"LTC/USDT","bids":[],"asks":[{"price":83.30485,"qty":10.00000000}],"checksum":1512474260,"timestamp":"2024-06-01T17:52:53.677041Z"}]}
{"channel":"book","type":"update","data":[{"symbol":"LTC/USDT","bids":[],"asks":[{"price":83.30485,"qty":0.00000000},{"price":83.32816,"qty":3.02951062}],"checksum":2209049488,"timestamp":"2024-06-01T17:52:53.929439Z"}]}
{"channel":"book","type":"update","data":[{"symbol":"LTC/USDT","bids":[{"price":83.24982,"qty":0.00000000},{"price":83.21015,"qty":9.76343889}],"asks":[],"checksum":1322611635,"timestamp":"2024-06-01T17:52:53.990951Z"}]}
{"channel":"book","type":"update","data":[{"symbol":"LTC/USDT","bids":[{"price":83.25257,"qty":9.01425497}],"asks":[],"checksum":2291158840,"timestamp":"2024-06-01T17:52:54.031484Z"}]}
{"channel":"book","type":"update","data":[{"symbol":"LTC/USDT","bids":[{"price":83.25490,"qty":0.00000000},{"price":83.21015,"qty":9.76343889}],"asks":[],"checksum":22942825,"timestamp":"2024-06-01T17:52:54.055641Z"}]}
{"channel":"book","type":"update","data":[{"symbol":"LTC/USDT","bids":[{"price":83.25732,"qty":18.02858977}],"asks":[],"checksum":1230906258,"timestamp":"2024-06-01T17:52:54.095746Z"}]}
{"channel":"book","type":"update","data":[{"symbol":"LTC/USDT","bids":[],"asks":[{"price":83.30498,"qty":10.00000000}],"checksum":3807973688,"timestamp":"2024-06-01T17:52:54.202739Z"}]}
{"channel":"book","type":"update","data":[{"symbol":"LTC/USDT","bids":[{"price":83.25257,"qty":0.00000000},{"price":83.21015,"qty":9.76343889}],"asks":[],"checksum":616312243,"timestamp":"2024-06-01T17:52:54.541713Z"}]}
{"channel":"book","type":"update","data":[{"symbol":"LTC/USDT","bids":[],"asks":[{"price":83.28284,"qty":1.99000000}],"checksum":3243053071,"timestamp":"2024-06-01T17:52:54.547210Z"}]}
{"channel":"book","type":"update","data":[{"symbol":"LTC/USDT","bids":[],"asks":[{"price":83.28304,"qty":0.00000000},{"price":83.32787,"qty":36.00236031}],"checksum":805560697,"timestamp":"2024-06-01T17:52:54.549865Z"}]}
{"channel":"book","type":"update","data":[{"symbol":"LTC/USDT","bids":[],"asks":[{"price":83.28100,"qty":1.80000000}],"checksum":1450948419,"timestamp":"2024-06-01T17:52:54.550089Z"}]}
{"channel":"book","type":"update","data":[{"symbol":"LTC/USDT","bids":[{"price":83.25238,"qty":9.01431721}],"asks":[],"checksum":2285730305,"timestamp":"2024-06-01T17:52:54.582351Z"}]}
{"channel":"book","type":"update","data":[{"symbol":"LTC/USDT","bids":[],"asks":[{"price":83.28284,"qty":0.00000000},{"price":83.32787,"qty":36.00236031}],"checksum":2466256080,"timestamp":"2024-06-01T17:52:54.588299Z"}]}
{"channel":"book","type":"update","data":[{"symbol":"LTC/USDT","bids":[{"price":83.25732,"qty":0.00000000},{"price":83.21015,"qty":9.76343889}],"asks":[],"checksum":1205505174,"timestamp":"2024-06-01T17:52:54.605940Z"}]}
{"channel":"book","type":"update","data":[{"symbol":"LTC/USDT","bids":[{"price":83.21054,"qty":0.00000000},{"price":83.21003,"qty":3.02951062}],"asks":[],"checksum":2612417224,"timestamp":"2024-06-01T17:52:54.768979Z"}]}
{"channel":"book","type":"update","data":[{"symbol":"LTC/USDT","bids":[{"price":83.25239,"qty":23.85306512}],"asks":[],"checksum":3980199235,"timestamp":"2024-06-01T17:52:55.007720Z"}]}
{"channel":"book","type":"update","data":[{"symbol":"LTC/USDT","bids":[],"asks":[{"price":83.28080,"qty":1.99000000}],"checksum":2958916372,"timestamp":"2024-06-01T17:52:55.013077Z"}]}
{"channel":"book","type":"update","data":[{"symbol":"LTC/USDT","bids":[],"asks":[{"price":83.28424,"qty":0.00000000},{"price":83.32787,"qty":36.00236031}],"checksum":3541076220,"timestamp":"2024-06-01T17:52:55.086283Z"}]}
{"channel":"book","type":"update","data":[{"symbol":"LTC/USDT","bids":[],"asks":[{"price":83.28100,"qty":0.00000000},{"price":83.32816,"qty":3.02951062}],"checksum":373603984,"timestamp":"2024-06-01T17:52:55.089377Z"}]}
{"channel":"book","type":"update","data":[{"symbol":"LTC/USDT","bids":[],"asks":[{"price":83.28722,"qty":1.80000000}],"checksum":2735658772,"timestamp":"2024-06-01T17:52:55.089559Z"}]}
{"channel":"book","type":"update","data":[{"symbol":"LTC/USDT","bids":[{"price":83.24983,"qty":0.00000000},{"price":83.21003,"qty":3.02951062}],"asks":[],"checksum":3516857122,"timestamp":"2024-06-01T17:52:55.090545Z"}]}
{"channel":"book","type":"update","data":[{"symbol":"LTC/USDT","bids":[{"price":83.25238,"qty":0.00000000},{"price":83.20979,"qty":2.55000000}],"asks":[],"checksum":3560467237,"timestamp":"2024-06-01T17:52:55.093016Z"}]}
{"channel":"book","type":"update","data":[{"symbol":"LTC/USDT","bids":[{"price":83.25751,"qty":18.02865150}],"asks":[],"checksum":755633039,"timestamp":"2024-06-01T17:52:55.093031Z"}]}
{"channel":"book","type":"update","data":[{"symbol":"LTC/USDT","bids":[],"asks":[{"price":83.28722,"qty":0.00000000},{"price":83.32816,"qty":3.02951062}],"checksum":2554356235,"timestamp":"2024-06-01T17:52:55.093131Z"}]}
{"channel":"book","type":"update","data":[{"symbol":"LTC/USDT","bids":[],"asks":[{"price":83.28060,"qty":1.80000000}],"checksum":3314714066,"timestamp":"2024-06-01T17:52:55.093224Z"}]}
{"channel":"book","type":"update","data":[{"symbol":"LTC/USDT","bids":[{"price":83.25243,"qty":9.01432575}],"asks":[],"checksum":3660645858,"timestamp":"2024-06-01T17:52:55.133061Z"}]}
{"channel":"book","type":"update","data":[{"symbol":"LTC/USDT","bids":[{"price":83.25243,"qty":0.00000000},{"price":83.21003,"qty":3.02951062}],"asks":[],"checksum":3314714066,"timestamp":"2024-06-01T17:52:55.579084Z"}]}
{"channel":"book","type":"update","data":[{"symbol":"LTC/USDT","bids":[],"asks":[{"price":83.28040,"qty":1.99000000}],"checksum":2940023656,"timestamp":"2024-06-01T17:52:55.586400Z"}]}
{"channel":"book","type":"update","data":[{"symbol":"LTC/USDT","bids":[],"asks":[{"price":83.28060,"qty":0.00000000},{"price":83.32787,"qty":36.00236031}],"checksum":3443129764,"timestamp":"2024-06-01T17:52:55.589119Z"}]}
{"channel":"book","type":"update","data":[{"symbol":"LTC/USDT","bids":[],"asks":[{"price":83.27955,"qty":1.80000000}],"checksum":1661621429,"timestamp":"2024-06-01T17:52:55.589389Z"}]}
{"channel":"book","type":"update","data":[{"symbol":"LTC/USDT","bids":[{"price":83.25751,"qty":0.00000000},{"price":83.20979,"qty":2.55000000}],"asks":[],"checksum":3504604615,"timestamp":"2024-06-01T17:52:55.604960Z"}]}
{"channel":"book","type":"update","data":[{"symbol":"LTC/USDT","bids":[{"price":83.25294,"qty":9.01429033}],"asks":[],"checksum":137731850,"timestamp":"2024-06-01T17:52:55.619347Z"}]}
{"channel":"book","type":"update","data":[{"symbol":"LTC/USDT","bids":[{"price":83.25295,"qty":23.85306512}],"asks":[],"checksum":1181485003,"timestamp":"2024-06-01T17:52:55.623086Z"}]}
{"channel":"book","type":"update","data":[{"symbol":"LTC/USDT","bids":[],"asks":[{"price":83.28040,"qty":0.00000000},{"price":83.32787,"qty":36.00236031}],"checksum":390670594,"timestamp":"2024-06-01T17:52:55.624747Z"}]}
{"channel":"book","type":"update","data":[{"symbol":"LTC/USDT","bids":[{"price":83.25749,"qty":18.02865150}],"asks":[],"checksum":3917025643,"timestamp":"2024-06-01T17:52:55.645529Z"}]}
{"channel":"book","type":"update","data":[{"symbol":"LTC/USDT","bids":[],"asks":[{"price":83.30498,"qty":0.00000000},{"price":83.32816,"qty":3.02951062}],"checksum":2060923090,"timestamp":"2024-06-01T17:52:55.702936Z"}]}
{"channel":"book","type":"update","data":[{"symbol":"LTC/USDT","bids":[],"asks":[{"price":83.30493,"qty":10.00000000}],"checksum":966034551,"timestamp":"2024-06-01T17:52:55.991999Z"}]}
{"channel":"book","type":"update","data":[{"symbol":"LTC/USDT","bids":[{"price":83.25295,"qty":0.00000000},{"price":83.21015,"qty":9.76343889}],"asks":[],"checksum":3538187109,"timestamp":"2024-06-01T17:52:56.006882Z"}]}
{"channel":"book","type":"update","data":[{"symbol":"LTC/USDT","bids":[{"price":83.25294,"qty":0.00000000},{"price":83.21003,"qty":3.02951062}],"asks":[],"checksum":1472448986,"timestamp":"2024-06-01T17:52:56.132400Z"}]}
{"channel":"book","type":"update","data":[{"symbol":"LTC/USDT","bids":[{"price":83.25749,"qty":0.00000000},{"price":83.20979,"qty":2.55000000}],"asks":[],"checksum":2687297257,"timestamp":"2024-06-01T17:52:56.156429Z"}]}
{"channel":"book","type":"update","data":[{"symbol":"LTC/USDT","bids":[{"price":83.25239,"qty":0.00000000},{"price":83.20924,"qty":8.37200000}],"asks":[],"checksum":1393608697,"timestamp":"2024-06-01T17:52:56.506749Z"}]}
