{"channel":"book","type":"snapshot","data":[{"symbol":"LTC/EUR","bids":[{"price":76.73,"qty":60.08036228},{"price":76.72,"qty":24.09345319},{"price":76.71,"qty":67.63104983},{"price":76.70,"qty":223.13635476},{"price":76.69,"qty":83.59282771},{"price":76.68,"qty":153.07203847},{"price":76.67,"qty":94.21381224},{"price":76.66,"qty":8.56249336},{"price":76.65,"qty":162.16877545},{"price":76.64,"qty":6.01200000}],"asks":[{"price":76.74,"qty":0.15255723},{"price":76.75,"qty":0.46524243},{"price":76.76,"qty":79.81521254},{"price":76.77,"qty":30.30000000},{"price":76.78,"qty":62.69110993},{"price":76.80,"qty":60.03019863},{"price":76.81,"qty":75.94100000},{"price":76.82,"qty":2.68579621},{"price":76.83,"qty":108.17849511},{"price":76.84,"qty":60.00096596}],"checksum":1432324665}]}
{"channel":"book","type":"update","data":[{"symbol":"LTC/EUR","bids":[{"price":76.66,"qty":2.65000000}],"asks":[],"checksum":4206057075,"timestamp":"2024-06-01T17:52:08.691923Z"}]}
{"channel":"book","type":"update","data":[{"symbol":"LTC/EUR","bids":[{"price":76.66,"qty":9.49474814}],"asks":[],"checksum":2958357211,"timestamp":"2024-06-01T17:52:08.734529Z"}]}
{"channel":"book","type":"update","data":[{"symbol":"LTC/EUR","bids":[{"price":76.69,"qty":75.29082771}],"asks":[],"checksum":1022804922,"timestamp":"2024-06-01T17:52:10.673501Z"}]}
{"channel":"book","type":"update","data":[{"symbol":"LTC/EUR","bids":[{"price":76.70,"qty":231.33635476}],"asks":[],"checksum":3680818992,"timestamp":"2024-06-01T17:52:10.676195Z"}]}
{"channel":"book","type":"update","data":[{"symbol":"LTC/EUR","bids":[{"price":76.66,"qty":2.65000000}],"asks":[],"checksum":2441311128,"timestamp":"2024-06-01T17:52:10.839371Z"}]}
{"channel":"book","type":"update","data":[{"symbol":"LTC/EUR","bids":[{"price":76.66,"qty":10.24055195}],"asks":[],"checksum":3585438916,"timestamp":"2024-06-01T17:52:10.845634Z"}]}
{"channel":"book","type":"update","data":[{"symbol":"LTC/EUR","bids":[{"price":76.65,"qty":157.72227545}],"asks":[],"checksum":3387305525,"timestamp":"2024-06-01T17:52:11.651436Z"}]}
{"channel":"book","type":"update","data":[{"symbol":"LTC/EUR","bids":[{"price":76.65,"qty":137.90807545}],"asks":[],"checksum":1173116548,"timestamp":"2024-06-01T17:52:11.702672Z"}]}
{"channel":"book","type":"update","data":[{"symbol":"LTC/EUR","bids":[{"price":76.65,"qty":158.34197545}],"asks":[],"checksum":3710343900,"timestamp":"2024-06-01T17:52:12.714874Z"}]}
{"channel":"book","type":"update","data":[{"symbol":"LTC/EUR","bids":[{"price":76.65,"qty":162.56007545}],"asks":[],"checksum":801335198,"timestamp":"2024-06-01T17:52:12.730247Z"}]}
{"channel":"book","type":"update","data":[{"symbol":"LTC/EUR","bids":[{"price":76.66,"qty":2.65000000}],"asks":[],"checksum":1811243202,"timestamp":"2024-06-01T17:52:12.911028Z"}]}
{"channel":"book","type":"update","data":[{"symbol":"LTC/EUR","bids":[{"price":76.71,"qty":65.89320470}],"asks":[],"checksum":986666967,"timestamp":"2024-06-01T17:52:12.911071Z"}]}
{"channel":"book","type":"update","data":[{"symbol":"LTC/EUR","bids":[],"asks":[{"price":76.82,"qty":0.24038807},{"price":76.81,"qty":78.38640814}],"checksum":1767781688,"timestamp":"2024-06-01T17:52:12.914935Z"}]}
{"channel":"book","type":"update","data":[{"symbol":"LTC/EUR","bids":[{"price":76.71,"qty":67.44386770}],"asks":[],"checksum":3032206213,"timestamp":"2024-06-01T17:52:12.917024Z"}]}
{"channel":"book","type":"update","data":[{"symbol":"LTC/EUR","bids":[{"price":76.64,"qty":13.97947534}],"asks":[],"checksum":1457691243,"timestamp":"2024-06-01T17:52:12.917349Z"}]}
{"channel":"book","type":"update","data":[{"symbol":"LTC/EUR","bids":[{"price":76.64,"qty":6.01200000}],"asks":[],"checksum":3032206213,"timestamp":"2024-06-01T17:52:15.103532Z"}]}
{"channel":"book","type":"update","data":[{"symbol":"LTC/EUR","bids":[{"price":76.71,"qty":65.89320470}],"asks":[],"checksum":1767781688,"timestamp":"2024-06-01T17:52:15.103559Z"}]}
{"channel":"book","type":"update","data":[{"symbol":"LTC/EUR","bids":[{"price":76.66,"qty":10.42700290}],"asks":[],"checksum":3256394749,"timestamp":"2024-06-01T17:52:15.147879Z"}]}
{"channel":"book","type":"update","data":[{"symbol":"LTC/EUR","bids":[{"price":76.71,"qty":67.63104983}],"asks":[],"checksum":2945744161,"timestamp":"2024-06-01T17:52:15.147935Z"}]}
{"channel":"book","type":"update","data":[{"symbol":"LTC/EUR","bids":[{"price":76.72,"qty":23.85306512}],"asks":[],"checksum":2778232978,"timestamp":"2024-06-01T17:52:17.279779Z"}]}
{"channel":"book","type":"update","data":[{"symbol":"LTC/EUR","bids":[{"price":76.71,"qty":65.89320470}],"asks":[],"checksum":3356796494,"timestamp":"2024-06-01T17:52:17.279885Z"}]}
{"channel":"book","type":"update","data":[{"symbol":"LTC/EUR","bids":[{"price":76.66,"qty":2.65000000}],"asks":[],"checksum":1710596534,"timestamp":"2024-06-01T17:52:17.279925Z"}]}
{"channel":"book","type":"update","data":[{"symbol":"LTC/EUR","bids":[],"asks":[{"price":76.82,"qty":0.00000000},{"price":76.85,"qty":53.24800000}],"checksum":1617985159,"timestamp":"2024-06-01T17:52:17.301008Z"}]}
{"channel":"book","type":"update","data":[{"symbol":"LTC/EUR","bids":[{"price":76.71,"qty":68.19247125}],"asks":[],"checksum":4183582201,"timestamp":"2024-06-01T17:52:17.320615Z"}]}
{"channel":"book","type":"update","data":[{"symbol":"LTC/EUR","bids":[{"price":76.72,"qty":24.28061208}],"asks":[],"checksum":1465778981,"timestamp":"2024-06-01T17:52:17.320686Z"}]}
{"channel":"book","type":"update","data":[{"symbol":"LTC/EUR","bids":[{"price":76.66,"qty":8.92445209}],"asks":[],"checksum":1740090472,"timestamp":"2024-06-01T17:52:17.320811Z"}]}
{"channel":"book","type":"update","data":[{"symbol":"LTC/EUR","bids":[],"asks":[{"price":76.82,"qty":0.23458327}],"checksum":930883227,"timestamp":"2024-06-01T17:52:19.480287Z"}]}
{"channel":"book","type":"update","data":[{"symbol":"LTC/EUR","bids":[{"price":76.71,"qty":65.89320470}],"asks":[],"checksum":2924494309,"timestamp":"2024-06-01T17:52:19.494938Z"}]}
{"channel":"book","type":"update","data":[{"symbol":"LTC/EUR","bids":[{"price":76.72,"qty":23.85306512}],"asks":[],"checksum":5397305,"timestamp":"2024-06-01T17:52:19.495015Z"}]}
{"channel":"book","type":"update","data":[{"symbol":"LTC/EUR","bids":[{"price":76.66,"qty":2.65000000}],"asks":[],"checksum":817624180,"timestamp":"2024-06-01T17:52:19.495193Z"}]}
{"channel":"book","type":"update","data":[{"symbol":"LTC/EUR","bids":[{"price":76.71,"qty":67.63104983}],"asks":[],"checksum":1635894113,"timestamp":"2024-06-01T17:52:19.537737Z"}]}
{"channel":"book","type":"update","data":[{"symbol":"LTC/EUR","bids":[{"price":76.72,"qty":24.09345319}],"asks":[],"checksum":1831491567,"timestamp":"2024-06-01T17:52:19.537861Z"}]}
{"channel":"book","type":"update","data":[{"symbol":"LTC/EUR","bids":[{"price":76.66,"qty":7.63023861}],"asks":[],"checksum":1994297593,"timestamp":"2024-06-01T17:52:19.537939Z"}]}
{"channel":"book","type":"update","data":[{"symbol":"LTC/EUR","bids":[],"asks":[{"price":76.76,"qty":73.74900998}],"checksum":1645884031,"timestamp":"2024-06-01T17:52:19.876436Z"}]}
{"channel":"book","type":"update","data":[{"symbol":"LTC/EUR","bids":[],"asks":[{"price":76.76,"qty":78.93146254}],"checksum":856661304,"timestamp":"2024-06-01T17:52:19.881245Z"}]}
{"channel":"book","type":"update","data":[{"symbol":"LTC/EUR","bids":[],"asks":[{"price":76.76,"qty":79.39670497}],"checksum":3373181084,"timestamp":"2024-06-01T17:52:20.052324Z"}]}
{"channel":"book","type":"update","data":[{"symbol":"LTC/EUR","bids":[],"asks":[{"price":76.75,"qty":0.00000000},{"price":76.85,"qty":53.24800000}],"checksum":2846864184,"timestamp":"2024-06-01T17:52:20.218929Z"}]}
{"channel":"book","type":"update","data":[{"symbol":"LTC/EUR","bids":[{"price":76.66,"qty":2.65000000}],"asks":[],"checksum":2992337966,"timestamp":"2024-06-01T17:52:21.745501Z"}]}
{"channel":"book","type":"update","data":[{"symbol":"LTC/EUR","bids":[{"price":76.66,"qty":9.68119909}],"asks":[],"checksum":224412091,"timestamp":"2024-06-01T17:52:21.752324Z"}]}
{"channel":"book","type":"update","data":[{"symbol":"LTC/EUR","bids":[{"price":76.64,"qty":8.95722573}],"asks":[],"checksum":2116397791,"timestamp":"2024-06-01T17:52:21.977406Z"}]}
{"channel":"book","type":"update","data":[{"symbol":"LTC/EUR","bids":[{"price":76.64,"qty":6.01200000}],"asks":[],"checksum":224412091,"timestamp":"2024-06-01T17:52:22.018360Z"}]}
{"channel":"book","type":"update","data":[{"symbol":"LTC/EUR","bids":[{"price":76.64,"qty":8.95722573}],"asks":[],"checksum":2116397791,"timestamp":"2024-06-01T17:52:22.032028Z"}]}
{"channel":"book","type":"update","data":[{"symbol":"LTC/EUR","bids":[{"price":76.64,"qty":6.01200000}],"asks":[],"checksum":224412091,"timestamp":"2024-06-01T17:52:22.132851Z"}]}
{"channel":"book","type":"update","data":[{"symbol":"LTC/EUR","bids":[],"asks":[{"price":76.74,"qty":0.00000000},{"price":76.86,"qty":8.83137436}],"checksum":1227073677,"timestamp":"2024-06-01T17:52:22.870393Z"}]}
{"channel":"book","type":"update","data":[{"symbol":"LTC/EUR","bids":[],"asks":[{"price":76.82,"qty":0.38709789}],"checksum":98967873,"timestamp":"2024-06-01T17:52:22.970270Z"}]}
{"channel":"book","type":"update","data":[{"symbol":"LTC/EUR","bids":[{"price":76.64,"qty":8.95722573}],"asks":[],"checksum":1990445605,"timestamp":"2024-06-01T17:52:23.284298Z"}]}
{"channel":"book","type":"update","data":[{"symbol":"LTC/EUR","bids":[{"price":76.64,"qty":6.01200000}],"asks":[],"checksum":98967873,"timestamp":"2024-06-01T17:52:23.323570Z"}]}
{"channel":"book","type":"update","data":[{"symbol":"LTC/EUR","bids":[{"price":76.64,"qty":8.95722573}],"asks":[],"checksum":1990445605,"timestamp":"2024-06-01T17:52:23.338456Z"}]}
{"channel":"book","type":"update","data":[{"symbol":"LTC/EUR","bids":[{"price":76.64,"qty":6.01200000}],"asks":[],"checksum":98967873,"timestamp":"2024-06-01T17:52:23.682947Z"}]}
{"channel":"book","type":"update","data":[{"symbol":"LTC/EUR","bids":[{"price":76.66,"qty":2.65000000}],"asks":[],"checksum":3135050964,"timestamp":"2024-06-01T17:52:23.851352Z"}]}
{"channel":"book","type":"update","data":[{"symbol":"LTC/EUR","bids":[{"price":76.66,"qty":9.30829719}],"asks":[],"checksum":2407183602,"timestamp":"2024-06-01T17:52:23.858037Z"}]}
{"channel":"book","type":"update","data":[{"symbol":"LTC/EUR","bids":[],"asks":[{"price":76.82,"qty":0.15251462}],"checksum":515865833,"timestamp":"2024-06-01T17:52:23.927265Z"}]}
{"channel":"book","type":"update","data":[{"symbol":"LTC/EUR","bids":[],"asks":[{"price":76.79,"qty":2.29216662}],"checksum":3704441451,"timestamp":"2024-06-01T17:52:24.198169Z"}]}
{"channel":"book","type":"update","data":[{"symbol":"LTC/EUR","bids":[],"asks":[{"price":76.79,"qty":0.00000000},{"price":76.86,"qty":8.83137436}],"checksum":515865833,"timestamp":"2024-06-01T17:52:24.413007Z"}]}
{"channel":"book","type":"update","data":[{"symbol":"LTC/EUR","bids":[{"price":76.64,"qty":8.95722573}],"asks":[],"checksum":1845139341,"timestamp":"2024-06-01T17:52:24.481517Z"}]}
{"channel":"book","type":"update","data":[{"symbol":"LTC/EUR","bids":[{"price":76.72,"qty":23.85306512}],"asks":[],"checksum":1632699139,"timestamp":"2024-06-01T17:52:26.007826Z"}]}
{"channel":"book","type":"update","data":[{"symbol":"LTC/EUR","bids":[{"price":76.71,"qty":65.89320470}],"asks":[],"checksum":812332054,"timestamp":"2024-06-01T17:52:26.008028Z"}]}
{"channel":"book","type":"update","data":[{"symbol":"LTC/EUR","bids":[{"price":76.66,"qty":2.65000000}],"asks":[],"checksum":97293360,"timestamp":"2024-06-01T17:52:26.008041Z"}]}
{"channel":"book","type":"update","data":[{"symbol":"LTC/EUR","bids":[{"price":76.71,"qty":68.12904054}],"asks":[],"checksum":866787936,"timestamp":"2024-06-01T17:52:26.013592Z"}]}
{"channel":"book","type":"update","data":[{"symbol":"LTC/EUR","bids":[{"price":76.72,"qty":24.27484565}],"asks":[],"checksum":767633002,"timestamp":"2024-06-01T17:52:26.013653Z"}]}
{"channel":"book","type":"update","data":[{"symbol":"LTC/EUR","bids":[{"price":76.66,"qty":9.44546684}],"asks":[],"checksum":4165878780,"timestamp":"2024-06-01T17:52:26.013805Z"}]}
{"channel":"book","type":"update","data":[{"symbol":"LTC/EUR","bids":[{"price":76.66,"qty":2.65000000}],"asks":[],"checksum":767633002,"timestamp":"2024-06-01T17:52:28.139945Z"}]}
{"channel":"book","type":"update","data":[{"symbol":"LTC/EUR","bids":[{"price":76.66,"qty":9.92448243}],"asks":[],"checksum":1741442598,"timestamp":"2024-06-01T17:52:28.182873Z"}]}
{"channel":"book","type":"update","data":[{"symbol":"LTC/EUR","bids":[{"price":76.66,"qty":2.65000000}],"asks":[],"checksum":767633002,"timestamp":"2024-06-01T17:52:30.260748Z"}]}
{"channel":"book","type":"update","data":[{"symbol":"LTC/EUR","bids":[{"price":76.71,"qty":65.89320470}],"asks":[],"checksum":463966266,"timestamp":"2024-06-01T17:52:30.260890Z"}]}
{"channel":"book","type":"update","data":[{"symbol":"LTC/EUR","bids":[{"price":76.71,"qty":68.31746966}],"asks":[],"checksum":1487230885,"timestamp":"2024-06-01T17:52:30.303481Z"}]}
{"channel":"book","type":"update","data":[{"symbol":"LTC/EUR","bids":[{"price":76.66,"qty":10.12943464}],"asks":[],"checksum":311408018,"timestamp":"2024-06-01T17:52:30.303752Z"}]}
{"channel":"book","type":"update","data":[{"symbol":"LTC/EUR","bids":[],"asks":[{"price":76.76,"qty":74.21425241}],"checksum":3129266619,"timestamp":"2024-06-01T17:52:30.841058Z"}]}
{"channel":"book","type":"update","data":[{"symbol":"LTC/EUR","bids":[],"asks":[{"price":76.77,"qty":58.85320256}],"checksum":2127896728,"timestamp":"2024-06-01T17:52:30.845788Z"}]}
{"channel":"book","type":"update","data":[{"symbol":"LTC/EUR","bids":[],"asks":[{"price":76.81,"qty":75.94100000}],"checksum":656076893,"timestamp":"2024-06-01T17:52:30.846411Z"}]}
{"channel":"book","type":"update","data":[{"symbol":"LTC/EUR","bids":[],"asks":[{"price":76.77,"qty":28.55320256}],"checksum":472574013,"timestamp":"2024-06-01T17:52:30.855238Z"}]}
{"channel":"book","type":"update","data":[{"symbol":"LTC/EUR","bids":[],"asks":[{"price":76.76,"qty":60.52218696}],"checksum":3588070513,"timestamp":"2024-06-01T17:52:30.857026Z"}]}
{"channel":"book","type":"update","data":[{"symbol":"LTC/EUR","bids":[],"asks":[{"price":76.77,"qty":42.24526801}],"checksum":2316323231,"timestamp":"2024-06-01T17:52:30.857104Z"}]}
{"channel":"book","type":"update","data":[{"symbol":"LTC/EUR","bids":[],"asks":[{"price":76.83,"qty":110.63236548}],"checksum":137546114,"timestamp":"2024-06-01T17:52:30.860295Z"}]}
{"channel":"book","type":"update","data":[{"symbol":"LTC/EUR","bids":[],"asks":[{"price":76.76,"qty":0.46524243}],"checksum":2037166942,"timestamp":"2024-06-01T17:52:30.869853Z"}]}
{"channel":"book","type":"update","data":[{"symbol":"LTC/EUR","bids":[{"price":76.69,"qty":69.25616961}],"asks":[],"checksum":1390532865,"timestamp":"2024-06-01T17:52:30.870410Z"}]}
{"channel":"book","type":"update","data":[{"symbol":"LTC/EUR","bids":[{"price":76.71,"qty":62.51746966}],"asks":[],"checksum":1712529498,"timestamp":"2024-06-01T17:52:30.873212Z"}]}
{"channel":"book","type":"update","data":[{"symbol":"LTC/EUR","bids":[{"price":76.73,"qty":65.88036228}],"asks":[],"checksum":1504236074,"timestamp":"2024-06-01T17:52:30.873425Z"}]}
{"channel":"book","type":"update","data":[{"symbol":"LTC/EUR","bids":[],"asks":[{"price":76.77,"qty":102.30091800}],"checksum":2970509240,"timestamp":"2024-06-01T17:52:30.874709Z"}]}
{"channel":"book","type":"update","data":[{"symbol":"LTC/EUR","bids":[],"asks":[{"price":76.77,"qty":108.10091800}],"checksum":526261651,"timestamp":"2024-06-01T17:52:30.877368Z"}]}
{"channel":"book","type":"update","data":[{"symbol":"LTC/EUR","bids":[],"asks":[{"price":76.78,"qty":60.16110993}],"checksum":36942333,"timestamp":"2024-06-01T17:52:30.944835Z"}]}
{"channel":"book","type":"update","data":[{"symbol":"LTC/EUR","bids":[],"asks":[{"price":76.86,"qty":0.00000000},{"price":76.87,"qty":131.67523348}],"checksum":3734444531,"timestamp":"2024-06-01T17:52:30.947104Z"}]}
{"channel":"book","type":"update","data":[{"symbol":"LTC/EUR","bids":[{"price":76.64,"qty":6.01200000}],"asks":[],"checksum":2916283031,"timestamp":"2024-06-01T17:52:30.998305Z"}]}
{"channel":"book","type":"update","data":[{"symbol":"LTC/EUR","bids":[{"price":76.64,"qty":8.95722573}],"asks":[],"checksum":3734444531,"timestamp":"2024-06-01T17:52:31.038319Z"}]}
{"channel":"book","type":"update","data":[{"symbol":"LTC/EUR","bids":[],"asks":[{"price":76.79,"qty":2.20000000}],"checksum":722742352,"timestamp":"2024-06-01T17:52:31.046427Z"}]}
{"channel":"book","type":"update","data":[{"symbol":"LTC/EUR","bids":[{"price":76.64,"qty":6.01200000}],"asks":[],"checksum":1481754420,"timestamp":"2024-06-01T17:52:31.067496Z"}]}
{"channel":"book","type":"update","data":[{"symbol":"LTC/EUR","bids":[],"asks":[{"price":76.81,"qty":67.64000000}],"checksum":3579572757,"timestamp":"2024-06-01T17:52:31.072499Z"}]}
{"channel":"book","type":"update","data":[{"symbol":"LTC/EUR","bids":[{"price":76.64,"qty":8.95722573}],"asks":[],"checksum":2786990449,"timestamp":"2024-06-01T17:52:31.074019Z"}]}
{"channel":"book","type":"update","data":[{"symbol":"LTC/EUR","bids":[],"asks":[{"price":76.82,"qty":8.27651462}],"checksum":1711160948,"timestamp":"2024-06-01T17:52:31.082533Z"}]}
{"channel":"book","type":"update","data":[{"symbol":"LTC/EUR","bids":[{"price":76.71,"qty":68.55055439}],"asks":[],"checksum":4150353071,"timestamp":"2024-06-01T17:52:31.091606Z"}]}
{"channel":"book","type":"update","data":[{"symbol":"LTC/EUR","bids":[],"asks":[{"price":76.81,"qty":0.00000000},{"price":76.87,"qty":131.67523348},{"price":76.82,"qty":75.91651462}],"checksum":2710083964,"timestamp":"2024-06-01T17:52:31.091924Z"}]}
{"channel":"book","type":"update","data":[{"symbol":"LTC/EUR","bids":[{"price":76.71,"qty":62.51746966}],"asks":[],"checksum":857209767,"timestamp":"2024-06-01T17:52:31.103102Z"}]}
{"channel":"book","type":"update","data":[{"symbol":"LTC/EUR","bids":[],"asks":[{"price":76.77,"qty":48.04526801}],"checksum":2081978122,"timestamp":"2024-06-01T17:52:31.125194Z"}]}
{"channel":"book","type":"update","data":[{"symbol":"LTC/EUR","bids":[],"asks":[{"price":76.83,"qty":50.50236548},{"price":76.82,"qty":136.04651462}],"checksum":2851165291,"timestamp":"2024-06-01T17:52:31.126211Z"}]}
{"channel":"book","type":"update","data":[{"symbol":"LTC/EUR","bids":[{"price":76.70,"qty":229.10635476}],"asks":[],"checksum":3406839540,"timestamp":"2024-06-01T17:52:31.131201Z"}]}
{"channel":"book","type":"update","data":[{"symbol":"LTC/EUR","bids":[],"asks":[{"price":76.76,"qty":60.52266165}],"checksum":621634666,"timestamp":"2024-06-01T17:52:31.133565Z"}]}
{"channel":"book","type":"update","data":[{"symbol":"LTC/EUR","bids":[],"asks":[{"price":76.77,"qty":62.30863072}],"checksum":921447292,"timestamp":"2024-06-01T17:52:31.147317Z"}]}
{"channel":"book","type":"update","data":[{"symbol":"LTC/EUR","bids":[{"price":76.64,"qty":6.01200000}],"asks":[],"checksum":1168752664,"timestamp":"2024-06-01T17:52:31.147817Z"}]}
{"channel":"book","type":"update","data":[{"symbol":"LTC/EUR","bids":[],"asks":[{"price":76.77,"qty":48.04526801}],"checksum":1447595790,"timestamp":"2024-06-01T17:52:31.154684Z"}]}
{"channel":"book","type":"update","data":[{"symbol":"LTC/EUR","bids":[{"price":76.71,"qty":68.55055439}],"asks":[],"checksum":3302485461,"timestamp":"2024-06-01T17:52:31.226520Z"}]}
{"channel":"book","type":"update","data":[{"symbol":"LTC/EUR","bids":[{"price":76.71,"qty":62.51746966}],"asks":[],"checksum":1447595790,"timestamp":"2024-06-01T17:52:31.252893Z"}]}
{"channel":"book","type":"update","data":[{"symbol":"LTC/EUR","bids":[{"price":76.73,"qty":5.80000000}],"asks":[],"checksum":720859650,"timestamp":"2024-06-01T17:52:31.263377Z"}]}
{"channel":"book","type":"update","data":[{"symbol":"LTC/EUR","bids":[{"price":76.72,"qty":84.35661134}],"asks":[],"checksum":2509902678,"timestamp":"2024-06-01T17:52:31.269951Z"}]}
{"channel":"book","type":"update","data":[{"symbol":"LTC/EUR","bids":[{"price":76.73,"qty":0.00000000},{"price":76.63,"qty":190.06600000}],"asks":[],"checksum":2218753437,"timestamp":"2024-06-01T17:52:31.274487Z"}]}
{"channel":"book","type":"update","data":[{"symbol":"LTC/EUR","bids":[{"price":76.72,"qty":90.15661134}],"asks":[],"checksum":201845827,"timestamp":"2024-06-01T17:52:31.293856Z"}]}
{"channel":"book","type":"update","data":[{"symbol":"LTC/EUR","bids":[],"asks":[{"price":76.79,"qty":2.66524243}],"checksum":1392088225,"timestamp":"2024-06-01T17:52:31.369250Z"}]}
{"channel":"book","type":"update","data":[{"symbol":"LTC/EUR","bids":[],"asks":[{"price":76.83,"qty":48.04849511},{"price":76.82,"qty":138.50038499}],"checksum":3102396318,"timestamp":"2024-06-01T17:52:31.373341Z"}]}
{"channel":"book","type":"update","data":[{"symbol":"LTC/EUR","bids":[{"price":76.70,"qty":235.14022608}],"asks":[],"checksum":1768873246,"timestamp":"2024-06-01T17:52:31.374691Z"}]}
{"channel":"book","type":"update","data":[{"symbol":"LTC/EUR","bids":[{"price":76.69,"qty":79.02123191}],"asks":[],"checksum":447855832,"timestamp":"2024-06-01T17:52:31.443611Z"}]}
{"channel":"book","type":"update","data":[{"symbol":"LTC/EUR","bids":[{"price":76.69,"qty":79.61539257}],"asks":[],"checksum":583643263,"timestamp":"2024-06-01T17:52:31.505296Z"}]}
{"channel":"book","type":"update","data":[{"symbol":"LTC/EUR","bids":[{"price":76.69,"qty":93.30745802}],"asks":[],"checksum":1291729753,"timestamp":"2024-06-01T17:52:31.522984Z"}]}
{"channel":"book","type":"update","data":[{"symbol":"LTC/EUR","bids":[],"asks":[{"price":76.76,"qty":60.05741922}],"checksum":4242154861,"timestamp":"2024-06-01T17:52:31.537043Z"}]}
{"channel":"book","type":"update","data":[{"symbol":"LTC/EUR","bids":[],"asks":[{"price":76.76,"qty":0.00000000},{"price":76.88,"qty":24.03000000}],"checksum":215393647,"timestamp":"2024-06-01T17:52:31.583565Z"}]}
{"channel":"book","type":"update","data":[{"symbol":"LTC/EUR","bids":[],"asks":[{"price":76.77,"qty":62.30871054}],"checksum":3382430980,"timestamp":"2024-06-01T17:52:31.587321Z"}]}
{"channel":"book","type":"update","data":[{"symbol":"LTC/EUR","bids":[],"asks":[{"price":76.80,"qty":83.88326375}],"checksum":2613248773,"timestamp":"2024-06-01T17:52:31.587664Z"}]}
{"channel":"book","type":"update","data":[{"symbol":"LTC/EUR","bids":[],"asks":[{"price":76.77,"qty":122.36433561}],"checksum":255346404,"timestamp":"2024-06-01T17:52:31.588842Z"}]}
{"channel":"book","type":"update","data":[{"symbol":"LTC/EUR","bids":[{"price":76.67,"qty":80.52174679}],"asks":[],"checksum":4287866095,"timestamp":"2024-06-01T17:52:31.601609Z"}]}
{"channel":"book","type":"update","data":[{"symbol":"LTC/EUR","bids":[{"price":76.69,"qty":83.54239572}],"asks":[],"checksum":3368718530,"timestamp":"2024-06-01T17:52:31.708090Z"}]}
{"channel":"book","type":"update","data":[{"symbol":"LTC/EUR","bids":[],"asks":[{"price":76.80,"qty":86.17543037}],"checksum":3047464307,"timestamp":"2024-06-01T17:52:31.708206Z"}]}
{"channel":"book","type":"update","data":[{"symbol":"LTC/EUR","bids":[{"price":76.64,"qty":8.95722573}],"asks":[],"checksum":3456538473,"timestamp":"2024-06-01T17:52:31.710160Z"}]}
{"channel":"book","type":"update","data":[{"symbol":"LTC/EUR","bids":[{"price":76.70,"qty":234.54606542}],"asks":[],"checksum":3428433346,"timestamp":"2024-06-01T17:52:31.712691Z"}]}
{"channel":"book","type":"update","data":[{"symbol":"LTC/EUR","bids":[],"asks":[{"price":76.78,"qty":0.11978631}],"checksum":3156638067,"timestamp":"2024-06-01T17:52:31.848747Z"}]}
{"channel":"book","type":"update","data":[{"symbol":"LTC/EUR","bids":[{"price":76.72,"qty":30.07484565}],"asks":[],"checksum":3870616264,"timestamp":"2024-06-01T17:52:31.848802Z"}]}
{"channel":"book","type":"update","data":[{"symbol":"LTC/EUR","bids":[],"asks":[{"price":76.81,"qty":60.01821275}],"checksum":1529733497,"timestamp":"2024-06-01T17:52:31.852890Z"}]}
{"channel":"book","type":"update","data":[{"symbol":"LTC/EUR","bids":[{"price":76.73,"qty":60.07691509}],"asks":[],"checksum":3527761146,"timestamp":"2024-06-01T17:52:31.852938Z"}]}
{"channel":"book","type":"update","data":[{"symbol":"LTC/EUR","bids":[],"asks":[{"price":76.82,"qty":70.86038499},{"price":76.81,"qty":127.65821275}],"checksum":1259405600,"timestamp":"2024-06-01T17:52:31.856351Z"}]}
{"channel":"book","type":"update","data":[{"symbol":"LTC/EUR","bids":[{"price":76.64,"qty":6.01200000}],"asks":[],"checksum":945089092,"timestamp":"2024-06-01T17:52:31.917229Z"}]}
{"channel":"book","type":"update","data":[{"symbol":"LTC/EUR","bids":[{"price":76.69,"qty":113.84239572}],"asks":[],"checksum":311631913,"timestamp":"2024-06-01T17:52:32.135236Z"}]}
{"channel":"book","type":"update","data":[{"symbol":"LTC/EUR","bids":[],"asks":[{"price":76.78,"qty":30.41978631}],"checksum":2526433650,"timestamp":"2024-06-01T17:52:32.135282Z"}]}
{"channel":"book","type":"update","data":[{"symbol":"LTC/EUR","bids":[{"price":76.68,"qty":122.77203847}],"asks":[],"checksum":737708769,"timestamp":"2024-06-01T17:52:32.140284Z"}]}
{"channel":"book","type":"update","data":[{"symbol":"LTC/EUR","bids":[],"asks":[{"price":76.80,"qty":83.88326375}],"checksum":1452705616,"timestamp":"2024-06-01T17:52:32.185769Z"}]}
{"channel":"book","type":"update","data":[{"symbol":"LTC/EUR","bids":[{"price":76.66,"qty":2.65000000}],"asks":[],"checksum":2936203818,"timestamp":"2024-06-01T17:52:32.516590Z"}]}
{"channel":"book","type":"update","data":[{"symbol":"LTC/EUR","bids":[{"price":76.72,"qty":29.65306512}],"asks":[],"checksum":3484216767,"timestamp":"2024-06-01T17:52:32.516647Z"}]}
{"channel":"book","type":"update","data":[{"symbol":"LTC/EUR","bids":[{"price":76.66,"qty":7.12367974}],"asks":[],"checksum":2254308504,"timestamp":"2024-06-01T17:52:32.522788Z"}]}
{"channel":"book","type":"update","data":[{"symbol":"LTC/EUR","bids":[{"price":76.72,"qty":29.89344012}],"asks":[],"checksum":1543592074,"timestamp":"2024-06-01T17:52:32.522886Z"}]}
{"channel":"book","type":"update","data":[{"symbol":"LTC/EUR","bids":[],"asks":[{"price":76.82,"qty":10.73038499}],"checksum":716663531,"timestamp":"2024-06-01T17:52:33.181293Z"}]}
{"channel":"book","type":"update","data":[{"symbol":"LTC/EUR","bids":[],"asks":[{"price":76.82,"qty":70.78038499}],"checksum":3135610163,"timestamp":"2024-06-01T17:52:34.228592Z"}]}
{"channel":"book","type":"update","data":[{"symbol":"LTC/EUR","bids":[{"price":76.70,"qty":228.51219410}],"asks":[],"checksum":3126823508,"timestamp":"2024-06-01T17:52:34.348985Z"}]}
{"channel":"book","type":"update","data":[{"symbol":"LTC/EUR","bids":[{"price":76.71,"qty":68.55055439}],"asks":[],"checksum":683731087,"timestamp":"2024-06-01T17:52:34.469713Z"}]}
{"channel":"book","type":"update","data":[{"symbol":"LTC/EUR","bids":[],"asks":[{"price":76.82,"qty":62.65638499}],"checksum":583464245,"timestamp":"2024-06-01T17:52:34.517274Z"}]}
{"channel":"book","type":"update","data":[{"symbol":"LTC/EUR","bids":[],"asks":[{"price":76.81,"qty":135.78221275}],"checksum":699721022,"timestamp":"2024-06-01T17:52:34.519715Z"}]}
{"channel":"book","type":"update","data":[{"symbol":"LTC/EUR","bids":[{"price":76.66,"qty":2.65000000}],"asks":[],"checksum":1615203353,"timestamp":"2024-06-01T17:52:34.642145Z"}]}
{"channel":"book","type":"update","data":[{"symbol":"LTC/EUR","bids":[{"price":76.66,"qty":8.61228172}],"asks":[],"checksum":1423220421,"timestamp":"2024-06-01T17:52:34.684801Z"}]}
{"channel":"book","type":"update","data":[{"symbol":"LTC/EUR","bids":[{"price":76.71,"qty":62.51746966}],"asks":[],"checksum":3326868510,"timestamp":"2024-06-01T17:52:35.546881Z"}]}
{"channel":"book","type":"update","data":[{"symbol":"LTC/EUR","bids":[{"price":76.71,"qty":68.55055439}],"asks":[],"checksum":1423220421,"timestamp":"2024-06-01T17:52:35.671215Z"}]}
{"channel":"book","type":"update","data":[{"symbol":"LTC/EUR","bids":[],"asks":[{"price":76.77,"qty":108.10089308}],"checksum":563628353,"timestamp":"2024-06-01T17:52:35.681261Z"}]}
{"channel":"book","type":"update","data":[{"symbol":"LTC/EUR","bids":[],"asks":[{"price":76.80,"qty":23.85306512}],"checksum":397751104,"timestamp":"2024-06-01T17:52:36.524280Z"}]}
{"channel":"book","type":"update","data":[{"symbol":"LTC/EUR","bids":[],"asks":[{"price":76.79,"qty":62.70021536}],"checksum":1422343129,"timestamp":"2024-06-01T17:52:36.529146Z"}]}
{"channel":"book","type":"update","data":[{"symbol":"LTC/EUR","bids":[{"price":76.72,"qty":29.65306512}],"asks":[],"checksum":2392352715,"timestamp":"2024-06-01T17:52:36.782780Z"}]}
{"channel":"book","type":"update","data":[{"symbol":"LTC/EUR","bids":[{"price":76.66,"qty":2.65000000}],"asks":[],"checksum":3121280279,"timestamp":"2024-06-01T17:52:36.782873Z"}]}
{"channel":"book","type":"update","data":[{"symbol":"LTC/EUR","bids":[{"price":76.72,"qty":30.08061208}],"asks":[],"checksum":3047484417,"timestamp":"2024-06-01T17:52:36.825001Z"}]}
{"channel":"book","type":"update","data":[{"symbol":"LTC/EUR","bids":[{"price":76.66,"qty":7.86688402}],"asks":[],"checksum":3235419999,"timestamp":"2024-06-01T17:52:36.825083Z"}]}
{"channel":"book","type":"update","data":[{"symbol":"LTC/EUR","bids":[{"price":76.71,"qty":62.51746966}],"asks":[],"checksum":1380447620,"timestamp":"2024-06-01T17:52:37.150742Z"}]}
{"channel":"book","type":"update","data":[{"symbol":"LTC/EUR","bids":[{"price":76.71,"qty":68.55055439}],"asks":[],"checksum":3235419999,"timestamp":"2024-06-01T17:52:37.276305Z"}]}
{"channel":"book","type":"update","data":[{"symbol":"LTC/EUR","bids":[],"asks":[{"price":76.80,"qty":26.14523174}],"checksum":1622834369,"timestamp":"2024-06-01T17:52:38.016820Z"}]}
{"channel":"book","type":"update","data":[{"symbol":"LTC/EUR","bids":[{"price":76.71,"qty":62.51746966}],"asks":[],"checksum":4062518810,"timestamp":"2024-06-01T17:52:38.330751Z"}]}
{"channel":"book","type":"update","data":[{"symbol":"LTC/EUR","bids":[{"price":76.73,"qty":0.00000000},{"price":76.63,"qty":190.06600000}],"asks":[],"checksum":1336833703,"timestamp":"2024-06-01T17:52:38.394820Z"}]}
{"channel":"book","type":"update","data":[{"symbol":"LTC/EUR","bids":[{"price":76.72,"qty":62.53018170}],"asks":[],"checksum":646543333,"timestamp":"2024-06-01T17:52:38.397640Z"}]}
{"channel":"book","type":"update","data":[{"symbol":"LTC/EUR","bids":[{"price":76.74,"qty":60.07235076}],"asks":[],"checksum":3361823550,"timestamp":"2024-06-01T17:52:38.399208Z"}]}
{"channel":"book","type":"update","data":[{"symbol":"LTC/EUR","bids":[{"price":76.71,"qty":68.55055439}],"asks":[],"checksum":1526610405,"timestamp":"2024-06-01T17:52:38.456757Z"}]}
{"channel":"book","type":"update","data":[{"symbol":"LTC/EUR","bids":[{"price":76.69,"qty":97.83422611}],"asks":[],"checksum":4171288849,"timestamp":"2024-06-01T17:52:38.459474Z"}]}
{"channel":"book","type":"update","data":[{"symbol":"LTC/EUR","bids":[{"price":76.70,"qty":244.50145030}],"asks":[],"checksum":1993877945,"timestamp":"2024-06-01T17:52:38.462995Z"}]}
{"channel":"book","type":"update","data":[{"symbol":"LTC/EUR","bids":[{"price":76.74,"qty":0.00000000},{"price":76.63,"qty":190.06600000}],"asks":[],"checksum":2309006441,"timestamp":"2024-06-01T17:52:38.759403Z"}]}
{"channel":"book","type":"update","data":[{"symbol":"LTC/EUR","bids":[{"price":76.73,"qty":60.07382854}],"asks":[],"checksum":1606951855,"timestamp":"2024-06-01T17:52:38.763700Z"}]}
{"channel":"book","type":"update","data":[{"symbol":"LTC/EUR","bids":[{"price":76.71,"qty":66.12628943}],"asks":[],"checksum":3496299335,"timestamp":"2024-06-01T17:52:38.852356Z"}]}
{"channel":"book","type":"update","data":[{"symbol":"LTC/EUR","bids":[{"price":76.66,"qty":2.65000000}],"asks":[],"checksum":2769891353,"timestamp":"2024-06-01T17:52:38.852684Z"}]}
{"channel":"book","type":"update","data":[{"symbol":"LTC/EUR","bids":[{"price":76.72,"qty":62.10263474}],"asks":[],"checksum":4166231657,"timestamp":"2024-06-01T17:52:38.852763Z"}]}
{"channel":"book","type":"update","data":[{"symbol":"LTC/EUR","bids":[{"price":76.66,"qty":6.38813840}],"asks":[],"checksum":810763438,"timestamp":"2024-06-01T17:52:38.859132Z"}]}
{"channel":"book","type":"update","data":[{"symbol":"LTC/EUR","bids":[{"price":76.71,"qty":68.42555598}],"asks":[],"checksum":3422491762,"timestamp":"2024-06-01T17:52:38.859143Z"}]}
{"channel":"book","type":"update","data":[{"symbol":"LTC/EUR","bids":[],"asks":[{"price":76.80,"qty":26.38561981}],"checksum":596293786,"timestamp":"2024-06-01T17:52:39.090772Z"}]}
{"channel":"book","type":"update","data":[{"symbol":"LTC/EUR","bids":[],"asks":[{"price":76.82,"qty":2.60638499}],"checksum":2475586553,"timestamp":"2024-06-01T17:52:40.365575Z"}]}
{"channel":"book","type":"update","data":[{"symbol":"LTC/EUR","bids":[],"asks":[{"price":76.82,"qty":62.65638499}],"checksum":596293786,"timestamp":"2024-06-01T17:52:40.590400Z"}]}
{"channel":"book","type":"update","data":[{"symbol":"LTC/EUR","bids":[{"price":76.71,"qty":66.12628943}],"asks":[],"checksum":3626428486,"timestamp":"2024-06-01T17:52:41.113734Z"}]}
{"channel":"book","type":"update","data":[{"symbol":"LTC/EUR","bids":[{"price":76.66,"qty":2.65000000}],"asks":[],"checksum":270928513,"timestamp":"2024-06-01T17:52:41.113763Z"}]}
{"channel":"book","type":"update","data":[{"symbol":"LTC/EUR","bids":[{"price":76.66,"qty":6.82121286}],"asks":[],"checksum":3359186199,"timestamp":"2024-06-01T17:52:41.119147Z"}]}
{"channel":"book","type":"update","data":[{"symbol":"LTC/EUR","bids":[{"price":76.64,"qty":7.05309664}],"asks":[],"checksum":3370364485,"timestamp":"2024-06-01T17:52:41.119206Z"}]}
{"channel":"book","type":"update","data":[{"symbol":"LTC/EUR","bids":[{"price":76.71,"qty":67.86413456}],"asks":[],"checksum":1639390930,"timestamp":"2024-06-01T17:52:41.119291Z"}]}
{"channel":"book","type":"update","data":[{"symbol":"LTC/EUR","bids":[{"price":76.71,"qty":61.83104983}],"asks":[],"checksum":1860909343,"timestamp":"2024-06-01T17:52:41.150575Z"}]}
{"channel":"book","type":"update","data":[{"symbol":"LTC/EUR","bids":[{"price":76.71,"qty":67.86413456}],"asks":[],"checksum":1639390930,"timestamp":"2024-06-01T17:52:41.270561Z"}]}
{"channel":"book","type":"update","data":[{"symbol":"LTC/EUR","bids":[],"asks":[{"price":76.76,"qty":0.46524243}],"checksum":3799473208,"timestamp":"2024-06-01T17:52:41.283555Z"}]}
{"channel":"book","type":"update","data":[{"symbol":"LTC/EUR","bids":[{"price":76.71,"qty":61.83104983}],"asks":[],"checksum":3979049973,"timestamp":"2024-06-01T17:52:41.366209Z"}]}
{"channel":"book","type":"update","data":[{"symbol":"LTC/EUR","bids":[],"asks":[{"price":76.79,"qty":62.23497293}],"checksum":318550897,"timestamp":"2024-06-01T17:52:41.455987Z"}]}
{"channel":"book","type":"update","data":[{"symbol":"LTC/EUR","bids":[{"price":76.71,"qty":67.86413456}],"asks":[],"checksum":497063100,"timestamp":"2024-06-01T17:52:41.492264Z"}]}
{"channel":"book","type":"update","data":[{"symbol":"LTC/EUR","bids":[{"price":76.71,"qty":61.83104983}],"asks":[],"checksum":318550897,"timestamp":"2024-06-01T17:52:41.939589Z"}]}
{"channel":"book","type":"update","data":[{"symbol":"LTC/EUR","bids":[{"price":76.71,"qty":67.86413456}],"asks":[],"checksum":497063100,"timestamp":"2024-06-01T17:52:42.059761Z"}]}
{"channel":"book","type":"update","data":[{"symbol":"LTC/EUR","bids":[{"price":76.70,"qty":245.09561096}],"asks":[],"checksum":3343059537,"timestamp":"2024-06-01T17:52:42.150735Z"}]}
{"channel":"book","type":"update","data":[{"symbol":"LTC/EUR","bids":[{"price":76.69,"qty":97.24006545}],"asks":[],"checksum":1974096683,"timestamp":"2024-06-01T17:52:42.317510Z"}]}
{"channel":"book","type":"update","data":[{"symbol":"LTC/EUR","bids":[{"price":76.71,"qty":61.83104983}],"asks":[],"checksum":2062972134,"timestamp":"2024-06-01T17:52:42.745476Z"}]}
{"channel":"book","type":"update","data":[{"symbol":"LTC/EUR","bids":[{"price":76.70,"qty":251.12948228}],"asks":[],"checksum":567774044,"timestamp":"2024-06-01T17:52:42.869019Z"}]}
{"channel":"book","type":"update","data":[{"symbol":"LTC/EUR","bids":[{"price":76.66,"qty":2.65000000}],"asks":[],"checksum":4190674122,"timestamp":"2024-06-01T17:52:43.325873Z"}]}
{"channel":"book","type":"update","data":[{"symbol":"LTC/EUR","bids":[{"price":76.64,"qty":6.01200000}],"asks":[],"checksum":4178718616,"timestamp":"2024-06-01T17:52:43.325950Z"}]}
{"channel":"book","type":"update","data":[{"symbol":"LTC/EUR","bids":[{"price":76.71,"qty":60.09320470}],"asks":[],"checksum":1990288857,"timestamp":"2024-06-01T17:52:43.326036Z"}]}
{"channel":"book","type":"update","data":[{"symbol":"LTC/EUR","bids":[{"price":76.66,"qty":6.44684860}],"asks":[],"checksum":518257210,"timestamp":"2024-06-01T17:52:43.368789Z"}]}
{"channel":"book","type":"update","data":[{"symbol":"LTC/EUR","bids":[{"price":76.64,"qty":9.09747650}],"asks":[],"checksum":3017145521,"timestamp":"2024-06-01T17:52:43.368908Z"}]}
{"channel":"book","type":"update","data":[{"symbol":"LTC/EUR","bids":[{"price":76.71,"qty":61.64386770}],"asks":[],"checksum":787942114,"timestamp":"2024-06-01T17:52:43.368937Z"}]}
{"channel":"book","type":"update","data":[{"symbol":"LTC/EUR","bids":[{"price":76.70,"qty":245.09561096}],"asks":[],"checksum":1977021784,"timestamp":"2024-06-01T17:52:43.548190Z"}]}
{"channel":"book","type":"update","data":[{"symbol":"LTC/EUR","bids":[{"price":76.70,"qty":251.12948228}],"asks":[],"checksum":787942114,"timestamp":"2024-06-01T17:52:43.675915Z"}]}
{"channel":"book","type":"update","data":[{"symbol":"LTC/EUR","bids":[{"price":76.70,"qty":245.09561096}],"asks":[],"checksum":1977021784,"timestamp":"2024-06-01T17:52:44.752893Z"}]}
{"channel":"book","type":"update","data":[{"symbol":"LTC/EUR","bids":[{"price":76.70,"qty":251.12948228}],"asks":[],"checksum":787942114,"timestamp":"2024-06-01T17:52:44.871511Z"}]}
{"channel":"book","type":"update","data":[{"symbol":"LTC/EUR","bids":[{"price":76.64,"qty":6.01200000}],"asks":[],"checksum":2210466921,"timestamp":"2024-06-01T17:52:45.532888Z"}]}
{"channel":"book","type":"update","data":[{"symbol":"LTC/EUR","bids":[{"price":76.64,"qty":9.46836766}],"asks":[],"checksum":1689510288,"timestamp":"2024-06-01T17:52:45.537976Z"}]}
{"channel":"book","type":"update","data":[{"symbol":"LTC/EUR","bids":[{"price":76.70,"qty":245.09561096}],"asks":[],"checksum":1066540586,"timestamp":"2024-06-01T17:52:45.556982Z"}]}
{"channel":"book","type":"update","data":[{"symbol":"LTC/EUR","bids":[{"price":76.70,"qty":251.12948228}],"asks":[],"checksum":1689510288,"timestamp":"2024-06-01T17:52:45.680459Z"}]}
{"channel":"book","type":"update","data":[{"symbol":"LTC/EUR","bids":[{"price":76.70,"qty":245.09561096}],"asks":[],"checksum":1066540586,"timestamp":"2024-06-01T17:52:46.363095Z"}]}
{"channel":"book","type":"update","data":[{"symbol":"LTC/EUR","bids":[{"price":76.71,"qty":67.67695243}],"asks":[],"checksum":2272061878,"timestamp":"2024-06-01T17:52:46.495456Z"}]}
{"channel":"book","type":"update","data":[{"symbol":"LTC/EUR","bids":[{"price":76.67,"qty":32.47022671}],"asks":[],"checksum":919276773,"timestamp":"2024-06-01T17:52:47.038612Z"}]}
{"channel":"book","type":"update","data":[{"symbol":"LTC/EUR","bids":[{"price":76.69,"qty":145.28002174}],"asks":[],"checksum":1526588262,"timestamp":"2024-06-01T17:52:47.325406Z"}]}
{"channel":"book","type":"update","data":[{"symbol":"LTC/EUR","bids":[{"price":76.66,"qty":2.65000000}],"asks":[],"checksum":851410053,"timestamp":"2024-06-01T17:52:47.758142Z"}]}
{"channel":"book","type":"update","data":[{"symbol":"LTC/EUR","bids":[{"price":76.64,"qty":6.01200000}],"asks":[],"checksum":3587019132,"timestamp":"2024-06-01T17:52:47.758256Z"}]}
{"channel":"book","type":"update","data":[{"symbol":"LTC/EUR","bids":[{"price":76.71,"qty":66.12628943}],"asks":[],"checksum":1417666669,"timestamp":"2024-06-01T17:52:47.758594Z"}]}
{"channel":"book","type":"update","data":[{"symbol":"LTC/EUR","bids":[{"price":76.66,"qty":6.63403073}],"asks":[],"checksum":3183952530,"timestamp":"2024-06-01T17:52:47.764839Z"}]}
{"channel":"book","type":"update","data":[{"symbol":"LTC/EUR","bids":[{"price":76.64,"qty":9.65308206}],"asks":[],"checksum":3025218246,"timestamp":"2024-06-01T17:52:47.764898Z"}]}
{"channel":"book","type":"update","data":[{"symbol":"LTC/EUR","bids":[{"price":76.71,"qty":67.48977030}],"asks":[],"checksum":2465053817,"timestamp":"2024-06-01T17:52:47.764994Z"}]}
{"channel":"book","type":"update","data":[{"symbol":"LTC/EUR","bids":[],"asks":[{"price":76.80,"qty":24.09345319}],"checksum":1755806074,"timestamp":"2024-06-01T17:52:49.151345Z"}]}
{"channel":"book","type":"update","data":[{"symbol":"LTC/EUR","bids":[],"asks":[{"price":76.79,"qty":64.52713955}],"checksum":3612591780,"timestamp":"2024-06-01T17:52:49.253018Z"}]}
{"channel":"book","type":"update","data":[{"symbol":"LTC/EUR","bids":[{"price":76.64,"qty":6.01200000}],"asks":[],"checksum":3737497328,"timestamp":"2024-06-01T17:52:49.937049Z"}]}
{"channel":"book","type":"update","data":[{"symbol":"LTC/EUR","bids":[{"price":76.71,"qty":66.12628943}],"asks":[],"checksum":4168693839,"timestamp":"2024-06-01T17:52:49.937158Z"}]}
{"channel":"book","type":"update","data":[{"symbol":"LTC/EUR","bids":[{"price":76.71,"qty":67.67695243}],"asks":[],"checksum":2043365726,"timestamp":"2024-06-01T17:52:49.942950Z"}]}
{"channel":"book","type":"update","data":[{"symbol":"LTC/EUR","bids":[{"price":76.64,"qty":7.61235810}],"asks":[],"checksum":3484008065,"timestamp":"2024-06-01T17:52:49.943005Z"}]}
{"channel":"book","type":"update","data":[{"symbol":"LTC/EUR","bids":[{"price":76.73,"qty":0.00000000},{"price":76.63,"qty":204.46043201}],"asks":[],"checksum":2612320208,"timestamp":"2024-06-01T17:52:50.296740Z"}]}
{"channel":"book","type":"update","data":[{"symbol":"LTC/EUR","bids":[],"asks":[{"price":76.77,"qty":79.54769052}],"checksum":1695506440,"timestamp":"2024-06-01T17:52:50.299613Z"}]}
{"channel":"book","type":"update","data":[{"symbol":"LTC/EUR","bids":[{"price":76.74,"qty":60.07242315}],"asks":[],"checksum":2234857492,"timestamp":"2024-06-01T17:52:50.301080Z"}]}
{"channel":"book","type":"update","data":[{"symbol":"LTC/EUR","bids":[],"asks":[{"price":76.77,"qty":100.50414308}],"checksum":818228185,"timestamp":"2024-06-01T17:52:50.302543Z"}]}
{"channel":"book","type":"update","data":[{"symbol":"LTC/EUR","bids":[{"price":76.64,"qty":6.01200000}],"asks":[],"checksum":2259147782,"timestamp":"2024-06-01T17:52:52.144833Z"}]}
{"channel":"book","type":"update","data":[{"symbol":"LTC/EUR","bids":[{"price":76.64,"qty":9.28054574}],"asks":[],"checksum":3389945952,"timestamp":"2024-06-01T17:52:52.150994Z"}]}
{"channel":"book","type":"update","data":[{"symbol":"LTC/EUR","bids":[],"asks":[{"price":76.80,"qty":23.85306512}],"checksum":172380546,"timestamp":"2024-06-01T17:52:52.352584Z"}]}
{"channel":"book","type":"update","data":[{"symbol":"LTC/EUR","bids":[],"asks":[{"price":76.80,"qty":24.32797241}],"checksum":2186703887,"timestamp":"2024-06-01T17:52:52.353284Z"}]}
{"channel":"book","type":"update","data":[{"symbol":"LTC/EUR","bids":[{"price":76.71,"qty":7.58374773}],"asks":[],"checksum":35685777,"timestamp":"2024-06-01T17:52:53.069201Z"}]}
{"channel":"book","type":"update","data":[{"symbol":"LTC/EUR","bids":[{"price":76.72,"qty":122.18936702}],"asks":[],"checksum":2165760076,"timestamp":"2024-06-01T17:52:53.073757Z"}]}
{"channel":"book","type":"update","data":[{"symbol":"LTC/EUR","bids":[],"asks":[{"price":76.79,"qty":62.23497293}],"checksum":1055022994,"timestamp":"2024-06-01T17:52:53.891884Z"}]}
{"channel":"book","type":"update","data":[{"symbol":"LTC/EUR","bids":[],"asks":[{"price":76.79,"qty":64.52713955}],"checksum":2165760076,"timestamp":"2024-06-01T17:52:54.163482Z"}]}
{"channel":"book","type":"update","data":[{"symbol":"LTC/EUR","bids":[{"price":76.66,"qty":2.65000000}],"asks":[],"checksum":1756250803,"timestamp":"2024-06-01T17:52:54.446901Z"}]}
{"channel":"book","type":"update","data":[{"symbol":"LTC/EUR","bids":[{"price":76.64,"qty":6.01200000}],"asks":[],"checksum":604497621,"timestamp":"2024-06-01T17:52:54.447197Z"}]}
{"channel":"book","type":"update","data":[{"symbol":"LTC/EUR","bids":[{"price":76.66,"qty":6.44675480}],"asks":[],"checksum":2889072225,"timestamp":"2024-06-01T17:52:54.453066Z"}]}
{"channel":"book","type":"update","data":[{"symbol":"LTC/EUR","bids":[{"price":76.64,"qty":7.79927498}],"asks":[],"checksum":3617779169,"timestamp":"2024-06-01T17:52:54.454136Z"}]}
{"channel":"book","type":"update","data":[{"symbol":"LTC/EUR","bids":[],"asks":[{"price":76.80,"qty":23.85306512}],"checksum":1605552236,"timestamp":"2024-06-01T17:52:54.607443Z"}]}
{"channel":"book","type":"update","data":[{"symbol":"LTC/EUR","bids":[],"asks":[{"price":76.80,"qty":24.09344725}],"checksum":4190454134,"timestamp":"2024-06-01T17:52:54.609855Z"}]}
{"channel":"book","type":"update","data":[{"symbol":"LTC/EUR","bids":[{"price":76.64,"qty":6.01200000}],"asks":[],"checksum":2186547958,"timestamp":"2024-06-01T17:52:56.610817Z"}]}
{"channel":"book","type":"update","data":[{"symbol":"LTC/EUR","bids":[{"price":76.64,"qty":6.50133218}],"asks":[],"checksum":2869353899,"timestamp":"2024-06-01T17:52:56.616371Z"}]}
{"channel":"book","type":"update","data":[{"symbol":"LTC/EUR","bids":[{"price":76.71,"qty":1.55066300}],"asks":[],"checksum":182883471,"timestamp":"2024-06-01T17:52:58.415516Z"}]}
{"channel":"book","type":"update","data":[{"symbol":"LTC/EUR","bids":[{"price":76.71,"qty":7.58374773}],"asks":[],"checksum":2869353899,"timestamp":"2024-06-01T17:52:58.539177Z"}]}
{"channel":"book","type":"update","data":[{"symbol":"LTC/EUR","bids":[{"price":76.66,"qty":2.65000000}],"asks":[],"checksum":590513439,"timestamp":"2024-06-01T17:52:58.720444Z"}]}
{"channel":"book","type":"update","data":[{"symbol":"LTC/EUR","bids":[{"price":76.64,"qty":6.01200000}],"asks":[],"checksum":174082626,"timestamp":"2024-06-01T17:52:58.720552Z"}]}
{"channel":"book","type":"update","data":[{"symbol":"LTC/EUR","bids":[{"price":76.66,"qty":6.63403073}],"asks":[],"checksum":3822643389,"timestamp":"2024-06-01T17:52:58.727307Z"}]}
{"channel":"book","type":"update","data":[{"symbol":"LTC/EUR","bids":[{"price":76.64,"qty":6.87094137}],"asks":[],"checksum":685522504,"timestamp":"2024-06-01T17:52:58.727419Z"}]}
{"channel":"book","type":"update","data":[{"symbol":"LTC/EUR","bids":[],"asks":[{"price":76.80,"qty":23.85306512}],"checksum":2393618258,"timestamp":"2024-06-01T17:52:59.104469Z"}]}
{"channel":"book","type":"update","data":[{"symbol":"LTC/EUR","bids":[],"asks":[{"price":76.80,"qty":24.32797241}],"checksum":112956127,"timestamp":"2024-06-01T17:52:59.104679Z"}]}
{"channel":"book","type":"update","data":[{"symbol":"LTC/EUR","bids":[{"price":76.64,"qty":6.01200000}],"asks":[],"checksum":3451864106,"timestamp":"2024-06-01T17:53:00.954041Z"}]}
{"channel":"book","type":"update","data":[{"symbol":"LTC/EUR","bids":[{"price":76.64,"qty":8.16842065}],"asks":[],"checksum":3562192780,"timestamp":"2024-06-01T17:53:00.959174Z"}]}
{"channel":"book","type":"update","data":[{"symbol":"LTC/EUR","bids":[{"price":76.64,"qty":11.11364638}],"asks":[],"checksum":1278151438,"timestamp":"2024-06-01T17:53:02.836883Z"}]}
{"channel":"book","type":"update","data":[{"symbol":"LTC/EUR","bids":[{"price":76.64,"qty":8.16842065}],"asks":[],"checksum":3562192780,"timestamp":"2024-06-01T17:53:02.930566Z"}]}
{"channel":"book","type":"update","data":[{"symbol":"LTC/EUR","bids":[{"price":76.71,"qty":6.03308473}],"asks":[],"checksum":3576354092,"timestamp":"2024-06-01T17:53:03.127535Z"}]}
{"channel":"book","type":"update","data":[{"symbol":"LTC/EUR","bids":[{"price":76.66,"qty":2.65000000}],"asks":[],"checksum":1016231891,"timestamp":"2024-06-01T17:53:03.127547Z"}]}
{"channel":"book","type":"update","data":[{"symbol":"LTC/EUR","bids":[{"price":76.64,"qty":6.01200000}],"asks":[],"checksum":629116021,"timestamp":"2024-06-01T17:53:03.127650Z"}]}
{"channel":"book","type":"update","data":[{"symbol":"LTC/EUR","bids":[{"price":76.66,"qty":7.19557713}],"asks":[],"checksum":2269829644,"timestamp":"2024-06-01T17:53:03.177479Z"}]}
{"channel":"book","type":"update","data":[{"symbol":"LTC/EUR","bids":[{"price":76.71,"qty":7.77092986}],"asks":[],"checksum":2078259562,"timestamp":"2024-06-01T17:53:03.177703Z"}]}
{"channel":"book","type":"update","data":[{"symbol":"LTC/EUR","bids":[{"price":76.64,"qty":7.60559468}],"asks":[],"checksum":4225357872,"timestamp":"2024-06-01T17:53:03.177856Z"}]}
{"channel":"book","type":"update","data":[{"symbol":"LTC/EUR","bids":[{"price":76.64,"qty":10.55082041}],"asks":[],"checksum":1944376587,"timestamp":"2024-06-01T17:53:03.203145Z"}]}
{"channel":"book","type":"update","data":[{"symbol":"LTC/EUR","bids":[{"price":76.64,"qty":7.60559468}],"asks":[],"checksum":4225357872,"timestamp":"2024-06-01T17:53:03.216541Z"}]}
{"channel":"book","type":"update","data":[{"symbol":"LTC/EUR","bids":[],"asks":[{"price":76.79,"qty":62.23497293}],"checksum":1143826414,"timestamp":"2024-06-01T17:53:04.124120Z"}]}
{"channel":"book","type":"update","data":[{"symbol":"LTC/EUR","bids":[{"price":76.64,"qty":6.01200000}],"asks":[],"checksum":3291154100,"timestamp":"2024-06-01T17:53:05.350184Z"}]}
{"channel":"book","type":"update","data":[{"symbol":"LTC/EUR","bids":[{"price":76.66,"qty":2.65000000}],"asks":[],"checksum":1713262797,"timestamp":"2024-06-01T17:53:05.350335Z"}]}
{"channel":"book","type":"update","data":[{"symbol":"LTC/EUR","bids":[{"price":76.66,"qty":6.38313195}],"asks":[],"checksum":2229250596,"timestamp":"2024-06-01T17:53:05.355229Z"}]}
{"channel":"book","type":"update","data":[{"symbol":"LTC/EUR","bids":[],"asks":[{"price":76.77,"qty":102.78414308}],"checksum":1448227114,"timestamp":"2024-06-01T17:53:06.108476Z"}]}
{"channel":"book","type":"update","data":[{"symbol":"LTC/EUR","bids":[{"price":76.71,"qty":6.03308473}],"asks":[],"checksum":2865189452,"timestamp":"2024-06-01T17:53:07.435565Z"}]}
{"channel":"book","type":"update","data":[{"symbol":"LTC/EUR","bids":[{"price":76.66,"qty":2.65000000}],"asks":[],"checksum":1208395941,"timestamp":"2024-06-01T17:53:07.435781Z"}]}
{"channel":"book","type":"update","data":[{"symbol":"LTC/EUR","bids":[{"price":76.71,"qty":7.95811200}],"asks":[],"checksum":1494998635,"timestamp":"2024-06-01T17:53:07.441579Z"}]}
{"channel":"book","type":"update","data":[{"symbol":"LTC/EUR","bids":[{"price":76.66,"qty":7.19557713}],"asks":[],"checksum":4214130706,"timestamp":"2024-06-01T17:53:07.441695Z"}]}
{"channel":"book","type":"update","data":[{"symbol":"LTC/EUR","bids":[{"price":76.64,"qty":7.41841255}],"asks":[],"checksum":2317460684,"timestamp":"2024-06-01T17:53:07.441836Z"}]}
{"channel":"book","type":"update","data":[{"symbol":"LTC/EUR","bids":[{"price":76.66,"qty":2.65000000}],"asks":[],"checksum":672461493,"timestamp":"2024-06-01T17:53:09.647096Z"}]}
{"channel":"book","type":"update","data":[{"symbol":"LTC/EUR","bids":[{"price":76.64,"qty":6.01200000}],"asks":[],"checksum":1494998635,"timestamp":"2024-06-01T17:53:09.647210Z"}]}
{"channel":"book","type":"update","data":[{"symbol":"LTC/EUR","bids":[{"price":76.66,"qty":7.38275926}],"asks":[],"checksum":1311244611,"timestamp":"2024-06-01T17:53:09.689591Z"}]}
{"channel":"book","type":"update","data":[{"symbol":"LTC/EUR","bids":[{"price":76.64,"qty":7.60175599}],"asks":[],"checksum":2499053753,"timestamp":"2024-06-01T17:53:09.689728Z"}]}
{"channel":"book","type":"update","data":[{"symbol":"LTC/EUR","bids":[{"price":76.64,"qty":6.01200000}],"asks":[],"checksum":1311244611,"timestamp":"2024-06-01T17:53:11.796676Z"}]}
{"channel":"book","type":"update","data":[{"symbol":"LTC/EUR","bids":[{"price":76.64,"qty":6.67681303}],"asks":[],"checksum":1669708975,"timestamp":"2024-06-01T17:53:11.804344Z"}]}
{"channel":"book","type":"update","data":[{"symbol":"LTC/EUR","bids":[],"asks":[{"price":76.82,"qty":60.20251462},{"price":76.81,"qty":138.23608312}],"checksum":932752746,"timestamp":"2024-06-01T17:53:12.552701Z"}]}
{"channel":"book","type":"update","data":[{"symbol":"LTC/EUR","bids":[{"price":76.64,"qty":6.01200000}],"asks":[],"checksum":439685254,"timestamp":"2024-06-01T17:53:13.982063Z"}]}
{"channel":"book","type":"update","data":[{"symbol":"LTC/EUR","bids":[{"price":76.64,"qty":7.23177880}],"asks":[],"checksum":3076349734,"timestamp":"2024-06-01T17:53:13.987446Z"}]}
{"channel":"book","type":"update","data":[{"symbol":"LTC/EUR","bids":[],"asks":[{"price":76.80,"qty":0.47490729}],"checksum":2309557951,"timestamp":"2024-06-01T17:53:15.556818Z"}]}
{"channel":"book","type":"update","data":[{"symbol":"LTC/EUR","bids":[{"price":76.64,"qty":10.17700453}],"asks":[],"checksum":929110736,"timestamp":"2024-06-01T17:53:15.560086Z"}]}
{"channel":"book","type":"update","data":[{"symbol":"LTC/EUR","bids":[{"price":76.64,"qty":7.23177880}],"asks":[],"checksum":2309557951,"timestamp":"2024-06-01T17:53:15.825306Z"}]}
{"channel":"book","type":"update","data":[{"symbol":"LTC/EUR","bids":[{"price":76.64,"qty":6.01200000}],"asks":[],"checksum":616644895,"timestamp":"2024-06-01T17:53:16.156518Z"}]}
{"channel":"book","type":"update","data":[{"symbol":"LTC/EUR","bids":[{"price":76.71,"qty":6.03308473}],"asks":[],"checksum":903624657,"timestamp":"2024-06-01T17:53:16.156554Z"}]}
