{"channel":"book","type":"snapshot","data":[{"symbol":"LTC/GBP","bids":[{"price":65.26100,"qty":19.74141110},{"price":65.26099,"qty":8.68000000},{"price":65.25471,"qty":6.01117861},{"price":65.22565,"qty":7.85910303},{"price":65.20100,"qty":4.82112449},{"price":65.08656,"qty":6.44724715},{"price":65.08655,"qty":26.96324305},{"price":65.00000,"qty":7.69231000},{"price":64.97500,"qty":0.13090947},{"price":64.84839,"qty":17.82430478}],"asks":[{"price":65.31984,"qty":6.00000000},{"price":65.31985,"qty":63.21095256},{"price":65.35457,"qty":1.84738230},{"price":65.35458,"qty":8.83137436},{"price":65.36249,"qty":0.14271661},{"price":65.36290,"qty":4.82112449},{"price":65.47847,"qty":9.13893827},{"price":65.47850,"qty":17.82430478},{"price":65.67494,"qty":17.82430478},{"price":65.73807,"qty":12.06939088}],"checksum":3156195688}]}
{"channel":"book","type":"update","data":[{"symbol":"LTC/GBP","bids":[{"price":65.26099,"qty":0.00000000},{"price":64.79874,"qty":2.14703376},{"price":65.26101,"qty":8.68000000}],"asks":[],"checksum":3847109886,"timestamp":"2024-06-01T17:52:03.948678Z"}]}
{"channel":"book","type":"update","data":[{"symbol":"LTC/GBP","bids":[{"price":65.26100,"qty":0.00000000},{"price":64.79874,"qty":2.14703376},{"price":65.26102,"qty":19.74140614}],"asks":[],"checksum":584201951,"timestamp":"2024-06-01T17:52:03.955358Z"}]}
{"channel":"book","type":"update","data":[{"symbol":"LTC/GBP","bids":[{"price":65.26102,"qty":0.00000000},{"price":64.79874,"qty":2.14703376},{"price":65.26102,"qty":17.93014956}],"asks":[],"checksum":4123954588,"timestamp":"2024-06-01T17:52:04.361183Z"}]}
{"channel":"book","type":"update","data":[{"symbol":"LTC/GBP","bids":[{"price":65.26101,"qty":0.00000000},{"price":64.79874,"qty":2.14703376},{"price":65.26103,"qty":8.68000000}],"asks":[],"checksum":3420315229,"timestamp":"2024-06-01T17:52:04.678669Z"}]}
{"channel":"book","type":"update","data":[{"symbol":"LTC/GBP","bids":[{"price":65.26102,"qty":0.00000000},{"price":64.79874,"qty":2.14703376},{"price":65.26104,"qty":18.00637157}],"asks":[],"checksum":601255589,"timestamp":"2024-06-01T17:52:04.688739Z"}]}
{"channel":"book","type":"update","data":[{"symbol":"LTC/GBP","bids":[{"price":65.26103,"qty":0.00000000},{"price":64.79874,"qty":2.14703376},{"price":65.26105,"qty":8.68000000}],"asks":[],"checksum":3757705453,"timestamp":"2024-06-01T17:52:05.012304Z"}]}
{"channel":"book","type":"update","data":[{"symbol":"LTC/GBP","bids":[{"price":65.26104,"qty":0.00000000},{"price":64.79874,"qty":2.14703376},{"price":65.26106,"qty":18.00636599}],"asks":[],"checksum":3310888884,"timestamp":"2024-06-01T17:52:05.049507Z"}]}
{"channel":"book","type":"update","data":[{"symbol":"LTC/GBP","bids":[{"price":65.26105,"qty":0.00000000},{"price":64.79874,"qty":2.14703376},{"price":65.26107,"qty":8.68000000}],"asks":[],"checksum":2145510182,"timestamp":"2024-06-01T17:52:05.381500Z"}]}
{"channel":"book","type":"update","data":[{"symbol":"LTC/GBP","bids":[{"price":65.26106,"qty":0.00000000},{"price":64.79874,"qty":2.14703376},{"price":65.26108,"qty":18.00636045}],"asks":[],"checksum":3658119911,"timestamp":"2024-06-01T17:52:05.443479Z"}]}
{"channel":"book","type":"update","data":[{"symbol":"LTC/GBP","bids":[{"price":65.26107,"qty":0.00000000},{"price":64.79874,"qty":2.14703376},{"price":65.26109,"qty":8.68000000}],"asks":[],"checksum":2237887115,"timestamp":"2024-06-01T17:52:05.775996Z"}]}
{"channel":"book","type":"update","data":[{"symbol":"LTC/GBP","bids":[{"price":65.26108,"qty":0.00000000},{"price":64.79874,"qty":2.14703376},{"price":65.26110,"qty":18.00635492}],"asks":[],"checksum":2305025467,"timestamp":"2024-06-01T17:52:05.794206Z"}]}
{"channel":"book","type":"update","data":[{"symbol":"LTC/GBP","bids":[{"price":65.08655,"qty":17.82430478}],"asks":[],"checksum":2464909094,"timestamp":"2024-06-01T17:52:06.032513Z"}]}
{"channel":"book","type":"update","data":[{"symbol":"LTC/GBP","bids":[],"asks":[{"price":65.47847,"qty":0.00000000},{"price":65.85680,"qty":127.06288084}],"checksum":1256844367,"timestamp":"2024-06-01T17:52:06.032647Z"}]}
{"channel":"book","type":"update","data":[{"symbol":"LTC/GBP","bids":[{"price":64.84839,"qty":0.00000000},{"price":64.79874,"qty":2.14703376}],"asks":[],"checksum":2933909385,"timestamp":"2024-06-01T17:52:06.032657Z"}]}
{"channel":"book","type":"update","data":[{"symbol":"LTC/GBP","bids":[{"price":65.08657,"qty":9.13893827}],"asks":[],"checksum":3632780790,"timestamp":"2024-06-01T17:52:06.035383Z"}]}
{"channel":"book","type":"update","data":[{"symbol":"LTC/GBP","bids":[],"asks":[{"price":65.47846,"qty":9.13893827}],"checksum":2912051146,"timestamp":"2024-06-01T17:52:06.035464Z"}]}
{"channel":"book","type":"update","data":[{"symbol":"LTC/GBP","bids":[],"asks":[{"price":65.73806,"qty":0.29347284}],"checksum":1407146093,"timestamp":"2024-06-01T17:52:06.036910Z"}]}
{"channel":"book","type":"update","data":[{"symbol":"LTC/GBP","bids":[{"price":65.08656,"qty":0.00000000},{"price":64.87186,"qty":0.15596138}],"asks":[],"checksum":4172082758,"timestamp":"2024-06-01T17:52:06.064294Z"}]}
{"channel":"book","type":"update","data":[{"symbol":"LTC/GBP","bids":[{"price":65.08658,"qty":6.44724457}],"asks":[],"checksum":4057712368,"timestamp":"2024-06-01T17:52:06.064330Z"}]}
{"channel":"book","type":"update","data":[{"symbol":"LTC/GBP","bids":[{"price":65.26109,"qty":0.00000000},{"price":64.87186,"qty":0.15596138},{"price":65.26111,"qty":8.68000000}],"asks":[],"checksum":3023880801,"timestamp":"2024-06-01T17:52:06.387543Z"}]}
{"channel":"book","type":"update","data":[{"symbol":"LTC/GBP","bids":[{"price":65.26110,"qty":0.00000000},{"price":64.87186,"qty":0.15596138},{"price":65.26112,"qty":18.00441721}],"asks":[],"checksum":3955060148,"timestamp":"2024-06-01T17:52:06.391072Z"}]}
{"channel":"book","type":"update","data":[{"symbol":"LTC/GBP","bids":[{"price":65.26111,"qty":0.00000000},{"price":64.87186,"qty":0.15596138},{"price":65.26113,"qty":8.68000000}],"asks":[],"checksum":31039148,"timestamp":"2024-06-01T17:52:06.724334Z"}]}
{"channel":"book","type":"update","data":[{"symbol":"LTC/GBP","bids":[{"price":65.26112,"qty":0.00000000},{"price":64.87186,"qty":0.15596138},{"price":65.26114,"qty":18.00441044}],"asks":[],"checksum":3615105772,"timestamp":"2024-06-01T17:52:06.732609Z"}]}
{"channel":"book","type":"update","data":[{"symbol":"LTC/GBP","bids":[{"price":65.26113,"qty":0.00000000},{"price":64.87186,"qty":0.15596138},{"price":65.26115,"qty":8.68000000}],"asks":[],"checksum":1098355961,"timestamp":"2024-06-01T17:52:07.058449Z"}]}
{"channel":"book","type":"update","data":[{"symbol":"LTC/GBP","bids":[{"price":65.26114,"qty":0.00000000},{"price":64.87186,"qty":0.15596138},{"price":65.26116,"qty":18.00440449}],"asks":[],"checksum":682011871,"timestamp":"2024-06-01T17:52:07.107576Z"}]}
{"channel":"book","type":"update","data":[{"symbol":"LTC/GBP","bids":[{"price":65.26115,"qty":0.00000000},{"price":64.87186,"qty":0.15596138},{"price":65.26117,"qty":8.68000000}],"asks":[],"checksum":3142141868,"timestamp":"2024-06-01T17:52:07.727581Z"}]}
{"channel":"book","type":"update","data":[{"symbol":"LTC/GBP","bids":[{"price":65.26116,"qty":0.00000000},{"price":64.87186,"qty":0.15596138},{"price":65.26118,"qty":18.00439872}],"asks":[],"checksum":605113280,"timestamp":"2024-06-01T17:52:07.730633Z"}]}
{"channel":"book","type":"update","data":[{"symbol":"LTC/GBP","bids":[{"price":65.26118,"qty":24.01557733}],"asks":[],"checksum":4173611259,"timestamp":"2024-06-01T17:52:07.896467Z"}]}
{"channel":"book","type":"update","data":[{"symbol":"LTC/GBP","bids":[{"price":65.25471,"qty":0.00000000},{"price":64.87186,"qty":0.15596138}],"asks":[],"checksum":2276757319,"timestamp":"2024-06-01T17:52:08.077095Z"}]}
{"channel":"book","type":"update","data":[{"symbol":"LTC/GBP","bids":[{"price":65.26118,"qty":6.01117861},{"price":65.26119,"qty":18.00439593}],"asks":[],"checksum":4105650527,"timestamp":"2024-06-01T17:52:08.096523Z"}]}
{"channel":"book","type":"update","data":[{"symbol":"LTC/GBP","bids":[{"price":65.26117,"qty":0.00000000},{"price":64.84840,"qty":17.82430478},{"price":65.26120,"qty":8.68000000}],"asks":[],"checksum":374277904,"timestamp":"2024-06-01T17:52:08.431558Z"}]}
{"channel":"book","type":"update","data":[{"symbol":"LTC/GBP","bids":[{"price":65.22565,"qty":0.00000000},{"price":64.84840,"qty":17.82430478}],"asks":[],"checksum":2700014357,"timestamp":"2024-06-01T17:52:08.432698Z"}]}
{"channel":"book","type":"update","data":[{"symbol":"LTC/GBP","bids":[],"asks":[{"price":65.31985,"qty":0.00000000},{"price":65.73807,"qty":12.06939088}],"checksum":2940245047,"timestamp":"2024-06-01T17:52:08.432713Z"}]}
{"channel":"book","type":"update","data":[{"symbol":"LTC/GBP","bids":[{"price":64.87196,"qty":0.15611513}],"asks":[],"checksum":3776155288,"timestamp":"2024-06-01T17:52:08.435046Z"}]}
{"channel":"book","type":"update","data":[{"symbol":"LTC/GBP","bids":[{"price":65.26652,"qty":1.30000000}],"asks":[],"checksum":3156038127,"timestamp":"2024-06-01T17:52:08.435760Z"}]}
{"channel":"book","type":"update","data":[{"symbol":"LTC/GBP","bids":[{"price":65.26119,"qty":0.00000000},{"price":64.87196,"qty":0.15611513},{"price":65.08659,"qty":18.05364993}],"asks":[],"checksum":2611728269,"timestamp":"2024-06-01T17:52:08.435944Z"}]}
{"channel":"book","type":"update","data":[{"symbol":"LTC/GBP","bids":[],"asks":[{"price":65.73806,"qty":0.00000000},{"price":65.85680,"qty":127.06288084}],"checksum":3746823580,"timestamp":"2024-06-01T17:52:08.436658Z"}]}
{"channel":"book","type":"update","data":[{"symbol":"LTC/GBP","bids":[],"asks":[{"price":65.31200,"qty":63.58970256}],"checksum":3645365402,"timestamp":"2024-06-01T17:52:08.437450Z"}]}
{"channel":"book","type":"update","data":[{"symbol":"LTC/GBP","bids":[{"price":65.22565,"qty":12.11535643}],"asks":[],"checksum":1583400696,"timestamp":"2024-06-01T17:52:08.438015Z"}]}
{"channel":"book","type":"update","data":[{"symbol":"LTC/GBP","bids":[{"price":65.26652,"qty":0.00000000},{"price":64.97500,"qty":0.13090947}],"asks":[],"checksum":1265415155,"timestamp":"2024-06-01T17:52:08.440165Z"}]}
{"channel":"book","type":"update","data":[{"symbol":"LTC/GBP","bids":[{"price":65.08657,"qty":0.00000000},{"price":64.87196,"qty":0.15611513}],"asks":[],"checksum":3406298712,"timestamp":"2024-06-01T17:52:08.440699Z"}]}
{"channel":"book","type":"update","data":[{"symbol":"LTC/GBP","bids":[],"asks":[{"price":65.47846,"qty":0.00000000},{"price":65.85680,"qty":127.06288084}],"checksum":2271043450,"timestamp":"2024-06-01T17:52:08.440845Z"}]}
{"channel":"book","type":"update","data":[{"symbol":"LTC/GBP","bids":[],"asks":[{"price":65.73806,"qty":0.29347284}],"checksum":2221065188,"timestamp":"2024-06-01T17:52:08.443279Z"}]}
{"channel":"book","type":"update","data":[{"symbol":"LTC/GBP","bids":[{"price":65.08660,"qty":9.13893827}],"asks":[],"checksum":1287280139,"timestamp":"2024-06-01T17:52:08.443485Z"}]}
{"channel":"book","type":"update","data":[{"symbol":"LTC/GBP","bids":[],"asks":[{"price":65.47845,"qty":9.13893827}],"checksum":3411226275,"timestamp":"2024-06-01T17:52:08.443647Z"}]}
{"channel":"book","type":"update","data":[{"symbol":"LTC/GBP","bids":[{"price":65.08658,"qty":0.00000000},{"price":64.87197,"qty":17.82430478}],"asks":[],"checksum":41230896,"timestamp":"2024-06-01T17:52:08.453633Z"}]}
{"channel":"book","type":"update","data":[{"symbol":"LTC/GBP","bids":[{"price":65.08661,"qty":6.44724160}],"asks":[],"checksum":835145806,"timestamp":"2024-06-01T17:52:08.453720Z"}]}
{"channel":"book","type":"update","data":[{"symbol":"LTC/GBP","bids":[{"price":65.08659,"qty":0.00000000},{"price":64.87197,"qty":17.82430478},{"price":65.26121,"qty":18.00534362}],"asks":[],"checksum":3663139188,"timestamp":"2024-06-01T17:52:08.495953Z"}]}
{"channel":"book","type":"update","data":[{"symbol":"LTC/GBP","bids":[],"asks":[{"price":65.31199,"qty":6.00000000}],"checksum":1719497794,"timestamp":"2024-06-01T17:52:08.501221Z"}]}
{"channel":"book","type":"update","data":[{"symbol":"LTC/GBP","bids":[],"asks":[{"price":65.31984,"qty":0.00000000},{"price":65.73806,"qty":0.29347284}],"checksum":2297417172,"timestamp":"2024-06-01T17:52:08.728655Z"}]}
{"channel":"book","type":"update","data":[{"symbol":"LTC/GBP","bids":[{"price":65.26120,"qty":0.00000000},{"price":64.87197,"qty":17.82430478},{"price":65.26122,"qty":8.68000000}],"asks":[],"checksum":3895767070,"timestamp":"2024-06-01T17:52:09.377152Z"}]}
{"channel":"book","type":"update","data":[{"symbol":"LTC/GBP","bids":[{"price":65.26121,"qty":0.00000000},{"price":64.87197,"qty":17.82430478},{"price":65.26123,"qty":18.00533787}],"asks":[],"checksum":1653931564,"timestamp":"2024-06-01T17:52:09.380179Z"}]}
{"channel":"book","type":"update","data":[{"symbol":"LTC/GBP","bids":[{"price":65.26122,"qty":0.00000000},{"price":64.87197,"qty":17.82430478},{"price":65.26124,"qty":8.68000000}],"asks":[],"checksum":3900402650,"timestamp":"2024-06-01T17:52:09.712592Z"}]}
{"channel":"book","type":"update","data":[{"symbol":"LTC/GBP","bids":[{"price":65.26123,"qty":0.00000000},{"price":64.87197,"qty":17.82430478},{"price":65.26125,"qty":18.00533234}],"asks":[],"checksum":1288283745,"timestamp":"2024-06-01T17:52:09.803134Z"}]}
{"channel":"book","type":"update","data":[{"symbol":"LTC/GBP","bids":[{"price":65.26124,"qty":0.00000000},{"price":64.87197,"qty":17.82430478},{"price":65.26126,"qty":8.68000000}],"asks":[],"checksum":2060348763,"timestamp":"2024-06-01T17:52:10.140295Z"}]}
{"channel":"book","type":"update","data":[{"symbol":"LTC/GBP","bids":[{"price":65.26125,"qty":0.00000000},{"price":64.87197,"qty":17.82430478},{"price":65.26127,"qty":18.00532680}],"asks":[],"checksum":2448567139,"timestamp":"2024-06-01T17:52:10.183203Z"}]}
{"channel":"book","type":"update","data":[{"symbol":"LTC/GBP","bids":[{"price":65.26126,"qty":0.00000000},{"price":64.87197,"qty":17.82430478},{"price":65.26128,"qty":8.68000000}],"asks":[],"checksum":3614018389,"timestamp":"2024-06-01T17:52:10.628811Z"}]}
{"channel":"book","type":"update","data":[{"symbol":"LTC/GBP","bids":[{"price":65.26127,"qty":0.00000000},{"price":64.87197,"qty":17.82430478},{"price":65.26129,"qty":18.00442195}],"asks":[],"checksum":3531893602,"timestamp":"2024-06-01T17:52:10.632169Z"}]}
{"channel":"book","type":"update","data":[{"symbol":"LTC/GBP","bids":[],"asks":[{"price":65.73806,"qty":0.00000000},{"price":65.73807,"qty":12.06939088}],"checksum":645277107,"timestamp":"2024-06-01T17:52:10.838574Z"}]}
{"channel":"book","type":"update","data":[{"symbol":"LTC/GBP","bids":[{"price":65.26128,"qty":0.00000000},{"price":64.87197,"qty":17.82430478},{"price":65.26130,"qty":8.68000000}],"asks":[],"checksum":3162104235,"timestamp":"2024-06-01T17:52:11.180788Z"}]}
{"channel":"book","type":"update","data":[{"symbol":"LTC/GBP","bids":[{"price":65.26129,"qty":0.00000000},{"price":64.87197,"qty":17.82430478},{"price":65.26131,"qty":18.00441506}],"asks":[],"checksum":2959142683,"timestamp":"2024-06-01T17:52:11.184384Z"}]}
{"channel":"book","type":"update","data":[{"symbol":"LTC/GBP","bids":[{"price":65.26130,"qty":0.00000000},{"price":64.87197,"qty":17.82430478},{"price":65.26132,"qty":8.68000000}],"asks":[],"checksum":551536047,"timestamp":"2024-06-01T17:52:11.819053Z"}]}
{"channel":"book","type":"update","data":[{"symbol":"LTC/GBP","bids":[{"price":65.26131,"qty":0.00000000},{"price":64.87197,"qty":17.82430478},{"price":65.26133,"qty":18.00440873}],"asks":[],"checksum":2699402780,"timestamp":"2024-06-01T17:52:11.822302Z"}]}
{"channel":"book","type":"update","data":[{"symbol":"LTC/GBP","bids":[{"price":65.26132,"qty":0.00000000},{"price":64.87197,"qty":17.82430478},{"price":65.26134,"qty":8.68000000}],"asks":[],"checksum":2409768776,"timestamp":"2024-06-01T17:52:12.153162Z"}]}
{"channel":"book","type":"update","data":[{"symbol":"LTC/GBP","bids":[{"price":65.26133,"qty":0.00000000},{"price":64.87197,"qty":17.82430478},{"price":65.26135,"qty":18.00440310}],"asks":[],"checksum":1913994807,"timestamp":"2024-06-01T17:52:12.183141Z"}]}
{"channel":"book","type":"update","data":[{"symbol":"LTC/GBP","bids":[{"price":65.26134,"qty":0.00000000},{"price":64.87197,"qty":17.82430478},{"price":65.26136,"qty":8.68000000}],"asks":[],"checksum":120637154,"timestamp":"2024-06-01T17:52:12.643071Z"}]}
{"channel":"book","type":"update","data":[{"symbol":"LTC/GBP","bids":[{"price":65.26135,"qty":0.00000000},{"price":64.87197,"qty":17.82430478},{"price":65.26137,"qty":18.00561979}],"asks":[],"checksum":178108002,"timestamp":"2024-06-01T17:52:12.646795Z"}]}
{"channel":"book","type":"update","data":[{"symbol":"LTC/GBP","bids":[{"price":65.26136,"qty":0.00000000},{"price":64.87197,"qty":17.82430478},{"price":65.26138,"qty":8.68000000}],"asks":[],"checksum":2719227265,"timestamp":"2024-06-01T17:52:13.281651Z"}]}
{"channel":"book","type":"update","data":[{"symbol":"LTC/GBP","bids":[{"price":65.26137,"qty":0.00000000},{"price":64.87197,"qty":17.82430478},{"price":65.26139,"qty":18.00561417}],"asks":[],"checksum":1901729957,"timestamp":"2024-06-01T17:52:13.285069Z"}]}
{"channel":"book","type":"update","data":[{"symbol":"LTC/GBP","bids":[{"price":65.26138,"qty":0.00000000},{"price":64.87197,"qty":17.82430478},{"price":65.26140,"qty":8.68000000}],"asks":[],"checksum":2956376305,"timestamp":"2024-06-01T17:52:13.615529Z"}]}
{"channel":"book","type":"update","data":[{"symbol":"LTC/GBP","bids":[{"price":65.26139,"qty":0.00000000},{"price":64.87197,"qty":17.82430478},{"price":65.26141,"qty":18.00560863}],"asks":[],"checksum":3515425514,"timestamp":"2024-06-01T17:52:13.669377Z"}]}
{"channel":"book","type":"update","data":[{"symbol":"LTC/GBP","bids":[{"price":65.26140,"qty":0.00000000},{"price":64.87197,"qty":17.82430478},{"price":65.26142,"qty":8.68000000}],"asks":[],"checksum":3167321917,"timestamp":"2024-06-01T17:52:14.285798Z"}]}
{"channel":"book","type":"update","data":[{"symbol":"LTC/GBP","bids":[{"price":65.26141,"qty":0.00000000},{"price":64.87197,"qty":17.82430478},{"price":65.26143,"qty":18.00449885}],"asks":[],"checksum":2831425121,"timestamp":"2024-06-01T17:52:14.289139Z"}]}
{"channel":"book","type":"update","data":[{"symbol":"LTC/GBP","bids":[{"price":65.26142,"qty":0.00000000},{"price":64.87197,"qty":17.82430478},{"price":65.26144,"qty":8.68000000}],"asks":[],"checksum":2704434019,"timestamp":"2024-06-01T17:52:14.623221Z"}]}
{"channel":"book","type":"update","data":[{"symbol":"LTC/GBP","bids":[{"price":65.26143,"qty":0.00000000},{"price":64.87197,"qty":17.82430478},{"price":65.26145,"qty":18.00449309}],"asks":[],"checksum":2834882645,"timestamp":"2024-06-01T17:52:14.663523Z"}]}
{"channel":"book","type":"update","data":[{"symbol":"LTC/GBP","bids":[{"price":65.26144,"qty":0.00000000},{"price":64.87197,"qty":17.82430478},{"price":65.26146,"qty":8.68000000}],"asks":[],"checksum":2817225829,"timestamp":"2024-06-01T17:52:14.989587Z"}]}
{"channel":"book","type":"update","data":[{"symbol":"LTC/GBP","bids":[{"price":65.26145,"qty":0.00000000},{"price":64.87197,"qty":17.82430478},{"price":65.26147,"qty":18.00448740}],"asks":[],"checksum":3031460042,"timestamp":"2024-06-01T17:52:15.072169Z"}]}
{"channel":"book","type":"update","data":[{"symbol":"LTC/GBP","bids":[{"price":65.26146,"qty":0.00000000},{"price":64.87197,"qty":17.82430478},{"price":65.26148,"qty":8.68000000}],"asks":[],"checksum":2509989360,"timestamp":"2024-06-01T17:52:15.687695Z"}]}
{"channel":"book","type":"update","data":[{"symbol":"LTC/GBP","bids":[{"price":65.26147,"qty":0.00000000},{"price":64.87197,"qty":17.82430478},{"price":65.26149,"qty":18.00448178}],"asks":[],"checksum":3743999264,"timestamp":"2024-06-01T17:52:15.691533Z"}]}
{"channel":"book","type":"update","data":[{"symbol":"LTC/GBP","bids":[{"price":65.26148,"qty":0.00000000},{"price":64.87197,"qty":17.82430478},{"price":65.26150,"qty":8.68000000}],"asks":[],"checksum":80381275,"timestamp":"2024-06-01T17:52:16.028271Z"}]}
{"channel":"book","type":"update","data":[{"symbol":"LTC/GBP","bids":[{"price":65.26149,"qty":0.00000000},{"price":64.87197,"qty":17.82430478},{"price":65.26151,"qty":18.00447625}],"asks":[],"checksum":3645515486,"timestamp":"2024-06-01T17:52:16.090764Z"}]}
{"channel":"book","type":"update","data":[{"symbol":"LTC/GBP","bids":[{"price":65.26150,"qty":0.00000000},{"price":64.87197,"qty":17.82430478},{"price":65.26152,"qty":8.68000000}],"asks":[],"checksum":4102534665,"timestamp":"2024-06-01T17:52:16.722994Z"}]}
{"channel":"book","type":"update","data":[{"symbol":"LTC/GBP","bids":[{"price":65.26151,"qty":0.00000000},{"price":64.87197,"qty":17.82430478},{"price":65.26153,"qty":18.00492263}],"asks":[],"checksum":389357908,"timestamp":"2024-06-01T17:52:16.727300Z"}]}
{"channel":"book","type":"update","data":[{"symbol":"LTC/GBP","bids":[{"price":65.26152,"qty":0.00000000},{"price":64.87197,"qty":17.82430478},{"price":65.26154,"qty":8.68000000}],"asks":[],"checksum":4169052809,"timestamp":"2024-06-01T17:52:17.056632Z"}]}
{"channel":"book","type":"update","data":[{"symbol":"LTC/GBP","bids":[{"price":65.26153,"qty":0.00000000},{"price":64.87197,"qty":17.82430478},{"price":65.26155,"qty":18.00491740}],"asks":[],"checksum":3275718632,"timestamp":"2024-06-01T17:52:17.116332Z"}]}
{"channel":"book","type":"update","data":[{"symbol":"LTC/GBP","bids":[{"price":65.26154,"qty":0.00000000},{"price":64.87197,"qty":17.82430478},{"price":65.26156,"qty":8.68000000}],"asks":[],"checksum":2411104863,"timestamp":"2024-06-01T17:52:17.454629Z"}]}
{"channel":"book","type":"update","data":[{"symbol":"LTC/GBP","bids":[{"price":65.26155,"qty":0.00000000},{"price":64.87197,"qty":17.82430478},{"price":65.26157,"qty":18.00491230}],"asks":[],"checksum":3593740904,"timestamp":"2024-06-01T17:52:17.502334Z"}]}
{"channel":"book","type":"update","data":[{"symbol":"LTC/GBP","bids":[{"price":65.26156,"qty":0.00000000},{"price":64.87197,"qty":17.82430478},{"price":65.26158,"qty":8.68000000}],"asks":[],"checksum":1433117352,"timestamp":"2024-06-01T17:52:18.458529Z"}]}
{"channel":"book","type":"update","data":[{"symbol":"LTC/GBP","bids":[{"price":65.26157,"qty":0.00000000},{"price":64.87197,"qty":17.82430478},{"price":65.26159,"qty":18.00425010}],"asks":[],"checksum":3019765534,"timestamp":"2024-06-01T17:52:18.462512Z"}]}
{"channel":"book","type":"update","data":[{"symbol":"LTC/GBP","bids":[{"price":65.26158,"qty":0.00000000},{"price":64.87197,"qty":17.82430478},{"price":65.26160,"qty":8.68000000}],"asks":[],"checksum":1657557781,"timestamp":"2024-06-01T17:52:18.793106Z"}]}
{"channel":"book","type":"update","data":[{"symbol":"LTC/GBP","bids":[{"price":65.26159,"qty":0.00000000},{"price":64.87197,"qty":17.82430478},{"price":65.26161,"qty":18.00424430}],"asks":[],"checksum":594048494,"timestamp":"2024-06-01T17:52:18.799427Z"}]}
{"channel":"book","type":"update","data":[{"symbol":"LTC/GBP","bids":[{"price":65.26160,"qty":0.00000000},{"price":64.87197,"qty":17.82430478},{"price":65.26162,"qty":8.68000000}],"asks":[],"checksum":2892295435,"timestamp":"2024-06-01T17:52:19.128128Z"}]}
{"channel":"book","type":"update","data":[{"symbol":"LTC/GBP","bids":[{"price":65.26161,"qty":0.00000000},{"price":64.87197,"qty":17.82430478},{"price":65.26163,"qty":18.00423865}],"asks":[],"checksum":1404807482,"timestamp":"2024-06-01T17:52:19.169868Z"}]}
{"channel":"book","type":"update","data":[{"symbol":"LTC/GBP","bids":[{"price":65.26162,"qty":0.00000000},{"price":64.87197,"qty":17.82430478},{"price":65.26164,"qty":8.68000000}],"asks":[],"checksum":4144498854,"timestamp":"2024-06-01T17:52:19.798868Z"}]}
{"channel":"book","type":"update","data":[{"symbol":"LTC/GBP","bids":[{"price":65.26163,"qty":0.00000000},{"price":64.87197,"qty":17.82430478},{"price":65.26165,"qty":18.00423306}],"asks":[],"checksum":2169178385,"timestamp":"2024-06-01T17:52:19.802238Z"}]}
{"channel":"book","type":"update","data":[{"symbol":"LTC/GBP","bids":[{"price":65.26164,"qty":0.00000000},{"price":64.87197,"qty":17.82430478},{"price":65.26166,"qty":8.68000000}],"asks":[],"checksum":2140858636,"timestamp":"2024-06-01T17:52:20.258234Z"}]}
{"channel":"book","type":"update","data":[{"symbol":"LTC/GBP","bids":[{"price":65.26165,"qty":0.00000000},{"price":64.87197,"qty":17.82430478},{"price":65.26167,"qty":18.00377465}],"asks":[],"checksum":1248380383,"timestamp":"2024-06-01T17:52:20.263768Z"}]}
{"channel":"book","type":"update","data":[{"symbol":"LTC/GBP","bids":[{"price":65.26167,"qty":0.00000000},{"price":64.87197,"qty":17.82430478},{"price":65.26168,"qty":18.00377189}],"asks":[],"checksum":3889370345,"timestamp":"2024-06-01T17:52:20.580350Z"}]}
{"channel":"book","type":"update","data":[{"symbol":"LTC/GBP","bids":[{"price":65.26168,"qty":0.00000000},{"price":64.87197,"qty":17.82430478},{"price":65.26167,"qty":18.00377513}],"asks":[],"checksum":4002758233,"timestamp":"2024-06-01T17:52:20.583597Z"}]}
{"channel":"book","type":"update","data":[{"symbol":"LTC/GBP","bids":[{"price":65.26166,"qty":0.00000000},{"price":64.87197,"qty":17.82430478},{"price":65.26168,"qty":8.68000000}],"asks":[],"checksum":440865409,"timestamp":"2024-06-01T17:52:20.918908Z"}]}
{"channel":"book","type":"update","data":[{"symbol":"LTC/GBP","bids":[{"price":65.26167,"qty":0.00000000},{"price":64.87197,"qty":17.82430478},{"price":65.26169,"qty":18.00376976}],"asks":[],"checksum":4275644366,"timestamp":"2024-06-01T17:52:20.931011Z"}]}
{"channel":"book","type":"update","data":[{"symbol":"LTC/GBP","bids":[{"price":65.26168,"qty":0.00000000},{"price":64.87197,"qty":17.82430478},{"price":65.26170,"qty":8.68000000}],"asks":[],"checksum":3389397865,"timestamp":"2024-06-01T17:52:21.254590Z"}]}
{"channel":"book","type":"update","data":[{"symbol":"LTC/GBP","bids":[{"price":65.26169,"qty":0.00000000},{"price":64.87197,"qty":17.82430478},{"price":65.26171,"qty":18.00376441}],"asks":[],"checksum":843452317,"timestamp":"2024-06-01T17:52:21.348843Z"}]}
{"channel":"book","type":"update","data":[{"symbol":"LTC/GBP","bids":[{"price":65.08662,"qty":55.11221680}],"asks":[],"checksum":2643268163,"timestamp":"2024-06-01T17:52:21.491352Z"}]}
{"channel":"book","type":"update","data":[{"symbol":"LTC/GBP","bids":[{"price":65.08661,"qty":0.00000000},{"price":64.97500,"qty":0.13090947}],"asks":[],"checksum":2714477568,"timestamp":"2024-06-01T17:52:21.499112Z"}]}
{"channel":"book","type":"update","data":[{"symbol":"LTC/GBP","bids":[{"price":65.08663,"qty":6.44723962}],"asks":[],"checksum":1209456616,"timestamp":"2024-06-01T17:52:21.499381Z"}]}
{"channel":"book","type":"update","data":[{"symbol":"LTC/GBP","bids":[{"price":65.26170,"qty":0.00000000},{"price":64.97500,"qty":0.13090947},{"price":65.26172,"qty":8.68000000}],"asks":[],"checksum":18052827,"timestamp":"2024-06-01T17:52:21.500430Z"}]}
{"channel":"book","type":"update","data":[{"symbol":"LTC/GBP","bids":[{"price":65.26171,"qty":0.00000000},{"price":64.97500,"qty":0.13090947},{"price":65.26173,"qty":18.00375894}],"asks":[],"checksum":2916217552,"timestamp":"2024-06-01T17:52:21.723675Z"}]}
{"channel":"book","type":"update","data":[{"symbol":"LTC/GBP","bids":[{"price":65.26172,"qty":0.00000000},{"price":64.97500,"qty":0.13090947},{"price":65.26174,"qty":8.68000000}],"asks":[],"checksum":1121043214,"timestamp":"2024-06-01T17:52:22.050881Z"}]}
{"channel":"book","type":"update","data":[{"symbol":"LTC/GBP","bids":[{"price":65.26173,"qty":0.00000000},{"price":64.97500,"qty":0.13090947},{"price":65.26175,"qty":18.00375349}],"asks":[],"checksum":1814475356,"timestamp":"2024-06-01T17:52:22.132543Z"}]}
{"channel":"book","type":"update","data":[{"symbol":"LTC/GBP","bids":[{"price":65.26174,"qty":0.00000000},{"price":64.97500,"qty":0.13090947},{"price":65.26176,"qty":8.68000000}],"asks":[],"checksum":2162048224,"timestamp":"2024-06-01T17:52:22.784762Z"}]}
{"channel":"book","type":"update","data":[{"symbol":"LTC/GBP","bids":[{"price":65.26175,"qty":0.00000000},{"price":64.97500,"qty":0.13090947},{"price":65.26177,"qty":18.00565314}],"asks":[],"checksum":4279497428,"timestamp":"2024-06-01T17:52:22.787930Z"}]}
{"channel":"book","type":"update","data":[{"symbol":"LTC/GBP","bids":[],"asks":[{"price":65.35458,"qty":0.00000000},{"price":65.85790,"qty":127.06698109}],"checksum":3852689403,"timestamp":"2024-06-01T17:52:22.874884Z"}]}
{"channel":"book","type":"update","data":[{"symbol":"LTC/GBP","bids":[],"asks":[{"price":65.73806,"qty":0.29347284}],"checksum":3705258719,"timestamp":"2024-06-01T17:52:22.877425Z"}]}
{"channel":"book","type":"update","data":[{"symbol":"LTC/GBP","bids":[],"asks":[{"price":65.36248,"qty":8.83137436}],"checksum":2129801583,"timestamp":"2024-06-01T17:52:22.901172Z"}]}
{"channel":"book","type":"update","data":[{"symbol":"LTC/GBP","bids":[{"price":65.26176,"qty":0.00000000},{"price":64.97500,"qty":0.13090947},{"price":65.26178,"qty":8.68000000}],"asks":[],"checksum":3587411233,"timestamp":"2024-06-01T17:52:22.905824Z"}]}
{"channel":"book","type":"update","data":[{"symbol":"LTC/GBP","bids":[{"price":65.26177,"qty":0.00000000},{"price":64.97500,"qty":0.13090947},{"price":65.26179,"qty":18.00564697}],"asks":[],"checksum":1274706697,"timestamp":"2024-06-01T17:52:23.186822Z"}]}
{"channel":"book","type":"update","data":[{"symbol":"LTC/GBP","bids":[{"price":65.26178,"qty":0.00000000},{"price":64.97500,"qty":0.13090947},{"price":65.26180,"qty":8.68000000}],"asks":[],"checksum":3682466598,"timestamp":"2024-06-01T17:52:23.609376Z"}]}
{"channel":"book","type":"update","data":[{"symbol":"LTC/GBP","bids":[],"asks":[{"price":65.31200,"qty":0.00000000},{"price":65.73807,"qty":12.06939088}],"checksum":2636365237,"timestamp":"2024-06-01T17:52:23.612439Z"}]}
{"channel":"book","type":"update","data":[{"symbol":"LTC/GBP","bids":[{"price":65.26709,"qty":1.30000000}],"asks":[],"checksum":735685068,"timestamp":"2024-06-01T17:52:23.615171Z"}]}
{"channel":"book","type":"update","data":[{"symbol":"LTC/GBP","bids":[],"asks":[{"price":65.30415,"qty":35.87195256}],"checksum":169961584,"timestamp":"2024-06-01T17:52:23.615265Z"}]}
{"channel":"book","type":"update","data":[{"symbol":"LTC/GBP","bids":[{"price":65.26709,"qty":0.00000000},{"price":65.00000,"qty":7.69231000}],"asks":[],"checksum":3168500745,"timestamp":"2024-06-01T17:52:23.617890Z"}]}
{"channel":"book","type":"update","data":[{"symbol":"LTC/GBP","bids":[{"price":65.26179,"qty":0.00000000},{"price":64.97500,"qty":0.13090947},{"price":65.26181,"qty":18.00564050}],"asks":[],"checksum":1891769854,"timestamp":"2024-06-01T17:52:23.619671Z"}]}
{"channel":"book","type":"update","data":[{"symbol":"LTC/GBP","bids":[{"price":65.26180,"qty":0.00000000},{"price":64.97500,"qty":0.13090947},{"price":65.26182,"qty":8.68000000}],"asks":[],"checksum":806972728,"timestamp":"2024-06-01T17:52:24.247870Z"}]}
{"channel":"book","type":"update","data":[{"symbol":"LTC/GBP","bids":[{"price":65.26181,"qty":0.00000000},{"price":64.97500,"qty":0.13090947},{"price":65.26183,"qty":18.00563468}],"asks":[],"checksum":2258857201,"timestamp":"2024-06-01T17:52:24.251026Z"}]}
{"channel":"book","type":"update","data":[{"symbol":"LTC/GBP","bids":[{"price":65.26182,"qty":0.00000000},{"price":64.97500,"qty":0.13090947},{"price":65.26184,"qty":8.68000000}],"asks":[],"checksum":74855908,"timestamp":"2024-06-01T17:52:24.583000Z"}]}
{"channel":"book","type":"update","data":[{"symbol":"LTC/GBP","bids":[{"price":65.26183,"qty":0.00000000},{"price":64.97500,"qty":0.13090947},{"price":65.26185,"qty":18.00542044}],"asks":[],"checksum":932407830,"timestamp":"2024-06-01T17:52:24.673830Z"}]}
{"channel":"book","type":"update","data":[{"symbol":"LTC/GBP","bids":[],"asks":[{"price":65.73806,"qty":0.00000000},{"price":65.73807,"qty":12.06939088}],"checksum":3456026974,"timestamp":"2024-06-01T17:52:25.277837Z"}]}
{"channel":"book","type":"update","data":[{"symbol":"LTC/GBP","bids":[{"price":65.26184,"qty":0.00000000},{"price":64.97500,"qty":0.13090947},{"price":65.26186,"qty":8.68000000}],"asks":[],"checksum":1111845311,"timestamp":"2024-06-01T17:52:25.320458Z"}]}
{"channel":"book","type":"update","data":[{"symbol":"LTC/GBP","bids":[{"price":65.26185,"qty":0.00000000},{"price":64.97500,"qty":0.13090947},{"price":65.26187,"qty":18.00541485}],"asks":[],"checksum":2509334316,"timestamp":"2024-06-01T17:52:25.324101Z"}]}
{"channel":"book","type":"update","data":[{"symbol":"LTC/GBP","bids":[{"price":65.26186,"qty":0.00000000},{"price":64.97500,"qty":0.13090947},{"price":65.26188,"qty":8.68000000}],"asks":[],"checksum":2759145629,"timestamp":"2024-06-01T17:52:25.654556Z"}]}
{"channel":"book","type":"update","data":[{"symbol":"LTC/GBP","bids":[{"price":65.26187,"qty":0.00000000},{"price":64.97500,"qty":0.13090947},{"price":65.26189,"qty":18.00540932}],"asks":[],"checksum":1012987516,"timestamp":"2024-06-01T17:52:25.660965Z"}]}
{"channel":"book","type":"update","data":[{"symbol":"LTC/GBP","bids":[{"price":65.26188,"qty":0.00000000},{"price":64.97500,"qty":0.13090947},{"price":65.26190,"qty":8.68000000}],"asks":[],"checksum":3479577404,"timestamp":"2024-06-01T17:52:26.045993Z"}]}
{"channel":"book","type":"update","data":[{"symbol":"LTC/GBP","bids":[{"price":65.26189,"qty":0.00000000},{"price":64.97500,"qty":0.13090947},{"price":65.26191,"qty":18.00540379}],"asks":[],"checksum":4036393349,"timestamp":"2024-06-01T17:52:26.055458Z"}]}
{"channel":"book","type":"update","data":[{"symbol":"LTC/GBP","bids":[{"price":65.26190,"qty":0.00000000},{"price":64.97500,"qty":0.13090947},{"price":65.26192,"qty":8.68000000}],"asks":[],"checksum":1172061299,"timestamp":"2024-06-01T17:52:26.684272Z"}]}
{"channel":"book","type":"update","data":[{"symbol":"LTC/GBP","bids":[{"price":65.26191,"qty":0.00000000},{"price":64.97500,"qty":0.13090947},{"price":65.26193,"qty":18.00580128}],"asks":[],"checksum":3516074153,"timestamp":"2024-06-01T17:52:26.687692Z"}]}
{"channel":"book","type":"update","data":[{"symbol":"LTC/GBP","bids":[{"price":65.26192,"qty":0.00000000},{"price":64.97500,"qty":0.13090947},{"price":65.26194,"qty":8.68000000}],"asks":[],"checksum":293166214,"timestamp":"2024-06-01T17:52:27.020015Z"}]}
{"channel":"book","type":"update","data":[{"symbol":"LTC/GBP","bids":[{"price":65.26193,"qty":0.00000000},{"price":64.97500,"qty":0.13090947},{"price":65.26195,"qty":18.00579579}],"asks":[],"checksum":2738530899,"timestamp":"2024-06-01T17:52:27.047971Z"}]}
{"channel":"book","type":"update","data":[{"symbol":"LTC/GBP","bids":[{"price":65.26194,"qty":0.00000000},{"price":64.97500,"qty":0.13090947},{"price":65.26196,"qty":8.68000000}],"asks":[],"checksum":3717482731,"timestamp":"2024-06-01T17:52:27.690672Z"}]}
{"channel":"book","type":"update","data":[{"symbol":"LTC/GBP","bids":[{"price":65.26195,"qty":0.00000000},{"price":64.97500,"qty":0.13090947},{"price":65.26197,"qty":18.00579032}],"asks":[],"checksum":194869220,"timestamp":"2024-06-01T17:52:27.693986Z"}]}
{"channel":"book","type":"update","data":[{"symbol":"LTC/GBP","bids":[{"price":65.26196,"qty":0.00000000},{"price":64.97500,"qty":0.13090947},{"price":65.26198,"qty":8.68000000}],"asks":[],"checksum":1340375206,"timestamp":"2024-06-01T17:52:28.025427Z"}]}
{"channel":"book","type":"update","data":[{"symbol":"LTC/GBP","bids":[{"price":65.26197,"qty":0.00000000},{"price":64.97500,"qty":0.13090947},{"price":65.26199,"qty":18.00578481}],"asks":[],"checksum":3458035907,"timestamp":"2024-06-01T17:52:28.045523Z"}]}
{"channel":"book","type":"update","data":[{"symbol":"LTC/GBP","bids":[{"price":65.26198,"qty":0.00000000},{"price":64.97500,"qty":0.13090947},{"price":65.26200,"qty":8.68000000}],"asks":[],"checksum":3509189572,"timestamp":"2024-06-01T17:52:28.454286Z"}]}
{"channel":"book","type":"update","data":[{"symbol":"LTC/GBP","bids":[{"price":65.26199,"qty":0.00000000},{"price":64.97500,"qty":0.13090947},{"price":65.26201,"qty":18.00478777}],"asks":[],"checksum":3412124851,"timestamp":"2024-06-01T17:52:28.457489Z"}]}
{"channel":"book","type":"update","data":[{"symbol":"LTC/GBP","bids":[{"price":65.26200,"qty":0.00000000},{"price":64.97500,"qty":0.13090947},{"price":65.26202,"qty":8.68000000}],"asks":[],"checksum":3332867495,"timestamp":"2024-06-01T17:52:29.136786Z"}]}
{"channel":"book","type":"update","data":[{"symbol":"LTC/GBP","bids":[{"price":65.26201,"qty":0.00000000},{"price":64.97500,"qty":0.13090947},{"price":65.26203,"qty":18.00478210}],"asks":[],"checksum":1927271683,"timestamp":"2024-06-01T17:52:29.140000Z"}]}
{"channel":"book","type":"update","data":[{"symbol":"LTC/GBP","bids":[],"asks":[{"price":65.36248,"qty":0.00000000},{"price":65.85790,"qty":127.06698109}],"checksum":1139130889,"timestamp":"2024-06-01T17:52:29.390212Z"}]}
{"channel":"book","type":"update","data":[{"symbol":"LTC/GBP","bids":[],"asks":[{"price":65.47844,"qty":8.83137436}],"checksum":3915598484,"timestamp":"2024-06-01T17:52:29.390291Z"}]}
{"channel":"book","type":"update","data":[{"symbol":"LTC/GBP","bids":[],"asks":[{"price":65.68292,"qty":0.29371921}],"checksum":468319797,"timestamp":"2024-06-01T17:52:29.393976Z"}]}
{"channel":"book","type":"update","data":[{"symbol":"LTC/GBP","bids":[{"price":65.26202,"qty":0.00000000},{"price":64.97500,"qty":0.13090947},{"price":65.26204,"qty":8.68000000}],"asks":[],"checksum":1591173311,"timestamp":"2024-06-01T17:52:29.415827Z"}]}
{"channel":"book","type":"update","data":[{"symbol":"LTC/GBP","bids":[{"price":65.26203,"qty":0.00000000},{"price":64.97500,"qty":0.13090947},{"price":65.26205,"qty":18.00477658}],"asks":[],"checksum":3575375874,"timestamp":"2024-06-01T17:52:29.514481Z"}]}
{"channel":"book","type":"update","data":[{"symbol":"LTC/GBP","bids":[{"price":65.26204,"qty":0.00000000},{"price":64.97500,"qty":0.13090947},{"price":65.26206,"qty":8.68000000}],"asks":[],"checksum":1738006590,"timestamp":"2024-06-01T17:52:30.137790Z"}]}
{"channel":"book","type":"update","data":[{"symbol":"LTC/GBP","bids":[{"price":65.26205,"qty":0.00000000},{"price":64.97500,"qty":0.13090947},{"price":65.26207,"qty":18.00477106}],"asks":[],"checksum":1449918847,"timestamp":"2024-06-01T17:52:30.141143Z"}]}
{"channel":"book","type":"update","data":[{"symbol":"LTC/GBP","bids":[{"price":65.26206,"qty":0.00000000},{"price":64.97500,"qty":0.13090947},{"price":65.26208,"qty":8.68000000}],"asks":[],"checksum":2499289361,"timestamp":"2024-06-01T17:52:30.473182Z"}]}
{"channel":"book","type":"update","data":[{"symbol":"LTC/GBP","bids":[{"price":65.26207,"qty":0.00000000},{"price":64.97500,"qty":0.13090947},{"price":65.26209,"qty":18.00452809}],"asks":[],"checksum":704380573,"timestamp":"2024-06-01T17:52:30.506638Z"}]}
{"channel":"book","type":"update","data":[{"symbol":"LTC/GBP","bids":[{"price":65.26208,"qty":0.00000000},{"price":64.97500,"qty":0.13090947},{"price":65.26210,"qty":8.68000000}],"asks":[],"checksum":744276820,"timestamp":"2024-06-01T17:52:30.840783Z"}]}
{"channel":"book","type":"update","data":[{"symbol":"LTC/GBP","bids":[],"asks":[{"price":65.31199,"qty":0.00000000},{"price":65.73807,"qty":12.06939088}],"checksum":4224633469,"timestamp":"2024-06-01T17:52:30.842675Z"}]}
{"channel":"book","type":"update","data":[{"symbol":"LTC/GBP","bids":[{"price":65.26233,"qty":1.30000000}],"asks":[],"checksum":4149509197,"timestamp":"2024-06-01T17:52:30.872008Z"}]}
{"channel":"book","type":"update","data":[{"symbol":"LTC/GBP","bids":[{"price":65.26209,"qty":0.00000000},{"price":65.00000,"qty":7.69231000},{"price":65.26234,"qty":18.00445816}],"asks":[],"checksum":1426846725,"timestamp":"2024-06-01T17:52:30.906159Z"}]}
{"channel":"book","type":"update","data":[{"symbol":"LTC/GBP","bids":[{"price":65.26233,"qty":0.00000000},{"price":65.00000,"qty":7.69231000}],"asks":[],"checksum":3973346419,"timestamp":"2024-06-01T17:52:30.908774Z"}]}
{"channel":"book","type":"update","data":[{"symbol":"LTC/GBP","bids":[{"price":65.26255,"qty":1.30000000}],"asks":[],"checksum":15105177,"timestamp":"2024-06-01T17:52:30.908991Z"}]}
{"channel":"book","type":"update","data":[{"symbol":"LTC/GBP","bids":[{"price":65.26234,"qty":0.00000000},{"price":65.00000,"qty":7.69231000},{"price":65.26211,"qty":18.00452162}],"asks":[],"checksum":2834265665,"timestamp":"2024-06-01T17:52:30.911827Z"}]}
{"channel":"book","type":"update","data":[{"symbol":"LTC/GBP","bids":[{"price":65.26234,"qty":6.01117861}],"asks":[],"checksum":2466365993,"timestamp":"2024-06-01T17:52:31.165379Z"}]}
{"channel":"book","type":"update","data":[{"symbol":"LTC/GBP","bids":[],"asks":[{"price":65.41774,"qty":6.00000000}],"checksum":1051784015,"timestamp":"2024-06-01T17:52:31.231185Z"}]}
{"channel":"book","type":"update","data":[{"symbol":"LTC/GBP","bids":[{"price":65.26211,"qty":0.00000000},{"price":65.08655,"qty":17.82430478},{"price":65.26256,"qty":18.00439747}],"asks":[],"checksum":3163484856,"timestamp":"2024-06-01T17:52:31.264622Z"}]}
{"channel":"book","type":"update","data":[{"symbol":"LTC/GBP","bids":[],"asks":[{"price":65.36248,"qty":8.83137436}],"checksum":1257512594,"timestamp":"2024-06-01T17:52:31.278884Z"}]}
{"channel":"book","type":"update","data":[{"symbol":"LTC/GBP","bids":[],"asks":[{"price":65.47844,"qty":0.00000000},{"price":65.68292,"qty":0.29371921}],"checksum":3308645195,"timestamp":"2024-06-01T17:52:31.278966Z"}]}
{"channel":"book","type":"update","data":[{"symbol":"LTC/GBP","bids":[{"price":65.26210,"qty":0.00000000},{"price":65.08655,"qty":17.82430478},{"price":65.26256,"qty":26.68439747}],"asks":[],"checksum":3372380393,"timestamp":"2024-06-01T17:52:31.305300Z"}]}
{"channel":"book","type":"update","data":[{"symbol":"LTC/GBP","bids":[{"price":65.26118,"qty":0.00000000},{"price":65.00000,"qty":7.69231000}],"asks":[],"checksum":1990295814,"timestamp":"2024-06-01T17:52:31.330682Z"}]}
{"channel":"book","type":"update","data":[{"symbol":"LTC/GBP","bids":[{"price":65.26256,"qty":8.68000000},{"price":65.26257,"qty":18.00439427}],"asks":[],"checksum":1265960441,"timestamp":"2024-06-01T17:52:31.689195Z"}]}
{"channel":"book","type":"update","data":[{"symbol":"LTC/GBP","bids":[],"asks":[{"price":65.68292,"qty":0.00000000},{"price":65.73807,"qty":12.06939088}],"checksum":2501253172,"timestamp":"2024-06-01T17:52:31.788732Z"}]}
{"channel":"book","type":"update","data":[{"symbol":"LTC/GBP","bids":[],"asks":[{"price":65.68292,"qty":0.29371921}],"checksum":1265960441,"timestamp":"2024-06-01T17:52:31.791150Z"}]}
{"channel":"book","type":"update","data":[{"symbol":"LTC/GBP","bids":[{"price":65.26256,"qty":0.00000000},{"price":65.00000,"qty":7.69231000},{"price":65.26257,"qty":26.68439427}],"asks":[],"checksum":1702416429,"timestamp":"2024-06-01T17:52:32.103977Z"}]}
{"channel":"book","type":"update","data":[{"symbol":"LTC/GBP","bids":[{"price":65.26257,"qty":8.68000000},{"price":65.26258,"qty":18.00439122}],"asks":[],"checksum":2026542269,"timestamp":"2024-06-01T17:52:32.107393Z"}]}
{"channel":"book","type":"update","data":[{"symbol":"LTC/GBP","bids":[{"price":65.26257,"qty":0.00000000},{"price":65.00000,"qty":7.69231000},{"price":65.26259,"qty":8.68000000}],"asks":[],"checksum":2563707228,"timestamp":"2024-06-01T17:52:32.475254Z"}]}
{"channel":"book","type":"update","data":[{"symbol":"LTC/GBP","bids":[{"price":65.26258,"qty":0.00000000},{"price":65.00000,"qty":7.69231000},{"price":65.26260,"qty":18.00524740}],"asks":[],"checksum":875835951,"timestamp":"2024-06-01T17:52:32.521253Z"}]}
{"channel":"book","type":"update","data":[{"symbol":"LTC/GBP","bids":[{"price":65.26259,"qty":0.00000000},{"price":65.00000,"qty":7.69231000},{"price":65.26261,"qty":8.68000000}],"asks":[],"checksum":2677723032,"timestamp":"2024-06-01T17:52:33.266060Z"}]}
{"channel":"book","type":"update","data":[{"symbol":"LTC/GBP","bids":[{"price":65.26260,"qty":0.00000000},{"price":65.00000,"qty":7.69231000},{"price":65.26262,"qty":18.00524429}],"asks":[],"checksum":4178399917,"timestamp":"2024-06-01T17:52:33.269876Z"}]}
{"channel":"book","type":"update","data":[{"symbol":"LTC/GBP","bids":[{"price":65.26261,"qty":0.00000000},{"price":65.00000,"qty":7.69231000},{"price":65.26263,"qty":8.68000000}],"asks":[],"checksum":2197884940,"timestamp":"2024-06-01T17:52:33.602303Z"}]}
{"channel":"book","type":"update","data":[{"symbol":"LTC/GBP","bids":[{"price":65.26262,"qty":0.00000000},{"price":65.00000,"qty":7.69231000},{"price":65.26264,"qty":18.00523890}],"asks":[],"checksum":1342463675,"timestamp":"2024-06-01T17:52:33.673807Z"}]}
{"channel":"book","type":"update","data":[{"symbol":"LTC/GBP","bids":[],"asks":[{"price":65.68292,"qty":0.00000000},{"price":65.73807,"qty":12.06939088}],"checksum":2389132150,"timestamp":"2024-06-01T17:52:34.178517Z"}]}
{"channel":"book","type":"update","data":[{"symbol":"LTC/GBP","bids":[],"asks":[{"price":65.68292,"qty":0.29371921}],"checksum":1342463675,"timestamp":"2024-06-01T17:52:34.180944Z"}]}
{"channel":"book","type":"update","data":[{"symbol":"LTC/GBP","bids":[{"price":65.26263,"qty":0.00000000},{"price":65.00000,"qty":7.69231000},{"price":65.26265,"qty":8.68000000}],"asks":[],"checksum":472212377,"timestamp":"2024-06-01T17:52:34.212767Z"}]}
{"channel":"book","type":"update","data":[{"symbol":"LTC/GBP","bids":[{"price":65.26264,"qty":0.00000000},{"price":65.00000,"qty":7.69231000},{"price":65.26266,"qty":18.00447626}],"asks":[],"checksum":1122252792,"timestamp":"2024-06-01T17:52:34.215789Z"}]}
{"channel":"book","type":"update","data":[{"symbol":"LTC/GBP","bids":[{"price":65.26265,"qty":0.00000000},{"price":65.00000,"qty":7.69231000},{"price":65.26267,"qty":8.68000000}],"asks":[],"checksum":1012217308,"timestamp":"2024-06-01T17:52:34.515097Z"}]}
{"channel":"book","type":"update","data":[{"symbol":"LTC/GBP","bids":[{"price":65.26266,"qty":0.00000000},{"price":65.00000,"qty":7.69231000},{"price":65.26268,"qty":18.00447115}],"asks":[],"checksum":3736323986,"timestamp":"2024-06-01T17:52:34.609760Z"}]}
{"channel":"book","type":"update","data":[{"symbol":"LTC/GBP","bids":[{"price":65.26267,"qty":0.00000000},{"price":65.00000,"qty":7.69231000},{"price":65.26269,"qty":8.68000000}],"asks":[],"checksum":3654053058,"timestamp":"2024-06-01T17:52:35.009095Z"}]}
{"channel":"book","type":"update","data":[{"symbol":"LTC/GBP","bids":[{"price":65.26268,"qty":0.00000000},{"price":65.00000,"qty":7.69231000},{"price":65.26270,"qty":18.00446634}],"asks":[],"checksum":3683504954,"timestamp":"2024-06-01T17:52:35.037655Z"}]}
{"channel":"book","type":"update","data":[{"symbol":"LTC/GBP","bids":[{"price":65.26269,"qty":0.00000000},{"price":65.00000,"qty":7.69231000},{"price":65.26271,"qty":8.68000000}],"asks":[],"checksum":1129488246,"timestamp":"2024-06-01T17:52:36.008766Z"}]}
{"channel":"book","type":"update","data":[{"symbol":"LTC/GBP","bids":[{"price":65.26270,"qty":0.00000000},{"price":65.00000,"qty":7.69231000},{"price":65.26272,"qty":18.00446111}],"asks":[],"checksum":2018826395,"timestamp":"2024-06-01T17:52:36.011952Z"}]}
{"channel":"book","type":"update","data":[{"symbol":"LTC/GBP","bids":[{"price":65.26271,"qty":0.00000000},{"price":65.00000,"qty":7.69231000},{"price":65.26273,"qty":8.68000000}],"asks":[],"checksum":90469955,"timestamp":"2024-06-01T17:52:36.346006Z"}]}
{"channel":"book","type":"update","data":[{"symbol":"LTC/GBP","bids":[{"price":65.26272,"qty":0.00000000},{"price":65.00000,"qty":7.69231000},{"price":65.26274,"qty":18.00355117}],"asks":[],"checksum":3597941144,"timestamp":"2024-06-01T17:52:36.353085Z"}]}
{"channel":"book","type":"update","data":[{"symbol":"LTC/GBP","bids":[],"asks":[{"price":65.68292,"qty":0.00000000},{"price":65.73807,"qty":12.06939088}],"checksum":135734357,"timestamp":"2024-06-01T17:52:36.578585Z"}]}
{"channel":"book","type":"update","data":[{"symbol":"LTC/GBP","bids":[],"asks":[{"price":65.68292,"qty":0.29371921}],"checksum":3597941144,"timestamp":"2024-06-01T17:52:36.581033Z"}]}
{"channel":"book","type":"update","data":[{"symbol":"LTC/GBP","bids":[{"price":65.26273,"qty":0.00000000},{"price":65.00000,"qty":7.69231000},{"price":65.26275,"qty":8.68000000}],"asks":[],"checksum":3091285645,"timestamp":"2024-06-01T17:52:36.893937Z"}]}
{"channel":"book","type":"update","data":[{"symbol":"LTC/GBP","bids":[{"price":65.26274,"qty":0.00000000},{"price":65.00000,"qty":7.69231000},{"price":65.26276,"qty":18.00354514}],"asks":[],"checksum":265370843,"timestamp":"2024-06-01T17:52:36.897119Z"}]}
{"channel":"book","type":"update","data":[{"symbol":"LTC/GBP","bids":[{"price":65.26275,"qty":0.00000000},{"price":65.00000,"qty":7.69231000},{"price":65.26277,"qty":8.68000000}],"asks":[],"checksum":816179064,"timestamp":"2024-06-01T17:52:37.530762Z"}]}
{"channel":"book","type":"update","data":[{"symbol":"LTC/GBP","bids":[{"price":65.26276,"qty":0.00000000},{"price":65.00000,"qty":7.69231000},{"price":65.26278,"qty":18.00353950}],"asks":[],"checksum":970075962,"timestamp":"2024-06-01T17:52:37.533984Z"}]}
{"channel":"book","type":"update","data":[{"symbol":"LTC/GBP","bids":[{"price":65.26277,"qty":0.00000000},{"price":65.00000,"qty":7.69231000},{"price":65.26279,"qty":8.68000000}],"asks":[],"checksum":3830404979,"timestamp":"2024-06-01T17:52:37.865702Z"}]}
{"channel":"book","type":"update","data":[{"symbol":"LTC/GBP","bids":[{"price":65.26278,"qty":0.00000000},{"price":65.00000,"qty":7.69231000},{"price":65.26280,"qty":18.00353396}],"asks":[],"checksum":3689280655,"timestamp":"2024-06-01T17:52:37.900009Z"}]}
{"channel":"book","type":"update","data":[{"symbol":"LTC/GBP","bids":[],"asks":[{"price":65.36248,"qty":0.00000000},{"price":65.73807,"qty":12.06939088}],"checksum":2421963829,"timestamp":"2024-06-01T17:52:37.974939Z"}]}
{"channel":"book","type":"update","data":[{"symbol":"LTC/GBP","bids":[],"asks":[{"price":65.41773,"qty":8.83137436}],"checksum":1746607019,"timestamp":"2024-06-01T17:52:37.975110Z"}]}
{"channel":"book","type":"update","data":[{"symbol":"LTC/GBP","bids":[],"asks":[{"price":65.35457,"qty":0.00000000},{"price":65.73807,"qty":12.06939088},{"price":65.41772,"qty":1.84738230}],"checksum":2918797368,"timestamp":"2024-06-01T17:52:38.215251Z"}]}
{"channel":"book","type":"update","data":[{"symbol":"LTC/GBP","bids":[{"price":65.26279,"qty":0.00000000},{"price":65.00000,"qty":7.69231000},{"price":65.26281,"qty":8.68000000}],"asks":[],"checksum":1174835193,"timestamp":"2024-06-01T17:52:38.539880Z"}]}
{"channel":"book","type":"update","data":[{"symbol":"LTC/GBP","bids":[{"price":65.26280,"qty":0.00000000},{"price":65.00000,"qty":7.69231000},{"price":65.26282,"qty":18.00507711}],"asks":[],"checksum":2803353668,"timestamp":"2024-06-01T17:52:38.543201Z"}]}
{"channel":"book","type":"update","data":[{"symbol":"LTC/GBP","bids":[{"price":65.26281,"qty":0.00000000},{"price":65.00000,"qty":7.69231000},{"price":65.26283,"qty":8.68000000}],"asks":[],"checksum":1256459885,"timestamp":"2024-06-01T17:52:38.872849Z"}]}
{"channel":"book","type":"update","data":[{"symbol":"LTC/GBP","bids":[{"price":65.22565,"qty":0.00000000},{"price":65.00000,"qty":7.69231000}],"asks":[],"checksum":3282306031,"timestamp":"2024-06-01T17:52:38.875680Z"}]}
{"channel":"book","type":"update","data":[{"symbol":"LTC/GBP","bids":[{"price":65.23350,"qty":11.32481065}],"asks":[],"checksum":3673846472,"timestamp":"2024-06-01T17:52:38.878448Z"}]}
{"channel":"book","type":"update","data":[{"symbol":"LTC/GBP","bids":[{"price":65.26282,"qty":0.00000000},{"price":65.00000,"qty":7.69231000},{"price":65.08664,"qty":18.05381362}],"asks":[],"checksum":3827867886,"timestamp":"2024-06-01T17:52:38.878862Z"}]}
{"channel":"book","type":"update","data":[{"symbol":"LTC/GBP","bids":[{"price":65.08664,"qty":0.00000000},{"price":65.00000,"qty":7.69231000},{"price":65.26284,"qty":18.00507099}],"asks":[],"checksum":2204804761,"timestamp":"2024-06-01T17:52:38.898418Z"}]}
{"channel":"book","type":"update","data":[{"symbol":"LTC/GBP","bids":[],"asks":[{"price":65.36249,"qty":0.00000000},{"price":65.73807,"qty":12.06939088}],"checksum":3668095238,"timestamp":"2024-06-01T17:52:38.947576Z"}]}
{"channel":"book","type":"update","data":[{"symbol":"LTC/GBP","bids":[],"asks":[{"price":65.68292,"qty":0.00000000},{"price":65.85866,"qty":126.99042402}],"checksum":360068133,"timestamp":"2024-06-01T17:52:38.978453Z"}]}
{"channel":"book","type":"update","data":[{"symbol":"LTC/GBP","bids":[],"asks":[{"price":65.42149,"qty":0.14261345}],"checksum":1695723927,"timestamp":"2024-06-01T17:52:39.015064Z"}]}
{"channel":"book","type":"update","data":[{"symbol":"LTC/GBP","bids":[],"asks":[{"price":65.68292,"qty":0.29371921}],"checksum":1857350828,"timestamp":"2024-06-01T17:52:39.018302Z"}]}
{"channel":"book","type":"update","data":[{"symbol":"LTC/GBP","bids":[{"price":65.26283,"qty":0.00000000},{"price":65.00000,"qty":7.69231000},{"price":65.26285,"qty":8.68000000}],"asks":[],"checksum":980708388,"timestamp":"2024-06-01T17:52:39.335135Z"}]}
{"channel":"book","type":"update","data":[{"symbol":"LTC/GBP","bids":[{"price":65.26284,"qty":0.00000000},{"price":65.00000,"qty":7.69231000},{"price":65.26286,"qty":18.00506519}],"asks":[],"checksum":1683206322,"timestamp":"2024-06-01T17:52:39.338510Z"}]}
{"channel":"book","type":"update","data":[{"symbol":"LTC/GBP","bids":[{"price":65.26285,"qty":0.00000000},{"price":65.00000,"qty":7.69231000},{"price":65.26287,"qty":8.68000000}],"asks":[],"checksum":561912839,"timestamp":"2024-06-01T17:52:39.670312Z"}]}
{"channel":"book","type":"update","data":[{"symbol":"LTC/GBP","bids":[{"price":65.26286,"qty":0.00000000},{"price":65.00000,"qty":7.69231000},{"price":65.26288,"qty":18.00505954}],"asks":[],"checksum":171992420,"timestamp":"2024-06-01T17:52:39.718590Z"}]}
{"channel":"book","type":"update","data":[{"symbol":"LTC/GBP","bids":[{"price":65.26287,"qty":0.00000000},{"price":65.00000,"qty":7.69231000},{"price":65.26289,"qty":8.68000000}],"asks":[],"checksum":3009452036,"timestamp":"2024-06-01T17:52:40.340813Z"}]}
{"channel":"book","type":"update","data":[{"symbol":"LTC/GBP","bids":[{"price":65.26288,"qty":0.00000000},{"price":65.00000,"qty":7.69231000},{"price":65.26290,"qty":18.00386120}],"asks":[],"checksum":658837855,"timestamp":"2024-06-01T17:52:40.344205Z"}]}
{"channel":"book","type":"update","data":[{"symbol":"LTC/GBP","bids":[{"price":65.26289,"qty":0.00000000},{"price":65.00000,"qty":7.69231000},{"price":65.26291,"qty":8.68000000}],"asks":[],"checksum":553051888,"timestamp":"2024-06-01T17:52:40.677898Z"}]}
{"channel":"book","type":"update","data":[{"symbol":"LTC/GBP","bids":[{"price":65.26290,"qty":0.00000000},{"price":65.00000,"qty":7.69231000},{"price":65.26292,"qty":18.00385535}],"asks":[],"checksum":1554996648,"timestamp":"2024-06-01T17:52:40.714446Z"}]}
{"channel":"book","type":"update","data":[{"symbol":"LTC/GBP","bids":[{"price":65.26291,"qty":0.00000000},{"price":65.00000,"qty":7.69231000},{"price":65.26293,"qty":8.68000000}],"asks":[],"checksum":1390043447,"timestamp":"2024-06-01T17:52:41.043575Z"}]}
{"channel":"book","type":"update","data":[{"symbol":"LTC/GBP","bids":[{"price":65.26292,"qty":0.00000000},{"price":65.00000,"qty":7.69231000},{"price":65.26294,"qty":18.00384975}],"asks":[],"checksum":3007957148,"timestamp":"2024-06-01T17:52:41.118101Z"}]}
{"channel":"book","type":"update","data":[{"symbol":"LTC/GBP","bids":[],"asks":[{"price":65.68292,"qty":0.00000000},{"price":65.73807,"qty":12.06939088}],"checksum":3102709159,"timestamp":"2024-06-01T17:52:41.408661Z"}]}
{"channel":"book","type":"update","data":[{"symbol":"LTC/GBP","bids":[],"asks":[{"price":65.68292,"qty":0.29371921}],"checksum":3007957148,"timestamp":"2024-06-01T17:52:41.411975Z"}]}
{"channel":"book","type":"update","data":[{"symbol":"LTC/GBP","bids":[{"price":65.26293,"qty":0.00000000},{"price":65.00000,"qty":7.69231000},{"price":65.26295,"qty":8.68000000}],"asks":[],"checksum":117607437,"timestamp":"2024-06-01T17:52:41.744313Z"}]}
{"channel":"book","type":"update","data":[{"symbol":"LTC/GBP","bids":[{"price":65.26294,"qty":0.00000000},{"price":65.00000,"qty":7.69231000},{"price":65.26296,"qty":18.00384418}],"asks":[],"checksum":963865157,"timestamp":"2024-06-01T17:52:41.747833Z"}]}
{"channel":"book","type":"update","data":[{"symbol":"LTC/GBP","bids":[{"price":65.26295,"qty":0.00000000},{"price":65.00000,"qty":7.69231000},{"price":65.26297,"qty":8.68000000}],"asks":[],"checksum":4191364251,"timestamp":"2024-06-01T17:52:42.381473Z"}]}
{"channel":"book","type":"update","data":[{"symbol":"LTC/GBP","bids":[{"price":65.26296,"qty":0.00000000},{"price":65.00000,"qty":7.69231000},{"price":65.26298,"qty":18.00462452}],"asks":[],"checksum":1095663602,"timestamp":"2024-06-01T17:52:42.384702Z"}]}
{"channel":"book","type":"update","data":[{"symbol":"LTC/GBP","bids":[{"price":65.26297,"qty":0.00000000},{"price":65.00000,"qty":7.69231000},{"price":65.26299,"qty":8.68000000}],"asks":[],"checksum":3046716226,"timestamp":"2024-06-01T17:52:42.717421Z"}]}
{"channel":"book","type":"update","data":[{"symbol":"LTC/GBP","bids":[{"price":65.26298,"qty":0.00000000},{"price":65.00000,"qty":7.69231000},{"price":65.26300,"qty":18.00461906}],"asks":[],"checksum":3626563575,"timestamp":"2024-06-01T17:52:42.736107Z"}]}
{"channel":"book","type":"update","data":[{"symbol":"LTC/GBP","bids":[{"price":65.26299,"qty":0.00000000},{"price":65.01996,"qty":0.13080672},{"price":65.26301,"qty":8.68000000}],"asks":[],"checksum":3972612023,"timestamp":"2024-06-01T17:52:43.387019Z"}]}
{"channel":"book","type":"update","data":[{"symbol":"LTC/GBP","bids":[{"price":65.26300,"qty":0.00000000},{"price":65.01996,"qty":0.13080672},{"price":65.26302,"qty":18.00461350}],"asks":[],"checksum":4020303065,"timestamp":"2024-06-01T17:52:43.390306Z"}]}
{"channel":"book","type":"update","data":[{"symbol":"LTC/GBP","bids":[],"asks":[{"price":65.68292,"qty":0.00000000},{"price":65.73807,"qty":12.06939088}],"checksum":3825641954,"timestamp":"2024-06-01T17:52:43.808522Z"}]}
{"channel":"book","type":"update","data":[{"symbol":"LTC/GBP","bids":[{"price":65.26301,"qty":0.00000000},{"price":65.01996,"qty":0.13080672},{"price":65.26303,"qty":8.68000000}],"asks":[],"checksum":1852426411,"timestamp":"2024-06-01T17:52:43.844429Z"}]}
{"channel":"book","type":"update","data":[{"symbol":"LTC/GBP","bids":[{"price":65.26302,"qty":0.00000000},{"price":65.01996,"qty":0.13080672},{"price":65.26304,"qty":18.00460797}],"asks":[],"checksum":3033789436,"timestamp":"2024-06-01T17:52:43.847761Z"}]}
{"channel":"book","type":"update","data":[{"symbol":"LTC/GBP","bids":[{"price":65.26303,"qty":0.00000000},{"price":65.01996,"qty":0.13080672},{"price":65.26305,"qty":8.68000000}],"asks":[],"checksum":3254406372,"timestamp":"2024-06-01T17:52:44.482629Z"}]}
{"channel":"book","type":"update","data":[{"symbol":"LTC/GBP","bids":[{"price":65.26304,"qty":0.00000000},{"price":65.01996,"qty":0.13080672},{"price":65.26306,"qty":18.00427058}],"asks":[],"checksum":3445744175,"timestamp":"2024-06-01T17:52:44.485909Z"}]}
{"channel":"book","type":"update","data":[{"symbol":"LTC/GBP","bids":[{"price":65.26305,"qty":0.00000000},{"price":65.01996,"qty":0.13080672},{"price":65.26307,"qty":8.68000000}],"asks":[],"checksum":3732915742,"timestamp":"2024-06-01T17:52:44.819573Z"}]}
{"channel":"book","type":"update","data":[{"symbol":"LTC/GBP","bids":[{"price":65.26306,"qty":0.00000000},{"price":65.01996,"qty":0.13080672},{"price":65.26308,"qty":18.00426499}],"asks":[],"checksum":1135033200,"timestamp":"2024-06-01T17:52:44.822873Z"}]}
{"channel":"book","type":"update","data":[{"symbol":"LTC/GBP","bids":[{"price":65.26307,"qty":0.00000000},{"price":65.01996,"qty":0.13080672},{"price":65.26309,"qty":8.68000000}],"asks":[],"checksum":1600139351,"timestamp":"2024-06-01T17:52:45.154276Z"}]}
{"channel":"book","type":"update","data":[{"symbol":"LTC/GBP","bids":[{"price":65.26308,"qty":0.00000000},{"price":65.01996,"qty":0.13080672},{"price":65.26310,"qty":18.00425940}],"asks":[],"checksum":2629665669,"timestamp":"2024-06-01T17:52:45.188620Z"}]}
{"channel":"book","type":"update","data":[{"symbol":"LTC/GBP","bids":[{"price":65.26309,"qty":0.00000000},{"price":65.01996,"qty":0.13080672},{"price":65.26311,"qty":8.68000000}],"asks":[],"checksum":2251881631,"timestamp":"2024-06-01T17:52:45.822889Z"}]}
{"channel":"book","type":"update","data":[{"symbol":"LTC/GBP","bids":[{"price":65.26310,"qty":0.00000000},{"price":65.01996,"qty":0.13080672},{"price":65.26312,"qty":18.00425384}],"asks":[],"checksum":1684899610,"timestamp":"2024-06-01T17:52:45.826301Z"}]}
{"channel":"book","type":"update","data":[{"symbol":"LTC/GBP","bids":[{"price":65.26311,"qty":0.00000000},{"price":65.01996,"qty":0.13080672},{"price":65.26313,"qty":8.68000000}],"asks":[],"checksum":107839350,"timestamp":"2024-06-01T17:52:46.461819Z"}]}
{"channel":"book","type":"update","data":[{"symbol":"LTC/GBP","bids":[{"price":65.26312,"qty":0.00000000},{"price":65.01996,"qty":0.13080672},{"price":65.26314,"qty":18.00411496}],"asks":[],"checksum":3785322407,"timestamp":"2024-06-01T17:52:46.465077Z"}]}
{"channel":"book","type":"update","data":[{"symbol":"LTC/GBP","bids":[{"price":65.26313,"qty":0.00000000},{"price":65.01996,"qty":0.13080672},{"price":65.26315,"qty":8.68000000}],"asks":[],"checksum":2017211639,"timestamp":"2024-06-01T17:52:47.099751Z"}]}
{"channel":"book","type":"update","data":[{"symbol":"LTC/GBP","bids":[{"price":65.26314,"qty":0.00000000},{"price":65.01996,"qty":0.13080672},{"price":65.26316,"qty":18.00410899}],"asks":[],"checksum":3041616322,"timestamp":"2024-06-01T17:52:47.103401Z"}]}
{"channel":"book","type":"update","data":[{"symbol":"LTC/GBP","bids":[{"price":65.26315,"qty":0.00000000},{"price":65.01996,"qty":0.13080672},{"price":65.26317,"qty":8.68000000}],"asks":[],"checksum":1051068085,"timestamp":"2024-06-01T17:52:47.435460Z"}]}
{"channel":"book","type":"update","data":[{"symbol":"LTC/GBP","bids":[{"price":65.26316,"qty":0.00000000},{"price":65.01996,"qty":0.13080672},{"price":65.26318,"qty":18.00410336}],"asks":[],"checksum":2191829966,"timestamp":"2024-06-01T17:52:47.449317Z"}]}
{"channel":"book","type":"update","data":[{"symbol":"LTC/GBP","bids":[{"price":65.26317,"qty":0.00000000},{"price":65.01996,"qty":0.13080672},{"price":65.26319,"qty":8.68000000}],"asks":[],"checksum":3094462760,"timestamp":"2024-06-01T17:52:48.072757Z"}]}
{"channel":"book","type":"update","data":[{"symbol":"LTC/GBP","bids":[{"price":65.26318,"qty":0.00000000},{"price":65.01996,"qty":0.13080672},{"price":65.26320,"qty":18.00409778}],"asks":[],"checksum":815112748,"timestamp":"2024-06-01T17:52:48.076169Z"}]}
{"channel":"book","type":"update","data":[{"symbol":"LTC/GBP","bids":[{"price":65.26319,"qty":0.00000000},{"price":65.01996,"qty":0.13080672},{"price":65.26321,"qty":8.68000000}],"asks":[],"checksum":243164334,"timestamp":"2024-06-01T17:52:48.408151Z"}]}
{"channel":"book","type":"update","data":[{"symbol":"LTC/GBP","bids":[{"price":65.26320,"qty":0.00000000},{"price":65.01996,"qty":0.13080672},{"price":65.26322,"qty":18.00530695}],"asks":[],"checksum":1778422684,"timestamp":"2024-06-01T17:52:48.412457Z"}]}
{"channel":"book","type":"update","data":[{"symbol":"LTC/GBP","bids":[{"price":65.26321,"qty":0.00000000},{"price":65.01996,"qty":0.13080672},{"price":65.26323,"qty":8.68000000}],"asks":[],"checksum":884291504,"timestamp":"2024-06-01T17:52:48.743111Z"}]}
{"channel":"book","type":"update","data":[{"symbol":"LTC/GBP","bids":[{"price":65.26322,"qty":0.00000000},{"price":65.01996,"qty":0.13080672},{"price":65.26324,"qty":18.00530133}],"asks":[],"checksum":719299799,"timestamp":"2024-06-01T17:52:48.782549Z"}]}
{"channel":"book","type":"update","data":[{"symbol":"LTC/GBP","bids":[{"price":65.26323,"qty":0.00000000},{"price":65.01996,"qty":0.13080672},{"price":65.26325,"qty":8.68000000}],"asks":[],"checksum":2341883766,"timestamp":"2024-06-01T17:52:49.295445Z"}]}
{"channel":"book","type":"update","data":[{"symbol":"LTC/GBP","bids":[{"price":65.26324,"qty":0.00000000},{"price":65.01996,"qty":0.13080672},{"price":65.26326,"qty":18.00529566}],"asks":[],"checksum":3517789184,"timestamp":"2024-06-01T17:52:49.298514Z"}]}
{"channel":"book","type":"update","data":[{"symbol":"LTC/GBP","bids":[{"price":65.26325,"qty":0.00000000},{"price":65.01996,"qty":0.13080672},{"price":65.26327,"qty":8.68000000}],"asks":[],"checksum":1313823114,"timestamp":"2024-06-01T17:52:50.059501Z"}]}
{"channel":"book","type":"update","data":[{"symbol":"LTC/GBP","bids":[{"price":65.26326,"qty":0.00000000},{"price":65.01996,"qty":0.13080672},{"price":65.26328,"qty":18.00529009}],"asks":[],"checksum":1982536848,"timestamp":"2024-06-01T17:52:50.065038Z"}]}
{"channel":"book","type":"update","data":[{"symbol":"LTC/GBP","bids":[{"price":65.26327,"qty":0.00000000},{"price":65.01996,"qty":0.13080672},{"price":65.26329,"qty":8.68000000}],"asks":[],"checksum":2639035292,"timestamp":"2024-06-01T17:52:50.693350Z"}]}
{"channel":"book","type":"update","data":[{"symbol":"LTC/GBP","bids":[{"price":65.26328,"qty":0.00000000},{"price":65.01996,"qty":0.13080672},{"price":65.26330,"qty":18.00517302}],"asks":[],"checksum":559079535,"timestamp":"2024-06-01T17:52:50.696399Z"}]}
{"channel":"book","type":"update","data":[{"symbol":"LTC/GBP","bids":[{"price":65.26329,"qty":0.00000000},{"price":65.01996,"qty":0.13080672},{"price":65.26331,"qty":8.68000000}],"asks":[],"checksum":3921984231,"timestamp":"2024-06-01T17:52:51.027969Z"}]}
{"channel":"book","type":"update","data":[{"symbol":"LTC/GBP","bids":[{"price":65.26330,"qty":0.00000000},{"price":65.01996,"qty":0.13080672},{"price":65.26332,"qty":18.00516784}],"asks":[],"checksum":2965548711,"timestamp":"2024-06-01T17:52:51.033267Z"}]}
{"channel":"book","type":"update","data":[{"symbol":"LTC/GBP","bids":[{"price":65.26331,"qty":0.00000000},{"price":65.01996,"qty":0.13080672},{"price":65.26333,"qty":8.68000000}],"asks":[],"checksum":3706857459,"timestamp":"2024-06-01T17:52:51.666487Z"}]}
{"channel":"book","type":"update","data":[{"symbol":"LTC/GBP","bids":[{"price":65.26332,"qty":0.00000000},{"price":65.01996,"qty":0.13080672},{"price":65.26334,"qty":18.00516252}],"asks":[],"checksum":3671371025,"timestamp":"2024-06-01T17:52:51.669781Z"}]}
{"channel":"book","type":"update","data":[{"symbol":"LTC/GBP","bids":[{"price":65.26333,"qty":0.00000000},{"price":65.01996,"qty":0.13080672},{"price":65.26335,"qty":8.68000000}],"asks":[],"checksum":502463490,"timestamp":"2024-06-01T17:52:51.791148Z"}]}
{"channel":"book","type":"update","data":[{"symbol":"LTC/GBP","bids":[{"price":65.26334,"qty":24.01634113}],"asks":[],"checksum":194498754,"timestamp":"2024-06-01T17:52:51.840251Z"}]}
{"channel":"book","type":"update","data":[{"symbol":"LTC/GBP","bids":[{"price":65.26334,"qty":6.01117861},{"price":65.26336,"qty":18.00515704}],"asks":[],"checksum":195316833,"timestamp":"2024-06-01T17:52:51.934385Z"}]}
{"channel":"book","type":"update","data":[{"symbol":"LTC/GBP","bids":[{"price":65.26234,"qty":0.00000000},{"price":65.08655,"qty":17.82430478}],"asks":[],"checksum":243434916,"timestamp":"2024-06-01T17:52:52.006510Z"}]}
{"channel":"book","type":"update","data":[{"symbol":"LTC/GBP","bids":[{"price":65.26255,"qty":0.00000000},{"price":65.01996,"qty":0.13080672}],"asks":[],"checksum":3047575980,"timestamp":"2024-06-01T17:52:52.009420Z"}]}
{"channel":"book","type":"update","data":[{"symbol":"LTC/GBP","bids":[{"price":65.26335,"qty":0.00000000},{"price":65.00000,"qty":7.69231000},{"price":65.26337,"qty":8.68000000}],"asks":[],"checksum":2497579744,"timestamp":"2024-06-01T17:52:52.341489Z"}]}
{"channel":"book","type":"update","data":[{"symbol":"LTC/GBP","bids":[{"price":65.26336,"qty":0.00000000},{"price":65.00000,"qty":7.69231000},{"price":65.26338,"qty":18.00417324}],"asks":[],"checksum":3317403981,"timestamp":"2024-06-01T17:52:52.344760Z"}]}
{"channel":"book","type":"update","data":[{"symbol":"LTC/GBP","bids":[{"price":65.26337,"qty":0.00000000},{"price":65.00000,"qty":7.69231000},{"price":65.26339,"qty":8.68000000}],"asks":[],"checksum":876273305,"timestamp":"2024-06-01T17:52:52.979397Z"}]}
{"channel":"book","type":"update","data":[{"symbol":"LTC/GBP","bids":[{"price":65.26338,"qty":0.00000000},{"price":65.00000,"qty":7.69231000},{"price":65.26340,"qty":18.00416799}],"asks":[],"checksum":2076513366,"timestamp":"2024-06-01T17:52:52.982683Z"}]}
{"channel":"book","type":"update","data":[{"symbol":"LTC/GBP","bids":[{"price":65.26339,"qty":0.00000000},{"price":65.00000,"qty":7.69231000},{"price":65.26341,"qty":8.68000000}],"asks":[],"checksum":3616115237,"timestamp":"2024-06-01T17:52:53.620174Z"}]}
{"channel":"book","type":"update","data":[{"symbol":"LTC/GBP","bids":[{"price":65.26340,"qty":0.00000000},{"price":65.00000,"qty":7.69231000},{"price":65.26342,"qty":18.00416259}],"asks":[],"checksum":3007524768,"timestamp":"2024-06-01T17:52:53.623528Z"}]}
{"channel":"book","type":"update","data":[{"symbol":"LTC/GBP","bids":[{"price":65.26341,"qty":0.00000000},{"price":65.00000,"qty":7.69231000},{"price":65.26343,"qty":8.68000000}],"asks":[],"checksum":145410919,"timestamp":"2024-06-01T17:52:54.256341Z"}]}
{"channel":"book","type":"update","data":[{"symbol":"LTC/GBP","bids":[{"price":65.26342,"qty":0.00000000},{"price":65.00000,"qty":7.69231000},{"price":65.26344,"qty":18.00415712}],"asks":[],"checksum":4133516052,"timestamp":"2024-06-01T17:52:54.260682Z"}]}
{"channel":"book","type":"update","data":[{"symbol":"LTC/GBP","bids":[{"price":65.26343,"qty":0.00000000},{"price":65.00000,"qty":7.69231000},{"price":65.26345,"qty":8.68000000}],"asks":[],"checksum":256248120,"timestamp":"2024-06-01T17:52:54.591655Z"}]}
{"channel":"book","type":"update","data":[{"symbol":"LTC/GBP","bids":[{"price":65.26344,"qty":0.00000000},{"price":65.00000,"qty":7.69231000},{"price":65.26346,"qty":18.00457195}],"asks":[],"checksum":4104238322,"timestamp":"2024-06-01T17:52:54.594958Z"}]}
{"channel":"book","type":"update","data":[{"symbol":"LTC/GBP","bids":[{"price":65.26345,"qty":0.00000000},{"price":65.00000,"qty":7.69231000},{"price":65.26347,"qty":8.68000000}],"asks":[],"checksum":1713185218,"timestamp":"2024-06-01T17:52:55.229938Z"}]}
{"channel":"book","type":"update","data":[{"symbol":"LTC/GBP","bids":[{"price":65.26346,"qty":0.00000000},{"price":65.00000,"qty":7.69231000},{"price":65.26348,"qty":18.00456573}],"asks":[],"checksum":799641290,"timestamp":"2024-06-01T17:52:55.233241Z"}]}
{"channel":"book","type":"update","data":[{"symbol":"LTC/GBP","bids":[{"price":65.26347,"qty":0.00000000},{"price":65.00000,"qty":7.69231000},{"price":65.26349,"qty":8.68000000}],"asks":[],"checksum":3405329370,"timestamp":"2024-06-01T17:52:55.355349Z"}]}
{"channel":"book","type":"update","data":[{"symbol":"LTC/GBP","bids":[{"price":65.26348,"qty":0.00000000},{"price":65.00000,"qty":7.69231000},{"price":65.26350,"qty":18.00456011}],"asks":[],"checksum":1166434896,"timestamp":"2024-06-01T17:52:55.502264Z"}]}
{"channel":"book","type":"update","data":[{"symbol":"LTC/GBP","bids":[{"price":65.26349,"qty":0.00000000},{"price":65.00000,"qty":7.69231000},{"price":65.26351,"qty":8.68000000}],"asks":[],"checksum":2750816481,"timestamp":"2024-06-01T17:52:55.843124Z"}]}
{"channel":"book","type":"update","data":[{"symbol":"LTC/GBP","bids":[{"price":65.26350,"qty":0.00000000},{"price":65.00000,"qty":7.69231000},{"price":65.26352,"qty":18.00455447}],"asks":[],"checksum":2863499704,"timestamp":"2024-06-01T17:52:55.846232Z"}]}
{"channel":"book","type":"update","data":[{"symbol":"LTC/GBP","bids":[{"price":65.26351,"qty":0.00000000},{"price":65.00000,"qty":7.69231000},{"price":65.26353,"qty":8.68000000}],"asks":[],"checksum":31420087,"timestamp":"2024-06-01T17:52:56.480951Z"}]}
{"channel":"book","type":"update","data":[{"symbol":"LTC/GBP","bids":[{"price":65.26352,"qty":0.00000000},{"price":65.00000,"qty":7.69231000},{"price":65.26354,"qty":18.00378236}],"asks":[],"checksum":3752212742,"timestamp":"2024-06-01T17:52:56.485985Z"}]}
{"channel":"book","type":"update","data":[{"symbol":"LTC/GBP","bids":[{"price":65.26353,"qty":0.00000000},{"price":65.00000,"qty":7.69231000},{"price":65.26355,"qty":8.68000000}],"asks":[],"checksum":2156525430,"timestamp":"2024-06-01T17:52:56.815986Z"}]}
{"channel":"book","type":"update","data":[{"symbol":"LTC/GBP","bids":[{"price":65.26354,"qty":0.00000000},{"price":65.00000,"qty":7.69231000},{"price":65.26356,"qty":18.00377688}],"asks":[],"checksum":1697689006,"timestamp":"2024-06-01T17:52:56.819380Z"}]}
{"channel":"book","type":"update","data":[{"symbol":"LTC/GBP","bids":[{"price":65.26355,"qty":0.00000000},{"price":65.00000,"qty":7.69231000},{"price":65.26357,"qty":8.68000000}],"asks":[],"checksum":3917090455,"timestamp":"2024-06-01T17:52:57.151104Z"}]}
{"channel":"book","type":"update","data":[{"symbol":"LTC/GBP","bids":[{"price":65.26356,"qty":0.00000000},{"price":65.00000,"qty":7.69231000},{"price":65.26358,"qty":18.00377140}],"asks":[],"checksum":639678657,"timestamp":"2024-06-01T17:52:57.154865Z"}]}
{"channel":"book","type":"update","data":[{"symbol":"LTC/GBP","bids":[{"price":65.26357,"qty":0.00000000},{"price":65.00000,"qty":7.69231000},{"price":65.26359,"qty":8.68000000}],"asks":[],"checksum":1475691266,"timestamp":"2024-06-01T17:52:57.791050Z"}]}
{"channel":"book","type":"update","data":[{"symbol":"LTC/GBP","bids":[{"price":65.26358,"qty":0.00000000},{"price":65.00000,"qty":7.69231000},{"price":65.26360,"qty":18.00376591}],"asks":[],"checksum":2219187462,"timestamp":"2024-06-01T17:52:57.794367Z"}]}
{"channel":"book","type":"update","data":[{"symbol":"LTC/GBP","bids":[{"price":65.26359,"qty":0.00000000},{"price":65.00000,"qty":7.69231000},{"price":65.26361,"qty":8.68000000}],"asks":[],"checksum":27605547,"timestamp":"2024-06-01T17:52:58.430932Z"}]}
{"channel":"book","type":"update","data":[{"symbol":"LTC/GBP","bids":[{"price":65.26360,"qty":0.00000000},{"price":65.00000,"qty":7.69231000},{"price":65.26362,"qty":18.00464111}],"asks":[],"checksum":2171647848,"timestamp":"2024-06-01T17:52:58.435036Z"}]}
{"channel":"book","type":"update","data":[{"symbol":"LTC/GBP","bids":[{"price":65.26361,"qty":0.00000000},{"price":65.00000,"qty":7.69231000},{"price":65.26363,"qty":8.68000000}],"asks":[],"checksum":2316662491,"timestamp":"2024-06-01T17:52:59.068484Z"}]}
{"channel":"book","type":"update","data":[{"symbol":"LTC/GBP","bids":[{"price":65.26362,"qty":0.00000000},{"price":65.00000,"qty":7.69231000},{"price":65.26364,"qty":18.00463645}],"asks":[],"checksum":2093200208,"timestamp":"2024-06-01T17:52:59.071703Z"}]}
{"channel":"book","type":"update","data":[{"symbol":"LTC/GBP","bids":[{"price":65.26363,"qty":0.00000000},{"price":65.00000,"qty":7.69231000},{"price":65.26365,"qty":8.68000000}],"asks":[],"checksum":3282605668,"timestamp":"2024-06-01T17:52:59.707013Z"}]}
{"channel":"book","type":"update","data":[{"symbol":"LTC/GBP","bids":[{"price":65.26364,"qty":0.00000000},{"price":65.00000,"qty":7.69231000},{"price":65.26366,"qty":18.00463120}],"asks":[],"checksum":2568058546,"timestamp":"2024-06-01T17:52:59.710445Z"}]}
{"channel":"book","type":"update","data":[{"symbol":"LTC/GBP","bids":[{"price":65.26365,"qty":0.00000000},{"price":65.00000,"qty":7.69231000},{"price":65.26367,"qty":8.68000000}],"asks":[],"checksum":2988127434,"timestamp":"2024-06-01T17:53:00.043399Z"}]}
{"channel":"book","type":"update","data":[{"symbol":"LTC/GBP","bids":[{"price":65.26366,"qty":0.00000000},{"price":65.00000,"qty":7.69231000},{"price":65.26368,"qty":18.00462571}],"asks":[],"checksum":3011812583,"timestamp":"2024-06-01T17:53:00.046712Z"}]}
{"channel":"book","type":"update","data":[{"symbol":"LTC/GBP","bids":[{"price":65.26367,"qty":0.00000000},{"price":65.00000,"qty":7.69231000},{"price":65.26369,"qty":8.68000000}],"asks":[],"checksum":861345292,"timestamp":"2024-06-01T17:53:00.680787Z"}]}
{"channel":"book","type":"update","data":[{"symbol":"LTC/GBP","bids":[{"price":65.26368,"qty":0.00000000},{"price":65.00000,"qty":7.69231000},{"price":65.26370,"qty":18.00450362}],"asks":[],"checksum":2460263529,"timestamp":"2024-06-01T17:53:00.684211Z"}]}
{"channel":"book","type":"update","data":[{"symbol":"LTC/GBP","bids":[{"price":65.26369,"qty":0.00000000},{"price":65.00000,"qty":7.69231000},{"price":65.26371,"qty":8.68000000}],"asks":[],"checksum":1610571117,"timestamp":"2024-06-01T17:53:01.320222Z"}]}
{"channel":"book","type":"update","data":[{"symbol":"LTC/GBP","bids":[{"price":65.26370,"qty":0.00000000},{"price":65.00000,"qty":7.69231000},{"price":65.26372,"qty":18.00449818}],"asks":[],"checksum":4011128325,"timestamp":"2024-06-01T17:53:01.323345Z"}]}
{"channel":"book","type":"update","data":[{"symbol":"LTC/GBP","bids":[{"price":65.26371,"qty":0.00000000},{"price":65.00000,"qty":7.69231000},{"price":65.26373,"qty":8.68000000}],"asks":[],"checksum":792029769,"timestamp":"2024-06-01T17:53:01.958286Z"}]}
{"channel":"book","type":"update","data":[{"symbol":"LTC/GBP","bids":[{"price":65.26372,"qty":0.00000000},{"price":65.00000,"qty":7.69231000},{"price":65.26374,"qty":18.00449270}],"asks":[],"checksum":2233107840,"timestamp":"2024-06-01T17:53:01.961357Z"}]}
{"channel":"book","type":"update","data":[{"symbol":"LTC/GBP","bids":[{"price":65.26373,"qty":0.00000000},{"price":65.00000,"qty":7.69231000},{"price":65.26375,"qty":8.68000000}],"asks":[],"checksum":526140022,"timestamp":"2024-06-01T17:53:02.596765Z"}]}
{"channel":"book","type":"update","data":[{"symbol":"LTC/GBP","bids":[{"price":65.26374,"qty":0.00000000},{"price":65.00000,"qty":7.69231000},{"price":65.26376,"qty":18.00458698}],"asks":[],"checksum":12159063,"timestamp":"2024-06-01T17:53:02.600048Z"}]}
{"channel":"book","type":"update","data":[{"symbol":"LTC/GBP","bids":[{"price":65.26375,"qty":0.00000000},{"price":65.00000,"qty":7.69231000},{"price":65.26377,"qty":8.68000000}],"asks":[],"checksum":2290405952,"timestamp":"2024-06-01T17:53:02.930417Z"}]}
{"channel":"book","type":"update","data":[{"symbol":"LTC/GBP","bids":[{"price":65.26376,"qty":0.00000000},{"price":65.00000,"qty":7.69231000},{"price":65.26378,"qty":18.00458095}],"asks":[],"checksum":1420158241,"timestamp":"2024-06-01T17:53:02.933825Z"}]}
{"channel":"book","type":"update","data":[{"symbol":"LTC/GBP","bids":[{"price":65.26377,"qty":0.00000000},{"price":65.00000,"qty":7.69231000},{"price":65.26379,"qty":8.68000000}],"asks":[],"checksum":1793849658,"timestamp":"2024-06-01T17:53:03.573977Z"}]}
{"channel":"book","type":"update","data":[{"symbol":"LTC/GBP","bids":[{"price":65.26378,"qty":0.00000000},{"price":65.00000,"qty":7.69231000},{"price":65.26380,"qty":18.00457512}],"asks":[],"checksum":2128503002,"timestamp":"2024-06-01T17:53:03.577431Z"}]}
{"channel":"book","type":"update","data":[{"symbol":"LTC/GBP","bids":[{"price":65.26379,"qty":0.00000000},{"price":65.00000,"qty":7.69231000},{"price":65.26381,"qty":8.68000000}],"asks":[],"checksum":1094706280,"timestamp":"2024-06-01T17:53:03.905097Z"}]}
{"channel":"book","type":"update","data":[{"symbol":"LTC/GBP","bids":[{"price":65.26380,"qty":0.00000000},{"price":65.00000,"qty":7.69231000},{"price":65.26382,"qty":18.00456953}],"asks":[],"checksum":2171058897,"timestamp":"2024-06-01T17:53:03.908124Z"}]}
{"channel":"book","type":"update","data":[{"symbol":"LTC/GBP","bids":[{"price":65.26381,"qty":0.00000000},{"price":65.00000,"qty":7.69231000},{"price":65.26383,"qty":8.68000000}],"asks":[],"checksum":2830824031,"timestamp":"2024-06-01T17:53:04.364954Z"}]}
{"channel":"book","type":"update","data":[{"symbol":"LTC/GBP","bids":[{"price":65.26382,"qty":0.00000000},{"price":65.00000,"qty":7.69231000},{"price":65.26384,"qty":18.00426791}],"asks":[],"checksum":2019474653,"timestamp":"2024-06-01T17:53:04.368279Z"}]}
{"channel":"book","type":"update","data":[{"symbol":"LTC/GBP","bids":[{"price":65.26383,"qty":0.00000000},{"price":65.00000,"qty":7.69231000},{"price":65.26385,"qty":8.68000000}],"asks":[],"checksum":2376931695,"timestamp":"2024-06-01T17:53:05.003559Z"}]}
{"channel":"book","type":"update","data":[{"symbol":"LTC/GBP","bids":[{"price":65.26384,"qty":0.00000000},{"price":65.00000,"qty":7.69231000},{"price":65.26386,"qty":18.00426244}],"asks":[],"checksum":198880447,"timestamp":"2024-06-01T17:53:05.006944Z"}]}
{"channel":"book","type":"update","data":[{"symbol":"LTC/GBP","bids":[{"price":65.26385,"qty":0.00000000},{"price":65.00000,"qty":7.69231000},{"price":65.26387,"qty":8.68000000}],"asks":[],"checksum":502006735,"timestamp":"2024-06-01T17:53:05.336781Z"}]}
{"channel":"book","type":"update","data":[{"symbol":"LTC/GBP","bids":[{"price":65.26386,"qty":0.00000000},{"price":65.00000,"qty":7.69231000},{"price":65.26388,"qty":18.00425694}],"asks":[],"checksum":2377063737,"timestamp":"2024-06-01T17:53:05.340419Z"}]}
{"channel":"book","type":"update","data":[{"symbol":"LTC/GBP","bids":[{"price":65.26387,"qty":0.00000000},{"price":65.00000,"qty":7.69231000},{"price":65.26389,"qty":8.68000000}],"asks":[],"checksum":2363077865,"timestamp":"2024-06-01T17:53:05.973302Z"}]}
{"channel":"book","type":"update","data":[{"symbol":"LTC/GBP","bids":[{"price":65.26388,"qty":0.00000000},{"price":65.00000,"qty":7.69231000},{"price":65.26390,"qty":18.00425144}],"asks":[],"checksum":10558958,"timestamp":"2024-06-01T17:53:05.976453Z"}]}
{"channel":"book","type":"update","data":[{"symbol":"LTC/GBP","bids":[{"price":65.26389,"qty":0.00000000},{"price":65.00000,"qty":7.69231000},{"price":65.26391,"qty":8.68000000}],"asks":[],"checksum":3253558466,"timestamp":"2024-06-01T17:53:06.308538Z"}]}
{"channel":"book","type":"update","data":[{"symbol":"LTC/GBP","bids":[{"price":65.26390,"qty":0.00000000},{"price":65.00000,"qty":7.69231000},{"price":65.26392,"qty":18.00466389}],"asks":[],"checksum":1857030091,"timestamp":"2024-06-01T17:53:06.311847Z"}]}
{"channel":"book","type":"update","data":[{"symbol":"LTC/GBP","bids":[{"price":65.26391,"qty":0.00000000},{"price":65.00000,"qty":7.69231000},{"price":65.26393,"qty":8.68000000}],"asks":[],"checksum":1869085363,"timestamp":"2024-06-01T17:53:06.687333Z"}]}
{"channel":"book","type":"update","data":[{"symbol":"LTC/GBP","bids":[{"price":65.26392,"qty":0.00000000},{"price":65.00000,"qty":7.69231000},{"price":65.26394,"qty":18.00465902}],"asks":[],"checksum":3989110350,"timestamp":"2024-06-01T17:53:06.690866Z"}]}
{"channel":"book","type":"update","data":[{"symbol":"LTC/GBP","bids":[{"price":65.26393,"qty":0.00000000},{"price":65.00000,"qty":7.69231000},{"price":65.26395,"qty":8.68000000}],"asks":[],"checksum":2760042821,"timestamp":"2024-06-01T17:53:07.341806Z"}]}
{"channel":"book","type":"update","data":[{"symbol":"LTC/GBP","bids":[{"price":65.26394,"qty":0.00000000},{"price":65.00000,"qty":7.69231000},{"price":65.26396,"qty":18.00465387}],"asks":[],"checksum":179570645,"timestamp":"2024-06-01T17:53:07.344845Z"}]}
