{"channel":"book","type":"snapshot","data":[{"symbol":"LTC/AUD","bids":[{"price":125.04,"qty":1.28221908},{"price":125.03,"qty":29.11092099},{"price":125.01,"qty":18.00000000},{"price":124.92,"qty":34.09251601},{"price":124.91,"qty":2.04654681},{"price":124.82,"qty":6.77631339},{"price":124.80,"qty":27.07369434},{"price":124.69,"qty":0.68263965},{"price":124.65,"qty":0.15268110},{"price":124.41,"qty":20.53819152}],"asks":[{"price":125.26,"qty":55.01395256},{"price":125.31,"qty":0.13330985},{"price":125.38,"qty":8.83137436},{"price":125.39,"qty":2.04654681},{"price":125.49,"qty":6.77631339},{"price":125.61,"qty":27.07369434},{"price":125.62,"qty":18.00000000},{"price":125.74,"qty":20.53819152},{"price":125.75,"qty":0.68263965},{"price":125.92,"qty":0.29377649}],"checksum":1325615209}]}
{"channel":"book","type":"update","data":[{"symbol":"LTC/AUD","bids":[{"price":125.03,"qty":0.00000000},{"price":124.38,"qty":46.29839281}],"asks":[],"checksum":3283325211,"timestamp":"2024-06-01T17:52:05.079626Z"}]}
{"channel":"book","type":"update","data":[{"symbol":"LTC/AUD","bids":[],"asks":[{"price":125.26,"qty":0.00000000},{"price":126.07,"qty":199.92693932}],"checksum":530606207,"timestamp":"2024-06-01T17:52:05.081875Z"}]}
{"channel":"book","type":"update","data":[{"symbol":"LTC/AUD","bids":[],"asks":[{"price":125.92,"qty":0.00000000},{"price":126.50,"qty":13.31456049}],"checksum":3159281879,"timestamp":"2024-06-01T17:52:05.083547Z"}]}
{"channel":"book","type":"update","data":[{"symbol":"LTC/AUD","bids":[{"price":125.04,"qty":30.38964200}],"asks":[],"checksum":3296499380,"timestamp":"2024-06-01T17:52:05.084259Z"}]}
{"channel":"book","type":"update","data":[{"symbol":"LTC/AUD","bids":[],"asks":[{"price":125.39,"qty":7.11460814}],"checksum":2850211224,"timestamp":"2024-06-01T17:52:05.085187Z"}]}
{"channel":"book","type":"update","data":[{"symbol":"LTC/AUD","bids":[],"asks":[{"price":125.28,"qty":37.62295256}],"checksum":3929812583,"timestamp":"2024-06-01T17:52:05.086708Z"}]}
{"channel":"book","type":"update","data":[{"symbol":"LTC/AUD","bids":[],"asks":[{"price":125.39,"qty":2.04654681},{"price":125.48,"qty":5.06806133}],"checksum":1972788590,"timestamp":"2024-06-01T17:52:06.271053Z"}]}
{"channel":"book","type":"update","data":[{"symbol":"LTC/AUD","bids":[],"asks":[{"price":125.48,"qty":0.00000000},{"price":126.07,"qty":199.92693932},{"price":125.38,"qty":13.89943569}],"checksum":2551566674,"timestamp":"2024-06-01T17:52:07.334578Z"}]}
{"channel":"book","type":"update","data":[{"symbol":"LTC/AUD","bids":[],"asks":[{"price":125.94,"qty":0.29372984}],"checksum":2571949400,"timestamp":"2024-06-01T17:52:07.336987Z"}]}
{"channel":"book","type":"update","data":[{"symbol":"LTC/AUD","bids":[],"asks":[{"price":125.94,"qty":0.00000000},{"price":126.07,"qty":199.92693932}],"checksum":2551566674,"timestamp":"2024-06-01T17:52:09.728543Z"}]}
{"channel":"book","type":"update","data":[{"symbol":"LTC/AUD","bids":[],"asks":[{"price":126.07,"qty":0.00000000},{"price":126.50,"qty":13.31456049}],"checksum":2667280547,"timestamp":"2024-06-01T17:52:09.730714Z"}]}
{"channel":"book","type":"update","data":[{"symbol":"LTC/AUD","bids":[],"asks":[{"price":126.08,"qty":199.89472073}],"checksum":3692911743,"timestamp":"2024-06-01T17:52:09.771663Z"}]}
{"channel":"book","type":"update","data":[{"symbol":"LTC/AUD","bids":[],"asks":[{"price":125.94,"qty":0.29376962}],"checksum":3204811361,"timestamp":"2024-06-01T17:52:09.774188Z"}]}
{"channel":"book","type":"update","data":[{"symbol":"LTC/AUD","bids":[],"asks":[{"price":125.38,"qty":8.83137436}],"checksum":3158619704,"timestamp":"2024-06-01T17:52:10.511730Z"}]}
{"channel":"book","type":"update","data":[{"symbol":"LTC/AUD","bids":[],"asks":[{"price":125.38,"qty":13.89943569}],"checksum":3204811361,"timestamp":"2024-06-01T17:52:11.054929Z"}]}
{"channel":"book","type":"update","data":[{"symbol":"LTC/AUD","bids":[],"asks":[{"price":125.94,"qty":0.00000000},{"price":126.08,"qty":199.89472073}],"checksum":3692911743,"timestamp":"2024-06-01T17:52:12.168456Z"}]}
{"channel":"book","type":"update","data":[{"symbol":"LTC/AUD","bids":[],"asks":[{"price":125.38,"qty":8.83137436}],"checksum":3445113274,"timestamp":"2024-06-01T17:52:14.190892Z"}]}
{"channel":"book","type":"update","data":[{"symbol":"LTC/AUD","bids":[],"asks":[{"price":125.38,"qty":13.89943569}],"checksum":3692911743,"timestamp":"2024-06-01T17:52:14.603849Z"}]}
{"channel":"book","type":"update","data":[{"symbol":"LTC/AUD","bids":[],"asks":[{"price":125.38,"qty":8.83137436}],"checksum":3445113274,"timestamp":"2024-06-01T17:52:17.721141Z"}]}
{"channel":"book","type":"update","data":[{"symbol":"LTC/AUD","bids":[],"asks":[{"price":125.40,"qty":5.06806133}],"checksum":3075514132,"timestamp":"2024-06-01T17:52:17.740515Z"}]}
{"channel":"book","type":"update","data":[{"symbol":"LTC/AUD","bids":[],"asks":[{"price":125.40,"qty":0.00000000},{"price":126.08,"qty":199.89472073},{"price":125.48,"qty":5.06806133}],"checksum":1972788590,"timestamp":"2024-06-01T17:52:19.043486Z"}]}
{"channel":"book","type":"update","data":[{"symbol":"LTC/AUD","bids":[],"asks":[{"price":125.28,"qty":0.00000000},{"price":126.08,"qty":199.89472073}],"checksum":369776155,"timestamp":"2024-06-01T17:52:20.176268Z"}]}
{"channel":"book","type":"update","data":[{"symbol":"LTC/AUD","bids":[{"price":125.04,"qty":1.28221908}],"asks":[],"checksum":3339420401,"timestamp":"2024-06-01T17:52:20.176359Z"}]}
{"channel":"book","type":"update","data":[{"symbol":"LTC/AUD","bids":[],"asks":[{"price":125.97,"qty":0.29369966}],"checksum":99186513,"timestamp":"2024-06-01T17:52:20.179545Z"}]}
{"channel":"book","type":"update","data":[{"symbol":"LTC/AUD","bids":[{"price":125.04,"qty":30.38964200}],"asks":[],"checksum":3223197446,"timestamp":"2024-06-01T17:52:20.181066Z"}]}
{"channel":"book","type":"update","data":[{"symbol":"LTC/AUD","bids":[],"asks":[{"price":125.28,"qty":36.71645256}],"checksum":2913193720,"timestamp":"2024-06-01T17:52:20.181178Z"}]}
{"channel":"book","type":"update","data":[{"symbol":"LTC/AUD","bids":[],"asks":[{"price":125.37,"qty":18.00000000}],"checksum":3141688131,"timestamp":"2024-06-01T17:52:20.181809Z"}]}
{"channel":"book","type":"update","data":[{"symbol":"LTC/AUD","bids":[],"asks":[{"price":125.37,"qty":0.00000000},{"price":125.75,"qty":0.68263965}],"checksum":2913193720,"timestamp":"2024-06-01T17:52:20.640832Z"}]}
{"channel":"book","type":"update","data":[{"symbol":"LTC/AUD","bids":[{"price":125.02,"qty":34.06524712}],"asks":[],"checksum":519348278,"timestamp":"2024-06-01T17:52:25.131239Z"}]}
{"channel":"book","type":"update","data":[{"symbol":"LTC/AUD","bids":[{"price":124.92,"qty":0.00000000},{"price":124.38,"qty":46.29839281}],"asks":[],"checksum":467457486,"timestamp":"2024-06-01T17:52:25.131456Z"}]}
{"channel":"book","type":"update","data":[{"symbol":"LTC/AUD","bids":[],"asks":[{"price":125.38,"qty":0.00000000},{"price":126.08,"qty":199.89472073}],"checksum":738822022,"timestamp":"2024-06-01T17:52:30.946939Z"}]}
{"channel":"book","type":"update","data":[{"symbol":"LTC/AUD","bids":[],"asks":[{"price":125.94,"qty":0.29376962}],"checksum":1078395983,"timestamp":"2024-06-01T17:52:30.948816Z"}]}
{"channel":"book","type":"update","data":[{"symbol":"LTC/AUD","bids":[],"asks":[{"price":125.47,"qty":8.83137436}],"checksum":1462089851,"timestamp":"2024-06-01T17:52:30.961146Z"}]}
{"channel":"book","type":"update","data":[{"symbol":"LTC/AUD","bids":[],"asks":[{"price":125.48,"qty":0.00000000},{"price":125.94,"qty":0.29376962},{"price":125.46,"qty":5.06806133}],"checksum":3957908545,"timestamp":"2024-06-01T17:52:30.964347Z"}]}
{"channel":"book","type":"update","data":[{"symbol":"LTC/AUD","bids":[{"price":124.92,"qty":34.09251601}],"asks":[],"checksum":4005597625,"timestamp":"2024-06-01T17:52:30.998220Z"}]}
{"channel":"book","type":"update","data":[{"symbol":"LTC/AUD","bids":[{"price":125.02,"qty":0.00000000},{"price":124.38,"qty":46.29839281}],"asks":[],"checksum":1570242423,"timestamp":"2024-06-01T17:52:30.999898Z"}]}
{"channel":"book","type":"update","data":[{"symbol":"LTC/AUD","bids":[{"price":125.05,"qty":18.00000000}],"asks":[],"checksum":2473010655,"timestamp":"2024-06-01T17:52:31.000068Z"}]}
{"channel":"book","type":"update","data":[{"symbol":"LTC/AUD","bids":[{"price":125.02,"qty":34.06524636}],"asks":[],"checksum":2507462131,"timestamp":"2024-06-01T17:52:31.037471Z"}]}
{"channel":"book","type":"update","data":[{"symbol":"LTC/AUD","bids":[{"price":124.92,"qty":0.00000000},{"price":124.41,"qty":20.53819152}],"asks":[],"checksum":753251948,"timestamp":"2024-06-01T17:52:31.038691Z"}]}
{"channel":"book","type":"update","data":[{"symbol":"LTC/AUD","bids":[{"price":124.92,"qty":34.09251601}],"asks":[],"checksum":2507462131,"timestamp":"2024-06-01T17:52:31.053370Z"}]}
{"channel":"book","type":"update","data":[{"symbol":"LTC/AUD","bids":[{"price":125.02,"qty":0.00000000},{"price":124.41,"qty":20.53819152}],"asks":[],"checksum":2473010655,"timestamp":"2024-06-01T17:52:31.053564Z"}]}
{"channel":"book","type":"update","data":[{"symbol":"LTC/AUD","bids":[{"price":125.01,"qty":0.00000000},{"price":124.38,"qty":46.29839281}],"asks":[],"checksum":1106848696,"timestamp":"2024-06-01T17:52:31.058421Z"}]}
{"channel":"book","type":"update","data":[{"symbol":"LTC/AUD","bids":[{"price":125.04,"qty":1.28221908}],"asks":[],"checksum":1991041093,"timestamp":"2024-06-01T17:52:46.192006Z"}]}
{"channel":"book","type":"update","data":[{"symbol":"LTC/AUD","bids":[],"asks":[{"price":125.28,"qty":0.00000000},{"price":126.08,"qty":199.89472073}],"checksum":1078604841,"timestamp":"2024-06-01T17:52:46.192087Z"}]}
{"channel":"book","type":"update","data":[{"symbol":"LTC/AUD","bids":[],"asks":[{"price":125.97,"qty":0.29369966}],"checksum":560642901,"timestamp":"2024-06-01T17:52:46.194251Z"}]}
{"channel":"book","type":"update","data":[{"symbol":"LTC/AUD","bids":[],"asks":[{"price":125.28,"qty":43.00545256}],"checksum":1755331136,"timestamp":"2024-06-01T17:52:46.196975Z"}]}
{"channel":"book","type":"update","data":[{"symbol":"LTC/AUD","bids":[{"price":125.06,"qty":32.16188187}],"asks":[],"checksum":176886260,"timestamp":"2024-06-01T17:52:46.196996Z"}]}
{"channel":"book","type":"update","data":[{"symbol":"LTC/AUD","bids":[],"asks":[{"price":125.47,"qty":0.00000000},{"price":125.97,"qty":0.29369966}],"checksum":929545885,"timestamp":"2024-06-01T17:52:46.197347Z"}]}
{"channel":"book","type":"update","data":[{"symbol":"LTC/AUD","bids":[],"asks":[{"price":125.38,"qty":18.00000000}],"checksum":1247996818,"timestamp":"2024-06-01T17:52:46.197444Z"}]}
{"channel":"book","type":"update","data":[{"symbol":"LTC/AUD","bids":[],"asks":[{"price":125.38,"qty":26.83137436}],"checksum":2866780149,"timestamp":"2024-06-01T17:52:46.197459Z"}]}
{"channel":"book","type":"update","data":[{"symbol":"LTC/AUD","bids":[],"asks":[{"price":125.46,"qty":0.00000000},{"price":125.97,"qty":0.29369966},{"price":125.48,"qty":5.06806133}],"checksum":3073627128,"timestamp":"2024-06-01T17:52:46.201246Z"}]}
{"channel":"book","type":"update","data":[{"symbol":"LTC/AUD","bids":[],"asks":[{"price":125.38,"qty":18.00000000}],"checksum":1468968863,"timestamp":"2024-06-01T17:52:46.585482Z"}]}
{"channel":"book","type":"update","data":[{"symbol":"LTC/AUD","bids":[],"asks":[{"price":125.47,"qty":8.83137436}],"checksum":1873375538,"timestamp":"2024-06-01T17:52:46.585580Z"}]}
{"channel":"book","type":"update","data":[{"symbol":"LTC/AUD","bids":[],"asks":[{"price":125.38,"qty":0.00000000},{"price":125.75,"qty":0.68263965}],"checksum":2706649413,"timestamp":"2024-06-01T17:52:46.590819Z"}]}
{"channel":"book","type":"update","data":[{"symbol":"LTC/AUD","bids":[],"asks":[{"price":125.48,"qty":0.00000000},{"price":125.97,"qty":0.29369966},{"price":125.46,"qty":5.06806133}],"checksum":176886260,"timestamp":"2024-06-01T17:52:46.701806Z"}]}
{"channel":"book","type":"update","data":[{"symbol":"LTC/AUD","bids":[],"asks":[{"price":125.31,"qty":0.00000000},{"price":125.97,"qty":0.29369966}],"checksum":1401057846,"timestamp":"2024-06-01T17:52:47.310161Z"}]}
{"channel":"book","type":"update","data":[{"symbol":"LTC/AUD","bids":[],"asks":[{"price":125.29,"qty":0.13316305}],"checksum":3655148787,"timestamp":"2024-06-01T17:52:47.390106Z"}]}
{"channel":"book","type":"update","data":[{"symbol":"LTC/AUD","bids":[{"price":124.65,"qty":0.00000000},{"price":124.38,"qty":46.29839281}],"asks":[],"checksum":2378139481,"timestamp":"2024-06-01T17:52:51.053399Z"}]}
{"channel":"book","type":"update","data":[{"symbol":"LTC/AUD","bids":[{"price":124.74,"qty":0.15250245}],"asks":[],"checksum":3781856378,"timestamp":"2024-06-01T17:52:51.117445Z"}]}
{"channel":"book","type":"update","data":[{"symbol":"LTC/AUD","bids":[],"asks":[{"price":125.62,"qty":0.00000000},{"price":126.08,"qty":199.89472073}],"checksum":1822991501,"timestamp":"2024-06-01T17:53:00.642420Z"}]}
{"channel":"book","type":"update","data":[{"symbol":"LTC/AUD","bids":[],"asks":[{"price":125.94,"qty":0.29376962}],"checksum":1833924952,"timestamp":"2024-06-01T17:53:00.644899Z"}]}
{"channel":"book","type":"update","data":[{"symbol":"LTC/AUD","bids":[],"asks":[{"price":125.69,"qty":18.00000000}],"checksum":1895201246,"timestamp":"2024-06-01T17:53:01.141471Z"}]}
{"channel":"book","type":"update","data":[{"symbol":"LTC/AUD","bids":[{"price":125.06,"qty":0.00000000},{"price":124.38,"qty":46.29839281}],"asks":[],"checksum":2811501217,"timestamp":"2024-06-01T17:53:01.258675Z"}]}
