{"channel":"book","type":"snapshot","data":[{"symbol":"LTC/USD","bids":[{"price":83.19,"qty":20.77500000},{"price":83.18,"qty":69.28199235},{"price":83.17,"qty":20.44101316},{"price":83.16,"qty":220.08405973},{"price":83.15,"qty":18.55485958},{"price":83.14,"qty":338.86926121},{"price":83.13,"qty":12.85701062},{"price":83.12,"qty":126.66290391},{"price":83.11,"qty":69.26283006},{"price":83.10,"qty":7.68750000}],"asks":[{"price":83.21,"qty":15.23750000},{"price":83.22,"qty":65.01799565},{"price":83.23,"qty":27.95698841},{"price":83.24,"qty":127.04492059},{"price":83.25,"qty":68.74519002},{"price":83.26,"qty":251.69681541},{"price":83.27,"qty":3.54763685},{"price":83.28,"qty":61.76250000},{"price":83.31,"qty":110.34660636},{"price":83.32,"qty":142.94010945}],"checksum":3671629586}]}
{"channel":"book","type":"update","data":[{"symbol":"LTC/USD","bids":[{"price":83.19,"qty":13.08750000}],"asks":[],"checksum":3218880429,"timestamp":"2024-06-01T17:52:09.973583Z"}]}
{"channel":"book","type":"update","data":[{"symbol":"LTC/USD","bids":[],"asks":[{"price":83.21,"qty":22.92500000}],"checksum":2950232169,"timestamp":"2024-06-01T17:52:09.973744Z"}]}
{"channel":"book","type":"update","data":[{"symbol":"LTC/USD","bids":[{"price":83.19,"qty":5.40000000}],"asks":[],"checksum":704843562,"timestamp":"2024-06-01T17:52:09.974048Z"}]}
{"channel":"book","type":"update","data":[{"symbol":"LTC/USD","bids":[{"price":83.19,"qty":13.08750000}],"asks":[],"checksum":2950232169,"timestamp":"2024-06-01T17:52:09.995846Z"}]}
{"channel":"book","type":"update","data":[{"symbol":"LTC/USD","bids":[{"price":83.15,"qty":10.57750000}],"asks":[],"checksum":1633328873,"timestamp":"2024-06-01T17:52:10.912525Z"}]}
{"channel":"book","type":"update","data":[{"symbol":"LTC/USD","bids":[{"price":83.17,"qty":19.33718232}],"asks":[],"checksum":2871187901,"timestamp":"2024-06-01T17:52:10.912559Z"}]}
{"channel":"book","type":"update","data":[{"symbol":"LTC/USD","bids":[{"price":83.17,"qty":20.65687385}],"asks":[],"checksum":3649377039,"timestamp":"2024-06-01T17:52:10.920321Z"}]}
{"channel":"book","type":"update","data":[{"symbol":"LTC/USD","bids":[{"price":83.15,"qty":18.34437432}],"asks":[],"checksum":2079457667,"timestamp":"2024-06-01T17:52:10.920458Z"}]}
{"channel":"book","type":"update","data":[{"symbol":"LTC/USD","bids":[{"price":83.19,"qty":5.40000000}],"asks":[],"checksum":4264163008,"timestamp":"2024-06-01T17:52:11.290014Z"}]}
{"channel":"book","type":"update","data":[{"symbol":"LTC/USD","bids":[{"price":83.19,"qty":13.08750000}],"asks":[],"checksum":2079457667,"timestamp":"2024-06-01T17:52:11.390616Z"}]}
{"channel":"book","type":"update","data":[{"symbol":"LTC/USD","bids":[{"price":83.19,"qty":5.40000000}],"asks":[],"checksum":4264163008,"timestamp":"2024-06-01T17:52:11.670266Z"}]}
{"channel":"book","type":"update","data":[{"symbol":"LTC/USD","bids":[],"asks":[{"price":83.32,"qty":139.85770945}],"checksum":339552206,"timestamp":"2024-06-01T17:52:11.674514Z"}]}
{"channel":"book","type":"update","data":[{"symbol":"LTC/USD","bids":[{"price":83.19,"qty":13.08750000}],"asks":[],"checksum":2627745877,"timestamp":"2024-06-01T17:52:11.880531Z"}]}
{"channel":"book","type":"update","data":[{"symbol":"LTC/USD","bids":[{"price":83.19,"qty":20.77500000}],"asks":[],"checksum":4188311786,"timestamp":"2024-06-01T17:52:12.135370Z"}]}
{"channel":"book","type":"update","data":[{"symbol":"LTC/USD","bids":[],"asks":[{"price":83.21,"qty":15.23750000}],"checksum":3919601454,"timestamp":"2024-06-01T17:52:12.135913Z"}]}
{"channel":"book","type":"update","data":[{"symbol":"LTC/USD","bids":[],"asks":[{"price":83.21,"qty":7.55000000}],"checksum":4220532462,"timestamp":"2024-06-01T17:52:12.140115Z"}]}
{"channel":"book","type":"update","data":[{"symbol":"LTC/USD","bids":[],"asks":[{"price":83.21,"qty":15.23750000}],"checksum":3919601454,"timestamp":"2024-06-01T17:52:12.162088Z"}]}
{"channel":"book","type":"update","data":[{"symbol":"LTC/USD","bids":[],"asks":[{"price":83.21,"qty":22.92500000}],"checksum":4188311786,"timestamp":"2024-06-01T17:52:12.546251Z"}]}
{"channel":"book","type":"update","data":[{"symbol":"LTC/USD","bids":[],"asks":[{"price":83.32,"qty":142.50360945}],"checksum":2208603688,"timestamp":"2024-06-01T17:52:12.747244Z"}]}
{"channel":"book","type":"update","data":[{"symbol":"LTC/USD","bids":[],"asks":[{"price":83.21,"qty":15.23750000}],"checksum":2476757484,"timestamp":"2024-06-01T17:52:12.870117Z"}]}
{"channel":"book","type":"update","data":[{"symbol":"LTC/USD","bids":[],"asks":[{"price":83.28,"qty":7.68750000}],"checksum":2664836671,"timestamp":"2024-06-01T17:52:13.140265Z"}]}
{"channel":"book","type":"update","data":[{"symbol":"LTC/USD","bids":[],"asks":[{"price":83.29,"qty":54.06800000}],"checksum":3622246209,"timestamp":"2024-06-01T17:52:13.142890Z"}]}
{"channel":"book","type":"update","data":[{"symbol":"LTC/USD","bids":[],"asks":[{"price":83.21,"qty":22.92500000}],"checksum":3655813292,"timestamp":"2024-06-01T17:52:13.333641Z"}]}
{"channel":"book","type":"update","data":[{"symbol":"LTC/USD","bids":[],"asks":[{"price":83.21,"qty":22.47653139}],"checksum":3667335374,"timestamp":"2024-06-01T17:52:13.974207Z"}]}
{"channel":"book","type":"update","data":[{"symbol":"LTC/USD","bids":[],"asks":[{"price":83.21,"qty":14.78903139}],"checksum":1272261166,"timestamp":"2024-06-01T17:52:13.990150Z"}]}
{"channel":"book","type":"update","data":[{"symbol":"LTC/USD","bids":[],"asks":[{"price":83.21,"qty":22.47653139}],"checksum":3667335374,"timestamp":"2024-06-01T17:52:14.902280Z"}]}
{"channel":"book","type":"update","data":[{"symbol":"LTC/USD","bids":[],"asks":[{"price":83.21,"qty":14.78903139}],"checksum":1272261166,"timestamp":"2024-06-01T17:52:15.069679Z"}]}
{"channel":"book","type":"update","data":[{"symbol":"LTC/USD","bids":[],"asks":[{"price":83.21,"qty":7.68750000}],"checksum":2247895531,"timestamp":"2024-06-01T17:52:15.316649Z"}]}
{"channel":"book","type":"update","data":[{"symbol":"LTC/USD","bids":[],"asks":[{"price":83.22,"qty":57.46799565}],"checksum":3530325676,"timestamp":"2024-06-01T17:52:15.319991Z"}]}
{"channel":"book","type":"update","data":[{"symbol":"LTC/USD","bids":[],"asks":[{"price":83.21,"qty":0.00000000},{"price":83.32,"qty":142.50360945}],"checksum":3603564189,"timestamp":"2024-06-01T17:52:15.355524Z"}]}
{"channel":"book","type":"update","data":[{"symbol":"LTC/USD","bids":[],"asks":[{"price":83.22,"qty":65.15549565}],"checksum":1248020510,"timestamp":"2024-06-01T17:52:15.359644Z"}]}
{"channel":"book","type":"update","data":[{"symbol":"LTC/USD","bids":[],"asks":[{"price":83.26,"qty":275.54988053}],"checksum":3418011879,"timestamp":"2024-06-01T17:52:15.360860Z"}]}
{"channel":"book","type":"update","data":[{"symbol":"LTC/USD","bids":[],"asks":[{"price":83.26,"qty":275.83480111}],"checksum":2128498127,"timestamp":"2024-06-01T17:52:15.362089Z"}]}
{"channel":"book","type":"update","data":[{"symbol":"LTC/USD","bids":[],"asks":[{"price":83.26,"qty":276.11972169}],"checksum":4173569158,"timestamp":"2024-06-01T17:52:15.362718Z"}]}
{"channel":"book","type":"update","data":[{"symbol":"LTC/USD","bids":[],"asks":[{"price":83.26,"qty":276.40464227}],"checksum":4142650398,"timestamp":"2024-06-01T17:52:15.363059Z"}]}
{"channel":"book","type":"update","data":[{"symbol":"LTC/USD","bids":[],"asks":[{"price":83.26,"qty":276.68956285}],"checksum":3223695940,"timestamp":"2024-06-01T17:52:15.363230Z"}]}
{"channel":"book","type":"update","data":[{"symbol":"LTC/USD","bids":[],"asks":[{"price":83.21,"qty":7.68750000}],"checksum":3825851909,"timestamp":"2024-06-01T17:52:15.372096Z"}]}
{"channel":"book","type":"update","data":[{"symbol":"LTC/USD","bids":[],"asks":[{"price":83.21,"qty":0.00000000},{"price":83.32,"qty":142.50360945}],"checksum":3223695940,"timestamp":"2024-06-01T17:52:15.374953Z"}]}
{"channel":"book","type":"update","data":[{"symbol":"LTC/USD","bids":[],"asks":[{"price":83.21,"qty":7.68750000}],"checksum":3825851909,"timestamp":"2024-06-01T17:52:15.381719Z"}]}
{"channel":"book","type":"update","data":[{"symbol":"LTC/USD","bids":[],"asks":[{"price":83.25,"qty":71.03735664}],"checksum":1669827220,"timestamp":"2024-06-01T17:52:15.446939Z"}]}
{"channel":"book","type":"update","data":[{"symbol":"LTC/USD","bids":[],"asks":[{"price":83.21,"qty":0.00000000},{"price":83.32,"qty":142.50360945}],"checksum":55569686,"timestamp":"2024-06-01T17:52:15.448874Z"}]}
{"channel":"book","type":"update","data":[{"symbol":"LTC/USD","bids":[],"asks":[{"price":83.25,"qty":83.16807013}],"checksum":2363092764,"timestamp":"2024-06-01T17:52:15.451661Z"}]}
{"channel":"book","type":"update","data":[{"symbol":"LTC/USD","bids":[],"asks":[{"price":83.22,"qty":72.70549565}],"checksum":372320561,"timestamp":"2024-06-01T17:52:15.498614Z"}]}
{"channel":"book","type":"update","data":[{"symbol":"LTC/USD","bids":[],"asks":[{"price":83.21,"qty":7.55000000}],"checksum":18178649,"timestamp":"2024-06-01T17:52:15.596976Z"}]}
{"channel":"book","type":"update","data":[{"symbol":"LTC/USD","bids":[],"asks":[{"price":83.25,"qty":71.03735664}],"checksum":2120146854,"timestamp":"2024-06-01T17:52:15.751186Z"}]}
{"channel":"book","type":"update","data":[{"symbol":"LTC/USD","bids":[{"price":83.17,"qty":19.33718232}],"asks":[],"checksum":217650452,"timestamp":"2024-06-01T17:52:16.465933Z"}]}
{"channel":"book","type":"update","data":[{"symbol":"LTC/USD","bids":[{"price":83.15,"qty":10.57750000}],"asks":[],"checksum":2928543640,"timestamp":"2024-06-01T17:52:16.466158Z"}]}
{"channel":"book","type":"update","data":[{"symbol":"LTC/USD","bids":[{"price":83.15,"qty":19.63572596}],"asks":[],"checksum":3376869318,"timestamp":"2024-06-01T17:52:16.472061Z"}]}
{"channel":"book","type":"update","data":[{"symbol":"LTC/USD","bids":[{"price":83.17,"qty":21.30434900}],"asks":[],"checksum":2769395560,"timestamp":"2024-06-01T17:52:16.472125Z"}]}
{"channel":"book","type":"update","data":[{"symbol":"LTC/USD","bids":[],"asks":[{"price":83.21,"qty":0.00000000},{"price":83.32,"qty":142.50360945}],"checksum":1122528245,"timestamp":"2024-06-01T17:52:16.545485Z"}]}
{"channel":"book","type":"update","data":[{"symbol":"LTC/USD","bids":[],"asks":[{"price":83.22,"qty":65.15549565}],"checksum":3623923160,"timestamp":"2024-06-01T17:52:16.545499Z"}]}
{"channel":"book","type":"update","data":[{"symbol":"LTC/USD","bids":[],"asks":[{"price":83.24,"qty":119.49492059}],"checksum":569165137,"timestamp":"2024-06-01T17:52:16.545614Z"}]}
{"channel":"book","type":"update","data":[{"symbol":"LTC/USD","bids":[],"asks":[{"price":83.21,"qty":7.55000000},{"price":83.22,"qty":72.70549565},{"price":83.24,"qty":127.04492059}],"checksum":2769395560,"timestamp":"2024-06-01T17:52:16.693768Z"}]}
{"channel":"book","type":"update","data":[{"symbol":"LTC/USD","bids":[],"asks":[{"price":83.25,"qty":70.09341091}],"checksum":2838300796,"timestamp":"2024-06-01T17:52:17.300826Z"}]}
{"channel":"book","type":"update","data":[{"symbol":"LTC/USD","bids":[],"asks":[{"price":83.25,"qty":70.68554562}],"checksum":3698605335,"timestamp":"2024-06-01T17:52:17.302301Z"}]}
{"channel":"book","type":"update","data":[{"symbol":"LTC/USD","bids":[],"asks":[{"price":83.21,"qty":0.00000000},{"price":83.32,"qty":142.50360945}],"checksum":360379259,"timestamp":"2024-06-01T17:52:17.680331Z"}]}
{"channel":"book","type":"update","data":[{"symbol":"LTC/USD","bids":[],"asks":[{"price":83.22,"qty":65.15549565}],"checksum":2408723798,"timestamp":"2024-06-01T17:52:17.684033Z"}]}
{"channel":"book","type":"update","data":[{"symbol":"LTC/USD","bids":[],"asks":[{"price":83.21,"qty":7.55000000},{"price":83.22,"qty":72.70549565}],"checksum":3698605335,"timestamp":"2024-06-01T17:52:17.840636Z"}]}
{"channel":"book","type":"update","data":[{"symbol":"LTC/USD","bids":[{"price":83.16,"qty":208.60905973}],"asks":[],"checksum":4213558631,"timestamp":"2024-06-01T17:52:17.869558Z"}]}
{"channel":"book","type":"update","data":[{"symbol":"LTC/USD","bids":[{"price":83.17,"qty":32.77934900}],"asks":[],"checksum":604708035,"timestamp":"2024-06-01T17:52:17.872500Z"}]}
{"channel":"book","type":"update","data":[{"symbol":"LTC/USD","bids":[],"asks":[{"price":83.25,"qty":68.39337900}],"checksum":982624991,"timestamp":"2024-06-01T17:52:18.050480Z"}]}
{"channel":"book","type":"update","data":[{"symbol":"LTC/USD","bids":[],"asks":[{"price":83.21,"qty":15.23750000}],"checksum":2996969806,"timestamp":"2024-06-01T17:52:18.248824Z"}]}
{"channel":"book","type":"update","data":[{"symbol":"LTC/USD","bids":[{"price":83.17,"qty":25.22934900}],"asks":[],"checksum":3736319988,"timestamp":"2024-06-01T17:52:18.251284Z"}]}
{"channel":"book","type":"update","data":[{"symbol":"LTC/USD","bids":[],"asks":[{"price":83.21,"qty":7.55000000}],"checksum":1451244645,"timestamp":"2024-06-01T17:52:18.252436Z"}]}
{"channel":"book","type":"update","data":[{"symbol":"LTC/USD","bids":[{"price":83.16,"qty":201.05905973}],"asks":[],"checksum":3391919375,"timestamp":"2024-06-01T17:52:18.254938Z"}]}
{"channel":"book","type":"update","data":[{"symbol":"LTC/USD","bids":[],"asks":[{"price":83.21,"qty":15.23750000}],"checksum":1109335710,"timestamp":"2024-06-01T17:52:18.329447Z"}]}
{"channel":"book","type":"update","data":[{"symbol":"LTC/USD","bids":[{"price":83.17,"qty":32.77934900},{"price":83.16,"qty":208.60905973}],"asks":[],"checksum":2996969806,"timestamp":"2024-06-01T17:52:18.383364Z"}]}
{"channel":"book","type":"update","data":[{"symbol":"LTC/USD","bids":[{"price":83.19,"qty":13.08750000}],"asks":[],"checksum":3618015729,"timestamp":"2024-06-01T17:52:18.402197Z"}]}
{"channel":"book","type":"update","data":[{"symbol":"LTC/USD","bids":[],"asks":[{"price":83.21,"qty":22.92500000}],"checksum":3651589660,"timestamp":"2024-06-01T17:52:18.402409Z"}]}
{"channel":"book","type":"update","data":[{"symbol":"LTC/USD","bids":[{"price":83.19,"qty":5.40000000}],"asks":[],"checksum":129621774,"timestamp":"2024-06-01T17:52:18.403018Z"}]}
{"channel":"book","type":"update","data":[{"symbol":"LTC/USD","bids":[{"price":83.19,"qty":13.08750000}],"asks":[],"checksum":3651589660,"timestamp":"2024-06-01T17:52:18.405702Z"}]}
{"channel":"book","type":"update","data":[{"symbol":"LTC/USD","bids":[{"price":83.17,"qty":25.22934900}],"asks":[],"checksum":3048685734,"timestamp":"2024-06-01T17:52:18.436505Z"}]}
{"channel":"book","type":"update","data":[{"symbol":"LTC/USD","bids":[{"price":83.16,"qty":201.05905973}],"asks":[],"checksum":689695180,"timestamp":"2024-06-01T17:52:18.439750Z"}]}
{"channel":"book","type":"update","data":[{"symbol":"LTC/USD","bids":[],"asks":[{"price":83.21,"qty":15.23750000}],"checksum":656127521,"timestamp":"2024-06-01T17:52:18.532723Z"}]}
{"channel":"book","type":"update","data":[{"symbol":"LTC/USD","bids":[{"price":83.19,"qty":20.77500000}],"asks":[],"checksum":1109335710,"timestamp":"2024-06-01T17:52:18.536264Z"}]}
{"channel":"book","type":"update","data":[{"symbol":"LTC/USD","bids":[{"price":83.17,"qty":32.77934900},{"price":83.16,"qty":208.60905973}],"asks":[],"checksum":2996969806,"timestamp":"2024-06-01T17:52:18.620077Z"}]}
{"channel":"book","type":"update","data":[{"symbol":"LTC/USD","bids":[],"asks":[{"price":83.21,"qty":7.55000000}],"checksum":982624991,"timestamp":"2024-06-01T17:52:18.640550Z"}]}
{"channel":"book","type":"update","data":[{"symbol":"LTC/USD","bids":[{"price":83.15,"qty":10.57750000}],"asks":[],"checksum":1566130817,"timestamp":"2024-06-01T17:52:19.444089Z"}]}
{"channel":"book","type":"update","data":[{"symbol":"LTC/USD","bids":[{"price":83.17,"qty":30.81218232}],"asks":[],"checksum":4091560639,"timestamp":"2024-06-01T17:52:19.444640Z"}]}
{"channel":"book","type":"update","data":[{"symbol":"LTC/USD","bids":[],"asks":[{"price":83.25,"qty":67.80124429}],"checksum":4084382737,"timestamp":"2024-06-01T17:52:19.478980Z"}]}
{"channel":"book","type":"update","data":[{"symbol":"LTC/USD","bids":[],"asks":[{"price":83.25,"qty":68.74519002}],"checksum":328270413,"timestamp":"2024-06-01T17:52:19.480106Z"}]}
{"channel":"book","type":"update","data":[{"symbol":"LTC/USD","bids":[],"asks":[{"price":83.21,"qty":15.23750000}],"checksum":2611120604,"timestamp":"2024-06-01T17:52:19.623878Z"}]}
{"channel":"book","type":"update","data":[{"symbol":"LTC/USD","bids":[{"price":83.15,"qty":18.56023501}],"asks":[],"checksum":252093995,"timestamp":"2024-06-01T17:52:19.793824Z"}]}
{"channel":"book","type":"update","data":[{"symbol":"LTC/USD","bids":[{"price":83.17,"qty":31.91601316}],"asks":[],"checksum":1252666815,"timestamp":"2024-06-01T17:52:19.793922Z"}]}
{"channel":"book","type":"update","data":[{"symbol":"LTC/USD","bids":[],"asks":[{"price":83.21,"qty":22.92500000}],"checksum":1152021074,"timestamp":"2024-06-01T17:52:20.277931Z"}]}
{"channel":"book","type":"update","data":[{"symbol":"LTC/USD","bids":[{"price":83.19,"qty":13.08750000}],"asks":[],"checksum":565107437,"timestamp":"2024-06-01T17:52:20.290260Z"}]}
{"channel":"book","type":"update","data":[{"symbol":"LTC/USD","bids":[{"price":83.19,"qty":5.40000000}],"asks":[],"checksum":3144253191,"timestamp":"2024-06-01T17:52:20.293530Z"}]}
{"channel":"book","type":"update","data":[{"symbol":"LTC/USD","bids":[{"price":83.19,"qty":13.08750000}],"asks":[],"checksum":565107437,"timestamp":"2024-06-01T17:52:20.324319Z"}]}
{"channel":"book","type":"update","data":[{"symbol":"LTC/USD","bids":[],"asks":[{"price":83.21,"qty":15.23750000}],"checksum":799966464,"timestamp":"2024-06-01T17:52:20.655018Z"}]}
{"channel":"book","type":"update","data":[{"symbol":"LTC/USD","bids":[],"asks":[{"price":83.21,"qty":7.68750000}],"checksum":2109062058,"timestamp":"2024-06-01T17:52:20.658422Z"}]}
{"channel":"book","type":"update","data":[{"symbol":"LTC/USD","bids":[{"price":83.19,"qty":20.77500000}],"asks":[],"checksum":414257941,"timestamp":"2024-06-01T17:52:20.658806Z"}]}
{"channel":"book","type":"update","data":[{"symbol":"LTC/USD","bids":[],"asks":[{"price":83.22,"qty":65.15549565}],"checksum":3745575708,"timestamp":"2024-06-01T17:52:20.662096Z"}]}
{"channel":"book","type":"update","data":[{"symbol":"LTC/USD","bids":[],"asks":[{"price":83.21,"qty":15.37500000}],"checksum":2675426046,"timestamp":"2024-06-01T17:52:20.663866Z"}]}
{"channel":"book","type":"update","data":[{"symbol":"LTC/USD","bids":[],"asks":[{"price":83.21,"qty":7.68750000}],"checksum":3745575708,"timestamp":"2024-06-01T17:52:20.721743Z"}]}
{"channel":"book","type":"update","data":[{"symbol":"LTC/USD","bids":[],"asks":[{"price":83.21,"qty":15.23750000},{"price":83.22,"qty":72.70549565}],"checksum":1252666815,"timestamp":"2024-06-01T17:52:20.823887Z"}]}
{"channel":"book","type":"update","data":[{"symbol":"LTC/USD","bids":[],"asks":[{"price":83.21,"qty":7.55000000}],"checksum":3264849454,"timestamp":"2024-06-01T17:52:21.174365Z"}]}
{"channel":"book","type":"update","data":[{"symbol":"LTC/USD","bids":[],"asks":[{"price":83.21,"qty":0.00000000},{"price":83.32,"qty":142.50360945}],"checksum":1636063600,"timestamp":"2024-06-01T17:52:21.777770Z"}]}
{"channel":"book","type":"update","data":[{"symbol":"LTC/USD","bids":[],"asks":[{"price":83.22,"qty":65.15549565}],"checksum":4218199901,"timestamp":"2024-06-01T17:52:21.781307Z"}]}
{"channel":"book","type":"update","data":[{"symbol":"LTC/USD","bids":[],"asks":[{"price":83.22,"qty":59.08929309}],"checksum":1278891309,"timestamp":"2024-06-01T17:52:21.782227Z"}]}
{"channel":"book","type":"update","data":[{"symbol":"LTC/USD","bids":[],"asks":[{"price":83.22,"qty":64.24349565}],"checksum":1716783038,"timestamp":"2024-06-01T17:52:21.786907Z"}]}
{"channel":"book","type":"update","data":[{"symbol":"LTC/USD","bids":[],"asks":[{"price":83.21,"qty":7.55000000},{"price":83.22,"qty":71.79349565}],"checksum":398412570,"timestamp":"2024-06-01T17:52:21.867373Z"}]}
{"channel":"book","type":"update","data":[{"symbol":"LTC/USD","bids":[],"asks":[{"price":83.25,"qty":8.68519002}],"checksum":1017206568,"timestamp":"2024-06-01T17:52:21.893977Z"}]}
{"channel":"book","type":"update","data":[{"symbol":"LTC/USD","bids":[{"price":83.20,"qty":7.68750000}],"asks":[],"checksum":3913848026,"timestamp":"2024-06-01T17:52:21.971834Z"}]}
{"channel":"book","type":"update","data":[{"symbol":"LTC/USD","bids":[{"price":83.20,"qty":15.37500000}],"asks":[],"checksum":992189874,"timestamp":"2024-06-01T17:52:21.971853Z"}]}
{"channel":"book","type":"update","data":[{"symbol":"LTC/USD","bids":[{"price":83.18,"qty":61.59449235}],"asks":[],"checksum":2923523615,"timestamp":"2024-06-01T17:52:21.972083Z"}]}
{"channel":"book","type":"update","data":[{"symbol":"LTC/USD","bids":[{"price":83.20,"qty":7.68750000}],"asks":[],"checksum":2083153783,"timestamp":"2024-06-01T17:52:21.975389Z"}]}
{"channel":"book","type":"update","data":[{"symbol":"LTC/USD","bids":[],"asks":[{"price":83.27,"qty":63.60763685}],"checksum":4182396560,"timestamp":"2024-06-01T17:52:21.975420Z"}]}
{"channel":"book","type":"update","data":[{"symbol":"LTC/USD","bids":[],"asks":[{"price":83.22,"qty":64.10599565}],"checksum":1050765521,"timestamp":"2024-06-01T17:52:21.975474Z"}]}
{"channel":"book","type":"update","data":[{"symbol":"LTC/USD","bids":[{"price":83.20,"qty":15.37500000}],"asks":[],"checksum":2444682189,"timestamp":"2024-06-01T17:52:21.978866Z"}]}
{"channel":"book","type":"update","data":[{"symbol":"LTC/USD","bids":[],"asks":[{"price":83.29,"qty":61.75550000}],"checksum":4032265656,"timestamp":"2024-06-01T17:52:21.981125Z"}]}
{"channel":"book","type":"update","data":[{"symbol":"LTC/USD","bids":[{"price":83.20,"qty":7.68750000}],"asks":[],"checksum":3032534543,"timestamp":"2024-06-01T17:52:21.999165Z"}]}
{"channel":"book","type":"update","data":[{"symbol":"LTC/USD","bids":[{"price":83.20,"qty":0.00000000},{"price":83.10,"qty":7.68750000}],"asks":[],"checksum":3160055932,"timestamp":"2024-06-01T17:52:22.003412Z"}]}
{"channel":"book","type":"update","data":[{"symbol":"LTC/USD","bids":[{"price":83.20,"qty":7.68750000}],"asks":[],"checksum":3032534543,"timestamp":"2024-06-01T17:52:22.022831Z"}]}
{"channel":"book","type":"update","data":[{"symbol":"LTC/USD","bids":[{"price":83.20,"qty":15.37500000}],"asks":[],"checksum":4032265656,"timestamp":"2024-06-01T17:52:22.023200Z"}]}
{"channel":"book","type":"update","data":[{"symbol":"LTC/USD","bids":[{"price":83.20,"qty":7.68750000}],"asks":[],"checksum":3032534543,"timestamp":"2024-06-01T17:52:22.026812Z"}]}
{"channel":"book","type":"update","data":[{"symbol":"LTC/USD","bids":[{"price":83.20,"qty":0.00000000},{"price":83.10,"qty":7.68750000}],"asks":[],"checksum":3160055932,"timestamp":"2024-06-01T17:52:22.117355Z"}]}
{"channel":"book","type":"update","data":[{"symbol":"LTC/USD","bids":[],"asks":[{"price":83.22,"qty":71.79349565}],"checksum":2075231805,"timestamp":"2024-06-01T17:52:22.150378Z"}]}
{"channel":"book","type":"update","data":[{"symbol":"LTC/USD","bids":[{"price":83.17,"qty":20.44101316}],"asks":[],"checksum":3919965129,"timestamp":"2024-06-01T17:52:22.598860Z"}]}
{"channel":"book","type":"update","data":[{"symbol":"LTC/USD","bids":[{"price":83.16,"qty":219.97805973}],"asks":[],"checksum":3592066231,"timestamp":"2024-06-01T17:52:22.601272Z"}]}
{"channel":"book","type":"update","data":[{"symbol":"LTC/USD","bids":[],"asks":[{"price":83.21,"qty":0.00000000},{"price":83.32,"qty":142.50360945}],"checksum":1646384355,"timestamp":"2024-06-01T17:52:22.708678Z"}]}
{"channel":"book","type":"update","data":[{"symbol":"LTC/USD","bids":[],"asks":[{"price":83.31,"qty":101.51523200}],"checksum":2897994447,"timestamp":"2024-06-01T17:52:22.874715Z"}]}
{"channel":"book","type":"update","data":[{"symbol":"LTC/USD","bids":[],"asks":[{"price":83.21,"qty":7.55000000}],"checksum":3646684103,"timestamp":"2024-06-01T17:52:22.926205Z"}]}
{"channel":"book","type":"update","data":[{"symbol":"LTC/USD","bids":[],"asks":[{"price":83.21,"qty":0.00000000},{"price":83.32,"qty":142.50360945}],"checksum":2897994447,"timestamp":"2024-06-01T17:52:23.241835Z"}]}
{"channel":"book","type":"update","data":[{"symbol":"LTC/USD","bids":[],"asks":[{"price":83.22,"qty":64.24349565}],"checksum":2187378423,"timestamp":"2024-06-01T17:52:23.245574Z"}]}
{"channel":"book","type":"update","data":[{"symbol":"LTC/USD","bids":[{"price":83.20,"qty":7.68750000}],"asks":[],"checksum":2841915321,"timestamp":"2024-06-01T17:52:23.266762Z"}]}
{"channel":"book","type":"update","data":[{"symbol":"LTC/USD","bids":[{"price":83.20,"qty":15.37500000}],"asks":[],"checksum":167129493,"timestamp":"2024-06-01T17:52:23.266953Z"}]}
{"channel":"book","type":"update","data":[{"symbol":"LTC/USD","bids":[],"asks":[{"price":83.22,"qty":56.55599565}],"checksum":4015407073,"timestamp":"2024-06-01T17:52:23.268078Z"}]}
{"channel":"book","type":"update","data":[{"symbol":"LTC/USD","bids":[{"price":83.20,"qty":7.68750000}],"asks":[],"checksum":1781947126,"timestamp":"2024-06-01T17:52:23.269925Z"}]}
{"channel":"book","type":"update","data":[{"symbol":"LTC/USD","bids":[{"price":83.20,"qty":0.00000000},{"price":83.10,"qty":7.68750000}],"asks":[],"checksum":1093847992,"timestamp":"2024-06-01T17:52:23.314859Z"}]}
{"channel":"book","type":"update","data":[{"symbol":"LTC/USD","bids":[{"price":83.20,"qty":7.68750000}],"asks":[],"checksum":1781947126,"timestamp":"2024-06-01T17:52:23.330312Z"}]}
{"channel":"book","type":"update","data":[{"symbol":"LTC/USD","bids":[{"price":83.20,"qty":15.37500000}],"asks":[],"checksum":4015407073,"timestamp":"2024-06-01T17:52:23.331414Z"}]}
{"channel":"book","type":"update","data":[{"symbol":"LTC/USD","bids":[{"price":83.20,"qty":7.68750000}],"asks":[],"checksum":1781947126,"timestamp":"2024-06-01T17:52:23.334084Z"}]}
{"channel":"book","type":"update","data":[{"symbol":"LTC/USD","bids":[{"price":83.20,"qty":15.37500000}],"asks":[],"checksum":4015407073,"timestamp":"2024-06-01T17:52:23.338771Z"}]}
{"channel":"book","type":"update","data":[{"symbol":"LTC/USD","bids":[],"asks":[{"price":83.21,"qty":7.55000000},{"price":83.22,"qty":64.10599565}],"checksum":778608732,"timestamp":"2024-06-01T17:52:23.383047Z"}]}
{"channel":"book","type":"update","data":[{"symbol":"LTC/USD","bids":[{"price":83.20,"qty":7.68750000}],"asks":[],"checksum":901008584,"timestamp":"2024-06-01T17:52:23.387462Z"}]}
{"channel":"book","type":"update","data":[{"symbol":"LTC/USD","bids":[{"price":83.20,"qty":15.37500000}],"asks":[],"checksum":778608732,"timestamp":"2024-06-01T17:52:23.393440Z"}]}
{"channel":"book","type":"update","data":[{"symbol":"LTC/USD","bids":[],"asks":[{"price":83.21,"qty":0.00000000},{"price":83.32,"qty":142.50360945}],"checksum":737228434,"timestamp":"2024-06-01T17:52:23.451453Z"}]}
{"channel":"book","type":"update","data":[{"symbol":"LTC/USD","bids":[{"price":83.20,"qty":7.68750000}],"asks":[],"checksum":2893385999,"timestamp":"2024-06-01T17:52:23.454987Z"}]}
{"channel":"book","type":"update","data":[{"symbol":"LTC/USD","bids":[{"price":83.20,"qty":15.37500000}],"asks":[],"checksum":737228434,"timestamp":"2024-06-01T17:52:23.458634Z"}]}
{"channel":"book","type":"update","data":[{"symbol":"LTC/USD","bids":[],"asks":[{"price":83.22,"qty":56.41849565}],"checksum":1848357490,"timestamp":"2024-06-01T17:52:23.474778Z"}]}
{"channel":"book","type":"update","data":[{"symbol":"LTC/USD","bids":[],"asks":[{"price":83.22,"qty":64.10599565}],"checksum":737228434,"timestamp":"2024-06-01T17:52:23.480242Z"}]}
{"channel":"book","type":"update","data":[{"symbol":"LTC/USD","bids":[],"asks":[{"price":83.21,"qty":7.55000000}],"checksum":778608732,"timestamp":"2024-06-01T17:52:23.664603Z"}]}
{"channel":"book","type":"update","data":[{"symbol":"LTC/USD","bids":[{"price":83.20,"qty":7.68750000}],"asks":[],"checksum":901008584,"timestamp":"2024-06-01T17:52:23.668491Z"}]}
{"channel":"book","type":"update","data":[{"symbol":"LTC/USD","bids":[{"price":83.20,"qty":0.00000000},{"price":83.10,"qty":7.68750000}],"asks":[],"checksum":514907526,"timestamp":"2024-06-01T17:52:23.668753Z"}]}
{"channel":"book","type":"update","data":[{"symbol":"LTC/USD","bids":[],"asks":[{"price":83.22,"qty":71.79349565}],"checksum":3646684103,"timestamp":"2024-06-01T17:52:23.824832Z"}]}
{"channel":"book","type":"update","data":[{"symbol":"LTC/USD","bids":[],"asks":[{"price":83.25,"qty":7.74124429}],"checksum":522438384,"timestamp":"2024-06-01T17:52:23.927287Z"}]}
{"channel":"book","type":"update","data":[{"symbol":"LTC/USD","bids":[],"asks":[{"price":83.25,"qty":8.86101857}],"checksum":2962638698,"timestamp":"2024-06-01T17:52:23.927964Z"}]}
{"channel":"book","type":"update","data":[{"symbol":"LTC/USD","bids":[],"asks":[{"price":83.21,"qty":0.00000000},{"price":83.32,"qty":142.50360945}],"checksum":2073552582,"timestamp":"2024-06-01T17:52:24.401196Z"}]}
{"channel":"book","type":"update","data":[{"symbol":"LTC/USD","bids":[],"asks":[{"price":83.22,"qty":64.24349565}],"checksum":1431091966,"timestamp":"2024-06-01T17:52:24.404884Z"}]}
{"channel":"book","type":"update","data":[{"symbol":"LTC/USD","bids":[{"price":83.15,"qty":10.57750000}],"asks":[],"checksum":3253245193,"timestamp":"2024-06-01T17:52:24.454859Z"}]}
{"channel":"book","type":"update","data":[{"symbol":"LTC/USD","bids":[{"price":83.17,"qty":19.33718232}],"asks":[],"checksum":194040413,"timestamp":"2024-06-01T17:52:24.455223Z"}]}
{"channel":"book","type":"update","data":[{"symbol":"LTC/USD","bids":[{"price":83.20,"qty":7.68750000}],"asks":[],"checksum":4046483467,"timestamp":"2024-06-01T17:52:24.460829Z"}]}
{"channel":"book","type":"update","data":[{"symbol":"LTC/USD","bids":[{"price":83.20,"qty":15.37500000}],"asks":[],"checksum":4286971534,"timestamp":"2024-06-01T17:52:24.461064Z"}]}
{"channel":"book","type":"update","data":[{"symbol":"LTC/USD","bids":[{"price":83.17,"qty":21.19582151}],"asks":[],"checksum":3850298535,"timestamp":"2024-06-01T17:52:24.463444Z"}]}
{"channel":"book","type":"update","data":[{"symbol":"LTC/USD","bids":[{"price":83.15,"qty":18.20356999}],"asks":[],"checksum":2403548404,"timestamp":"2024-06-01T17:52:24.463508Z"}]}
{"channel":"book","type":"update","data":[{"symbol":"LTC/USD","bids":[{"price":83.20,"qty":7.68750000}],"asks":[],"checksum":2180428401,"timestamp":"2024-06-01T17:52:24.464100Z"}]}
{"channel":"book","type":"update","data":[{"symbol":"LTC/USD","bids":[{"price":83.20,"qty":15.37500000}],"asks":[],"checksum":2403548404,"timestamp":"2024-06-01T17:52:24.470573Z"}]}
{"channel":"book","type":"update","data":[{"symbol":"LTC/USD","bids":[],"asks":[{"price":83.21,"qty":7.55000000},{"price":83.22,"qty":71.79349565}],"checksum":2026156372,"timestamp":"2024-06-01T17:52:24.631646Z"}]}
{"channel":"book","type":"update","data":[{"symbol":"LTC/USD","bids":[{"price":83.20,"qty":7.68750000}],"asks":[],"checksum":1680625637,"timestamp":"2024-06-01T17:52:24.635162Z"}]}
{"channel":"book","type":"update","data":[{"symbol":"LTC/USD","bids":[{"price":83.20,"qty":15.37500000}],"asks":[],"checksum":2026156372,"timestamp":"2024-06-01T17:52:24.638877Z"}]}
{"channel":"book","type":"update","data":[{"symbol":"LTC/USD","bids":[],"asks":[{"price":83.21,"qty":0.00000000},{"price":83.32,"qty":121.04962115},{"price":83.26,"qty":284.23956285}],"checksum":1012805710,"timestamp":"2024-06-01T17:52:25.284960Z"}]}
{"channel":"book","type":"update","data":[{"symbol":"LTC/USD","bids":[],"asks":[{"price":83.26,"qty":291.78956285}],"checksum":3260150906,"timestamp":"2024-06-01T17:52:25.288647Z"}]}
{"channel":"book","type":"update","data":[{"symbol":"LTC/USD","bids":[],"asks":[{"price":83.22,"qty":64.10599565}],"checksum":3363475647,"timestamp":"2024-06-01T17:52:25.288805Z"}]}
{"channel":"book","type":"update","data":[{"symbol":"LTC/USD","bids":[],"asks":[{"price":83.26,"qty":284.23956285}],"checksum":913659019,"timestamp":"2024-06-01T17:52:25.289254Z"}]}
{"channel":"book","type":"update","data":[{"symbol":"LTC/USD","bids":[],"asks":[{"price":83.25,"qty":7.74124429}],"checksum":386033778,"timestamp":"2024-06-01T17:52:26.105315Z"}]}
{"channel":"book","type":"update","data":[{"symbol":"LTC/USD","bids":[],"asks":[{"price":83.25,"qty":9.00758511}],"checksum":1553825798,"timestamp":"2024-06-01T17:52:26.105734Z"}]}
{"channel":"book","type":"update","data":[{"symbol":"LTC/USD","bids":[{"price":83.15,"qty":10.57750000}],"asks":[],"checksum":916478037,"timestamp":"2024-06-01T17:52:26.935768Z"}]}
{"channel":"book","type":"update","data":[{"symbol":"LTC/USD","bids":[{"price":83.15,"qty":19.74662484}],"asks":[],"checksum":3101572171,"timestamp":"2024-06-01T17:52:26.940140Z"}]}
{"channel":"book","type":"update","data":[{"symbol":"LTC/USD","bids":[],"asks":[{"price":83.32,"qty":67.32692115}],"checksum":3494706132,"timestamp":"2024-06-01T17:52:27.027419Z"}]}
{"channel":"book","type":"update","data":[{"symbol":"LTC/USD","bids":[{"price":83.16,"qty":208.60905973}],"asks":[],"checksum":337282546,"timestamp":"2024-06-01T17:52:27.328253Z"}]}
{"channel":"book","type":"update","data":[{"symbol":"LTC/USD","bids":[{"price":83.17,"qty":32.56482151}],"asks":[],"checksum":3087377945,"timestamp":"2024-06-01T17:52:27.330656Z"}]}
{"channel":"book","type":"update","data":[{"symbol":"LTC/USD","bids":[],"asks":[{"price":83.22,"qty":56.41849565}],"checksum":3185390388,"timestamp":"2024-06-01T17:52:28.594107Z"}]}
{"channel":"book","type":"update","data":[{"symbol":"LTC/USD","bids":[],"asks":[{"price":83.22,"qty":48.86849565}],"checksum":3934550030,"timestamp":"2024-06-01T17:52:29.402820Z"}]}
{"channel":"book","type":"update","data":[{"symbol":"LTC/USD","bids":[],"asks":[{"price":83.22,"qty":68.86849565}],"checksum":154070204,"timestamp":"2024-06-01T17:52:29.408169Z"}]}
{"channel":"book","type":"update","data":[{"symbol":"LTC/USD","bids":[],"asks":[{"price":83.22,"qty":76.41849565}],"checksum":1584899974,"timestamp":"2024-06-01T17:52:29.552345Z"}]}
{"channel":"book","type":"update","data":[{"symbol":"LTC/USD","bids":[],"asks":[{"price":83.22,"qty":68.86849565}],"checksum":154070204,"timestamp":"2024-06-01T17:52:29.673565Z"}]}
{"channel":"book","type":"update","data":[{"symbol":"LTC/USD","bids":[],"asks":[{"price":83.22,"qty":76.41849565}],"checksum":1584899974,"timestamp":"2024-06-01T17:52:29.833457Z"}]}
{"channel":"book","type":"update","data":[{"symbol":"LTC/USD","bids":[],"asks":[{"price":83.25,"qty":7.74124429}],"checksum":3310064803,"timestamp":"2024-06-01T17:52:30.517419Z"}]}
{"channel":"book","type":"update","data":[{"symbol":"LTC/USD","bids":[],"asks":[{"price":83.25,"qty":8.86101857}],"checksum":109303959,"timestamp":"2024-06-01T17:52:30.518975Z"}]}
{"channel":"book","type":"update","data":[{"symbol":"LTC/USD","bids":[],"asks":[{"price":83.22,"qty":68.86849565}],"checksum":1373279149,"timestamp":"2024-06-01T17:52:30.768631Z"}]}
{"channel":"book","type":"update","data":[{"symbol":"LTC/USD","bids":[],"asks":[{"price":83.22,"qty":76.55599565}],"checksum":3306718787,"timestamp":"2024-06-01T17:52:30.792344Z"}]}
{"channel":"book","type":"update","data":[{"symbol":"LTC/USD","bids":[],"asks":[{"price":83.22,"qty":68.86849565}],"checksum":1373279149,"timestamp":"2024-06-01T17:52:30.820939Z"}]}
{"channel":"book","type":"update","data":[{"symbol":"LTC/USD","bids":[],"asks":[{"price":83.22,"qty":48.86849565}],"checksum":2993686303,"timestamp":"2024-06-01T17:52:30.842278Z"}]}
{"channel":"book","type":"update","data":[{"symbol":"LTC/USD","bids":[],"asks":[{"price":83.22,"qty":43.71429309}],"checksum":4253048248,"timestamp":"2024-06-01T17:52:30.843356Z"}]}
{"channel":"book","type":"update","data":[{"symbol":"LTC/USD","bids":[],"asks":[{"price":83.23,"qty":63.19144097}],"checksum":1493422850,"timestamp":"2024-06-01T17:52:30.847385Z"}]}
{"channel":"book","type":"update","data":[{"symbol":"LTC/USD","bids":[],"asks":[{"price":83.23,"qty":43.19144097}],"checksum":1673392211,"timestamp":"2024-06-01T17:52:30.855329Z"}]}
{"channel":"book","type":"update","data":[{"symbol":"LTC/USD","bids":[],"asks":[{"price":83.22,"qty":30.04094927}],"checksum":2144648566,"timestamp":"2024-06-01T17:52:30.861037Z"}]}
{"channel":"book","type":"update","data":[{"symbol":"LTC/USD","bids":[],"asks":[{"price":83.23,"qty":56.86478479}],"checksum":4148999129,"timestamp":"2024-06-01T17:52:30.861157Z"}]}
{"channel":"book","type":"update","data":[{"symbol":"LTC/USD","bids":[{"price":83.14,"qty":331.83595128}],"asks":[],"checksum":97040640,"timestamp":"2024-06-01T17:52:30.870491Z"}]}
{"channel":"book","type":"update","data":[{"symbol":"LTC/USD","bids":[],"asks":[{"price":83.23,"qty":49.17728479}],"checksum":1978713973,"timestamp":"2024-06-01T17:52:30.889468Z"}]}
{"channel":"book","type":"update","data":[{"symbol":"LTC/USD","bids":[],"asks":[{"price":83.31,"qty":109.20273200}],"checksum":3705542620,"timestamp":"2024-06-01T17:52:30.894848Z"}]}
{"channel":"book","type":"update","data":[{"symbol":"LTC/USD","bids":[{"price":83.17,"qty":25.01482151},{"price":83.18,"qty":69.14449235}],"asks":[],"checksum":4014023400,"timestamp":"2024-06-01T17:52:30.897457Z"}]}
{"channel":"book","type":"update","data":[{"symbol":"LTC/USD","bids":[],"asks":[{"price":83.26,"qty":276.68956285}],"checksum":1038154729,"timestamp":"2024-06-01T17:52:30.900859Z"}]}
{"channel":"book","type":"update","data":[{"symbol":"LTC/USD","bids":[{"price":83.18,"qty":76.69449235}],"asks":[],"checksum":2026135362,"timestamp":"2024-06-01T17:52:30.900936Z"}]}
{"channel":"book","type":"update","data":[{"symbol":"LTC/USD","bids":[],"asks":[{"price":83.24,"qty":119.49492059}],"checksum":2166896587,"timestamp":"2024-06-01T17:52:30.901058Z"}]}
{"channel":"book","type":"update","data":[{"symbol":"LTC/USD","bids":[{"price":83.19,"qty":23.82500000}],"asks":[],"checksum":3128960741,"timestamp":"2024-06-01T17:52:30.955813Z"}]}
{"channel":"book","type":"update","data":[{"symbol":"LTC/USD","bids":[],"asks":[{"price":83.24,"qty":116.46540997}],"checksum":3547913334,"timestamp":"2024-06-01T17:52:30.965127Z"}]}
{"channel":"book","type":"update","data":[{"symbol":"LTC/USD","bids":[{"price":83.18,"qty":69.14449235}],"asks":[],"checksum":2522642653,"timestamp":"2024-06-01T17:52:30.967650Z"}]}
{"channel":"book","type":"update","data":[{"symbol":"LTC/USD","bids":[{"price":83.18,"qty":61.59449235}],"asks":[],"checksum":1673098351,"timestamp":"2024-06-01T17:52:30.972787Z"}]}
{"channel":"book","type":"update","data":[{"symbol":"LTC/USD","bids":[{"price":83.16,"qty":201.05905973}],"asks":[],"checksum":556293164,"timestamp":"2024-06-01T17:52:30.974908Z"}]}
{"channel":"book","type":"update","data":[{"symbol":"LTC/USD","bids":[{"price":83.14,"qty":324.28595128}],"asks":[],"checksum":1337750259,"timestamp":"2024-06-01T17:52:30.975097Z"}]}
{"channel":"book","type":"update","data":[{"symbol":"LTC/USD","bids":[],"asks":[{"price":83.23,"qty":56.86478479}],"checksum":1065618566,"timestamp":"2024-06-01T17:52:30.981827Z"}]}
{"channel":"book","type":"update","data":[{"symbol":"LTC/USD","bids":[],"asks":[{"price":83.21,"qty":7.55000000}],"checksum":1631139425,"timestamp":"2024-06-01T17:52:30.987365Z"}]}
{"channel":"book","type":"update","data":[{"symbol":"LTC/USD","bids":[{"price":83.20,"qty":7.68750000}],"asks":[],"checksum":152760247,"timestamp":"2024-06-01T17:52:30.992367Z"}]}
{"channel":"book","type":"update","data":[{"symbol":"LTC/USD","bids":[{"price":83.20,"qty":0.00000000},{"price":83.10,"qty":7.68750000}],"asks":[],"checksum":1966920365,"timestamp":"2024-06-01T17:52:30.992792Z"}]}
{"channel":"book","type":"update","data":[{"symbol":"LTC/USD","bids":[],"asks":[{"price":83.31,"qty":101.51523200}],"checksum":3952556924,"timestamp":"2024-06-01T17:52:30.994802Z"}]}
{"channel":"book","type":"update","data":[{"symbol":"LTC/USD","bids":[],"asks":[{"price":83.22,"qty":37.59094927},{"price":83.24,"qty":124.01540997},{"price":83.26,"qty":284.23956285}],"checksum":3617608334,"timestamp":"2024-06-01T17:52:30.995307Z"}]}
{"channel":"book","type":"update","data":[{"symbol":"LTC/USD","bids":[{"price":83.20,"qty":7.68750000}],"asks":[],"checksum":2877714324,"timestamp":"2024-06-01T17:52:30.996153Z"}]}
{"channel":"book","type":"update","data":[{"symbol":"LTC/USD","bids":[{"price":83.20,"qty":15.37500000}],"asks":[],"checksum":3288128403,"timestamp":"2024-06-01T17:52:30.997196Z"}]}
{"channel":"book","type":"update","data":[{"symbol":"LTC/USD","bids":[{"price":83.20,"qty":7.68750000}],"asks":[],"checksum":2877714324,"timestamp":"2024-06-01T17:52:30.999098Z"}]}
{"channel":"book","type":"update","data":[{"symbol":"LTC/USD","bids":[],"asks":[{"price":83.22,"qty":45.27844927}],"checksum":111199418,"timestamp":"2024-06-01T17:52:30.999676Z"}]}
{"channel":"book","type":"update","data":[{"symbol":"LTC/USD","bids":[{"price":83.20,"qty":0.00000000},{"price":83.10,"qty":7.68750000}],"asks":[],"checksum":2055666080,"timestamp":"2024-06-01T17:52:30.999885Z"}]}
{"channel":"book","type":"update","data":[{"symbol":"LTC/USD","bids":[{"price":83.20,"qty":7.68750000}],"asks":[],"checksum":111199418,"timestamp":"2024-06-01T17:52:31.003235Z"}]}
{"channel":"book","type":"update","data":[{"symbol":"LTC/USD","bids":[{"price":83.20,"qty":15.37500000}],"asks":[],"checksum":529002743,"timestamp":"2024-06-01T17:52:31.004023Z"}]}
{"channel":"book","type":"update","data":[{"symbol":"LTC/USD","bids":[],"asks":[{"price":83.22,"qty":37.59094927}],"checksum":3288128403,"timestamp":"2024-06-01T17:52:31.007039Z"}]}
{"channel":"book","type":"update","data":[{"symbol":"LTC/USD","bids":[{"price":83.20,"qty":7.68750000}],"asks":[],"checksum":2877714324,"timestamp":"2024-06-01T17:52:31.008654Z"}]}
{"channel":"book","type":"update","data":[{"symbol":"LTC/USD","bids":[{"price":83.20,"qty":0.00000000},{"price":83.10,"qty":7.68750000}],"asks":[],"checksum":3617608334,"timestamp":"2024-06-01T17:52:31.008819Z"}]}
{"channel":"book","type":"update","data":[{"symbol":"LTC/USD","bids":[],"asks":[{"price":83.22,"qty":45.27844927}],"checksum":2055666080,"timestamp":"2024-06-01T17:52:31.011598Z"}]}
{"channel":"book","type":"update","data":[{"symbol":"LTC/USD","bids":[{"price":83.20,"qty":7.68750000}],"asks":[],"checksum":111199418,"timestamp":"2024-06-01T17:52:31.023249Z"}]}
{"channel":"book","type":"update","data":[{"symbol":"LTC/USD","bids":[{"price":83.20,"qty":15.37500000}],"asks":[],"checksum":529002743,"timestamp":"2024-06-01T17:52:31.025139Z"}]}
{"channel":"book","type":"update","data":[{"symbol":"LTC/USD","bids":[],"asks":[{"price":83.22,"qty":37.59094927}],"checksum":3288128403,"timestamp":"2024-06-01T17:52:31.028916Z"}]}
{"channel":"book","type":"update","data":[{"symbol":"LTC/USD","bids":[{"price":83.20,"qty":7.68750000}],"asks":[],"checksum":2877714324,"timestamp":"2024-06-01T17:52:31.031841Z"}]}
{"channel":"book","type":"update","data":[{"symbol":"LTC/USD","bids":[{"price":83.20,"qty":15.37500000}],"asks":[],"checksum":3288128403,"timestamp":"2024-06-01T17:52:31.036202Z"}]}
{"channel":"book","type":"update","data":[{"symbol":"LTC/USD","bids":[{"price":83.20,"qty":7.68750000}],"asks":[],"checksum":2877714324,"timestamp":"2024-06-01T17:52:31.040898Z"}]}
{"channel":"book","type":"update","data":[{"symbol":"LTC/USD","bids":[{"price":83.20,"qty":0.00000000},{"price":83.10,"qty":7.68750000}],"asks":[],"checksum":3617608334,"timestamp":"2024-06-01T17:52:31.041972Z"}]}
{"channel":"book","type":"update","data":[{"symbol":"LTC/USD","bids":[{"price":83.20,"qty":7.68750000}],"asks":[],"checksum":2877714324,"timestamp":"2024-06-01T17:52:31.052212Z"}]}
{"channel":"book","type":"update","data":[{"symbol":"LTC/USD","bids":[],"asks":[{"price":83.22,"qty":45.27844927}],"checksum":111199418,"timestamp":"2024-06-01T17:52:31.058034Z"}]}
{"channel":"book","type":"update","data":[{"symbol":"LTC/USD","bids":[{"price":83.20,"qty":15.37500000}],"asks":[],"checksum":529002743,"timestamp":"2024-06-01T17:52:31.071302Z"}]}
{"channel":"book","type":"update","data":[{"symbol":"LTC/USD","bids":[{"price":83.19,"qty":20.77500000}],"asks":[],"checksum":607117785,"timestamp":"2024-06-01T17:52:31.077970Z"}]}
{"channel":"book","type":"update","data":[{"symbol":"LTC/USD","bids":[{"price":83.20,"qty":7.68750000}],"asks":[],"checksum":1023989140,"timestamp":"2024-06-01T17:52:31.086293Z"}]}
{"channel":"book","type":"update","data":[{"symbol":"LTC/USD","bids":[],"asks":[{"price":83.26,"qty":287.26907347}],"checksum":3516016368,"timestamp":"2024-06-01T17:52:31.087527Z"}]}
{"channel":"book","type":"update","data":[{"symbol":"LTC/USD","bids":[{"price":83.16,"qty":208.09067815}],"asks":[],"checksum":1851769631,"timestamp":"2024-06-01T17:52:31.091128Z"}]}
{"channel":"book","type":"update","data":[{"symbol":"LTC/USD","bids":[{"price":83.20,"qty":0.00000000},{"price":83.10,"qty":7.68750000}],"asks":[],"checksum":3750437271,"timestamp":"2024-06-01T17:52:31.095500Z"}]}
{"channel":"book","type":"update","data":[{"symbol":"LTC/USD","bids":[],"asks":[{"price":83.26,"qty":279.71907347}],"checksum":830915420,"timestamp":"2024-06-01T17:52:31.096514Z"}]}
{"channel":"book","type":"update","data":[{"symbol":"LTC/USD","bids":[{"price":83.20,"qty":7.68750000}],"asks":[],"checksum":2152866260,"timestamp":"2024-06-01T17:52:31.099872Z"}]}
{"channel":"book","type":"update","data":[{"symbol":"LTC/USD","bids":[{"price":83.16,"qty":201.05905973}],"asks":[],"checksum":1067435067,"timestamp":"2024-06-01T17:52:31.103512Z"}]}
{"channel":"book","type":"update","data":[{"symbol":"LTC/USD","bids":[{"price":83.20,"qty":0.00000000},{"price":83.10,"qty":7.68750000}],"asks":[],"checksum":2107190299,"timestamp":"2024-06-01T17:52:31.107766Z"}]}
{"channel":"book","type":"update","data":[{"symbol":"LTC/USD","bids":[{"price":83.20,"qty":7.68750000}],"asks":[],"checksum":1067435067,"timestamp":"2024-06-01T17:52:31.108571Z"}]}
{"channel":"book","type":"update","data":[{"symbol":"LTC/USD","bids":[{"price":83.20,"qty":15.37500000}],"asks":[],"checksum":1648674993,"timestamp":"2024-06-01T17:52:31.114321Z"}]}
{"channel":"book","type":"update","data":[{"symbol":"LTC/USD","bids":[{"price":83.20,"qty":7.68750000}],"asks":[],"checksum":1067435067,"timestamp":"2024-06-01T17:52:31.116348Z"}]}
{"channel":"book","type":"update","data":[{"symbol":"LTC/USD","bids":[{"price":83.20,"qty":0.00000000},{"price":83.10,"qty":7.68750000}],"asks":[],"checksum":2107190299,"timestamp":"2024-06-01T17:52:31.117192Z"}]}
{"channel":"book","type":"update","data":[{"symbol":"LTC/USD","bids":[],"asks":[{"price":83.21,"qty":0.00000000},{"price":83.32,"qty":67.32692115},{"price":83.20,"qty":7.55000000}],"checksum":425131103,"timestamp":"2024-06-01T17:52:31.135979Z"}]}
{"channel":"book","type":"update","data":[{"symbol":"LTC/USD","bids":[],"asks":[{"price":83.20,"qty":15.10000000}],"checksum":2987218983,"timestamp":"2024-06-01T17:52:31.141476Z"}]}
{"channel":"book","type":"update","data":[{"symbol":"LTC/USD","bids":[],"asks":[{"price":83.20,"qty":7.55000000}],"checksum":425131103,"timestamp":"2024-06-01T17:52:31.141517Z"}]}
{"channel":"book","type":"update","data":[{"symbol":"LTC/USD","bids":[],"asks":[{"price":83.24,"qty":127.00540997}],"checksum":3827423824,"timestamp":"2024-06-01T17:52:31.203207Z"}]}
{"channel":"book","type":"update","data":[{"symbol":"LTC/USD","bids":[],"asks":[{"price":83.29,"qty":54.06800000}],"checksum":1849719950,"timestamp":"2024-06-01T17:52:31.214994Z"}]}
{"channel":"book","type":"update","data":[{"symbol":"LTC/USD","bids":[],"asks":[{"price":83.21,"qty":7.68750000}],"checksum":1053942588,"timestamp":"2024-06-01T17:52:31.219910Z"}]}
{"channel":"book","type":"update","data":[{"symbol":"LTC/USD","bids":[],"asks":[{"price":83.21,"qty":0.00000000},{"price":83.31,"qty":101.51523200}],"checksum":1849719950,"timestamp":"2024-06-01T17:52:31.224560Z"}]}
{"channel":"book","type":"update","data":[{"symbol":"LTC/USD","bids":[{"price":83.16,"qty":208.09067815}],"asks":[],"checksum":576689097,"timestamp":"2024-06-01T17:52:31.225783Z"}]}
{"channel":"book","type":"update","data":[{"symbol":"LTC/USD","bids":[],"asks":[{"price":83.21,"qty":7.68750000}],"checksum":1926106235,"timestamp":"2024-06-01T17:52:31.230005Z"}]}
{"channel":"book","type":"update","data":[{"symbol":"LTC/USD","bids":[],"asks":[{"price":83.21,"qty":0.00000000},{"price":83.31,"qty":101.51523200}],"checksum":576689097,"timestamp":"2024-06-01T17:52:31.233512Z"}]}
{"channel":"book","type":"update","data":[{"symbol":"LTC/USD","bids":[{"price":83.19,"qty":13.08750000}],"asks":[],"checksum":1197161334,"timestamp":"2024-06-01T17:52:31.238032Z"}]}
{"channel":"book","type":"update","data":[{"symbol":"LTC/USD","bids":[],"asks":[{"price":83.21,"qty":7.68750000}],"checksum":399156420,"timestamp":"2024-06-01T17:52:31.239566Z"}]}
{"channel":"book","type":"update","data":[{"symbol":"LTC/USD","bids":[{"price":83.19,"qty":20.77500000}],"asks":[],"checksum":1926106235,"timestamp":"2024-06-01T17:52:31.242129Z"}]}
{"channel":"book","type":"update","data":[{"symbol":"LTC/USD","bids":[],"asks":[{"price":83.21,"qty":0.00000000},{"price":83.31,"qty":101.51523200}],"checksum":576689097,"timestamp":"2024-06-01T17:52:31.245478Z"}]}
{"channel":"book","type":"update","data":[{"symbol":"LTC/USD","bids":[{"price":83.16,"qty":215.64067815},{"price":83.14,"qty":331.83595128},{"price":83.12,"qty":134.21290391}],"asks":[],"checksum":3437075034,"timestamp":"2024-06-01T17:52:31.249079Z"}]}
{"channel":"book","type":"update","data":[{"symbol":"LTC/USD","bids":[{"price":83.12,"qty":126.66290391}],"asks":[],"checksum":3400058382,"timestamp":"2024-06-01T17:52:31.251060Z"}]}
{"channel":"book","type":"update","data":[{"symbol":"LTC/USD","bids":[],"asks":[{"price":83.20,"qty":0.00000000},{"price":83.32,"qty":67.32692115}],"checksum":3320571324,"timestamp":"2024-06-01T17:52:31.251219Z"}]}
{"channel":"book","type":"update","data":[{"symbol":"LTC/USD","bids":[{"price":83.16,"qty":208.60905973}],"asks":[],"checksum":618631158,"timestamp":"2024-06-01T17:52:31.252101Z"}]}
{"channel":"book","type":"update","data":[{"symbol":"LTC/USD","bids":[{"price":83.19,"qty":13.08750000}],"asks":[],"checksum":1104881481,"timestamp":"2024-06-01T17:52:31.253560Z"}]}
{"channel":"book","type":"update","data":[{"symbol":"LTC/USD","bids":[],"asks":[{"price":83.21,"qty":7.68750000}],"checksum":4034879876,"timestamp":"2024-06-01T17:52:31.257637Z"}]}
{"channel":"book","type":"update","data":[{"symbol":"LTC/USD","bids":[{"price":83.19,"qty":20.77500000}],"asks":[],"checksum":2507917627,"timestamp":"2024-06-01T17:52:31.259319Z"}]}
{"channel":"book","type":"update","data":[{"symbol":"LTC/USD","bids":[],"asks":[{"price":83.21,"qty":0.00000000},{"price":83.32,"qty":67.32692115}],"checksum":618631158,"timestamp":"2024-06-01T17:52:31.260795Z"}]}
{"channel":"book","type":"update","data":[{"symbol":"LTC/USD","bids":[],"asks":[{"price":83.27,"qty":3.54763685},{"price":83.25,"qty":68.92101857}],"checksum":3081689831,"timestamp":"2024-06-01T17:52:31.266624Z"}]}
{"channel":"book","type":"update","data":[{"symbol":"LTC/USD","bids":[],"asks":[{"price":83.21,"qty":7.68750000}],"checksum":3556783195,"timestamp":"2024-06-01T17:52:31.270155Z"}]}
{"channel":"book","type":"update","data":[{"symbol":"LTC/USD","bids":[],"asks":[{"price":83.21,"qty":15.37500000}],"checksum":2486633913,"timestamp":"2024-06-01T17:52:31.270759Z"}]}
{"channel":"book","type":"update","data":[{"symbol":"LTC/USD","bids":[],"asks":[{"price":83.21,"qty":7.68750000}],"checksum":3556783195,"timestamp":"2024-06-01T17:52:31.275140Z"}]}
{"channel":"book","type":"update","data":[{"symbol":"LTC/USD","bids":[{"price":83.16,"qty":201.05905973}],"asks":[],"checksum":1219271985,"timestamp":"2024-06-01T17:52:31.344630Z"}]}
{"channel":"book","type":"update","data":[{"symbol":"LTC/USD","bids":[{"price":83.12,"qty":134.21290391}],"asks":[],"checksum":1322893669,"timestamp":"2024-06-01T17:52:31.350267Z"}]}
{"channel":"book","type":"update","data":[{"symbol":"LTC/USD","bids":[],"asks":[{"price":83.21,"qty":0.00000000},{"price":83.32,"qty":67.32692115}],"checksum":762785753,"timestamp":"2024-06-01T17:52:31.351137Z"}]}
{"channel":"book","type":"update","data":[{"symbol":"LTC/USD","bids":[],"asks":[{"price":83.22,"qty":52.96594927}],"checksum":1863625225,"timestamp":"2024-06-01T17:52:31.355285Z"}]}
{"channel":"book","type":"update","data":[{"symbol":"LTC/USD","bids":[{"price":83.14,"qty":324.28595128}],"asks":[],"checksum":3060061097,"timestamp":"2024-06-01T17:52:31.355587Z"}]}
{"channel":"book","type":"update","data":[{"symbol":"LTC/USD","bids":[],"asks":[{"price":83.21,"qty":7.68750000}],"checksum":242329956,"timestamp":"2024-06-01T17:52:31.356359Z"}]}
{"channel":"book","type":"update","data":[{"symbol":"LTC/USD","bids":[],"asks":[{"price":83.21,"qty":0.00000000},{"price":83.32,"qty":67.32692115}],"checksum":3060061097,"timestamp":"2024-06-01T17:52:31.365067Z"}]}
{"channel":"book","type":"update","data":[{"symbol":"LTC/USD","bids":[{"price":83.15,"qty":26.77908892}],"asks":[],"checksum":524875670,"timestamp":"2024-06-01T17:52:31.372840Z"}]}
{"channel":"book","type":"update","data":[{"symbol":"LTC/USD","bids":[],"asks":[{"price":83.21,"qty":7.68750000}],"checksum":2807926107,"timestamp":"2024-06-01T17:52:31.394124Z"}]}
{"channel":"book","type":"update","data":[{"symbol":"LTC/USD","bids":[],"asks":[{"price":83.21,"qty":0.00000000},{"price":83.32,"qty":67.32692115}],"checksum":524875670,"timestamp":"2024-06-01T17:52:31.402900Z"}]}
{"channel":"book","type":"update","data":[{"symbol":"LTC/USD","bids":[],"asks":[{"price":83.21,"qty":7.68750000}],"checksum":2807926107,"timestamp":"2024-06-01T17:52:31.407132Z"}]}
{"channel":"book","type":"update","data":[{"symbol":"LTC/USD","bids":[],"asks":[{"price":83.21,"qty":0.00000000},{"price":83.32,"qty":67.32692115}],"checksum":524875670,"timestamp":"2024-06-01T17:52:31.410721Z"}]}
{"channel":"book","type":"update","data":[{"symbol":"LTC/USD","bids":[],"asks":[{"price":83.21,"qty":7.68750000}],"checksum":2807926107,"timestamp":"2024-06-01T17:52:31.415080Z"}]}
{"channel":"book","type":"update","data":[{"symbol":"LTC/USD","bids":[],"asks":[{"price":83.21,"qty":0.00000000},{"price":83.32,"qty":67.32692115}],"checksum":524875670,"timestamp":"2024-06-01T17:52:31.417896Z"}]}
{"channel":"book","type":"update","data":[{"symbol":"LTC/USD","bids":[{"price":83.16,"qty":208.60905973},{"price":83.14,"qty":331.83595128}],"asks":[],"checksum":1519658844,"timestamp":"2024-06-01T17:52:31.418844Z"}]}
{"channel":"book","type":"update","data":[{"symbol":"LTC/USD","bids":[{"price":83.13,"qty":10.71701062}],"asks":[],"checksum":2511399919,"timestamp":"2024-06-01T17:52:31.424647Z"}]}
{"channel":"book","type":"update","data":[{"symbol":"LTC/USD","bids":[],"asks":[{"price":83.21,"qty":7.55000000}],"checksum":4153222169,"timestamp":"2024-06-01T17:52:31.445661Z"}]}
{"channel":"book","type":"update","data":[{"symbol":"LTC/USD","bids":[],"asks":[{"price":83.21,"qty":15.23750000}],"checksum":2143203208,"timestamp":"2024-06-01T17:52:31.474855Z"}]}
{"channel":"book","type":"update","data":[{"symbol":"LTC/USD","bids":[],"asks":[{"price":83.21,"qty":7.55000000}],"checksum":4153222169,"timestamp":"2024-06-01T17:52:31.500518Z"}]}
{"channel":"book","type":"update","data":[{"symbol":"LTC/USD","bids":[],"asks":[{"price":83.21,"qty":15.23750000}],"checksum":2143203208,"timestamp":"2024-06-01T17:52:31.531876Z"}]}
{"channel":"book","type":"update","data":[{"symbol":"LTC/USD","bids":[{"price":83.12,"qty":126.66290391}],"asks":[],"checksum":2043409372,"timestamp":"2024-06-01T17:52:31.537843Z"}]}
{"channel":"book","type":"update","data":[{"symbol":"LTC/USD","bids":[],"asks":[{"price":83.21,"qty":7.55000000}],"checksum":4059592781,"timestamp":"2024-06-01T17:52:31.543749Z"}]}
{"channel":"book","type":"update","data":[{"symbol":"LTC/USD","bids":[],"asks":[{"price":83.25,"qty":8.86101857}],"checksum":15221224,"timestamp":"2024-06-01T17:52:31.609388Z"}]}
{"channel":"book","type":"update","data":[{"symbol":"LTC/USD","bids":[],"asks":[{"price":83.21,"qty":0.00000000},{"price":83.32,"qty":67.32692115}],"checksum":2949203807,"timestamp":"2024-06-01T17:52:31.617088Z"}]}
{"channel":"book","type":"update","data":[{"symbol":"LTC/USD","bids":[{"price":83.17,"qty":32.56482151}],"asks":[],"checksum":1340786065,"timestamp":"2024-06-01T17:52:31.621051Z"}]}
{"channel":"book","type":"update","data":[{"symbol":"LTC/USD","bids":[],"asks":[{"price":83.22,"qty":45.41594927}],"checksum":3233132354,"timestamp":"2024-06-01T17:52:31.639360Z"}]}
{"channel":"book","type":"update","data":[{"symbol":"LTC/USD","bids":[{"price":83.20,"qty":7.68750000}],"asks":[],"checksum":2142020613,"timestamp":"2024-06-01T17:52:31.645318Z"}]}
{"channel":"book","type":"update","data":[{"symbol":"LTC/USD","bids":[{"price":83.20,"qty":0.00000000},{"price":83.10,"qty":7.68750000}],"asks":[],"checksum":3233132354,"timestamp":"2024-06-01T17:52:31.648620Z"}]}
{"channel":"book","type":"update","data":[{"symbol":"LTC/USD","bids":[{"price":83.20,"qty":7.68750000}],"asks":[],"checksum":2142020613,"timestamp":"2024-06-01T17:52:31.703423Z"}]}
{"channel":"book","type":"update","data":[{"symbol":"LTC/USD","bids":[{"price":83.20,"qty":15.37500000}],"asks":[],"checksum":2902894629,"timestamp":"2024-06-01T17:52:31.703620Z"}]}
{"channel":"book","type":"update","data":[{"symbol":"LTC/USD","bids":[{"price":83.20,"qty":7.68750000}],"asks":[],"checksum":2142020613,"timestamp":"2024-06-01T17:52:31.706965Z"}]}
{"channel":"book","type":"update","data":[{"symbol":"LTC/USD","bids":[],"asks":[{"price":83.22,"qty":37.72844927}],"checksum":3975951639,"timestamp":"2024-06-01T17:52:31.707076Z"}]}
{"channel":"book","type":"update","data":[{"symbol":"LTC/USD","bids":[],"asks":[{"price":83.29,"qty":61.75550000}],"checksum":374847659,"timestamp":"2024-06-01T17:52:31.710246Z"}]}
{"channel":"book","type":"update","data":[{"symbol":"LTC/USD","bids":[{"price":83.20,"qty":15.37500000}],"asks":[],"checksum":2617368022,"timestamp":"2024-06-01T17:52:31.710784Z"}]}
{"channel":"book","type":"update","data":[{"symbol":"LTC/USD","bids":[],"asks":[{"price":83.24,"qty":119.45540997}],"checksum":4017954107,"timestamp":"2024-06-01T17:52:31.714170Z"}]}
{"channel":"book","type":"update","data":[{"symbol":"LTC/USD","bids":[],"asks":[{"price":83.26,"qty":287.26907347}],"checksum":1202126216,"timestamp":"2024-06-01T17:52:31.717751Z"}]}
{"channel":"book","type":"update","data":[{"symbol":"LTC/USD","bids":[],"asks":[{"price":83.24,"qty":127.00540997}],"checksum":886717797,"timestamp":"2024-06-01T17:52:31.745091Z"}]}
{"channel":"book","type":"update","data":[{"symbol":"LTC/USD","bids":[],"asks":[{"price":83.24,"qty":124.01540997}],"checksum":1666211755,"timestamp":"2024-06-01T17:52:31.755807Z"}]}
{"channel":"book","type":"update","data":[{"symbol":"LTC/USD","bids":[{"price":83.17,"qty":30.70618232}],"asks":[],"checksum":270623066,"timestamp":"2024-06-01T17:52:31.813276Z"}]}
{"channel":"book","type":"update","data":[{"symbol":"LTC/USD","bids":[{"price":83.15,"qty":17.60996408}],"asks":[],"checksum":891273676,"timestamp":"2024-06-01T17:52:31.813369Z"}]}
{"channel":"book","type":"update","data":[{"symbol":"LTC/USD","bids":[],"asks":[{"price":83.27,"qty":63.60763685}],"checksum":1032603853,"timestamp":"2024-06-01T17:52:31.816546Z"}]}
{"channel":"book","type":"update","data":[{"symbol":"LTC/USD","bids":[{"price":83.15,"qty":25.35496721}],"asks":[],"checksum":694427660,"timestamp":"2024-06-01T17:52:31.818260Z"}]}
{"channel":"book","type":"update","data":[{"symbol":"LTC/USD","bids":[{"price":83.17,"qty":31.65012805}],"asks":[],"checksum":3609664947,"timestamp":"2024-06-01T17:52:31.818497Z"}]}
{"channel":"book","type":"update","data":[{"symbol":"LTC/USD","bids":[],"asks":[{"price":83.25,"qty":16.12170500}],"checksum":2338352435,"timestamp":"2024-06-01T17:52:31.826399Z"}]}
{"channel":"book","type":"update","data":[{"symbol":"LTC/USD","bids":[],"asks":[{"price":83.22,"qty":45.27844927}],"checksum":1611678828,"timestamp":"2024-06-01T17:52:31.888522Z"}]}
{"channel":"book","type":"update","data":[{"symbol":"LTC/USD","bids":[],"asks":[{"price":83.22,"qty":52.96594927}],"checksum":2096805055,"timestamp":"2024-06-01T17:52:31.906964Z"}]}
{"channel":"book","type":"update","data":[{"symbol":"LTC/USD","bids":[{"price":83.20,"qty":7.68750000}],"asks":[],"checksum":108726025,"timestamp":"2024-06-01T17:52:31.907248Z"}]}
{"channel":"book","type":"update","data":[{"symbol":"LTC/USD","bids":[{"price":83.20,"qty":0.00000000},{"price":83.10,"qty":8.10669724}],"asks":[],"checksum":863466151,"timestamp":"2024-06-01T17:52:31.907279Z"}]}
{"channel":"book","type":"update","data":[{"symbol":"LTC/USD","bids":[{"price":83.20,"qty":7.68750000}],"asks":[],"checksum":108726025,"timestamp":"2024-06-01T17:52:31.924047Z"}]}
{"channel":"book","type":"update","data":[{"symbol":"LTC/USD","bids":[{"price":83.20,"qty":0.00000000},{"price":83.10,"qty":8.10669724}],"asks":[],"checksum":863466151,"timestamp":"2024-06-01T17:52:31.927590Z"}]}
{"channel":"book","type":"update","data":[{"symbol":"LTC/USD","bids":[],"asks":[{"price":83.26,"qty":279.71907347},{"price":83.21,"qty":7.55000000}],"checksum":1756428680,"timestamp":"2024-06-01T17:52:31.928901Z"}]}
{"channel":"book","type":"update","data":[{"symbol":"LTC/USD","bids":[],"asks":[{"price":83.21,"qty":0.00000000},{"price":83.32,"qty":67.32692115}],"checksum":2611778068,"timestamp":"2024-06-01T17:52:31.933672Z"}]}
{"channel":"book","type":"update","data":[{"symbol":"LTC/USD","bids":[],"asks":[{"price":83.21,"qty":7.55000000}],"checksum":1756428680,"timestamp":"2024-06-01T17:52:31.933718Z"}]}
{"channel":"book","type":"update","data":[{"symbol":"LTC/USD","bids":[],"asks":[{"price":83.24,"qty":112.54040997}],"checksum":3231194917,"timestamp":"2024-06-01T17:52:32.057960Z"}]}
{"channel":"book","type":"update","data":[{"symbol":"LTC/USD","bids":[],"asks":[{"price":83.25,"qty":27.49070500}],"checksum":4040618373,"timestamp":"2024-06-01T17:52:32.060806Z"}]}
{"channel":"book","type":"update","data":[{"symbol":"LTC/USD","bids":[],"asks":[{"price":83.24,"qty":132.54040997}],"checksum":1330923693,"timestamp":"2024-06-01T17:52:32.063485Z"}]}
{"channel":"book","type":"update","data":[{"symbol":"LTC/USD","bids":[],"asks":[{"price":83.25,"qty":20.23001857}],"checksum":2556304403,"timestamp":"2024-06-01T17:52:32.178491Z"}]}
{"channel":"book","type":"update","data":[{"symbol":"LTC/USD","bids":[],"asks":[{"price":83.21,"qty":0.00000000},{"price":83.32,"qty":67.32692115}],"checksum":2860810679,"timestamp":"2024-06-01T17:52:32.315543Z"}]}
{"channel":"book","type":"update","data":[{"symbol":"LTC/USD","bids":[],"asks":[{"price":83.26,"qty":287.26907347}],"checksum":39805188,"timestamp":"2024-06-01T17:52:32.502985Z"}]}
{"channel":"book","type":"update","data":[{"symbol":"LTC/USD","bids":[{"price":83.15,"qty":45.35496721}],"asks":[],"checksum":3047877743,"timestamp":"2024-06-01T17:52:32.508919Z"}]}
{"channel":"book","type":"update","data":[{"symbol":"LTC/USD","bids":[],"asks":[{"price":83.21,"qty":7.68750000}],"checksum":1886892578,"timestamp":"2024-06-01T17:52:32.536706Z"}]}
{"channel":"book","type":"update","data":[{"symbol":"LTC/USD","bids":[],"asks":[{"price":83.21,"qty":0.00000000},{"price":83.32,"qty":67.32692115}],"checksum":3047877743,"timestamp":"2024-06-01T17:52:32.545005Z"}]}
{"channel":"book","type":"update","data":[{"symbol":"LTC/USD","bids":[],"asks":[{"price":83.21,"qty":7.68750000}],"checksum":1886892578,"timestamp":"2024-06-01T17:52:32.886959Z"}]}
{"channel":"book","type":"update","data":[{"symbol":"LTC/USD","bids":[],"asks":[{"price":83.29,"qty":54.06800000}],"checksum":4195751164,"timestamp":"2024-06-01T17:52:32.999589Z"}]}
{"channel":"book","type":"update","data":[{"symbol":"LTC/USD","bids":[],"asks":[{"price":83.21,"qty":15.37500000}],"checksum":3025313945,"timestamp":"2024-06-01T17:52:33.000345Z"}]}
{"channel":"book","type":"update","data":[{"symbol":"LTC/USD","bids":[],"asks":[{"price":83.21,"qty":7.68750000}],"checksum":4195751164,"timestamp":"2024-06-01T17:52:33.097670Z"}]}
{"channel":"book","type":"update","data":[{"symbol":"LTC/USD","bids":[],"asks":[{"price":83.21,"qty":0.00000000},{"price":83.32,"qty":67.32692115}],"checksum":1325490643,"timestamp":"2024-06-01T17:52:33.724878Z"}]}
{"channel":"book","type":"update","data":[{"symbol":"LTC/USD","bids":[],"asks":[{"price":83.26,"qty":279.71907347},{"price":83.21,"qty":7.55000000}],"checksum":2781493158,"timestamp":"2024-06-01T17:52:33.729355Z"}]}
{"channel":"book","type":"update","data":[{"symbol":"LTC/USD","bids":[],"asks":[{"price":83.21,"qty":15.10000000}],"checksum":2561467215,"timestamp":"2024-06-01T17:52:33.733930Z"}]}
{"channel":"book","type":"update","data":[{"symbol":"LTC/USD","bids":[],"asks":[{"price":83.21,"qty":7.55000000}],"checksum":2781493158,"timestamp":"2024-06-01T17:52:33.734006Z"}]}
{"channel":"book","type":"update","data":[{"symbol":"LTC/USD","bids":[],"asks":[{"price":83.21,"qty":15.23750000}],"checksum":575318015,"timestamp":"2024-06-01T17:52:33.799453Z"}]}
{"channel":"book","type":"update","data":[{"symbol":"LTC/USD","bids":[],"asks":[{"price":83.21,"qty":22.92500000}],"checksum":4244584805,"timestamp":"2024-06-01T17:52:34.041229Z"}]}
{"channel":"book","type":"update","data":[{"symbol":"LTC/USD","bids":[],"asks":[{"price":83.21,"qty":15.23750000}],"checksum":575318015,"timestamp":"2024-06-01T17:52:34.047607Z"}]}
{"channel":"book","type":"update","data":[{"symbol":"LTC/USD","bids":[{"price":83.15,"qty":38.32250313}],"asks":[],"checksum":4153504445,"timestamp":"2024-06-01T17:52:34.348922Z"}]}
{"channel":"book","type":"update","data":[{"symbol":"LTC/USD","bids":[],"asks":[{"price":83.21,"qty":22.92500000}],"checksum":690285607,"timestamp":"2024-06-01T17:52:34.373312Z"}]}
{"channel":"book","type":"update","data":[{"symbol":"LTC/USD","bids":[{"price":83.19,"qty":13.08750000}],"asks":[],"checksum":1277183128,"timestamp":"2024-06-01T17:52:34.374345Z"}]}
{"channel":"book","type":"update","data":[{"symbol":"LTC/USD","bids":[{"price":83.19,"qty":5.40000000}],"asks":[],"checksum":756505100,"timestamp":"2024-06-01T17:52:34.374504Z"}]}
{"channel":"book","type":"update","data":[{"symbol":"LTC/USD","bids":[{"price":83.16,"qty":215.64067815}],"asks":[],"checksum":3424858182,"timestamp":"2024-06-01T17:52:34.467586Z"}]}
{"channel":"book","type":"update","data":[{"symbol":"LTC/USD","bids":[{"price":83.19,"qty":13.08750000}],"asks":[],"checksum":2903781074,"timestamp":"2024-06-01T17:52:34.599407Z"}]}
{"channel":"book","type":"update","data":[{"symbol":"LTC/USD","bids":[{"price":83.19,"qty":20.77500000}],"asks":[],"checksum":3356526189,"timestamp":"2024-06-01T17:52:34.791295Z"}]}
{"channel":"book","type":"update","data":[{"symbol":"LTC/USD","bids":[],"asks":[{"price":83.21,"qty":15.23750000}],"checksum":379918583,"timestamp":"2024-06-01T17:52:34.791444Z"}]}
{"channel":"book","type":"update","data":[{"symbol":"LTC/USD","bids":[],"asks":[{"price":83.21,"qty":22.92500000}],"checksum":3356526189,"timestamp":"2024-06-01T17:52:34.842881Z"}]}
{"channel":"book","type":"update","data":[{"symbol":"LTC/USD","bids":[{"price":83.17,"qty":24.10012805}],"asks":[],"checksum":2725016411,"timestamp":"2024-06-01T17:52:34.865923Z"}]}
{"channel":"book","type":"update","data":[{"symbol":"LTC/USD","bids":[{"price":83.16,"qty":208.09067815}],"asks":[],"checksum":2481676092,"timestamp":"2024-06-01T17:52:34.870447Z"}]}
{"channel":"book","type":"update","data":[{"symbol":"LTC/USD","bids":[{"price":83.19,"qty":13.08750000}],"asks":[],"checksum":4142921603,"timestamp":"2024-06-01T17:52:34.919066Z"}]}
{"channel":"book","type":"update","data":[{"symbol":"LTC/USD","bids":[{"price":83.19,"qty":5.40000000}],"asks":[],"checksum":2547575063,"timestamp":"2024-06-01T17:52:34.919121Z"}]}
{"channel":"book","type":"update","data":[{"symbol":"LTC/USD","bids":[{"price":83.17,"qty":31.65012805},{"price":83.16,"qty":215.64067815}],"asks":[],"checksum":3424858182,"timestamp":"2024-06-01T17:52:35.103204Z"}]}
{"channel":"book","type":"update","data":[{"symbol":"LTC/USD","bids":[{"price":83.15,"qty":30.57750000}],"asks":[],"checksum":2936349653,"timestamp":"2024-06-01T17:52:35.283045Z"}]}
{"channel":"book","type":"update","data":[{"symbol":"LTC/USD","bids":[{"price":83.10,"qty":7.68750000}],"asks":[],"checksum":2289499547,"timestamp":"2024-06-01T17:52:35.283122Z"}]}
{"channel":"book","type":"update","data":[{"symbol":"LTC/USD","bids":[{"price":83.17,"qty":30.70618232}],"asks":[],"checksum":3283883192,"timestamp":"2024-06-01T17:52:35.283130Z"}]}
{"channel":"book","type":"update","data":[{"symbol":"LTC/USD","bids":[{"price":83.19,"qty":13.08750000}],"asks":[],"checksum":2727021100,"timestamp":"2024-06-01T17:52:35.284960Z"}]}
{"channel":"book","type":"update","data":[{"symbol":"LTC/USD","bids":[{"price":83.19,"qty":5.40000000}],"asks":[],"checksum":3283883192,"timestamp":"2024-06-01T17:52:35.505755Z"}]}
{"channel":"book","type":"update","data":[{"symbol":"LTC/USD","bids":[{"price":83.15,"qty":38.56391151}],"asks":[],"checksum":3100882292,"timestamp":"2024-06-01T17:52:35.550325Z"}]}
{"channel":"book","type":"update","data":[{"symbol":"LTC/USD","bids":[{"price":83.17,"qty":33.10504692}],"asks":[],"checksum":4004705684,"timestamp":"2024-06-01T17:52:35.550368Z"}]}
{"channel":"book","type":"update","data":[{"symbol":"LTC/USD","bids":[{"price":83.16,"qty":208.60905973}],"asks":[],"checksum":260480990,"timestamp":"2024-06-01T17:52:35.551386Z"}]}
{"channel":"book","type":"update","data":[{"symbol":"LTC/USD","bids":[{"price":83.16,"qty":215.64067815}],"asks":[],"checksum":4004705684,"timestamp":"2024-06-01T17:52:35.675006Z"}]}
{"channel":"book","type":"update","data":[{"symbol":"LTC/USD","bids":[{"price":83.19,"qty":13.08750000}],"asks":[],"checksum":2407918336,"timestamp":"2024-06-01T17:52:35.917346Z"}]}
{"channel":"book","type":"update","data":[{"symbol":"LTC/USD","bids":[],"asks":[{"price":83.21,"qty":15.23750000}],"checksum":1362130330,"timestamp":"2024-06-01T17:52:35.923073Z"}]}
{"channel":"book","type":"update","data":[{"symbol":"LTC/USD","bids":[],"asks":[{"price":83.21,"qty":22.92500000}],"checksum":2407918336,"timestamp":"2024-06-01T17:52:35.927375Z"}]}
{"channel":"book","type":"update","data":[{"symbol":"LTC/USD","bids":[{"price":83.19,"qty":5.40000000}],"asks":[],"checksum":4004705684,"timestamp":"2024-06-01T17:52:35.932713Z"}]}
{"channel":"book","type":"update","data":[{"symbol":"LTC/USD","bids":[{"price":83.19,"qty":13.08750000}],"asks":[],"checksum":2407918336,"timestamp":"2024-06-01T17:52:36.157263Z"}]}
{"channel":"book","type":"update","data":[{"symbol":"LTC/USD","bids":[{"price":83.19,"qty":5.40000000}],"asks":[],"checksum":4004705684,"timestamp":"2024-06-01T17:52:36.169713Z"}]}
{"channel":"book","type":"update","data":[{"symbol":"LTC/USD","bids":[{"price":83.19,"qty":13.08750000}],"asks":[],"checksum":2407918336,"timestamp":"2024-06-01T17:52:36.549314Z"}]}
{"channel":"book","type":"update","data":[{"symbol":"LTC/USD","bids":[{"price":83.19,"qty":5.40000000}],"asks":[],"checksum":4004705684,"timestamp":"2024-06-01T17:52:36.560992Z"}]}
{"channel":"book","type":"update","data":[{"symbol":"LTC/USD","bids":[{"price":83.19,"qty":13.08750000}],"asks":[],"checksum":2407918336,"timestamp":"2024-06-01T17:52:36.578376Z"}]}
{"channel":"book","type":"update","data":[{"symbol":"LTC/USD","bids":[{"price":83.19,"qty":5.40000000}],"asks":[],"checksum":4004705684,"timestamp":"2024-06-01T17:52:36.702671Z"}]}
{"channel":"book","type":"update","data":[{"symbol":"LTC/USD","bids":[],"asks":[{"price":83.24,"qty":135.53040997}],"checksum":3583121889,"timestamp":"2024-06-01T17:52:36.761855Z"}]}
{"channel":"book","type":"update","data":[{"symbol":"LTC/USD","bids":[{"price":83.17,"qty":21.73604692}],"asks":[],"checksum":2428079866,"timestamp":"2024-06-01T17:52:36.787088Z"}]}
{"channel":"book","type":"update","data":[{"symbol":"LTC/USD","bids":[{"price":83.16,"qty":227.00967815}],"asks":[],"checksum":4193369958,"timestamp":"2024-06-01T17:52:36.789576Z"}]}
{"channel":"book","type":"update","data":[{"symbol":"LTC/USD","bids":[{"price":83.17,"qty":14.18604692}],"asks":[],"checksum":4063931891,"timestamp":"2024-06-01T17:52:36.860944Z"}]}
{"channel":"book","type":"update","data":[{"symbol":"LTC/USD","bids":[{"price":83.16,"qty":219.45967815}],"asks":[],"checksum":2155480088,"timestamp":"2024-06-01T17:52:36.864069Z"}]}
{"channel":"book","type":"update","data":[{"symbol":"LTC/USD","bids":[],"asks":[{"price":83.25,"qty":19.11024429}],"checksum":3678007128,"timestamp":"2024-06-01T17:52:36.972838Z"}]}
{"channel":"book","type":"update","data":[{"symbol":"LTC/USD","bids":[],"asks":[{"price":83.25,"qty":20.05413871}],"checksum":897814947,"timestamp":"2024-06-01T17:52:37.013330Z"}]}
{"channel":"book","type":"update","data":[{"symbol":"LTC/USD","bids":[{"price":83.17,"qty":21.73604692},{"price":83.16,"qty":227.00967815}],"asks":[],"checksum":1275603677,"timestamp":"2024-06-01T17:52:37.031926Z"}]}
{"channel":"book","type":"update","data":[{"symbol":"LTC/USD","bids":[{"price":83.16,"qty":219.97805973}],"asks":[],"checksum":4224388725,"timestamp":"2024-06-01T17:52:37.151017Z"}]}
{"channel":"book","type":"update","data":[{"symbol":"LTC/USD","bids":[{"price":83.16,"qty":227.00967815}],"asks":[],"checksum":1275603677,"timestamp":"2024-06-01T17:52:37.270268Z"}]}
{"channel":"book","type":"update","data":[{"symbol":"LTC/USD","bids":[{"price":83.17,"qty":19.33718232}],"asks":[],"checksum":2814315963,"timestamp":"2024-06-01T17:52:37.646449Z"}]}
{"channel":"book","type":"update","data":[{"symbol":"LTC/USD","bids":[{"price":83.17,"qty":22.37853484}],"asks":[],"checksum":2099154503,"timestamp":"2024-06-01T17:52:37.656127Z"}]}
{"channel":"book","type":"update","data":[{"symbol":"LTC/USD","bids":[{"price":83.17,"qty":14.82853484}],"asks":[],"checksum":490519680,"timestamp":"2024-06-01T17:52:37.814708Z"}]}
{"channel":"book","type":"update","data":[{"symbol":"LTC/USD","bids":[{"price":83.16,"qty":219.45967815}],"asks":[],"checksum":1870402923,"timestamp":"2024-06-01T17:52:37.818207Z"}]}
{"channel":"book","type":"update","data":[{"symbol":"LTC/USD","bids":[{"price":83.14,"qty":324.28595128}],"asks":[],"checksum":3054267595,"timestamp":"2024-06-01T17:52:37.818370Z"}]}
{"channel":"book","type":"update","data":[{"symbol":"LTC/USD","bids":[{"price":83.17,"qty":22.37853484},{"price":83.16,"qty":227.00967815},{"price":83.14,"qty":331.83595128}],"asks":[],"checksum":2099154503,"timestamp":"2024-06-01T17:52:37.950963Z"}]}
{"channel":"book","type":"update","data":[{"symbol":"LTC/USD","bids":[],"asks":[{"price":83.21,"qty":15.37500000}],"checksum":1630723810,"timestamp":"2024-06-01T17:52:37.962390Z"}]}
{"channel":"book","type":"update","data":[{"symbol":"LTC/USD","bids":[],"asks":[{"price":83.22,"qty":45.41594927}],"checksum":907412248,"timestamp":"2024-06-01T17:52:37.968318Z"}]}
{"channel":"book","type":"update","data":[{"symbol":"LTC/USD","bids":[{"price":83.19,"qty":13.08750000}],"asks":[],"checksum":356358971,"timestamp":"2024-06-01T17:52:37.969020Z"}]}
{"channel":"book","type":"update","data":[{"symbol":"LTC/USD","bids":[],"asks":[{"price":83.24,"qty":127.98040997}],"checksum":883684507,"timestamp":"2024-06-01T17:52:37.969333Z"}]}
{"channel":"book","type":"update","data":[{"symbol":"LTC/USD","bids":[],"asks":[{"price":83.21,"qty":7.68750000}],"checksum":2062500094,"timestamp":"2024-06-01T17:52:37.970377Z"}]}
{"channel":"book","type":"update","data":[{"symbol":"LTC/USD","bids":[],"asks":[{"price":83.21,"qty":0.00000000},{"price":83.32,"qty":67.32692115}],"checksum":2809549985,"timestamp":"2024-06-01T17:52:37.970566Z"}]}
{"channel":"book","type":"update","data":[{"symbol":"LTC/USD","bids":[{"price":83.19,"qty":20.77500000}],"asks":[],"checksum":3262315550,"timestamp":"2024-06-01T17:52:37.971041Z"}]}
{"channel":"book","type":"update","data":[{"symbol":"LTC/USD","bids":[],"asks":[{"price":83.21,"qty":7.68750000}],"checksum":535554113,"timestamp":"2024-06-01T17:52:37.974963Z"}]}
{"channel":"book","type":"update","data":[{"symbol":"LTC/USD","bids":[{"price":83.14,"qty":302.91577047}],"asks":[],"checksum":4074786310,"timestamp":"2024-06-01T17:52:37.975206Z"}]}
{"channel":"book","type":"update","data":[{"symbol":"LTC/USD","bids":[{"price":83.19,"qty":13.08750000}],"asks":[],"checksum":2548360889,"timestamp":"2024-06-01T17:52:37.979111Z"}]}
{"channel":"book","type":"update","data":[{"symbol":"LTC/USD","bids":[{"price":83.15,"qty":67.48061425}],"asks":[],"checksum":375608586,"timestamp":"2024-06-01T17:52:37.980223Z"}]}
{"channel":"book","type":"update","data":[{"symbol":"LTC/USD","bids":[],"asks":[{"price":83.21,"qty":15.37500000}],"checksum":1479008623,"timestamp":"2024-06-01T17:52:37.980787Z"}]}
{"channel":"book","type":"update","data":[{"symbol":"LTC/USD","bids":[{"price":83.19,"qty":5.40000000}],"asks":[],"checksum":2013332440,"timestamp":"2024-06-01T17:52:37.982027Z"}]}
{"channel":"book","type":"update","data":[{"symbol":"LTC/USD","bids":[{"price":83.19,"qty":13.08750000}],"asks":[],"checksum":1479008623,"timestamp":"2024-06-01T17:52:37.991564Z"}]}
{"channel":"book","type":"update","data":[{"symbol":"LTC/USD","bids":[],"asks":[{"price":83.21,"qty":7.68750000}],"checksum":375608586,"timestamp":"2024-06-01T17:52:37.993754Z"}]}
{"channel":"book","type":"update","data":[{"symbol":"LTC/USD","bids":[{"price":83.19,"qty":20.77500000}],"asks":[],"checksum":1936194997,"timestamp":"2024-06-01T17:52:37.994368Z"}]}
{"channel":"book","type":"update","data":[{"symbol":"LTC/USD","bids":[],"asks":[{"price":83.21,"qty":0.00000000},{"price":83.32,"qty":67.32692115}],"checksum":2935941610,"timestamp":"2024-06-01T17:52:38.000986Z"}]}
{"channel":"book","type":"update","data":[{"symbol":"LTC/USD","bids":[],"asks":[{"price":83.21,"qty":7.68750000}],"checksum":1936194997,"timestamp":"2024-06-01T17:52:38.014216Z"}]}
{"channel":"book","type":"update","data":[{"symbol":"LTC/USD","bids":[{"price":83.17,"qty":14.82853484},{"price":83.18,"qty":69.14449235}],"asks":[],"checksum":1896331192,"timestamp":"2024-06-01T17:52:38.031763Z"}]}
{"channel":"book","type":"update","data":[{"symbol":"LTC/USD","bids":[],"asks":[{"price":83.21,"qty":0.00000000},{"price":83.32,"qty":67.32692115}],"checksum":2896077799,"timestamp":"2024-06-01T17:52:38.033064Z"}]}
{"channel":"book","type":"update","data":[{"symbol":"LTC/USD","bids":[{"price":83.18,"qty":76.69449235}],"asks":[],"checksum":1835388272,"timestamp":"2024-06-01T17:52:38.034252Z"}]}
{"channel":"book","type":"update","data":[{"symbol":"LTC/USD","bids":[{"price":83.18,"qty":69.14449235},{"price":83.17,"qty":22.37853484}],"asks":[],"checksum":3434909984,"timestamp":"2024-06-01T17:52:38.201746Z"}]}
{"channel":"book","type":"update","data":[{"symbol":"LTC/USD","bids":[{"price":83.18,"qty":61.59449235}],"asks":[],"checksum":2935941610,"timestamp":"2024-06-01T17:52:38.205484Z"}]}
{"channel":"book","type":"update","data":[{"symbol":"LTC/USD","bids":[],"asks":[{"price":83.21,"qty":7.68750000}],"checksum":1936194997,"timestamp":"2024-06-01T17:52:38.213630Z"}]}
{"channel":"book","type":"update","data":[{"symbol":"LTC/USD","bids":[],"asks":[{"price":83.22,"qty":52.96594927},{"price":83.24,"qty":135.53040997},{"price":83.26,"qty":287.26907347}],"checksum":3787673345,"timestamp":"2024-06-01T17:52:38.224189Z"}]}
{"channel":"book","type":"update","data":[{"symbol":"LTC/USD","bids":[],"asks":[{"price":83.21,"qty":0.00000000},{"price":83.32,"qty":67.32692115}],"checksum":2721281830,"timestamp":"2024-06-01T17:52:38.233013Z"}]}
{"channel":"book","type":"update","data":[{"symbol":"LTC/USD","bids":[],"asks":[{"price":83.22,"qty":45.41594927}],"checksum":2772559587,"timestamp":"2024-06-01T17:52:38.259704Z"}]}
{"channel":"book","type":"update","data":[{"symbol":"LTC/USD","bids":[],"asks":[{"price":83.26,"qty":279.71907347}],"checksum":228197968,"timestamp":"2024-06-01T17:52:38.304636Z"}]}
{"channel":"book","type":"update","data":[{"symbol":"LTC/USD","bids":[],"asks":[{"price":83.21,"qty":7.68750000}],"checksum":1391563285,"timestamp":"2024-06-01T17:52:38.307884Z"}]}
{"channel":"book","type":"update","data":[{"symbol":"LTC/USD","bids":[{"price":83.16,"qty":219.97805973}],"asks":[],"checksum":3845306045,"timestamp":"2024-06-01T17:52:38.335783Z"}]}
{"channel":"book","type":"update","data":[{"symbol":"LTC/USD","bids":[],"asks":[{"price":83.21,"qty":0.00000000},{"price":83.32,"qty":67.32692115}],"checksum":3126403832,"timestamp":"2024-06-01T17:52:38.367523Z"}]}
{"channel":"book","type":"update","data":[{"symbol":"LTC/USD","bids":[],"asks":[{"price":83.21,"qty":7.68750000}],"checksum":3845306045,"timestamp":"2024-06-01T17:52:38.407128Z"}]}
{"channel":"book","type":"update","data":[{"symbol":"LTC/USD","bids":[],"asks":[{"price":83.21,"qty":15.23750000},{"price":83.22,"qty":52.96594927}],"checksum":2388449450,"timestamp":"2024-06-01T17:52:38.410832Z"}]}
{"channel":"book","type":"update","data":[{"symbol":"LTC/USD","bids":[{"price":83.16,"qty":227.00967815}],"asks":[],"checksum":966786050,"timestamp":"2024-06-01T17:52:38.461320Z"}]}
{"channel":"book","type":"update","data":[{"symbol":"LTC/USD","bids":[],"asks":[{"price":83.21,"qty":7.68750000}],"checksum":265203146,"timestamp":"2024-06-01T17:52:38.596469Z"}]}
{"channel":"book","type":"update","data":[{"symbol":"LTC/USD","bids":[],"asks":[{"price":83.21,"qty":15.23750000}],"checksum":966786050,"timestamp":"2024-06-01T17:52:38.811249Z"}]}
{"channel":"book","type":"update","data":[{"symbol":"LTC/USD","bids":[],"asks":[{"price":83.21,"qty":7.55000000}],"checksum":3189730395,"timestamp":"2024-06-01T17:52:38.868066Z"}]}
{"channel":"book","type":"update","data":[{"symbol":"LTC/USD","bids":[],"asks":[{"price":83.21,"qty":15.23750000}],"checksum":966786050,"timestamp":"2024-06-01T17:52:38.916584Z"}]}
{"channel":"book","type":"update","data":[{"symbol":"LTC/USD","bids":[],"asks":[{"price":83.21,"qty":7.55000000}],"checksum":3189730395,"timestamp":"2024-06-01T17:52:39.027195Z"}]}
{"channel":"book","type":"update","data":[{"symbol":"LTC/USD","bids":[],"asks":[{"price":83.25,"qty":19.11024429}],"checksum":2493447601,"timestamp":"2024-06-01T17:52:39.090116Z"}]}
{"channel":"book","type":"update","data":[{"symbol":"LTC/USD","bids":[],"asks":[{"price":83.25,"qty":20.52322846}],"checksum":2123590990,"timestamp":"2024-06-01T17:52:39.090686Z"}]}
{"channel":"book","type":"update","data":[{"symbol":"LTC/USD","bids":[],"asks":[{"price":83.21,"qty":15.23750000}],"checksum":4178836759,"timestamp":"2024-06-01T17:52:39.101189Z"}]}
{"channel":"book","type":"update","data":[{"symbol":"LTC/USD","bids":[{"price":83.19,"qty":13.08750000}],"asks":[],"checksum":2618774952,"timestamp":"2024-06-01T17:52:40.781190Z"}]}
{"channel":"book","type":"update","data":[{"symbol":"LTC/USD","bids":[],"asks":[{"price":83.21,"qty":22.92500000}],"checksum":1117965106,"timestamp":"2024-06-01T17:52:40.781351Z"}]}
{"channel":"book","type":"update","data":[{"symbol":"LTC/USD","bids":[{"price":83.19,"qty":5.40000000}],"asks":[],"checksum":671032268,"timestamp":"2024-06-01T17:52:40.781722Z"}]}
{"channel":"book","type":"update","data":[{"symbol":"LTC/USD","bids":[{"price":83.17,"qty":19.33718232}],"asks":[],"checksum":4250837040,"timestamp":"2024-06-01T17:52:40.783740Z"}]}
{"channel":"book","type":"update","data":[{"symbol":"LTC/USD","bids":[{"price":83.15,"qty":59.49420274}],"asks":[],"checksum":149759011,"timestamp":"2024-06-01T17:52:40.783751Z"}]}
{"channel":"book","type":"update","data":[{"symbol":"LTC/USD","bids":[{"price":83.17,"qty":11.78718232}],"asks":[],"checksum":2902653865,"timestamp":"2024-06-01T17:52:40.784487Z"}]}
{"channel":"book","type":"update","data":[{"symbol":"LTC/USD","bids":[{"price":83.19,"qty":13.08750000}],"asks":[],"checksum":3361674071,"timestamp":"2024-06-01T17:52:40.786736Z"}]}
{"channel":"book","type":"update","data":[{"symbol":"LTC/USD","bids":[{"price":83.14,"qty":295.36577047}],"asks":[],"checksum":362921483,"timestamp":"2024-06-01T17:52:40.788129Z"}]}
{"channel":"book","type":"update","data":[{"symbol":"LTC/USD","bids":[{"price":83.16,"qty":219.45967815}],"asks":[],"checksum":1742804960,"timestamp":"2024-06-01T17:52:40.788182Z"}]}
{"channel":"book","type":"update","data":[{"symbol":"LTC/USD","bids":[{"price":83.17,"qty":13.95033967}],"asks":[],"checksum":2344144044,"timestamp":"2024-06-01T17:52:40.799525Z"}]}
{"channel":"book","type":"update","data":[{"symbol":"LTC/USD","bids":[{"price":83.15,"qty":66.32664737}],"asks":[],"checksum":979752260,"timestamp":"2024-06-01T17:52:40.799679Z"}]}
{"channel":"book","type":"update","data":[{"symbol":"LTC/USD","bids":[{"price":83.19,"qty":5.40000000}],"asks":[],"checksum":1597521338,"timestamp":"2024-06-01T17:52:40.840528Z"}]}
{"channel":"book","type":"update","data":[{"symbol":"LTC/USD","bids":[{"price":83.19,"qty":13.08750000}],"asks":[],"checksum":979752260,"timestamp":"2024-06-01T17:52:40.881359Z"}]}
{"channel":"book","type":"update","data":[{"symbol":"LTC/USD","bids":[{"price":83.17,"qty":21.50033967},{"price":83.16,"qty":227.00967815},{"price":83.14,"qty":302.91577047}],"asks":[],"checksum":1754096549,"timestamp":"2024-06-01T17:52:40.952647Z"}]}
{"channel":"book","type":"update","data":[{"symbol":"LTC/USD","bids":[],"asks":[{"price":83.21,"qty":15.23750000}],"checksum":3057188159,"timestamp":"2024-06-01T17:52:41.077030Z"}]}
{"channel":"book","type":"update","data":[{"symbol":"LTC/USD","bids":[{"price":83.19,"qty":20.77500000}],"asks":[],"checksum":3543946624,"timestamp":"2024-06-01T17:52:41.077487Z"}]}
{"channel":"book","type":"update","data":[{"symbol":"LTC/USD","bids":[],"asks":[{"price":83.21,"qty":7.55000000}],"checksum":1421657561,"timestamp":"2024-06-01T17:52:41.097394Z"}]}
{"channel":"book","type":"update","data":[{"symbol":"LTC/USD","bids":[],"asks":[{"price":83.21,"qty":15.23750000}],"checksum":3543946624,"timestamp":"2024-06-01T17:52:41.101672Z"}]}
{"channel":"book","type":"update","data":[{"symbol":"LTC/USD","bids":[{"price":83.16,"qty":219.97805973}],"asks":[],"checksum":1694462248,"timestamp":"2024-06-01T17:52:41.153595Z"}]}
{"channel":"book","type":"update","data":[{"symbol":"LTC/USD","bids":[],"asks":[{"price":83.21,"qty":22.92500000}],"checksum":3125473202,"timestamp":"2024-06-01T17:52:41.268491Z"}]}
{"channel":"book","type":"update","data":[{"symbol":"LTC/USD","bids":[{"price":83.16,"qty":227.00967815}],"asks":[],"checksum":227134234,"timestamp":"2024-06-01T17:52:41.275604Z"}]}
{"channel":"book","type":"update","data":[{"symbol":"LTC/USD","bids":[{"price":83.16,"qty":219.97805973}],"asks":[],"checksum":3125473202,"timestamp":"2024-06-01T17:52:41.366039Z"}]}
{"channel":"book","type":"update","data":[{"symbol":"LTC/USD","bids":[],"asks":[{"price":83.21,"qty":15.23750000}],"checksum":1694462248,"timestamp":"2024-06-01T17:52:41.402404Z"}]}
{"channel":"book","type":"update","data":[{"symbol":"LTC/USD","bids":[{"price":83.16,"qty":227.00967815}],"asks":[],"checksum":3543946624,"timestamp":"2024-06-01T17:52:41.493502Z"}]}
{"channel":"book","type":"update","data":[{"symbol":"LTC/USD","bids":[],"asks":[{"price":83.21,"qty":22.92500000}],"checksum":227134234,"timestamp":"2024-06-01T17:52:41.498713Z"}]}
{"channel":"book","type":"update","data":[{"symbol":"LTC/USD","bids":[],"asks":[{"price":83.25,"qty":9.15422846}],"checksum":4108183161,"timestamp":"2024-06-01T17:52:41.516466Z"}]}
{"channel":"book","type":"update","data":[{"symbol":"LTC/USD","bids":[],"asks":[{"price":83.24,"qty":146.89940997}],"checksum":2376470572,"timestamp":"2024-06-01T17:52:41.518744Z"}]}
{"channel":"book","type":"update","data":[{"symbol":"LTC/USD","bids":[],"asks":[{"price":83.21,"qty":15.23750000}],"checksum":2208714689,"timestamp":"2024-06-01T17:52:41.610407Z"}]}
{"channel":"book","type":"update","data":[{"symbol":"LTC/USD","bids":[{"price":83.16,"qty":219.97805973}],"asks":[],"checksum":879061865,"timestamp":"2024-06-01T17:52:41.941858Z"}]}
{"channel":"book","type":"update","data":[{"symbol":"LTC/USD","bids":[{"price":83.18,"qty":69.19888571}],"asks":[],"checksum":1094162173,"timestamp":"2024-06-01T17:52:41.945306Z"}]}
{"channel":"book","type":"update","data":[{"symbol":"LTC/USD","bids":[],"asks":[{"price":83.22,"qty":61.29252297}],"checksum":1768315859,"timestamp":"2024-06-01T17:52:41.945404Z"}]}
{"channel":"book","type":"update","data":[{"symbol":"LTC/USD","bids":[{"price":83.16,"qty":227.00967815}],"asks":[],"checksum":3735388027,"timestamp":"2024-06-01T17:52:42.062573Z"}]}
{"channel":"book","type":"update","data":[{"symbol":"LTC/USD","bids":[],"asks":[{"price":83.21,"qty":22.92500000}],"checksum":3500482710,"timestamp":"2024-06-01T17:52:42.133189Z"}]}
{"channel":"book","type":"update","data":[{"symbol":"LTC/USD","bids":[],"asks":[{"price":83.21,"qty":15.23750000}],"checksum":3735388027,"timestamp":"2024-06-01T17:52:42.302138Z"}]}
{"channel":"book","type":"update","data":[{"symbol":"LTC/USD","bids":[],"asks":[{"price":83.21,"qty":7.55000000}],"checksum":1452733674,"timestamp":"2024-06-01T17:52:42.303943Z"}]}
{"channel":"book","type":"update","data":[{"symbol":"LTC/USD","bids":[],"asks":[{"price":83.21,"qty":15.23750000}],"checksum":3735388027,"timestamp":"2024-06-01T17:52:42.307907Z"}]}
{"channel":"book","type":"update","data":[{"symbol":"LTC/USD","bids":[],"asks":[{"price":83.21,"qty":22.92500000}],"checksum":3500482710,"timestamp":"2024-06-01T17:52:42.307982Z"}]}
{"channel":"book","type":"update","data":[{"symbol":"LTC/USD","bids":[],"asks":[{"price":83.21,"qty":15.23750000}],"checksum":3735388027,"timestamp":"2024-06-01T17:52:42.406253Z"}]}
{"channel":"book","type":"update","data":[{"symbol":"LTC/USD","bids":[],"asks":[{"price":83.21,"qty":7.68750000}],"checksum":2361278929,"timestamp":"2024-06-01T17:52:42.515605Z"}]}
{"channel":"book","type":"update","data":[{"symbol":"LTC/USD","bids":[],"asks":[{"price":83.21,"qty":15.23750000}],"checksum":3735388027,"timestamp":"2024-06-01T17:52:42.735249Z"}]}
{"channel":"book","type":"update","data":[{"symbol":"LTC/USD","bids":[{"price":83.16,"qty":219.97805973}],"asks":[],"checksum":1768315859,"timestamp":"2024-06-01T17:52:42.745351Z"}]}
{"channel":"book","type":"update","data":[{"symbol":"LTC/USD","bids":[],"asks":[{"price":83.21,"qty":22.92500000}],"checksum":1734739006,"timestamp":"2024-06-01T17:52:42.758521Z"}]}
{"channel":"book","type":"update","data":[{"symbol":"LTC/USD","bids":[{"price":83.16,"qty":227.00967815}],"asks":[],"checksum":3500482710,"timestamp":"2024-06-01T17:52:42.869179Z"}]}
{"channel":"book","type":"update","data":[{"symbol":"LTC/USD","bids":[{"price":83.15,"qty":59.49420274}],"asks":[],"checksum":1635268990,"timestamp":"2024-06-01T17:52:42.870624Z"}]}
{"channel":"book","type":"update","data":[{"symbol":"LTC/USD","bids":[{"price":83.15,"qty":66.20380587}],"asks":[],"checksum":3010570602,"timestamp":"2024-06-01T17:52:42.878846Z"}]}
{"channel":"book","type":"update","data":[{"symbol":"LTC/USD","bids":[],"asks":[{"price":83.21,"qty":15.23750000}],"checksum":3178362503,"timestamp":"2024-06-01T17:52:43.070727Z"}]}
{"channel":"book","type":"update","data":[{"symbol":"LTC/USD","bids":[],"asks":[{"price":83.21,"qty":22.92500000}],"checksum":3010570602,"timestamp":"2024-06-01T17:52:43.141948Z"}]}
{"channel":"book","type":"update","data":[{"symbol":"LTC/USD","bids":[{"price":83.19,"qty":13.08750000}],"asks":[],"checksum":3597992405,"timestamp":"2024-06-01T17:52:43.536187Z"}]}
{"channel":"book","type":"update","data":[{"symbol":"LTC/USD","bids":[],"asks":[{"price":83.25,"qty":7.74124429}],"checksum":1284785266,"timestamp":"2024-06-01T17:52:43.537766Z"}]}
{"channel":"book","type":"update","data":[{"symbol":"LTC/USD","bids":[],"asks":[{"price":83.25,"qty":9.00765395}],"checksum":4242814587,"timestamp":"2024-06-01T17:52:43.538122Z"}]}
{"channel":"book","type":"update","data":[{"symbol":"LTC/USD","bids":[{"price":83.19,"qty":20.77500000}],"asks":[],"checksum":2581634756,"timestamp":"2024-06-01T17:52:43.539582Z"}]}
{"channel":"book","type":"update","data":[{"symbol":"LTC/USD","bids":[],"asks":[{"price":83.22,"qty":53.74252297}],"checksum":1613779075,"timestamp":"2024-06-01T17:52:43.544354Z"}]}
{"channel":"book","type":"update","data":[{"symbol":"LTC/USD","bids":[],"asks":[{"price":83.21,"qty":15.37500000}],"checksum":2082209830,"timestamp":"2024-06-01T17:52:43.544418Z"}]}
{"channel":"book","type":"update","data":[{"symbol":"LTC/USD","bids":[{"price":83.16,"qty":219.97805973}],"asks":[],"checksum":3420398734,"timestamp":"2024-06-01T17:52:43.548254Z"}]}
{"channel":"book","type":"update","data":[{"symbol":"LTC/USD","bids":[{"price":83.16,"qty":227.00967815}],"asks":[],"checksum":2082209830,"timestamp":"2024-06-01T17:52:43.676021Z"}]}
{"channel":"book","type":"update","data":[{"symbol":"LTC/USD","bids":[],"asks":[{"price":83.21,"qty":22.92500000},{"price":83.22,"qty":61.29252297}],"checksum":2581634756,"timestamp":"2024-06-01T17:52:43.703469Z"}]}
{"channel":"book","type":"update","data":[{"symbol":"LTC/USD","bids":[{"price":83.19,"qty":13.08750000}],"asks":[],"checksum":4242814587,"timestamp":"2024-06-01T17:52:44.157740Z"}]}
{"channel":"book","type":"update","data":[{"symbol":"LTC/USD","bids":[{"price":83.19,"qty":5.40000000}],"asks":[],"checksum":4236478565,"timestamp":"2024-06-01T17:52:44.164505Z"}]}
{"channel":"book","type":"update","data":[{"symbol":"LTC/USD","bids":[{"price":83.19,"qty":13.08750000}],"asks":[],"checksum":4242814587,"timestamp":"2024-06-01T17:52:44.518368Z"}]}
{"channel":"book","type":"update","data":[{"symbol":"LTC/USD","bids":[{"price":83.16,"qty":219.97805973}],"asks":[],"checksum":1260851923,"timestamp":"2024-06-01T17:52:44.756987Z"}]}
{"channel":"book","type":"update","data":[{"symbol":"LTC/USD","bids":[{"price":83.16,"qty":227.00967815}],"asks":[],"checksum":4242814587,"timestamp":"2024-06-01T17:52:44.895599Z"}]}
{"channel":"book","type":"update","data":[{"symbol":"LTC/USD","bids":[{"price":83.19,"qty":5.40000000}],"asks":[],"checksum":4236478565,"timestamp":"2024-06-01T17:52:45.002293Z"}]}
{"channel":"book","type":"update","data":[{"symbol":"LTC/USD","bids":[{"price":83.19,"qty":13.08750000}],"asks":[],"checksum":4242814587,"timestamp":"2024-06-01T17:52:45.214232Z"}]}
{"channel":"book","type":"update","data":[{"symbol":"LTC/USD","bids":[{"price":83.19,"qty":5.40000000}],"asks":[],"checksum":4236478565,"timestamp":"2024-06-01T17:52:45.328585Z"}]}
{"channel":"book","type":"update","data":[{"symbol":"LTC/USD","bids":[{"price":83.15,"qty":59.49420274}],"asks":[],"checksum":780802161,"timestamp":"2024-06-01T17:52:45.511772Z"}]}
{"channel":"book","type":"update","data":[{"symbol":"LTC/USD","bids":[{"price":83.17,"qty":19.33718232}],"asks":[],"checksum":2590682849,"timestamp":"2024-06-01T17:52:45.511917Z"}]}
{"channel":"book","type":"update","data":[{"symbol":"LTC/USD","bids":[{"price":83.17,"qty":21.73617732}],"asks":[],"checksum":3015890442,"timestamp":"2024-06-01T17:52:45.520077Z"}]}
{"channel":"book","type":"update","data":[{"symbol":"LTC/USD","bids":[{"price":83.15,"qty":65.96796822}],"asks":[],"checksum":2536687770,"timestamp":"2024-06-01T17:52:45.521180Z"}]}
{"channel":"book","type":"update","data":[{"symbol":"LTC/USD","bids":[{"price":83.16,"qty":219.97805973}],"asks":[],"checksum":552725554,"timestamp":"2024-06-01T17:52:45.557668Z"}]}
{"channel":"book","type":"update","data":[{"symbol":"LTC/USD","bids":[{"price":83.16,"qty":227.00967815}],"asks":[],"checksum":2536687770,"timestamp":"2024-06-01T17:52:45.689437Z"}]}
{"channel":"book","type":"update","data":[{"symbol":"LTC/USD","bids":[{"price":83.19,"qty":13.08750000}],"asks":[],"checksum":2538960516,"timestamp":"2024-06-01T17:52:45.743525Z"}]}
{"channel":"book","type":"update","data":[{"symbol":"LTC/USD","bids":[{"price":83.19,"qty":5.40000000}],"asks":[],"checksum":2536687770,"timestamp":"2024-06-01T17:52:46.154949Z"}]}
{"channel":"book","type":"update","data":[{"symbol":"LTC/USD","bids":[{"price":83.16,"qty":215.64067815}],"asks":[],"checksum":4269472006,"timestamp":"2024-06-01T17:52:46.245607Z"}]}
{"channel":"book","type":"update","data":[{"symbol":"LTC/USD","bids":[{"price":83.17,"qty":33.10517732}],"asks":[],"checksum":3142675997,"timestamp":"2024-06-01T17:52:46.248416Z"}]}
{"channel":"book","type":"update","data":[{"symbol":"LTC/USD","bids":[{"price":83.16,"qty":208.60905973}],"asks":[],"checksum":1516569687,"timestamp":"2024-06-01T17:52:46.363185Z"}]}
{"channel":"book","type":"update","data":[{"symbol":"LTC/USD","bids":[{"price":83.16,"qty":215.64067815}],"asks":[],"checksum":3142675997,"timestamp":"2024-06-01T17:52:46.506982Z"}]}
{"channel":"book","type":"update","data":[{"symbol":"LTC/USD","bids":[{"price":83.19,"qty":13.08750000}],"asks":[],"checksum":3140931587,"timestamp":"2024-06-01T17:52:46.741295Z"}]}
{"channel":"book","type":"update","data":[{"symbol":"LTC/USD","bids":[{"price":83.19,"qty":5.40000000}],"asks":[],"checksum":3142675997,"timestamp":"2024-06-01T17:52:46.965735Z"}]}
{"channel":"book","type":"update","data":[{"symbol":"LTC/USD","bids":[{"price":83.11,"qty":21.21050000}],"asks":[],"checksum":3477968437,"timestamp":"2024-06-01T17:52:47.196405Z"}]}
{"channel":"book","type":"update","data":[{"symbol":"LTC/USD","bids":[{"price":83.19,"qty":13.08750000}],"asks":[],"checksum":3475646507,"timestamp":"2024-06-01T17:52:47.206157Z"}]}
{"channel":"book","type":"update","data":[{"symbol":"LTC/USD","bids":[{"price":83.13,"qty":58.75696258}],"asks":[],"checksum":809029941,"timestamp":"2024-06-01T17:52:47.484052Z"}]}
{"channel":"book","type":"update","data":[{"symbol":"LTC/USD","bids":[],"asks":[{"price":83.21,"qty":15.23750000}],"checksum":1043893976,"timestamp":"2024-06-01T17:52:47.610640Z"}]}
{"channel":"book","type":"update","data":[{"symbol":"LTC/USD","bids":[{"price":83.19,"qty":20.77500000}],"asks":[],"checksum":1530668647,"timestamp":"2024-06-01T17:52:47.615242Z"}]}
{"channel":"book","type":"update","data":[{"symbol":"LTC/USD","bids":[],"asks":[{"price":83.21,"qty":22.92500000}],"checksum":1430026634,"timestamp":"2024-06-01T17:52:47.618582Z"}]}
{"channel":"book","type":"update","data":[{"symbol":"LTC/USD","bids":[{"price":83.19,"qty":13.08750000}],"asks":[],"checksum":809029941,"timestamp":"2024-06-01T17:52:47.624834Z"}]}
{"channel":"book","type":"update","data":[{"symbol":"LTC/USD","bids":[{"price":83.19,"qty":5.40000000}],"asks":[],"checksum":811560747,"timestamp":"2024-06-01T17:52:47.639552Z"}]}
{"channel":"book","type":"update","data":[{"symbol":"LTC/USD","bids":[{"price":83.19,"qty":13.08750000}],"asks":[],"checksum":809029941,"timestamp":"2024-06-01T17:52:47.664158Z"}]}
{"channel":"book","type":"update","data":[{"symbol":"LTC/USD","bids":[],"asks":[{"price":83.21,"qty":15.23750000}],"checksum":1043893976,"timestamp":"2024-06-01T17:52:47.668059Z"}]}
{"channel":"book","type":"update","data":[{"symbol":"LTC/USD","bids":[{"price":83.19,"qty":20.77500000}],"asks":[],"checksum":1530668647,"timestamp":"2024-06-01T17:52:47.668659Z"}]}
{"channel":"book","type":"update","data":[{"symbol":"LTC/USD","bids":[],"asks":[{"price":83.21,"qty":22.92500000}],"checksum":1430026634,"timestamp":"2024-06-01T17:52:47.706491Z"}]}
{"channel":"book","type":"update","data":[{"symbol":"LTC/USD","bids":[],"asks":[{"price":83.21,"qty":15.23750000}],"checksum":1530668647,"timestamp":"2024-06-01T17:52:47.739420Z"}]}
{"channel":"book","type":"update","data":[{"symbol":"LTC/USD","bids":[],"asks":[{"price":83.21,"qty":7.68750000}],"checksum":153557197,"timestamp":"2024-06-01T17:52:47.743322Z"}]}
{"channel":"book","type":"update","data":[{"symbol":"LTC/USD","bids":[],"asks":[{"price":83.22,"qty":53.74252297}],"checksum":4042774154,"timestamp":"2024-06-01T17:52:47.744615Z"}]}
{"channel":"book","type":"update","data":[{"symbol":"LTC/USD","bids":[],"asks":[{"price":83.24,"qty":139.34940997}],"checksum":3951996244,"timestamp":"2024-06-01T17:52:47.744832Z"}]}
{"channel":"book","type":"update","data":[{"symbol":"LTC/USD","bids":[],"asks":[{"price":83.21,"qty":15.37500000}],"checksum":2881068214,"timestamp":"2024-06-01T17:52:47.747034Z"}]}
{"channel":"book","type":"update","data":[{"symbol":"LTC/USD","bids":[],"asks":[{"price":83.21,"qty":7.68750000}],"checksum":3951996244,"timestamp":"2024-06-01T17:52:47.760695Z"}]}
{"channel":"book","type":"update","data":[{"symbol":"LTC/USD","bids":[],"asks":[{"price":83.21,"qty":15.23750000},{"price":83.22,"qty":61.29252297},{"price":83.24,"qty":146.89940997}],"checksum":1530668647,"timestamp":"2024-06-01T17:52:47.857516Z"}]}
{"channel":"book","type":"update","data":[{"symbol":"LTC/USD","bids":[],"asks":[{"price":83.25,"qty":7.74124429}],"checksum":3947648110,"timestamp":"2024-06-01T17:52:47.906403Z"}]}
{"channel":"book","type":"update","data":[{"symbol":"LTC/USD","bids":[],"asks":[{"price":83.25,"qty":9.15422846}],"checksum":1907167689,"timestamp":"2024-06-01T17:52:47.906755Z"}]}
{"channel":"book","type":"update","data":[{"symbol":"LTC/USD","bids":[],"asks":[{"price":83.21,"qty":22.92500000}],"checksum":2142064164,"timestamp":"2024-06-01T17:52:48.282067Z"}]}
{"channel":"book","type":"update","data":[{"symbol":"LTC/USD","bids":[{"price":83.15,"qty":59.49420274}],"asks":[],"checksum":1532842164,"timestamp":"2024-06-01T17:52:48.434621Z"}]}
{"channel":"book","type":"update","data":[{"symbol":"LTC/USD","bids":[{"price":83.17,"qty":30.70618232}],"asks":[],"checksum":3475197913,"timestamp":"2024-06-01T17:52:48.434860Z"}]}
{"channel":"book","type":"update","data":[{"symbol":"LTC/USD","bids":[{"price":83.17,"qty":32.88931663}],"asks":[],"checksum":1617079688,"timestamp":"2024-06-01T17:52:48.440455Z"}]}
{"channel":"book","type":"update","data":[{"symbol":"LTC/USD","bids":[{"price":83.15,"qty":66.18382891}],"asks":[],"checksum":4081862565,"timestamp":"2024-06-01T17:52:48.441758Z"}]}
{"channel":"book","type":"update","data":[{"symbol":"LTC/USD","bids":[{"price":83.17,"qty":25.33931663}],"asks":[],"checksum":4058981127,"timestamp":"2024-06-01T17:52:49.002257Z"}]}
{"channel":"book","type":"update","data":[{"symbol":"LTC/USD","bids":[{"price":83.16,"qty":208.09067815}],"asks":[],"checksum":3228045152,"timestamp":"2024-06-01T17:52:49.006082Z"}]}
{"channel":"book","type":"update","data":[{"symbol":"LTC/USD","bids":[{"price":83.19,"qty":13.08750000}],"asks":[],"checksum":2775361503,"timestamp":"2024-06-01T17:52:49.017019Z"}]}
{"channel":"book","type":"update","data":[{"symbol":"LTC/USD","bids":[{"price":83.19,"qty":5.40000000}],"asks":[],"checksum":1904612500,"timestamp":"2024-06-01T17:52:49.017333Z"}]}
{"channel":"book","type":"update","data":[{"symbol":"LTC/USD","bids":[{"price":83.14,"qty":295.36577047}],"asks":[],"checksum":2893593032,"timestamp":"2024-06-01T17:52:49.020062Z"}]}
{"channel":"book","type":"update","data":[{"symbol":"LTC/USD","bids":[],"asks":[{"price":83.24,"qty":143.90940997}],"checksum":2887629809,"timestamp":"2024-06-01T17:52:49.139030Z"}]}
{"channel":"book","type":"update","data":[{"symbol":"LTC/USD","bids":[{"price":83.19,"qty":13.08750000}],"asks":[],"checksum":664266633,"timestamp":"2024-06-01T17:52:49.220444Z"}]}
{"channel":"book","type":"update","data":[{"symbol":"LTC/USD","bids":[{"price":83.17,"qty":32.88931663},{"price":83.16,"qty":215.64067815},{"price":83.14,"qty":302.91577047}],"asks":[],"checksum":3377267216,"timestamp":"2024-06-01T17:52:49.401968Z"}]}
{"channel":"book","type":"update","data":[{"symbol":"LTC/USD","bids":[{"price":83.19,"qty":5.40000000}],"asks":[],"checksum":1120362088,"timestamp":"2024-06-01T17:52:49.986742Z"}]}
{"channel":"book","type":"update","data":[{"symbol":"LTC/USD","bids":[{"price":83.19,"qty":13.08750000}],"asks":[],"checksum":3377267216,"timestamp":"2024-06-01T17:52:49.989227Z"}]}
{"channel":"book","type":"update","data":[{"symbol":"LTC/USD","bids":[{"price":83.19,"qty":5.40000000}],"asks":[],"checksum":1120362088,"timestamp":"2024-06-01T17:52:50.013830Z"}]}
{"channel":"book","type":"update","data":[{"symbol":"LTC/USD","bids":[{"price":83.19,"qty":13.08750000}],"asks":[],"checksum":3377267216,"timestamp":"2024-06-01T17:52:50.276666Z"}]}
{"channel":"book","type":"update","data":[{"symbol":"LTC/USD","bids":[{"price":83.19,"qty":5.40000000}],"asks":[],"checksum":1120362088,"timestamp":"2024-06-01T17:52:50.315574Z"}]}
{"channel":"book","type":"update","data":[{"symbol":"LTC/USD","bids":[{"price":83.19,"qty":13.08750000}],"asks":[],"checksum":3377267216,"timestamp":"2024-06-01T17:52:50.607147Z"}]}
{"channel":"book","type":"update","data":[{"symbol":"LTC/USD","bids":[{"price":83.19,"qty":5.40000000}],"asks":[],"checksum":1120362088,"timestamp":"2024-06-01T17:52:50.745762Z"}]}
{"channel":"book","type":"update","data":[{"symbol":"LTC/USD","bids":[{"price":83.17,"qty":21.52031663}],"asks":[],"checksum":515318412,"timestamp":"2024-06-01T17:52:50.974970Z"}]}
{"channel":"book","type":"update","data":[{"symbol":"LTC/USD","bids":[{"price":83.16,"qty":227.37667815}],"asks":[],"checksum":1837666108,"timestamp":"2024-06-01T17:52:50.977585Z"}]}
{"channel":"book","type":"update","data":[{"symbol":"LTC/USD","bids":[],"asks":[{"price":83.21,"qty":15.23750000}],"checksum":3059699764,"timestamp":"2024-06-01T17:52:51.942822Z"}]}
{"channel":"book","type":"update","data":[{"symbol":"LTC/USD","bids":[{"price":83.19,"qty":13.08750000}],"asks":[],"checksum":3892481193,"timestamp":"2024-06-01T17:52:51.943162Z"}]}
{"channel":"book","type":"update","data":[{"symbol":"LTC/USD","bids":[{"price":83.19,"qty":20.77500000}],"asks":[],"checksum":2365989910,"timestamp":"2024-06-01T17:52:51.943360Z"}]}
{"channel":"book","type":"update","data":[{"symbol":"LTC/USD","bids":[],"asks":[{"price":83.21,"qty":7.55000000}],"checksum":87404423,"timestamp":"2024-06-01T17:52:51.943590Z"}]}
{"channel":"book","type":"update","data":[{"symbol":"LTC/USD","bids":[],"asks":[{"price":83.21,"qty":0.00000000},{"price":83.32,"qty":67.32692115}],"checksum":2405339031,"timestamp":"2024-06-01T17:52:51.946537Z"}]}
{"channel":"book","type":"update","data":[{"symbol":"LTC/USD","bids":[],"asks":[{"price":83.22,"qty":53.74252297}],"checksum":3793290927,"timestamp":"2024-06-01T17:52:51.946662Z"}]}
{"channel":"book","type":"update","data":[{"symbol":"LTC/USD","bids":[],"asks":[{"price":83.24,"qty":136.35940997}],"checksum":2157684844,"timestamp":"2024-06-01T17:52:51.949449Z"}]}
{"channel":"book","type":"update","data":[{"symbol":"LTC/USD","bids":[],"asks":[{"price":83.21,"qty":7.68750000}],"checksum":2347529480,"timestamp":"2024-06-01T17:52:51.950425Z"}]}
{"channel":"book","type":"update","data":[{"symbol":"LTC/USD","bids":[],"asks":[{"price":83.23,"qty":21.63033223}],"checksum":3449125908,"timestamp":"2024-06-01T17:52:51.951793Z"}]}
{"channel":"book","type":"update","data":[{"symbol":"LTC/USD","bids":[{"price":83.19,"qty":13.08750000}],"asks":[],"checksum":2828129451,"timestamp":"2024-06-01T17:52:51.954182Z"}]}
{"channel":"book","type":"update","data":[{"symbol":"LTC/USD","bids":[],"asks":[{"price":83.21,"qty":15.37500000}],"checksum":3903251785,"timestamp":"2024-06-01T17:52:51.955389Z"}]}
{"channel":"book","type":"update","data":[{"symbol":"LTC/USD","bids":[],"asks":[{"price":83.27,"qty":3.54763685},{"price":83.25,"qty":69.21422846}],"checksum":182497329,"timestamp":"2024-06-01T17:52:51.955682Z"}]}
{"channel":"book","type":"update","data":[{"symbol":"LTC/USD","bids":[],"asks":[{"price":83.23,"qty":29.38953479}],"checksum":1460953610,"timestamp":"2024-06-01T17:52:51.957633Z"}]}
{"channel":"book","type":"update","data":[{"symbol":"LTC/USD","bids":[{"price":83.19,"qty":20.77500000}],"asks":[],"checksum":839961269,"timestamp":"2024-06-01T17:52:51.957980Z"}]}
{"channel":"book","type":"update","data":[{"symbol":"LTC/USD","bids":[],"asks":[{"price":83.21,"qty":7.68750000}],"checksum":1915222871,"timestamp":"2024-06-01T17:52:51.965096Z"}]}
{"channel":"book","type":"update","data":[{"symbol":"LTC/USD","bids":[],"asks":[{"price":83.25,"qty":9.15422846}],"checksum":2788157736,"timestamp":"2024-06-01T17:52:51.971833Z"}]}
{"channel":"book","type":"update","data":[{"symbol":"LTC/USD","bids":[],"asks":[{"price":83.21,"qty":15.37500000}],"checksum":1310027202,"timestamp":"2024-06-01T17:52:51.985345Z"}]}
{"channel":"book","type":"update","data":[{"symbol":"LTC/USD","bids":[],"asks":[{"price":83.25,"qty":21.28494195}],"checksum":635115146,"timestamp":"2024-06-01T17:52:52.035814Z"}]}
{"channel":"book","type":"update","data":[{"symbol":"LTC/USD","bids":[],"asks":[{"price":83.21,"qty":7.68750000}],"checksum":1709975400,"timestamp":"2024-06-01T17:52:52.035948Z"}]}
{"channel":"book","type":"update","data":[{"symbol":"LTC/USD","bids":[],"asks":[{"price":83.21,"qty":15.37500000}],"checksum":635115146,"timestamp":"2024-06-01T17:52:52.069480Z"}]}
{"channel":"book","type":"update","data":[{"symbol":"LTC/USD","bids":[],"asks":[{"price":83.21,"qty":22.92500000},{"price":83.22,"qty":61.29252297},{"price":83.24,"qty":143.90940997}],"checksum":1829120411,"timestamp":"2024-06-01T17:52:52.113903Z"}]}
{"channel":"book","type":"update","data":[{"symbol":"LTC/USD","bids":[{"price":83.19,"qty":13.08750000}],"asks":[],"checksum":134381860,"timestamp":"2024-06-01T17:52:52.176181Z"}]}
{"channel":"book","type":"update","data":[{"symbol":"LTC/USD","bids":[{"price":83.19,"qty":5.40000000}],"asks":[],"checksum":1673249598,"timestamp":"2024-06-01T17:52:52.204125Z"}]}
{"channel":"book","type":"update","data":[{"symbol":"LTC/USD","bids":[{"price":83.19,"qty":13.08750000}],"asks":[],"checksum":134381860,"timestamp":"2024-06-01T17:52:52.250538Z"}]}
{"channel":"book","type":"update","data":[{"symbol":"LTC/USD","bids":[],"asks":[{"price":83.25,"qty":19.87195778}],"checksum":1294570330,"timestamp":"2024-06-01T17:52:52.352476Z"}]}
{"channel":"book","type":"update","data":[{"symbol":"LTC/USD","bids":[],"asks":[{"price":83.25,"qty":21.13836744}],"checksum":1119506147,"timestamp":"2024-06-01T17:52:52.353253Z"}]}
{"channel":"book","type":"update","data":[{"symbol":"LTC/USD","bids":[],"asks":[{"price":83.24,"qty":83.83724026}],"checksum":2877684557,"timestamp":"2024-06-01T17:52:53.069861Z"}]}
{"channel":"book","type":"update","data":[{"symbol":"LTC/USD","bids":[],"asks":[{"price":83.22,"qty":31.25157370}],"checksum":2588952512,"timestamp":"2024-06-01T17:52:53.069998Z"}]}
{"channel":"book","type":"update","data":[{"symbol":"LTC/USD","bids":[],"asks":[{"price":83.26,"qty":339.77907347}],"checksum":2866675100,"timestamp":"2024-06-01T17:52:53.072944Z"}]}
{"channel":"book","type":"update","data":[{"symbol":"LTC/USD","bids":[],"asks":[{"price":83.23,"qty":59.42727793}],"checksum":446560452,"timestamp":"2024-06-01T17:52:53.075645Z"}]}
{"channel":"book","type":"update","data":[{"symbol":"LTC/USD","bids":[],"asks":[{"price":83.29,"qty":114.10595642}],"checksum":569483727,"timestamp":"2024-06-01T17:52:53.075755Z"}]}
{"channel":"book","type":"update","data":[{"symbol":"LTC/USD","bids":[],"asks":[{"price":83.21,"qty":15.23750000}],"checksum":804388386,"timestamp":"2024-06-01T17:52:53.110192Z"}]}
{"channel":"book","type":"update","data":[{"symbol":"LTC/USD","bids":[{"price":83.19,"qty":20.77500000}],"asks":[],"checksum":1257592477,"timestamp":"2024-06-01T17:52:53.134946Z"}]}
{"channel":"book","type":"update","data":[{"symbol":"LTC/USD","bids":[{"price":83.15,"qty":59.49420274}],"asks":[],"checksum":3655056560,"timestamp":"2024-06-01T17:52:53.478273Z"}]}
{"channel":"book","type":"update","data":[{"symbol":"LTC/USD","bids":[{"price":83.17,"qty":19.33718232}],"asks":[],"checksum":3524776600,"timestamp":"2024-06-01T17:52:53.478395Z"}]}
{"channel":"book","type":"update","data":[{"symbol":"LTC/USD","bids":[{"price":83.17,"qty":21.95203801}],"asks":[],"checksum":151197067,"timestamp":"2024-06-01T17:52:53.488142Z"}]}
{"channel":"book","type":"update","data":[{"symbol":"LTC/USD","bids":[{"price":83.15,"qty":65.75416284}],"asks":[],"checksum":1726594104,"timestamp":"2024-06-01T17:52:53.488475Z"}]}
{"channel":"book","type":"update","data":[{"symbol":"LTC/USD","bids":[],"asks":[{"price":83.21,"qty":7.55000000}],"checksum":4007278505,"timestamp":"2024-06-01T17:52:53.579730Z"}]}
{"channel":"book","type":"update","data":[{"symbol":"LTC/USD","bids":[],"asks":[{"price":83.21,"qty":0.00000000},{"price":83.32,"qty":67.32692115}],"checksum":237010405,"timestamp":"2024-06-01T17:52:53.588918Z"}]}
{"channel":"book","type":"update","data":[{"symbol":"LTC/USD","bids":[],"asks":[{"price":83.22,"qty":23.70157370}],"checksum":569238065,"timestamp":"2024-06-01T17:52:53.593772Z"}]}
{"channel":"book","type":"update","data":[{"symbol":"LTC/USD","bids":[],"asks":[{"price":83.24,"qty":76.28724026}],"checksum":199059503,"timestamp":"2024-06-01T17:52:53.593837Z"}]}
{"channel":"book","type":"update","data":[{"symbol":"LTC/USD","bids":[],"asks":[{"price":83.21,"qty":7.68750000}],"checksum":3508735643,"timestamp":"2024-06-01T17:52:53.808086Z"}]}
{"channel":"book","type":"update","data":[{"symbol":"LTC/USD","bids":[],"asks":[{"price":83.22,"qty":31.25157370},{"price":83.24,"qty":83.83724026},{"price":83.26,"qty":347.32907347}],"checksum":420839157,"timestamp":"2024-06-01T17:52:53.841638Z"}]}
{"channel":"book","type":"update","data":[{"symbol":"LTC/USD","bids":[],"asks":[{"price":83.25,"qty":9.00765395}],"checksum":931286973,"timestamp":"2024-06-01T17:52:53.893388Z"}]}
{"channel":"book","type":"update","data":[{"symbol":"LTC/USD","bids":[],"asks":[{"price":83.26,"qty":323.47600835}],"checksum":3669942751,"timestamp":"2024-06-01T17:52:54.509785Z"}]}
{"channel":"book","type":"update","data":[{"symbol":"LTC/USD","bids":[],"asks":[{"price":83.25,"qty":7.74124429}],"checksum":1791923158,"timestamp":"2024-06-01T17:52:54.607457Z"}]}
{"channel":"book","type":"update","data":[{"symbol":"LTC/USD","bids":[],"asks":[{"price":83.25,"qty":9.38870698}],"checksum":2287928993,"timestamp":"2024-06-01T17:52:54.609794Z"}]}
{"channel":"book","type":"update","data":[{"symbol":"LTC/USD","bids":[],"asks":[{"price":83.21,"qty":15.37500000}],"checksum":1617265227,"timestamp":"2024-06-01T17:52:55.039796Z"}]}
{"channel":"book","type":"update","data":[{"symbol":"LTC/USD","bids":[],"asks":[{"price":83.21,"qty":7.68750000}],"checksum":2287928993,"timestamp":"2024-06-01T17:52:55.181660Z"}]}
{"channel":"book","type":"update","data":[{"symbol":"LTC/USD","bids":[],"asks":[{"price":83.21,"qty":0.00000000},{"price":83.32,"qty":67.32692115}],"checksum":3976439228,"timestamp":"2024-06-01T17:52:55.424990Z"}]}
{"channel":"book","type":"update","data":[{"symbol":"LTC/USD","bids":[{"price":83.17,"qty":14.40203801}],"asks":[],"checksum":3791227883,"timestamp":"2024-06-01T17:52:55.537384Z"}]}
{"channel":"book","type":"update","data":[{"symbol":"LTC/USD","bids":[{"price":83.16,"qty":219.82667815}],"asks":[],"checksum":507623429,"timestamp":"2024-06-01T17:52:55.541017Z"}]}
{"channel":"book","type":"update","data":[{"symbol":"LTC/USD","bids":[],"asks":[{"price":83.21,"qty":7.68750000}],"checksum":2065505048,"timestamp":"2024-06-01T17:52:55.551972Z"}]}
{"channel":"book","type":"update","data":[{"symbol":"LTC/USD","bids":[],"asks":[{"price":83.21,"qty":15.37500000}],"checksum":2468847602,"timestamp":"2024-06-01T17:52:55.575031Z"}]}
{"channel":"book","type":"update","data":[{"symbol":"LTC/USD","bids":[],"asks":[{"price":83.26,"qty":315.92600835},{"price":83.21,"qty":22.92500000}],"checksum":2251728917,"timestamp":"2024-06-01T17:52:55.615776Z"}]}
{"channel":"book","type":"update","data":[{"symbol":"LTC/USD","bids":[],"asks":[{"price":83.21,"qty":30.47500000}],"checksum":2948615501,"timestamp":"2024-06-01T17:52:55.621454Z"}]}
{"channel":"book","type":"update","data":[{"symbol":"LTC/USD","bids":[],"asks":[{"price":83.21,"qty":22.78750000}],"checksum":883059886,"timestamp":"2024-06-01T17:52:55.666158Z"}]}
{"channel":"book","type":"update","data":[{"symbol":"LTC/USD","bids":[{"price":83.17,"qty":21.95203801},{"price":83.16,"qty":227.37667815}],"asks":[],"checksum":3353374999,"timestamp":"2024-06-01T17:52:55.697611Z"}]}
{"channel":"book","type":"update","data":[{"symbol":"LTC/USD","bids":[{"price":83.16,"qty":215.64067815}],"asks":[],"checksum":3034569895,"timestamp":"2024-06-01T17:52:55.704338Z"}]}
{"channel":"book","type":"update","data":[{"symbol":"LTC/USD","bids":[{"price":83.17,"qty":33.68803801}],"asks":[],"checksum":3805651482,"timestamp":"2024-06-01T17:52:55.706960Z"}]}
{"channel":"book","type":"update","data":[{"symbol":"LTC/USD","bids":[{"price":83.17,"qty":31.07318232}],"asks":[],"checksum":201828361,"timestamp":"2024-06-01T17:52:56.103952Z"}]}
{"channel":"book","type":"update","data":[{"symbol":"LTC/USD","bids":[{"price":83.15,"qty":59.49420274}],"asks":[],"checksum":1676476858,"timestamp":"2024-06-01T17:52:56.104173Z"}]}
{"channel":"book","type":"update","data":[{"symbol":"LTC/USD","bids":[{"price":83.17,"qty":33.47211806}],"asks":[],"checksum":2244906024,"timestamp":"2024-06-01T17:52:56.346280Z"}]}
{"channel":"book","type":"update","data":[{"symbol":"LTC/USD","bids":[{"price":83.15,"qty":65.96780829}],"asks":[],"checksum":306759057,"timestamp":"2024-06-01T17:52:56.346595Z"}]}
{"channel":"book","type":"update","data":[{"symbol":"LTC/USD","bids":[],"asks":[{"price":83.21,"qty":15.10000000}],"checksum":183819400,"timestamp":"2024-06-01T17:52:56.375467Z"}]}
{"channel":"book","type":"update","data":[{"symbol":"LTC/USD","bids":[],"asks":[{"price":83.26,"qty":255.87164472}],"checksum":3300000657,"timestamp":"2024-06-01T17:52:56.458956Z"}]}
{"channel":"book","type":"update","data":[{"symbol":"LTC/USD","bids":[],"asks":[{"price":83.25,"qty":69.45107897}],"checksum":3181452145,"timestamp":"2024-06-01T17:52:56.463720Z"}]}
{"channel":"book","type":"update","data":[{"symbol":"LTC/USD","bids":[],"asks":[{"price":83.21,"qty":22.78750000}],"checksum":3654422440,"timestamp":"2024-06-01T17:52:56.845574Z"}]}
{"channel":"book","type":"update","data":[{"symbol":"LTC/USD","bids":[{"price":83.17,"qty":25.92211806},{"price":83.12,"qty":134.21290391}],"asks":[],"checksum":4062817981,"timestamp":"2024-06-01T17:52:57.084384Z"}]}
{"channel":"book","type":"update","data":[{"symbol":"LTC/USD","bids":[{"price":83.12,"qty":141.76290391}],"asks":[],"checksum":3551574152,"timestamp":"2024-06-01T17:52:57.088886Z"}]}
{"channel":"book","type":"update","data":[{"symbol":"LTC/USD","bids":[{"price":83.16,"qty":208.09067815}],"asks":[],"checksum":3795293423,"timestamp":"2024-06-01T17:52:57.151166Z"}]}
{"channel":"book","type":"update","data":[{"symbol":"LTC/USD","bids":[{"price":83.14,"qty":295.36577047}],"asks":[],"checksum":1070152115,"timestamp":"2024-06-01T17:52:57.154610Z"}]}
{"channel":"book","type":"update","data":[{"symbol":"LTC/USD","bids":[{"price":83.16,"qty":215.64067815},{"price":83.14,"qty":302.91577047}],"asks":[],"checksum":3551574152,"timestamp":"2024-06-01T17:52:57.303510Z"}]}
{"channel":"book","type":"update","data":[{"symbol":"LTC/USD","bids":[{"price":83.16,"qty":208.09067815}],"asks":[],"checksum":3795293423,"timestamp":"2024-06-01T17:52:57.693410Z"}]}
{"channel":"book","type":"update","data":[{"symbol":"LTC/USD","bids":[{"price":83.16,"qty":215.64067815}],"asks":[],"checksum":3551574152,"timestamp":"2024-06-01T17:52:57.818414Z"}]}
{"channel":"book","type":"update","data":[{"symbol":"LTC/USD","bids":[{"price":83.19,"qty":13.08750000}],"asks":[],"checksum":3065253943,"timestamp":"2024-06-01T17:52:58.027346Z"}]}
{"channel":"book","type":"update","data":[{"symbol":"LTC/USD","bids":[],"asks":[{"price":83.21,"qty":30.47500000}],"checksum":2402075092,"timestamp":"2024-06-01T17:52:58.027581Z"}]}
{"channel":"book","type":"update","data":[{"symbol":"LTC/USD","bids":[{"price":83.19,"qty":5.40000000}],"asks":[],"checksum":3642115006,"timestamp":"2024-06-01T17:52:58.028232Z"}]}
{"channel":"book","type":"update","data":[{"symbol":"LTC/USD","bids":[{"price":83.19,"qty":13.08750000}],"asks":[],"checksum":2402075092,"timestamp":"2024-06-01T17:52:58.051385Z"}]}
{"channel":"book","type":"update","data":[{"symbol":"LTC/USD","bids":[],"asks":[{"price":83.21,"qty":22.92500000},{"price":83.26,"qty":263.42164472}],"checksum":1745131412,"timestamp":"2024-06-01T17:52:58.224005Z"}]}
{"channel":"book","type":"update","data":[{"symbol":"LTC/USD","bids":[],"asks":[{"price":83.21,"qty":15.37500000}],"checksum":1948829489,"timestamp":"2024-06-01T17:52:58.228584Z"}]}
{"channel":"book","type":"update","data":[{"symbol":"LTC/USD","bids":[],"asks":[{"price":83.21,"qty":7.68750000}],"checksum":874510035,"timestamp":"2024-06-01T17:52:58.385578Z"}]}
{"channel":"book","type":"update","data":[{"symbol":"LTC/USD","bids":[{"price":83.16,"qty":208.60905973}],"asks":[],"checksum":3576405145,"timestamp":"2024-06-01T17:52:58.415923Z"}]}
{"channel":"book","type":"update","data":[{"symbol":"LTC/USD","bids":[{"price":83.19,"qty":20.77500000}],"asks":[],"checksum":2955883558,"timestamp":"2024-06-01T17:52:58.419129Z"}]}
{"channel":"book","type":"update","data":[{"symbol":"LTC/USD","bids":[{"price":83.16,"qty":215.64067815}],"asks":[],"checksum":1360748140,"timestamp":"2024-06-01T17:52:58.536079Z"}]}
{"channel":"book","type":"update","data":[{"symbol":"LTC/USD","bids":[{"price":83.16,"qty":208.09067815}],"asks":[],"checksum":1620865547,"timestamp":"2024-06-01T17:52:58.568191Z"}]}
{"channel":"book","type":"update","data":[{"symbol":"LTC/USD","bids":[{"price":83.16,"qty":215.64067815}],"asks":[],"checksum":1360748140,"timestamp":"2024-06-01T17:52:58.683566Z"}]}
{"channel":"book","type":"update","data":[{"symbol":"LTC/USD","bids":[{"price":83.17,"qty":23.52318232}],"asks":[],"checksum":2429026305,"timestamp":"2024-06-01T17:52:58.694020Z"}]}
{"channel":"book","type":"update","data":[{"symbol":"LTC/USD","bids":[{"price":83.15,"qty":59.49420274}],"asks":[],"checksum":122571192,"timestamp":"2024-06-01T17:52:58.694153Z"}]}
{"channel":"book","type":"update","data":[{"symbol":"LTC/USD","bids":[],"asks":[{"price":83.21,"qty":0.00000000},{"price":83.32,"qty":67.32692115}],"checksum":3489027168,"timestamp":"2024-06-01T17:52:58.948027Z"}]}
{"channel":"book","type":"update","data":[{"symbol":"LTC/USD","bids":[{"price":83.13,"qty":66.94164539}],"asks":[],"checksum":2283224969,"timestamp":"2024-06-01T17:52:58.995040Z"}]}
{"channel":"book","type":"update","data":[{"symbol":"LTC/USD","bids":[{"price":83.17,"qty":25.70631663}],"asks":[],"checksum":1784944958,"timestamp":"2024-06-01T17:52:58.995072Z"}]}
{"channel":"book","type":"update","data":[{"symbol":"LTC/USD","bids":[],"asks":[{"price":83.21,"qty":7.68750000}],"checksum":2732328166,"timestamp":"2024-06-01T17:52:59.311265Z"}]}
{"channel":"book","type":"update","data":[{"symbol":"LTC/USD","bids":[],"asks":[{"price":83.21,"qty":5.29595482}],"checksum":2848745191,"timestamp":"2024-06-01T17:52:59.485528Z"}]}
{"channel":"book","type":"update","data":[{"symbol":"LTC/USD","bids":[],"asks":[{"price":83.21,"qty":0.00000000},{"price":83.32,"qty":67.32692115}],"checksum":1784944958,"timestamp":"2024-06-01T17:52:59.489229Z"}]}
{"channel":"book","type":"update","data":[{"symbol":"LTC/USD","bids":[],"asks":[{"price":83.24,"qty":72.46824026}],"checksum":2500560820,"timestamp":"2024-06-01T17:53:00.433733Z"}]}
{"channel":"book","type":"update","data":[{"symbol":"LTC/USD","bids":[],"asks":[{"price":83.25,"qty":81.18707897}],"checksum":3556228673,"timestamp":"2024-06-01T17:53:00.435973Z"}]}
{"channel":"book","type":"update","data":[{"symbol":"LTC/USD","bids":[],"asks":[{"price":83.22,"qty":31.05987345}],"checksum":773699063,"timestamp":"2024-06-01T17:53:02.549023Z"}]}
{"channel":"book","type":"update","data":[{"symbol":"LTC/USD","bids":[{"price":83.20,"qty":7.68750000}],"asks":[],"checksum":3455120059,"timestamp":"2024-06-01T17:53:02.832939Z"}]}
{"channel":"book","type":"update","data":[{"symbol":"LTC/USD","bids":[{"price":83.20,"qty":15.37500000}],"asks":[],"checksum":4183683688,"timestamp":"2024-06-01T17:53:02.833587Z"}]}
{"channel":"book","type":"update","data":[{"symbol":"LTC/USD","bids":[{"price":83.20,"qty":7.68750000}],"asks":[],"checksum":3455120059,"timestamp":"2024-06-01T17:53:02.836770Z"}]}
{"channel":"book","type":"update","data":[{"symbol":"LTC/USD","bids":[{"price":83.20,"qty":0.00000000},{"price":83.10,"qty":7.68750000}],"asks":[],"checksum":773699063,"timestamp":"2024-06-01T17:53:02.913728Z"}]}
{"channel":"book","type":"update","data":[{"symbol":"LTC/USD","bids":[{"price":83.20,"qty":7.68750000}],"asks":[],"checksum":3455120059,"timestamp":"2024-06-01T17:53:03.191986Z"}]}
{"channel":"book","type":"update","data":[{"symbol":"LTC/USD","bids":[{"price":83.20,"qty":15.37500000}],"asks":[],"checksum":4183683688,"timestamp":"2024-06-01T17:53:03.192521Z"}]}
{"channel":"book","type":"update","data":[{"symbol":"LTC/USD","bids":[],"asks":[{"price":83.22,"qty":23.37237345}],"checksum":2782702840,"timestamp":"2024-06-01T17:53:03.195445Z"}]}
{"channel":"book","type":"update","data":[{"symbol":"LTC/USD","bids":[{"price":83.20,"qty":7.68750000}],"asks":[],"checksum":4291061248,"timestamp":"2024-06-01T17:53:03.196165Z"}]}
{"channel":"book","type":"update","data":[{"symbol":"LTC/USD","bids":[],"asks":[{"price":83.22,"qty":31.05987345}],"checksum":3455120059,"timestamp":"2024-06-01T17:53:03.198399Z"}]}
{"channel":"book","type":"update","data":[{"symbol":"LTC/USD","bids":[{"price":83.20,"qty":0.00000000},{"price":83.10,"qty":7.68750000}],"asks":[],"checksum":773699063,"timestamp":"2024-06-01T17:53:03.204212Z"}]}
{"channel":"book","type":"update","data":[{"symbol":"LTC/USD","bids":[],"asks":[{"price":83.25,"qty":79.53961628}],"checksum":3020616150,"timestamp":"2024-06-01T17:53:03.486141Z"}]}
{"channel":"book","type":"update","data":[{"symbol":"LTC/USD","bids":[],"asks":[{"price":83.25,"qty":81.01123026}],"checksum":2892012563,"timestamp":"2024-06-01T17:53:03.486629Z"}]}
{"channel":"book","type":"update","data":[{"symbol":"LTC/USD","bids":[{"price":83.13,"qty":58.75696258}],"asks":[],"checksum":3951163386,"timestamp":"2024-06-01T17:53:03.958942Z"}]}
{"channel":"book","type":"update","data":[{"symbol":"LTC/USD","bids":[{"price":83.17,"qty":23.52318232}],"asks":[],"checksum":166908237,"timestamp":"2024-06-01T17:53:03.959321Z"}]}
{"channel":"book","type":"update","data":[{"symbol":"LTC/USD","bids":[{"price":83.17,"qty":25.87040158}],"asks":[],"checksum":130102908,"timestamp":"2024-06-01T17:53:03.969915Z"}]}
{"channel":"book","type":"update","data":[{"symbol":"LTC/USD","bids":[{"price":83.13,"qty":66.11286904}],"asks":[],"checksum":3646771791,"timestamp":"2024-06-01T17:53:03.969951Z"}]}
{"channel":"book","type":"update","data":[{"symbol":"LTC/USD","bids":[{"price":83.16,"qty":208.09067815}],"asks":[],"checksum":3906633256,"timestamp":"2024-06-01T17:53:04.578504Z"}]}
{"channel":"book","type":"update","data":[{"symbol":"LTC/USD","bids":[{"price":83.12,"qty":134.21290391}],"asks":[],"checksum":3376637981,"timestamp":"2024-06-01T17:53:04.583669Z"}]}
{"channel":"book","type":"update","data":[{"symbol":"LTC/USD","bids":[{"price":83.14,"qty":295.36577047}],"asks":[],"checksum":347981121,"timestamp":"2024-06-01T17:53:04.583695Z"}]}
{"channel":"book","type":"update","data":[{"symbol":"LTC/USD","bids":[{"price":83.12,"qty":126.66290391}],"asks":[],"checksum":315136277,"timestamp":"2024-06-01T17:53:04.583809Z"}]}
{"channel":"book","type":"update","data":[{"symbol":"LTC/USD","bids":[{"price":83.16,"qty":215.64067815},{"price":83.14,"qty":302.91577047},{"price":83.12,"qty":134.21290391}],"asks":[],"checksum":4173612154,"timestamp":"2024-06-01T17:53:04.786798Z"}]}
{"channel":"book","type":"update","data":[{"symbol":"LTC/USD","bids":[{"price":83.20,"qty":7.68750000}],"asks":[],"checksum":1185718441,"timestamp":"2024-06-01T17:53:05.411943Z"}]}
{"channel":"book","type":"update","data":[{"symbol":"LTC/USD","bids":[{"price":83.20,"qty":15.37500000}],"asks":[],"checksum":1469698774,"timestamp":"2024-06-01T17:53:05.412154Z"}]}
{"channel":"book","type":"update","data":[{"symbol":"LTC/USD","bids":[],"asks":[{"price":83.22,"qty":23.50987345}],"checksum":3590850948,"timestamp":"2024-06-01T17:53:05.414843Z"}]}
{"channel":"book","type":"update","data":[{"symbol":"LTC/USD","bids":[{"price":83.20,"qty":7.68750000}],"asks":[],"checksum":1767980925,"timestamp":"2024-06-01T17:53:05.415360Z"}]}
{"channel":"book","type":"update","data":[{"symbol":"LTC/USD","bids":[{"price":83.20,"qty":0.00000000},{"price":83.10,"qty":7.68750000}],"asks":[],"checksum":3607747502,"timestamp":"2024-06-01T17:53:05.415870Z"}]}
{"channel":"book","type":"update","data":[{"symbol":"LTC/USD","bids":[],"asks":[{"price":83.22,"qty":31.05987345}],"checksum":4173612154,"timestamp":"2024-06-01T17:53:05.618610Z"}]}
{"channel":"book","type":"update","data":[{"symbol":"LTC/USD","bids":[],"asks":[{"price":83.25,"qty":83.30339688}],"checksum":2156044625,"timestamp":"2024-06-01T17:53:05.659280Z"}]}
{"channel":"book","type":"update","data":[{"symbol":"LTC/USD","bids":[],"asks":[{"price":83.25,"qty":81.83178290}],"checksum":2709323874,"timestamp":"2024-06-01T17:53:05.758902Z"}]}
{"channel":"book","type":"update","data":[{"symbol":"LTC/USD","bids":[],"asks":[{"price":83.25,"qty":83.47928629}],"checksum":2130716684,"timestamp":"2024-06-01T17:53:05.759358Z"}]}
{"channel":"book","type":"update","data":[{"symbol":"LTC/USD","bids":[],"asks":[{"price":83.25,"qty":81.18711967}],"checksum":1583411515,"timestamp":"2024-06-01T17:53:05.868402Z"}]}
{"channel":"book","type":"update","data":[{"symbol":"LTC/USD","bids":[],"asks":[{"price":83.25,"qty":83.47928629}],"checksum":2130716684,"timestamp":"2024-06-01T17:53:05.960288Z"}]}
{"channel":"book","type":"update","data":[{"symbol":"LTC/USD","bids":[{"price":83.13,"qty":58.75696258}],"asks":[],"checksum":2711374911,"timestamp":"2024-06-01T17:53:06.604669Z"}]}
{"channel":"book","type":"update","data":[{"symbol":"LTC/USD","bids":[{"price":83.13,"qty":66.56075114}],"asks":[],"checksum":3992910312,"timestamp":"2024-06-01T17:53:06.888660Z"}]}
{"channel":"book","type":"update","data":[{"symbol":"LTC/USD","bids":[{"price":83.13,"qty":63.53124052}],"asks":[],"checksum":1909063497,"timestamp":"2024-06-01T17:53:07.347458Z"}]}
{"channel":"book","type":"update","data":[{"symbol":"LTC/USD","bids":[{"price":83.14,"qty":305.94528109}],"asks":[],"checksum":724794561,"timestamp":"2024-06-01T17:53:07.446561Z"}]}
{"channel":"book","type":"update","data":[{"symbol":"LTC/USD","bids":[],"asks":[{"price":83.24,"qty":75.25824026}],"checksum":782121001,"timestamp":"2024-06-01T17:53:07.553973Z"}]}
{"channel":"book","type":"update","data":[{"symbol":"LTC/USD","bids":[],"asks":[{"price":83.25,"qty":81.83178290}],"checksum":4041412679,"timestamp":"2024-06-01T17:53:07.981943Z"}]}
{"channel":"book","type":"update","data":[{"symbol":"LTC/USD","bids":[],"asks":[{"price":83.25,"qty":83.30339688}],"checksum":3508318580,"timestamp":"2024-06-01T17:53:07.982287Z"}]}
{"channel":"book","type":"update","data":[{"symbol":"LTC/USD","bids":[{"price":83.13,"qty":55.72745196}],"asks":[],"checksum":4263874822,"timestamp":"2024-06-01T17:53:09.110653Z"}]}
{"channel":"book","type":"update","data":[{"symbol":"LTC/USD","bids":[{"price":83.13,"qty":63.10057314}],"asks":[],"checksum":1079341650,"timestamp":"2024-06-01T17:53:09.114955Z"}]}
{"channel":"book","type":"update","data":[{"symbol":"LTC/USD","bids":[{"price":83.17,"qty":14.13440158}],"asks":[],"checksum":533502426,"timestamp":"2024-06-01T17:53:09.892303Z"}]}
{"channel":"book","type":"update","data":[{"symbol":"LTC/USD","bids":[{"price":83.16,"qty":227.37767815}],"asks":[],"checksum":2896846832,"timestamp":"2024-06-01T17:53:09.894646Z"}]}
{"channel":"book","type":"update","data":[{"symbol":"LTC/USD","bids":[{"price":83.20,"qty":7.68750000}],"asks":[],"checksum":3005136959,"timestamp":"2024-06-01T17:53:10.764738Z"}]}
{"channel":"book","type":"update","data":[{"symbol":"LTC/USD","bids":[{"price":83.20,"qty":15.37500000}],"asks":[],"checksum":3721423656,"timestamp":"2024-06-01T17:53:10.765276Z"}]}
{"channel":"book","type":"update","data":[{"symbol":"LTC/USD","bids":[{"price":83.20,"qty":7.68750000}],"asks":[],"checksum":3005136959,"timestamp":"2024-06-01T17:53:10.767658Z"}]}
{"channel":"book","type":"update","data":[{"symbol":"LTC/USD","bids":[{"price":83.20,"qty":0.00000000},{"price":83.10,"qty":7.68750000}],"asks":[],"checksum":2896846832,"timestamp":"2024-06-01T17:53:10.767826Z"}]}
{"channel":"book","type":"update","data":[{"symbol":"LTC/USD","bids":[],"asks":[{"price":83.23,"qty":51.66807537}],"checksum":3052417248,"timestamp":"2024-06-01T17:53:10.767899Z"}]}
{"channel":"book","type":"update","data":[{"symbol":"LTC/USD","bids":[],"asks":[{"price":83.23,"qty":69.35752793}],"checksum":970926816,"timestamp":"2024-06-01T17:53:10.770980Z"}]}
{"channel":"book","type":"update","data":[{"symbol":"LTC/USD","bids":[{"price":83.12,"qty":126.66290391},{"price":83.17,"qty":21.68440158}],"asks":[],"checksum":4062946457,"timestamp":"2024-06-01T17:53:11.213723Z"}]}
{"channel":"book","type":"update","data":[{"symbol":"LTC/USD","bids":[{"price":83.17,"qty":29.23440158}],"asks":[],"checksum":1472494355,"timestamp":"2024-06-01T17:53:11.218288Z"}]}
{"channel":"book","type":"update","data":[{"symbol":"LTC/USD","bids":[{"price":83.17,"qty":26.88718232}],"asks":[],"checksum":767971788,"timestamp":"2024-06-01T17:53:11.656645Z"}]}
{"channel":"book","type":"update","data":[{"symbol":"LTC/USD","bids":[{"price":83.13,"qty":55.72745196}],"asks":[],"checksum":2478224024,"timestamp":"2024-06-01T17:53:11.657076Z"}]}
{"channel":"book","type":"update","data":[{"symbol":"LTC/USD","bids":[{"price":83.13,"qty":63.26044206}],"asks":[],"checksum":23906686,"timestamp":"2024-06-01T17:53:11.665488Z"}]}
{"channel":"book","type":"update","data":[{"symbol":"LTC/USD","bids":[{"price":83.17,"qty":29.71789871}],"asks":[],"checksum":845872265,"timestamp":"2024-06-01T17:53:11.665576Z"}]}
{"channel":"book","type":"update","data":[{"symbol":"LTC/USD","bids":[],"asks":[{"price":83.25,"qty":81.01123026}],"checksum":1244404130,"timestamp":"2024-06-01T17:53:11.706398Z"}]}
{"channel":"book","type":"update","data":[{"symbol":"LTC/USD","bids":[],"asks":[{"price":83.25,"qty":83.30339688}],"checksum":845872265,"timestamp":"2024-06-01T17:53:11.811322Z"}]}
{"channel":"book","type":"update","data":[{"symbol":"LTC/USD","bids":[],"asks":[{"price":83.25,"qty":81.01123026}],"checksum":1244404130,"timestamp":"2024-06-01T17:53:13.837728Z"}]}
{"channel":"book","type":"update","data":[{"symbol":"LTC/USD","bids":[{"price":83.13,"qty":55.72745196}],"asks":[],"checksum":3640025668,"timestamp":"2024-06-01T17:53:14.196794Z"}]}
{"channel":"book","type":"update","data":[{"symbol":"LTC/USD","bids":[{"price":83.13,"qty":62.82998548}],"asks":[],"checksum":479807949,"timestamp":"2024-06-01T17:53:14.202134Z"}]}
{"channel":"book","type":"update","data":[{"symbol":"LTC/USD","bids":[],"asks":[{"price":83.25,"qty":83.30339688}],"checksum":1692380390,"timestamp":"2024-06-01T17:53:14.338289Z"}]}
{"channel":"book","type":"update","data":[{"symbol":"LTC/USD","bids":[{"price":83.12,"qty":72.58890391}],"asks":[],"checksum":400321388,"timestamp":"2024-06-01T17:53:14.621730Z"}]}
{"channel":"book","type":"update","data":[{"symbol":"LTC/USD","bids":[{"price":83.11,"qty":75.28150000}],"asks":[],"checksum":4279033479,"timestamp":"2024-06-01T17:53:14.624132Z"}]}
{"channel":"book","type":"update","data":[{"symbol":"LTC/USD","bids":[{"price":83.20,"qty":7.68750000}],"asks":[],"checksum":2681532262,"timestamp":"2024-06-01T17:53:15.554854Z"}]}
{"channel":"book","type":"update","data":[{"symbol":"LTC/USD","bids":[{"price":83.20,"qty":15.37500000}],"asks":[],"checksum":1697904681,"timestamp":"2024-06-01T17:53:15.554885Z"}]}
{"channel":"book","type":"update","data":[{"symbol":"LTC/USD","bids":[],"asks":[{"price":83.22,"qty":23.37237345}],"checksum":1460104338,"timestamp":"2024-06-01T17:53:15.554900Z"}]}
{"channel":"book","type":"update","data":[{"symbol":"LTC/USD","bids":[],"asks":[{"price":83.22,"qty":31.05987345}],"checksum":1697904681,"timestamp":"2024-06-01T17:53:15.560560Z"}]}
{"channel":"book","type":"update","data":[{"symbol":"LTC/USD","bids":[],"asks":[{"price":83.29,"qty":121.79345642}],"checksum":2081952760,"timestamp":"2024-06-01T17:53:15.560631Z"}]}
{"channel":"book","type":"update","data":[{"symbol":"LTC/USD","bids":[{"price":83.20,"qty":7.68750000}],"asks":[],"checksum":3624488944,"timestamp":"2024-06-01T17:53:15.732493Z"}]}
{"channel":"book","type":"update","data":[{"symbol":"LTC/USD","bids":[{"price":83.20,"qty":0.00000000},{"price":83.10,"qty":7.68750000}],"asks":[],"checksum":3100737041,"timestamp":"2024-06-01T17:53:15.794258Z"}]}
{"channel":"book","type":"update","data":[{"symbol":"LTC/USD","bids":[],"asks":[{"price":83.25,"qty":81.01123026}],"checksum":4194170713,"timestamp":"2024-06-01T17:53:15.935717Z"}]}
{"channel":"book","type":"update","data":[{"symbol":"LTC/USD","bids":[],"asks":[{"price":83.25,"qty":83.30339688}],"checksum":3100737041,"timestamp":"2024-06-01T17:53:16.187412Z"}]}
{"channel":"book","type":"update","data":[{"symbol":"LTC/USD","bids":[{"price":83.20,"qty":7.68750000}],"asks":[],"checksum":3624488944,"timestamp":"2024-06-01T17:53:16.580991Z"}]}
{"channel":"book","type":"update","data":[{"symbol":"LTC/USD","bids":[{"price":83.20,"qty":15.37500000}],"asks":[],"checksum":2081952760,"timestamp":"2024-06-01T17:53:16.581058Z"}]}
{"channel":"book","type":"update","data":[{"symbol":"LTC/USD","bids":[{"price":83.20,"qty":7.68750000}],"asks":[],"checksum":3624488944,"timestamp":"2024-06-01T17:53:16.584694Z"}]}
{"channel":"book","type":"update","data":[{"symbol":"LTC/USD","bids":[{"price":83.20,"qty":15.37500000}],"asks":[],"checksum":2081952760,"timestamp":"2024-06-01T17:53:16.589194Z"}]}
{"channel":"book","type":"update","data":[{"symbol":"LTC/USD","bids":[],"asks":[{"price":83.22,"qty":23.37237345}],"checksum":1311541059,"timestamp":"2024-06-01T17:53:16.644328Z"}]}
{"channel":"book","type":"update","data":[{"symbol":"LTC/USD","bids":[],"asks":[{"price":83.22,"qty":15.87657370}],"checksum":2755487298,"timestamp":"2024-06-01T17:53:16.647262Z"}]}
{"channel":"book","type":"update","data":[{"symbol":"LTC/USD","bids":[],"asks":[{"price":83.22,"qty":23.56407370}],"checksum":1327925344,"timestamp":"2024-06-01T17:53:16.650788Z"}]}
{"channel":"book","type":"update","data":[{"symbol":"LTC/USD","bids":[],"asks":[{"price":83.25,"qty":81.01123026}],"checksum":929066315,"timestamp":"2024-06-01T17:53:16.695675Z"}]}
{"channel":"book","type":"update","data":[{"symbol":"LTC/USD","bids":[],"asks":[{"price":83.22,"qty":31.25157370}],"checksum":4189388133,"timestamp":"2024-06-01T17:53:16.821223Z"}]}
{"channel":"book","type":"update","data":[{"symbol":"LTC/USD","bids":[{"price":83.13,"qty":55.72745196}],"asks":[],"checksum":2604585403,"timestamp":"2024-06-01T17:53:16.857249Z"}]}
