{"channel":"book","type":"snapshot","data":[{"symbol":"USD/JPY","bids":[{"price":156.932,"qty":792.82294242},{"price":156.931,"qty":17647.87231091},{"price":156.929,"qty":13956.61168039},{"price":156.641,"qty":200.00000000},{"price":154.515,"qty":9304.40778693},{"price":154.012,"qty":550.00000000},{"price":150.343,"qty":4652.20389346},{"price":150.200,"qty":1288.01597869},{"price":150.000,"qty":10.50000000},{"price":149.398,"qty":18608.81557386}],"asks":[{"price":157.552,"qty":1935.48387096},{"price":157.836,"qty":684.22180000},{"price":157.837,"qty":37001.00000000},{"price":157.852,"qty":21002.00000000},{"price":158.350,"qty":511.00000000},{"price":159.560,"qty":500.00000000},{"price":160.000,"qty":600.00000000},{"price":160.555,"qty":1000.00000000},{"price":161.547,"qty":2164.96380420},{"price":161.555,"qty":1000.00000000}],"checksum":81414921}]}
{"channel":"book","type":"update","data":[{"symbol":"USD/JPY","bids":[{"price":156.929,"qty":0.00000000},{"price":146.252,"qty":32565.42725426}],"asks":[],"checksum":2605181126,"timestamp":"2024-06-01T17:51:51.905983Z"}]}
{"channel":"book","type":"update","data":[{"symbol":"USD/JPY","bids":[{"price":156.933,"qty":13956.61168039}],"asks":[],"checksum":1627185876,"timestamp":"2024-06-01T17:51:51.946296Z"}]}
{"channel":"book","type":"update","data":[{"symbol":"USD/JPY","bids":[{"price":156.932,"qty":0.00000000},{"price":146.252,"qty":32565.42725426}],"asks":[],"checksum":4005244895,"timestamp":"2024-06-01T17:51:51.956947Z"}]}
{"channel":"book","type":"update","data":[{"symbol":"USD/JPY","bids":[{"price":156.934,"qty":792.81283851}],"asks":[],"checksum":2185249864,"timestamp":"2024-06-01T17:51:51.957148Z"}]}
{"channel":"book","type":"update","data":[{"symbol":"USD/JPY","bids":[{"price":156.931,"qty":0.00000000},{"price":146.252,"qty":32565.42725426},{"price":156.934,"qty":18440.34778711}],"asks":[],"checksum":2475936212,"timestamp":"2024-06-01T17:51:52.023252Z"}]}
{"channel":"book","type":"update","data":[{"symbol":"USD/JPY","bids":[{"price":156.934,"qty":792.81283851},{"price":156.935,"qty":17647.42249737}],"asks":[],"checksum":3132903986,"timestamp":"2024-06-01T17:51:52.068993Z"}]}
{"channel":"book","type":"update","data":[{"symbol":"USD/JPY","bids":[{"price":156.936,"qty":792.80273487}],"asks":[],"checksum":3111487838,"timestamp":"2024-06-01T17:51:52.079301Z"}]}
{"channel":"book","type":"update","data":[{"symbol":"USD/JPY","bids":[{"price":156.934,"qty":0.00000000},{"price":149.398,"qty":18608.81557386}],"asks":[],"checksum":2504149066,"timestamp":"2024-06-01T17:51:52.079351Z"}]}
{"channel":"book","type":"update","data":[{"symbol":"USD/JPY","bids":[{"price":156.933,"qty":0.00000000},{"price":146.252,"qty":32565.42725426}],"asks":[],"checksum":3611132544,"timestamp":"2024-06-01T17:51:56.716316Z"}]}
{"channel":"book","type":"update","data":[{"symbol":"USD/JPY","bids":[{"price":156.937,"qty":13956.61168039}],"asks":[],"checksum":3061463663,"timestamp":"2024-06-01T17:51:56.756638Z"}]}
{"channel":"book","type":"update","data":[{"symbol":"USD/JPY","bids":[{"price":156.936,"qty":0.00000000},{"price":146.252,"qty":32565.42725426}],"asks":[],"checksum":439015937,"timestamp":"2024-06-01T17:51:56.778480Z"}]}
{"channel":"book","type":"update","data":[{"symbol":"USD/JPY","bids":[{"price":156.938,"qty":792.79263148}],"asks":[],"checksum":624687534,"timestamp":"2024-06-01T17:51:56.778500Z"}]}
{"channel":"book","type":"update","data":[{"symbol":"USD/JPY","bids":[{"price":156.935,"qty":0.00000000},{"price":146.252,"qty":32565.42725426},{"price":156.938,"qty":18439.87778373}],"asks":[],"checksum":2481838624,"timestamp":"2024-06-01T17:51:56.819653Z"}]}
{"channel":"book","type":"update","data":[{"symbol":"USD/JPY","bids":[{"price":156.938,"qty":792.79263148},{"price":156.939,"qty":17646.97270675}],"asks":[],"checksum":2545036198,"timestamp":"2024-06-01T17:51:56.894963Z"}]}
{"channel":"book","type":"update","data":[{"symbol":"USD/JPY","bids":[{"price":156.938,"qty":0.00000000},{"price":146.252,"qty":32565.42725426}],"asks":[],"checksum":1620924532,"timestamp":"2024-06-01T17:51:56.900853Z"}]}
{"channel":"book","type":"update","data":[{"symbol":"USD/JPY","bids":[{"price":156.940,"qty":792.78252835}],"asks":[],"checksum":3848237496,"timestamp":"2024-06-01T17:51:56.901036Z"}]}
{"channel":"book","type":"update","data":[{"symbol":"USD/JPY","bids":[{"price":156.937,"qty":0.00000000},{"price":146.252,"qty":32565.42725426}],"asks":[],"checksum":151836057,"timestamp":"2024-06-01T17:52:01.800562Z"}]}
{"channel":"book","type":"update","data":[{"symbol":"USD/JPY","bids":[{"price":156.941,"qty":13956.61168039}],"asks":[],"checksum":2843444920,"timestamp":"2024-06-01T17:52:01.840761Z"}]}
{"channel":"book","type":"update","data":[{"symbol":"USD/JPY","bids":[{"price":156.940,"qty":0.00000000},{"price":146.252,"qty":32565.42725426}],"asks":[],"checksum":3969782476,"timestamp":"2024-06-01T17:52:01.849882Z"}]}
{"channel":"book","type":"update","data":[{"symbol":"USD/JPY","bids":[{"price":156.942,"qty":792.77242548}],"asks":[],"checksum":1870073835,"timestamp":"2024-06-01T17:52:01.849915Z"}]}
{"channel":"book","type":"update","data":[{"symbol":"USD/JPY","bids":[{"price":156.939,"qty":0.00000000},{"price":146.252,"qty":32565.42725426},{"price":156.943,"qty":17646.52293905}],"asks":[],"checksum":1872394201,"timestamp":"2024-06-01T17:52:01.900432Z"}]}
{"channel":"book","type":"update","data":[{"symbol":"USD/JPY","bids":[{"price":156.942,"qty":0.00000000},{"price":146.252,"qty":32565.42725426}],"asks":[],"checksum":3038755224,"timestamp":"2024-06-01T17:52:01.923266Z"}]}
{"channel":"book","type":"update","data":[{"symbol":"USD/JPY","bids":[{"price":156.944,"qty":792.76232286}],"asks":[],"checksum":3800158295,"timestamp":"2024-06-01T17:52:01.923373Z"}]}
{"channel":"book","type":"update","data":[{"symbol":"USD/JPY","bids":[{"price":154.515,"qty":0.00000000},{"price":146.252,"qty":32565.42725426}],"asks":[],"checksum":384377622,"timestamp":"2024-06-01T17:52:02.478335Z"}]}
{"channel":"book","type":"update","data":[{"symbol":"USD/JPY","bids":[{"price":154.516,"qty":9304.40778693}],"asks":[],"checksum":2863482455,"timestamp":"2024-06-01T17:52:02.518653Z"}]}
{"channel":"book","type":"update","data":[{"symbol":"USD/JPY","bids":[{"price":156.941,"qty":0.00000000},{"price":146.252,"qty":32565.42725426}],"asks":[],"checksum":3197796700,"timestamp":"2024-06-01T17:52:07.501193Z"}]}
{"channel":"book","type":"update","data":[{"symbol":"USD/JPY","bids":[{"price":156.945,"qty":13956.61168039}],"asks":[],"checksum":150446414,"timestamp":"2024-06-01T17:52:07.541578Z"}]}
{"channel":"book","type":"update","data":[{"symbol":"USD/JPY","bids":[{"price":156.944,"qty":0.00000000},{"price":146.252,"qty":32565.42725426}],"asks":[],"checksum":3667617489,"timestamp":"2024-06-01T17:52:07.562787Z"}]}
{"channel":"book","type":"update","data":[{"symbol":"USD/JPY","bids":[{"price":156.946,"qty":792.75222050}],"asks":[],"checksum":3223596045,"timestamp":"2024-06-01T17:52:07.563071Z"}]}
{"channel":"book","type":"update","data":[{"symbol":"USD/JPY","bids":[{"price":156.943,"qty":0.00000000},{"price":146.252,"qty":32565.42725426},{"price":156.946,"qty":18438.93784883}],"asks":[],"checksum":3955627120,"timestamp":"2024-06-01T17:52:07.635827Z"}]}
{"channel":"book","type":"update","data":[{"symbol":"USD/JPY","bids":[{"price":156.946,"qty":792.75222050},{"price":156.947,"qty":17646.07319429}],"asks":[],"checksum":372834494,"timestamp":"2024-06-01T17:52:07.701470Z"}]}
{"channel":"book","type":"update","data":[{"symbol":"USD/JPY","bids":[{"price":156.946,"qty":0.00000000},{"price":146.252,"qty":32565.42725426}],"asks":[],"checksum":1191800897,"timestamp":"2024-06-01T17:52:07.708599Z"}]}
{"channel":"book","type":"update","data":[{"symbol":"USD/JPY","bids":[{"price":156.948,"qty":792.74211840}],"asks":[],"checksum":1629144309,"timestamp":"2024-06-01T17:52:07.708639Z"}]}
{"channel":"book","type":"update","data":[{"symbol":"USD/JPY","bids":[{"price":156.945,"qty":0.00000000},{"price":146.252,"qty":32565.42725426}],"asks":[],"checksum":3674303765,"timestamp":"2024-06-01T17:52:13.710529Z"}]}
{"channel":"book","type":"update","data":[{"symbol":"USD/JPY","bids":[{"price":156.949,"qty":13956.61168039}],"asks":[],"checksum":593785774,"timestamp":"2024-06-01T17:52:13.750722Z"}]}
{"channel":"book","type":"update","data":[{"symbol":"USD/JPY","bids":[{"price":156.948,"qty":0.00000000},{"price":146.252,"qty":32565.42725426}],"asks":[],"checksum":2813318721,"timestamp":"2024-06-01T17:52:13.759989Z"}]}
{"channel":"book","type":"update","data":[{"symbol":"USD/JPY","bids":[{"price":156.950,"qty":792.73201656}],"asks":[],"checksum":3697179809,"timestamp":"2024-06-01T17:52:13.761928Z"}]}
{"channel":"book","type":"update","data":[{"symbol":"USD/JPY","bids":[{"price":156.947,"qty":0.00000000},{"price":146.252,"qty":32565.42725426},{"price":156.950,"qty":18438.46791732}],"asks":[],"checksum":1476704723,"timestamp":"2024-06-01T17:52:13.805803Z"}]}
{"channel":"book","type":"update","data":[{"symbol":"USD/JPY","bids":[{"price":156.950,"qty":792.73201656},{"price":156.951,"qty":17645.62347245}],"asks":[],"checksum":66825429,"timestamp":"2024-06-01T17:52:13.850479Z"}]}
{"channel":"book","type":"update","data":[{"symbol":"USD/JPY","bids":[{"price":156.950,"qty":0.00000000},{"price":146.252,"qty":32565.42725426}],"asks":[],"checksum":1243820309,"timestamp":"2024-06-01T17:52:13.856469Z"}]}
{"channel":"book","type":"update","data":[{"symbol":"USD/JPY","bids":[{"price":156.952,"qty":792.72191498}],"asks":[],"checksum":3112622740,"timestamp":"2024-06-01T17:52:13.856595Z"}]}
{"channel":"book","type":"update","data":[{"symbol":"USD/JPY","bids":[{"price":150.343,"qty":0.00000000},{"price":146.252,"qty":32565.42725426}],"asks":[],"checksum":1654997228,"timestamp":"2024-06-01T17:52:14.387993Z"}]}
{"channel":"book","type":"update","data":[{"symbol":"USD/JPY","bids":[{"price":150.344,"qty":4652.20389346}],"asks":[],"checksum":2674630536,"timestamp":"2024-06-01T17:52:14.428003Z"}]}
{"channel":"book","type":"update","data":[{"symbol":"USD/JPY","bids":[{"price":154.516,"qty":0.00000000},{"price":146.252,"qty":32565.42725426}],"asks":[],"checksum":638749703,"timestamp":"2024-06-01T17:52:16.784476Z"}]}
{"channel":"book","type":"update","data":[{"symbol":"USD/JPY","bids":[{"price":154.517,"qty":9304.40778693}],"asks":[],"checksum":295759799,"timestamp":"2024-06-01T17:52:16.824596Z"}]}
{"channel":"book","type":"update","data":[{"symbol":"USD/JPY","bids":[{"price":156.949,"qty":0.00000000},{"price":146.252,"qty":32565.42725426}],"asks":[],"checksum":2299739982,"timestamp":"2024-06-01T17:52:18.914803Z"}]}
{"channel":"book","type":"update","data":[{"symbol":"USD/JPY","bids":[{"price":156.953,"qty":13956.61168039}],"asks":[],"checksum":3109617710,"timestamp":"2024-06-01T17:52:18.956042Z"}]}
{"channel":"book","type":"update","data":[{"symbol":"USD/JPY","bids":[{"price":156.952,"qty":0.00000000},{"price":146.252,"qty":32565.42725426}],"asks":[],"checksum":348506775,"timestamp":"2024-06-01T17:52:18.975508Z"}]}
{"channel":"book","type":"update","data":[{"symbol":"USD/JPY","bids":[{"price":156.954,"qty":792.71181365}],"asks":[],"checksum":2479113672,"timestamp":"2024-06-01T17:52:18.975673Z"}]}
{"channel":"book","type":"update","data":[{"symbol":"USD/JPY","bids":[{"price":156.951,"qty":0.00000000},{"price":146.252,"qty":32565.42725426},{"price":156.955,"qty":17645.17377353}],"asks":[],"checksum":930253268,"timestamp":"2024-06-01T17:52:19.027596Z"}]}
{"channel":"book","type":"update","data":[{"symbol":"USD/JPY","bids":[{"price":156.954,"qty":0.00000000},{"price":146.252,"qty":32565.42725426}],"asks":[],"checksum":1101079786,"timestamp":"2024-06-01T17:52:19.037781Z"}]}
{"channel":"book","type":"update","data":[{"symbol":"USD/JPY","bids":[{"price":156.956,"qty":792.70171258}],"asks":[],"checksum":4157754078,"timestamp":"2024-06-01T17:52:19.037949Z"}]}
{"channel":"book","type":"update","data":[{"symbol":"USD/JPY","bids":[{"price":156.953,"qty":0.00000000},{"price":146.252,"qty":32565.42725426}],"asks":[],"checksum":2994991906,"timestamp":"2024-06-01T17:52:24.863890Z"}]}
{"channel":"book","type":"update","data":[{"symbol":"USD/JPY","bids":[{"price":156.957,"qty":13956.61168039}],"asks":[],"checksum":1850124231,"timestamp":"2024-06-01T17:52:24.962001Z"}]}
{"channel":"book","type":"update","data":[{"symbol":"USD/JPY","bids":[{"price":156.958,"qty":792.69161176}],"asks":[],"checksum":3335897600,"timestamp":"2024-06-01T17:52:24.971041Z"}]}
{"channel":"book","type":"update","data":[{"symbol":"USD/JPY","bids":[{"price":156.956,"qty":0.00000000},{"price":149.398,"qty":18608.81557386}],"asks":[],"checksum":2049051647,"timestamp":"2024-06-01T17:52:24.971087Z"}]}
{"channel":"book","type":"update","data":[{"symbol":"USD/JPY","bids":[{"price":156.955,"qty":0.00000000},{"price":146.252,"qty":32565.42725426},{"price":156.959,"qty":17644.72409753}],"asks":[],"checksum":2889088557,"timestamp":"2024-06-01T17:52:25.020555Z"}]}
{"channel":"book","type":"update","data":[{"symbol":"USD/JPY","bids":[{"price":156.958,"qty":0.00000000},{"price":146.252,"qty":32565.42725426}],"asks":[],"checksum":786291783,"timestamp":"2024-06-01T17:52:25.043987Z"}]}
{"channel":"book","type":"update","data":[{"symbol":"USD/JPY","bids":[{"price":156.960,"qty":792.68151121}],"asks":[],"checksum":754735117,"timestamp":"2024-06-01T17:52:25.044135Z"}]}
{"channel":"book","type":"update","data":[{"symbol":"USD/JPY","bids":[{"price":156.641,"qty":0.00000000},{"price":146.252,"qty":32565.42725426}],"asks":[],"checksum":2420053128,"timestamp":"2024-06-01T17:52:26.408409Z"}]}
{"channel":"book","type":"update","data":[{"symbol":"USD/JPY","bids":[{"price":156.957,"qty":0.00000000},{"price":145.500,"qty":1030.92783505}],"asks":[],"checksum":3356277927,"timestamp":"2024-06-01T17:52:30.547304Z"}]}
{"channel":"book","type":"update","data":[{"symbol":"USD/JPY","bids":[{"price":156.961,"qty":13956.61168039}],"asks":[],"checksum":2117129844,"timestamp":"2024-06-01T17:52:30.587377Z"}]}
{"channel":"book","type":"update","data":[{"symbol":"USD/JPY","bids":[{"price":156.960,"qty":0.00000000},{"price":145.500,"qty":1030.92783505}],"asks":[],"checksum":3086425859,"timestamp":"2024-06-01T17:52:30.607856Z"}]}
{"channel":"book","type":"update","data":[{"symbol":"USD/JPY","bids":[{"price":156.962,"qty":792.67141091}],"asks":[],"checksum":3991030205,"timestamp":"2024-06-01T17:52:30.608091Z"}]}
{"channel":"book","type":"update","data":[{"symbol":"USD/JPY","bids":[{"price":156.959,"qty":0.00000000},{"price":145.500,"qty":1030.92783505},{"price":156.962,"qty":18437.05826648}],"asks":[],"checksum":1866572903,"timestamp":"2024-06-01T17:52:30.633658Z"}]}
{"channel":"book","type":"update","data":[{"symbol":"USD/JPY","bids":[{"price":154.517,"qty":0.00000000},{"price":145.000,"qty":5.40000000}],"asks":[],"checksum":214666198,"timestamp":"2024-06-01T17:52:30.665496Z"}]}
{"channel":"book","type":"update","data":[{"symbol":"USD/JPY","bids":[{"price":156.962,"qty":792.67141091},{"price":156.963,"qty":17644.27444445}],"asks":[],"checksum":3852447553,"timestamp":"2024-06-01T17:52:30.680785Z"}]}
{"channel":"book","type":"update","data":[{"symbol":"USD/JPY","bids":[{"price":156.962,"qty":0.00000000},{"price":145.000,"qty":5.40000000}],"asks":[],"checksum":3794301877,"timestamp":"2024-06-01T17:52:30.692376Z"}]}
{"channel":"book","type":"update","data":[{"symbol":"USD/JPY","bids":[{"price":156.964,"qty":792.66131087}],"asks":[],"checksum":2202010003,"timestamp":"2024-06-01T17:52:30.692398Z"}]}
{"channel":"book","type":"update","data":[{"symbol":"USD/JPY","bids":[{"price":154.518,"qty":9304.40778693}],"asks":[],"checksum":678948221,"timestamp":"2024-06-01T17:52:30.705813Z"}]}
{"channel":"book","type":"update","data":[{"symbol":"USD/JPY","bids":[{"price":156.961,"qty":0.00000000},{"price":145.500,"qty":1030.92783505}],"asks":[],"checksum":2448892429,"timestamp":"2024-06-01T17:52:35.941884Z"}]}
{"channel":"book","type":"update","data":[{"symbol":"USD/JPY","bids":[{"price":156.965,"qty":13956.61168039}],"asks":[],"checksum":1242451500,"timestamp":"2024-06-01T17:52:35.982176Z"}]}
{"channel":"book","type":"update","data":[{"symbol":"USD/JPY","bids":[{"price":156.966,"qty":792.65121109}],"asks":[],"checksum":748113149,"timestamp":"2024-06-01T17:52:36.016320Z"}]}
{"channel":"book","type":"update","data":[{"symbol":"USD/JPY","bids":[{"price":156.964,"qty":0.00000000},{"price":146.252,"qty":32565.42725426}],"asks":[],"checksum":2597166210,"timestamp":"2024-06-01T17:52:36.016350Z"}]}
{"channel":"book","type":"update","data":[{"symbol":"USD/JPY","bids":[{"price":156.963,"qty":0.00000000},{"price":145.500,"qty":1030.92783505},{"price":156.966,"qty":18436.58843077}],"asks":[],"checksum":3190750244,"timestamp":"2024-06-01T17:52:36.040249Z"}]}
{"channel":"book","type":"update","data":[{"symbol":"USD/JPY","bids":[{"price":156.966,"qty":792.65121109},{"price":156.967,"qty":17643.82481429}],"asks":[],"checksum":1786002755,"timestamp":"2024-06-01T17:52:36.083493Z"}]}
{"channel":"book","type":"update","data":[{"symbol":"USD/JPY","bids":[{"price":156.966,"qty":0.00000000},{"price":145.500,"qty":1030.92783505}],"asks":[],"checksum":2745091444,"timestamp":"2024-06-01T17:52:36.110802Z"}]}
{"channel":"book","type":"update","data":[{"symbol":"USD/JPY","bids":[{"price":156.968,"qty":792.64111156}],"asks":[],"checksum":1347139940,"timestamp":"2024-06-01T17:52:36.110830Z"}]}
{"channel":"book","type":"update","data":[{"symbol":"USD/JPY","bids":[{"price":156.717,"qty":200.00000000}],"asks":[],"checksum":3488664853,"timestamp":"2024-06-01T17:52:37.310770Z"}]}
{"channel":"book","type":"update","data":[{"symbol":"USD/JPY","bids":[{"price":156.965,"qty":0.00000000},{"price":146.252,"qty":32565.42725426}],"asks":[],"checksum":624630327,"timestamp":"2024-06-01T17:52:40.914306Z"}]}
{"channel":"book","type":"update","data":[{"symbol":"USD/JPY","bids":[{"price":156.969,"qty":13956.61168039}],"asks":[],"checksum":3055648251,"timestamp":"2024-06-01T17:52:40.954740Z"}]}
{"channel":"book","type":"update","data":[{"symbol":"USD/JPY","bids":[{"price":156.968,"qty":0.00000000},{"price":146.252,"qty":32565.42725426}],"asks":[],"checksum":454700615,"timestamp":"2024-06-01T17:52:40.973091Z"}]}
{"channel":"book","type":"update","data":[{"symbol":"USD/JPY","bids":[{"price":156.970,"qty":792.63101229}],"asks":[],"checksum":2276403014,"timestamp":"2024-06-01T17:52:40.973465Z"}]}
{"channel":"book","type":"update","data":[{"symbol":"USD/JPY","bids":[{"price":156.967,"qty":0.00000000},{"price":146.252,"qty":32565.42725426},{"price":156.970,"qty":18436.11861899}],"asks":[],"checksum":672477678,"timestamp":"2024-06-01T17:52:41.006877Z"}]}
{"channel":"book","type":"update","data":[{"symbol":"USD/JPY","bids":[{"price":156.970,"qty":792.63101229},{"price":156.971,"qty":17643.37520704}],"asks":[],"checksum":2427052158,"timestamp":"2024-06-01T17:52:41.050344Z"}]}
{"channel":"book","type":"update","data":[{"symbol":"USD/JPY","bids":[{"price":156.970,"qty":0.00000000},{"price":146.252,"qty":32565.42725426}],"asks":[],"checksum":140364599,"timestamp":"2024-06-01T17:52:41.079724Z"}]}
{"channel":"book","type":"update","data":[{"symbol":"USD/JPY","bids":[{"price":156.972,"qty":792.62091328}],"asks":[],"checksum":462295619,"timestamp":"2024-06-01T17:52:41.079857Z"}]}
{"channel":"book","type":"update","data":[{"symbol":"USD/JPY","bids":[{"price":150.344,"qty":0.00000000},{"price":146.252,"qty":32565.42725426}],"asks":[],"checksum":1855438425,"timestamp":"2024-06-01T17:52:41.480149Z"}]}
{"channel":"book","type":"update","data":[{"symbol":"USD/JPY","bids":[{"price":150.345,"qty":4652.20389346}],"asks":[],"checksum":1382530908,"timestamp":"2024-06-01T17:52:41.520463Z"}]}
{"channel":"book","type":"update","data":[{"symbol":"USD/JPY","bids":[{"price":154.518,"qty":0.00000000},{"price":146.252,"qty":32565.42725426}],"asks":[],"checksum":2518800048,"timestamp":"2024-06-01T17:52:44.271002Z"}]}
{"channel":"book","type":"update","data":[{"symbol":"USD/JPY","bids":[{"price":154.519,"qty":9304.40778693}],"asks":[],"checksum":3702312803,"timestamp":"2024-06-01T17:52:44.311025Z"}]}
{"channel":"book","type":"update","data":[{"symbol":"USD/JPY","bids":[{"price":156.969,"qty":0.00000000},{"price":146.252,"qty":32565.42725426}],"asks":[],"checksum":1120879197,"timestamp":"2024-06-01T17:52:45.822541Z"}]}
{"channel":"book","type":"update","data":[{"symbol":"USD/JPY","bids":[{"price":156.973,"qty":13956.61168039}],"asks":[],"checksum":2887978633,"timestamp":"2024-06-01T17:52:45.863009Z"}]}
{"channel":"book","type":"update","data":[{"symbol":"USD/JPY","bids":[{"price":156.974,"qty":792.61081452}],"asks":[],"checksum":3581505155,"timestamp":"2024-06-01T17:52:45.893451Z"}]}
{"channel":"book","type":"update","data":[{"symbol":"USD/JPY","bids":[{"price":156.972,"qty":0.00000000},{"price":149.398,"qty":18608.81557386}],"asks":[],"checksum":3005577700,"timestamp":"2024-06-01T17:52:45.893604Z"}]}
{"channel":"book","type":"update","data":[{"symbol":"USD/JPY","bids":[{"price":156.971,"qty":0.00000000},{"price":146.252,"qty":32565.42725426},{"price":156.974,"qty":18435.64883116}],"asks":[],"checksum":3906206529,"timestamp":"2024-06-01T17:52:45.925057Z"}]}
{"channel":"book","type":"update","data":[{"symbol":"USD/JPY","bids":[{"price":156.974,"qty":792.61081452},{"price":156.975,"qty":17642.92562270}],"asks":[],"checksum":4160298878,"timestamp":"2024-06-01T17:52:45.977657Z"}]}
{"channel":"book","type":"update","data":[{"symbol":"USD/JPY","bids":[{"price":156.974,"qty":0.00000000},{"price":146.252,"qty":32565.42725426}],"asks":[],"checksum":3291548863,"timestamp":"2024-06-01T17:52:46.002010Z"}]}
{"channel":"book","type":"update","data":[{"symbol":"USD/JPY","bids":[{"price":156.976,"qty":792.60071603}],"asks":[],"checksum":1458741684,"timestamp":"2024-06-01T17:52:46.002312Z"}]}
{"channel":"book","type":"update","data":[{"symbol":"USD/JPY","bids":[{"price":156.973,"qty":0.00000000},{"price":146.252,"qty":32565.42725426}],"asks":[],"checksum":359875983,"timestamp":"2024-06-01T17:52:50.860600Z"}]}
{"channel":"book","type":"update","data":[{"symbol":"USD/JPY","bids":[{"price":156.977,"qty":13956.61168039}],"asks":[],"checksum":1219238667,"timestamp":"2024-06-01T17:52:50.900746Z"}]}
{"channel":"book","type":"update","data":[{"symbol":"USD/JPY","bids":[{"price":156.976,"qty":0.00000000},{"price":146.252,"qty":32565.42725426}],"asks":[],"checksum":1002127687,"timestamp":"2024-06-01T17:52:50.918812Z"}]}
{"channel":"book","type":"update","data":[{"symbol":"USD/JPY","bids":[{"price":156.978,"qty":792.59061779}],"asks":[],"checksum":2181787647,"timestamp":"2024-06-01T17:52:50.918829Z"}]}
{"channel":"book","type":"update","data":[{"symbol":"USD/JPY","bids":[{"price":156.975,"qty":0.00000000},{"price":146.252,"qty":32565.42725426},{"price":156.979,"qty":17642.47606128}],"asks":[],"checksum":592759964,"timestamp":"2024-06-01T17:52:50.971878Z"}]}
{"channel":"book","type":"update","data":[{"symbol":"USD/JPY","bids":[{"price":156.978,"qty":0.00000000},{"price":146.252,"qty":32565.42725426}],"asks":[],"checksum":4160295229,"timestamp":"2024-06-01T17:52:51.005790Z"}]}
{"channel":"book","type":"update","data":[{"symbol":"USD/JPY","bids":[{"price":156.980,"qty":792.58051981}],"asks":[],"checksum":4155771259,"timestamp":"2024-06-01T17:52:51.006022Z"}]}
{"channel":"book","type":"update","data":[{"symbol":"USD/JPY","bids":[{"price":156.977,"qty":0.00000000},{"price":146.252,"qty":32565.42725426}],"asks":[],"checksum":437879723,"timestamp":"2024-06-01T17:52:55.379752Z"}]}
{"channel":"book","type":"update","data":[{"symbol":"USD/JPY","bids":[{"price":154.519,"qty":0.00000000},{"price":145.500,"qty":1030.92783505}],"asks":[],"checksum":595232974,"timestamp":"2024-06-01T17:52:55.930059Z"}]}
