{"channel":"book","type":"snapshot","data":[{"symbol":"USDT/AUD","bids":[{"price":1.5034,"qty":3710.82373900},{"price":1.5033,"qty":4281.50623423},{"price":1.5032,"qty":2422.00000000},{"price":1.5031,"qty":2222.00000000},{"price":1.5030,"qty":2222.00000000},{"price":1.5029,"qty":2222.00000000},{"price":1.5027,"qty":3220.16868522},{"price":1.5026,"qty":19576.05352704},{"price":1.5025,"qty":10249.82682195},{"price":1.5024,"qty":5331.92000000}],"asks":[{"price":1.5038,"qty":1626.78669962},{"price":1.5039,"qty":24138.38000000},{"price":1.5040,"qty":467.38683861},{"price":1.5041,"qty":5440.96118843},{"price":1.5042,"qty":23121.42013619},{"price":1.5043,"qty":20000.00000000},{"price":1.5044,"qty":14250.26242548},{"price":1.5045,"qty":46204.79515616},{"price":1.5056,"qty":1002.00000000},{"price":1.5057,"qty":7301.00000000}],"checksum":1537023174}]}
{"channel":"book","type":"update","data":[{"symbol":"USDT/AUD","bids":[],"asks":[{"price":1.5041,"qty":5402.07000000}],"checksum":1461449608,"timestamp":"2024-06-01T17:51:25.950643Z"}]}
{"channel":"book","type":"update","data":[{"symbol":"USDT/AUD","bids":[],"asks":[{"price":1.5041,"qty":5453.92491790}],"checksum":50941631,"timestamp":"2024-06-01T17:51:25.956478Z"}]}
{"channel":"book","type":"update","data":[{"symbol":"USDT/AUD","bids":[],"asks":[{"price":1.5041,"qty":5610.01367024}],"checksum":704906125,"timestamp":"2024-06-01T17:51:26.031891Z"}]}
{"channel":"book","type":"update","data":[{"symbol":"USDT/AUD","bids":[],"asks":[{"price":1.5042,"qty":22965.33138385}],"checksum":3557621805,"timestamp":"2024-06-01T17:51:26.595562Z"}]}
{"channel":"book","type":"update","data":[{"symbol":"USDT/AUD","bids":[],"asks":[{"price":1.5045,"qty":3710.82373900}],"checksum":1230434715,"timestamp":"2024-06-01T17:51:26.749402Z"}]}
{"channel":"book","type":"update","data":[{"symbol":"USDT/AUD","bids":[],"asks":[{"price":1.5044,"qty":47737.90829350}],"checksum":2643053774,"timestamp":"2024-06-01T17:51:26.754171Z"}]}
{"channel":"book","type":"update","data":[{"symbol":"USDT/AUD","bids":[],"asks":[{"price":1.5042,"qty":397.00000000}],"checksum":2740028407,"timestamp":"2024-06-01T17:51:28.617847Z"}]}
{"channel":"book","type":"update","data":[{"symbol":"USDT/AUD","bids":[],"asks":[{"price":1.5044,"qty":36481.43101911}],"checksum":2496053629,"timestamp":"2024-06-01T17:51:28.617930Z"}]}
{"channel":"book","type":"update","data":[{"symbol":"USDT/AUD","bids":[],"asks":[{"price":1.5042,"qty":28706.55166730}],"checksum":2609968857,"timestamp":"2024-06-01T17:51:28.622828Z"}]}
{"channel":"book","type":"update","data":[{"symbol":"USDT/AUD","bids":[],"asks":[{"price":1.5043,"qty":23016.26602752}],"checksum":3282417653,"timestamp":"2024-06-01T17:51:28.622927Z"}]}
{"channel":"book","type":"update","data":[{"symbol":"USDT/AUD","bids":[],"asks":[{"price":1.5041,"qty":5558.15875234}],"checksum":2522685781,"timestamp":"2024-06-01T17:51:28.641898Z"}]}
{"channel":"book","type":"update","data":[{"symbol":"USDT/AUD","bids":[],"asks":[{"price":1.5041,"qty":5596.47688774}],"checksum":2190605589,"timestamp":"2024-06-01T17:51:28.647569Z"}]}
{"channel":"book","type":"update","data":[{"symbol":"USDT/AUD","bids":[],"asks":[{"price":1.5042,"qty":397.00000000}],"checksum":1233961662,"timestamp":"2024-06-01T17:51:32.096175Z"}]}
{"channel":"book","type":"update","data":[{"symbol":"USDT/AUD","bids":[],"asks":[{"price":1.5043,"qty":20000.00000000}],"checksum":297370514,"timestamp":"2024-06-01T17:51:32.096232Z"}]}
{"channel":"book","type":"update","data":[{"symbol":"USDT/AUD","bids":[],"asks":[{"price":1.5042,"qty":30157.17063470}],"checksum":2418457145,"timestamp":"2024-06-01T17:51:32.101214Z"}]}
{"channel":"book","type":"update","data":[{"symbol":"USDT/AUD","bids":[],"asks":[{"price":1.5041,"qty":5558.15875234}],"checksum":2229954169,"timestamp":"2024-06-01T17:51:34.367093Z"}]}
{"channel":"book","type":"update","data":[{"symbol":"USDT/AUD","bids":[],"asks":[{"price":1.5041,"qty":5651.49766191}],"checksum":1438467788,"timestamp":"2024-06-01T17:51:34.372779Z"}]}
{"channel":"book","type":"update","data":[{"symbol":"USDT/AUD","bids":[],"asks":[{"price":1.5042,"qty":397.00000000}],"checksum":1644596902,"timestamp":"2024-06-01T17:51:35.549759Z"}]}
{"channel":"book","type":"update","data":[{"symbol":"USDT/AUD","bids":[],"asks":[{"price":1.5042,"qty":29135.36087370}],"checksum":3014190051,"timestamp":"2024-06-01T17:51:35.552886Z"}]}
{"channel":"book","type":"update","data":[{"symbol":"USDT/AUD","bids":[],"asks":[{"price":1.5043,"qty":22043.61952200}],"checksum":2303058221,"timestamp":"2024-06-01T17:51:35.553037Z"}]}
{"channel":"book","type":"update","data":[{"symbol":"USDT/AUD","bids":[],"asks":[{"price":1.5042,"qty":29291.44962604}],"checksum":3334791767,"timestamp":"2024-06-01T17:51:35.718068Z"}]}
{"channel":"book","type":"update","data":[{"symbol":"USDT/AUD","bids":[],"asks":[{"price":1.5041,"qty":5495.40890957}],"checksum":1608848125,"timestamp":"2024-06-01T17:51:35.883963Z"}]}
{"channel":"book","type":"update","data":[{"symbol":"USDT/AUD","bids":[],"asks":[{"price":1.5041,"qty":5402.07000000}],"checksum":1510334669,"timestamp":"2024-06-01T17:51:37.116461Z"}]}
{"channel":"book","type":"update","data":[{"symbol":"USDT/AUD","bids":[],"asks":[{"price":1.5041,"qty":5448.73948358}],"checksum":2721506873,"timestamp":"2024-06-01T17:51:37.121247Z"}]}
{"channel":"book","type":"update","data":[{"symbol":"USDT/AUD","bids":[],"asks":[{"price":1.5043,"qty":20000.00000000}],"checksum":2564547831,"timestamp":"2024-06-01T17:51:38.954282Z"}]}
{"channel":"book","type":"update","data":[{"symbol":"USDT/AUD","bids":[],"asks":[{"price":1.5043,"qty":23065.42928299}],"checksum":4217175691,"timestamp":"2024-06-01T17:51:38.958301Z"}]}
{"channel":"book","type":"update","data":[{"symbol":"USDT/AUD","bids":[{"price":1.5026,"qty":0.00000000},{"price":1.5021,"qty":5901.00000000}],"asks":[],"checksum":3002369418,"timestamp":"2024-06-01T17:51:39.100677Z"}]}
{"channel":"book","type":"update","data":[{"symbol":"USDT/AUD","bids":[{"price":1.5026,"qty":17867.47612790}],"asks":[],"checksum":613354026,"timestamp":"2024-06-01T17:51:39.101814Z"}]}
{"channel":"book","type":"update","data":[{"symbol":"USDT/AUD","bids":[{"price":1.5026,"qty":18218.86009996}],"asks":[],"checksum":2247257105,"timestamp":"2024-06-01T17:51:39.336848Z"}]}
{"channel":"book","type":"update","data":[{"symbol":"USDT/AUD","bids":[{"price":1.5027,"qty":2868.78471316}],"asks":[],"checksum":2535534233,"timestamp":"2024-06-01T17:51:39.511272Z"}]}
{"channel":"book","type":"update","data":[{"symbol":"USDT/AUD","bids":[{"price":1.5027,"qty":2834.12336833}],"asks":[],"checksum":3589566905,"timestamp":"2024-06-01T17:51:39.966672Z"}]}
{"channel":"book","type":"update","data":[{"symbol":"USDT/AUD","bids":[{"price":1.5027,"qty":2854.13928098}],"asks":[],"checksum":3112701839,"timestamp":"2024-06-01T17:51:39.967485Z"}]}
{"channel":"book","type":"update","data":[{"symbol":"USDT/AUD","bids":[{"price":1.5024,"qty":0.00000000},{"price":1.5021,"qty":5901.00000000},{"price":1.5021,"qty":11140.66000000}],"asks":[],"checksum":3560484069,"timestamp":"2024-06-01T17:51:40.176264Z"}]}
{"channel":"book","type":"update","data":[{"symbol":"USDT/AUD","bids":[],"asks":[{"price":1.5039,"qty":19050.82000000},{"price":1.5037,"qty":4891.83000000}],"checksum":2180370281,"timestamp":"2024-06-01T17:51:40.176451Z"}]}
{"channel":"book","type":"update","data":[{"symbol":"USDT/AUD","bids":[],"asks":[{"price":1.5038,"qty":0.00000000},{"price":1.5057,"qty":7301.00000000},{"price":1.5036,"qty":1640.32719283}],"checksum":4011884415,"timestamp":"2024-06-01T17:51:40.182799Z"}]}
{"channel":"book","type":"update","data":[{"symbol":"USDT/AUD","bids":[],"asks":[{"price":1.5039,"qty":19473.82000000}],"checksum":2400701347,"timestamp":"2024-06-01T17:51:40.499674Z"}]}
{"channel":"book","type":"update","data":[{"symbol":"USDT/AUD","bids":[],"asks":[{"price":1.5042,"qty":28894.44962604}],"checksum":1912018816,"timestamp":"2024-06-01T17:51:40.994961Z"}]}
{"channel":"book","type":"update","data":[{"symbol":"USDT/AUD","bids":[{"price":1.5022,"qty":346.40354141}],"asks":[],"checksum":3108520413,"timestamp":"2024-06-01T17:51:41.781597Z"}]}
{"channel":"book","type":"update","data":[{"symbol":"USDT/AUD","bids":[{"price":1.5026,"qty":351.38397206}],"asks":[],"checksum":2236251704,"timestamp":"2024-06-01T17:51:42.167150Z"}]}
{"channel":"book","type":"update","data":[{"symbol":"USDT/AUD","bids":[{"price":1.5026,"qty":2352.97523712}],"asks":[],"checksum":2746225936,"timestamp":"2024-06-01T17:51:42.168472Z"}]}
{"channel":"book","type":"update","data":[{"symbol":"USDT/AUD","bids":[{"price":1.5022,"qty":19873.64644952}],"asks":[],"checksum":397653685,"timestamp":"2024-06-01T17:51:42.168547Z"}]}
{"channel":"book","type":"update","data":[{"symbol":"USDT/AUD","bids":[],"asks":[{"price":1.5043,"qty":20000.00000000}],"checksum":2855563024,"timestamp":"2024-06-01T17:51:42.592975Z"}]}
{"channel":"book","type":"update","data":[{"symbol":"USDT/AUD","bids":[],"asks":[{"price":1.5042,"qty":156.08875234}],"checksum":3621365383,"timestamp":"2024-06-01T17:51:42.593090Z"}]}
{"channel":"book","type":"update","data":[{"symbol":"USDT/AUD","bids":[],"asks":[{"price":1.5042,"qty":32043.73258475}],"checksum":3863349142,"timestamp":"2024-06-01T17:51:42.597692Z"}]}
{"channel":"book","type":"update","data":[{"symbol":"USDT/AUD","bids":[],"asks":[{"price":1.5040,"qty":437.00000000}],"checksum":2001772988,"timestamp":"2024-06-01T17:51:42.631434Z"}]}
{"channel":"book","type":"update","data":[{"symbol":"USDT/AUD","bids":[],"asks":[{"price":1.5041,"qty":5402.07000000}],"checksum":547819236,"timestamp":"2024-06-01T17:51:42.631511Z"}]}
{"channel":"book","type":"update","data":[{"symbol":"USDT/AUD","bids":[],"asks":[{"price":1.5038,"qty":30.38689620}],"checksum":863496131,"timestamp":"2024-06-01T17:51:42.636450Z"}]}
{"channel":"book","type":"update","data":[{"symbol":"USDT/AUD","bids":[],"asks":[{"price":1.5040,"qty":477.75787976}],"checksum":3166861379,"timestamp":"2024-06-01T17:51:42.636517Z"}]}
{"channel":"book","type":"update","data":[{"symbol":"USDT/AUD","bids":[],"asks":[{"price":1.5041,"qty":5433.84823763}],"checksum":2955083180,"timestamp":"2024-06-01T17:51:42.636779Z"}]}
{"channel":"book","type":"update","data":[{"symbol":"USDT/AUD","bids":[{"price":1.5027,"qty":2834.12336833}],"asks":[],"checksum":3697181594,"timestamp":"2024-06-01T17:51:42.947094Z"}]}
{"channel":"book","type":"update","data":[{"symbol":"USDT/AUD","bids":[{"price":1.5023,"qty":98.12488428}],"asks":[],"checksum":3156693454,"timestamp":"2024-06-01T17:51:42.948387Z"}]}
{"channel":"book","type":"update","data":[{"symbol":"USDT/AUD","bids":[],"asks":[{"price":1.5040,"qty":437.00000000}],"checksum":3203622672,"timestamp":"2024-06-01T17:51:45.277650Z"}]}
{"channel":"book","type":"update","data":[{"symbol":"USDT/AUD","bids":[],"asks":[{"price":1.5041,"qty":5402.07000000}],"checksum":2952060911,"timestamp":"2024-06-01T17:51:45.277943Z"}]}
{"channel":"book","type":"update","data":[{"symbol":"USDT/AUD","bids":[],"asks":[{"price":1.5040,"qty":488.81440611}],"checksum":2787227960,"timestamp":"2024-06-01T17:51:45.281910Z"}]}
{"channel":"book","type":"update","data":[{"symbol":"USDT/AUD","bids":[],"asks":[{"price":1.5041,"qty":5558.15875234}],"checksum":2440648850,"timestamp":"2024-06-01T17:51:45.452977Z"}]}
{"channel":"book","type":"update","data":[{"symbol":"USDT/AUD","bids":[],"asks":[{"price":1.5042,"qty":31887.64383241}],"checksum":2525996274,"timestamp":"2024-06-01T17:51:45.620588Z"}]}
{"channel":"book","type":"update","data":[{"symbol":"USDT/AUD","bids":[{"price":1.5023,"qty":0.00000000},{"price":1.5022,"qty":19527.24290811}],"asks":[],"checksum":2755041194,"timestamp":"2024-06-01T17:51:45.942173Z"}]}
{"channel":"book","type":"update","data":[{"symbol":"USDT/AUD","bids":[{"price":1.5023,"qty":78.59764137}],"asks":[],"checksum":4061549325,"timestamp":"2024-06-01T17:51:45.943302Z"}]}
{"channel":"book","type":"update","data":[{"symbol":"USDT/AUD","bids":[{"price":1.5033,"qty":441.00000000},{"price":1.5032,"qty":6262.50340515}],"asks":[],"checksum":1687903952,"timestamp":"2024-06-01T17:51:47.210502Z"}]}
{"channel":"book","type":"update","data":[{"symbol":"USDT/AUD","bids":[],"asks":[{"price":1.5038,"qty":0.00000000},{"price":1.5056,"qty":1002.00000000}],"checksum":1837303268,"timestamp":"2024-06-01T17:51:47.861466Z"}]}
{"channel":"book","type":"update","data":[{"symbol":"USDT/AUD","bids":[],"asks":[{"price":1.5038,"qty":26.74509612}],"checksum":2404945854,"timestamp":"2024-06-01T17:51:47.866265Z"}]}
{"channel":"book","type":"update","data":[{"symbol":"USDT/AUD","bids":[{"price":1.5023,"qty":0.00000000},{"price":1.5022,"qty":19527.24290811}],"asks":[],"checksum":3754373402,"timestamp":"2024-06-01T17:51:48.840619Z"}]}
{"channel":"book","type":"update","data":[{"symbol":"USDT/AUD","bids":[{"price":1.5023,"qty":59.07039847}],"asks":[],"checksum":3809932452,"timestamp":"2024-06-01T17:51:48.842071Z"}]}
{"channel":"book","type":"update","data":[{"symbol":"USDT/AUD","bids":[{"price":1.5032,"qty":2422.00000000},{"price":1.5033,"qty":4280.85216692}],"asks":[],"checksum":1291638168,"timestamp":"2024-06-01T17:51:49.709020Z"}]}
{"channel":"book","type":"update","data":[{"symbol":"USDT/AUD","bids":[],"asks":[{"price":1.5042,"qty":0.00000000},{"price":1.5056,"qty":1002.00000000}],"checksum":2585149762,"timestamp":"2024-06-01T17:51:49.730596Z"}]}
{"channel":"book","type":"update","data":[{"symbol":"USDT/AUD","bids":[],"asks":[{"price":1.5042,"qty":30795.03545898}],"checksum":3181961017,"timestamp":"2024-06-01T17:51:49.735776Z"}]}
{"channel":"book","type":"update","data":[{"symbol":"USDT/AUD","bids":[],"asks":[{"price":1.5041,"qty":8551.94390343}],"checksum":3556136601,"timestamp":"2024-06-01T17:51:50.243863Z"}]}
{"channel":"book","type":"update","data":[{"symbol":"USDT/AUD","bids":[],"asks":[{"price":1.5044,"qty":33487.64586802}],"checksum":3941762747,"timestamp":"2024-06-01T17:51:50.244882Z"}]}
{"channel":"book","type":"update","data":[{"symbol":"USDT/AUD","bids":[],"asks":[{"price":1.5038,"qty":6781.27366418}],"checksum":3961936993,"timestamp":"2024-06-01T17:51:53.266707Z"}]}
{"channel":"book","type":"update","data":[{"symbol":"USDT/AUD","bids":[],"asks":[{"price":1.5038,"qty":6754.52856806}],"checksum":3501415404,"timestamp":"2024-06-01T17:51:53.285421Z"}]}
{"channel":"book","type":"update","data":[{"symbol":"USDT/AUD","bids":[],"asks":[{"price":1.5040,"qty":437.00000000}],"checksum":3647356219,"timestamp":"2024-06-01T17:51:53.285563Z"}]}
{"channel":"book","type":"update","data":[{"symbol":"USDT/AUD","bids":[],"asks":[{"price":1.5038,"qty":6866.58695974}],"checksum":4076588478,"timestamp":"2024-06-01T17:51:53.290272Z"}]}
{"channel":"book","type":"update","data":[{"symbol":"USDT/AUD","bids":[{"price":1.5023,"qty":0.00000000},{"price":1.5022,"qty":19527.24290811}],"asks":[],"checksum":508101842,"timestamp":"2024-06-01T17:51:54.780989Z"}]}
{"channel":"book","type":"update","data":[{"symbol":"USDT/AUD","bids":[{"price":1.5023,"qty":78.59764137}],"asks":[],"checksum":2662708900,"timestamp":"2024-06-01T17:51:54.782191Z"}]}
{"channel":"book","type":"update","data":[{"symbol":"USDT/AUD","bids":[{"price":1.5033,"qty":441.00000000},{"price":1.5032,"qty":6262.22763132}],"asks":[],"checksum":3718100852,"timestamp":"2024-06-01T17:51:55.508699Z"}]}
{"channel":"book","type":"update","data":[{"symbol":"USDT/AUD","bids":[{"price":1.5032,"qty":2422.00000000},{"price":1.5033,"qty":4280.97217814}],"asks":[],"checksum":482911049,"timestamp":"2024-06-01T17:51:55.687211Z"}]}
{"channel":"book","type":"update","data":[{"symbol":"USDT/AUD","bids":[],"asks":[{"price":1.5038,"qty":6754.52856806}],"checksum":928338892,"timestamp":"2024-06-01T17:51:55.900604Z"}]}
{"channel":"book","type":"update","data":[{"symbol":"USDT/AUD","bids":[],"asks":[{"price":1.5038,"qty":6816.72408563}],"checksum":4020050785,"timestamp":"2024-06-01T17:51:55.905330Z"}]}
{"channel":"book","type":"update","data":[{"symbol":"USDT/AUD","bids":[],"asks":[{"price":1.5037,"qty":4922.21689620}],"checksum":1369788195,"timestamp":"2024-06-01T17:51:55.905476Z"}]}
{"channel":"book","type":"update","data":[{"symbol":"USDT/AUD","bids":[{"price":1.5023,"qty":424.97812456}],"asks":[],"checksum":4044585291,"timestamp":"2024-06-01T17:51:56.334205Z"}]}
{"channel":"book","type":"update","data":[{"symbol":"USDT/AUD","bids":[],"asks":[{"price":1.5042,"qty":0.00000000},{"price":1.5056,"qty":1002.00000000}],"checksum":361627518,"timestamp":"2024-06-01T17:51:56.982623Z"}]}
{"channel":"book","type":"update","data":[{"symbol":"USDT/AUD","bids":[],"asks":[{"price":1.5038,"qty":62.19551757}],"checksum":1317789673,"timestamp":"2024-06-01T17:51:56.982813Z"}]}
{"channel":"book","type":"update","data":[{"symbol":"USDT/AUD","bids":[],"asks":[{"price":1.5042,"qty":28921.98635551}],"checksum":3308158416,"timestamp":"2024-06-01T17:51:56.985782Z"}]}
{"channel":"book","type":"update","data":[{"symbol":"USDT/AUD","bids":[],"asks":[{"price":1.5038,"qty":10290.48512375}],"checksum":593857402,"timestamp":"2024-06-01T17:51:56.985884Z"}]}
{"channel":"book","type":"update","data":[{"symbol":"USDT/AUD","bids":[],"asks":[{"price":1.5042,"qty":29078.07510785}],"checksum":671430468,"timestamp":"2024-06-01T17:51:57.150963Z"}]}
{"channel":"book","type":"update","data":[{"symbol":"USDT/AUD","bids":[{"price":1.5026,"qty":351.38397206}],"asks":[],"checksum":3798757584,"timestamp":"2024-06-01T17:51:57.218020Z"}]}
{"channel":"book","type":"update","data":[{"symbol":"USDT/AUD","bids":[{"price":1.5026,"qty":4305.69952793}],"asks":[],"checksum":1032227241,"timestamp":"2024-06-01T17:51:57.219464Z"}]}
{"channel":"book","type":"update","data":[{"symbol":"USDT/AUD","bids":[],"asks":[{"price":1.5041,"qty":8395.85515109}],"checksum":1237903639,"timestamp":"2024-06-01T17:51:57.319411Z"}]}
{"channel":"book","type":"update","data":[{"symbol":"USDT/AUD","bids":[{"price":1.5026,"qty":3954.31555587}],"asks":[],"checksum":3053491229,"timestamp":"2024-06-01T17:51:57.568757Z"}]}
{"channel":"book","type":"update","data":[{"symbol":"USDT/AUD","bids":[{"price":1.5023,"qty":346.38048319}],"asks":[],"checksum":1640601111,"timestamp":"2024-06-01T17:51:57.769942Z"}]}
{"channel":"book","type":"update","data":[{"symbol":"USDT/AUD","bids":[{"price":1.5023,"qty":385.43496901}],"asks":[],"checksum":3543390862,"timestamp":"2024-06-01T17:51:57.773339Z"}]}
{"channel":"book","type":"update","data":[{"symbol":"USDT/AUD","bids":[{"price":1.5026,"qty":3974.33146852}],"asks":[],"checksum":4150022336,"timestamp":"2024-06-01T17:51:57.773410Z"}]}
{"channel":"book","type":"update","data":[{"symbol":"USDT/AUD","bids":[],"asks":[{"price":1.5037,"qty":4891.83000000}],"checksum":1494570642,"timestamp":"2024-06-01T17:51:58.415074Z"}]}
{"channel":"book","type":"update","data":[{"symbol":"USDT/AUD","bids":[],"asks":[{"price":1.5038,"qty":10228.28960618}],"checksum":1880034369,"timestamp":"2024-06-01T17:51:58.415185Z"}]}
{"channel":"book","type":"update","data":[{"symbol":"USDT/AUD","bids":[],"asks":[{"price":1.5037,"qty":4932.58787976}],"checksum":1537107329,"timestamp":"2024-06-01T17:51:58.417392Z"}]}
{"channel":"book","type":"update","data":[{"symbol":"USDT/AUD","bids":[],"asks":[{"price":1.5038,"qty":10259.40255684}],"checksum":470842451,"timestamp":"2024-06-01T17:51:58.417435Z"}]}
{"channel":"book","type":"update","data":[{"symbol":"USDT/AUD","bids":[],"asks":[{"price":1.5039,"qty":9972.46000000},{"price":1.5037,"qty":15105.61787976}],"checksum":2164596238,"timestamp":"2024-06-01T17:52:00.190215Z"}]}
{"channel":"book","type":"update","data":[{"symbol":"USDT/AUD","bids":[],"asks":[{"price":1.5039,"qty":423.00000000},{"price":1.5037,"qty":25233.10787976}],"checksum":18622468,"timestamp":"2024-06-01T17:52:00.190654Z"}]}
{"channel":"book","type":"update","data":[{"symbol":"USDT/AUD","bids":[{"price":1.5026,"qty":20.01591265}],"asks":[],"checksum":3407757236,"timestamp":"2024-06-01T17:52:00.207822Z"}]}
{"channel":"book","type":"update","data":[{"symbol":"USDT/AUD","bids":[{"price":1.5026,"qty":5927.05575933}],"asks":[],"checksum":2095185878,"timestamp":"2024-06-01T17:52:00.209222Z"}]}
{"channel":"book","type":"update","data":[{"symbol":"USDT/AUD","bids":[],"asks":[{"price":1.5042,"qty":156.08875234}],"checksum":4113576594,"timestamp":"2024-06-01T17:52:00.599608Z"}]}
{"channel":"book","type":"update","data":[{"symbol":"USDT/AUD","bids":[],"asks":[{"price":1.5042,"qty":31070.47861234}],"checksum":733199059,"timestamp":"2024-06-01T17:52:00.605023Z"}]}
{"channel":"book","type":"update","data":[{"symbol":"USDT/AUD","bids":[{"price":1.5026,"qty":5907.03984668}],"asks":[],"checksum":1783376122,"timestamp":"2024-06-01T17:52:00.762491Z"}]}
{"channel":"book","type":"update","data":[{"symbol":"USDT/AUD","bids":[{"price":1.5023,"qty":346.38048319}],"asks":[],"checksum":3635831907,"timestamp":"2024-06-01T17:52:00.762691Z"}]}
{"channel":"book","type":"update","data":[{"symbol":"USDT/AUD","bids":[{"price":1.5027,"qty":2873.66652389}],"asks":[],"checksum":2151878846,"timestamp":"2024-06-01T17:52:00.763291Z"}]}
{"channel":"book","type":"update","data":[{"symbol":"USDT/AUD","bids":[],"asks":[{"price":1.5037,"qty":25192.35000000}],"checksum":3245258947,"timestamp":"2024-06-01T17:52:01.019217Z"}]}
{"channel":"book","type":"update","data":[{"symbol":"USDT/AUD","bids":[],"asks":[{"price":1.5038,"qty":10228.28960618}],"checksum":338135015,"timestamp":"2024-06-01T17:52:01.019315Z"}]}
{"channel":"book","type":"update","data":[{"symbol":"USDT/AUD","bids":[],"asks":[{"price":1.5040,"qty":519.24181397}],"checksum":3324506848,"timestamp":"2024-06-01T17:52:01.024154Z"}]}
{"channel":"book","type":"update","data":[{"symbol":"USDT/AUD","bids":[{"price":1.5023,"qty":0.00000000},{"price":1.5022,"qty":15942.66698151}],"asks":[],"checksum":1867936950,"timestamp":"2024-06-01T17:52:03.527025Z"}]}
{"channel":"book","type":"update","data":[{"symbol":"USDT/AUD","bids":[{"price":1.5027,"qty":2834.12336833}],"asks":[],"checksum":212345396,"timestamp":"2024-06-01T17:52:03.738960Z"}]}
{"channel":"book","type":"update","data":[{"symbol":"USDT/AUD","bids":[{"price":1.5027,"qty":2854.13928098}],"asks":[],"checksum":1624529922,"timestamp":"2024-06-01T17:52:03.740322Z"}]}
{"channel":"book","type":"update","data":[{"symbol":"USDT/AUD","bids":[{"price":1.5023,"qty":39.05448582}],"asks":[],"checksum":1758638343,"timestamp":"2024-06-01T17:52:03.740442Z"}]}
{"channel":"book","type":"update","data":[{"symbol":"USDT/AUD","bids":[],"asks":[{"price":1.5038,"qty":0.00000000},{"price":1.5056,"qty":1002.00000000}],"checksum":2609799759,"timestamp":"2024-06-01T17:52:04.171779Z"}]}
{"channel":"book","type":"update","data":[{"symbol":"USDT/AUD","bids":[],"asks":[{"price":1.5042,"qty":156.08875234}],"checksum":3556983020,"timestamp":"2024-06-01T17:52:04.171949Z"}]}
{"channel":"book","type":"update","data":[{"symbol":"USDT/AUD","bids":[],"asks":[{"price":1.5040,"qty":4577.50766431}],"checksum":4209220611,"timestamp":"2024-06-01T17:52:04.174091Z"}]}
{"channel":"book","type":"update","data":[{"symbol":"USDT/AUD","bids":[],"asks":[{"price":1.5042,"qty":37465.45115094}],"checksum":3833787559,"timestamp":"2024-06-01T17:52:04.174113Z"}]}
{"channel":"book","type":"update","data":[{"symbol":"USDT/AUD","bids":[],"asks":[{"price":1.5040,"qty":4495.26585034}],"checksum":1424842826,"timestamp":"2024-06-01T17:52:06.180164Z"}]}
{"channel":"book","type":"update","data":[{"symbol":"USDT/AUD","bids":[],"asks":[{"price":1.5039,"qty":463.75787976}],"checksum":3701322825,"timestamp":"2024-06-01T17:52:06.184704Z"}]}
{"channel":"book","type":"update","data":[{"symbol":"USDT/AUD","bids":[],"asks":[{"price":1.5040,"qty":4557.43098417}],"checksum":2176864120,"timestamp":"2024-06-01T17:52:06.185149Z"}]}
{"channel":"book","type":"update","data":[{"symbol":"USDT/AUD","bids":[{"price":1.5026,"qty":0.00000000},{"price":1.5022,"qty":15942.66698151}],"asks":[],"checksum":3105447486,"timestamp":"2024-06-01T17:52:06.229570Z"}]}
{"channel":"book","type":"update","data":[{"symbol":"USDT/AUD","bids":[{"price":1.5022,"qty":351.38397206}],"asks":[],"checksum":4161880789,"timestamp":"2024-06-01T17:52:06.229807Z"}]}
{"channel":"book","type":"update","data":[{"symbol":"USDT/AUD","bids":[{"price":1.5026,"qty":3954.31555587}],"asks":[],"checksum":1531481519,"timestamp":"2024-06-01T17:52:06.230783Z"}]}
{"channel":"book","type":"update","data":[{"symbol":"USDT/AUD","bids":[{"price":1.5027,"qty":2834.12336833}],"asks":[],"checksum":1688390523,"timestamp":"2024-06-01T17:52:06.660257Z"}]}
{"channel":"book","type":"update","data":[{"symbol":"USDT/AUD","bids":[{"price":1.5026,"qty":3974.33146852}],"asks":[],"checksum":3213566856,"timestamp":"2024-06-01T17:52:06.661525Z"}]}
{"channel":"book","type":"update","data":[{"symbol":"USDT/AUD","bids":[],"asks":[{"price":1.5042,"qty":156.08875234}],"checksum":3299993248,"timestamp":"2024-06-01T17:52:07.802601Z"}]}
{"channel":"book","type":"update","data":[{"symbol":"USDT/AUD","bids":[],"asks":[{"price":1.5042,"qty":34701.19802816}],"checksum":466861368,"timestamp":"2024-06-01T17:52:07.807313Z"}]}
{"channel":"book","type":"update","data":[{"symbol":"USDT/AUD","bids":[{"price":1.5027,"qty":3185.50734039}],"asks":[],"checksum":3651396308,"timestamp":"2024-06-01T17:52:07.968803Z"}]}
{"channel":"book","type":"update","data":[{"symbol":"USDT/AUD","bids":[{"price":1.5026,"qty":20.01591265}],"asks":[],"checksum":4031595879,"timestamp":"2024-06-01T17:52:09.210633Z"}]}
{"channel":"book","type":"update","data":[{"symbol":"USDT/AUD","bids":[{"price":1.5026,"qty":2021.60717771}],"asks":[],"checksum":3910111114,"timestamp":"2024-06-01T17:52:09.211837Z"}]}
{"channel":"book","type":"update","data":[{"symbol":"USDT/AUD","bids":[],"asks":[{"price":1.5041,"qty":3373.78515109},{"price":1.5038,"qty":4990.08000000}],"checksum":3895818323,"timestamp":"2024-06-01T17:52:10.157866Z"}]}
{"channel":"book","type":"update","data":[{"symbol":"USDT/AUD","bids":[],"asks":[{"price":1.5041,"qty":3529.87390343}],"checksum":3860194099,"timestamp":"2024-06-01T17:52:11.026130Z"}]}
{"channel":"book","type":"update","data":[{"symbol":"USDT/AUD","bids":[],"asks":[{"price":1.5042,"qty":34545.10927582}],"checksum":84757207,"timestamp":"2024-06-01T17:52:11.189594Z"}]}
{"channel":"book","type":"update","data":[{"symbol":"USDT/AUD","bids":[],"asks":[{"price":1.5042,"qty":0.00000000},{"price":1.5056,"qty":1002.00000000}],"checksum":3092821346,"timestamp":"2024-06-01T17:52:11.417117Z"}]}
{"channel":"book","type":"update","data":[{"symbol":"USDT/AUD","bids":[],"asks":[{"price":1.5040,"qty":499.16513383}],"checksum":336067532,"timestamp":"2024-06-01T17:52:11.417275Z"}]}
{"channel":"book","type":"update","data":[{"symbol":"USDT/AUD","bids":[],"asks":[{"price":1.5042,"qty":40390.62641437}],"checksum":1539181952,"timestamp":"2024-06-01T17:52:11.419701Z"}]}
{"channel":"book","type":"update","data":[{"symbol":"USDT/AUD","bids":[],"asks":[{"price":1.5039,"qty":423.00000000}],"checksum":3696080311,"timestamp":"2024-06-01T17:52:11.636972Z"}]}
{"channel":"book","type":"update","data":[{"symbol":"USDT/AUD","bids":[],"asks":[{"price":1.5040,"qty":437.00000000}],"checksum":808101908,"timestamp":"2024-06-01T17:52:11.636997Z"}]}
{"channel":"book","type":"update","data":[{"symbol":"USDT/AUD","bids":[],"asks":[{"price":1.5041,"qty":3628.75357468}],"checksum":93374266,"timestamp":"2024-06-01T17:52:11.638248Z"}]}
{"channel":"book","type":"update","data":[{"symbol":"USDT/AUD","bids":[],"asks":[{"price":1.5041,"qty":3529.87390343}],"checksum":808101908,"timestamp":"2024-06-01T17:52:14.452181Z"}]}
{"channel":"book","type":"update","data":[{"symbol":"USDT/AUD","bids":[],"asks":[{"price":1.5041,"qty":3653.59965161}],"checksum":1423552194,"timestamp":"2024-06-01T17:52:14.455324Z"}]}
{"channel":"book","type":"update","data":[{"symbol":"USDT/AUD","bids":[],"asks":[{"price":1.5036,"qty":0.00000000},{"price":1.5056,"qty":1002.00000000},{"price":1.5036,"qty":1891.85246315}],"checksum":2190133862,"timestamp":"2024-06-01T17:52:14.675580Z"}]}
{"channel":"book","type":"update","data":[{"symbol":"USDT/AUD","bids":[{"price":1.5026,"qty":20.01591265}],"asks":[],"checksum":3929291109,"timestamp":"2024-06-01T17:52:15.229329Z"}]}
{"channel":"book","type":"update","data":[{"symbol":"USDT/AUD","bids":[{"price":1.5026,"qty":3974.33146852}],"asks":[],"checksum":2988877624,"timestamp":"2024-06-01T17:52:15.230519Z"}]}
{"channel":"book","type":"update","data":[{"symbol":"USDT/AUD","bids":[],"asks":[{"price":1.5041,"qty":3529.87390343}],"checksum":3604324846,"timestamp":"2024-06-01T17:52:17.140436Z"}]}
{"channel":"book","type":"update","data":[{"symbol":"USDT/AUD","bids":[],"asks":[{"price":1.5041,"qty":3643.22866805}],"checksum":1843185291,"timestamp":"2024-06-01T17:52:17.145395Z"}]}
{"channel":"book","type":"update","data":[{"symbol":"USDT/AUD","bids":[{"price":1.5023,"qty":385.43496901}],"asks":[],"checksum":1235416915,"timestamp":"2024-06-01T17:52:17.867588Z"}]}
{"channel":"book","type":"update","data":[{"symbol":"USDT/AUD","bids":[{"price":1.5026,"qty":20.01591265}],"asks":[],"checksum":2484707455,"timestamp":"2024-06-01T17:52:18.223334Z"}]}
{"channel":"book","type":"update","data":[{"symbol":"USDT/AUD","bids":[{"price":1.5026,"qty":5927.05575933}],"asks":[],"checksum":878649473,"timestamp":"2024-06-01T17:52:18.224398Z"}]}
{"channel":"book","type":"update","data":[{"symbol":"USDT/AUD","bids":[{"price":1.5027,"qty":2834.12336833}],"asks":[],"checksum":2636250765,"timestamp":"2024-06-01T17:52:18.556582Z"}]}
{"channel":"book","type":"update","data":[{"symbol":"USDT/AUD","bids":[{"price":1.5023,"qty":346.38048319}],"asks":[],"checksum":802927124,"timestamp":"2024-06-01T17:52:18.606936Z"}]}
{"channel":"book","type":"update","data":[{"symbol":"USDT/AUD","bids":[{"price":1.5026,"qty":5907.03984668}],"asks":[],"checksum":1847861309,"timestamp":"2024-06-01T17:52:18.607023Z"}]}
{"channel":"book","type":"update","data":[{"symbol":"USDT/AUD","bids":[{"price":1.5027,"qty":2893.17469722}],"asks":[],"checksum":1971843633,"timestamp":"2024-06-01T17:52:18.607640Z"}]}
{"channel":"book","type":"update","data":[{"symbol":"USDT/AUD","bids":[],"asks":[{"price":1.5042,"qty":0.00000000},{"price":1.5056,"qty":1002.00000000}],"checksum":392924148,"timestamp":"2024-06-01T17:52:18.666113Z"}]}
{"channel":"book","type":"update","data":[{"symbol":"USDT/AUD","bids":[],"asks":[{"price":1.5042,"qty":38956.86030832}],"checksum":466625647,"timestamp":"2024-06-01T17:52:18.671193Z"}]}
