{"channel":"book","type":"snapshot","data":[{"symbol":"USDT/EUR","bids":[{"price":0.9217,"qty":22.34904565},{"price":0.9216,"qty":283363.52689504},{"price":0.9215,"qty":202524.05001656},{"price":0.9214,"qty":727709.36901899},{"price":0.9213,"qty":349616.62088864},{"price":0.9212,"qty":313449.60900415},{"price":0.9211,"qty":62460.81826149},{"price":0.9210,"qty":18207.99246601},{"price":0.9209,"qty":58488.39148911},{"price":0.9208,"qty":85676.49593567}],"asks":[{"price":0.9218,"qty":401190.00950288},{"price":0.9219,"qty":299119.39515647},{"price":0.9220,"qty":170697.23014985},{"price":0.9221,"qty":108457.58192246},{"price":0.9222,"qty":92505.73255894},{"price":0.9223,"qty":129103.69260185},{"price":0.9224,"qty":51132.71039958},{"price":0.9225,"qty":155964.01976658},{"price":0.9226,"qty":50109.29278321},{"price":0.9228,"qty":53050.10160363}],"checksum":1694686297}]}
{"channel":"book","type":"update","data":[{"symbol":"USDT/EUR","bids":[],"asks":[{"price":0.9220,"qty":179502.52774985}],"checksum":2049612406,"timestamp":"2024-06-01T17:51:26.973441Z"}]}
{"channel":"book","type":"update","data":[{"symbol":"USDT/EUR","bids":[{"price":0.9215,"qty":202169.88096668}],"asks":[],"checksum":1317949436,"timestamp":"2024-06-01T17:51:27.040940Z"}]}
{"channel":"book","type":"update","data":[{"symbol":"USDT/EUR","bids":[{"price":0.9215,"qty":202784.58774904}],"asks":[],"checksum":59820740,"timestamp":"2024-06-01T17:51:27.043872Z"}]}
{"channel":"book","type":"update","data":[{"symbol":"USDT/EUR","bids":[],"asks":[{"price":0.9218,"qty":400190.00950288}],"checksum":1316765360,"timestamp":"2024-06-01T17:51:27.634939Z"}]}
{"channel":"book","type":"update","data":[{"symbol":"USDT/EUR","bids":[{"price":0.9216,"qty":277896.52689504}],"asks":[],"checksum":2752440088,"timestamp":"2024-06-01T17:51:28.079003Z"}]}
{"channel":"book","type":"update","data":[{"symbol":"USDT/EUR","bids":[{"price":0.9214,"qty":173888.05024115}],"asks":[],"checksum":1098931299,"timestamp":"2024-06-01T17:51:28.513268Z"}]}
{"channel":"book","type":"update","data":[{"symbol":"USDT/EUR","bids":[{"price":0.9215,"qty":216815.59256226}],"asks":[],"checksum":139963752,"timestamp":"2024-06-01T17:51:28.519364Z"}]}
{"channel":"book","type":"update","data":[{"symbol":"USDT/EUR","bids":[{"price":0.9214,"qty":675684.16701104}],"asks":[],"checksum":3313947150,"timestamp":"2024-06-01T17:51:28.519597Z"}]}
{"channel":"book","type":"update","data":[{"symbol":"USDT/EUR","bids":[],"asks":[{"price":0.9218,"qty":273759.61142028}],"checksum":3615274070,"timestamp":"2024-06-01T17:51:28.617419Z"}]}
{"channel":"book","type":"update","data":[{"symbol":"USDT/EUR","bids":[],"asks":[{"price":0.9219,"qty":243233.68186182}],"checksum":3441408039,"timestamp":"2024-06-01T17:51:28.617451Z"}]}
{"channel":"book","type":"update","data":[{"symbol":"USDT/EUR","bids":[],"asks":[{"price":0.9218,"qty":418431.32112237}],"checksum":1403586896,"timestamp":"2024-06-01T17:51:28.622320Z"}]}
{"channel":"book","type":"update","data":[{"symbol":"USDT/EUR","bids":[],"asks":[{"price":0.9219,"qty":301854.47861296}],"checksum":625200050,"timestamp":"2024-06-01T17:51:28.622340Z"}]}
{"channel":"book","type":"update","data":[{"symbol":"USDT/EUR","bids":[{"price":0.9215,"qty":216200.88577990}],"asks":[],"checksum":804907690,"timestamp":"2024-06-01T17:51:29.209306Z"}]}
{"channel":"book","type":"update","data":[{"symbol":"USDT/EUR","bids":[{"price":0.9215,"qty":217393.72370946}],"asks":[],"checksum":112945924,"timestamp":"2024-06-01T17:51:29.251392Z"}]}
{"channel":"book","type":"update","data":[{"symbol":"USDT/EUR","bids":[{"price":0.9210,"qty":8758.76246601},{"price":0.9209,"qty":68202.09148911}],"asks":[],"checksum":3165361943,"timestamp":"2024-06-01T17:51:30.231901Z"}]}
{"channel":"book","type":"update","data":[{"symbol":"USDT/EUR","bids":[],"asks":[{"price":0.9222,"qty":81959.56255894},{"price":0.9221,"qty":118373.89192246}],"checksum":2146873216,"timestamp":"2024-06-01T17:51:30.232160Z"}]}
{"channel":"book","type":"update","data":[{"symbol":"USDT/EUR","bids":[{"price":0.9216,"qty":279966.52689504},{"price":0.9214,"qty":679883.16701104}],"asks":[],"checksum":301868887,"timestamp":"2024-06-01T17:51:30.528931Z"}]}
{"channel":"book","type":"update","data":[{"symbol":"USDT/EUR","bids":[{"price":0.9215,"qty":203362.71889624}],"asks":[],"checksum":1459491565,"timestamp":"2024-06-01T17:51:31.101900Z"}]}
{"channel":"book","type":"update","data":[{"symbol":"USDT/EUR","bids":[{"price":0.9214,"qty":178087.05024115}],"asks":[],"checksum":3376549910,"timestamp":"2024-06-01T17:51:31.102031Z"}]}
{"channel":"book","type":"update","data":[{"symbol":"USDT/EUR","bids":[{"price":0.9215,"qty":226588.14029434}],"asks":[],"checksum":1393442275,"timestamp":"2024-06-01T17:51:31.104539Z"}]}
{"channel":"book","type":"update","data":[{"symbol":"USDT/EUR","bids":[{"price":0.9214,"qty":795246.76658208}],"asks":[],"checksum":856866501,"timestamp":"2024-06-01T17:51:31.104620Z"}]}
{"channel":"book","type":"update","data":[{"symbol":"USDT/EUR","bids":[{"price":0.9215,"qty":225395.30236478}],"asks":[],"checksum":1736664534,"timestamp":"2024-06-01T17:51:31.444633Z"}]}
{"channel":"book","type":"update","data":[{"symbol":"USDT/EUR","bids":[{"price":0.9215,"qty":226917.57033199}],"asks":[],"checksum":23616193,"timestamp":"2024-06-01T17:51:31.450727Z"}]}
{"channel":"book","type":"update","data":[{"symbol":"USDT/EUR","bids":[],"asks":[{"price":0.9218,"qty":273759.61142028}],"checksum":3545009862,"timestamp":"2024-06-01T17:51:32.095899Z"}]}
{"channel":"book","type":"update","data":[{"symbol":"USDT/EUR","bids":[],"asks":[{"price":0.9219,"qty":243233.68186182}],"checksum":3855613062,"timestamp":"2024-06-01T17:51:32.096013Z"}]}
{"channel":"book","type":"update","data":[{"symbol":"USDT/EUR","bids":[],"asks":[{"price":0.9219,"qty":411825.91453460}],"checksum":3583258269,"timestamp":"2024-06-01T17:51:32.101683Z"}]}
{"channel":"book","type":"update","data":[{"symbol":"USDT/EUR","bids":[{"price":0.9216,"qty":283833.52689504}],"asks":[],"checksum":3313609937,"timestamp":"2024-06-01T17:51:33.529527Z"}]}
{"channel":"book","type":"update","data":[{"symbol":"USDT/EUR","bids":[{"price":0.9215,"qty":203692.14893389}],"asks":[],"checksum":1549521997,"timestamp":"2024-06-01T17:51:33.558751Z"}]}
{"channel":"book","type":"update","data":[{"symbol":"USDT/EUR","bids":[{"price":0.9214,"qty":178087.05024115}],"asks":[],"checksum":1011308395,"timestamp":"2024-06-01T17:51:33.558835Z"}]}
{"channel":"book","type":"update","data":[{"symbol":"USDT/EUR","bids":[{"price":0.9214,"qty":779138.03713363}],"asks":[],"checksum":932409044,"timestamp":"2024-06-01T17:51:33.560594Z"}]}
{"channel":"book","type":"update","data":[{"symbol":"USDT/EUR","bids":[{"price":0.9215,"qty":218074.34677885}],"asks":[],"checksum":1286307193,"timestamp":"2024-06-01T17:51:33.560628Z"}]}
{"channel":"book","type":"update","data":[{"symbol":"USDT/EUR","bids":[{"price":0.9215,"qty":216552.07881164}],"asks":[],"checksum":960123027,"timestamp":"2024-06-01T17:51:33.658912Z"}]}
{"channel":"book","type":"update","data":[{"symbol":"USDT/EUR","bids":[{"price":0.9215,"qty":217834.53806672}],"asks":[],"checksum":4038045428,"timestamp":"2024-06-01T17:51:33.701674Z"}]}
{"channel":"book","type":"update","data":[{"symbol":"USDT/EUR","bids":[],"asks":[{"price":0.9228,"qty":53016.84281809},{"price":0.9218,"qty":273792.85681115}],"checksum":590193580,"timestamp":"2024-06-01T17:51:34.346241Z"}]}
{"channel":"book","type":"update","data":[{"symbol":"USDT/EUR","bids":[{"price":0.9216,"qty":279966.52689504}],"asks":[],"checksum":859316704,"timestamp":"2024-06-01T17:51:34.459802Z"}]}
{"channel":"book","type":"update","data":[{"symbol":"USDT/EUR","bids":[],"asks":[{"price":0.9222,"qty":69202.62735894},{"price":0.9221,"qty":106598.25942246}],"checksum":1693810046,"timestamp":"2024-06-01T17:51:35.246684Z"}]}
{"channel":"book","type":"update","data":[{"symbol":"USDT/EUR","bids":[],"asks":[{"price":0.9219,"qty":243233.68186182}],"checksum":1420734309,"timestamp":"2024-06-01T17:51:35.549414Z"}]}
{"channel":"book","type":"update","data":[{"symbol":"USDT/EUR","bids":[],"asks":[{"price":0.9219,"qty":422109.28746100}],"checksum":769813792,"timestamp":"2024-06-01T17:51:35.552253Z"}]}
{"channel":"book","type":"update","data":[{"symbol":"USDT/EUR","bids":[{"price":0.9216,"qty":285173.52689504}],"asks":[],"checksum":3780018538,"timestamp":"2024-06-01T17:51:35.710388Z"}]}
{"channel":"book","type":"update","data":[{"symbol":"USDT/EUR","bids":[{"price":0.9215,"qty":216552.07881164}],"asks":[],"checksum":685473549,"timestamp":"2024-06-01T17:51:35.723765Z"}]}
{"channel":"book","type":"update","data":[{"symbol":"USDT/EUR","bids":[{"price":0.9215,"qty":217881.29522756}],"asks":[],"checksum":2540400342,"timestamp":"2024-06-01T17:51:35.728658Z"}]}
{"channel":"book","type":"update","data":[{"symbol":"USDT/EUR","bids":[{"price":0.9215,"qty":203499.09738260}],"asks":[],"checksum":2127732541,"timestamp":"2024-06-01T17:51:36.109283Z"}]}
{"channel":"book","type":"update","data":[{"symbol":"USDT/EUR","bids":[{"price":0.9214,"qty":178087.05024115}],"asks":[],"checksum":1963370114,"timestamp":"2024-06-01T17:51:36.109328Z"}]}
{"channel":"book","type":"update","data":[{"symbol":"USDT/EUR","bids":[{"price":0.9214,"qty":794699.29201389}],"asks":[],"checksum":1112861125,"timestamp":"2024-06-01T17:51:36.111494Z"}]}
{"channel":"book","type":"update","data":[{"symbol":"USDT/EUR","bids":[{"price":0.9215,"qty":219649.95331041}],"asks":[],"checksum":433124356,"timestamp":"2024-06-01T17:51:36.111548Z"}]}
{"channel":"book","type":"update","data":[{"symbol":"USDT/EUR","bids":[{"price":0.9210,"qty":6335.75526601},{"price":0.9214,"qty":790975.29201389}],"asks":[],"checksum":933862429,"timestamp":"2024-06-01T17:51:37.414772Z"}]}
{"channel":"book","type":"update","data":[{"symbol":"USDT/EUR","bids":[{"price":0.9215,"qty":218320.73689449}],"asks":[],"checksum":2924735729,"timestamp":"2024-06-01T17:51:37.978469Z"}]}
{"channel":"book","type":"update","data":[{"symbol":"USDT/EUR","bids":[{"price":0.9215,"qty":219790.22479290}],"asks":[],"checksum":2503866110,"timestamp":"2024-06-01T17:51:37.983971Z"}]}
{"channel":"book","type":"update","data":[{"symbol":"USDT/EUR","bids":[{"price":0.9215,"qty":203639.36886509}],"asks":[],"checksum":695480678,"timestamp":"2024-06-01T17:51:38.506865Z"}]}
{"channel":"book","type":"update","data":[{"symbol":"USDT/EUR","bids":[{"price":0.9214,"qty":174363.05024115}],"asks":[],"checksum":1510767984,"timestamp":"2024-06-01T17:51:38.506925Z"}]}
{"channel":"book","type":"update","data":[{"symbol":"USDT/EUR","bids":[{"price":0.9215,"qty":210946.93437868}],"asks":[],"checksum":1006401224,"timestamp":"2024-06-01T17:51:38.511703Z"}]}
{"channel":"book","type":"update","data":[{"symbol":"USDT/EUR","bids":[{"price":0.9214,"qty":799550.86562846}],"asks":[],"checksum":2710507352,"timestamp":"2024-06-01T17:51:38.511794Z"}]}
{"channel":"book","type":"update","data":[{"symbol":"USDT/EUR","bids":[],"asks":[{"price":0.9219,"qty":243233.68186182}],"checksum":3636710685,"timestamp":"2024-06-01T17:51:38.953740Z"}]}
{"channel":"book","type":"update","data":[{"symbol":"USDT/EUR","bids":[],"asks":[{"price":0.9218,"qty":280936.13453941}],"checksum":1928128911,"timestamp":"2024-06-01T17:51:38.957689Z"}]}
{"channel":"book","type":"update","data":[{"symbol":"USDT/EUR","bids":[],"asks":[{"price":0.9219,"qty":425027.19552438}],"checksum":1466906465,"timestamp":"2024-06-01T17:51:38.957809Z"}]}
{"channel":"book","type":"update","data":[{"symbol":"USDT/EUR","bids":[],"asks":[{"price":0.9218,"qty":275675.13453941}],"checksum":2019309438,"timestamp":"2024-06-01T17:51:40.130556Z"}]}
{"channel":"book","type":"update","data":[{"symbol":"USDT/EUR","bids":[{"price":0.9215,"qty":209477.44648027}],"asks":[],"checksum":2150880665,"timestamp":"2024-06-01T17:51:40.181382Z"}]}
{"channel":"book","type":"update","data":[{"symbol":"USDT/EUR","bids":[{"price":0.9215,"qty":211243.06306394}],"asks":[],"checksum":4252665517,"timestamp":"2024-06-01T17:51:40.186737Z"}]}
{"channel":"book","type":"update","data":[{"symbol":"USDT/EUR","bids":[],"asks":[{"price":0.9219,"qty":430371.19552438}],"checksum":3390601608,"timestamp":"2024-06-01T17:51:40.320121Z"}]}
{"channel":"book","type":"update","data":[{"symbol":"USDT/EUR","bids":[],"asks":[{"price":0.9218,"qty":275661.93210941}],"checksum":3511845605,"timestamp":"2024-06-01T17:51:40.572667Z"}]}
{"channel":"book","type":"update","data":[{"symbol":"USDT/EUR","bids":[],"asks":[{"price":0.9218,"qty":279954.93210941}],"checksum":1605036503,"timestamp":"2024-06-01T17:51:40.963514Z"}]}
{"channel":"book","type":"update","data":[{"symbol":"USDT/EUR","bids":[{"price":0.9215,"qty":203935.49755035}],"asks":[],"checksum":3210433519,"timestamp":"2024-06-01T17:51:41.039085Z"}]}
{"channel":"book","type":"update","data":[{"symbol":"USDT/EUR","bids":[{"price":0.9214,"qty":174363.05024115}],"asks":[],"checksum":623389311,"timestamp":"2024-06-01T17:51:41.039173Z"}]}
{"channel":"book","type":"update","data":[{"symbol":"USDT/EUR","bids":[{"price":0.9214,"qty":793093.09369636}],"asks":[],"checksum":4163351096,"timestamp":"2024-06-01T17:51:41.040859Z"}]}
{"channel":"book","type":"update","data":[{"symbol":"USDT/EUR","bids":[{"price":0.9213,"qty":335396.54263513}],"asks":[],"checksum":2516167051,"timestamp":"2024-06-01T17:51:41.366929Z"}]}
{"channel":"book","type":"update","data":[{"symbol":"USDT/EUR","bids":[{"price":0.9213,"qty":349616.62088864}],"asks":[],"checksum":4163351096,"timestamp":"2024-06-01T17:51:41.396150Z"}]}
{"channel":"book","type":"update","data":[{"symbol":"USDT/EUR","bids":[{"price":0.9217,"qty":0.00000000},{"price":0.9207,"qty":71556.62432406},{"price":0.9216,"qty":284957.06715769}],"asks":[],"checksum":2244072122,"timestamp":"2024-06-01T17:51:41.483840Z"}]}
{"channel":"book","type":"update","data":[{"symbol":"USDT/EUR","bids":[],"asks":[{"price":0.9219,"qty":330353.43013136}],"checksum":3228722558,"timestamp":"2024-06-01T17:51:41.489017Z"}]}
{"channel":"book","type":"update","data":[{"symbol":"USDT/EUR","bids":[{"price":0.9217,"qty":22.15558466}],"asks":[],"checksum":4291326316,"timestamp":"2024-06-01T17:51:41.490218Z"}]}
{"channel":"book","type":"update","data":[{"symbol":"USDT/EUR","bids":[],"asks":[{"price":0.9222,"qty":57857.08631777}],"checksum":4198596283,"timestamp":"2024-06-01T17:51:41.490887Z"}]}
{"channel":"book","type":"update","data":[{"symbol":"USDT/EUR","bids":[],"asks":[{"price":0.9218,"qty":379985.20050453}],"checksum":3342151590,"timestamp":"2024-06-01T17:51:41.493057Z"}]}
{"channel":"book","type":"update","data":[{"symbol":"USDT/EUR","bids":[],"asks":[{"price":0.9218,"qty":379951.95511366},{"price":0.9228,"qty":53050.09184549}],"checksum":2912630248,"timestamp":"2024-06-01T17:51:41.496915Z"}]}
{"channel":"book","type":"update","data":[{"symbol":"USDT/EUR","bids":[],"asks":[{"price":0.9222,"qty":69202.62735894}],"checksum":2819766847,"timestamp":"2024-06-01T17:51:41.521226Z"}]}
{"channel":"book","type":"update","data":[{"symbol":"USDT/EUR","bids":[],"asks":[{"price":0.9218,"qty":372808.67738540}],"checksum":1555983505,"timestamp":"2024-06-01T17:51:42.592432Z"}]}
{"channel":"book","type":"update","data":[{"symbol":"USDT/EUR","bids":[],"asks":[{"price":0.9219,"qty":148559.91646880}],"checksum":2111399553,"timestamp":"2024-06-01T17:51:42.592496Z"}]}
{"channel":"book","type":"update","data":[{"symbol":"USDT/EUR","bids":[],"asks":[{"price":0.9219,"qty":293500.39141085}],"checksum":634013889,"timestamp":"2024-06-01T17:51:42.597378Z"}]}
{"channel":"book","type":"update","data":[{"symbol":"USDT/EUR","bids":[],"asks":[{"price":0.9220,"qty":178081.52774985},{"price":0.9221,"qty":106017.25942246}],"checksum":1772920314,"timestamp":"2024-06-01T17:51:43.004292Z"}]}
{"channel":"book","type":"update","data":[{"symbol":"USDT/EUR","bids":[],"asks":[{"price":0.9220,"qty":178121.52774985}],"checksum":2101323132,"timestamp":"2024-06-01T17:51:43.205465Z"}]}
{"channel":"book","type":"update","data":[{"symbol":"USDT/EUR","bids":[{"price":0.9214,"qty":174363.05024115}],"asks":[],"checksum":2687515963,"timestamp":"2024-06-01T17:51:43.547261Z"}]}
{"channel":"book","type":"update","data":[{"symbol":"USDT/EUR","bids":[{"price":0.9215,"qty":234235.61814091}],"asks":[],"checksum":623350629,"timestamp":"2024-06-01T17:51:43.552386Z"}]}
{"channel":"book","type":"update","data":[{"symbol":"USDT/EUR","bids":[{"price":0.9214,"qty":711344.22536209}],"asks":[],"checksum":3062779412,"timestamp":"2024-06-01T17:51:43.552531Z"}]}
{"channel":"book","type":"update","data":[{"symbol":"USDT/EUR","bids":[{"price":0.9209,"qty":34996.14148911}],"asks":[],"checksum":2492556637,"timestamp":"2024-06-01T17:51:43.719142Z"}]}
{"channel":"book","type":"update","data":[{"symbol":"USDT/EUR","bids":[],"asks":[{"price":0.9219,"qty":260294.44141085}],"checksum":2229149748,"timestamp":"2024-06-01T17:51:43.724342Z"}]}
{"channel":"book","type":"update","data":[{"symbol":"USDT/EUR","bids":[],"asks":[{"price":0.9218,"qty":406014.62738540}],"checksum":4184407570,"timestamp":"2024-06-01T17:51:43.731697Z"}]}
{"channel":"book","type":"update","data":[{"symbol":"USDT/EUR","bids":[{"price":0.9216,"qty":279750.06715769}],"asks":[],"checksum":3015108500,"timestamp":"2024-06-01T17:51:43.753072Z"}]}
{"channel":"book","type":"update","data":[{"symbol":"USDT/EUR","bids":[{"price":0.9217,"qty":0.00000000},{"price":0.9207,"qty":104762.57432406}],"asks":[],"checksum":3006123923,"timestamp":"2024-06-01T17:51:43.926827Z"}]}
{"channel":"book","type":"update","data":[{"symbol":"USDT/EUR","bids":[{"price":0.9217,"qty":22.15558466}],"asks":[],"checksum":3015108500,"timestamp":"2024-06-01T17:51:43.930798Z"}]}
{"channel":"book","type":"update","data":[{"symbol":"USDT/EUR","bids":[],"asks":[{"price":0.9228,"qty":53016.84281809},{"price":0.9218,"qty":406047.87650272}],"checksum":3094130695,"timestamp":"2024-06-01T17:51:43.933715Z"}]}
{"channel":"book","type":"update","data":[{"symbol":"USDT/EUR","bids":[],"asks":[{"price":0.9218,"qty":406014.62738540},{"price":0.9228,"qty":53050.09193541}],"checksum":1538734935,"timestamp":"2024-06-01T17:51:43.938063Z"}]}
{"channel":"book","type":"update","data":[{"symbol":"USDT/EUR","bids":[{"price":0.9215,"qty":232470.00155724}],"asks":[],"checksum":2690492017,"timestamp":"2024-06-01T17:51:44.464325Z"}]}
{"channel":"book","type":"update","data":[{"symbol":"USDT/EUR","bids":[{"price":0.9215,"qty":234173.35527266}],"asks":[],"checksum":3732983164,"timestamp":"2024-06-01T17:51:44.470329Z"}]}
{"channel":"book","type":"update","data":[{"symbol":"USDT/EUR","bids":[],"asks":[{"price":0.9221,"qty":105017.25942246}],"checksum":2614631679,"timestamp":"2024-06-01T17:51:45.484341Z"}]}
{"channel":"book","type":"update","data":[{"symbol":"USDT/EUR","bids":[{"price":0.9216,"qty":278750.06715769}],"asks":[],"checksum":34618608,"timestamp":"2024-06-01T17:51:45.484359Z"}]}
{"channel":"book","type":"update","data":[{"symbol":"USDT/EUR","bids":[],"asks":[{"price":0.9221,"qty":106017.25942246}],"checksum":1195961715,"timestamp":"2024-06-01T17:51:45.490099Z"}]}
{"channel":"book","type":"update","data":[{"symbol":"USDT/EUR","bids":[{"price":0.9216,"qty":279750.06715769}],"asks":[],"checksum":3732983164,"timestamp":"2024-06-01T17:51:45.490160Z"}]}
{"channel":"book","type":"update","data":[{"symbol":"USDT/EUR","bids":[{"price":0.9216,"qty":283801.06715769}],"asks":[],"checksum":2300827789,"timestamp":"2024-06-01T17:51:45.981581Z"}]}
{"channel":"book","type":"update","data":[{"symbol":"USDT/EUR","bids":[{"price":0.9215,"qty":203873.23468210}],"asks":[],"checksum":3484718881,"timestamp":"2024-06-01T17:51:46.015762Z"}]}
{"channel":"book","type":"update","data":[{"symbol":"USDT/EUR","bids":[{"price":0.9214,"qty":174363.05024115}],"asks":[],"checksum":1545423440,"timestamp":"2024-06-01T17:51:46.015777Z"}]}
{"channel":"book","type":"update","data":[{"symbol":"USDT/EUR","bids":[{"price":0.9215,"qty":239479.32952119}],"asks":[],"checksum":2123549037,"timestamp":"2024-06-01T17:51:46.020738Z"}]}
{"channel":"book","type":"update","data":[{"symbol":"USDT/EUR","bids":[{"price":0.9214,"qty":768375.67611059}],"asks":[],"checksum":3860140389,"timestamp":"2024-06-01T17:51:46.021043Z"}]}
{"channel":"book","type":"update","data":[{"symbol":"USDT/EUR","bids":[],"asks":[{"price":0.9219,"qty":115353.96646880}],"checksum":1186693503,"timestamp":"2024-06-01T17:51:46.129879Z"}]}
{"channel":"book","type":"update","data":[{"symbol":"USDT/EUR","bids":[],"asks":[{"price":0.9219,"qty":261322.77870349}],"checksum":3907140381,"timestamp":"2024-06-01T17:51:46.134756Z"}]}
{"channel":"book","type":"update","data":[{"symbol":"USDT/EUR","bids":[],"asks":[{"price":0.9228,"qty":53016.84281809},{"price":0.9218,"qty":406047.85897483}],"checksum":3090288537,"timestamp":"2024-06-01T17:51:46.151899Z"}]}
{"channel":"book","type":"update","data":[{"symbol":"USDT/EUR","bids":[{"price":0.9217,"qty":0.00000000},{"price":0.9207,"qty":104762.57432406},{"price":0.9216,"qty":283823.00884414}],"asks":[],"checksum":2738909981,"timestamp":"2024-06-01T17:51:46.162176Z"}]}
{"channel":"book","type":"update","data":[{"symbol":"USDT/EUR","bids":[{"price":0.9215,"qty":139431.05312106}],"asks":[],"checksum":4042934678,"timestamp":"2024-06-01T17:51:46.166652Z"}]}
{"channel":"book","type":"update","data":[{"symbol":"USDT/EUR","bids":[],"asks":[{"price":0.9218,"qty":406014.62738540},{"price":0.9217,"qty":33.23158943}],"checksum":1527025642,"timestamp":"2024-06-01T17:51:46.169497Z"}]}
{"channel":"book","type":"update","data":[{"symbol":"USDT/EUR","bids":[{"price":0.9216,"qty":383860.70271513}],"asks":[],"checksum":2702269984,"timestamp":"2024-06-01T17:51:46.170696Z"}]}
{"channel":"book","type":"update","data":[{"symbol":"USDT/EUR","bids":[{"price":0.9216,"qty":383838.76102868},{"price":0.9215,"qty":139452.99718859}],"asks":[],"checksum":3330979915,"timestamp":"2024-06-01T17:51:46.173879Z"}]}
{"channel":"book","type":"update","data":[{"symbol":"USDT/EUR","bids":[{"price":0.9215,"qty":137749.64347317}],"asks":[],"checksum":3525250924,"timestamp":"2024-06-01T17:51:46.664769Z"}]}
{"channel":"book","type":"update","data":[{"symbol":"USDT/EUR","bids":[{"price":0.9215,"qty":139624.36009878}],"asks":[],"checksum":2072240193,"timestamp":"2024-06-01T17:51:46.670856Z"}]}
{"channel":"book","type":"update","data":[{"symbol":"USDT/EUR","bids":[{"price":0.9216,"qty":379787.76102868}],"asks":[],"checksum":840412719,"timestamp":"2024-06-01T17:51:48.277620Z"}]}
{"channel":"book","type":"update","data":[{"symbol":"USDT/EUR","bids":[{"price":0.9215,"qty":104018.26525969}],"asks":[],"checksum":802564462,"timestamp":"2024-06-01T17:51:48.521220Z"}]}
{"channel":"book","type":"update","data":[{"symbol":"USDT/EUR","bids":[{"price":0.9214,"qty":174363.05024115}],"asks":[],"checksum":1248086383,"timestamp":"2024-06-01T17:51:48.521303Z"}]}
{"channel":"book","type":"update","data":[{"symbol":"USDT/EUR","bids":[{"price":0.9214,"qty":903658.15658882}],"asks":[],"checksum":3348107257,"timestamp":"2024-06-01T17:51:48.526348Z"}]}
{"channel":"book","type":"update","data":[{"symbol":"USDT/EUR","bids":[{"price":0.9215,"qty":137855.70201594}],"asks":[],"checksum":822710204,"timestamp":"2024-06-01T17:51:48.526377Z"}]}
{"channel":"book","type":"update","data":[{"symbol":"USDT/EUR","bids":[],"asks":[{"price":0.9217,"qty":5585.23158943}],"checksum":1697583926,"timestamp":"2024-06-01T17:51:49.724703Z"}]}
{"channel":"book","type":"update","data":[{"symbol":"USDT/EUR","bids":[],"asks":[{"price":0.9219,"qty":115353.96646880}],"checksum":2155868775,"timestamp":"2024-06-01T17:51:49.730175Z"}]}
{"channel":"book","type":"update","data":[{"symbol":"USDT/EUR","bids":[],"asks":[{"price":0.9218,"qty":450178.04764871}],"checksum":3451493134,"timestamp":"2024-06-01T17:51:49.735042Z"}]}
{"channel":"book","type":"update","data":[{"symbol":"USDT/EUR","bids":[],"asks":[{"price":0.9219,"qty":244645.53889320}],"checksum":2844646369,"timestamp":"2024-06-01T17:51:49.735175Z"}]}
{"channel":"book","type":"update","data":[{"symbol":"USDT/EUR","bids":[],"asks":[{"price":0.9217,"qty":33.23158943}],"checksum":4255860587,"timestamp":"2024-06-01T17:51:49.758744Z"}]}
{"channel":"book","type":"update","data":[{"symbol":"USDT/EUR","bids":[{"price":0.9216,"qty":385007.76102868}],"asks":[],"checksum":645799776,"timestamp":"2024-06-01T17:51:49.877843Z"}]}
{"channel":"book","type":"update","data":[{"symbol":"USDT/EUR","bids":[],"asks":[{"price":0.9225,"qty":145870.38976658},{"price":0.9223,"qty":139062.52260185}],"checksum":971334523,"timestamp":"2024-06-01T17:51:50.236937Z"}]}
{"channel":"book","type":"update","data":[{"symbol":"USDT/EUR","bids":[{"price":0.9214,"qty":174363.05024115}],"asks":[],"checksum":3021022701,"timestamp":"2024-06-01T17:51:51.058523Z"}]}
{"channel":"book","type":"update","data":[{"symbol":"USDT/EUR","bids":[{"price":0.9215,"qty":104018.26525969}],"asks":[],"checksum":1116251560,"timestamp":"2024-06-01T17:51:51.058743Z"}]}
{"channel":"book","type":"update","data":[{"symbol":"USDT/EUR","bids":[{"price":0.9214,"qty":850223.37106974}],"asks":[],"checksum":1909838436,"timestamp":"2024-06-01T17:51:51.061590Z"}]}
{"channel":"book","type":"update","data":[{"symbol":"USDT/EUR","bids":[{"price":0.9215,"qty":102143.54863408}],"asks":[],"checksum":1602961133,"timestamp":"2024-06-01T17:51:51.161633Z"}]}
{"channel":"book","type":"update","data":[{"symbol":"USDT/EUR","bids":[{"price":0.9215,"qty":103207.80780529}],"asks":[],"checksum":449546302,"timestamp":"2024-06-01T17:51:51.169686Z"}]}
{"channel":"book","type":"update","data":[{"symbol":"USDT/EUR","bids":[{"price":0.9216,"qty":284969.97181675}],"asks":[],"checksum":1773507519,"timestamp":"2024-06-01T17:51:51.302299Z"}]}
{"channel":"book","type":"update","data":[{"symbol":"USDT/EUR","bids":[{"price":0.9215,"qty":203255.51793403}],"asks":[],"checksum":1865170173,"timestamp":"2024-06-01T17:51:51.306539Z"}]}
{"channel":"book","type":"update","data":[{"symbol":"USDT/EUR","bids":[{"price":0.9215,"qty":203233.57386650},{"price":0.9216,"qty":284991.91054702}],"asks":[],"checksum":115723877,"timestamp":"2024-06-01T17:51:51.309790Z"}]}
{"channel":"book","type":"update","data":[{"symbol":"USDT/EUR","bids":[{"price":0.9216,"qty":279771.91054702}],"asks":[],"checksum":328411365,"timestamp":"2024-06-01T17:51:51.432303Z"}]}
{"channel":"book","type":"update","data":[{"symbol":"USDT/EUR","bids":[],"asks":[{"price":0.9217,"qty":0.00000000},{"price":0.9228,"qty":53016.84281809},{"price":0.9217,"qty":32.36990689}],"checksum":1708964240,"timestamp":"2024-06-01T17:51:52.683752Z"}]}
{"channel":"book","type":"update","data":[{"symbol":"USDT/EUR","bids":[],"asks":[{"price":0.9218,"qty":406014.62738540}],"checksum":672846073,"timestamp":"2024-06-01T17:51:53.261775Z"}]}
{"channel":"book","type":"update","data":[{"symbol":"USDT/EUR","bids":[],"asks":[{"price":0.9219,"qty":115353.96646880}],"checksum":1278119958,"timestamp":"2024-06-01T17:51:53.261835Z"}]}
{"channel":"book","type":"update","data":[{"symbol":"USDT/EUR","bids":[],"asks":[{"price":0.9219,"qty":307860.63559517}],"checksum":3760465753,"timestamp":"2024-06-01T17:51:53.266254Z"}]}
{"channel":"book","type":"update","data":[{"symbol":"USDT/EUR","bids":[{"price":0.9215,"qty":202169.31469529}],"asks":[],"checksum":3559008299,"timestamp":"2024-06-01T17:51:53.400387Z"}]}
{"channel":"book","type":"update","data":[{"symbol":"USDT/EUR","bids":[{"price":0.9215,"qty":203467.35967065}],"asks":[],"checksum":2762329464,"timestamp":"2024-06-01T17:51:53.442410Z"}]}
{"channel":"book","type":"update","data":[{"symbol":"USDT/EUR","bids":[{"price":0.9214,"qty":174363.05024115}],"asks":[],"checksum":2549660340,"timestamp":"2024-06-01T17:51:53.568197Z"}]}
{"channel":"book","type":"update","data":[{"symbol":"USDT/EUR","bids":[{"price":0.9214,"qty":952691.36045106}],"asks":[],"checksum":1846306253,"timestamp":"2024-06-01T17:51:53.570859Z"}]}
{"channel":"book","type":"update","data":[{"symbol":"USDT/EUR","bids":[{"price":0.9216,"qty":284774.91054702}],"asks":[],"checksum":1322252647,"timestamp":"2024-06-01T17:51:53.937859Z"}]}
{"channel":"book","type":"update","data":[{"symbol":"USDT/EUR","bids":[{"price":0.9216,"qty":279771.91054702}],"asks":[],"checksum":1846306253,"timestamp":"2024-06-01T17:51:54.320334Z"}]}
{"channel":"book","type":"update","data":[{"symbol":"USDT/EUR","bids":[],"asks":[{"price":0.9217,"qty":0.00000000},{"price":0.9228,"qty":53016.84281809},{"price":0.9218,"qty":405992.69729229}],"checksum":2019054171,"timestamp":"2024-06-01T17:51:54.946665Z"}]}
{"channel":"book","type":"update","data":[{"symbol":"USDT/EUR","bids":[],"asks":[{"price":0.9217,"qty":32.36990689}],"checksum":124775156,"timestamp":"2024-06-01T17:51:54.950958Z"}]}
{"channel":"book","type":"update","data":[{"symbol":"USDT/EUR","bids":[{"price":0.9214,"qty":852599.77665188}],"asks":[],"checksum":124074635,"timestamp":"2024-06-01T17:51:55.356110Z"}]}
{"channel":"book","type":"update","data":[{"symbol":"USDT/EUR","bids":[{"price":0.9213,"qty":249525.03708946}],"asks":[],"checksum":3002241318,"timestamp":"2024-06-01T17:51:55.356363Z"}]}
{"channel":"book","type":"update","data":[{"symbol":"USDT/EUR","bids":[{"price":0.9215,"qty":202169.31469529}],"asks":[],"checksum":3262477429,"timestamp":"2024-06-01T17:51:55.568418Z"}]}
{"channel":"book","type":"update","data":[{"symbol":"USDT/EUR","bids":[{"price":0.9215,"qty":203389.43106927}],"asks":[],"checksum":2085162322,"timestamp":"2024-06-01T17:51:55.573086Z"}]}
{"channel":"book","type":"update","data":[{"symbol":"USDT/EUR","bids":[{"price":0.9214,"qty":74271.46644197}],"asks":[],"checksum":3264215363,"timestamp":"2024-06-01T17:51:55.906502Z"}]}
{"channel":"book","type":"update","data":[{"symbol":"USDT/EUR","bids":[{"price":0.9214,"qty":854368.17464492}],"asks":[],"checksum":1465656279,"timestamp":"2024-06-01T17:51:55.908641Z"}]}
{"channel":"book","type":"update","data":[{"symbol":"USDT/EUR","bids":[{"price":0.9216,"qty":279749.97181675},{"price":0.9214,"qty":854390.14500036}],"asks":[],"checksum":1551237719,"timestamp":"2024-06-01T17:51:55.911158Z"}]}
{"channel":"book","type":"update","data":[{"symbol":"USDT/EUR","bids":[{"price":0.9214,"qty":854368.17464492},{"price":0.9216,"qty":279771.93740432}],"asks":[],"checksum":1104726762,"timestamp":"2024-06-01T17:51:55.915747Z"}]}
{"channel":"book","type":"update","data":[{"symbol":"USDT/EUR","bids":[{"price":0.9213,"qty":235304.95883595}],"asks":[],"checksum":2488249813,"timestamp":"2024-06-01T17:51:56.396245Z"}]}
{"channel":"book","type":"update","data":[{"symbol":"USDT/EUR","bids":[{"price":0.9216,"qty":283621.93740432}],"asks":[],"checksum":370177834,"timestamp":"2024-06-01T17:51:56.425908Z"}]}
{"channel":"book","type":"update","data":[{"symbol":"USDT/EUR","bids":[{"price":0.9212,"qty":327671.23090488}],"asks":[],"checksum":3818615435,"timestamp":"2024-06-01T17:51:56.426515Z"}]}
{"channel":"book","type":"update","data":[{"symbol":"USDT/EUR","bids":[],"asks":[{"price":0.9222,"qty":57857.08631777}],"checksum":1833813304,"timestamp":"2024-06-01T17:51:56.521755Z"}]}
{"channel":"book","type":"update","data":[{"symbol":"USDT/EUR","bids":[],"asks":[{"price":0.9221,"qty":117362.80046363}],"checksum":2163939252,"timestamp":"2024-06-01T17:51:56.551345Z"}]}
{"channel":"book","type":"update","data":[{"symbol":"USDT/EUR","bids":[{"price":0.9216,"qty":279771.93740432}],"asks":[],"checksum":44354891,"timestamp":"2024-06-01T17:51:56.637719Z"}]}
{"channel":"book","type":"update","data":[{"symbol":"USDT/EUR","bids":[{"price":0.9209,"qty":135087.72528829}],"asks":[],"checksum":16930759,"timestamp":"2024-06-01T17:51:56.852312Z"}]}
{"channel":"book","type":"update","data":[{"symbol":"USDT/EUR","bids":[{"price":0.9208,"qty":185768.07973485}],"asks":[],"checksum":3496700953,"timestamp":"2024-06-01T17:51:56.852803Z"}]}
{"channel":"book","type":"update","data":[{"symbol":"USDT/EUR","bids":[],"asks":[{"price":0.9219,"qty":115353.96646880}],"checksum":4069504502,"timestamp":"2024-06-01T17:51:56.982487Z"}]}
{"channel":"book","type":"update","data":[{"symbol":"USDT/EUR","bids":[],"asks":[{"price":0.9217,"qty":57564.17497452}],"checksum":541715435,"timestamp":"2024-06-01T17:51:56.985026Z"}]}
{"channel":"book","type":"update","data":[{"symbol":"USDT/EUR","bids":[],"asks":[{"price":0.9218,"qty":543734.81118586}],"checksum":354286864,"timestamp":"2024-06-01T17:51:56.985046Z"}]}
{"channel":"book","type":"update","data":[{"symbol":"USDT/EUR","bids":[],"asks":[{"price":0.9219,"qty":129476.38259694}],"checksum":3913976890,"timestamp":"2024-06-01T17:51:56.985203Z"}]}
{"channel":"book","type":"update","data":[{"symbol":"USDT/EUR","bids":[{"price":0.9214,"qty":850169.17464492},{"price":0.9216,"qty":277701.93740432}],"asks":[],"checksum":2913647043,"timestamp":"2024-06-01T17:51:57.310310Z"}]}
{"channel":"book","type":"update","data":[{"symbol":"USDT/EUR","bids":[{"price":0.9215,"qty":202169.31469529}],"asks":[],"checksum":1589017602,"timestamp":"2024-06-01T17:51:57.712392Z"}]}
{"channel":"book","type":"update","data":[{"symbol":"USDT/EUR","bids":[{"price":0.9216,"qty":277679.97181675},{"price":0.9215,"qty":202191.29555090}],"asks":[],"checksum":3202999167,"timestamp":"2024-06-01T17:51:57.715714Z"}]}
{"channel":"book","type":"update","data":[{"symbol":"USDT/EUR","bids":[{"price":0.9215,"qty":203333.48332349}],"asks":[],"checksum":981009595,"timestamp":"2024-06-01T17:51:57.717494Z"}]}
{"channel":"book","type":"update","data":[{"symbol":"USDT/EUR","bids":[{"price":0.9215,"qty":203311.50246788},{"price":0.9216,"qty":277701.95028728}],"asks":[],"checksum":568027144,"timestamp":"2024-06-01T17:51:57.720570Z"}]}
{"channel":"book","type":"update","data":[{"symbol":"USDT/EUR","bids":[{"price":0.9214,"qty":70072.46644197}],"asks":[],"checksum":916450348,"timestamp":"2024-06-01T17:51:58.460889Z"}]}
{"channel":"book","type":"update","data":[{"symbol":"USDT/EUR","bids":[{"price":0.9214,"qty":804190.82682586}],"asks":[],"checksum":4091301703,"timestamp":"2024-06-01T17:51:58.462834Z"}]}
{"channel":"book","type":"update","data":[{"symbol":"USDT/EUR","bids":[{"price":0.9216,"qty":277679.97181675},{"price":0.9214,"qty":804212.81195615}],"asks":[],"checksum":38293190,"timestamp":"2024-06-01T17:51:58.464150Z"}]}
{"channel":"book","type":"update","data":[{"symbol":"USDT/EUR","bids":[{"price":0.9214,"qty":804190.82682586},{"price":0.9216,"qty":277701.95217596}],"asks":[],"checksum":3067354210,"timestamp":"2024-06-01T17:51:58.467218Z"}]}
{"channel":"book","type":"update","data":[{"symbol":"USDT/EUR","bids":[{"price":0.9210,"qty":12708.31506601},{"price":0.9211,"qty":67071.01776149}],"asks":[],"checksum":2387066849,"timestamp":"2024-06-01T17:51:59.170226Z"}]}
{"channel":"book","type":"update","data":[{"symbol":"USDT/EUR","bids":[{"price":0.9216,"qty":277679.97181675},{"price":0.9216,"qty":277699.52346022}],"asks":[],"checksum":3404716846,"timestamp":"2024-06-01T17:51:59.570065Z"}]}
{"channel":"book","type":"update","data":[{"symbol":"USDT/EUR","bids":[{"price":0.9215,"qty":202169.31469529}],"asks":[],"checksum":1818893277,"timestamp":"2024-06-01T17:51:59.961873Z"}]}
{"channel":"book","type":"update","data":[{"symbol":"USDT/EUR","bids":[{"price":0.9215,"qty":203363.68414835}],"asks":[],"checksum":3483583537,"timestamp":"2024-06-01T17:51:59.966724Z"}]}
{"channel":"book","type":"update","data":[{"symbol":"USDT/EUR","bids":[],"asks":[{"price":0.9217,"qty":32.36990689}],"checksum":2893541046,"timestamp":"2024-06-01T17:52:00.599249Z"}]}
{"channel":"book","type":"update","data":[{"symbol":"USDT/EUR","bids":[],"asks":[{"price":0.9218,"qty":405992.69729229}],"checksum":2251133236,"timestamp":"2024-06-01T17:52:00.599313Z"}]}
{"channel":"book","type":"update","data":[{"symbol":"USDT/EUR","bids":[],"asks":[{"price":0.9219,"qty":115353.96646880}],"checksum":1567231891,"timestamp":"2024-06-01T17:52:00.599332Z"}]}
{"channel":"book","type":"update","data":[{"symbol":"USDT/EUR","bids":[],"asks":[{"price":0.9217,"qty":80187.59541260}],"checksum":1322419266,"timestamp":"2024-06-01T17:52:00.604205Z"}]}
{"channel":"book","type":"update","data":[{"symbol":"USDT/EUR","bids":[],"asks":[{"price":0.9218,"qty":557640.31241633}],"checksum":2319508237,"timestamp":"2024-06-01T17:52:00.604230Z"}]}
{"channel":"book","type":"update","data":[{"symbol":"USDT/EUR","bids":[{"price":0.9214,"qty":70072.46644197}],"asks":[],"checksum":2261856805,"timestamp":"2024-06-01T17:52:00.840927Z"}]}
{"channel":"book","type":"update","data":[{"symbol":"USDT/EUR","bids":[{"price":0.9214,"qty":791867.36014842}],"asks":[],"checksum":1390471266,"timestamp":"2024-06-01T17:52:00.842908Z"}]}
{"channel":"book","type":"update","data":[{"symbol":"USDT/EUR","bids":[{"price":0.9216,"qty":277679.97181675},{"price":0.9214,"qty":791886.93426135}],"asks":[],"checksum":1772048541,"timestamp":"2024-06-01T17:52:00.844203Z"}]}
{"channel":"book","type":"update","data":[{"symbol":"USDT/EUR","bids":[{"price":0.9214,"qty":791867.36014842},{"price":0.9216,"qty":277699.54168183}],"asks":[],"checksum":2136774139,"timestamp":"2024-06-01T17:52:00.847494Z"}]}
{"channel":"book","type":"update","data":[{"symbol":"USDT/EUR","bids":[{"price":0.9215,"qty":202169.31469529}],"asks":[],"checksum":3700804119,"timestamp":"2024-06-01T17:52:02.022712Z"}]}
{"channel":"book","type":"update","data":[{"symbol":"USDT/EUR","bids":[{"price":0.9215,"qty":203592.04543287}],"asks":[],"checksum":467024248,"timestamp":"2024-06-01T17:52:02.028108Z"}]}
{"channel":"book","type":"update","data":[{"symbol":"USDT/EUR","bids":[{"price":0.9214,"qty":786331.47076417},{"price":0.9213,"qty":240841.44909823}],"asks":[],"checksum":666093164,"timestamp":"2024-06-01T17:52:03.074969Z"}]}
{"channel":"book","type":"update","data":[{"symbol":"USDT/EUR","bids":[{"price":0.9214,"qty":64536.57705772}],"asks":[],"checksum":1562762750,"timestamp":"2024-06-01T17:52:03.340388Z"}]}
{"channel":"book","type":"update","data":[{"symbol":"USDT/EUR","bids":[{"price":0.9214,"qty":791637.07250207}],"asks":[],"checksum":2462410906,"timestamp":"2024-06-01T17:52:03.342405Z"}]}
{"channel":"book","type":"update","data":[{"symbol":"USDT/EUR","bids":[{"price":0.9216,"qty":277679.97181675},{"price":0.9214,"qty":791656.62604453}],"asks":[],"checksum":1017531937,"timestamp":"2024-06-01T17:52:03.344060Z"}]}
{"channel":"book","type":"update","data":[{"symbol":"USDT/EUR","bids":[{"price":0.9214,"qty":791637.07250207},{"price":0.9216,"qty":277699.52111582}],"asks":[],"checksum":1091188013,"timestamp":"2024-06-01T17:52:03.347862Z"}]}
{"channel":"book","type":"update","data":[{"symbol":"USDT/EUR","bids":[],"asks":[{"price":0.9217,"qty":32.36990689}],"checksum":1387446012,"timestamp":"2024-06-01T17:52:04.171589Z"}]}
{"channel":"book","type":"update","data":[{"symbol":"USDT/EUR","bids":[],"asks":[{"price":0.9218,"qty":405992.69729229}],"checksum":2518735283,"timestamp":"2024-06-01T17:52:04.171645Z"}]}
{"channel":"book","type":"update","data":[{"symbol":"USDT/EUR","bids":[],"asks":[{"price":0.9217,"qty":93555.98021693}],"checksum":1794070485,"timestamp":"2024-06-01T17:52:04.173849Z"}]}
{"channel":"book","type":"update","data":[{"symbol":"USDT/EUR","bids":[],"asks":[{"price":0.9218,"qty":545881.71733867}],"checksum":3082468210,"timestamp":"2024-06-01T17:52:04.173958Z"}]}
{"channel":"book","type":"update","data":[{"symbol":"USDT/EUR","bids":[{"price":0.9215,"qty":202169.31469529}],"asks":[],"checksum":1895385117,"timestamp":"2024-06-01T17:52:04.281699Z"}]}
{"channel":"book","type":"update","data":[{"symbol":"USDT/EUR","bids":[{"price":0.9215,"qty":203623.21687342}],"asks":[],"checksum":374479113,"timestamp":"2024-06-01T17:52:04.288291Z"}]}
{"channel":"book","type":"update","data":[{"symbol":"USDT/EUR","bids":[{"price":0.9216,"qty":282362.52111582}],"asks":[],"checksum":3693198266,"timestamp":"2024-06-01T17:52:05.610382Z"}]}
{"channel":"book","type":"update","data":[{"symbol":"USDT/EUR","bids":[{"price":0.9216,"qty":282342.97181675},{"price":0.9215,"qty":203642.76926656}],"asks":[],"checksum":3799083108,"timestamp":"2024-06-01T17:52:05.613773Z"}]}
{"channel":"book","type":"update","data":[{"symbol":"USDT/EUR","bids":[{"price":0.9216,"qty":277679.97181675}],"asks":[],"checksum":1644764532,"timestamp":"2024-06-01T17:52:05.629508Z"}]}
{"channel":"book","type":"update","data":[{"symbol":"USDT/EUR","bids":[{"price":0.9214,"qty":64536.57705772}],"asks":[],"checksum":2663610222,"timestamp":"2024-06-01T17:52:05.700154Z"}]}
{"channel":"book","type":"update","data":[{"symbol":"USDT/EUR","bids":[{"price":0.9214,"qty":773951.73337574}],"asks":[],"checksum":527163276,"timestamp":"2024-06-01T17:52:05.702127Z"}]}
{"channel":"book","type":"update","data":[{"symbol":"USDT/EUR","bids":[{"price":0.9215,"qty":203623.21687342},{"price":0.9214,"qty":773971.28789091}],"asks":[],"checksum":1190399241,"timestamp":"2024-06-01T17:52:05.703589Z"}]}
{"channel":"book","type":"update","data":[{"symbol":"USDT/EUR","bids":[{"price":0.9214,"qty":773951.73337574},{"price":0.9215,"qty":203642.76926656}],"asks":[],"checksum":527163276,"timestamp":"2024-06-01T17:52:05.707470Z"}]}
{"channel":"book","type":"update","data":[{"symbol":"USDT/EUR","bids":[{"price":0.9215,"qty":202188.86708843}],"asks":[],"checksum":2655586541,"timestamp":"2024-06-01T17:52:06.438086Z"}]}
{"channel":"book","type":"update","data":[{"symbol":"USDT/EUR","bids":[{"price":0.9215,"qty":203377.81202185}],"asks":[],"checksum":35055145,"timestamp":"2024-06-01T17:52:06.443132Z"}]}
{"channel":"book","type":"update","data":[{"symbol":"USDT/EUR","bids":[{"price":0.9215,"qty":203358.25962871},{"price":0.9216,"qty":277699.51871126}],"asks":[],"checksum":1134056057,"timestamp":"2024-06-01T17:52:06.725853Z"}]}
{"channel":"book","type":"update","data":[{"symbol":"USDT/EUR","bids":[{"price":0.9216,"qty":277679.97181675},{"price":0.9215,"qty":203377.80866794}],"asks":[],"checksum":1353181933,"timestamp":"2024-06-01T17:52:06.875459Z"}]}
{"channel":"book","type":"update","data":[{"symbol":"USDT/EUR","bids":[],"asks":[{"price":0.9217,"qty":93523.61031004},{"price":0.9217,"qty":93489.28021693}],"checksum":1473947275,"timestamp":"2024-06-01T17:52:07.063728Z"}]}
{"channel":"book","type":"update","data":[{"symbol":"USDT/EUR","bids":[],"asks":[{"price":0.9217,"qty":93521.33009484}],"checksum":1788393319,"timestamp":"2024-06-01T17:52:07.068007Z"}]}
{"channel":"book","type":"update","data":[{"symbol":"USDT/EUR","bids":[{"price":0.9215,"qty":203358.25962871},{"price":0.9216,"qty":277699.51875108}],"asks":[],"checksum":1776640305,"timestamp":"2024-06-01T17:52:07.095836Z"}]}
{"channel":"book","type":"update","data":[{"symbol":"USDT/EUR","bids":[{"price":0.9216,"qty":277679.97181675},{"price":0.9215,"qty":203377.83093768}],"asks":[],"checksum":2906258401,"timestamp":"2024-06-01T17:52:07.393720Z"}]}
{"channel":"book","type":"update","data":[{"symbol":"USDT/EUR","bids":[],"asks":[{"price":0.9218,"qty":405992.69729229}],"checksum":1886132038,"timestamp":"2024-06-01T17:52:07.802151Z"}]}
{"channel":"book","type":"update","data":[{"symbol":"USDT/EUR","bids":[],"asks":[{"price":0.9217,"qty":32.04987791}],"checksum":1442338697,"timestamp":"2024-06-01T17:52:07.802297Z"}]}
{"channel":"book","type":"update","data":[{"symbol":"USDT/EUR","bids":[],"asks":[{"price":0.9218,"qty":504582.92809640}],"checksum":1931529613,"timestamp":"2024-06-01T17:52:07.806701Z"}]}
{"channel":"book","type":"update","data":[{"symbol":"USDT/EUR","bids":[],"asks":[{"price":0.9217,"qty":108978.97625251}],"checksum":611680113,"timestamp":"2024-06-01T17:52:07.806798Z"}]}
{"channel":"book","type":"update","data":[{"symbol":"USDT/EUR","bids":[{"price":0.9215,"qty":203358.25962871},{"price":0.9216,"qty":277699.54102102}],"asks":[],"checksum":3882491625,"timestamp":"2024-06-01T17:52:08.040309Z"}]}
{"channel":"book","type":"update","data":[{"symbol":"USDT/EUR","bids":[{"price":0.9216,"qty":277679.97181675},{"price":0.9215,"qty":203377.83095660}],"asks":[],"checksum":730385379,"timestamp":"2024-06-01T17:52:08.043432Z"}]}
{"channel":"book","type":"update","data":[{"symbol":"USDT/EUR","bids":[{"price":0.9215,"qty":203358.25962871},{"price":0.9216,"qty":277699.54102102}],"asks":[],"checksum":3882491625,"timestamp":"2024-06-01T17:52:08.103855Z"}]}
{"channel":"book","type":"update","data":[{"symbol":"USDT/EUR","bids":[{"price":0.9214,"qty":64536.57705772}],"asks":[],"checksum":4255939507,"timestamp":"2024-06-01T17:52:08.236336Z"}]}
{"channel":"book","type":"update","data":[{"symbol":"USDT/EUR","bids":[{"price":0.9216,"qty":277679.97181675},{"price":0.9214,"qty":64556.15050970}],"asks":[],"checksum":732743375,"timestamp":"2024-06-01T17:52:08.240768Z"}]}
{"channel":"book","type":"update","data":[{"symbol":"USDT/EUR","bids":[{"price":0.9214,"qty":827041.74881817}],"asks":[],"checksum":495068292,"timestamp":"2024-06-01T17:52:08.241517Z"}]}
{"channel":"book","type":"update","data":[{"symbol":"USDT/EUR","bids":[{"price":0.9214,"qty":827022.17536619},{"price":0.9216,"qty":277699.54102102}],"asks":[],"checksum":3320549033,"timestamp":"2024-06-01T17:52:08.245221Z"}]}
{"channel":"book","type":"update","data":[{"symbol":"USDT/EUR","bids":[{"price":0.9216,"qty":277679.97181675},{"price":0.9215,"qty":203377.83929833}],"asks":[],"checksum":2960392947,"timestamp":"2024-06-01T17:52:08.526912Z"}]}
{"channel":"book","type":"update","data":[{"symbol":"USDT/EUR","bids":[{"price":0.9215,"qty":202188.89436491}],"asks":[],"checksum":1836336473,"timestamp":"2024-06-01T17:52:08.690992Z"}]}
{"channel":"book","type":"update","data":[{"symbol":"USDT/EUR","bids":[{"price":0.9215,"qty":203642.79654599}],"asks":[],"checksum":3583549749,"timestamp":"2024-06-01T17:52:08.733378Z"}]}
{"channel":"book","type":"update","data":[{"symbol":"USDT/EUR","bids":[],"asks":[{"price":0.9220,"qty":178081.52774985}],"checksum":33716733,"timestamp":"2024-06-01T17:52:10.302847Z"}]}
{"channel":"book","type":"update","data":[{"symbol":"USDT/EUR","bids":[],"asks":[{"price":0.9218,"qty":507050.92809640}],"checksum":1773411348,"timestamp":"2024-06-01T17:52:10.526549Z"}]}
{"channel":"book","type":"update","data":[{"symbol":"USDT/EUR","bids":[{"price":0.9214,"qty":64536.57705772}],"asks":[],"checksum":516392600,"timestamp":"2024-06-01T17:52:10.723928Z"}]}
{"channel":"book","type":"update","data":[{"symbol":"USDT/EUR","bids":[{"price":0.9214,"qty":793419.39365962}],"asks":[],"checksum":508618965,"timestamp":"2024-06-01T17:52:10.725767Z"}]}
{"channel":"book","type":"update","data":[{"symbol":"USDT/EUR","bids":[{"price":0.9215,"qty":203623.21687637},{"price":0.9214,"qty":793438.97895719}],"asks":[],"checksum":2463483839,"timestamp":"2024-06-01T17:52:10.727678Z"}]}
{"channel":"book","type":"update","data":[{"symbol":"USDT/EUR","bids":[{"price":0.9214,"qty":793419.39365962},{"price":0.9215,"qty":203642.80004857}],"asks":[],"checksum":2654664560,"timestamp":"2024-06-01T17:52:10.731081Z"}]}
{"channel":"book","type":"update","data":[{"symbol":"USDT/EUR","bids":[{"price":0.9215,"qty":202188.89786749}],"asks":[],"checksum":4133795116,"timestamp":"2024-06-01T17:52:10.838486Z"}]}
{"channel":"book","type":"update","data":[{"symbol":"USDT/EUR","bids":[{"price":0.9215,"qty":203876.58585321}],"asks":[],"checksum":2019416856,"timestamp":"2024-06-01T17:52:10.844572Z"}]}
{"channel":"book","type":"update","data":[{"symbol":"USDT/EUR","bids":[],"asks":[{"price":0.9218,"qty":408460.69729229}],"checksum":2487159745,"timestamp":"2024-06-01T17:52:11.416898Z"}]}
{"channel":"book","type":"update","data":[{"symbol":"USDT/EUR","bids":[],"asks":[{"price":0.9217,"qty":32.04987791}],"checksum":3278551357,"timestamp":"2024-06-01T17:52:11.416982Z"}]}
{"channel":"book","type":"update","data":[{"symbol":"USDT/EUR","bids":[],"asks":[{"price":0.9217,"qty":65731.00316850}],"checksum":3608640625,"timestamp":"2024-06-01T17:52:11.419319Z"}]}
{"channel":"book","type":"update","data":[{"symbol":"USDT/EUR","bids":[],"asks":[{"price":0.9218,"qty":556056.25890142}],"checksum":2019755340,"timestamp":"2024-06-01T17:52:11.419384Z"}]}
{"channel":"book","type":"update","data":[{"symbol":"USDT/EUR","bids":[],"asks":[{"price":0.9219,"qty":123106.03376390}],"checksum":91099611,"timestamp":"2024-06-01T17:52:11.419733Z"}]}
{"channel":"book","type":"update","data":[{"symbol":"USDT/EUR","bids":[{"price":0.9212,"qty":313449.60900415}],"asks":[],"checksum":3670640788,"timestamp":"2024-06-01T17:52:11.426579Z"}]}
{"channel":"book","type":"update","data":[{"symbol":"USDT/EUR","bids":[{"price":0.9212,"qty":327671.23090488}],"asks":[],"checksum":91099611,"timestamp":"2024-06-01T17:52:11.466602Z"}]}
{"channel":"book","type":"update","data":[{"symbol":"USDT/EUR","bids":[],"asks":[{"price":0.9221,"qty":106017.25942246}],"checksum":2085438198,"timestamp":"2024-06-01T17:52:11.551498Z"}]}
{"channel":"book","type":"update","data":[{"symbol":"USDT/EUR","bids":[],"asks":[{"price":0.9221,"qty":117362.80046363}],"checksum":91099611,"timestamp":"2024-06-01T17:52:11.601994Z"}]}
{"channel":"book","type":"update","data":[{"symbol":"USDT/EUR","bids":[{"price":0.9215,"qty":202188.89786749}],"asks":[],"checksum":2337767407,"timestamp":"2024-06-01T17:52:12.910418Z"}]}
{"channel":"book","type":"update","data":[{"symbol":"USDT/EUR","bids":[{"price":0.9215,"qty":203175.22843930}],"asks":[],"checksum":3642738210,"timestamp":"2024-06-01T17:52:12.916082Z"}]}
{"channel":"book","type":"update","data":[{"symbol":"USDT/EUR","bids":[{"price":0.9214,"qty":64536.57705772}],"asks":[],"checksum":2252457443,"timestamp":"2024-06-01T17:52:13.176854Z"}]}
{"channel":"book","type":"update","data":[{"symbol":"USDT/EUR","bids":[{"price":0.9215,"qty":203155.64526710},{"price":0.9214,"qty":64556.16390760}],"asks":[],"checksum":2328165728,"timestamp":"2024-06-01T17:52:13.180036Z"}]}
{"channel":"book","type":"update","data":[{"symbol":"USDT/EUR","bids":[{"price":0.9214,"qty":784596.14320444}],"asks":[],"checksum":612928225,"timestamp":"2024-06-01T17:52:13.181902Z"}]}
{"channel":"book","type":"update","data":[{"symbol":"USDT/EUR","bids":[{"price":0.9214,"qty":784576.55635456},{"price":0.9215,"qty":203175.22999144}],"asks":[],"checksum":2570669682,"timestamp":"2024-06-01T17:52:13.185140Z"}]}
{"channel":"book","type":"update","data":[{"symbol":"USDT/EUR","bids":[{"price":0.9216,"qty":277578.36421675}],"asks":[],"checksum":1164882680,"timestamp":"2024-06-01T17:52:13.522767Z"}]}
{"channel":"book","type":"update","data":[{"symbol":"USDT/EUR","bids":[{"price":0.9213,"qty":235304.95883595},{"price":0.9214,"qty":790112.44573879}],"asks":[],"checksum":591869379,"timestamp":"2024-06-01T17:52:13.890182Z"}]}
{"channel":"book","type":"update","data":[{"symbol":"USDT/EUR","bids":[{"price":0.9215,"qty":203155.64526710},{"price":0.9215,"qty":203174.10861718}],"asks":[],"checksum":2549266013,"timestamp":"2024-06-01T17:52:14.635160Z"}]}
{"channel":"book","type":"update","data":[{"symbol":"USDT/EUR","bids":[],"asks":[{"price":0.9217,"qty":32.04987791}],"checksum":2207216401,"timestamp":"2024-06-01T17:52:15.095605Z"}]}
{"channel":"book","type":"update","data":[{"symbol":"USDT/EUR","bids":[],"asks":[{"price":0.9218,"qty":408460.69729229}],"checksum":754649644,"timestamp":"2024-06-01T17:52:15.095651Z"}]}
{"channel":"book","type":"update","data":[{"symbol":"USDT/EUR","bids":[],"asks":[{"price":0.9219,"qty":115353.96646880}],"checksum":1375084219,"timestamp":"2024-06-01T17:52:15.095782Z"}]}
{"channel":"book","type":"update","data":[{"symbol":"USDT/EUR","bids":[],"asks":[{"price":0.9218,"qty":508432.73380845}],"checksum":1023753407,"timestamp":"2024-06-01T17:52:15.100095Z"}]}
{"channel":"book","type":"update","data":[{"symbol":"USDT/EUR","bids":[],"asks":[{"price":0.9217,"qty":128517.06632060}],"checksum":2330178337,"timestamp":"2024-06-01T17:52:15.100137Z"}]}
{"channel":"book","type":"update","data":[{"symbol":"USDT/EUR","bids":[{"price":0.9215,"qty":202187.77804537}],"asks":[],"checksum":952102962,"timestamp":"2024-06-01T17:52:15.102834Z"}]}
{"channel":"book","type":"update","data":[{"symbol":"USDT/EUR","bids":[{"price":0.9215,"qty":203252.03721873}],"asks":[],"checksum":1731346009,"timestamp":"2024-06-01T17:52:15.146352Z"}]}
{"channel":"book","type":"update","data":[{"symbol":"USDT/EUR","bids":[{"price":0.9214,"qty":70072.46644195}],"asks":[],"checksum":3233304948,"timestamp":"2024-06-01T17:52:15.658041Z"}]}
{"channel":"book","type":"update","data":[{"symbol":"USDT/EUR","bids":[{"price":0.9214,"qty":797186.71557162}],"asks":[],"checksum":2460479786,"timestamp":"2024-06-01T17:52:15.660377Z"}]}
{"channel":"book","type":"update","data":[{"symbol":"USDT/EUR","bids":[{"price":0.9215,"qty":203233.57386865},{"price":0.9214,"qty":797205.19702747}],"asks":[],"checksum":1527952310,"timestamp":"2024-06-01T17:52:15.661349Z"}]}
{"channel":"book","type":"update","data":[{"symbol":"USDT/EUR","bids":[{"price":0.9214,"qty":797186.71557162},{"price":0.9215,"qty":203252.05331891}],"asks":[],"checksum":3513640710,"timestamp":"2024-06-01T17:52:15.681063Z"}]}
{"channel":"book","type":"update","data":[{"symbol":"USDT/EUR","bids":[{"price":0.9216,"qty":277379.36421675}],"asks":[],"checksum":3200578220,"timestamp":"2024-06-01T17:52:17.091208Z"}]}
{"channel":"book","type":"update","data":[{"symbol":"USDT/EUR","bids":[{"price":0.9215,"qty":202187.79414555}],"asks":[],"checksum":2863936204,"timestamp":"2024-06-01T17:52:17.278966Z"}]}
{"channel":"book","type":"update","data":[{"symbol":"USDT/EUR","bids":[{"price":0.9215,"qty":203002.68179396}],"asks":[],"checksum":2703704795,"timestamp":"2024-06-01T17:52:17.319335Z"}]}
{"channel":"book","type":"update","data":[{"symbol":"USDT/EUR","bids":[{"price":0.9214,"qty":70072.46644195}],"asks":[],"checksum":1125532953,"timestamp":"2024-06-01T17:52:18.166271Z"}]}
{"channel":"book","type":"update","data":[{"symbol":"USDT/EUR","bids":[{"price":0.9214,"qty":747666.82674184}],"asks":[],"checksum":3518491183,"timestamp":"2024-06-01T17:52:18.168514Z"}]}
{"channel":"book","type":"update","data":[{"symbol":"USDT/EUR","bids":[{"price":0.9215,"qty":202984.20234370},{"price":0.9214,"qty":747685.30700509}],"asks":[],"checksum":2074515235,"timestamp":"2024-06-01T17:52:18.169866Z"}]}
{"channel":"book","type":"update","data":[{"symbol":"USDT/EUR","bids":[{"price":0.9214,"qty":747666.82674184},{"price":0.9215,"qty":203002.68060149}],"asks":[],"checksum":1305769802,"timestamp":"2024-06-01T17:52:18.172887Z"}]}
{"channel":"book","type":"update","data":[{"symbol":"USDT/EUR","bids":[],"asks":[{"price":0.9218,"qty":408460.69729229}],"checksum":556225870,"timestamp":"2024-06-01T17:52:18.665612Z"}]}
{"channel":"book","type":"update","data":[{"symbol":"USDT/EUR","bids":[],"asks":[{"price":0.9217,"qty":32.04987791}],"checksum":2529286864,"timestamp":"2024-06-01T17:52:18.665673Z"}]}
{"channel":"book","type":"update","data":[{"symbol":"USDT/EUR","bids":[],"asks":[{"price":0.9218,"qty":483753.04109087}],"checksum":642164201,"timestamp":"2024-06-01T17:52:18.670689Z"}]}
{"channel":"book","type":"update","data":[{"symbol":"USDT/EUR","bids":[],"asks":[{"price":0.9217,"qty":137771.95108970}],"checksum":3615559467,"timestamp":"2024-06-01T17:52:18.670736Z"}]}
{"channel":"book","type":"update","data":[{"symbol":"USDT/EUR","bids":[{"price":0.9215,"qty":202187.79295308}],"asks":[],"checksum":3021671014,"timestamp":"2024-06-01T17:52:19.494208Z"}]}
{"channel":"book","type":"update","data":[{"symbol":"USDT/EUR","bids":[{"price":0.9215,"qty":202645.79195910}],"asks":[],"checksum":3263159647,"timestamp":"2024-06-01T17:52:19.536465Z"}]}
{"channel":"book","type":"update","data":[{"symbol":"USDT/EUR","bids":[{"price":0.9216,"qty":277230.36421675}],"asks":[],"checksum":3843445601,"timestamp":"2024-06-01T17:52:19.687872Z"}]}
{"channel":"book","type":"update","data":[{"symbol":"USDT/EUR","bids":[{"price":0.9210,"qty":7633.71506601},{"price":0.9209,"qty":140439.04528829}],"asks":[],"checksum":2553355648,"timestamp":"2024-06-01T17:52:20.146897Z"}]}
{"channel":"book","type":"update","data":[{"symbol":"USDT/EUR","bids":[],"asks":[{"price":0.9220,"qty":172942.41774985},{"price":0.9219,"qty":120786.08646880}],"checksum":3619985448,"timestamp":"2024-06-01T17:52:20.147145Z"}]}
{"channel":"book","type":"update","data":[{"symbol":"USDT/EUR","bids":[{"price":0.9209,"qty":129506.70528829},{"price":0.9208,"qty":196035.68973485}],"asks":[],"checksum":3725751314,"timestamp":"2024-06-01T17:52:20.147257Z"}]}
{"channel":"book","type":"update","data":[{"symbol":"USDT/EUR","bids":[],"asks":[{"price":0.9221,"qty":106633.53046363},{"price":0.9220,"qty":182869.53774985}],"checksum":1326404931,"timestamp":"2024-06-01T17:52:20.147623Z"}]}
{"channel":"book","type":"update","data":[{"symbol":"USDT/EUR","bids":[{"price":0.9215,"qty":202627.31370131},{"price":0.9216,"qty":277248.84283024}],"asks":[],"checksum":3734804157,"timestamp":"2024-06-01T17:52:20.588208Z"}]}
{"channel":"book","type":"update","data":[{"symbol":"USDT/EUR","bids":[{"price":0.9216,"qty":277230.36421675},{"price":0.9215,"qty":202645.79432008}],"asks":[],"checksum":935054084,"timestamp":"2024-06-01T17:52:20.595300Z"}]}
{"channel":"book","type":"update","data":[{"symbol":"USDT/EUR","bids":[{"price":0.9214,"qty":70072.46644195}],"asks":[],"checksum":401393548,"timestamp":"2024-06-01T17:52:20.680095Z"}]}
{"channel":"book","type":"update","data":[{"symbol":"USDT/EUR","bids":[{"price":0.9214,"qty":733518.28707619}],"asks":[],"checksum":1152229214,"timestamp":"2024-06-01T17:52:20.681924Z"}]}
{"channel":"book","type":"update","data":[{"symbol":"USDT/EUR","bids":[{"price":0.9215,"qty":202627.31370131},{"price":0.9214,"qty":733536.76970067}],"asks":[],"checksum":437513121,"timestamp":"2024-06-01T17:52:20.683774Z"}]}
{"channel":"book","type":"update","data":[{"symbol":"USDT/EUR","bids":[{"price":0.9214,"qty":733518.28707619},{"price":0.9215,"qty":202645.79432008}],"asks":[],"checksum":1152229214,"timestamp":"2024-06-01T17:52:20.687805Z"}]}
{"channel":"book","type":"update","data":[{"symbol":"USDT/EUR","bids":[{"price":0.9215,"qty":202187.79531406}],"asks":[],"checksum":416885712,"timestamp":"2024-06-01T17:52:21.744822Z"}]}
{"channel":"book","type":"update","data":[{"symbol":"USDT/EUR","bids":[{"price":0.9215,"qty":203180.94463851}],"asks":[],"checksum":2133853983,"timestamp":"2024-06-01T17:52:21.751401Z"}]}
{"channel":"book","type":"update","data":[{"symbol":"USDT/EUR","bids":[],"asks":[{"price":0.9218,"qty":408460.69729229}],"checksum":685186149,"timestamp":"2024-06-01T17:52:22.295924Z"}]}
{"channel":"book","type":"update","data":[{"symbol":"USDT/EUR","bids":[],"asks":[{"price":0.9217,"qty":32.04987791}],"checksum":1000316084,"timestamp":"2024-06-01T17:52:22.296012Z"}]}
{"channel":"book","type":"update","data":[{"symbol":"USDT/EUR","bids":[],"asks":[{"price":0.9217,"qty":145998.51532889}],"checksum":1112459587,"timestamp":"2024-06-01T17:52:22.300759Z"}]}
{"channel":"book","type":"update","data":[{"symbol":"USDT/EUR","bids":[],"asks":[{"price":0.9218,"qty":501818.94571283}],"checksum":2559456749,"timestamp":"2024-06-01T17:52:22.300813Z"}]}
{"channel":"book","type":"update","data":[{"symbol":"USDT/EUR","bids":[{"price":0.9214,"qty":70072.46644195}],"asks":[],"checksum":3796614050,"timestamp":"2024-06-01T17:52:23.079044Z"}]}
{"channel":"book","type":"update","data":[{"symbol":"USDT/EUR","bids":[{"price":0.9214,"qty":761126.18073625}],"asks":[],"checksum":785466769,"timestamp":"2024-06-01T17:52:23.081615Z"}]}
{"channel":"book","type":"update","data":[{"symbol":"USDT/EUR","bids":[{"price":0.9215,"qty":203162.46401974},{"price":0.9214,"qty":761144.66708531}],"asks":[],"checksum":1183143914,"timestamp":"2024-06-01T17:52:23.082285Z"}]}
{"channel":"book","type":"update","data":[{"symbol":"USDT/EUR","bids":[{"price":0.9214,"qty":761126.18073625},{"price":0.9215,"qty":203180.94836268}],"asks":[],"checksum":2459551698,"timestamp":"2024-06-01T17:52:23.085301Z"}]}
{"channel":"book","type":"update","data":[{"symbol":"USDT/EUR","bids":[{"price":0.9215,"qty":202187.79903823}],"asks":[],"checksum":3671167322,"timestamp":"2024-06-01T17:52:23.850062Z"}]}
{"channel":"book","type":"update","data":[{"symbol":"USDT/EUR","bids":[{"price":0.9215,"qty":203111.78672881}],"asks":[],"checksum":892239405,"timestamp":"2024-06-01T17:52:23.857378Z"}]}
{"channel":"book","type":"update","data":[{"symbol":"USDT/EUR","bids":[{"price":0.9213,"qty":239507.95883595}],"asks":[],"checksum":309728561,"timestamp":"2024-06-01T17:52:24.527044Z"}]}
{"channel":"book","type":"update","data":[{"symbol":"USDT/EUR","bids":[{"price":0.9214,"qty":755590.29135202},{"price":0.9213,"qty":245044.44909820}],"asks":[],"checksum":852902266,"timestamp":"2024-06-01T17:52:24.741011Z"}]}
{"channel":"book","type":"update","data":[{"symbol":"USDT/EUR","bids":[{"price":0.9214,"qty":64536.57705772}],"asks":[],"checksum":2421434793,"timestamp":"2024-06-01T17:52:25.588734Z"}]}
{"channel":"book","type":"update","data":[{"symbol":"USDT/EUR","bids":[{"price":0.9215,"qty":203093.30238587},{"price":0.9214,"qty":64555.09571660}],"asks":[],"checksum":1235526971,"timestamp":"2024-06-01T17:52:25.591965Z"}]}
{"channel":"book","type":"update","data":[{"symbol":"USDT/EUR","bids":[{"price":0.9214,"qty":784595.07501344}],"asks":[],"checksum":18445381,"timestamp":"2024-06-01T17:52:25.593912Z"}]}
{"channel":"book","type":"update","data":[{"symbol":"USDT/EUR","bids":[{"price":0.9214,"qty":784576.55635456},{"price":0.9215,"qty":203111.81903512}],"asks":[],"checksum":1408660187,"timestamp":"2024-06-01T17:52:25.597207Z"}]}
{"channel":"book","type":"update","data":[{"symbol":"USDT/EUR","bids":[],"asks":[{"price":0.9217,"qty":32.04987791}],"checksum":707209004,"timestamp":"2024-06-01T17:52:25.965669Z"}]}
{"channel":"book","type":"update","data":[{"symbol":"USDT/EUR","bids":[],"asks":[{"price":0.9218,"qty":408460.69729229}],"checksum":4041726850,"timestamp":"2024-06-01T17:52:25.965733Z"}]}
{"channel":"book","type":"update","data":[{"symbol":"USDT/EUR","bids":[],"asks":[{"price":0.9217,"qty":157310.04115779}],"checksum":243854509,"timestamp":"2024-06-01T17:52:25.972291Z"}]}
{"channel":"book","type":"update","data":[{"symbol":"USDT/EUR","bids":[],"asks":[{"price":0.9218,"qty":507501.82254750}],"checksum":3338615632,"timestamp":"2024-06-01T17:52:25.972326Z"}]}
{"channel":"book","type":"update","data":[{"symbol":"USDT/EUR","bids":[{"price":0.9215,"qty":202187.83134454}],"asks":[],"checksum":2136411933,"timestamp":"2024-06-01T17:52:26.007420Z"}]}
{"channel":"book","type":"update","data":[{"symbol":"USDT/EUR","bids":[{"price":0.9215,"qty":203174.60262156}],"asks":[],"checksum":3436155669,"timestamp":"2024-06-01T17:52:26.012638Z"}]}
{"channel":"book","type":"update","data":[{"symbol":"USDT/EUR","bids":[{"price":0.9212,"qty":313449.60900415}],"asks":[],"checksum":196681657,"timestamp":"2024-06-01T17:52:26.467984Z"}]}
{"channel":"book","type":"update","data":[{"symbol":"USDT/EUR","bids":[{"price":0.9212,"qty":327671.23090488}],"asks":[],"checksum":3436155669,"timestamp":"2024-06-01T17:52:26.502973Z"}]}
{"channel":"book","type":"update","data":[{"symbol":"USDT/EUR","bids":[],"asks":[{"price":0.9221,"qty":95287.98942246}],"checksum":397467588,"timestamp":"2024-06-01T17:52:26.602120Z"}]}
{"channel":"book","type":"update","data":[{"symbol":"USDT/EUR","bids":[],"asks":[{"price":0.9221,"qty":106633.53046363}],"checksum":3436155669,"timestamp":"2024-06-01T17:52:26.642049Z"}]}
{"channel":"book","type":"update","data":[{"symbol":"USDT/EUR","bids":[{"price":0.9214,"qty":64536.57705772}],"asks":[],"checksum":3351467033,"timestamp":"2024-06-01T17:52:28.128865Z"}]}
{"channel":"book","type":"update","data":[{"symbol":"USDT/EUR","bids":[{"price":0.9214,"qty":766890.88177250}],"asks":[],"checksum":3555590693,"timestamp":"2024-06-01T17:52:28.131483Z"}]}
{"channel":"book","type":"update","data":[{"symbol":"USDT/EUR","bids":[{"price":0.9215,"qty":203156.08597231},{"price":0.9214,"qty":766909.39941457}],"asks":[],"checksum":46378406,"timestamp":"2024-06-01T17:52:28.132136Z"}]}
{"channel":"book","type":"update","data":[{"symbol":"USDT/EUR","bids":[{"price":0.9214,"qty":766890.88177250},{"price":0.9215,"qty":203174.60160486}],"asks":[],"checksum":2983573614,"timestamp":"2024-06-01T17:52:28.135514Z"}]}
{"channel":"book","type":"update","data":[{"symbol":"USDT/EUR","bids":[{"price":0.9215,"qty":202187.83032784}],"asks":[],"checksum":516087568,"timestamp":"2024-06-01T17:52:28.138896Z"}]}
{"channel":"book","type":"update","data":[{"symbol":"USDT/EUR","bids":[{"price":0.9215,"qty":203345.60382305}],"asks":[],"checksum":3376809982,"timestamp":"2024-06-01T17:52:28.181542Z"}]}
{"channel":"book","type":"update","data":[{"symbol":"USDT/EUR","bids":[],"asks":[{"price":0.9221,"qty":105068.68364094}],"checksum":1851521276,"timestamp":"2024-06-01T17:52:29.045981Z"}]}
{"channel":"book","type":"update","data":[{"symbol":"USDT/EUR","bids":[],"asks":[{"price":0.9221,"qty":106633.51112865}],"checksum":3388449019,"timestamp":"2024-06-01T17:52:29.301037Z"}]}
{"channel":"book","type":"update","data":[{"symbol":"USDT/EUR","bids":[],"asks":[{"price":0.9218,"qty":408460.69729229}],"checksum":25196294,"timestamp":"2024-06-01T17:52:29.574260Z"}]}
{"channel":"book","type":"update","data":[{"symbol":"USDT/EUR","bids":[],"asks":[{"price":0.9217,"qty":32.04987791}],"checksum":4293869609,"timestamp":"2024-06-01T17:52:29.574292Z"}]}
{"channel":"book","type":"update","data":[{"symbol":"USDT/EUR","bids":[],"asks":[{"price":0.9217,"qty":166564.92592688}],"checksum":1573737813,"timestamp":"2024-06-01T17:52:29.579265Z"}]}
{"channel":"book","type":"update","data":[{"symbol":"USDT/EUR","bids":[],"asks":[{"price":0.9218,"qty":485536.53450991}],"checksum":3103342536,"timestamp":"2024-06-01T17:52:29.579316Z"}]}
{"channel":"book","type":"update","data":[{"symbol":"USDT/EUR","bids":[{"price":0.9216,"qty":277146.44421675}],"asks":[],"checksum":3489610996,"timestamp":"2024-06-01T17:52:29.731792Z"}]}
{"channel":"book","type":"update","data":[{"symbol":"USDT/EUR","bids":[],"asks":[{"price":0.9217,"qty":166532.87604897},{"price":0.9217,"qty":165933.22592688}],"checksum":1307116942,"timestamp":"2024-06-01T17:52:30.129907Z"}]}
{"channel":"book","type":"update","data":[{"symbol":"USDT/EUR","bids":[],"asks":[{"price":0.9217,"qty":165965.24844194}],"checksum":3348973776,"timestamp":"2024-06-01T17:52:30.133983Z"}]}
{"channel":"book","type":"update","data":[{"symbol":"USDT/EUR","bids":[{"price":0.9214,"qty":64536.57705772}],"asks":[],"checksum":3050696197,"timestamp":"2024-06-01T17:52:30.626107Z"}]}
{"channel":"book","type":"update","data":[{"symbol":"USDT/EUR","bids":[{"price":0.9214,"qty":761815.45671672}],"asks":[],"checksum":2685486120,"timestamp":"2024-06-01T17:52:30.631166Z"}]}
{"channel":"book","type":"update","data":[{"symbol":"USDT/EUR","bids":[{"price":0.9215,"qty":203327.08819050},{"price":0.9214,"qty":761834.77766531}],"asks":[],"checksum":1503752679,"timestamp":"2024-06-01T17:52:30.665009Z"}]}
{"channel":"book","type":"update","data":[{"symbol":"USDT/EUR","bids":[{"price":0.9214,"qty":761815.45671672},{"price":0.9215,"qty":203346.40704241}],"asks":[],"checksum":2643700150,"timestamp":"2024-06-01T17:52:30.668190Z"}]}
{"channel":"book","type":"update","data":[{"symbol":"USDT/EUR","bids":[],"asks":[{"price":0.9217,"qty":165732.37867964}],"checksum":4093378656,"timestamp":"2024-06-01T17:52:30.994550Z"}]}
{"channel":"book","type":"update","data":[{"symbol":"USDT/EUR","bids":[],"asks":[{"price":0.9217,"qty":162273.45930532}],"checksum":2658599238,"timestamp":"2024-06-01T17:52:31.044135Z"}]}
{"channel":"book","type":"update","data":[{"symbol":"USDT/EUR","bids":[{"price":0.9216,"qty":282492.44421675}],"asks":[],"checksum":2802978605,"timestamp":"2024-06-01T17:52:31.045184Z"}]}
{"channel":"book","type":"update","data":[{"symbol":"USDT/EUR","bids":[{"price":0.9216,"qty":277146.44421675}],"asks":[],"checksum":2658599238,"timestamp":"2024-06-01T17:52:31.061977Z"}]}
{"channel":"book","type":"update","data":[{"symbol":"USDT/EUR","bids":[],"asks":[{"price":0.9218,"qty":481243.53450991}],"checksum":3103592579,"timestamp":"2024-06-01T17:52:31.071440Z"}]}
{"channel":"book","type":"update","data":[{"symbol":"USDT/EUR","bids":[],"asks":[{"price":0.9219,"qty":115442.08646880}],"checksum":4000431372,"timestamp":"2024-06-01T17:52:31.097064Z"}]}
{"channel":"book","type":"update","data":[{"symbol":"USDT/EUR","bids":[{"price":0.9215,"qty":198454.40704241}],"asks":[],"checksum":637273003,"timestamp":"2024-06-01T17:52:31.139349Z"}]}
{"channel":"book","type":"update","data":[{"symbol":"USDT/EUR","bids":[],"asks":[{"price":0.9217,"qty":166793.45930532}],"checksum":1549851993,"timestamp":"2024-06-01T17:52:31.192968Z"}]}
{"channel":"book","type":"update","data":[{"symbol":"USDT/EUR","bids":[],"asks":[{"price":0.9221,"qty":105068.68364094}],"checksum":4224484702,"timestamp":"2024-06-01T17:52:31.276028Z"}]}
{"channel":"book","type":"update","data":[{"symbol":"USDT/EUR","bids":[{"price":0.9215,"qty":198435.08819050},{"price":0.9216,"qty":277165.79481467}],"asks":[],"checksum":1480888955,"timestamp":"2024-06-01T17:52:31.319043Z"}]}
{"channel":"book","type":"update","data":[{"symbol":"USDT/EUR","bids":[],"asks":[{"price":0.9217,"qty":162273.45930532}],"checksum":567823497,"timestamp":"2024-06-01T17:52:31.323185Z"}]}
{"channel":"book","type":"update","data":[{"symbol":"USDT/EUR","bids":[{"price":0.9216,"qty":277146.44421675},{"price":0.9215,"qty":198454.44088832}],"asks":[],"checksum":3885386019,"timestamp":"2024-06-01T17:52:31.424481Z"}]}
{"channel":"book","type":"update","data":[{"symbol":"USDT/EUR","bids":[{"price":0.9215,"qty":198435.08819050},{"price":0.9216,"qty":277165.79481467}],"asks":[],"checksum":567823497,"timestamp":"2024-06-01T17:52:31.446553Z"}]}
{"channel":"book","type":"update","data":[{"symbol":"USDT/EUR","bids":[{"price":0.9216,"qty":277146.44421675},{"price":0.9215,"qty":198454.44090058}],"asks":[],"checksum":69052215,"timestamp":"2024-06-01T17:52:31.540388Z"}]}
{"channel":"book","type":"update","data":[{"symbol":"USDT/EUR","bids":[],"asks":[{"price":0.9223,"qty":140627.36388952}],"checksum":1848012911,"timestamp":"2024-06-01T17:52:31.556553Z"}]}
{"channel":"book","type":"update","data":[{"symbol":"USDT/EUR","bids":[{"price":0.9215,"qty":204085.44090058}],"asks":[],"checksum":3383068144,"timestamp":"2024-06-01T17:52:32.451673Z"}]}
{"channel":"book","type":"update","data":[{"symbol":"USDT/EUR","bids":[{"price":0.9215,"qty":204066.08819050},{"price":0.9216,"qty":277165.80075672}],"asks":[],"checksum":3071060691,"timestamp":"2024-06-01T17:52:32.455493Z"}]}
{"channel":"book","type":"update","data":[{"symbol":"USDT/EUR","bids":[{"price":0.9215,"qty":202908.31469529}],"asks":[],"checksum":1943452230,"timestamp":"2024-06-01T17:52:32.515794Z"}]}
{"channel":"book","type":"update","data":[{"symbol":"USDT/EUR","bids":[{"price":0.9216,"qty":277146.44421675},{"price":0.9215,"qty":202927.67333580}],"asks":[],"checksum":2894222496,"timestamp":"2024-06-01T17:52:32.519074Z"}]}
{"channel":"book","type":"update","data":[{"symbol":"USDT/EUR","bids":[{"price":0.9215,"qty":203882.83246699}],"asks":[],"checksum":3200007541,"timestamp":"2024-06-01T17:52:32.521770Z"}]}
{"channel":"book","type":"update","data":[{"symbol":"USDT/EUR","bids":[{"price":0.9215,"qty":203863.47382648},{"price":0.9216,"qty":277165.80066867}],"asks":[],"checksum":153333371,"timestamp":"2024-06-01T17:52:32.524902Z"}]}
{"channel":"book","type":"update","data":[{"symbol":"USDT/EUR","bids":[],"asks":[{"price":0.9218,"qty":485139.53450991}],"checksum":3498645835,"timestamp":"2024-06-01T17:52:32.927138Z"}]}
{"channel":"book","type":"update","data":[{"symbol":"USDT/EUR","bids":[{"price":0.9214,"qty":64536.57705772}],"asks":[],"checksum":1199309312,"timestamp":"2024-06-01T17:52:33.074854Z"}]}
{"channel":"book","type":"update","data":[{"symbol":"USDT/EUR","bids":[{"price":0.9214,"qty":747278.32810941}],"asks":[],"checksum":2696897272,"timestamp":"2024-06-01T17:52:33.077039Z"}]}
{"channel":"book","type":"update","data":[{"symbol":"USDT/EUR","bids":[{"price":0.9216,"qty":277146.44421675},{"price":0.9214,"qty":747297.68866205}],"asks":[],"checksum":1902495162,"timestamp":"2024-06-01T17:52:33.079685Z"}]}
{"channel":"book","type":"update","data":[{"symbol":"USDT/EUR","bids":[{"price":0.9214,"qty":747278.32810941},{"price":0.9216,"qty":277165.80054002}],"asks":[],"checksum":432415990,"timestamp":"2024-06-01T17:52:33.083572Z"}]}
{"channel":"book","type":"update","data":[{"symbol":"USDT/EUR","bids":[{"price":0.9216,"qty":277146.44421675},{"price":0.9215,"qty":203882.83225027}],"asks":[],"checksum":916154824,"timestamp":"2024-06-01T17:52:33.128591Z"}]}
{"channel":"book","type":"update","data":[{"symbol":"USDT/EUR","bids":[],"asks":[{"price":0.9218,"qty":408063.69729229}],"checksum":2492181657,"timestamp":"2024-06-01T17:52:33.177553Z"}]}
{"channel":"book","type":"update","data":[{"symbol":"USDT/EUR","bids":[],"asks":[{"price":0.9217,"qty":32.02251506}],"checksum":2319841680,"timestamp":"2024-06-01T17:52:33.177783Z"}]}
{"channel":"book","type":"update","data":[{"symbol":"USDT/EUR","bids":[],"asks":[{"price":0.9217,"qty":170334.53027424}],"checksum":2118567375,"timestamp":"2024-06-01T17:52:33.181997Z"}]}
{"channel":"book","type":"update","data":[{"symbol":"USDT/EUR","bids":[],"asks":[{"price":0.9218,"qty":452856.81945562}],"checksum":2303320375,"timestamp":"2024-06-01T17:52:33.182243Z"}]}
{"channel":"book","type":"update","data":[{"symbol":"USDT/EUR","bids":[{"price":0.9215,"qty":203863.47382648},{"price":0.9216,"qty":277165.80052102}],"asks":[],"checksum":856006690,"timestamp":"2024-06-01T17:52:33.454299Z"}]}
{"channel":"book","type":"update","data":[{"symbol":"USDT/EUR","bids":[{"price":0.9216,"qty":277146.44421675},{"price":0.9215,"qty":203882.83223127}],"asks":[],"checksum":2770989317,"timestamp":"2024-06-01T17:52:33.458972Z"}]}
{"channel":"book","type":"update","data":[{"symbol":"USDT/EUR","bids":[{"price":0.9215,"qty":203863.47382648},{"price":0.9216,"qty":277165.79825103}],"asks":[],"checksum":1792723725,"timestamp":"2024-06-01T17:52:34.309103Z"}]}
{"channel":"book","type":"update","data":[{"symbol":"USDT/EUR","bids":[{"price":0.9215,"qty":202908.31469529}],"asks":[],"checksum":3120292574,"timestamp":"2024-06-01T17:52:34.641339Z"}]}
{"channel":"book","type":"update","data":[{"symbol":"USDT/EUR","bids":[{"price":0.9216,"qty":277146.44421675},{"price":0.9215,"qty":202927.67074061}],"asks":[],"checksum":2301120945,"timestamp":"2024-06-01T17:52:34.644623Z"}]}
{"channel":"book","type":"update","data":[{"symbol":"USDT/EUR","bids":[{"price":0.9215,"qty":204288.05859984}],"asks":[],"checksum":2652109380,"timestamp":"2024-06-01T17:52:34.683620Z"}]}
{"channel":"book","type":"update","data":[{"symbol":"USDT/EUR","bids":[{"price":0.9215,"qty":204268.70255452},{"price":0.9216,"qty":277165.79816181}],"asks":[],"checksum":2076267881,"timestamp":"2024-06-01T17:52:34.687203Z"}]}
{"channel":"book","type":"update","data":[{"symbol":"USDT/EUR","bids":[{"price":0.9214,"qty":64536.57705772}],"asks":[],"checksum":2189575466,"timestamp":"2024-06-01T17:52:35.638293Z"}]}
{"channel":"book","type":"update","data":[{"symbol":"USDT/EUR","bids":[{"price":0.9214,"qty":734869.00227997}],"asks":[],"checksum":1728079248,"timestamp":"2024-06-01T17:52:35.640428Z"}]}
{"channel":"book","type":"update","data":[{"symbol":"USDT/EUR","bids":[{"price":0.9216,"qty":277146.44421675},{"price":0.9214,"qty":734888.36051042}],"asks":[],"checksum":3867424026,"timestamp":"2024-06-01T17:52:35.641554Z"}]}
