{"channel":"book","type":"snapshot","data":[{"symbol":"USDT/JPY","bids":[{"price":156.710,"qty":793.94609132},{"price":156.709,"qty":20784.03769414},{"price":156.708,"qty":5586.33688371},{"price":156.677,"qty":55.49500000},{"price":156.674,"qty":12.76540000},{"price":156.589,"qty":34060.93004763},{"price":156.280,"qty":543.18000000},{"price":156.279,"qty":2241.30500000},{"price":156.274,"qty":12.79810000},{"price":156.162,"qty":18.92150801}],"asks":[{"price":157.392,"qty":1723.30827067},{"price":157.405,"qty":55.49500000},{"price":157.477,"qty":2993.78515109},{"price":157.478,"qty":13.70020000},{"price":157.836,"qty":524.79424042},{"price":157.841,"qty":47124.46409775},{"price":157.846,"qty":32278.08666167},{"price":157.881,"qty":13.66780000},{"price":157.958,"qty":22.93459701},{"price":157.977,"qty":37.22608421}],"checksum":1127506018}]}
{"channel":"book","type":"update","data":[{"symbol":"USDT/JPY","bids":[],"asks":[{"price":157.836,"qty":0.00000000},{"price":157.993,"qty":14.34648488}],"checksum":1013250047,"timestamp":"2024-06-01T17:51:25.624853Z"}]}
{"channel":"book","type":"update","data":[{"symbol":"USDT/JPY","bids":[],"asks":[{"price":157.835,"qty":524.79424042}],"checksum":3426537445,"timestamp":"2024-06-01T17:51:25.627615Z"}]}
{"channel":"book","type":"update","data":[{"symbol":"USDT/JPY","bids":[{"price":156.708,"qty":0.00000000},{"price":156.154,"qty":34.81499558}],"asks":[],"checksum":1063680251,"timestamp":"2024-06-01T17:51:26.561235Z"}]}
{"channel":"book","type":"update","data":[{"symbol":"USDT/JPY","bids":[{"price":156.710,"qty":6380.28297503}],"asks":[],"checksum":1197068317,"timestamp":"2024-06-01T17:51:26.601429Z"}]}
{"channel":"book","type":"update","data":[{"symbol":"USDT/JPY","bids":[{"price":156.709,"qty":0.00000000},{"price":156.132,"qty":61.72543959},{"price":156.711,"qty":20783.77244106}],"asks":[],"checksum":2989450038,"timestamp":"2024-06-01T17:51:26.663211Z"}]}
{"channel":"book","type":"update","data":[{"symbol":"USDT/JPY","bids":[{"price":156.710,"qty":5586.33688371}],"asks":[],"checksum":3920407583,"timestamp":"2024-06-01T17:51:26.683799Z"}]}
{"channel":"book","type":"update","data":[{"symbol":"USDT/JPY","bids":[{"price":156.712,"qty":793.93596943}],"asks":[],"checksum":1267992369,"timestamp":"2024-06-01T17:51:26.683866Z"}]}
{"channel":"book","type":"update","data":[{"symbol":"USDT/JPY","bids":[{"price":156.710,"qty":0.00000000},{"price":156.154,"qty":34.81499558}],"asks":[],"checksum":2557814168,"timestamp":"2024-06-01T17:51:32.062352Z"}]}
{"channel":"book","type":"update","data":[{"symbol":"USDT/JPY","bids":[{"price":156.712,"qty":6380.27285314}],"asks":[],"checksum":1139928919,"timestamp":"2024-06-01T17:51:32.102307Z"}]}
{"channel":"book","type":"update","data":[{"symbol":"USDT/JPY","bids":[{"price":156.711,"qty":0.00000000},{"price":156.132,"qty":61.72543959},{"price":156.713,"qty":20783.50719475}],"asks":[],"checksum":1560093569,"timestamp":"2024-06-01T17:51:32.149083Z"}]}
{"channel":"book","type":"update","data":[{"symbol":"USDT/JPY","bids":[{"price":156.712,"qty":5586.33688371}],"asks":[],"checksum":2496906284,"timestamp":"2024-06-01T17:51:32.170215Z"}]}
{"channel":"book","type":"update","data":[{"symbol":"USDT/JPY","bids":[{"price":156.714,"qty":793.92586712}],"asks":[],"checksum":3957590799,"timestamp":"2024-06-01T17:51:32.170338Z"}]}
{"channel":"book","type":"update","data":[{"symbol":"USDT/JPY","bids":[{"price":156.712,"qty":0.00000000},{"price":156.154,"qty":34.81499558}],"asks":[],"checksum":3101644436,"timestamp":"2024-06-01T17:51:36.638136Z"}]}
{"channel":"book","type":"update","data":[{"symbol":"USDT/JPY","bids":[{"price":156.714,"qty":6380.26348610}],"asks":[],"checksum":1289832862,"timestamp":"2024-06-01T17:51:36.678421Z"}]}
{"channel":"book","type":"update","data":[{"symbol":"USDT/JPY","bids":[{"price":156.713,"qty":0.00000000},{"price":156.132,"qty":61.72543959},{"price":156.715,"qty":20783.24195521}],"asks":[],"checksum":3080128580,"timestamp":"2024-06-01T17:51:36.755789Z"}]}
{"channel":"book","type":"update","data":[{"symbol":"USDT/JPY","bids":[{"price":156.714,"qty":5586.33761898}],"asks":[],"checksum":3556739589,"timestamp":"2024-06-01T17:51:36.781894Z"}]}
{"channel":"book","type":"update","data":[{"symbol":"USDT/JPY","bids":[{"price":156.716,"qty":793.91570125}],"asks":[],"checksum":1294279743,"timestamp":"2024-06-01T17:51:36.782058Z"}]}
{"channel":"book","type":"update","data":[{"symbol":"USDT/JPY","bids":[{"price":156.714,"qty":0.00000000},{"price":156.154,"qty":34.81499558}],"asks":[],"checksum":3420100817,"timestamp":"2024-06-01T17:51:41.332181Z"}]}
{"channel":"book","type":"update","data":[{"symbol":"USDT/JPY","bids":[{"price":156.716,"qty":6380.26391754}],"asks":[],"checksum":3041260714,"timestamp":"2024-06-01T17:51:41.372469Z"}]}
{"channel":"book","type":"update","data":[{"symbol":"USDT/JPY","bids":[{"price":156.715,"qty":0.00000000},{"price":156.132,"qty":61.72543959},{"price":156.717,"qty":20782.97672244}],"asks":[],"checksum":4027598995,"timestamp":"2024-06-01T17:51:41.461606Z"}]}
{"channel":"book","type":"update","data":[{"symbol":"USDT/JPY","bids":[{"price":156.718,"qty":793.90560699}],"asks":[],"checksum":3206495725,"timestamp":"2024-06-01T17:51:41.495173Z"}]}
{"channel":"book","type":"update","data":[{"symbol":"USDT/JPY","bids":[{"price":156.716,"qty":5586.34821629}],"asks":[],"checksum":1265552466,"timestamp":"2024-06-01T17:51:41.495210Z"}]}
{"channel":"book","type":"update","data":[{"symbol":"USDT/JPY","bids":[{"price":156.280,"qty":0.00000000},{"price":156.154,"qty":34.81499558}],"asks":[],"checksum":2218399154,"timestamp":"2024-06-01T17:51:43.279649Z"}]}
{"channel":"book","type":"update","data":[{"symbol":"USDT/JPY","bids":[{"price":156.281,"qty":543.18000000}],"asks":[],"checksum":4252314658,"timestamp":"2024-06-01T17:51:43.282677Z"}]}
{"channel":"book","type":"update","data":[{"symbol":"USDT/JPY","bids":[{"price":156.716,"qty":0.00000000},{"price":156.154,"qty":34.81499558}],"asks":[],"checksum":3233233295,"timestamp":"2024-06-01T17:51:46.102189Z"}]}
{"channel":"book","type":"update","data":[{"symbol":"USDT/JPY","bids":[{"price":156.718,"qty":6380.25382328}],"asks":[],"checksum":2640134273,"timestamp":"2024-06-01T17:51:46.142490Z"}]}
{"channel":"book","type":"update","data":[{"symbol":"USDT/JPY","bids":[{"price":156.717,"qty":0.00000000},{"price":156.132,"qty":61.72543959},{"price":156.719,"qty":20782.71149644}],"asks":[],"checksum":164411946,"timestamp":"2024-06-01T17:51:46.213125Z"}]}
{"channel":"book","type":"update","data":[{"symbol":"USDT/JPY","bids":[{"price":156.718,"qty":5586.34821629}],"asks":[],"checksum":3930983341,"timestamp":"2024-06-01T17:51:46.228219Z"}]}
{"channel":"book","type":"update","data":[{"symbol":"USDT/JPY","bids":[{"price":156.720,"qty":793.89541858}],"asks":[],"checksum":3738739406,"timestamp":"2024-06-01T17:51:46.228365Z"}]}
{"channel":"book","type":"update","data":[{"symbol":"USDT/JPY","bids":[],"asks":[{"price":157.835,"qty":0.00000000},{"price":157.993,"qty":14.34648488}],"checksum":780180180,"timestamp":"2024-06-01T17:51:49.163016Z"}]}
{"channel":"book","type":"update","data":[{"symbol":"USDT/JPY","bids":[],"asks":[{"price":157.835,"qty":490.53874442}],"checksum":1715381029,"timestamp":"2024-06-01T17:51:49.165846Z"}]}
{"channel":"book","type":"update","data":[{"symbol":"USDT/JPY","bids":[{"price":156.718,"qty":0.00000000},{"price":156.154,"qty":34.81499558}],"asks":[],"checksum":731697316,"timestamp":"2024-06-01T17:51:51.079371Z"}]}
{"channel":"book","type":"update","data":[{"symbol":"USDT/JPY","bids":[{"price":156.720,"qty":6380.24363487}],"asks":[],"checksum":3487230278,"timestamp":"2024-06-01T17:51:51.119684Z"}]}
{"channel":"book","type":"update","data":[{"symbol":"USDT/JPY","bids":[{"price":156.719,"qty":0.00000000},{"price":156.132,"qty":61.72543959},{"price":156.721,"qty":20782.44627721}],"asks":[],"checksum":668956250,"timestamp":"2024-06-01T17:51:51.181964Z"}]}
{"channel":"book","type":"update","data":[{"symbol":"USDT/JPY","bids":[{"price":156.720,"qty":5586.34821629}],"asks":[],"checksum":2120679916,"timestamp":"2024-06-01T17:51:51.188865Z"}]}
{"channel":"book","type":"update","data":[{"symbol":"USDT/JPY","bids":[{"price":156.722,"qty":793.88528732}],"asks":[],"checksum":133903000,"timestamp":"2024-06-01T17:51:51.188990Z"}]}
{"channel":"book","type":"update","data":[{"symbol":"USDT/JPY","bids":[],"asks":[{"price":157.835,"qty":0.00000000},{"price":157.993,"qty":14.34648488}],"checksum":1329924969,"timestamp":"2024-06-01T17:51:55.047433Z"}]}
{"channel":"book","type":"update","data":[{"symbol":"USDT/JPY","bids":[],"asks":[{"price":157.835,"qty":482.76883191}],"checksum":381359303,"timestamp":"2024-06-01T17:51:55.050285Z"}]}
{"channel":"book","type":"update","data":[{"symbol":"USDT/JPY","bids":[{"price":156.720,"qty":0.00000000},{"price":156.154,"qty":34.81499558}],"asks":[],"checksum":141487068,"timestamp":"2024-06-01T17:51:55.871794Z"}]}
{"channel":"book","type":"update","data":[{"symbol":"USDT/JPY","bids":[{"price":156.722,"qty":6380.23350361}],"asks":[],"checksum":1551328482,"timestamp":"2024-06-01T17:51:55.911972Z"}]}
{"channel":"book","type":"update","data":[{"symbol":"USDT/JPY","bids":[{"price":156.721,"qty":0.00000000},{"price":156.132,"qty":61.72543959},{"price":156.723,"qty":20782.18106475}],"asks":[],"checksum":1296387241,"timestamp":"2024-06-01T17:51:55.968906Z"}]}
{"channel":"book","type":"update","data":[{"symbol":"USDT/JPY","bids":[{"price":156.722,"qty":5586.34821629}],"asks":[],"checksum":593107337,"timestamp":"2024-06-01T17:51:55.981596Z"}]}
{"channel":"book","type":"update","data":[{"symbol":"USDT/JPY","bids":[{"price":156.724,"qty":793.87515632}],"asks":[],"checksum":988870084,"timestamp":"2024-06-01T17:51:55.981671Z"}]}
{"channel":"book","type":"update","data":[{"symbol":"USDT/JPY","bids":[{"price":156.281,"qty":0.00000000},{"price":156.154,"qty":34.81499558}],"asks":[],"checksum":3595257801,"timestamp":"2024-06-01T17:52:00.931996Z"}]}
{"channel":"book","type":"update","data":[{"symbol":"USDT/JPY","bids":[{"price":156.722,"qty":0.00000000},{"price":156.132,"qty":61.72543959}],"asks":[],"checksum":591906213,"timestamp":"2024-06-01T17:52:00.932662Z"}]}
{"channel":"book","type":"update","data":[{"symbol":"USDT/JPY","bids":[{"price":156.282,"qty":543.18000000}],"asks":[],"checksum":3695888825,"timestamp":"2024-06-01T17:52:00.934729Z"}]}
{"channel":"book","type":"update","data":[{"symbol":"USDT/JPY","bids":[{"price":156.724,"qty":6380.22337261}],"asks":[],"checksum":2044258095,"timestamp":"2024-06-01T17:52:00.972761Z"}]}
{"channel":"book","type":"update","data":[{"symbol":"USDT/JPY","bids":[{"price":156.723,"qty":0.00000000},{"price":156.132,"qty":61.72543959},{"price":156.725,"qty":20781.91585906}],"asks":[],"checksum":2353739675,"timestamp":"2024-06-01T17:52:01.021330Z"}]}
{"channel":"book","type":"update","data":[{"symbol":"USDT/JPY","bids":[{"price":156.724,"qty":5586.34821629}],"asks":[],"checksum":2100412205,"timestamp":"2024-06-01T17:52:01.024335Z"}]}
{"channel":"book","type":"update","data":[{"symbol":"USDT/JPY","bids":[{"price":156.726,"qty":793.86502558}],"asks":[],"checksum":953162874,"timestamp":"2024-06-01T17:52:01.024471Z"}]}
{"channel":"book","type":"update","data":[{"symbol":"USDT/JPY","bids":[{"price":156.724,"qty":0.00000000},{"price":156.154,"qty":34.81499558}],"asks":[],"checksum":2788265409,"timestamp":"2024-06-01T17:52:07.246216Z"}]}
{"channel":"book","type":"update","data":[{"symbol":"USDT/JPY","bids":[{"price":156.726,"qty":6380.21344695}],"asks":[],"checksum":2202055176,"timestamp":"2024-06-01T17:52:07.286470Z"}]}
{"channel":"book","type":"update","data":[{"symbol":"USDT/JPY","bids":[{"price":156.725,"qty":0.00000000},{"price":156.132,"qty":61.72543959},{"price":156.727,"qty":20781.65066013}],"asks":[],"checksum":1207874779,"timestamp":"2024-06-01T17:52:07.360904Z"}]}
{"channel":"book","type":"update","data":[{"symbol":"USDT/JPY","bids":[{"price":156.726,"qty":5586.34842137}],"asks":[],"checksum":1049651790,"timestamp":"2024-06-01T17:52:07.393689Z"}]}
{"channel":"book","type":"update","data":[{"symbol":"USDT/JPY","bids":[{"price":156.728,"qty":793.85489510}],"asks":[],"checksum":734172870,"timestamp":"2024-06-01T17:52:07.393861Z"}]}
{"channel":"book","type":"update","data":[{"symbol":"USDT/JPY","bids":[{"price":156.589,"qty":0.00000000},{"price":156.154,"qty":34.81499558}],"asks":[],"checksum":3041567348,"timestamp":"2024-06-01T17:52:09.127204Z"}]}
{"channel":"book","type":"update","data":[{"symbol":"USDT/JPY","bids":[{"price":156.588,"qty":34064.34250616}],"asks":[],"checksum":3272932372,"timestamp":"2024-06-01T17:52:09.167935Z"}]}
{"channel":"book","type":"update","data":[{"symbol":"USDT/JPY","bids":[],"asks":[{"price":157.835,"qty":0.00000000},{"price":157.993,"qty":14.34648488}],"checksum":2599084986,"timestamp":"2024-06-01T17:52:12.701670Z"}]}
{"channel":"book","type":"update","data":[{"symbol":"USDT/JPY","bids":[],"asks":[{"price":157.835,"qty":477.48912812}],"checksum":929353574,"timestamp":"2024-06-01T17:52:12.704484Z"}]}
{"channel":"book","type":"update","data":[{"symbol":"USDT/JPY","bids":[{"price":156.726,"qty":0.00000000},{"price":156.154,"qty":34.81499558}],"asks":[],"checksum":3714358720,"timestamp":"2024-06-01T17:52:12.900159Z"}]}
{"channel":"book","type":"update","data":[{"symbol":"USDT/JPY","bids":[{"price":156.728,"qty":6380.22293907}],"asks":[],"checksum":1154858094,"timestamp":"2024-06-01T17:52:12.940364Z"}]}
{"channel":"book","type":"update","data":[{"symbol":"USDT/JPY","bids":[{"price":156.727,"qty":0.00000000},{"price":156.132,"qty":61.72543959},{"price":156.729,"qty":20781.38546798}],"asks":[],"checksum":4022617945,"timestamp":"2024-06-01T17:52:12.991003Z"}]}
{"channel":"book","type":"update","data":[{"symbol":"USDT/JPY","bids":[{"price":156.728,"qty":5586.36804397}],"asks":[],"checksum":630314734,"timestamp":"2024-06-01T17:52:13.010060Z"}]}
{"channel":"book","type":"update","data":[{"symbol":"USDT/JPY","bids":[{"price":156.730,"qty":793.84476488}],"asks":[],"checksum":2472671914,"timestamp":"2024-06-01T17:52:13.010309Z"}]}
{"channel":"book","type":"update","data":[{"symbol":"USDT/JPY","bids":[{"price":156.728,"qty":0.00000000},{"price":156.154,"qty":34.81499558}],"asks":[],"checksum":3354659106,"timestamp":"2024-06-01T17:52:18.179477Z"}]}
{"channel":"book","type":"update","data":[{"symbol":"USDT/JPY","bids":[{"price":156.730,"qty":6380.21280885}],"asks":[],"checksum":2502192355,"timestamp":"2024-06-01T17:52:18.219579Z"}]}
{"channel":"book","type":"update","data":[{"symbol":"USDT/JPY","bids":[{"price":156.729,"qty":0.00000000},{"price":156.132,"qty":61.72543959},{"price":156.731,"qty":20781.12028259}],"asks":[],"checksum":1270905566,"timestamp":"2024-06-01T17:52:18.286901Z"}]}
{"channel":"book","type":"update","data":[{"symbol":"USDT/JPY","bids":[{"price":156.730,"qty":5586.36804397}],"asks":[],"checksum":130470207,"timestamp":"2024-06-01T17:52:18.300360Z"}]}
{"channel":"book","type":"update","data":[{"symbol":"USDT/JPY","bids":[{"price":156.732,"qty":793.83463491}],"asks":[],"checksum":2990178683,"timestamp":"2024-06-01T17:52:18.300449Z"}]}
{"channel":"book","type":"update","data":[{"symbol":"USDT/JPY","bids":[{"price":156.730,"qty":0.00000000},{"price":156.154,"qty":34.81499558}],"asks":[],"checksum":1534567394,"timestamp":"2024-06-01T17:52:24.091023Z"}]}
{"channel":"book","type":"update","data":[{"symbol":"USDT/JPY","bids":[{"price":156.732,"qty":6380.20267888}],"asks":[],"checksum":2876778602,"timestamp":"2024-06-01T17:52:24.131412Z"}]}
{"channel":"book","type":"update","data":[{"symbol":"USDT/JPY","bids":[{"price":156.731,"qty":0.00000000},{"price":156.132,"qty":61.72543959},{"price":156.733,"qty":20780.85510397}],"asks":[],"checksum":1226060305,"timestamp":"2024-06-01T17:52:24.181091Z"}]}
{"channel":"book","type":"update","data":[{"symbol":"USDT/JPY","bids":[{"price":156.734,"qty":793.82450521}],"asks":[],"checksum":3235832813,"timestamp":"2024-06-01T17:52:24.204207Z"}]}
{"channel":"book","type":"update","data":[{"symbol":"USDT/JPY","bids":[{"price":156.732,"qty":5586.36804397}],"asks":[],"checksum":4226890397,"timestamp":"2024-06-01T17:52:24.204289Z"}]}
{"channel":"book","type":"update","data":[{"symbol":"USDT/JPY","bids":[],"asks":[{"price":157.835,"qty":0.00000000},{"price":157.993,"qty":14.34648488}],"checksum":1451169345,"timestamp":"2024-06-01T17:52:24.469676Z"}]}
{"channel":"book","type":"update","data":[{"symbol":"USDT/JPY","bids":[],"asks":[{"price":157.835,"qty":470.78845659}],"checksum":934618301,"timestamp":"2024-06-01T17:52:24.472474Z"}]}
