{"channel":"book","type":"snapshot","data":[{"symbol":"USDT/GBP","bids":[{"price":0.7839,"qty":879.47513992},{"price":0.7838,"qty":13796.78440286},{"price":0.7837,"qty":18982.17436638},{"price":0.7836,"qty":60583.14558332},{"price":0.7835,"qty":25566.95341476},{"price":0.7834,"qty":123600.96741982},{"price":0.7833,"qty":229201.69317384},{"price":0.7831,"qty":6101.65692807},{"price":0.7830,"qty":45123.93000000},{"price":0.7829,"qty":252552.58825512}],"asks":[{"price":0.7840,"qty":21735.57315328},{"price":0.7841,"qty":263034.98210469},{"price":0.7842,"qty":37956.28729881},{"price":0.7843,"qty":88068.89966721},{"price":0.7844,"qty":60594.31122931},{"price":0.7845,"qty":252498.93250547},{"price":0.7846,"qty":18239.58000000},{"price":0.7847,"qty":11573.48000000},{"price":0.7848,"qty":2255.00000000},{"price":0.7849,"qty":2255.00000000}],"checksum":3263717705}]}
{"channel":"book","type":"update","data":[{"symbol":"USDT/GBP","bids":[{"price":0.7838,"qty":12498.78440286}],"asks":[],"checksum":3207890730,"timestamp":"2024-06-01T17:51:23.865796Z"}]}
{"channel":"book","type":"update","data":[{"symbol":"USDT/GBP","bids":[],"asks":[{"price":0.7840,"qty":20437.57315328}],"checksum":528587266,"timestamp":"2024-06-01T17:51:24.149138Z"}]}
{"channel":"book","type":"update","data":[{"symbol":"USDT/GBP","bids":[{"price":0.7837,"qty":20270.17436638}],"asks":[],"checksum":3682843925,"timestamp":"2024-06-01T17:51:24.496248Z"}]}
{"channel":"book","type":"update","data":[{"symbol":"USDT/GBP","bids":[{"price":0.7834,"qty":25034.44146162}],"asks":[],"checksum":1778153795,"timestamp":"2024-06-01T17:51:25.055692Z"}]}
{"channel":"book","type":"update","data":[{"symbol":"USDT/GBP","bids":[{"price":0.7834,"qty":97063.82581569}],"asks":[],"checksum":2143544779,"timestamp":"2024-06-01T17:51:25.057674Z"}]}
{"channel":"book","type":"update","data":[{"symbol":"USDT/GBP","bids":[],"asks":[{"price":0.7841,"qty":9090.75414277}],"checksum":1498677430,"timestamp":"2024-06-01T17:51:25.100565Z"}]}
{"channel":"book","type":"update","data":[{"symbol":"USDT/GBP","bids":[],"asks":[{"price":0.7840,"qty":12914.08769440},{"price":0.7841,"qty":16614.23960165}],"checksum":53690242,"timestamp":"2024-06-01T17:51:25.103629Z"}]}
{"channel":"book","type":"update","data":[{"symbol":"USDT/GBP","bids":[],"asks":[{"price":0.7841,"qty":267473.45026394}],"checksum":525951645,"timestamp":"2024-06-01T17:51:25.105669Z"}]}
{"channel":"book","type":"update","data":[{"symbol":"USDT/GBP","bids":[],"asks":[{"price":0.7840,"qty":14017.08769440}],"checksum":1034073085,"timestamp":"2024-06-01T17:51:25.196748Z"}]}
{"channel":"book","type":"update","data":[{"symbol":"USDT/GBP","bids":[],"asks":[{"price":0.7841,"qty":259949.96480506},{"price":0.7840,"qty":21540.57315328}],"checksum":132470079,"timestamp":"2024-06-01T17:51:25.199710Z"}]}
{"channel":"book","type":"update","data":[{"symbol":"USDT/GBP","bids":[{"price":0.7838,"qty":13641.78440286}],"asks":[],"checksum":350521004,"timestamp":"2024-06-01T17:51:25.552535Z"}]}
{"channel":"book","type":"update","data":[{"symbol":"USDT/GBP","bids":[{"price":0.7836,"qty":0.00000000},{"price":0.7828,"qty":10511.26000000}],"asks":[],"checksum":3289428748,"timestamp":"2024-06-01T17:51:27.526439Z"}]}
{"channel":"book","type":"update","data":[{"symbol":"USDT/GBP","bids":[{"price":0.7834,"qty":25034.44146162}],"asks":[],"checksum":2200642126,"timestamp":"2024-06-01T17:51:27.526530Z"}]}
{"channel":"book","type":"update","data":[{"symbol":"USDT/GBP","bids":[{"price":0.7836,"qty":58630.42691397}],"asks":[],"checksum":231815502,"timestamp":"2024-06-01T17:51:27.527508Z"}]}
{"channel":"book","type":"update","data":[{"symbol":"USDT/GBP","bids":[{"price":0.7834,"qty":133187.21424678}],"asks":[],"checksum":1099521830,"timestamp":"2024-06-01T17:51:27.527530Z"}]}
{"channel":"book","type":"update","data":[{"symbol":"USDT/GBP","bids":[{"price":0.7837,"qty":7526.45982526},{"price":0.7835,"qty":38310.66795588}],"asks":[],"checksum":1627531358,"timestamp":"2024-06-01T17:51:27.529864Z"}]}
{"channel":"book","type":"update","data":[{"symbol":"USDT/GBP","bids":[],"asks":[{"price":0.7840,"qty":20437.57315328}],"checksum":2317215798,"timestamp":"2024-06-01T17:51:27.540417Z"}]}
{"channel":"book","type":"update","data":[{"symbol":"USDT/GBP","bids":[],"asks":[{"price":0.7841,"qty":9090.75414277}],"checksum":1068727767,"timestamp":"2024-06-01T17:51:28.617722Z"}]}
{"channel":"book","type":"update","data":[{"symbol":"USDT/GBP","bids":[],"asks":[{"price":0.7840,"qty":12914.08769440},{"price":0.7841,"qty":16614.23960165}],"checksum":1708409571,"timestamp":"2024-06-01T17:51:28.621188Z"}]}
{"channel":"book","type":"update","data":[{"symbol":"USDT/GBP","bids":[{"price":0.7835,"qty":25566.95341476},{"price":0.7837,"qty":20270.17436638}],"asks":[],"checksum":4099753597,"timestamp":"2024-06-01T17:51:28.621248Z"}]}
{"channel":"book","type":"update","data":[{"symbol":"USDT/GBP","bids":[],"asks":[{"price":0.7841,"qty":273600.72792862}],"checksum":209348026,"timestamp":"2024-06-01T17:51:28.622546Z"}]}
{"channel":"book","type":"update","data":[{"symbol":"USDT/GBP","bids":[],"asks":[{"price":0.7841,"qty":273643.58140227}],"checksum":2260367389,"timestamp":"2024-06-01T17:51:28.788775Z"}]}
{"channel":"book","type":"update","data":[{"symbol":"USDT/GBP","bids":[],"asks":[{"price":0.7841,"qty":266120.09594339},{"price":0.7840,"qty":20437.57315328}],"checksum":267177514,"timestamp":"2024-06-01T17:51:28.792131Z"}]}
{"channel":"book","type":"update","data":[{"symbol":"USDT/GBP","bids":[],"asks":[{"price":0.7840,"qty":20394.71967963}],"checksum":1443076970,"timestamp":"2024-06-01T17:51:28.958817Z"}]}
{"channel":"book","type":"update","data":[{"symbol":"USDT/GBP","bids":[],"asks":[{"price":0.7849,"qty":6194.04935413}],"checksum":2680610729,"timestamp":"2024-06-01T17:51:30.010811Z"}]}
{"channel":"book","type":"update","data":[{"symbol":"USDT/GBP","bids":[],"asks":[{"price":0.7849,"qty":8163.57403119}],"checksum":2392488768,"timestamp":"2024-06-01T17:51:30.011037Z"}]}
{"channel":"book","type":"update","data":[{"symbol":"USDT/GBP","bids":[{"price":0.7834,"qty":25034.44146162}],"asks":[],"checksum":2757805688,"timestamp":"2024-06-01T17:51:30.015584Z"}]}
{"channel":"book","type":"update","data":[{"symbol":"USDT/GBP","bids":[{"price":0.7836,"qty":0.00000000},{"price":0.7828,"qty":10511.26000000}],"asks":[],"checksum":714792312,"timestamp":"2024-06-01T17:51:30.015620Z"}]}
{"channel":"book","type":"update","data":[{"symbol":"USDT/GBP","bids":[{"price":0.7836,"qty":60583.14558332}],"asks":[],"checksum":2875909394,"timestamp":"2024-06-01T17:51:30.016738Z"}]}
{"channel":"book","type":"update","data":[{"symbol":"USDT/GBP","bids":[{"price":0.7834,"qty":119809.94719066}],"asks":[],"checksum":4266670610,"timestamp":"2024-06-01T17:51:30.016939Z"}]}
{"channel":"book","type":"update","data":[{"symbol":"USDT/GBP","bids":[{"price":0.7837,"qty":7526.45982526},{"price":0.7835,"qty":38310.66795588}],"asks":[],"checksum":3094976058,"timestamp":"2024-06-01T17:51:30.019039Z"}]}
{"channel":"book","type":"update","data":[{"symbol":"USDT/GBP","bids":[],"asks":[{"price":0.7841,"qty":9133.60761642}],"checksum":3270307270,"timestamp":"2024-06-01T17:51:32.096113Z"}]}
{"channel":"book","type":"update","data":[{"symbol":"USDT/GBP","bids":[],"asks":[{"price":0.7840,"qty":12871.23422075},{"price":0.7841,"qty":16657.09307530}],"checksum":2832503791,"timestamp":"2024-06-01T17:51:32.100635Z"}]}
{"channel":"book","type":"update","data":[{"symbol":"USDT/GBP","bids":[{"price":0.7835,"qty":25566.95341476},{"price":0.7837,"qty":20270.17436638}],"asks":[],"checksum":150581580,"timestamp":"2024-06-01T17:51:32.100811Z"}]}
{"channel":"book","type":"update","data":[{"symbol":"USDT/GBP","bids":[],"asks":[{"price":0.7841,"qty":268544.64645194}],"checksum":2880814073,"timestamp":"2024-06-01T17:51:32.101703Z"}]}
{"channel":"book","type":"update","data":[{"symbol":"USDT/GBP","bids":[{"price":0.7834,"qty":25034.44146162}],"asks":[],"checksum":1271734693,"timestamp":"2024-06-01T17:51:32.530217Z"}]}
{"channel":"book","type":"update","data":[{"symbol":"USDT/GBP","bids":[{"price":0.7834,"qty":125496.94114944}],"asks":[],"checksum":1090351339,"timestamp":"2024-06-01T17:51:32.530548Z"}]}
{"channel":"book","type":"update","data":[{"symbol":"USDT/GBP","bids":[],"asks":[{"price":0.7841,"qty":261021.16099306},{"price":0.7840,"qty":20394.71967963}],"checksum":730039574,"timestamp":"2024-06-01T17:51:32.533574Z"}]}
{"channel":"book","type":"update","data":[{"symbol":"USDT/GBP","bids":[{"price":0.7839,"qty":1134.61227475}],"asks":[],"checksum":820760496,"timestamp":"2024-06-01T17:51:33.903174Z"}]}
{"channel":"book","type":"update","data":[{"symbol":"USDT/GBP","bids":[],"asks":[{"price":0.7840,"qty":21580.71967963}],"checksum":3546438424,"timestamp":"2024-06-01T17:51:34.509906Z"}]}
{"channel":"book","type":"update","data":[{"symbol":"USDT/GBP","bids":[],"asks":[{"price":0.7840,"qty":20394.71967963}],"checksum":820760496,"timestamp":"2024-06-01T17:51:35.024204Z"}]}
{"channel":"book","type":"update","data":[{"symbol":"USDT/GBP","bids":[],"asks":[{"price":0.7841,"qty":9133.60761642}],"checksum":3151994117,"timestamp":"2024-06-01T17:51:35.549638Z"}]}
{"channel":"book","type":"update","data":[{"symbol":"USDT/GBP","bids":[],"asks":[{"price":0.7841,"qty":263077.83557834}],"checksum":4136037247,"timestamp":"2024-06-01T17:51:35.552435Z"}]}
{"channel":"book","type":"update","data":[{"symbol":"USDT/GBP","bids":[],"asks":[{"price":0.7840,"qty":12871.23422075},{"price":0.7841,"qty":270601.32103722}],"checksum":3015390699,"timestamp":"2024-06-01T17:51:35.552712Z"}]}
{"channel":"book","type":"update","data":[{"symbol":"USDT/GBP","bids":[],"asks":[{"price":0.7840,"qty":14181.23422075}],"checksum":4044116985,"timestamp":"2024-06-01T17:51:36.554316Z"}]}
{"channel":"book","type":"update","data":[{"symbol":"USDT/GBP","bids":[],"asks":[{"price":0.7841,"qty":263077.83557834},{"price":0.7840,"qty":21704.71967963}],"checksum":1422881613,"timestamp":"2024-06-01T17:51:36.557325Z"}]}
{"channel":"book","type":"update","data":[{"symbol":"USDT/GBP","bids":[],"asks":[{"price":0.7840,"qty":20394.71967963}],"checksum":4136037247,"timestamp":"2024-06-01T17:51:38.299520Z"}]}
{"channel":"book","type":"update","data":[{"symbol":"USDT/GBP","bids":[],"asks":[{"price":0.7841,"qty":9133.60761642}],"checksum":3151994117,"timestamp":"2024-06-01T17:51:38.953810Z"}]}
{"channel":"book","type":"update","data":[{"symbol":"USDT/GBP","bids":[],"asks":[{"price":0.7840,"qty":12871.23422075},{"price":0.7841,"qty":16657.09307530}],"checksum":1210332397,"timestamp":"2024-06-01T17:51:38.956849Z"}]}
{"channel":"book","type":"update","data":[{"symbol":"USDT/GBP","bids":[],"asks":[{"price":0.7841,"qty":273686.33291514}],"checksum":3819480025,"timestamp":"2024-06-01T17:51:38.958000Z"}]}
{"channel":"book","type":"update","data":[{"symbol":"USDT/GBP","bids":[],"asks":[{"price":0.7840,"qty":13798.23422075}],"checksum":3293790188,"timestamp":"2024-06-01T17:51:39.569497Z"}]}
{"channel":"book","type":"update","data":[{"symbol":"USDT/GBP","bids":[],"asks":[{"price":0.7841,"qty":266162.84745626},{"price":0.7840,"qty":21321.71967963}],"checksum":1951296763,"timestamp":"2024-06-01T17:51:39.572517Z"}]}
{"channel":"book","type":"update","data":[{"symbol":"USDT/GBP","bids":[{"price":0.7834,"qty":25034.44146162}],"asks":[],"checksum":2517159372,"timestamp":"2024-06-01T17:51:39.984730Z"}]}
{"channel":"book","type":"update","data":[{"symbol":"USDT/GBP","bids":[{"price":0.7834,"qty":127392.45672080}],"asks":[],"checksum":3741022444,"timestamp":"2024-06-01T17:51:39.985619Z"}]}
{"channel":"book","type":"update","data":[{"symbol":"USDT/GBP","bids":[],"asks":[{"price":0.7840,"qty":20394.71967963}],"checksum":1443011673,"timestamp":"2024-06-01T17:51:40.139855Z"}]}
{"channel":"book","type":"update","data":[{"symbol":"USDT/GBP","bids":[],"asks":[{"price":0.7849,"qty":4224.52467706}],"checksum":3068777103,"timestamp":"2024-06-01T17:51:40.478255Z"}]}
{"channel":"book","type":"update","data":[{"symbol":"USDT/GBP","bids":[],"asks":[{"price":0.7849,"qty":2255.00000000}],"checksum":2371996783,"timestamp":"2024-06-01T17:51:40.479328Z"}]}
{"channel":"book","type":"update","data":[{"symbol":"USDT/GBP","bids":[{"price":0.7839,"qty":2166.61227475}],"asks":[],"checksum":1207734521,"timestamp":"2024-06-01T17:51:40.653910Z"}]}
{"channel":"book","type":"update","data":[{"symbol":"USDT/GBP","bids":[{"price":0.7839,"qty":1134.61227475}],"asks":[],"checksum":2371996783,"timestamp":"2024-06-01T17:51:40.930108Z"}]}
{"channel":"book","type":"update","data":[{"symbol":"USDT/GBP","bids":[],"asks":[{"price":0.7840,"qty":21420.71967963}],"checksum":752926657,"timestamp":"2024-06-01T17:51:41.777902Z"}]}
{"channel":"book","type":"update","data":[{"symbol":"USDT/GBP","bids":[{"price":0.7836,"qty":0.00000000},{"price":0.7828,"qty":13243.60756503}],"asks":[],"checksum":1691183178,"timestamp":"2024-06-01T17:51:42.470132Z"}]}
{"channel":"book","type":"update","data":[{"symbol":"USDT/GBP","bids":[{"price":0.7834,"qty":25034.44146162}],"asks":[],"checksum":1888746177,"timestamp":"2024-06-01T17:51:42.470213Z"}]}
{"channel":"book","type":"update","data":[{"symbol":"USDT/GBP","bids":[{"price":0.7836,"qty":56677.87140777}],"asks":[],"checksum":3614274574,"timestamp":"2024-06-01T17:51:42.472271Z"}]}
{"channel":"book","type":"update","data":[{"symbol":"USDT/GBP","bids":[{"price":0.7834,"qty":133296.22216273}],"asks":[],"checksum":3600841594,"timestamp":"2024-06-01T17:51:42.472406Z"}]}
{"channel":"book","type":"update","data":[{"symbol":"USDT/GBP","bids":[{"price":0.7837,"qty":7526.45982526},{"price":0.7835,"qty":38310.66795588}],"asks":[],"checksum":1197590025,"timestamp":"2024-06-01T17:51:42.473538Z"}]}
{"channel":"book","type":"update","data":[{"symbol":"USDT/GBP","bids":[],"asks":[{"price":0.7841,"qty":9133.60761642}],"checksum":3111673739,"timestamp":"2024-06-01T17:51:42.592825Z"}]}
{"channel":"book","type":"update","data":[{"symbol":"USDT/GBP","bids":[],"asks":[{"price":0.7840,"qty":13897.23422075},{"price":0.7841,"qty":16657.09307530}],"checksum":822204110,"timestamp":"2024-06-01T17:51:42.595932Z"}]}
{"channel":"book","type":"update","data":[{"symbol":"USDT/GBP","bids":[{"price":0.7835,"qty":25566.95341476},{"price":0.7837,"qty":20270.17436638}],"asks":[],"checksum":3554036857,"timestamp":"2024-06-01T17:51:42.596065Z"}]}
{"channel":"book","type":"update","data":[{"symbol":"USDT/GBP","bids":[],"asks":[{"price":0.7841,"qty":256204.59894025}],"checksum":309816375,"timestamp":"2024-06-01T17:51:42.597616Z"}]}
{"channel":"book","type":"update","data":[{"symbol":"USDT/GBP","bids":[{"price":0.7838,"qty":13880.40165218}],"asks":[],"checksum":798837205,"timestamp":"2024-06-01T17:51:42.761336Z"}]}
{"channel":"book","type":"update","data":[{"symbol":"USDT/GBP","bids":[],"asks":[{"price":0.7841,"qty":248681.11348137},{"price":0.7840,"qty":21420.71967963}],"checksum":2025148395,"timestamp":"2024-06-01T17:51:42.764232Z"}]}
{"channel":"book","type":"update","data":[{"symbol":"USDT/GBP","bids":[{"price":0.7837,"qty":20031.55711706}],"asks":[],"checksum":2585600567,"timestamp":"2024-06-01T17:51:42.927984Z"}]}
{"channel":"book","type":"update","data":[{"symbol":"USDT/GBP","bids":[{"price":0.7838,"qty":12737.40165218}],"asks":[],"checksum":1559191059,"timestamp":"2024-06-01T17:51:43.823450Z"}]}
{"channel":"book","type":"update","data":[{"symbol":"USDT/GBP","bids":[{"price":0.7836,"qty":0.00000000},{"price":0.7828,"qty":13243.60756503}],"asks":[],"checksum":1836427618,"timestamp":"2024-06-01T17:51:44.937270Z"}]}
{"channel":"book","type":"update","data":[{"symbol":"USDT/GBP","bids":[{"price":0.7836,"qty":58521.89913161}],"asks":[],"checksum":3094109664,"timestamp":"2024-06-01T17:51:44.938083Z"}]}
{"channel":"book","type":"update","data":[{"symbol":"USDT/GBP","bids":[{"price":0.7837,"qty":7287.84257594},{"price":0.7835,"qty":38310.66795588}],"asks":[],"checksum":3904405349,"timestamp":"2024-06-01T17:51:44.940250Z"}]}
{"channel":"book","type":"update","data":[{"symbol":"USDT/GBP","bids":[{"price":0.7838,"qty":13962.40165218}],"asks":[],"checksum":793207459,"timestamp":"2024-06-01T17:51:45.692532Z"}]}
{"channel":"book","type":"update","data":[{"symbol":"USDT/GBP","bids":[{"price":0.7835,"qty":25566.95341476},{"price":0.7837,"qty":20031.55711706}],"asks":[],"checksum":3400320376,"timestamp":"2024-06-01T17:51:45.695617Z"}]}
{"channel":"book","type":"update","data":[{"symbol":"USDT/GBP","bids":[],"asks":[{"price":0.7841,"qty":9133.60761642}],"checksum":1511731102,"timestamp":"2024-06-01T17:51:46.129719Z"}]}
{"channel":"book","type":"update","data":[{"symbol":"USDT/GBP","bids":[],"asks":[{"price":0.7840,"qty":13897.23422075},{"price":0.7841,"qty":16657.09307530}],"checksum":1545986824,"timestamp":"2024-06-01T17:51:46.132654Z"}]}
{"channel":"book","type":"update","data":[{"symbol":"USDT/GBP","bids":[],"asks":[{"price":0.7841,"qty":262374.62269609}],"checksum":3896244692,"timestamp":"2024-06-01T17:51:46.134946Z"}]}
{"channel":"book","type":"update","data":[{"symbol":"USDT/GBP","bids":[],"asks":[{"price":0.7840,"qty":13940.08769440}],"checksum":3323054040,"timestamp":"2024-06-01T17:51:46.306255Z"}]}
{"channel":"book","type":"update","data":[{"symbol":"USDT/GBP","bids":[],"asks":[{"price":0.7841,"qty":254851.13723721},{"price":0.7840,"qty":21463.57315328}],"checksum":2540584340,"timestamp":"2024-06-01T17:51:46.309912Z"}]}
{"channel":"book","type":"update","data":[{"symbol":"USDT/GBP","bids":[],"asks":[{"price":0.7841,"qty":254808.28376356}],"checksum":675969098,"timestamp":"2024-06-01T17:51:46.473897Z"}]}
{"channel":"book","type":"update","data":[{"symbol":"USDT/GBP","bids":[{"price":0.7836,"qty":0.00000000},{"price":0.7828,"qty":13243.60756503}],"asks":[],"checksum":4250111176,"timestamp":"2024-06-01T17:51:47.409312Z"}]}
{"channel":"book","type":"update","data":[{"symbol":"USDT/GBP","bids":[{"price":0.7836,"qty":56677.87140777}],"asks":[],"checksum":3435756473,"timestamp":"2024-06-01T17:51:47.409437Z"}]}
{"channel":"book","type":"update","data":[{"symbol":"USDT/GBP","bids":[{"price":0.7837,"qty":7287.84257594},{"price":0.7835,"qty":38310.66795588}],"asks":[],"checksum":2500020121,"timestamp":"2024-06-01T17:51:47.412189Z"}]}
{"channel":"book","type":"update","data":[{"symbol":"USDT/GBP","bids":[{"price":0.7835,"qty":25566.95341476},{"price":0.7837,"qty":20031.55711706}],"asks":[],"checksum":3435756473,"timestamp":"2024-06-01T17:51:47.880366Z"}]}
{"channel":"book","type":"update","data":[{"symbol":"USDT/GBP","bids":[{"price":0.7838,"qty":12737.40165218}],"asks":[],"checksum":3188319009,"timestamp":"2024-06-01T17:51:49.695374Z"}]}
{"channel":"book","type":"update","data":[{"symbol":"USDT/GBP","bids":[],"asks":[{"price":0.7841,"qty":9090.75414277}],"checksum":735341286,"timestamp":"2024-06-01T17:51:49.730368Z"}]}
{"channel":"book","type":"update","data":[{"symbol":"USDT/GBP","bids":[],"asks":[{"price":0.7840,"qty":13940.08769440},{"price":0.7841,"qty":16614.23960165}],"checksum":2752824806,"timestamp":"2024-06-01T17:51:49.735212Z"}]}
{"channel":"book","type":"update","data":[{"symbol":"USDT/GBP","bids":[],"asks":[{"price":0.7841,"qty":246906.70983284}],"checksum":3459794983,"timestamp":"2024-06-01T17:51:49.735307Z"}]}
{"channel":"book","type":"update","data":[{"symbol":"USDT/GBP","bids":[],"asks":[{"price":0.7840,"qty":13926.64058613},{"price":0.7841,"qty":246920.15694111}],"checksum":3777663591,"timestamp":"2024-06-01T17:51:49.826836Z"}]}
{"channel":"book","type":"update","data":[{"symbol":"USDT/GBP","bids":[],"asks":[{"price":0.7841,"qty":239396.67148223},{"price":0.7840,"qty":21450.12604501}],"checksum":3694686978,"timestamp":"2024-06-01T17:51:49.829938Z"}]}
{"channel":"book","type":"update","data":[{"symbol":"USDT/GBP","bids":[],"asks":[{"price":0.7840,"qty":20424.12604501}],"checksum":571023659,"timestamp":"2024-06-01T17:51:49.838160Z"}]}
{"channel":"book","type":"update","data":[{"symbol":"USDT/GBP","bids":[],"asks":[{"price":0.7841,"qty":239383.22437396},{"price":0.7840,"qty":20437.57315328}],"checksum":1276665928,"timestamp":"2024-06-01T17:51:49.859332Z"}]}
{"channel":"book","type":"update","data":[{"symbol":"USDT/GBP","bids":[{"price":0.7836,"qty":0.00000000},{"price":0.7828,"qty":10511.26000000}],"asks":[],"checksum":1664023309,"timestamp":"2024-06-01T17:51:49.988464Z"}]}
{"channel":"book","type":"update","data":[{"symbol":"USDT/GBP","bids":[{"price":0.7836,"qty":58521.89913161}],"asks":[],"checksum":2828755899,"timestamp":"2024-06-01T17:51:49.989594Z"}]}
{"channel":"book","type":"update","data":[{"symbol":"USDT/GBP","bids":[{"price":0.7837,"qty":7287.84257594},{"price":0.7835,"qty":38310.66795588}],"asks":[],"checksum":3321659135,"timestamp":"2024-06-01T17:51:49.991582Z"}]}
{"channel":"book","type":"update","data":[{"symbol":"USDT/GBP","bids":[],"asks":[{"price":0.7849,"qty":6194.04935413}],"checksum":205077052,"timestamp":"2024-06-01T17:51:50.946648Z"}]}
{"channel":"book","type":"update","data":[{"symbol":"USDT/GBP","bids":[],"asks":[{"price":0.7849,"qty":8163.57403119}],"checksum":493199061,"timestamp":"2024-06-01T17:51:50.947842Z"}]}
{"channel":"book","type":"update","data":[{"symbol":"USDT/GBP","bids":[{"price":0.7835,"qty":25566.95341476},{"price":0.7837,"qty":20031.55711706}],"asks":[],"checksum":1945645965,"timestamp":"2024-06-01T17:51:50.949517Z"}]}
{"channel":"book","type":"update","data":[{"symbol":"USDT/GBP","bids":[{"price":0.7838,"qty":13935.40165218}],"asks":[],"checksum":625479223,"timestamp":"2024-06-01T17:51:51.121028Z"}]}
{"channel":"book","type":"update","data":[{"symbol":"USDT/GBP","bids":[],"asks":[{"price":0.7840,"qty":21376.57315328}],"checksum":893094471,"timestamp":"2024-06-01T17:51:51.138787Z"}]}
{"channel":"book","type":"update","data":[{"symbol":"USDT/GBP","bids":[{"price":0.7839,"qty":432.47419875},{"price":0.7839,"qty":255.13713483},{"price":0.7839,"qty":0.00000000},{"price":0.7828,"qty":10511.26000000},{"price":0.7838,"qty":13768.97392693}],"asks":[],"checksum":1025200645,"timestamp":"2024-06-01T17:51:52.009841Z"}]}
{"channel":"book","type":"update","data":[{"symbol":"USDT/GBP","bids":[{"price":0.7838,"qty":14396.36672994}],"asks":[],"checksum":4042230166,"timestamp":"2024-06-01T17:51:52.854754Z"}]}
{"channel":"book","type":"update","data":[{"symbol":"USDT/GBP","bids":[],"asks":[{"price":0.7841,"qty":238927.56159418}],"checksum":3401352131,"timestamp":"2024-06-01T17:51:52.863865Z"}]}
{"channel":"book","type":"update","data":[{"symbol":"USDT/GBP","bids":[{"price":0.7838,"qty":13768.97392693},{"price":0.7839,"qty":627.31269518}],"asks":[],"checksum":2732581595,"timestamp":"2024-06-01T17:51:53.347031Z"}]}
{"channel":"book","type":"update","data":[{"symbol":"USDT/GBP","bids":[],"asks":[{"price":0.7840,"qty":20437.57315328}],"checksum":186763329,"timestamp":"2024-06-01T17:51:53.943054Z"}]}
{"channel":"book","type":"update","data":[{"symbol":"USDT/GBP","bids":[],"asks":[{"price":0.7840,"qty":20668.62698252}],"checksum":3675354025,"timestamp":"2024-06-01T17:51:53.949072Z"}]}
{"channel":"book","type":"update","data":[{"symbol":"USDT/GBP","bids":[{"price":0.7834,"qty":25034.44146162}],"asks":[],"checksum":185571716,"timestamp":"2024-06-01T17:51:54.861473Z"}]}
{"channel":"book","type":"update","data":[{"symbol":"USDT/GBP","bids":[{"price":0.7834,"qty":125706.53204805}],"asks":[],"checksum":1427632655,"timestamp":"2024-06-01T17:51:54.862806Z"}]}
{"channel":"book","type":"update","data":[{"symbol":"USDT/GBP","bids":[],"asks":[{"price":0.7840,"qty":21832.62698252}],"checksum":67666466,"timestamp":"2024-06-01T17:51:55.133809Z"}]}
{"channel":"book","type":"update","data":[{"symbol":"USDT/GBP","bids":[],"asks":[{"price":0.7840,"qty":20668.62698252}],"checksum":1427632655,"timestamp":"2024-06-01T17:51:56.349219Z"}]}
{"channel":"book","type":"update","data":[{"symbol":"USDT/GBP","bids":[],"asks":[{"price":0.7841,"qty":8635.09136299}],"checksum":3838028026,"timestamp":"2024-06-01T17:51:56.982273Z"}]}
{"channel":"book","type":"update","data":[{"symbol":"USDT/GBP","bids":[],"asks":[{"price":0.7841,"qty":245097.58535002}],"checksum":2647653162,"timestamp":"2024-06-01T17:51:56.985327Z"}]}
{"channel":"book","type":"update","data":[{"symbol":"USDT/GBP","bids":[],"asks":[{"price":0.7840,"qty":13145.14152364},{"price":0.7841,"qty":252621.07080890}],"checksum":1526510786,"timestamp":"2024-06-01T17:51:56.985489Z"}]}
{"channel":"book","type":"update","data":[{"symbol":"USDT/GBP","bids":[],"asks":[{"price":0.7840,"qty":14360.14152364}],"checksum":1674897144,"timestamp":"2024-06-01T17:51:57.169711Z"}]}
{"channel":"book","type":"update","data":[{"symbol":"USDT/GBP","bids":[],"asks":[{"price":0.7841,"qty":245097.58535002},{"price":0.7840,"qty":21883.62698252}],"checksum":418821261,"timestamp":"2024-06-01T17:51:57.172835Z"}]}
{"channel":"book","type":"update","data":[{"symbol":"USDT/GBP","bids":[],"asks":[{"price":0.7840,"qty":20668.62698252}],"checksum":2647653162,"timestamp":"2024-06-01T17:51:59.703263Z"}]}
{"channel":"book","type":"update","data":[{"symbol":"USDT/GBP","bids":[],"asks":[{"price":0.7841,"qty":8635.09136299}],"checksum":3838028026,"timestamp":"2024-06-01T17:52:00.599856Z"}]}
{"channel":"book","type":"update","data":[{"symbol":"USDT/GBP","bids":[],"asks":[{"price":0.7840,"qty":13145.14152364},{"price":0.7841,"qty":16158.57682187}],"checksum":512641925,"timestamp":"2024-06-01T17:52:00.603272Z"}]}
{"channel":"book","type":"update","data":[{"symbol":"USDT/GBP","bids":[],"asks":[{"price":0.7841,"qty":259819.43185738}],"checksum":2874160899,"timestamp":"2024-06-01T17:52:00.604551Z"}]}
{"channel":"book","type":"update","data":[{"symbol":"USDT/GBP","bids":[],"asks":[{"price":0.7849,"qty":6194.04935413}],"checksum":3121386474,"timestamp":"2024-06-01T17:52:01.424764Z"}]}
{"channel":"book","type":"update","data":[{"symbol":"USDT/GBP","bids":[],"asks":[{"price":0.7849,"qty":2255.00000000}],"checksum":1942607657,"timestamp":"2024-06-01T17:52:01.425074Z"}]}
{"channel":"book","type":"update","data":[{"symbol":"USDT/GBP","bids":[],"asks":[{"price":0.7841,"qty":252295.94639850},{"price":0.7840,"qty":20668.62698252}],"checksum":2067650950,"timestamp":"2024-06-01T17:52:01.426600Z"}]}
{"channel":"book","type":"update","data":[{"symbol":"USDT/GBP","bids":[{"price":0.7836,"qty":0.00000000},{"price":0.7828,"qty":13243.65043379}],"asks":[],"checksum":1696871867,"timestamp":"2024-06-01T17:52:02.186913Z"}]}
{"channel":"book","type":"update","data":[{"symbol":"USDT/GBP","bids":[{"price":0.7834,"qty":25034.44146162}],"asks":[],"checksum":1367417420,"timestamp":"2024-06-01T17:52:02.186951Z"}]}
{"channel":"book","type":"update","data":[{"symbol":"USDT/GBP","bids":[{"price":0.7834,"qty":119810.22002931}],"asks":[],"checksum":535268993,"timestamp":"2024-06-01T17:52:02.187755Z"}]}
{"channel":"book","type":"update","data":[{"symbol":"USDT/GBP","bids":[{"price":0.7836,"qty":60583.31998939}],"asks":[],"checksum":311711376,"timestamp":"2024-06-01T17:52:02.187775Z"}]}
{"channel":"book","type":"update","data":[{"symbol":"USDT/GBP","bids":[{"price":0.7837,"qty":7287.84257594},{"price":0.7835,"qty":38310.66795588}],"asks":[],"checksum":3933465013,"timestamp":"2024-06-01T17:52:02.190154Z"}]}
{"channel":"book","type":"update","data":[{"symbol":"USDT/GBP","bids":[{"price":0.7837,"qty":7526.45982526}],"asks":[],"checksum":2614238968,"timestamp":"2024-06-01T17:52:02.355588Z"}]}
{"channel":"book","type":"update","data":[{"symbol":"USDT/GBP","bids":[{"price":0.7835,"qty":25566.95341476},{"price":0.7837,"qty":20270.17436638}],"asks":[],"checksum":4030479180,"timestamp":"2024-06-01T17:52:02.358536Z"}]}
{"channel":"book","type":"update","data":[{"symbol":"USDT/GBP","bids":[],"asks":[{"price":0.7840,"qty":21583.62698252}],"checksum":3082546736,"timestamp":"2024-06-01T17:52:02.405526Z"}]}
{"channel":"book","type":"update","data":[{"symbol":"USDT/GBP","bids":[{"price":0.7838,"qty":13530.35667761}],"asks":[],"checksum":3195282348,"timestamp":"2024-06-01T17:52:02.523207Z"}]}
{"channel":"book","type":"update","data":[{"symbol":"USDT/GBP","bids":[{"price":0.7839,"qty":0.00000000},{"price":0.7828,"qty":13243.65043379}],"asks":[],"checksum":2328436833,"timestamp":"2024-06-01T17:52:04.216019Z"}]}
{"channel":"book","type":"update","data":[{"symbol":"USDT/GBP","bids":[],"asks":[{"price":0.7840,"qty":21596.01025194}],"checksum":2673192768,"timestamp":"2024-06-01T17:52:04.368685Z"}]}
{"channel":"book","type":"update","data":[{"symbol":"USDT/GBP","bids":[],"asks":[{"price":0.7840,"qty":21496.01025194}],"checksum":3916573015,"timestamp":"2024-06-01T17:52:04.495139Z"}]}
{"channel":"book","type":"update","data":[{"symbol":"USDT/GBP","bids":[{"price":0.7834,"qty":25034.44146162}],"asks":[],"checksum":2097196953,"timestamp":"2024-06-01T17:52:04.650852Z"}]}
{"channel":"book","type":"update","data":[{"symbol":"USDT/GBP","bids":[{"price":0.7836,"qty":0.00000000},{"price":0.7827,"qty":20533.89000000}],"asks":[],"checksum":1707868494,"timestamp":"2024-06-01T17:52:04.651054Z"}]}
{"channel":"book","type":"update","data":[{"symbol":"USDT/GBP","bids":[{"price":0.7836,"qty":62536.04428020}],"asks":[],"checksum":3470584961,"timestamp":"2024-06-01T17:52:04.652689Z"}]}
{"channel":"book","type":"update","data":[{"symbol":"USDT/GBP","bids":[{"price":0.7834,"qty":125395.69800567}],"asks":[],"checksum":3541697608,"timestamp":"2024-06-01T17:52:04.652805Z"}]}
{"channel":"book","type":"update","data":[{"symbol":"USDT/GBP","bids":[{"price":0.7837,"qty":7526.45982526},{"price":0.7835,"qty":38310.66795588}],"asks":[],"checksum":506418880,"timestamp":"2024-06-01T17:52:04.654088Z"}]}
{"channel":"book","type":"update","data":[{"symbol":"USDT/GBP","bids":[],"asks":[{"price":0.7840,"qty":20581.01025194}],"checksum":1087717634,"timestamp":"2024-06-01T17:52:05.611943Z"}]}
{"channel":"book","type":"update","data":[{"symbol":"USDT/GBP","bids":[{"price":0.7835,"qty":25566.95341476},{"price":0.7837,"qty":20270.17436638}],"asks":[],"checksum":2788056515,"timestamp":"2024-06-01T17:52:05.615209Z"}]}
{"channel":"book","type":"update","data":[{"symbol":"USDT/GBP","bids":[],"asks":[{"price":0.7840,"qty":21767.01025194}],"checksum":1736709673,"timestamp":"2024-06-01T17:52:06.662456Z"}]}
{"channel":"book","type":"update","data":[{"symbol":"USDT/GBP","bids":[{"price":0.7834,"qty":25034.44146162}],"asks":[],"checksum":1534114429,"timestamp":"2024-06-01T17:52:07.137530Z"}]}
{"channel":"book","type":"update","data":[{"symbol":"USDT/GBP","bids":[{"price":0.7834,"qty":117821.26354951}],"asks":[],"checksum":14679249,"timestamp":"2024-06-01T17:52:07.139108Z"}]}
{"channel":"book","type":"update","data":[{"symbol":"USDT/GBP","bids":[],"asks":[{"price":0.7840,"qty":20581.01025194}],"checksum":3245717307,"timestamp":"2024-06-01T17:52:07.633846Z"}]}
{"channel":"book","type":"update","data":[{"symbol":"USDT/GBP","bids":[],"asks":[{"price":0.7841,"qty":8635.09136299}],"checksum":1918154291,"timestamp":"2024-06-01T17:52:07.802327Z"}]}
{"channel":"book","type":"update","data":[{"symbol":"USDT/GBP","bids":[],"asks":[{"price":0.7840,"qty":13057.52479306},{"price":0.7841,"qty":16158.57682187}],"checksum":2580235010,"timestamp":"2024-06-01T17:52:07.805623Z"}]}
{"channel":"book","type":"update","data":[{"symbol":"USDT/GBP","bids":[],"asks":[{"price":0.7840,"qty":13045.14152364},{"price":0.7841,"qty":16170.95416938}],"checksum":3668317337,"timestamp":"2024-06-01T17:52:07.806285Z"}]}
{"channel":"book","type":"update","data":[{"symbol":"USDT/GBP","bids":[],"asks":[{"price":0.7839,"qty":6114.87338465}],"checksum":2517119474,"timestamp":"2024-06-01T17:52:07.806876Z"}]}
{"channel":"book","type":"update","data":[{"symbol":"USDT/GBP","bids":[],"asks":[{"price":0.7841,"qty":252453.70561474}],"checksum":552427026,"timestamp":"2024-06-01T17:52:07.806987Z"}]}
{"channel":"book","type":"update","data":[{"symbol":"USDT/GBP","bids":[{"price":0.7838,"qty":13271.00378588},{"price":0.7837,"qty":20529.52725811}],"asks":[],"checksum":1830510953,"timestamp":"2024-06-01T17:52:07.824059Z"}]}
{"channel":"book","type":"update","data":[{"symbol":"USDT/GBP","bids":[],"asks":[{"price":0.7841,"qty":252441.32826723},{"price":0.7839,"qty":6127.25073216}],"checksum":902531802,"timestamp":"2024-06-01T17:52:07.903125Z"}]}
{"channel":"book","type":"update","data":[{"symbol":"USDT/GBP","bids":[],"asks":[{"price":0.7841,"qty":244917.84280835},{"price":0.7840,"qty":20568.62698252}],"checksum":2661675993,"timestamp":"2024-06-01T17:52:07.906203Z"}]}
{"channel":"book","type":"update","data":[{"symbol":"USDT/GBP","bids":[{"price":0.7828,"qty":10511.26000000}],"asks":[],"checksum":1855150619,"timestamp":"2024-06-01T17:52:08.800313Z"}]}
{"channel":"book","type":"update","data":[{"symbol":"USDT/GBP","bids":[],"asks":[{"price":0.7840,"qty":21775.62698252}],"checksum":2300290962,"timestamp":"2024-06-01T17:52:08.866435Z"}]}
{"channel":"book","type":"update","data":[{"symbol":"USDT/GBP","bids":[{"price":0.7834,"qty":25034.44146162}],"asks":[],"checksum":2232170166,"timestamp":"2024-06-01T17:52:09.607417Z"}]}
{"channel":"book","type":"update","data":[{"symbol":"USDT/GBP","bids":[{"price":0.7834,"qty":119714.87216355}],"asks":[],"checksum":3952735271,"timestamp":"2024-06-01T17:52:09.608004Z"}]}
{"channel":"book","type":"update","data":[{"symbol":"USDT/GBP","bids":[{"price":0.7838,"qty":14271.00378588}],"asks":[],"checksum":221696794,"timestamp":"2024-06-01T17:52:09.613822Z"}]}
{"channel":"book","type":"update","data":[{"symbol":"USDT/GBP","bids":[{"price":0.7838,"qty":14843.25989242}],"asks":[],"checksum":670789562,"timestamp":"2024-06-01T17:52:10.718975Z"}]}
{"channel":"book","type":"update","data":[{"symbol":"USDT/GBP","bids":[],"asks":[{"price":0.7841,"qty":8635.09136299}],"checksum":1617180521,"timestamp":"2024-06-01T17:52:15.095807Z"}]}
{"channel":"book","type":"update","data":[{"symbol":"USDT/GBP","bids":[],"asks":[{"price":0.7839,"qty":12.37734751}],"checksum":162107659,"timestamp":"2024-06-01T17:52:15.095867Z"}]}
{"channel":"book","type":"update","data":[{"symbol":"USDT/GBP","bids":[],"asks":[{"price":0.7840,"qty":14252.14152364},{"price":0.7841,"qty":16158.57682187}],"checksum":2880189930,"timestamp":"2024-06-01T17:52:15.098891Z"}]}
{"channel":"book","type":"update","data":[{"symbol":"USDT/GBP","bids":[],"asks":[{"price":0.7841,"qty":253700.61922865}],"checksum":691546911,"timestamp":"2024-06-01T17:52:15.100362Z"}]}
{"channel":"book","type":"update","data":[{"symbol":"USDT/GBP","bids":[],"asks":[{"price":0.7839,"qty":2013.96861257}],"checksum":4142819781,"timestamp":"2024-06-01T17:52:15.100393Z"}]}
{"channel":"book","type":"update","data":[{"symbol":"USDT/GBP","bids":[],"asks":[{"price":0.7841,"qty":253743.47270230}],"checksum":824342136,"timestamp":"2024-06-01T17:52:15.280229Z"}]}
{"channel":"book","type":"update","data":[{"symbol":"USDT/GBP","bids":[],"asks":[{"price":0.7841,"qty":246219.98724342},{"price":0.7840,"qty":21775.62698252}],"checksum":1163931332,"timestamp":"2024-06-01T17:52:15.283209Z"}]}
{"channel":"book","type":"update","data":[{"symbol":"USDT/GBP","bids":[],"asks":[{"price":0.7840,"qty":21732.77350887}],"checksum":2047649223,"timestamp":"2024-06-01T17:52:15.446675Z"}]}
{"channel":"book","type":"update","data":[{"symbol":"USDT/GBP","bids":[],"asks":[{"price":0.7840,"qty":20525.77350887}],"checksum":2408767757,"timestamp":"2024-06-01T17:52:18.427675Z"}]}
{"channel":"book","type":"update","data":[{"symbol":"USDT/GBP","bids":[],"asks":[{"price":0.7841,"qty":8677.94483664}],"checksum":1365332881,"timestamp":"2024-06-01T17:52:18.665795Z"}]}
{"channel":"book","type":"update","data":[{"symbol":"USDT/GBP","bids":[],"asks":[{"price":0.7840,"qty":13002.28804999},{"price":0.7841,"qty":16201.43029552}],"checksum":1406614093,"timestamp":"2024-06-01T17:52:18.669137Z"}]}
{"channel":"book","type":"update","data":[{"symbol":"USDT/GBP","bids":[],"asks":[{"price":0.7841,"qty":248601.87005280}],"checksum":4095069560,"timestamp":"2024-06-01T17:52:18.670751Z"}]}
{"channel":"book","type":"update","data":[{"symbol":"USDT/GBP","bids":[{"price":0.7828,"qty":13243.56469627}],"asks":[],"checksum":2846659455,"timestamp":"2024-06-01T17:52:19.263924Z"}]}
{"channel":"book","type":"update","data":[{"symbol":"USDT/GBP","bids":[],"asks":[{"price":0.7841,"qty":241078.38459392},{"price":0.7840,"qty":20525.77350887}],"checksum":1151363144,"timestamp":"2024-06-01T17:52:19.266921Z"}]}
{"channel":"book","type":"update","data":[{"symbol":"USDT/GBP","bids":[],"asks":[{"price":0.7840,"qty":21606.77350887}],"checksum":419777085,"timestamp":"2024-06-01T17:52:19.720453Z"}]}
{"channel":"book","type":"update","data":[{"symbol":"USDT/GBP","bids":[{"price":0.7836,"qty":0.00000000},{"price":0.7827,"qty":20533.89000000}],"asks":[],"checksum":621501606,"timestamp":"2024-06-01T17:52:22.070456Z"}]}
